File: 1-C1(0.6mol%)+C20(0.6mol%)/matlab/140-2.txt
CLOSED
Version	1.0
Language	English
Mode	Standard
Run	2
RunSerial	11852
Instrument	DSC Q2000 V24.11 Build 124
Module	DSC Standard Cell RC
Operator	Jing
File	\\AE520-1454\TA\Data\DSC\UQ Composites\Nan\C1(5.5)+C20P(3)+CL(HotplateMixtureAB)\140-2
ProcName	Ramp
InstSerial	2000-0883
AutoSerial	1293
Sample	Iso-140-2
Size	40.4000	mg
PanMass	Not available
PanResist	Automatic Automatic  K/W
PanFactor	Default Default
Method	Ramp
Comment
Xcomment	Pan: Tzero Aluminum Hermetic
Xcomment	Gas1: Nitrogen 50.0 ml/min
Xcomment	Gas2: Nitrogen 50.0 ml/min
Text
Exotherm	UP
Kcell	1.05230
Cpconst	Standard: 0.938
Calib	-38.6961
TempCal	1	pts	157.46	156.60
TzeroDt	-87.6168 -0.0009 -1.4231
TzeroDtz	-87.6168 0.0057 6.9570
InstCalFile	Tzero: \\Ae520-1454\ta\Data\DSC\Calibration\2017\CALIBRATION\1562_RCS (90)_05_18_2017 10_50_44.TZR
InstCalFile	Baseline: \\Ae520-1454\ta\Data\DSC\Calibration\2017\2017-05-17_Calibration.001
InstCalFile	Sapphire: \\Ae520-1454\ta\Data\DSC\Calibration\2017\2017-05-17_Saphire.001
InstCalDate	Tzero 2017-05-18 Time 10:50:44
TempRange	-87.39 to 398.39 °C at 10.00 °C/min Heat Only
AutoZero	Delta T Offset 0.000 uV
AutoZero	Delta T0 Offset 0.000 uV
MultiptCal	0
MultiPtDesc	0) Not set
AutoCellConst	Calibration Date 2017-05-18 16:59:28
Controls	Gas 1  Event Off  Sampling 0.2
Cell#	RC-01562
CoolingUnit	RCS (90)
SelHeatFlow	Heat Flow T4 (mW)
AutoLidII	Installed
AutoAnalysis	Off
MacroFile
Nsig	3
Sig1	Time (min)
Sig2	Temperature (°C)
Sig3	Heat Flow (mW)
Date	2017-06-20
Time	17:46:38
OrgMethod	1: Equilibrate at 20.00 °C
OrgMethod	2: Ramp 40.00 °C/min to 140.00 °C
OrgMethod	3: Mark end of cycle 1
OrgMethod	4: Isothermal for 40.00 min
OrgMethod	5: Mark end of cycle 2
OrgMethod	6: Ramp 20.00 °C/min to 280.00 °C
OrgMethod	7: Mark end of cycle 3
OrgMethod	8: Ramp 20.00 °C/min to 20.00 °C
OrgMethod	9: Mark end of cycle 4
OrgMethod	10: Ramp 20.00 °C/min to 280.00 °C
OrgMethod	11: Mark end of cycle 5
OrgFile	C:\Users\jarra\Desktop\DSC\1-C1(0.6mol%)+C20(0.6mol%)\140-2.001
StartOfData
4.99994E-4	20.05280	0.3234908
0.05383332	20.16814	0.4516726
0.1055000	21.01961	-0.1712709
0.1571666	22.25184	-3.287641
0.2105000	23.71642	-7.375040
0.2605000	25.22348	-11.34482
0.3138333	26.92978	-15.24951
0.3655000	28.66128	-18.55146
0.4171667	30.45065	-21.33252
0.4705000	32.34798	-23.72810
0.5205000	34.16570	-25.59047
0.5738334	36.13350	-27.24054
0.6238334	38.00236	-28.56145
0.6771668	40.01464	-29.76550
0.7288332	41.97647	-30.82865
0.7805000	43.94360	-31.93700
0.8338332	45.97450	-33.07715
0.8838332	47.89298	-33.89165
0.9371668	49.95578	-34.59040
0.9888332	51.96296	-35.23254
1.040500	53.97002	-35.97428
1.092167	55.97193	-36.88684
1.143833	57.96634	-37.93785
1.197166	60.02150	-39.09732
1.247166	61.94656	-40.31012
1.300500	63.98622	-41.94694
1.352166	65.93184	-44.29420
1.403833	67.80976	-48.23072
1.457167	69.61196	-55.37012
1.507167	71.12056	-65.48748
1.560500	72.56849	-78.73151
1.610500	73.85969	-91.72280
1.663834	75.25286	-104.8560
1.715500	76.64170	-117.4008
1.767167	77.98938	-130.7898
1.820500	79.44972	-142.2724
1.870500	80.94505	-150.9590
1.923834	82.70172	-156.7625
1.975500	84.61438	-158.1320
2.027166	86.78324	-155.4905
2.078833	89.00790	-152.9407
2.130500	91.27649	-149.1791
2.183833	93.77791	-140.9999
2.233833	96.46829	-126.6976
2.287166	99.36970	-113.5200
2.338833	102.0677	-102.8956
2.390500	104.6530	-94.23712
2.443833	107.2207	-87.06301
2.493833	109.5483	-81.62408
2.547166	111.9660	-77.00778
2.597167	114.1786	-73.56402
2.650500	116.4941	-70.69184
2.702166	118.6998	-68.52369
2.753833	120.8758	-66.91930
2.807167	123.0961	-65.70584
2.857167	125.1593	-64.90380
2.910500	127.3437	-64.30795
2.962167	129.4472	-63.93896
3.010500	131.4060	-63.76474
3.060500	133.2584	-63.89609
3.113833	134.4478	-62.09632
3.165500	135.2892	-57.04324
3.217166	135.9485	-51.07434
3.270500	136.5002	-44.90703
3.320500	136.9252	-39.67134
3.373834	137.3025	-34.82457
3.425500	137.6076	-30.86466
3.477167	137.8622	-27.56587
3.528833	138.0760	-24.84141
3.580500	138.2556	-22.59047
3.633833	138.4124	-20.68276
3.683833	138.5365	-19.20395
3.737167	138.6486	-17.90212
3.788833	138.7402	-16.85823
3.840500	138.8188	-15.98799
3.893833	138.8877	-15.24329
3.943833	138.9426	-14.65717
3.997166	138.9934	-14.13217
4.047167	139.0349	-13.71103
4.100500	139.0722	-13.33494
4.152166	139.1036	-13.02694
4.203833	139.1308	-12.75590
4.257167	139.1554	-12.51962
4.307167	139.1757	-12.32740
4.360500	139.1942	-12.14945
4.412167	139.2100	-11.99574
4.463834	139.2243	-11.86474
4.515500	139.2370	-11.74334
4.567167	139.2480	-11.63940
4.620500	139.2581	-11.53614
4.670500	139.2666	-11.44766
4.723834	139.2750	-11.36600
4.775500	139.2830	-11.28507
4.827167	139.2912	-11.20548
4.880500	139.2967	-11.11741
4.930500	139.3041	-11.03539
4.983834	139.3108	-10.94751
5.033834	139.3170	-10.86237
5.087167	139.3229	-10.77623
5.138833	139.3290	-10.68903
5.190500	139.3345	-10.60134
5.243834	139.3410	-10.51024
5.293832	139.3462	-10.42319
5.347168	139.3524	-10.32556
5.398834	139.3582	-10.23550
5.450500	139.3628	-10.14452
5.503834	139.3693	-10.04650
5.553834	139.3737	-9.955139
5.607168	139.3795	-9.863134
5.657166	139.3844	-9.777145
5.710500	139.3895	-9.686020
5.762168	139.3942	-9.599208
5.813832	139.3995	-9.517430
5.867168	139.4035	-9.429809
5.917168	139.4090	-9.351445
5.970500	139.4131	-9.268454
6.020500	139.4179	-9.195614
6.073834	139.4213	-9.114684
6.125500	139.4259	-9.041597
6.177166	139.4304	-8.969371
6.230500	139.4337	-8.895186
6.280500	139.4377	-8.822418
6.333832	139.4424	-8.748215
6.385500	139.4464	-8.673187
6.437168	139.4504	-8.602197
6.490500	139.4544	-8.524322
6.540500	139.4573	-8.451968
6.593832	139.4624	-8.377460
6.643832	139.4664	-8.306586
6.697168	139.4709	-8.227268
6.748834	139.4743	-8.149960
6.800500	139.4788	-8.072341
6.853832	139.4824	-7.993012
6.903832	139.4860	-7.913800
6.957168	139.4908	-7.831420
7.008832	139.4948	-7.748149
7.060500	139.5000	-7.663470
7.112168	139.5039	-7.576065
7.163832	139.5084	-7.488419
7.217168	139.5132	-7.403656
7.267168	139.5177	-7.319790
7.320500	139.5224	-7.214668
7.372168	139.5275	-7.107775
7.423834	139.5339	-7.003730
7.477168	139.5390	-6.883442
7.527168	139.5453	-6.783249
7.580500	139.5506	-6.663816
7.630500	139.5562	-6.549905
7.683832	139.5632	-6.419397
7.735500	139.5694	-6.298234
7.787168	139.5757	-6.167202
7.840500	139.5825	-6.020976
7.890500	139.5899	-5.886250
7.943832	139.5971	-5.729968
7.995500	139.6048	-5.568384
8.047168	139.6139	-5.401680
8.098832	139.6225	-5.237106
8.150500	139.6312	-5.064866
8.203834	139.6407	-4.863800
8.253834	139.6509	-4.663696
8.307168	139.6621	-4.439430
8.358832	139.6736	-4.207722
8.410499	139.6863	-3.962766
8.463834	139.6990	-3.699620
8.513832	139.7119	-3.454591
8.567166	139.7242	-3.211254
8.617166	139.7346	-3.021410
8.670500	139.7443	-2.835660
8.722168	139.7529	-2.660808
8.773834	139.7612	-2.498546
8.827168	139.7699	-2.341841
8.877168	139.7764	-2.213272
8.930500	139.7840	-2.088184
8.982166	139.7898	-1.981077
9.033832	139.7944	-1.885224
9.085501	139.7992	-1.803467
9.137168	139.8034	-1.728267
9.190500	139.8071	-1.659294
9.240500	139.8103	-1.601449
9.293834	139.8132	-1.548886
9.345500	139.8159	-1.501650
9.397168	139.8186	-1.459939
9.450500	139.8205	-1.422993
9.500500	139.8225	-1.391965
9.553832	139.8254	-1.363735
9.603832	139.8269	-1.335839
9.657166	139.8272	-1.307447
9.708832	139.8287	-1.285474
9.760499	139.8294	-1.264793
9.813834	139.8316	-1.245760
9.863834	139.8324	-1.229875
9.917168	139.8328	-1.211264
9.968834	139.8345	-1.196315
10.02050	139.8351	-1.182994
10.07217	139.8358	-1.167952
10.12383	139.8366	-1.154947
10.17717	139.8378	-1.143726
10.22717	139.8376	-1.132218
10.28050	139.8390	-1.120806
10.33217	139.8400	-1.109857
10.38383	139.8396	-1.098098
10.43717	139.8401	-1.087076
10.48717	139.8419	-1.076776
10.54050	139.8424	-1.066199
10.59050	139.8426	-1.056028
10.64383	139.8427	-1.045398
10.69550	139.8437	-1.035304
10.74717	139.8439	-1.025454
10.80050	139.8444	-1.015330
10.85050	139.8452	-1.006277
10.90383	139.8462	-0.9965405
10.95550	139.8462	-0.9872926
11.00717	139.8465	-0.9774788
11.05884	139.8473	-0.9683756
11.11050	139.8485	-0.9595382
11.16383	139.8488	-0.9505347
11.21383	139.8484	-0.9420985
11.26717	139.8491	-0.9330828
11.31883	139.8503	-0.9245007
11.37050	139.8509	-0.9156795
11.42383	139.8508	-0.9065216
11.47383	139.8514	-0.8978482
11.52717	139.8516	-0.8889012
11.57717	139.8520	-0.8803801
11.63050	139.8525	-0.8714102
11.68217	139.8533	-0.8628076
11.73383	139.8534	-0.8542697
11.78717	139.8542	-0.8456176
11.83717	139.8543	-0.8377356
11.89050	139.8551	-0.8289152
11.94217	139.8554	-0.8204522
11.99384	139.8552	-0.8116837
12.04717	139.8557	-0.8027332
12.09717	139.8563	-0.7944629
12.15050	139.8562	-0.7854275
12.20050	139.8579	-0.7772984
12.25384	139.8574	-0.7686488
12.30550	139.8580	-0.7598378
12.35717	139.8586	-0.7512738
12.41050	139.8591	-0.7425249
12.46050	139.8592	-0.7343784
12.51383	139.8604	-0.7258809
12.56383	139.8606	-0.7177695
12.61716	139.8607	-0.7092194
12.66883	139.8618	-0.7006978
12.72050	139.8624	-0.6920000
12.77383	139.8627	-0.6834098
12.82384	139.8633	-0.6751348
12.87717	139.8639	-0.6663192
12.92883	139.8644	-0.6575696
12.98050	139.8640	-0.6478944
13.03383	139.8658	-0.6384200
13.08383	139.8658	-0.6293090
13.13717	139.8665	-0.6199094
13.18716	139.8663	-0.6099936
13.24050	139.8672	-0.6008618
13.29216	139.8676	-0.5917970
13.34383	139.8683	-0.5825184
13.39717	139.8687	-0.5729877
13.44717	139.8695	-0.5641271
13.50050	139.8700	-0.5543484
13.55217	139.8701	-0.5441978
13.60383	139.8700	-0.5348582
13.65550	139.8714	-0.5250996
13.70717	139.8716	-0.5147790
13.76050	139.8716	-0.5043951
13.81050	139.8723	-0.4949274
13.86383	139.8730	-0.4839252
13.91550	139.8741	-0.4732051
13.96716	139.8738	-0.4618348
14.02050	139.8750	-0.4509464
14.07050	139.8754	-0.4409388
14.12384	139.8762	-0.4288104
14.17383	139.8770	-0.4183354
14.22717	139.8777	-0.4065045
14.27883	139.8777	-0.3942430
14.33050	139.8793	-0.3807059
14.38383	139.8802	-0.3687284
14.43383	139.8800	-0.3534828
14.48716	139.8810	-0.3375416
14.53883	139.8820	-0.3196354
14.59050	139.8826	-0.3012484
14.64216	139.8831	-0.2828544
14.69384	139.8848	-0.2609985
14.74717	139.8859	-0.2401949
14.79717	139.8866	-0.2190666
14.85050	139.8875	-0.1948218
14.90217	139.8889	-0.1707209
14.95383	139.8900	-0.1438672
15.00717	139.8915	-0.1148367
15.05717	139.8926	-.08675388
15.11050	139.8937	-.05726543
15.16050	139.8958	-.02817630
15.21383	139.8970	.002770760
15.26550	139.8986	0.03415588
15.31716	139.9010	0.06991724
15.37050	139.9028	0.1075552
15.42050	139.9037	0.1424726
15.47383	139.9058	0.1811862
15.52550	139.9076	0.2180220
15.57717	139.9091	0.2565006
15.62883	139.9117	0.2951028
15.68050	139.9138	0.3349592
15.73383	139.9163	0.3803435
15.78383	139.9180	0.4197036
15.83717	139.9207	0.4638891
15.88883	139.9216	0.5061674
15.94050	139.9245	0.5492214
15.99383	139.9260	0.5938918
16.04383	139.9285	0.6362203
16.09717	139.9316	0.6822180
16.14716	139.9336	0.7236782
16.20050	139.9362	0.7709347
16.25217	139.9371	0.8132418
16.30383	139.9400	0.8547189
16.35716	139.9416	0.8997360
16.40716	139.9450	0.9391759
16.46050	139.9469	0.9815994
16.51216	139.9486	1.023419
16.56383	139.9508	1.066000
16.61550	139.9524	1.108652
16.66716	139.9547	1.148672
16.72050	139.9560	1.191161
16.77050	139.9589	1.228666
16.82383	139.9610	1.269353
16.87550	139.9626	1.308745
16.92716	139.9647	1.346808
16.98050	139.9667	1.386003
17.03050	139.9682	1.422912
17.08383	139.9707	1.462012
17.13383	139.9735	1.496847
17.18716	139.9756	1.538004
17.23883	139.9769	1.573467
17.29050	139.9781	1.612749
17.34383	139.9806	1.649203
17.39383	139.9824	1.685541
17.44716	139.9843	1.721344
17.49883	139.9862	1.757364
17.55050	139.9876	1.793693
17.60216	139.9894	1.829303
17.65383	139.9906	1.864126
17.70716	139.9931	1.898495
17.75716	139.9949	1.934512
17.81050	139.9973	1.970487
17.86216	139.9988	2.004372
17.91383	140.0007	2.040616
17.96716	140.0024	2.077091
18.01716	140.0038	2.110677
18.07050	140.0064	2.146002
18.12050	140.0079	2.177985
18.17383	140.0090	2.215593
18.22550	140.0119	2.248376
18.27716	140.0130	2.283372
18.33050	140.0142	2.321384
18.38050	140.0159	2.353600
18.43383	140.0175	2.388508
18.48550	140.0197	2.419458
18.53717	140.0207	2.452974
18.59050	140.0224	2.486339
18.64050	140.0246	2.519360
18.69383	140.0261	2.552440
18.74383	140.0275	2.585537
18.79716	140.0304	2.617795
18.84883	140.0317	2.649334
18.90050	140.0336	2.681484
18.95383	140.0356	2.714184
19.00383	140.0373	2.745167
19.05716	140.0383	2.779220
19.10716	140.0403	2.811184
19.16050	140.0416	2.844516
19.21216	140.0438	2.874478
19.26383	140.0448	2.908313
19.31716	140.0465	2.939556
19.36716	140.0482	2.970628
19.42050	140.0494	3.001451
19.47216	140.0518	3.032766
19.52383	140.0532	3.063528
19.57716	140.0548	3.095578
19.62716	140.0558	3.126736
19.68050	140.0574	3.156520
19.73050	140.0593	3.185398
19.78383	140.0603	3.217640
19.83550	140.0622	3.249066
19.88716	140.0639	3.282924
19.94050	140.0654	3.312388
19.99050	140.0666	3.342556
20.04383	140.0691	3.371756
20.09550	140.0702	3.401660
20.14716	140.0722	3.432022
20.19884	140.0738	3.462912
20.25050	140.0752	3.493132
20.30383	140.0766	3.525306
20.35383	140.0779	3.555854
20.40716	140.0792	3.587456
20.45883	140.0810	3.616713
20.51050	140.0826	3.648098
20.56383	140.0833	3.681170
20.61383	140.0851	3.709419
20.66716	140.0873	3.739804
20.71716	140.0884	3.768550
20.77050	140.0901	3.800064
20.82216	140.0911	3.829340
20.87383	140.0931	3.859457
20.92717	140.0952	3.890008
20.97716	140.0962	3.919766
21.03050	140.0982	3.953558
21.08216	140.0996	3.982468
21.13383	140.1011	4.012858
21.18550	140.1024	4.043846
21.23716	140.1051	4.070974
21.29050	140.1061	4.101928
21.34050	140.1073	4.133205
21.39383	140.1087	4.163860
21.44550	140.1102	4.192950
21.49716	140.1116	4.223678
21.55050	140.1139	4.255458
21.60050	140.1150	4.284772
21.65383	140.1169	4.314520
21.70383	140.1185	4.343781
21.75716	140.1199	4.375565
21.80883	140.1214	4.405682
21.86050	140.1227	4.435156
21.91383	140.1247	4.464644
21.96383	140.1256	4.493332
22.01716	140.1279	4.524906
22.06883	140.1286	4.554092
22.12050	140.1303	4.583946
22.17216	140.1322	4.611626
22.22383	140.1329	4.640050
22.27717	140.1345	4.670307
22.32716	140.1362	4.697148
22.38050	140.1386	4.726802
22.43216	140.1395	4.755391
22.48383	140.1406	4.785426
22.53717	140.1418	4.815776
22.58716	140.1437	4.841141
22.64050	140.1448	4.868106
22.69050	140.1460	4.896194
22.74383	140.1476	4.924374
22.79550	140.1488	4.952090
22.84716	140.1502	4.980876
22.90050	140.1512	5.005722
22.95050	140.1532	5.031510
23.00383	140.1550	5.055826
23.05550	140.1560	5.081090
23.10716	140.1569	5.107437
23.15883	140.1586	5.133162
23.21050	140.1597	5.155890
23.26383	140.1618	5.181826
23.31383	140.1624	5.200738
23.36716	140.1636	5.225490
23.41883	140.1649	5.246929
23.47050	140.1662	5.269520
23.52383	140.1672	5.295058
23.57383	140.1680	5.316445
23.62716	140.1695	5.334768
23.67717	140.1704	5.353783
23.73050	140.1704	5.374557
23.78216	140.1719	5.388244
23.83383	140.1736	5.404400
23.88716	140.1734	5.419788
23.93716	140.1737	5.435121
23.99050	140.1749	5.450650
24.04216	140.1764	5.462282
24.09383	140.1760	5.475674
24.14550	140.1774	5.488329
24.19716	140.1779	5.502887
24.25050	140.1786	5.514558
24.30050	140.1794	5.524439
24.35383	140.1793	5.534185
24.40550	140.1807	5.542810
24.45717	140.1813	5.551270
24.51050	140.1810	5.559620
24.56050	140.1817	5.566980
24.61383	140.1822	5.574082
24.66383	140.1820	5.580304
24.71716	140.1822	5.586168
24.76883	140.1824	5.591125
24.82050	140.1820	5.595656
24.87383	140.1824	5.599566
24.92383	140.1817	5.602660
24.97716	140.1822	5.604813
25.02883	140.1821	5.605871
25.08050	140.1818	5.606985
25.13383	140.1824	5.608696
25.18383	140.1811	5.604908
25.23716	140.1814	5.600022
25.28717	140.1809	5.595410
25.34050	140.1796	5.590176
25.39216	140.1796	5.583968
25.44383	140.1789	5.576889
25.49716	140.1783	5.569196
25.54716	140.1782	5.562157
25.60050	140.1780	5.554180
25.65050	140.1777	5.546244
25.70383	140.1768	5.536934
25.75550	140.1771	5.527198
25.80716	140.1759	5.516865
25.86050	140.1752	5.505865
25.91050	140.1749	5.493519
25.96383	140.1740	5.480240
26.01550	140.1734	5.465820
26.06716	140.1720	5.452771
26.12050	140.1722	5.437324
26.17050	140.1712	5.421682
26.22383	140.1697	5.407261
26.27383	140.1693	5.391033
26.32717	140.1678	5.371255
26.37883	140.1673	5.353540
26.43050	140.1669	5.334122
26.48383	140.1655	5.310520
26.53383	140.1650	5.287856
26.58716	140.1633	5.265757
26.63883	140.1633	5.243271
26.69050	140.1617	5.223600
26.74216	140.1605	5.204887
26.79383	140.1596	5.185196
26.84716	140.1583	5.162226
26.89716	140.1569	5.140824
26.95050	140.1563	5.119153
27.00217	140.1551	5.095863
27.05383	140.1543	5.073543
27.10716	140.1528	5.049582
27.15716	140.1516	5.030464
27.21050	140.1509	5.004843
27.26050	140.1494	4.979835
27.31383	140.1470	4.955384
27.36550	140.1468	4.929084
27.41716	140.1463	4.903906
27.47050	140.1442	4.879612
27.52050	140.1431	4.857481
27.57383	140.1416	4.832250
27.62550	140.1398	4.807253
27.67717	140.1393	4.778992
27.72883	140.1380	4.752781
27.78050	140.1367	4.726734
27.83383	140.1352	4.701563
27.88383	140.1342	4.677914
27.93717	140.1334	4.650702
27.98883	140.1316	4.625148
28.04050	140.1299	4.597371
28.09383	140.1285	4.570216
28.14383	140.1272	4.543768
28.19717	140.1263	4.514276
28.24716	140.1249	4.490859
28.30050	140.1238	4.465239
28.35217	140.1223	4.439130
28.40383	140.1210	4.413861
28.45716	140.1197	4.386134
28.50716	140.1183	4.360039
28.56050	140.1173	4.336120
28.61216	140.1158	4.311344
28.66383	140.1148	4.283956
28.71550	140.1134	4.259924
28.76716	140.1119	4.233300
28.82050	140.1114	4.206637
28.87050	140.1088	4.183395
28.92383	140.1086	4.155731
28.97550	140.1069	4.131791
29.02717	140.1050	4.107480
29.08050	140.1044	4.081448
29.13050	140.1024	4.058695
29.18383	140.1007	4.034088
29.23383	140.1010	4.011560
29.28717	140.0990	3.985348
29.33883	140.0980	3.963876
29.39050	140.0962	3.940520
29.44383	140.0952	3.915878
29.49383	140.0945	3.892363
29.54716	140.0928	3.868346
29.59883	140.0920	3.846164
29.65050	140.0910	3.823120
29.70217	140.0894	3.801480
29.75383	140.0884	3.778906
29.80716	140.0874	3.755410
29.85716	140.0858	3.732060
29.91050	140.0852	3.707158
29.96216	140.0845	3.687155
30.01383	140.0832	3.666070
30.06716	140.0826	3.645066
30.11716	140.0810	3.622434
30.17050	140.0806	3.600958
30.22050	140.0789	3.580563
30.27383	140.0776	3.560191
30.32550	140.0769	3.540294
30.37716	140.0764	3.521825
30.43050	140.0744	3.500216
30.48050	140.0736	3.480528
30.53383	140.0727	3.458784
30.58550	140.0719	3.440167
30.63716	140.0702	3.419414
30.68883	140.0687	3.399600
30.74050	140.0681	3.380163
30.79383	140.0675	3.359406
30.84383	140.0654	3.341504
30.89716	140.0649	3.324542
30.94883	140.0638	3.304484
31.00050	140.0628	3.284640
31.05383	140.0620	3.264442
31.10383	140.0609	3.245729
31.15716	140.0598	3.226201
31.20716	140.0584	3.208172
31.26050	140.0573	3.186112
31.31217	140.0569	3.167794
31.36383	140.0559	3.148550
31.41716	140.0549	3.130400
31.46716	140.0539	3.115071
31.52050	140.0530	3.095526
31.57217	140.0523	3.075094
31.62383	140.0521	3.056135
31.67717	140.0504	3.039222
31.72717	140.0494	3.023265
31.78050	140.0493	3.006608
31.83050	140.0476	2.990034
31.88383	140.0469	2.972940
31.93550	140.0462	2.955960
31.98717	140.0462	2.935274
32.04050	140.0450	2.919976
32.09050	140.0438	2.903563
32.14383	140.0431	2.886127
32.19383	140.0423	2.866780
32.24716	140.0414	2.850363
32.29883	140.0409	2.832827
32.35050	140.0394	2.816854
32.40383	140.0384	2.800058
32.45383	140.0379	2.782831
32.50716	140.0371	2.765596
32.55883	140.0366	2.749621
32.61050	140.0358	2.733258
32.66383	140.0351	2.716224
32.71383	140.0329	2.700424
32.76716	140.0332	2.685988
32.81716	140.0320	2.669565
32.87050	140.0310	2.653300
32.92216	140.0301	2.637790
32.97383	140.0291	2.622560
33.02716	140.0287	2.605312
33.07717	140.0278	2.590156
33.13050	140.0264	2.574521
33.18216	140.0266	2.556164
33.23383	140.0250	2.539496
33.28550	140.0246	2.524556
33.33716	140.0242	2.508720
33.39050	140.0230	2.491889
33.44050	140.0218	2.477654
33.49383	140.0211	2.460018
33.54550	140.0204	2.444715
33.59716	140.0194	2.429350
33.65050	140.0180	2.414687
33.70050	140.0187	2.399509
33.75383	140.0172	2.385150
33.80383	140.0162	2.370483
33.85716	140.0152	2.354799
33.90883	140.0145	2.339632
33.96050	140.0146	2.323008
34.01383	140.0139	2.306725
34.06383	140.0127	2.291538
34.11716	140.0122	2.273047
34.16883	140.0110	2.258111
34.22050	140.0110	2.243624
34.27217	140.0100	2.229355
34.32383	140.0088	2.216276
34.37717	140.0082	2.202310
34.42717	140.0078	2.188264
34.48050	140.0067	2.173434
34.53216	140.0059	2.159176
34.58383	140.0048	2.145114
34.63716	140.0041	2.129740
34.68716	140.0036	2.116208
34.74050	140.0024	2.101387
34.79050	140.0017	2.086618
34.84384	140.0016	2.071308
34.89550	140.0006	2.057526
34.94717	140.0002	2.041545
35.00050	139.9996	2.026380
35.05050	139.9990	2.010757
35.10383	139.9981	1.997552
35.15550	139.9972	1.981586
35.20716	139.9969	1.966991
35.25883	139.9958	1.954638
35.31050	139.9946	1.940216
35.36383	139.9939	1.927459
35.41383	139.9942	1.915186
35.46716	139.9926	1.901736
35.51883	139.9921	1.889596
35.57050	139.9910	1.876592
35.62383	139.9906	1.863314
35.67383	139.9895	1.848541
35.72717	139.9890	1.834541
35.77716	139.9877	1.818690
35.83050	139.9878	1.804047
35.88216	139.9873	1.789606
35.93384	139.9860	1.775713
35.98717	139.9854	1.760700
36.03717	139.9849	1.746687
36.09050	139.9840	1.733390
36.14216	139.9838	1.718472
36.19383	139.9827	1.704650
36.24550	139.9822	1.692323
36.29716	139.9812	1.679839
36.35050	139.9814	1.664349
36.40050	139.9802	1.651752
36.45383	139.9797	1.637430
36.50550	139.9789	1.626108
36.55716	139.9783	1.612900
36.61050	139.9776	1.600544
36.66050	139.9759	1.587778
36.71383	139.9764	1.573377
36.76383	139.9753	1.559669
36.81716	139.9737	1.547800
36.86883	139.9735	1.534876
36.92050	139.9730	1.521584
36.97383	139.9730	1.507510
37.02383	139.9710	1.494925
37.07717	139.9714	1.481224
37.12883	139.9701	1.466934
37.18050	139.9696	1.452188
37.23216	139.9692	1.438281
37.28383	139.9683	1.426410
37.33716	139.9673	1.413595
37.38716	139.9673	1.401949
37.44050	139.9663	1.389152
37.49216	139.9659	1.376832
37.54383	139.9654	1.363156
37.59716	139.9654	1.347126
37.64717	139.9640	1.334581
37.70050	139.9636	1.322616
37.75050	139.9627	1.311143
37.80383	139.9619	1.299001
37.85550	139.9614	1.287045
37.90716	139.9603	1.272382
37.96050	139.9598	1.259179
38.01050	139.9594	1.248478
38.06383	139.9586	1.233522
38.11550	139.9588	1.220608
38.16716	139.9576	1.208195
38.22050	139.9566	1.194452
38.27050	139.9566	1.181847
38.32383	139.9559	1.169042
38.37383	139.9546	1.157603
38.42717	139.9540	1.145767
38.47883	139.9536	1.131283
38.53050	139.9533	1.118339
38.58383	139.9520	1.105678
38.63383	139.9517	1.092494
38.68716	139.9507	1.080518
38.73717	139.9504	1.067167
38.79050	139.9502	1.055266
38.84216	139.9494	1.043195
38.89383	139.9491	1.031652
38.94717	139.9476	1.018272
38.99716	139.9468	1.006296
39.05050	139.9463	0.9931124
39.10217	139.9464	0.9792616
39.15383	139.9456	0.9664726
39.20716	139.9446	0.9534516
39.25716	139.9448	0.9410744
39.31050	139.9436	0.9286601
39.36050	139.9439	0.9162921
39.41383	139.9425	0.9039136
39.46550	139.9419	0.8907672
39.51716	139.9418	0.8789747
39.57050	139.9401	0.8663312
39.62050	139.9400	0.8541034
39.67383	139.9389	0.8414111
39.72550	139.9383	0.8313951
39.77716	139.9375	0.8217132
39.82883	139.9373	0.8104622
39.88050	139.9365	0.7962768
39.93384	139.9350	0.7831808
39.98383	139.9355	0.7662800
40.03717	139.9346	0.7531281
40.08883	139.9336	0.7383634
40.14050	139.9334	0.7231738
40.19383	139.9320	0.7072511
40.24383	139.9319	0.6924500
40.29716	139.9317	0.6803222
40.34716	139.9304	0.6687602
40.40050	139.9290	0.6550412
40.45216	139.9286	0.6402063
40.50383	139.9286	0.6269877
40.55716	139.9284	0.6123308
40.60716	139.9266	0.6001244
40.66050	139.9260	0.5858993
40.71216	139.9252	0.5720282
40.76383	139.9250	0.5589466
40.81550	139.9240	0.5454960
40.86716	139.9232	0.5300930
40.92050	139.9224	0.5151365
40.97050	139.9215	0.5024814
41.02383	139.9206	0.4878844
41.07550	139.9202	0.4742929
41.12717	139.9204	0.4596730
41.18050	139.9188	0.4427691
41.23050	139.9179	0.4284003
41.28383	139.9164	0.4135437
41.33383	139.9164	0.3985979
41.38716	139.9165	0.3816279
41.43883	139.9148	0.3668836
41.49050	139.9145	0.3546151
41.54383	139.9137	0.3374064
41.59384	139.9124	0.3228928
41.64717	139.9125	0.3073165
41.69883	139.9111	0.2924330
41.75050	139.9114	0.2762550
41.80217	139.9104	0.2605330
41.85383	139.9088	0.2466929
41.90717	139.9085	0.2305787
41.95717	139.9082	0.2130274
42.01050	139.9069	0.1981130
42.06216	139.9064	0.1837919
42.11383	139.9051	0.1702089
42.16716	139.9046	0.1559873
42.21717	139.9030	0.1408736
42.27050	139.9022	0.1241438
42.32050	139.9018	0.1098378
42.37383	139.9011	0.09098179
42.42550	139.8997	0.07261447
42.47717	139.8996	0.05507460
42.53050	139.8980	0.03756613
42.58050	139.8968	0.02496282
42.63383	139.8964	.007734738
42.68550	139.8960	-7.8078E-3
42.73717	139.8955	-.02488652
42.78883	139.8947	-.04160211
42.84050	139.8941	-.05722729
42.89383	139.8936	-.07420926
42.94383	139.8914	-.09078843
42.99716	139.8913	-0.1075210
43.04550	139.9218	-0.1282431
43.09716	140.2824	-0.5005557
43.15050	140.8923	-2.737556
43.20050	141.5577	-5.528776
43.25383	142.3395	-8.611906
43.30550	143.1505	-11.35514
43.35717	144.0026	-13.74142
43.41050	144.9151	-15.80808
43.46050	145.7960	-17.41479
43.51383	146.7567	-18.82372
43.56383	147.6749	-19.91247
43.61716	148.6692	-20.86228
43.66883	149.6442	-21.61966
43.72050	150.6289	-22.24556
43.77383	151.6514	-22.78284
43.82383	152.6168	-23.20671
43.87717	153.6526	-23.60124
43.92883	154.6590	-23.92241
43.98050	155.6694	-24.20586
44.03217	156.6827	-24.46084
44.08383	157.6978	-24.69088
44.13716	158.7478	-24.90813
44.18716	159.7342	-25.09450
44.24050	160.7854	-25.27845
44.29217	161.8079	-25.46318
44.34384	162.8302	-25.63657
44.39717	163.8864	-25.80736
44.44717	164.8769	-25.96990
44.50050	165.9341	-26.13325
44.55050	166.9248	-26.29337
44.60383	167.9817	-26.46858
44.65550	169.0060	-26.63252
44.70717	170.0302	-26.80985
44.76050	171.0878	-27.00296
44.81050	172.0801	-27.17676
44.86383	173.1382	-27.37603
44.91550	174.1627	-27.56293
44.96717	175.1863	-27.75868
45.01883	176.2114	-27.96248
45.07050	177.2351	-28.17363
45.12383	178.2917	-28.39941
45.17383	179.2824	-28.61950
45.22717	180.3374	-28.86372
45.27883	181.3597	-29.11844
45.33050	182.3822	-29.38436
45.38383	183.4373	-29.66318
45.43383	184.4263	-29.94381
45.48717	185.4803	-30.24902
45.53717	186.4677	-30.53738
45.59050	187.5209	-30.86162
45.64217	188.5402	-31.18987
45.69383	189.5590	-31.52498
45.74716	190.6086	-31.90302
45.79716	191.5925	-32.26894
45.85050	192.6426	-32.68402
45.90216	193.6582	-33.09292
45.95383	194.6738	-33.52045
46.00717	195.7209	-33.97845
46.05717	196.7022	-34.43650
46.11050	197.7462	-34.95362
46.16050	198.7254	-35.46214
46.21383	199.7666	-36.04042
46.26550	200.7744	-36.64408
46.31717	201.7801	-37.28561
46.37050	202.8164	-38.00617
46.42050	203.7854	-38.72972
46.47383	204.8171	-39.56622
46.52383	205.7813	-40.42164
46.57717	206.8049	-41.40954
46.62883	207.7927	-42.46370
46.68050	208.7760	-43.63450
46.73383	209.7852	-44.97434
46.78383	210.7248	-46.38585
46.83716	211.7183	-48.08262
46.88883	212.6726	-49.94978
46.94050	213.6133	-52.09339
46.99383	214.5705	-54.63484
47.04383	215.4538	-57.36232
47.09716	216.3777	-60.67046
47.14717	217.2266	-64.15358
47.20050	218.1152	-68.24134
47.25217	218.9612	-72.50007
47.30383	219.7963	-76.92460
47.35717	220.6580	-81.43259
47.40717	221.4841	-85.09358
47.46050	222.4180	-87.51484
47.51216	223.4070	-87.91113
47.56383	224.4730	-86.82860
47.61550	225.5934	-84.58747
47.66716	226.7621	-81.39764
47.72050	228.0132	-77.09122
47.77050	229.2309	-72.02740
47.82383	230.5816	-65.50744
47.87550	231.9084	-59.27428
47.92717	233.1994	-54.03844
47.98050	234.4831	-49.67602
48.03050	235.6449	-46.41508
48.08383	236.8518	-43.64540
48.13383	237.9542	-41.58750
48.18716	239.1089	-39.85042
48.23883	240.2096	-38.52612
48.29050	241.2960	-37.48166
48.34384	242.4077	-36.64492
48.39383	243.4406	-36.01556
48.44717	244.5369	-35.48793
48.49883	245.5911	-35.08469
48.55050	246.6430	-34.76822
48.60217	247.6896	-34.51103
48.65383	248.7340	-34.31730
48.70717	249.8097	-34.15578
48.75717	250.8174	-34.05350
48.81050	251.8910	-33.97192
48.86217	252.9295	-33.91297
48.91383	253.9675	-33.87472
48.96717	255.0376	-33.84407
49.01717	256.0397	-33.82937
49.07050	257.1094	-33.82615
49.12050	258.1106	-33.82532
49.17383	259.1784	-33.82825
49.22550	260.2123	-33.84601
49.27716	261.2471	-33.87590
49.33050	262.3130	-33.90940
49.38050	263.3145	-33.96368
49.43383	264.3806	-34.00178
49.48550	265.4135	-34.04904
49.53717	266.4462	-34.09531
49.58883	267.4805	-34.13898
49.64050	268.5130	-34.18709
49.69383	269.5787	-34.23961
49.74383	270.5798	-34.28206
49.79716	271.6455	-34.32050
49.84883	272.6783	-34.35834
49.90050	273.7121	-34.39798
49.95383	274.7784	-34.43766
50.00050	275.7124	-34.47772
50.05383	276.6543	-34.58859
50.10550	276.8161	-32.52890
50.15717	276.6087	-26.58850
50.21050	276.1863	-19.28522
50.26050	275.6685	-12.58921
50.31383	275.0187	-6.229138
50.36550	274.3152	-0.9863303
50.41716	273.5542	3.405891
50.47050	272.7204	7.157864
50.52050	271.9034	10.07136
50.57383	271.0005	12.62941
50.62383	270.1282	14.59378
50.67717	269.1759	16.31413
50.72883	268.2349	17.68761
50.78050	267.2805	18.81910
50.83383	266.2822	19.78858
50.88383	265.3368	20.54376
50.93716	264.3180	21.20584
50.98883	263.3262	21.74730
51.04050	262.3280	22.19826
51.09217	261.3252	22.57898
51.14383	260.3194	22.90733
51.19717	259.2776	23.18695
51.24717	258.2980	23.41331
51.30050	257.2507	23.62414
51.35217	256.2338	23.79810
51.40383	255.2151	23.95245
51.45717	254.1615	24.07807
51.50717	253.1725	24.16022
51.56050	252.1162	24.25056
51.61050	251.1260	24.32824
51.66383	250.0692	24.39952
51.71550	249.0442	24.46868
51.76716	248.0198	24.53096
51.82050	246.9604	24.59130
51.87050	245.9685	24.63142
51.92383	244.9097	24.67749
51.97550	243.8824	24.71778
52.02717	242.8566	24.74425
52.07883	241.8296	24.77250
52.13050	240.8031	24.79465
52.18383	239.7427	24.81978
52.23383	238.7473	24.84761
52.28716	237.6873	24.87378
52.33883	236.6584	24.88951
52.39050	235.6294	24.91658
52.44384	234.5683	24.92600
52.49382	233.5734	24.93322
52.54717	232.5115	24.94011
52.59716	231.5177	24.94598
52.65050	230.4552	24.95345
52.70216	229.4270	24.96138
52.75383	228.3980	24.96944
52.80717	227.3364	24.98448
52.85717	226.3412	24.99680
52.91050	225.2794	25.00759
52.96216	224.2502	25.02366
53.01382	223.2210	25.03451
53.06550	222.1916	25.04352
53.11716	221.1615	25.05198
53.17050	220.0996	25.06002
53.22050	219.1030	25.06786
53.27383	218.0411	25.07632
53.32550	217.0119	25.08314
53.37717	215.9835	25.08942
53.43050	214.9208	25.09566
53.48050	213.9255	25.10125
53.53383	212.8626	25.10700
53.58383	211.8679	25.11183
53.63716	210.8047	25.11710
53.68882	209.7758	25.12248
53.74050	208.7459	25.12774
53.79382	207.6825	25.13228
53.84384	206.6856	25.13606
53.89717	205.6223	25.13894
53.94883	204.5923	25.14000
54.00050	203.5617	25.14002
54.05217	202.5319	25.13846
54.10383	201.5027	25.13422
54.15717	200.4401	25.12954
54.20717	199.4438	25.12522
54.26050	198.3815	25.12116
54.31216	197.3513	25.11782
54.36382	196.3227	25.11455
54.41716	195.2600	25.11195
54.46717	194.2640	25.11127
54.52050	193.2015	25.11180
54.57050	192.2050	25.11268
54.62383	191.1430	25.11344
54.67550	190.1132	25.11441
54.72717	189.0832	25.11457
54.78050	188.0201	25.11482
54.83050	187.0237	25.11447
54.88383	185.9601	25.11392
54.93550	184.9308	25.11309
54.98717	183.9006	25.11154
55.03882	182.8706	25.10867
55.09050	181.8394	25.10633
55.14384	180.7772	25.10332
55.19384	179.7782	25.10029
55.24717	178.7149	25.09739
55.29883	177.6853	25.09502
55.35050	176.6544	25.09355
55.40383	175.5907	25.09299
55.45383	174.5939	25.09350
55.50717	173.5308	25.09525
55.55717	172.5339	25.09781
55.61050	171.4708	25.10133
55.66216	170.4422	25.10794
55.71382	169.4133	25.14062
55.76716	168.3538	25.20703
55.81716	167.3610	25.30594
55.87050	166.3050	25.50395
55.92217	165.2909	25.88299
55.97382	164.2908	26.63258
56.02717	163.2854	28.04728
56.07717	162.3799	30.19528
56.13050	161.4617	33.51467
56.18050	160.6501	37.57214
56.23383	159.8247	42.63348
56.28550	159.0460	47.73593
56.33716	158.2586	52.46641
56.39050	157.4104	56.42834
56.44050	156.5632	58.99228
56.49382	155.5954	60.37902
56.54382	154.6258	60.45655
56.59716	153.5326	59.40351
56.64883	152.4241	57.47930
56.70050	151.2810	54.94438
56.75383	150.0763	51.96074
56.80383	148.9386	49.07233
56.85717	147.7251	46.09116
56.90883	146.5603	43.43258
56.96050	145.4089	41.06396
57.01382	144.2344	38.93510
57.06382	143.1461	37.19998
57.11716	141.9985	35.60238
57.16716	140.9334	34.31808
57.22050	139.8081	33.13438
57.27217	138.7261	32.14796
57.32383	137.6519	31.30625
57.37717	136.5490	30.55152
57.42717	135.5202	29.93952
57.48050	134.4266	29.37128
57.53217	133.3716	28.89112
57.58383	132.3192	28.46802
57.63550	131.2690	28.09336
57.68716	130.2215	27.75691
57.74050	129.1429	27.45633
57.79050	128.1333	27.20370
57.84384	127.0566	26.96400
57.89550	126.0151	26.75356
57.94717	124.9744	26.55888
58.00050	123.9012	26.37984
58.05050	122.8954	26.20712
58.10383	121.8229	26.03327
58.15383	120.8192	25.89444
58.20717	119.7494	25.74922
58.25883	118.7112	25.61865
58.31050	117.6751	25.49647
58.36382	116.6052	25.38619
58.41382	115.6025	25.28373
58.46717	114.5342	25.17735
58.51884	113.4987	25.07525
58.57050	112.4626	24.98127
58.62217	111.4281	24.88877
58.67383	110.3922	24.78812
58.72717	109.3247	24.68873
58.77717	108.3215	24.60432
58.83050	107.2551	24.51216
58.88217	106.2204	24.41878
58.93383	105.1857	24.33031
58.98717	104.1183	24.24562
59.03716	103.1169	24.17520
59.09050	102.0493	24.10052
59.14050	101.0482	24.02263
59.19384	99.98038	23.94411
59.24550	98.94589	23.86982
59.29717	97.91203	23.78654
59.35050	96.84389	23.72192
59.40050	95.84321	23.64490
59.45383	94.77593	23.56391
59.50550	93.74175	23.50942
59.55717	92.70761	23.42768
59.60883	91.67371	23.35150
59.66050	90.63960	23.28298
59.71382	89.57244	23.19944
59.76382	88.57153	23.12828
59.81716	87.50508	23.06004
59.86882	86.47112	22.98234
59.92050	85.43686	22.90852
59.97382	84.36969	22.83085
60.02383	83.36881	22.77323
60.07717	82.30170	22.70432
60.12717	81.30108	22.63576
60.18050	80.23363	22.55472
60.23217	79.19995	22.48588
60.28383	78.16563	22.41904
60.33716	77.09830	22.35242
60.38716	76.09724	22.29207
60.44050	75.03066	22.22600
60.49216	73.99690	22.15461
60.54382	72.96314	22.08623
60.59550	71.92860	22.02455
60.64717	70.89545	21.96083
60.70050	69.82800	21.89416
60.75050	68.82782	21.82898
60.80383	67.76038	21.75610
60.85550	66.72659	21.68506
60.90717	65.69299	21.61889
60.96050	64.62580	21.55237
61.01050	63.62493	21.48290
61.06382	62.55692	21.40055
61.11382	61.55636	21.31789
61.16716	60.48668	21.24234
61.21884	59.45348	21.15876
61.27050	58.41699	21.05775
61.32383	57.35031	20.98963
61.37383	56.34954	20.92032
61.42717	55.28242	20.85453
61.47883	54.24921	20.79604
61.53050	53.21536	20.72130
61.58217	52.18088	20.64558
61.63383	51.14567	20.57306
61.68716	50.07786	20.49414
61.73717	49.07780	20.42161
61.79050	48.00850	20.34511
61.84217	46.97333	20.27317
61.89384	45.93842	20.19928
61.94717	44.86883	20.12644
61.99717	43.86750	20.05152
62.05050	42.79956	19.97450
62.10050	41.79736	19.90403
62.15383	40.73016	19.81602
62.20550	39.69282	19.74064
62.25717	38.65730	19.63096
62.31050	37.58800	19.51616
62.36050	36.58350	19.39729
62.41382	35.51502	19.32088
62.46550	34.48015	19.23243
62.51716	33.44535	19.15199
62.57050	32.37442	19.03193
62.62050	31.37270	18.95854
62.67383	30.30315	18.87131
62.72382	29.30039	18.79086
62.77717	28.23013	18.69461
62.82883	27.19428	18.59820
62.88050	26.15706	18.49196
62.93383	25.08664	18.37325
62.98383	24.08264	18.27551
63.03383	23.09836	18.16357
63.08550	22.63096	17.86757
63.13716	22.71150	15.09094
63.19050	23.02688	10.95578
63.24050	23.48460	6.789720
63.29382	24.09262	2.619047
63.34550	24.77098	-0.9262791
63.39717	25.52238	-3.926683
63.45050	26.35364	-6.485645
63.50050	27.17474	-8.452286
63.55383	28.08656	-10.15483
63.60383	28.96664	-11.45082
63.65717	29.92790	-12.56816
63.70883	30.87587	-13.45656
63.76050	31.83776	-14.20396
63.81382	32.84190	-14.84222
63.86384	33.79306	-15.33065
63.91716	34.81561	-15.77074
63.96884	35.81178	-16.14130
64.02050	36.81226	-16.47022
64.07218	37.81814	-16.76778
64.12383	38.82405	-17.04516
64.17718	39.86696	-17.25825
64.22718	40.84974	-17.43051
64.28050	41.89863	-17.60524
64.33217	42.91714	-17.74963
64.38384	43.93734	-17.90249
64.43717	44.99042	-18.03892
64.48717	45.97976	-18.15989
64.54050	47.03637	-18.28530
64.59050	48.02615	-18.40086
64.64384	49.08608	-18.51703
64.69550	50.11158	-18.62658
64.74717	51.13742	-18.73538
64.80050	52.19564	-18.84630
64.85050	53.18926	-18.94047
64.90384	54.25000	-19.05156
64.95550	55.27696	-19.16343
65.00718	56.30548	-19.25434
65.05884	57.33374	-19.34813
65.11050	58.36238	-19.44150
65.16382	59.42364	-19.54144
65.21384	60.42075	-19.63672
65.26716	61.48165	-19.73037
65.31884	62.51171	-19.83084
65.37050	63.54118	-19.92202
65.42383	64.60351	-20.01341
65.47384	65.60024	-20.10004
65.52717	66.66344	-20.19412
65.57718	67.65978	-20.28116
65.63050	68.72339	-20.38410
65.68218	69.75418	-20.47264
65.73384	70.78418	-20.56253
65.78718	71.84880	-20.64974
65.83716	72.84640	-20.73732
65.89050	73.90838	-20.82438
65.94218	74.93946	-20.91022
65.99384	75.96909	-20.99875
66.04550	76.99934	-21.09176
66.09718	78.02891	-21.18342
66.15050	79.09222	-21.28051
66.20050	80.08862	-21.37236
66.25384	81.15128	-21.47200
66.30550	82.18144	-21.57340
66.35718	83.21164	-21.66764
66.41050	84.27550	-21.76581
66.46050	85.27188	-21.86347
66.51384	86.33642	-21.96805
66.56384	87.33288	-22.06280
66.61718	88.39594	-22.15997
66.66884	89.42709	-22.25570
66.72050	90.45749	-22.36176
66.77384	91.52119	-22.45897
66.82384	92.51876	-22.55490
66.87718	93.58192	-22.65358
66.92884	94.61251	-22.75138
66.98050	95.64309	-22.85930
67.03218	96.67269	-22.95318
67.08384	97.70459	-23.04365
67.13718	98.76706	-23.14106
67.18718	99.76391	-23.22325
67.24050	100.8276	-23.32057
67.29218	101.8572	-23.42143
67.34384	102.8877	-23.52500
67.39718	103.9507	-23.62782
67.44718	104.9471	-23.72524
67.50050	106.0114	-23.82988
67.55050	107.0073	-23.92348
67.60384	108.0717	-24.03702
67.65550	109.1011	-24.13861
67.70718	110.1320	-24.23770
67.76050	111.1960	-24.33990
67.81050	112.1927	-24.43914
67.86384	113.2566	-24.54187
67.91550	114.2876	-24.64444
67.96718	115.3172	-24.73836
68.02050	116.3816	-24.84100
68.07050	117.3786	-24.93516
68.12384	118.4416	-25.04455
68.17384	119.4389	-25.14148
68.22718	120.5022	-25.25233
68.27884	121.5321	-25.35692
68.33050	122.5615	-25.47392
68.38384	123.6244	-25.59308
68.43384	124.6216	-25.69837
68.48718	125.6843	-25.81625
68.53718	126.6808	-25.92768
68.59050	127.7429	-26.04272
68.64216	128.7736	-26.14764
68.69384	129.8024	-26.26573
68.74718	130.8648	-26.38523
68.79718	131.8609	-26.51430
68.85050	132.9228	-26.64967
68.90218	133.9522	-26.76255
68.95384	134.9817	-26.88594
69.00718	136.0436	-27.03110
69.05718	137.0398	-27.15960
69.11050	138.1016	-27.30298
69.16050	139.0969	-27.43454
69.21384	140.1587	-27.57861
69.26550	141.1883	-27.72057
69.31718	142.2172	-27.85711
69.37050	143.2798	-28.00490
69.42050	144.2744	-28.13985
69.47384	145.3367	-28.27796
69.52550	146.3652	-28.41088
69.57718	147.3934	-28.54910
69.62884	148.4226	-28.68344
69.68050	149.4509	-28.82600
69.73384	150.5116	-28.96834
69.78384	151.5059	-29.10572
69.83716	152.5683	-29.25780
69.88884	153.5960	-29.41260
69.94050	154.6236	-29.56730
69.99384	155.6836	-29.73735
70.04384	156.6793	-29.89838
70.09718	157.7392	-30.06719
70.14718	158.7341	-30.22976
70.20050	159.7933	-30.40046
70.25218	160.8210	-30.56724
70.30384	161.8500	-30.73438
70.35718	162.9102	-30.89096
70.40718	163.9066	-31.03232
70.46050	164.9676	-31.16901
70.51218	165.9976	-31.28169
70.56384	167.0274	-31.38350
70.61550	168.0586	-31.47600
70.66718	169.0904	-31.55188
70.72050	170.1556	-31.62417
70.77050	171.1541	-31.69469
70.82384	172.2185	-31.76861
70.87550	173.2503	-31.85848
70.92718	174.2813	-31.94770
70.98050	175.3452	-32.05880
71.03050	176.3410	-32.17068
71.08384	177.4037	-32.31600
71.13384	178.3970	-32.46388
71.18718	179.4569	-32.65318
71.23882	180.4825	-32.85088
71.29050	181.5077	-33.08200
71.34384	182.5635	-33.35153
71.39384	183.5542	-33.62450
71.44718	184.6081	-33.95106
71.49884	185.6280	-34.29438
71.55050	186.6464	-34.67317
71.60218	187.6623	-35.09473
71.65384	188.6770	-35.56379
71.70718	189.7201	-36.09919
71.75718	190.6966	-36.68358
71.81050	191.7337	-37.35960
71.86218	192.7366	-38.08434
71.91382	193.7360	-38.86591
71.96718	194.7652	-39.71682
72.01716	195.7292	-40.53858
72.07050	196.7568	-41.44183
72.12050	197.7203	-42.30589
72.17384	198.7459	-43.24542
72.22551	199.7371	-44.19580
72.27718	200.7266	-45.20498
72.33050	201.7453	-46.31182
72.38050	202.6976	-47.42883
72.43384	203.7091	-48.67615
72.48550	204.6881	-49.91455
72.53718	205.6670	-51.12116
72.58884	206.6495	-52.21534
72.64050	207.6424	-53.04753
72.69384	208.6870	-53.42824
72.74384	209.6931	-53.12610
72.79718	210.8037	-51.93754
72.84882	211.9194	-49.94658
72.90050	213.0678	-47.30446
72.95384	214.2719	-44.34704
73.00384	215.3960	-41.83680
73.05718	216.5742	-39.60289
73.10718	217.6614	-37.91195
73.16050	218.8016	-36.47266
73.21218	219.8930	-35.35342
73.26384	220.9736	-34.47806
73.31718	222.0772	-33.76719
73.36718	223.1064	-33.23974
73.42050	224.1968	-32.80231
73.47218	225.2492	-32.46870
73.52384	226.2979	-32.20597
73.57550	227.3430	-32.01633
73.62718	228.3852	-31.85752
73.68050	229.4597	-31.75090
73.73050	230.4657	-31.68588
73.78384	231.5368	-31.64095
73.83550	232.5739	-31.62078
73.88718	233.6094	-31.61682
73.94050	234.6793	-31.61504
73.99050	235.6808	-31.61637
74.04384	236.7496	-31.62391
74.09384	237.7496	-31.63890
74.14718	238.8167	-31.66863
74.19884	239.8506	-31.70716
74.25050	240.8833	-31.75987
74.30384	241.9498	-31.81312
74.35384	242.9497	-31.86849
74.40718	244.0173	-31.92392
74.45884	245.0510	-31.97330
74.51050	246.0843	-32.01929
74.56384	247.1506	-32.07256
74.61384	248.1510	-32.11298
74.66718	249.2168	-32.15524
74.71718	250.2169	-32.19981
74.77050	251.2832	-32.25570
74.82218	252.3161	-32.30288
74.87384	253.3488	-32.34898
74.92718	254.4156	-32.39982
74.97718	255.4158	-32.44763
75.03050	256.4816	-32.51095
75.08050	257.4804	-32.56909
75.13384	258.5457	-32.62561
75.18550	259.5775	-32.69318
75.23718	260.6097	-32.75698
75.29050	261.6738	-32.82275
75.34050	262.6730	-32.88606
75.39384	263.7400	-32.96026
75.44550	264.7715	-33.02246
75.49718	265.8030	-33.08784
75.55050	266.8698	-33.16110
75.60050	267.8679	-33.22186
75.65384	268.9335	-33.28874
75.70384	269.9326	-33.35929
75.75718	270.9973	-33.42416
75.80884	272.0290	-33.48400
-2.000000	5.000000	0.0000000