File: 1-C1(0.6mol%)+C20(0.6mol%)/matlab/140-1.txt
CLOSED
Version	1.0
Language	English
Mode	Standard
Run	1
RunSerial	11851
Instrument	DSC Q2000 V24.11 Build 124
Module	DSC Standard Cell RC
Operator	Jing
File	\\AE520-1454\TA\Data\DSC\UQ Composites\Nan\C1(5.5)+C20P(3)+CL(HotplateMixtureAB)\140-1
ProcName	Ramp
InstSerial	2000-0883
AutoSerial	1293
Sample	Iso-140-1
Size	40.5000	mg
PanMass	Not available
PanResist	Automatic Automatic  K/W
PanFactor	Default Default
Method	Ramp
Comment
Xcomment	Pan: Tzero Aluminum Hermetic
Xcomment	Gas1: Nitrogen 50.0 ml/min
Xcomment	Gas2: Nitrogen 50.0 ml/min
Text
Exotherm	UP
Kcell	1.05230
Cpconst	Standard: 0.938
Calib	-38.6961
TempCal	1	pts	157.46	156.60
TzeroDt	-87.6168 -0.0009 -1.4231
TzeroDtz	-87.6168 0.0057 6.9570
InstCalFile	Tzero: \\Ae520-1454\ta\Data\DSC\Calibration\2017\CALIBRATION\1562_RCS (90)_05_18_2017 10_50_44.TZR
InstCalFile	Baseline: \\Ae520-1454\ta\Data\DSC\Calibration\2017\2017-05-17_Calibration.001
InstCalFile	Sapphire: \\Ae520-1454\ta\Data\DSC\Calibration\2017\2017-05-17_Saphire.001
InstCalDate	Tzero 2017-05-18 Time 10:50:44
TempRange	-87.39 to 398.39 °C at 10.00 °C/min Heat Only
AutoZero	Delta T Offset 0.000 uV
AutoZero	Delta T0 Offset 0.000 uV
MultiptCal	0
MultiPtDesc	0) Not set
AutoCellConst	Calibration Date 2017-05-18 16:59:28
Controls	Gas 1  Event Off  Sampling 0.2
Cell#	RC-01562
CoolingUnit	RCS (90)
SelHeatFlow	Heat Flow T4 (mW)
AutoLidII	Installed
AutoAnalysis	Off
MacroFile
Nsig	3
Sig1	Time (min)
Sig2	Temperature (°C)
Sig3	Heat Flow (mW)
Date	2017-06-20
Time	16:22:42
OrgMethod	1: Equilibrate at 20.00 °C
OrgMethod	2: Ramp 40.00 °C/min to 140.00 °C
OrgMethod	3: Mark end of cycle 1
OrgMethod	4: Isothermal for 40.00 min
OrgMethod	5: Mark end of cycle 2
OrgMethod	6: Ramp 20.00 °C/min to 280.00 °C
OrgMethod	7: Mark end of cycle 3
OrgMethod	8: Ramp 20.00 °C/min to 20.00 °C
OrgMethod	9: Mark end of cycle 4
OrgMethod	10: Ramp 20.00 °C/min to 280.00 °C
OrgMethod	11: Mark end of cycle 5
OrgFile	C:\Users\jarra\Desktop\DSC\1-C1(0.6mol%)+C20(0.6mol%)\140-1.001
StartOfData
4.99994E-4	19.96985	0.3335622
0.05383332	20.09200	0.3252820
0.1055000	20.98630	-0.4623740
0.1571666	22.26378	-3.310217
0.2105000	23.76118	-7.129538
0.2605000	25.28870	-10.89928
0.3138333	27.00508	-14.67598
0.3655000	28.74161	-17.92983
0.4171667	30.53232	-20.72941
0.4705000	32.42834	-23.18588
0.5205000	34.24154	-25.12608
0.5738334	36.20448	-26.87952
0.6238334	38.06872	-28.29263
0.6771668	40.07480	-29.60222
0.7288332	42.03274	-30.73808
0.7805000	43.99967	-31.82544
0.8338332	46.03766	-32.84668
0.8838332	47.96270	-33.61660
0.9371668	50.02668	-34.33828
0.9888332	52.03238	-35.03466
1.040500	54.03989	-35.79330
1.092167	56.04484	-36.63476
1.143833	58.04724	-37.59684
1.197166	60.10956	-38.69570
1.247166	62.04060	-39.83626
1.300500	64.09276	-41.25307
1.352166	66.05978	-43.13458
1.403833	67.98194	-46.13929
1.457167	69.86701	-51.55354
1.507167	71.47280	-59.94116
1.560500	73.00884	-71.76050
1.610500	74.35434	-84.06924
1.663834	75.78258	-96.58624
1.715500	77.24092	-107.2246
1.767167	78.73843	-117.8982
1.820500	80.25525	-129.4874
1.870500	81.70741	-138.9631
1.923834	83.37738	-146.9161
1.975500	85.12528	-152.0447
2.027166	87.11818	-152.0064
2.078833	89.22944	-151.5297
2.130500	91.37999	-149.9724
2.183833	93.71799	-145.5044
2.233833	96.13078	-135.9522
2.287166	98.99780	-122.1238
2.338833	101.7224	-110.9070
2.390500	104.3461	-101.5034
2.443833	106.9580	-93.54556
2.493833	109.3260	-87.40042
2.547166	111.7834	-82.08300
2.597167	114.0308	-78.04239
2.650500	116.3765	-74.59472
2.702166	118.6090	-71.96378
2.753833	120.8078	-69.92339
2.807167	123.0499	-68.33606
2.857167	125.1313	-67.20269
2.910500	127.3341	-66.28987
2.962167	129.4534	-65.62399
3.010500	131.4260	-65.18784
3.060500	133.2773	-64.97112
3.113833	134.4341	-62.83424
3.165500	135.2485	-57.96680
3.217166	135.8884	-52.12774
3.270500	136.4302	-46.02979
3.320500	136.8536	-40.76045
3.373834	137.2326	-35.81435
3.425500	137.5396	-31.70980
3.477167	137.7988	-28.23843
3.528833	138.0192	-25.33382
3.580500	138.2044	-22.90306
3.633833	138.3666	-20.82536
3.683833	138.4963	-19.19953
3.737167	138.6131	-17.75478
3.788833	138.7096	-16.58753
3.840500	138.7926	-15.61412
3.893833	138.8646	-14.77438
3.943833	138.9236	-14.11056
3.997166	138.9764	-13.51007
4.047167	139.0208	-13.03809
4.100500	139.0615	-12.60789
4.152166	139.0955	-12.25467
4.203833	139.1248	-11.94964
4.257167	139.1506	-11.68313
4.307167	139.1725	-11.46442
4.360500	139.1934	-11.26262
4.412167	139.2104	-11.09267
4.463834	139.2256	-10.94436
4.515500	139.2388	-10.81376
4.567167	139.2512	-10.69337
4.620500	139.2625	-10.58686
4.670500	139.2717	-10.49855
4.723834	139.2802	-10.40916
4.775500	139.2888	-10.33330
4.827167	139.2956	-10.26570
4.880500	139.3017	-10.19252
4.930500	139.3088	-10.13614
4.983834	139.3144	-10.07492
5.033834	139.3185	-10.02430
5.087167	139.3232	-9.969598
5.138833	139.3281	-9.921555
5.190500	139.3323	-9.874444
5.243834	139.3367	-9.826340
5.293832	139.3402	-9.783035
5.347168	139.3425	-9.736518
5.398834	139.3466	-9.694215
5.450500	139.3500	-9.651376
5.503834	139.3538	-9.609218
5.553834	139.3554	-9.568625
5.607168	139.3587	-9.525128
5.657166	139.3616	-9.485884
5.710500	139.3652	-9.442156
5.762168	139.3679	-9.404412
5.813832	139.3706	-9.362026
5.867168	139.3731	-9.320197
5.917168	139.3766	-9.280488
5.970500	139.3795	-9.235878
6.020500	139.3815	-9.194410
6.073834	139.3849	-9.146899
6.125500	139.3867	-9.101444
6.177166	139.3904	-9.055091
6.230500	139.3929	-9.005197
6.280500	139.3958	-8.955702
6.333832	139.3988	-8.902218
6.385500	139.4013	-8.849152
6.437168	139.4044	-8.795986
6.490500	139.4074	-8.737670
6.540500	139.4106	-8.682862
6.593832	139.4148	-8.622047
6.643832	139.4175	-8.565626
6.697168	139.4205	-8.502345
6.748834	139.4245	-8.441968
6.800500	139.4274	-8.381988
6.853832	139.4314	-8.315764
6.903832	139.4351	-8.253169
6.957168	139.4387	-8.184216
7.008832	139.4422	-8.118614
7.060500	139.4460	-8.049598
7.112168	139.4495	-7.977699
7.163832	139.4531	-7.903570
7.217168	139.4581	-7.810682
7.267168	139.4638	-7.717893
7.320500	139.4692	-7.610020
7.372168	139.4745	-7.500550
7.423834	139.4808	-7.386240
7.477168	139.4868	-7.264260
7.527168	139.4926	-7.147503
7.580500	139.4996	-7.025526
7.630500	139.5052	-6.902174
7.683832	139.5118	-6.777407
7.735500	139.5187	-6.647888
7.787168	139.5250	-6.514594
7.840500	139.5313	-6.380042
7.890500	139.5397	-6.250590
7.943832	139.5455	-6.108387
7.995500	139.5535	-5.972050
8.047168	139.5614	-5.834688
8.098832	139.5673	-5.700356
8.150500	139.5742	-5.566254
8.203834	139.5819	-5.427888
8.253834	139.5885	-5.302384
8.307168	139.5953	-5.166206
8.358832	139.6025	-5.036744
8.410499	139.6086	-4.904420
8.463834	139.6161	-4.770191
8.513832	139.6230	-4.643804
8.567166	139.6294	-4.507412
8.617166	139.6360	-4.382053
8.670500	139.6428	-4.247494
8.722168	139.6499	-4.120129
8.773834	139.6564	-3.989738
8.827168	139.6625	-3.861636
8.877168	139.6692	-3.743695
8.930500	139.6756	-3.616073
8.982166	139.6822	-3.489069
9.033832	139.6891	-3.363755
9.085501	139.6957	-3.233194
9.137168	139.7024	-3.101272
9.190500	139.7086	-2.957351
9.240500	139.7168	-2.823968
9.293834	139.7238	-2.677029
9.345500	139.7316	-2.532501
9.397168	139.7384	-2.388061
9.450500	139.7466	-2.234155
9.500500	139.7528	-2.084991
9.553832	139.7619	-1.930484
9.603832	139.7689	-1.777280
9.657166	139.7770	-1.619489
9.708832	139.7847	-1.474177
9.760499	139.7922	-1.334236
9.813834	139.7978	-1.203054
9.863834	139.8048	-1.086396
9.917168	139.8112	-0.9785985
9.968834	139.8164	-0.8836101
10.02050	139.8212	-0.7996247
10.07217	139.8254	-0.7195352
10.12383	139.8293	-0.6482245
10.17717	139.8330	-0.5790641
10.22717	139.8361	-0.5223217
10.28050	139.8390	-0.4687154
10.33217	139.8420	-0.4169745
10.38383	139.8449	-0.3725964
10.43717	139.8472	-0.3273670
10.48717	139.8491	-0.2863735
10.54050	139.8520	-0.2492969
10.59050	139.8534	-0.2115617
10.64383	139.8568	-0.1772578
10.69550	139.8584	-0.1436105
10.74717	139.8600	-0.1087911
10.80050	139.8614	-.07472280
10.85050	139.8629	-.04412162
10.90383	139.8655	-.01375274
10.95550	139.8673	0.01899278
11.00717	139.8693	0.05231734
11.05884	139.8708	0.08539191
11.11050	139.8724	0.1176684
11.16383	139.8748	0.1540801
11.21383	139.8761	0.1886114
11.26717	139.8781	0.2308268
11.31883	139.8804	0.2696913
11.37050	139.8818	0.3157644
11.42383	139.8850	0.3651526
11.47383	139.8874	0.4183037
11.52717	139.8903	0.4797468
11.57717	139.8934	0.5426044
11.63050	139.8974	0.6112516
11.68217	139.9009	0.6889804
11.73383	139.9046	0.7726526
11.78717	139.9093	0.8631330
11.83717	139.9132	0.9520098
11.89050	139.9187	1.055158
11.94217	139.9235	1.158847
11.99384	139.9294	1.265150
12.04717	139.9352	1.379644
12.09717	139.9405	1.492899
12.15050	139.9466	1.610599
12.20050	139.9518	1.722108
12.25384	139.9584	1.838917
12.30550	139.9646	1.953418
12.35717	139.9705	2.066822
12.41050	139.9762	2.182434
12.46050	139.9820	2.287858
12.51383	139.9871	2.395666
12.56383	139.9920	2.493898
12.61716	139.9974	2.594648
12.66883	140.0028	2.684688
12.72050	140.0073	2.777378
12.77383	140.0120	2.866030
12.82384	140.0165	2.944334
12.87717	140.0208	3.021865
12.92883	140.0245	3.094128
12.98050	140.0279	3.166687
13.03383	140.0320	3.234859
13.08383	140.0347	3.297939
13.13717	140.0384	3.360594
13.18716	140.0412	3.417166
13.24050	140.0446	3.473242
13.29216	140.0476	3.530106
13.34383	140.0506	3.583452
13.39717	140.0536	3.638196
13.44717	140.0562	3.686211
13.50050	140.0579	3.740544
13.55217	140.0608	3.788790
13.60383	140.0629	3.840921
13.65550	140.0664	3.888473
13.70717	140.0684	3.936516
13.76050	140.0715	3.984306
13.81050	140.0740	4.031139
13.86383	140.0759	4.083120
13.91550	140.0784	4.128396
13.96716	140.0815	4.175493
14.02050	140.0839	4.228994
14.07050	140.0864	4.275694
14.12384	140.0885	4.322928
14.17383	140.0914	4.371582
14.22717	140.0934	4.422756
14.27883	140.0959	4.473164
14.33050	140.0984	4.523046
14.38383	140.1009	4.576297
14.43383	140.1036	4.625340
14.48716	140.1069	4.677464
14.53883	140.1093	4.731004
14.59050	140.1121	4.781356
14.64216	140.1146	4.833970
14.69384	140.1166	4.889013
14.74717	140.1212	4.943088
14.79717	140.1237	4.992792
14.85050	140.1265	5.052263
14.90217	140.1291	5.104016
14.95383	140.1316	5.162392
15.00717	140.1345	5.218110
15.05717	140.1370	5.272620
15.11050	140.1406	5.328985
15.16050	140.1439	5.383598
15.21383	140.1465	5.440908
15.26550	140.1486	5.498340
15.31716	140.1527	5.551575
15.37050	140.1544	5.611504
15.42050	140.1581	5.666898
15.47383	140.1607	5.725507
15.52550	140.1632	5.781744
15.57717	140.1661	5.837300
15.62883	140.1692	5.891679
15.68050	140.1725	5.946304
15.73383	140.1750	6.000244
15.78383	140.1784	6.051588
15.83717	140.1808	6.104718
15.88883	140.1830	6.155980
15.94050	140.1859	6.206039
15.99383	140.1878	6.257485
16.04383	140.1912	6.305163
16.09717	140.1934	6.349735
16.14716	140.1953	6.390874
16.20050	140.1978	6.431988
16.25217	140.1996	6.471270
16.30383	140.2021	6.505136
16.35716	140.2033	6.540748
16.40716	140.2054	6.569861
16.46050	140.2066	6.599946
16.51216	140.2086	6.628848
16.56383	140.2093	6.649914
16.61550	140.2109	6.666765
16.66716	140.2112	6.675548
16.72050	140.2114	6.681582
16.77050	140.2121	6.688951
16.82383	140.2131	6.695576
16.87550	140.2129	6.701448
16.92716	140.2134	6.706158
16.98050	140.2125	6.709325
17.03050	140.2136	6.710528
17.08383	140.2113	6.710169
17.13383	140.2123	6.707854
17.18716	140.2115	6.703099
17.23883	140.2104	6.692642
17.29050	140.2102	6.679141
17.34383	140.2085	6.659782
17.39383	140.2076	6.636678
17.44716	140.2060	6.609516
17.49883	140.2052	6.580708
17.55050	140.2042	6.542778
17.60216	140.2022	6.509262
17.65383	140.2004	6.473845
17.70716	140.1991	6.437877
17.75716	140.1968	6.407459
17.81050	140.1956	6.370528
17.86216	140.1937	6.335888
17.91383	140.1915	6.300937
17.96716	140.1906	6.263762
18.01716	140.1876	6.228184
18.07050	140.1866	6.191636
18.12050	140.1849	6.154724
18.17383	140.1821	6.117579
18.22550	140.1813	6.079224
18.27716	140.1791	6.043418
18.33050	140.1774	6.006705
18.38050	140.1751	5.972394
18.43383	140.1738	5.936446
18.48550	140.1719	5.900569
18.53717	140.1702	5.866863
18.59050	140.1688	5.834378
18.64050	140.1665	5.803719
18.69383	140.1654	5.770688
18.74383	140.1640	5.741832
18.79716	140.1624	5.712889
18.84883	140.1610	5.682500
18.90050	140.1592	5.654566
18.95383	140.1576	5.627178
19.00383	140.1574	5.601531
19.05716	140.1549	5.574566
19.10716	140.1543	5.550535
19.16050	140.1524	5.524836
19.21216	140.1518	5.502090
19.26383	140.1498	5.477837
19.31716	140.1492	5.453272
19.36716	140.1488	5.433320
19.42050	140.1469	5.413270
19.47216	140.1460	5.398438
19.52383	140.1450	5.383060
19.57716	140.1442	5.365953
19.62716	140.1437	5.349609
19.68050	140.1421	5.333748
19.73050	140.1417	5.321024
19.78383	140.1408	5.307556
19.83550	140.1398	5.293894
19.88716	140.1394	5.280590
19.94050	140.1382	5.268442
19.99050	140.1380	5.257428
20.04383	140.1376	5.245849
20.09550	140.1369	5.234547
20.14716	140.1372	5.223884
20.19884	140.1364	5.213672
20.25050	140.1356	5.203984
20.30383	140.1365	5.193828
20.35383	140.1349	5.184702
20.40716	140.1349	5.175278
20.45883	140.1348	5.166748
20.51050	140.1345	5.158735
20.56383	140.1339	5.150982
20.61383	140.1331	5.144286
20.66716	140.1334	5.137967
20.71716	140.1329	5.132578
20.77050	140.1328	5.127239
20.82216	140.1325	5.122546
20.87383	140.1327	5.118300
20.92717	140.1333	5.114456
20.97716	140.1322	5.111191
21.03050	140.1325	5.108044
21.08216	140.1325	5.105305
21.13383	140.1325	5.102994
21.18550	140.1334	5.101087
21.23716	140.1330	5.099455
21.29050	140.1331	5.098219
21.34050	140.1330	5.097583
21.39383	140.1334	5.097351
21.44550	140.1334	5.097738
21.49716	140.1334	5.098239
21.55050	140.1341	5.098594
21.60050	140.1336	5.098819
21.65383	140.1338	5.099444
21.70383	140.1339	5.100126
21.75716	140.1339	5.100836
21.80883	140.1337	5.101526
21.86050	140.1343	5.101748
21.91383	140.1339	5.101559
21.96383	140.1342	5.100626
22.01716	140.1332	5.099333
22.06883	140.1332	5.097648
22.12050	140.1337	5.095244
22.17216	140.1327	5.091920
22.22383	140.1332	5.087711
22.27717	140.1314	5.082450
22.32716	140.1310	5.076278
22.38050	140.1311	5.068948
22.43216	140.1303	5.059028
22.48383	140.1293	5.046785
22.53717	140.1286	5.031456
22.58716	140.1278	5.015496
22.64050	140.1270	4.997187
22.69050	140.1261	4.979154
22.74383	140.1249	4.956590
22.79550	140.1239	4.934260
22.84716	140.1227	4.909376
22.90050	140.1216	4.882800
22.95050	140.1209	4.855684
23.00383	140.1192	4.831456
23.05550	140.1177	4.803746
23.10716	140.1170	4.773988
23.15883	140.1153	4.743856
23.21050	140.1138	4.715152
23.26383	140.1130	4.685588
23.31383	140.1117	4.661780
23.36716	140.1094	4.633250
23.41883	140.1086	4.598913
23.47050	140.1070	4.566776
23.52383	140.1060	4.535454
23.57383	140.1038	4.506494
23.62716	140.1024	4.475761
23.67717	140.0997	4.445875
23.73050	140.0989	4.415071
23.78216	140.0973	4.386074
23.83383	140.0953	4.356217
23.88716	140.0938	4.326310
23.93716	140.0920	4.298926
23.99050	140.0916	4.268134
24.04216	140.0894	4.238388
24.09383	140.0887	4.210694
24.14550	140.0868	4.180900
24.19716	140.0850	4.151852
24.25050	140.0834	4.125054
24.30050	140.0831	4.096318
24.35383	140.0806	4.068772
24.40550	140.0796	4.042812
24.45717	140.0787	4.017320
24.51050	140.0774	3.992502
24.56050	140.0758	3.967065
24.61383	140.0744	3.941368
24.66383	140.0733	3.918250
24.71716	140.0719	3.893158
24.76883	140.0716	3.869188
24.82050	140.0702	3.844829
24.87383	140.0696	3.821525
24.92383	140.0675	3.800375
24.97716	140.0671	3.778188
25.02883	140.0659	3.756734
25.08050	140.0654	3.733338
25.13383	140.0639	3.713744
25.18383	140.0638	3.692091
25.23716	140.0620	3.670642
25.28717	140.0613	3.652602
25.34050	140.0600	3.633210
25.39216	140.0587	3.615016
25.44383	140.0587	3.596900
25.49716	140.0571	3.576761
25.54716	140.0556	3.558142
25.60050	140.0548	3.539454
25.65050	140.0534	3.522270
25.70383	140.0520	3.504122
25.75550	140.0511	3.484395
25.80716	140.0506	3.466348
25.86050	140.0489	3.449046
25.91050	140.0490	3.431300
25.96383	140.0478	3.411294
26.01550	140.0466	3.394178
26.06716	140.0456	3.373453
26.12050	140.0452	3.356682
26.17050	140.0447	3.340533
26.22383	140.0440	3.323664
26.27383	140.0432	3.308011
26.32717	140.0420	3.291800
26.37883	140.0409	3.274781
26.43050	140.0410	3.258964
26.48383	140.0395	3.240828
26.53383	140.0391	3.227068
26.58716	140.0377	3.211668
26.63883	140.0369	3.195834
26.69050	140.0370	3.179570
26.74216	140.0352	3.166304
26.79383	140.0353	3.150400
26.84716	140.0338	3.134834
26.89716	140.0326	3.118228
26.95050	140.0327	3.102005
27.00217	140.0314	3.084419
27.05383	140.0304	3.069692
27.10716	140.0295	3.055195
27.15716	140.0294	3.038675
27.21050	140.0284	3.024800
27.26050	140.0275	3.010803
27.31383	140.0270	2.995472
27.36550	140.0258	2.982363
27.41716	140.0247	2.968152
27.47050	140.0244	2.954376
27.52050	140.0236	2.940436
27.57383	140.0232	2.925845
27.62550	140.0211	2.911147
27.67717	140.0215	2.895178
27.72883	140.0202	2.880845
27.78050	140.0202	2.866682
27.83383	140.0195	2.851200
27.88383	140.0180	2.838098
27.93717	140.0176	2.824716
27.98883	140.0167	2.809734
28.04050	140.0164	2.795265
28.09383	140.0161	2.780423
28.14383	140.0149	2.765402
28.19717	140.0148	2.751030
28.24716	140.0142	2.734915
28.30050	140.0134	2.719944
28.35217	140.0122	2.707268
28.40383	140.0115	2.693624
28.45716	140.0109	2.677437
28.50716	140.0099	2.663462
28.56050	140.0093	2.649746
28.61216	140.0090	2.636658
28.66383	140.0083	2.623187
28.71550	140.0074	2.610889
28.76716	140.0065	2.596897
28.82050	140.0062	2.582208
28.87050	140.0052	2.567845
28.92383	140.0051	2.554377
28.97550	140.0039	2.542051
29.02717	140.0030	2.527866
29.08050	140.0017	2.514354
29.13050	140.0017	2.498673
29.18383	140.0015	2.482542
29.23383	140.0005	2.468696
29.28717	139.9996	2.454215
29.33883	139.9989	2.442344
29.39050	139.9990	2.427784
29.44383	139.9983	2.412827
29.49383	139.9968	2.400616
29.54716	139.9959	2.385412
29.59883	139.9954	2.372904
29.65050	139.9948	2.358113
29.70217	139.9940	2.343980
29.75383	139.9934	2.330274
29.80716	139.9927	2.315336
29.85716	139.9920	2.301168
29.91050	139.9910	2.286304
29.96216	139.9906	2.272735
30.01383	139.9894	2.257877
30.06716	139.9884	2.242218
30.11716	139.9882	2.228221
30.17050	139.9871	2.212858
30.22050	139.9878	2.198344
30.27383	139.9859	2.184444
30.32550	139.9851	2.170836
30.37716	139.9848	2.155689
30.43050	139.9835	2.140422
30.48050	139.9827	2.125994
30.53383	139.9821	2.109656
30.58550	139.9820	2.093883
30.63716	139.9807	2.079792
30.68883	139.9805	2.065786
30.74050	139.9794	2.049940
30.79383	139.9790	2.033575
30.84383	139.9782	2.020358
30.89716	139.9782	2.003989
30.94883	139.9765	1.991340
31.00050	139.9763	1.975991
31.05383	139.9756	1.960709
31.10383	139.9744	1.945455
31.15716	139.9738	1.928462
31.20716	139.9732	1.914374
31.26050	139.9719	1.899126
31.31217	139.9714	1.883097
31.36383	139.9699	1.866795
31.41716	139.9700	1.849269
31.46716	139.9686	1.834671
31.52050	139.9681	1.818154
31.57217	139.9674	1.801798
31.62383	139.9659	1.787759
31.67717	139.9651	1.767760
31.72717	139.9644	1.751373
31.78050	139.9641	1.734341
31.83050	139.9635	1.719647
31.88383	139.9628	1.702028
31.93550	139.9617	1.682984
31.98717	139.9604	1.667614
32.04050	139.9596	1.649567
32.09050	139.9588	1.631720
32.14383	139.9580	1.615436
32.19383	139.9569	1.601395
32.24716	139.9558	1.585859
32.29883	139.9552	1.564236
32.35050	139.9537	1.546593
32.40383	139.9540	1.525313
32.45383	139.9524	1.505452
32.50716	139.9518	1.489020
32.55883	139.9513	1.467525
32.61050	139.9504	1.446817
32.66383	139.9489	1.426830
32.71383	139.9481	1.407161
32.76716	139.9467	1.386496
32.81716	139.9458	1.365581
32.87050	139.9452	1.345213
32.92216	139.9442	1.325237
32.97383	139.9434	1.304994
33.02716	139.9421	1.284736
33.07717	139.9408	1.264557
33.13050	139.9402	1.241547
33.18216	139.9387	1.221067
33.23383	139.9380	1.201534
33.28550	139.9367	1.179347
33.33716	139.9356	1.158110
33.39050	139.9344	1.135060
33.44050	139.9329	1.114460
33.49383	139.9318	1.088276
33.54550	139.9306	1.065464
33.59716	139.9297	1.042627
33.65050	139.9279	1.016280
33.70050	139.9276	0.9930801
33.75383	139.9261	0.9690932
33.80383	139.9259	0.9454032
33.85716	139.9242	0.9202784
33.90883	139.9225	0.8987024
33.96050	139.9214	0.8739569
34.01383	139.9206	0.8473312
34.06383	139.9184	0.8242555
34.11716	139.9178	0.7969782
34.16883	139.9161	0.7720550
34.22050	139.9158	0.7441084
34.27217	139.9137	0.7181963
34.32383	139.9126	0.6934915
34.37717	139.9117	0.6648087
34.42717	139.9100	0.6391003
34.48050	139.9091	0.6140410
34.53216	139.9073	0.5877210
34.58383	139.9060	0.5615176
34.63716	139.9039	0.5339900
34.68716	139.9034	0.5068425
34.74050	139.9022	0.4802447
34.79050	139.9009	0.4528164
34.84384	139.8995	0.4251799
34.89550	139.8975	0.4003668
34.94717	139.8966	0.3723796
35.00050	139.8947	0.3465970
35.05050	139.8940	0.3191278
35.10383	139.8922	0.2914414
35.15550	139.8909	0.2639038
35.20716	139.8893	0.2378819
35.25883	139.8885	0.2104288
35.31050	139.8869	0.1849274
35.36383	139.8854	0.1568818
35.41383	139.8842	0.1300946
35.46716	139.8830	0.1033008
35.51883	139.8819	0.07785074
35.57050	139.8808	0.05189560
35.62383	139.8801	0.02673766
35.67383	139.8779	.002232166
35.72717	139.8768	-.02437099
35.77716	139.8757	-.04752598
35.83050	139.8744	-.07346268
35.88216	139.8726	-.09620626
35.93384	139.8716	-0.1211558
35.98717	139.8701	-0.1460748
36.03717	139.8692	-0.1650914
36.09050	139.8678	-0.1875776
36.14216	139.8668	-0.2100210
36.19383	139.8654	-0.2342774
36.24550	139.8647	-0.2551238
36.29716	139.8636	-0.2756228
36.35050	139.8622	-0.2971123
36.40050	139.8608	-0.3183887
36.45383	139.8601	-0.3386247
36.50550	139.8590	-0.3593450
36.55716	139.8572	-0.3781883
36.61050	139.8564	-0.3992664
36.66050	139.8552	-0.4170204
36.71383	139.8555	-0.4372104
36.76383	139.8538	-0.4558630
36.81716	139.8526	-0.4730893
36.86883	139.8520	-0.4890228
36.92050	139.8511	-0.5047900
36.97383	139.8502	-0.5230359
37.02383	139.8500	-0.5374329
37.07717	139.8491	-0.5493330
37.12883	139.8486	-0.5623062
37.18050	139.8474	-0.5765366
37.23216	139.8467	-0.5930725
37.28383	139.8465	-0.6074840
37.33716	139.8457	-0.6223348
37.38716	139.8446	-0.6375606
37.44050	139.8436	-0.6540820
37.49216	139.8430	-0.6694462
37.54383	139.8432	-0.6852312
37.59716	139.8410	-0.6968870
37.64717	139.8411	-0.7089202
37.70050	139.8399	-0.7213366
37.75050	139.8395	-0.7334372
37.80383	139.8392	-0.7457270
37.85550	139.8382	-0.7560796
37.90716	139.8379	-0.7669872
37.96050	139.8377	-0.7783339
38.01050	139.8367	-0.7897384
38.06383	139.8358	-0.8021768
38.11550	139.8354	-0.8131953
38.16716	139.8347	-0.8241290
38.22050	139.8345	-0.8343853
38.27050	139.8336	-0.8438266
38.32383	139.8332	-0.8538886
38.37383	139.8333	-0.8639734
38.42717	139.8323	-0.8743422
38.47883	139.8316	-0.8835619
38.53050	139.8323	-0.8928172
38.58383	139.8311	-0.9020848
38.63383	139.8308	-0.9106894
38.68716	139.8301	-0.9198691
38.73717	139.8299	-0.9282476
38.79050	139.8297	-0.9369231
38.84216	139.8290	-0.9451906
38.89383	139.8292	-0.9532469
38.94717	139.8283	-0.9615089
38.99716	139.8278	-0.9687566
39.05050	139.8272	-0.9763907
39.10217	139.8276	-0.9836897
39.15383	139.8269	-0.9905032
39.20716	139.8262	-0.9974836
39.25716	139.8271	-1.003830
39.31050	139.8259	-1.010520
39.36050	139.8256	-1.016508
39.41383	139.8256	-1.022691
39.46550	139.8254	-1.028954
39.51716	139.8247	-1.034986
39.57050	139.8247	-1.041007
39.62050	139.8244	-1.046524
39.67383	139.8246	-1.052378
39.72550	139.8235	-1.057594
39.77716	139.8234	-1.062828
39.82883	139.8236	-1.068154
39.88050	139.8231	-1.073192
39.93384	139.8225	-1.078229
39.98383	139.8222	-1.082918
40.03717	139.8223	-1.087768
40.08883	139.8223	-1.092346
40.14050	139.8226	-1.096931
40.19383	139.8214	-1.101551
40.24383	139.8210	-1.105828
40.29716	139.8218	-1.110212
40.34716	139.8218	-1.114305
40.40050	139.8215	-1.118614
40.45216	139.8215	-1.122614
40.50383	139.8208	-1.126400
40.55716	139.8212	-1.130218
40.60716	139.8203	-1.133761
40.66050	139.8210	-1.137407
40.71216	139.8203	-1.140807
40.76383	139.8206	-1.144079
40.81550	139.8206	-1.147369
40.86716	139.8194	-1.150312
40.92050	139.8200	-1.153396
40.97050	139.8193	-1.156210
41.02383	139.8192	-1.159151
41.07550	139.8194	-1.161762
41.12717	139.8193	-1.164639
41.18050	139.8197	-1.167604
41.23050	139.8189	-1.170294
41.28383	139.8184	-1.173141
41.33383	139.8187	-1.175679
41.38716	139.8185	-1.178383
41.43883	139.8186	-1.180856
41.49050	139.8187	-1.183438
41.54383	139.8175	-1.185772
41.59384	139.8186	-1.187932
41.64717	139.8186	-1.190578
41.69883	139.8181	-1.193008
41.75050	139.8177	-1.195440
41.80217	139.8171	-1.197591
41.85383	139.8175	-1.199787
41.90717	139.8176	-1.202020
41.95717	139.8167	-1.204148
42.01050	139.8170	-1.206353
42.06216	139.8166	-1.208366
42.11383	139.8167	-1.210461
42.16716	139.8167	-1.212724
42.21717	139.8166	-1.214560
42.27050	139.8174	-1.216527
42.32050	139.8168	-1.218274
42.37383	139.8168	-1.220154
42.42550	139.8167	-1.221887
42.47717	139.8171	-1.223464
42.53050	139.8172	-1.225327
42.58050	139.8162	-1.226995
42.63383	139.8163	-1.228734
42.68550	139.8167	-1.230373
42.73717	139.8158	-1.231769
42.78883	139.8156	-1.233376
42.84050	139.8159	-1.234912
42.89383	139.8159	-1.236646
42.94383	139.8156	-1.238254
42.99716	139.8156	-1.239710
43.04550	139.8481	-1.239770
43.09716	140.2243	-1.650929
43.15050	140.8526	-3.746730
43.20050	141.5316	-6.377224
43.25383	142.3250	-9.298231
43.30550	143.1412	-11.92172
43.35717	143.9964	-14.22619
43.41050	144.9112	-16.24362
43.46050	145.7925	-17.82996
43.51383	146.7545	-19.23622
43.56383	147.6715	-20.33257
43.61716	148.6643	-21.30844
43.66883	149.6380	-22.09762
43.72050	150.6198	-22.75496
43.77383	151.6414	-23.33550
43.82383	152.6054	-23.80196
43.87717	153.6392	-24.24051
43.92883	154.6442	-24.60837
43.98050	155.6524	-24.94388
44.03217	156.6650	-25.24603
44.08383	157.6784	-25.52234
44.13716	158.7276	-25.79229
44.18716	159.7122	-26.02618
44.24050	160.7639	-26.25918
44.29217	161.7839	-26.48414
44.34384	162.8052	-26.69752
44.39717	163.8606	-26.91351
44.44717	164.8505	-27.11078
44.50050	165.9069	-27.31722
44.55050	166.8981	-27.51430
44.60383	167.9544	-27.72441
44.65550	168.9779	-27.92288
44.70717	170.0024	-28.12488
44.76050	171.0588	-28.33735
44.81050	172.0503	-28.54159
44.86383	173.1075	-28.76365
44.91550	174.1323	-28.97421
44.96717	175.1572	-29.18586
45.01883	176.1808	-29.39465
45.07050	177.2045	-29.61012
45.12383	178.2619	-29.83230
45.17383	179.2526	-30.03958
45.22717	180.3078	-30.24246
45.27883	181.3315	-30.44605
45.33050	182.3542	-30.64528
45.38383	183.4088	-30.78615
45.43383	184.3979	-30.48476
45.48717	185.4535	-30.85260
45.53717	186.4419	-31.24714
45.59050	187.4950	-31.62053
45.64217	188.5162	-31.95756
45.69383	189.5356	-32.29326
45.74716	190.5884	-32.65800
45.79716	191.5742	-33.00458
45.85050	192.6250	-33.39178
45.90216	193.6419	-33.78687
45.95383	194.6572	-34.19891
46.00717	195.7059	-34.64939
46.05717	196.6876	-35.10062
46.11050	197.7324	-35.61050
46.16050	198.7108	-36.11094
46.21383	199.7524	-36.68666
46.26550	200.7609	-37.29430
46.31717	201.7668	-37.93904
46.37050	202.8029	-38.67216
46.42050	203.7723	-39.40472
46.47383	204.8026	-40.25500
46.52383	205.7651	-41.13045
46.57717	206.7878	-42.14852
46.62883	207.7749	-43.24412
46.68050	208.7561	-44.46793
46.73383	209.7630	-45.88444
46.78383	210.6988	-47.37900
46.83716	211.6870	-49.20717
46.88883	212.6330	-51.24196
46.94050	213.5656	-53.59349
46.99383	214.5120	-56.39217
47.04383	215.3826	-59.38308
47.09716	216.2938	-62.97675
47.14717	217.1328	-66.68676
47.20050	218.0114	-70.92584
47.25217	218.8577	-75.09192
47.30383	219.7116	-78.92754
47.35717	220.6213	-82.17282
47.40717	221.5104	-84.37275
47.46050	222.5120	-85.37589
47.51216	223.5505	-84.88930
47.56383	224.6410	-83.37530
47.61550	225.7749	-80.96729
47.66716	226.9447	-77.77316
47.72050	228.1953	-73.49874
47.77050	229.4124	-68.43050
47.82383	230.7594	-62.11912
47.87550	232.0627	-56.47049
47.92717	233.3270	-51.78790
47.98050	234.5872	-47.89963
48.03050	235.7330	-44.99496
48.08383	236.9238	-42.51420
48.13383	238.0163	-40.67017
48.18716	239.1627	-39.10831
48.23883	240.2566	-37.91246
48.29050	241.3392	-36.96403
48.34384	242.4461	-36.20515
48.39383	243.4756	-35.63008
48.44717	244.5677	-35.15375
48.49883	245.6199	-34.78816
48.55050	246.6688	-34.50422
48.60217	247.7144	-34.28093
48.65383	248.7581	-34.10778
48.70717	249.8334	-33.96855
48.75717	250.8402	-33.87328
48.81050	251.9117	-33.79822
48.86217	252.9484	-33.74972
48.91383	253.9856	-33.72414
48.96717	255.0540	-33.71251
49.01717	256.0560	-33.70797
49.07050	257.1249	-33.70854
49.12050	258.1250	-33.71472
49.17383	259.1932	-33.73640
49.22550	260.2268	-33.78608
49.27716	261.2604	-33.83258
49.33050	262.3262	-33.87832
49.38050	263.3266	-33.93997
49.43383	264.3927	-33.99348
49.48550	265.4253	-34.04650
49.53717	266.4584	-34.10738
49.58883	267.4918	-34.15960
49.64050	268.5239	-34.21554
49.69383	269.5897	-34.28300
49.74383	270.5891	-34.33304
49.79716	271.6544	-34.38379
49.84883	272.6865	-34.44444
49.90050	273.7193	-34.49714
49.95383	274.7844	-34.56174
50.00050	275.7179	-34.61150
50.05383	276.6555	-34.72515
50.10550	276.8212	-32.35826
50.15717	276.6268	-26.02310
50.21050	276.2198	-18.32032
50.26050	275.7136	-11.31995
50.31383	275.0714	-4.721246
50.36550	274.3726	0.6685062
50.41716	273.6132	5.119304
50.47050	272.7785	8.871959
50.52050	271.9579	11.72608
50.57383	271.0490	14.21420
50.62383	270.1714	16.10536
50.67717	269.2139	17.75237
50.72883	268.2688	19.04759
50.78050	267.3104	20.11492
50.83383	266.3090	21.01225
50.88383	265.3604	21.71132
50.93716	264.3404	22.32772
50.98883	263.3454	22.82037
51.04050	262.3458	23.23106
51.09217	261.3404	23.58025
51.14383	260.3332	23.87441
51.19717	259.2900	24.12650
51.24717	258.3094	24.32865
51.30050	257.2612	24.51217
51.35217	256.2437	24.66457
51.40383	255.2256	24.79762
51.45717	254.1723	24.92126
51.50717	253.1839	25.02033
51.56050	252.1286	25.11173
51.61050	251.1383	25.18861
51.66383	250.0810	25.25898
51.71550	249.0554	25.31648
51.76716	248.0291	25.36807
51.82050	246.9707	25.41098
51.87050	245.9776	25.43652
51.92383	244.9182	25.46117
51.97550	243.8914	25.48488
52.02717	242.8636	25.50182
52.07883	241.8370	25.51589
52.13050	240.8097	25.52628
52.18383	239.7480	25.53574
52.23383	238.7531	25.54472
52.28716	237.6919	25.55416
52.33883	236.6650	25.56206
52.39050	235.6364	25.57092
52.44384	234.5760	25.57867
52.49382	233.5794	25.58542
52.54717	232.5182	25.59196
52.59716	231.5234	25.59695
52.65050	230.4618	25.60170
52.70216	229.4318	25.60568
52.75383	228.4043	25.60814
52.80717	227.3414	25.61135
52.85717	226.3461	25.61465
52.91050	225.2840	25.61770
52.96216	224.2558	25.62175
53.01382	223.2257	25.62592
53.06550	222.1958	25.62482
53.11716	221.1666	25.62378
53.17050	220.1051	25.62326
53.22050	219.1089	25.62375
53.27383	218.0460	25.62505
53.32550	217.0179	25.62556
53.37717	215.9879	25.62591
53.43050	214.9264	25.62613
53.48050	213.9292	25.62589
53.53383	212.8672	25.62498
53.58383	211.8701	25.62374
53.63716	210.8076	25.62238
53.68882	209.7789	25.62053
53.74050	208.7481	25.61833
53.79382	207.6856	25.61502
53.84384	206.6889	25.61104
53.89717	205.6266	25.60500
53.94883	204.5975	25.59789
54.00050	203.5680	25.59230
54.05217	202.5391	25.58683
54.10383	201.5101	25.58080
54.15717	200.4479	25.57540
54.20717	199.4520	25.57352
54.26050	198.3882	25.57114
54.31216	197.3582	25.56776
54.36382	196.3280	25.56186
54.41716	195.2652	25.55438
54.46717	194.2684	25.54676
54.52050	193.2056	25.53906
54.57050	192.2087	25.52946
54.62383	191.1453	25.52012
54.67550	190.1157	25.51108
54.72717	189.0858	25.49866
54.78050	188.0240	25.48864
54.83050	187.0276	25.47972
54.88383	185.9655	25.47128
54.93550	184.9348	25.46391
54.98717	183.9049	25.45644
55.03882	182.8744	25.44896
55.09050	181.8445	25.44198
55.14384	180.7809	25.43446
55.19384	179.7856	25.42777
55.24717	178.7233	25.42289
55.29883	177.6939	25.41925
55.35050	176.6641	25.41692
55.40383	175.6008	25.41548
55.45383	174.6041	25.41565
55.50717	173.5412	25.41907
55.55717	172.5446	25.42838
55.61050	171.4832	25.44744
55.66216	170.4534	25.48887
55.71382	169.4269	25.54797
55.76716	168.3661	25.61174
55.81716	167.3726	25.67871
55.87050	166.3146	25.79056
55.92217	165.2940	26.01538
55.97382	164.2820	26.46952
56.02717	163.2584	27.45432
56.07717	162.3311	29.17874
56.13050	161.3969	32.20585
56.18050	160.5801	36.25969
56.23383	159.7622	41.58096
56.28550	159.0014	47.09558
56.33716	158.2371	52.27602
56.39050	157.4112	56.69782
56.44050	156.5850	59.66938
56.49382	155.6367	61.44142
56.54382	154.6835	61.76820
56.59716	153.5960	60.75971
56.64883	152.4457	56.98028
56.70050	151.2980	55.47230
56.75383	150.1148	52.85438
56.80383	148.9894	50.16317
56.85717	147.7819	47.26625
56.90883	146.6167	44.57779
56.96050	145.4602	42.10384
57.01382	144.2790	39.81690
57.06382	143.1834	37.92785
57.11716	142.0246	36.03426
57.16716	140.9499	34.58354
57.22050	139.8165	33.24142
57.27217	138.7298	32.17226
57.32383	137.6508	31.26700
57.37717	136.5467	30.51213
57.42717	135.5182	29.89680
57.48050	134.4238	29.29156
57.53217	133.3675	28.77516
57.58383	132.3137	28.33044
57.63550	131.2628	27.93797
57.68716	130.2148	27.58804
57.74050	129.1351	27.27428
57.79050	128.1241	27.01708
57.84384	127.0477	26.76875
57.89550	126.0059	26.54658
57.94717	124.9653	26.34484
58.00050	123.8919	26.14992
58.05050	122.8864	25.97954
58.10383	121.8150	25.81178
58.15383	120.8115	25.66534
58.20717	119.7398	25.51856
58.25883	118.7036	25.39037
58.31050	117.6668	25.27296
58.36382	116.5979	25.16377
58.41382	115.5951	25.05734
58.46717	114.5269	24.94696
58.51884	113.4908	24.84770
58.57050	112.4561	24.75204
58.62217	111.4205	24.66194
58.67383	110.3867	24.57257
58.72717	109.3181	24.47533
58.77717	108.3176	24.39964
58.83050	107.2495	24.30835
58.88217	106.2146	24.22293
58.93383	105.1810	24.13633
58.98717	104.1134	24.04922
59.03716	103.1131	23.97248
59.09050	102.0452	23.89542
59.14050	101.0449	23.81450
59.19384	99.97551	23.73370
59.24550	98.94134	23.65240
59.29717	97.90662	23.56728
59.35050	96.83856	23.49431
59.40050	95.83838	23.41333
59.45383	94.77045	23.33226
59.50550	93.73632	23.25532
59.55717	92.70219	23.18092
59.60883	91.66803	23.09820
59.66050	90.63410	23.02733
59.71382	89.56682	22.94719
59.76382	88.56629	22.87326
59.81716	87.50003	22.79817
59.86882	86.46611	22.72344
59.92050	85.43243	22.65096
59.97382	84.36501	22.57502
60.02383	83.36476	22.50826
60.07717	82.29780	22.43719
60.12717	81.29729	22.38074
60.18050	80.23100	22.30177
60.23217	79.19611	22.23532
60.28383	78.16197	22.16712
60.33716	77.09458	22.09328
60.38716	76.09376	22.02742
60.44050	75.02556	21.95607
60.49216	73.99201	21.88736
60.54382	72.95765	21.82048
60.59550	71.92370	21.75059
60.64717	70.88921	21.68170
60.70050	69.82158	21.61287
60.75050	68.82062	21.54146
60.80383	67.75340	21.46368
60.85550	66.72022	21.39005
60.90717	65.68744	21.31952
60.96050	64.61908	21.25223
61.01050	63.61797	21.18583
61.06382	62.55084	21.10480
61.11382	61.54920	21.02704
61.16716	60.48254	20.94666
61.21884	59.44704	20.87035
61.27050	58.41392	20.79042
61.32383	57.34613	20.70880
61.37383	56.34402	20.63828
61.42717	55.27761	20.55852
61.47883	54.24370	20.48730
61.53050	53.20812	20.41047
61.58217	52.17414	20.33456
61.63383	51.13920	20.25920
61.68716	50.07050	20.17526
61.73717	49.06850	20.09076
61.79050	48.00063	20.01305
61.84217	46.96578	19.93137
61.89384	45.93244	19.86286
61.94717	44.86256	19.78810
61.99717	43.86252	19.71349
62.05050	42.79390	19.63412
62.10050	41.79262	19.56252
62.15383	40.72340	19.47970
62.20550	39.68784	19.39596
62.25717	38.65357	19.30752
62.31050	37.58460	19.21129
62.36050	36.58230	19.12059
62.41382	35.51550	19.02175
62.46550	34.47837	18.92919
62.51716	33.44328	18.83228
62.57050	32.37451	18.73674
62.62050	31.37280	18.63872
62.67383	30.30348	18.53838
62.72382	29.30037	18.45087
62.77717	28.23008	18.33894
62.82883	27.19303	18.23174
62.88050	26.15595	18.11740
62.93383	25.08415	17.95127
62.98383	24.08014	17.86324
63.03383	23.09711	17.75890
63.08550	22.62614	17.45597
63.13716	22.70210	14.60243
63.19050	23.01128	10.42484
63.24050	23.46654	6.257100
63.29382	24.07364	2.126917
63.34550	24.75356	-1.365277
63.39717	25.50516	-4.310194
63.45050	26.33824	-6.803958
63.50050	27.16283	-8.712492
63.55383	28.07589	-10.35974
63.60383	28.95876	-11.61364
63.65717	29.92124	-12.69232
63.70883	30.87165	-13.54454
63.76050	31.83697	-14.24416
63.81382	32.84317	-14.84494
63.86384	33.79513	-15.31821
63.91716	34.81967	-15.74234
63.96884	35.81674	-16.09207
64.02050	36.81855	-16.39314
64.07218	37.82541	-16.66248
64.12383	38.83494	-16.89886
64.17718	39.88057	-17.12244
64.22718	40.86150	-17.30856
64.28050	41.91086	-17.49342
64.33217	42.92836	-17.65042
64.38384	43.94826	-17.80189
64.43717	45.00148	-17.94793
64.48717	45.99060	-18.07102
64.54050	47.04796	-18.20599
64.59050	48.03868	-18.32252
64.64384	49.09649	-18.44607
64.69550	50.12168	-18.55488
64.74717	51.14787	-18.66538
64.80050	52.20704	-18.77875
64.85050	53.20043	-18.87634
64.90384	54.26112	-18.98680
64.95550	55.28934	-19.08156
65.00718	56.31774	-19.18359
65.05884	57.34560	-19.28085
65.11050	58.37349	-19.37595
65.16382	59.43590	-19.48151
65.21384	60.43101	-19.57730
65.26716	61.49268	-19.67793
65.31884	62.52214	-19.77874
65.37050	63.55120	-19.87455
65.42383	64.61422	-19.97632
65.47384	65.61124	-20.06735
65.52717	66.67350	-20.15660
65.57718	67.66946	-20.24774
65.63050	68.73206	-20.34448
65.68218	69.76169	-20.43595
65.73384	70.79106	-20.52731
65.78718	71.85522	-20.61900
65.83716	72.85243	-20.70551
65.89050	73.91602	-20.79453
65.94218	74.94669	-20.87525
65.99384	75.97732	-20.96036
66.04550	77.00724	-21.04424
66.09718	78.03826	-21.13120
66.15050	79.10205	-21.21770
66.20050	80.09885	-21.30232
66.25384	81.16200	-21.39260
66.30550	82.19251	-21.47932
66.35718	83.22340	-21.56233
66.41050	84.28650	-21.64600
66.46050	85.28429	-21.72956
66.51384	86.34751	-21.82405
66.56384	87.34356	-21.91206
66.61718	88.40838	-22.00289
66.66884	89.43861	-22.09177
66.72050	90.46887	-22.18806
66.77384	91.53211	-22.28066
66.82384	92.52957	-22.36934
66.87718	93.59306	-22.46272
66.92884	94.62403	-22.54855
66.98050	95.65453	-22.64342
67.03218	96.68526	-22.73878
67.08384	97.71528	-22.82357
67.13718	98.77908	-22.91635
67.18718	99.77597	-23.00424
67.24050	100.8403	-23.10294
67.29218	101.8703	-23.20042
67.34384	102.9004	-23.29747
67.39718	103.9638	-23.39531
67.44718	104.9612	-23.49626
67.50050	106.0238	-23.60606
67.55050	107.0206	-23.70400
67.60384	108.0828	-23.81566
67.65550	109.1114	-23.92002
67.70718	110.1416	-24.03084
67.76050	111.2051	-24.14730
67.81050	112.2017	-24.25539
67.86384	113.2646	-24.36594
67.91550	114.2944	-24.47278
67.96718	115.3240	-24.57629
68.02050	116.3875	-24.69073
68.07050	117.3822	-24.79076
68.12384	118.4450	-24.90642
68.17384	119.4409	-25.01871
68.22718	120.5030	-25.14443
68.27884	121.5323	-25.27073
68.33050	122.5622	-25.39677
68.38384	123.6240	-25.53144
68.43384	124.6204	-25.65000
68.48718	125.6824	-25.78230
68.53718	126.6784	-25.90106
68.59050	127.7400	-26.02275
68.64216	128.7695	-26.14392
68.69384	129.7984	-26.26498
68.74718	130.8610	-26.39266
68.79718	131.8569	-26.51810
68.85050	132.9208	-26.64311
68.90218	133.9487	-26.76255
68.95384	134.9786	-26.88484
69.00718	136.0404	-27.02348
69.05718	137.0360	-27.14668
69.11050	138.0973	-27.28530
69.16050	139.0917	-27.41580
69.21384	140.1540	-27.55921
69.26550	141.1825	-27.70572
69.31718	142.2109	-27.85210
69.37050	143.2729	-28.00144
69.42050	144.2678	-28.14344
69.47384	145.3289	-28.29028
69.52550	146.3574	-28.42674
69.57718	147.3851	-28.57288
69.62884	148.4136	-28.71354
69.68050	149.4418	-28.86275
69.73384	150.5028	-29.01604
69.78384	151.4966	-29.16978
69.83716	152.5584	-29.32831
69.88884	153.5858	-29.52002
69.94050	154.6142	-29.66998
69.99384	155.6750	-29.83918
70.04384	156.6705	-29.98929
70.09718	157.7316	-30.15193
70.14718	158.7261	-30.31107
70.20050	159.7870	-30.47203
70.25218	160.8163	-30.62656
70.30384	161.8449	-30.78390
70.35718	162.9055	-30.92378
70.40718	163.9019	-31.05040
70.46050	164.9652	-31.16894
70.51218	165.9958	-31.26354
70.56384	167.0262	-31.35059
70.61550	168.0584	-31.43140
70.66718	169.0906	-31.49472
70.72050	170.1578	-31.56344
70.77050	171.1566	-31.63441
70.82384	172.2218	-31.70321
70.87550	173.2540	-31.79102
70.92718	174.2832	-31.88595
70.98050	175.3475	-31.99462
71.03050	176.3446	-32.11645
71.08384	177.4069	-32.26814
71.13384	178.4001	-32.42539
71.18718	179.4603	-32.62197
71.23882	180.4856	-32.82583
71.29050	181.5101	-33.06579
71.34384	182.5659	-33.34159
71.39384	183.5541	-33.62752
71.44718	184.6070	-33.97770
71.49884	185.6253	-34.34842
71.55050	186.6434	-34.76338
71.60218	187.6561	-35.23253
71.65384	188.6686	-35.75224
71.70718	189.7092	-36.34563
71.75718	190.6842	-36.97788
71.81050	191.7202	-37.70911
71.86218	192.7197	-38.47856
71.91382	193.7187	-39.29000
71.96718	194.7472	-40.15542
72.01716	195.7094	-40.99240
72.07050	196.7364	-41.90910
72.12050	197.6968	-42.80124
72.17384	198.7215	-43.77896
72.22551	199.7104	-44.78980
72.27718	200.6973	-45.86898
72.33050	201.7122	-47.06036
72.38050	202.6607	-48.24580
72.43384	203.6698	-49.55659
72.48550	204.6465	-50.84212
72.53718	205.6235	-52.06753
72.58884	206.6072	-53.14054
72.64050	207.6022	-53.90860
72.69384	208.6519	-54.13805
72.74384	209.6679	-53.57964
72.79718	210.7942	-52.01818
72.84882	211.9270	-49.69967
72.90050	213.0862	-46.87787
72.95384	214.2963	-43.83840
73.00384	215.4220	-41.30078
73.05718	216.6010	-39.08454
73.10718	217.6870	-37.42408
73.16050	218.8256	-36.02016
73.21218	219.9154	-34.94168
73.26384	220.9934	-34.10311
73.31718	222.0954	-33.42659
73.36718	223.1225	-32.92712
73.42050	224.2114	-32.52050
73.47218	225.2633	-32.21217
73.52384	226.3096	-31.97334
73.57550	227.3538	-31.79994
73.62718	228.3945	-31.66495
73.68050	229.4686	-31.57461
73.73050	230.4740	-31.52262
73.78384	231.5440	-31.49010
73.83550	232.5803	-31.47730
73.88718	233.6162	-31.47456
73.94050	234.6839	-31.47468
73.99050	235.6852	-31.47992
74.04384	236.7522	-31.49710
74.09384	237.7533	-31.52163
74.14718	238.8194	-31.56260
74.19884	239.8539	-31.58957
74.25050	240.8885	-31.61760
74.30384	241.9568	-31.65150
74.35384	242.9570	-31.68130
74.40718	244.0262	-31.68637
74.45884	245.0611	-31.68969
74.51050	246.0930	-31.78998
74.56384	247.1568	-31.86477
74.61384	248.1561	-31.91302
74.66718	249.2225	-31.95747
74.71718	250.2214	-31.99120
74.77050	251.2898	-32.03340
74.82218	252.3215	-32.08172
74.87384	253.3546	-32.13016
74.92718	254.4210	-32.18717
74.97718	255.4202	-32.22728
75.03050	256.4875	-32.29004
75.08050	257.4865	-32.35830
75.13384	258.5513	-32.40984
75.18550	259.5842	-32.46746
75.23718	260.6167	-32.53365
75.29050	261.6806	-32.58879
75.34050	262.6799	-32.65278
75.39384	263.7464	-32.72617
75.44550	264.7787	-32.78838
75.49718	265.8111	-32.84888
75.55050	266.8772	-32.91484
75.60050	267.8745	-32.96507
75.65384	268.9400	-33.02886
75.70384	269.9391	-33.09950
75.75718	271.0050	-33.16505
75.80884	272.0371	-33.21844
-2.000000	5.000000	0.0000000