File: 1-C1(0.6mol%)+C20(0.6mol%)/matlab/140-3.txt
CLOSED
Version	1.0
Language	English
Mode	Standard
Run	3
RunSerial	11853
Instrument	DSC Q2000 V24.11 Build 124
Module	DSC Standard Cell RC
Operator	Jing
File	\\AE520-1454\TA\Data\DSC\UQ Composites\Nan\C1(5.5)+C20P(3)+CL(HotplateMixtureAB)\140-3
ProcName	Ramp
InstSerial	2000-0883
AutoSerial	1293
Sample	Iso-140-3
Size	43.5000	mg
PanMass	Not available
PanResist	Automatic Automatic  K/W
PanFactor	Default Default
Method	Ramp
Comment
Xcomment	Pan: Tzero Aluminum Hermetic
Xcomment	Gas1: Nitrogen 50.0 ml/min
Xcomment	Gas2: Nitrogen 50.0 ml/min
Text
Exotherm	UP
Kcell	1.05230
Cpconst	Standard: 0.938
Calib	-38.6961
TempCal	1	pts	157.46	156.60
TzeroDt	-87.6168 -0.0009 -1.4231
TzeroDtz	-87.6168 0.0057 6.9570
InstCalFile	Tzero: \\Ae520-1454\ta\Data\DSC\Calibration\2017\CALIBRATION\1562_RCS (90)_05_18_2017 10_50_44.TZR
InstCalFile	Baseline: \\Ae520-1454\ta\Data\DSC\Calibration\2017\2017-05-17_Calibration.001
InstCalFile	Sapphire: \\Ae520-1454\ta\Data\DSC\Calibration\2017\2017-05-17_Saphire.001
InstCalDate	Tzero 2017-05-18 Time 10:50:44
TempRange	-87.39 to 398.39 °C at 10.00 °C/min Heat Only
AutoZero	Delta T Offset 0.000 uV
AutoZero	Delta T0 Offset 0.000 uV
MultiptCal	0
MultiPtDesc	0) Not set
AutoCellConst	Calibration Date 2017-05-18 16:59:28
Controls	Gas 1  Event Off  Sampling 0.2
Cell#	RC-01562
CoolingUnit	RCS (90)
SelHeatFlow	Heat Flow T4 (mW)
AutoLidII	Installed
AutoAnalysis	Off
MacroFile
Nsig	3
Sig1	Time (min)
Sig2	Temperature (°C)
Sig3	Heat Flow (mW)
Date	2017-06-20
Time	19:10:36
OrgMethod	1: Equilibrate at 20.00 °C
OrgMethod	2: Ramp 40.00 °C/min to 140.00 °C
OrgMethod	3: Mark end of cycle 1
OrgMethod	4: Isothermal for 40.00 min
OrgMethod	5: Mark end of cycle 2
OrgMethod	6: Ramp 20.00 °C/min to 280.00 °C
OrgMethod	7: Mark end of cycle 3
OrgMethod	8: Ramp 20.00 °C/min to 20.00 °C
OrgMethod	9: Mark end of cycle 4
OrgMethod	10: Ramp 20.00 °C/min to 280.00 °C
OrgMethod	11: Mark end of cycle 5
OrgFile	C:\Users\jarra\Desktop\DSC\1-C1(0.6mol%)+C20(0.6mol%)\140-3.001
StartOfData
4.99994E-4	20.06176	0.3048435
0.05383332	20.17615	0.4152722
0.1055000	21.02954	-0.2077113
0.1571666	22.26114	-3.387250
0.2105000	23.71977	-7.626401
0.2605000	25.21677	-11.79086
0.3138333	26.91024	-15.94090
0.3655000	28.62876	-19.49167
0.4171667	30.40554	-22.52519
0.4705000	32.29108	-25.16081
0.5205000	34.09444	-27.23250
0.5738334	36.05222	-29.07946
0.6238334	37.91092	-30.56625
0.6771668	39.91309	-31.92908
0.7288332	41.86841	-33.10304
0.7805000	43.83076	-34.27998
0.8338332	45.85508	-35.56980
0.8838332	47.76238	-36.56750
0.9371668	49.81391	-37.37172
0.9888332	51.81640	-38.02900
1.040500	53.82176	-38.74588
1.092167	55.82249	-39.63550
1.143833	57.81587	-40.71050
1.197166	59.87078	-41.88650
1.247166	61.79378	-43.08206
1.300500	63.83826	-44.62510
1.352166	65.79547	-46.68446
1.403833	67.70106	-49.97884
1.457167	69.54870	-56.24870
1.507167	71.08711	-65.92968
1.560500	72.55372	-78.92157
1.610500	73.83518	-92.30761
1.663834	75.21619	-105.5095
1.715500	76.61418	-117.6875
1.767167	77.96580	-130.9513
1.820500	79.45640	-141.9118
1.870500	80.98671	-150.0094
1.923834	82.66669	-157.4688
1.975500	84.57994	-158.8748
2.027166	86.58270	-160.8162
2.078833	88.56839	-162.5289
2.130500	90.63286	-162.4756
2.183833	92.86684	-159.9726
2.233833	95.21272	-151.3870
2.287166	98.14097	-135.3269
2.338833	100.9664	-122.3860
2.390500	103.6608	-112.1868
2.443833	106.3000	-103.5526
2.493833	108.7091	-96.64186
2.547166	111.2020	-90.67595
2.597167	113.4861	-85.91974
2.650500	115.8701	-81.76522
2.702166	118.1352	-78.52691
2.753833	120.3626	-75.99582
2.807167	122.6275	-73.99551
2.857167	124.7266	-72.56070
2.910500	126.9430	-71.38874
2.962167	129.0759	-70.52094
3.010500	131.0570	-69.92601
3.060500	132.9306	-69.67972
3.113833	134.1376	-67.43940
3.165500	134.9963	-61.91730
3.217166	135.6765	-55.41191
3.270500	136.2516	-48.65092
3.320500	136.7016	-42.85430
3.373834	137.1046	-37.43994
3.425500	137.4319	-32.97934
3.477167	137.7086	-29.22914
3.528833	137.9437	-26.10370
3.580500	138.1422	-23.50444
3.633833	138.3169	-21.27552
3.683833	138.4560	-19.53735
3.737167	138.5830	-17.98718
3.788833	138.6885	-16.73958
3.840500	138.7790	-15.68922
3.893833	138.8580	-14.78351
3.943833	138.9225	-14.07009
3.997166	138.9824	-13.42627
4.047167	139.0311	-12.91370
4.100500	139.0752	-12.44848
4.152166	139.1128	-12.06138
4.203833	139.1461	-11.73198
4.257167	139.1760	-11.43916
4.307167	139.2000	-11.20315
4.360500	139.2226	-10.98150
4.412167	139.2423	-10.79340
4.463834	139.2608	-10.62831
4.515500	139.2748	-10.48185
4.567167	139.2889	-10.35403
4.620500	139.3019	-10.23108
4.670500	139.3127	-10.13148
4.723834	139.3225	-10.03123
4.775500	139.3313	-9.942422
4.827167	139.3397	-9.861832
4.880500	139.3478	-9.781531
4.930500	139.3548	-9.714064
4.983834	139.3613	-9.643281
5.033834	139.3674	-9.581085
5.087167	139.3729	-9.516041
5.138833	139.3788	-9.456644
5.190500	139.3836	-9.397064
5.243834	139.3887	-9.335636
5.293832	139.3927	-9.277416
5.347168	139.3978	-9.220025
5.398834	139.4019	-9.162774
5.450500	139.4063	-9.101398
5.503834	139.4104	-9.034582
5.553834	139.4151	-8.970514
5.607168	139.4200	-8.903149
5.657166	139.4234	-8.835132
5.710500	139.4284	-8.765959
5.762168	139.4331	-8.694280
5.813832	139.4369	-8.626132
5.867168	139.4417	-8.550609
5.917168	139.4462	-8.480101
5.970500	139.4509	-8.402410
6.020500	139.4549	-8.326138
6.073834	139.4596	-8.245770
6.125500	139.4644	-8.166934
6.177166	139.4696	-8.084844
6.230500	139.4740	-8.000489
6.280500	139.4791	-7.918628
6.333832	139.4828	-7.831839
6.385500	139.4878	-7.747129
6.437168	139.4924	-7.661897
6.490500	139.4971	-7.574390
6.540500	139.5012	-7.487464
6.593832	139.5071	-7.396819
6.643832	139.5116	-7.310390
6.697168	139.5162	-7.217070
6.748834	139.5212	-7.123384
6.800500	139.5259	-7.026679
6.853832	139.5309	-6.924490
6.903832	139.5369	-6.830331
6.957168	139.5420	-6.729306
7.008832	139.5474	-6.626820
7.060500	139.5534	-6.521943
7.112168	139.5582	-6.419822
7.163832	139.5640	-6.318820
7.217168	139.5684	-6.215984
7.267168	139.5747	-6.114984
7.320500	139.5802	-6.009701
7.372168	139.5860	-5.911230
7.423834	139.5900	-5.807818
7.477168	139.5963	-5.700754
7.527168	139.6011	-5.601299
7.580500	139.6069	-5.496118
7.630500	139.6125	-5.399984
7.683832	139.6168	-5.296374
7.735500	139.6218	-5.197378
7.787168	139.6280	-5.094056
7.840500	139.6329	-4.994895
7.890500	139.6375	-4.897270
7.943832	139.6433	-4.795033
7.995500	139.6475	-4.698402
8.047168	139.6534	-4.595795
8.098832	139.6583	-4.492612
8.150500	139.6644	-4.375864
8.203834	139.6704	-4.252860
8.253834	139.6754	-4.136732
8.307168	139.6839	-4.011536
8.358832	139.6894	-3.881481
8.410499	139.6960	-3.750975
8.463834	139.7031	-3.608578
8.513832	139.7108	-3.469906
8.567166	139.7186	-3.314911
8.617166	139.7250	-3.165802
8.670500	139.7341	-2.999390
8.722168	139.7420	-2.839307
8.773834	139.7506	-2.672482
8.827168	139.7601	-2.487370
8.877168	139.7698	-2.306308
8.930500	139.7789	-2.099147
8.982166	139.7896	-1.883630
9.033832	139.8003	-1.669336
9.085501	139.8114	-1.459662
9.137168	139.8215	-1.265045
9.190500	139.8314	-1.080747
9.240500	139.8393	-0.9313968
9.293834	139.8470	-0.7854431
9.345500	139.8534	-0.6555734
9.397168	139.8594	-0.5393506
9.450500	139.8652	-0.4383494
9.500500	139.8704	-0.3469704
9.553832	139.8752	-0.2588104
9.603832	139.8791	-0.1839391
9.657166	139.8830	-0.1118308
9.708832	139.8870	-.05249972
9.760499	139.8892	.005874654
9.813834	139.8934	0.06482750
9.863834	139.8958	0.1208818
9.917168	139.8984	0.1762946
9.968834	139.9009	0.2226434
10.02050	139.9031	0.2695740
10.07217	139.9060	0.3107068
10.12383	139.9083	0.3492159
10.17717	139.9097	0.3881200
10.22717	139.9119	0.4252770
10.28050	139.9138	0.4583542
10.33217	139.9159	0.4922390
10.38383	139.9180	0.5255568
10.43717	139.9197	0.5589574
10.48717	139.9209	0.5882710
10.54050	139.9227	0.6221652
10.59050	139.9234	0.6515305
10.64383	139.9256	0.6838681
10.69550	139.9271	0.7148399
10.74717	139.9292	0.7453192
10.80050	139.9301	0.7771445
10.85050	139.9320	0.8067595
10.90383	139.9331	0.8410431
10.95550	139.9351	0.8657228
11.00717	139.9372	0.8905766
11.05884	139.9382	0.9197720
11.11050	139.9398	0.9521295
11.16383	139.9416	0.9851288
11.21383	139.9435	1.016862
11.26717	139.9452	1.049681
11.31883	139.9467	1.084080
11.37050	139.9486	1.120209
11.42383	139.9504	1.159463
11.47383	139.9527	1.195244
11.52717	139.9546	1.234786
11.57717	139.9568	1.272593
11.63050	139.9590	1.313615
11.68217	139.9605	1.352300
11.73383	139.9626	1.394006
11.78717	139.9646	1.433256
11.83717	139.9666	1.473456
11.89050	139.9691	1.520160
11.94217	139.9708	1.569116
11.99384	139.9741	1.618154
12.04717	139.9768	1.674356
12.09717	139.9800	1.733404
12.15050	139.9824	1.805513
12.20050	139.9865	1.875375
12.25384	139.9906	1.958434
12.30550	139.9947	2.050133
12.35717	139.9993	2.151028
12.41050	140.0052	2.268974
12.46050	140.0111	2.387612
12.51383	140.0172	2.526550
12.56383	140.0238	2.659620
12.61716	140.0312	2.815600
12.66883	140.0398	2.969475
12.72050	140.0480	3.128752
12.77383	140.0551	3.293444
12.82384	140.0634	3.444578
12.87717	140.0716	3.606000
12.92883	140.0800	3.757283
12.98050	140.0871	3.904833
13.03383	140.0947	4.050633
13.08383	140.1018	4.181486
13.13717	140.1079	4.306477
13.18716	140.1136	4.423802
13.24050	140.1197	4.538652
13.29216	140.1256	4.640781
13.34383	140.1308	4.746900
13.39717	140.1360	4.841946
13.44717	140.1412	4.928989
13.50050	140.1453	5.019128
13.55217	140.1486	5.101314
13.60383	140.1529	5.180460
13.65550	140.1576	5.255152
13.70717	140.1613	5.327259
13.76050	140.1649	5.399678
13.81050	140.1684	5.468704
13.86383	140.1725	5.536506
13.91550	140.1763	5.604218
13.96716	140.1791	5.672422
14.02050	140.1831	5.741223
14.07050	140.1864	5.803134
14.12384	140.1896	5.872818
14.17383	140.1926	5.935484
14.22717	140.1966	6.004400
14.27883	140.2000	6.068870
14.33050	140.2030	6.135296
14.38383	140.2065	6.206486
14.43383	140.2099	6.270866
14.48716	140.2135	6.341658
14.53883	140.2168	6.408202
14.59050	140.2207	6.475562
14.64216	140.2240	6.544912
14.69384	140.2280	6.616969
14.74717	140.2312	6.687980
14.79717	140.2351	6.755940
14.85050	140.2386	6.829431
14.90217	140.2419	6.904449
14.95383	140.2452	6.974840
15.00717	140.2497	7.054060
15.05717	140.2532	7.128315
15.11050	140.2571	7.203520
15.16050	140.2607	7.277886
15.21383	140.2647	7.354359
15.26550	140.2687	7.431301
15.31716	140.2727	7.507850
15.37050	140.2762	7.591349
15.42050	140.2804	7.666701
15.47383	140.2840	7.748126
15.52550	140.2883	7.828642
15.57717	140.2930	7.907724
15.62883	140.2966	7.990754
15.68050	140.3007	8.073616
15.73383	140.3052	8.160834
15.78383	140.3096	8.238500
15.83717	140.3145	8.326887
15.88883	140.3186	8.413456
15.94050	140.3230	8.497485
15.99383	140.3267	8.587356
16.04383	140.3314	8.671480
16.09717	140.3364	8.766028
16.14716	140.3408	8.851176
16.20050	140.3451	8.948340
16.25217	140.3494	9.040664
16.30383	140.3548	9.134391
16.35716	140.3600	9.229910
16.40716	140.3644	9.320642
16.46050	140.3698	9.421207
16.51216	140.3745	9.519745
16.56383	140.3794	9.620659
16.61550	140.3844	9.719476
16.66716	140.3891	9.825809
16.72050	140.3954	9.931703
16.77050	140.4002	10.03080
16.82383	140.4056	10.14122
16.87550	140.4112	10.24731
16.92716	140.4167	10.35754
16.98050	140.4232	10.47364
17.03050	140.4280	10.58130
17.08383	140.4341	10.70194
17.13383	140.4387	10.81300
17.18716	140.4454	10.93170
17.23883	140.4521	11.05206
17.29050	140.4582	11.16662
17.34383	140.4642	11.29102
17.39383	140.4703	11.41646
17.44716	140.4772	11.54387
17.49883	140.4831	11.66936
17.55050	140.4894	11.78749
17.60216	140.4961	11.91967
17.65383	140.5018	12.03504
17.70716	140.5070	12.10782
17.75716	140.5096	12.15771
17.81050	140.5128	12.24674
17.86216	140.5174	12.35566
17.91383	140.5230	12.46099
17.96716	140.5281	12.56572
18.01716	140.5332	12.65550
18.07050	140.5373	12.74182
18.12050	140.5417	12.81684
18.17383	140.5450	12.88660
18.22550	140.5483	12.94637
18.27716	140.5517	12.99299
18.33050	140.5541	13.02996
18.38050	140.5554	13.05208
18.43383	140.5566	13.06576
18.48550	140.5572	13.07075
18.53717	140.5571	13.07417
18.59050	140.5562	13.07381
18.64050	140.5546	13.06128
18.69383	140.5535	13.01934
18.74383	140.5506	12.96449
18.79716	140.5485	12.89662
18.84883	140.5444	12.82618
18.90050	140.5409	12.74673
18.95383	140.5370	12.66170
19.00383	140.5329	12.57377
19.05716	140.5279	12.47814
19.10716	140.5233	12.37761
19.16050	140.5172	12.27255
19.21216	140.5122	12.16209
19.26383	140.5066	12.04739
19.31716	140.5005	11.93075
19.36716	140.4949	11.81580
19.42050	140.4888	11.69192
19.47216	140.4825	11.57727
19.52383	140.4768	11.45864
19.57716	140.4712	11.34126
19.62716	140.4652	11.22729
19.68050	140.4600	11.10905
19.73050	140.4536	10.99994
19.78383	140.4481	10.88951
19.83550	140.4428	10.77958
19.88716	140.4370	10.67075
19.94050	140.4313	10.56322
19.99050	140.4269	10.46622
20.04383	140.4213	10.36204
20.09550	140.4165	10.26693
20.14716	140.4110	10.17358
20.19884	140.4069	10.08361
20.25050	140.4019	9.997632
20.30383	140.3976	9.908399
20.35383	140.3933	9.823742
20.40716	140.3894	9.742407
20.45883	140.3858	9.660322
20.51050	140.3824	9.583069
20.56383	140.3780	9.504996
20.61383	140.3741	9.436158
20.66716	140.3704	9.361212
20.71716	140.3673	9.294975
20.77050	140.3637	9.227989
20.82216	140.3602	9.164999
20.87383	140.3563	9.100879
20.92717	140.3536	9.039916
20.97716	140.3502	8.981391
21.03050	140.3477	8.920454
21.08216	140.3444	8.863038
21.13383	140.3422	8.807197
21.18550	140.3391	8.752187
21.23716	140.3360	8.696918
21.29050	140.3332	8.645179
21.34050	140.3310	8.592960
21.39383	140.3286	8.543007
21.44550	140.3258	8.495966
21.49716	140.3236	8.447160
21.55050	140.3210	8.397629
21.60050	140.3181	8.354611
21.65383	140.3152	8.307952
21.70383	140.3128	8.265250
21.75716	140.3106	8.217246
21.80883	140.3087	8.170515
21.86050	140.3069	8.128782
21.91383	140.3049	8.086305
21.96383	140.3015	8.048094
22.01716	140.3004	8.005159
22.06883	140.2978	7.962842
22.12050	140.2957	7.922364
22.17216	140.2938	7.880157
22.22383	140.2908	7.840558
22.27717	140.2897	7.799546
22.32716	140.2876	7.762958
22.38050	140.2863	7.722906
22.43216	140.2836	7.686128
22.48383	140.2814	7.648530
22.53717	140.2798	7.608756
22.58716	140.2780	7.575085
22.64050	140.2758	7.536840
22.69050	140.2745	7.501081
22.74383	140.2720	7.464208
22.79550	140.2703	7.426826
22.84716	140.2689	7.390747
22.90050	140.2672	7.354506
22.95050	140.2651	7.317795
23.00383	140.2629	7.281294
23.05550	140.2616	7.244890
23.10716	140.2591	7.209705
23.15883	140.2579	7.174155
23.21050	140.2559	7.134887
23.26383	140.2539	7.096553
23.31383	140.2531	7.061426
23.36716	140.2514	7.025428
23.41883	140.2491	6.990575
23.47050	140.2472	6.954330
23.52383	140.2458	6.914486
23.57383	140.2442	6.877670
23.62716	140.2421	6.841156
23.67717	140.2398	6.807568
23.73050	140.2376	6.771390
23.78216	140.2364	6.735620
23.83383	140.2347	6.697680
23.88716	140.2327	6.658402
23.93716	140.2307	6.620282
23.99050	140.2286	6.584759
24.04216	140.2266	6.547363
24.09383	140.2247	6.512000
24.14550	140.2228	6.473110
24.19716	140.2202	6.437302
24.25050	140.2188	6.395866
24.30050	140.2170	6.356608
24.35383	140.2154	6.316828
24.40550	140.2134	6.278907
24.45717	140.2120	6.235762
24.51050	140.2090	6.196212
24.56050	140.2076	6.159184
24.61383	140.2054	6.115809
24.66383	140.2024	6.078262
24.71716	140.2006	6.035494
24.76883	140.1987	5.992148
24.82050	140.1960	5.949981
24.87383	140.1949	5.904890
24.92383	140.1920	5.863532
24.97716	140.1896	5.817652
25.02883	140.1876	5.772924
25.08050	140.1850	5.726153
25.13383	140.1827	5.684311
25.18383	140.1808	5.638103
25.23716	140.1792	5.587707
25.28717	140.1771	5.538772
25.34050	140.1746	5.489726
25.39216	140.1713	5.442559
25.44383	140.1693	5.387621
25.49716	140.1668	5.339728
25.54716	140.1643	5.290500
25.60050	140.1617	5.238333
25.65050	140.1582	5.188758
25.70383	140.1552	5.134796
25.75550	140.1528	5.082028
25.80716	140.1498	5.026455
25.86050	140.1476	4.969942
25.91050	140.1438	4.915615
25.96383	140.1409	4.853786
26.01550	140.1372	4.796250
26.06716	140.1350	4.735048
26.12050	140.1311	4.668989
26.17050	140.1287	4.612530
26.22383	140.1248	4.546400
26.27383	140.1222	4.484205
26.32717	140.1183	4.415260
26.37883	140.1159	4.348602
26.43050	140.1115	4.281420
26.48383	140.1089	4.208606
26.53383	140.1048	4.142186
26.58716	140.1014	4.070094
26.63883	140.0976	3.996175
26.69050	140.0948	3.920164
26.74216	140.0909	3.847290
26.79383	140.0867	3.774544
26.84716	140.0832	3.695139
26.89716	140.0796	3.620504
26.95050	140.0757	3.539063
27.00217	140.0716	3.458960
27.05383	140.0678	3.377054
27.10716	140.0634	3.294920
27.15716	140.0593	3.217382
27.21050	140.0556	3.131114
27.26050	140.0501	3.048954
27.31383	140.0467	2.960497
27.36550	140.0424	2.876172
27.41716	140.0388	2.790829
27.47050	140.0336	2.700440
27.52050	140.0296	2.616025
27.57383	140.0247	2.529374
27.62550	140.0204	2.441274
27.67717	140.0164	2.352317
27.72883	140.0122	2.266892
27.78050	140.0078	2.181800
27.83383	140.0027	2.092787
27.88383	139.9990	2.012917
27.93717	139.9939	1.925705
27.98883	139.9895	1.842877
28.04050	139.9864	1.756950
28.09383	139.9817	1.670781
28.14383	139.9775	1.589250
28.19717	139.9734	1.511139
28.24716	139.9697	1.434808
28.30050	139.9652	1.355068
28.35217	139.9615	1.280009
28.40383	139.9580	1.205955
28.45716	139.9540	1.131419
28.50716	139.9507	1.062988
28.56050	139.9471	0.9960774
28.61216	139.9436	0.9313147
28.66383	139.9402	0.8684875
28.71550	139.9366	0.8066462
28.76716	139.9335	0.7492996
28.82050	139.9300	0.6900697
28.87050	139.9272	0.6346894
28.92383	139.9241	0.5795199
28.97550	139.9216	0.5265024
29.02717	139.9187	0.4767054
29.08050	139.9169	0.4277382
29.13050	139.9137	0.3829434
29.18383	139.9122	0.3357340
29.23383	139.9090	0.2907035
29.28717	139.9069	0.2503904
29.33883	139.9052	0.2111482
29.39050	139.9034	0.1750878
29.44383	139.9015	0.1379482
29.49383	139.8992	0.1079218
29.54716	139.8977	0.07366156
29.59883	139.8964	0.04122994
29.65050	139.8946	0.01145008
29.70217	139.8938	-.01939751
29.75383	139.8924	-.04695560
29.80716	139.8916	-.07553840
29.85716	139.8907	-.09806775
29.91050	139.8884	-0.1196305
29.96216	139.8882	-0.1410981
30.01383	139.8865	-0.1644559
30.06716	139.8858	-0.1828453
30.11716	139.8849	-0.2031794
30.17050	139.8829	-0.2202053
30.22050	139.8829	-0.2370564
30.27383	139.8804	-0.2537348
30.32550	139.8799	-0.2684061
30.37716	139.8799	-0.2837384
30.43050	139.8786	-0.2987526
30.48050	139.8780	-0.3112339
30.53383	139.8777	-0.3263216
30.58550	139.8768	-0.3406438
30.63716	139.8772	-0.3548500
30.68883	139.8758	-0.3675775
30.74050	139.8757	-0.3786914
30.79383	139.8743	-0.3887778
30.84383	139.8729	-0.3982808
30.89716	139.8728	-0.4085125
30.94883	139.8720	-0.4179685
31.00050	139.8713	-0.4274575
31.05383	139.8700	-0.4370312
31.10383	139.8699	-0.4460182
31.15716	139.8700	-0.4553720
31.20716	139.8693	-0.4642797
31.26050	139.8684	-0.4740994
31.31217	139.8681	-0.4833032
31.36383	139.8680	-0.4923032
31.41716	139.8679	-0.5013856
31.46716	139.8668	-0.5095413
31.52050	139.8669	-0.5180104
31.57217	139.8665	-0.5260396
31.62383	139.8661	-0.5335274
31.67717	139.8658	-0.5410722
31.72717	139.8658	-0.5476998
31.78050	139.8654	-0.5543500
31.83050	139.8654	-0.5606407
31.88383	139.8649	-0.5673731
31.93550	139.8640	-0.5734730
31.98717	139.8636	-0.5793600
32.04050	139.8638	-0.5852871
32.09050	139.8638	-0.5906032
32.14383	139.8634	-0.5961812
32.19383	139.8633	-0.6015149
32.24716	139.8630	-0.6070322
32.29883	139.8631	-0.6122304
32.35050	139.8634	-0.6174717
32.40383	139.8628	-0.6226606
32.45383	139.8629	-0.6273224
32.50716	139.8621	-0.6317529
32.55883	139.8626	-0.6358381
32.61050	139.8626	-0.6397234
32.66383	139.8618	-0.6436304
32.71383	139.8619	-0.6469416
32.76716	139.8617	-0.6504442
32.81716	139.8611	-0.6535520
32.87050	139.8619	-0.6568937
32.92216	139.8616	-0.6601584
32.97383	139.8611	-0.6635738
33.02716	139.8605	-0.6670730
33.07717	139.8611	-0.6701640
33.13050	139.8610	-0.6737599
33.18216	139.8608	-0.6768855
33.23383	139.8606	-0.6797122
33.28550	139.8604	-0.6824372
33.33716	139.8610	-0.6851201
33.39050	139.8613	-0.6882884
33.44050	139.8606	-0.6910934
33.49383	139.8609	-0.6943134
33.54550	139.8608	-0.6971253
33.59716	139.8605	-0.6996025
33.65050	139.8604	-0.7015894
33.70050	139.8595	-0.7028616
33.75383	139.8600	-0.7044816
33.80383	139.8594	-0.7060263
33.85716	139.8595	-0.7077407
33.90883	139.8592	-0.7097194
33.96050	139.8598	-0.7117456
34.01383	139.8590	-0.7137592
34.06383	139.8592	-0.7152157
34.11716	139.8591	-0.7172739
34.16883	139.8582	-0.7189770
34.22050	139.8589	-0.7207353
34.27217	139.8585	-0.7222184
34.32383	139.8586	-0.7239308
34.37717	139.8582	-0.7257800
34.42717	139.8579	-0.7275162
34.48050	139.8581	-0.7294614
34.53216	139.8579	-0.7310342
34.58383	139.8584	-0.7327071
34.63716	139.8574	-0.7341656
34.68716	139.8582	-0.7356631
34.74050	139.8577	-0.7368991
34.79050	139.8575	-0.7381570
34.84384	139.8572	-0.7394776
34.89550	139.8574	-0.7411838
34.94717	139.8572	-0.7428262
35.00050	139.8572	-0.7445040
35.05050	139.8578	-0.7459191
35.10383	139.8568	-0.7473053
35.15550	139.8569	-0.7483074
35.20716	139.8566	-0.7494607
35.25883	139.8569	-0.7505420
35.31050	139.8566	-0.7518782
35.36383	139.8571	-0.7532911
35.41383	139.8569	-0.7542801
35.46716	139.8564	-0.7552094
35.51883	139.8566	-0.7559524
35.57050	139.8557	-0.7569679
35.62383	139.8562	-0.7579496
35.67383	139.8566	-0.7591406
35.72717	139.8563	-0.7601876
35.77716	139.8560	-0.7611134
35.83050	139.8570	-0.7622650
35.88216	139.8563	-0.7634292
35.93384	139.8556	-0.7644626
35.98717	139.8559	-0.7654988
36.03717	139.8562	-0.7664335
36.09050	139.8560	-0.7674512
36.14216	139.8562	-0.7684930
36.19383	139.8566	-0.7696990
36.24550	139.8559	-0.7707750
36.29716	139.8562	-0.7719695
36.35050	139.8559	-0.7732415
36.40050	139.8556	-0.7743332
36.45383	139.8563	-0.7751214
36.50550	139.8558	-0.7757772
36.55716	139.8560	-0.7764812
36.61050	139.8563	-0.7771493
36.66050	139.8562	-0.7779257
36.71383	139.8555	-0.7787276
36.76383	139.8558	-0.7794419
36.81716	139.8561	-0.7801969
36.86883	139.8554	-0.7808692
36.92050	139.8557	-0.7814795
36.97383	139.8556	-0.7821093
37.02383	139.8558	-0.7828235
37.07717	139.8556	-0.7835969
37.12883	139.8556	-0.7843110
37.18050	139.8551	-0.7851266
37.23216	139.8552	-0.7856835
37.28383	139.8560	-0.7863428
37.33716	139.8546	-0.7869671
37.38716	139.8550	-0.7876014
37.44050	139.8559	-0.7884189
37.49216	139.8551	-0.7891775
37.54383	139.8553	-0.7898858
37.59716	139.8554	-0.7906384
37.64717	139.8550	-0.7913569
37.70050	139.8556	-0.7917764
37.75050	139.8550	-0.7920632
37.80383	139.8551	-0.7924929
37.85550	139.8558	-0.7931640
37.90716	139.8554	-0.7939179
37.96050	139.8555	-0.7947056
38.01050	139.8554	-0.7954782
38.06383	139.8559	-0.7964190
38.11550	139.8556	-0.7970630
38.16716	139.8555	-0.7976563
38.22050	139.8546	-0.7981262
38.27050	139.8557	-0.7986953
38.32383	139.8558	-0.7991076
38.37383	139.8551	-0.7992439
38.42717	139.8561	-0.7995202
38.47883	139.8547	-0.7994508
38.53050	139.8551	-0.7996026
38.58383	139.8558	-0.8000103
38.63383	139.8555	-0.8003071
38.68716	139.8546	-0.8007300
38.73717	139.8548	-0.8010844
38.79050	139.8551	-0.8014430
38.84216	139.8542	-0.8016282
38.89383	139.8546	-0.8015776
38.94717	139.8545	-0.8016801
38.99716	139.8558	-0.8019085
39.05050	139.8547	-0.8021575
39.10217	139.8547	-0.8026468
39.15383	139.8541	-0.8032543
39.20716	139.8551	-0.8039028
39.25716	139.8542	-0.8046426
39.31050	139.8548	-0.8053321
39.36050	139.8542	-0.8058692
39.41383	139.8535	-0.8062535
39.46550	139.8546	-0.8066931
39.51716	139.8542	-0.8069843
39.57050	139.8544	-0.8073697
39.62050	139.8548	-0.8074902
39.67383	139.8539	-0.8078042
39.72550	139.8555	-0.8084756
39.77716	139.8551	-0.8092194
39.82883	139.8549	-0.8099128
39.88050	139.8546	-0.8104300
39.93384	139.8552	-0.8106834
39.98383	139.8554	-0.8111600
40.03717	139.8552	-0.8115264
40.08883	139.8542	-0.8118503
40.14050	139.8549	-0.8118857
40.19383	139.8545	-0.8122324
40.24383	139.8551	-0.8122862
40.29716	139.8544	-0.8124982
40.34716	139.8537	-0.8125442
40.40050	139.8546	-0.8124884
40.45216	139.8541	-0.8128660
40.50383	139.8538	-0.8130628
40.55716	139.8539	-0.8132966
40.60716	139.8536	-0.8135960
40.66050	139.8539	-0.8139996
40.71216	139.8544	-0.8144931
40.76383	139.8539	-0.8149612
40.81550	139.8539	-0.8152202
40.86716	139.8540	-0.8151684
40.92050	139.8533	-0.8151918
40.97050	139.8540	-0.8153687
41.02383	139.8545	-0.8158306
41.07550	139.8541	-0.8165482
41.12717	139.8546	-0.8168890
41.18050	139.8544	-0.8172082
41.23050	139.8545	-0.8174295
41.28383	139.8545	-0.8180405
41.33383	139.8550	-0.8183753
41.38716	139.8546	-0.8189069
41.43883	139.8543	-0.8193210
41.49050	139.8547	-0.8198910
41.54383	139.8546	-0.8208266
41.59384	139.8548	-0.8214049
41.64717	139.8550	-0.8217264
41.69883	139.8542	-0.8217830
41.75050	139.8538	-0.8216688
41.80217	139.8539	-0.8212556
41.85383	139.8537	-0.8206982
41.90717	139.8538	-0.8202050
41.95717	139.8534	-0.8199324
42.01050	139.8532	-0.8197700
42.06216	139.8534	-0.8199236
42.11383	139.8532	-0.8199988
42.16716	139.8528	-0.8201180
42.21717	139.8530	-0.8204058
42.27050	139.8538	-0.8208429
42.32050	139.8539	-0.8211824
42.37383	139.8526	-0.8212970
42.42550	139.8527	-0.8213366
42.47717	139.8538	-0.8217178
42.53050	139.8528	-0.8221710
42.58050	139.8535	-0.8228179
42.63383	139.8536	-0.8235736
42.68550	139.8539	-0.8242593
42.73717	139.8534	-0.8247730
42.78883	139.8532	-0.8253644
42.84050	139.8535	-0.8259872
42.89383	139.8534	-0.8262848
42.94383	139.8542	-0.8264755
42.99716	139.8541	-0.8266750
43.04550	139.8854	-0.8123496
43.09716	140.2488	-1.126413
43.15050	140.8616	-3.365404
43.20050	141.5274	-6.208849
43.25383	142.3077	-9.379914
43.30550	143.1136	-12.24340
43.35717	143.9589	-14.75803
43.41050	144.8649	-16.96507
43.46050	145.7366	-18.70888
43.51383	146.6907	-20.26299
43.56383	147.6022	-21.48248
43.61716	148.5882	-22.56902
43.66883	149.5564	-23.45397
43.72050	150.5328	-24.20302
43.77383	151.5504	-24.86472
43.82383	152.5100	-25.39636
43.87717	153.5394	-25.90410
43.92883	154.5420	-26.32929
43.98050	155.5479	-26.71698
44.03217	156.5570	-27.05842
44.08383	157.5681	-27.37578
44.13716	158.6148	-27.67781
44.18716	159.5980	-27.94250
44.24050	160.6477	-28.20025
44.29217	161.6672	-28.44825
44.34384	162.6867	-28.68118
44.39717	163.7404	-28.91386
44.44717	164.7286	-29.12643
44.50050	165.7838	-29.34832
44.55050	166.7719	-29.55507
44.60383	167.8285	-29.78016
44.65550	168.8514	-29.98474
44.70717	169.8749	-30.19592
44.76050	170.9308	-30.40791
44.81050	171.9217	-30.60341
44.86383	172.9784	-30.81854
44.91550	174.0024	-31.02366
44.96717	175.0274	-31.22714
45.01883	176.0508	-31.43411
45.07050	177.0753	-31.64356
45.12383	178.1322	-31.86644
45.17383	179.1226	-32.07971
45.22717	180.1791	-32.31617
45.27883	181.2018	-32.56032
45.33050	182.2236	-32.81617
45.38383	183.2792	-33.08926
45.43383	184.2684	-33.35791
45.48717	185.3217	-33.66036
45.53717	186.3104	-33.94936
45.59050	187.3623	-34.26684
45.64217	188.3824	-34.58762
45.69383	189.4018	-34.92498
45.74716	190.4544	-35.28822
45.79716	191.4398	-35.64570
45.85050	192.4906	-36.04144
45.90216	193.5074	-36.44394
45.95383	194.5224	-36.86313
46.00717	195.5706	-37.31924
46.05717	196.5519	-37.77106
46.11050	197.5977	-38.28748
46.16050	198.5757	-38.80063
46.21383	199.6175	-39.37484
46.26550	200.6261	-39.97150
46.31717	201.6324	-40.60109
46.37050	202.6694	-41.29872
46.42050	203.6396	-41.99604
46.47383	204.6725	-42.79720
46.52383	205.6377	-43.61407
46.57717	206.6636	-44.57690
46.62883	207.6541	-45.60473
46.68050	208.6382	-46.75174
46.73383	209.6500	-48.06680
46.78383	210.5909	-49.44134
46.83716	211.5866	-51.10937
46.88883	212.5406	-52.95666
46.94050	213.4838	-55.09130
46.99383	214.4402	-57.65244
47.04383	215.3204	-60.43081
47.09716	216.2410	-63.82257
47.14717	217.0866	-67.40272
47.20050	217.9684	-71.61402
47.25217	218.8078	-76.03513
47.30383	219.6344	-80.67302
47.35717	220.4856	-85.38559
47.40717	221.3042	-89.20762
47.46050	222.2196	-92.17286
47.51216	223.1804	-93.11874
47.56383	224.2366	-92.13087
47.61550	225.3504	-90.11089
47.66716	226.5026	-87.31879
47.72050	227.7296	-83.63728
47.77050	228.9158	-79.36224
47.82383	230.2237	-73.81835
47.87550	231.5338	-67.55322
47.92717	232.8508	-61.59163
47.98050	234.1719	-56.38201
48.03050	235.3702	-52.37410
48.08383	236.6086	-48.91566
48.13383	237.7387	-46.29861
48.18716	238.9166	-44.06103
48.23883	240.0368	-42.32507
48.29050	241.1396	-40.93800
48.34384	242.2652	-39.79783
48.39383	243.3094	-38.93426
48.44717	244.4140	-38.20245
48.49883	245.4770	-37.62844
48.55050	246.5348	-37.16928
48.60217	247.5880	-36.80098
48.65383	248.6374	-36.50010
48.70717	249.7183	-36.25270
48.75717	250.7286	-36.06951
48.81050	251.8043	-35.92160
48.86217	252.8442	-35.80875
48.91383	253.8837	-35.72442
48.96717	254.9545	-35.65789
49.01717	255.9590	-35.61892
49.07050	257.0298	-35.60790
49.12050	258.0314	-35.59998
49.17383	259.1004	-35.59388
49.22550	260.1355	-35.59212
49.27716	261.1712	-35.59338
49.33050	262.2380	-35.59978
49.38050	263.2398	-35.62693
49.43383	264.3070	-35.65344
49.48550	265.3410	-35.68850
49.53717	266.3764	-35.72355
49.58883	267.4104	-35.75140
49.64050	268.4448	-35.78108
49.69383	269.5116	-35.81594
49.74383	270.5114	-35.84911
49.79716	271.5782	-35.87626
49.84883	272.6113	-35.90994
49.90050	273.6448	-35.95018
49.95383	274.7123	-35.98496
50.00050	275.6451	-36.03702
50.05383	276.5854	-36.15217
50.10550	276.7490	-33.87373
50.15717	276.5520	-27.46403
50.21050	276.1476	-19.56648
50.26050	275.6491	-12.30357
50.31383	275.0200	-5.377710
50.36550	274.3340	0.3532224
50.41716	273.5891	5.144144
50.47050	272.7694	9.225363
50.52050	271.9626	12.37617
50.57383	271.0688	15.15067
50.62383	270.2062	17.29705
50.67717	269.2610	19.18490
50.72883	268.3286	20.70730
50.78050	267.3795	21.96555
50.83383	266.3875	23.04686
50.88383	265.4460	23.89670
50.93716	264.4344	24.65483
50.98883	263.4465	25.26589
51.04050	262.4518	25.78185
51.09217	261.4532	26.21736
51.14383	260.4501	26.58968
51.19717	259.4114	26.91307
51.24717	258.4339	27.17198
51.30050	257.3894	27.41682
51.35217	256.3739	27.60546
51.40383	255.3578	27.77810
51.45717	254.3063	27.93748
51.50717	253.3211	28.06690
51.56050	252.2668	28.18270
51.61050	251.2777	28.27612
51.66383	250.2223	28.36205
51.71550	249.1994	28.43659
51.76716	248.1751	28.50360
51.82050	247.1172	28.56777
51.87050	246.1260	28.61301
51.92383	245.0661	28.65777
51.97550	244.0402	28.69102
52.02717	243.0132	28.71185
52.07883	241.9860	28.72921
52.13050	240.9588	28.73826
52.18383	239.8980	28.75238
52.23383	238.9046	28.76296
52.28716	237.8442	28.77406
52.33883	236.8170	28.78536
52.39050	235.7894	28.80312
52.44384	234.7274	28.81297
52.49382	233.7323	28.82009
52.54717	232.6713	28.82575
52.59716	231.6756	28.82900
52.65050	230.6138	28.83078
52.70216	229.5852	28.83175
52.75383	228.5570	28.83102
52.80717	227.4952	28.83153
52.85717	226.4987	28.83330
52.91050	225.4375	28.83487
52.96216	224.4080	28.83740
53.01382	223.3783	28.83951
53.06550	222.3494	28.83993
53.11716	221.3200	28.83938
53.17050	220.2582	28.83774
53.22050	219.2620	28.83602
53.27383	218.1999	28.83468
53.32550	217.1705	28.83272
53.37717	216.1414	28.82999
53.43050	215.0788	28.82660
53.48050	214.0828	28.82260
53.53383	213.0188	28.81714
53.58383	212.0216	28.81066
53.63716	210.9586	28.80222
53.68882	209.9287	28.79230
53.74050	208.8989	28.78149
53.79382	207.8364	28.76604
53.84384	206.8395	28.75359
53.89717	205.7756	28.74015
53.94883	204.7466	28.71786
54.00050	203.7153	28.70444
54.05217	202.6862	28.68782
54.10383	201.6560	28.66134
54.15717	200.5930	28.64268
54.20717	199.5967	28.62648
54.26050	198.5344	28.61090
54.31216	197.5053	28.60019
54.36382	196.4750	28.58794
54.41716	195.4114	28.57715
54.46717	194.4149	28.56880
54.52050	193.3514	28.56068
54.57050	192.3545	28.55112
54.62383	191.2911	28.53952
54.67550	190.2612	28.52856
54.72717	189.2305	28.50678
54.78050	188.1680	28.49210
54.83050	187.1710	28.47682
54.88383	186.1077	28.46368
54.93550	185.0778	28.45186
54.98717	184.0471	28.43494
55.03882	183.0169	28.41110
55.09050	181.9855	28.39392
55.14384	180.9225	28.37278
55.19384	179.9246	28.35474
55.24717	178.8625	28.34093
55.29883	177.8320	28.33148
55.35050	176.8016	28.32389
55.40383	175.7395	28.31639
55.45383	174.7428	28.31030
55.50717	173.6787	28.30511
55.55717	172.6824	28.30076
55.61050	171.6189	28.29572
55.66216	170.5883	28.29160
55.71382	169.5592	28.28931
55.76716	168.4964	28.29274
55.81716	167.5012	28.32836
55.87050	166.4420	28.41730
55.92217	165.4192	28.57910
55.97382	164.4019	28.87626
56.02717	163.3628	29.48906
56.07717	162.4096	30.55908
56.13050	161.4286	32.53800
56.18050	160.5568	35.43090
56.23383	159.6848	39.71774
56.28550	158.8921	44.79859
56.33716	158.1290	50.27778
56.39050	157.3405	55.68664
56.44050	156.5750	60.04230
56.49382	155.7088	63.57046
56.54382	154.8392	65.65189
56.59716	153.8484	66.55859
56.64883	152.8243	66.19556
56.70050	151.7465	64.80163
56.75383	150.5848	62.48428
56.80383	149.4635	59.75952
56.85717	148.2463	56.51710
56.90883	147.0582	53.30613
56.96050	145.8719	50.21383
57.01382	144.6581	47.27881
57.06382	143.5348	44.82088
57.11716	142.3500	42.46780
57.16716	141.2527	40.54480
57.22050	140.0966	38.78700
57.27217	138.9924	37.34050
57.32383	137.8946	36.10328
57.37717	136.7746	35.00002
57.42717	135.7299	34.11340
57.48050	134.6233	33.29334
57.53217	133.5569	32.60928
57.58383	132.4948	32.02098
57.63550	131.4379	31.50317
57.68716	130.3843	31.04434
57.74050	129.3006	30.63988
57.79050	128.2855	30.30518
57.84384	127.2047	29.98724
57.89550	126.1601	29.70530
57.94717	125.1165	29.44464
58.00050	124.0410	29.19700
58.05050	123.0333	28.98349
58.10383	121.9594	28.77682
58.15383	120.9531	28.59547
58.20717	119.8808	28.41506
58.25883	118.8424	28.25594
58.31050	117.8034	28.10530
58.36382	116.7333	27.96936
58.41382	115.7299	27.83592
58.46717	114.6598	27.70442
58.51884	113.6238	27.58550
58.57050	112.5880	27.46872
58.62217	111.5526	27.35962
58.67383	110.5175	27.25681
58.72717	109.4493	27.15712
58.77717	108.4476	27.07043
58.83050	107.3789	26.96822
58.88217	106.3443	26.86963
58.93383	105.3096	26.77322
58.98717	104.2416	26.68010
59.03716	103.2419	26.59426
59.09050	102.1746	26.50178
59.14050	101.1742	26.41511
59.19384	100.1052	26.33564
59.24550	99.07066	26.25639
59.29717	98.03692	26.16963
59.35050	96.96834	26.09195
59.40050	95.96682	26.01769
59.45383	94.90012	25.92713
59.50550	93.86681	25.84297
59.55717	92.83231	25.75870
59.60883	91.79863	25.67828
59.66050	90.76399	25.60028
59.71382	89.69599	25.50625
59.76382	88.69405	25.42726
59.81716	87.62756	25.34245
59.86882	86.59363	25.25427
59.92050	85.55985	25.17158
59.97382	84.49276	25.08675
60.02383	83.49188	25.01264
60.07717	82.42512	24.93195
60.12717	81.42537	24.85834
60.18050	80.35734	24.77616
60.23217	79.32325	24.70597
60.28383	78.28925	24.63104
60.33716	77.22187	24.55426
60.38716	76.22132	24.48364
60.44050	75.15338	24.41069
60.49216	74.12062	24.33626
60.54382	73.08700	24.26470
60.59550	72.05348	24.19158
60.64717	71.01913	24.11566
60.70050	69.95208	24.04146
60.75050	68.95116	23.96836
60.80383	67.88340	23.89056
60.85550	66.85034	23.81425
60.90717	65.81690	23.73778
60.96050	64.74800	23.66396
61.01050	63.74735	23.59011
61.06382	62.68004	23.50494
61.11382	61.67818	23.42558
61.16716	60.61090	23.33323
61.21884	59.57548	23.24758
61.27050	58.54039	23.16363
61.32383	57.47320	23.07800
61.37383	56.47085	22.99414
61.42717	55.40518	22.91043
61.47883	54.37012	22.83234
61.53050	53.33540	22.74658
61.58217	52.30070	22.66706
61.63383	51.26678	22.58088
61.68716	50.19814	22.49640
61.73717	49.19740	22.41484
61.79050	48.12966	22.33263
61.84217	47.09445	22.24842
61.89384	46.05966	22.17090
61.94717	44.98990	22.08978
61.99717	43.98802	22.01282
62.05050	42.91883	21.92395
62.10050	41.91726	21.84190
62.15383	40.84691	21.74461
62.20550	39.81234	21.65309
62.25717	38.77692	21.55776
62.31050	37.70698	21.44589
62.36050	36.70554	21.33628
62.41382	35.63522	21.22461
62.46550	34.59832	21.11442
62.51716	33.56239	21.00125
62.57050	32.49296	20.88394
62.62050	31.48925	20.77065
62.67383	30.41826	20.65706
62.72382	29.41492	20.55590
62.77717	28.34457	20.43374
62.82883	27.30732	20.31182
62.88050	26.26958	20.19156
62.93383	25.19668	20.06138
62.98383	24.19276	19.93786
63.03383	23.20785	19.78566
63.08550	22.72251	18.93281
63.13716	22.76830	15.51769
63.19050	23.05224	10.84729
63.24050	23.48686	6.271794
63.29382	24.07605	1.775088
63.34550	24.74021	-2.014444
63.39717	25.48051	-5.200107
63.45050	26.30207	-7.904138
63.50050	27.11672	-9.980391
63.55383	28.02198	-11.78298
63.60383	28.89732	-13.15872
63.65717	29.85524	-14.34993
63.70883	30.80041	-15.29173
63.76050	31.76029	-16.06666
63.81382	32.76506	-16.72220
63.86384	33.71600	-17.23942
63.91716	34.73694	-17.70384
63.96884	35.73407	-18.08263
64.02050	36.73422	-18.41486
64.07218	37.73977	-18.70715
64.12383	38.74829	-18.96577
64.17718	39.79222	-19.19544
64.22718	40.77307	-19.39335
64.28050	41.82232	-19.58684
64.33217	42.83850	-19.75429
64.38384	43.85759	-19.91182
64.43717	44.91152	-20.06540
64.48717	45.89959	-20.19868
64.54050	46.95671	-20.33033
64.59050	47.94720	-20.45193
64.64384	49.00626	-20.57679
64.69550	50.03166	-20.69158
64.74717	51.05767	-20.80020
64.80050	52.11654	-20.91350
64.85050	53.11120	-21.01487
64.90384	54.17160	-21.12168
64.95550	55.19970	-21.21740
65.00718	56.22826	-21.31574
65.05884	57.25653	-21.41410
65.11050	58.28495	-21.50838
65.16382	59.34620	-21.60765
65.21384	60.34179	-21.69783
65.26716	61.40298	-21.79580
65.31884	62.43290	-21.90044
65.37050	63.46172	-21.99710
65.42383	64.52506	-22.09608
65.47384	65.52064	-22.18564
65.52717	66.58400	-22.27180
65.57718	67.58111	-22.36161
65.63050	68.64365	-22.45608
65.68218	69.67488	-22.54946
65.73384	70.70515	-22.63395
65.78718	71.76894	-22.72526
65.83716	72.76604	-22.81326
65.89050	73.82903	-22.90159
65.94218	74.85930	-22.98622
65.99384	75.88890	-23.07190
66.04550	76.91907	-23.16483
66.09718	77.94872	-23.25828
66.15050	79.01264	-23.35488
66.20050	80.00855	-23.44463
66.25384	81.07239	-23.54512
66.30550	82.10322	-23.63942
66.35718	83.13412	-23.73034
66.41050	84.19688	-23.82659
66.46050	85.19434	-23.92278
66.51384	86.25742	-24.02420
66.56384	87.25353	-24.11603
66.61718	88.31756	-24.21735
66.66884	89.34747	-24.31750
66.72050	90.37792	-24.42646
66.77384	91.44093	-24.52498
66.82384	92.43912	-24.62419
66.87718	93.50314	-24.72442
66.92884	94.53270	-24.81576
66.98050	95.56336	-24.91333
67.03218	96.59378	-25.01158
67.08384	97.62407	-25.10246
67.13718	98.68671	-25.20080
67.18718	99.68251	-25.29518
67.24050	100.7467	-25.39707
67.29218	101.7765	-25.49954
67.34384	102.8079	-25.59955
67.39718	103.8706	-25.69874
67.44718	104.8673	-25.79545
67.50050	105.9307	-25.90197
67.55050	106.9288	-25.99882
67.60384	107.9912	-26.10082
67.65550	109.0211	-26.20188
67.70718	110.0508	-26.29852
67.76050	111.1161	-26.40227
67.81050	112.1122	-26.49732
67.86384	113.1756	-26.60268
67.91550	114.2062	-26.70384
67.96718	115.2350	-26.80390
68.02050	116.2979	-26.92567
68.07050	117.2942	-27.03626
68.12384	118.3558	-27.15515
68.17384	119.3519	-27.27478
68.22718	120.4134	-27.40328
68.27884	121.4432	-27.52718
68.33050	122.4722	-27.65360
68.38384	123.5346	-27.78137
68.43384	124.5311	-27.90068
68.48718	125.5931	-28.02428
68.53718	126.5887	-28.13880
68.59050	127.6501	-28.26298
68.64216	128.6789	-28.38424
68.69384	129.7087	-28.50996
68.74718	130.7715	-28.63758
68.79718	131.7677	-28.76858
68.85050	132.8296	-28.89696
68.90218	133.8585	-29.02256
68.95384	134.8878	-29.15290
69.00718	135.9495	-29.29444
69.05718	136.9461	-29.42120
69.11050	138.0081	-29.57037
69.16050	139.0030	-29.69959
69.21384	140.0658	-29.84250
69.26550	141.0940	-29.99480
69.31718	142.1216	-30.13646
69.37050	143.1840	-30.28856
69.42050	144.1788	-30.42975
69.47384	145.2408	-30.58122
69.52550	146.2690	-30.72741
69.57718	147.2967	-30.88410
69.62884	148.3246	-31.03595
69.68050	149.3512	-31.19528
69.73384	150.4120	-31.35650
69.78384	151.4057	-31.51207
69.83716	152.4669	-31.67984
69.88884	153.4942	-31.85232
69.94050	154.5212	-32.01446
69.99384	155.5837	-32.18104
70.04384	156.5776	-32.32915
70.09718	157.6396	-32.48538
70.14718	158.6350	-32.63514
70.20050	159.6951	-32.78794
70.25218	160.7244	-32.93985
70.30384	161.7526	-33.09034
70.35718	162.8149	-33.22904
70.40718	163.8108	-33.35144
70.46050	164.8735	-33.46560
70.51218	165.9039	-33.55213
70.56384	166.9352	-33.63244
70.61550	167.9670	-33.70510
70.66718	168.9989	-33.76564
70.72050	170.0644	-33.82922
70.77050	171.0638	-33.89870
70.82384	172.1288	-33.97843
70.87550	173.1607	-34.06472
70.92718	174.1924	-34.15970
70.98050	175.2551	-34.26970
71.03050	176.2523	-34.38640
71.08384	177.3138	-34.53108
71.13384	178.3079	-34.68801
71.18718	179.3673	-34.88200
71.23882	180.3930	-35.09006
71.29050	181.4168	-35.33100
71.34384	182.4728	-35.61109
71.39384	183.4624	-35.89400
71.44718	184.5148	-36.24439
71.49884	185.5341	-36.61582
71.55050	186.5504	-37.02568
71.60218	187.5653	-37.48633
71.65384	188.5776	-37.99800
71.70718	189.6195	-38.58112
71.75718	190.5938	-39.21202
71.81050	191.6289	-39.93859
71.86218	192.6298	-40.70445
71.91382	193.6280	-41.51940
71.96718	194.6562	-42.39326
72.01716	195.6184	-43.23881
72.07050	196.6443	-44.16586
72.12050	197.6042	-45.06807
72.17384	198.6268	-46.07411
72.22551	199.6148	-47.10738
72.27718	200.5999	-48.21705
72.33050	201.6124	-49.44852
72.38050	202.5588	-50.69871
72.43384	203.5636	-52.09596
72.48550	204.5350	-53.49753
72.53718	205.5064	-54.88154
72.58884	206.4804	-56.17691
72.64050	207.4628	-57.24770
72.69384	208.4956	-57.87082
72.74384	209.4927	-57.74110
72.79718	210.5992	-56.59180
72.84882	211.7158	-54.58656
72.90050	212.8638	-52.01959
72.95384	214.0656	-49.07902
73.00384	215.1960	-46.34241
73.05718	216.3906	-43.75894
73.10718	217.4920	-41.74590
73.16050	218.6484	-39.99436
73.21218	219.7512	-38.62587
73.26384	220.8411	-37.52732
73.31718	221.9554	-36.63448
73.36718	222.9912	-35.96383
73.42050	224.0881	-35.39382
73.47218	225.1446	-34.95344
73.52384	226.1976	-34.60382
73.57550	227.2455	-34.34195
73.62718	228.2908	-34.12472
73.68050	229.3667	-33.96270
73.73050	230.3760	-33.85794
73.78384	231.4489	-33.77615
73.83550	232.4874	-33.72434
73.88718	233.5240	-33.69446
73.94050	234.5952	-33.68057
73.99050	235.5981	-33.67336
74.04384	236.6665	-33.67066
74.09384	237.6686	-33.66893
74.14718	238.7364	-33.66994
74.19884	239.7711	-33.67834
74.25050	240.8045	-33.70487
74.30384	241.8712	-33.74649
74.35384	242.8710	-33.79529
74.40718	243.9370	-33.84702
74.45884	244.9709	-33.89602
74.51050	246.0040	-33.94403
74.56384	247.0707	-33.99342
74.61384	248.0712	-34.02992
74.66718	249.1369	-34.07256
74.71718	250.1375	-34.11308
74.77050	251.2037	-34.16156
74.82218	252.2364	-34.21265
74.87384	253.2692	-34.25993
74.92718	254.3356	-34.30958
74.97718	255.3336	-34.35778
75.03050	256.4009	-34.42386
75.08050	257.4012	-34.48399
75.13384	258.4668	-34.54056
75.18550	259.4984	-34.60380
75.23718	260.5313	-34.67294
75.29050	261.5958	-34.73290
75.34050	262.5940	-34.80080
75.39384	263.6599	-34.88220
75.44550	264.6906	-34.95579
75.49718	265.7214	-35.04074
75.55050	266.7866	-35.13467
75.60050	267.7844	-35.20903
75.65384	268.8492	-35.30187
75.70384	269.8466	-35.38730
75.75718	270.9116	-35.47607
75.80884	271.9424	-35.55933
-2.000000	5.000000	0.0000000