File: 1-C1(0.6mol%)+C20(0.6mol%)/matlab/150-2.txt
CLOSED
Version	1.0
Language	English
Mode	Standard
Run	5
RunSerial	11855
Instrument	DSC Q2000 V24.11 Build 124
Module	DSC Standard Cell RC
Operator	Jing
File	\\AE520-1454\TA\Data\DSC\UQ Composites\Nan\C1(5.5)+C20P(3)+CL(HotplateMixtureAB)\150-2
ProcName	Ramp
InstSerial	2000-0883
AutoSerial	1293
Sample	Iso-150-2
Size	42.6000	mg
PanMass	Not available
PanResist	Automatic Automatic  K/W
PanFactor	Default Default
Method	Ramp
Comment
Xcomment	Pan: Tzero Aluminum Hermetic
Xcomment	Gas1: Nitrogen 50.0 ml/min
Xcomment	Gas2: Nitrogen 50.0 ml/min
Text
Exotherm	UP
Kcell	1.05230
Cpconst	Standard: 0.938
Calib	-38.6961
TempCal	1	pts	157.46	156.60
TzeroDt	-87.6168 -0.0009 -1.4231
TzeroDtz	-87.6168 0.0057 6.9570
InstCalFile	Tzero: \\Ae520-1454\ta\Data\DSC\Calibration\2017\CALIBRATION\1562_RCS (90)_05_18_2017 10_50_44.TZR
InstCalFile	Baseline: \\Ae520-1454\ta\Data\DSC\Calibration\2017\2017-05-17_Calibration.001
InstCalFile	Sapphire: \\Ae520-1454\ta\Data\DSC\Calibration\2017\2017-05-17_Saphire.001
InstCalDate	Tzero 2017-05-18 Time 10:50:44
TempRange	-87.39 to 398.39 °C at 10.00 °C/min Heat Only
AutoZero	Delta T Offset 0.000 uV
AutoZero	Delta T0 Offset 0.000 uV
MultiptCal	0
MultiPtDesc	0) Not set
AutoCellConst	Calibration Date 2017-05-18 16:59:28
Controls	Gas 1  Event Off  Sampling 0.2
Cell#	RC-01562
CoolingUnit	RCS (90)
SelHeatFlow	Heat Flow T4 (mW)
AutoLidII	Installed
AutoAnalysis	Off
MacroFile
Nsig	3
Sig1	Time (min)
Sig2	Temperature (°C)
Sig3	Heat Flow (mW)
Date	2017-06-20
Time	21:58:24
OrgMethod	1: Equilibrate at 20.00 °C
OrgMethod	2: Ramp 40.00 °C/min to 150.00 °C
OrgMethod	3: Mark end of cycle 1
OrgMethod	4: Isothermal for 40.00 min
OrgMethod	5: Mark end of cycle 2
OrgMethod	6: Ramp 20.00 °C/min to 280.00 °C
OrgMethod	7: Mark end of cycle 3
OrgMethod	8: Ramp 20.00 °C/min to 20.00 °C
OrgMethod	9: Mark end of cycle 4
OrgMethod	10: Ramp 20.00 °C/min to 280.00 °C
OrgMethod	11: Mark end of cycle 5
OrgFile	C:\Users\jarra\Desktop\DSC\1-C1(0.6mol%)+C20(0.6mol%)\150-2.001
StartOfData
4.99994E-4	20.09488	0.2943017
0.05383332	20.20908	0.4097072
0.1055000	21.05750	-0.2752677
0.1571666	22.28286	-3.460050
0.2088333	23.69184	-7.529156
0.2605000	25.23744	-11.77366
0.3121666	26.87664	-15.71441
0.3638334	28.59260	-19.19214
0.4171667	30.42603	-22.23034
0.4671667	32.19064	-24.62725
0.5205000	34.11407	-26.74354
0.5705000	35.94670	-28.38838
0.6238334	37.92800	-29.87395
0.6738334	39.80228	-31.04974
0.7271668	41.81941	-32.17000
0.7771668	43.71490	-33.21994
0.8305000	45.73425	-34.49958
0.8804999	47.63146	-35.55205
0.9338332	49.67679	-36.38078
0.9854999	51.67190	-37.06960
1.037167	53.67088	-37.82114
1.088833	55.66198	-38.83417
1.140500	57.64048	-40.07656
1.192167	59.61736	-41.32111
1.243833	61.59740	-42.59873
1.295500	63.57062	-44.10578
1.347166	65.52060	-46.20637
1.400500	67.47908	-49.71757
1.450500	69.20640	-55.49676
1.503833	70.86713	-65.24793
1.553833	72.26512	-76.94174
1.607167	73.65925	-90.63494
1.657167	74.97251	-102.7497
1.710500	76.40576	-115.4859
1.760500	77.71543	-128.3265
1.813834	79.12043	-141.3338
1.863834	80.57112	-150.5098
1.917167	82.17413	-159.5270
1.968833	84.06684	-160.2238
2.020500	86.21922	-158.5444
2.072166	88.32266	-158.9024
2.123834	90.40494	-158.8357
2.175500	92.57944	-156.2578
2.227167	94.98984	-147.8184
2.280500	97.88941	-132.2670
2.330500	100.6145	-119.8463
2.383833	103.4009	-108.8554
2.433833	105.9064	-100.4486
2.487166	108.4793	-93.13590
2.537166	110.8155	-87.58478
2.590500	113.2413	-82.81371
2.640500	115.4627	-79.23434
2.693833	117.7850	-76.21215
2.743833	119.9286	-74.01660
2.797167	122.1804	-72.29162
2.848834	124.3375	-71.01642
2.900500	126.4753	-70.07968
2.952166	128.5975	-69.39840
3.003833	130.7058	-68.95691
3.055500	132.8048	-68.75603
3.107167	134.8949	-68.72588
3.158834	136.9753	-68.87384
3.210500	139.0498	-69.17218
3.260500	141.0542	-69.50012
3.310500	142.8917	-70.00488
3.363834	144.0741	-68.45397
3.413833	144.8880	-63.73076
3.467166	145.5718	-57.62397
3.518833	146.1145	-51.62235
3.570500	146.5647	-46.14150
3.622166	146.9409	-41.35688
3.673834	147.2556	-37.30818
3.725500	147.5210	-33.88713
3.777167	147.7452	-31.03506
3.828833	147.9357	-28.66154
3.880500	148.0971	-26.68076
3.933833	148.2396	-24.98924
3.983833	148.3526	-23.66020
4.037167	148.4564	-22.47314
4.087167	148.5416	-21.53611
4.140500	148.6185	-20.69114
4.190500	148.6812	-20.01667
4.243834	148.7389	-19.39714
4.293833	148.7866	-18.89523
4.347166	148.8308	-18.43231
4.397167	148.8667	-18.05047
4.450500	148.9005	-17.69195
4.502167	148.9298	-17.38224
4.553834	148.9548	-17.10752
4.605500	148.9776	-16.85966
4.657166	148.9984	-16.63386
4.708834	149.0167	-16.42412
4.760500	149.0327	-16.23086
4.813834	149.0485	-16.04646
4.863834	149.0616	-15.88213
4.917167	149.0746	-15.71318
4.967167	149.0854	-15.56279
5.020500	149.0969	-15.40386
5.070500	149.1070	-15.26267
5.123833	149.1189	-15.11297
5.173834	149.1269	-14.97296
5.227167	149.1365	-14.82906
5.277168	149.1451	-14.69828
5.330500	149.1536	-14.56308
5.382168	149.1615	-14.42398
5.433832	149.1696	-14.29616
5.485500	149.1776	-14.16082
5.537168	149.1848	-14.03125
5.588832	149.1934	-13.89734
5.640500	149.2010	-13.76775
5.692166	149.2075	-13.63828
5.743834	149.2148	-13.50727
5.797168	149.2224	-13.36740
5.847168	149.2294	-13.23899
5.900500	149.2367	-13.09915
5.950500	149.2442	-12.96020
6.003834	149.2529	-12.80914
6.053834	149.2598	-12.66431
6.107168	149.2680	-12.50431
6.157166	149.2765	-12.34692
6.210500	149.2852	-12.16892
6.260500	149.2944	-11.99347
6.313832	149.3038	-11.79581
6.365500	149.3138	-11.60007
6.417168	149.3243	-11.38991
6.468832	149.3349	-11.17852
6.520500	149.3466	-10.95880
6.572168	149.3580	-10.73198
6.623834	149.3696	-10.48510
6.677168	149.3827	-10.21180
6.727168	149.3974	-9.937309
6.780500	149.4125	-9.626830
6.830500	149.4277	-9.315801
6.883832	149.4443	-8.974558
6.933832	149.4612	-8.641468
6.987168	149.4792	-8.280801
7.037168	149.4960	-7.935849
7.090500	149.5150	-7.549375
7.140500	149.5330	-7.187776
7.193832	149.5528	-6.791943
7.245500	149.5721	-6.409094
7.297168	149.5918	-6.027428
7.348832	149.6104	-5.643176
7.400500	149.6302	-5.258970
7.452168	149.6486	-4.869887
7.503832	149.6694	-4.491104
7.555500	149.6867	-4.137206
7.607168	149.7039	-3.811029
7.660500	149.7194	-3.503306
7.710500	149.7324	-3.247778
7.763834	149.7458	-3.009663
7.813834	149.7559	-2.808070
7.867166	149.7669	-2.611836
7.917168	149.7758	-2.449051
7.970500	149.7836	-2.295430
8.020500	149.7910	-2.160686
8.073834	149.7972	-2.037863
8.123834	149.8031	-1.929512
8.177168	149.8094	-1.826873
8.228834	149.8141	-1.737968
8.280500	149.8187	-1.654192
8.332168	149.8226	-1.580220
8.383832	149.8264	-1.508087
8.435499	149.8298	-1.438026
8.487168	149.8344	-1.372533
8.540500	149.8368	-1.307827
8.590500	149.8399	-1.250776
8.643832	149.8435	-1.196594
8.693832	149.8461	-1.143103
8.747168	149.8488	-1.086502
8.797168	149.8522	-1.036742
8.850500	149.8543	-0.9887862
8.900500	149.8555	-0.9438129
8.953834	149.8590	-0.8931374
9.003834	149.8622	-0.8504749
9.057168	149.8646	-0.8051757
9.108832	149.8663	-0.7595475
9.160499	149.8691	-0.7167029
9.212168	149.8708	-0.6748894
9.263832	149.8733	-0.6341044
9.315500	149.8749	-0.5940728
9.367166	149.8774	-0.5513870
9.418832	149.8798	-0.5145566
9.470500	149.8812	-0.4741632
9.523834	149.8836	-0.4334104
9.573834	149.8855	-0.3978768
9.627168	149.8880	-0.3578994
9.677168	149.8892	-0.3204541
9.730500	149.8916	-0.2785170
9.780500	149.8936	-0.2421398
9.833832	149.8953	-0.2037730
9.883832	149.8979	-0.1680863
9.937166	149.8999	-0.1248583
9.987168	149.9015	-.08913026
10.04050	149.9039	-.05196910
10.09217	149.9060	-.01084298
10.14383	149.9080	0.02920490
10.19550	149.9094	0.07122410
10.24717	149.9110	0.1083730
10.29883	149.9138	0.1483496
10.35050	149.9156	0.1865396
10.40383	149.9180	0.2265106
10.45383	149.9195	0.2630272
10.50717	149.9222	0.3071633
10.55717	149.9237	0.3451190
10.61050	149.9260	0.3881369
10.66050	149.9278	0.4290213
10.71383	149.9303	0.4706570
10.76383	149.9323	0.5104734
10.81716	149.9339	0.5536414
10.86716	149.9367	0.5969020
10.92050	149.9381	0.6414630
10.97217	149.9409	0.6859180
11.02383	149.9439	0.7302099
11.07550	149.9456	0.7808241
11.12717	149.9483	0.8328586
11.17883	149.9509	0.8878616
11.23050	149.9537	0.9476495
11.28217	149.9572	1.016252
11.33383	149.9607	1.087023
11.38717	149.9642	1.167440
11.43716	149.9683	1.249246
11.49050	149.9722	1.342999
11.54050	149.9778	1.434572
11.59383	149.9820	1.536669
11.64383	149.9878	1.641581
11.69717	149.9932	1.755682
11.74717	149.9993	1.864506
11.80050	150.0054	1.988706
11.85050	150.0107	2.107197
11.90383	150.0173	2.233562
11.95550	150.0236	2.361709
12.00717	150.0294	2.494418
12.05884	150.0372	2.627722
12.11050	150.0440	2.762525
12.16217	150.0506	2.901729
12.21383	150.0575	3.043208
12.26717	150.0646	3.183691
12.31716	150.0714	3.320544
12.37050	150.0790	3.467437
12.42050	150.0858	3.605527
12.47383	150.0919	3.752213
12.52383	150.0993	3.888946
12.57717	150.1073	4.035678
12.62717	150.1143	4.173878
12.68050	150.1212	4.318217
12.73050	150.1275	4.456434
12.78383	150.1355	4.602641
12.83550	150.1424	4.741804
12.88717	150.1490	4.878987
12.93883	150.1561	5.017834
12.99050	150.1633	5.158133
13.04216	150.1702	5.292254
13.09383	150.1776	5.427261
13.14550	150.1830	5.567618
13.19717	150.1907	5.699540
13.25050	150.1977	5.832558
13.30050	150.2034	5.958758
13.35383	150.2108	6.087846
13.40383	150.2169	6.213690
13.45717	150.2222	6.338793
13.50717	150.2294	6.453095
13.56050	150.2350	6.574348
13.61050	150.2402	6.682793
13.66383	150.2460	6.795956
13.71383	150.2515	6.898613
13.76717	150.2573	7.005660
13.81884	150.2622	7.104296
13.87050	150.2657	7.199694
13.92217	150.2716	7.288840
13.97383	150.2759	7.374656
14.02550	150.2801	7.454278
14.07717	150.2848	7.533004
14.13050	150.2887	7.609016
14.18050	150.2914	7.677822
14.23383	150.2947	7.746038
14.28383	150.2988	7.807055
14.33717	150.3015	7.869370
14.38717	150.3042	7.923634
14.44050	150.3076	7.976638
14.49050	150.3099	8.024030
14.54384	150.3126	8.072084
14.59383	150.3144	8.113197
14.64717	150.3167	8.154707
14.69884	150.3190	8.199230
14.75050	150.3202	8.243610
14.80217	150.3226	8.269434
14.85383	150.3244	8.295822
14.90550	150.3256	8.325324
14.95717	150.3269	8.347730
15.00883	150.3285	8.371897
15.06050	150.3295	8.397118
15.11383	150.3307	8.416290
15.16383	150.3319	8.434040
15.21716	150.3331	8.450570
15.26717	150.3334	8.465707
15.32050	150.3349	8.478839
15.37050	150.3350	8.487820
15.42383	150.3361	8.500251
15.47383	150.3361	8.508437
15.52717	150.3374	8.517742
15.57717	150.3378	8.526055
15.63050	150.3370	8.533453
15.68217	150.3381	8.540311
15.73383	150.3376	8.546444
15.78550	150.3379	8.551209
15.83717	150.3384	8.555601
15.88883	150.3371	8.558007
15.94050	150.3382	8.559832
15.99383	150.3373	8.560444
16.04383	150.3374	8.560212
16.09717	150.3376	8.560626
16.14716	150.3371	8.559376
16.20050	150.3375	8.557495
16.25050	150.3365	8.554452
16.30383	150.3364	8.550397
16.35383	150.3359	8.546044
16.40716	150.3358	8.540314
16.45716	150.3354	8.534855
16.51050	150.3345	8.528192
16.56216	150.3346	8.521772
16.61383	150.3335	8.515044
16.66550	150.3336	8.508312
16.71716	150.3332	8.501163
16.76883	150.3330	8.494312
16.82050	150.3324	8.486555
16.87216	150.3319	8.479410
16.92383	150.3315	8.471728
16.97716	150.3316	8.464255
17.02716	150.3314	8.457062
17.08050	150.3298	8.449379
17.13050	150.3304	8.443403
17.18383	150.3302	8.436169
17.23383	150.3299	8.429775
17.28717	150.3288	8.422428
17.33716	150.3286	8.415984
17.39050	150.3288	8.407947
17.44050	150.3280	8.400903
17.49383	150.3275	8.393328
17.54550	150.3270	8.385730
17.59716	150.3269	8.377700
17.64883	150.3263	8.369872
17.70050	150.3266	8.362656
17.75216	150.3256	8.354706
17.80383	150.3258	8.347230
17.85716	150.3243	8.338922
17.90716	150.3252	8.331290
17.96050	150.3241	8.322236
18.01050	150.3233	8.314243
18.06383	150.3231	8.305559
18.11383	150.3227	8.297321
18.16716	150.3222	8.288166
18.21716	150.3223	8.278293
18.27050	150.3220	8.269118
18.32050	150.3215	8.257580
18.37383	150.3202	8.246818
18.42550	150.3198	8.236668
18.47716	150.3195	8.224163
18.52883	150.3190	8.213451
18.58050	150.3175	8.201147
18.63216	150.3176	8.189850
18.68383	150.3170	8.178374
18.73550	150.3164	8.165686
18.78717	150.3149	8.155136
18.84050	150.3151	8.143546
18.89050	150.3150	8.133243
18.94383	150.3134	8.120007
18.99383	150.3138	8.109926
19.04716	150.3124	8.098510
19.09716	150.3118	8.087510
19.15050	150.3120	8.076732
19.20050	150.3113	8.067376
19.25383	150.3108	8.056256
19.30383	150.3112	8.046411
19.35716	150.3111	8.036736
19.40883	150.3104	8.027699
19.46050	150.3102	8.019134
19.51216	150.3105	8.010308
19.56383	150.3100	8.002384
19.61550	150.3107	7.995170
19.66716	150.3106	7.988879
19.72050	150.3108	7.983144
19.77050	150.3105	7.978812
19.82383	150.3106	7.975610
19.87383	150.3112	7.973794
19.92716	150.3100	7.972370
19.97716	150.3110	7.972429
20.03050	150.3109	7.972961
20.08050	150.3106	7.973728
20.13383	150.3101	7.975062
20.18383	150.3100	7.975226
20.23716	150.3082	7.974929
20.28883	150.3085	7.972761
20.34050	150.3080	7.967825
20.39216	150.3064	7.957511
20.44383	150.3052	7.937456
20.49550	150.3040	7.899836
20.54716	150.3022	7.857495
20.59883	150.3008	7.817681
20.65050	150.2993	7.765366
20.70383	150.2966	7.718360
20.75383	150.2947	7.662906
20.80716	150.2910	7.608660
20.85716	150.2883	7.554697
20.91050	150.2851	7.489770
20.96050	150.2825	7.430792
21.01383	150.2784	7.362268
21.06383	150.2755	7.295950
21.11716	150.2724	7.221778
21.16716	150.2680	7.149595
21.22050	150.2640	7.070976
21.27216	150.2609	6.996499
21.32383	150.2567	6.916820
21.37550	150.2535	6.834530
21.42717	150.2489	6.752922
21.47883	150.2446	6.667822
21.53050	150.2411	6.586946
21.58383	150.2368	6.498284
21.63383	150.2320	6.411948
21.68716	150.2268	6.323000
21.73716	150.2224	6.232402
21.79050	150.2176	6.140718
21.84050	150.2132	6.051184
21.89383	150.2079	5.955414
21.94383	150.2038	5.861793
21.99716	150.1987	5.768820
22.04716	150.1948	5.674390
22.10050	150.1908	5.574270
22.15216	150.1854	5.480626
22.20383	150.1813	5.388834
22.25550	150.1763	5.297115
22.30716	150.1718	5.209044
22.35883	150.1675	5.118278
22.41050	150.1631	5.031429
22.46216	150.1584	4.945941
22.51383	150.1532	4.855374
22.56716	150.1491	4.773922
22.61716	150.1459	4.689326
22.67050	150.1408	4.605248
22.72050	150.1373	4.526657
22.77383	150.1324	4.443688
22.82383	150.1295	4.365393
22.87716	150.1259	4.283993
22.92717	150.1219	4.209170
22.98050	150.1190	4.132932
23.03050	150.1156	4.057410
23.08383	150.1122	3.984714
23.13550	150.1083	3.914829
23.18716	150.1038	3.848456
23.23883	150.1004	3.776516
23.29050	150.0966	3.707324
23.34216	150.0934	3.641352
23.39383	150.0892	3.571399
23.44716	150.0864	3.501523
23.49716	150.0824	3.439761
23.55050	150.0791	3.370325
23.60050	150.0758	3.306145
23.65383	150.0718	3.234258
23.70383	150.0701	3.175278
23.75716	150.0658	3.103899
23.80716	150.0622	3.041464
23.86050	150.0600	2.973460
23.91050	150.0571	2.911300
23.96383	150.0535	2.844309
24.01550	150.0500	2.777395
24.06716	150.0463	2.717606
24.11883	150.0445	2.651413
24.17050	150.0407	2.588042
24.22216	150.0376	2.523068
24.27383	150.0346	2.460352
24.32550	150.0318	2.393700
24.37716	150.0284	2.330782
24.43050	150.0256	2.266002
24.48050	150.0224	2.211812
24.53383	150.0198	2.141584
24.58383	150.0167	2.081631
24.63716	150.0128	2.016575
24.68716	150.0099	1.955768
24.74050	150.0069	1.891775
24.79050	150.0032	1.832421
24.84383	150.0002	1.770487
24.89383	149.9966	1.708435
24.94716	149.9939	1.644696
24.99883	149.9903	1.584660
25.05050	149.9877	1.522277
25.10216	149.9842	1.459751
25.15383	149.9820	1.396004
25.20550	149.9784	1.334917
25.25716	149.9752	1.274795
25.31050	149.9720	1.212272
25.36050	149.9706	1.152782
25.41383	149.9667	1.092789
25.46383	149.9633	1.035200
25.51716	149.9598	0.9751538
25.56716	149.9572	0.9201732
25.62050	149.9534	0.8618116
25.67050	149.9503	0.8074497
25.72383	149.9473	0.7473462
25.77383	149.9446	0.6943847
25.82717	149.9410	0.6382320
25.87883	149.9382	0.5802695
25.93050	149.9361	0.5232050
25.98216	149.9324	0.4704422
26.03383	149.9306	0.4155453
26.08550	149.9276	0.3613458
26.13716	149.9248	0.3057927
26.18883	149.9217	0.2572090
26.24050	149.9194	0.2057574
26.29383	149.9159	0.1512919
26.34383	149.9138	0.1062919
26.39716	149.9118	0.05243285
26.44717	149.9084	.006612824
26.50050	149.9060	-.04615522
26.55050	149.9046	-.09155301
26.60383	149.9023	-0.1387895
26.65383	149.8995	-0.1858044
26.70716	149.8970	-0.2327390
26.75716	149.8954	-0.2766294
26.81050	149.8928	-0.3237035
26.86216	149.8910	-0.3680670
26.91383	149.8904	-0.4149678
26.96550	149.8874	-0.4548402
27.01716	149.8858	-0.4924256
27.06883	149.8839	-0.5367344
27.12050	149.8824	-0.5737836
27.17383	149.8796	-0.6133959
27.22383	149.8786	-0.6470344
27.27717	149.8760	-0.6838874
27.32717	149.8749	-0.7205499
27.38050	149.8726	-0.7574813
27.43050	149.8718	-0.7910735
27.48383	149.8701	-0.8265175
27.53383	149.8679	-0.8588488
27.58716	149.8669	-0.8922936
27.63716	149.8649	-0.9184897
27.69050	149.8640	-0.9516332
27.74216	149.8627	-0.9823884
27.79383	149.8610	-1.010240
27.84550	149.8591	-1.037846
27.89716	149.8577	-1.065660
27.94883	149.8562	-1.090827
28.00050	149.8538	-1.117699
28.05217	149.8529	-1.142808
28.10383	149.8517	-1.166058
28.15716	149.8495	-1.189156
28.20716	149.8485	-1.212828
28.26050	149.8471	-1.233505
28.31050	149.8464	-1.256792
28.36383	149.8448	-1.282700
28.41383	149.8438	-1.302748
28.46716	149.8431	-1.323556
28.51716	149.8422	-1.343931
28.57050	149.8400	-1.368461
28.62050	149.8394	-1.385293
28.67383	149.8396	-1.404538
28.72550	149.8386	-1.425148
28.77717	149.8376	-1.438894
28.82883	149.8359	-1.453334
28.88050	149.8358	-1.470522
28.93216	149.8344	-1.484206
28.98383	149.8340	-1.496592
29.03717	149.8319	-1.508718
29.08716	149.8323	-1.523258
29.14050	149.8311	-1.540167
29.19050	149.8296	-1.550335
29.24383	149.8298	-1.563522
29.29383	149.8295	-1.576084
29.34716	149.8291	-1.592320
29.39716	149.8288	-1.604706
29.45050	149.8283	-1.619456
29.50050	149.8276	-1.630249
29.55383	149.8270	-1.640934
29.60550	149.8264	-1.651656
29.65716	149.8262	-1.662440
29.70883	149.8249	-1.673528
29.76050	149.8251	-1.682850
29.81217	149.8245	-1.693334
29.86383	149.8244	-1.703250
29.91550	149.8228	-1.712209
29.96716	149.8226	-1.721445
30.02050	149.8227	-1.730627
30.07050	149.8216	-1.738902
30.12383	149.8208	-1.747555
30.17383	149.8207	-1.754997
30.22717	149.8196	-1.762722
30.27717	149.8194	-1.770220
30.33050	149.8188	-1.777958
30.38050	149.8183	-1.784894
30.43383	149.8176	-1.792469
30.48383	149.8176	-1.799675
30.53717	149.8175	-1.807070
30.58883	149.8170	-1.814547
30.64050	149.8175	-1.821749
30.69216	149.8177	-1.829174
30.74383	149.8172	-1.836403
30.79550	149.8181	-1.843813
30.84716	149.8166	-1.851156
30.90050	149.8172	-1.857869
30.95050	149.8163	-1.864014
31.00383	149.8161	-1.870158
31.05383	149.8163	-1.875344
31.10716	149.8156	-1.880556
31.15716	149.8159	-1.885404
31.21050	149.8152	-1.890323
31.26050	149.8148	-1.894662
31.31383	149.8145	-1.899244
31.36383	149.8134	-1.903039
31.41716	149.8140	-1.907049
31.46883	149.8131	-1.910868
31.52050	149.8128	-1.914421
31.57217	149.8130	-1.918213
31.62383	149.8118	-1.921680
31.67550	149.8118	-1.925108
31.72717	149.8119	-1.928564
31.77883	149.8118	-1.931763
31.83050	149.8109	-1.935009
31.88383	149.8106	-1.938592
31.93384	149.8106	-1.941882
31.98717	149.8110	-1.945754
32.03717	149.8111	-1.949372
32.09050	149.8112	-1.953338
32.14050	149.8123	-1.957152
32.19383	149.8115	-1.961016
32.24383	149.8112	-1.964425
32.29716	149.8116	-1.968242
32.34716	149.8112	-1.971997
32.40050	149.8116	-1.975762
32.45216	149.8117	-1.978828
32.50383	149.8122	-1.981956
32.55550	149.8119	-1.985077
32.60716	149.8117	-1.987964
32.65883	149.8119	-1.990590
32.71050	149.8117	-1.993051
32.76383	149.8109	-1.995252
32.81383	149.8112	-1.996661
32.86716	149.8096	-1.998478
32.91716	149.8101	-1.999749
32.97050	149.8094	-2.001206
33.02050	149.8098	-2.002625
33.07383	149.8088	-2.003959
33.12383	149.8087	-2.005376
33.17717	149.8092	-2.006574
33.22717	149.8078	-2.007964
33.28050	149.8078	-2.009924
33.33216	149.8083	-2.011881
33.38383	149.8087	-2.014139
33.43550	149.8084	-2.016474
33.48717	149.8075	-2.018483
33.53883	149.8086	-2.020623
33.59050	149.8081	-2.022942
33.64216	149.8078	-2.025097
33.69383	149.8081	-2.027319
33.74716	149.8081	-2.029623
33.79716	149.8094	-2.032124
33.85050	149.8098	-2.034809
33.90050	149.8085	-2.036726
33.95383	149.8092	-2.038795
34.00383	149.8079	-2.040966
34.05716	149.8088	-2.042782
34.10716	149.8081	-2.044526
34.16050	149.8081	-2.045790
34.21050	149.8077	-2.046916
34.26383	149.8074	-2.048009
34.31550	149.8067	-2.048324
34.36716	149.8075	-2.049271
34.41883	149.8069	-2.050526
34.47050	149.8071	-2.051384
34.52217	149.8069	-2.052669
34.57383	149.8072	-2.054074
34.62717	149.8070	-2.055724
34.67717	149.8064	-2.057007
34.73050	149.8065	-2.058658
34.78050	149.8066	-2.060316
34.83383	149.8074	-2.062417
34.88383	149.8074	-2.064668
34.93716	149.8079	-2.066646
34.98717	149.8076	-2.068662
35.04050	149.8076	-2.070148
35.09050	149.8067	-2.071231
35.14383	149.8073	-2.072266
35.19550	149.8071	-2.073476
35.24716	149.8064	-2.074094
35.29883	149.8064	-2.074512
35.35050	149.8065	-2.074921
35.40216	149.8061	-2.074876
35.45383	149.8066	-2.075174
35.50550	149.8057	-2.075526
35.55716	149.8058	-2.075869
35.61050	149.8051	-2.076168
35.66050	149.8060	-2.076902
35.71383	149.8062	-2.078157
35.76383	149.8056	-2.079027
35.81716	149.8056	-2.080330
35.86716	149.8064	-2.082031
35.92050	149.8059	-2.083672
35.97050	149.8062	-2.084794
36.02383	149.8066	-2.086064
36.07383	149.8061	-2.086799
36.12717	149.8061	-2.087923
36.17883	149.8068	-2.089182
36.23050	149.8072	-2.090218
36.28216	149.8065	-2.091694
36.33383	149.8070	-2.092752
36.38550	149.8068	-2.093467
36.43716	149.8072	-2.094543
36.49050	149.8056	-2.094938
36.54050	149.8064	-2.095413
36.59384	149.8061	-2.095594
36.64383	149.8061	-2.095585
36.69717	149.8052	-2.095243
36.74716	149.8049	-2.095053
36.80050	149.8047	-2.094932
36.85050	149.8046	-2.095169
36.90383	149.8047	-2.095194
36.95383	149.8050	-2.095283
37.00716	149.8052	-2.096066
37.05883	149.8051	-2.097235
37.11050	149.8054	-2.098674
37.16217	149.8057	-2.100281
37.21383	149.8057	-2.101804
37.26550	149.8054	-2.103822
37.31716	149.8058	-2.105334
37.36883	149.8061	-2.106592
37.42050	149.8056	-2.107832
37.47383	149.8057	-2.108705
37.52383	149.8054	-2.108960
37.57717	149.8051	-2.109076
37.62717	149.8054	-2.109400
37.68050	149.8050	-2.109682
37.73050	149.8049	-2.110052
37.78383	149.8052	-2.110353
37.83383	149.8049	-2.110930
37.88716	149.8044	-2.111756
37.93716	149.8057	-2.112584
37.99050	149.8043	-2.113316
38.04217	149.8050	-2.114002
38.09384	149.8050	-2.114668
38.14550	149.8050	-2.115490
38.19717	149.8051	-2.116175
38.24883	149.8056	-2.116754
38.30050	149.8053	-2.117467
38.35383	149.8050	-2.118316
38.40383	149.8051	-2.118730
38.45716	149.8050	-2.118908
38.50716	149.8056	-2.118972
38.56050	149.8053	-2.119199
38.61050	149.8050	-2.119104
38.66383	149.8047	-2.119202
38.71383	149.8053	-2.119494
38.76716	149.8045	-2.119774
38.81716	149.8048	-2.120240
38.87050	149.8043	-2.120208
38.92216	149.8044	-2.120146
38.97383	149.8039	-2.120444
39.02550	149.8040	-2.120818
39.07717	149.8040	-2.120886
39.12883	149.8042	-2.121289
39.18050	149.8032	-2.122036
39.23216	149.8039	-2.122650
39.28383	149.8040	-2.123303
39.33716	149.8048	-2.123749
39.38716	149.8042	-2.124498
39.44050	149.8036	-2.125290
39.49050	149.8045	-2.126114
39.54383	149.8038	-2.126980
39.59384	149.8038	-2.127334
39.64717	149.8044	-2.127935
39.69717	149.8046	-2.128853
39.75050	149.8046	-2.129677
39.80050	149.8039	-2.130430
39.85383	149.8036	-2.130893
39.90550	149.8046	-2.131802
39.95716	149.8046	-2.132412
40.00883	149.8041	-2.132317
40.06050	149.8045	-2.132605
40.11217	149.8046	-2.132963
40.16383	149.8041	-2.132892
40.21716	149.8034	-2.132856
40.26716	149.8030	-2.132968
40.32050	149.8035	-2.132801
40.37050	149.8036	-2.132328
40.42383	149.8036	-2.132240
40.47383	149.8033	-2.132438
40.52716	149.8032	-2.132948
40.57717	149.8040	-2.133438
40.63050	149.8035	-2.134322
40.68050	149.8030	-2.135120
40.73383	149.8041	-2.135328
40.78550	149.8033	-2.135729
40.83716	149.8035	-2.136254
40.88883	149.8035	-2.136535
40.94050	149.8034	-2.136830
40.99216	149.8035	-2.137152
41.04383	149.8026	-2.137120
41.09550	149.8032	-2.137396
41.14717	149.8035	-2.137380
41.20050	149.8032	-2.137492
41.25050	149.8020	-2.137544
41.30383	149.8025	-2.137742
41.35383	149.8032	-2.137736
41.40717	149.8027	-2.138100
41.45717	149.8022	-2.138471
41.51050	149.8022	-2.138882
41.56050	149.8033	-2.139185
41.61383	149.8032	-2.139660
41.66383	149.8036	-2.140264
41.71717	149.8032	-2.140822
41.76883	149.8037	-2.141195
41.82050	149.8032	-2.141570
41.87216	149.8042	-2.142125
41.92383	149.8027	-2.142348
41.97550	149.8036	-2.142852
42.02716	149.8031	-2.143226
42.08050	149.8036	-2.143047
42.13050	149.8025	-2.142920
42.18383	149.8031	-2.142954
42.23383	149.8037	-2.142622
42.28717	149.8036	-2.142304
42.33716	149.8036	-2.142422
42.39050	149.8034	-2.142691
42.44050	149.8035	-2.143192
42.49383	149.8040	-2.143627
42.54383	149.8035	-2.144192
42.59716	149.8024	-2.144796
42.64883	149.8028	-2.145033
42.70050	149.8026	-2.145560
42.75217	149.8035	-2.145965
42.80383	149.8029	-2.146192
42.85550	149.8032	-2.146803
42.90717	149.8044	-2.147720
42.95883	149.8036	-2.148378
43.01050	149.8041	-2.148645
43.06383	149.8034	-2.149133
43.11383	149.8038	-2.149108
43.16716	149.8035	-2.149313
43.21717	149.8032	-2.149096
43.26717	149.8036	-2.149025
43.32050	149.9595	-2.080405
43.37050	150.4467	-3.367482
43.42383	151.1009	-6.161868
43.47383	151.7986	-9.180780
43.52716	152.6021	-12.31423
43.57717	153.4016	-14.96452
43.63050	154.2906	-17.42365
43.68050	155.1536	-19.36807
43.73383	156.0977	-21.09380
43.78550	157.0332	-22.48374
43.83716	157.9834	-23.65958
43.88883	158.9465	-24.65308
43.94050	159.9203	-25.49930
43.99216	160.9032	-26.18619
44.04383	161.8942	-26.81404
44.09716	162.9197	-27.37866
44.14717	163.8885	-27.83865
44.20050	164.9264	-28.26869
44.25050	165.9019	-28.63680
44.30383	166.9448	-29.01072
44.35383	167.9235	-29.34225
44.40717	168.9703	-29.65805
44.45717	169.9544	-29.92361
44.51050	171.0041	-30.23063
44.56050	171.9898	-30.49271
44.61383	173.0429	-30.74746
44.66550	174.0620	-31.01400
44.71717	175.0825	-31.25463
44.76883	176.1036	-31.48442
44.82050	177.1245	-31.75082
44.87216	178.1450	-31.98770
44.92383	179.1676	-32.23556
44.97550	180.1881	-32.50466
45.02716	181.2110	-32.74047
45.08050	182.2638	-33.04856
45.13050	183.2518	-33.30650
45.18383	184.3070	-33.61587
45.23383	185.2944	-33.90820
45.28717	186.3479	-34.20522
45.33716	187.3342	-34.52019
45.39050	188.3864	-34.83825
45.44050	189.3738	-35.15492
45.49383	190.4244	-35.54668
45.54383	191.4111	-35.87176
45.59716	192.4602	-36.29484
45.64883	193.4771	-36.66847
45.70050	194.4936	-37.09197
45.75217	195.5083	-37.53820
45.80383	196.5226	-37.97895
45.85550	197.5359	-38.47258
45.90717	198.5477	-38.99969
45.96050	199.5906	-39.54875
46.01050	200.5661	-40.14884
46.06383	201.6041	-40.82139
46.11383	202.5781	-41.44632
46.16716	203.6139	-42.18976
46.21717	204.5828	-42.91498
46.27050	205.6139	-43.75633
46.32050	206.5776	-44.60286
46.37383	207.6023	-45.58602
46.42383	208.5598	-46.59104
46.47717	209.5781	-47.74669
46.52883	210.5572	-48.97898
46.58050	211.5313	-50.37478
46.63217	212.4961	-51.97903
46.68383	213.4504	-53.87890
46.73550	214.3869	-56.16480
46.78717	215.3033	-58.94195
46.83883	216.1961	-62.27890
46.89050	217.0625	-66.15665
46.94383	217.9334	-70.63384
46.99383	218.7359	-75.13087
47.04716	219.5822	-79.98241
47.09716	220.3850	-84.25145
47.15050	221.2660	-88.10142
47.20050	222.1361	-90.62359
47.25383	223.1382	-91.48638
47.30383	224.1576	-90.59712
47.35717	225.3113	-88.36832
47.40717	226.4400	-85.32938
47.46050	227.6852	-81.20082
47.51216	228.9304	-76.37085
47.56383	230.2158	-70.59392
47.61550	231.5332	-64.37242
47.66716	232.8341	-58.84451
47.71884	234.0924	-54.30511
47.77050	235.3081	-50.66800
47.82383	236.5259	-47.66102
47.87383	237.6380	-45.42790
47.92717	238.8008	-43.52514
47.97717	239.8730	-42.11676
48.03050	241.0003	-40.93358
48.08050	242.0461	-40.05772
48.13383	243.1520	-39.31606
48.18383	244.1816	-38.78086
48.23717	245.2737	-38.31291
48.28717	246.2930	-37.97961
48.34050	247.3762	-37.69086
48.39217	248.4219	-37.47250
48.44383	249.4655	-37.30092
48.49550	250.5070	-37.16717
48.54716	251.5475	-37.08552
48.59883	252.5859	-37.01835
48.65050	253.6250	-36.97698
48.70216	254.6618	-36.93944
48.75383	255.6978	-36.92630
48.80717	256.7672	-36.92322
48.85717	257.7682	-36.92310
48.91050	258.8369	-36.92666
48.96050	259.8378	-36.95322
49.01383	260.9055	-36.98791
49.06383	261.9056	-37.02890
49.11716	262.9730	-37.07984
49.16716	263.9724	-37.12301
49.22050	265.0387	-37.18066
49.27050	266.0389	-37.23372
49.32383	267.1055	-37.29035
49.37550	268.1390	-37.34067
49.42717	269.1717	-37.39119
49.47883	270.2056	-37.45002
49.53050	271.2382	-37.49756
49.58217	272.2701	-37.53995
49.63383	273.3034	-37.59264
49.68716	274.3706	-37.61936
49.73717	275.3697	-37.67963
49.78717	276.3424	-37.68866
49.84050	276.7604	-36.65895
49.89050	276.6360	-31.58551
49.94383	276.2789	-24.30222
49.99383	275.8030	-17.28514
50.04716	275.1876	-10.48916
50.09716	274.5305	-5.049938
50.15050	273.7646	-0.1482146
50.20050	272.9968	3.660632
50.25383	272.1387	7.025925
50.30550	271.2703	9.711491
50.35717	270.3764	11.93324
50.40883	269.4612	13.77824
50.46050	268.5256	15.23786
50.51216	267.5746	16.52719
50.56383	266.6144	17.64253
50.61550	265.6433	18.58462
50.66716	264.6633	19.37045
50.72050	263.6428	20.05582
50.77050	262.6801	20.60017
50.82383	261.6498	21.09434
50.87383	260.6782	21.49020
50.92717	259.6372	21.85327
50.97717	258.6606	22.15033
51.03050	257.6140	22.42480
51.08050	256.6327	22.65201
51.13383	255.5825	22.85593
51.18383	254.5976	23.03620
51.23717	253.5461	23.21285
51.28883	252.5252	23.36060
51.34050	251.5037	23.49609
51.39216	250.4820	23.61556
51.44384	249.4587	23.72875
51.49550	248.4358	23.83429
51.54717	247.4106	23.92994
51.60050	246.3537	24.03872
51.65050	245.3621	24.10094
51.70383	244.3038	24.17805
51.75383	243.3110	24.23724
51.80717	242.2516	24.28694
51.85717	241.2590	24.34038
51.91050	240.2000	24.39960
51.96050	239.2054	24.43884
52.01383	238.1453	24.50103
52.06383	237.1496	24.53414
52.11716	236.0900	24.58246
52.16883	235.0614	24.62313
52.22050	234.0339	24.64142
52.27217	233.0062	24.67367
52.32383	231.9794	24.70108
52.37550	230.9506	24.72414
52.42717	229.9228	24.76230
52.47883	228.8950	24.77671
52.53050	227.8668	24.81492
52.58383	226.8050	24.85925
52.63383	225.8099	24.87230
52.68716	224.7486	24.91934
52.73717	223.7532	24.93484
52.79050	222.6920	24.96734
52.84050	221.6972	24.99738
52.89384	220.6347	25.00996
52.94384	219.6390	25.04150
52.99717	218.5762	25.06650
53.04717	217.5815	25.08580
53.10050	216.5184	25.10505
53.15217	215.4903	25.11338
53.20383	214.4598	25.13513
53.25550	213.4315	25.14294
53.30717	212.4030	25.15704
53.35883	211.3744	25.17457
53.41050	210.3457	25.18528
53.46382	209.2841	25.21005
53.51382	208.2871	25.21654
53.56716	207.2246	25.23616
53.61716	206.2287	25.24561
53.67050	205.1662	25.26148
53.72050	204.1711	25.27600
53.77383	203.1076	25.28221
53.82383	202.1124	25.29512
53.87717	201.0498	25.29937
53.92717	200.0538	25.31976
53.98050	198.9918	25.32552
54.03217	197.9625	25.34335
54.08383	196.9324	25.35041
54.13550	195.9032	25.36121
54.18716	194.8745	25.36948
54.23882	193.8455	25.37532
54.29050	192.8166	25.39664
54.34217	191.7871	25.40254
54.39384	190.7582	25.41930
54.44717	189.6949	25.43073
54.49717	188.6979	25.43436
54.55050	187.6364	25.44840
54.60050	186.6402	25.45152
54.65383	185.5781	25.46902
54.70383	184.5815	25.47444
54.75717	183.5183	25.47852
54.80717	182.5232	25.49032
54.86050	181.4593	25.49409
54.91050	180.4628	25.50592
54.96382	179.4000	25.51239
55.01550	178.3703	25.51784
55.06716	177.3418	25.54937
55.11882	176.3120	25.55503
55.17050	175.2840	25.58962
55.22217	174.2539	25.60890
55.27383	173.2231	25.61643
55.32717	172.1627	25.66715
55.37717	171.1659	25.67689
55.43050	170.1050	25.75504
55.48050	169.1100	25.81826
55.53383	168.0519	25.95574
55.58383	167.0638	26.14616
55.63716	166.0138	26.44707
55.68716	165.0362	26.90812
55.74050	164.0086	27.74224
55.79050	163.0638	28.98506
55.84384	162.0919	31.16390
55.89550	161.1976	34.26558
55.94717	160.3554	38.46590
55.99883	159.5625	43.52270
56.05050	158.7919	48.82812
56.10217	158.0138	53.72143
56.15383	157.2012	57.75535
56.20550	156.3347	60.59052
56.25717	155.4050	62.10844
56.31050	154.3805	62.34968
56.36050	153.3631	61.52105
56.41382	152.2275	59.64019
56.46382	151.1219	57.18704
56.51716	149.9153	54.15637
56.56716	148.7732	51.15525
56.62050	147.5503	48.00742
56.67050	146.4129	45.25464
56.72382	145.2141	42.62300
56.77383	144.1044	40.46044
56.82717	142.9364	38.46720
56.87883	141.8195	36.81510
56.93050	140.7143	35.40316
56.98217	139.6206	34.18615
57.03383	138.5356	33.14939
57.08550	137.4570	32.26453
57.13716	136.3874	31.49727
57.19050	135.2882	30.82518
57.24050	134.2612	30.27888
57.29382	133.1700	29.76650
57.34384	132.1510	29.35670
57.39717	131.0676	28.97364
57.44717	130.0532	28.65396
57.50050	128.9728	28.35233
57.55050	127.9619	28.09730
57.60383	126.8853	27.85156
57.65383	125.8782	27.64557
57.70717	124.8037	27.43870
57.75883	123.7636	27.24241
57.81050	122.7238	27.05490
57.86217	121.6850	26.89278
57.91382	120.6476	26.73756
57.96550	119.6104	26.59321
58.01716	118.5735	26.46956
58.06884	117.5367	26.35475
58.12050	116.5010	26.24754
58.17383	115.4317	26.14033
58.22382	114.4299	26.04306
58.27717	113.3608	25.94476
58.32717	112.3590	25.85662
58.38050	111.2902	25.75708
58.43050	110.2890	25.66555
58.48383	109.2198	25.57766
58.53383	108.2191	25.49190
58.58716	107.1510	25.41050
58.63716	106.1504	25.32452
58.69050	105.0812	25.23538
58.74216	104.0465	25.16663
58.79382	103.0128	25.08792
58.84550	101.9783	25.01360
58.89717	100.9436	24.93865
58.94883	99.90949	24.87194
59.00050	98.87460	24.79760
59.05383	97.80795	24.72344
59.10383	96.80705	24.66190
59.15717	95.74090	24.58752
59.20717	94.74051	24.53041
59.26050	93.67219	24.46019
59.31050	92.67195	24.40196
59.36382	91.60391	24.32230
59.41382	90.60253	24.27271
59.46717	89.53563	24.18682
59.51716	88.53445	24.11828
59.57050	87.46762	24.04369
59.62217	86.43374	23.97399
59.67383	85.40055	23.90402
59.72550	84.36751	23.83291
59.77717	83.33322	23.77600
59.82883	82.30005	23.71540
59.88050	81.26680	23.65184
59.93217	80.23340	23.58415
59.98383	79.19921	23.51884
60.03716	78.13165	23.45679
60.08716	77.13193	23.38953
60.14050	76.06509	23.32552
60.19050	75.06372	23.26669
60.24382	73.99650	23.20125
60.29382	72.99632	23.14213
60.34716	71.92925	23.07565
60.39717	70.92759	23.01392
60.45050	69.86100	22.95032
60.50050	68.85904	22.88626
60.55383	67.79270	22.81568
60.60550	66.75932	22.74722
60.65717	65.72511	22.67999
60.70883	64.69175	22.61774
60.76050	63.65740	22.55179
60.81216	62.62354	22.48239
60.86382	61.58888	22.40440
60.91716	60.52087	22.32473
60.96717	59.51994	22.24143
61.02050	58.45022	22.14961
61.07050	57.44978	22.06199
61.12383	56.38042	21.97275
61.17383	55.37876	21.89732
61.22717	54.31115	21.81870
61.27717	53.30970	21.74168
61.33050	52.24140	21.65314
61.38050	51.24024	21.57434
61.43383	50.17210	21.49128
61.48550	49.13676	21.41702
61.53716	48.10178	21.34728
61.58882	47.06750	21.27141
61.64050	46.03271	21.20310
61.69216	44.99796	21.12813
61.74382	43.96288	21.05725
61.79550	42.92878	20.98797
61.84716	41.89366	20.89620
61.90050	40.82430	20.79291
61.95050	39.82168	20.70268
62.00383	38.75218	20.60811
62.05383	37.74960	20.51170
62.10717	36.68048	20.40816
62.15717	35.67802	20.31336
62.21050	34.60718	20.21384
62.26050	33.60448	20.11600
62.31382	32.53488	20.01032
62.36382	31.53306	19.90684
62.41716	30.46353	19.80266
62.46884	29.42656	19.70959
62.52050	28.39127	19.60646
62.57217	27.35389	19.50282
62.62383	26.31643	19.39713
62.67550	25.27896	19.28558
62.72717	24.24292	19.17402
62.77550	23.27624	19.04910
62.82717	22.66600	18.68080
62.88050	22.68281	15.83527
62.93050	22.92925	11.84581
62.98383	23.38396	7.245778
63.03383	23.93008	3.161850
63.08716	24.61280	-0.6764512
63.13716	25.32442	-3.730715
63.19050	26.14465	-6.434846
63.24050	26.95734	-8.512139
63.29382	27.86095	-10.32439
63.34384	28.73657	-11.71112
63.39717	29.69404	-12.91976
63.44883	30.63899	-13.87490
63.50050	31.59883	-14.66926
63.55217	32.56840	-15.33894
63.60383	33.54919	-15.89678
63.65550	34.53682	-16.37664
63.70717	35.53076	-16.79392
63.75883	36.53150	-17.15283
63.81050	37.53544	-17.47214
63.86384	38.57526	-17.75985
63.91382	39.55385	-18.00112
63.96717	40.59984	-18.23405
64.01716	41.58243	-18.42697
64.07050	42.63238	-18.62052
64.12050	43.61902	-18.78754
64.17383	44.67154	-18.95146
64.22384	45.66008	-19.09926
64.27717	46.71519	-19.24862
64.32718	47.70563	-19.38645
64.38050	48.76203	-19.52928
64.43218	49.78692	-19.65904
64.48383	50.81269	-19.78612
64.53550	51.83820	-19.91489
64.58716	52.86394	-20.03844
64.63884	53.89135	-20.16056
64.69050	54.91775	-20.26993
64.74384	55.97877	-20.39274
64.79384	56.97218	-20.50078
64.84717	58.03384	-20.62348
64.89717	59.02912	-20.73464
64.95050	60.09155	-20.84563
65.00050	61.08580	-20.95050
65.05383	62.14875	-21.06747
65.10383	63.14413	-21.17579
65.15718	64.20630	-21.28860
65.20717	65.20270	-21.39048
65.26050	66.26548	-21.49984
65.31216	67.29460	-21.60489
65.36384	68.32450	-21.70614
65.41550	69.35455	-21.80965
65.46717	70.38455	-21.91082
65.51882	71.41398	-22.01363
65.57050	72.44344	-22.11641
65.62218	73.47306	-22.21867
65.67384	74.50269	-22.31969
65.72718	75.56528	-22.42470
65.77718	76.56357	-22.52332
65.83050	77.62588	-22.62945
65.88050	78.62305	-22.72890
65.93384	79.68574	-22.83662
65.98384	80.68324	-22.93518
66.03718	81.74759	-23.04609
66.08716	82.74328	-23.14580
66.14050	83.80744	-23.25151
66.19050	84.80520	-23.35120
66.24384	85.86785	-23.46550
66.29550	86.89864	-23.56832
66.34718	87.92805	-23.67701
66.39884	88.95881	-23.78492
66.45050	89.98835	-23.89546
66.50218	91.01952	-24.00816
66.55384	92.05004	-24.11701
66.60718	93.11256	-24.22226
66.65718	94.10946	-24.32868
66.71050	95.17334	-24.43880
66.76050	96.17022	-24.53888
66.81384	97.23380	-24.64732
66.86384	98.23012	-24.74136
66.91718	99.29428	-24.85554
66.96718	100.2909	-24.95370
67.02050	101.3550	-25.05645
67.07050	102.3526	-25.15652
67.12384	103.4160	-25.25900
67.17550	104.4463	-25.35280
67.22718	105.4764	-25.46042
67.27884	106.5063	-25.56385
67.33050	107.5358	-25.68110
67.38218	108.5666	-25.78979
67.43384	109.5961	-25.89636
67.48550	110.6252	-26.01597
67.53718	111.6546	-26.13470
67.59050	112.7171	-26.25189
67.64050	113.7138	-26.36045
67.69384	114.7763	-26.47550
67.74384	115.7735	-26.58924
67.79718	116.8363	-26.70923
67.84718	117.8326	-26.81398
67.90050	118.8964	-26.93524
67.95050	119.8926	-27.04892
68.00384	120.9564	-27.16885
68.05384	121.9528	-27.28330
68.10718	123.0158	-27.42048
68.15884	124.0453	-27.54433
68.21050	125.0750	-27.66059
68.26218	126.1051	-27.78297
68.31384	127.1345	-27.90190
68.36550	128.1635	-28.03171
68.41718	129.1934	-28.15262
68.47050	130.2557	-28.26844
68.52050	131.2526	-28.39146
68.57384	132.3152	-28.54018
68.62384	133.3094	-28.66000
68.67718	134.3725	-28.80559
68.72718	135.3677	-28.94090
68.78050	136.4300	-29.09248
68.83050	137.4245	-29.24448
68.88384	138.4871	-29.39277
68.93384	139.4827	-29.53619
68.98718	140.5439	-29.68824
69.03882	141.5734	-29.83341
69.09050	142.6020	-29.98126
69.14216	143.6304	-30.12818
69.19384	144.6585	-30.27396
69.24550	145.6867	-30.42328
69.29718	146.7138	-30.57458
69.34882	147.7418	-30.73760
69.40050	148.7686	-30.89174
69.45384	149.8303	-31.05783
69.50384	150.8250	-31.21209
69.55718	151.8848	-31.38396
69.60718	152.8789	-31.54797
69.66050	153.9401	-31.72978
69.71050	154.9353	-31.89722
69.76384	155.9952	-32.07966
69.81384	156.9888	-32.25283
69.86718	158.0488	-32.43992
69.91718	159.0432	-32.61826
69.97050	160.1034	-32.80325
70.02218	161.1318	-32.97694
70.07384	162.1609	-33.15062
70.12550	163.1881	-33.30456
70.17718	164.2170	-33.44507
70.22884	165.2466	-33.58011
70.28050	166.2758	-33.68576
70.33384	167.3406	-33.78960
70.38384	168.3393	-33.87458
70.43718	169.4047	-33.95452
70.48718	170.4039	-34.02480
70.54050	171.4688	-34.10903
70.59050	172.4681	-34.19072
70.64384	173.5326	-34.28870
70.69384	174.5297	-34.38348
70.74718	175.5939	-34.50309
70.79718	176.5899	-34.63643
70.85050	177.6504	-34.78755
70.90218	178.6788	-34.95306
70.95384	179.7058	-35.15152
71.00550	180.7311	-35.36418
71.05718	181.7554	-35.60486
71.10884	182.7788	-35.87510
71.16050	183.8014	-36.16989
71.21218	184.8231	-36.50438
71.26384	185.8416	-36.86408
71.31718	186.8929	-37.27653
71.36718	187.8754	-37.71418
71.42050	188.9205	-38.23274
71.47050	189.8990	-38.76453
71.52384	190.9392	-39.41536
71.57384	191.9120	-40.07666
71.62718	192.9448	-40.85011
71.67718	193.9121	-41.62355
71.73050	194.9429	-42.47168
71.78050	195.9056	-43.30000
71.83384	196.9326	-44.21632
71.88550	197.9263	-45.13410
71.93718	198.9179	-46.08602
71.98882	199.9079	-47.08762
72.04050	200.8950	-48.16710
72.09216	201.8794	-49.31716
72.14384	202.8596	-50.54969
72.19718	203.8685	-51.88044
72.24718	204.8128	-53.16030
72.30050	205.8194	-54.50546
72.35050	206.7678	-55.64829
72.40384	207.7891	-56.59230
72.45384	208.7648	-57.01190
72.50718	209.8387	-56.67320
72.55718	210.8839	-55.43726
72.61050	212.0414	-53.26075
72.66050	213.1534	-50.73332
72.71384	214.3552	-47.84854
72.76550	215.5172	-45.19106
72.81718	216.6644	-42.91558
72.86884	217.7925	-41.06148
72.92050	218.9026	-39.57786
72.97218	219.9970	-38.39076
73.02384	221.0797	-37.47148
73.07550	222.1515	-36.74630
73.12718	223.2161	-36.17954
73.18050	224.3072	-35.72806
73.23050	225.3264	-35.39392
73.28384	226.4085	-35.12464
73.33384	227.4204	-34.94137
73.38718	228.4972	-34.78828
73.43718	229.5046	-34.69406
73.49050	230.5778	-34.62985
73.54050	231.5806	-34.59579
73.59384	232.6506	-34.58167
73.64384	233.6519	-34.58043
73.69718	234.7203	-34.58376
73.74884	235.7555	-34.60359
73.80050	236.7896	-34.63687
73.85218	237.8237	-34.67161
73.90384	238.8571	-34.72068
73.95550	239.8903	-34.76968
74.00718	240.9242	-34.83055
74.06050	241.9910	-34.89288
74.11050	242.9915	-34.95653
74.16382	244.0585	-35.02188
74.21384	245.0584	-35.07696
74.26716	246.1241	-35.13210
74.31718	247.1242	-35.19506
74.37050	248.1908	-35.25110
74.42050	249.1904	-35.30418
74.47384	250.2569	-35.35991
74.52384	251.2558	-35.42216
74.57718	252.3215	-35.48345
74.62884	253.3545	-35.54697
74.68050	254.3869	-35.60606
74.73218	255.4190	-35.66888
74.78384	256.4518	-35.74778
74.83550	257.4837	-35.81902
74.88718	258.5152	-35.88907
74.93884	259.5474	-35.97150
74.99050	260.5792	-36.05368
75.04384	261.6442	-36.12783
75.09384	262.6436	-36.20763
75.14718	263.7080	-36.29861
75.19718	264.7066	-36.37969
75.25050	265.7722	-36.47346
75.30050	266.7708	-36.56811
75.35384	267.8358	-36.65594
75.40384	268.8347	-36.75119
75.45718	269.8990	-36.86254
75.50718	270.8960	-36.96240
75.56050	271.9589	-37.07288
-2.000000	5.000000	0.0000000