File: 1-C1(0.6mol%)+C20(0.6mol%)/matlab/150-1.txt
CLOSED
Version	1.0
Language	English
Mode	Standard
Run	4
RunSerial	11854
Instrument	DSC Q2000 V24.11 Build 124
Module	DSC Standard Cell RC
Operator	Jing
File	\\AE520-1454\TA\Data\DSC\UQ Composites\Nan\C1(5.5)+C20P(3)+CL(HotplateMixtureAB)\150-1
ProcName	Ramp
InstSerial	2000-0883
AutoSerial	1293
Sample	Iso-150-1
Size	50.4000	mg
PanMass	Not available
PanResist	Automatic Automatic  K/W
PanFactor	Default Default
Method	Ramp
Comment
Xcomment	Pan: Tzero Aluminum Hermetic
Xcomment	Gas1: Nitrogen 50.0 ml/min
Xcomment	Gas2: Nitrogen 50.0 ml/min
Text
Exotherm	UP
Kcell	1.05230
Cpconst	Standard: 0.938
Calib	-38.6961
TempCal	1	pts	157.46	156.60
TzeroDt	-87.6168 -0.0009 -1.4231
TzeroDtz	-87.6168 0.0057 6.9570
InstCalFile	Tzero: \\Ae520-1454\ta\Data\DSC\Calibration\2017\CALIBRATION\1562_RCS (90)_05_18_2017 10_50_44.TZR
InstCalFile	Baseline: \\Ae520-1454\ta\Data\DSC\Calibration\2017\2017-05-17_Calibration.001
InstCalFile	Sapphire: \\Ae520-1454\ta\Data\DSC\Calibration\2017\2017-05-17_Saphire.001
InstCalDate	Tzero 2017-05-18 Time 10:50:44
TempRange	-87.39 to 398.39 °C at 10.00 °C/min Heat Only
AutoZero	Delta T Offset 0.000 uV
AutoZero	Delta T0 Offset 0.000 uV
MultiptCal	0
MultiPtDesc	0) Not set
AutoCellConst	Calibration Date 2017-05-18 16:59:28
Controls	Gas 1  Event Off  Sampling 0.2
Cell#	RC-01562
CoolingUnit	RCS (90)
SelHeatFlow	Heat Flow T4 (mW)
AutoLidII	Installed
AutoAnalysis	Off
MacroFile
Nsig	3
Sig1	Time (min)
Sig2	Temperature (°C)
Sig3	Heat Flow (mW)
Date	2017-06-20
Time	20:34:37
OrgMethod	1: Equilibrate at 20.00 °C
OrgMethod	2: Ramp 40.00 °C/min to 150.00 °C
OrgMethod	3: Mark end of cycle 1
OrgMethod	4: Isothermal for 40.00 min
OrgMethod	5: Mark end of cycle 2
OrgMethod	6: Ramp 20.00 °C/min to 280.00 °C
OrgMethod	7: Mark end of cycle 3
OrgMethod	8: Ramp 20.00 °C/min to 20.00 °C
OrgMethod	9: Mark end of cycle 4
OrgMethod	10: Ramp 20.00 °C/min to 280.00 °C
OrgMethod	11: Mark end of cycle 5
OrgFile	C:\Users\jarra\Desktop\DSC\1-C1(0.6mol%)+C20(0.6mol%)\150-1.001
StartOfData
4.99994E-4	20.10796	0.5657032
0.05383332	20.21975	0.6660981
0.1055000	21.07590	.006590520
0.1571666	22.30137	-3.368762
0.2088333	23.69934	-7.784818
0.2605000	25.22415	-12.47778
0.3121666	26.83864	-16.93437
0.3638334	28.52768	-20.95402
0.4171667	30.33220	-24.55815
0.4671667	32.07128	-27.46270
0.5205000	33.96828	-30.09837
0.5705000	35.77856	-32.19366
0.6238334	37.73609	-34.12246
0.6738334	39.59355	-35.68020
0.7271668	41.59206	-37.14382
0.7771668	43.47640	-38.44551
0.8305000	45.48824	-39.91390
0.8804999	47.37666	-41.26526
0.9338332	49.40389	-42.47692
0.9854999	51.38306	-43.46778
1.037167	53.37093	-44.40819
1.088833	55.35787	-45.53194
1.140500	57.33096	-47.00846
1.192167	59.29170	-48.67932
1.243833	61.25334	-50.30407
1.295500	63.21884	-51.94448
1.347166	65.17563	-53.93235
1.400500	67.15660	-56.94902
1.450500	68.93921	-61.50611
1.503833	70.69358	-69.55774
1.553833	72.16772	-80.06462
1.607167	73.61934	-92.99043
1.657167	74.94599	-105.2166
1.710500	76.36349	-118.3163
1.760500	77.70660	-130.2019
1.813834	79.19934	-141.5973
1.863834	80.54395	-154.2721
1.917167	82.02179	-166.9509
1.968833	83.53064	-174.8930
2.020500	85.42922	-175.9734
2.072166	87.58630	-174.1109
2.123834	89.69178	-174.7772
2.175500	91.74059	-175.5909
2.227167	93.82722	-175.3678
2.280500	96.09295	-172.2985
2.330500	98.41902	-164.7911
2.383833	101.2750	-149.9839
2.433833	103.9760	-138.0150
2.487166	106.7461	-127.3798
2.537166	109.2477	-119.0364
2.590500	111.8277	-111.6402
2.640500	114.1799	-105.8709
2.693833	116.6270	-100.7774
2.743833	118.8708	-96.83391
2.797167	121.2202	-93.46295
2.848834	123.4574	-90.87187
2.900500	125.6654	-88.78038
2.952166	127.8471	-87.11053
3.003833	130.0072	-85.81116
3.055500	132.1509	-84.82201
3.107167	134.2796	-84.08130
3.158834	136.3956	-83.58880
3.210500	138.5026	-83.29556
3.260500	140.5306	-83.18664
3.310500	142.3828	-83.42687
3.363834	143.5714	-81.52382
3.413833	144.3956	-76.16680
3.467166	145.1054	-69.16816
3.518833	145.6756	-62.19288
3.570500	146.1612	-55.69090
3.622166	146.5718	-49.91513
3.673834	146.9226	-44.89260
3.725500	147.2219	-40.58060
3.777167	147.4792	-36.89985
3.828833	147.6986	-33.75178
3.880500	147.8884	-31.07195
3.933833	148.0560	-28.71367
3.983833	148.1931	-26.81943
4.037167	148.3172	-25.09074
4.087167	148.4203	-23.69795
4.140500	148.5140	-22.41934
4.190500	148.5902	-21.38127
4.243834	148.6622	-20.42586
4.293833	148.7210	-19.64730
4.347166	148.7751	-18.92260
4.397167	148.8206	-18.32741
4.450500	148.8622	-17.77288
4.502167	148.8985	-17.29900
4.553834	148.9298	-16.87986
4.605500	148.9582	-16.50796
4.657166	148.9839	-16.16948
4.708834	149.0068	-15.86438
4.760500	149.0277	-15.58886
4.813834	149.0469	-15.32360
4.863834	149.0634	-15.09564
4.917167	149.0802	-14.86643
4.967167	149.0937	-14.66840
5.020500	149.1081	-14.46319
5.070500	149.1202	-14.28416
5.123833	149.1336	-14.09561
5.173834	149.1452	-13.92276
5.227167	149.1561	-13.74615
5.277168	149.1670	-13.58426
5.330500	149.1779	-13.41175
5.382168	149.1882	-13.25216
5.433832	149.1981	-13.09016
5.485500	149.2071	-12.92645
5.537168	149.2159	-12.76543
5.588832	149.2261	-12.60749
5.640500	149.2354	-12.44749
5.692166	149.2443	-12.28072
5.743834	149.2539	-12.11246
5.797168	149.2638	-11.94110
5.847168	149.2728	-11.77231
5.900500	149.2821	-11.59158
5.950500	149.2922	-11.41207
6.003834	149.3019	-11.22403
6.053834	149.3126	-11.03656
6.107168	149.3229	-10.83402
6.157166	149.3336	-10.63439
6.210500	149.3451	-10.41048
6.260500	149.3556	-10.18806
6.313832	149.3690	-9.937382
6.365500	149.3830	-9.666074
6.417168	149.3982	-9.355949
6.468832	149.4150	-8.999488
6.520500	149.4348	-8.596328
6.572168	149.4573	-8.129298
6.623834	149.4831	-7.595880
6.677168	149.5139	-6.960309
6.727168	149.5451	-6.319296
6.780500	149.5794	-5.619581
6.830500	149.6121	-4.983525
6.883832	149.6446	-4.360488
6.933832	149.6721	-3.830668
6.987168	149.6991	-3.318110
7.037168	149.7223	-2.884928
7.090500	149.7435	-2.470481
7.140500	149.7626	-2.116306
7.193832	149.7804	-1.784175
7.245500	149.7955	-1.486304
7.297168	149.8100	-1.220742
7.348832	149.8229	-0.9817389
7.400500	149.8341	-0.7661366
7.452168	149.8445	-0.5698824
7.503832	149.8538	-0.3937624
7.555500	149.8622	-0.2262337
7.607168	149.8715	-.07360237
7.660500	149.8789	0.06975400
7.710500	149.8846	0.1977406
7.763834	149.8930	0.3275722
7.813834	149.8983	0.4442162
7.867166	149.9039	0.5606200
7.917168	149.9093	0.6657449
7.970500	149.9156	0.7730206
8.020500	149.9206	0.8667820
8.073834	149.9262	0.9676609
8.123834	149.9302	1.056731
8.177168	149.9356	1.155054
8.228834	149.9406	1.244848
8.280500	149.9453	1.331187
8.332168	149.9494	1.420462
8.383832	149.9547	1.507797
8.435499	149.9587	1.594160
8.487168	149.9629	1.679171
8.540500	149.9689	1.769755
8.590500	149.9727	1.852762
8.643832	149.9763	1.943933
8.693832	149.9812	2.024559
8.747168	149.9860	2.117958
8.797168	149.9900	2.201207
8.850500	149.9950	2.292410
8.900500	149.9990	2.382717
8.953834	150.0040	2.481452
9.003834	150.0088	2.573128
9.057168	150.0142	2.677699
9.108832	150.0195	2.791988
9.160499	150.0254	2.919136
9.212168	150.0325	3.054596
9.263832	150.0394	3.213826
9.315500	150.0494	3.392944
9.367166	150.0584	3.596089
9.418832	150.0689	3.819668
9.470500	150.0810	4.060512
9.523834	150.0944	4.325796
9.573834	150.1077	4.590347
9.627168	150.1210	4.882187
9.677168	150.1356	5.170398
9.730500	150.1521	5.479996
9.780500	150.1677	5.780666
9.833832	150.1829	6.104885
9.883832	150.1983	6.412601
9.937166	150.2141	6.736047
9.987168	150.2301	7.040300
10.04050	150.2464	7.364621
10.09217	150.2608	7.661374
10.14383	150.2764	7.955939
10.19550	150.2906	8.238207
10.24717	150.3043	8.509474
10.29883	150.3172	8.766352
10.35050	150.3297	9.011982
10.40383	150.3423	9.249254
10.45383	150.3522	9.455788
10.50717	150.3647	9.663285
10.55717	150.3728	9.840592
10.61050	150.3822	10.01727
10.66050	150.3893	10.16367
10.71383	150.3970	10.30837
10.76383	150.4039	10.42968
10.81716	150.4098	10.54556
10.86716	150.4147	10.63962
10.92050	150.4199	10.72699
10.97217	150.4233	10.80122
11.02383	150.4270	10.86218
11.07550	150.4305	10.91111
11.12717	150.4328	10.94732
11.17883	150.4340	10.97357
11.23050	150.4349	10.99414
11.28217	150.4362	11.00570
11.33383	150.4367	11.01121
11.38717	150.4363	11.01566
11.43716	150.4367	11.01809
11.49050	150.4363	11.01797
11.54050	150.4349	11.01408
11.59383	150.4344	11.00218
11.64383	150.4344	10.98110
11.69717	150.4330	10.94736
11.74717	150.4305	10.91814
11.80050	150.4292	10.87979
11.85050	150.4281	10.84614
11.90383	150.4259	10.80858
11.95550	150.4245	10.77108
12.00717	150.4224	10.73920
12.05884	150.4206	10.70158
12.11050	150.4192	10.66571
12.16217	150.4171	10.63077
12.21383	150.4156	10.59516
12.26717	150.4136	10.55631
12.31716	150.4114	10.52167
12.37050	150.4104	10.48493
12.42050	150.4084	10.45017
12.47383	150.4068	10.41417
12.52383	150.4047	10.38331
12.57717	150.4038	10.34063
12.62717	150.4010	10.30571
12.68050	150.3986	10.27086
12.73050	150.3976	10.23764
12.78383	150.3959	10.19749
12.83550	150.3940	10.16234
12.88717	150.3924	10.12556
12.93883	150.3902	10.09457
12.99050	150.3889	10.06145
13.04216	150.3871	10.03033
13.09383	150.3865	9.994576
13.14550	150.3839	9.961750
13.19717	150.3817	9.932739
13.25050	150.3808	9.900062
13.30050	150.3796	9.868847
13.35383	150.3782	9.835837
13.40383	150.3762	9.807791
13.45717	150.3754	9.776262
13.50717	150.3736	9.751156
13.56050	150.3719	9.720726
13.61050	150.3705	9.691379
13.66383	150.3691	9.658461
13.71383	150.3682	9.629902
13.76717	150.3662	9.600528
13.81884	150.3647	9.573462
13.87050	150.3631	9.545844
13.92217	150.3624	9.517960
13.97383	150.3605	9.487391
14.02550	150.3593	9.461747
14.07717	150.3575	9.430894
14.13050	150.3569	9.397668
14.18050	150.3546	9.369025
14.23383	150.3529	9.342625
14.28383	150.3513	9.311369
14.33717	150.3500	9.278106
14.38717	150.3492	9.245903
14.44050	150.3466	9.211855
14.49050	150.3458	9.177138
14.54384	150.3447	9.141891
14.59383	150.3428	9.110674
14.64717	150.3402	9.076871
14.69884	150.3396	9.043553
14.75050	150.3370	9.007086
14.80217	150.3361	8.970922
14.85383	150.3337	8.936211
14.90550	150.3328	8.902960
14.95717	150.3308	8.864813
15.00883	150.3290	8.826759
15.06050	150.3269	8.788289
15.11383	150.3252	8.747532
15.16383	150.3234	8.706501
15.21716	150.3210	8.666681
15.26717	150.3190	8.622619
15.32050	150.3162	8.582562
15.37050	150.3152	8.541337
15.42383	150.3124	8.501189
15.47383	150.3109	8.458439
15.52717	150.3077	8.410958
15.57717	150.3058	8.367632
15.63050	150.3042	8.314406
15.68217	150.3015	8.267701
15.73383	150.2991	8.220265
15.78550	150.2966	8.172302
15.83717	150.2940	8.122876
15.88883	150.2914	8.073843
15.94050	150.2893	8.023212
15.99383	150.2864	7.973097
16.04383	150.2845	7.925141
16.09717	150.2816	7.871460
16.14716	150.2805	7.823050
16.20050	150.2764	7.769331
16.25050	150.2741	7.719944
16.30383	150.2709	7.667078
16.35383	150.2696	7.615800
16.40716	150.2671	7.563653
16.45716	150.2642	7.515411
16.51050	150.2609	7.461556
16.56216	150.2590	7.411363
16.61383	150.2560	7.356897
16.66550	150.2540	7.307124
16.71716	150.2519	7.251574
16.76883	150.2485	7.199839
16.82050	150.2467	7.147674
16.87216	150.2439	7.096204
16.92383	150.2407	7.045350
16.97716	150.2379	6.990512
17.02716	150.2352	6.939691
17.08050	150.2331	6.882818
17.13050	150.2300	6.833413
17.18383	150.2279	6.777198
17.23383	150.2253	6.727884
17.28717	150.2221	6.673512
17.33716	150.2204	6.622390
17.39050	150.2172	6.567124
17.44050	150.2145	6.516959
17.49383	150.2122	6.461102
17.54550	150.2096	6.409066
17.59716	150.2073	6.360266
17.64883	150.2046	6.306488
17.70050	150.2018	6.252780
17.75216	150.1995	6.201188
17.80383	150.1964	6.149982
17.85716	150.1947	6.098594
17.90716	150.1924	6.045834
17.96050	150.1901	5.994948
18.01050	150.1875	5.942085
18.06383	150.1851	5.889433
18.11383	150.1830	5.847110
18.16716	150.1795	5.796148
18.21716	150.1772	5.748806
18.27050	150.1736	5.700799
18.32050	150.1710	5.654160
18.37383	150.1694	5.606528
18.42550	150.1666	5.558976
18.47716	150.1641	5.509516
18.52883	150.1618	5.465871
18.58050	150.1592	5.417082
18.63216	150.1567	5.368722
18.68383	150.1545	5.325009
18.73550	150.1519	5.277398
18.78717	150.1502	5.233330
18.84050	150.1479	5.183618
18.89050	150.1450	5.141761
18.94383	150.1438	5.094063
18.99383	150.1412	5.051504
19.04716	150.1389	5.005838
19.09716	150.1377	4.962082
19.15050	150.1360	4.917534
19.20050	150.1334	4.878083
19.25383	150.1312	4.836044
19.30383	150.1280	4.796678
19.35716	150.1267	4.756884
19.40883	150.1244	4.719354
19.46050	150.1220	4.682830
19.51216	150.1199	4.644106
19.56383	150.1187	4.605627
19.61550	150.1163	4.565721
19.66716	150.1135	4.528866
19.72050	150.1126	4.489620
19.77050	150.1106	4.451524
19.82383	150.1093	4.413026
19.87383	150.1067	4.377734
19.92716	150.1046	4.340842
19.97716	150.1029	4.304438
20.03050	150.1014	4.268810
20.08050	150.0993	4.232397
20.13383	150.0977	4.199914
20.18383	150.0962	4.165422
20.23716	150.0942	4.130638
20.28883	150.0932	4.094717
20.34050	150.0916	4.063105
20.39216	150.0896	4.029934
20.44383	150.0882	3.999202
20.49550	150.0867	3.965766
20.54716	150.0853	3.936100
20.59883	150.0835	3.905248
20.65050	150.0822	3.873942
20.70383	150.0811	3.843877
20.75383	150.0792	3.814604
20.80716	150.0786	3.780070
20.85716	150.0766	3.752788
20.91050	150.0755	3.724780
20.96050	150.0740	3.696186
21.01383	150.0731	3.669306
21.06383	150.0710	3.645681
21.11716	150.0696	3.619246
21.16716	150.0680	3.596767
21.22050	150.0666	3.573838
21.27216	150.0656	3.549967
21.32383	150.0640	3.524391
21.37550	150.0633	3.500275
21.42717	150.0611	3.473370
21.47883	150.0604	3.448953
21.53050	150.0598	3.422409
21.58383	150.0584	3.397647
21.63383	150.0580	3.376500
21.68716	150.0566	3.354836
21.73716	150.0552	3.336410
21.79050	150.0534	3.317986
21.84050	150.0531	3.297310
21.89383	150.0513	3.277019
21.94383	150.0508	3.257854
21.99716	150.0498	3.237576
22.04716	150.0489	3.221769
22.10050	150.0479	3.204836
22.15216	150.0472	3.186119
22.20383	150.0461	3.168122
22.25550	150.0456	3.151900
22.30716	150.0450	3.135108
22.35883	150.0450	3.116878
22.41050	150.0440	3.101825
22.46216	150.0434	3.090511
22.51383	150.0425	3.079302
22.56716	150.0414	3.067973
22.61716	150.0406	3.058263
22.67050	150.0408	3.047905
22.72050	150.0396	3.038424
22.77383	150.0378	3.029252
22.82383	150.0379	3.020784
22.87716	150.0370	3.012158
22.92717	150.0370	3.004485
22.98050	150.0364	2.996612
23.03050	150.0359	2.989397
23.08383	150.0359	2.982331
23.13550	150.0354	2.975918
23.18716	150.0354	2.970016
23.23883	150.0354	2.964381
23.29050	150.0359	2.959146
23.34216	150.0362	2.954054
23.39383	150.0362	2.949286
23.44716	150.0360	2.944836
23.49716	150.0349	2.940806
23.55050	150.0354	2.936783
23.60050	150.0352	2.933018
23.65383	150.0358	2.929260
23.70383	150.0352	2.925825
23.75716	150.0351	2.922070
23.80716	150.0355	2.918464
23.86050	150.0343	2.914484
23.91050	150.0346	2.910291
23.96383	150.0334	2.905281
24.01550	150.0329	2.899809
24.06716	150.0331	2.893153
24.11883	150.0325	2.885684
24.17050	150.0309	2.878128
24.22216	150.0311	2.868784
24.27383	150.0308	2.857939
24.32550	150.0306	2.844800
24.37716	150.0310	2.828525
24.43050	150.0297	2.811004
24.48050	150.0281	2.794197
24.53383	150.0277	2.774244
24.58383	150.0265	2.755647
24.63716	150.0254	2.736145
24.68716	150.0247	2.716972
24.74050	150.0229	2.697180
24.79050	150.0220	2.676474
24.84383	150.0207	2.655664
24.89383	150.0192	2.634734
24.94716	150.0172	2.612340
24.99883	150.0161	2.589610
25.05050	150.0159	2.563626
25.10216	150.0152	2.539245
25.15383	150.0132	2.516917
25.20550	150.0124	2.493849
25.25716	150.0120	2.467580
25.31050	150.0101	2.445295
25.36050	150.0099	2.422289
25.41383	150.0077	2.397064
25.46383	150.0064	2.377558
25.51716	150.0056	2.353498
25.56716	150.0051	2.330163
25.62050	150.0036	2.306762
25.67050	150.0030	2.287840
25.72383	150.0024	2.264906
25.77383	150.0016	2.242096
25.82717	150.0011	2.217549
25.87883	149.9996	2.198372
25.93050	149.9980	2.180484
25.98216	149.9983	2.159020
26.03383	149.9965	2.138606
26.08550	149.9955	2.124092
26.13716	149.9946	2.107712
26.18883	149.9931	2.091854
26.24050	149.9912	2.075239
26.29383	149.9911	2.057688
26.34383	149.9894	2.037242
26.39716	149.9883	2.016117
26.44717	149.9880	1.996363
26.50050	149.9875	1.978389
26.55050	149.9866	1.958031
26.60383	149.9853	1.937151
26.65383	149.9846	1.919038
26.70716	149.9832	1.899080
26.75716	149.9827	1.884057
26.81050	149.9820	1.868694
26.86216	149.9804	1.851361
26.91383	149.9797	1.838786
26.96550	149.9790	1.824565
27.01716	149.9786	1.811782
27.06883	149.9775	1.794593
27.12050	149.9761	1.779122
27.17383	149.9755	1.761071
27.22383	149.9745	1.743012
27.27717	149.9736	1.726589
27.32717	149.9731	1.709034
27.38050	149.9717	1.693325
27.43050	149.9714	1.677344
27.48383	149.9704	1.659413
27.53383	149.9689	1.643287
27.58716	149.9688	1.624934
27.63716	149.9686	1.607737
27.69050	149.9683	1.589660
27.74216	149.9670	1.575008
27.79383	149.9668	1.560388
27.84550	149.9653	1.544874
27.89716	149.9652	1.530280
27.94883	149.9641	1.516724
28.00050	149.9631	1.503378
28.05217	149.9630	1.488652
28.10383	149.9615	1.476316
28.15716	149.9611	1.465871
28.20716	149.9598	1.453918
28.26050	149.9594	1.440290
28.31050	149.9590	1.424170
28.36383	149.9581	1.406757
28.41383	149.9565	1.390779
28.46716	149.9566	1.374911
28.51716	149.9554	1.358668
28.57050	149.9551	1.342763
28.62050	149.9547	1.326439
28.67383	149.9542	1.310723
28.72550	149.9529	1.297510
28.77717	149.9524	1.283070
28.82883	149.9521	1.267340
28.88050	149.9514	1.252690
28.93216	149.9501	1.239900
28.98383	149.9490	1.225174
29.03717	149.9492	1.207899
29.08716	149.9481	1.192816
29.14050	149.9478	1.179846
29.19050	149.9471	1.163586
29.24383	149.9468	1.147388
29.29383	149.9452	1.132678
29.34716	149.9446	1.116442
29.39716	149.9432	1.101955
29.45050	149.9430	1.087134
29.50050	149.9426	1.075689
29.55383	149.9406	1.063624
29.60550	149.9397	1.049084
29.65716	149.9391	1.032543
29.70883	149.9384	1.015131
29.76050	149.9380	0.9984322
29.81217	149.9364	0.9801772
29.86383	149.9359	0.9654145
29.91550	149.9350	0.9488547
29.96716	149.9343	0.9330376
30.02050	149.9327	0.9186508
30.07050	149.9322	0.9028916
30.12383	149.9316	0.8840722
30.17383	149.9309	0.8693105
30.22717	149.9299	0.8511170
30.27717	149.9286	0.8334955
30.33050	149.9281	0.8162845
30.38050	149.9274	0.7981845
30.43383	149.9277	0.7824568
30.48383	149.9254	0.7655405
30.53717	149.9259	0.7470611
30.58883	149.9253	0.7275730
30.64050	149.9243	0.7093203
30.69216	149.9238	0.6904955
30.74383	149.9226	0.6742475
30.79550	149.9216	0.6593904
30.84716	149.9207	0.6456501
30.90050	149.9195	0.6295422
30.95050	149.9187	0.6147966
31.00383	149.9184	0.5968680
31.05383	149.9180	0.5809376
31.10716	149.9169	0.5626972
31.15716	149.9150	0.5444658
31.21050	149.9153	0.5319166
31.26050	149.9139	0.5168442
31.31383	149.9128	0.4969852
31.36383	149.9132	0.4775540
31.41716	149.9116	0.4573770
31.46883	149.9106	0.4419403
31.52050	149.9102	0.4228333
31.57217	149.9093	0.4073706
31.62383	149.9086	0.3923535
31.67550	149.9069	0.3768656
31.72717	149.9061	0.3625961
31.77883	149.9051	0.3481696
31.83050	149.9042	0.3330898
31.88383	149.9035	0.3147082
31.93384	149.9025	0.2980985
31.98717	149.9022	0.2813367
32.03717	149.9015	0.2651186
32.09050	149.9006	0.2485636
32.14050	149.9001	0.2310021
32.19383	149.8992	0.2126952
32.24383	149.8991	0.1986402
32.29716	149.8983	0.1820114
32.34716	149.8974	0.1670074
32.40050	149.8959	0.1540696
32.45216	149.8951	0.1422026
32.50383	149.8945	0.1301438
32.55550	149.8937	0.1191658
32.60716	149.8928	0.1072840
32.65883	149.8919	0.09445361
32.71050	149.8916	0.07640684
32.76383	149.8908	0.06025478
32.81383	149.8904	0.04449734
32.86716	149.8891	0.02973845
32.91716	149.8884	0.01659156
32.97050	149.8880	8.24802E-4
33.02050	149.8868	-.01154539
33.07383	149.8874	-.02773710
33.12383	149.8863	-.04099548
33.17717	149.8859	-.05408551
33.22717	149.8845	-.06569266
33.28050	149.8846	-.07787744
33.33216	149.8841	-.08962351
33.38383	149.8830	-0.1010508
33.43550	149.8829	-0.1126202
33.48717	149.8826	-0.1256893
33.53883	149.8817	-0.1379310
33.59050	149.8809	-0.1484585
33.64216	149.8800	-0.1601878
33.69383	149.8792	-0.1706509
33.74716	149.8786	-0.1828982
33.79716	149.8780	-0.1928284
33.85050	149.8775	-0.2049246
33.90050	149.8765	-0.2157735
33.95383	149.8761	-0.2270756
34.00383	149.8759	-0.2371076
34.05716	149.8744	-0.2477058
34.10716	149.8751	-0.2578174
34.16050	149.8744	-0.2691125
34.21050	149.8743	-0.2795294
34.26383	149.8737	-0.2915359
34.31550	149.8730	-0.3021023
34.36716	149.8720	-0.3127376
34.41883	149.8711	-0.3226904
34.47050	149.8717	-0.3332716
34.52217	149.8708	-0.3425069
34.57383	149.8708	-0.3514875
34.62717	149.8691	-0.3603511
34.67717	149.8695	-0.3687584
34.73050	149.8694	-0.3787359
34.78050	149.8687	-0.3871074
34.83383	149.8690	-0.3960947
34.88383	149.8686	-0.4047621
34.93716	149.8689	-0.4141328
34.98717	149.8684	-0.4227774
35.04050	149.8679	-0.4317317
35.09050	149.8676	-0.4398894
35.14383	149.8668	-0.4480701
35.19550	149.8667	-0.4557968
35.24716	149.8661	-0.4631539
35.29883	149.8658	-0.4700911
35.35050	149.8646	-0.4763078
35.40216	149.8648	-0.4820874
35.45383	149.8637	-0.4877123
35.50550	149.8639	-0.4932623
35.55716	149.8634	-0.4987416
35.61050	149.8636	-0.5044166
35.66050	149.8633	-0.5100454
35.71383	149.8624	-0.5158736
35.76383	149.8628	-0.5216433
35.81716	149.8619	-0.5277662
35.86716	149.8627	-0.5335010
35.92050	149.8619	-0.5397862
35.97050	149.8627	-0.5453820
36.02383	149.8618	-0.5511687
36.07383	149.8612	-0.5563360
36.12717	149.8611	-0.5617451
36.17883	149.8611	-0.5671105
36.23050	149.8610	-0.5724242
36.28216	149.8612	-0.5779624
36.33383	149.8602	-0.5835299
36.38550	149.8601	-0.5889980
36.43716	149.8602	-0.5947070
36.49050	149.8600	-0.6000630
36.54050	149.8595	-0.6049646
36.59384	149.8588	-0.6097618
36.64383	149.8583	-0.6140356
36.69717	149.8576	-0.6187527
36.74716	149.8578	-0.6231629
36.80050	149.8572	-0.6281470
36.85050	149.8565	-0.6328774
36.90383	149.8558	-0.6386948
36.95383	149.8553	-0.6443215
37.00716	149.8557	-0.6505132
37.05883	149.8564	-0.6565919
37.11050	149.8551	-0.6628543
37.16217	149.8556	-0.6692800
37.21383	149.8550	-0.6760285
37.26550	149.8556	-0.6827042
37.31716	149.8544	-0.6891518
37.36883	149.8538	-0.6952932
37.42050	149.8539	-0.7010634
37.47383	149.8536	-0.7067613
37.52383	149.8540	-0.7114798
37.57717	149.8532	-0.7163075
37.62717	149.8525	-0.7205410
37.68050	149.8518	-0.7252242
37.73050	149.8517	-0.7300519
37.78383	149.8520	-0.7326284
37.83383	149.8525	-0.7352466
37.88716	149.8513	-0.7390811
37.93716	149.8513	-0.7436188
37.99050	149.8512	-0.7495612
38.04217	149.8504	-0.7554160
38.09384	149.8504	-0.7615054
38.14550	149.8510	-0.7676670
38.19717	149.8513	-0.7740922
38.24883	149.8502	-0.7803554
38.30050	149.8496	-0.7864965
38.35383	149.8487	-0.7927789
38.40383	149.8496	-0.7986530
38.45716	149.8497	-0.8048626
38.50716	149.8498	-0.8104022
38.56050	149.8496	-0.8164959
38.61050	149.8486	-0.8218576
38.66383	149.8482	-0.8272599
38.71383	149.8497	-0.8322242
38.76716	149.8485	-0.8372089
38.81716	149.8484	-0.8413062
38.87050	149.8474	-0.8455140
38.92216	149.8470	-0.8494506
38.97383	149.8469	-0.8532594
39.02550	149.8466	-0.8572894
39.07717	149.8464	-0.8611488
39.12883	149.8460	-0.8650868
39.18050	149.8458	-0.8689736
39.23216	149.8450	-0.8730566
39.28383	149.8452	-0.8772792
39.33716	149.8444	-0.8814962
39.38716	149.8453	-0.8854188
39.44050	149.8445	-0.8899774
39.49050	149.8447	-0.8944166
39.54383	149.8444	-0.8992684
39.59384	149.8441	-0.9038116
39.64717	149.8451	-0.9084816
39.69717	149.8445	-0.9125632
39.75050	149.8439	-0.9167711
39.80050	149.8444	-0.9204054
39.85383	149.8431	-0.9240663
39.90550	149.8435	-0.9276085
39.95716	149.8429	-0.9312024
40.00883	149.8436	-0.9349381
40.06050	149.8440	-0.9387028
40.11217	149.8433	-0.9423575
40.16383	149.8430	-0.9458653
40.21716	149.8426	-0.9493439
40.26716	149.8426	-0.9526842
40.32050	149.8428	-0.9560639
40.37050	149.8430	-0.9591828
40.42383	149.8419	-0.9624950
40.47383	149.8418	-0.9653266
40.52716	149.8414	-0.9681553
40.57717	149.8409	-0.9703924
40.63050	149.8407	-0.9725129
40.68050	149.8396	-0.9746705
40.73383	149.8394	-0.9768309
40.78550	149.8397	-0.9796997
40.83716	149.8404	-0.9826580
40.88883	149.8395	-0.9858031
40.94050	149.8394	-0.9889022
40.99216	149.8390	-0.9920282
41.04383	149.8395	-0.9955118
41.09550	149.8391	-0.9986828
41.14717	149.8390	-1.002009
41.20050	149.8384	-1.005092
41.25050	149.8384	-1.008268
41.30383	149.8386	-1.011495
41.35383	149.8389	-1.014500
41.40717	149.8386	-1.017733
41.45717	149.8385	-1.020682
41.51050	149.8383	-1.024050
41.56050	149.8384	-1.027132
41.61383	149.8385	-1.030455
41.66383	149.8379	-1.033453
41.71717	149.8372	-1.036378
41.76883	149.8376	-1.039321
41.82050	149.8379	-1.042062
41.87216	149.8375	-1.044946
41.92383	149.8372	-1.047669
41.97550	149.8366	-1.050132
42.02716	149.8372	-1.052697
42.08050	149.8370	-1.055803
42.13050	149.8373	-1.058659
42.18383	149.8369	-1.061535
42.23383	149.8376	-1.064642
42.28717	149.8372	-1.068218
42.33716	149.8367	-1.071002
42.39050	149.8359	-1.073772
42.44050	149.8364	-1.076115
42.49383	149.8354	-1.078822
42.54383	149.8357	-1.081380
42.59716	149.8354	-1.084010
42.64883	149.8351	-1.086621
42.70050	149.8353	-1.089114
42.75217	149.8346	-1.091606
42.80383	149.8353	-1.094204
42.85550	149.8343	-1.096973
42.90717	149.8340	-1.099672
42.95883	149.8344	-1.102750
43.01050	149.8341	-1.105773
43.06383	149.8345	-1.108740
43.11383	149.8335	-1.111509
43.16716	149.8340	-1.114206
43.21717	149.8340	-1.117130
43.26717	149.8337	-1.120424
43.32050	149.9919	-1.058194
43.37050	150.4784	-2.497383
43.42383	151.1232	-5.620084
43.47383	151.8056	-9.017006
43.52716	152.5892	-12.61183
43.57717	153.3666	-15.69928
43.63050	154.2329	-18.59163
43.68050	155.0737	-20.93136
43.73383	155.9953	-23.05842
43.78550	156.9096	-24.80718
43.83716	157.8411	-26.28930
43.88883	158.7863	-27.56272
43.94050	159.7436	-28.64632
43.99216	160.7116	-29.57492
44.04383	161.6880	-30.39089
44.09716	162.7034	-31.11946
44.14717	163.6612	-31.71687
44.20050	164.6880	-32.27642
44.25050	165.6552	-32.74524
44.30383	166.6908	-33.19754
44.35383	167.6634	-33.56768
44.40717	168.7069	-33.91619
44.45717	169.6858	-34.22446
44.51050	170.7317	-34.51912
44.56050	171.7146	-34.79763
44.61383	172.7639	-35.08922
44.66550	173.7804	-35.35002
44.71717	174.7987	-35.60665
44.76883	175.8173	-35.84929
44.82050	176.8378	-36.08933
44.87216	177.8581	-36.31441
44.92383	178.8792	-36.54322
44.97550	179.8998	-36.79419
45.02716	180.9190	-37.05520
45.08050	181.9727	-37.33723
45.13050	182.9603	-37.61111
45.18383	184.0124	-37.90688
45.23383	185.0002	-38.19444
45.28717	186.0530	-38.52079
45.33716	187.0392	-38.82656
45.39050	188.0901	-39.17324
45.44050	189.0758	-39.51902
45.49383	190.1259	-39.89866
45.54383	191.1100	-40.27984
45.59716	192.1586	-40.70590
45.64883	193.1730	-41.13775
45.70050	194.1872	-41.59803
45.75217	195.2001	-42.07480
45.80383	196.2120	-42.57824
45.85550	197.2226	-43.12119
45.90717	198.2332	-43.69218
45.96050	199.2740	-44.30639
46.01050	200.2482	-44.91983
46.06383	201.2864	-45.61282
46.11383	202.2581	-46.32529
46.16716	203.2912	-47.10622
46.21717	204.2579	-47.90483
46.27050	205.2858	-48.80947
46.32050	206.2469	-49.74097
46.37383	207.2669	-50.82217
46.42383	208.2190	-51.93074
46.47717	209.2307	-53.25947
46.52883	210.2020	-54.70580
46.58050	211.1649	-56.34360
46.63217	212.1186	-58.21230
46.68383	213.0602	-60.35089
46.73550	213.9894	-62.78290
46.78717	214.9042	-65.52120
46.83883	215.8050	-68.57350
46.89050	216.6942	-71.80495
46.94383	217.6088	-75.22174
46.99383	218.4662	-78.40145
47.04716	219.3820	-81.75784
47.09716	220.2433	-84.85538
47.15050	221.1642	-88.10138
47.20050	222.0356	-90.95819
47.25383	222.9814	-93.49884
47.30383	223.9023	-95.03128
47.35717	224.9356	-95.46369
47.40717	225.9532	-94.78439
47.46050	227.0840	-93.19509
47.51216	228.2142	-90.96026
47.56383	229.3696	-88.19532
47.61550	230.5508	-84.85092
47.66716	231.7634	-80.80342
47.71884	233.0102	-75.97989
47.77050	234.2767	-70.89312
47.82383	235.5730	-66.12674
47.87383	236.7606	-62.27735
47.92717	237.9984	-58.81668
47.97717	239.1316	-56.10800
48.03050	240.3184	-53.70176
48.08050	241.4114	-51.83007
48.13383	242.5622	-50.19075
48.18383	243.6270	-48.90533
48.23717	244.7520	-47.77190
48.28717	245.7985	-46.88130
48.34050	246.9060	-46.10286
48.39217	247.9727	-45.46604
48.44383	249.0343	-44.93648
48.49550	250.0912	-44.50406
48.54716	251.1431	-44.15320
48.59883	252.1931	-43.86694
48.65050	253.2394	-43.63842
48.70216	254.2855	-43.44730
48.75383	255.3292	-43.29592
48.80717	256.4050	-43.19100
48.85717	257.4111	-43.11502
48.91050	258.4835	-43.04732
48.96050	259.4884	-43.01646
49.01383	260.5581	-42.99512
49.06383	261.5618	-42.98216
49.11716	262.6320	-42.97914
49.16716	263.6345	-42.98184
49.22050	264.7031	-42.98985
49.27050	265.7041	-43.01598
49.32383	266.7722	-43.05168
49.37550	267.8064	-43.08514
49.42717	268.8396	-43.12934
49.47883	269.8736	-43.17571
49.53050	270.9068	-43.21360
49.58217	271.9402	-43.24402
49.63383	272.9744	-43.28549
49.68716	274.0411	-43.32630
49.73717	275.0419	-43.37242
49.78717	276.0156	-43.42067
49.84050	276.3965	-43.54170
49.89050	276.2373	-38.88209
49.94383	275.8680	-31.53060
49.99383	275.4008	-24.04146
50.04716	274.8122	-16.44124
50.09716	274.1933	-10.02648
50.15050	273.4731	-4.036724
50.20050	272.7520	0.7923566
50.25383	271.9414	5.229206
50.30550	271.1209	8.948134
50.35717	270.2736	12.14035
50.40883	269.4028	14.89383
50.46050	268.5096	17.25898
50.51216	267.5993	19.30845
50.56383	266.6731	21.07588
50.61550	265.7336	22.60166
50.66716	264.7806	23.92680
50.72050	263.7883	25.10294
50.77050	262.8475	26.06240
50.82383	261.8378	26.94794
50.87383	260.8845	27.65999
50.92717	259.8620	28.31450
50.97717	258.8974	28.85045
51.03050	257.8654	29.34638
51.08050	256.8946	29.75203
51.13383	255.8555	30.13918
51.18383	254.8794	30.47302
51.23717	253.8348	30.78541
51.28883	252.8212	31.04872
51.34050	251.8070	31.28865
51.39216	250.7894	31.48691
51.44384	249.7720	31.66576
51.49550	248.7517	31.82850
51.54717	247.7308	31.97493
51.60050	246.6765	32.09804
51.65050	245.6875	32.20084
51.70383	244.6314	32.30156
51.75383	243.6409	32.37392
51.80717	242.5838	32.44899
51.85717	241.5919	32.49741
51.91050	240.5332	32.55223
51.96050	239.5412	32.59473
52.01383	238.4820	32.64712
52.06383	237.4890	32.68249
52.11716	236.4290	32.71997
52.16883	235.4020	32.74907
52.22050	234.3761	32.76785
52.27217	233.3485	32.78541
52.32383	232.3216	32.79813
52.37550	231.2935	32.81158
52.42717	230.2660	32.82532
52.47883	229.2391	32.83470
52.53050	228.2114	32.84740
52.58383	227.1510	32.87789
52.63383	226.1565	32.89006
52.68716	225.0955	32.90767
52.73717	224.1003	32.93463
52.79050	223.0400	32.94625
52.84050	222.0454	32.95590
52.89384	220.9839	32.96508
52.94384	219.9886	32.97422
52.99717	218.9281	32.99070
53.04717	217.9325	33.00073
53.10050	216.8712	33.01022
53.15217	215.8435	33.01884
53.20383	214.8144	33.02700
53.25550	213.7862	33.03406
53.30717	212.7573	33.04006
53.35883	211.7287	33.04460
53.41050	210.6999	33.04812
53.46382	209.6386	33.05060
53.51382	208.6433	33.05242
53.56716	207.5818	33.05332
53.61716	206.5856	33.05380
53.67050	205.5242	33.05406
53.72050	204.5274	33.05350
53.77383	203.4654	33.05260
53.82383	202.4692	33.05122
53.87717	201.4065	33.04850
53.92717	200.4098	33.04439
53.98050	199.3469	33.03908
54.03217	198.3181	33.03254
54.08383	197.2880	33.02602
54.13550	196.2591	33.01788
54.18716	195.2292	33.00911
54.23882	194.2001	33.00203
54.29050	193.1712	32.99505
54.34217	192.1408	32.98683
54.39384	191.1117	32.97818
54.44717	190.0481	32.96906
54.49717	189.0519	32.95386
54.55050	187.9894	32.93975
54.60050	186.9935	32.92718
54.65383	185.9309	32.91462
54.70383	184.9341	32.90356
54.75717	183.8708	32.88795
54.80717	182.8733	32.86704
54.86050	181.8100	32.85083
54.91050	180.8142	32.83082
54.96382	179.7501	32.81809
55.01550	178.7212	32.80878
55.06716	177.6909	32.80066
55.11882	176.6616	32.79410
55.17050	175.6319	32.78967
55.22217	174.6024	32.78928
55.27383	173.5739	32.80514
55.32717	172.5120	32.84710
55.37717	171.5184	32.89796
55.43050	170.4589	32.96274
55.48050	169.4659	33.04729
55.53383	168.4077	33.15289
55.58383	167.4171	33.27474
55.63716	166.3616	33.43458
55.68716	165.3755	33.64966
55.74050	164.3286	33.99472
55.79050	163.3551	34.54596
55.84384	162.3351	35.56580
55.89550	161.3759	37.24468
55.94717	160.4588	39.86242
55.99883	159.5934	43.55050
56.05050	158.7765	48.16106
56.10217	157.9942	53.27837
56.15383	157.2217	58.40612
56.20550	156.4334	63.07359
56.25717	155.6127	66.94524
56.31050	154.7185	69.91297
56.36050	153.8310	71.69415
56.41382	152.8322	72.53412
56.46382	151.8479	72.40516
56.51716	150.7520	71.36616
56.56716	149.6858	69.66954
56.62050	148.5148	67.22224
56.67050	147.3924	64.55776
56.72382	146.1853	61.56982
56.77383	145.0509	58.81787
56.82717	143.8444	55.93531
56.87883	142.6826	53.34205
56.93050	141.5295	50.96717
56.98217	140.3913	48.84993
57.03383	139.2644	46.97840
57.08550	138.1483	45.31869
57.13716	137.0414	43.85156
57.19050	135.9100	42.51894
57.24050	134.8558	41.41367
57.29382	133.7390	40.38050
57.34384	132.6981	39.53381
57.39717	131.5920	38.72312
57.44717	130.5598	38.04288
57.50050	129.4640	37.40910
57.55050	128.4388	36.87537
57.60383	127.3494	36.36858
57.65383	126.3305	35.94171
57.70717	125.2461	35.52178
57.75883	124.1986	35.15631
57.81050	123.1508	34.81626
57.86217	122.1062	34.50802
57.91382	121.0606	34.22105
57.96550	120.0180	33.96611
58.01716	118.9761	33.72624
58.06884	117.9349	33.50854
58.12050	116.8948	33.31145
58.17383	115.8216	33.11690
58.22382	114.8158	32.94366
58.27717	113.7430	32.77050
58.32717	112.7390	32.61621
58.38050	111.6672	32.45780
58.43050	110.6634	32.31469
58.48383	109.5933	32.15451
58.53383	108.5878	32.02586
58.58716	107.5183	31.88066
58.63716	106.5154	31.74694
58.69050	105.4456	31.61251
58.74216	104.4100	31.49086
58.79382	103.3745	31.36872
58.84550	102.3381	31.25765
58.89717	101.3018	31.14014
58.94883	100.2663	31.03359
59.00050	99.23059	30.92354
59.05383	98.16108	30.80854
59.10383	97.16075	30.70895
59.15717	96.09168	30.59512
59.20717	95.09034	30.49108
59.26050	94.02145	30.38090
59.31050	93.01972	30.28729
59.36382	91.95131	30.18045
59.41382	90.94969	30.07596
59.46717	89.88138	29.96412
59.51716	88.87968	29.86025
59.57050	87.81191	29.75420
59.62217	86.77689	29.65049
59.67383	85.74205	29.55583
59.72550	84.70907	29.45480
59.77717	83.67368	29.36204
59.82883	82.63860	29.26472
59.88050	81.60376	29.17596
59.93217	80.56913	29.08022
59.98383	79.53496	28.98392
60.03716	78.46692	28.88965
60.08716	77.46644	28.80056
60.14050	76.39882	28.70930
60.19050	75.39680	28.62875
60.24382	74.32905	28.54054
60.29382	73.32900	28.45498
60.34716	72.26118	28.36618
60.39717	71.26018	28.28023
60.45050	70.19180	28.19225
60.50050	69.19078	28.10966
60.55383	68.12216	28.01148
60.60550	67.08782	27.91852
60.65717	66.05340	27.82162
60.70883	65.01877	27.73180
60.76050	63.98482	27.63736
60.81216	62.94964	27.53290
60.86382	61.91468	27.43674
60.91716	60.84628	27.33067
60.96717	59.84444	27.23055
61.02050	58.77646	27.13096
61.07050	57.77479	27.03563
61.12383	56.70824	26.92875
61.17383	55.70618	26.84076
61.22717	54.63732	26.73972
61.27717	53.63652	26.65182
61.33050	52.56822	26.55100
61.38050	51.56542	26.46036
61.43383	50.49768	26.35884
61.48550	49.46213	26.26532
61.53716	48.42734	26.17035
61.58882	47.39170	26.06575
61.64050	46.35670	25.97441
61.69216	45.32126	25.87781
61.74382	44.28580	25.78604
61.79550	43.25066	25.68736
61.84716	42.21448	25.59281
61.90050	41.14602	25.48890
61.95050	40.14275	25.39098
62.00383	39.07348	25.28026
62.05383	38.07074	25.16963
62.10717	37.00208	25.04303
62.15717	35.99865	24.92511
62.21050	34.92766	24.80267
62.26050	33.92431	24.68078
62.31382	32.85459	24.54629
62.36382	31.85102	24.41882
62.41716	30.78075	24.28451
62.46884	29.74288	24.16006
62.52050	28.70564	24.03092
62.57217	27.66756	23.89115
62.62383	26.62986	23.75557
62.67550	25.59111	23.61062
62.72717	24.55213	23.46390
62.77550	23.58596	23.31455
62.82717	22.98822	23.39869
62.88050	23.03266	20.75605
62.93050	23.27926	16.54967
62.98383	23.71399	11.43996
63.03383	24.22624	6.720857
63.08716	24.86706	2.127164
63.13716	25.53472	-1.645456
63.19050	26.31008	-5.095246
63.24050	27.08015	-7.822506
63.29382	27.94360	-10.26628
63.34384	28.78315	-12.18701
63.39717	29.70639	-13.89979
63.44883	30.62095	-15.28226
63.50050	31.55322	-16.45007
63.55217	32.50001	-17.44853
63.60383	33.45922	-18.29231
63.65550	34.42719	-19.02001
63.70717	35.40383	-19.64672
63.75883	36.38892	-20.19479
63.81050	37.37769	-20.67142
63.86384	38.40622	-21.10372
63.91382	39.37229	-21.46414
63.96717	40.40808	-21.80140
64.01716	41.38243	-22.08349
64.07050	42.42466	-22.35990
64.12050	43.40286	-22.59354
64.17383	44.44918	-22.82172
64.22384	45.43186	-23.02063
64.27717	46.48118	-23.21744
64.32718	47.46814	-23.39415
64.38050	48.52050	-23.57576
64.43218	49.54098	-23.74125
64.48383	50.56308	-23.89265
64.53550	51.58614	-24.05020
64.58716	52.60922	-24.19471
64.63884	53.63351	-24.33198
64.69050	54.65764	-24.46236
64.74384	55.71684	-24.59581
64.79384	56.70914	-24.71570
64.84717	57.76891	-24.84490
64.89717	58.76280	-24.96310
64.95050	59.82321	-25.08422
65.00050	60.81658	-25.20222
65.05383	61.87760	-25.32472
65.10383	62.87274	-25.43744
65.15718	63.93310	-25.55770
65.20717	64.92789	-25.65767
65.26050	65.98972	-25.76720
65.31216	67.01850	-25.87999
65.36384	68.04736	-25.98727
65.41550	69.07545	-26.09687
65.46717	70.10462	-26.20433
65.51882	71.13311	-26.30835
65.57050	72.16216	-26.41535
65.62218	73.19164	-26.52461
65.67384	74.22075	-26.62769
65.72718	75.28300	-26.73695
65.77718	76.27818	-26.83787
65.83050	77.34108	-26.94953
65.88050	78.33634	-27.05872
65.93384	79.39859	-27.17260
65.98384	80.39460	-27.28154
66.03718	81.45710	-27.40054
66.08716	82.45226	-27.51193
66.14050	83.51562	-27.62707
66.19050	84.51178	-27.73794
66.24384	85.57428	-27.85805
66.29550	86.60297	-27.97581
66.34718	87.63251	-28.09690
66.39884	88.66218	-28.21281
66.45050	89.69152	-28.33336
66.50218	90.72006	-28.45935
66.55384	91.74989	-28.57312
66.60718	92.81250	-28.69778
66.65718	93.80770	-28.80998
66.71050	94.86978	-28.92953
66.76050	95.86652	-29.04700
66.81384	96.92795	-29.17184
66.86384	97.92481	-29.27688
66.91718	98.98770	-29.40259
66.96718	99.98389	-29.51132
67.02050	101.0462	-29.62558
67.07050	102.0426	-29.74348
67.12384	103.1045	-29.86334
67.17550	104.1336	-29.97607
67.22718	105.1638	-30.09418
67.27884	106.1924	-30.21870
67.33050	107.2214	-30.34275
67.38218	108.2508	-30.46134
67.43384	109.2810	-30.58031
67.48550	110.3104	-30.70597
67.53718	111.3386	-30.82450
67.59050	112.4013	-30.94698
67.64050	113.3976	-31.06478
67.69384	114.4594	-31.19048
67.74384	115.4573	-31.30322
67.79718	116.5199	-31.43090
67.84718	117.5159	-31.53554
67.90050	118.5774	-31.66150
67.95050	119.5740	-31.77602
68.00384	120.6362	-31.91000
68.05384	121.5693	-33.48302
68.10718	122.6333	-33.30600
68.15884	123.6687	-33.33032
68.21050	124.7034	-33.36991
68.26218	125.7367	-33.41769
68.31384	126.7686	-33.47746
68.36550	127.8010	-33.54518
68.41718	128.8325	-33.61703
68.47050	129.8965	-33.70328
68.52050	130.8942	-33.78912
68.57384	131.9586	-33.90708
68.62384	132.9558	-34.00588
68.67718	134.0195	-34.11898
68.72718	135.0167	-34.22092
68.78050	136.0806	-34.32281
68.83050	137.0778	-34.41750
68.88384	138.1424	-34.54238
68.93384	139.1385	-34.65715
68.98718	140.2016	-34.78747
69.03882	141.2319	-34.92420
69.09050	142.2611	-35.05807
69.14216	143.2895	-35.19714
69.19384	144.3182	-35.33616
69.24550	145.3464	-35.47997
69.29718	146.3750	-35.63247
69.34882	147.4018	-35.79025
69.40050	148.4303	-35.93445
69.45384	149.4920	-36.08476
69.50384	150.4872	-36.22029
69.55718	151.5486	-36.36872
69.60718	152.5430	-36.51050
69.66050	153.6048	-36.67028
69.71050	154.5988	-36.82540
69.76384	155.6589	-37.00008
69.81384	156.6532	-37.16914
69.86718	157.7142	-37.35396
69.91718	158.7073	-37.53769
69.97050	159.7664	-37.73213
70.02218	160.7940	-37.92392
70.07384	161.8208	-38.12322
70.12550	162.8482	-38.30850
70.17718	163.8748	-38.48780
70.22884	164.9026	-38.66245
70.28050	165.9300	-38.82386
70.33384	166.9907	-38.97858
70.38384	167.9862	-39.11632
70.43718	169.0489	-39.23769
70.48718	170.0442	-39.34276
70.54050	171.1090	-39.44567
70.59050	172.1061	-39.53729
70.64384	173.1706	-39.64761
70.69384	174.1674	-39.74463
70.74718	175.2315	-39.85858
70.79718	176.2280	-39.97511
70.85050	177.2904	-40.11544
70.90218	178.3179	-40.27233
70.95384	179.3451	-40.45469
71.00550	180.3714	-40.65020
71.05718	181.3948	-40.88962
71.10884	182.4182	-41.15128
71.16050	183.4408	-41.43900
71.21218	184.4618	-41.77090
71.26384	185.4794	-42.13653
71.31718	186.5297	-42.55040
71.36718	187.5125	-42.98676
71.42050	188.5578	-43.49938
71.47050	189.5363	-44.03102
71.52384	190.5755	-44.67695
71.57384	191.5480	-45.33310
71.62718	192.5813	-46.10525
71.67718	193.5479	-46.89713
71.73050	194.5747	-47.79965
71.78050	195.5359	-48.69534
71.83384	196.5583	-49.69889
71.88550	197.5479	-50.71938
71.93718	198.5352	-51.76650
71.98882	199.5212	-52.84711
72.04050	200.5059	-53.97544
72.09216	201.4879	-55.14678
72.14384	202.4670	-56.40174
72.19718	203.4744	-57.75128
72.24718	204.4166	-59.07274
72.30050	205.4203	-60.51198
72.35050	206.3595	-61.87161
72.40384	207.3636	-63.25246
72.45384	208.3109	-64.40570
72.50718	209.3333	-65.34247
72.55718	210.3088	-65.75152
72.61050	211.3790	-65.51196
72.66050	212.4170	-64.50391
72.71384	213.5626	-62.57388
72.76550	214.7075	-60.01676
72.81718	215.8749	-57.09486
72.86884	217.0467	-54.20709
72.92050	218.2069	-51.64610
72.97218	219.3495	-49.46713
73.02384	220.4751	-47.63789
73.07550	221.5860	-46.12932
73.12718	222.6836	-44.87260
73.18050	223.8047	-43.80816
73.23050	224.8482	-42.98050
73.28384	225.9520	-42.24329
73.33384	226.9816	-41.68844
73.38718	228.0744	-41.19368
73.43718	229.0944	-40.82280
73.49050	230.1792	-40.50748
73.54050	231.1940	-40.27103
73.59384	232.2722	-40.07378
73.64384	233.2821	-39.93240
73.69718	234.3572	-39.81240
73.74884	235.3965	-39.73395
73.80050	236.4352	-39.67035
73.85218	237.4734	-39.61956
73.90384	238.5115	-39.59779
73.95550	239.5474	-39.58652
74.00718	240.5840	-39.58141
74.06050	241.6524	-39.57976
74.11050	242.6536	-39.58856
74.16382	243.7216	-39.61285
74.21384	244.7222	-39.65003
74.26716	245.7900	-39.68555
74.31718	246.7899	-39.72717
74.37050	247.8562	-39.76794
74.42050	248.8562	-39.80680
74.47384	249.9219	-39.85254
74.52384	250.9216	-39.90550
74.57718	251.9872	-39.96832
74.62884	253.0202	-40.02230
74.68050	254.0522	-40.08198
74.73218	255.0846	-40.14252
74.78384	256.1179	-40.21287
74.83550	257.1492	-40.28467
74.88718	258.1819	-40.35010
74.93884	259.2137	-40.44598
74.99050	260.2455	-40.53910
75.04384	261.3095	-40.61296
75.09384	262.3076	-40.68943
75.14718	263.3736	-40.78782
75.19718	264.3713	-40.86294
75.25050	265.4350	-40.95676
75.30050	266.4336	-41.06198
75.35384	267.4966	-41.17228
75.40384	268.4945	-41.28679
75.45718	269.5532	-41.53700
75.50718	270.5471	-41.68163
75.56050	271.6106	-41.75039
-2.000000	5.000000	0.0000000