File: 1-C1(0.6mol%)+C20(0.6mol%)/matlab/160-2.txt
CLOSED
Version	1.0
Language	English
Mode	Standard
Run	8
RunSerial	11858
Instrument	DSC Q2000 V24.11 Build 124
Module	DSC Standard Cell RC
Operator	Jing
File	\\AE520-1454\TA\Data\DSC\UQ Composites\Nan\C1(5.5)+C20P(3)+CL(HotplateMixtureAB)\160-2
ProcName	Ramp
InstSerial	2000-0883
AutoSerial	1293
Sample	Iso-160-2
Size	33.2000	mg
PanMass	Not available
PanResist	Automatic Automatic  K/W
PanFactor	Default Default
Method	Ramp
Comment
Xcomment	Pan: Tzero Aluminum Hermetic
Xcomment	Gas1: Nitrogen 50.0 ml/min
Xcomment	Gas2: Nitrogen 50.0 ml/min
Text
Exotherm	UP
Kcell	1.05230
Cpconst	Standard: 0.938
Calib	-38.6961
TempCal	1	pts	157.46	156.60
TzeroDt	-87.6168 -0.0009 -1.4231
TzeroDtz	-87.6168 0.0057 6.9570
InstCalFile	Tzero: \\Ae520-1454\ta\Data\DSC\Calibration\2017\CALIBRATION\1562_RCS (90)_05_18_2017 10_50_44.TZR
InstCalFile	Baseline: \\Ae520-1454\ta\Data\DSC\Calibration\2017\2017-05-17_Calibration.001
InstCalFile	Sapphire: \\Ae520-1454\ta\Data\DSC\Calibration\2017\2017-05-17_Saphire.001
InstCalDate	Tzero 2017-05-18 Time 10:50:44
TempRange	-87.39 to 398.39 °C at 10.00 °C/min Heat Only
AutoZero	Delta T Offset 0.000 uV
AutoZero	Delta T0 Offset 0.000 uV
MultiptCal	0
MultiPtDesc	0) Not set
AutoCellConst	Calibration Date 2017-05-18 16:59:28
Controls	Gas 1  Event Off  Sampling 0.2
Cell#	RC-01562
CoolingUnit	RCS (90)
SelHeatFlow	Heat Flow T4 (mW)
AutoLidII	Installed
AutoAnalysis	Off
MacroFile
Nsig	3
Sig1	Time (min)
Sig2	Temperature (°C)
Sig3	Heat Flow (mW)
Date	2017-06-21
Time	02:09:23
OrgMethod	1: Equilibrate at 20.00 °C
OrgMethod	2: Ramp 40.00 °C/min to 160.00 °C
OrgMethod	3: Mark end of cycle 1
OrgMethod	4: Isothermal for 40.00 min
OrgMethod	5: Mark end of cycle 2
OrgMethod	6: Ramp 20.00 °C/min to 280.00 °C
OrgMethod	7: Mark end of cycle 3
OrgMethod	8: Ramp 20.00 °C/min to 20.00 °C
OrgMethod	9: Mark end of cycle 4
OrgMethod	10: Ramp 20.00 °C/min to 280.00 °C
OrgMethod	11: Mark end of cycle 5
OrgFile	C:\Users\jarra\Desktop\DSC\1-C1(0.6mol%)+C20(0.6mol%)\160-2.001
StartOfData
4.99994E-4	20.05549	0.04787460
0.05383332	20.18661	0.2585683
0.1038333	21.03146	-0.1054751
0.1571666	22.32556	-2.938934
0.2071666	23.72438	-6.276055
0.2605000	25.36450	-9.888220
0.3105000	26.99684	-12.94598
0.3638334	28.81854	-15.72166
0.4138333	30.58093	-17.85472
0.4671667	32.50930	-19.68862
0.5171667	34.35231	-21.05680
0.5705000	36.34433	-22.21875
0.6205000	38.23205	-23.09679
0.6721668	40.19791	-23.83879
0.7238332	42.17540	-24.49656
0.7755000	44.15874	-25.18838
0.8271668	46.14808	-25.75437
0.8788332	48.15448	-26.12190
0.9305000	50.16867	-26.44604
0.9821668	52.18406	-26.84558
1.033833	54.19138	-27.53216
1.083833	56.11140	-28.72052
1.137166	58.14807	-29.93252
1.187166	60.08266	-30.50380
1.240500	62.16618	-31.08551
1.290500	64.10886	-31.99871
1.343833	66.14643	-33.79622
1.393833	67.98782	-37.09170
1.447166	69.81141	-43.76528
1.497166	71.31804	-54.04858
1.550500	72.72260	-68.21262
1.600500	73.96360	-81.90226
1.653833	75.30606	-95.98172
1.703833	76.61481	-108.0907
1.755500	77.99650	-120.5482
1.807167	79.38269	-132.9702
1.858834	80.90118	-141.2527
1.910500	82.74028	-143.3868
1.962166	84.93569	-138.6222
2.013833	87.38309	-131.3814
2.065500	89.83201	-124.7247
2.117167	92.43072	-112.9004
2.167167	95.19603	-98.76538
2.220500	98.04184	-86.78451
2.270500	100.5789	-77.84070
2.323833	103.1666	-70.25612
2.373834	105.5045	-64.64795
2.427167	107.9249	-59.95170
2.477167	110.1352	-56.49350
2.530500	112.4465	-53.62832
2.580500	114.5766	-51.55785
2.633833	116.8178	-49.86130
2.683833	118.8969	-48.66454
2.737167	121.0946	-47.72104
2.787167	123.1420	-47.08044
2.838833	125.2486	-46.58194
2.890500	127.3475	-46.19253
2.942167	129.4419	-45.89098
2.993833	131.5322	-45.66818
3.045500	133.6188	-45.48609
3.097167	135.7030	-45.35634
3.148833	137.7855	-45.28764
3.200500	139.8664	-45.25494
3.250500	141.8764	-45.25817
3.303833	144.0188	-45.29275
3.353833	146.0251	-45.38181
3.407167	148.1635	-45.50457
3.457167	150.1680	-45.62332
3.505500	152.1064	-45.74509
3.557167	154.0271	-46.08848
3.608833	155.1906	-44.87434
3.660500	156.0110	-40.32202
3.712167	156.6471	-34.78062
3.763833	157.1558	-29.23496
3.815500	157.5690	-24.25572
3.867166	157.9098	-20.00288
3.917167	158.1821	-16.58524
3.970500	158.4252	-13.61074
4.020500	158.6159	-11.34932
4.073834	158.7866	-9.401899
4.123833	158.9236	-7.924908
4.177166	159.0460	-6.649145
4.227167	159.1442	-5.680470
4.280500	159.2336	-4.843010
4.330500	159.3064	-4.211216
4.383834	159.3734	-3.649748
4.433834	159.4263	-3.213960
4.487167	159.4770	-2.811865
4.537167	159.5189	-2.498158
4.588834	159.5564	-2.216747
4.640500	159.5894	-1.973840
4.692166	159.6189	-1.768353
4.743834	159.6453	-1.590655
4.795500	159.6687	-1.428782
4.847166	159.6895	-1.284110
4.898834	159.7075	-1.157593
4.950500	159.7250	-1.042057
5.000500	159.7385	-0.9398306
5.053834	159.7535	-0.8381778
5.103833	159.7652	-0.7443904
5.157166	159.7767	-0.6509443
5.207167	159.7874	-0.5630169
5.260500	159.7975	-0.4763196
5.310500	159.8070	-0.3935605
5.363834	159.8157	-0.3075296
5.413832	159.8234	-0.2280374
5.467168	159.8313	-0.1406114
5.517168	159.8389	-.06308035
5.570500	159.8460	0.01958197
5.620500	159.8524	0.09946719
5.672168	159.8592	0.1773647
5.723834	159.8650	0.2600608
5.775500	159.8716	0.3407178
5.827168	159.8772	0.4239290
5.878834	159.8831	0.5058720
5.930500	159.8887	0.5910271
5.982168	159.8942	0.6735434
6.033832	159.8998	0.7623247
6.083832	159.9060	0.8445480
6.137168	159.9110	0.9370680
6.187168	159.9164	1.025323
6.240500	159.9217	1.120893
6.290500	159.9276	1.208612
6.343834	159.9329	1.306380
6.393832	159.9384	1.399592
6.447168	159.9435	1.498951
6.497168	159.9487	1.593766
6.550500	159.9546	1.693459
6.600500	159.9596	1.788748
6.653832	159.9656	1.893178
6.703832	159.9704	1.996603
6.755500	159.9765	2.099234
6.807166	159.9822	2.205301
6.858832	159.9876	2.310638
6.910500	159.9932	2.421984
6.962168	159.9995	2.529831
7.013834	160.0051	2.646365
7.065500	160.0110	2.759237
7.117166	160.0170	2.876227
7.167168	160.0235	2.995808
7.220500	160.0295	3.117299
7.270500	160.0355	3.234485
7.323834	160.0419	3.366470
7.373834	160.0480	3.485812
7.427168	160.0552	3.622311
7.477168	160.0622	3.745624
7.530500	160.0686	3.889817
7.580500	160.0753	4.016395
7.633832	160.0830	4.160799
7.683832	160.0898	4.290662
7.737168	160.0973	4.435379
7.787168	160.1037	4.572180
7.838834	160.1111	4.713408
7.890500	160.1179	4.859703
7.942168	160.1257	5.005538
7.993834	160.1327	5.152522
8.045500	160.1410	5.304482
8.097168	160.1479	5.454574
8.148834	160.1554	5.604359
8.200500	160.1631	5.756319
8.250500	160.1708	5.898394
8.303832	160.1786	6.055390
8.353832	160.1856	6.202601
8.407166	160.1938	6.357587
8.457168	160.2010	6.502416
8.510499	160.2087	6.651078
8.560500	160.2158	6.796016
8.613834	160.2237	6.949753
8.663834	160.2301	7.091132
8.717168	160.2390	7.250955
8.767168	160.2465	7.405651
8.820500	160.2549	7.580734
8.870499	160.2637	7.763140
8.922168	160.2737	7.968940
8.973832	160.2847	8.203413
9.025499	160.2969	8.459712
9.077168	160.3102	8.745828
9.128834	160.3257	9.066832
9.180500	160.3424	9.434041
9.232166	160.3622	9.839274
9.283832	160.3837	10.29161
9.333832	160.4067	10.76098
9.387168	160.4324	11.29159
9.437166	160.4588	11.80909
9.490500	160.4861	12.36812
9.540500	160.5108	12.88353
9.593832	160.5379	13.41928
9.643832	160.5621	13.89595
9.697168	160.5866	14.37815
9.747168	160.6072	14.78599
9.800500	160.6271	15.16942
9.850500	160.6434	15.48923
9.903832	160.6592	15.77178
9.953834	160.6709	15.98808
10.00550	160.6800	16.15550
10.05717	160.6871	16.27523
10.10883	160.6914	16.34325
10.16050	160.6931	16.36874
10.21217	160.6944	16.36975
10.26383	160.6922	16.34632
10.31550	160.6893	16.26254
10.36717	160.6851	16.16600
10.41717	160.6810	16.05629
10.47050	160.6744	15.93365
10.52050	160.6688	15.80618
10.57383	160.6625	15.66725
10.62383	160.6559	15.53975
10.67717	160.6494	15.40106
10.72717	160.6425	15.27199
10.78050	160.6367	15.13126
10.83050	160.6304	15.00882
10.88383	160.6238	14.88113
10.93383	160.6173	14.76208
10.98717	160.6120	14.64608
11.03717	160.6067	14.53867
11.08883	160.6016	14.43802
11.14050	160.5973	14.34270
11.19217	160.5928	14.25116
11.24384	160.5878	14.16678
11.29550	160.5840	14.08789
11.34717	160.5812	14.02060
11.39883	160.5778	13.95867
11.45050	160.5744	13.90614
11.50050	160.5733	13.85672
11.55383	160.5701	13.81881
11.60383	160.5694	13.78935
11.65717	160.5674	13.76980
11.70717	160.5674	13.76097
11.76050	160.5660	13.75562
11.81050	160.5669	13.75345
11.86383	160.5683	13.75942
11.91383	160.5699	13.79054
11.96717	160.5720	13.85580
12.01717	160.5753	13.92724
12.07050	160.5800	14.01230
12.12050	160.5834	14.10844
12.17217	160.5878	14.21456
12.22383	160.5936	14.33664
12.27550	160.6006	14.47168
12.32717	160.6066	14.61420
12.37884	160.6142	14.76779
12.43050	160.6226	14.93346
12.48217	160.6308	15.10254
12.53383	160.6398	15.28322
12.58383	160.6482	15.45899
12.63717	160.6585	15.65208
12.68716	160.6667	15.83326
12.74050	160.6762	16.02354
12.79050	160.6850	16.19703
12.84383	160.6939	16.36838
12.89383	160.7006	16.50941
12.94717	160.7080	16.63028
12.99717	160.7111	16.69896
13.05050	160.7138	16.72686
13.10050	160.7127	16.71865
13.15383	160.7094	16.60056
13.20383	160.7023	16.42798
13.25550	160.6924	16.18939
13.30717	160.6786	15.88312
13.35883	160.6618	15.51897
13.41050	160.6421	15.10522
13.46217	160.6210	14.65218
13.51383	160.5962	14.16515
13.56550	160.5722	13.65786
13.61716	160.5462	13.13368
13.66716	160.5221	12.62556
13.72050	160.4960	12.07672
13.77050	160.4700	11.57348
13.82384	160.4436	11.04175
13.87384	160.4194	10.55256
13.92717	160.3948	10.03880
13.97717	160.3708	9.565575
14.03050	160.3465	9.066192
14.08050	160.3228	8.610129
14.13383	160.3007	8.133709
14.18383	160.2780	7.700266
14.23716	160.2553	7.249497
14.28717	160.2363	6.837524
14.33883	160.2155	6.439395
14.39050	160.1958	6.053046
14.44217	160.1775	5.685771
14.49384	160.1603	5.339729
14.54550	160.1431	5.008828
14.59717	160.1265	4.689534
14.64883	160.1118	4.388128
14.70050	160.0973	4.102194
14.75050	160.0836	3.837728
14.80383	160.0703	3.571494
14.85383	160.0586	3.334134
14.90717	160.0460	3.090710
14.95717	160.0356	2.877564
15.01050	160.0242	2.659581
15.06050	160.0151	2.463440
15.11383	160.0047	2.268725
15.16383	159.9968	2.090138
15.21716	159.9873	1.913663
15.26717	159.9798	1.754920
15.32050	159.9724	1.596652
15.37050	159.9645	1.454345
15.42217	159.9577	1.318972
15.47383	159.9512	1.184445
15.52550	159.9450	1.062785
15.57717	159.9388	0.9491594
15.62883	159.9336	0.8374519
15.68050	159.9282	0.7355228
15.73216	159.9233	0.6349301
15.78383	159.9180	0.5382441
15.83383	159.9146	0.4533102
15.88716	159.9099	0.3635261
15.93717	159.9057	0.2855790
15.99050	159.9024	0.2067982
16.04050	159.8982	0.1338017
16.09383	159.8944	0.06156174
16.14383	159.8912	-2.6910E-3
16.19717	159.8873	-.06730089
16.24716	159.8852	-0.1262735
16.30050	159.8817	-0.1831215
16.35050	159.8793	-0.2357008
16.40383	159.8761	-0.2916025
16.45383	159.8743	-0.3386040
16.50550	159.8720	-0.3846124
16.55716	159.8696	-0.4248934
16.60883	159.8675	-0.4697083
16.66050	159.8651	-0.5102600
16.71216	159.8633	-0.5456586
16.76383	159.8617	-0.5803328
16.81550	159.8594	-0.6145743
16.86716	159.8582	-0.6465422
16.91716	159.8562	-0.6763876
16.97050	159.8550	-0.7070532
17.02050	159.8537	-0.7344980
17.07383	159.8519	-0.7609884
17.12383	159.8511	-0.7844056
17.17716	159.8499	-0.8086248
17.22716	159.8483	-0.8329678
17.28050	159.8474	-0.8531168
17.33050	159.8469	-0.8726486
17.38383	159.8455	-0.8921705
17.43383	159.8444	-0.9092974
17.48716	159.8441	-0.9276100
17.53717	159.8427	-0.9435401
17.58883	159.8421	-0.9589468
17.64050	159.8411	-0.9756049
17.69216	159.8407	-0.9890128
17.74383	159.8395	-1.002612
17.79550	159.8389	-1.016574
17.84716	159.8380	-1.028538
17.89883	159.8376	-1.040657
17.95050	159.8369	-1.052208
18.00050	159.8362	-1.062436
18.05383	159.8358	-1.073671
18.10383	159.8359	-1.084535
18.15716	159.8352	-1.095245
18.20716	159.8340	-1.104905
18.26050	159.8345	-1.115064
18.31050	159.8343	-1.124608
18.36383	159.8337	-1.134489
18.41383	159.8326	-1.143494
18.46716	159.8330	-1.152593
18.51716	159.8330	-1.161164
18.57050	159.8309	-1.170002
18.62050	159.8308	-1.177750
18.67216	159.8311	-1.185654
18.72383	159.8304	-1.193622
18.77550	159.8304	-1.201039
18.82716	159.8294	-1.208293
18.87883	159.8299	-1.215125
18.93050	159.8295	-1.221856
18.98216	159.8290	-1.228415
19.03383	159.8284	-1.234531
19.08383	159.8284	-1.240559
19.13716	159.8283	-1.246736
19.18716	159.8281	-1.252149
19.24050	159.8281	-1.258252
19.29050	159.8268	-1.263801
19.34383	159.8281	-1.269570
19.39383	159.8279	-1.274962
19.44716	159.8270	-1.280024
19.49716	159.8270	-1.284340
19.55050	159.8273	-1.289188
19.60050	159.8275	-1.293451
19.65383	159.8272	-1.298086
19.70383	159.8268	-1.302593
19.75550	159.8270	-1.306942
19.80716	159.8265	-1.311288
19.85883	159.8272	-1.315478
19.91050	159.8264	-1.319272
19.96216	159.8261	-1.322638
20.01383	159.8262	-1.325513
20.06550	159.8257	-1.328209
20.11716	159.8254	-1.330919
20.16716	159.8259	-1.333531
20.22050	159.8259	-1.336450
20.27050	159.8242	-1.339261
20.32383	159.8245	-1.342064
20.37383	159.8246	-1.345017
20.42716	159.8242	-1.347936
20.47716	159.8249	-1.350839
20.53050	159.8235	-1.353684
20.58050	159.8236	-1.356116
20.63383	159.8239	-1.358343
20.68383	159.8236	-1.360501
20.73716	159.8237	-1.362794
20.78717	159.8228	-1.365042
20.83883	159.8236	-1.367448
20.89050	159.8232	-1.369726
20.94216	159.8234	-1.372212
20.99383	159.8241	-1.374918
21.04550	159.8237	-1.377616
21.09716	159.8239	-1.380396
21.14883	159.8239	-1.383238
21.20050	159.8245	-1.385858
21.25050	159.8241	-1.388199
21.30383	159.8243	-1.390424
21.35383	159.8242	-1.392120
21.40716	159.8234	-1.393682
21.45717	159.8232	-1.394835
21.51050	159.8231	-1.395726
21.56050	159.8234	-1.396821
21.61383	159.8231	-1.397906
21.66383	159.8227	-1.398963
21.71716	159.8226	-1.400218
21.76716	159.8221	-1.401451
21.82050	159.8222	-1.402759
21.87050	159.8218	-1.404036
21.92216	159.8208	-1.404839
21.97383	159.8214	-1.406073
22.02550	159.8212	-1.407873
22.07716	159.8215	-1.409697
22.12883	159.8217	-1.411496
22.18050	159.8213	-1.413242
22.23216	159.8218	-1.415141
22.28383	159.8225	-1.417420
22.33383	159.8227	-1.419306
22.38716	159.8222	-1.421111
22.43716	159.8211	-1.422730
22.49050	159.8214	-1.424380
22.54050	159.8214	-1.425852
22.59383	159.8209	-1.426856
22.64383	159.8211	-1.427777
22.69716	159.8208	-1.428489
22.74716	159.8209	-1.428995
22.80050	159.8212	-1.429381
22.85050	159.8201	-1.429646
22.90383	159.8211	-1.430346
22.95383	159.8211	-1.431520
23.00550	159.8209	-1.432692
23.05716	159.8201	-1.433792
23.10883	159.8213	-1.434852
23.16050	159.8208	-1.436105
23.21216	159.8205	-1.437207
23.26383	159.8214	-1.438840
23.31550	159.8208	-1.440504
23.36716	159.8211	-1.441859
23.41716	159.8205	-1.443108
23.47050	159.8215	-1.444538
23.52050	159.8224	-1.445624
23.57383	159.8206	-1.446551
23.62383	159.8214	-1.447358
23.67717	159.8214	-1.448263
23.72716	159.8208	-1.449069
23.78050	159.8211	-1.449842
23.83050	159.8207	-1.450433
23.88383	159.8205	-1.450786
23.93383	159.8201	-1.451059
23.98716	159.8194	-1.451259
24.03717	159.8196	-1.451431
24.08883	159.8200	-1.451529
24.14050	159.8204	-1.451827
24.19216	159.8198	-1.452323
24.24383	159.8196	-1.452716
24.29550	159.8196	-1.453326
24.34716	159.8200	-1.454191
24.39883	159.8198	-1.455019
24.45050	159.8198	-1.456304
24.50050	159.8202	-1.457554
24.55383	159.8207	-1.458944
24.60383	159.8201	-1.460140
24.65716	159.8202	-1.461268
24.70717	159.8207	-1.462336
24.76050	159.8201	-1.463066
24.81050	159.8204	-1.463569
24.86383	159.8196	-1.464009
24.91383	159.8200	-1.464205
24.96716	159.8198	-1.464530
25.01716	159.8197	-1.464788
25.07050	159.8201	-1.465317
25.12050	159.8202	-1.466053
25.17216	159.8198	-1.467076
25.22383	159.8203	-1.468030
25.27550	159.8211	-1.468727
25.32716	159.8201	-1.469439
25.37883	159.8197	-1.469456
25.43050	159.8196	-1.469823
25.48216	159.8198	-1.469945
25.53383	159.8198	-1.470067
25.58383	159.8195	-1.470252
25.63716	159.8190	-1.470265
25.68717	159.8192	-1.470233
25.74050	159.8192	-1.470472
25.79050	159.8186	-1.470494
25.84383	159.8191	-1.470998
25.89383	159.8192	-1.471912
25.94717	159.8187	-1.472879
25.99716	159.8201	-1.474030
26.05050	159.8199	-1.475236
26.10050	159.8195	-1.476175
26.15383	159.8193	-1.477230
26.20383	159.8193	-1.478002
26.25550	159.8191	-1.478486
26.30716	159.8187	-1.478900
26.35883	159.8198	-1.479224
26.41050	159.8194	-1.479309
26.46216	159.8192	-1.479476
26.51383	159.8194	-1.479683
26.56550	159.8195	-1.480155
26.61716	159.8191	-1.480670
26.66716	159.8193	-1.481114
26.72050	159.8198	-1.481768
26.77050	159.8190	-1.482498
26.82383	159.8202	-1.483057
26.87383	159.8202	-1.483823
26.92717	159.8201	-1.484209
26.97717	159.8197	-1.484634
27.03050	159.8199	-1.485064
27.08050	159.8196	-1.485156
27.13383	159.8195	-1.485306
27.18383	159.8197	-1.485484
27.23716	159.8204	-1.485889
27.28717	159.8196	-1.486305
27.33883	159.8198	-1.486662
27.39050	159.8194	-1.486838
27.44216	159.8198	-1.487030
27.49383	159.8184	-1.487257
27.54550	159.8192	-1.487171
27.59716	159.8185	-1.487126
27.64883	159.8186	-1.487047
27.70050	159.8182	-1.487158
27.75050	159.8186	-1.487444
27.80383	159.8181	-1.487768
27.85383	159.8181	-1.487761
27.90716	159.8184	-1.488269
27.95716	159.8183	-1.488296
28.01050	159.8184	-1.488576
28.06050	159.8183	-1.489268
28.11383	159.8180	-1.489781
28.16383	159.8179	-1.490162
28.21716	159.8188	-1.490518
28.26716	159.8179	-1.491128
28.32050	159.8179	-1.491914
28.37050	159.8183	-1.492378
28.42216	159.8183	-1.492688
28.47383	159.8184	-1.493176
28.52550	159.8186	-1.493513
28.57717	159.8186	-1.493967
28.62883	159.8188	-1.494469
28.68050	159.8190	-1.495108
28.73216	159.8187	-1.495731
28.78383	159.8184	-1.496434
28.83383	159.8192	-1.497105
28.88716	159.8188	-1.497827
28.93717	159.8191	-1.498486
28.99050	159.8188	-1.498980
29.04050	159.8198	-1.499570
29.09383	159.8186	-1.499930
29.14383	159.8191	-1.500147
29.19717	159.8188	-1.500353
29.24716	159.8186	-1.500354
29.30050	159.8181	-1.500119
29.35050	159.8184	-1.499839
29.40383	159.8181	-1.499589
29.45383	159.8175	-1.499486
29.50550	159.8184	-1.499386
29.55716	159.8181	-1.499636
29.60883	159.8186	-1.500179
29.66050	159.8185	-1.500770
29.71216	159.8186	-1.501117
29.76383	159.8184	-1.501798
29.81550	159.8187	-1.502354
29.86716	159.8188	-1.502834
29.91716	159.8192	-1.503537
29.97050	159.8193	-1.504028
30.02050	159.8190	-1.504668
30.07383	159.8195	-1.505365
30.12383	159.8198	-1.505462
30.17717	159.8199	-1.505763
30.22717	159.8196	-1.506382
30.28050	159.8192	-1.506521
30.33050	159.8188	-1.506824
30.38383	159.8196	-1.506942
30.43383	159.8190	-1.507212
30.48716	159.8193	-1.507319
30.53717	159.8191	-1.507435
30.58883	159.8196	-1.507358
30.64050	159.8194	-1.507238
30.69216	159.8191	-1.507114
30.74383	159.8189	-1.507102
30.79550	159.8184	-1.506967
30.84716	159.8183	-1.506984
30.89883	159.8186	-1.506936
30.95050	159.8182	-1.507182
31.00050	159.8180	-1.506756
31.05383	159.8184	-1.506451
31.10383	159.8181	-1.506286
31.15716	159.8180	-1.506396
31.20716	159.8183	-1.506768
31.26050	159.8181	-1.507376
31.31050	159.8184	-1.508122
31.36383	159.8175	-1.508956
31.41383	159.8189	-1.509360
31.46716	159.8193	-1.509972
31.51716	159.8184	-1.510448
31.57050	159.8193	-1.510779
31.62050	159.8187	-1.511144
31.67216	159.8187	-1.511265
31.72383	159.8192	-1.511740
31.77550	159.8184	-1.512179
31.82717	159.8186	-1.512624
31.87883	159.8190	-1.512797
31.93050	159.8185	-1.512864
31.98216	159.8186	-1.512752
32.03383	159.8188	-1.512648
32.08383	159.8184	-1.512520
32.13716	159.8186	-1.512179
32.18716	159.8183	-1.511812
32.24050	159.8173	-1.511524
32.29050	159.8180	-1.511138
32.34384	159.8175	-1.511047
32.39383	159.8169	-1.511064
32.44717	159.8177	-1.511043
32.49716	159.8170	-1.511304
32.55050	159.8166	-1.511632
32.60050	159.8174	-1.511698
32.65383	159.8173	-1.511798
32.70383	159.8165	-1.512111
32.75550	159.8174	-1.512450
32.80716	159.8172	-1.513166
32.85883	159.8174	-1.513966
32.91050	159.8177	-1.514818
32.96216	159.8176	-1.515539
33.01383	159.8179	-1.516248
33.06550	159.8181	-1.516872
33.11716	159.8176	-1.517516
33.16716	159.8183	-1.517742
33.22050	159.8182	-1.518093
33.27050	159.8180	-1.518464
33.32383	159.8181	-1.518423
33.37383	159.8188	-1.518605
33.42717	159.8183	-1.518740
33.47717	159.8190	-1.518878
33.53050	159.8190	-1.519216
33.58050	159.8183	-1.518893
33.63383	159.8187	-1.518561
33.68384	159.8177	-1.518452
33.73717	159.8186	-1.518135
33.78717	159.8181	-1.518082
33.83883	159.8184	-1.517979
33.89050	159.8185	-1.517945
33.94216	159.8181	-1.518024
33.99383	159.8182	-1.518549
34.04550	159.8182	-1.518674
34.09716	159.8189	-1.518972
34.14883	159.8183	-1.519450
34.20050	159.8184	-1.519802
34.25050	159.8188	-1.520295
34.30383	159.8187	-1.520646
34.35383	159.8184	-1.521011
34.40716	159.8184	-1.521180
34.45716	159.8188	-1.520783
34.51050	159.8182	-1.520590
34.56050	159.8180	-1.520521
34.61383	159.8173	-1.520109
34.66383	159.8187	-1.519930
34.71716	159.8173	-1.519781
34.76716	159.8178	-1.519519
34.82050	159.8180	-1.519228
34.87050	159.8172	-1.518937
34.92216	159.8174	-1.518779
34.97383	159.8176	-1.519269
35.02550	159.8185	-1.519679
35.07717	159.8182	-1.520247
35.12883	159.8186	-1.520978
35.18050	159.8187	-1.521655
35.23216	159.8187	-1.522260
35.28383	159.8182	-1.522820
35.33383	159.8183	-1.522791
35.38716	159.8179	-1.522781
35.43716	159.8182	-1.523076
35.49050	159.8181	-1.523120
35.54050	159.8186	-1.523289
35.59384	159.8184	-1.523563
35.64383	159.8193	-1.523861
35.69717	159.8177	-1.524196
35.74716	159.8179	-1.523996
35.80050	159.8175	-1.523636
35.85050	159.8182	-1.523636
35.90383	159.8184	-1.523320
35.95383	159.8173	-1.523109
36.00550	159.8173	-1.522665
36.05716	159.8168	-1.522394
36.10883	159.8178	-1.522215
36.16050	159.8170	-1.522186
36.21216	159.8176	-1.521748
36.26383	159.8172	-1.521748
36.31550	159.8172	-1.521968
36.36716	159.8176	-1.522106
36.41716	159.8184	-1.522494
36.47050	159.8181	-1.523350
36.52050	159.8189	-1.524174
36.57383	159.8184	-1.525065
36.62383	159.8190	-1.525637
36.67717	159.8190	-1.525974
36.72717	159.8186	-1.526498
36.78050	159.8193	-1.526838
36.83050	159.8188	-1.526990
36.88383	159.8186	-1.526849
36.93384	159.8184	-1.526460
36.98717	159.8177	-1.525862
37.03717	159.8175	-1.525474
37.08883	159.8174	-1.524785
37.14050	159.8175	-1.524342
37.19216	159.8177	-1.523917
37.24383	159.8170	-1.523476
37.29550	159.8173	-1.523247
37.34716	159.8177	-1.523329
37.39883	159.8167	-1.523487
37.45050	159.8170	-1.524128
37.50050	159.8173	-1.524617
37.55383	159.8183	-1.525334
37.60383	159.8170	-1.525952
37.65716	159.8182	-1.526714
37.70716	159.8176	-1.527514
37.76050	159.8186	-1.528239
37.81050	159.8185	-1.528759
37.86383	159.8181	-1.529178
37.91383	159.8186	-1.529466
37.96716	159.8186	-1.529138
38.01716	159.8180	-1.528909
38.07050	159.8177	-1.528542
38.12050	159.8170	-1.528110
38.17216	159.8171	-1.527810
38.22383	159.8176	-1.527631
38.27550	159.8182	-1.527454
38.32717	159.8179	-1.527154
38.37883	159.8176	-1.526989
38.43050	159.8176	-1.527145
38.48216	159.8177	-1.527481
38.53383	159.8173	-1.527871
38.58383	159.8179	-1.528257
38.63716	159.8175	-1.528519
38.68716	159.8177	-1.528703
38.74050	159.8179	-1.528892
38.79050	159.8184	-1.529096
38.84384	159.8181	-1.529404
38.89383	159.8183	-1.529770
38.94717	159.8186	-1.530342
38.99716	159.8186	-1.530831
39.05050	159.8194	-1.531140
39.10050	159.8190	-1.531386
39.15383	159.8180	-1.531421
39.20383	159.8187	-1.531692
39.25550	159.8183	-1.531548
39.30716	159.8182	-1.531290
39.35883	159.8180	-1.530763
39.41050	159.8185	-1.530120
39.46216	159.8174	-1.529456
39.51383	159.8171	-1.528859
39.56550	159.8173	-1.528378
39.61716	159.8167	-1.527862
39.66716	159.8166	-1.527327
39.72050	159.8170	-1.527016
39.77050	159.8172	-1.527062
39.82383	159.8176	-1.527216
39.87383	159.8172	-1.527696
39.92717	159.8178	-1.528306
39.97717	159.8172	-1.528837
40.03050	159.8171	-1.529585
40.08050	159.8172	-1.530141
40.13383	159.8172	-1.530276
40.18384	159.8168	-1.530689
40.23717	159.8174	-1.530986
40.28717	159.8175	-1.531190
40.33883	159.8175	-1.531705
40.39050	159.8176	-1.532136
40.44216	159.8175	-1.532478
40.49383	159.8176	-1.532761
40.54550	159.8181	-1.532976
40.59716	159.8183	-1.533266
40.64883	159.8182	-1.533469
40.70050	159.8184	-1.533712
40.75050	159.8188	-1.533856
40.80383	159.8185	-1.533812
40.85383	159.8182	-1.533860
40.90716	159.8178	-1.533870
40.95716	159.8180	-1.534052
41.01050	159.8187	-1.534020
41.06050	159.8182	-1.533974
41.11383	159.8181	-1.533877
41.16383	159.8190	-1.533807
41.21717	159.8186	-1.533939
41.26717	159.8179	-1.533999
41.32050	159.8180	-1.533947
41.37050	159.8184	-1.534197
41.42216	159.8186	-1.534134
41.47383	159.8177	-1.534116
41.52550	159.8182	-1.534087
41.57717	159.8186	-1.533904
41.62883	159.8181	-1.533578
41.68050	159.8179	-1.533449
41.73217	159.8180	-1.533576
41.78383	159.8190	-1.533818
41.83383	159.8177	-1.533803
41.88716	159.8186	-1.533516
41.93716	159.8182	-1.533294
41.99050	159.8181	-1.533031
42.04050	159.8179	-1.532790
42.09384	159.8176	-1.532655
42.14383	159.8168	-1.532275
42.19717	159.8168	-1.531684
42.24716	159.8158	-1.531388
42.30050	159.8168	-1.530770
42.35050	159.8168	-1.530552
42.40383	159.8171	-1.530575
42.45383	159.8174	-1.530732
42.50550	159.8170	-1.531163
42.55717	159.8170	-1.531408
42.60883	159.8172	-1.531955
42.66050	159.8170	-1.532473
42.71216	159.8173	-1.532978
42.76383	159.8166	-1.533270
42.81550	159.8170	-1.533676
42.86716	159.8172	-1.533872
42.91716	159.8178	-1.534009
42.97050	159.8176	-1.534001
43.02050	159.8172	-1.533909
43.07383	159.8170	-1.534060
43.12383	159.8172	-1.534272
43.17717	159.8168	-1.534255
43.22717	159.8184	-1.534662
43.28050	159.8180	-1.535330
43.33050	159.8180	-1.535681
43.38383	159.8186	-1.536029
43.43383	159.8182	-1.536310
43.48717	159.8183	-1.536571
43.53383	159.8285	-1.538206
43.58383	160.0971	-1.697627
43.63716	160.6725	-3.764363
43.68716	161.3168	-6.572345
43.74050	162.0900	-9.691092
43.79050	162.8691	-12.37578
43.84384	163.7467	-14.83244
43.89383	164.6018	-16.74221
43.94717	165.5427	-18.40813
43.99716	166.4457	-19.67497
44.05050	167.4267	-20.76328
44.10050	168.3604	-21.59730
44.15383	169.3660	-22.33412
44.20383	170.3186	-22.90566
44.25550	171.3082	-23.40218
44.30717	172.3054	-23.82588
44.35883	173.3057	-24.19966
44.41050	174.3107	-24.52434
44.46216	175.3170	-24.81666
44.51383	176.3272	-25.08874
44.56550	177.3395	-25.35064
44.61716	178.3517	-25.59946
44.66716	179.3346	-25.83484
44.72050	180.3828	-26.08525
44.77050	181.3664	-26.32917
44.82383	182.4164	-26.59670
44.87383	183.4004	-26.85678
44.92717	184.4513	-27.14334
44.97717	185.4368	-27.42339
45.03050	186.4875	-27.72814
45.08050	187.4719	-28.02834
45.13383	188.5212	-28.36487
45.18383	189.5049	-28.69548
45.23717	190.5540	-29.08154
45.28717	191.5370	-29.45779
45.33883	192.5516	-29.87208
45.39050	193.5643	-30.31356
45.44217	194.5762	-30.78236
45.49383	195.5878	-31.27499
45.54550	196.5983	-31.80748
45.59716	197.6076	-32.28494
45.64883	198.6229	-32.72219
45.70050	199.6353	-33.20120
45.75050	200.6120	-33.72694
45.80383	201.6525	-34.34041
45.85383	202.6251	-34.99602
45.90717	203.6584	-35.76611
45.95717	204.6231	-36.59816
46.01050	205.6470	-37.61527
46.06050	206.5996	-38.72046
46.11383	207.6099	-40.06576
46.16383	208.5446	-41.61514
46.21717	209.5253	-43.64280
46.26717	210.4269	-45.96264
46.32050	211.3672	-48.89612
46.37050	212.2310	-52.02994
46.42216	213.1076	-55.57200
46.47383	213.9734	-59.34802
46.52550	214.8317	-63.24250
46.57717	215.6895	-67.09098
46.62883	216.5559	-70.69926
46.68050	217.4376	-73.91763
46.73217	218.3484	-76.36158
46.78383	219.3297	-76.72710
46.83383	220.4094	-74.10962
46.88716	221.6576	-69.76829
46.93716	222.8705	-64.95557
46.99050	224.1937	-59.21980
47.04050	225.4517	-53.62766
47.09384	226.7739	-48.40994
47.14383	227.9716	-44.44814
47.19717	229.2063	-41.10869
47.24716	230.3332	-38.65363
47.30050	231.5045	-36.60383
47.35050	232.5817	-35.10227
47.40383	233.7130	-33.86194
47.45383	234.7614	-32.94746
47.50550	235.8328	-32.21848
47.55717	236.8980	-31.64066
47.60883	237.9549	-31.20381
47.66050	239.0074	-30.86832
47.71216	240.0557	-30.61150
47.76383	241.1005	-30.41906
47.81550	242.1433	-30.28112
47.86716	243.1845	-30.17810
47.91716	244.1910	-30.11150
47.97050	245.2625	-30.05473
48.02050	246.2674	-30.01832
48.07383	247.3377	-30.00122
48.12383	248.3392	-29.98438
48.17717	249.4090	-29.97655
48.22717	250.4114	-29.97137
48.28050	251.4807	-29.96861
48.33050	252.4823	-29.96825
48.38383	253.5496	-29.97074
48.43383	254.5520	-29.97524
48.48717	255.6189	-29.98785
48.53717	256.6206	-30.02133
48.58883	257.6535	-30.05855
48.64050	258.6885	-30.09260
48.69217	259.7220	-30.13838
48.74383	260.7561	-30.18208
48.79550	261.7880	-30.22237
48.84716	262.8216	-30.26572
48.89883	263.8557	-30.31855
48.95050	264.8890	-30.36908
49.00050	265.8888	-30.41676
49.05383	266.9547	-30.47570
49.10383	267.9537	-30.51900
49.15717	269.0202	-30.57588
49.20717	270.0203	-30.63580
49.26050	271.0865	-30.69025
49.31050	272.0860	-30.73224
49.36383	273.1518	-30.79464
49.41383	274.1516	-30.84087
49.46717	275.2184	-30.90228
49.51383	276.1514	-30.94824
49.56550	276.8951	-31.42065
49.61716	276.8880	-28.63342
49.66716	276.6199	-22.77092
49.72050	276.1513	-15.69087
49.77050	275.6024	-9.407793
49.82383	274.9237	-3.568765
49.87383	274.2197	1.015007
49.92717	273.4120	5.018840
49.97717	272.6129	8.074176
50.03050	271.7226	10.71266
50.08050	270.8592	12.71667
50.13383	269.9141	14.45288
50.18383	269.0097	15.77623
50.23717	268.0281	16.92984
50.28717	267.0957	17.82867
50.33883	266.1212	18.58338
50.39050	265.1369	19.22005
50.44217	264.1461	19.73986
50.49383	263.1492	20.17893
50.54550	262.1472	20.53827
50.59716	261.1414	20.84912
50.64883	260.1316	21.10350
50.70050	259.1192	21.32636
50.75050	258.1371	21.50863
50.80383	257.0875	21.67705
50.85383	256.1006	21.81153
50.90717	255.0468	21.93281
50.95717	254.0583	22.03752
51.01050	253.0030	22.13123
51.06050	252.0126	22.20724
51.11383	250.9548	22.26949
51.16383	249.9626	22.32881
51.21717	248.9050	22.38345
51.26716	247.9116	22.43002
51.32050	246.8528	22.47346
51.37050	245.8594	22.50269
51.42217	244.8324	22.53552
51.47383	243.8047	22.56635
51.52550	242.7768	22.58422
51.57717	241.7483	22.59877
51.62883	240.7208	22.60907
51.68050	239.6923	22.61990
51.73217	238.6642	22.63554
51.78383	237.6353	22.65007
51.83383	236.6389	22.65892
51.88716	235.5760	22.67192
51.93716	234.5816	22.67990
51.99050	233.5198	22.68721
52.04050	232.5237	22.69348
52.09384	231.4610	22.69879
52.14384	230.4660	22.70356
52.19717	229.4031	22.70864
52.24717	228.4083	22.71356
52.30050	227.3456	22.72179
52.35050	226.3492	22.72899
52.40383	225.2870	22.73608
52.45383	224.2910	22.74460
52.50550	223.2615	22.75270
52.55717	222.2322	22.76042
52.60883	221.2023	22.76781
52.66050	220.1723	22.77470
52.71216	219.1425	22.78205
52.76382	218.1131	22.78917
52.81550	217.0834	22.79503
52.86716	216.0537	22.79932
52.91716	215.0576	22.80274
52.97050	213.9944	22.80574
53.02050	212.9980	22.80792
53.07383	211.9348	22.80998
53.12383	210.9393	22.81140
53.17717	209.8756	22.81258
53.22717	208.8787	22.81435
53.28050	207.8153	22.81580
53.33050	206.8193	22.81662
53.38383	205.7564	22.81704
53.43383	204.7592	22.81680
53.48717	203.6968	22.81687
53.53716	202.6992	22.81676
53.58882	201.6694	22.81559
53.64050	200.6393	22.81378
53.69216	199.6090	22.81222
53.74382	198.5795	22.81047
53.79550	197.5486	22.80890
53.84716	196.5186	22.80672
53.89883	195.4877	22.80437
53.95050	194.4570	22.80260
54.00050	193.4602	22.80132
54.05383	192.3966	22.79897
54.10383	191.3994	22.79646
54.15717	190.3357	22.79398
54.20717	189.3388	22.78949
54.26050	188.2758	22.78567
54.31050	187.2789	22.78171
54.36382	186.2156	22.77771
54.41382	185.2190	22.77448
54.46717	184.1544	22.77077
54.51716	183.1569	22.76660
54.57050	182.0936	22.76219
54.62050	181.0960	22.75707
54.67217	180.0665	22.75156
54.72382	179.0358	22.74740
54.77550	178.0052	22.74389
54.82717	176.9748	22.74208
54.87883	175.9450	22.74108
54.93050	174.9130	22.74078
54.98217	173.8832	22.74117
55.03383	172.8516	22.74135
55.08383	171.8553	22.74037
55.13716	170.7910	22.73882
55.18716	169.7939	22.73686
55.24050	168.7307	22.73609
55.29050	167.7335	22.74262
55.34384	166.6729	22.80620
55.39384	165.6813	22.96066
55.44717	164.6316	23.26577
55.49717	163.6554	23.81088
55.55050	162.6346	24.86047
55.60050	161.7067	26.48894
55.65383	160.7558	29.10268
55.70383	159.9072	32.39085
55.75550	159.0660	36.41744
55.80717	158.2451	40.71334
55.85883	157.4249	44.84994
55.91050	156.5852	48.46731
55.96216	155.7123	51.30514
56.01382	154.7977	53.22865
56.06550	153.8338	54.20474
56.11716	152.8239	54.23040
56.16716	151.8046	53.43336
56.22050	150.6750	51.80420
56.27050	149.5849	49.70556
56.32383	148.3984	47.05488
56.37383	147.2708	44.38450
56.42717	146.0675	41.56368
56.47717	144.9437	39.10840
56.53050	143.7584	36.77764
56.58050	142.6623	34.87222
56.63383	141.5069	33.14543
56.68383	140.4379	31.77592
56.73717	139.3079	30.54497
56.78716	138.2588	29.57059
56.83882	137.1826	28.71443
56.89050	136.1142	27.99079
56.94216	135.0513	27.37178
56.99382	133.9924	26.82748
57.04550	132.9362	26.34099
57.09716	131.8841	25.91914
57.14883	130.8344	25.55306
57.20050	129.7876	25.23778
57.25050	128.7762	24.97225
57.30383	127.6989	24.72207
57.35383	126.6908	24.51350
57.40717	125.6157	24.31360
57.45717	124.6094	24.14044
57.51050	123.5376	23.97060
57.56050	122.5317	23.82191
57.61382	121.4611	23.67640
57.66382	120.4574	23.55032
57.71717	119.3869	23.42749
57.76716	118.3842	23.32404
57.82050	117.3140	23.21350
57.87050	116.3118	23.12152
57.92217	115.2765	23.02353
57.97382	114.2432	22.93303
58.02550	113.2072	22.84753
58.07717	112.1723	22.76532
58.12883	111.1376	22.68270
58.18050	110.1024	22.60017
58.23217	109.0686	22.51762
58.28383	108.0338	22.44150
58.33383	107.0329	22.36570
58.38716	105.9658	22.28565
58.43716	104.9646	22.21177
58.49050	103.8970	22.13696
58.54050	102.8973	22.07368
58.59384	101.8283	22.00201
58.64384	100.8286	21.93532
58.69717	99.76049	21.86162
58.74717	98.76024	21.80103
58.80050	97.69301	21.73158
58.85050	96.69316	21.67421
58.90383	95.62566	21.60288
58.95383	94.62514	21.53908
59.00550	93.59236	21.49121
59.05717	92.55734	21.39102
59.10883	91.52205	21.29789
59.16050	90.48697	21.21242
59.21216	89.45272	21.12234
59.26382	88.41749	21.04540
59.31550	87.38319	20.96937
59.36716	86.34882	20.89550
59.41716	85.34741	20.82470
59.47050	84.28068	20.74848
59.52050	83.28001	20.68478
59.57383	82.21155	20.61511
59.62383	81.21085	20.55032
59.67717	80.14307	20.48027
59.72717	79.14178	20.41847
59.78050	78.07451	20.34647
59.83050	77.07400	20.28258
59.88383	76.00716	20.21161
59.93383	75.00628	20.15613
59.98717	73.93926	20.08780
60.03716	72.93913	20.02979
60.08882	71.90516	19.96726
60.14050	70.87010	19.90904
60.19216	69.83699	19.84796
60.24382	68.80242	19.78595
60.29550	67.76838	19.72201
60.34716	66.73272	19.65447
60.39883	65.69998	19.58856
60.45050	64.66587	19.52877
60.50050	63.66516	19.46778
60.55383	62.59758	19.39530
60.60383	61.59766	19.33281
60.65717	60.52920	19.26579
60.70717	59.52854	19.19242
60.76050	58.46086	19.12819
60.81050	57.45940	19.06031
60.86382	56.39188	18.98892
60.91382	55.39108	18.92489
60.96717	54.32341	18.85904
61.01716	53.32209	18.79213
61.07050	52.25488	18.72579
61.12050	51.25265	18.66074
61.17217	50.21837	18.58631
61.22382	49.18324	18.52152
61.27550	48.14835	18.45802
61.32717	47.11399	18.38728
61.37883	46.07811	18.32179
61.43050	45.04244	18.25496
61.48217	44.00750	18.18824
61.53383	42.97180	18.12013
61.58383	41.97046	18.05406
61.63716	40.90195	17.97456
61.68716	39.89974	17.90464
61.74050	38.83060	17.82797
61.79050	37.82915	17.75018
61.84384	36.76192	17.66100
61.89384	35.75974	17.58178
61.94717	34.69183	17.49856
61.99717	33.68810	17.42088
62.05050	32.62021	17.33465
62.10050	31.61865	17.24731
62.15383	30.54752	17.16170
62.20383	29.54541	17.08461
62.25550	28.50867	16.99319
62.30717	27.47314	16.89730
62.35883	26.43712	16.80103
62.41050	25.40060	16.70521
62.46216	24.36278	16.60458
62.51050	23.39205	16.50515
62.56050	22.61182	16.53363
62.61382	22.53211	14.87793
62.66382	22.73352	11.41496
62.71717	23.16642	7.213940
62.76716	23.70111	3.374594
62.82050	24.38104	-0.2459865
62.87050	25.09493	-3.117592
62.92217	25.89303	-5.567537
62.97382	26.73707	-7.550092
63.02550	27.61908	-9.138004
63.07717	28.52914	-10.41050
63.12883	29.45990	-11.43162
63.18050	30.40886	-12.26273
63.23217	31.37351	-12.92126
63.28383	32.34751	-13.44920
63.33383	33.30026	-13.87076
63.38716	34.32168	-14.24371
63.43716	35.28598	-14.54205
63.49050	36.31964	-14.80816
63.54050	37.29309	-15.02554
63.59384	38.33352	-15.22832
63.64384	39.31270	-15.39276
63.69717	40.35996	-15.54910
63.74717	41.34320	-15.68105
63.80050	42.39396	-15.80934
63.85050	43.38062	-15.92154
63.90383	44.43370	-16.03168
63.95383	45.42276	-16.12852
64.00550	46.44522	-16.22435
64.05717	47.46792	-16.31741
64.10884	48.49295	-16.41222
64.16050	49.51688	-16.49856
64.21217	50.54293	-16.58301
64.26384	51.56941	-16.67543
64.31550	52.59598	-16.76169
64.36718	53.62329	-16.84489
64.41717	54.61821	-16.92512
64.47050	55.67882	-17.00390
64.52050	56.67461	-17.08510
64.57384	57.73481	-17.17200
64.62383	58.73085	-17.25252
64.67718	59.79368	-17.33662
64.72718	60.78896	-17.41950
64.78050	61.85264	-17.51035
64.83050	62.84878	-17.58936
64.88384	63.91150	-17.67648
64.93384	64.90776	-17.74973
64.98717	65.97226	-17.83469
65.03717	66.96829	-17.91472
65.08884	67.99828	-17.99390
65.14050	69.02853	-18.07778
65.19217	70.05905	-18.16542
65.24384	71.08887	-18.24405
65.29550	72.11939	-18.32878
65.34717	73.15087	-18.41626
65.39883	74.18053	-18.49518
65.45050	75.21084	-18.57758
65.50050	76.20803	-18.65802
65.55384	77.27212	-18.74479
65.60384	78.26910	-18.82940
65.65718	79.33288	-18.92020
65.70718	80.33044	-19.00444
65.76050	81.39415	-19.09554
65.81050	82.39054	-19.18332
65.86384	83.45387	-19.27158
65.91382	84.45272	-19.36255
65.96718	85.51620	-19.45655
66.01716	86.51436	-19.54211
66.07050	87.57726	-19.63794
66.12050	88.57524	-19.72551
66.17218	89.60524	-19.81598
66.22384	90.63512	-19.91531
66.27550	91.66666	-20.00482
66.32718	92.69696	-20.09800
66.37884	93.72782	-20.19009
66.43050	94.75861	-20.27945
66.48218	95.78868	-20.37022
66.53384	96.81874	-20.46741
66.58384	97.81684	-20.54963
66.63718	98.87989	-20.64603
66.68718	99.87750	-20.73196
66.74050	100.9420	-20.83301
66.79050	101.9388	-20.92331
66.84384	103.0024	-21.01796
66.89384	104.0001	-21.10660
66.94718	105.0648	-21.20683
66.99718	106.0605	-21.29610
67.05050	107.1256	-21.39487
67.10050	108.1229	-21.49148
67.15384	109.1857	-21.59119
67.20384	110.1830	-21.68834
67.25550	111.2133	-21.78802
67.30718	112.2430	-21.88682
67.35884	113.2742	-21.98757
67.41050	114.3043	-22.08702
67.46218	115.3336	-22.18275
67.51384	116.3642	-22.28487
67.56550	117.3952	-22.38280
67.61718	118.4258	-22.48310
67.66718	119.4225	-22.58225
67.72050	120.4850	-22.69342
67.77050	121.4826	-22.79764
67.82384	122.5462	-22.91662
67.87384	123.5419	-23.02310
67.92718	124.6048	-23.13946
67.97718	125.6019	-23.24772
68.03050	126.6650	-23.36686
68.08050	127.6617	-23.47084
68.13384	128.7254	-23.58608
68.18384	129.7216	-23.69236
68.23718	130.7844	-23.80908
68.28718	131.7804	-23.92986
68.33884	132.8096	-24.05030
68.39050	133.8394	-24.16865
68.44218	134.8684	-24.29368
68.49384	135.8975	-24.42566
68.54550	136.9271	-24.55525
68.59718	137.9554	-24.68991
68.64884	138.9854	-24.81784
68.70050	140.0142	-24.95278
68.75050	141.0105	-25.08770
68.80384	142.0734	-25.22744
68.85384	143.0688	-25.36169
68.90718	144.1308	-25.50484
68.95718	145.1269	-25.63438
69.01050	146.1888	-25.77295
69.06050	147.1849	-25.91466
69.11384	148.2459	-26.06000
69.16382	149.2411	-26.19922
69.21718	150.3030	-26.34082
69.26716	151.2982	-26.48068
69.32050	152.3600	-26.62405
69.37050	153.3560	-26.76056
69.42218	154.3849	-26.90378
69.47384	155.4139	-27.04349
69.52550	156.4424	-27.18664
69.57718	157.4717	-27.32861
69.62884	158.5004	-27.47674
69.68050	159.5297	-27.61346
69.73218	160.5574	-27.75076
69.78384	161.5872	-27.87812
69.83384	162.5844	-27.98861
69.88718	163.6484	-28.09345
69.93718	164.6465	-28.17485
69.99050	165.7129	-28.24504
70.04050	166.7124	-28.30416
70.09384	167.7783	-28.36069
70.14384	168.7784	-28.40734
70.19718	169.8446	-28.47897
70.24718	170.8440	-28.54398
70.30050	171.9092	-28.62695
70.35050	172.9078	-28.72320
70.40384	173.9713	-28.82644
70.45384	174.9680	-28.94226
70.50550	175.9979	-29.07303
70.55718	177.0265	-29.22337
70.60884	178.0547	-29.38469
70.66050	179.0804	-29.57173
70.71218	180.1081	-29.77598
70.76384	181.1340	-30.00311
70.81550	182.1571	-30.25590
70.86718	183.1800	-30.53079
70.91718	184.1681	-30.83472
70.97050	185.2214	-31.19077
71.02050	186.2066	-31.55854
71.07384	187.2559	-31.98722
71.12384	188.2389	-32.44520
71.17718	189.2828	-32.98663
71.22718	190.2603	-33.55122
71.28050	191.2986	-34.20859
71.33050	192.2702	-34.87962
71.38384	193.3041	-35.64291
71.43384	194.2720	-36.38208
71.48718	195.3044	-37.18363
71.53718	196.2700	-37.95566
71.58884	197.2682	-38.77952
71.64050	198.2656	-39.63910
71.69218	199.2595	-40.55728
71.74384	200.2498	-41.54805
71.79550	201.2374	-42.62734
71.84718	202.2203	-43.80598
71.89884	203.1999	-45.04192
71.95050	204.1772	-46.31254
72.00050	205.1238	-47.50671
72.05384	206.1385	-48.66040
72.10384	207.0997	-49.45120
72.15718	208.1485	-49.68726
72.20718	209.1680	-48.99219
72.26050	210.3113	-47.01320
72.31050	211.4286	-44.27368
72.36384	212.6436	-41.13364
72.41382	213.7737	-38.48844
72.46718	214.9594	-36.16845
72.51716	216.0485	-34.44913
72.57050	217.1904	-33.01407
72.62050	218.2459	-31.97588
72.67218	219.3240	-31.12708
72.72384	220.3928	-30.47685
72.77550	221.4538	-29.97800
72.82718	222.5095	-29.59820
72.87884	223.5594	-29.31252
72.93050	224.6050	-29.10261
72.98218	225.6488	-28.93249
73.03384	226.6911	-28.82260
73.08384	227.6973	-28.74579
73.13718	228.7690	-28.69026
73.18718	229.7728	-28.66735
73.24050	230.8427	-28.65935
73.29050	231.8447	-28.65604
73.34384	232.9140	-28.65826
73.39384	233.9150	-28.67094
73.44718	234.9839	-28.69975
73.49718	235.9844	-28.73485
73.55050	237.0533	-28.76301
73.60050	238.0539	-28.79841
73.65384	239.1208	-28.84103
73.70384	240.1205	-28.88127
73.75550	241.1547	-28.93236
73.80718	242.1885	-28.98488
73.85884	243.2223	-29.03512
73.91050	244.2558	-29.08869
73.96218	245.2889	-29.13081
74.01384	246.3224	-29.17842
74.06550	247.3564	-29.23037
74.11718	248.3898	-29.27184
74.16718	249.3894	-29.31490
74.22050	250.4570	-29.36399
74.27050	251.4571	-29.41302
74.32384	252.5238	-29.46175
74.37384	253.5240	-29.51010
74.42718	254.5912	-29.55080
74.47718	255.5915	-29.59415
74.53050	256.6582	-29.65451
74.58050	257.6582	-29.70594
74.63384	258.7242	-29.75617
74.68384	259.7242	-29.81125
74.73718	260.7905	-29.87161
74.78718	261.7890	-29.92200
74.83884	262.8222	-29.98397
74.89050	263.8555	-30.04050
74.94218	264.8884	-30.10842
74.99384	265.9202	-30.16925
75.04550	266.9537	-30.23430
75.09718	267.9858	-30.29417
75.14884	269.0186	-30.35984
75.20050	270.0509	-30.42992
75.25050	271.0494	-30.48868
75.30384	272.1160	-30.55112
-2.000000	5.000000	0.0000000