File: 1-C1(0.6mol%)+C20(0.6mol%)/matlab/160-1.txt
CLOSED
Version	1.0
Language	English
Mode	Standard
Run	7
RunSerial	11857
Instrument	DSC Q2000 V24.11 Build 124
Module	DSC Standard Cell RC
Operator	Jing
File	\\AE520-1454\TA\Data\DSC\UQ Composites\Nan\C1(5.5)+C20P(3)+CL(HotplateMixtureAB)\160-1
ProcName	Ramp
InstSerial	2000-0883
AutoSerial	1293
Sample	Iso-160-1
Size	38.2000	mg
PanMass	Not available
PanResist	Automatic Automatic  K/W
PanFactor	Default Default
Method	Ramp
Comment
Xcomment	Pan: Tzero Aluminum Hermetic
Xcomment	Gas1: Nitrogen 50.0 ml/min
Xcomment	Gas2: Nitrogen 50.0 ml/min
Text
Exotherm	UP
Kcell	1.05230
Cpconst	Standard: 0.938
Calib	-38.6961
TempCal	1	pts	157.46	156.60
TzeroDt	-87.6168 -0.0009 -1.4231
TzeroDtz	-87.6168 0.0057 6.9570
InstCalFile	Tzero: \\Ae520-1454\ta\Data\DSC\Calibration\2017\CALIBRATION\1562_RCS (90)_05_18_2017 10_50_44.TZR
InstCalFile	Baseline: \\Ae520-1454\ta\Data\DSC\Calibration\2017\2017-05-17_Calibration.001
InstCalFile	Sapphire: \\Ae520-1454\ta\Data\DSC\Calibration\2017\2017-05-17_Saphire.001
InstCalDate	Tzero 2017-05-18 Time 10:50:44
TempRange	-87.39 to 398.39 °C at 10.00 °C/min Heat Only
AutoZero	Delta T Offset 0.000 uV
AutoZero	Delta T0 Offset 0.000 uV
MultiptCal	0
MultiPtDesc	0) Not set
AutoCellConst	Calibration Date 2017-05-18 16:59:28
Controls	Gas 1  Event Off  Sampling 0.2
Cell#	RC-01562
CoolingUnit	RCS (90)
SelHeatFlow	Heat Flow T4 (mW)
AutoLidII	Installed
AutoAnalysis	Off
MacroFile
Nsig	3
Sig1	Time (min)
Sig2	Temperature (°C)
Sig3	Heat Flow (mW)
Date	2017-06-21
Time	00:45:54
OrgMethod	1: Equilibrate at 20.00 °C
OrgMethod	2: Ramp 40.00 °C/min to 160.00 °C
OrgMethod	3: Mark end of cycle 1
OrgMethod	4: Isothermal for 40.00 min
OrgMethod	5: Mark end of cycle 2
OrgMethod	6: Ramp 20.00 °C/min to 280.00 °C
OrgMethod	7: Mark end of cycle 3
OrgMethod	8: Ramp 20.00 °C/min to 20.00 °C
OrgMethod	9: Mark end of cycle 4
OrgMethod	10: Ramp 20.00 °C/min to 280.00 °C
OrgMethod	11: Mark end of cycle 5
OrgFile	C:\Users\jarra\Desktop\DSC\1-C1(0.6mol%)+C20(0.6mol%)\160-1.001
StartOfData
4.99994E-4	20.05361	0.1568683
0.05383332	20.18340	0.2456789
0.1038333	21.01474	-0.5788892
0.1571666	22.28612	-3.879551
0.2071666	23.66275	-7.693101
0.2605000	25.27608	-11.83383
0.3105000	26.88313	-15.36680
0.3638334	28.67928	-18.62695
0.4138333	30.42045	-21.17358
0.4671667	32.32580	-23.41939
0.5171667	34.15044	-25.13766
0.5705000	36.12484	-26.65353
0.6205000	37.99922	-27.84144
0.6721668	39.95362	-28.88889
0.7238332	41.92018	-29.83314
0.7755000	43.89262	-30.82024
0.8271668	45.86098	-31.94062
0.8788332	47.83574	-32.87986
0.9305000	49.83041	-33.53760
0.9821668	51.83598	-34.18472
1.033833	53.83674	-35.02954
1.083833	55.76213	-36.09990
1.137166	57.80950	-37.34091
1.187166	59.73304	-38.43926
1.240500	61.78584	-39.73666
1.290500	63.69765	-41.37246
1.343833	65.69884	-44.02188
1.393833	67.50229	-48.16738
1.447166	69.29088	-55.55730
1.497166	70.79843	-65.58705
1.550500	72.25946	-78.54575
1.600500	73.57020	-91.15319
1.653833	74.99161	-103.8589
1.703833	76.32824	-116.2660
1.755500	77.62058	-131.1564
1.807167	78.99356	-143.0709
1.858834	80.42750	-154.3020
1.910500	82.00908	-162.1936
1.962166	83.77188	-166.6387
2.013833	85.87303	-162.0673
2.065500	88.52303	-151.0982
2.117167	91.09588	-142.4040
2.167167	93.78834	-127.7916
2.220500	96.77306	-113.1986
2.270500	99.44288	-102.0052
2.323833	102.1588	-92.37082
2.373834	104.5975	-85.11558
2.427167	107.1098	-78.94288
2.477167	109.3926	-74.34280
2.530500	111.7657	-70.49200
2.580500	113.9458	-67.67169
2.633833	116.2292	-65.34107
2.683833	118.3399	-63.67504
2.737167	120.5632	-62.39010
2.787167	122.6271	-61.55949
2.838833	124.7450	-60.97984
2.890500	126.8494	-60.62207
2.942167	128.9438	-60.42468
2.993833	131.0298	-60.38614
3.045500	133.1078	-60.48078
3.097167	135.1794	-60.71188
3.148833	137.2463	-61.06434
3.200500	139.3058	-61.51940
3.250500	141.2965	-62.05310
3.303833	143.4146	-62.70162
3.353833	145.3970	-63.38036
3.407167	147.5082	-64.16991
3.457167	149.4831	-64.96322
3.505500	151.3898	-65.77795
3.557167	153.2765	-66.79148
3.608833	154.4213	-65.77851
3.660500	155.2327	-61.33828
3.712167	155.8586	-55.83776
3.763833	156.3587	-50.28492
3.815500	156.7634	-45.27266
3.867166	157.0956	-40.96032
3.917167	157.3588	-37.46726
3.970500	157.5934	-34.40638
4.020500	157.7751	-32.05566
4.073834	157.9370	-30.00898
4.123833	158.0647	-28.44230
4.177166	158.1790	-27.07554
4.227167	158.2702	-26.02040
4.280500	158.3527	-25.08011
4.330500	158.4196	-24.34315
4.383834	158.4803	-23.67010
4.433834	158.5306	-23.12652
4.487167	158.5776	-22.62461
4.537167	158.6164	-22.19537
4.588834	158.6522	-21.79710
4.640500	158.6853	-21.43206
4.692166	158.7141	-21.08733
4.743834	158.7419	-20.76275
4.795500	158.7666	-20.44866
4.847166	158.7907	-20.13734
4.898834	158.8134	-19.83054
4.950500	158.8348	-19.52131
5.000500	158.8558	-19.21680
5.053834	158.8776	-18.86547
5.103833	158.8999	-18.49070
5.157166	158.9246	-18.04466
5.207167	158.9510	-17.59258
5.260500	158.9782	-17.09697
5.310500	159.0046	-16.61135
5.363834	159.0337	-16.08123
5.413832	159.0603	-15.57034
5.467168	159.0901	-14.99719
5.517168	159.1185	-14.43560
5.570500	159.1513	-13.81876
5.620500	159.1822	-13.22434
5.672168	159.2150	-12.59282
5.723834	159.2478	-11.95268
5.775500	159.2804	-11.30712
5.827168	159.3137	-10.65912
5.878834	159.3472	-9.993161
5.930500	159.3805	-9.313759
5.982168	159.4157	-8.626691
6.033832	159.4496	-7.923135
6.083832	159.4846	-7.220438
6.137168	159.5214	-6.451636
6.187168	159.5579	-5.734034
6.240500	159.5940	-5.033507
6.290500	159.6243	-4.468367
6.343834	159.6519	-3.962966
6.393832	159.6732	-3.557375
6.447168	159.6922	-3.201859
6.497168	159.7077	-2.915692
6.550500	159.7213	-2.663160
6.600500	159.7330	-2.461260
6.653832	159.7426	-2.280628
6.703832	159.7502	-2.131315
6.755500	159.7581	-1.999246
6.807166	159.7639	-1.890188
6.858832	159.7691	-1.794090
6.910500	159.7737	-1.708790
6.962168	159.7783	-1.632780
7.013834	159.7823	-1.569586
7.065500	159.7854	-1.512266
7.117166	159.7889	-1.460416
7.167168	159.7908	-1.411152
7.220500	159.7933	-1.369726
7.270500	159.7956	-1.330088
7.323834	159.7983	-1.296188
7.373834	159.7999	-1.261558
7.427168	159.8015	-1.229922
7.477168	159.8032	-1.201042
7.530500	159.8052	-1.172453
7.580500	159.8075	-1.146162
7.633832	159.8090	-1.120220
7.683832	159.8101	-1.094951
7.737168	159.8110	-1.072598
7.787168	159.8136	-1.048432
7.838834	159.8148	-1.024396
7.890500	159.8158	-1.001427
7.942168	159.8174	-0.9796089
7.993834	159.8184	-0.9568562
8.045500	159.8198	-0.9352352
8.097168	159.8211	-0.9146558
8.148834	159.8218	-0.8934128
8.200500	159.8226	-0.8707269
8.250500	159.8241	-0.8505068
8.303832	159.8247	-0.8302878
8.353832	159.8273	-0.8122749
8.407166	159.8279	-0.7939122
8.457168	159.8290	-0.7748451
8.510499	159.8303	-0.7551025
8.560500	159.8306	-0.7351894
8.613834	159.8324	-0.7138624
8.663834	159.8336	-0.6951069
8.717168	159.8343	-0.6745581
8.767168	159.8363	-0.6560540
8.820500	159.8370	-0.6345346
8.870499	159.8377	-0.6150691
8.922168	159.8390	-0.5971714
8.973832	159.8406	-0.5788740
9.025499	159.8410	-0.5579250
9.077168	159.8422	-0.5379350
9.128834	159.8434	-0.5177341
9.180500	159.8438	-0.4983774
9.232166	159.8458	-0.4803446
9.283832	159.8466	-0.4602558
9.333832	159.8468	-0.4401870
9.387168	159.8491	-0.4185054
9.437166	159.8500	-0.3991555
9.490500	159.8510	-0.3802630
9.540500	159.8516	-0.3585660
9.593832	159.8530	-0.3382851
9.643832	159.8549	-0.3196278
9.697168	159.8558	-0.2974583
9.747168	159.8567	-0.2780846
9.800500	159.8586	-0.2588990
9.850500	159.8587	-0.2367503
9.903832	159.8606	-0.2148784
9.953834	159.8619	-0.1951116
10.00550	159.8622	-0.1714024
10.05717	159.8634	-0.1490812
10.10883	159.8649	-0.1281224
10.16050	159.8661	-0.1045235
10.21217	159.8668	-.08312593
10.26383	159.8686	-.06045557
10.31550	159.8687	-.03953397
10.36717	159.8700	-.01796892
10.41717	159.8716	.003018656
10.47050	159.8726	0.02654136
10.52050	159.8738	0.04968406
10.57383	159.8740	0.07131872
10.62383	159.8751	0.09394508
10.67717	159.8769	0.1166340
10.72717	159.8773	0.1368497
10.78050	159.8797	0.1607805
10.83050	159.8802	0.1826823
10.88383	159.8811	0.2098236
10.93383	159.8829	0.2339564
10.98717	159.8841	0.2555848
11.03717	159.8854	0.2813730
11.08883	159.8870	0.3041002
11.14050	159.8876	0.3258560
11.19217	159.8889	0.3501928
11.24384	159.8907	0.3746740
11.29550	159.8915	0.3975956
11.34717	159.8933	0.4239470
11.39883	159.8937	0.4479408
11.45050	159.8954	0.4736159
11.50050	159.8964	0.4974533
11.55383	159.8979	0.5229396
11.60383	159.8991	0.5465574
11.65717	159.9005	0.5720188
11.70717	159.9023	0.5962296
11.76050	159.9039	0.6212480
11.81050	159.9042	0.6446753
11.86383	159.9070	0.6745371
11.91383	159.9065	0.6962020
11.96717	159.9081	0.7256170
12.01717	159.9100	0.7517264
12.07050	159.9119	0.7752100
12.12050	159.9125	0.8003891
12.17217	159.9144	0.8247650
12.22383	159.9141	0.8514247
12.27550	159.9168	0.8774432
12.32717	159.9174	0.9016322
12.37884	159.9191	0.9269644
12.43050	159.9206	0.9524399
12.48217	159.9212	0.9803390
12.53383	159.9232	1.006145
12.58383	159.9242	1.027846
12.63717	159.9249	1.056522
12.68716	159.9258	1.082160
12.74050	159.9283	1.105939
12.79050	159.9292	1.131176
12.84383	159.9308	1.158769
12.89383	159.9317	1.182227
12.94717	159.9337	1.205542
12.99717	159.9337	1.227476
13.05050	159.9353	1.254998
13.10050	159.9366	1.279431
13.15383	159.9379	1.307225
13.20383	159.9394	1.333203
13.25550	159.9409	1.360454
13.30717	159.9421	1.389169
13.35883	159.9435	1.421806
13.41050	159.9446	1.456170
13.46217	159.9464	1.495648
13.51383	159.9498	1.538884
13.56550	159.9511	1.588979
13.61716	159.9540	1.642145
13.66716	159.9561	1.697086
13.72050	159.9594	1.765318
13.77050	159.9632	1.832856
13.82384	159.9668	1.911375
13.87384	159.9700	1.988304
13.92717	159.9744	2.075309
13.97717	159.9780	2.162994
14.03050	159.9833	2.257139
14.08050	159.9870	2.345498
14.13383	159.9927	2.444761
14.18383	159.9970	2.536807
14.23716	160.0025	2.633922
14.28717	160.0066	2.727808
14.33883	160.0110	2.820928
14.39050	160.0156	2.911360
14.44217	160.0206	3.004170
14.49384	160.0248	3.090592
14.54550	160.0290	3.176208
14.59717	160.0335	3.258960
14.64883	160.0378	3.336848
14.70050	160.0408	3.412326
14.75050	160.0444	3.481685
14.80383	160.0486	3.556491
14.85383	160.0524	3.621631
14.90717	160.0552	3.690227
14.95717	160.0588	3.753917
15.01050	160.0619	3.815874
15.06050	160.0648	3.877623
15.11383	160.0676	3.936648
15.16383	160.0706	3.994428
15.21716	160.0732	4.054709
15.26717	160.0759	4.110656
15.32050	160.0794	4.168289
15.37050	160.0817	4.223697
15.42217	160.0844	4.279122
15.47383	160.0869	4.340061
15.52550	160.0908	4.397746
15.57717	160.0931	4.456467
15.62883	160.0965	4.515341
15.68050	160.0996	4.575136
15.73216	160.1024	4.635110
15.78383	160.1058	4.694635
15.83383	160.1084	4.753192
15.88716	160.1111	4.811972
15.93717	160.1138	4.866714
15.99050	160.1169	4.921098
16.04050	160.1193	4.971179
16.09383	160.1226	5.021216
16.14383	160.1243	5.066624
16.19717	160.1266	5.108993
16.24716	160.1291	5.146179
16.30050	160.1309	5.180728
16.35050	160.1322	5.210700
16.40383	160.1334	5.236033
16.45383	160.1346	5.255986
16.50550	160.1359	5.277088
16.55716	160.1367	5.293510
16.60883	160.1378	5.306887
16.66050	160.1378	5.315258
16.71216	160.1392	5.322961
16.76383	160.1392	5.331025
16.81550	160.1396	5.338230
16.86716	160.1397	5.344986
16.91716	160.1401	5.351100
16.97050	160.1401	5.356940
17.02050	160.1406	5.361462
17.07383	160.1411	5.365512
17.12383	160.1402	5.368305
17.17716	160.1396	5.370537
17.22716	160.1402	5.371441
17.28050	160.1401	5.371608
17.33050	160.1394	5.371101
17.38383	160.1396	5.370022
17.43383	160.1394	5.368356
17.48716	160.1390	5.365912
17.53717	160.1389	5.363332
17.58883	160.1395	5.359966
17.64050	160.1382	5.356034
17.69216	160.1382	5.351456
17.74383	160.1372	5.346152
17.79550	160.1380	5.340671
17.84716	160.1371	5.334738
17.89883	160.1362	5.328380
17.95050	160.1368	5.321687
18.00050	160.1357	5.315254
18.05383	160.1360	5.307526
18.10383	160.1350	5.300274
18.15716	160.1344	5.291748
18.20716	160.1340	5.283735
18.26050	160.1336	5.274868
18.31050	160.1336	5.265874
18.36383	160.1324	5.256990
18.41383	160.1319	5.247720
18.46716	160.1316	5.236141
18.51716	160.1311	5.226071
18.57050	160.1306	5.213522
18.62050	160.1292	5.197666
18.67216	160.1284	5.180422
18.72383	160.1282	5.158830
18.77550	160.1271	5.136408
18.82716	160.1262	5.111544
18.87883	160.1256	5.086162
18.93050	160.1241	5.062500
18.98216	160.1231	5.037797
19.03383	160.1227	5.009266
19.08383	160.1212	4.982709
19.13716	160.1203	4.953766
19.18716	160.1186	4.928798
19.24050	160.1181	4.898278
19.29050	160.1160	4.872924
19.34383	160.1138	4.843344
19.39383	160.1136	4.814357
19.44716	160.1118	4.784854
19.49716	160.1100	4.756092
19.55050	160.1079	4.730384
19.60050	160.1075	4.702976
19.65383	160.1054	4.670708
19.70383	160.1039	4.642864
19.75550	160.1021	4.613472
19.80716	160.1011	4.584028
19.85883	160.1002	4.555455
19.91050	160.0982	4.525118
19.96216	160.0981	4.498032
20.01383	160.0953	4.471134
20.06550	160.0938	4.443767
20.11716	160.0922	4.418122
20.16716	160.0907	4.391806
20.22050	160.0898	4.362743
20.27050	160.0885	4.339130
20.32383	160.0863	4.311264
20.37383	160.0861	4.285628
20.42716	160.0849	4.259478
20.47716	160.0832	4.234314
20.53050	160.0824	4.207910
20.58050	160.0811	4.183676
20.63383	160.0806	4.160351
20.68383	160.0790	4.138687
20.73716	160.0777	4.111630
20.78717	160.0756	4.091153
20.83883	160.0751	4.066884
20.89050	160.0745	4.044325
20.94216	160.0726	4.021364
20.99383	160.0716	4.001395
21.04550	160.0707	3.977172
21.09716	160.0708	3.955960
21.14883	160.0678	3.934720
21.20050	160.0678	3.915557
21.25050	160.0664	3.894050
21.30383	160.0655	3.872562
21.35383	160.0642	3.853087
21.40716	160.0633	3.831814
21.45717	160.0629	3.811169
21.51050	160.0620	3.791280
21.56050	160.0614	3.771586
21.61383	160.0606	3.753482
21.66383	160.0595	3.733792
21.71716	160.0582	3.714687
21.76716	160.0583	3.696937
21.82050	160.0573	3.681566
21.87050	160.0560	3.666965
21.92216	160.0554	3.652622
21.97383	160.0539	3.636870
22.02550	160.0535	3.623694
22.07716	160.0517	3.609632
22.12883	160.0518	3.592850
22.18050	160.0504	3.578346
22.23216	160.0497	3.563446
22.28383	160.0486	3.548702
22.33383	160.0486	3.535103
22.38716	160.0474	3.518705
22.43716	160.0474	3.506496
22.49050	160.0464	3.491434
22.54050	160.0464	3.476600
22.59383	160.0457	3.461175
22.64383	160.0459	3.448925
22.69716	160.0438	3.436215
22.74716	160.0455	3.422903
22.80050	160.0440	3.409084
22.85050	160.0429	3.399704
22.90383	160.0425	3.389212
22.95383	160.0428	3.378454
23.00550	160.0412	3.368816
23.05716	160.0412	3.358790
23.10883	160.0400	3.349090
23.16050	160.0398	3.339532
23.21216	160.0388	3.330119
23.26383	160.0391	3.321096
23.31550	160.0384	3.312126
23.36716	160.0369	3.303638
23.41716	160.0369	3.295534
23.47050	160.0366	3.287187
23.52050	160.0361	3.279510
23.57383	160.0363	3.271152
23.62383	160.0346	3.263646
23.67717	160.0351	3.256004
23.72716	160.0343	3.249088
23.78050	160.0339	3.242187
23.83050	160.0329	3.236033
23.88383	160.0336	3.229600
23.93383	160.0326	3.223798
23.98716	160.0340	3.217914
24.03717	160.0328	3.213057
24.08883	160.0333	3.208461
24.14050	160.0331	3.204042
24.19216	160.0327	3.200033
24.24383	160.0327	3.196332
24.29550	160.0327	3.192952
24.34716	160.0322	3.190038
24.39883	160.0327	3.187422
24.45050	160.0328	3.185266
24.50050	160.0335	3.183927
24.55383	160.0327	3.182660
24.60383	160.0334	3.181954
24.65716	160.0329	3.181537
24.70717	160.0337	3.181925
24.76050	160.0336	3.182840
24.81050	160.0342	3.184391
24.86383	160.0342	3.186483
24.91383	160.0348	3.189090
24.96716	160.0355	3.192416
25.01716	160.0354	3.196366
25.07050	160.0364	3.201658
25.12050	160.0354	3.207674
25.17216	160.0368	3.214315
25.22383	160.0369	3.221925
25.27550	160.0377	3.231338
25.32716	160.0376	3.242394
25.37883	160.0393	3.253440
25.43050	160.0397	3.268952
25.48216	160.0405	3.286391
25.53383	160.0412	3.304987
25.58383	160.0420	3.324554
25.63716	160.0438	3.345270
25.68717	160.0442	3.364756
25.74050	160.0461	3.387246
25.79050	160.0469	3.405413
25.84383	160.0478	3.429210
25.89383	160.0495	3.450228
25.94717	160.0498	3.472800
25.99716	160.0512	3.491409
26.05050	160.0522	3.510822
26.10050	160.0531	3.528284
26.15383	160.0535	3.547846
26.20383	160.0542	3.560095
26.25550	160.0553	3.571712
26.30716	160.0555	3.581695
26.35883	160.0565	3.590796
26.41050	160.0570	3.598988
26.46216	160.0572	3.606628
26.51383	160.0566	3.613210
26.56550	160.0576	3.618772
26.61716	160.0565	3.622893
26.66716	160.0564	3.625523
26.72050	160.0558	3.626669
26.77050	160.0552	3.626120
26.82383	160.0548	3.623482
26.87383	160.0535	3.618730
26.92717	160.0538	3.609772
26.97717	160.0525	3.596611
27.03050	160.0518	3.578876
27.08050	160.0509	3.555878
27.13383	160.0501	3.532794
27.18383	160.0483	3.512548
27.23716	160.0470	3.485359
27.28717	160.0458	3.459640
27.33883	160.0450	3.433820
27.39050	160.0432	3.408306
27.44216	160.0424	3.378556
27.49383	160.0411	3.350472
27.54550	160.0404	3.320020
27.59716	160.0376	3.290085
27.64883	160.0373	3.263015
27.70050	160.0353	3.231957
27.75050	160.0340	3.202196
27.80383	160.0333	3.166869
27.85383	160.0311	3.136928
27.90716	160.0303	3.104928
27.95716	160.0287	3.073644
28.01050	160.0264	3.038779
28.06050	160.0245	3.011536
28.11383	160.0235	2.976002
28.16383	160.0218	2.947717
28.21716	160.0199	2.913898
28.26716	160.0173	2.882112
28.32050	160.0170	2.844838
28.37050	160.0140	2.811839
28.42216	160.0126	2.777482
28.47383	160.0113	2.741094
28.52550	160.0084	2.702252
28.57717	160.0067	2.669160
28.62883	160.0054	2.632478
28.68050	160.0024	2.597926
28.73216	160.0012	2.557299
28.78383	159.9990	2.519948
28.83383	159.9974	2.479138
28.88716	159.9960	2.439200
28.93717	159.9943	2.400077
28.99050	159.9929	2.360130
29.04050	159.9908	2.318520
29.09383	159.9889	2.278174
29.14383	159.9871	2.238456
29.19717	159.9849	2.198218
29.24716	159.9834	2.155986
29.30050	159.9808	2.114035
29.35050	159.9790	2.070344
29.40383	159.9768	2.031218
29.45383	159.9750	1.989828
29.50550	159.9728	1.946586
29.55716	159.9708	1.904260
29.60883	159.9685	1.866413
29.66050	159.9657	1.821792
29.71216	159.9646	1.778792
29.76383	159.9624	1.736348
29.81550	159.9598	1.694751
29.86716	159.9572	1.651415
29.91716	159.9550	1.610851
29.97050	159.9533	1.566406
30.02050	159.9512	1.524385
30.07383	159.9498	1.479379
30.12383	159.9469	1.439742
30.17717	159.9452	1.395813
30.22717	159.9434	1.358022
30.28050	159.9416	1.312949
30.33050	159.9396	1.273769
30.38383	159.9372	1.230802
30.43383	159.9366	1.192250
30.48716	159.9344	1.151705
30.53717	159.9331	1.115125
30.58883	159.9308	1.076750
30.64050	159.9280	1.042470
30.69216	159.9266	1.003873
30.74383	159.9252	0.9658551
30.79550	159.9233	0.9270020
30.84716	159.9222	0.8941518
30.89883	159.9197	0.8608102
30.95050	159.9179	0.8261681
31.00050	159.9164	0.7945880
31.05383	159.9144	0.7648468
31.10383	159.9128	0.7304786
31.15716	159.9101	0.6967490
31.20716	159.9092	0.6653913
31.26050	159.9076	0.6317725
31.31050	159.9050	0.6024976
31.36383	159.9044	0.5709156
31.41383	159.9036	0.5387957
31.46716	159.9014	0.5072748
31.51716	159.9009	0.4809997
31.57050	159.8994	0.4572363
31.62050	159.8986	0.4243284
31.67216	159.8966	0.3952672
31.72383	159.8954	0.3683160
31.77550	159.8942	0.3402846
31.82717	159.8932	0.3131926
31.87883	159.8914	0.2868960
31.93050	159.8892	0.2608169
31.98216	159.8879	0.2351165
32.03383	159.8867	0.2097908
32.08383	159.8855	0.1858780
32.13716	159.8836	0.1619990
32.18716	159.8828	0.1389575
32.24050	159.8820	0.1224828
32.29050	159.8808	0.1176467
32.34384	159.8797	0.09586704
32.39383	159.8788	0.06664680
32.44717	159.8771	0.03861634
32.49716	159.8763	0.01565850
32.55050	159.8743	-9.3374E-3
32.60050	159.8736	-.03526524
32.65383	159.8722	-.05834443
32.70383	159.8713	-.07693456
32.75550	159.8706	-.09851453
32.80716	159.8698	-0.1188195
32.85883	159.8692	-0.1400951
32.91050	159.8681	-0.1609889
32.96216	159.8675	-0.1772354
33.01383	159.8666	-0.1958578
33.06550	159.8653	-0.2137606
33.11716	159.8646	-0.2332095
33.16716	159.8637	-0.2511700
33.22050	159.8631	-0.2696064
33.27050	159.8616	-0.2844524
33.32383	159.8616	-0.3051382
33.37383	159.8602	-0.3235312
33.42717	159.8590	-0.3402028
33.47717	159.8588	-0.3546850
33.53050	159.8578	-0.3705979
33.58050	159.8570	-0.3871383
33.63383	159.8559	-0.4029291
33.68384	159.8549	-0.4155403
33.73717	159.8540	-0.4286716
33.78717	159.8533	-0.4436310
33.83883	159.8519	-0.4590988
33.89050	159.8517	-0.4719694
33.94216	159.8510	-0.4863779
33.99383	159.8493	-0.4999762
34.04550	159.8482	-0.5145874
34.09716	159.8476	-0.5302880
34.14883	159.8473	-0.5458940
34.20050	159.8455	-0.5598056
34.25050	159.8462	-0.5749520
34.30383	159.8458	-0.5905944
34.35383	159.8458	-0.6037219
34.40716	159.8446	-0.6178782
34.45716	159.8436	-0.6313774
34.51050	159.8427	-0.6448270
34.56050	159.8434	-0.6584296
34.61383	159.8414	-0.6728174
34.66383	159.8414	-0.6850366
34.71716	159.8406	-0.6965772
34.76716	159.8402	-0.7080911
34.82050	159.8394	-0.7205560
34.87050	159.8391	-0.7304820
34.92216	159.8381	-0.7407788
34.97383	159.8372	-0.7532189
35.02550	159.8368	-0.7635247
35.07717	159.8362	-0.7734538
35.12883	159.8354	-0.7836400
35.18050	159.8350	-0.7949053
35.23216	159.8345	-0.8070950
35.28383	159.8343	-0.8195087
35.33383	159.8329	-0.8299625
35.38716	159.8331	-0.8418709
35.43716	159.8331	-0.8526153
35.49050	159.8329	-0.8642761
35.54050	159.8319	-0.8741955
35.59384	159.8316	-0.8843066
35.64383	159.8320	-0.8935996
35.69717	159.8306	-0.9039371
35.74716	159.8310	-0.9131381
35.80050	159.8304	-0.9232066
35.85050	159.8301	-0.9322553
35.90383	159.8286	-0.9420806
35.95383	159.8279	-0.9507978
36.00550	159.8275	-0.9597599
36.05716	159.8270	-0.9684174
36.10883	159.8263	-0.9768462
36.16050	159.8262	-0.9851951
36.21216	159.8256	-0.9934788
36.26383	159.8250	-1.001704
36.31550	159.8246	-1.010647
36.36716	159.8243	-1.018984
36.41716	159.8235	-1.026936
36.47050	159.8234	-1.035822
36.52050	159.8231	-1.043956
36.57383	159.8224	-1.052499
36.62383	159.8227	-1.060399
36.67717	159.8221	-1.069139
36.72717	159.8222	-1.077146
36.78050	159.8220	-1.085519
36.83050	159.8217	-1.093220
36.88383	159.8210	-1.101007
36.93384	159.8213	-1.108020
36.98717	159.8207	-1.115329
37.03717	159.8202	-1.121962
37.08883	159.8198	-1.128845
37.14050	159.8195	-1.135628
37.19216	159.8197	-1.142150
37.24383	159.8196	-1.148783
37.29550	159.8189	-1.155222
37.34716	159.8189	-1.161696
37.39883	159.8178	-1.167947
37.45050	159.8178	-1.174015
37.50050	159.8178	-1.179894
37.55383	159.8174	-1.186347
37.60383	159.8176	-1.192235
37.65716	159.8175	-1.198496
37.70716	159.8167	-1.204508
37.76050	159.8163	-1.210613
37.81050	159.8152	-1.216082
37.86383	159.8163	-1.221423
37.91383	159.8150	-1.226094
37.96716	159.8149	-1.230478
38.01716	159.8156	-1.234783
38.07050	159.8141	-1.239410
38.12050	159.8139	-1.243830
38.17216	159.8133	-1.248870
38.22383	159.8134	-1.254138
38.27550	159.8133	-1.259325
38.32717	159.8134	-1.264787
38.37883	159.8129	-1.270078
38.43050	159.8129	-1.275114
38.48216	159.8136	-1.280198
38.53383	159.8132	-1.285489
38.58383	159.8131	-1.290497
38.63716	159.8133	-1.295215
38.68716	159.8123	-1.299217
38.74050	159.8125	-1.303432
38.79050	159.8121	-1.307152
38.84384	159.8114	-1.310787
38.89383	159.8118	-1.314234
38.94717	159.8112	-1.317999
38.99716	159.8104	-1.321542
39.05050	159.8108	-1.325579
39.10050	159.8097	-1.329169
39.15383	159.8101	-1.333215
39.20383	159.8092	-1.337134
39.25550	159.8104	-1.341254
39.30716	159.8100	-1.345230
39.35883	159.8092	-1.349105
39.41050	159.8099	-1.353029
39.46216	159.8094	-1.356809
39.51383	159.8096	-1.360622
39.56550	159.8092	-1.364508
39.61716	159.8093	-1.368331
39.66716	159.8092	-1.371851
39.72050	159.8081	-1.375254
39.77050	159.8080	-1.378373
39.82383	159.8084	-1.381475
39.87383	159.8076	-1.384405
39.92717	159.8080	-1.387239
39.97717	159.8072	-1.389717
40.03050	159.8076	-1.392494
40.08050	159.8066	-1.395198
40.13383	159.8074	-1.398138
40.18384	159.8074	-1.401352
40.23717	159.8075	-1.404971
40.28717	159.8071	-1.408403
40.33883	159.8070	-1.411799
40.39050	159.8076	-1.415117
40.44216	159.8075	-1.418356
40.49383	159.8069	-1.420948
40.54550	159.8066	-1.423470
40.59716	159.8056	-1.425827
40.64883	159.8064	-1.427773
40.70050	159.8056	-1.429418
40.75050	159.8056	-1.431173
40.80383	159.8057	-1.433228
40.85383	159.8049	-1.435361
40.90716	159.8049	-1.437668
40.95716	159.8051	-1.440024
41.01050	159.8044	-1.442689
41.06050	159.8055	-1.445291
41.11383	159.8050	-1.448137
41.16383	159.8044	-1.450608
41.21717	159.8052	-1.453281
41.26717	159.8045	-1.456031
41.32050	159.8048	-1.458612
41.37050	159.8049	-1.460925
41.42216	159.8041	-1.463181
41.47383	159.8036	-1.465219
41.52550	159.8037	-1.467074
41.57717	159.8042	-1.468794
41.62883	159.8033	-1.470542
41.68050	159.8030	-1.472411
41.73217	159.8035	-1.474108
41.78383	159.8042	-1.476026
41.83383	159.8028	-1.478194
41.88716	159.8029	-1.480446
41.93716	159.8029	-1.482425
41.99050	159.8038	-1.484928
42.04050	159.8034	-1.487307
42.09384	159.8026	-1.489623
42.14383	159.8031	-1.491444
42.19717	159.8034	-1.493571
42.24716	159.8036	-1.495799
42.30050	159.8022	-1.497815
42.35050	159.8034	-1.499346
42.40383	159.8028	-1.501228
42.45383	159.8036	-1.502810
42.50550	159.8029	-1.504470
42.55717	159.8032	-1.505858
42.60883	159.8027	-1.507278
42.66050	159.8026	-1.509030
42.71216	159.8025	-1.510544
42.76383	159.8024	-1.512051
42.81550	159.8022	-1.513562
42.86716	159.8023	-1.514859
42.91716	159.8023	-1.516184
42.97050	159.8016	-1.517434
43.02050	159.8019	-1.518560
43.07383	159.8013	-1.519748
43.12383	159.8015	-1.520531
43.17717	159.8006	-1.521456
43.22717	159.8007	-1.522451
43.28050	159.8007	-1.523992
43.33050	159.8004	-1.525551
43.38383	159.8012	-1.527319
43.43383	159.8012	-1.529069
43.48717	159.8011	-1.530886
43.53383	159.8121	-1.535116
43.58383	160.0771	-1.823984
43.63716	160.6486	-4.014372
43.68716	161.2920	-6.916350
43.74050	162.0597	-10.12034
43.79050	162.8376	-12.86934
43.84384	163.7128	-15.38795
43.89383	164.5658	-17.35608
43.94717	165.5055	-19.07752
43.99716	166.4070	-20.39481
44.05050	167.3858	-21.55337
44.10050	168.3182	-22.43778
44.15383	169.3234	-23.22083
44.20383	170.2756	-23.84980
44.25550	171.2655	-24.39752
44.30717	172.2616	-24.87324
44.35883	173.2632	-25.29589
44.41050	174.2676	-25.65576
44.46216	175.2754	-25.98073
44.51383	176.2871	-26.27858
44.56550	177.3004	-26.55217
44.61716	178.3144	-26.81868
44.66716	179.2974	-27.07430
44.72050	180.3479	-27.34010
44.77050	181.3328	-27.58964
44.82383	182.3840	-27.86558
44.87383	183.3694	-28.11332
44.92717	184.4227	-28.38752
44.97717	185.4094	-28.64448
45.03050	186.4624	-28.91130
45.08050	187.4493	-29.17861
45.13383	188.5027	-29.47146
45.18383	189.4888	-29.75870
45.23717	190.5409	-30.09136
45.28717	191.5268	-30.41078
45.33883	192.5434	-30.76197
45.39050	193.5609	-31.13168
45.44217	194.5763	-31.51831
45.49383	195.5919	-31.91550
45.54550	196.6058	-32.34736
45.59716	197.6196	-32.79815
45.64883	198.6326	-33.27540
45.70050	199.6442	-33.77748
45.75050	200.6205	-34.29810
45.80383	201.6625	-34.89125
45.85383	202.6373	-35.49012
45.90717	203.6711	-36.26986
45.95717	204.6404	-36.93044
46.01050	205.6739	-37.72312
46.06050	206.6375	-38.55310
46.11383	207.6628	-39.54380
46.16383	208.6176	-40.59156
46.21717	209.6286	-41.89298
46.26717	210.5663	-43.36515
46.32050	211.5520	-45.30762
46.37050	212.4570	-47.56930
46.42216	213.3699	-50.40787
46.47383	214.2607	-53.72363
46.52550	215.1310	-57.43842
46.57717	215.9869	-61.46078
46.62883	216.8326	-65.64069
46.68050	217.6739	-69.89021
46.73217	218.5211	-73.89590
46.78383	219.3953	-77.13531
46.83383	220.2893	-79.07496
46.88716	221.3115	-79.57574
46.93716	222.3435	-78.36934
46.99050	223.5238	-75.44605
47.04050	224.6848	-71.66340
47.09384	225.9720	-66.47418
47.14383	227.2323	-60.50030
47.19717	228.5940	-54.18441
47.24716	229.8362	-49.30616
47.30050	231.1106	-45.16896
47.35050	232.2638	-42.13324
47.40383	233.4582	-39.61316
47.45383	234.5524	-37.76672
47.50550	235.6621	-36.27643
47.55717	236.7557	-35.11230
47.60883	237.8356	-34.20511
47.66050	238.9059	-33.49988
47.71216	239.9672	-32.95160
47.76383	241.0233	-32.53304
47.81550	242.0740	-32.21844
47.86716	243.1217	-31.97702
47.91716	244.1321	-31.80271
47.97050	245.2083	-31.65612
48.02050	246.2147	-31.55775
48.07383	247.2876	-31.48224
48.12383	248.2922	-31.42925
48.17717	249.3607	-31.41098
48.22717	250.3626	-31.40691
48.28050	251.4312	-31.40634
48.33050	252.4318	-31.40896
48.38383	253.4987	-31.42246
48.43383	254.5002	-31.44194
48.48717	255.5670	-31.45710
48.53717	256.5679	-31.48785
48.58883	257.6007	-31.52820
48.64050	258.6350	-31.56494
48.69217	259.6676	-31.62036
48.74383	260.7005	-31.66912
48.79550	261.7328	-31.71006
48.84716	262.7664	-31.76571
48.89883	263.7983	-31.82503
48.95050	264.8316	-31.88662
49.00050	265.8301	-31.94520
49.05383	266.8969	-32.01079
49.10383	267.8962	-32.06726
49.15717	268.9613	-32.12980
49.20717	269.9598	-32.19520
49.26050	271.0250	-32.25398
49.31050	272.0234	-32.30236
49.36383	273.0889	-32.37230
49.41383	274.0871	-32.44698
49.46717	275.1526	-32.51414
49.51383	276.0841	-32.55982
49.56550	276.8345	-32.73120
49.61716	276.8403	-29.69198
49.66716	276.5713	-23.94784
49.72050	276.0918	-17.10689
49.77050	275.5300	-11.03332
49.82383	274.8386	-5.427608
49.87383	274.1252	-0.9747124
49.92717	273.3104	2.959235
49.97717	272.5070	5.992864
50.03050	271.6141	8.636986
50.08050	270.7496	10.65753
50.13383	269.8057	12.44343
50.18383	268.9026	13.82910
50.23717	267.9243	15.06232
50.28717	266.9941	16.03265
50.33883	266.0240	16.87428
50.39050	265.0437	17.59098
50.44217	264.0575	18.19744
50.49383	263.0628	18.71113
50.54550	262.0646	19.15464
50.59716	261.0627	19.53802
50.64883	260.0565	19.87744
50.70050	259.0471	20.17125
50.75050	258.0680	20.41567
50.80383	257.0212	20.64267
50.85383	256.0388	20.82920
50.90717	254.9888	21.00655
50.95717	254.0029	21.16316
51.01050	252.9498	21.30694
51.06050	251.9612	21.42875
51.11383	250.9063	21.54033
51.16383	249.9169	21.63294
51.21717	248.8596	21.72736
51.26716	247.8698	21.80482
51.32050	246.8126	21.88309
51.37050	245.8209	21.94900
51.42217	244.7951	22.01246
51.47383	243.7696	22.06858
51.52550	242.7442	22.11514
51.57717	241.7174	22.16260
51.62883	240.6909	22.20246
51.68050	239.6645	22.24420
51.73217	238.6377	22.28838
51.78383	237.6107	22.32451
51.83383	236.6163	22.35605
51.88716	235.5553	22.39374
51.93716	234.5606	22.41658
51.99050	233.5003	22.44000
52.04050	232.5049	22.45725
52.09384	231.4442	22.47539
52.14384	230.4496	22.49332
52.19717	229.3878	22.51646
52.24717	228.3930	22.53652
52.30050	227.3319	22.56716
52.35050	226.3367	22.59065
52.40383	225.2749	22.61357
52.45383	224.2802	22.63879
52.50550	223.2506	22.65831
52.55717	222.2223	22.67347
52.60883	221.1938	22.68870
52.66050	220.1658	22.70301
52.71216	219.1367	22.72328
52.76382	218.1078	22.74525
52.81550	217.0788	22.75743
52.86716	216.0492	22.76791
52.91716	215.0544	22.77825
52.97050	213.9916	22.78911
53.02050	212.9960	22.79816
53.07383	211.9332	22.80811
53.12383	210.9380	22.81877
53.17717	209.8758	22.82882
53.22717	208.8799	22.84051
53.28050	207.8175	22.85070
53.33050	206.8208	22.86176
53.38383	205.7596	22.87274
53.43383	204.7627	22.88178
53.48717	203.6996	22.89209
53.53716	202.7025	22.90087
53.58882	201.6738	22.90790
53.64050	200.6434	22.91396
53.69216	199.6136	22.91948
53.74382	198.5841	22.92444
53.79550	197.5554	22.92905
53.84716	196.5259	22.93291
53.89883	195.4967	22.93732
53.95050	194.4678	22.94246
54.00050	193.4719	22.94880
54.05383	192.4099	22.95517
54.10383	191.4124	22.96086
54.15717	190.3491	22.96716
54.20717	189.3533	22.97170
54.26050	188.2903	22.97639
54.31050	187.2935	22.97970
54.36382	186.2308	22.98235
54.41382	185.2341	22.98516
54.46717	184.1711	22.98762
54.51716	183.1741	22.98937
54.57050	182.1118	22.99124
54.62050	181.1144	22.99261
54.67217	180.0839	22.99378
54.72382	179.0547	22.99605
54.77550	178.0251	23.00068
54.82717	176.9951	23.01260
54.87883	175.9680	23.04109
54.93050	174.9391	23.08519
54.98217	173.9110	23.14578
55.03383	172.8834	23.21138
55.08383	171.8893	23.27340
55.13716	170.8294	23.35818
55.18716	169.8363	23.45033
55.24050	168.7784	23.57552
55.29050	167.7895	23.74140
55.34384	166.7374	24.01014
55.39384	165.7583	24.43205
55.44717	164.7292	25.21882
55.49717	163.7839	26.45940
55.55050	162.8098	28.58030
55.60050	161.9406	31.52382
55.65383	161.0669	35.71272
55.70383	160.2883	40.37011
55.75550	159.5045	45.38521
55.80717	158.7108	49.97198
55.85883	157.8802	53.58748
55.91050	156.9926	55.98030
55.96216	156.0414	57.04946
56.01382	155.0259	56.87343
56.06550	153.9552	55.62180
56.11716	152.8375	53.51894
56.16716	151.7211	50.79543
56.22050	150.4841	47.13139
56.27050	149.3412	44.33400
56.32383	148.1367	41.56314
56.37383	147.0181	39.19798
56.42717	145.8389	36.97630
56.47717	144.7463	35.16529
56.53050	143.5964	33.50514
56.58050	142.5285	32.17174
56.63383	141.4003	30.95772
56.68383	140.3518	29.98013
56.73717	139.2404	29.09159
56.78716	138.2064	28.37762
56.83882	137.1414	27.73948
56.89050	136.0825	27.18825
56.94216	135.0278	26.71010
56.99382	133.9745	26.29416
57.04550	132.9270	25.93610
57.09716	131.8794	25.61862
57.14883	130.8341	25.33579
57.20050	129.7922	25.09110
57.25050	128.7833	24.87606
57.30383	127.7090	24.67175
57.35383	126.7020	24.49526
57.40717	125.6290	24.32266
57.45717	124.6245	24.17024
57.51050	123.5536	24.01936
57.56050	122.5493	23.88616
57.61382	121.4790	23.74627
57.66382	120.4763	23.63196
57.71717	119.4068	23.50962
57.76716	118.4038	23.41148
57.82050	117.3354	23.31101
57.87050	116.3335	23.22228
57.92217	115.2981	23.13478
57.97382	114.2631	23.04638
58.02550	113.2283	22.96260
58.07717	112.1932	22.88044
58.12883	111.1586	22.79750
58.18050	110.1240	22.71408
58.23217	109.0903	22.63598
58.28383	108.0556	22.55685
58.33383	107.0563	22.48158
58.38716	105.9880	22.40325
58.43716	104.9869	22.33325
58.49050	103.9206	22.25458
58.54050	102.9200	22.19384
58.59384	101.8535	22.12087
58.64384	100.8522	22.05416
58.69717	99.78526	21.98164
58.74717	98.78511	21.92208
58.80050	97.71782	21.85286
58.85050	96.71726	21.79644
58.90383	95.64966	21.72528
58.95383	94.64993	21.65932
59.00550	93.61644	21.59511
59.05717	92.58309	21.52754
59.10883	91.54890	21.45951
59.16050	90.51556	21.39682
59.21216	89.48176	21.31964
59.26382	88.44746	21.25263
59.31550	87.41431	21.17842
59.36716	86.38108	21.11766
59.41716	85.38106	21.04899
59.47050	84.31531	20.98056
59.52050	83.31564	20.92267
59.57383	82.24884	20.85995
59.62383	81.24993	20.80279
59.67717	80.18310	20.74334
59.72717	79.18413	20.68500
59.78050	78.11638	20.62424
59.83050	77.11595	20.56566
59.88383	76.04907	20.50838
59.93383	75.04960	20.45391
59.98717	73.98284	20.39509
60.03716	72.98169	20.33854
60.08882	71.94824	20.27824
60.14050	70.91494	20.21498
60.19216	69.88099	20.15894
60.24382	68.84768	20.09452
60.29550	67.81328	20.03093
60.34716	66.77910	19.96530
60.39883	65.74612	19.90108
60.45050	64.71272	19.83986
60.50050	63.71186	19.77742
60.55383	62.64459	19.70592
60.60383	61.64380	19.63584
60.65717	60.57637	19.56401
60.70717	59.57592	19.49381
60.76050	58.50906	19.42442
60.81050	57.50961	19.35811
60.86382	56.44195	19.28668
60.91382	55.44056	19.22465
60.96717	54.37339	19.15435
61.01716	53.37144	19.08842
61.07050	52.30388	19.01593
61.12050	51.30372	18.94774
61.17217	50.26941	18.87196
61.22382	49.23570	18.80244
61.27550	48.20120	18.73680
61.32717	47.16666	18.66757
61.37883	46.13338	18.60263
61.43050	45.09747	18.53454
61.48217	44.06400	18.46746
61.53383	43.02894	18.39973
61.58383	42.02799	18.33453
61.63716	40.95955	18.25581
61.68716	39.95874	18.18642
61.74050	38.89066	18.11016
61.79050	37.88918	18.03413
61.84384	36.82075	17.94157
61.89384	35.81886	17.86091
61.94717	34.74986	17.77689
61.99717	33.74759	17.69280
62.05050	32.67978	17.59736
62.10050	31.67824	17.50703
62.15383	30.60815	17.41516
62.20383	29.60671	17.33461
62.25550	28.57053	17.23780
62.30717	27.53330	17.14231
62.35883	26.49706	17.04016
62.41050	25.45967	16.94193
62.46216	24.42293	16.83568
62.51050	23.45250	16.73204
62.56050	22.66983	16.77797
62.61382	22.59802	15.31928
62.66382	22.80815	12.02031
62.71717	23.24590	7.921762
62.76716	23.77904	4.104776
62.82050	24.45326	0.4466498
62.87050	25.15992	-2.491543
62.92217	25.94910	-5.022530
62.97382	26.78514	-7.100832
63.02550	27.65784	-8.780701
63.07717	28.56015	-10.14361
63.12883	29.48510	-11.25283
63.18050	30.42902	-12.14475
63.23217	31.38775	-12.88425
63.28383	32.35806	-13.49554
63.33383	33.30691	-13.98131
63.38716	34.32626	-14.42030
63.43716	35.28894	-14.77155
63.49050	36.32051	-15.08906
63.54050	37.29265	-15.35207
63.59384	38.33230	-15.59917
63.64384	39.31020	-15.80065
63.69717	40.35638	-15.99212
63.74717	41.33860	-16.15438
63.80050	42.38956	-16.31484
63.85050	43.37519	-16.44384
63.90383	44.42840	-16.57863
63.95383	45.41722	-16.69432
64.00550	46.44020	-16.81085
64.05717	47.46440	-16.91934
64.10884	48.48853	-17.03349
64.16050	49.51348	-17.13510
64.21217	50.53937	-17.23005
64.26384	51.56536	-17.33719
64.31550	52.59209	-17.43175
64.36718	53.62029	-17.53141
64.41717	54.61437	-17.61796
64.47050	55.67706	-17.70785
64.52050	56.67176	-17.79519
64.57384	57.73322	-17.88693
64.62383	58.72930	-17.97346
64.67718	59.79211	-18.06147
64.72718	60.78962	-18.14552
64.78050	61.85089	-18.23886
64.83050	62.84928	-18.32039
64.88384	63.91130	-18.40971
64.93384	64.90834	-18.48694
64.98717	65.97119	-18.56903
65.03717	66.96829	-18.65061
65.08884	67.99852	-18.73593
65.14050	69.02884	-18.82207
65.19217	70.05948	-18.90265
65.24384	71.08955	-18.97975
65.29550	72.12050	-19.06467
65.34717	73.15110	-19.14979
65.39883	74.18068	-19.22868
65.45050	75.21260	-19.31014
65.50050	76.21046	-19.39144
65.55384	77.27385	-19.47772
65.60384	78.27199	-19.55871
65.65718	79.33570	-19.64464
65.70718	80.33324	-19.72499
65.76050	81.39795	-19.81552
65.81050	82.39660	-19.90191
65.86384	83.46028	-19.98310
65.91382	84.45844	-20.06370
65.96718	85.52290	-20.15134
66.01716	86.52106	-20.23439
66.07050	87.58368	-20.32472
66.12050	88.58184	-20.40700
66.17218	89.61318	-20.49888
66.22384	90.64410	-20.59419
66.27550	91.67428	-20.68111
66.32718	92.70491	-20.77062
66.37884	93.73545	-20.85905
66.43050	94.76590	-20.94758
66.48218	95.79639	-21.03930
66.53384	96.82808	-21.13108
66.58384	97.82647	-21.20726
66.63718	98.88968	-21.29688
66.68718	99.88671	-21.37544
66.74050	100.9509	-21.46839
66.79050	101.9484	-21.55682
66.84384	103.0122	-21.64780
66.89384	104.0100	-21.73090
66.94718	105.0729	-21.82621
66.99718	106.0705	-21.91633
67.05050	107.1340	-22.01502
67.10050	108.1313	-22.10440
67.15384	109.1945	-22.19535
67.20384	110.1918	-22.29179
67.25550	111.2221	-22.38898
67.30718	112.2518	-22.48320
67.35884	113.2830	-22.57908
67.41050	114.3139	-22.67260
67.46218	115.3444	-22.76260
67.51384	116.3741	-22.85590
67.56550	117.4050	-22.94592
67.61718	118.4349	-23.04051
67.66718	119.4324	-23.13283
67.72050	120.4961	-23.23976
67.77050	121.4938	-23.34673
67.82384	122.5571	-23.46055
67.87384	123.5523	-23.55960
67.92718	124.6133	-23.75354
67.97718	125.6084	-23.88431
68.03050	126.6671	-24.08405
68.08050	127.6610	-24.26616
68.13384	128.7186	-24.46397
68.18384	129.7151	-24.58362
68.23718	130.7769	-24.67909
68.28718	131.7752	-24.76613
68.33884	132.8072	-24.84392
68.39050	133.8382	-24.92662
68.44218	134.8688	-25.01858
68.49384	135.9000	-25.12570
68.54550	136.9303	-25.22493
68.59718	137.9614	-25.33184
68.64884	138.9910	-25.44158
68.70050	140.0209	-25.55373
68.75050	141.0164	-25.66868
68.80384	142.0805	-25.78682
68.85384	143.0768	-25.90738
68.90718	144.1402	-26.03296
68.95718	145.1364	-26.14902
69.01050	146.1984	-26.27231
69.06050	147.1947	-26.39572
69.11384	148.2581	-26.53256
69.16382	149.2535	-26.66178
69.21718	150.3158	-26.79351
69.26716	151.3113	-26.92031
69.32050	152.3740	-27.05997
69.37050	153.3698	-27.20015
69.42218	154.3975	-27.34175
69.47384	155.4256	-27.49320
69.52550	156.4541	-27.64390
69.57718	157.4817	-27.80008
69.62884	158.5102	-27.96096
69.68050	159.5396	-28.11312
69.73218	160.5668	-28.26306
69.78384	161.5950	-28.42035
69.83384	162.5907	-28.56972
69.88718	163.6522	-28.71600
69.93718	164.6484	-28.84384
69.99050	165.7101	-28.97022
70.04050	166.7078	-29.07896
70.09384	167.7728	-29.17355
70.14384	168.7711	-29.24856
70.19718	169.8367	-29.32095
70.24718	170.8362	-29.37874
70.30050	171.9020	-29.44224
70.35050	172.9013	-29.51104
70.40384	173.9670	-29.57744
70.45384	174.9649	-29.64874
70.50550	175.9966	-29.73380
70.55718	177.0274	-29.83530
70.60884	178.0577	-29.94982
70.66050	179.0864	-30.07541
70.71218	180.1146	-30.23149
70.76384	181.1412	-30.40485
70.81550	182.1666	-30.60592
70.86718	183.1923	-30.82546
70.91718	184.1835	-31.06506
70.97050	185.2395	-31.35507
71.02050	186.2281	-31.64587
71.07384	187.2809	-31.98817
71.12384	188.2673	-32.34709
71.17718	189.3176	-32.78286
71.22718	190.2988	-33.24185
71.28050	191.3430	-33.78445
71.33050	192.3190	-34.35972
71.38384	193.3576	-35.03774
71.43384	194.3276	-35.73036
71.48718	195.3617	-36.49783
71.53718	196.3284	-37.25235
71.58884	197.3276	-38.04828
71.64050	198.3262	-38.86175
71.69218	199.3220	-39.69482
71.74384	200.3178	-40.56555
71.79550	201.3106	-41.49232
71.84718	202.3009	-42.50019
71.89884	203.2874	-43.57446
71.95050	204.2712	-44.71720
72.00050	205.2209	-45.85907
72.05384	206.2332	-47.09728
72.10384	207.1842	-48.18770
72.15718	208.2046	-49.16320
72.20718	209.1751	-49.76660
72.26050	210.2286	-49.88522
72.31050	211.2459	-49.35118
72.36384	212.3664	-47.98050
72.41382	213.4502	-45.98027
72.46718	214.6360	-43.32381
72.51716	215.7580	-40.74122
72.57050	216.9456	-38.28518
72.62050	218.0430	-36.40100
72.67218	219.1560	-34.84026
72.72384	220.2530	-33.59552
72.77550	221.3380	-32.62850
72.82718	222.4116	-31.87139
72.87884	223.4780	-31.28010
72.93050	224.5361	-30.81758
72.98218	225.5896	-30.45532
73.03384	226.6396	-30.17636
73.08384	227.6518	-29.97432
73.13718	228.7282	-29.81161
73.18718	229.7354	-29.71414
73.24050	230.8082	-29.64336
73.29050	231.8135	-29.60188
73.34384	232.8843	-29.58424
73.39384	233.8864	-29.57906
73.44718	234.9555	-29.57624
73.49718	235.9574	-29.57704
73.55050	237.0251	-29.58342
73.60050	238.0256	-29.60587
73.65384	239.0934	-29.64682
73.70384	240.0950	-29.68255
73.75550	241.1281	-29.72947
73.80718	242.1624	-29.78045
73.85884	243.1960	-29.82854
73.91050	244.2297	-29.87930
73.96218	245.2623	-29.92687
74.01384	246.2965	-29.97834
74.06550	247.3297	-30.03255
74.11718	248.3632	-30.07696
74.16718	249.3623	-30.12137
74.22050	250.4298	-30.17249
74.27050	251.4292	-30.22360
74.32384	252.4948	-30.28215
74.37384	253.4943	-30.33509
74.42718	254.5598	-30.38544
74.47718	255.5599	-30.43647
74.53050	256.6260	-30.50134
74.58050	257.6242	-30.56262
74.63384	258.6914	-30.61934
74.68384	259.6905	-30.68106
74.73718	260.7570	-30.73820
74.78718	261.7558	-30.78990
74.83884	262.7885	-30.85308
74.89050	263.8215	-30.91575
74.94218	264.8537	-31.00473
74.99384	265.8853	-31.09372
75.04550	266.9164	-31.19082
75.09718	267.9469	-31.28654
75.14884	268.9772	-31.40063
75.20050	270.0079	-31.49940
75.25050	271.0055	-31.59648
75.30384	272.0700	-31.68792
-2.000000	5.000000	0.0000000