File: 1-C1(0.6mol%)+C20(0.6mol%)/matlab/160-3.txt
CLOSED
Version	1.0
Language	English
Mode	Standard
Run	9
RunSerial	11859
Instrument	DSC Q2000 V24.11 Build 124
Module	DSC Standard Cell RC
Operator	Jing
File	\\AE520-1454\TA\Data\DSC\UQ Composites\Nan\C1(5.5)+C20P(3)+CL(HotplateMixtureAB)\160-3
ProcName	Ramp
InstSerial	2000-0883
AutoSerial	1293
Sample	Iso-160-3
Size	31.3000	mg
PanMass	Not available
PanResist	Automatic Automatic  K/W
PanFactor	Default Default
Method	Ramp
Comment
Xcomment	Pan: Tzero Aluminum Hermetic
Xcomment	Gas1: Nitrogen 50.0 ml/min
Xcomment	Gas2: Nitrogen 50.0 ml/min
Text
Exotherm	UP
Kcell	1.05230
Cpconst	Standard: 0.938
Calib	-38.6961
TempCal	1	pts	157.46	156.60
TzeroDt	-87.6168 -0.0009 -1.4231
TzeroDtz	-87.6168 0.0057 6.9570
InstCalFile	Tzero: \\Ae520-1454\ta\Data\DSC\Calibration\2017\CALIBRATION\1562_RCS (90)_05_18_2017 10_50_44.TZR
InstCalFile	Baseline: \\Ae520-1454\ta\Data\DSC\Calibration\2017\2017-05-17_Calibration.001
InstCalFile	Sapphire: \\Ae520-1454\ta\Data\DSC\Calibration\2017\2017-05-17_Saphire.001
InstCalDate	Tzero 2017-05-18 Time 10:50:44
TempRange	-87.39 to 398.39 °C at 10.00 °C/min Heat Only
AutoZero	Delta T Offset 0.000 uV
AutoZero	Delta T0 Offset 0.000 uV
MultiptCal	0
MultiPtDesc	0) Not set
AutoCellConst	Calibration Date 2017-05-18 16:59:28
Controls	Gas 1  Event Off  Sampling 0.2
Cell#	RC-01562
CoolingUnit	RCS (90)
SelHeatFlow	Heat Flow T4 (mW)
AutoLidII	Installed
AutoAnalysis	Off
MacroFile
Nsig	3
Sig1	Time (min)
Sig2	Temperature (°C)
Sig3	Heat Flow (mW)
Date	2017-06-21
Time	03:32:51
OrgMethod	1: Equilibrate at 20.00 °C
OrgMethod	2: Ramp 40.00 °C/min to 160.00 °C
OrgMethod	3: Mark end of cycle 1
OrgMethod	4: Isothermal for 40.00 min
OrgMethod	5: Mark end of cycle 2
OrgMethod	6: Ramp 20.00 °C/min to 280.00 °C
OrgMethod	7: Mark end of cycle 3
OrgMethod	8: Ramp 20.00 °C/min to 20.00 °C
OrgMethod	9: Mark end of cycle 4
OrgMethod	10: Ramp 20.00 °C/min to 280.00 °C
OrgMethod	11: Mark end of cycle 5
OrgFile	C:\Users\jarra\Desktop\DSC\1-C1(0.6mol%)+C20(0.6mol%)\160-3.001
StartOfData
4.99994E-4	20.05333	-0.1364615
0.05383332	20.17021	0.04285269
0.1038333	20.99437	-0.2842431
0.1571666	22.28789	-3.000388
0.2071666	23.68863	-6.212356
0.2605000	25.33767	-9.681053
0.3105000	26.97880	-12.58777
0.3638334	28.81104	-15.20316
0.4138333	30.58420	-17.19611
0.4671667	32.52178	-18.89832
0.5171667	34.37340	-20.15839
0.5705000	36.37419	-21.22892
0.6205000	38.27089	-22.03985
0.6721668	40.24610	-22.72514
0.7238332	42.23268	-23.32602
0.7755000	44.22530	-23.93724
0.8271668	46.22500	-24.43223
0.8788332	48.23666	-24.78017
0.9305000	50.25449	-25.11936
0.9821668	52.27344	-25.58787
1.033833	54.27549	-26.58626
1.083833	56.17385	-28.30167
1.137166	58.19853	-29.68365
1.187166	60.14200	-30.12285
1.240500	62.23863	-30.61047
1.290500	64.18984	-31.49813
1.343833	66.23461	-33.29703
1.393833	68.08212	-36.64228
1.447166	69.89728	-43.79560
1.497166	71.37389	-54.84358
1.550500	72.74855	-69.46646
1.600500	74.00478	-82.69397
1.653833	75.44472	-94.39920
1.703833	76.84179	-105.7911
1.755500	78.24685	-118.2700
1.807167	79.54764	-132.5489
1.858834	81.03366	-141.8367
1.910500	82.72976	-146.7736
1.962166	85.10454	-135.9712
2.013833	87.76446	-126.1645
2.065500	90.43453	-114.1090
2.117167	93.33194	-98.68928
2.167167	96.04856	-86.75707
2.220500	98.79619	-76.63428
2.270500	101.2500	-69.15024
2.323833	103.7654	-62.88076
2.373834	106.0482	-58.29734
2.427167	108.4176	-54.48717
2.477167	110.5918	-51.73290
2.530500	112.8714	-49.46478
2.580500	114.9776	-47.84171
2.633833	117.1996	-46.53730
2.683833	119.2644	-45.62404
2.737167	121.4513	-44.92136
2.787167	123.4926	-44.43754
2.838833	125.5946	-44.06409
2.890500	127.6900	-43.76881
2.942167	129.7814	-43.53795
2.993833	131.8698	-43.38374
3.045500	133.9547	-43.27304
3.097167	136.0385	-43.22540
3.148833	138.1186	-43.22044
3.200500	140.1972	-43.22568
3.250500	142.2067	-43.26627
3.303833	144.3495	-43.33819
3.353833	146.3578	-43.39948
3.407167	148.4982	-43.48654
3.457167	150.5046	-43.57297
3.505500	152.4439	-43.64642
3.557167	154.3875	-43.77623
3.608833	155.5696	-42.67334
3.660500	156.3855	-38.28728
3.712167	157.0115	-32.91091
3.763833	157.5058	-27.52137
3.815500	157.9036	-22.69518
3.867166	158.2278	-18.58442
3.917167	158.4833	-15.28818
3.970500	158.7079	-12.42368
4.020500	158.8796	-10.25404
4.073834	159.0327	-8.393074
4.123833	159.1511	-6.987947
4.177166	159.2562	-5.783350
4.227167	159.3390	-4.869636
4.280500	159.4118	-4.079075
4.330500	159.4694	-3.478967
4.383834	159.5205	-2.951836
4.433834	159.5627	-2.547057
4.487167	159.5988	-2.187255
4.537167	159.6289	-1.908895
4.588834	159.6553	-1.665785
4.640500	159.6778	-1.459412
4.692166	159.6974	-1.282775
4.743834	159.7147	-1.128686
4.795500	159.7298	-0.9933769
4.847166	159.7430	-0.8773953
4.898834	159.7551	-0.7709628
4.950500	159.7655	-0.6783910
5.000500	159.7739	-0.5903849
5.053834	159.7839	-0.5065781
5.103833	159.7919	-0.4328517
5.157166	159.7981	-0.3548694
5.207167	159.8045	-0.2879995
5.260500	159.8112	-0.2172234
5.310500	159.8178	-0.1526720
5.363834	159.8236	-.08380429
5.413832	159.8294	-.01958830
5.467168	159.8344	0.04948791
5.517168	159.8397	0.1104514
5.570500	159.8444	0.1827622
5.620500	159.8484	0.2472776
5.672168	159.8533	0.3114104
5.723834	159.8570	0.3822042
5.775500	159.8628	0.4496186
5.827168	159.8676	0.5194256
5.878834	159.8720	0.5896101
5.930500	159.8762	0.6635507
5.982168	159.8803	0.7387372
6.033832	159.8849	0.8122222
6.083832	159.8887	0.8892350
6.137168	159.8946	0.9665230
6.187168	159.8985	1.046296
6.240500	159.9035	1.126608
6.290500	159.9077	1.205331
6.343834	159.9119	1.295720
6.393832	159.9168	1.375954
6.447168	159.9213	1.465647
6.497168	159.9262	1.553186
6.550500	159.9319	1.647804
6.600500	159.9359	1.735230
6.653832	159.9417	1.831752
6.703832	159.9463	1.924590
6.755500	159.9516	2.025790
6.807166	159.9566	2.125853
6.858832	159.9622	2.223658
6.910500	159.9673	2.328016
6.962168	159.9735	2.432662
7.013834	159.9788	2.539850
7.065500	159.9842	2.652590
7.117166	159.9904	2.764256
7.167168	159.9954	2.869790
7.220500	160.0019	2.990591
7.270500	160.0074	3.104200
7.323834	160.0144	3.224745
7.373834	160.0205	3.342597
7.427168	160.0271	3.469578
7.477168	160.0331	3.589232
7.530500	160.0387	3.718848
7.580500	160.0461	3.841460
7.633832	160.0526	3.975076
7.683832	160.0588	4.098590
7.737168	160.0665	4.234818
7.787168	160.0710	4.365672
7.838834	160.0792	4.496530
7.890500	160.0856	4.628809
7.942168	160.0925	4.763234
7.993834	160.0988	4.898812
8.045500	160.1059	5.027578
8.097168	160.1133	5.162032
8.148834	160.1194	5.294045
8.200500	160.1258	5.426001
8.250500	160.1322	5.554826
8.303832	160.1395	5.694770
8.353832	160.1467	5.831808
8.407166	160.1532	5.984630
8.457168	160.1620	6.143082
8.510499	160.1706	6.320050
8.560500	160.1792	6.504607
8.613834	160.1896	6.724529
8.663834	160.2006	6.950947
8.717168	160.2135	7.219344
8.767168	160.2266	7.485564
8.820500	160.2423	7.787088
8.870499	160.2565	8.085476
8.922168	160.2719	8.403651
8.973832	160.2875	8.725908
9.025499	160.3037	9.049747
9.077168	160.3198	9.374528
9.128834	160.3359	9.688544
9.180500	160.3518	9.994994
9.232166	160.3662	10.28821
9.283832	160.3804	10.57436
9.333832	160.3939	10.83710
9.387168	160.4077	11.10655
9.437166	160.4196	11.34641
9.490500	160.4329	11.59410
9.540500	160.4436	11.80875
9.593832	160.4541	12.02428
9.643832	160.4642	12.21766
9.697168	160.4733	12.40587
9.747168	160.4821	12.56847
9.800500	160.4904	12.73147
9.850500	160.4982	12.86671
9.903832	160.5047	12.99796
9.953834	160.5107	13.10769
10.00550	160.5157	13.20627
10.05717	160.5205	13.29414
10.10883	160.5244	13.36902
10.16050	160.5280	13.43099
10.21217	160.5298	13.47905
10.26383	160.5319	13.51740
10.31550	160.5342	13.54393
10.36717	160.5356	13.56006
10.41717	160.5359	13.56942
10.47050	160.5368	13.57498
10.52050	160.5366	13.57938
10.57383	160.5364	13.58237
10.62383	160.5363	13.58228
10.67717	160.5350	13.57347
10.72717	160.5338	13.54661
10.78050	160.5326	13.49612
10.83050	160.5303	13.44208
10.88383	160.5277	13.37870
10.93383	160.5244	13.31020
10.98717	160.5208	13.22712
11.03717	160.5172	13.14581
11.08883	160.5130	13.05890
11.14050	160.5072	12.96670
11.19217	160.5031	12.87236
11.24384	160.4988	12.77610
11.29550	160.4935	12.67733
11.34717	160.4888	12.57913
11.39883	160.4840	12.48095
11.45050	160.4791	12.38737
11.50050	160.4753	12.29576
11.55383	160.4702	12.19807
11.60383	160.4655	12.11277
11.65717	160.4612	12.02626
11.70717	160.4581	11.94203
11.76050	160.4539	11.85519
11.81050	160.4500	11.78012
11.86383	160.4461	11.70311
11.91383	160.4423	11.63679
11.96717	160.4392	11.56834
12.01717	160.4360	11.50829
12.07050	160.4334	11.44907
12.12050	160.4307	11.39817
12.17217	160.4279	11.34863
12.22383	160.4258	11.30345
12.27550	160.4239	11.26177
12.32717	160.4219	11.22536
12.37884	160.4201	11.19307
12.43050	160.4183	11.16536
12.48217	160.4170	11.14108
12.53383	160.4163	11.12258
12.58383	160.4154	11.11094
12.63717	160.4148	11.10233
12.68716	160.4148	11.09611
12.74050	160.4144	11.09062
12.79050	160.4141	11.08697
12.84383	160.4157	11.08580
12.89383	160.4160	11.08799
12.94717	160.4170	11.10099
12.99717	160.4180	11.12198
13.05050	160.4195	11.15090
13.10050	160.4214	11.18342
13.15383	160.4226	11.22448
13.20383	160.4251	11.26056
13.25550	160.4264	11.29725
13.30717	160.4287	11.33824
13.35883	160.4303	11.37898
13.41050	160.4320	11.41780
13.46217	160.4342	11.46044
13.51383	160.4362	11.49971
13.56550	160.4381	11.54661
13.61716	160.4408	11.59442
13.66716	160.4432	11.63720
13.72050	160.4445	11.68650
13.77050	160.4475	11.72408
13.82384	160.4496	11.75359
13.87384	160.4507	11.76761
13.92717	160.4505	11.77134
13.97717	160.4504	11.76584
14.03050	160.4474	11.69888
14.08050	160.4432	11.59399
14.13383	160.4371	11.45613
14.18383	160.4302	11.29450
14.23716	160.4195	11.08762
14.28717	160.4095	10.86478
14.33883	160.3975	10.60303
14.39050	160.3833	10.31750
14.44217	160.3689	10.00771
14.49384	160.3537	9.687304
14.54550	160.3376	9.351045
14.59717	160.3204	9.006109
14.64883	160.3030	8.658676
14.70050	160.2854	8.307105
14.75050	160.2686	7.964690
14.80383	160.2521	7.604511
14.85383	160.2352	7.272046
14.90717	160.2174	6.913130
14.95717	160.2011	6.585949
15.01050	160.1843	6.240628
15.06050	160.1678	5.924554
15.11383	160.1521	5.593904
15.16383	160.1371	5.292534
15.21716	160.1213	4.979384
15.26717	160.1066	4.696287
15.32050	160.0928	4.400220
15.37050	160.0792	4.135048
15.42217	160.0659	3.869456
15.47383	160.0527	3.614732
15.52550	160.0409	3.373779
15.57717	160.0289	3.139917
15.62883	160.0179	2.918545
15.68050	160.0074	2.704250
15.73216	159.9966	2.504705
15.78383	159.9878	2.308458
15.83383	159.9782	2.131029
15.88716	159.9698	1.951048
15.93717	159.9619	1.790351
15.99050	159.9544	1.628460
16.04050	159.9468	1.485186
16.09383	159.9393	1.340050
16.14383	159.9326	1.216230
16.19717	159.9265	1.088309
16.24716	159.9201	0.9751350
16.30050	159.9147	0.8614716
16.35050	159.9099	0.7614600
16.40383	159.9047	0.6563494
16.45383	159.8999	0.5689510
16.50550	159.8953	0.4810329
16.55716	159.8914	0.3954564
16.60883	159.8873	0.3190732
16.66050	159.8832	0.2432775
16.71216	159.8802	0.1718434
16.76383	159.8768	0.1045698
16.81550	159.8734	0.04200589
16.86716	159.8704	-.01835032
16.91716	159.8680	-.07220354
16.97050	159.8644	-0.1241830
17.02050	159.8624	-0.1739218
17.07383	159.8596	-0.2223477
17.12383	159.8572	-0.2545842
17.17716	159.8567	-0.2811351
17.22716	159.8556	-0.3081070
17.28050	159.8536	-0.3460759
17.33050	159.8516	-0.3893342
17.38383	159.8497	-0.4259829
17.43383	159.8483	-0.4606686
17.48716	159.8469	-0.4993820
17.53717	159.8457	-0.5252180
17.58883	159.8442	-0.5557730
17.64050	159.8433	-0.5864850
17.69216	159.8416	-0.6109907
17.74383	159.8396	-0.6326313
17.79550	159.8392	-0.6553379
17.84716	159.8372	-0.6767993
17.89883	159.8369	-0.6972218
17.95050	159.8353	-0.7167601
18.00050	159.8345	-0.7329321
18.05383	159.8334	-0.7505600
18.10383	159.8324	-0.7688125
18.15716	159.8314	-0.7842688
18.20716	159.8298	-0.7993851
18.26050	159.8297	-0.8151368
18.31050	159.8280	-0.8257178
18.36383	159.8274	-0.8392386
18.41383	159.8265	-0.8513124
18.46716	159.8262	-0.8625147
18.51716	159.8251	-0.8749509
18.57050	159.8246	-0.8874141
18.62050	159.8243	-0.8979476
18.67216	159.8234	-0.9085078
18.72383	159.8229	-0.9194232
18.77550	159.8224	-0.9296751
18.82716	159.8226	-0.9403586
18.87883	159.8214	-0.9508094
18.93050	159.8216	-0.9604264
18.98216	159.8212	-0.9704639
19.03383	159.8200	-0.9801689
19.08383	159.8204	-0.9892028
19.13716	159.8196	-0.9987024
19.18716	159.8198	-1.007045
19.24050	159.8190	-1.015467
19.29050	159.8192	-1.023086
19.34383	159.8186	-1.031018
19.39383	159.8182	-1.037981
19.44716	159.8184	-1.045251
19.49716	159.8181	-1.051979
19.55050	159.8181	-1.058779
19.60050	159.8171	-1.065053
19.65383	159.8170	-1.071430
19.70383	159.8171	-1.077206
19.75550	159.8169	-1.082778
19.80716	159.8161	-1.088290
19.85883	159.8160	-1.093589
19.91050	159.8159	-1.098995
19.96216	159.8157	-1.104014
20.01383	159.8157	-1.108916
20.06550	159.8156	-1.113507
20.11716	159.8156	-1.118064
20.16716	159.8154	-1.122279
20.22050	159.8151	-1.126718
20.27050	159.8145	-1.130497
20.32383	159.8142	-1.134361
20.37383	159.8150	-1.138230
20.42716	159.8141	-1.142066
20.47716	159.8143	-1.145561
20.53050	159.8141	-1.149228
20.58050	159.8135	-1.152532
20.63383	159.8136	-1.156195
20.68383	159.8139	-1.159638
20.73716	159.8141	-1.163000
20.78717	159.8136	-1.166153
20.83883	159.8136	-1.169430
20.89050	159.8130	-1.172161
20.94216	159.8132	-1.174952
20.99383	159.8119	-1.177576
21.04550	159.8126	-1.180123
21.09716	159.8128	-1.182616
21.14883	159.8122	-1.185186
21.20050	159.8122	-1.187357
21.25050	159.8121	-1.189624
21.30383	159.8125	-1.192204
21.35383	159.8116	-1.194446
21.40716	159.8125	-1.197439
21.45717	159.8125	-1.199974
21.51050	159.8124	-1.202423
21.56050	159.8128	-1.204473
21.61383	159.8126	-1.206668
21.66383	159.8121	-1.208302
21.71716	159.8128	-1.210327
21.76716	159.8127	-1.212353
21.82050	159.8131	-1.214465
21.87050	159.8130	-1.216605
21.92216	159.8132	-1.219023
21.97383	159.8130	-1.221286
22.02550	159.8132	-1.223302
22.07716	159.8133	-1.225115
22.12883	159.8133	-1.226444
22.18050	159.8129	-1.227900
22.23216	159.8128	-1.229519
22.28383	159.8132	-1.230784
22.33383	159.8118	-1.231681
22.38716	159.8118	-1.232590
22.43716	159.8116	-1.233356
22.49050	159.8110	-1.233910
22.54050	159.8114	-1.234529
22.59383	159.8115	-1.235179
22.64383	159.8110	-1.236060
22.69716	159.8099	-1.237187
22.74716	159.8102	-1.238260
22.80050	159.8104	-1.239886
22.85050	159.8106	-1.241248
22.90383	159.8111	-1.243034
22.95383	159.8116	-1.244744
23.00550	159.8104	-1.246554
23.05716	159.8111	-1.247921
23.10883	159.8104	-1.249394
23.16050	159.8105	-1.250631
23.21216	159.8101	-1.251448
23.26383	159.8102	-1.252150
23.31550	159.8096	-1.252548
23.36716	159.8098	-1.253139
23.41716	159.8095	-1.253963
23.47050	159.8096	-1.254786
23.52050	159.8096	-1.255636
23.57383	159.8096	-1.256882
23.62383	159.8091	-1.257723
23.67717	159.8083	-1.258851
23.72716	159.8095	-1.259891
23.78050	159.8096	-1.260840
23.83050	159.8080	-1.261507
23.88383	159.8084	-1.262424
23.93383	159.8084	-1.263124
23.98716	159.8092	-1.263918
24.03717	159.8090	-1.264790
24.08883	159.8084	-1.265736
24.14050	159.8085	-1.266918
24.19216	159.8089	-1.268310
24.24383	159.8092	-1.269663
24.29550	159.8092	-1.270923
24.34716	159.8093	-1.272352
24.39883	159.8094	-1.273628
24.45050	159.8098	-1.274819
24.50050	159.8093	-1.276120
24.55383	159.8097	-1.276975
24.60383	159.8097	-1.277652
24.65716	159.8106	-1.278394
24.70717	159.8087	-1.278633
24.76050	159.8095	-1.278764
24.81050	159.8104	-1.279036
24.86383	159.8093	-1.278771
24.91383	159.8094	-1.278798
24.96716	159.8085	-1.279064
25.01716	159.8085	-1.279064
25.07050	159.8095	-1.279307
25.12050	159.8090	-1.279838
25.17216	159.8094	-1.280537
25.22383	159.8098	-1.281734
25.27550	159.8091	-1.283102
25.32716	159.8092	-1.283966
25.37883	159.8096	-1.284853
25.43050	159.8089	-1.285735
25.48216	159.8089	-1.286011
25.53383	159.8096	-1.286353
25.58383	159.8093	-1.286906
25.63716	159.8078	-1.287007
25.68717	159.8090	-1.287112
25.74050	159.8081	-1.287273
25.79050	159.8087	-1.287137
25.84383	159.8075	-1.287157
25.89383	159.8080	-1.287175
25.94717	159.8076	-1.287302
25.99716	159.8070	-1.287504
26.05050	159.8080	-1.288094
26.10050	159.8073	-1.288686
26.15383	159.8084	-1.289453
26.20383	159.8070	-1.290194
26.25550	159.8083	-1.290770
26.30716	159.8080	-1.291554
26.35883	159.8076	-1.292243
26.41050	159.8089	-1.292899
26.46216	159.8082	-1.293588
26.51383	159.8084	-1.294542
26.56550	159.8085	-1.295610
26.61716	159.8091	-1.296656
26.66716	159.8092	-1.297766
26.72050	159.8091	-1.298593
26.77050	159.8100	-1.299341
26.82383	159.8097	-1.299976
26.87383	159.8094	-1.300463
26.92717	159.8094	-1.300699
26.97717	159.8099	-1.300968
27.03050	159.8092	-1.301090
27.08050	159.8095	-1.301326
27.13383	159.8088	-1.301530
27.18383	159.8083	-1.301244
27.23716	159.8088	-1.301089
27.28717	159.8086	-1.300907
27.33883	159.8084	-1.300769
27.39050	159.8080	-1.300656
27.44216	159.8082	-1.300730
27.49383	159.8083	-1.301088
27.54550	159.8083	-1.301651
27.59716	159.8078	-1.302078
27.64883	159.8084	-1.302356
27.70050	159.8087	-1.302913
27.75050	159.8079	-1.303244
27.80383	159.8086	-1.303592
27.85383	159.8085	-1.304246
27.90716	159.8093	-1.304784
27.95716	159.8086	-1.305394
28.01050	159.8087	-1.306166
28.06050	159.8084	-1.306792
28.11383	159.8089	-1.307061
28.16383	159.8087	-1.307410
28.21716	159.8084	-1.307538
28.26716	159.8090	-1.307787
28.32050	159.8083	-1.307729
28.37050	159.8082	-1.307410
28.42216	159.8080	-1.307180
28.47383	159.8080	-1.307122
28.52550	159.8078	-1.306740
28.57717	159.8071	-1.306307
28.62883	159.8073	-1.306392
28.68050	159.8079	-1.306319
28.73216	159.8080	-1.306766
28.78383	159.8076	-1.307368
28.83383	159.8077	-1.307883
28.88716	159.8084	-1.308344
28.93717	159.8079	-1.308948
28.99050	159.8081	-1.309326
29.04050	159.8077	-1.309881
29.09383	159.8082	-1.310593
29.14383	159.8077	-1.311254
29.19717	159.8084	-1.312250
29.24716	159.8088	-1.313040
29.30050	159.8082	-1.313658
29.35050	159.8081	-1.314014
29.40383	159.8074	-1.314242
29.45383	159.8079	-1.314292
29.50550	159.8078	-1.314508
29.55716	159.8079	-1.314331
29.60883	159.8073	-1.313938
29.66050	159.8074	-1.313759
29.71216	159.8069	-1.313577
29.76383	159.8075	-1.313578
29.81550	159.8071	-1.313695
29.86716	159.8072	-1.313824
29.91716	159.8073	-1.313988
29.97050	159.8074	-1.314418
30.02050	159.8075	-1.314834
30.07383	159.8079	-1.315248
30.12383	159.8078	-1.315634
30.17717	159.8080	-1.316008
30.22717	159.8087	-1.316690
30.28050	159.8085	-1.317406
30.33050	159.8080	-1.318102
30.38383	159.8070	-1.318422
30.43383	159.8078	-1.318829
30.48716	159.8072	-1.319105
30.53717	159.8085	-1.319037
30.58883	159.8079	-1.318798
30.64050	159.8075	-1.318343
30.69216	159.8071	-1.318048
30.74383	159.8074	-1.317891
30.79550	159.8071	-1.317966
30.84716	159.8078	-1.317704
30.89883	159.8068	-1.317827
30.95050	159.8076	-1.317794
31.00050	159.8072	-1.317905
31.05383	159.8068	-1.317886
31.10383	159.8074	-1.317994
31.15716	159.8070	-1.318266
31.20716	159.8071	-1.318625
31.26050	159.8078	-1.319363
31.31050	159.8073	-1.319966
31.36383	159.8076	-1.320678
31.41383	159.8078	-1.321129
31.46716	159.8084	-1.321584
31.51716	159.8086	-1.322024
31.57050	159.8078	-1.322291
31.62050	159.8076	-1.322398
31.67216	159.8082	-1.322615
31.72383	159.8077	-1.322647
31.77550	159.8083	-1.322636
31.82717	159.8095	-1.323130
31.87883	159.8087	-1.323712
31.93050	159.8092	-1.324104
31.98216	159.8091	-1.324520
32.03383	159.8084	-1.324736
32.08383	159.8080	-1.324690
32.13716	159.8088	-1.324731
32.18716	159.8085	-1.324412
32.24050	159.8076	-1.323892
32.29050	159.8085	-1.323522
32.34384	159.8078	-1.323301
32.39383	159.8086	-1.323074
32.44717	159.8080	-1.323194
32.49716	159.8086	-1.323236
32.55050	159.8082	-1.323178
32.60050	159.8082	-1.323236
32.65383	159.8084	-1.322980
32.70383	159.8074	-1.322694
32.75550	159.8073	-1.322347
32.80716	159.8068	-1.322026
32.85883	159.8075	-1.321549
32.91050	159.8073	-1.321323
32.96216	159.8066	-1.321121
33.01383	159.8075	-1.321225
33.06550	159.8073	-1.321783
33.11716	159.8076	-1.322312
33.16716	159.8078	-1.323272
33.22050	159.8077	-1.324354
33.27050	159.8078	-1.325289
33.32383	159.8079	-1.325942
33.37383	159.8079	-1.326544
33.42717	159.8080	-1.326787
33.47717	159.8090	-1.326979
33.53050	159.8086	-1.327058
33.58050	159.8084	-1.327024
33.63383	159.8090	-1.327397
33.68384	159.8082	-1.327827
33.73717	159.8080	-1.327804
33.78717	159.8086	-1.327792
33.83883	159.8085	-1.327679
33.89050	159.8080	-1.327424
33.94216	159.8077	-1.327302
33.99383	159.8074	-1.327202
34.04550	159.8071	-1.326683
34.09716	159.8073	-1.326294
34.14883	159.8072	-1.326093
34.20050	159.8071	-1.325861
34.25050	159.8076	-1.325778
34.30383	159.8073	-1.325841
34.35383	159.8084	-1.325992
34.40716	159.8077	-1.326098
34.45716	159.8075	-1.326561
34.51050	159.8080	-1.326805
34.56050	159.8084	-1.327162
34.61383	159.8068	-1.327672
34.66383	159.8078	-1.327991
34.71716	159.8077	-1.328495
34.76716	159.8084	-1.328951
34.82050	159.8080	-1.329114
34.87050	159.8081	-1.329302
34.92216	159.8079	-1.329516
34.97383	159.8078	-1.329536
35.02550	159.8079	-1.329737
35.07717	159.8073	-1.329997
35.12883	159.8079	-1.330072
35.18050	159.8074	-1.330044
35.23216	159.8080	-1.329964
35.28383	159.8081	-1.329831
35.33383	159.8077	-1.329592
35.38716	159.8071	-1.329431
35.43716	159.8065	-1.329046
35.49050	159.8066	-1.328693
35.54050	159.8066	-1.328256
35.59384	159.8065	-1.327689
35.64383	159.8070	-1.327504
35.69717	159.8069	-1.327758
35.74716	159.8078	-1.328173
35.80050	159.8081	-1.328961
35.85050	159.8073	-1.329764
35.90383	159.8082	-1.330551
35.95383	159.8080	-1.331258
36.00550	159.8074	-1.331964
36.05716	159.8081	-1.332301
36.10883	159.8074	-1.332487
36.16050	159.8079	-1.332250
36.21216	159.8077	-1.331758
36.26383	159.8070	-1.331007
36.31550	159.8073	-1.330524
36.36716	159.8069	-1.330172
36.41716	159.8075	-1.329910
36.47050	159.8076	-1.329762
36.52050	159.8070	-1.329609
36.57383	159.8072	-1.329750
36.62383	159.8074	-1.330060
36.67717	159.8074	-1.330609
36.72717	159.8079	-1.331140
36.78050	159.8082	-1.331889
36.83050	159.8077	-1.332181
36.88383	159.8079	-1.332305
36.93384	159.8071	-1.332176
36.98717	159.8072	-1.331928
37.03717	159.8069	-1.331526
37.08883	159.8069	-1.331436
37.14050	159.8072	-1.331440
37.19216	159.8071	-1.331582
37.24383	159.8069	-1.331608
37.29550	159.8074	-1.331624
37.34716	159.8086	-1.332133
37.39883	159.8078	-1.332785
37.45050	159.8080	-1.333310
37.50050	159.8070	-1.333866
37.55383	159.8079	-1.334378
37.60383	159.8075	-1.334850
37.65716	159.8075	-1.334835
37.70716	159.8074	-1.334642
37.76050	159.8081	-1.333988
37.81050	159.8076	-1.333641
37.86383	159.8073	-1.333244
37.91383	159.8072	-1.332844
37.96716	159.8072	-1.332675
38.01716	159.8070	-1.332662
38.07050	159.8073	-1.332558
38.12050	159.8084	-1.332610
38.17216	159.8070	-1.332583
38.22383	159.8070	-1.332519
38.27550	159.8071	-1.332601
38.32717	159.8069	-1.332966
38.37883	159.8072	-1.333049
38.43050	159.8080	-1.333240
38.48216	159.8080	-1.333617
38.53383	159.8076	-1.333880
38.58383	159.8078	-1.334230
38.63716	159.8075	-1.334624
38.68716	159.8077	-1.334705
38.74050	159.8080	-1.334696
38.79050	159.8075	-1.334376
38.84384	159.8082	-1.334064
38.89383	159.8064	-1.333691
38.94717	159.8073	-1.333347
38.99716	159.8072	-1.333380
39.05050	159.8076	-1.333556
39.10050	159.8069	-1.333586
39.15383	159.8072	-1.333531
39.20383	159.8070	-1.333905
39.25550	159.8074	-1.334113
39.30716	159.8072	-1.334221
39.35883	159.8079	-1.334815
39.41050	159.8075	-1.335600
39.46216	159.8078	-1.336262
39.51383	159.8076	-1.336914
39.56550	159.8074	-1.337262
39.61716	159.8077	-1.337370
39.66716	159.8071	-1.337459
39.72050	159.8072	-1.336894
39.77050	159.8072	-1.336477
39.82383	159.8066	-1.336114
39.87383	159.8069	-1.335681
39.92717	159.8073	-1.335299
39.97717	159.8066	-1.335342
40.03050	159.8066	-1.335321
40.08050	159.8072	-1.335214
40.13383	159.8072	-1.335386
40.18384	159.8076	-1.335608
40.23717	159.8070	-1.335838
40.28717	159.8072	-1.336170
40.33883	159.8074	-1.336436
40.39050	159.8080	-1.336926
40.44216	159.8082	-1.337624
40.49383	159.8080	-1.338068
40.54550	159.8082	-1.338412
40.59716	159.8078	-1.338766
40.64883	159.8072	-1.338638
40.70050	159.8084	-1.338376
40.75050	159.8079	-1.338037
40.80383	159.8073	-1.337705
40.85383	159.8076	-1.337350
40.90716	159.8069	-1.336859
40.95716	159.8071	-1.336446
41.01050	159.8078	-1.336142
41.06050	159.8078	-1.336011
41.11383	159.8075	-1.335890
41.16383	159.8080	-1.335790
41.21717	159.8079	-1.336030
41.26717	159.8073	-1.336279
41.32050	159.8075	-1.336495
41.37050	159.8074	-1.336990
41.42216	159.8084	-1.337255
41.47383	159.8078	-1.337317
41.52550	159.8077	-1.337684
41.57717	159.8082	-1.337776
41.62883	159.8075	-1.337794
41.68050	159.8078	-1.337666
41.73217	159.8076	-1.337535
41.78383	159.8080	-1.337554
41.83383	159.8071	-1.337872
41.88716	159.8074	-1.337889
41.93716	159.8077	-1.338118
41.99050	159.8075	-1.338447
42.04050	159.8082	-1.338428
42.09384	159.8077	-1.338358
42.14383	159.8080	-1.338377
42.19717	159.8074	-1.338461
42.24716	159.8074	-1.338418
42.30050	159.8074	-1.338506
42.35050	159.8072	-1.338418
42.40383	159.8074	-1.338186
42.45383	159.8068	-1.337952
42.50550	159.8071	-1.337526
42.55717	159.8062	-1.337328
42.60883	159.8070	-1.337290
42.66050	159.8074	-1.337472
42.71216	159.8068	-1.337564
42.76383	159.8072	-1.337732
42.81550	159.8075	-1.337947
42.86716	159.8072	-1.338162
42.91716	159.8082	-1.338668
42.97050	159.8077	-1.339066
43.02050	159.8077	-1.339586
43.07383	159.8077	-1.340246
43.12383	159.8080	-1.340697
43.17717	159.8078	-1.340784
43.22717	159.8076	-1.340759
43.28050	159.8065	-1.340264
43.33050	159.8079	-1.339860
43.38383	159.8062	-1.339182
43.43383	159.8066	-1.338373
43.48717	159.8071	-1.337867
43.53383	159.8153	-1.338918
43.58383	160.0710	-1.450185
43.63716	160.6479	-3.379626
43.68716	161.2972	-6.089066
43.74050	162.0742	-9.119920
43.79050	162.8602	-11.74041
43.84384	163.7431	-14.13328
43.89383	164.6046	-15.99900
43.94717	165.5515	-17.61576
43.99716	166.4596	-18.84953
44.05050	167.4456	-19.90939
44.10050	168.3829	-20.72114
44.15383	169.3950	-21.43458
44.20383	170.3498	-21.98528
44.25550	171.3444	-22.47287
44.30717	172.3450	-22.88330
44.35883	173.3499	-23.24090
44.41050	174.3578	-23.55891
44.46216	175.3696	-23.84515
44.51383	176.3826	-24.10574
44.56550	177.3986	-24.35047
44.61716	178.4146	-24.58187
44.66716	179.3993	-24.80457
44.72050	180.4511	-25.03326
44.77050	181.4380	-25.25536
44.82383	182.4899	-25.49804
44.87383	183.4775	-25.72758
44.92717	184.5311	-25.98856
44.97717	185.5178	-26.24068
45.03050	186.5709	-26.51682
45.08050	187.5582	-26.79074
45.13383	188.6104	-27.09516
45.18383	189.5976	-27.39300
45.23717	190.6496	-27.74435
45.28717	191.6338	-28.08685
45.33883	192.6493	-28.46968
45.39050	193.6658	-28.87507
45.44217	194.6801	-29.22886
45.49383	195.6986	-29.58066
45.54550	196.7142	-29.98012
45.59716	197.7280	-30.42862
45.64883	198.7406	-30.92170
45.70050	199.7502	-31.47028
45.75050	200.7249	-32.02697
45.80383	201.7625	-32.67378
45.85383	202.7337	-33.34303
45.90717	203.7665	-34.14615
45.95717	204.7281	-35.02164
46.01050	205.7498	-36.07574
46.06050	206.6992	-37.21322
46.11383	207.7056	-38.65014
46.16383	208.6363	-40.27117
46.21717	209.6137	-42.35915
46.26717	210.5135	-44.68196
46.32050	211.4545	-47.54981
46.37050	212.3229	-50.52902
46.42216	213.2101	-53.82824
46.47383	214.0902	-57.25211
46.52550	214.9670	-60.70025
46.57717	215.8467	-64.06532
46.62883	216.7352	-67.16434
46.68050	217.6440	-69.74858
46.73217	218.5948	-71.12744
46.78383	219.6326	-70.33126
46.83383	220.7253	-67.81503
46.88716	221.9491	-64.11680
46.93716	223.1338	-59.88440
46.99050	224.4324	-54.66355
47.04050	225.6664	-49.59708
47.09384	226.9617	-44.88026
47.14383	228.1407	-41.28012
47.19717	229.3596	-38.25378
47.24716	230.4720	-36.03381
47.30050	231.6332	-34.18492
47.35050	232.7023	-32.83934
47.40383	233.8267	-31.72418
47.45383	234.8686	-30.90548
47.50550	235.9367	-30.25857
47.55717	236.9963	-29.74380
47.60883	238.0504	-29.35218
47.66050	239.1006	-29.05365
47.71216	240.1465	-28.83095
47.76383	241.1902	-28.65599
47.81550	242.2314	-28.53721
47.86716	243.2713	-28.44372
47.91716	244.2758	-28.38078
47.97050	245.3468	-28.32855
48.02050	246.3506	-28.29617
48.07383	247.4201	-28.27725
48.12383	248.4222	-28.26104
48.17717	249.4904	-28.25161
48.22717	250.4917	-28.24632
48.28050	251.5596	-28.24217
48.33050	252.5612	-28.24062
48.38383	253.6283	-28.24178
48.43383	254.6291	-28.24468
48.48717	255.6960	-28.25341
48.53717	256.6968	-28.28009
48.58883	257.7308	-28.31428
48.64050	258.7644	-28.34448
48.69217	259.7982	-28.38114
48.74383	260.8313	-28.41990
48.79550	261.8639	-28.45404
48.84716	262.8972	-28.49842
48.89883	263.9306	-28.53384
48.95050	264.9639	-28.57724
49.00050	265.9636	-28.61932
49.05383	267.0314	-28.66308
49.10383	268.0300	-28.69987
49.15717	269.0966	-28.74388
49.20717	270.0966	-28.78874
49.26050	271.1628	-28.83041
49.31050	272.1612	-28.87028
49.36383	273.2268	-28.92900
49.41383	274.2268	-28.98650
49.46717	275.2912	-29.06174
49.51383	276.2226	-29.12104
49.56550	276.9894	-29.64730
49.61716	276.9832	-27.32906
49.66716	276.7022	-21.83632
49.72050	276.2158	-15.09088
49.77050	275.6478	-9.030209
49.82383	274.9512	-3.366782
49.87383	274.2333	1.088884
49.92717	273.4102	4.992178
49.97717	272.5976	7.958745
50.03050	271.6960	10.51298
50.08050	270.8220	12.44961
50.13383	269.8680	14.10768
50.18383	268.9557	15.37310
50.23717	267.9674	16.46456
50.28717	267.0284	17.29963
50.33883	266.0492	18.00512
50.39050	265.0608	18.58464
50.44217	264.0662	19.05320
50.49383	263.0664	19.44524
50.54550	262.0614	19.76882
50.59716	261.0531	20.03758
50.64883	260.0416	20.25661
50.70050	259.0266	20.44225
50.75050	258.0436	20.59297
50.80383	256.9936	20.72662
50.85383	256.0062	20.83856
50.90717	254.9524	20.94020
50.95717	253.9630	21.02400
51.01050	252.9069	21.09392
51.06050	251.9156	21.15552
51.11383	250.8592	21.20653
51.16383	249.8667	21.25197
51.21717	248.8087	21.29727
51.26716	247.8162	21.33506
51.32050	246.7572	21.37096
51.37050	245.7640	21.39528
51.42217	244.7364	21.41766
51.47383	243.7098	21.43467
51.52550	242.6825	21.44708
51.57717	241.6556	21.45686
51.62883	240.6272	21.46719
51.68050	239.5994	21.47883
51.73217	238.5710	21.49065
51.78383	237.5429	21.49953
51.83383	236.5484	21.50822
51.88716	235.4870	21.51950
51.93716	234.4918	21.52711
51.99050	233.4295	21.53470
52.04050	232.4346	21.54075
52.09384	231.3728	21.54553
52.14384	230.3768	21.54953
52.19717	229.3151	21.55336
52.24717	228.3200	21.55598
52.30050	227.2584	21.55990
52.35050	226.2627	21.56413
52.40383	225.2006	21.56904
52.45383	224.2057	21.57555
52.50550	223.1763	21.58146
52.55717	222.1469	21.58736
52.60883	221.1183	21.59298
52.66050	220.0894	21.59783
52.71216	219.0600	21.60276
52.76382	218.0317	21.60759
52.81550	217.0020	21.61144
52.86716	215.9732	21.61494
52.91716	214.9772	21.61814
52.97050	213.9143	21.62079
53.02050	212.9181	21.62260
53.07383	211.8560	21.62416
53.12383	210.8592	21.62559
53.17717	209.7965	21.62670
53.22717	208.8002	21.62751
53.28050	207.7366	21.62762
53.33050	206.7400	21.62741
53.38383	205.6777	21.62646
53.43383	204.6812	21.62420
53.48717	203.6170	21.62154
53.53716	202.6217	21.61825
53.58882	201.5920	21.61355
53.64050	200.5620	21.60808
53.69216	199.5324	21.60256
53.74382	198.5035	21.59725
53.79550	197.4736	21.59203
53.84716	196.4432	21.58690
53.89883	195.4137	21.58230
53.95050	194.3839	21.57810
54.00050	193.3881	21.57468
54.05383	192.3242	21.57112
54.10383	191.3282	21.56716
54.15717	190.2652	21.56303
54.20717	189.2680	21.55869
54.26050	188.2047	21.55444
54.31050	187.2078	21.54984
54.36382	186.1442	21.54436
54.41382	185.1475	21.53960
54.46717	184.0846	21.53370
54.51716	183.0869	21.52633
54.57050	182.0240	21.51908
54.62050	181.0267	21.51213
54.67217	179.9968	21.50488
54.72382	178.9671	21.49875
54.77550	177.9365	21.49318
54.82717	176.9063	21.48867
54.87883	175.8762	21.48516
54.93050	174.8458	21.48203
54.98217	173.8156	21.47976
55.03383	172.7852	21.47770
55.08383	171.7880	21.47454
55.13716	170.7239	21.47005
55.18716	169.7274	21.46375
55.24050	168.6647	21.45846
55.29050	167.6675	21.45484
55.34384	166.6045	21.45383
55.39384	165.6089	21.48616
55.44717	164.5534	21.66227
55.49717	163.5688	22.02360
55.55050	162.5385	22.86182
55.60050	161.6028	24.35388
55.65383	160.6481	26.92495
55.70383	159.8012	30.29230
55.75550	158.9689	34.53313
55.80717	158.1610	39.11160
55.85883	157.3544	43.49918
55.91050	156.5227	47.21042
55.96216	155.6481	49.94419
56.01382	154.7210	51.57114
56.06550	153.7391	52.11239
56.11716	152.7063	51.63800
56.16716	151.6632	50.38488
56.22050	150.5134	48.38342
56.27050	149.4101	46.08633
56.32383	148.2180	43.39926
56.37383	147.0957	40.87120
56.42717	145.9020	38.30460
56.47717	144.7925	36.13602
56.53050	143.6230	34.09145
56.58050	142.5383	32.43913
56.63383	141.3974	30.94825
56.68383	140.3368	29.74889
56.73717	139.2159	28.65892
56.78716	138.1725	27.78390
56.83882	137.1008	26.99028
56.89050	136.0351	26.29805
56.94216	134.9734	25.70657
56.99382	133.9163	25.20760
57.04550	132.8639	24.78338
57.09716	131.8128	24.41165
57.14883	130.7662	24.08259
57.20050	129.7203	23.80199
57.25050	128.7110	23.56091
57.30383	127.6368	23.33418
57.35383	126.6291	23.14262
57.40717	125.5561	22.95946
57.45717	124.5506	22.80110
57.51050	123.4785	22.64612
57.56050	122.4748	22.51036
57.61382	121.4038	22.37292
57.66382	120.4008	22.25045
57.71717	119.3324	22.13247
57.76716	118.3305	22.03383
57.82050	117.2620	21.93494
57.87050	116.2589	21.84549
57.92217	115.2249	21.75343
57.97382	114.1897	21.66830
58.02550	113.1550	21.58034
58.07717	112.1207	21.49698
58.12883	111.0858	21.41458
58.18050	110.0523	21.33363
58.23217	109.0171	21.25725
58.28383	107.9822	21.18270
58.33383	106.9812	21.10894
58.38716	105.9133	21.03303
58.43716	104.9121	20.95771
58.49050	103.8442	20.88686
58.54050	102.8437	20.82201
58.59384	101.7759	20.74995
58.64384	100.7760	20.68358
58.69717	99.70851	20.61365
58.74717	98.70842	20.55166
58.80050	97.64066	20.48586
58.85050	96.64072	20.42720
58.90383	95.57372	20.35854
58.95383	94.57356	20.28984
59.00550	93.54004	20.22981
59.05717	92.50648	20.16835
59.10883	91.47281	20.10126
59.16050	90.43912	20.04767
59.21216	89.40649	19.98084
59.26382	88.37281	19.92909
59.31550	87.33847	19.83203
59.36716	86.30414	19.74322
59.41716	85.30241	19.66345
59.47050	84.23429	19.58684
59.52050	83.23378	19.51958
59.57383	82.16658	19.44554
59.62383	81.16505	19.37424
59.67717	80.09785	19.30444
59.72717	79.09828	19.24112
59.78050	78.03079	19.17613
59.83050	77.03697	19.26378
59.88383	75.96980	19.20148
59.93383	74.97129	19.13196
59.98717	73.90249	19.05122
60.03716	72.90150	18.98469
60.08882	71.86901	18.95002
60.14050	70.83501	18.88763
60.19216	69.80130	18.81618
60.24382	68.76680	18.74793
60.29550	67.73297	18.69352
60.34716	66.69946	18.62284
60.39883	65.66538	18.55271
60.45050	64.63137	18.48922
60.50050	63.63164	18.42499
60.55383	62.56392	18.34670
60.60383	61.56361	18.28226
60.65717	60.49516	18.21481
60.70717	59.49439	18.14672
60.76050	58.42838	18.07716
60.81050	57.42615	18.01342
60.86382	56.35935	17.94271
60.91382	55.35885	17.87775
60.96717	54.29066	17.80611
61.01716	53.28838	17.74326
61.07050	52.22300	17.67367
61.12050	51.22175	17.61088
61.17217	50.18762	17.54147
61.22382	49.15380	17.47638
61.27550	48.11959	17.41377
61.32717	47.08530	17.34541
61.37883	46.05190	17.28444
61.43050	45.01812	17.22134
61.48217	43.98274	17.16178
61.53383	42.94961	17.10385
61.58383	41.94840	17.04241
61.63716	40.88032	16.97522
61.68716	39.87987	16.90910
61.74050	38.81175	16.84352
61.79050	37.81163	16.77060
61.84384	36.74324	16.68598
61.89384	35.74154	16.61124
61.94717	34.67308	16.53287
61.99717	33.66986	16.45205
62.05050	32.60104	16.36584
62.10050	31.59967	16.28398
62.15383	30.52921	16.19689
62.20383	29.52765	16.11666
62.25550	28.49094	16.02746
62.30717	27.45471	15.93493
62.35883	26.41914	15.84362
62.41050	25.38224	15.75128
62.46216	24.34565	15.65742
62.51050	23.37653	15.56366
62.56050	22.57504	15.57990
62.61382	22.48217	14.09745
62.66382	22.68811	10.78914
62.71717	23.12593	6.747758
62.76716	23.66950	3.037419
62.82050	24.35763	-0.4622510
62.87050	25.07857	-3.237091
62.92217	25.88455	-5.593179
62.97382	26.73452	-7.492535
63.02550	27.62182	-9.011230
63.07717	28.53613	-10.22919
63.12883	29.47356	-11.19937
63.18050	30.42732	-11.97160
63.23217	31.39524	-12.59812
63.28383	32.37418	-13.11098
63.33383	33.32946	-13.51698
63.38716	34.35412	-13.87653
63.43716	35.32172	-14.15986
63.49050	36.35748	-14.42044
63.54050	37.33319	-14.63340
63.59384	38.37702	-14.82954
63.64384	39.35900	-14.98905
63.69717	40.40772	-15.14368
63.74717	41.39342	-15.26934
63.80050	42.44504	-15.39467
63.85050	43.43450	-15.50296
63.90383	44.48990	-15.60566
63.95383	45.48127	-15.69832
64.00550	46.50463	-15.78712
64.05717	47.53082	-15.87966
64.10884	48.55598	-15.96994
64.16050	49.58178	-16.05184
64.21217	50.60946	-16.13466
64.26384	51.63646	-16.21888
64.31550	52.66410	-16.29877
64.36718	53.69207	-16.37545
64.41717	54.68760	-16.45100
64.47050	55.74895	-16.52975
64.52050	56.74496	-16.60306
64.57384	57.80707	-16.68378
64.62383	58.80389	-16.75896
64.67718	59.86511	-16.83912
64.72718	60.86264	-16.91338
64.78050	61.92623	-16.99658
64.83050	62.92285	-17.07061
64.88384	63.98772	-17.15112
64.93384	64.98480	-17.22229
64.98717	66.04902	-17.29171
65.03717	67.04611	-17.36242
65.08884	68.07686	-17.43710
65.14050	69.10825	-17.51216
65.19217	70.13892	-17.58428
65.24384	71.17011	-17.65504
65.29550	72.20079	-17.73580
65.34717	73.23237	-17.80463
65.39883	74.26197	-17.88306
65.45050	75.29322	-17.95426
65.50050	76.29024	-18.02638
65.55384	77.35461	-18.10361
65.60384	78.35220	-18.18355
65.65718	79.41500	-18.26424
65.70718	80.41321	-18.34076
65.76050	81.47651	-18.42648
65.81050	82.47442	-18.50034
65.86384	83.53888	-18.58406
65.91382	84.53668	-18.66708
65.96718	85.60109	-18.74357
66.01716	86.59856	-18.82172
66.07050	87.66186	-18.90717
66.12050	88.65991	-18.98133
66.17218	89.69108	-19.06372
66.22384	90.72126	-19.15720
66.27550	91.75176	-19.23475
66.32718	92.78364	-19.32062
66.37884	93.81395	-19.40059
66.43050	94.84441	-19.48171
66.48218	95.87507	-19.56332
66.53384	96.90601	-19.65119
66.58384	97.90344	-19.72229
66.63718	98.96684	-19.80955
66.68718	99.96399	-19.88703
66.74050	101.0278	-19.97123
66.79050	102.0260	-20.05396
66.84384	103.0896	-20.14145
66.89384	104.0881	-20.21502
66.94718	105.1515	-20.30532
66.99718	106.1493	-20.39050
67.05050	107.2123	-20.47916
67.10050	108.2101	-20.56412
67.15384	109.2724	-20.65361
67.20384	110.2704	-20.74210
67.25550	111.3018	-20.83164
67.30718	112.3325	-20.91982
67.35884	113.3639	-21.00803
67.41050	114.3935	-21.09204
67.46218	115.4239	-21.18901
67.51384	116.4543	-21.27520
67.56550	117.4845	-21.37472
67.61718	118.5134	-21.46800
67.66718	119.5108	-21.55030
67.72050	120.5732	-21.65763
67.77050	121.5708	-21.75318
67.82384	122.6338	-21.86138
67.87384	123.6303	-21.96498
67.92718	124.6924	-22.07521
67.97718	125.6902	-22.17916
68.03050	126.7534	-22.28490
68.08050	127.7486	-22.38483
68.13384	128.8115	-22.48861
68.18384	129.8079	-22.58906
68.23718	130.8714	-22.70195
68.28718	131.8669	-22.81412
68.33884	132.8972	-22.92414
68.39050	133.9267	-23.03312
68.44218	134.9565	-23.14666
68.49384	135.9844	-23.26527
68.54550	137.0155	-23.38424
68.59718	138.0440	-23.50932
68.64884	139.0741	-23.62642
68.70050	140.1029	-23.74776
68.75050	141.0996	-23.87245
68.80384	142.1608	-23.99884
68.85384	143.1564	-24.12264
68.90718	144.2191	-24.25699
68.95718	145.2142	-24.37864
69.01050	146.2769	-24.50623
69.06050	147.2728	-24.63377
69.11384	148.3339	-24.76570
69.16382	149.3292	-24.89467
69.21718	150.3906	-25.03264
69.26716	151.3854	-25.16213
69.32050	152.4472	-25.31133
69.37050	153.4416	-25.45058
69.42218	154.4714	-25.59374
69.47384	155.4990	-25.74125
69.52550	156.5270	-25.89488
69.57718	157.5544	-26.03751
69.62884	158.5836	-26.18608
69.68050	159.6114	-26.32884
69.73218	160.6404	-26.45326
69.78384	161.6702	-26.57520
69.83384	162.6669	-26.67173
69.88718	163.7301	-26.77405
69.93718	164.7287	-26.84694
69.99050	165.7934	-26.91131
70.04050	166.7926	-26.96382
70.09384	167.8588	-27.02305
70.14384	168.8572	-27.06978
70.19718	169.9234	-27.13274
70.24718	170.9225	-27.19763
70.30050	171.9874	-27.27859
70.35050	172.9846	-27.36982
70.40384	174.0494	-27.47024
70.45384	175.0461	-27.57641
70.50550	176.0743	-27.70435
70.55718	177.1028	-27.84439
70.60884	178.1298	-28.00578
70.66050	179.1568	-28.18535
70.71218	180.1814	-28.38376
70.76384	181.2063	-28.61101
70.81550	182.2296	-28.86935
70.86718	183.2520	-29.14840
70.91718	184.2402	-29.44672
70.97050	185.2938	-29.80015
71.02050	186.2789	-30.16128
71.07384	187.3270	-30.59082
71.12384	188.3078	-31.04342
71.17718	189.3519	-31.58341
71.22718	190.3280	-32.14628
71.28050	191.3662	-32.80170
71.33050	192.3376	-33.46687
71.38384	193.3714	-34.21054
71.43384	194.3406	-34.92760
71.48718	195.3724	-35.70322
71.53718	196.3398	-36.44486
71.58884	197.3379	-37.24310
71.64050	198.3355	-38.07484
71.69218	199.3302	-38.96230
71.74384	200.3219	-39.91703
71.79550	201.3112	-40.94878
71.84718	202.2967	-42.04804
71.89884	203.2802	-43.17280
71.95050	204.2640	-44.27783
72.00050	205.2200	-45.24312
72.05384	206.2479	-46.03175
72.10384	207.2306	-46.29623
72.15718	208.3087	-45.79324
72.20718	209.3617	-44.40612
72.26050	210.5254	-42.09740
72.31050	211.6404	-39.59086
72.36384	212.8323	-36.96535
72.41382	213.9397	-34.81460
72.46718	215.1020	-32.94334
72.51716	216.1741	-31.55118
72.57050	217.3014	-30.39328
72.62050	218.3459	-29.55686
72.67218	219.4152	-28.88070
72.72384	220.4759	-28.35460
72.77550	221.5306	-27.96210
72.82718	222.5812	-27.65977
72.87884	223.6275	-27.43204
72.93050	224.6713	-27.26178
72.98218	225.7131	-27.13034
73.03384	226.7524	-27.04219
73.08384	227.7560	-26.98262
73.13718	228.8276	-26.94209
73.18718	229.8294	-26.92928
73.24050	230.8984	-26.92546
73.29050	231.8989	-26.92373
73.34384	232.9668	-26.92887
73.39384	233.9670	-26.94596
73.44718	235.0346	-26.97654
73.49718	236.0352	-27.01627
73.55050	237.1014	-27.04654
73.60050	238.1006	-27.08285
73.65384	239.1680	-27.12538
73.70384	240.1680	-27.16240
73.75550	241.2006	-27.20632
73.80718	242.2332	-27.25759
73.85884	243.2660	-27.30232
73.91050	244.2992	-27.35078
73.96218	245.3311	-27.39146
74.01384	246.3646	-27.43432
74.06550	247.3977	-27.47896
74.11718	248.4299	-27.51941
74.16718	249.4294	-27.55438
74.22050	250.4955	-27.59806
74.27050	251.4948	-27.64502
74.32384	252.5606	-27.69114
74.37384	253.5594	-27.73505
74.42718	254.6250	-27.77850
74.47718	255.6250	-27.81722
74.53050	256.6906	-27.87934
74.58050	257.6900	-27.92704
74.63384	258.7560	-27.97749
74.68384	259.7552	-28.03194
74.73718	260.8201	-28.08826
74.78718	261.8193	-28.13855
74.83884	262.8507	-28.19629
74.89050	263.8828	-28.25769
74.94218	264.9150	-28.31730
74.99384	265.9458	-28.37800
75.04550	266.9793	-28.44372
75.09718	268.0105	-28.50244
75.14884	269.0430	-28.56088
75.20050	270.0747	-28.62605
75.25050	271.0738	-28.68303
75.30384	272.1390	-28.74324
-2.000000	5.000000	0.0000000