File: 1-C1(0.6mol%)+C20(0.6mol%)/matlab/170-2.txt
CLOSED
Version	1.0
Language	English
Mode	Standard
Run	11
RunSerial	11861
Instrument	DSC Q2000 V24.11 Build 124
Module	DSC Standard Cell RC
Operator	Jing
File	\\AE520-1454\TA\Data\DSC\UQ Composites\Nan\C1(5.5)+C20P(3)+CL(HotplateMixtureAB)\170-2
ProcName	Ramp
InstSerial	2000-0883
AutoSerial	1293
Sample	Iso-170-2
Size	42.5000	mg
PanMass	Not available
PanResist	Automatic Automatic  K/W
PanFactor	Default Default
Method	Ramp
Comment
Xcomment	Pan: Tzero Aluminum Hermetic
Xcomment	Gas1: Nitrogen 50.0 ml/min
Xcomment	Gas2: Nitrogen 50.0 ml/min
Text
Exotherm	UP
Kcell	1.05230
Cpconst	Standard: 0.938
Calib	-38.6961
TempCal	1	pts	157.46	156.60
TzeroDt	-87.6168 -0.0009 -1.4231
TzeroDtz	-87.6168 0.0057 6.9570
InstCalFile	Tzero: \\Ae520-1454\ta\Data\DSC\Calibration\2017\CALIBRATION\1562_RCS (90)_05_18_2017 10_50_44.TZR
InstCalFile	Baseline: \\Ae520-1454\ta\Data\DSC\Calibration\2017\2017-05-17_Calibration.001
InstCalFile	Sapphire: \\Ae520-1454\ta\Data\DSC\Calibration\2017\2017-05-17_Saphire.001
InstCalDate	Tzero 2017-05-18 Time 10:50:44
TempRange	-87.39 to 398.39 °C at 10.00 °C/min Heat Only
AutoZero	Delta T Offset 0.000 uV
AutoZero	Delta T0 Offset 0.000 uV
MultiptCal	0
MultiPtDesc	0) Not set
AutoCellConst	Calibration Date 2017-05-18 16:59:28
Controls	Gas 1  Event Off  Sampling 0.2
Cell#	RC-01562
CoolingUnit	RCS (90)
SelHeatFlow	Heat Flow T4 (mW)
AutoLidII	Installed
AutoAnalysis	Off
MacroFile
Nsig	3
Sig1	Time (min)
Sig2	Temperature (°C)
Sig3	Heat Flow (mW)
Date	2017-06-21
Time	06:19:34
OrgMethod	1: Equilibrate at 20.00 °C
OrgMethod	2: Ramp 40.00 °C/min to 170.00 °C
OrgMethod	3: Mark end of cycle 1
OrgMethod	4: Isothermal for 40.00 min
OrgMethod	5: Mark end of cycle 2
OrgMethod	6: Ramp 20.00 °C/min to 280.00 °C
OrgMethod	7: Mark end of cycle 3
OrgMethod	8: Ramp 20.00 °C/min to 20.00 °C
OrgMethod	9: Mark end of cycle 4
OrgMethod	10: Ramp 20.00 °C/min to 280.00 °C
OrgMethod	11: Mark end of cycle 5
OrgFile	C:\Users\jarra\Desktop\DSC\1-C1(0.6mol%)+C20(0.6mol%)\170-2.001
StartOfData
4.99994E-4	20.07992	0.3614697
0.05383332	20.20011	0.8300468
0.1038333	21.08848	2.074133
0.1571666	22.45050	0.2914341
0.2071666	23.87850	-2.679442
0.2588334	25.46858	-6.264294
0.3105000	27.13667	-9.822032
0.3605000	28.81172	-12.99252
0.4138333	30.64988	-15.96664
0.4638333	32.41456	-18.36870
0.5171667	34.33303	-20.55439
0.5671668	36.15960	-22.28644
0.6188334	38.07189	-23.82801
0.6705000	40.00376	-25.14774
0.7205000	41.88590	-26.27327
0.7738332	43.90735	-27.37641
0.8238334	45.80684	-28.45035
0.8771668	47.83047	-29.68723
0.9271668	49.73588	-30.68527
0.9788332	51.71834	-31.59675
1.030500	53.70375	-32.56440
1.080500	55.61860	-33.70674
1.133833	57.64846	-35.22220
1.183833	59.54063	-36.83936
1.237166	61.55188	-38.77204
1.287167	63.42688	-40.85978
1.338833	65.31370	-43.93050
1.390500	67.14959	-48.72641
1.440500	68.93176	-52.12517
1.493833	70.76824	-58.09536
1.543833	72.36782	-66.12680
1.595500	73.89721	-76.50361
1.647167	75.35034	-87.84009
1.698833	76.81269	-98.26666
1.750500	78.37431	-106.8582
1.800500	79.93405	-114.5046
1.853833	81.72022	-120.1253
1.903833	83.49864	-123.6160
1.955500	85.41691	-126.1719
2.007167	87.37241	-128.1834
2.058833	89.38452	-129.1244
2.110500	91.44564	-129.2539
2.160500	93.41422	-130.9739
2.213833	95.36966	-135.0502
2.263833	97.28672	-135.5053
2.315500	99.51871	-130.6486
2.367167	102.0546	-120.2554
2.417167	104.6152	-110.4236
2.470500	107.2649	-101.6468
2.520500	109.6755	-94.64808
2.573833	112.1828	-88.36824
2.623834	114.4718	-83.56296
2.675500	116.7910	-79.29119
2.727167	119.0686	-75.80768
2.777166	121.2367	-73.08240
2.830500	123.3543	-76.20710
2.880500	125.3690	-74.24084
2.933833	127.6121	-72.33800
2.983833	129.7154	-70.62568
3.035500	131.8760	-69.21430
3.087167	134.0228	-68.06850
3.137167	136.0798	-67.43342
3.190500	138.2583	-66.97131
3.240500	140.2878	-66.78407
3.293833	142.4419	-66.78661
3.343834	144.4495	-67.11946
3.395500	146.5179	-67.38725
3.447167	148.5770	-67.91116
3.497166	150.5585	-68.60700
3.550500	152.6708	-69.42744
3.600500	154.6446	-70.33946
3.653833	156.7426	-71.44376
3.703833	158.7131	-72.44260
3.750500	160.5525	-73.31163
3.803833	162.5542	-74.23991
3.853833	163.7523	-73.33235
3.907166	164.6372	-68.35263
3.957167	165.2947	-62.35761
4.008833	165.8485	-55.95047
4.060500	166.3099	-50.06252
4.110500	166.6866	-45.08847
4.163834	167.0250	-40.58791
4.213834	167.2936	-37.05100
4.267166	167.5392	-33.88809
4.317167	167.7374	-31.39172
4.368834	167.9138	-29.22151
4.420500	168.0667	-27.38766
4.470500	168.1959	-25.86549
4.523834	168.3156	-24.47868
4.573834	168.4141	-23.34755
4.627167	168.5078	-22.28603
4.677166	168.5852	-21.39170
4.728833	168.6582	-20.53785
4.780500	168.7242	-19.73573
4.830500	168.7835	-18.99867
4.883834	168.8424	-18.23230
4.933834	168.8949	-17.51637
4.987167	168.9491	-16.73213
5.037167	168.9984	-15.98719
5.088834	169.0477	-15.21838
5.140500	169.0947	-14.45985
5.190500	169.1393	-13.74323
5.243834	169.1845	-13.00478
5.293832	169.2244	-12.33353
5.345500	169.2635	-11.65987
5.397168	169.3017	-11.00522
5.448834	169.3376	-10.37100
5.500500	169.3728	-9.720394
5.550500	169.4080	-9.077707
5.603832	169.4455	-8.390694
5.653834	169.4789	-7.744650
5.705500	169.5133	-7.100707
5.757168	169.5461	-6.499110
5.808832	169.5751	-5.954118
5.860500	169.6031	-5.447278
5.910500	169.6278	-4.982470
5.963832	169.6526	-4.508054
6.013834	169.6752	-4.083096
6.065500	169.6980	-3.655105
6.117168	169.7190	-3.246553
6.167168	169.7387	-2.862176
6.220500	169.7592	-2.467082
6.270500	169.7786	-2.107470
6.323834	169.7970	-1.735774
6.373832	169.8145	-1.393628
6.425500	169.8322	-1.057610
6.477168	169.8482	-0.7285088
6.527168	169.8643	-0.4269697
6.580500	169.8791	-0.1085653
6.630500	169.8959	0.1734662
6.683832	169.9098	0.4703537
6.733832	169.9225	0.7352676
6.785500	169.9367	1.001274
6.837168	169.9500	1.260671
6.887168	169.9617	1.500776
6.940500	169.9746	1.746707
6.990500	169.9862	1.970020
7.043832	169.9973	2.202570
7.093832	170.0079	2.409562
7.145500	170.0187	2.614511
7.197168	170.0295	2.816490
7.247168	170.0380	2.998486
7.300500	170.0470	3.183066
7.350500	170.0563	3.351340
7.403832	170.0651	3.521850
7.453832	170.0724	3.673192
7.505500	170.0799	3.828015
7.557166	170.0882	3.972636
7.607168	170.0939	4.112519
7.660500	170.1018	4.251578
7.710500	170.1086	4.381604
7.762168	170.1143	4.512784
7.813834	170.1214	4.636844
7.865500	170.1276	4.758813
7.917168	170.1346	4.876072
7.967168	170.1394	4.986868
8.020500	170.1455	5.101352
8.070500	170.1502	5.205981
8.122168	170.1562	5.310772
8.173832	170.1620	5.414399
8.225500	170.1667	5.515953
8.277168	170.1715	5.612696
8.327168	170.1765	5.705695
8.380500	170.1807	5.799443
8.430500	170.1855	5.883934
8.482166	170.1891	5.978806
8.533832	170.1924	6.032172
8.583832	170.1959	6.097144
8.637168	170.1994	6.163202
8.687166	170.2026	6.223608
8.740500	170.2055	6.281790
8.790500	170.2085	6.331855
8.842168	170.2109	6.384472
8.893832	170.2136	6.427754
8.943832	170.2161	6.471182
8.997168	170.2182	6.512551
9.047168	170.2190	6.551148
9.100500	170.2222	6.588900
9.150500	170.2235	6.622100
9.202168	170.2259	6.657662
9.253834	170.2271	6.690136
9.303832	170.2293	6.716301
9.357166	170.2310	6.745088
9.407166	170.2324	6.770780
9.460499	170.2334	6.792566
9.510499	170.2345	6.810902
9.562166	170.2361	6.829156
9.613834	170.2368	6.844561
9.663834	170.2365	6.855595
9.717168	170.2379	6.866776
9.767168	170.2388	6.875190
9.820500	170.2384	6.883904
9.870499	170.2392	6.891885
9.922168	170.2401	6.899840
9.973832	170.2399	6.907300
10.02383	170.2407	6.913805
10.07717	170.2410	6.919980
10.12717	170.2414	6.925044
10.17883	170.2416	6.929312
10.23050	170.2416	6.933218
10.28217	170.2422	6.936724
10.33383	170.2424	6.939886
10.38383	170.2422	6.942829
10.43717	170.2427	6.945663
10.48717	170.2423	6.948012
10.53883	170.2422	6.950562
10.59050	170.2434	6.953097
10.64050	170.2433	6.955674
10.69383	170.2434	6.958990
10.74384	170.2434	6.962310
10.79717	170.2438	6.966089
10.84717	170.2440	6.969874
10.89883	170.2441	6.973944
10.95050	170.2451	6.978278
11.00050	170.2448	6.982434
11.05383	170.2445	6.986840
11.10383	170.2455	6.991134
11.15717	170.2452	6.995813
11.20717	170.2451	7.000210
11.25883	170.2461	7.004797
11.31050	170.2465	7.009308
11.36050	170.2469	7.013734
11.41383	170.2467	7.018835
11.46383	170.2466	7.023906
11.51717	170.2474	7.029270
11.56716	170.2477	7.035382
11.61884	170.2480	7.039356
11.67050	170.2477	7.041626
11.72050	170.2471	7.043147
11.77383	170.2475	7.044684
11.82383	170.2478	7.045741
11.87717	170.2474	7.047134
11.92717	170.2477	7.048954
11.97884	170.2482	7.051475
12.03050	170.2481	7.054405
12.08050	170.2486	7.057704
12.13383	170.2494	7.061520
12.18383	170.2495	7.065530
12.23550	170.2500	7.069925
12.28717	170.2503	7.074505
12.33883	170.2505	7.078832
12.39050	170.2500	7.082789
12.44050	170.2506	7.085889
12.49384	170.2507	7.088250
12.54384	170.2508	7.089600
12.59550	170.2499	7.090028
12.64717	170.2502	7.089164
12.69883	170.2498	7.086743
12.75050	170.2496	7.083160
12.80050	170.2488	7.078306
12.85383	170.2479	7.069891
12.90383	170.2480	7.059588
12.95550	170.2473	7.046866
13.00717	170.2466	7.028682
13.05717	170.2455	7.010166
13.11050	170.2444	6.988534
13.16050	170.2432	6.964593
13.21383	170.2420	6.937045
13.26383	170.2405	6.912630
13.31550	170.2400	6.884789
13.36716	170.2380	6.855902
13.41716	170.2372	6.827697
13.47050	170.2360	6.797109
13.52050	170.2355	6.766186
13.57384	170.2330	6.736172
13.62384	170.2328	6.706313
13.67550	170.2303	6.677055
13.72717	170.2291	6.642749
13.77717	170.2281	6.611678
13.83050	170.2262	6.579488
13.88050	170.2242	6.549088
13.93383	170.2227	6.516025
13.98383	170.2219	6.486220
14.03550	170.2206	6.453943
14.08717	170.2191	6.422518
14.13717	170.2174	6.394224
14.19050	170.2162	6.363347
14.24050	170.2144	6.332050
14.29384	170.2116	6.302908
14.34383	170.2110	6.272695
14.39550	170.2098	6.242412
14.44717	170.2093	6.214332
14.49717	170.2072	6.188242
14.55050	170.2055	6.160480
14.60050	170.2047	6.132190
14.65217	170.2031	6.105846
14.70383	170.2016	6.082636
14.75550	170.2000	6.057424
14.80717	170.1998	6.034235
14.85716	170.1984	6.009773
14.91050	170.1961	5.984608
14.96050	170.1956	5.962383
15.01217	170.1946	5.938575
15.06383	170.1935	5.913278
15.11550	170.1921	5.888858
15.16716	170.1906	5.864418
15.21716	170.1897	5.840074
15.27050	170.1885	5.812650
15.32050	170.1878	5.787732
15.37217	170.1862	5.759404
15.42383	170.1854	5.728474
15.47383	170.1835	5.698907
15.52717	170.1830	5.663188
15.57717	170.1809	5.629263
15.63050	170.1799	5.589141
15.68050	170.1778	5.552191
15.73216	170.1764	5.510829
15.78383	170.1736	5.468076
15.83383	170.1708	5.424412
15.88716	170.1697	5.373021
15.93717	170.1665	5.327096
15.99050	170.1653	5.271222
16.04050	170.1616	5.217224
16.09216	170.1589	5.160238
16.14383	170.1563	5.098224
16.19383	170.1532	5.040059
16.24716	170.1504	4.973124
16.29716	170.1477	4.910491
16.35050	170.1434	4.842088
16.40050	170.1405	4.774243
16.45216	170.1369	4.702756
16.50383	170.1332	4.633428
16.55383	170.1302	4.562718
16.60716	170.1265	4.490838
16.65716	170.1233	4.421720
16.71050	170.1188	4.346280
16.76050	170.1160	4.275009
16.81216	170.1123	4.204098
16.86383	170.1084	4.135062
16.91383	170.1058	4.062872
16.96716	170.1022	3.991332
17.01716	170.0989	3.925838
17.06883	170.0954	3.858745
17.12050	170.0922	3.792487
17.17216	170.0897	3.731024
17.22383	170.0864	3.670152
17.27383	170.0839	3.609766
17.32716	170.0801	3.551922
17.37716	170.0784	3.499102
17.42883	170.0756	3.447641
17.48050	170.0729	3.396752
17.53050	170.0707	3.350133
17.58383	170.0680	3.303582
17.63383	170.0660	3.262086
17.68716	170.0636	3.220014
17.73716	170.0621	3.182368
17.78883	170.0605	3.143286
17.84050	170.0581	3.110378
17.89050	170.0572	3.080522
17.94383	170.0552	3.049140
17.99383	170.0541	3.022074
18.04716	170.0524	2.994797
18.09716	170.0512	2.970264
18.14883	170.0504	2.948257
18.20050	170.0488	2.923760
18.25050	170.0478	2.905525
18.30383	170.0474	2.885570
18.35383	170.0460	2.867189
18.40716	170.0449	2.849416
18.45716	170.0436	2.830745
18.50883	170.0435	2.810951
18.56050	170.0424	2.792875
18.61050	170.0408	2.773110
18.66383	170.0399	2.749415
18.71383	170.0391	2.724553
18.76716	170.0375	2.697332
18.81716	170.0370	2.670394
18.86883	170.0351	2.637898
18.92050	170.0341	2.604460
18.97050	170.0327	2.568839
19.02383	170.0310	2.529736
19.07383	170.0289	2.493868
19.12550	170.0271	2.449225
19.17716	170.0246	2.404414
19.22883	170.0226	2.357280
19.28050	170.0208	2.302334
19.33050	170.0184	2.252735
19.38383	170.0158	2.192776
19.43383	170.0124	2.136700
19.48550	170.0101	2.074034
19.53717	170.0062	2.011988
19.58883	170.0036	1.948411
19.64050	170.0012	1.881796
19.69050	169.9974	1.817423
19.74383	169.9936	1.748422
19.79383	169.9906	1.678998
19.84550	169.9873	1.610887
19.89716	169.9843	1.540332
19.94716	169.9802	1.470502
20.00050	169.9772	1.397877
20.05050	169.9736	1.331841
20.10383	169.9707	1.255813
20.15383	169.9662	1.192218
20.20550	169.9633	1.119568
20.25716	169.9602	1.049696
20.30716	169.9566	0.9868599
20.36050	169.9543	0.9153321
20.41050	169.9506	0.8504316
20.46383	169.9467	0.7821522
20.51383	169.9446	0.7152349
20.56550	169.9409	0.6513704
20.61716	169.9376	0.5880315
20.66716	169.9349	0.5272359
20.72050	169.9322	0.4624172
20.77050	169.9289	0.4029126
20.82383	169.9257	0.3402239
20.87383	169.9230	0.2844647
20.92550	169.9189	0.2271082
20.97716	169.9165	0.1674335
21.02717	169.9134	0.1101093
21.08050	169.9111	0.05259066
21.13050	169.9081	-2.0428E-3
21.18383	169.9052	-.05504053
21.23383	169.9028	-0.1083344
21.28550	169.8994	-0.1591259
21.33716	169.8978	-0.2109474
21.38716	169.8945	-0.2577675
21.44050	169.8928	-0.3065274
21.49050	169.8908	-0.3524190
21.54216	169.8880	-0.3981992
21.59383	169.8867	-0.4430090
21.64550	169.8849	-0.4862951
21.69716	169.8825	-0.5256772
21.74716	169.8804	-0.5645313
21.80050	169.8788	-0.6047202
21.85050	169.8768	-0.6401308
21.90216	169.8754	-0.6779669
21.95383	169.8734	-0.7108682
22.00550	169.8722	-0.7468432
22.05716	169.8694	-0.7798595
22.10716	169.8690	-0.8075112
22.16050	169.8667	-0.8368616
22.21050	169.8660	-0.8666906
22.26216	169.8635	-0.8956985
22.31383	169.8630	-0.9210972
22.36383	169.8619	-0.9481238
22.41716	169.8602	-0.9746437
22.46716	169.8589	-0.9983598
22.52050	169.8568	-1.021413
22.57050	169.8568	-1.042219
22.62216	169.8552	-1.063921
22.67383	169.8542	-1.083695
22.72383	169.8535	-1.101346
22.77717	169.8526	-1.120847
22.82716	169.8514	-1.139574
22.88050	169.8512	-1.157435
22.93050	169.8502	-1.175960
22.98216	169.8496	-1.191864
23.03383	169.8496	-1.209365
23.08383	169.8487	-1.225761
23.13716	169.8484	-1.241224
23.18716	169.8475	-1.251875
23.24050	169.8478	-1.263951
23.29050	169.8463	-1.275298
23.34216	169.8458	-1.285910
23.39383	169.8457	-1.297041
23.44383	169.8451	-1.308482
23.49716	169.8438	-1.319256
23.54716	169.8426	-1.328474
23.60050	169.8423	-1.339276
23.65050	169.8415	-1.349274
23.70216	169.8408	-1.359324
23.75383	169.8398	-1.368962
23.80383	169.8394	-1.378291
23.85716	169.8383	-1.389543
23.90716	169.8386	-1.398536
23.95883	169.8384	-1.408204
24.01050	169.8368	-1.417577
24.06216	169.8373	-1.426986
24.11383	169.8364	-1.436326
24.16383	169.8359	-1.444642
24.21716	169.8357	-1.453556
24.26716	169.8350	-1.461622
24.31883	169.8341	-1.469907
24.37050	169.8333	-1.478019
24.42050	169.8335	-1.485489
24.47383	169.8334	-1.493730
24.52383	169.8330	-1.501597
24.57716	169.8329	-1.510032
24.62716	169.8332	-1.517927
24.67883	169.8324	-1.526266
24.73050	169.8332	-1.534335
24.78050	169.8320	-1.542166
24.83383	169.8325	-1.550698
24.88383	169.8328	-1.558648
24.93716	169.8316	-1.566574
24.98716	169.8320	-1.573872
25.03883	169.8315	-1.580959
25.09050	169.8313	-1.587544
25.14050	169.8311	-1.593591
25.19383	169.8308	-1.599826
25.24383	169.8306	-1.604930
25.29716	169.8304	-1.610186
25.34716	169.8300	-1.614740
25.39883	169.8298	-1.619578
25.45050	169.8297	-1.624517
25.50050	169.8292	-1.629245
25.55383	169.8295	-1.633906
25.60383	169.8288	-1.638224
25.65716	169.8278	-1.642615
25.70716	169.8281	-1.646742
25.75883	169.8285	-1.651316
25.81050	169.8278	-1.655510
25.86050	169.8270	-1.659388
25.91383	169.8274	-1.663665
25.96383	169.8268	-1.667441
26.01550	169.8268	-1.671339
26.06716	169.8258	-1.675074
26.11883	169.8260	-1.678770
26.17050	169.8259	-1.682444
26.22050	169.8252	-1.685583
26.27383	169.8248	-1.688975
26.32383	169.8244	-1.692220
26.37550	169.8248	-1.695670
26.42717	169.8242	-1.699188
26.47883	169.8244	-1.702822
26.53050	169.8242	-1.706242
26.58050	169.8240	-1.709432
26.63383	169.8235	-1.712724
26.68383	169.8228	-1.715838
26.73550	169.8236	-1.719174
26.78717	169.8225	-1.722313
26.83716	169.8224	-1.725381
26.89050	169.8223	-1.728985
26.94050	169.8219	-1.732478
26.99383	169.8224	-1.736072
27.04383	169.8226	-1.739484
27.09550	169.8226	-1.743178
27.14716	169.8233	-1.746727
27.19717	169.8234	-1.750306
27.25050	169.8233	-1.753900
27.30050	169.8239	-1.757101
27.35383	169.8232	-1.760404
27.40383	169.8229	-1.763039
27.45550	169.8229	-1.765637
27.50716	169.8229	-1.768080
27.55716	169.8231	-1.770401
27.61050	169.8229	-1.772795
27.66050	169.8227	-1.774813
27.71383	169.8234	-1.776848
27.76383	169.8229	-1.778635
27.81550	169.8225	-1.780496
27.86716	169.8224	-1.782401
27.91716	169.8227	-1.784425
27.97050	169.8229	-1.786420
28.02050	169.8216	-1.787693
28.07383	169.8216	-1.788983
28.12383	169.8213	-1.789852
28.17550	169.8217	-1.790739
28.22717	169.8205	-1.791699
28.27717	169.8213	-1.792905
28.33050	169.8209	-1.794306
28.38050	169.8203	-1.795670
28.43216	169.8202	-1.797324
28.48383	169.8202	-1.799083
28.53550	169.8196	-1.800711
28.58716	169.8194	-1.802176
28.63716	169.8194	-1.803641
28.69050	169.8192	-1.805149
28.74050	169.8188	-1.806696
28.79216	169.8190	-1.808502
28.84383	169.8188	-1.810393
28.89550	169.8197	-1.812108
28.94717	169.8196	-1.813756
28.99716	169.8198	-1.815346
29.05050	169.8189	-1.817042
29.10050	169.8190	-1.818620
29.15216	169.8194	-1.820420
29.20383	169.8194	-1.822164
29.25383	169.8198	-1.823995
29.30716	169.8202	-1.825898
29.35716	169.8204	-1.827649
29.41050	169.8196	-1.829280
29.46050	169.8198	-1.830869
29.51216	169.8201	-1.832372
29.56383	169.8205	-1.833489
29.61383	169.8203	-1.834632
29.66716	169.8196	-1.835563
29.71716	169.8197	-1.836069
29.77050	169.8190	-1.836503
29.82050	169.8190	-1.836912
29.87216	169.8188	-1.837280
29.92383	169.8195	-1.837869
29.97383	169.8185	-1.838499
30.02717	169.8184	-1.839284
30.07717	169.8188	-1.840473
30.13050	169.8187	-1.841864
30.18050	169.8194	-1.843324
30.23216	169.8188	-1.844722
30.28383	169.8192	-1.846195
30.33383	169.8193	-1.847737
30.38716	169.8198	-1.849561
30.43717	169.8194	-1.851164
30.49050	169.8199	-1.852532
30.54050	169.8195	-1.853828
30.59216	169.8199	-1.854826
30.64383	169.8192	-1.855548
30.69383	169.8199	-1.856442
30.74716	169.8192	-1.856965
30.79716	169.8192	-1.857284
30.84883	169.8191	-1.857775
30.90050	169.8200	-1.858362
30.95217	169.8187	-1.858803
31.00383	169.8194	-1.859268
31.05383	169.8188	-1.859833
31.10716	169.8196	-1.860487
31.15716	169.8192	-1.861145
31.20883	169.8193	-1.861908
31.26050	169.8194	-1.862642
31.31050	169.8182	-1.863106
31.36383	169.8192	-1.863727
31.41383	169.8193	-1.864498
31.46716	169.8184	-1.865112
31.51716	169.8180	-1.865793
31.56883	169.8179	-1.866587
31.62050	169.8187	-1.866895
31.67050	169.8175	-1.867091
31.72383	169.8176	-1.867536
31.77383	169.8168	-1.867756
31.82717	169.8173	-1.868231
31.87717	169.8176	-1.869274
31.92883	169.8175	-1.869988
31.98050	169.8177	-1.870842
32.03050	169.8178	-1.871551
32.08383	169.8176	-1.872202
32.13383	169.8164	-1.872737
32.18716	169.8170	-1.873133
32.23717	169.8161	-1.873436
32.28883	169.8164	-1.873506
32.34050	169.8170	-1.873906
32.39050	169.8162	-1.874202
32.44383	169.8162	-1.874912
32.49383	169.8169	-1.875832
32.54716	169.8168	-1.876925
32.59716	169.8175	-1.878179
32.64883	169.8172	-1.879782
32.70050	169.8169	-1.880975
32.75050	169.8180	-1.882176
32.80383	169.8175	-1.883205
32.85383	169.8176	-1.884008
32.90550	169.8174	-1.884949
32.95716	169.8179	-1.885802
33.00883	169.8178	-1.886639
33.06050	169.8176	-1.887422
33.11050	169.8184	-1.888032
33.16383	169.8179	-1.888396
33.21383	169.8183	-1.888704
33.26550	169.8171	-1.888871
33.31716	169.8168	-1.889041
33.36883	169.8171	-1.888822
33.42050	169.8174	-1.888573
33.47050	169.8176	-1.888159
33.52383	169.8171	-1.888005
33.57383	169.8167	-1.887814
33.62550	169.8176	-1.887896
33.67717	169.8168	-1.888087
33.72717	169.8173	-1.888606
33.78050	169.8166	-1.889405
33.83050	169.8179	-1.890367
33.88383	169.8171	-1.891383
33.93384	169.8162	-1.892250
33.98550	169.8176	-1.893161
34.03717	169.8175	-1.894037
34.08716	169.8179	-1.894552
34.14050	169.8170	-1.895089
34.19050	169.8173	-1.895483
34.24383	169.8170	-1.895616
34.29383	169.8164	-1.895844
34.34550	169.8167	-1.896022
34.39717	169.8170	-1.896026
34.44717	169.8168	-1.895988
34.50050	169.8168	-1.895977
34.55050	169.8166	-1.895916
34.60383	169.8167	-1.895729
34.65383	169.8167	-1.895813
34.70550	169.8164	-1.895896
34.75716	169.8158	-1.895580
34.80716	169.8162	-1.895439
34.86050	169.8156	-1.895756
34.91050	169.8161	-1.896256
34.96383	169.8164	-1.897109
35.01383	169.8164	-1.898137
35.06550	169.8166	-1.899395
35.11716	169.8171	-1.900645
35.16716	169.8176	-1.901910
35.22050	169.8173	-1.903005
35.27050	169.8178	-1.903844
35.32217	169.8172	-1.904447
35.37383	169.8173	-1.905161
35.42550	169.8173	-1.905482
35.47717	169.8175	-1.905695
35.52716	169.8176	-1.905827
35.58050	169.8174	-1.905922
35.63050	169.8180	-1.905896
35.68216	169.8174	-1.906047
35.73383	169.8163	-1.905910
35.78550	169.8172	-1.905717
35.83716	169.8168	-1.905693
35.88716	169.8160	-1.905382
35.94050	169.8161	-1.904869
35.99050	169.8168	-1.904419
36.04217	169.8159	-1.904099
36.09384	169.8158	-1.903906
36.14383	169.8162	-1.903962
36.19717	169.8160	-1.904392
36.24716	169.8165	-1.905024
36.30050	169.8154	-1.905447
36.35050	169.8158	-1.905890
36.40216	169.8158	-1.906410
36.45383	169.8159	-1.906686
36.50383	169.8153	-1.907067
36.55716	169.8156	-1.907547
36.60716	169.8154	-1.907824
36.66050	169.8159	-1.907861
36.71050	169.8159	-1.907997
36.76216	169.8153	-1.908098
36.81383	169.8159	-1.908478
36.86383	169.8168	-1.909114
36.91716	169.8159	-1.909738
36.96716	169.8167	-1.910356
37.02050	169.8160	-1.911169
37.07050	169.8166	-1.912158
37.12216	169.8168	-1.913158
37.17383	169.8166	-1.913953
37.22383	169.8177	-1.914601
37.27716	169.8174	-1.915105
37.32717	169.8174	-1.915329
37.38050	169.8168	-1.915419
37.43050	169.8161	-1.915389
37.48216	169.8169	-1.915044
37.53383	169.8167	-1.914564
37.58383	169.8172	-1.914256
37.63716	169.8162	-1.913906
37.68716	169.8156	-1.913437
37.73883	169.8161	-1.912941
37.79050	169.8153	-1.912308
37.84216	169.8154	-1.911767
37.89383	169.8154	-1.911369
37.94383	169.8153	-1.911392
37.99716	169.8150	-1.911734
38.04716	169.8156	-1.912472
38.09883	169.8154	-1.913413
38.15050	169.8160	-1.914221
38.20050	169.8160	-1.914889
38.25383	169.8164	-1.915590
38.30383	169.8169	-1.916438
38.35716	169.8160	-1.917039
38.40716	169.8165	-1.917664
38.45883	169.8166	-1.918440
38.51050	169.8174	-1.919010
38.56050	169.8169	-1.919502
38.61383	169.8166	-1.919964
38.66383	169.8164	-1.920285
38.71716	169.8163	-1.920336
38.76716	169.8157	-1.920264
38.81883	169.8168	-1.920317
38.87050	169.8163	-1.919992
38.92050	169.8162	-1.919682
38.97383	169.8168	-1.919129
39.02383	169.8160	-1.918720
39.07717	169.8162	-1.918341
39.12717	169.8161	-1.918291
39.17883	169.8161	-1.918189
39.23050	169.8159	-1.918146
39.28050	169.8154	-1.918186
39.33383	169.8159	-1.918359
39.38383	169.8150	-1.918240
39.43716	169.8161	-1.918296
39.48717	169.8147	-1.918335
39.53883	169.8151	-1.918349
39.59050	169.8161	-1.918575
39.64050	169.8150	-1.918900
39.69383	169.8160	-1.919454
39.74383	169.8157	-1.920033
39.79550	169.8160	-1.920680
39.84716	169.8158	-1.921503
39.89883	169.8164	-1.922216
39.95050	169.8161	-1.922975
40.00050	169.8165	-1.923630
40.05383	169.8163	-1.924276
40.10383	169.8162	-1.924960
40.15550	169.8168	-1.925351
40.20716	169.8165	-1.925484
40.25883	169.8168	-1.925517
40.31050	169.8167	-1.925345
40.36050	169.8166	-1.925187
40.41383	169.8162	-1.924899
40.46383	169.8154	-1.924535
40.51550	169.8166	-1.924270
40.56716	169.8156	-1.923509
40.61716	169.8151	-1.922609
40.67050	169.8161	-1.921959
40.72050	169.8149	-1.921476
40.77383	169.8153	-1.921374
40.82383	169.8156	-1.921575
40.87550	169.8148	-1.921961
40.92717	169.8155	-1.922798
40.97717	169.8153	-1.923259
41.03050	169.8159	-1.923897
41.08050	169.8151	-1.924552
41.13383	169.8163	-1.924940
41.18383	169.8166	-1.925672
41.23550	169.8162	-1.926531
41.28717	169.8166	-1.927461
41.33716	169.8165	-1.928226
41.39050	169.8166	-1.928868
41.44050	169.8162	-1.929289
41.49383	169.8162	-1.929473
41.54383	169.8162	-1.929304
41.59550	169.8159	-1.929094
41.64717	169.8162	-1.928659
41.69717	169.8158	-1.927899
41.75050	169.8156	-1.926884
41.80050	169.8155	-1.926122
41.85383	169.8154	-1.925641
41.90383	169.8160	-1.925574
41.95550	169.8154	-1.925684
42.00717	169.8159	-1.926046
42.05717	169.8159	-1.926559
42.11050	169.8152	-1.927035
42.16050	169.8167	-1.927841
42.21216	169.8156	-1.928306
42.26383	169.8160	-1.928689
42.31550	169.8163	-1.929206
42.36716	169.8161	-1.929496
42.41716	169.8165	-1.929718
42.47050	169.8158	-1.929906
42.52050	169.8163	-1.930210
42.57217	169.8161	-1.930299
42.62383	169.8156	-1.930206
42.67550	169.8162	-1.929730
42.72717	169.8166	-1.929351
42.77716	169.8152	-1.928807
42.83050	169.8151	-1.928194
42.88050	169.8149	-1.927628
42.93217	169.8158	-1.926902
42.98383	169.8154	-1.926138
43.03383	169.8158	-1.925949
43.08716	169.8152	-1.925998
43.13716	169.8146	-1.926442
43.19050	169.8154	-1.926797
43.24050	169.8163	-1.927474
43.29217	169.8158	-1.927972
43.34384	169.8164	-1.928604
43.39383	169.8169	-1.929144
43.44717	169.8158	-1.929417
43.49716	169.8163	-1.929868
43.55050	169.8168	-1.930173
43.60050	169.8164	-1.930460
43.65216	169.8164	-1.930531
43.70383	169.8158	-1.930591
43.75050	169.8163	-1.930444
43.80383	169.8737	-1.949438
43.85383	170.2552	-3.192153
43.90717	170.8520	-6.271018
43.95717	171.5086	-9.660134
44.00883	172.2586	-13.09402
44.06050	173.0633	-16.17519
44.11050	173.8828	-18.73306
44.16383	174.7906	-21.01255
44.21383	175.6684	-22.78535
44.26717	176.6280	-24.34024
44.31717	177.5439	-25.53960
44.36883	178.5039	-26.57264
44.42050	179.4749	-27.44800
44.47050	180.4243	-28.16250
44.52383	181.4436	-28.82760
44.57383	182.4044	-29.38156
44.62717	183.4344	-29.90321
44.67717	184.4037	-30.35604
44.72883	185.4084	-30.78912
44.78050	186.4144	-31.20440
44.83050	187.3904	-31.59256
44.88383	188.4339	-32.00957
44.93383	189.4106	-32.40487
44.98717	190.4538	-32.84706
45.03717	191.4307	-33.27160
45.08883	192.4411	-33.73452
45.14050	193.4498	-34.20746
45.19050	194.4272	-34.66360
45.24383	195.4678	-35.21634
45.29383	196.4400	-35.81315
45.34550	197.4418	-36.51345
45.39717	198.4396	-37.31192
45.44883	199.4328	-38.23300
45.50050	200.4196	-39.30645
45.55050	201.3668	-40.52016
45.60383	202.3660	-42.05148
45.65383	203.2959	-43.64296
45.70550	204.2449	-45.56392
45.75717	205.1856	-47.65904
45.80883	206.1170	-49.95631
45.86050	207.0392	-52.47000
45.91050	207.9219	-55.14738
45.96383	208.8500	-58.27516
46.01383	209.7109	-61.38334
46.06550	210.5960	-64.65388
46.11716	211.4827	-67.85969
46.16716	212.3472	-70.79102
46.22050	213.2815	-73.61778
46.27050	214.1766	-75.79825
46.32383	215.1644	-77.28566
46.37383	216.1376	-77.53818
46.42550	217.2090	-76.28054
46.47717	218.3510	-73.54450
46.52716	219.5021	-70.06725
46.58050	220.7615	-65.71374
46.63050	221.9739	-60.92971
46.68383	223.2873	-55.65040
46.73383	224.4976	-51.38122
46.78550	225.7113	-47.75565
46.83716	226.8917	-44.87680
46.88716	228.0045	-42.65558
46.94050	229.1668	-40.79322
46.99050	230.2378	-39.43022
47.04383	231.3644	-38.28988
47.09384	232.4092	-37.45905
47.14550	233.4786	-36.79339
47.19717	234.5399	-36.27476
47.24716	235.5620	-35.89484
47.30050	236.6465	-35.57971
47.35050	237.6607	-35.35996
47.40383	238.7389	-35.18738
47.45383	239.7465	-35.07330
47.50550	240.7867	-34.99786
47.55717	241.8254	-34.95572
47.60717	242.8296	-34.94665
47.66050	243.8992	-34.94100
47.71050	244.9015	-34.94253
47.76216	245.9364	-34.95132
47.81383	246.9707	-34.99157
47.86550	248.0040	-35.03480
47.91716	249.0364	-35.11331
47.96717	250.0330	-35.26677
48.02050	251.0990	-35.33846
48.07050	252.0980	-35.39622
48.12216	253.1316	-35.45118
48.17383	254.1654	-35.50132
48.22550	255.1978	-35.55453
48.27716	256.2316	-35.61366
48.32717	257.2314	-35.68259
48.38050	258.2978	-35.74072
48.43050	259.2978	-35.80328
48.48217	260.3312	-35.87740
48.53383	261.3642	-35.93024
48.58383	262.3630	-35.98217
48.63716	263.4302	-36.05935
48.68716	264.4287	-36.11746
48.74050	265.4946	-36.19502
48.79050	266.4937	-36.26626
48.84217	267.5269	-36.34510
48.89383	268.5581	-36.43372
48.94383	269.5575	-36.51506
48.99716	270.6230	-36.58592
49.04716	271.6216	-36.65930
49.10050	272.6868	-36.74111
49.15050	273.6852	-36.81255
49.20216	274.7182	-36.89225
49.25050	275.6826	-36.98360
49.30383	276.6228	-37.07840
49.35383	276.7953	-34.86113
49.40717	276.5965	-28.54857
49.45717	276.2107	-21.60575
49.50883	275.6819	-14.64339
49.56050	275.0540	-8.481953
49.61050	274.3724	-3.428694
49.66383	273.5830	1.028834
49.71383	272.7963	4.457200
49.76717	271.9181	7.437566
49.81717	271.0635	9.727578
49.86883	270.1563	11.66860
49.92050	269.2289	13.26586
49.97050	268.3156	14.55866
50.02383	267.3285	15.72483
50.07383	266.3922	16.64090
50.12717	265.3844	17.47262
50.17717	264.4324	18.14877
50.22883	263.4414	18.74560
50.28050	262.4456	19.26798
50.33050	261.4774	19.71532
50.38383	260.4423	20.13980
50.43383	259.4684	20.48948
50.48717	258.4270	20.82859
50.53717	257.4501	21.11602
50.58883	256.4365	21.38765
50.64050	255.4221	21.63272
50.69050	254.4390	21.86064
50.74383	253.3890	22.08584
50.79383	252.4034	22.27586
50.84550	251.3844	22.45460
50.89717	250.3646	22.62448
50.94883	249.3426	22.78386
51.00050	248.3210	22.93198
51.05050	247.3328	23.07486
51.10383	246.2776	23.20505
51.15383	245.2879	23.32432
51.20550	244.2643	23.44211
51.25717	243.2409	23.54902
51.30883	242.2165	23.65213
51.36050	241.1924	23.74354
51.41050	240.2011	23.83318
51.46383	239.1423	23.92109
51.51383	238.1506	24.00508
51.56550	237.1248	24.08821
51.61716	236.0996	24.17512
51.66716	235.1073	24.24234
51.72050	234.0477	24.31372
51.77050	233.0554	24.37622
51.82383	231.9946	24.43998
51.87383	231.0008	24.49515
51.92550	229.9735	24.55566
51.97717	228.9459	24.60798
52.02717	227.9518	24.66623
52.08050	226.8920	24.72849
52.13050	225.8992	24.76978
52.18383	224.8386	24.82865
52.23383	223.8440	24.87285
52.28550	222.8168	24.92032
52.33716	221.7888	24.96730
52.38716	220.7944	25.01094
52.44050	219.7343	25.05548
52.49050	218.7390	25.10260
52.54382	217.6771	25.14132
52.59384	216.6826	25.17392
52.64550	215.6549	25.20758
52.69717	214.6264	25.23782
52.74717	213.6312	25.26816
52.80050	212.5696	25.29706
52.85050	211.5739	25.32553
52.90383	210.5125	25.35110
52.95383	209.5167	25.37699
53.00550	208.4888	25.39980
53.05717	207.4602	25.42093
53.10717	206.4646	25.44358
53.16050	205.4025	25.46700
53.21050	204.4069	25.48879
53.26216	203.3771	25.50916
53.31382	202.3494	25.52398
53.36550	201.3194	25.53042
53.41716	200.2900	25.54470
53.46717	199.2944	25.55930
53.52050	198.2322	25.57664
53.57050	197.2361	25.59159
53.62217	196.2069	25.60294
53.67383	195.1778	25.61962
53.72550	194.1480	25.63720
53.77717	193.1186	25.64890
53.82717	192.1222	25.65836
53.88050	191.0597	25.66848
53.93050	190.0637	25.67981
53.98217	189.0347	25.69106
54.03383	188.0047	25.70229
54.08383	187.0088	25.71220
54.13716	185.9459	25.72168
54.18716	184.9490	25.73050
54.24050	183.8866	25.73881
54.29050	182.8904	25.74510
54.34217	181.8604	25.75171
54.39384	180.8309	25.75824
54.44384	179.8349	25.76548
54.49717	178.7722	25.77924
54.54717	177.7761	25.80245
54.60050	176.7132	25.84550
54.65050	175.7189	25.90064
54.70216	174.6925	25.99047
54.75383	173.6667	26.13144
54.80383	172.6792	26.34805
54.85717	171.6309	26.73770
54.90717	170.6585	27.33547
54.96050	169.6359	28.32525
55.01050	168.6956	29.63272
55.06216	167.7436	31.40070
55.11382	166.8129	33.59308
55.16382	165.9352	36.18272
55.21717	165.0252	39.51684
55.26716	164.1972	43.10440
55.32050	163.3327	47.19941
55.37050	162.5234	50.94148
55.42217	161.6719	54.35738
55.47382	160.7889	57.04738
55.52383	159.8975	58.82541
55.57717	158.8987	59.76831
55.62717	157.9214	59.79171
55.67883	156.8714	59.05451
55.73050	155.7876	57.66675
55.78217	154.6741	55.75241
55.83383	153.5397	53.49558
55.88383	152.4281	51.06167
55.93716	151.2368	48.43984
55.98717	150.1189	46.03062
56.03882	148.9666	43.60424
56.09050	147.8234	41.40266
56.14050	146.7257	39.46781
56.19384	145.5701	37.69731
56.24382	144.4966	36.25440
56.29717	143.3634	34.92141
56.34716	142.3085	33.78199
56.39883	141.2170	32.43823
56.45050	140.1318	31.57074
56.50050	139.0986	30.91045
56.55383	138.0028	30.29779
56.60383	136.9795	29.79185
56.65717	135.8918	29.32772
56.70717	134.8750	28.93532
56.75883	133.8267	28.58908
56.81050	132.7798	28.27394
56.86050	131.7684	28.00945
56.91382	130.6924	27.75523
56.96382	129.6832	27.54465
57.01716	128.6087	27.34064
57.06716	127.6023	27.16051
57.11882	126.5638	26.98728
57.17050	125.5244	26.82451
57.22050	124.5211	26.67737
57.27383	123.4507	26.54315
57.32383	122.4481	26.41455
57.37717	121.3771	26.28772
57.42717	120.3750	26.17658
57.47883	119.3381	26.06110
57.53050	118.3024	25.95976
57.58050	117.2995	25.85783
57.63383	116.2319	25.76004
57.68383	115.2303	25.66636
57.73550	114.1956	25.57513
57.78716	113.1588	25.48002
57.83882	112.1235	25.38411
57.89050	111.0887	25.28683
57.94050	110.0857	25.19843
57.99382	109.0187	25.10643
58.04382	108.0165	25.01980
58.09550	106.9803	24.92016
58.14717	105.9449	24.82979
58.19883	104.9091	24.72458
58.25050	103.8731	24.63858
58.30050	102.8716	24.56596
58.35383	101.8037	24.48976
58.40383	100.8029	24.41443
58.45550	99.76953	24.34087
58.50717	98.73492	24.26980
58.55717	97.73410	24.20294
58.61050	96.66696	24.13078
58.66050	95.66629	24.05132
58.71382	94.59741	23.97342
58.76382	93.59692	23.90069
58.81550	92.56282	23.82928
58.86716	91.52919	23.75498
58.91716	90.52687	23.68920
58.97050	89.46061	23.60286
59.02050	88.45968	23.53517
59.07383	87.39232	23.45836
59.12383	86.39074	23.38724
59.17550	85.35702	23.31221
59.22717	84.32179	23.23344
59.27717	83.32216	23.16526
59.33050	82.25508	23.09009
59.38050	81.25418	23.01914
59.43383	80.18639	22.94976
59.48383	79.18605	22.88136
59.53550	78.15137	22.81572
59.58716	77.11689	22.74494
59.63716	76.11634	22.67908
59.69050	75.04908	22.61447
59.74050	74.04850	22.55047
59.79382	72.98134	22.49172
59.84384	71.98114	22.43287
59.89550	70.94714	22.37299
59.94717	69.91353	22.31298
59.99717	68.91324	22.25627
60.05050	67.84478	22.19358
60.10050	66.84478	22.12695
60.15217	65.81132	22.06121
60.20383	64.77608	21.99864
60.25550	63.74297	21.93667
60.30717	62.70903	21.86133
60.35717	61.70753	21.79285
60.41050	60.64100	21.71578
60.46050	59.63931	21.64162
60.51216	58.60428	21.57146
60.56382	57.57007	21.49765
60.61550	56.53463	21.41906
60.66716	55.49971	21.34381
60.71717	54.49722	21.26700
60.77050	53.42780	21.18304
60.82050	52.42566	21.10185
60.87217	51.39143	21.01990
60.92383	50.35654	20.93881
60.97382	49.35516	20.85823
61.02717	48.28620	20.78120
61.07717	47.28503	20.70195
61.13050	46.21611	20.62391
61.18050	45.21358	20.54654
61.23217	44.17838	20.47369
61.28383	43.14276	20.39362
61.33383	42.14062	20.31757
61.38716	41.07206	20.22963
61.43716	40.06979	20.14628
61.49050	39.00180	20.05634
61.54050	37.99909	19.97220
61.59217	36.96330	19.87219
61.64384	35.92687	19.77480
61.69384	34.92390	19.68546
61.74717	33.85334	19.57599
61.79717	32.85067	19.46823
61.85050	31.78009	19.34499
61.90050	30.77510	19.23962
61.95216	29.73900	19.12970
62.00383	28.70194	19.01722
62.05383	27.69834	18.89958
62.10717	26.62440	18.78205
62.15717	25.62162	18.66921
62.21050	24.55025	18.54556
62.26050	23.54476	18.42675
62.31050	22.73703	18.23009
62.36382	22.60948	16.08878
62.41382	22.77943	12.28158
62.46550	23.16436	7.863478
62.51716	23.69053	3.567048
62.56716	24.30440	-0.1326734
62.62050	25.04586	-3.477002
62.67050	25.80173	-6.060057
62.72382	26.66106	-8.294579
62.77383	27.50311	-9.981641
62.82550	28.40480	-11.37514
62.87717	29.33042	-12.49013
62.92717	30.24309	-13.35714
62.98050	31.23264	-14.09879
63.03050	32.17200	-14.66715
63.08217	33.15290	-15.15602
63.13383	34.13989	-15.56688
63.18550	35.13360	-15.92431
63.23717	36.13150	-16.23328
63.28716	37.10139	-16.49824
63.34050	38.13850	-16.76285
63.39050	39.11461	-16.98189
63.44216	40.12527	-17.18612
63.49382	41.13748	-17.37083
63.54550	42.15217	-17.55412
63.59716	43.16913	-17.72421
63.64717	44.15286	-17.88162
63.70050	45.20334	-18.03952
63.75050	46.19162	-18.18288
63.80217	47.21222	-18.32104
63.85383	48.23456	-18.45272
63.90383	49.22556	-18.57574
63.95717	50.28190	-18.70338
64.00718	51.27256	-18.82282
64.06050	52.33115	-18.94656
64.11050	53.32386	-19.05746
64.16217	54.34896	-19.17486
64.21384	55.37571	-19.28283
64.26384	56.36924	-19.39640
64.31717	57.42870	-19.51044
64.36718	58.42377	-19.61401
64.42050	59.48525	-19.72991
64.47050	60.48002	-19.83779
64.52217	61.50836	-19.94186
64.57384	62.53690	-20.04858
64.62383	63.53342	-20.15228
64.67718	64.59514	-20.25384
64.72718	65.59044	-20.34398
64.78050	66.65412	-20.44299
64.83050	67.64969	-20.53998
64.88218	68.67964	-20.63887
64.93384	69.71040	-20.73384
64.98383	70.70735	-20.82286
65.03717	71.77102	-20.91638
65.08716	72.76765	-21.00456
65.14050	73.83086	-21.09914
65.19050	74.82790	-21.18352
65.24218	75.85820	-21.27748
65.29384	76.88831	-21.36951
65.34384	77.88589	-21.46300
65.39717	78.94959	-21.56115
65.44717	79.94672	-21.65636
65.49884	80.97660	-21.75254
65.55050	82.00772	-21.85390
65.60218	83.03740	-21.94894
65.65384	84.06853	-22.04579
65.70384	85.06580	-22.14111
65.75718	86.12920	-22.24387
65.80718	87.12582	-22.34130
65.85884	88.15642	-22.44358
65.91050	89.18686	-22.54266
65.96050	90.18402	-22.64529
66.01384	91.24749	-22.75194
66.06384	92.24524	-22.85100
66.11718	93.30887	-22.95410
66.16718	94.30639	-23.05163
66.21884	95.33688	-23.15343
66.27050	96.36725	-23.25562
66.32050	97.36476	-23.34320
66.37384	98.42900	-23.44118
66.42384	99.42564	-23.54020
66.47718	100.4898	-23.64175
66.52718	101.4865	-23.74010
66.57884	102.5158	-23.84430
66.63050	103.5462	-23.94391
66.68050	104.5430	-24.04730
66.73384	105.6072	-24.15633
66.78384	106.6032	-24.26199
66.83716	107.6669	-24.37334
66.88718	108.6630	-24.47752
66.93884	109.6939	-24.58112
66.99050	110.7250	-24.69122
67.04050	111.7218	-24.79839
67.09384	112.7849	-24.90813
67.14384	113.7828	-25.00968
67.19718	114.8465	-25.11833
67.24718	115.8440	-25.21895
67.29884	116.8742	-25.32254
67.35050	117.9040	-25.42424
67.40050	118.9016	-25.52533
67.45384	119.9641	-25.64153
67.50384	120.9610	-25.75152
67.55550	121.9909	-25.86884
67.60718	123.0213	-25.98798
67.65884	124.0507	-26.10962
67.71050	125.0806	-26.22988
67.76050	126.0772	-26.34747
67.81384	127.1409	-26.46846
67.86384	128.1368	-26.58041
67.91550	129.1674	-26.69819
67.96718	130.1980	-26.81936
68.01882	131.2275	-26.94160
68.07050	132.2576	-27.06692
68.12050	133.2538	-27.17640
68.17384	134.3173	-27.30630
68.22384	135.3135	-27.43386
68.27550	136.3424	-27.56804
68.32718	137.3722	-27.69982
68.37718	138.3677	-27.82956
68.43050	139.4299	-27.97230
68.48050	140.4254	-28.10946
68.53384	141.4883	-28.25503
68.58384	142.4840	-28.39123
68.63550	143.5135	-28.53292
68.68718	144.5427	-28.67047
68.73718	145.5376	-28.80923
68.79050	146.5997	-28.95608
68.84050	147.5955	-29.10160
68.89384	148.6563	-29.25050
68.94384	149.6517	-29.39680
68.99550	150.6808	-29.54296
69.04718	151.7086	-29.69891
69.09718	152.7038	-29.84626
69.15050	153.7649	-30.01228
69.20050	154.7600	-30.16778
69.25384	155.8201	-30.34158
69.30384	156.8146	-30.50916
69.35550	157.8429	-30.68590
69.40718	158.8707	-30.86517
69.45718	159.8648	-31.03567
69.51050	160.9264	-31.21030
69.56050	161.9204	-31.38264
69.61384	162.9814	-31.56259
69.66382	163.9752	-31.72856
69.71550	165.0030	-31.90306
69.76716	166.0305	-32.06274
69.81718	167.0253	-32.22250
69.87050	168.0884	-32.38870
69.92050	169.0834	-32.52514
69.97218	170.1139	-32.65996
70.02384	171.1432	-32.78336
70.07550	172.1741	-32.89313
70.12718	173.2034	-33.00534
70.17718	174.2006	-33.10556
70.23050	175.2642	-33.21389
70.28050	176.2605	-33.32144
70.33218	177.2904	-33.44602
70.38384	178.3197	-33.58282
70.43550	179.3483	-33.74263
70.48718	180.3759	-33.91156
70.53718	181.3700	-34.09209
70.59050	182.4294	-34.29474
70.64050	183.4214	-34.51164
70.69218	184.4451	-34.77345
70.74384	185.4674	-35.06482
70.79384	186.4556	-35.38400
70.84718	187.5077	-35.75804
70.89718	188.4925	-36.15848
70.95050	189.5413	-36.63021
71.00050	190.5203	-37.13250
71.05218	191.5304	-37.70722
71.10384	192.5366	-38.35032
71.15384	193.5076	-39.03246
71.20718	194.5411	-39.82821
71.25718	195.5054	-40.62884
71.31050	196.5334	-41.54354
71.36050	197.4950	-42.45084
71.41218	198.4858	-43.43174
71.46384	199.4746	-44.45304
71.51384	200.4292	-45.46920
71.56718	201.4475	-46.58537
71.61718	202.3998	-47.67308
71.67050	203.4147	-48.85560
71.72050	204.3654	-49.99262
71.77218	205.3464	-51.17581
71.82384	206.3274	-52.36530
71.87384	207.2795	-53.45797
71.92718	208.3000	-54.46480
71.97718	209.2691	-55.15030
72.03050	210.3180	-55.43634
72.08050	211.3249	-55.18403
72.13218	212.3942	-54.27628
72.18384	213.4963	-52.61512
72.23384	214.5965	-50.26050
72.28718	215.7980	-47.24720
72.33716	216.9322	-44.44136
72.38884	218.0905	-41.93960
72.44050	219.2266	-39.90000
72.49218	220.3434	-38.27252
72.54384	221.4447	-36.99483
72.59384	222.4970	-36.01352
72.64718	223.6080	-35.19525
72.69718	224.6398	-34.59190
72.74884	225.7001	-34.09741
72.80050	226.7547	-33.71540
72.85050	227.7709	-33.43705
72.90384	228.8516	-33.20922
72.95384	229.8616	-33.06192
73.00718	230.9369	-32.95018
73.05718	231.9436	-32.88110
73.10884	232.9826	-32.84700
73.16050	234.0199	-32.82740
73.21050	235.0224	-32.82252
73.26384	236.0913	-32.82070
73.31384	237.0932	-32.82246
73.36718	238.1602	-32.84068
73.41718	239.1618	-32.88163
73.46884	240.1948	-32.92898
73.52050	241.2282	-32.98725
73.57050	242.2288	-33.05637
73.62384	243.2961	-33.12210
73.67384	244.2955	-33.18900
73.72718	245.3609	-33.25480
73.77718	246.3605	-33.31689
73.82884	247.3939	-33.38808
73.88050	248.4266	-33.45260
73.93050	249.4246	-33.51535
73.98384	250.4904	-33.59490
74.03384	251.4904	-33.67558
74.08716	252.5560	-33.75408
74.13718	253.5548	-33.83410
74.18884	254.5870	-33.91007
74.24050	255.6186	-33.99124
74.29050	256.6175	-34.08603
74.34384	257.6818	-34.18660
74.39384	258.6792	-34.28374
74.44550	259.7108	-34.39195
74.49718	260.7428	-34.50511
74.54884	261.7731	-34.61365
74.60050	262.8043	-34.73146
74.65050	263.8022	-34.83374
74.70384	264.8661	-34.95330
74.75384	265.8634	-35.06876
74.80550	266.8938	-35.19757
74.85718	267.9233	-35.32590
74.90884	268.9522	-35.46316
74.96050	269.9825	-35.60810
75.01050	270.9788	-35.75214
75.06384	272.0404	-35.90110
-2.000000	5.000000	0.0000000