File: 1-C1(0.6mol%)+C20(0.6mol%)/matlab/170-3.txt
CLOSED
Version	1.0
Language	English
Mode	Standard
Run	12
RunSerial	11862
Instrument	DSC Q2000 V24.11 Build 124
Module	DSC Standard Cell RC
Operator	Jing
File	\\AE520-1454\TA\Data\DSC\UQ Composites\Nan\C1(5.5)+C20P(3)+CL(HotplateMixtureAB)\170-3
ProcName	Ramp
InstSerial	2000-0883
AutoSerial	1293
Sample	Iso-170-3
Size	41.7000	mg
PanMass	Not available
PanResist	Automatic Automatic  K/W
PanFactor	Default Default
Method	Ramp
Comment
Xcomment	Pan: Tzero Aluminum Hermetic
Xcomment	Gas1: Nitrogen 50.0 ml/min
Xcomment	Gas2: Nitrogen 50.0 ml/min
Text
Exotherm	UP
Kcell	1.05230
Cpconst	Standard: 0.938
Calib	-38.6961
TempCal	1	pts	157.46	156.60
TzeroDt	-87.6168 -0.0009 -1.4231
TzeroDtz	-87.6168 0.0057 6.9570
InstCalFile	Tzero: \\Ae520-1454\ta\Data\DSC\Calibration\2017\CALIBRATION\1562_RCS (90)_05_18_2017 10_50_44.TZR
InstCalFile	Baseline: \\Ae520-1454\ta\Data\DSC\Calibration\2017\2017-05-17_Calibration.001
InstCalFile	Sapphire: \\Ae520-1454\ta\Data\DSC\Calibration\2017\2017-05-17_Saphire.001
InstCalDate	Tzero 2017-05-18 Time 10:50:44
TempRange	-87.39 to 398.39 °C at 10.00 °C/min Heat Only
AutoZero	Delta T Offset 0.000 uV
AutoZero	Delta T0 Offset 0.000 uV
MultiptCal	0
MultiPtDesc	0) Not set
AutoCellConst	Calibration Date 2017-05-18 16:59:28
Controls	Gas 1  Event Off  Sampling 0.2
Cell#	RC-01562
CoolingUnit	RCS (90)
SelHeatFlow	Heat Flow T4 (mW)
AutoLidII	Installed
AutoAnalysis	Off
MacroFile
Nsig	3
Sig1	Time (min)
Sig2	Temperature (°C)
Sig3	Heat Flow (mW)
Date	2017-06-21
Time	07:42:45
OrgMethod	1: Equilibrate at 20.00 °C
OrgMethod	2: Ramp 40.00 °C/min to 170.00 °C
OrgMethod	3: Mark end of cycle 1
OrgMethod	4: Isothermal for 40.00 min
OrgMethod	5: Mark end of cycle 2
OrgMethod	6: Ramp 20.00 °C/min to 280.00 °C
OrgMethod	7: Mark end of cycle 3
OrgMethod	8: Ramp 20.00 °C/min to 20.00 °C
OrgMethod	9: Mark end of cycle 4
OrgMethod	10: Ramp 20.00 °C/min to 280.00 °C
OrgMethod	11: Mark end of cycle 5
OrgFile	C:\Users\jarra\Desktop\DSC\1-C1(0.6mol%)+C20(0.6mol%)\170-3.001
StartOfData
4.99994E-4	20.05912	0.2567706
0.05383332	20.17156	0.2892408
0.1038333	20.97266	-0.5345283
0.1571666	22.22315	-3.931726
0.2071666	23.57913	-7.904856
0.2588334	25.12036	-12.12612
0.3105000	26.75955	-16.02129
0.3605000	28.42212	-19.32844
0.4138333	30.25992	-22.31595
0.4638333	32.03084	-24.64627
0.5171667	33.96186	-26.69306
0.5671668	35.80172	-28.27533
0.6188334	37.72678	-29.65205
0.6705000	39.67042	-30.81790
0.7205000	41.56620	-31.81297
0.7738332	43.59588	-32.86376
0.8238334	45.49680	-33.97370
0.8771668	47.52864	-35.05924
0.9271668	49.44822	-35.85446
0.9788332	51.44254	-36.63660
1.030500	53.43559	-37.55269
1.080500	55.35588	-38.69750
1.133833	57.38547	-40.29985
1.183833	59.28332	-41.80478
1.237166	61.31394	-43.36132
1.287167	63.21126	-45.13742
1.338833	65.14076	-47.75866
1.390500	66.99974	-52.12459
1.440500	68.67046	-59.17309
1.493833	70.25144	-70.38156
1.543833	71.52554	-85.87421
1.595500	72.65574	-102.3196
1.647167	73.83700	-117.5682
1.698833	75.16922	-130.5536
1.750500	76.50390	-144.0119
1.800500	77.87901	-154.3889
1.853833	79.52274	-161.8503
1.903833	81.12793	-169.4887
1.955500	83.09084	-168.8119
2.007167	85.37707	-164.2926
2.058833	87.59784	-163.0887
2.110500	89.77772	-160.8557
2.160500	92.06025	-154.3780
2.213833	94.90671	-138.2565
2.263833	97.75920	-123.5019
2.315500	100.5701	-111.0319
2.367167	103.2434	-100.9003
2.417167	105.7220	-92.93947
2.470500	108.2715	-86.03442
2.520500	110.5877	-80.82597
2.573833	112.9954	-76.37272
2.623834	115.2007	-73.08297
2.675500	117.4483	-70.12750
2.727167	119.6564	-67.97356
2.777166	121.7586	-66.57274
2.830500	123.9716	-65.53348
2.880500	126.0268	-64.86770
2.933833	128.2052	-64.39129
2.983833	130.2376	-64.11868
3.035500	132.3298	-64.05188
3.087167	134.4141	-64.13489
3.137167	136.4249	-64.35052
3.190500	138.5635	-64.75824
3.240500	140.5630	-65.26376
3.293833	142.6894	-65.92066
3.343834	144.6796	-66.62339
3.395500	146.7330	-67.42770
3.447167	148.7822	-68.31763
3.497166	150.7649	-69.19311
3.550500	152.8780	-70.16611
3.600500	154.8575	-71.14048
3.653833	156.9678	-72.23328
3.703833	158.9453	-73.30863
3.750500	160.7889	-74.32845
3.803833	162.7903	-75.67882
3.853833	163.9656	-75.63900
3.907166	164.8190	-71.58962
3.957167	165.4444	-66.34492
4.008833	165.9678	-60.55540
4.060500	166.4010	-55.12003
4.110500	166.7526	-50.41847
4.163834	167.0674	-46.06824
4.213834	167.3180	-42.56496
4.267166	167.5450	-39.35232
4.317167	167.7284	-36.75105
4.368834	167.8942	-34.36972
4.420500	168.0389	-32.25511
4.470500	168.1656	-30.40512
4.523834	168.2878	-28.56106
4.573834	168.3921	-26.93679
4.627167	168.4943	-25.30035
4.677166	168.5843	-23.85012
4.728833	168.6692	-22.45987
4.780500	168.7471	-21.18083
4.830500	168.8160	-20.02953
4.883834	168.8842	-18.87496
4.933834	168.9450	-17.81104
4.987167	169.0089	-16.65223
5.037167	169.0697	-15.50637
5.088834	169.1353	-14.25987
5.140500	169.2019	-13.00410
5.190500	169.2633	-11.86694
5.243834	169.3235	-10.74134
5.293832	169.3764	-9.749744
5.345500	169.4279	-8.760840
5.397168	169.4783	-7.785137
5.448834	169.5277	-6.843822
5.500500	169.5723	-6.011650
5.550500	169.6103	-5.319821
5.603832	169.6438	-4.683784
5.653834	169.6725	-4.169766
5.705500	169.6970	-3.713552
5.757168	169.7176	-3.322195
5.808832	169.7374	-2.974595
5.860500	169.7541	-2.669705
5.910500	169.7681	-2.406738
5.963832	169.7822	-2.154431
6.013834	169.7937	-1.936820
6.065500	169.8048	-1.726247
6.117168	169.8159	-1.532326
6.167168	169.8250	-1.357745
6.220500	169.8340	-1.185416
6.270500	169.8424	-1.027580
6.323834	169.8502	-0.8689679
6.373832	169.8573	-0.7314065
6.425500	169.8658	-0.5912454
6.477168	169.8728	-0.4505344
6.527168	169.8802	-0.3202219
6.580500	169.8867	-0.1798088
6.630500	169.8934	-.05248535
6.683832	169.9004	0.09242703
6.733832	169.9080	0.2309167
6.785500	169.9147	0.3630028
6.837168	169.9213	0.5029164
6.887168	169.9282	0.6326080
6.940500	169.9366	0.7753694
6.990500	169.9425	0.9024486
7.043832	169.9489	1.039979
7.093832	169.9558	1.171593
7.145500	169.9630	1.301701
7.197168	169.9697	1.435881
7.247168	169.9758	1.569810
7.300500	169.9829	1.700417
7.350500	169.9895	1.828644
7.403832	169.9973	1.969544
7.453832	170.0029	2.101210
7.505500	170.0094	2.231388
7.557166	170.0173	2.361328
7.607168	170.0227	2.489202
7.660500	170.0294	2.620277
7.710500	170.0361	2.742570
7.762168	170.0420	2.868190
7.813834	170.0478	2.987005
7.865500	170.0543	3.105370
7.917168	170.0592	3.224271
7.967168	170.0652	3.329996
8.020500	170.0720	3.441672
8.070500	170.0763	3.542880
8.122168	170.0816	3.641590
8.173832	170.0872	3.734811
8.225500	170.0910	3.825566
8.277168	170.0955	3.906766
8.327168	170.0989	3.979628
8.380500	170.1019	4.053190
8.430500	170.1060	4.110220
8.482166	170.1094	4.161910
8.533832	170.1117	4.209652
8.583832	170.1142	4.250503
8.637168	170.1159	4.286278
8.687166	170.1177	4.314470
8.740500	170.1194	4.336996
8.790500	170.1196	4.356939
8.842168	170.1214	4.374560
8.893832	170.1226	4.391134
8.943832	170.1244	4.405388
8.997168	170.1254	4.422238
9.047168	170.1257	4.442759
9.100500	170.1271	4.465862
9.150500	170.1282	4.489964
9.202168	170.1296	4.517305
9.253834	170.1312	4.548277
9.303832	170.1323	4.582668
9.357166	170.1342	4.619630
9.407166	170.1358	4.655258
9.460499	170.1384	4.688653
9.510499	170.1394	4.721529
9.562166	170.1413	4.758947
9.613834	170.1422	4.792800
9.663834	170.1440	4.826116
9.717168	170.1462	4.859885
9.767168	170.1484	4.889754
9.820500	170.1492	4.924012
9.870499	170.1515	4.956359
9.922168	170.1523	4.991384
9.973832	170.1546	5.024185
10.02383	170.1561	5.053035
10.07717	170.1580	5.089562
10.12717	170.1608	5.123150
10.17883	170.1616	5.158868
10.23050	170.1627	5.191322
10.28217	170.1653	5.223496
10.33383	170.1662	5.255562
10.38383	170.1687	5.282152
10.43717	170.1699	5.311382
10.48717	170.1707	5.333515
10.53883	170.1724	5.351001
10.59050	170.1728	5.364746
10.64050	170.1746	5.374224
10.69383	170.1745	5.381360
10.74384	170.1744	5.387198
10.79717	170.1738	5.391412
10.84717	170.1742	5.392254
10.89883	170.1730	5.389229
10.95050	170.1727	5.377118
11.00050	170.1710	5.353164
11.05383	170.1696	5.315684
11.10383	170.1674	5.273410
11.15717	170.1656	5.228982
11.20717	170.1632	5.183198
11.25883	170.1613	5.134550
11.31050	170.1589	5.084844
11.36050	170.1570	5.035273
11.41383	170.1536	4.976742
11.46383	170.1522	4.921937
11.51717	170.1486	4.864634
11.56716	170.1460	4.806687
11.61884	170.1430	4.747918
11.67050	170.1401	4.685690
11.72050	170.1365	4.625754
11.77383	170.1336	4.557399
11.82383	170.1309	4.495143
11.87717	170.1272	4.428000
11.92717	170.1248	4.361586
11.97884	170.1212	4.293722
12.03050	170.1185	4.225344
12.08050	170.1142	4.162119
12.13383	170.1111	4.089330
12.18383	170.1083	4.021491
12.23550	170.1050	3.952764
12.28717	170.1019	3.882868
12.33883	170.0982	3.815474
12.39050	170.0953	3.747450
12.44050	170.0918	3.685508
12.49384	170.0887	3.616258
12.54384	170.0860	3.556055
12.59550	170.0830	3.491396
12.64717	170.0800	3.435262
12.69883	170.0774	3.376729
12.75050	170.0748	3.316020
12.80050	170.0723	3.266239
12.85383	170.0692	3.209534
12.90383	170.0667	3.160298
12.95550	170.0645	3.110647
13.00717	170.0619	3.059611
13.05717	170.0595	3.012980
13.11050	170.0575	2.965568
13.16050	170.0556	2.922315
13.21383	170.0536	2.878030
13.26383	170.0516	2.836927
13.31550	170.0495	2.797218
13.36716	170.0478	2.758385
13.41716	170.0458	2.723538
13.47050	170.0440	2.686744
13.52050	170.0424	2.654534
13.57384	170.0403	2.622594
13.62384	170.0392	2.589153
13.67550	170.0368	2.556160
13.72717	170.0361	2.526634
13.77717	170.0344	2.500076
13.83050	170.0331	2.469270
13.88050	170.0315	2.443985
13.93383	170.0306	2.415218
13.98383	170.0292	2.390318
14.03550	170.0286	2.364076
14.08717	170.0270	2.339366
14.13717	170.0257	2.318013
14.19050	170.0247	2.296508
14.24050	170.0231	2.275539
14.29384	170.0232	2.255584
14.34383	170.0213	2.236929
14.39550	170.0203	2.217732
14.44717	170.0196	2.198058
14.49717	170.0181	2.182129
14.55050	170.0178	2.162742
14.60050	170.0174	2.145727
14.65217	170.0158	2.130176
14.70383	170.0154	2.113836
14.75550	170.0144	2.098677
14.80717	170.0134	2.085026
14.85716	170.0126	2.071515
14.91050	170.0111	2.056389
14.96050	170.0105	2.041220
15.01217	170.0103	2.023768
15.06383	170.0093	2.010338
15.11550	170.0084	1.998081
15.16716	170.0077	1.983238
15.21716	170.0083	1.968645
15.27050	170.0069	1.955826
15.32050	170.0064	1.942503
15.37217	170.0053	1.930630
15.42383	170.0057	1.916847
15.47383	170.0045	1.905150
15.52717	170.0042	1.890082
15.57717	170.0023	1.878821
15.63050	170.0034	1.866077
15.68050	170.0016	1.854769
15.73216	170.0015	1.843245
15.78383	170.0006	1.831532
15.83383	170.0006	1.821558
15.88716	170.0003	1.809920
15.93717	169.9997	1.798323
15.99050	169.9990	1.787040
16.04050	169.9985	1.775965
16.09216	169.9974	1.765379
16.14383	169.9974	1.754118
16.19383	169.9979	1.742196
16.24716	169.9966	1.730780
16.29716	169.9964	1.720821
16.35050	169.9956	1.709624
16.40050	169.9955	1.699359
16.45216	169.9946	1.689150
16.50383	169.9941	1.679140
16.55383	169.9941	1.669092
16.60716	169.9938	1.658981
16.65716	169.9930	1.649466
16.71050	169.9918	1.639558
16.76050	169.9928	1.630228
16.81216	169.9911	1.621049
16.86383	169.9908	1.612130
16.91383	169.9906	1.603401
16.96716	169.9894	1.594289
17.01716	169.9901	1.585894
17.06883	169.9887	1.576957
17.12050	169.9890	1.568340
17.17216	169.9884	1.559899
17.22383	169.9883	1.551322
17.27383	169.9883	1.543154
17.32716	169.9886	1.534978
17.37716	169.9876	1.527458
17.42883	169.9875	1.520140
17.48050	169.9871	1.512841
17.53050	169.9872	1.506051
17.58383	169.9863	1.498765
17.63383	169.9860	1.492154
17.68716	169.9856	1.485148
17.73716	169.9850	1.478977
17.78883	169.9850	1.472501
17.84050	169.9852	1.466132
17.89050	169.9846	1.460114
17.94383	169.9838	1.453697
17.99383	169.9842	1.447821
18.04716	169.9832	1.441744
18.09716	169.9825	1.436154
18.14883	169.9833	1.430374
18.20050	169.9827	1.424644
18.25050	169.9828	1.419044
18.30383	169.9821	1.413208
18.35383	169.9813	1.407701
18.40716	169.9820	1.401711
18.45716	169.9820	1.395750
18.50883	169.9812	1.389944
18.56050	169.9818	1.384549
18.61050	169.9814	1.379545
18.66383	169.9808	1.374599
18.71383	169.9808	1.369878
18.76716	169.9807	1.364707
18.81716	169.9807	1.359792
18.86883	169.9800	1.354645
18.92050	169.9795	1.349781
18.97050	169.9791	1.345268
19.02383	169.9788	1.340339
19.07383	169.9792	1.335833
19.12550	169.9788	1.331090
19.17716	169.9787	1.326677
19.22883	169.9783	1.322531
19.28050	169.9784	1.318236
19.33050	169.9782	1.313864
19.38383	169.9782	1.309256
19.43383	169.9775	1.304886
19.48550	169.9772	1.300282
19.53717	169.9779	1.295819
19.58883	169.9774	1.291287
19.64050	169.9774	1.286680
19.69050	169.9772	1.282559
19.74383	169.9772	1.278301
19.79383	169.9766	1.274358
19.84550	169.9765	1.270143
19.89716	169.9769	1.265982
19.94716	169.9759	1.262166
20.00050	169.9755	1.258150
20.05050	169.9754	1.254496
20.10383	169.9747	1.250839
20.15383	169.9750	1.247705
20.20550	169.9752	1.244107
20.25716	169.9745	1.240826
20.30716	169.9749	1.237595
20.36050	169.9741	1.234179
20.41050	169.9746	1.231268
20.46383	169.9746	1.228248
20.51383	169.9744	1.225260
20.56550	169.9738	1.222098
20.61716	169.9730	1.218657
20.66716	169.9738	1.215529
20.72050	169.9731	1.212208
20.77050	169.9736	1.208874
20.82383	169.9733	1.205515
20.87383	169.9735	1.202587
20.92550	169.9734	1.199797
20.97716	169.9726	1.197006
21.02717	169.9734	1.194284
21.08050	169.9728	1.191376
21.13050	169.9731	1.188582
21.18383	169.9726	1.185560
21.23383	169.9731	1.183051
21.28550	169.9719	1.180470
21.33716	169.9719	1.177940
21.38716	169.9716	1.175642
21.44050	169.9718	1.173178
21.49050	169.9723	1.170939
21.54216	169.9716	1.168780
21.59383	169.9720	1.166596
21.64550	169.9717	1.164379
21.69716	169.9711	1.162539
21.74716	169.9712	1.160546
21.80050	169.9715	1.158216
21.85050	169.9716	1.156109
21.90216	169.9708	1.154449
21.95383	169.9709	1.152545
22.00550	169.9709	1.150814
22.05716	169.9716	1.149022
22.10716	169.9712	1.147623
22.16050	169.9705	1.146156
22.21050	169.9708	1.144680
22.26216	169.9714	1.143201
22.31383	169.9705	1.141640
22.36383	169.9713	1.139784
22.41716	169.9702	1.138040
22.46716	169.9708	1.136591
22.52050	169.9708	1.134848
22.57050	169.9706	1.133539
22.62216	169.9702	1.132549
22.67383	169.9701	1.131683
22.72383	169.9709	1.130760
22.77717	169.9710	1.129696
22.82716	169.9705	1.128727
22.88050	169.9707	1.127588
22.93050	169.9708	1.126384
22.98216	169.9710	1.125128
23.03383	169.9721	1.123985
23.08383	169.9711	1.123088
23.13716	169.9709	1.122308
23.18716	169.9714	1.121959
23.24050	169.9709	1.121557
23.29050	169.9713	1.121400
23.34216	169.9716	1.121056
23.39383	169.9724	1.120596
23.44383	169.9721	1.120236
23.49716	169.9722	1.119993
23.54716	169.9716	1.120244
23.60050	169.9715	1.121038
23.65050	169.9718	1.121546
23.70216	169.9714	1.122740
23.75383	169.9720	1.124359
23.80383	169.9711	1.125830
23.85716	169.9718	1.127252
23.90716	169.9710	1.128198
23.95883	169.9712	1.129236
24.01050	169.9710	1.129946
24.06216	169.9710	1.130456
24.11383	169.9711	1.131126
24.16383	169.9710	1.132034
24.21716	169.9705	1.132910
24.26716	169.9709	1.133793
24.31883	169.9705	1.134486
24.37050	169.9711	1.135078
24.42050	169.9701	1.135508
24.47383	169.9704	1.135956
24.52383	169.9703	1.136223
24.57716	169.9704	1.136058
24.62716	169.9705	1.135940
24.67883	169.9707	1.135733
24.73050	169.9702	1.135281
24.78050	169.9710	1.134889
24.83383	169.9702	1.134530
24.88383	169.9702	1.134502
24.93716	169.9711	1.134223
24.98716	169.9703	1.134042
25.03883	169.9708	1.133720
25.09050	169.9717	1.133056
25.14050	169.9719	1.132016
25.19383	169.9718	1.130974
25.24383	169.9724	1.129856
25.29716	169.9722	1.128818
25.34716	169.9722	1.128089
25.39883	169.9731	1.127609
25.45050	169.9727	1.127544
25.50050	169.9726	1.127450
25.55383	169.9726	1.127232
25.60383	169.9736	1.127290
25.65716	169.9722	1.127265
25.70716	169.9729	1.127028
25.75883	169.9725	1.127015
25.81050	169.9726	1.126798
25.86050	169.9724	1.126819
25.91383	169.9726	1.126978
25.96383	169.9725	1.127044
26.01550	169.9724	1.126964
26.06716	169.9719	1.126636
26.11883	169.9716	1.126384
26.17050	169.9714	1.125982
26.22050	169.9713	1.125518
26.27383	169.9711	1.125037
26.32383	169.9711	1.124382
26.37550	169.9709	1.123460
26.42717	169.9704	1.122219
26.47883	169.9697	1.121225
26.53050	169.9698	1.119767
26.58050	169.9699	1.117984
26.63383	169.9697	1.115709
26.68383	169.9695	1.113422
26.73550	169.9692	1.110550
26.78717	169.9694	1.107407
26.83716	169.9688	1.104034
26.89050	169.9686	1.100351
26.94050	169.9696	1.096674
26.99383	169.9686	1.092554
27.04383	169.9682	1.088745
27.09550	169.9686	1.084723
27.14716	169.9684	1.080412
27.19717	169.9685	1.076201
27.25050	169.9678	1.071373
27.30050	169.9675	1.066535
27.35383	169.9666	1.061631
27.40383	169.9669	1.056940
27.45550	169.9662	1.051784
27.50716	169.9659	1.046614
27.55716	169.9658	1.041515
27.61050	169.9650	1.036031
27.66050	169.9642	1.030678
27.71383	169.9641	1.024487
27.76383	169.9634	1.018202
27.81550	169.9629	1.011679
27.86716	169.9633	1.004642
27.91716	169.9624	0.9975575
27.97050	169.9622	0.9890738
28.02050	169.9609	0.9816056
28.07383	169.9615	0.9736418
28.12383	169.9614	0.9652480
28.17550	169.9613	0.9562647
28.22717	169.9614	0.9469262
28.27717	169.9608	0.9377778
28.33050	169.9606	0.9279901
28.38050	169.9602	0.9182426
28.43216	169.9604	0.9071046
28.48383	169.9601	0.8964689
28.53550	169.9587	0.8868941
28.58716	169.9589	0.8773361
28.63716	169.9579	0.8679549
28.69050	169.9580	0.8581125
28.74050	169.9575	0.8481850
28.79216	169.9566	0.8380245
28.84383	169.9565	0.8276595
28.89550	169.9557	0.8171900
28.94717	169.9549	0.8056626
28.99716	169.9540	0.7955028
29.05050	169.9542	0.7849324
29.10050	169.9529	0.7737150
29.15216	169.9525	0.7628413
29.20383	169.9510	0.7522384
29.25383	169.9509	0.7408944
29.30716	169.9502	0.7293632
29.35716	169.9496	0.7185688
29.41050	169.9486	0.7060880
29.46050	169.9496	0.6935263
29.51216	169.9478	0.6818520
29.56383	169.9480	0.6708653
29.61383	169.9470	0.6595005
29.66716	169.9464	0.6465470
29.71716	169.9454	0.6363325
29.77050	169.9444	0.6247951
29.82050	169.9437	0.6141362
29.87216	169.9439	0.6033226
29.92383	169.9431	0.5922129
29.97383	169.9413	0.5815669
30.02717	169.9415	0.5698352
30.07717	169.9407	0.5584062
30.13050	169.9403	0.5473422
30.18050	169.9398	0.5358989
30.23216	169.9391	0.5249695
30.28383	169.9386	0.5140542
30.33383	169.9381	0.5039692
30.38716	169.9378	0.4930110
30.43717	169.9361	0.4825250
30.49050	169.9362	0.4720874
30.54050	169.9363	0.4610980
30.59216	169.9351	0.4504692
30.64383	169.9346	0.4401778
30.69383	169.9347	0.4285462
30.74716	169.9342	0.4169670
30.79716	169.9342	0.4058380
30.84883	169.9351	0.3955985
30.90050	169.9342	0.3850084
30.95217	169.9340	0.3751752
31.00383	169.9338	0.3653864
31.05383	169.9337	0.3559329
31.10716	169.9323	0.3460050
31.15716	169.9319	0.3368462
31.20883	169.9320	0.3271713
31.26050	169.9315	0.3185787
31.31050	169.9309	0.3105056
31.36383	169.9304	0.3018142
31.41383	169.9298	0.2937394
31.46716	169.9298	0.2854431
31.51716	169.9285	0.2776848
31.56883	169.9281	0.2693088
31.62050	169.9276	0.2610617
31.67050	169.9270	0.2530385
31.72383	169.9262	0.2443280
31.77383	169.9262	0.2360184
31.82717	169.9259	0.2263829
31.87717	169.9256	0.2171852
31.92883	169.9252	0.2081172
31.98050	169.9246	0.1987779
32.03050	169.9235	0.1896360
32.08383	169.9248	0.1796550
32.13383	169.9238	0.1698652
32.18716	169.9230	0.1596517
32.23717	169.9225	0.1500837
32.28883	169.9222	0.1401379
32.34050	169.9216	0.1307269
32.39050	169.9209	0.1216094
32.44383	169.9204	0.1120369
32.49383	169.9204	0.1025803
32.54716	169.9199	0.09277295
32.59716	169.9188	0.08330702
32.64883	169.9189	0.07369815
32.70050	169.9187	0.06339834
32.75050	169.9184	0.05345508
32.80383	169.9174	0.04311854
32.85383	169.9162	0.03333106
32.90550	169.9158	0.02337949
32.95716	169.9154	0.01318187
33.00883	169.9143	.003446836
33.06050	169.9138	-6.0493E-3
33.11050	169.9138	-.01543891
33.16383	169.9127	-.02541494
33.21383	169.9116	-.03608774
33.26550	169.9112	-.04774260
33.31716	169.9115	-.05939992
33.36883	169.9110	-.07344941
33.42050	169.9110	-.08518744
33.47050	169.9116	-.09713501
33.52383	169.9100	-0.1080655
33.57383	169.9105	-0.1193409
33.62550	169.9101	-0.1300080
33.67717	169.9095	-0.1400256
33.72717	169.9084	-0.1495420
33.78050	169.9086	-0.1597411
33.83050	169.9072	-0.1693724
33.88383	169.9072	-0.1796527
33.93384	169.9063	-0.1900072
33.98550	169.9058	-0.2000680
34.03717	169.9049	-0.2104029
34.08716	169.9037	-0.2200371
34.14050	169.9037	-0.2301198
34.19050	169.9034	-0.2397740
34.24383	169.9019	-0.2502609
34.29383	169.9016	-0.2596135
34.34550	169.9010	-0.2700327
34.39717	169.9006	-0.2801840
34.44717	169.9002	-0.2897556
34.50050	169.8989	-0.3009418
34.55050	169.8998	-0.3126197
34.60383	169.8986	-0.3249980
34.65383	169.8990	-0.3366008
34.70550	169.8982	-0.3487644
34.75716	169.8972	-0.3602188
34.80716	169.8976	-0.3713329
34.86050	169.8969	-0.3831313
34.91050	169.8970	-0.3943732
34.96383	169.8967	-0.4065525
35.01383	169.8950	-0.4179459
35.06550	169.8952	-0.4290152
35.11716	169.8944	-0.4398733
35.16716	169.8932	-0.4505960
35.22050	169.8930	-0.4618084
35.27050	169.8926	-0.4719598
35.32217	169.8918	-0.4830032
35.37383	169.8918	-0.4944254
35.42550	169.8910	-0.5066528
35.47717	169.8906	-0.5196380
35.52716	169.8899	-0.5309644
35.58050	169.8885	-0.5427561
35.63050	169.8884	-0.5554153
35.68216	169.8878	-0.5683350
35.73383	169.8865	-0.5802084
35.78550	169.8858	-0.5918720
35.83716	169.8850	-0.6040313
35.88716	169.8844	-0.6155674
35.94050	169.8840	-0.6287858
35.99050	169.8826	-0.6420066
36.04217	169.8826	-0.6556358
36.09384	169.8828	-0.6705152
36.14383	169.8821	-0.6844262
36.19717	169.8811	-0.6995855
36.24716	169.8802	-0.7151129
36.30050	169.8803	-0.7304020
36.35050	169.8792	-0.7426230
36.40216	169.8785	-0.7559010
36.45383	169.8781	-0.7696998
36.50383	169.8777	-0.7818163
36.55716	169.8770	-0.7944263
36.60716	169.8763	-0.8056134
36.66050	169.8748	-0.8175538
36.71050	169.8742	-0.8316181
36.76216	169.8737	-0.8430906
36.81383	169.8730	-0.8558546
36.86383	169.8721	-0.8676915
36.91716	169.8717	-0.8797736
36.96716	169.8710	-0.8921912
37.02050	169.8705	-0.9063828
37.07050	169.8701	-0.9196140
37.12216	169.8689	-0.9342630
37.17383	169.8686	-0.9466063
37.22383	169.8672	-0.9581493
37.27716	169.8674	-0.9706660
37.32717	169.8668	-0.9830006
37.38050	169.8667	-0.9958788
37.43050	169.8656	-1.007285
37.48216	169.8657	-1.019189
37.53383	169.8646	-1.031088
37.58383	169.8645	-1.042682
37.63716	169.8635	-1.055396
37.68716	169.8641	-1.066258
37.73883	169.8638	-1.077618
37.79050	169.8626	-1.088756
37.84216	169.8614	-1.099228
37.89383	169.8612	-1.109277
37.94383	169.8614	-1.119597
37.99716	169.8600	-1.129934
38.04716	169.8597	-1.140748
38.09883	169.8600	-1.150889
38.15050	169.8594	-1.161304
38.20050	169.8590	-1.171704
38.25383	169.8584	-1.182176
38.30383	169.8579	-1.191855
38.35716	169.8576	-1.202743
38.40716	169.8570	-1.211766
38.45883	169.8565	-1.220721
38.51050	169.8563	-1.229357
38.56050	169.8551	-1.237285
38.61383	169.8550	-1.245732
38.66383	169.8545	-1.253923
38.71716	169.8541	-1.262687
38.76716	169.8544	-1.271285
38.81883	169.8532	-1.279949
38.87050	169.8526	-1.288490
38.92050	169.8524	-1.296603
38.97383	169.8522	-1.305128
39.02383	169.8521	-1.313148
39.07717	169.8512	-1.321440
39.12717	169.8511	-1.329278
39.17883	169.8506	-1.337264
39.23050	169.8499	-1.344730
39.28050	169.8508	-1.352238
39.33383	169.8502	-1.359937
39.38383	169.8495	-1.366876
39.43716	169.8487	-1.374451
39.48717	169.8485	-1.381272
39.53883	169.8483	-1.388159
39.59050	169.8480	-1.395093
39.64050	169.8470	-1.401636
39.69383	169.8473	-1.408675
39.74383	169.8476	-1.415056
39.79550	169.8466	-1.421652
39.84716	169.8463	-1.428323
39.89883	169.8462	-1.434924
39.95050	169.8462	-1.441086
40.00050	169.8457	-1.447150
40.05383	169.8456	-1.453202
40.10383	169.8449	-1.458454
40.15550	169.8444	-1.464002
40.20716	169.8439	-1.469330
40.25883	169.8432	-1.474545
40.31050	169.8428	-1.479691
40.36050	169.8432	-1.484701
40.41383	169.8425	-1.490089
40.46383	169.8422	-1.495091
40.51550	169.8422	-1.500730
40.56716	169.8424	-1.506674
40.61716	169.8418	-1.512456
40.67050	169.8428	-1.518954
40.72050	169.8420	-1.524955
40.77383	169.8421	-1.531300
40.82383	169.8419	-1.537089
40.87550	169.8422	-1.542826
40.92717	169.8414	-1.548216
40.97717	169.8414	-1.552965
41.03050	169.8402	-1.557874
41.08050	169.8412	-1.562646
41.13383	169.8402	-1.567358
41.18383	169.8401	-1.571236
41.23550	169.8397	-1.575040
41.28717	169.8399	-1.579159
41.33716	169.8400	-1.583189
41.39050	169.8398	-1.587522
41.44050	169.8394	-1.591543
41.49383	169.8391	-1.595745
41.54383	169.8386	-1.599851
41.59550	169.8385	-1.604013
41.64717	169.8376	-1.608073
41.69717	169.8375	-1.611774
41.75050	169.8368	-1.615662
41.80050	169.8372	-1.619292
41.85383	169.8373	-1.623264
41.90383	169.8372	-1.626696
41.95550	169.8365	-1.630238
42.00717	169.8368	-1.633714
42.05717	169.8353	-1.637009
42.11050	169.8354	-1.640635
42.16050	169.8353	-1.644086
42.21216	169.8354	-1.647884
42.26383	169.8356	-1.651679
42.31550	169.8356	-1.655455
42.36716	169.8356	-1.659460
42.41716	169.8356	-1.663542
42.47050	169.8352	-1.667726
42.52050	169.8356	-1.671797
42.57217	169.8353	-1.675604
42.62383	169.8346	-1.679298
42.67550	169.8355	-1.682888
42.72717	169.8349	-1.686639
42.77716	169.8348	-1.689953
42.83050	169.8353	-1.693228
42.88050	169.8344	-1.696212
42.93217	169.8352	-1.699417
42.98383	169.8339	-1.702370
43.03383	169.8341	-1.705191
43.08716	169.8339	-1.708061
43.13716	169.8335	-1.710401
43.19050	169.8335	-1.712939
43.24050	169.8328	-1.714986
43.29217	169.8325	-1.717179
43.34384	169.8329	-1.719330
43.39383	169.8321	-1.721375
43.44717	169.8322	-1.723780
43.49716	169.8322	-1.726587
43.55050	169.8319	-1.729754
43.60050	169.8306	-1.732464
43.65216	169.8327	-1.735756
43.70383	169.8320	-1.739291
43.75050	169.8320	-1.742214
43.80383	169.8917	-1.753664
43.85383	170.2765	-2.877444
43.90717	170.8800	-5.870139
43.95717	171.5399	-9.227680
44.00883	172.2907	-12.66486
44.06050	173.0953	-15.77528
44.11050	173.9149	-18.37758
44.16383	174.8224	-20.72031
44.21383	175.6993	-22.54721
44.26717	176.6567	-24.16882
44.31717	177.5726	-25.42791
44.36883	178.5320	-26.51968
44.42050	179.5030	-27.44639
44.47050	180.4514	-28.21331
44.52383	181.4702	-28.92684
44.57383	182.4317	-29.52552
44.62717	183.4616	-30.09458
44.67717	184.4316	-30.58882
44.72883	185.4368	-31.07218
44.78050	186.4447	-31.52008
44.83050	187.4205	-31.93688
44.88383	188.4638	-32.37772
44.93383	189.4425	-32.78522
44.98717	190.4870	-33.24463
45.03717	191.4658	-33.66015
45.08883	192.4772	-34.13289
45.14050	193.4881	-34.62734
45.19050	194.4658	-35.13808
45.24383	195.5061	-35.72562
45.29383	196.4783	-36.32794
45.34550	197.4815	-37.01575
45.39717	198.4813	-37.77886
45.44883	199.4772	-38.63160
45.50050	200.4689	-39.59787
45.55050	201.4234	-40.64416
45.60383	202.4358	-41.92690
45.65383	203.3768	-43.27478
45.70550	204.3416	-44.84809
45.75717	205.2982	-46.61087
45.80883	206.2455	-48.58360
45.86050	207.1848	-50.71310
45.91050	208.0867	-52.93907
45.96383	209.0383	-55.57660
46.01383	209.9196	-58.32230
46.06550	210.8155	-61.41454
46.11716	211.7039	-64.66164
46.16716	212.5615	-67.77864
46.22050	213.4827	-70.94286
46.27050	214.3561	-73.61329
46.32383	215.3132	-75.85864
46.37383	216.2465	-77.08404
46.42550	217.2588	-77.22307
46.47717	218.3242	-76.22722
46.52716	219.4002	-74.34561
46.58050	220.5874	-71.51514
46.63050	221.7340	-68.15900
46.68383	222.9940	-63.70963
46.73383	224.2125	-58.84924
46.78550	225.4733	-54.05832
46.83716	226.7058	-50.05134
46.88716	227.8638	-46.90841
46.94050	229.0648	-44.24864
46.99050	230.1655	-42.29409
47.04383	231.3172	-40.64996
47.09384	232.3802	-39.44739
47.14550	233.4652	-38.47120
47.19717	234.5380	-37.71096
47.24716	235.5697	-37.14356
47.30050	236.6618	-36.68262
47.35050	237.6810	-36.34235
47.40383	238.7632	-36.06860
47.45383	239.7754	-35.87810
47.50550	240.8186	-35.73752
47.55717	241.8594	-35.64094
47.60717	242.8650	-35.58084
47.66050	243.9378	-35.54487
47.71050	244.9408	-35.52323
47.76216	245.9773	-35.51110
47.81383	247.0130	-35.50437
47.86550	248.0490	-35.50242
47.91716	249.0850	-35.50252
47.96717	250.0875	-35.50506
48.02050	251.1553	-35.51698
48.07050	252.1561	-35.54079
48.12216	253.1904	-35.56980
48.17383	254.2242	-35.60175
48.22550	255.2575	-35.63897
48.27716	256.2916	-35.68816
48.32717	257.2915	-35.74408
48.38050	258.3580	-35.79678
48.43050	259.3566	-35.87398
48.48217	260.3896	-35.94234
48.53383	261.4219	-35.99694
48.58383	262.4205	-36.06022
48.63716	263.4879	-36.13302
48.68716	264.4878	-36.18600
48.74050	265.5547	-36.24436
48.79050	266.5537	-36.30670
48.84217	267.5863	-36.36686
48.89383	268.6184	-36.44038
48.94383	269.6178	-36.51728
48.99716	270.6832	-36.59697
49.04716	271.6825	-36.69128
49.10050	272.7454	-36.86935
49.15050	273.7404	-37.01046
49.20216	274.7700	-37.14274
49.25050	275.7332	-37.26192
49.30383	276.6737	-37.31571
49.35383	276.8584	-34.73376
49.40717	276.6780	-27.99264
49.45717	276.3089	-20.61806
49.50883	275.7957	-13.23893
49.56050	275.1810	-6.688205
49.61050	274.5107	-1.285878
49.66383	273.7319	3.503203
49.71383	272.9527	7.194389
49.76717	272.0788	10.41209
49.81717	271.2279	12.88606
49.86883	270.3235	14.97356
49.92050	269.3970	16.68354
49.97050	268.4830	18.05111
50.02383	267.4936	19.24496
50.07383	266.5556	20.16337
50.12717	265.5420	20.93255
50.17717	264.5833	21.54744
50.22883	263.5884	22.10268
50.28050	262.5875	22.57450
50.33050	261.6072	22.69896
50.38383	260.5629	23.01877
50.43383	259.5835	23.28353
50.48717	258.5364	23.53015
50.53717	257.5527	23.74548
50.58883	256.5361	23.93872
50.64050	255.5164	24.11217
50.69050	254.5296	24.26277
50.74383	253.4756	24.41310
50.79383	252.4873	24.52891
50.84550	251.4650	24.64340
50.89717	250.4408	24.74541
50.94883	249.4175	24.83872
51.00050	248.3924	24.92665
51.05050	247.3992	25.00662
51.10383	246.3408	25.07082
51.15383	245.3480	25.12430
51.20550	244.3210	25.17869
51.25717	243.2954	25.21815
51.30883	242.2681	25.26418
51.36050	241.2424	25.29634
51.41050	240.2480	25.33808
51.46383	239.1870	25.37592
51.51383	238.1926	25.41024
51.56550	237.1646	25.43869
51.61716	236.1362	25.47640
51.66716	235.1408	25.49956
51.72050	234.0801	25.51906
51.77050	233.0850	25.53914
51.82383	232.0239	25.55387
51.87383	231.0282	25.56869
51.92550	229.9995	25.58764
51.97717	228.9708	25.60414
52.02717	227.9762	25.62368
52.08050	226.9145	25.66016
52.13050	225.9184	25.67990
52.18383	224.8580	25.71416
52.23383	223.8623	25.74276
52.28550	222.8324	25.76024
52.33716	221.8026	25.77522
52.38716	220.8077	25.79020
52.44050	219.7454	25.80591
52.49050	218.7500	25.82905
52.54382	217.6880	25.84744
52.59384	216.6918	25.86202
52.64550	215.6638	25.87788
52.69717	214.6332	25.89381
52.74717	213.6383	25.90831
52.80050	212.5755	25.92013
52.85050	211.5791	25.93170
52.90383	210.5158	25.94177
52.95383	209.5205	25.95200
53.00550	208.4908	25.96134
53.05717	207.4610	25.97058
53.10717	206.4649	25.97934
53.16050	205.4017	25.98792
53.21050	204.4057	25.99532
53.26216	203.3762	26.00267
53.31382	202.3466	26.00994
53.36550	201.3166	26.01608
53.41716	200.2872	26.02197
53.46717	199.2910	26.02740
53.52050	198.2269	26.03313
53.57050	197.2318	26.03854
53.62217	196.2019	26.04362
53.67383	195.1727	26.04946
53.72550	194.1429	26.05852
53.77717	193.1132	26.06740
53.82717	192.1156	26.07486
53.88050	191.0522	26.08262
53.93050	190.0550	26.08934
53.98217	189.0246	26.09487
54.03383	187.9946	26.09983
54.08383	186.9987	26.10362
54.13716	185.9354	26.10732
54.18716	184.9384	26.11092
54.24050	183.8751	26.11364
54.29050	182.8780	26.11500
54.34217	181.8473	26.11611
54.39384	180.8176	26.11654
54.44384	179.8206	26.11636
54.49717	178.7579	26.11754
54.54717	177.7611	26.12009
54.60050	176.6981	26.12518
54.65050	175.7022	26.13373
54.70216	174.6723	26.15161
54.75383	173.6422	26.17583
54.80383	172.6462	26.20271
54.85717	171.5836	26.22215
54.90717	170.5880	26.25419
54.96050	169.5265	26.32112
55.01050	168.5328	26.42050
55.06216	167.5104	26.58812
55.11382	166.4930	26.87451
55.16382	165.5168	27.37104
55.21717	164.4915	28.29888
55.26716	163.5554	29.74756
55.32050	162.5943	32.15167
55.37050	161.7379	35.35995
55.42217	160.9020	39.61137
55.47382	160.1058	44.55142
55.52383	159.3532	49.53079
55.57717	158.5444	54.51194
55.62717	157.7561	58.41064
55.67883	156.8944	61.36520
55.73050	155.9728	63.06882
55.78217	154.9886	63.48894
55.83383	153.9446	62.73950
55.88383	152.8824	61.02954
55.93716	151.7048	58.41619
55.98717	150.5701	55.44398
56.03882	149.3816	52.18147
56.09050	148.1907	48.95519
56.14050	147.0449	46.03814
56.19384	145.8378	43.25756
56.24382	144.7222	40.98708
56.29717	143.5568	39.04019
56.34716	142.4699	37.35034
56.39883	141.3613	35.86297
56.45050	140.2640	34.59357
56.50050	139.2108	33.55200
56.55383	138.0974	32.60375
56.60383	137.0600	31.84265
56.65717	135.9601	31.15127
56.70717	134.9327	30.58696
56.75883	133.8766	30.08906
56.81050	132.8223	29.66260
56.86050	131.8070	29.29049
56.91382	130.7247	28.94230
56.96382	129.7126	28.66144
57.01716	128.6344	28.39290
57.06716	127.6210	28.04354
57.11882	126.5791	27.84118
57.17050	125.5386	27.64525
57.22050	124.5333	27.47503
57.27383	123.4574	27.19758
57.32383	122.4510	27.05314
57.37717	121.3785	26.89566
57.42717	120.3745	26.76538
57.47883	119.3360	26.58552
57.53050	118.2979	26.45790
57.58050	117.2912	26.21198
57.63383	116.2188	26.12056
57.68383	115.2164	26.02929
57.73550	114.1807	25.93882
57.78716	113.1458	25.85788
57.83882	112.1102	25.77338
57.89050	111.0751	25.69240
57.94050	110.0732	25.59692
57.99382	109.0020	25.44536
58.04382	107.9993	25.36470
58.09550	106.9653	25.29386
58.14717	105.9362	25.29046
58.19883	104.9000	25.18274
58.25050	103.8648	25.07213
58.30050	102.8552	24.82412
58.35383	101.7857	24.72152
58.40383	100.7835	24.65608
58.45550	99.74866	24.58211
58.50717	98.71547	24.52314
58.55717	97.71585	24.46302
58.61050	96.64832	24.40308
58.66050	95.64747	24.32971
58.71382	94.57984	24.25068
58.76382	93.57860	24.18748
58.81550	92.54414	24.11296
58.86716	91.50953	24.03363
58.91716	90.50801	23.96324
58.97050	89.44106	23.87342
59.02050	88.44074	23.79984
59.07383	87.37303	23.72208
59.12383	86.37293	23.65181
59.17550	85.33972	23.57634
59.22717	84.30572	23.50350
59.27717	83.30469	23.43724
59.33050	82.23749	23.36949
59.38050	81.23657	23.29557
59.43383	80.16881	23.22187
59.48383	79.16910	23.15806
59.53550	78.13325	23.08996
59.58716	77.09982	23.01967
59.63716	76.09889	22.95906
59.69050	75.03159	22.89201
59.74050	74.03022	22.83268
59.79382	72.96321	22.75720
59.84384	71.96116	22.69270
59.89550	70.92728	22.62482
59.94717	69.89328	22.55458
59.99717	68.89228	22.49088
60.05050	67.82499	22.41619
60.10050	66.82344	22.34738
60.15217	65.78961	22.27652
60.20383	64.75426	22.21196
60.25550	63.72072	22.14045
60.30717	62.68645	22.06186
60.35717	61.68530	21.98764
60.41050	60.61722	21.90684
60.46050	59.61655	21.82606
60.51216	58.58251	21.75278
60.56382	57.54805	21.68108
60.61550	56.51332	21.60122
60.66716	55.47844	21.52876
60.71717	54.47622	21.45667
60.77050	53.40795	21.37392
60.82050	52.40668	21.30342
60.87217	51.37209	21.22581
60.92383	50.33747	21.14549
60.97382	49.33632	21.07192
61.02717	48.26768	20.99949
61.07717	47.26656	20.92568
61.13050	46.19748	20.84783
61.18050	45.19684	20.77900
61.23217	44.16210	20.70735
61.28383	43.12626	20.63306
61.33383	42.12490	20.55931
61.38716	41.05745	20.47589
61.43716	40.05525	20.40280
61.49050	38.98563	20.31880
61.54050	37.98304	20.23387
61.59217	36.94791	20.13441
61.64384	35.91120	20.03893
61.69384	34.90918	19.94986
61.74717	33.83912	19.84497
61.79717	32.83680	19.73256
61.85050	31.76394	19.58834
61.90050	30.76117	19.49840
61.95216	29.72492	19.41435
62.00383	28.68922	19.31768
62.05383	27.68625	19.22384
62.10717	26.61475	19.11684
62.15717	25.61177	19.01733
62.21050	24.54152	18.90886
62.26050	23.53838	18.80152
62.31050	22.73918	18.94387
62.36382	22.65169	17.59754
62.41382	22.84909	14.13394
62.46550	23.25054	9.885156
62.51716	23.78243	5.584330
62.56716	24.39301	1.794001
62.62050	25.12885	-1.717047
62.67050	25.87564	-4.492504
62.72382	26.72466	-6.951726
62.77383	27.55788	-8.842719
62.82550	28.45025	-10.45731
62.87717	29.36675	-11.78247
62.92717	30.27348	-12.84105
62.98050	31.25527	-13.77852
63.03050	32.18968	-14.50947
63.08217	33.16510	-15.15252
63.13383	34.14786	-15.69733
63.18550	35.13972	-16.16168
63.23717	36.13678	-16.56290
63.28716	37.10634	-16.90659
63.34050	38.14388	-17.23006
63.39050	39.12007	-17.50369
63.44216	40.13193	-17.75087
63.49382	41.14650	-17.97309
63.54550	42.16248	-18.17853
63.59716	43.18141	-18.36423
63.64717	44.16806	-18.53068
63.70050	45.22184	-18.69763
63.75050	46.21162	-18.84217
63.80217	47.23380	-18.98544
63.85383	48.25916	-19.12864
63.90383	49.25126	-19.25006
63.95717	50.31010	-19.38407
64.00718	51.30332	-19.50371
64.06050	52.36276	-19.62728
64.11050	53.35740	-19.73901
64.16217	54.38530	-19.85438
64.21384	55.41250	-19.96053
64.26384	56.40812	-20.06985
64.31717	57.46890	-20.18485
64.36718	58.46401	-20.29109
64.42050	59.52540	-20.40670
64.47050	60.52187	-20.51149
64.52217	61.55059	-20.62356
64.57384	62.58000	-20.73607
64.62383	63.57630	-20.83791
64.67718	64.64045	-20.94461
64.72718	65.63644	-21.04209
64.78050	66.69934	-21.14609
64.83050	67.69507	-21.25133
64.88218	68.72570	-21.35740
64.93384	69.75540	-21.45899
64.98383	70.75322	-21.55910
65.03717	71.81731	-21.65560
65.08716	72.81318	-21.75017
65.14050	73.87776	-21.85823
65.19050	74.87407	-21.95163
65.24218	75.90290	-22.04830
65.29384	76.93398	-22.15620
65.34384	77.93024	-22.26160
65.39717	78.99336	-22.37175
65.44717	79.98950	-22.47252
65.49884	81.02014	-22.58352
65.55050	82.04976	-22.69130
65.60218	83.07978	-22.79731
65.65384	84.10991	-22.90852
65.70384	85.10694	-23.01522
65.75718	86.16946	-23.13119
65.80718	87.16664	-23.23986
65.85884	88.19682	-23.34846
65.91050	89.22680	-23.45960
65.96050	90.22361	-23.57445
66.01384	91.28801	-23.68880
66.06384	92.28539	-23.79750
66.11718	93.34775	-23.91048
66.16718	94.34569	-24.01386
66.21884	95.37548	-24.12668
66.27050	96.40582	-24.23967
66.32050	97.40228	-24.34059
66.37384	98.46532	-24.45558
66.42384	99.46137	-24.56689
66.47718	100.5245	-24.68247
66.52718	101.5200	-24.80719
66.57884	102.5503	-24.91992
66.63050	103.5805	-25.03445
66.68050	104.5770	-25.14789
66.73384	105.6401	-25.26863
66.78384	106.6360	-25.38170
66.83716	107.6987	-25.50816
66.88718	108.6968	-25.62263
66.93884	109.7264	-25.73687
66.99050	110.7560	-25.86199
67.04050	111.7526	-25.97581
67.09384	112.8153	-26.10095
67.14384	113.8112	-26.21880
67.19718	114.8740	-26.34295
67.24718	115.8704	-26.46323
67.29884	116.8998	-26.58353
67.35050	117.9286	-26.69970
67.40050	118.9256	-26.82366
67.45384	119.9874	-26.95858
67.50384	120.9833	-27.08357
67.55550	122.0134	-27.21678
67.60718	123.0422	-27.35322
67.65884	124.0707	-27.49060
67.71050	125.1002	-27.63425
67.76050	126.0964	-27.76704
67.81384	127.1594	-27.90283
67.86384	128.1552	-28.03174
67.91550	129.1849	-28.16202
67.96718	130.2148	-28.27710
68.01882	131.2450	-28.39778
68.07050	132.2753	-28.52244
68.12050	133.2707	-28.63986
68.17384	134.3334	-28.78091
68.22384	135.3288	-28.91450
68.27550	136.3577	-29.06368
68.32718	137.3866	-29.21016
68.37718	138.3826	-29.35303
68.43050	139.4450	-29.50906
68.48050	140.4406	-29.65482
68.53384	141.5019	-29.81225
68.58384	142.4968	-29.95955
68.63550	143.5259	-30.11650
68.68718	144.5540	-30.27062
68.73718	145.5488	-30.42486
68.79050	146.6111	-30.58629
68.84050	147.6063	-30.74308
68.89384	148.6677	-30.90634
68.94384	149.6625	-31.06310
68.99550	150.6909	-31.21785
69.04718	151.7180	-31.38378
69.09718	152.7113	-31.54220
69.15050	153.7727	-31.72621
69.20050	154.7681	-31.89945
69.25384	155.8281	-32.08198
69.30384	156.8230	-32.25747
69.35550	157.8505	-32.43218
69.40718	158.8787	-32.61184
69.45718	159.8717	-32.77974
69.51050	160.9343	-32.94405
69.56050	161.9280	-33.10276
69.61384	162.9900	-33.25678
69.66382	163.9862	-33.39297
69.71550	165.0165	-33.52331
69.76716	166.0465	-33.62369
69.81718	167.0449	-33.71716
69.87050	168.1099	-33.81183
69.92050	169.1094	-33.88191
69.97218	170.1411	-33.95728
70.02384	171.1731	-34.03886
70.07550	172.2052	-34.11815
70.12718	173.2373	-34.21723
70.17718	174.2354	-34.31163
70.23050	175.2996	-34.42586
70.28050	176.2972	-34.54622
70.33218	177.3257	-34.68580
70.38384	178.3528	-34.84372
70.43550	179.3806	-35.02734
70.48718	180.4067	-35.22971
70.53718	181.3986	-35.45388
70.59050	182.4552	-35.72242
70.64050	183.4445	-35.99981
70.69218	184.4662	-36.32480
70.74384	185.4866	-36.67920
70.79384	186.4712	-37.05010
70.84718	187.5199	-37.49460
70.89718	188.5015	-37.96360
70.95050	189.5461	-38.51021
71.00050	190.5226	-39.10173
71.05218	191.5280	-39.76199
71.10384	192.5305	-40.49264
71.15384	193.4984	-41.24731
71.20718	194.5289	-42.08644
71.25718	195.4933	-42.89914
71.31050	196.5210	-43.79247
71.36050	197.4844	-44.66284
71.41218	198.4774	-45.59088
71.46384	199.4694	-46.56778
71.51384	200.4263	-47.58380
71.56718	201.4430	-48.74082
71.61718	202.3928	-49.91761
71.67050	203.4017	-51.23834
71.72050	204.3455	-52.52609
71.77218	205.3201	-53.85540
71.82384	206.2974	-55.13079
71.87384	207.2490	-56.17422
71.92718	208.2784	-56.89200
71.97718	209.2698	-56.96145
72.03050	210.3641	-56.13301
72.08050	211.4307	-54.47830
72.13218	212.5660	-52.11524
72.18384	213.7242	-49.41064
72.23384	214.8524	-46.70116
72.28718	216.0502	-44.03890
72.33716	217.1566	-41.93756
72.38884	218.2808	-40.18919
72.44050	219.3866	-38.78812
72.49218	220.4782	-37.68340
72.54384	221.5576	-36.82432
72.59384	222.5934	-36.17060
72.64718	223.6902	-35.63330
72.69718	224.7115	-35.24135
72.74884	225.7641	-34.92141
72.80050	226.8125	-34.68865
72.85050	227.8226	-34.51760
72.90384	228.8996	-34.38511
72.95384	229.9063	-34.31145
73.00718	230.9784	-34.25803
73.05718	231.9825	-34.23331
73.10884	233.0188	-34.22894
73.16050	234.0546	-34.22882
73.21050	235.0567	-34.23558
73.26384	236.1244	-34.27347
73.31384	237.1256	-34.30867
73.36718	238.1938	-34.36074
73.41718	239.1936	-34.40846
73.46884	240.2275	-34.46138
73.52050	241.2605	-34.52145
73.57050	242.2613	-34.59106
73.62384	243.3273	-34.65731
73.67384	244.3270	-34.72744
73.72718	245.3938	-34.79109
73.77718	246.3939	-34.85052
73.82884	247.4266	-34.90770
73.88050	248.4602	-34.96494
73.93050	249.4594	-35.01430
73.98384	250.5268	-35.07546
74.03384	251.5267	-35.13709
74.08716	252.5936	-35.20255
74.13718	253.5929	-35.25766
74.18884	254.6256	-35.31180
74.24050	255.6574	-35.36865
74.29050	256.6578	-35.44150
74.34384	257.7224	-35.51538
74.39384	258.7219	-35.58204
74.44550	259.7546	-35.65916
74.49718	260.7876	-35.73218
74.54884	261.8170	-35.80642
74.60050	262.8506	-35.88968
74.65050	263.8491	-35.96636
74.70384	264.9143	-36.05297
74.75384	265.9130	-36.13938
74.80550	266.9462	-36.22052
74.85718	267.9788	-36.29713
74.90884	269.0108	-36.37459
74.96050	270.0438	-36.45307
75.01050	271.0418	-36.52770
75.06384	272.1064	-36.62473
-2.000000	5.000000	0.0000000