File: 1-C1(0.6mol%)+C20(0.6mol%)/matlab/170-1.txt
CLOSED
Version	1.0
Language	English
Mode	Standard
Run	10
RunSerial	11860
Instrument	DSC Q2000 V24.11 Build 124
Module	DSC Standard Cell RC
Operator	Jing
File	\\AE520-1454\TA\Data\DSC\UQ Composites\Nan\C1(5.5)+C20P(3)+CL(HotplateMixtureAB)\170-1
ProcName	Ramp
InstSerial	2000-0883
AutoSerial	1293
Sample	Iso-170-1
Size	25.0000	mg
PanMass	Not available
PanResist	Automatic Automatic  K/W
PanFactor	Default Default
Method	Ramp
Comment
Xcomment	Pan: Tzero Aluminum Hermetic
Xcomment	Gas1: Nitrogen 50.0 ml/min
Xcomment	Gas2: Nitrogen 50.0 ml/min
Text
Exotherm	UP
Kcell	1.05230
Cpconst	Standard: 0.938
Calib	-38.6961
TempCal	1	pts	157.46	156.60
TzeroDt	-87.6168 -0.0009 -1.4231
TzeroDtz	-87.6168 0.0057 6.9570
InstCalFile	Tzero: \\Ae520-1454\ta\Data\DSC\Calibration\2017\CALIBRATION\1562_RCS (90)_05_18_2017 10_50_44.TZR
InstCalFile	Baseline: \\Ae520-1454\ta\Data\DSC\Calibration\2017\2017-05-17_Calibration.001
InstCalFile	Sapphire: \\Ae520-1454\ta\Data\DSC\Calibration\2017\2017-05-17_Saphire.001
InstCalDate	Tzero 2017-05-18 Time 10:50:44
TempRange	-87.39 to 398.39 °C at 10.00 °C/min Heat Only
AutoZero	Delta T Offset 0.000 uV
AutoZero	Delta T0 Offset 0.000 uV
MultiptCal	0
MultiPtDesc	0) Not set
AutoCellConst	Calibration Date 2017-05-18 16:59:28
Controls	Gas 1  Event Off  Sampling 0.2
Cell#	RC-01562
CoolingUnit	RCS (90)
SelHeatFlow	Heat Flow T4 (mW)
AutoLidII	Installed
AutoAnalysis	Off
MacroFile
Nsig	3
Sig1	Time (min)
Sig2	Temperature (°C)
Sig3	Heat Flow (mW)
Date	2017-06-21
Time	04:56:20
OrgMethod	1: Equilibrate at 20.00 °C
OrgMethod	2: Ramp 40.00 °C/min to 170.00 °C
OrgMethod	3: Mark end of cycle 1
OrgMethod	4: Isothermal for 40.00 min
OrgMethod	5: Mark end of cycle 2
OrgMethod	6: Ramp 20.00 °C/min to 280.00 °C
OrgMethod	7: Mark end of cycle 3
OrgMethod	8: Ramp 20.00 °C/min to 20.00 °C
OrgMethod	9: Mark end of cycle 4
OrgMethod	10: Ramp 20.00 °C/min to 280.00 °C
OrgMethod	11: Mark end of cycle 5
OrgFile	C:\Users\jarra\Desktop\DSC\1-C1(0.6mol%)+C20(0.6mol%)\170-1.001
StartOfData
4.99994E-4	20.05456	-0.1726797
0.05383332	20.17136	-.04568750
0.1038333	20.98267	-0.6177574
0.1571666	22.27073	-3.199455
0.2071666	23.68639	-6.026630
0.2588334	25.30681	-8.850821
0.3105000	27.03240	-11.28211
0.3605000	28.77957	-13.19594
0.4138333	30.69912	-14.78065
0.4638333	32.54039	-15.92096
0.5171667	34.53662	-16.84162
0.5671668	36.42835	-17.49936
0.6188334	38.40194	-18.04081
0.6705000	40.38608	-18.48882
0.7205000	42.31190	-18.91851
0.7738332	44.36472	-19.52466
0.8238334	46.29190	-19.95097
0.8771668	48.36700	-20.16274
0.9271668	50.31804	-20.42242
0.9788332	52.33015	-20.83912
1.030500	54.33662	-21.41980
1.080500	56.27558	-22.01881
1.133833	58.34621	-22.67861
1.183833	60.28174	-23.51206
1.237166	62.33099	-24.81866
1.287167	64.21957	-26.78035
1.338833	66.11084	-30.22251
1.390500	67.88876	-36.16709
1.440500	69.45153	-45.07592
1.493833	70.95232	-57.18858
1.543833	72.28311	-69.34408
1.595500	73.68244	-80.76625
1.647167	75.12738	-92.17616
1.698833	76.51246	-105.0193
1.750500	77.90339	-116.0349
1.800500	79.57038	-119.2331
1.853833	81.88849	-112.5652
1.903833	84.33566	-103.6276
1.955500	87.03995	-90.36136
2.007167	89.90382	-76.09750
2.058833	92.63966	-64.99463
2.110500	95.22518	-56.50034
2.160500	97.60613	-50.27758
2.213833	100.0440	-45.32646
2.263833	102.2554	-41.89481
2.315500	104.4840	-39.28833
2.367167	106.6702	-37.42313
2.417167	108.7566	-36.12142
2.470500	110.9470	-35.33540
2.520500	112.9854	-34.83911
2.573833	115.1443	-34.55344
2.623834	117.1590	-34.47858
2.675500	119.2310	-34.56031
2.727167	121.2957	-34.77286
2.777166	123.2898	-35.07048
2.830500	125.4139	-35.45885
2.880500	127.4014	-35.86270
2.933833	129.5191	-36.34336
2.983833	131.5018	-36.85956
3.035500	133.5473	-37.43500
3.087167	135.5905	-38.07341
3.137167	137.5671	-38.73828
3.190500	139.6724	-39.48413
3.240500	141.6453	-40.21738
3.293833	143.7476	-41.05378
3.343834	145.7176	-41.87522
3.395500	147.7506	-42.78372
3.447167	149.7798	-43.74324
3.497166	151.7412	-44.72114
3.550500	153.8312	-45.82537
3.600500	155.7869	-46.93644
3.653833	157.8724	-48.16789
3.703833	159.8270	-49.38168
3.750500	161.6495	-50.54832
3.803833	163.6265	-51.98634
3.853833	164.7792	-52.14014
3.907166	165.5796	-49.12926
3.957167	166.1244	-45.50058
4.008833	166.5441	-41.79687
4.060500	166.8642	-38.62060
4.110500	167.1082	-36.11200
4.163834	167.3159	-34.03213
4.213834	167.4744	-32.55628
4.267166	167.6138	-31.40006
4.317167	167.7206	-30.64728
4.368834	167.8120	-30.08626
4.420500	167.8919	-29.65396
4.470500	167.9590	-29.31172
4.523834	168.0254	-29.00045
4.573834	168.0805	-28.73206
4.627167	168.1361	-28.45304
4.677166	168.1842	-28.18352
4.728833	168.2309	-27.88254
4.780500	168.2773	-27.52680
4.830500	168.3224	-27.12109
4.883834	168.3706	-26.62172
4.933834	168.4165	-26.09550
4.987167	168.4654	-25.47789
5.037167	168.5123	-24.85514
5.088834	168.5614	-24.16711
5.140500	168.6094	-23.44368
5.190500	168.6579	-22.70523
5.243834	168.7080	-21.86415
5.293832	168.7588	-21.02106
5.345500	168.8115	-20.07318
5.397168	168.8688	-19.03435
5.448834	168.9288	-17.89876
5.500500	168.9931	-16.66486
5.550500	169.0592	-15.38478
5.603832	169.1330	-13.93826
5.653834	169.2054	-12.51374
5.705500	169.2830	-10.98323
5.757168	169.3617	-9.422719
5.808832	169.4394	-7.893738
5.860500	169.5131	-6.475753
5.910500	169.5775	-5.264524
5.963832	169.6361	-4.174574
6.013834	169.6829	-3.329114
6.065500	169.7220	-2.614213
6.117168	169.7530	-2.032142
6.167168	169.7791	-1.580246
6.220500	169.8012	-1.188523
6.270500	169.8179	-0.8849309
6.323834	169.8331	-0.6259092
6.373832	169.8450	-0.4263758
6.425500	169.8546	-0.2562508
6.477168	169.8629	-0.1119486
6.527168	169.8701	-1.7749E-3
6.580500	169.8751	0.08872461
6.630500	169.8802	0.1575433
6.683832	169.8837	0.2201463
6.733832	169.8872	0.2670674
6.785500	169.8905	0.3059028
6.837168	169.8927	0.3383984
6.887168	169.8953	0.3641456
6.940500	169.8969	0.3874675
6.990500	169.8984	0.4069596
7.043832	169.8996	0.4295674
7.093832	169.9017	0.4535281
7.145500	169.9032	0.4821391
7.197168	169.9056	0.5133406
7.247168	169.9070	0.5454141
7.300500	169.9089	0.5811652
7.350500	169.9120	0.6227250
7.403832	169.9140	0.6794104
7.453832	169.9165	0.7350478
7.505500	169.9194	0.7940299
7.557166	169.9228	0.8518805
7.607168	169.9254	0.9088509
7.660500	169.9286	0.9615981
7.710500	169.9312	1.016802
7.762168	169.9347	1.075276
7.813834	169.9383	1.129195
7.865500	169.9408	1.184006
7.917168	169.9433	1.233955
7.967168	169.9448	1.274034
8.020500	169.9475	1.310546
8.070500	169.9494	1.333509
8.122168	169.9504	1.348488
8.173832	169.9509	1.359577
8.225500	169.9521	1.366677
8.277168	169.9530	1.372645
8.327168	169.9536	1.377471
8.380500	169.9528	1.380776
8.430500	169.9526	1.381446
8.482166	169.9521	1.377285
8.533832	169.9512	1.365270
8.583832	169.9500	1.338864
8.637168	169.9486	1.300837
8.687166	169.9474	1.266282
8.740500	169.9459	1.227214
8.790500	169.9443	1.187541
8.842168	169.9430	1.148248
8.893832	169.9413	1.108843
8.943832	169.9388	1.069045
8.997168	169.9369	1.031701
9.047168	169.9354	0.9902245
9.100500	169.9333	0.9494649
9.150500	169.9311	0.9128879
9.202168	169.9291	0.8773851
9.253834	169.9272	0.8406730
9.303832	169.9258	0.8052605
9.357166	169.9242	0.7706638
9.407166	169.9223	0.7398179
9.460499	169.9211	0.7091620
9.510499	169.9191	0.6800103
9.562166	169.9183	0.6470708
9.613834	169.9160	0.6215184
9.663834	169.9147	0.5967744
9.717168	169.9136	0.5694249
9.767168	169.9125	0.5460730
9.820500	169.9111	0.5219490
9.870499	169.9112	0.4991800
9.922168	169.9095	0.4806887
9.973832	169.9091	0.4634850
10.02383	169.9081	0.4447662
10.07717	169.9067	0.4248884
10.12717	169.9059	0.4098009
10.17883	169.9052	0.3925525
10.23050	169.9043	0.3774294
10.28217	169.9043	0.3601882
10.33383	169.9042	0.3456418
10.38383	169.9034	0.3318942
10.43717	169.9021	0.3171152
10.48717	169.9020	0.3028770
10.53883	169.9006	0.2903454
10.59050	169.8999	0.2769920
10.64050	169.8998	0.2631002
10.69383	169.8989	0.2500680
10.74384	169.8984	0.2383326
10.79717	169.8981	0.2240448
10.84717	169.8970	0.2121176
10.89883	169.8966	0.1998409
10.95050	169.8961	0.1886396
11.00050	169.8955	0.1780806
11.05383	169.8951	0.1667815
11.10383	169.8954	0.1557858
11.15717	169.8946	0.1450554
11.20717	169.8937	0.1348166
11.25883	169.8937	0.1244990
11.31050	169.8930	0.1135488
11.36050	169.8928	0.1029660
11.41383	169.8928	0.09290081
11.46383	169.8919	0.08343999
11.51717	169.8912	0.07399524
11.56716	169.8911	0.06530061
11.61884	169.8914	0.05661144
11.67050	169.8910	0.04798626
11.72050	169.8906	0.03986404
11.77383	169.8906	0.03118838
11.82383	169.8901	0.02334732
11.87717	169.8897	0.01536550
11.92717	169.8900	.008142930
11.97884	169.8895	9.61628E-4
12.03050	169.8894	-5.8543E-3
12.08050	169.8890	-.01219878
12.13383	169.8888	-.01896066
12.18383	169.8884	-.02490841
12.23550	169.8881	-.03062006
12.28717	169.8877	-.03632440
12.33883	169.8876	-.04177154
12.39050	169.8882	-.04694328
12.44050	169.8877	-.05203988
12.49384	169.8872	-.05700664
12.54384	169.8875	-.06162770
12.59550	169.8878	-.06643757
12.64717	169.8886	-.07125538
12.69883	169.8881	-.07586782
12.75050	169.8883	-.07994072
12.80050	169.8877	-.08352524
12.85383	169.8866	-.08678556
12.90383	169.8872	-.08956106
12.95550	169.8870	-.09204098
13.00717	169.8869	-.09420350
13.05717	169.8863	-.09587070
13.11050	169.8858	-.09732012
13.16050	169.8854	-.09879731
13.21383	169.8856	-0.1004211
13.26383	169.8852	-0.1021378
13.31550	169.8849	-0.1040370
13.36716	169.8849	-0.1059750
13.41716	169.8851	-0.1083404
13.47050	169.8849	-0.1111112
13.52050	169.8851	-0.1136562
13.57384	169.8844	-0.1163299
13.62384	169.8845	-0.1187472
13.67550	169.8838	-0.1211406
13.72717	169.8844	-0.1237201
13.77717	169.8839	-0.1260930
13.83050	169.8844	-0.1283423
13.88050	169.8843	-0.1305194
13.93383	169.8840	-0.1323921
13.98383	169.8837	-0.1336286
14.03550	169.8842	-0.1346373
14.08717	169.8847	-0.1353961
14.13717	169.8848	-0.1356638
14.19050	169.8851	-0.1357077
14.24050	169.8852	-0.1354395
14.29384	169.8861	-0.1347879
14.34383	169.8851	-0.1336983
14.39550	169.8864	-0.1325724
14.44717	169.8861	-0.1313089
14.49717	169.8867	-0.1298270
14.55050	169.8868	-0.1284643
14.60050	169.8872	-0.1269025
14.65217	169.8867	-0.1252569
14.70383	169.8876	-0.1237790
14.75550	169.8878	-0.1225106
14.80717	169.8882	-0.1210943
14.85716	169.8881	-0.1198293
14.91050	169.8882	-0.1183630
14.96050	169.8879	-0.1174370
15.01217	169.8878	-0.1163612
15.06383	169.8875	-0.1155196
15.11550	169.8882	-0.1146623
15.16716	169.8874	-0.1134590
15.21716	169.8874	-0.1125769
15.27050	169.8867	-0.1117539
15.32050	169.8868	-0.1108623
15.37217	169.8866	-0.1099362
15.42383	169.8875	-0.1087485
15.47383	169.8878	-0.1072180
15.52717	169.8874	-0.1055046
15.57717	169.8886	-0.1036420
15.63050	169.8884	-0.1017762
15.68050	169.8879	-.09988592
15.73216	169.8888	-.09828902
15.78383	169.8897	-.09651056
15.83383	169.8892	-.09468484
15.88716	169.8894	-.09231955
15.93717	169.8896	-.08971824
15.99050	169.8904	-.08650161
16.04050	169.8910	-.08287548
16.09216	169.8906	-.07853813
16.14383	169.8908	-.07390913
16.19383	169.8906	-.06924055
16.24716	169.8905	-.06347949
16.29716	169.8906	-.05803525
16.35050	169.8912	-.05224133
16.40050	169.8905	-.04639097
16.45216	169.8909	-.03992570
16.50383	169.8916	-.03365512
16.55383	169.8921	-.02755647
16.60716	169.8926	-.02082795
16.65716	169.8935	-.01449212
16.71050	169.8933	-7.0710E-3
16.76050	169.8951	1.80675E-5
16.81216	169.8954	.007306389
16.86383	169.8965	0.01495099
16.91383	169.8968	0.02276374
16.96716	169.8973	0.03167815
17.01716	169.8974	0.04075898
17.06883	169.8981	0.04966338
17.12050	169.8988	0.05899105
17.17216	169.8987	0.06874001
17.22383	169.8984	0.07884812
17.27383	169.8990	0.08814395
17.32716	169.9000	0.09810501
17.37716	169.9002	0.1076432
17.42883	169.9002	0.1172624
17.48050	169.9013	0.1269728
17.53050	169.9020	0.1359394
17.58383	169.9019	0.1451959
17.63383	169.9022	0.1534156
17.68716	169.9032	0.1622300
17.73716	169.9039	0.1699379
17.78883	169.9038	0.1776181
17.84050	169.9032	0.1850147
17.89050	169.9037	0.1923264
17.94383	169.9049	0.1992934
17.99383	169.9044	0.2053211
18.04716	169.9050	0.2108597
18.09716	169.9048	0.2153309
18.14883	169.9049	0.2193576
18.20050	169.9043	0.2229481
18.25050	169.9059	0.2254812
18.30383	169.9056	0.2274166
18.35383	169.9058	0.2287172
18.40716	169.9056	0.2293470
18.45716	169.9051	0.2292814
18.50883	169.9058	0.2283856
18.56050	169.9048	0.2268959
18.61050	169.9045	0.2249159
18.66383	169.9047	0.2221732
18.71383	169.9043	0.2188758
18.76716	169.9034	0.2147265
18.81716	169.9033	0.2103077
18.86883	169.9027	0.2049156
18.92050	169.9024	0.1985633
18.97050	169.9014	0.1918974
19.02383	169.9014	0.1840056
19.07383	169.8998	0.1759809
19.12550	169.8995	0.1667851
19.17716	169.8992	0.1569934
19.22883	169.8982	0.1453745
19.28050	169.8982	0.1333755
19.33050	169.8964	0.1214194
19.38383	169.8971	0.1072752
19.43383	169.8955	0.09214068
19.48550	169.8959	0.07375014
19.53717	169.8950	0.05984775
19.58883	169.8940	0.04236744
19.64050	169.8930	0.02767368
19.69050	169.8931	0.01037270
19.74383	169.8924	-7.7069E-3
19.79383	169.8916	-.02784738
19.84550	169.8904	-.04655250
19.89716	169.8899	-.06436154
19.94716	169.8894	-.08112514
20.00050	169.8886	-.09988536
20.05050	169.8878	-0.1178098
20.10383	169.8856	-0.1350636
20.15383	169.8864	-0.1531999
20.20550	169.8849	-0.1747651
20.25716	169.8839	-0.1924242
20.30716	169.8830	-0.2104717
20.36050	169.8813	-0.2309209
20.41050	169.8805	-0.2503230
20.46383	169.8796	-0.2716024
20.51383	169.8789	-0.2921909
20.56550	169.8773	-0.3151452
20.61716	169.8762	-0.3360579
20.66716	169.8754	-0.3594329
20.72050	169.8750	-0.3813963
20.77050	169.8724	-0.4017468
20.82383	169.8719	-0.4221691
20.87383	169.8712	-0.4476624
20.92550	169.8694	-0.4695511
20.97716	169.8686	-0.4933822
21.02717	169.8674	-0.5187153
21.08050	169.8658	-0.5425014
21.13050	169.8649	-0.5664597
21.18383	169.8634	-0.5938988
21.23383	169.8624	-0.6164088
21.28550	169.8617	-0.6408784
21.33716	169.8602	-0.6661381
21.38716	169.8588	-0.6892730
21.44050	169.8576	-0.7146254
21.49050	169.8565	-0.7403940
21.54216	169.8554	-0.7648406
21.59383	169.8540	-0.7915371
21.64550	169.8529	-0.8156190
21.69716	169.8523	-0.8410401
21.74716	169.8510	-0.8651801
21.80050	169.8502	-0.8897759
21.85050	169.8480	-0.9125259
21.90216	169.8471	-0.9377961
21.95383	169.8468	-0.9603726
22.00550	169.8457	-0.9844199
22.05716	169.8453	-1.008962
22.10716	169.8442	-1.031335
22.16050	169.8431	-1.052455
22.21050	169.8430	-1.072925
22.26216	169.8409	-1.095364
22.31383	169.8403	-1.116316
22.36383	169.8386	-1.135651
22.41716	169.8379	-1.154958
22.46716	169.8372	-1.174833
22.52050	169.8359	-1.193739
22.57050	169.8347	-1.213002
22.62216	169.8338	-1.233818
22.67383	169.8322	-1.252413
22.72383	169.8328	-1.272371
22.77717	169.8306	-1.292421
22.82716	169.8292	-1.309460
22.88050	169.8285	-1.328258
22.93050	169.8280	-1.346202
22.98216	169.8260	-1.364757
23.03383	169.8261	-1.385601
23.08383	169.8236	-1.404326
23.13716	169.8227	-1.425514
23.18716	169.8226	-1.444188
23.24050	169.8216	-1.463901
23.29050	169.8194	-1.480908
23.34216	169.8205	-1.502244
23.39383	169.8185	-1.520141
23.44383	169.8175	-1.538789
23.49716	169.8171	-1.555176
23.54716	169.8164	-1.571361
23.60050	169.8152	-1.591054
23.65050	169.8156	-1.609427
23.70216	169.8141	-1.627944
23.75383	169.8138	-1.647218
23.80383	169.8132	-1.664137
23.85716	169.8109	-1.679071
23.90716	169.8108	-1.694376
23.95883	169.8091	-1.711620
24.01050	169.8084	-1.727099
24.06216	169.8069	-1.743058
24.11383	169.8063	-1.760745
24.16383	169.8058	-1.778729
24.21716	169.8048	-1.795166
24.26716	169.8041	-1.812252
24.31883	169.8034	-1.827678
24.37050	169.8028	-1.843776
24.42050	169.8024	-1.858994
24.47383	169.8020	-1.874525
24.52383	169.8009	-1.887076
24.57716	169.8010	-1.902895
24.62716	169.8003	-1.916008
24.67883	169.7998	-1.928239
24.73050	169.7987	-1.940959
24.78050	169.7981	-1.952042
24.83383	169.7978	-1.964433
24.88383	169.7968	-1.976309
24.93716	169.7964	-1.988829
24.98716	169.7958	-1.999082
25.03883	169.7950	-2.010071
25.09050	169.7946	-2.020478
25.14050	169.7939	-2.030452
25.19383	169.7936	-2.041308
25.24383	169.7920	-2.051121
25.29716	169.7914	-2.061494
25.34716	169.7913	-2.070703
25.39883	169.7906	-2.080202
25.45050	169.7912	-2.089734
25.50050	169.7914	-2.099218
25.55383	169.7904	-2.108711
25.60383	169.7897	-2.117000
25.65716	169.7893	-2.125704
25.70716	169.7894	-2.133620
25.75883	169.7888	-2.141531
25.81050	169.7886	-2.149046
25.86050	169.7890	-2.156086
25.91383	169.7886	-2.163530
25.96383	169.7886	-2.169989
26.01550	169.7883	-2.176414
26.06716	169.7879	-2.182520
26.11883	169.7877	-2.188140
26.17050	169.7874	-2.193730
26.22050	169.7872	-2.198862
26.27383	169.7872	-2.204426
26.32383	169.7866	-2.209498
26.37550	169.7864	-2.214501
26.42717	169.7864	-2.219338
26.47883	169.7862	-2.224307
26.53050	169.7858	-2.229082
26.58050	169.7861	-2.233313
26.63383	169.7851	-2.237448
26.68383	169.7858	-2.241334
26.73550	169.7848	-2.245247
26.78717	169.7848	-2.248927
26.83716	169.7849	-2.252342
26.89050	169.7844	-2.256015
26.94050	169.7842	-2.259140
26.99383	169.7838	-2.262620
27.04383	169.7839	-2.265743
27.09550	169.7840	-2.269098
27.14716	169.7839	-2.272302
27.19717	169.7840	-2.275411
27.25050	169.7835	-2.278670
27.30050	169.7842	-2.281522
27.35383	169.7838	-2.284694
27.40383	169.7837	-2.287234
27.45550	169.7829	-2.289736
27.50716	169.7826	-2.292408
27.55716	169.7826	-2.294773
27.61050	169.7818	-2.297138
27.66050	169.7819	-2.299258
27.71383	169.7812	-2.301286
27.76383	169.7813	-2.303157
27.81550	169.7817	-2.305184
27.86716	169.7811	-2.307333
27.91716	169.7814	-2.309348
27.97050	169.7815	-2.311825
28.02050	169.7818	-2.313836
28.07383	169.7819	-2.316156
28.12383	169.7816	-2.318222
28.17550	169.7816	-2.320494
28.22717	169.7812	-2.322534
28.27717	169.7828	-2.324536
28.33050	169.7814	-2.326559
28.38050	169.7818	-2.328070
28.43216	169.7814	-2.329713
28.48383	169.7817	-2.331313
28.53550	169.7818	-2.332970
28.58716	169.7813	-2.334563
28.63716	169.7818	-2.336326
28.69050	169.7810	-2.338027
28.74050	169.7812	-2.339628
28.79216	169.7811	-2.341191
28.84383	169.7812	-2.342549
28.89550	169.7809	-2.343773
28.94717	169.7808	-2.345187
28.99716	169.7809	-2.346520
29.05050	169.7801	-2.347718
29.10050	169.7802	-2.348913
29.15216	169.7797	-2.349779
29.20383	169.7802	-2.350723
29.25383	169.7798	-2.351570
29.30716	169.7793	-2.352744
29.35716	169.7794	-2.353758
29.41050	169.7795	-2.355213
29.46050	169.7794	-2.356803
29.51216	169.7799	-2.358381
29.56383	169.7796	-2.359799
29.61383	169.7801	-2.361136
29.66716	169.7794	-2.362692
29.71716	169.7798	-2.364035
29.77050	169.7804	-2.365500
29.82050	169.7795	-2.366728
29.87216	169.7802	-2.367659
29.92383	169.7799	-2.368686
29.97383	169.7794	-2.369511
30.02717	169.7800	-2.370387
30.07717	169.7793	-2.371248
30.13050	169.7787	-2.372324
30.18050	169.7795	-2.373293
30.23216	169.7794	-2.374448
30.28383	169.7789	-2.375372
30.33383	169.7789	-2.375938
30.38716	169.7789	-2.376718
30.43717	169.7781	-2.377565
30.49050	169.7788	-2.378276
30.54050	169.7794	-2.379394
30.59216	169.7786	-2.380442
30.64383	169.7792	-2.381774
30.69383	169.7793	-2.383081
30.74716	169.7792	-2.384496
30.79716	169.7789	-2.385742
30.84883	169.7798	-2.386915
30.90050	169.7795	-2.388088
30.95217	169.7796	-2.388801
31.00383	169.7789	-2.389446
31.05383	169.7792	-2.390074
31.10716	169.7794	-2.390916
31.15716	169.7785	-2.391634
31.20883	169.7793	-2.392454
31.26050	169.7782	-2.393300
31.31050	169.7785	-2.393873
31.36383	169.7795	-2.394768
31.41383	169.7797	-2.395576
31.46716	169.7787	-2.396143
31.51716	169.7792	-2.396994
31.56883	169.7788	-2.397964
31.62050	169.7788	-2.398748
31.67050	169.7783	-2.399330
31.72383	169.7782	-2.399696
31.77383	169.7778	-2.400097
31.82717	169.7780	-2.400339
31.87717	169.7780	-2.400799
31.92883	169.7778	-2.401260
31.98050	169.7781	-2.401806
32.03050	169.7782	-2.402638
32.08383	169.7771	-2.403267
32.13383	169.7782	-2.404104
32.18716	169.7776	-2.404963
32.23717	169.7782	-2.405667
32.28883	169.7776	-2.406249
32.34050	169.7778	-2.407012
32.39050	169.7779	-2.407773
32.44383	169.7786	-2.408243
32.49383	169.7781	-2.408932
32.54716	169.7778	-2.409631
32.59716	169.7776	-2.410396
32.64883	169.7781	-2.411078
32.70050	169.7778	-2.411802
32.75050	169.7780	-2.412445
32.80383	169.7775	-2.412676
32.85383	169.7775	-2.413040
32.90550	169.7780	-2.413304
32.95716	169.7771	-2.413409
33.00883	169.7765	-2.413525
33.06050	169.7773	-2.414066
33.11050	169.7769	-2.414341
33.16383	169.7780	-2.414789
33.21383	169.7772	-2.415174
33.26550	169.7780	-2.415450
33.31716	169.7787	-2.416016
33.36883	169.7782	-2.416436
33.42050	169.7786	-2.416738
33.47050	169.7787	-2.417147
33.52383	169.7784	-2.417598
33.57383	169.7777	-2.417873
33.62550	169.7777	-2.417900
33.67717	169.7780	-2.417938
33.72717	169.7782	-2.417934
33.78050	169.7781	-2.417889
33.83050	169.7783	-2.418255
33.88383	169.7778	-2.418452
33.93384	169.7776	-2.418873
33.98550	169.7777	-2.419338
34.03717	169.7776	-2.419775
34.08716	169.7775	-2.420253
34.14050	169.7772	-2.420584
34.19050	169.7784	-2.421047
34.24383	169.7766	-2.421117
34.29383	169.7769	-2.421480
34.34550	169.7771	-2.421945
34.39717	169.7768	-2.422316
34.44717	169.7768	-2.422774
34.50050	169.7766	-2.423205
34.55050	169.7770	-2.423847
34.60383	169.7772	-2.424385
34.65383	169.7766	-2.425056
34.70550	169.7768	-2.425576
34.75716	169.7781	-2.426139
34.80716	169.7780	-2.426775
34.86050	169.7775	-2.427483
34.91050	169.7776	-2.428046
34.96383	169.7774	-2.428333
35.01383	169.7770	-2.428383
35.06550	169.7773	-2.428392
35.11716	169.7776	-2.428325
35.16716	169.7774	-2.428430
35.22050	169.7775	-2.428482
35.27050	169.7778	-2.428654
35.32217	169.7774	-2.428803
35.37383	169.7777	-2.429269
35.42550	169.7775	-2.429539
35.47717	169.7772	-2.429828
35.52716	169.7778	-2.430290
35.58050	169.7771	-2.430684
35.63050	169.7776	-2.430926
35.68216	169.7771	-2.431186
35.73383	169.7776	-2.431563
35.78550	169.7772	-2.432058
35.83716	169.7773	-2.432406
35.88716	169.7778	-2.432709
35.94050	169.7777	-2.433070
35.99050	169.7773	-2.433302
36.04217	169.7772	-2.433714
36.09384	169.7780	-2.434260
36.14383	169.7779	-2.434647
36.19717	169.7780	-2.434847
36.24716	169.7776	-2.434875
36.30050	169.7774	-2.435120
36.35050	169.7780	-2.435616
36.40216	169.7776	-2.435900
36.45383	169.7767	-2.436086
36.50383	169.7776	-2.436367
36.55716	169.7772	-2.436484
36.60716	169.7772	-2.436416
36.66050	169.7767	-2.436430
36.71050	169.7767	-2.436379
36.76216	169.7770	-2.436359
36.81383	169.7759	-2.436342
36.86383	169.7753	-2.436083
36.91716	169.7756	-2.435959
36.96716	169.7756	-2.435906
37.02050	169.7763	-2.435972
37.07050	169.7758	-2.436030
37.12216	169.7756	-2.436059
37.17383	169.7760	-2.436142
37.22383	169.7767	-2.436230
37.27716	169.7765	-2.436578
37.32717	169.7771	-2.436875
37.38050	169.7764	-2.437224
37.43050	169.7774	-2.437618
37.48216	169.7769	-2.438025
37.53383	169.7769	-2.438054
37.58383	169.7771	-2.438080
37.63716	169.7762	-2.438307
37.68716	169.7772	-2.438405
37.73883	169.7775	-2.438564
37.79050	169.7772	-2.438576
37.84216	169.7770	-2.438642
37.89383	169.7769	-2.438508
37.94383	169.7776	-2.438622
37.99716	169.7774	-2.438762
38.04716	169.7774	-2.438727
38.09883	169.7772	-2.438768
38.15050	169.7774	-2.438672
38.20050	169.7768	-2.438613
38.25383	169.7772	-2.438780
38.30383	169.7767	-2.438990
38.35716	169.7779	-2.439232
38.40716	169.7776	-2.439470
38.45883	169.7767	-2.439626
38.51050	169.7768	-2.439809
38.56050	169.7767	-2.439719
38.61383	169.7765	-2.439910
38.66383	169.7762	-2.439910
38.71716	169.7774	-2.440288
38.76716	169.7760	-2.440450
38.81883	169.7762	-2.440628
38.87050	169.7769	-2.440936
38.92050	169.7760	-2.441262
38.97383	169.7762	-2.441558
39.02383	169.7758	-2.441953
39.07717	169.7762	-2.442336
39.12717	169.7762	-2.442736
39.17883	169.7759	-2.442928
39.23050	169.7756	-2.443213
39.28050	169.7765	-2.443497
39.33383	169.7755	-2.443770
39.38383	169.7769	-2.444183
39.43716	169.7754	-2.444940
39.48717	169.7768	-2.445570
39.53883	169.7760	-2.446130
39.59050	169.7760	-2.446490
39.64050	169.7759	-2.446601
39.69383	169.7763	-2.446691
39.74383	169.7767	-2.446934
39.79550	169.7769	-2.447048
39.84716	169.7760	-2.447185
39.89883	169.7761	-2.447289
39.95050	169.7762	-2.447482
40.00050	169.7762	-2.447420
40.05383	169.7770	-2.447554
40.10383	169.7760	-2.447640
40.15550	169.7768	-2.447867
40.20716	169.7762	-2.448435
40.25883	169.7770	-2.448744
40.31050	169.7766	-2.448830
40.36050	169.7770	-2.448952
40.41383	169.7765	-2.449255
40.46383	169.7771	-2.449516
40.51550	169.7775	-2.449793
40.56716	169.7770	-2.450236
40.61716	169.7762	-2.450611
40.67050	169.7774	-2.450936
40.72050	169.7775	-2.451355
40.77383	169.7762	-2.451508
40.82383	169.7777	-2.451689
40.87550	169.7768	-2.451677
40.92717	169.7769	-2.451770
40.97717	169.7772	-2.451766
41.03050	169.7772	-2.451546
41.08050	169.7771	-2.451412
41.13383	169.7762	-2.451119
41.18383	169.7761	-2.451065
41.23550	169.7768	-2.451001
41.28717	169.7763	-2.450868
41.33716	169.7766	-2.450806
41.39050	169.7760	-2.450597
41.44050	169.7762	-2.450466
41.49383	169.7766	-2.450238
41.54383	169.7764	-2.450276
41.59550	169.7758	-2.450331
41.64717	169.7766	-2.450590
41.69717	169.7760	-2.450958
41.75050	169.7765	-2.451199
41.80050	169.7766	-2.451551
41.85383	169.7762	-2.451686
41.90383	169.7772	-2.451685
41.95550	169.7768	-2.451740
42.00717	169.7777	-2.451798
42.05717	169.7762	-2.452156
42.11050	169.7771	-2.452274
42.16050	169.7767	-2.452204
42.21216	169.7761	-2.452114
42.26383	169.7774	-2.452275
42.31550	169.7772	-2.452407
42.36716	169.7771	-2.452472
42.41716	169.7768	-2.452408
42.47050	169.7771	-2.452566
42.52050	169.7766	-2.452634
42.57217	169.7766	-2.452514
42.62383	169.7762	-2.452455
42.67550	169.7764	-2.452438
42.72717	169.7762	-2.452547
42.77716	169.7770	-2.452668
42.83050	169.7766	-2.452824
42.88050	169.7772	-2.452792
42.93217	169.7770	-2.452702
42.98383	169.7765	-2.452537
43.03383	169.7769	-2.452590
43.08716	169.7766	-2.452559
43.13716	169.7769	-2.452595
43.19050	169.7765	-2.452612
43.24050	169.7754	-2.452449
43.29217	169.7772	-2.452472
43.34384	169.7761	-2.452556
43.39383	169.7769	-2.452429
43.44717	169.7763	-2.452237
43.49716	169.7759	-2.452214
43.55050	169.7759	-2.452070
43.60050	169.7755	-2.451752
43.65216	169.7753	-2.451831
43.70383	169.7757	-2.451928
43.75050	169.7753	-2.451751
43.80383	169.8362	-2.445324
43.85383	170.2372	-3.011300
43.90717	170.8852	-4.886606
43.95717	171.6072	-6.856580
44.00883	172.4311	-8.722656
44.06050	173.3098	-10.26072
44.11050	174.1972	-11.43300
44.16383	175.1710	-12.37881
44.21383	176.1034	-13.04643
44.26717	177.1104	-13.57530
44.31717	178.0669	-13.95114
44.36883	179.0606	-14.25441
44.42050	180.0614	-14.49687
44.47050	181.0331	-14.70122
44.52383	182.0735	-14.88757
44.57383	183.0521	-15.05060
44.62717	184.0978	-15.21817
44.67717	185.0796	-15.37103
44.72883	186.0952	-15.53237
44.78050	187.1116	-15.69396
44.83050	188.0955	-15.87039
44.88383	189.1452	-16.06942
44.93383	190.1296	-16.26962
44.98717	191.1798	-16.51054
45.03717	192.1636	-16.75617
45.08883	193.1794	-17.04259
45.14050	194.1934	-17.37012
45.19050	195.1731	-17.71559
45.24383	196.2179	-18.13562
45.29383	197.1957	-18.58676
45.34550	198.2037	-19.10372
45.39717	199.2086	-19.72972
45.44883	200.2080	-20.47338
45.50050	201.2006	-21.35549
45.55050	202.1556	-22.36581
45.60383	203.1660	-23.61375
45.65383	204.1056	-24.95767
45.70550	205.0699	-26.50764
45.75717	206.0260	-28.21998
45.80883	206.9764	-30.06737
45.86050	207.9209	-31.99835
45.91050	208.8351	-33.85675
45.96383	209.8118	-35.81054
46.01383	210.7297	-37.60310
46.06550	211.6800	-39.39328
46.11716	212.6382	-40.93984
46.16716	213.5892	-41.78650
46.22050	214.6539	-41.41320
46.27050	215.7144	-39.64944
46.32383	216.9166	-36.29494
46.37383	218.0910	-32.27102
46.42550	219.3166	-28.18300
46.47717	220.5178	-24.82067
46.52716	221.6421	-22.44842
46.58050	222.8029	-20.69423
46.63050	223.8630	-19.56898
46.68383	224.9744	-18.75313
46.73383	226.0024	-18.23131
46.78550	227.0555	-17.88358
46.83716	228.1020	-17.65875
46.88716	229.1100	-17.52907
46.94050	230.1827	-17.45330
46.99050	231.1863	-17.41839
47.04383	232.2556	-17.40755
47.09384	233.2572	-17.40803
47.14550	234.2906	-17.41577
47.19717	235.3236	-17.44282
47.24716	236.3235	-17.48804
47.30050	237.3894	-17.53542
47.35050	238.3882	-17.58206
47.40383	239.4550	-17.63511
47.45383	240.4526	-17.69044
47.50550	241.4842	-17.74732
47.55717	242.5164	-17.81439
47.60717	243.5150	-17.87061
47.66050	244.5800	-17.93123
47.71050	245.5796	-17.98922
47.76216	246.6110	-18.04586
47.81383	247.6430	-18.10495
47.86550	248.6751	-18.16069
47.91716	249.7064	-18.22886
47.96717	250.7052	-18.28784
48.02050	251.7703	-18.34947
48.07050	252.7696	-18.41075
48.12216	253.8014	-18.47677
48.17383	254.8320	-18.53914
48.22550	255.8631	-18.61218
48.27716	256.8936	-18.69973
48.32717	257.8920	-18.77966
48.38050	258.9548	-18.86796
48.43050	259.9526	-18.96149
48.48217	260.9821	-19.06382
48.53383	262.0122	-19.17952
48.58383	263.0076	-19.29701
48.63716	264.0699	-19.43629
48.68716	265.0656	-19.57488
48.74050	266.1240	-20.06715
48.79050	267.1144	-20.01677
48.84217	268.1504	-19.99611
48.89383	269.1852	-19.98612
48.94383	270.1859	-19.98448
48.99716	271.2529	-19.98532
49.04716	272.2528	-19.98944
49.10050	273.3196	-20.01202
49.15050	274.3191	-20.04556
49.20216	275.3520	-20.09415
49.25050	276.3175	-20.14320
49.30383	277.2592	-20.25479
49.35383	277.4144	-18.86137
49.40717	277.1444	-14.57574
49.45717	276.6590	-10.21193
49.50883	276.0100	-6.211041
49.56050	275.2580	-3.016077
49.61050	274.4611	-0.6652389
49.66383	273.5620	1.192939
49.71383	272.6838	2.467584
49.76717	271.7216	3.465172
49.81717	270.8000	4.157019
49.86883	269.8345	4.702585
49.92050	268.8574	5.121938
49.97050	267.9037	5.447384
50.02383	266.8788	5.726818
50.07383	265.9140	5.944072
50.12717	264.8778	6.142707
50.17717	263.9046	6.305528
50.22883	262.8940	6.449407
50.28050	261.8818	6.584338
50.33050	260.8991	6.699136
50.38383	259.8496	6.804480
50.43383	258.8645	6.898569
50.48717	257.8120	6.992829
50.53717	256.8229	7.072900
50.58883	255.8006	7.146006
50.64050	254.7780	7.220484
50.69050	253.7874	7.286853
50.74383	252.7294	7.355612
50.79383	251.7379	7.414718
50.84550	250.7120	7.477328
50.89717	249.6864	7.532907
50.94883	248.6592	7.587510
51.00050	247.6335	7.637470
51.05050	246.6388	7.687086
51.10383	245.5792	7.735707
51.15383	244.5857	7.776672
51.20550	243.5583	7.819961
51.25717	242.5309	7.864500
51.30883	241.5027	7.902275
51.36050	240.4745	7.944446
51.41050	239.4791	7.981109
51.46383	238.4183	8.021282
51.51383	237.4227	8.056324
51.56550	236.3938	8.094678
51.61716	235.3650	8.130942
51.66716	234.3687	8.159844
51.72050	233.3069	8.190075
51.77050	232.3105	8.220480
51.82383	231.2485	8.249028
51.87383	230.2526	8.281524
51.92550	229.2246	8.312790
51.97717	228.1951	8.346430
52.02717	227.1994	8.380000
52.08050	226.1371	8.410614
52.13050	225.1408	8.442176
52.18383	224.0786	8.475501
52.23383	223.0823	8.503862
52.28550	222.0528	8.534946
52.33716	221.0238	8.565489
52.38716	220.0276	8.592194
52.44050	218.9640	8.624822
52.49050	217.9678	8.651400
52.54382	216.9045	8.676179
52.59384	215.9084	8.700621
52.64550	214.8794	8.724549
52.69717	213.8494	8.748578
52.74717	212.8525	8.773780
52.80050	211.7906	8.799862
52.85050	210.7935	8.826144
52.90383	209.7308	8.852789
52.95383	208.7347	8.875641
53.00550	207.7048	8.897278
53.05717	206.6751	8.922092
53.10717	205.6798	8.945656
53.16050	204.6160	8.971506
53.21050	203.6198	8.995438
53.26216	202.5885	9.017750
53.31382	201.5594	9.035328
53.36550	200.5290	9.055066
53.41716	199.4992	9.078366
53.46717	198.5029	9.102098
53.52050	197.4396	9.125566
53.57050	196.4429	9.148192
53.62217	195.4140	9.172250
53.67383	194.3843	9.196480
53.72550	193.3552	9.223957
53.77717	192.3260	9.247181
53.82717	191.3295	9.272759
53.88050	190.2671	9.299661
53.93050	189.2708	9.320269
53.98217	188.2401	9.340912
54.03383	187.2102	9.360334
54.08383	186.2141	9.379715
54.13716	185.1498	9.401801
54.18716	184.1531	9.420709
54.24050	183.0900	9.440949
54.29050	182.0927	9.461592
54.34217	181.0633	9.479975
54.39384	180.0327	9.504816
54.44384	179.0365	9.534622
54.49717	177.9738	9.573641
54.54717	176.9778	9.620841
54.60050	175.9153	9.673754
54.65050	174.9206	9.724184
54.70216	173.8917	9.784672
54.75383	172.8639	9.848541
54.80383	171.8686	9.919149
54.85717	170.8088	10.03377
54.90717	169.8178	10.20692
54.96050	168.7677	10.51708
55.01050	167.7897	11.00255
55.06216	166.7928	11.79467
55.11382	165.8121	12.96387
55.16382	164.8836	14.49811
55.21717	163.9123	16.50061
55.26716	163.0148	18.59817
55.32050	162.0622	20.87520
55.37050	161.1659	22.85696
55.42217	160.2271	24.57483
55.47382	159.2666	25.81364
55.52383	158.3114	26.45984
55.57717	157.2627	26.52342
55.62717	156.2506	26.04573
55.67883	155.1822	25.11244
55.73050	154.0962	23.87789
55.78217	153.0002	22.49244
55.83383	151.9004	21.09246
55.88383	150.8374	19.80921
55.93716	149.7094	18.56628
55.98717	148.6570	17.53016
56.03882	147.5770	16.59780
56.09050	146.5038	15.78268
56.14050	145.4698	15.09791
56.19384	144.3725	14.45838
56.24382	143.3470	13.94386
56.29717	142.2586	13.47005
56.34716	141.2405	13.08809
56.39883	140.1904	12.73945
56.45050	139.1442	12.44464
56.50050	138.1324	12.19822
56.55383	137.0558	11.97041
56.60383	136.0481	11.79216
56.65717	134.9758	11.62881
56.70717	133.9702	11.49801
56.75883	132.9334	11.38945
56.81050	131.8968	11.29617
56.86050	130.8943	11.21790
56.91382	129.8271	11.14250
56.96382	128.8254	11.08729
57.01716	127.7574	11.03259
57.06716	126.7563	10.98974
57.11882	125.7229	10.94417
57.17050	124.6890	10.90788
57.22050	123.6884	10.86527
57.27383	122.6212	10.83214
57.32383	121.6215	10.79924
57.37717	120.5546	10.76548
57.42717	119.5555	10.73647
57.47883	118.5221	10.71012
57.53050	117.4893	10.68391
57.58050	116.4903	10.65931
57.63383	115.4238	10.62743
57.68383	114.4234	10.60505
57.73550	113.3926	10.57605
57.78716	112.3588	10.55048
57.83882	111.3261	10.52556
57.89050	110.2936	10.50098
57.94050	109.2938	10.47038
57.99382	108.2274	10.44805
58.04382	107.2282	10.42496
58.09550	106.1961	10.40041
58.14717	105.1634	10.37504
58.19883	104.1305	10.35302
58.25050	103.0979	10.33385
58.30050	102.0986	10.31598
58.35383	101.0328	10.29521
58.40383	100.0337	10.27878
58.45550	99.00106	10.26031
58.50717	97.96878	10.23758
58.55717	96.96949	10.22167
58.61050	95.90326	10.20333
58.66050	94.90453	10.18359
58.71382	93.83882	10.16145
58.76382	92.83892	10.14440
58.81550	91.80741	10.12490
58.86716	90.77434	10.10877
58.91716	89.77641	10.08876
58.97050	88.71016	10.06483
59.02050	87.71121	10.04742
59.07383	86.64572	10.02963
59.12383	85.64718	10.00705
59.17550	84.61551	9.987262
59.22717	83.58407	9.968180
59.27717	82.58544	9.956225
59.33050	81.51982	9.940792
59.38050	80.52039	9.926806
59.43383	79.45532	9.909504
59.48383	78.45678	9.892816
59.53550	77.42485	9.874764
59.58716	76.39349	9.859555
59.63716	75.39456	9.844879
59.69050	74.32895	9.828775
59.74050	73.33030	9.814613
59.79382	72.26455	9.797144
59.84384	71.26580	9.780801
59.89550	70.23324	9.764419
59.94717	69.20078	9.748126
59.99717	68.20150	9.731630
60.05050	67.13668	9.708734
60.10050	66.13672	9.686920
60.15217	65.10461	9.668151
60.20383	64.07142	9.651212
60.25550	63.03914	9.629814
60.30717	62.00727	9.604526
60.35717	61.00742	9.579376
60.41050	59.94213	9.556304
60.46050	58.94238	9.540099
60.51216	57.91042	9.517540
60.56382	56.87795	9.493610
60.61550	55.84481	9.470375
60.66716	54.81295	9.447911
60.71717	53.81374	9.427556
60.77050	52.74724	9.403532
60.82050	51.74807	9.382202
60.87217	50.71578	9.357313
60.92383	49.68256	9.336041
60.97382	48.68457	9.324359
61.02717	47.61715	9.311418
61.07717	46.61862	9.295566
61.13050	45.55188	9.275636
61.18050	44.55344	9.254647
61.23217	43.51958	9.231795
61.28383	42.48606	9.207642
61.33383	41.48628	9.183420
61.38716	40.42067	9.151150
61.43716	39.41925	9.119462
61.49050	38.35306	9.083835
61.54050	37.35306	9.045594
61.59217	36.31824	8.997799
61.64384	35.28437	8.953840
61.69384	34.28486	8.911642
61.74717	33.21622	8.870949
61.79717	32.21452	8.830124
61.85050	31.14694	8.784120
61.90050	30.14606	8.744941
61.95216	29.11111	8.706201
62.00383	28.07705	8.659969
62.05383	27.07588	8.617039
62.10717	26.00793	8.567694
62.15717	25.00600	8.517134
62.21050	23.93738	8.462574
62.26050	22.93490	8.407812
62.31050	22.13180	8.353500
62.36382	22.03519	7.009800
62.41382	22.28020	4.732274
62.46550	22.77696	2.265547
62.51716	23.42586	0.03421244
62.56716	24.15952	-1.741430
62.62050	25.01570	-3.231295
62.67050	25.87106	-4.288492
62.72382	26.81950	-5.134629
62.77383	27.73397	-5.722932
62.82550	28.69776	-6.172509
62.87717	29.67568	-6.511082
62.92717	30.63097	-6.760040
62.98050	31.65678	-6.966350
63.03050	32.62580	-7.127070
63.08217	33.63164	-7.259388
63.13383	34.64060	-7.370661
63.18550	35.65286	-7.469226
63.23717	36.66709	-7.556738
63.28716	37.65089	-7.634828
63.34050	38.70238	-7.712718
63.39050	39.68968	-7.782422
63.44216	40.71036	-7.848009
63.49382	41.73378	-7.914418
63.54550	42.75650	-7.976575
63.59716	43.78128	-8.038822
63.64717	44.77388	-8.097925
63.70050	45.83320	-8.157284
63.75050	46.82614	-8.213004
63.80217	47.85305	-8.269260
63.85383	48.88089	-8.331389
63.90383	49.87562	-8.388324
63.95717	50.93652	-8.446570
64.00718	51.93134	-8.508019
64.06050	52.99370	-8.569562
64.11050	53.99000	-8.627442
64.16217	55.01880	-8.685257
64.21384	56.04861	-8.743376
64.26384	57.04440	-8.799530
64.31717	58.10858	-8.857269
64.36718	59.10520	-8.915056
64.42050	60.16904	-8.974707
64.47050	61.16657	-9.027765
64.52217	62.19672	-9.084924
64.57384	63.22760	-9.142472
64.62383	64.22476	-9.198625
64.67718	65.28982	-9.256119
64.72718	66.28688	-9.307676
64.78050	67.35188	-9.369897
64.83050	68.34822	-9.422975
64.88218	69.37952	-9.482594
64.93384	70.41070	-9.537452
64.98383	71.40894	-9.592261
65.03717	72.47360	-9.652878
65.08716	73.47182	-9.708874
65.14050	74.53755	-9.765112
65.19050	75.53556	-9.817931
65.24218	76.56669	-9.873390
65.29384	77.59810	-9.929739
65.34384	78.59720	-9.987147
65.39717	79.66144	-10.04432
65.44717	80.65928	-10.10078
65.49884	81.69119	-10.16114
65.55050	82.72219	-10.21797
65.60218	83.75384	-10.27892
65.65384	84.78472	-10.33628
65.70384	85.78394	-10.39713
65.75718	86.84842	-10.46134
65.80718	87.84719	-10.52027
65.85884	88.87814	-10.58137
65.91050	89.90966	-10.64452
65.96050	90.90809	-10.70624
66.01384	91.97332	-10.77054
66.06384	92.97078	-10.82785
66.11718	94.03543	-10.88984
66.16718	95.03418	-10.95055
66.21884	96.06546	-11.01376
66.27050	97.09789	-11.07653
66.32050	98.09538	-11.12993
66.37384	99.15929	-11.19632
66.42384	100.1576	-11.25594
66.47718	101.2227	-11.31534
66.52718	102.2206	-11.37575
66.57884	103.2516	-11.43653
66.63050	104.2838	-11.50055
66.68050	105.2820	-11.56118
66.73384	106.3464	-11.62520
66.78384	107.3456	-11.68832
66.83716	108.4096	-11.75320
66.88718	109.4066	-11.81021
66.93884	110.4380	-11.87880
66.99050	111.4693	-11.94654
67.04050	112.4678	-12.01048
67.09384	113.5331	-12.08009
67.14384	114.5304	-12.13675
67.19718	115.5957	-12.19971
67.24718	116.5934	-12.26439
67.29884	117.6256	-12.32374
67.35050	118.6570	-12.38595
67.40050	119.6554	-12.45040
67.45384	120.7208	-12.52066
67.50384	121.7181	-12.58538
67.55550	122.7498	-12.65434
67.60718	123.7807	-12.72100
67.65884	124.8107	-12.79234
67.71050	125.8421	-12.86383
67.76050	126.8393	-12.93199
67.81384	127.9042	-13.00168
67.86384	128.9015	-13.07028
67.91550	129.9331	-13.14063
67.96718	130.9639	-13.21070
68.01882	131.9944	-13.28763
68.07050	133.0253	-13.35989
68.12050	134.0238	-13.43420
68.17384	135.0882	-13.51177
68.22384	136.0864	-13.58719
68.27550	137.1185	-13.66044
68.32718	138.1492	-13.73802
68.37718	139.1470	-13.81261
68.43050	140.2113	-13.89224
68.48050	141.2090	-13.97276
68.53384	142.2724	-14.05551
68.58384	143.2700	-14.13683
68.63550	144.3010	-14.21552
68.68718	145.3319	-14.29699
68.73718	146.3287	-14.37360
68.79050	147.3929	-14.45994
68.84050	148.3895	-14.53944
68.89384	149.4537	-14.62815
68.94384	150.4509	-14.70519
68.99550	151.4822	-14.79062
69.04718	152.5128	-14.87404
69.09718	153.5102	-14.95517
69.15050	154.5730	-15.04257
69.20050	155.5709	-15.12910
69.25384	156.6336	-15.21501
69.30384	157.6315	-15.29819
69.35550	158.6622	-15.38138
69.40718	159.6924	-15.46056
69.45718	160.6892	-15.53129
69.51050	161.7544	-15.60445
69.56050	162.7530	-15.67114
69.61384	163.8192	-15.72769
69.66382	164.8186	-15.77763
69.71550	165.8502	-15.82086
69.76716	166.8834	-15.86682
69.81718	167.8828	-15.90525
69.87050	168.9490	-15.94504
69.92050	169.9479	-16.00702
69.97218	170.9799	-16.06806
70.02384	172.0117	-16.13132
70.07550	173.0434	-16.20613
70.12718	174.0746	-16.28079
70.17718	175.0720	-16.36113
70.23050	176.1354	-16.45508
70.28050	177.1322	-16.55713
70.33218	178.1617	-16.67085
70.38384	179.1903	-16.79421
70.43550	180.2184	-16.93316
70.48718	181.2456	-17.08750
70.53718	182.2389	-17.25266
70.59050	183.2976	-17.45008
70.64050	184.2899	-17.65464
70.69218	185.3141	-17.88915
70.74384	186.3371	-18.14384
70.79384	187.3263	-18.41432
70.84718	188.3806	-18.73662
70.89718	189.3658	-19.07012
70.95050	190.4161	-19.46528
71.00050	191.3986	-19.86871
71.05218	192.4122	-20.32006
71.10384	193.4248	-20.79921
71.15384	194.4038	-21.28198
71.20718	195.4470	-21.80612
71.25718	196.4244	-22.30095
71.31050	197.4674	-22.85586
71.36050	198.4445	-23.39455
71.41218	199.4518	-23.98775
71.46384	200.4571	-24.62692
71.51384	201.4278	-25.29163
71.56718	202.4619	-26.04292
71.61718	203.4307	-26.75444
71.67050	204.4652	-27.46534
71.72050	205.4381	-28.01185
71.77218	206.4542	-28.34804
71.82384	207.4844	-28.31762
71.87384	208.5016	-27.81888
71.92718	209.6125	-26.69130
71.97718	210.6794	-25.10481
72.03050	211.8377	-23.08479
72.08050	212.9255	-21.29591
72.13218	214.0331	-19.87883
72.18384	215.1212	-18.88059
72.23384	216.1574	-18.20832
72.28718	217.2523	-17.72458
72.33716	218.2696	-17.42645
72.38884	219.3146	-17.22511
72.44050	220.3554	-17.09854
72.49218	221.3942	-17.03002
72.54384	222.4316	-17.00205
72.59384	223.4336	-16.99330
72.64718	224.5028	-16.99085
72.69718	225.5022	-16.99318
72.74884	226.5370	-17.00295
72.80050	227.5691	-17.03387
72.85050	228.5697	-17.06341
72.90384	229.6365	-17.11089
72.95384	230.6363	-17.15639
73.00718	231.7028	-17.19955
73.05718	232.7007	-17.25061
73.10884	233.7334	-17.29759
73.16050	234.7659	-17.34428
73.21050	235.7662	-17.39767
73.26384	236.8321	-17.44092
73.31384	237.8315	-17.48162
73.36718	238.8974	-17.52816
73.41718	239.8964	-17.57217
73.46884	240.9284	-17.62243
73.52050	241.9615	-17.67603
73.57050	242.9608	-17.72787
73.62384	244.0264	-17.78477
73.67384	245.0252	-17.82986
73.72718	246.0904	-17.88056
73.77718	247.0910	-17.92985
73.82884	248.1230	-17.97332
73.88050	249.1557	-18.02160
73.93050	250.1549	-18.06760
73.98384	251.2202	-18.11692
74.03384	252.2190	-18.16878
74.08716	253.2844	-18.22059
74.13718	254.2833	-18.26846
74.18884	255.3157	-18.31837
74.24050	256.3481	-18.37216
74.29050	257.3472	-18.42598
74.34384	258.4124	-18.47906
74.39384	259.4110	-18.53478
74.44550	260.4432	-18.59393
74.49718	261.4746	-18.64682
74.54884	262.5064	-18.70285
74.60050	263.5386	-18.76279
74.65050	264.5377	-18.81709
74.70384	265.6030	-18.87908
74.75384	266.6016	-18.93424
74.80550	267.6343	-18.99258
74.85718	268.6652	-19.05045
74.90884	269.6966	-19.11242
74.96050	270.7290	-19.17066
75.01050	271.7274	-19.22036
75.06384	272.7927	-19.28309
-2.000000	5.000000	0.0000000