File: 9-C1(1.2mol%)+C20(1.0mol%)/matlab/130-2.txt
CLOSED
Version	1.0
Language	English
Mode	Standard
Run	2
RunSerial	12270
Instrument	DSC Q2000 V24.11 Build 124
Module	DSC Standard Cell RC
Operator
File	\\AE520-1454\Users\dsc\Desktop\Data\29-08-17\130-2.001
ProcName
InstSerial	2000-0883
AutoSerial	1293
Sample	130-2
Size	19.7000	mg
PanMass	Not available
PanResist	Automatic Automatic  K/W
PanFactor	Default Default
Method
Comment
Xcomment	Pan: Tzero Aluminum Hermetic
Xcomment	Gas1: Nitrogen 50.0 ml/min
Xcomment	Gas2: Nitrogen 50.0 ml/min
Text
Exotherm	UP
Kcell	1.05230
Cpconst	Standard: 0.938
Calib	-38.6961
TempCal	1	pts	157.46	156.60
TzeroDt	-87.6168 -0.0009 -1.4231
TzeroDtz	-87.6168 0.0057 6.9570
InstCalFile	Tzero: \\Ae520-1454\ta\Data\DSC\Calibration\2017\CALIBRATION\1562_RCS (90)_05_18_2017 10_50_44.TZR
InstCalFile	Baseline: \\Ae520-1454\ta\Data\DSC\Calibration\2017\2017-05-17_Calibration.001
InstCalFile	Sapphire: \\Ae520-1454\ta\Data\DSC\Calibration\2017\2017-05-17_Saphire.001
InstCalDate	Tzero 2017-05-18 Time 10:50:44
TempRange	-87.39 to 398.39 °C at 10.00 °C/min Heat Only
AutoZero	Delta T Offset 0.000 uV
AutoZero	Delta T0 Offset 0.000 uV
MultiptCal	0
MultiPtDesc	0) Not set
AutoCellConst	Calibration Date 2017-05-18 16:59:28
Controls	Gas 1  Event Off  Sampling 0.2
Cell#	RC-01562
CoolingUnit	RCS (90)
SelHeatFlow	Heat Flow T4P (mW)
AutoLidII	Installed
AutoAnalysis	Off
MacroFile
Nsig	3
Sig1	Time (min)
Sig2	Temperature (°C)
Sig3	Heat Flow (mW)
Date	2017-08-29
Time	12:40:47
OrgMethod	1: Equilibrate at 80.00 °C
OrgMethod	2: Isothermal for 3.00 min
OrgMethod	3: Jump to 130.00 °C
OrgMethod	4: Mark end of cycle 1
OrgMethod	5: Isothermal for 40.00 min
OrgMethod	6: Mark end of cycle 2
OrgMethod	7: Ramp 20.00 °C/min to 280.00 °C
OrgMethod	8: Mark end of cycle 3
OrgMethod	9: Ramp 20.00 °C/min to 20.00 °C
OrgMethod	10: Mark end of cycle 4
OrgMethod	11: Ramp 20.00 °C/min to 280.00 °C
OrgMethod	12: Mark end of cycle 5
OrgFile	C:\Users\jarra\Desktop\DSC\9-C1(1.2mol%)+C20(1.0mol%)\130-2.001
StartOfData
4.99994E-4	79.23001	-9.947376
0.05383332	79.35906	-8.218310
0.1071666	79.46484	-6.806339
0.1588333	79.55035	-5.680880
0.2105000	79.61752	-4.755914
0.2638334	79.67657	-3.970309
0.3155000	79.72242	-3.348160
0.3671667	79.75934	-2.832158
0.4205000	79.79078	-2.397474
0.4721666	79.81566	-2.051004
0.5238333	79.83453	-1.764613
0.5771668	79.85176	-1.521671
0.6305000	79.86510	-1.326196
0.6805000	79.87503	-1.175205
0.7338332	79.88394	-1.040909
0.7871668	79.89053	-0.9321908
0.8371668	79.89544	-0.8515874
0.8904999	79.89918	-0.7788868
0.9438332	79.90376	-0.7211340
0.9955000	79.90476	-0.6782907
1.047167	79.90728	-0.6417441
1.100500	79.90824	-0.6121086
1.152167	79.90900	-0.5900204
1.203834	79.90947	-0.5726838
1.257166	79.90939	-0.5588282
1.308833	79.91019	-0.5490002
1.360500	79.91046	-0.5413584
1.413834	79.91012	-0.5356754
1.465500	79.91011	-0.5310150
1.517167	79.90828	-0.5262640
1.570500	79.90920	-0.5212604
1.623833	79.90734	-0.5161757
1.673834	79.90740	-0.5114186
1.727167	79.90668	-0.5064194
1.780500	79.90532	-0.5015140
1.830500	79.90514	-0.4970166
1.883833	79.90520	-0.4923791
1.937166	79.90297	-0.4878523
1.988833	79.90280	-0.4836144
2.040500	79.90150	-0.4795617
2.093834	79.90122	-0.4755184
2.145500	79.90093	-0.4718338
2.197166	79.89932	-0.4682796
2.250500	79.89891	-0.4647770
2.302166	79.89924	-0.4615396
2.353833	79.89781	-0.4584563
2.407167	79.89714	-0.4554170
2.458833	79.89618	-0.4525963
2.510500	79.89654	-0.4499193
2.563833	79.89520	-0.4472906
2.617167	79.89397	-0.4448180
2.667167	79.89372	-0.4426813
2.720500	79.89325	-0.4405594
2.773833	79.89350	-0.4385918
2.823833	79.89205	-0.4367928
2.877167	79.89098	-0.4350112
2.930500	79.89119	-0.4333691
2.982167	79.89112	-0.4318801
3.030500	79.98681	-0.4521168
3.082167	82.19868	2.038816
3.133833	85.52919	0.2461633
3.187167	89.18734	-4.632080
3.238834	92.96715	-10.48039
3.290500	96.92520	-16.57704
3.343834	101.1585	-22.62213
3.397167	105.5096	-28.16828
3.447167	109.6730	-32.80395
3.500500	114.1834	-37.08568
3.553833	118.4303	-41.32522
3.603833	120.6035	-45.98022
3.657167	122.0326	-46.17302
3.710500	123.1828	-43.23801
3.762167	124.0934	-38.89834
3.813833	124.8651	-34.12045
3.867166	125.5393	-29.29248
3.918833	126.0963	-25.01482
3.970500	126.5727	-21.23516
4.023834	126.9928	-17.87188
4.075500	127.3411	-15.10703
4.127167	127.6410	-12.78031
4.180500	127.9077	-10.76580
4.232167	128.1301	-9.140008
4.283834	128.3220	-7.783503
4.337167	128.4952	-6.626038
4.390500	128.6437	-5.662799
4.440500	128.7651	-4.910486
4.493834	128.8782	-4.241944
4.547167	128.9767	-3.691594
4.597166	129.0574	-3.257385
4.650500	129.1330	-2.873560
4.703833	129.1985	-2.551056
4.755500	129.2535	-2.294549
4.807167	129.3043	-2.082502
4.860500	129.3486	-1.901809
4.912167	129.3874	-1.759848
4.963834	129.4211	-1.641348
5.017166	129.4524	-1.540125
5.068833	129.4800	-1.459067
5.120500	129.5038	-1.395752
5.173834	129.5262	-1.342257
5.225500	129.5453	-1.299698
5.277168	129.5629	-1.266522
5.330500	129.5790	-1.239171
5.383832	129.5930	-1.218131
5.433832	129.6060	-1.202834
5.487168	129.6172	-1.190289
5.540500	129.6287	-1.180680
5.590500	129.6384	-1.174195
5.643832	129.6465	-1.168884
5.697168	129.6552	-1.164094
5.748834	129.6622	-1.159282
5.800500	129.6685	-1.154385
5.853832	129.6754	-1.149292
5.905500	129.6813	-1.144362
5.957168	129.6870	-1.139434
6.010500	129.6913	-1.134439
6.062168	129.6956	-1.129659
6.113834	129.7006	-1.125025
6.167168	129.7052	-1.120344
6.220500	129.7091	-1.115742
6.270500	129.7119	-1.111550
6.323834	129.7160	-1.107154
6.377168	129.7190	-1.102854
6.427168	129.7215	-1.098949
6.480500	129.7251	-1.094916
6.533832	129.7268	-1.090965
6.585500	129.7293	-1.087276
6.637168	129.7316	-1.083645
6.690500	129.7339	-1.080001
6.742166	129.7358	-1.076512
6.793832	129.7391	-1.073089
6.847168	129.7392	-1.069632
6.898834	129.7410	-1.066245
6.950500	129.7425	-1.062897
7.003832	129.7445	-1.059468
7.055500	129.7461	-1.056196
7.107168	129.7460	-1.052948
7.160500	129.7488	-1.049593
7.213834	129.7505	-1.046308
7.263834	129.7510	-1.043201
7.317168	129.7521	-1.039933
7.370500	129.7529	-1.036684
7.420500	129.7540	-1.033669
7.473834	129.7560	-1.030493
7.527168	129.7566	-1.027299
7.578834	129.7579	-1.024201
7.630500	129.7577	-1.021114
7.683832	129.7596	-1.017893
7.735500	129.7596	-1.014756
7.787168	129.7604	-1.011641
7.840500	129.7614	-1.008419
7.892168	129.7624	-1.005313
7.943832	129.7628	-1.002171
7.997168	129.7648	-0.9989582
8.048834	129.7648	-0.9958070
8.100500	129.7654	-0.9926397
8.153832	129.7663	-0.9892882
8.207168	129.7664	-0.9860000
8.257168	129.7675	-0.9829028
8.310500	129.7675	-0.9795706
8.363834	129.7684	-0.9762542
8.413834	129.7690	-0.9730684
8.467168	129.7688	-0.9696206
8.520500	129.7702	-0.9661616
8.572168	129.7703	-0.9627770
8.623834	129.7705	-0.9593758
8.677168	129.7713	-0.9558157
8.728834	129.7720	-0.9523371
8.780500	129.7714	-0.9488160
8.833832	129.7724	-0.9451641
8.885499	129.7730	-0.9415658
8.937166	129.7740	-0.9380016
8.990500	129.7744	-0.9343366
9.042168	129.7752	-0.9307751
9.093832	129.7756	-0.9272392
9.147168	129.7757	-0.9235419
9.200500	129.7765	-0.9198254
9.250500	129.7765	-0.9163329
9.303832	129.7778	-0.9125570
9.357166	129.7768	-0.9086956
9.407166	129.7782	-0.9050951
9.460499	129.7788	-0.9012421
9.513832	129.7791	-0.8973312
9.565500	129.7795	-0.8935546
9.617166	129.7797	-0.8897919
9.670500	129.7802	-0.8859112
9.722168	129.7803	-0.8821934
9.773834	129.7819	-0.8784094
9.827168	129.7814	-0.8744696
9.878834	129.7825	-0.8706209
9.930500	129.7822	-0.8667469
9.983832	129.7817	-0.8626825
10.03550	129.7836	-0.8587897
10.08717	129.7838	-0.8548321
10.14050	129.7835	-0.8507155
10.19383	129.7848	-0.8465644
10.24383	129.7844	-0.8426220
10.29717	129.7847	-0.8383934
10.35050	129.7848	-0.8341556
10.40050	129.7854	-0.8301725
10.45383	129.7863	-0.8258898
10.50717	129.7869	-0.8216040
10.55884	129.7867	-0.8173962
10.61050	129.7872	-0.8131994
10.66383	129.7880	-0.8088020
10.71550	129.7884	-0.8045380
10.76717	129.7880	-0.8002444
10.82050	129.7889	-0.7957520
10.87217	129.7897	-0.7914126
10.92383	129.7896	-0.7870150
10.97717	129.7904	-0.7824179
11.03050	129.7913	-0.7777789
11.08050	129.7911	-0.7733570
11.13383	129.7918	-0.7686054
11.18716	129.7920	-0.7638328
11.23717	129.7927	-0.7593088
11.29050	129.7928	-0.7544250
11.34383	129.7934	-0.7494731
11.39550	129.7940	-0.7446022
11.44717	129.7944	-0.7396548
11.50050	129.7957	-0.7344459
11.55216	129.7952	-0.7292870
11.60383	129.7958	-0.7240138
11.65717	129.7963	-0.7184600
11.70883	129.7969	-0.7129431
11.76050	129.7972	-0.7072930
11.81383	129.7973	-0.7012584
11.86550	129.7988	-0.6952940
11.91717	129.7993	-0.6891593
11.97050	129.8002	-0.6826490
12.02383	129.8009	-0.6758688
12.07383	129.8012	-0.6692024
12.12717	129.8025	-0.6619126
12.18050	129.8040	-0.6542022
12.23050	129.8045	-0.6465839
12.28383	129.8054	-0.6376228
12.33717	129.8070	-0.6279832
12.38883	129.8072	-0.6166996
12.44050	129.8081	-0.6033457
12.49384	129.8098	-0.5881492
12.54550	129.8114	-0.5723199
12.59717	129.8128	-0.5535711
12.65050	129.8143	-0.5314947
12.70217	129.8162	-0.5098174
12.75384	129.8166	-0.4857971
12.80717	129.8189	-0.4598383
12.85883	129.8206	-0.4331894
12.91050	129.8215	-0.4054034
12.96383	129.8231	-0.3745134
13.01717	129.8249	-0.3440520
13.06716	129.8274	-0.3151365
13.12050	129.8293	-0.2849815
13.17383	129.8316	-0.2532560
13.22383	129.8329	-0.2233422
13.27717	129.8348	-0.1917323
13.33050	129.8365	-0.1612456
13.38216	129.8389	-0.1316128
13.43383	129.8406	-0.1023044
13.48716	129.8425	-.07115224
13.53883	129.8440	-.04126122
13.59050	129.8459	-.01235923
13.64383	129.8479	0.01673805
13.69550	129.8498	0.04316290
13.74717	129.8525	0.06929687
13.80050	129.8544	0.09727556
13.85217	129.8558	0.1225172
13.90383	129.8575	0.1482494
13.95717	129.8591	0.1731910
14.01050	129.8609	0.1975606
14.06050	129.8627	0.2211488
14.11383	129.8649	0.2428754
14.16716	129.8659	0.2658002
14.21716	129.8677	0.2864820
14.27050	129.8700	0.3080268
14.32384	129.8703	0.3284985
14.37550	129.8720	0.3480533
14.42717	129.8741	0.3669313
14.48050	129.8752	0.3847276
14.53217	129.8770	0.4026213
14.58383	129.8778	0.4205463
14.63717	129.8798	0.4382068
14.68883	129.8805	0.4542377
14.74050	129.8812	0.4710817
14.79384	129.8829	0.4883379
14.84550	129.8849	0.5028150
14.89717	129.8862	0.5177473
14.95050	129.8870	0.5334770
15.00383	129.8892	0.5489210
15.05383	129.8894	0.5640671
15.10716	129.8904	0.5805426
15.16050	129.8916	0.5947094
15.21050	129.8931	0.6091236
15.26383	129.8944	0.6240058
15.31716	129.8960	0.6392844
15.36884	129.8970	0.6553070
15.42050	129.8986	0.6718501
15.47383	129.8991	0.6888314
15.52550	129.9004	0.7048114
15.57717	129.9022	0.7211220
15.63050	129.9027	0.7381022
15.68217	129.9041	0.7546838
15.73383	129.9051	0.7722212
15.78717	129.9063	0.7899594
15.84050	129.9077	0.8075902
15.89050	129.9081	0.8251059
15.94384	129.9106	0.8429957
15.99717	129.9118	0.8614845
16.04716	129.9125	0.8793595
16.10050	129.9141	0.8994431
16.15383	129.9152	0.9192813
16.20550	129.9168	0.9393303
16.25716	129.9168	0.9583918
16.31050	129.9193	0.9785295
16.36216	129.9199	0.9983681
16.41383	129.9216	1.019287
16.46716	129.9236	1.040449
16.51883	129.9238	1.062328
16.57050	129.9266	1.083491
16.62383	129.9271	1.106249
16.67550	129.9286	1.127708
16.72716	129.9298	1.149636
16.78050	129.9320	1.170516
16.83383	129.9334	1.193460
16.88383	129.9347	1.217074
16.93716	129.9359	1.241660
16.99050	129.9369	1.266352
17.04050	129.9396	1.289428
17.09383	129.9412	1.314560
17.14716	129.9421	1.340169
17.19884	129.9438	1.364256
17.25050	129.9455	1.388939
17.30383	129.9469	1.414516
17.35550	129.9495	1.439191
17.40716	129.9502	1.464246
17.46050	129.9522	1.490323
17.51216	129.9541	1.514312
17.56383	129.9558	1.539996
17.61716	129.9581	1.566754
17.66883	129.9581	1.592789
17.72050	129.9604	1.618916
17.77383	129.9618	1.646119
17.82716	129.9643	1.672702
17.87716	129.9654	1.697401
17.93050	129.9680	1.723886
17.98383	129.9688	1.750756
18.03383	129.9721	1.774181
18.08716	129.9734	1.799766
18.14050	129.9748	1.824471
18.19216	129.9768	1.849626
18.24383	129.9784	1.873929
18.29716	129.9804	1.898428
18.34883	129.9822	1.922673
18.40050	129.9842	1.946309
18.45383	129.9858	1.969455
18.50550	129.9873	1.991717
18.55716	129.9887	2.012789
18.61050	129.9899	2.034365
18.66217	129.9907	2.054844
18.71383	129.9921	2.074773
18.76716	129.9950	2.093949
18.82050	129.9958	2.113432
18.87050	129.9973	2.130028
18.92383	129.9982	2.146660
18.97716	130.0002	2.161869
19.02716	130.0009	2.175518
19.08050	130.0020	2.189778
19.13383	130.0033	2.203450
19.18550	130.0035	2.215562
19.23716	130.0039	2.226480
19.29050	130.0060	2.236821
19.34216	130.0066	2.246672
19.39383	130.0076	2.255890
19.44716	130.0086	2.265060
19.49883	130.0092	2.273960
19.55050	130.0093	2.282804
19.60383	130.0097	2.292063
19.65550	130.0113	2.301047
19.70716	130.0110	2.310023
19.76050	130.0114	2.319277
19.81383	130.0129	2.328517
19.86383	130.0126	2.337142
19.91716	130.0146	2.346237
19.97050	130.0140	2.355338
20.02050	130.0147	2.363762
20.07383	130.0157	2.372622
20.12716	130.0154	2.381386
20.17883	130.0164	2.389755
20.23050	130.0169	2.398053
20.28383	130.0167	2.406514
20.33550	130.0181	2.414740
20.38716	130.0187	2.422894
20.44050	130.0194	2.431218
20.49216	130.0190	2.439240
20.54383	130.0198	2.447169
20.59716	130.0200	2.455316
20.65050	130.0209	2.463480
20.70050	130.0207	2.471105
20.75383	130.0221	2.479215
20.80716	130.0230	2.487295
20.85716	130.0237	2.494861
20.91050	130.0238	2.502944
20.96383	130.0239	2.511046
21.01550	130.0246	2.518894
21.06716	130.0250	2.526765
21.12050	130.0258	2.534941
21.17216	130.0266	2.542836
21.22383	130.0261	2.550742
21.27717	130.0280	2.558946
21.32883	130.0279	2.566953
21.38050	130.0293	2.575015
21.43383	130.0294	2.583385
21.48550	130.0302	2.591524
21.53717	130.0309	2.599754
21.59050	130.0314	2.608301
21.64383	130.0324	2.616872
21.69383	130.0329	2.624941
21.74716	130.0338	2.633646
21.80050	130.0343	2.642464
21.85050	130.0347	2.650774
21.90383	130.0356	2.659651
21.95717	130.0361	2.668610
22.00883	130.0366	2.677307
22.06050	130.0374	2.686138
22.11383	130.0386	2.695262
22.16550	130.0390	2.704187
22.21716	130.0386	2.713126
22.27050	130.0398	2.722382
22.32216	130.0417	2.731344
22.37383	130.0412	2.740314
22.42717	130.0420	2.749654
22.47883	130.0426	2.758715
22.53050	130.0430	2.767746
22.58383	130.0443	2.777018
22.63716	130.0446	2.786296
22.68716	130.0452	2.794974
22.74050	130.0466	2.804232
22.79383	130.0464	2.813455
22.84383	130.0468	2.822052
22.89716	130.0481	2.831173
22.95050	130.0476	2.840240
23.00217	130.0487	2.848954
23.05383	130.0490	2.857699
23.10716	130.0506	2.866522
23.15883	130.0506	2.874998
23.21050	130.0509	2.883386
23.26383	130.0518	2.891910
23.31550	130.0517	2.900050
23.36716	130.0522	2.907993
23.42050	130.0529	2.916059
23.47216	130.0530	2.923699
23.52383	130.0537	2.931135
23.57716	130.0536	2.938673
23.63050	130.0543	2.945974
23.68050	130.0538	2.952606
23.73383	130.0534	2.959500
23.78717	130.0538	2.966135
23.83716	130.0532	2.972089
23.89050	130.0537	2.978137
23.94383	130.0544	2.983900
23.99550	130.0543	2.989225
24.04716	130.0541	2.994288
24.10050	130.0541	2.999185
24.15216	130.0538	3.003594
24.20383	130.0538	3.007639
24.25716	130.0531	3.011490
24.30883	130.0538	3.014841
24.36050	130.0529	3.017841
24.41383	130.0529	3.020559
24.46550	130.0531	3.022789
24.51716	130.0528	3.024654
24.57050	130.0524	3.026319
24.62383	130.0513	3.027575
24.67383	130.0511	3.028375
24.72716	130.0514	3.028821
24.78050	130.0510	3.028834
24.83050	130.0494	3.028486
24.88383	130.0509	3.027666
24.93716	130.0489	3.026404
24.98883	130.0487	3.024774
25.04050	130.0487	3.022804
25.09383	130.0477	3.020350
25.14550	130.0470	3.017584
25.19716	130.0465	3.014378
25.25050	130.0458	3.010658
25.30217	130.0444	3.006655
25.35383	130.0446	3.002216
25.40716	130.0431	2.997263
25.46050	130.0419	2.991912
25.51050	130.0416	2.986494
25.56383	130.0411	2.980206
25.61716	130.0399	2.973138
25.66716	130.0392	2.966213
25.72050	130.0379	2.958407
25.77383	130.0375	2.950088
25.82550	130.0360	2.941289
25.87716	130.0358	2.932275
25.93050	130.0344	2.921881
25.98216	130.0332	2.911513
26.03383	130.0324	2.899864
26.08716	130.0316	2.888196
26.13883	130.0303	2.875694
26.19050	130.0294	2.863485
26.24383	130.0291	2.849912
26.29550	130.0269	2.837480
26.34716	130.0268	2.824358
26.40050	130.0248	2.811228
26.45383	130.0242	2.796892
26.50383	130.0228	2.782475
26.55716	130.0214	2.768301
26.61050	130.0202	2.752415
26.66050	130.0203	2.738690
26.71383	130.0186	2.722718
26.76716	130.0172	2.707676
26.81883	130.0161	2.692334
26.87050	130.0156	2.677484
26.92383	130.0137	2.661452
26.97550	130.0129	2.646741
27.02717	130.0125	2.631128
27.08050	130.0112	2.615385
27.13216	130.0096	2.600216
27.18383	130.0089	2.584844
27.23716	130.0077	2.568648
27.28883	130.0064	2.553595
27.34050	130.0062	2.537592
27.39383	130.0045	2.521297
27.44717	130.0029	2.504509
27.49716	130.0029	2.489449
27.55050	130.0018	2.473120
27.60383	130.0006	2.457622
27.65383	130.0000	2.442902
27.70716	129.9985	2.428775
27.76050	129.9967	2.414312
27.81217	129.9966	2.399901
27.86383	129.9956	2.385947
27.91716	129.9942	2.371594
27.96883	129.9934	2.358038
28.02050	129.9926	2.344018
28.07383	129.9916	2.330236
28.12550	129.9902	2.316908
28.17717	129.9894	2.303690
28.23050	129.9885	2.290047
28.28216	129.9868	2.276467
28.33383	129.9869	2.263320
28.38716	129.9855	2.248958
28.44050	129.9845	2.235412
28.49050	129.9831	2.223708
28.54383	129.9821	2.211132
28.59716	129.9817	2.199298
28.64716	129.9815	2.188000
28.70050	129.9802	2.175539
28.75383	129.9786	2.163664
28.80550	129.9774	2.151480
28.85716	129.9772	2.138821
28.91050	129.9756	2.126258
28.96216	129.9750	2.114344
29.01383	129.9745	2.101901
29.06716	129.9736	2.089448
29.11883	129.9724	2.077534
29.17050	129.9717	2.065737
29.22383	129.9712	2.053632
29.27550	129.9706	2.041386
29.32717	129.9699	2.029363
29.38050	129.9677	2.017613
29.43383	129.9675	2.005499
29.48383	129.9673	1.994172
29.53717	129.9663	1.982025
29.59050	129.9650	1.969926
29.64050	129.9652	1.958616
29.69383	129.9634	1.946495
29.74716	129.9627	1.934390
29.79883	129.9627	1.922996
29.85050	129.9620	1.911507
29.90383	129.9611	1.899821
29.95550	129.9599	1.888417
30.00716	129.9595	1.877036
30.06050	129.9587	1.865410
30.11216	129.9578	1.854168
30.16383	129.9575	1.842861
30.21716	129.9563	1.831354
30.27050	129.9556	1.819871
30.32050	129.9548	1.809128
30.37383	129.9536	1.797501
30.42717	129.9533	1.786121
30.47717	129.9526	1.775500
30.53050	129.9522	1.764171
30.58383	129.9510	1.752912
30.63550	129.9502	1.742066
30.68717	129.9480	1.731134
30.74050	129.9485	1.720039
30.79216	129.9480	1.709292
30.84383	129.9468	1.698572
30.89716	129.9458	1.687582
30.94883	129.9457	1.676932
31.00050	129.9454	1.666322
31.05383	129.9452	1.655440
31.10550	129.9437	1.644883
31.15716	129.9431	1.634399
31.21050	129.9421	1.623588
31.26383	129.9425	1.612759
31.31383	129.9408	1.602682
31.36716	129.9406	1.591968
31.42050	129.9397	1.581272
31.47050	129.9389	1.571275
31.52383	129.9380	1.560682
31.57717	129.9373	1.550111
31.62883	129.9372	1.539899
31.68050	129.9360	1.529699
31.73383	129.9356	1.519237
31.78550	129.9342	1.509162
31.83716	129.9346	1.499092
31.89050	129.9328	1.488701
31.94216	129.9326	1.478683
31.99383	129.9316	1.468752
32.04716	129.9322	1.458462
32.09883	129.9303	1.448518
32.15050	129.9300	1.438631
32.20383	129.9301	1.428446
32.25716	129.9295	1.418317
32.30716	129.9277	1.408845
32.36050	129.9285	1.398766
32.41383	129.9268	1.388650
32.46383	129.9264	1.379197
32.51716	129.9269	1.369108
32.57050	129.9254	1.359074
32.62216	129.9248	1.349348
32.67383	129.9244	1.339653
32.72717	129.9236	1.329640
32.77883	129.9231	1.319983
32.83050	129.9220	1.310344
32.88383	129.9224	1.300424
32.93550	129.9208	1.290787
32.98717	129.9204	1.281238
33.04050	129.9202	1.271398
33.09216	129.9193	1.261901
33.14383	129.9191	1.252404
33.19717	129.9188	1.242602
33.25050	129.9175	1.232826
33.30050	129.9168	1.223740
33.35383	129.9164	1.214060
33.40716	129.9154	1.204348
33.45716	129.9141	1.195269
33.51050	129.9136	1.185612
33.56383	129.9137	1.175856
33.61550	129.9125	1.166498
33.66716	129.9119	1.157106
33.72050	129.9118	1.147412
33.77217	129.9105	1.138067
33.82383	129.9098	1.128692
33.87717	129.9098	1.119061
33.92883	129.9088	1.109737
33.98050	129.9080	1.100359
34.03383	129.9068	1.090666
34.08550	129.9072	1.081303
34.13716	129.9067	1.071920
34.19050	129.9057	1.062259
34.24383	129.9051	1.052579
34.29383	129.9045	1.043515
34.34716	129.9040	1.033882
34.40050	129.9033	1.024272
34.45050	129.9028	1.015265
34.50383	129.9011	1.005681
34.55716	129.9009	0.9960778
34.60883	129.8994	0.9867455
34.66050	129.9006	0.9774361
34.71383	129.8996	0.9677759
34.76550	129.8979	0.9584634
34.81716	129.8976	0.9491020
34.87050	129.8977	0.9394144
34.92216	129.8962	0.9300689
34.97383	129.8950	0.9207012
35.02716	129.8953	0.9110406
35.08050	129.8943	0.9013390
35.13050	129.8941	0.8921974
35.18384	129.8927	0.8824844
35.23717	129.8926	0.8726482
35.28717	129.8919	0.8633986
35.34050	129.8902	0.8535384
35.39383	129.8906	0.8436128
35.44550	129.8892	0.8340032
35.49716	129.8884	0.8243328
35.55050	129.8894	0.8143084
35.60217	129.8872	0.8045696
35.65383	129.8876	0.7947719
35.70716	129.8852	0.7846018
35.75883	129.8857	0.7747412
35.81050	129.8835	0.7648203
35.86383	129.8833	0.7545810
35.91550	129.8826	0.7446036
35.96716	129.8812	0.7344832
36.02050	129.8811	0.7237689
36.07383	129.8799	0.7133189
36.12383	129.8793	0.7032758
36.17717	129.8794	0.6925806
36.23050	129.8777	0.6818730
36.28050	129.8783	0.6717097
36.33383	129.8761	0.6605681
36.38716	129.8748	0.6490792
36.43883	129.8751	0.6382326
36.49050	129.8728	0.6271836
36.54383	129.8726	0.6155087
36.59550	129.8723	0.6037176
36.64717	129.8712	0.5925002
36.70050	129.8704	0.5803284
36.75217	129.8694	0.5683206
36.80383	129.8684	0.5556208
36.85716	129.8683	0.5431558
36.90883	129.8674	0.5302622
36.96050	129.8657	0.5176285
37.01383	129.8660	0.5033465
37.06716	129.8643	0.4889649
37.11716	129.8631	0.4757186
37.17050	129.8616	0.4613762
37.22383	129.8608	0.4463726
37.27383	129.8601	0.4321670
37.32717	129.8596	0.4170072
37.38050	129.8578	0.4017114
37.43216	129.8574	0.3866842
37.48383	129.8556	0.3701580
37.53717	129.8554	0.3543236
37.58883	129.8534	0.3376722
37.64050	129.8522	0.3197364
37.69383	129.8521	0.3012855
37.74550	129.8502	0.2842504
37.79716	129.8494	0.2670082
37.85050	129.8472	0.2484749
37.90216	129.8472	0.2303945
37.95383	129.8460	0.2118554
38.00716	129.8442	0.1924893
38.06050	129.8439	0.1739360
38.11050	129.8424	0.1556361
38.16383	129.8421	0.1367220
38.21716	129.8402	0.1176970
38.26716	129.8391	0.1011949
38.32050	129.8386	0.08223200
38.37383	129.8369	0.06325168
38.42550	129.8358	0.04614283
38.47717	129.8343	0.02681914
38.53050	129.8334	.008003582
38.58216	129.8317	-9.1711E-3
38.63383	129.8313	-.02761221
38.68716	129.8304	-.04552750
38.73883	129.8281	-.06235301
38.79050	129.8274	-.07979090
38.84384	129.8254	-.09770409
38.89550	129.8251	-0.1141773
38.94717	129.8230	-0.1322481
39.00050	129.8227	-0.1488845
39.05383	129.8205	-0.1658182
39.10383	129.8202	-0.1803841
39.15716	129.8186	-0.1959451
39.21050	129.8180	-0.2126116
39.26050	129.8165	-0.2281992
39.31383	129.8151	-0.2440655
39.36716	129.8141	-0.2597736
39.41883	129.8131	-0.2737773
39.47050	129.8136	-0.2877095
39.52383	129.8112	-0.3036770
39.57550	129.8102	-0.3177701
39.62717	129.8093	-0.3306534
39.68050	129.8078	-0.3436029
39.73216	129.8078	-0.3568424
39.78383	129.8064	-0.3694287
39.83716	129.8040	-0.3825320
39.89050	129.8048	-0.3952289
39.94050	129.8037	-0.4064653
39.99383	129.8023	-0.4184902
40.04716	129.8012	-0.4304204
40.09716	129.8009	-0.4414828
40.15050	129.8008	-0.4532332
40.20383	129.8003	-0.4648840
40.25550	129.7988	-0.4761230
40.30716	129.7984	-0.4871659
40.36050	129.7970	-0.4983212
40.41217	129.7961	-0.5089986
40.46383	129.7953	-0.5197562
40.51716	129.7952	-0.5307630
40.56883	129.7939	-0.5414877
40.62050	129.7930	-0.5520985
40.67383	129.7934	-0.5630440
40.72550	129.7917	-0.5735863
40.77716	129.7911	-0.5840507
40.83050	129.7904	-0.5947712
40.88383	129.7897	-0.6054404
40.93384	129.7890	-0.6153438
40.98717	129.7892	-0.6258087
41.04050	129.7877	-0.6361609
41.09050	129.7879	-0.6457960
41.14383	129.7866	-0.6559578
41.19717	129.7867	-0.6659753
41.24883	129.7863	-0.6755543
41.30050	129.7855	-0.6850488
41.35383	129.7854	-0.6947496
41.40550	129.7848	-0.7040018
41.45717	129.7837	-0.7131794
41.51050	129.7834	-0.7225247
41.56216	129.7824	-0.7314294
41.61383	129.7822	-0.7401476
41.66716	129.7826	-0.7490141
41.71884	129.7818	-0.7574497
41.77050	129.7806	-0.7657571
41.82383	129.7810	-0.7742129
41.87717	129.7802	-0.7825462
41.92717	129.7794	-0.7901939
41.98050	129.7794	-0.7982366
42.03383	129.7795	-0.8061556
42.08383	129.7785	-0.8134342
42.13716	129.7781	-0.8210500
42.19050	129.7779	-0.8284913
42.24216	129.7773	-0.8356243
42.29383	129.7775	-0.8426847
42.34716	129.7771	-0.8497610
42.39883	129.7772	-0.8565526
42.45050	129.7769	-0.8631680
42.50383	129.7762	-0.8698528
42.55550	129.7759	-0.8761834
42.60717	129.7757	-0.8823670
42.66050	129.7750	-0.8886262
42.71216	129.7743	-0.8945660
42.76383	129.7748	-0.9003868
42.81717	129.7744	-0.9062938
42.87050	129.7746	-0.9120934
42.92050	129.7737	-0.9174119
42.97383	129.7731	-0.9229522
43.02217	129.7748	-0.9280382
43.07383	129.9409	-0.6741310
43.12717	130.5236	-0.6352146
43.17883	131.2096	-1.934747
43.23050	131.9687	-3.415320
43.28383	132.8024	-4.950635
43.33550	133.6480	-6.283410
43.38716	134.5239	-7.441338
43.44050	135.4525	-8.447562
43.49216	136.3740	-9.247086
43.54383	137.3108	-9.928216
43.59716	138.2937	-10.49438
43.65050	139.2887	-10.97034
43.70050	140.2302	-11.33684
43.75383	141.2419	-11.66443
43.80717	142.2621	-11.93338
43.85717	143.2236	-12.13648
43.91050	144.2536	-12.34492
43.96383	145.2874	-12.49400
44.01550	146.2923	-12.63339
44.06717	147.2999	-12.75255
44.12050	148.3436	-12.86996
44.17216	149.3554	-12.95974
44.22383	150.3693	-13.04824
44.27716	151.4189	-13.13684
44.32883	152.4363	-13.21431
44.38050	153.4538	-13.29151
44.43383	154.5068	-13.36848
44.48550	155.5267	-13.44750
44.53717	156.5475	-13.52145
44.59050	157.6028	-13.59792
44.64383	158.6585	-13.66848
44.69383	159.6475	-13.73689
44.74716	160.7038	-13.81484
44.80050	161.7622	-13.89484
44.85050	162.7526	-13.97201
44.90383	163.8110	-14.05280
44.95717	164.8666	-14.14136
45.00883	165.8917	-14.23202
45.06050	166.9154	-14.32814
45.11383	167.9730	-14.42613
45.16550	168.9976	-14.52384
45.21717	170.0227	-14.62719
45.27050	171.0805	-14.74704
45.32217	172.1048	-14.86410
45.37383	173.1297	-14.98046
45.42717	174.1868	-15.10364
45.48050	175.2435	-15.24439
45.53050	176.2355	-15.38140
45.58383	177.2913	-15.51998
45.63716	178.3482	-15.67603
45.68716	179.3390	-15.82559
45.74050	180.3952	-15.98842
45.79383	181.4522	-16.16396
45.84550	182.4738	-16.33274
45.89717	183.4964	-16.52844
45.95050	184.5509	-16.71226
46.00217	185.5732	-16.90247
46.05383	186.5946	-17.10836
46.10717	187.6482	-17.33576
46.15883	188.6685	-17.57330
46.21050	189.6874	-17.81690
46.26383	190.7390	-18.08611
46.31550	191.7559	-18.37078
46.36716	192.7728	-18.66035
46.42050	193.8210	-18.97794
46.47383	194.8683	-19.32195
46.52383	195.8486	-19.66469
46.57717	196.8926	-20.07015
46.63050	197.9356	-20.48938
46.68050	198.9118	-20.92100
46.73383	199.9505	-21.42841
46.78717	200.9880	-21.95660
46.83883	201.9910	-22.60246
46.89050	202.9864	-23.23505
46.94383	204.0149	-23.92796
46.99550	205.0086	-24.67232
47.04716	205.9986	-25.47765
47.10050	207.0164	-26.38422
47.15216	207.9972	-27.35674
47.20383	208.9737	-28.43054
47.25717	209.9746	-29.68950
47.30883	210.9369	-31.06789
47.36050	211.8904	-32.62975
47.41383	212.8632	-34.45410
47.46717	213.8242	-36.51239
47.51717	214.7130	-38.65505
47.57050	215.6469	-41.13640
47.62383	216.5689	-43.82566
47.67383	217.4231	-46.45616
47.72717	218.3261	-49.32966
47.78050	219.2274	-52.02631
47.83217	220.1153	-53.80136
47.88383	221.0489	-54.13589
47.93716	222.0888	-52.56126
47.98883	223.1759	-50.07852
48.04050	224.3278	-46.59813
48.09384	225.5902	-41.50084
48.14550	226.8880	-35.83938
48.19717	228.1942	-31.97392
48.25050	229.5006	-29.12237
48.30217	230.7216	-26.98008
48.35383	231.9073	-25.26515
48.40717	233.0987	-23.86837
48.46050	234.2656	-22.73545
48.51050	235.3398	-21.89412
48.56383	236.4714	-21.17017
48.61716	237.5900	-20.58848
48.66716	238.6286	-20.15029
48.72050	239.7278	-19.79360
48.77383	240.8203	-19.51134
48.82550	241.8744	-19.29865
48.87717	242.9226	-19.12796
48.93050	244.0040	-18.98672
48.98217	245.0464	-18.89083
49.03383	246.0894	-18.81236
49.08716	247.1620	-18.74656
49.13883	248.2013	-18.70135
49.19050	249.2391	-18.66801
49.24383	250.3097	-18.64447
49.29550	251.3454	-18.63352
49.34716	252.3800	-18.62547
49.40050	253.4475	-18.62170
49.45383	254.5153	-18.61905
49.50383	255.5158	-18.61695
49.55717	256.5840	-18.61573
49.61050	257.6507	-18.61565
49.66050	258.6506	-18.61704
49.71383	259.7158	-18.62248
49.76717	260.7832	-18.63206
49.81883	261.8144	-18.64228
49.87050	262.8471	-18.65889
49.92383	263.9128	-18.68514
49.97550	264.9447	-18.71350
50.02716	265.9767	-18.74260
50.08050	267.0423	-18.78105
50.13217	268.0744	-18.80998
50.18383	269.1060	-18.84970
50.23717	270.1716	-18.87867
50.29050	271.2372	-18.90344
50.34050	272.2346	-18.92842
50.39383	273.3000	-18.94914
50.44717	274.3660	-18.96902
50.49716	275.3636	-18.97583
50.54716	276.2966	-18.59078
50.59716	276.5230	-19.67950
50.65050	276.2744	-18.82342
50.70383	275.8295	-15.20395
50.75550	275.2798	-10.98598
50.80717	274.6445	-6.996499
50.86050	273.9178	-3.421095
50.91217	273.1591	-0.5361920
50.96383	272.3562	1.830490
51.01717	271.4904	3.812731
51.06883	270.6200	5.352717
51.12050	269.7275	6.591786
51.17383	268.7839	7.625968
51.22550	267.8534	8.428482
51.27717	266.9089	9.075880
51.33050	265.9225	9.612011
51.38383	264.9248	10.05200
51.43383	263.9834	10.38976
51.48717	262.9700	10.67882
51.54050	261.9512	10.92590
51.59050	260.9908	11.10961
51.64384	259.9624	11.26998
51.69717	258.9299	11.40771
51.74883	257.9271	11.51114
51.80050	256.9220	11.60137
51.85383	255.8807	11.68250
51.90550	254.8702	11.74919
51.95717	253.8584	11.80836
52.01050	252.8112	11.85563
52.06216	251.7960	11.89749
52.11383	250.7790	11.92481
52.16716	249.7292	11.95394
52.21884	248.7100	11.97831
52.27050	247.6909	11.99890
52.32383	246.6376	12.01531
52.37717	245.5832	12.03024
52.42717	244.5952	12.04100
52.48050	243.5404	12.05041
52.53383	242.4846	12.05838
52.58383	241.4958	12.06390
52.63716	240.4380	12.07083
52.69050	239.3825	12.07819
52.74216	238.3582	12.08492
52.79382	237.3335	12.09254
52.84716	236.2764	12.09991
52.89883	235.2522	12.10665
52.95050	234.2265	12.11327
53.00383	233.1697	12.12006
53.05550	232.1438	12.12659
53.10717	231.1170	12.13321
53.16050	230.0576	12.13998
53.21216	229.0317	12.14640
53.26382	228.0056	12.15289
53.31716	226.9460	12.15967
53.37050	225.8878	12.16622
53.42050	224.8957	12.17290
53.47382	223.8362	12.17983
53.52717	222.7759	12.18693
53.57717	221.7824	12.19350
53.63050	220.7231	12.20052
53.68383	219.6632	12.20766
53.73550	218.6370	12.21448
53.78716	217.6096	12.22122
53.84050	216.5490	12.22806
53.89216	215.5225	12.23457
53.94384	214.4962	12.24093
53.99717	213.4354	12.24737
54.04883	212.4085	12.25348
54.10050	211.3807	12.25945
54.15383	210.3207	12.26564
54.20550	209.2931	12.27148
54.25717	208.2652	12.27717
54.31050	207.2050	12.28290
54.36382	206.1444	12.28845
54.41382	205.1506	12.29333
54.46717	204.0888	12.29856
54.52050	203.0277	12.30375
54.57050	202.0330	12.30833
54.62383	200.9728	12.31308
54.67717	199.9103	12.31753
54.72883	198.8820	12.32177
54.78050	197.8543	12.32587
54.83383	196.7935	12.32978
54.88550	195.7648	12.33358
54.93716	194.7377	12.33740
54.99050	193.6758	12.34119
55.04217	192.6483	12.34475
55.09384	191.6204	12.34803
55.14717	190.5586	12.35132
55.20050	189.4972	12.35448
55.25050	188.5024	12.35746
55.30383	187.4406	12.36043
55.35717	186.3791	12.36332
55.40717	185.3845	12.36598
55.46050	184.3231	12.36850
55.51382	183.2625	12.37082
55.56550	182.2344	12.37310
55.61716	181.2064	12.37540
55.67050	180.1452	12.37797
55.72217	179.1178	12.38042
55.77383	178.0890	12.38341
55.82717	177.0272	12.38676
55.87883	175.9999	12.39007
55.93050	174.9718	12.39351
55.98383	173.9098	12.39720
56.03550	172.8824	12.40078
56.08716	171.8539	12.40441
56.14050	170.7928	12.40801
56.19384	169.7314	12.41185
56.24382	168.7357	12.41551
56.29717	167.6746	12.41990
56.35050	166.6134	12.42589
56.40050	165.6199	12.45699
56.45383	164.5626	12.59751
56.50717	163.5098	12.90637
56.55883	162.4977	13.36132
56.61050	161.4976	14.07877
56.66382	160.4846	15.21545
56.71550	159.5273	16.77349
56.76716	158.5950	18.72757
56.82050	157.6614	21.05586
56.87217	156.7730	23.42270
56.92383	155.8932	25.72717
56.97717	154.9839	27.88094
57.02883	154.0896	29.62052
57.08050	153.1784	30.95828
57.13383	152.2108	31.85768
57.18716	151.2145	32.27182
57.23717	150.2524	32.21440
57.29050	149.1958	31.80740
57.34384	148.1096	30.78638
57.39384	147.0664	29.61367
57.44717	145.9324	28.13007
57.50050	144.7800	26.52468
57.55217	143.6553	24.94144
57.60383	142.5250	23.39900
57.65717	141.3611	21.91698
57.70883	140.2380	20.62574
57.76050	139.1213	19.48325
57.81382	137.9778	18.45542
57.86550	136.8802	17.59145
57.91716	135.7917	16.86265
57.97050	134.6752	16.20478
58.02217	133.6010	15.66880
58.07383	132.5333	15.21173
58.12717	131.4367	14.79865
58.18050	130.3442	14.45036
58.23050	129.3243	14.16264
58.28383	128.2408	13.89638
58.33716	127.1592	13.65838
58.38716	126.1473	13.46656
58.44050	125.0703	13.26999
58.49382	123.9951	13.10540
58.54550	122.9547	12.96644
58.59716	121.9159	12.83441
58.65050	120.8435	12.71627
58.70216	119.8070	12.61437
58.75383	118.7693	12.51630
58.80717	117.7012	12.42434
58.85883	116.6650	12.34635
58.91050	115.6303	12.27260
58.96382	114.5618	12.19801
59.01550	113.5265	12.12832
59.06716	112.4916	12.06219
59.12050	111.4239	11.99634
59.17383	110.3545	11.92629
59.22382	109.3555	11.86613
59.27717	108.2871	11.80788
59.33050	107.2193	11.74257
59.38050	106.2198	11.68877
59.43383	105.1541	11.62499
59.48717	104.0872	11.57114
59.53882	103.0541	11.52006
59.59050	102.0213	11.47223
59.64384	100.9553	11.42328
59.69550	99.92258	11.37673
59.74717	98.88889	11.32610
59.80050	97.82368	11.28154
59.85217	96.79242	11.23386
59.90383	95.75949	11.18953
59.95717	94.69406	11.14410
60.01050	93.62751	11.10336
60.06050	92.62720	11.06218
60.11382	91.56178	11.01863
60.16716	90.49509	10.96986
60.21717	89.49589	10.92359
60.27050	88.43056	10.87463
60.32383	87.36325	10.82643
60.37550	86.33001	10.77572
60.42717	85.29688	10.72666
60.48050	84.23095	10.67782
60.53217	83.19955	10.63372
60.58383	82.16586	10.58969
60.63716	81.10000	10.54817
60.68882	80.06800	10.50877
60.74050	79.03602	10.46554
60.79382	77.96972	10.42774
60.84550	76.93679	10.38839
60.89717	75.90455	10.35490
60.95050	74.83870	10.31684
61.00383	73.77353	10.27543
61.05383	72.77350	10.23354
61.10717	71.70772	10.18703
61.16050	70.64284	10.14656
61.21050	69.64382	10.10631
61.26382	68.57626	10.06464
61.31716	67.50947	10.01994
61.36882	66.47734	9.975434
61.42050	65.44470	9.935702
61.47382	64.37926	9.893411
61.52550	63.34520	9.850956
61.57717	62.31345	9.803816
61.63050	61.24672	9.756858
61.68217	60.21504	9.710528
61.73383	59.18176	9.670332
61.78716	58.11606	9.627270
61.83882	57.08174	9.584640
61.89050	56.04958	9.543505
61.94384	54.98250	9.498684
61.99717	53.91611	9.460043
62.04717	52.91734	9.415656
62.10050	51.85156	9.369275
62.15383	50.78459	9.322038
62.20383	49.78586	9.280363
62.25717	48.71969	9.234824
62.31050	47.65398	9.191254
62.36217	46.61916	9.152159
62.41382	45.58680	9.111331
62.46717	44.52112	9.072328
62.51884	43.48743	9.028936
62.57050	42.45400	8.987852
62.62383	41.38700	8.939609
62.67550	40.35293	8.891775
62.72717	39.31881	8.843306
62.78050	38.25225	8.783136
62.83217	37.21831	8.726303
62.88383	36.18396	8.671259
62.93716	35.11715	8.616556
62.99050	34.04908	8.557226
63.04050	33.04766	8.505903
63.09384	31.98017	8.446908
63.14717	30.91308	8.386941
63.19717	29.91200	8.333454
63.25050	28.84546	8.274384
63.30383	27.77651	8.208844
63.35550	26.74040	8.152042
63.40717	25.70575	8.087128
63.46050	24.63659	8.049672
63.51050	23.63440	8.050464
63.56216	22.80093	7.550551
63.61382	22.82021	8.928295
63.66716	23.15533	9.080262
63.71884	23.64955	7.852737
63.77050	24.23724	6.033199
63.82383	24.92462	4.048089
63.87550	25.65023	2.249472
63.92717	26.42544	0.6497205
63.98050	27.26703	-0.7785575
64.03384	28.14324	-1.982649
64.08384	28.99255	-2.941008
64.13717	29.92079	-3.805676
64.19050	30.87130	-4.524700
64.24050	31.77639	-5.098730
64.29384	32.75552	-5.613276
64.34717	33.74497	-6.045958
64.39883	34.71441	-6.394442
64.45050	35.69135	-6.700331
64.50384	36.70602	-6.960434
64.55550	37.69508	-7.179839
64.60718	38.68874	-7.374579
64.66050	39.71956	-7.543958
64.71217	40.72183	-7.685587
64.76384	41.72524	-7.806796
64.81717	42.76588	-7.924246
64.87050	43.80785	-8.022510
64.92050	44.78831	-8.113490
64.97384	45.83381	-8.196074
65.02717	46.88160	-8.276913
65.07718	47.86526	-8.349566
65.13050	48.91606	-8.421892
65.18384	49.96675	-8.497507
65.23550	50.98662	-8.558906
65.28717	52.00828	-8.622481
65.34050	53.06214	-8.691438
65.39216	54.08365	-8.745147
65.44384	55.10738	-8.801634
65.49717	56.16324	-8.857976
65.54884	57.18754	-8.919325
65.60050	58.21171	-8.975524
65.65384	59.26992	-9.033241
65.70550	60.29614	-9.093519
65.75718	61.32047	-9.150837
65.81050	62.38144	-9.210230
65.86384	63.44066	-9.272836
65.91382	64.43476	-9.325219
65.96718	65.49420	-9.380472
66.02050	66.55450	-9.438031
66.07050	67.54750	-9.491924
66.12384	68.60900	-9.551769
66.17718	69.66940	-9.612710
66.22884	70.69700	-9.669038
66.28050	71.72498	-9.729735
66.33384	72.78594	-9.795250
66.38550	73.81542	-9.855390
66.43718	74.84349	-9.914234
66.49050	75.90530	-9.978798
66.54218	76.93497	-10.04314
66.59384	77.96440	-10.10590
66.64718	79.02526	-10.17238
66.69884	80.05389	-10.23378
66.75050	81.08194	-10.29839
66.80384	82.14510	-10.36437
66.85718	83.20699	-10.43276
66.90718	84.20212	-10.49570
66.96050	85.26618	-10.56992
67.01384	86.32650	-10.63840
67.06384	87.32266	-10.69714
67.11718	88.38507	-10.75943
67.17050	89.44775	-10.83001
67.22218	90.47681	-10.90007
67.27384	91.50655	-10.96859
67.32718	92.56884	-11.03726
67.37884	93.59796	-11.10380
67.43050	94.62756	-11.17277
67.48384	95.69009	-11.24372
67.53550	96.71986	-11.31253
67.58716	97.74920	-11.37650
67.64050	98.81122	-11.44685
67.69218	99.84179	-11.52167
67.74384	100.8700	-11.58750
67.79718	101.9334	-11.66337
67.85050	102.9962	-11.73020
67.90050	103.9928	-11.80378
67.95384	105.0542	-11.87898
68.00718	106.1161	-11.95312
68.05718	107.1131	-12.03277
68.11050	108.1743	-12.10586
68.16382	109.2377	-12.17767
68.21550	110.2659	-12.25521
68.26716	111.2961	-12.33526
68.32050	112.3573	-12.41256
68.37218	113.3877	-12.48750
68.42384	114.4170	-12.56688
68.47718	115.4793	-12.64386
68.52884	116.5078	-12.72190
68.58050	117.5384	-12.79956
68.63384	118.5991	-12.87897
68.68550	119.6286	-12.96390
68.73718	120.6572	-13.04615
68.79050	121.7191	-13.13606
68.84384	122.7808	-13.22916
68.89384	123.7762	-13.30628
68.94718	124.8390	-13.39840
69.00050	125.9004	-13.48630
69.05050	126.8959	-13.56682
69.10384	127.9580	-13.65685
69.15718	129.0207	-13.74675
69.20884	130.0477	-13.83394
69.26050	131.0762	-13.92938
69.31384	132.1384	-14.02272
69.36550	133.1663	-14.11614
69.41718	134.1950	-14.21515
69.47050	135.2561	-14.31691
69.52218	136.2842	-14.41444
69.57384	137.3119	-14.51478
69.62718	138.3740	-14.61811
69.68050	139.4347	-14.72596
69.73050	140.4296	-14.82674
69.78384	141.4898	-14.92821
69.83716	142.5503	-15.03961
69.88718	143.5446	-15.14002
69.94050	144.6064	-15.24982
69.99384	145.6667	-15.35914
70.04550	146.6942	-15.47246
70.09718	147.7220	-15.57662
70.15050	148.7823	-15.68530
70.20216	149.8105	-15.79373
70.25384	150.8385	-15.90294
70.30718	151.8987	-16.01424
70.35884	152.9257	-16.12356
70.41050	153.9540	-16.23120
70.46384	155.0140	-16.34994
70.51550	156.0409	-16.44984
70.56718	157.0682	-16.56202
70.62050	158.1278	-16.67258
70.67384	159.1894	-16.77260
70.72384	160.1844	-16.85376
70.77718	161.2456	-16.94185
70.83050	162.3084	-17.00822
70.88050	163.3063	-17.06104
70.93384	164.3690	-17.10706
70.98718	165.4359	-17.13993
71.03882	166.4672	-17.16529
71.09050	167.4988	-17.18262
71.14384	168.5660	-17.19861
71.19550	169.5983	-17.22266
71.24718	170.6308	-17.25298
71.30050	171.6958	-17.29939
71.35218	172.7276	-17.36851
71.40384	173.7598	-17.43725
71.45718	174.8244	-17.51251
71.50884	175.8547	-17.59757
71.56050	176.8850	-17.68854
71.61384	177.9466	-17.77939
71.66718	179.0076	-17.89786
71.71718	180.0020	-18.01778
71.77050	181.0609	-18.15958
71.82384	182.1203	-18.31926
71.87384	183.1124	-18.48573
71.92718	184.1702	-18.68085
71.98050	185.2261	-18.89346
72.03218	186.2479	-19.11759
72.08384	187.2688	-19.37011
72.13718	188.3200	-19.66804
72.18884	189.3358	-20.00100
72.24050	190.3519	-20.34011
72.29384	191.3963	-20.73846
72.34550	192.4073	-21.15134
72.39718	193.4171	-21.59457
72.45050	194.4569	-22.06576
72.50218	195.4639	-22.53342
72.55384	196.4690	-23.02098
72.60718	197.5060	-23.56311
72.66050	198.5414	-24.14555
72.71050	199.5080	-24.74707
72.76384	200.5386	-25.44530
72.81718	201.5635	-26.20184
72.86718	202.5216	-26.99033
72.92050	203.5398	-27.86658
72.97384	204.5558	-28.79161
73.02550	205.5369	-29.68695
73.07718	206.5180	-30.56988
73.13050	207.5322	-31.38237
73.18218	208.5184	-32.00364
73.23384	209.5164	-32.28222
73.28718	210.5686	-32.06157
73.33884	211.6230	-30.72082
73.39050	212.7245	-28.61904
73.44384	213.9039	-26.14703
73.49550	215.0598	-24.17402
73.54718	216.2056	-22.73290
73.60050	217.3682	-21.58584
73.65384	218.5120	-20.69446
73.70384	219.5697	-20.00936
73.75718	220.6877	-19.43930
73.81050	221.7947	-18.98272
73.86050	222.8246	-18.65190
73.91382	223.9182	-18.35493
73.96718	225.0050	-18.12572
74.01882	226.0543	-17.95302
74.07050	227.1012	-17.81894
74.12384	228.1777	-17.71186
74.17550	229.2199	-17.64077
74.22718	230.2588	-17.58899
74.28050	231.3297	-17.55565
74.33218	232.3664	-17.53643
74.38384	233.4011	-17.52766
74.43718	234.4703	-17.52468
74.49050	235.5369	-17.52296
74.54050	236.5376	-17.52164
74.59384	237.6055	-17.52090
74.64718	238.6718	-17.52104
74.69718	239.6726	-17.52318
74.75050	240.7386	-17.52671
74.80384	241.8037	-17.53647
74.85550	242.8373	-17.55050
74.90718	243.8695	-17.57358
74.96050	244.9356	-17.59189
75.01218	245.9685	-17.61404
75.06384	246.9998	-17.63903
75.11718	248.0665	-17.66000
75.16884	249.0986	-17.68366
75.22050	250.1307	-17.70991
75.27384	251.1961	-17.73661
75.32550	252.2284	-17.76262
75.37718	253.2607	-17.79115
75.43050	254.3248	-17.82184
75.48384	255.3906	-17.85480
75.53384	256.3887	-17.89308
75.58716	257.4546	-17.92998
75.64050	258.5189	-17.96476
75.69050	259.5179	-18.00200
75.74384	260.5834	-18.03924
75.79718	261.6478	-18.06990
75.84882	262.6800	-18.09970
75.90050	263.7120	-18.13631
75.95384	264.7766	-18.17156
76.00550	265.8084	-18.20588
76.05718	266.8402	-18.24249
76.11050	267.9044	-18.27840
76.16218	268.9354	-18.31436
76.21384	269.9665	-18.35088
76.26716	271.0311	-18.38721
76.31884	272.0616	-18.42362
-2.000000	5.000000	0.0000000