File: 9-C1(1.2mol%)+C20(1.0mol%)/matlab/130-1.txt
CLOSED
Version	1.0
Language	English
Mode	Standard
Run	1
RunSerial	12269
Instrument	DSC Q2000 V24.11 Build 124
Module	DSC Standard Cell RC
Operator
File	\\AE520-1454\Users\dsc\Desktop\Data\29-08-17\130-1.001
ProcName
InstSerial	2000-0883
AutoSerial	1293
Sample	130-1
Size	21.6000	mg
PanMass	Not available
PanResist	Automatic Automatic  K/W
PanFactor	Default Default
Method
Comment
Xcomment	Pan: Tzero Aluminum Hermetic
Xcomment	Gas1: Nitrogen 50.0 ml/min
Xcomment	Gas2: Nitrogen 50.0 ml/min
Text
Exotherm	UP
Kcell	1.05230
Cpconst	Standard: 0.938
Calib	-38.6961
TempCal	1	pts	157.46	156.60
TzeroDt	-87.6168 -0.0009 -1.4231
TzeroDtz	-87.6168 0.0057 6.9570
InstCalFile	Tzero: \\Ae520-1454\ta\Data\DSC\Calibration\2017\CALIBRATION\1562_RCS (90)_05_18_2017 10_50_44.TZR
InstCalFile	Baseline: \\Ae520-1454\ta\Data\DSC\Calibration\2017\2017-05-17_Calibration.001
InstCalFile	Sapphire: \\Ae520-1454\ta\Data\DSC\Calibration\2017\2017-05-17_Saphire.001
InstCalDate	Tzero 2017-05-18 Time 10:50:44
TempRange	-87.39 to 398.39 °C at 10.00 °C/min Heat Only
AutoZero	Delta T Offset 0.000 uV
AutoZero	Delta T0 Offset 0.000 uV
MultiptCal	0
MultiPtDesc	0) Not set
AutoCellConst	Calibration Date 2017-05-18 16:59:28
Controls	Gas 1  Event Off  Sampling 0.2
Cell#	RC-01562
CoolingUnit	RCS (90)
SelHeatFlow	Heat Flow T4P (mW)
AutoLidII	Installed
AutoAnalysis	Off
MacroFile
Nsig	3
Sig1	Time (min)
Sig2	Temperature (°C)
Sig3	Heat Flow (mW)
Date	2017-08-29
Time	11:17:17
OrgMethod	1: Equilibrate at 80.00 °C
OrgMethod	2: Isothermal for 3.00 min
OrgMethod	3: Jump to 130.00 °C
OrgMethod	4: Mark end of cycle 1
OrgMethod	5: Isothermal for 40.00 min
OrgMethod	6: Mark end of cycle 2
OrgMethod	7: Ramp 20.00 °C/min to 280.00 °C
OrgMethod	8: Mark end of cycle 3
OrgMethod	9: Ramp 20.00 °C/min to 20.00 °C
OrgMethod	10: Mark end of cycle 4
OrgMethod	11: Ramp 20.00 °C/min to 280.00 °C
OrgMethod	12: Mark end of cycle 5
OrgFile	C:\Users\jarra\Desktop\DSC\9-C1(1.2mol%)+C20(1.0mol%)\130-1.001
StartOfData
4.99994E-4	78.52612	-10.27355
0.05383332	78.69088	-8.529090
0.1071666	78.82898	-7.077170
0.1588333	78.94349	-5.909440
0.2105000	79.04230	-4.934806
0.2638334	79.12850	-4.108787
0.3155000	79.20006	-3.438034
0.3671667	79.26272	-2.884927
0.4205000	79.31720	-2.411672
0.4721666	79.36296	-2.034913
0.5238333	79.40372	-1.722614
0.5771668	79.43928	-1.454867
0.6305000	79.47106	-1.246859
0.6805000	79.49728	-1.081516
0.7338332	79.52001	-0.9409257
0.7871668	79.54174	-0.8223637
0.8371668	79.55978	-0.7426129
0.8904999	79.57666	-0.6682378
0.9438332	79.59212	-0.6155958
0.9955000	79.60488	-0.5713446
1.047167	79.61706	-0.5431238
1.100500	79.62836	-0.5203515
1.152167	79.63787	-0.5055526
1.203834	79.64765	-0.4964248
1.257166	79.65688	-0.4897800
1.308833	79.66382	-0.4863024
1.360500	79.67099	-0.4828320
1.413834	79.67726	-0.4793465
1.465500	79.68366	-0.4760176
1.517167	79.68912	-0.4730774
1.570500	79.69434	-0.4703002
1.623833	79.69946	-0.4679546
1.673834	79.70381	-0.4660907
1.727167	79.70894	-0.4644722
1.780500	79.71284	-0.4632664
1.830500	79.71640	-0.4625140
1.883833	79.72040	-0.4621456
1.937166	79.72422	-0.4620966
1.988833	79.72730	-0.4624320
2.040500	79.72942	-0.4629452
2.093834	79.73274	-0.4638822
2.145500	79.73652	-0.4650030
2.197166	79.73843	-0.4664422
2.250500	79.74156	-0.4680208
2.302166	79.74419	-0.4698154
2.353833	79.74624	-0.4717117
2.407167	79.74724	-0.4738818
2.458833	79.75028	-0.4760676
2.510500	79.75218	-0.4784426
2.563833	79.75647	-0.4802866
2.617167	79.75696	-0.4820713
2.667167	79.75960	-0.4841232
2.720500	79.76050	-0.4862263
2.773833	79.76197	-0.4885734
2.823833	79.76430	-0.4907157
2.877167	79.76626	-0.4931606
2.930500	79.76703	-0.4956524
2.982167	79.76811	-0.4980571
3.030500	79.89721	-0.3362332
3.082167	82.32778	3.146236
3.133833	85.77222	2.292190
3.187167	89.51429	-1.739236
3.238834	93.35101	-7.080951
3.290500	97.35407	-12.63296
3.343834	101.6205	-18.44724
3.397167	105.9953	-23.95656
3.447167	110.1701	-29.03157
3.500500	114.6681	-34.25066
3.553833	118.7770	-38.63135
3.603833	120.6741	-43.78320
3.657167	122.0163	-44.59714
3.710500	123.0574	-42.73963
3.762167	123.8891	-39.04880
3.813833	124.6170	-34.65195
3.867166	125.2671	-30.08820
3.918833	125.8061	-25.96018
3.970500	126.2732	-22.22970
4.023834	126.6901	-18.87440
4.075500	127.0404	-16.00552
4.127167	127.3438	-13.58870
4.180500	127.6180	-11.45181
4.232167	127.8456	-9.725891
4.283834	128.0455	-8.272249
4.337167	128.2262	-6.983429
4.390500	128.3834	-5.933166
4.440500	128.5132	-5.105552
4.493834	128.6350	-4.367984
4.547167	128.7421	-3.752833
4.597166	128.8303	-3.276687
4.650500	128.9155	-2.851549
4.703833	128.9898	-2.491640
4.755500	129.0524	-2.216486
4.807167	129.1101	-1.982978
4.860500	129.1629	-1.785274
4.912167	129.2067	-1.630434
4.963834	129.2480	-1.500042
5.017166	129.2852	-1.390688
5.068833	129.3188	-1.306554
5.120500	129.3492	-1.234416
5.173834	129.3760	-1.179804
5.225500	129.4009	-1.133944
5.277168	129.4232	-1.102538
5.330500	129.4430	-1.075166
5.383832	129.4615	-1.056234
5.433832	129.4783	-1.042348
5.487168	129.4951	-1.033252
5.540500	129.5080	-1.026847
5.590500	129.5216	-1.022795
5.643832	129.5346	-1.018638
5.697168	129.5458	-1.014487
5.748834	129.5561	-1.010442
5.800500	129.5655	-1.006538
5.853832	129.5742	-1.002836
5.905500	129.5826	-0.9992919
5.957168	129.5901	-0.9961749
6.010500	129.5973	-0.9931293
6.062168	129.6036	-0.9904889
6.113834	129.6106	-0.9879876
6.167168	129.6160	-0.9857080
6.220500	129.6227	-0.9836936
6.270500	129.6271	-0.9819726
6.323834	129.6324	-0.9803699
6.377168	129.6366	-0.9789080
6.427168	129.6402	-0.9777335
6.480500	129.6446	-0.9765751
6.533832	129.6496	-0.9756516
6.585500	129.6525	-0.9748111
6.637168	129.6561	-0.9740226
6.690500	129.6596	-0.9732644
6.742166	129.6625	-0.9726155
6.793832	129.6659	-0.9720975
6.847168	129.6684	-0.9715601
6.898834	129.6720	-0.9710663
6.950500	129.6744	-0.9705702
7.003832	129.6772	-0.9699696
7.055500	129.6789	-0.9694098
7.107168	129.6812	-0.9687668
7.160500	129.6832	-0.9680425
7.213834	129.6856	-0.9673793
7.263834	129.6881	-0.9666984
7.317168	129.6893	-0.9658776
7.370500	129.6905	-0.9649899
7.420500	129.6929	-0.9641524
7.473834	129.6951	-0.9632166
7.527168	129.6964	-0.9622166
7.578834	129.6976	-0.9611532
7.630500	129.6995	-0.9600148
7.683832	129.7012	-0.9587756
7.735500	129.7017	-0.9574520
7.787168	129.7041	-0.9561093
7.840500	129.7046	-0.9546174
7.892168	129.7060	-0.9530743
7.943832	129.7073	-0.9515138
7.997168	129.7083	-0.9498978
8.048834	129.7096	-0.9481934
8.100500	129.7121	-0.9464153
8.153832	129.7115	-0.9445299
8.207168	129.7141	-0.9426166
8.257168	129.7138	-0.9407381
8.310500	129.7145	-0.9387320
8.363834	129.7167	-0.9365228
8.413834	129.7168	-0.9344438
8.467168	129.7181	-0.9320809
8.520500	129.7190	-0.9296672
8.572168	129.7196	-0.9272795
8.623834	129.7202	-0.9248245
8.677168	129.7215	-0.9222095
8.728834	129.7225	-0.9196449
8.780500	129.7230	-0.9169761
8.833832	129.7234	-0.9141399
8.885499	129.7248	-0.9113301
8.937166	129.7257	-0.9084579
8.990500	129.7262	-0.9054358
9.042168	129.7273	-0.9024968
9.093832	129.7278	-0.8995421
9.147168	129.7295	-0.8963738
9.200500	129.7290	-0.8931786
9.250500	129.7304	-0.8901759
9.303832	129.7312	-0.8868491
9.357166	129.7319	-0.8834561
9.407166	129.7325	-0.8802275
9.460499	129.7327	-0.8767902
9.513832	129.7336	-0.8732538
9.565500	129.7344	-0.8699100
9.617166	129.7354	-0.8664764
9.670500	129.7351	-0.8628439
9.722168	129.7366	-0.8592703
9.773834	129.7370	-0.8556707
9.827168	129.7378	-0.8518444
9.878834	129.7384	-0.8480806
9.930500	129.7391	-0.8442761
9.983832	129.7394	-0.8403736
10.03550	129.7396	-0.8365475
10.08717	129.7412	-0.8326420
10.14050	129.7422	-0.8285500
10.19383	129.7422	-0.8244940
10.24383	129.7432	-0.8206200
10.29717	129.7440	-0.8164346
10.35050	129.7450	-0.8122255
10.40050	129.7451	-0.8082358
10.45383	129.7454	-0.8039278
10.50717	129.7465	-0.7994942
10.55884	129.7463	-0.7951412
10.61050	129.7482	-0.7907426
10.66383	129.7487	-0.7862472
10.71550	129.7497	-0.7818090
10.76717	129.7494	-0.7773488
10.82050	129.7499	-0.7726826
10.87217	129.7508	-0.7679648
10.92383	129.7517	-0.7632496
10.97717	129.7526	-0.7583270
11.03050	129.7527	-0.7532800
11.08050	129.7537	-0.7485141
11.13383	129.7541	-0.7433279
11.18716	129.7548	-0.7381520
11.23717	129.7558	-0.7331964
11.29050	129.7561	-0.7278192
11.34383	129.7564	-0.7223135
11.39550	129.7584	-0.7169080
11.44717	129.7584	-0.7113122
11.50050	129.7590	-0.7053830
11.55216	129.7606	-0.6996064
11.60383	129.7616	-0.6936569
11.65717	129.7614	-0.6872380
11.70883	129.7623	-0.6809397
11.76050	129.7630	-0.6743321
11.81383	129.7640	-0.6673751
11.86550	129.7652	-0.6601274
11.91717	129.7662	-0.6528295
11.97050	129.7672	-0.6447080
12.02383	129.7690	-0.6365318
12.07383	129.7702	-0.6281306
12.12717	129.7719	-0.6176119
12.18050	129.7723	-0.6052830
12.23050	129.7729	-0.5930134
12.28383	129.7750	-0.5776562
12.33717	129.7764	-0.5613175
12.38883	129.7778	-0.5422550
12.44050	129.7791	-0.5240693
12.49384	129.7809	-0.5005634
12.54550	129.7824	-0.4762704
12.59717	129.7849	-0.4522530
12.65050	129.7858	-0.4240210
12.70217	129.7876	-0.3962910
12.75384	129.7895	-0.3684992
12.80717	129.7913	-0.3382312
12.85883	129.7938	-0.3095311
12.91050	129.7956	-0.2789053
12.96383	129.7976	-0.2476128
13.01717	129.7993	-0.2154297
13.06716	129.8014	-0.1838560
13.12050	129.8030	-0.1507722
13.17383	129.8057	-0.1203770
13.22383	129.8073	-.09219609
13.27717	129.8097	-.05985306
13.33050	129.8118	-.02892894
13.38216	129.8140	-6.5715E-4
13.43383	129.8154	0.02880914
13.48716	129.8184	0.05835074
13.53883	129.8198	0.08554934
13.59050	129.8225	0.1117062
13.64383	129.8233	0.1402376
13.69550	129.8264	0.1651946
13.74717	129.8284	0.1895712
13.80050	129.8307	0.2145843
13.85217	129.8314	0.2385335
13.90383	129.8333	0.2611592
13.95717	129.8362	0.2845029
14.01050	129.8366	0.3069005
14.06050	129.8395	0.3265988
14.11383	129.8408	0.3472644
14.16716	129.8421	0.3689644
14.21716	129.8444	0.3868851
14.27050	129.8448	0.4065366
14.32384	129.8471	0.4242375
14.37550	129.8484	0.4411479
14.42717	129.8506	0.4581938
14.48050	129.8514	0.4756950
14.53217	129.8524	0.4926650
14.58383	129.8540	0.5088816
14.63717	129.8556	0.5253082
14.68883	129.8575	0.5402115
14.74050	129.8584	0.5551989
14.79384	129.8598	0.5714060
14.84550	129.8612	0.5874782
14.89717	129.8622	0.6040313
14.95050	129.8634	0.6207141
15.00383	129.8646	0.6371062
15.05383	129.8657	0.6515750
15.10716	129.8678	0.6680863
15.16050	129.8686	0.6839375
15.21050	129.8701	0.6987954
15.26383	129.8713	0.7146828
15.31716	129.8728	0.7323830
15.36884	129.8745	0.7474061
15.42050	129.8755	0.7647876
15.47383	129.8772	0.7819956
15.52550	129.8781	0.7995972
15.57717	129.8796	0.8170086
15.63050	129.8803	0.8350592
15.68217	129.8818	0.8520111
15.73383	129.8824	0.8696894
15.78717	129.8854	0.8883632
15.84050	129.8862	0.9070145
15.89050	129.8879	0.9256892
15.94384	129.8892	0.9451901
15.99717	129.8903	0.9651608
16.04716	129.8916	0.9842224
16.10050	129.8932	1.004800
16.15383	129.8951	1.026569
16.20550	129.8963	1.047683
16.25716	129.8974	1.067564
16.31050	129.8987	1.088088
16.36216	129.9001	1.108704
16.41383	129.9018	1.129873
16.46716	129.9037	1.151042
16.51883	129.9052	1.171868
16.57050	129.9063	1.194350
16.62383	129.9077	1.218377
16.67550	129.9100	1.241447
16.72716	129.9110	1.264663
16.78050	129.9131	1.289493
16.83383	129.9148	1.313957
16.88383	129.9155	1.336374
16.93716	129.9175	1.360748
16.99050	129.9198	1.384942
17.04050	129.9218	1.407168
17.09383	129.9227	1.431448
17.14716	129.9248	1.454991
17.19884	129.9262	1.478833
17.25050	129.9281	1.503741
17.30383	129.9291	1.528453
17.35550	129.9311	1.554451
17.40716	129.9334	1.579530
17.46050	129.9350	1.605616
17.51216	129.9362	1.632684
17.56383	129.9386	1.657435
17.61716	129.9401	1.684759
17.66883	129.9422	1.710493
17.72050	129.9435	1.737691
17.77383	129.9460	1.764125
17.82716	129.9478	1.790614
17.87716	129.9491	1.816278
17.93050	129.9514	1.843791
17.98383	129.9535	1.870692
18.03383	129.9552	1.897310
18.08716	129.9566	1.926390
18.14050	129.9592	1.952889
18.19216	129.9610	1.980519
18.24383	129.9633	2.005702
18.29716	129.9649	2.033836
18.34883	129.9673	2.060685
18.40050	129.9687	2.086920
18.45383	129.9707	2.113936
18.50550	129.9724	2.140307
18.55716	129.9751	2.165138
18.61050	129.9758	2.190860
18.66217	129.9778	2.215770
18.71383	129.9795	2.239922
18.76716	129.9812	2.265310
18.82050	129.9827	2.288094
18.87050	129.9848	2.309625
18.92383	129.9868	2.331194
18.97716	129.9880	2.352869
19.02716	129.9900	2.372365
19.08050	129.9912	2.392036
19.13383	129.9933	2.411608
19.18550	129.9947	2.429353
19.23716	129.9965	2.445827
19.29050	129.9975	2.462291
19.34216	129.9988	2.478323
19.39383	129.9992	2.492974
19.44716	130.0005	2.506824
19.49883	130.0018	2.519400
19.55050	130.0030	2.531674
19.60383	130.0031	2.543002
19.65550	130.0053	2.553139
19.70716	130.0059	2.562973
19.76050	130.0073	2.572764
19.81383	130.0080	2.582568
19.86383	130.0088	2.591108
19.91716	130.0091	2.600319
19.97050	130.0108	2.609635
20.02050	130.0115	2.618361
20.07383	130.0125	2.627728
20.12716	130.0127	2.637078
20.17883	130.0128	2.646107
20.23050	130.0133	2.655118
20.28383	130.0143	2.664422
20.33550	130.0155	2.673336
20.38716	130.0170	2.682195
20.44050	130.0161	2.691379
20.49216	130.0172	2.700289
20.54383	130.0185	2.709096
20.59716	130.0181	2.718156
20.65050	130.0195	2.727160
20.70050	130.0204	2.735608
20.75383	130.0208	2.744550
20.80716	130.0208	2.753469
20.85716	130.0219	2.761763
20.91050	130.0214	2.770580
20.96383	130.0225	2.779370
21.01550	130.0234	2.787809
21.06716	130.0231	2.796228
21.12050	130.0245	2.804869
21.17216	130.0253	2.813213
21.22383	130.0257	2.821568
21.27717	130.0263	2.830160
21.32883	130.0273	2.838456
21.38050	130.0272	2.846743
21.43383	130.0294	2.855254
21.48550	130.0288	2.863474
21.53717	130.0304	2.871680
21.59050	130.0298	2.880130
21.64383	130.0303	2.888532
21.69383	130.0316	2.896360
21.74716	130.0323	2.904710
21.80050	130.0324	2.913024
21.85050	130.0329	2.920732
21.90383	130.0338	2.928970
21.95717	130.0339	2.937164
22.00883	130.0347	2.945090
22.06050	130.0351	2.952925
22.11383	130.0355	2.960960
22.16550	130.0361	2.968662
22.21716	130.0360	2.976320
22.27050	130.0366	2.984127
22.32216	130.0370	2.991568
22.37383	130.0380	2.998880
22.42717	130.0388	3.006320
22.47883	130.0384	3.013374
22.53050	130.0391	3.020318
22.58383	130.0396	3.027268
22.63716	130.0400	3.034092
22.68716	130.0402	3.040350
22.74050	130.0399	3.046810
22.79383	130.0406	3.053134
22.84383	130.0404	3.058827
22.89716	130.0416	3.064682
22.95050	130.0411	3.070352
23.00217	130.0418	3.075616
23.05383	130.0414	3.080606
23.10716	130.0410	3.085522
23.15883	130.0418	3.090035
23.21050	130.0421	3.094294
23.26383	130.0419	3.098344
23.31550	130.0420	3.101980
23.36716	130.0418	3.105354
23.42050	130.0418	3.108480
23.47216	130.0415	3.111264
23.52383	130.0415	3.113665
23.57716	130.0421	3.115826
23.63050	130.0414	3.117659
23.68050	130.0410	3.119061
23.73383	130.0411	3.120238
23.78717	130.0406	3.121002
23.83716	130.0403	3.121372
23.89050	130.0399	3.121490
23.94383	130.0397	3.121305
23.99550	130.0395	3.120765
24.04716	130.0383	3.119972
24.10050	130.0385	3.118690
24.15216	130.0381	3.117037
24.20383	130.0375	3.115010
24.25716	130.0368	3.112582
24.30883	130.0364	3.109827
24.36050	130.0353	3.106735
24.41383	130.0348	3.103169
24.46550	130.0340	3.099340
24.51716	130.0340	3.095150
24.57050	130.0328	3.090421
24.62383	130.0331	3.085235
24.67383	130.0305	3.080103
24.72716	130.0303	3.074285
24.78050	130.0289	3.067986
24.83050	130.0291	3.061774
24.88383	130.0280	3.054814
24.93716	130.0270	3.047380
24.98883	130.0262	3.039536
25.04050	130.0263	3.031232
25.09383	130.0246	3.022200
25.14550	130.0240	3.013222
25.19716	130.0225	3.003790
25.25050	130.0217	2.993508
25.30217	130.0209	2.983296
25.35383	130.0197	2.971861
25.40716	130.0191	2.960562
25.46050	130.0184	2.948785
25.51050	130.0172	2.937116
25.56383	130.0165	2.925647
25.61716	130.0152	2.912829
25.66716	130.0142	2.900874
25.72050	130.0133	2.887735
25.77383	130.0123	2.874800
25.82550	130.0108	2.862074
25.87716	130.0112	2.848449
25.93050	130.0088	2.834429
25.98216	130.0086	2.820796
26.03383	130.0081	2.806958
26.08716	130.0068	2.792883
26.13883	130.0053	2.778454
26.19050	130.0042	2.764597
26.24383	130.0042	2.750471
26.29550	130.0027	2.737191
26.34716	130.0024	2.722690
26.40050	130.0008	2.709556
26.45383	129.9999	2.695112
26.50383	129.9984	2.681860
26.55716	129.9976	2.668278
26.61050	129.9972	2.654803
26.66050	129.9962	2.642346
26.71383	129.9952	2.628200
26.76716	129.9945	2.614509
26.81883	129.9936	2.601522
26.87050	129.9931	2.588302
26.92383	129.9916	2.574627
26.97550	129.9907	2.561643
27.02717	129.9899	2.548260
27.08050	129.9887	2.535079
27.13216	129.9885	2.522564
27.18383	129.9875	2.509834
27.23716	129.9863	2.496676
27.28883	129.9856	2.484312
27.34050	129.9851	2.472429
27.39383	129.9844	2.459798
27.44717	129.9832	2.446585
27.49716	129.9825	2.434918
27.55050	129.9808	2.422701
27.60383	129.9808	2.410046
27.65383	129.9802	2.398110
27.70716	129.9792	2.385534
27.76050	129.9790	2.372861
27.81217	129.9776	2.360823
27.86383	129.9764	2.349108
27.91716	129.9752	2.337208
27.96883	129.9746	2.325301
28.02050	129.9744	2.313766
28.07383	129.9734	2.301553
28.12550	129.9730	2.289608
28.17717	129.9719	2.277675
28.23050	129.9710	2.265749
28.28216	129.9703	2.254250
28.33383	129.9699	2.242828
28.38716	129.9685	2.231123
28.44050	129.9672	2.219350
28.49050	129.9674	2.208348
28.54383	129.9669	2.196278
28.59716	129.9654	2.184650
28.64716	129.9646	2.173843
28.70050	129.9640	2.162328
28.75383	129.9636	2.150820
28.80550	129.9625	2.139756
28.85716	129.9625	2.128703
28.91050	129.9607	2.117376
28.96216	129.9600	2.106380
29.01383	129.9594	2.095465
29.06716	129.9591	2.084208
29.11883	129.9586	2.073361
29.17050	129.9578	2.062526
29.22383	129.9582	2.051379
29.27550	129.9568	2.040646
29.32717	129.9564	2.029968
29.38050	129.9552	2.018920
29.43383	129.9547	2.007912
29.48383	129.9540	1.997615
29.53717	129.9540	1.986717
29.59050	129.9534	1.975866
29.64050	129.9530	1.965790
29.69383	129.9516	1.955023
29.74716	129.9508	1.944336
29.79883	129.9502	1.934060
29.85050	129.9490	1.923811
29.90383	129.9495	1.913326
29.95550	129.9486	1.903220
30.00716	129.9478	1.893132
30.06050	129.9473	1.882738
30.11216	129.9471	1.872712
30.16383	129.9462	1.862733
30.21716	129.9456	1.852457
30.27050	129.9447	1.842242
30.32050	129.9440	1.832727
30.37383	129.9436	1.822601
30.42717	129.9432	1.812487
30.47717	129.9416	1.803045
30.53050	129.9423	1.793025
30.58383	129.9418	1.783058
30.63550	129.9414	1.773444
30.68717	129.9402	1.763868
30.74050	129.9405	1.754002
30.79216	129.9385	1.744475
30.84383	129.9384	1.735012
30.89716	129.9381	1.725269
30.94883	129.9371	1.715876
31.00050	129.9371	1.706524
31.05383	129.9360	1.696958
31.10550	129.9354	1.687699
31.15716	129.9346	1.678502
31.21050	129.9340	1.669074
31.26383	129.9328	1.659699
31.31383	129.9327	1.650917
31.36716	129.9321	1.641636
31.42050	129.9316	1.632342
31.47050	129.9311	1.623652
31.52383	129.9303	1.614437
31.57717	129.9306	1.605238
31.62883	129.9291	1.596341
31.68050	129.9284	1.587475
31.73383	129.9283	1.578320
31.78550	129.9273	1.569444
31.83716	129.9273	1.560596
31.89050	129.9265	1.551527
31.94216	129.9262	1.542755
31.99383	129.9250	1.533994
32.04716	129.9252	1.524964
32.09883	129.9239	1.516249
32.15050	129.9234	1.507528
32.20383	129.9226	1.498571
32.25716	129.9229	1.489610
32.30716	129.9212	1.481248
32.36050	129.9207	1.472324
32.41383	129.9205	1.463389
32.46383	129.9198	1.455024
32.51716	129.9193	1.446182
32.57050	129.9185	1.437390
32.62216	129.9188	1.428795
32.67383	129.9181	1.420266
32.72717	129.9166	1.411426
32.77883	129.9165	1.402894
32.83050	129.9156	1.394375
32.88383	129.9157	1.385655
32.93550	129.9148	1.377174
32.98717	129.9144	1.368715
33.04050	129.9140	1.359994
33.09216	129.9131	1.351597
33.14383	129.9131	1.343157
33.19717	129.9120	1.334462
33.25050	129.9124	1.325769
33.30050	129.9115	1.317648
33.35383	129.9107	1.308984
33.40716	129.9106	1.300315
33.45716	129.9094	1.292186
33.51050	129.9097	1.283586
33.56383	129.9086	1.274954
33.61550	129.9079	1.266612
33.66716	129.9072	1.258246
33.72050	129.9068	1.249560
33.77217	129.9067	1.241200
33.82383	129.9066	1.232780
33.87717	129.9062	1.224086
33.92883	129.9047	1.215680
33.98050	129.9047	1.207246
34.03383	129.9040	1.198582
34.08550	129.9039	1.190210
34.13716	129.9025	1.181799
34.19050	129.9019	1.173115
34.24383	129.9005	1.164476
34.29383	129.9023	1.156358
34.34716	129.9004	1.147731
34.40050	129.9002	1.139100
34.45050	129.8998	1.130974
34.50383	129.8985	1.122368
34.55716	129.8989	1.113642
34.60883	129.8975	1.105209
34.66050	129.8969	1.096787
34.71383	129.8970	1.088048
34.76550	129.8956	1.079606
34.81716	129.8952	1.071088
34.87050	129.8950	1.062328
34.92216	129.8939	1.053814
34.97383	129.8932	1.045273
35.02716	129.8925	1.036411
35.08050	129.8930	1.027539
35.13050	129.8908	1.019223
35.18384	129.8914	1.010331
35.23717	129.8899	1.001383
35.28717	129.8900	0.9929949
35.34050	129.8899	0.9839911
35.39383	129.8885	0.9749519
35.44550	129.8876	0.9661359
35.49716	129.8874	0.9572606
35.55050	129.8867	0.9481212
35.60217	129.8857	0.9391895
35.65383	129.8849	0.9301774
35.70716	129.8848	0.9208589
35.75883	129.8843	0.9117801
35.81050	129.8839	0.9025906
35.86383	129.8827	0.8931122
35.91550	129.8818	0.8838321
35.96716	129.8812	0.8744884
36.02050	129.8802	0.8647736
36.07383	129.8801	0.8550189
36.12383	129.8793	0.8458012
36.17717	129.8785	0.8358522
36.23050	129.8780	0.8257681
36.28050	129.8773	0.8159837
36.33383	129.8757	0.8057993
36.38716	129.8753	0.7951666
36.43883	129.8745	0.7849503
36.49050	129.8735	0.7746190
36.54383	129.8720	0.7640145
36.59550	129.8710	0.7534214
36.64717	129.8712	0.7421543
36.70050	129.8702	0.7307952
36.75217	129.8690	0.7195869
36.80383	129.8675	0.7080274
36.85716	129.8672	0.6956171
36.90883	129.8664	0.6838572
36.96050	129.8654	0.6715239
37.01383	129.8639	0.6582266
37.06716	129.8631	0.6445385
37.11716	129.8634	0.6317294
37.17050	129.8618	0.6169368
37.22383	129.8614	0.6017187
37.27383	129.8595	0.5876397
37.32717	129.8588	0.5716900
37.38050	129.8579	0.5555781
37.43216	129.8564	0.5395242
37.48383	129.8549	0.5226570
37.53717	129.8544	0.5054658
37.58883	129.8526	0.4874046
37.64050	129.8524	0.4688994
37.69383	129.8503	0.4499379
37.74550	129.8496	0.4318962
37.79716	129.8480	0.4149150
37.85050	129.8480	0.3953961
37.90216	129.8463	0.3773114
37.95383	129.8447	0.3583050
38.00716	129.8445	0.3397034
38.06050	129.8426	0.3189440
38.11050	129.8417	0.3003636
38.16383	129.8407	0.2808078
38.21716	129.8390	0.2605011
38.26716	129.8374	0.2424496
38.32050	129.8360	0.2231140
38.37383	129.8355	0.2013330
38.42550	129.8338	0.1813356
38.47717	129.8332	0.1621998
38.53050	129.8310	0.1403561
38.58216	129.8301	0.1177797
38.63383	129.8276	0.08820965
38.68716	129.8270	0.04957035
38.73883	129.8254	0.02616460
38.79050	129.8239	.007667160
38.84384	129.8232	-8.1913E-3
38.89550	129.8220	-.02446066
38.94717	129.8206	-.04159584
39.00050	129.8188	-.05825741
39.05383	129.8175	-.07732830
39.10383	129.8172	-0.1015621
39.15716	129.8154	-0.1215444
39.21050	129.8139	-0.1382952
39.26050	129.8121	-0.1542940
39.31383	129.8114	-0.1703627
39.36716	129.8104	-0.1869144
39.41883	129.8094	-0.2012869
39.47050	129.8084	-0.2173965
39.52383	129.8070	-0.2346684
39.57550	129.8066	-0.2499932
39.62717	129.8045	-0.2648604
39.68050	129.8038	-0.2805908
39.73216	129.8023	-0.2949135
39.78383	129.8008	-0.3089618
39.83716	129.8005	-0.3229871
39.89050	129.7993	-0.3365460
39.94050	129.7974	-0.3486692
39.99383	129.7972	-0.3614846
40.04716	129.7966	-0.3739297
40.09716	129.7950	-0.3863784
40.15050	129.7942	-0.3994321
40.20383	129.7934	-0.4109282
40.25550	129.7927	-0.4223396
40.30716	129.7915	-0.4330919
40.36050	129.7908	-0.4446654
40.41217	129.7895	-0.4552197
40.46383	129.7900	-0.4657250
40.51716	129.7888	-0.4763873
40.56883	129.7878	-0.4867835
40.62050	129.7875	-0.4972314
40.67383	129.7865	-0.5078632
40.72550	129.7856	-0.5181370
40.77716	129.7850	-0.5285192
40.83050	129.7839	-0.5391399
40.88383	129.7836	-0.5497266
40.93384	129.7824	-0.5596415
40.98717	129.7823	-0.5701166
41.04050	129.7817	-0.5805508
41.09050	129.7818	-0.5902466
41.14383	129.7807	-0.6005307
41.19717	129.7801	-0.6106620
41.24883	129.7790	-0.6203722
41.30050	129.7792	-0.6299620
41.35383	129.7781	-0.6397700
41.40550	129.7770	-0.6491051
41.45717	129.7765	-0.6583613
41.51050	129.7761	-0.6677509
41.56216	129.7762	-0.6767451
41.61383	129.7749	-0.6856030
41.66716	129.7753	-0.6946145
41.71884	129.7754	-0.7032440
41.77050	129.7734	-0.7117400
41.82383	129.7739	-0.7203928
41.87717	129.7734	-0.7289025
41.92717	129.7728	-0.7366980
41.98050	129.7729	-0.7448774
42.03383	129.7729	-0.7529200
42.08383	129.7717	-0.7602774
42.13716	129.7718	-0.7680390
42.19050	129.7706	-0.7756665
42.24216	129.7712	-0.7829350
42.29383	129.7703	-0.7901063
42.34716	129.7703	-0.7973864
42.39883	129.7696	-0.8042769
42.45050	129.7698	-0.8110010
42.50383	129.7699	-0.8178134
42.55550	129.7692	-0.8242368
42.60717	129.7692	-0.8305761
42.66050	129.7687	-0.8370032
42.71216	129.7687	-0.8430668
42.76383	129.7681	-0.8489961
42.81717	129.7677	-0.8549969
42.87050	129.7673	-0.8609130
42.92050	129.7686	-0.8663251
42.97383	129.7681	-0.8719319
43.02217	129.7692	-0.8771358
43.07383	129.9550	-0.5550009
43.12717	130.5622	-0.4955156
43.17883	131.2629	-1.567557
43.23050	132.0317	-2.942806
43.28383	132.8694	-4.419439
43.33550	133.7181	-5.713184
43.38716	134.5910	-6.877086
43.44050	135.5193	-7.888328
43.49216	136.4363	-8.714780
43.54383	137.3703	-9.403199
43.59716	138.3470	-10.00039
43.65050	139.3380	-10.51586
43.70050	140.2740	-10.89985
43.75383	141.2823	-11.24586
43.80717	142.2984	-11.55384
43.85717	143.2571	-11.57013
43.91050	144.2821	-12.02333
43.96383	145.3126	-12.17663
44.01550	146.3142	-12.36464
44.06717	147.3199	-12.48439
44.12050	148.3604	-12.64461
44.17216	149.3711	-12.74132
44.22383	150.3841	-12.86221
44.27716	151.4313	-12.92909
44.32883	152.4466	-13.11787
44.38050	153.4630	-13.12232
44.43383	154.5131	-13.24184
44.48550	155.5319	-13.31274
44.53717	156.5511	-13.40386
44.59050	157.6045	-13.49212
44.64383	158.6584	-13.57536
44.69383	159.6486	-13.65006
44.74716	160.7030	-13.73515
44.80050	161.7588	-13.84591
44.85050	162.7491	-13.90082
44.90383	163.8144	-13.64159
44.95717	164.8699	-13.99834
45.00883	165.8941	-14.10606
45.06050	166.9116	-14.77233
45.11383	167.9639	-14.47188
45.16550	168.9884	-14.56846
45.21717	170.0132	-14.65674
45.27050	171.0695	-14.78653
45.32217	172.0948	-14.90367
45.37383	173.1192	-15.02609
45.42717	174.1769	-15.15277
45.48050	175.2344	-15.29184
45.53050	176.2256	-15.42839
45.58383	177.2824	-15.54372
45.63716	178.3391	-15.69476
45.68716	179.3295	-15.83353
45.74050	180.3858	-15.91345
45.79383	181.4415	-16.10209
45.84550	182.4654	-16.14304
45.89717	183.4868	-16.48616
45.95050	184.5434	-16.68644
46.00217	185.5664	-16.92113
46.05383	186.5889	-17.12488
46.10717	187.6440	-17.33878
46.15883	188.6657	-17.50518
46.21050	189.6870	-17.73245
46.26383	190.7416	-17.88982
46.31550	191.7620	-18.16683
46.36716	192.7817	-18.46008
46.42050	193.8338	-18.73953
46.47383	194.8852	-19.02973
46.52383	195.8690	-19.35669
46.57717	196.9175	-19.69537
46.63050	197.9648	-20.04072
46.68050	198.9447	-20.42578
46.73383	199.9889	-20.84183
46.78717	201.0297	-21.30856
46.83883	202.0386	-21.78859
46.89050	203.0446	-22.28970
46.94383	204.0803	-22.88955
46.99550	205.0802	-23.51845
47.04716	206.0772	-24.20802
47.10050	207.1028	-25.00010
47.15216	208.0906	-25.86585
47.20383	209.0746	-26.83050
47.25717	210.0838	-27.95480
47.30883	211.0544	-29.19776
47.36050	212.0165	-30.59846
47.41383	212.9990	-32.23390
47.46717	213.9722	-34.06482
47.51717	214.8736	-35.98265
47.57050	215.8220	-38.19583
47.62383	216.7614	-40.60584
47.67383	217.6317	-42.99179
47.72717	218.5525	-45.62447
47.78050	219.4668	-48.26444
47.83217	220.3550	-50.47610
47.88383	221.2630	-51.95300
47.93716	222.2360	-52.53915
47.98883	223.2352	-51.67348
48.04050	224.3069	-49.19086
48.09384	225.4898	-45.45762
48.14550	226.7082	-40.76264
48.19717	227.9869	-35.78574
48.25050	229.3108	-32.13777
48.30217	230.5577	-29.52419
48.35383	231.7694	-27.45167
48.40717	232.9860	-25.70447
48.46050	234.1740	-24.28538
48.51050	235.2678	-23.19340
48.56383	236.4162	-22.23861
48.61716	237.5489	-21.46211
48.66716	238.6001	-20.87290
48.72050	239.7108	-20.37511
48.77383	240.8136	-19.96339
48.82550	241.8754	-19.64969
48.87717	242.9310	-19.39050
48.93050	244.0176	-19.17604
48.98217	245.0661	-19.01741
49.03383	246.1123	-18.88684
49.08716	247.1890	-18.77892
49.13883	248.2318	-18.70458
49.19050	249.2715	-18.65059
49.24383	250.3438	-18.61414
49.29550	251.3808	-18.59706
49.34716	252.4162	-18.59162
49.40050	253.4850	-18.58964
49.45383	254.5539	-18.58868
49.50383	255.5546	-18.58824
49.55717	256.6224	-18.58840
49.61050	257.6894	-18.58989
49.66050	258.6895	-18.59216
49.71383	259.7572	-18.59639
49.76717	260.8238	-18.60492
49.81883	261.8568	-18.61342
49.87050	262.8900	-18.62923
49.92383	263.9575	-18.65149
49.97550	264.9914	-18.67455
50.02716	266.0234	-18.69404
50.08050	267.0897	-18.71078
50.13217	268.1224	-18.72802
50.18383	269.1559	-18.75084
50.23717	270.2238	-18.77342
50.29050	271.2888	-18.79088
50.34050	272.2881	-18.80708
50.39383	273.3554	-18.82121
50.44717	274.4217	-18.83747
50.49716	275.4210	-18.84825
50.54716	276.3403	-18.30576
50.59716	276.5056	-19.86839
50.65050	276.2106	-19.93359
50.70383	275.7312	-16.89962
50.75550	275.1653	-12.96949
50.80717	274.5224	-9.085099
50.86050	273.7953	-5.509307
50.91217	273.0394	-2.546133
50.96383	272.2422	-.06124882
51.01717	271.3833	2.057056
51.06883	270.5211	3.745410
51.12050	269.6352	5.134049
51.17383	268.7003	6.307550
51.22550	267.7757	7.242066
51.27717	266.8371	8.007834
51.33050	265.8569	8.656182
51.38383	264.8644	9.198540
51.43383	263.9265	9.617561
51.48717	262.9185	9.988124
51.54050	261.9029	10.29607
51.59050	260.9451	10.54644
51.64384	259.9220	10.75272
51.69717	258.8908	10.93571
51.74883	257.8911	11.08761
51.80050	256.8873	11.20764
51.85383	255.8489	11.30970
51.90550	254.8396	11.41167
51.95717	253.8288	11.49118
52.01050	252.7836	11.55924
52.06216	251.7694	11.61575
52.11383	250.7531	11.66422
52.16716	249.7050	11.70975
52.21884	248.6874	11.74537
52.27050	247.6697	11.78043
52.32383	246.6174	11.80824
52.37717	245.5643	11.83389
52.42717	244.5767	11.85341
52.48050	243.5213	11.87136
52.53383	242.4678	11.88427
52.58383	241.4785	11.89374
52.63716	240.4219	11.90472
52.69050	239.3657	11.91392
52.74216	238.3420	11.92337
52.79382	237.3182	11.93320
52.84716	236.2602	11.94325
52.89883	235.2341	11.95021
52.95050	234.2101	11.95704
53.00383	233.1519	11.96351
53.05550	232.1261	11.96952
53.10717	231.1004	11.97548
53.16050	230.0419	11.98152
53.21216	229.0158	11.98727
53.26382	227.9901	11.99313
53.31716	226.9302	11.99930
53.37050	225.8723	12.00550
53.42050	224.8793	12.01139
53.47382	223.8200	12.01759
53.52717	222.7603	12.02385
53.57717	221.7670	12.02992
53.63050	220.7077	12.03641
53.68383	219.6474	12.04307
53.73550	218.6211	12.04962
53.78716	217.5943	12.05595
53.84050	216.5336	12.06247
53.89216	215.5063	12.06859
53.94384	214.4795	12.07460
53.99717	213.4184	12.08064
54.04883	212.3916	12.08626
54.10050	211.3642	12.09176
54.15383	210.3032	12.09725
54.20550	209.2752	12.10245
54.25717	208.2480	12.10734
54.31050	207.1870	12.11239
54.36382	206.1258	12.11737
54.41382	205.1323	12.12173
54.46717	204.0694	12.12639
54.52050	203.0089	12.13080
54.57050	202.0141	12.13489
54.62383	200.9531	12.13899
54.67717	199.8918	12.14283
54.72883	198.8637	12.14658
54.78050	197.8349	12.15017
54.83383	196.7736	12.15388
54.88550	195.7445	12.15739
54.93716	194.7162	12.16085
54.99050	193.6546	12.16434
55.04217	192.6264	12.16766
55.09384	191.5983	12.17078
55.14717	190.5377	12.17374
55.20050	189.4754	12.17644
55.25050	188.4799	12.17894
55.30383	187.4192	12.18179
55.35717	186.3572	12.18426
55.40717	185.3629	12.18656
55.46050	184.3003	12.18882
55.51382	183.2403	12.19092
55.56550	182.2113	12.19288
55.61716	181.1829	12.19492
55.67050	180.1226	12.19708
55.72217	179.0944	12.19924
55.77383	178.0658	12.20165
55.82717	177.0054	12.20446
55.87883	175.9777	12.20731
55.93050	174.9485	12.21027
55.98383	173.8864	12.21359
56.03550	172.8594	12.21682
56.08716	171.8316	12.21997
56.14050	170.7678	12.22328
56.19384	169.7058	12.22684
56.24382	168.7112	12.23005
56.29717	167.6484	12.23352
56.35050	166.5892	12.23700
56.40050	165.5939	12.24133
56.45383	164.5327	12.26411
56.50717	163.4751	12.40226
56.55883	162.4533	12.65906
56.61050	161.4383	13.07075
56.66382	160.4042	13.74604
56.71550	159.4185	14.77772
56.76716	158.4553	16.24568
56.82050	157.4909	18.24302
56.87217	156.5833	20.53552
56.92383	155.6965	23.00472
56.97717	154.7942	25.51090
57.02883	153.9205	27.71483
57.08050	153.0346	29.56957
57.13383	152.1005	31.01224
57.18716	151.1370	31.93247
57.23717	150.2053	32.28401
57.29050	149.1776	32.16294
57.34384	148.1171	31.57505
57.39384	147.0960	30.63617
57.44717	145.9797	29.37084
57.50050	144.8440	27.92592
57.55217	143.7310	26.43612
57.60383	142.6084	24.96808
57.65717	141.4480	23.48793
57.70883	140.3266	22.16782
57.76050	139.2101	20.97662
57.81382	138.0639	19.88744
57.86550	136.9642	18.97283
57.91716	135.8714	18.15328
57.97050	134.7494	17.39766
58.02217	133.6686	16.74097
58.07383	132.5938	16.19596
58.12717	131.4910	15.68066
58.18050	130.3912	15.23099
58.23050	129.3671	14.87194
58.28383	128.2776	14.54664
58.33716	127.1914	14.25687
58.38716	126.1760	14.01484
58.44050	125.0953	13.78910
58.49382	124.0164	13.58612
58.54550	122.9728	13.41404
58.59716	121.9326	13.30269
58.65050	120.8609	13.16485
58.70216	119.8234	13.03345
58.75383	118.7850	12.91544
58.80717	117.7134	12.80473
58.85883	116.6757	12.67543
58.91050	115.6374	12.51287
58.96382	114.5658	12.41737
59.01550	113.5283	12.29596
59.06716	112.4928	12.21203
59.12050	111.4244	12.14131
59.17383	110.3573	12.12391
59.22382	109.3559	12.06916
59.27717	108.2897	11.99978
59.33050	107.2234	11.93439
59.38050	106.2225	11.87614
59.43383	105.1560	11.81942
59.48717	104.0891	11.76525
59.53882	103.0556	11.71246
59.59050	102.0221	11.65570
59.64384	100.9559	11.60244
59.69550	99.92316	11.55736
59.74717	98.89090	11.50089
59.80050	97.82555	11.46862
59.85217	96.79178	11.41931
59.90383	95.76016	11.37235
59.95717	94.69332	11.32632
60.01050	93.62819	11.27738
60.06050	92.62891	11.23695
60.11382	91.56301	11.19217
60.16716	90.49670	11.14426
60.21717	89.49847	11.09906
60.27050	88.43326	11.06248
60.32383	87.36714	11.01547
60.37550	86.33419	10.96282
60.42717	85.30134	10.91821
60.48050	84.23580	10.86933
60.53217	83.20258	10.82627
60.58383	82.16968	10.78004
60.63716	81.10339	10.73866
60.68882	80.07142	10.69482
60.74050	79.03804	10.64385
60.79382	77.97230	10.60813
60.84550	76.93834	10.55200
60.89717	75.90494	10.49731
60.95050	74.83920	10.44798
61.00383	73.77294	10.39478
61.05383	72.77358	10.34858
61.10717	71.70684	10.29692
61.16050	70.64226	10.25406
61.21050	69.64116	10.21328
61.26382	68.57538	10.16974
61.31716	67.50903	10.12165
61.36882	66.47716	10.07328
61.42050	65.44329	10.02822
61.47382	64.37609	9.985747
61.52550	63.34476	9.951268
61.57717	62.31201	9.908886
61.63050	61.24630	9.863121
61.68217	60.21356	9.826991
61.73383	59.18092	9.788378
61.78716	58.11454	9.742072
61.83882	57.08178	9.694939
61.89050	56.04825	9.652338
61.94384	54.98266	9.608184
61.99717	53.91566	9.557587
62.04717	52.91642	9.524637
62.10050	51.85115	9.485664
62.15383	50.78398	9.435995
62.20383	49.78511	9.392414
62.25717	48.72017	9.360284
62.31050	47.65417	9.309656
62.36217	46.62047	9.272813
62.41382	45.59160	9.294819
62.46717	44.52582	9.237506
62.51884	43.49268	9.165799
62.57050	42.45935	9.107975
62.62383	41.39256	9.073774
62.67550	40.35885	9.015524
62.72717	39.32489	8.958868
62.78050	38.25748	8.912492
62.83217	37.22200	8.847556
62.88383	36.18816	8.782372
62.93716	35.11916	8.724265
62.99050	34.05026	8.665298
63.04050	33.04938	8.639741
63.09384	31.98173	8.568476
63.14717	30.91283	8.494246
63.19717	29.91132	8.430168
63.25050	28.84243	8.362306
63.30383	27.77482	8.293299
63.35550	26.74101	8.257418
63.40717	25.70718	8.222632
63.46050	24.63779	8.178274
63.51050	23.63578	8.178950
63.56216	22.82741	7.615219
63.61382	22.89072	9.342278
63.66716	23.25218	9.805938
63.71884	23.76446	8.762909
63.77050	24.36087	7.016210
63.82383	25.05290	5.050375
63.87550	25.77774	3.231956
63.92717	26.54926	1.579672
63.98050	27.38562	0.08631890
64.03384	28.25568	-1.198448
64.08384	29.09795	-2.231988
64.13717	30.02121	-3.175845
64.19050	30.96218	-3.968888
64.24050	31.86056	-4.604546
64.29384	32.83218	-5.176288
64.34717	33.81572	-5.657825
64.39883	34.77865	-6.055359
64.45050	35.74931	-6.398351
64.50384	36.75959	-6.703112
64.55550	37.74472	-6.958188
64.60718	38.73471	-7.169944
64.66050	39.75946	-7.368299
64.71217	40.75807	-7.523281
64.76384	41.75869	-7.665504
64.81717	42.79565	-7.792690
64.87050	43.83354	-7.908792
64.92050	44.81213	-8.000626
64.97384	45.85528	-8.096536
65.02717	46.90152	-8.181030
65.07718	47.88284	-8.250382
65.13050	48.93228	-8.329062
65.18384	49.98172	-8.396011
65.23550	50.99970	-8.464066
65.28717	52.01871	-8.517491
65.34050	53.07132	-8.581962
65.39216	54.09260	-8.638166
65.44384	55.11429	-8.691955
65.49717	56.16964	-8.749559
65.54884	57.19291	-8.802001
65.60050	58.21732	-8.853028
65.65384	59.27424	-8.900738
65.70550	60.29838	-8.952920
65.75718	61.32218	-9.002574
65.81050	62.37938	-9.048991
65.86384	63.43801	-9.103899
65.91382	64.43098	-9.151157
65.96718	65.48990	-9.201206
66.02050	66.54869	-9.252672
66.07050	67.54452	-9.303999
66.12384	68.60475	-9.356332
66.17718	69.66378	-9.408151
66.22884	70.69126	-9.453170
66.28050	71.71870	-9.505043
66.33384	72.77884	-9.559228
66.38550	73.80675	-9.617329
66.43718	74.83550	-9.672144
66.49050	75.89566	-9.724028
66.54218	76.92508	-9.787951
66.59384	77.95280	-9.843660
66.64718	79.01282	-9.898628
66.69884	80.04140	-9.957746
66.75050	81.06963	-10.02313
66.80384	82.13097	-10.08566
66.85718	83.19360	-10.14576
66.90718	84.18775	-10.20764
66.96050	85.24939	-10.27262
67.01384	86.31007	-10.34055
67.06384	87.30475	-10.39363
67.11718	88.36694	-10.46443
67.17050	89.42803	-10.53653
67.22218	90.45699	-10.60224
67.27384	91.48595	-10.66675
67.32718	92.54863	-10.73187
67.37884	93.57774	-10.79863
67.43050	94.60691	-10.86116
67.48384	95.67011	-10.92746
67.53550	96.69843	-10.98932
67.58716	97.72759	-11.04509
67.64050	98.78982	-11.11466
67.69218	99.81974	-11.18059
67.74384	100.8495	-11.23899
67.79718	101.9138	-11.30923
67.85050	102.9756	-11.36707
67.90050	103.9715	-11.42944
67.95384	105.0356	-11.49904
68.00718	106.0978	-11.57280
68.05718	107.0945	-11.63813
68.11050	108.1573	-11.70540
68.16382	109.2197	-11.77077
68.21550	110.2488	-11.83731
68.26716	111.2779	-11.90581
68.32050	112.3406	-11.97839
68.37218	113.3707	-12.04813
68.42384	114.4000	-12.11763
68.47718	115.4633	-12.18812
68.52884	116.4925	-12.26102
68.58050	117.5217	-12.33144
68.63384	118.5847	-12.40205
68.68550	119.6134	-12.48274
68.73718	120.6415	-12.55579
68.79050	121.7043	-12.63754
68.84384	122.7669	-12.72138
68.89384	123.7627	-12.80008
68.94718	124.8244	-12.87882
69.00050	125.8879	-12.95801
69.05050	126.8832	-13.02881
69.10384	127.9453	-13.10816
69.15718	129.0065	-13.18545
69.20884	130.0361	-13.27590
69.26050	131.0647	-13.35784
69.31384	132.1286	-13.44754
69.36550	133.1570	-13.53037
69.41718	134.1863	-13.60806
69.47050	135.2470	-13.68236
69.52218	136.2769	-13.78480
69.57384	137.3019	-13.91052
69.62718	138.3640	-14.02794
69.68050	139.4234	-14.15486
69.73050	140.4167	-14.27909
69.78384	141.4766	-14.41054
69.83716	142.5352	-14.54112
69.88718	143.5289	-14.66844
69.94050	144.5874	-14.80266
69.99384	145.6475	-14.93548
70.04550	146.6734	-15.00170
70.09718	147.7019	-15.06714
70.15050	148.7626	-15.16632
70.20216	149.7916	-15.24520
70.25384	150.8209	-15.34329
70.30718	151.8814	-15.43783
70.35884	152.9096	-15.54732
70.41050	153.9374	-15.66150
70.46384	154.9990	-15.74852
70.51550	156.0276	-15.84160
70.56718	157.0561	-15.93746
70.62050	158.1170	-16.04251
70.67384	159.1791	-16.12742
70.72384	160.1743	-16.20594
70.77718	161.2361	-16.29026
70.83050	162.2990	-16.35446
70.88050	163.2948	-16.40190
70.93384	164.3588	-16.44672
70.98718	165.4246	-16.47225
71.03882	166.4570	-16.49554
71.09050	167.4890	-16.51251
71.14384	168.5552	-16.52710
71.19550	169.5881	-16.54349
71.24718	170.6196	-16.57030
71.30050	171.6857	-16.60477
71.35218	172.7168	-16.66452
71.40384	173.7474	-16.72974
71.45718	174.8114	-16.80889
71.50884	175.8422	-16.88997
71.56050	176.8719	-16.98024
71.61384	177.9354	-17.07052
71.66718	178.9961	-17.19474
71.71718	179.9914	-17.30598
71.77050	181.0515	-17.45274
71.82384	182.1102	-17.59968
71.87384	183.1019	-17.75724
71.92718	184.1605	-17.94840
71.98050	185.2164	-18.15346
72.03218	186.2389	-18.36982
72.08384	187.2599	-18.63226
72.13718	188.3116	-18.89340
72.18884	189.3290	-19.23039
72.24050	190.3458	-19.56784
72.29384	191.3909	-19.94524
72.34550	192.4021	-20.35216
72.39718	193.4115	-20.77225
72.45050	194.4525	-21.23918
72.50218	195.4585	-21.69362
72.55384	196.4652	-22.18806
72.60718	197.5028	-22.68848
72.66050	198.5392	-23.25273
72.71050	199.5067	-23.78245
72.76384	200.5379	-24.44840
72.81718	201.5653	-25.17312
72.86718	202.5248	-25.92323
72.92050	203.5458	-26.75726
72.97384	204.5638	-27.63624
73.02550	205.5474	-28.49869
73.07718	206.5302	-29.35437
73.13050	207.5459	-30.15508
73.18218	208.5341	-30.78124
73.23384	209.5296	-31.14587
73.28718	210.5746	-31.02108
73.33884	211.6136	-30.19284
73.39050	212.6925	-28.52087
73.44384	213.8496	-26.24321
73.49550	214.9951	-24.19273
73.54718	216.1382	-22.66654
73.60050	217.3034	-21.47022
73.65384	218.4512	-20.52289
73.70384	219.5125	-19.79491
73.75718	220.6332	-19.15737
73.81050	221.7444	-18.65044
73.86050	222.7790	-18.26223
73.91382	223.8748	-17.92634
73.96718	224.9654	-17.66650
74.01882	226.0177	-17.45468
74.07050	227.0647	-17.28008
74.12384	228.1446	-17.14862
74.17550	229.1884	-17.05135
74.22718	230.2293	-16.97714
74.28050	231.3022	-16.92189
74.33218	232.3400	-16.87734
74.38384	233.3780	-16.85604
74.43718	234.4474	-16.83516
74.49050	235.5162	-16.82700
74.54050	236.5185	-16.81664
74.59384	237.5856	-16.81287
74.64718	238.6532	-16.81116
74.69718	239.6532	-16.81086
74.75050	240.7208	-16.81263
74.80384	241.7868	-16.81370
74.85550	242.8199	-16.81503
74.90718	243.8526	-16.82171
74.96050	244.9190	-16.82960
75.01218	245.9509	-16.84914
75.06384	246.9839	-16.87128
75.11718	248.0486	-16.88836
75.16884	249.0810	-16.90664
75.22050	250.1136	-16.93038
75.27384	251.1797	-16.94763
75.32550	252.2134	-16.96917
75.37718	253.2450	-16.99654
75.43050	254.3102	-17.01106
75.48384	255.3756	-17.03477
75.53384	256.3740	-17.06389
75.58716	257.4394	-17.09631
75.64050	258.5047	-17.12764
75.69050	259.5037	-17.16670
75.74384	260.5688	-17.19506
75.79718	261.6330	-17.23076
75.84882	262.6656	-17.25665
75.90050	263.6961	-17.29130
75.95384	264.7615	-17.32549
76.00550	265.7938	-17.36008
76.05718	266.8258	-17.40376
76.11050	267.8909	-17.43259
76.16218	268.9215	-17.47276
76.21384	269.9531	-17.51816
76.26716	271.0183	-17.54733
76.31884	272.0490	-17.57924
-2.000000	5.000000	0.0000000