File: 9-C1(1.2mol%)+C20(1.0mol%)/matlab/140-2.txt
CLOSED
Version	1.0
Language	English
Mode	Standard
Run	4
RunSerial	12272
Instrument	DSC Q2000 V24.11 Build 124
Module	DSC Standard Cell RC
Operator
File	\\AE520-1454\Users\dsc\Desktop\Data\29-08-17\140-2.001
ProcName
InstSerial	2000-0883
AutoSerial	1293
Sample	140-2
Size	18.2000	mg
PanMass	Not available
PanResist	Automatic Automatic  K/W
PanFactor	Default Default
Method
Comment
Xcomment	Pan: Tzero Aluminum Hermetic
Xcomment	Gas1: Nitrogen 50.0 ml/min
Xcomment	Gas2: Nitrogen 50.0 ml/min
Text
Exotherm	UP
Kcell	1.05230
Cpconst	Standard: 0.938
Calib	-38.6961
TempCal	1	pts	157.46	156.60
TzeroDt	-87.6168 -0.0009 -1.4231
TzeroDtz	-87.6168 0.0057 6.9570
InstCalFile	Tzero: \\Ae520-1454\ta\Data\DSC\Calibration\2017\CALIBRATION\1562_RCS (90)_05_18_2017 10_50_44.TZR
InstCalFile	Baseline: \\Ae520-1454\ta\Data\DSC\Calibration\2017\2017-05-17_Calibration.001
InstCalFile	Sapphire: \\Ae520-1454\ta\Data\DSC\Calibration\2017\2017-05-17_Saphire.001
InstCalDate	Tzero 2017-05-18 Time 10:50:44
TempRange	-87.39 to 398.39 °C at 10.00 °C/min Heat Only
AutoZero	Delta T Offset 0.000 uV
AutoZero	Delta T0 Offset 0.000 uV
MultiptCal	0
MultiPtDesc	0) Not set
AutoCellConst	Calibration Date 2017-05-18 16:59:28
Controls	Gas 1  Event Off  Sampling 0.2
Cell#	RC-01562
CoolingUnit	RCS (90)
SelHeatFlow	Heat Flow T4P (mW)
AutoLidII	Installed
AutoAnalysis	Off
MacroFile
Nsig	3
Sig1	Time (min)
Sig2	Temperature (°C)
Sig3	Heat Flow (mW)
Date	2017-08-29
Time	15:26:07
OrgMethod	1: Equilibrate at 80.00 °C
OrgMethod	2: Isothermal for 3.00 min
OrgMethod	3: Jump to 140.00 °C
OrgMethod	4: Mark end of cycle 1
OrgMethod	5: Isothermal for 40.00 min
OrgMethod	6: Mark end of cycle 2
OrgMethod	7: Ramp 20.00 °C/min to 280.00 °C
OrgMethod	8: Mark end of cycle 3
OrgMethod	9: Ramp 20.00 °C/min to 20.00 °C
OrgMethod	10: Mark end of cycle 4
OrgMethod	11: Ramp 20.00 °C/min to 280.00 °C
OrgMethod	12: Mark end of cycle 5
OrgFile	C:\Users\jarra\Desktop\DSC\9-C1(1.2mol%)+C20(1.0mol%)\140-2.001
StartOfData
4.99994E-4	79.79886	-2.417679
0.05383332	79.83196	-1.955892
0.1055000	79.85553	-1.608339
0.1571666	79.87299	-1.339370
0.2105000	79.88563	-1.128491
0.2605000	79.89616	-0.9767062
0.3138333	79.90322	-0.8560900
0.3655000	79.90803	-0.7666620
0.4171667	79.91199	-0.6990986
0.4705000	79.91468	-0.6474842
0.5205000	79.91669	-0.6127900
0.5738334	79.91821	-0.5862926
0.6238334	79.91678	-0.5680810
0.6771668	79.91690	-0.5555943
0.7288332	79.91731	-0.5482900
0.7805000	79.91749	-0.5432886
0.8338332	79.91724	-0.5394798
0.8838332	79.91718	-0.5360141
0.9371668	79.91510	-0.5322238
0.9888332	79.91425	-0.5285722
1.040500	79.91372	-0.5249908
1.093833	79.91275	-0.5213866
1.143833	79.91155	-0.5181502
1.197166	79.91066	-0.5148734
1.247166	79.91022	-0.5119763
1.300500	79.90932	-0.5090127
1.352166	79.90900	-0.5063358
1.403833	79.90842	-0.5038690
1.457167	79.90706	-0.5014948
1.507167	79.90800	-0.4994403
1.560500	79.90588	-0.4973996
1.612166	79.90551	-0.4956088
1.663834	79.90494	-0.4939502
1.717167	79.90442	-0.4924056
1.767167	79.90308	-0.4910584
1.820500	79.90318	-0.4898194
1.870500	79.90220	-0.4887613
1.923834	79.90154	-0.4877074
1.975500	79.90116	-0.4868082
2.027166	79.90103	-0.4860312
2.080500	79.90041	-0.4853731
2.130500	79.89932	-0.4848594
2.183833	79.89924	-0.4844053
2.235500	79.89849	-0.4839950
2.287166	79.89790	-0.4836632
2.338833	79.89770	-0.4834036
2.390500	79.89714	-0.4831889
2.443833	79.89634	-0.4830242
2.493833	79.89570	-0.4829097
2.547166	79.89538	-0.4828078
2.598834	79.89550	-0.4827930
2.650500	79.89499	-0.4828604
2.703833	79.89475	-0.4829317
2.753833	79.89290	-0.4830451
2.807167	79.89288	-0.4831879
2.858833	79.89304	-0.4833770
2.910500	79.89242	-0.4835556
2.962167	79.89197	-0.4837671
3.010500	79.89570	-0.5129750
3.060500	80.75862	-2.730286
3.113833	83.58008	-8.773220
3.165500	86.74288	-15.79790
3.217166	90.28212	-23.03190
3.270500	94.23082	-29.95616
3.320500	98.14015	-35.66090
3.373834	102.4768	-40.83713
3.425500	106.7959	-45.00322
3.477167	111.2034	-48.42890
3.530500	115.8111	-51.33774
3.580500	120.1702	-53.47410
3.633833	124.8339	-55.18339
3.683833	128.4634	-54.91455
3.737167	130.7000	-50.37442
3.788833	132.3554	-44.23070
3.840500	133.6266	-37.33370
3.893833	134.6735	-30.59966
3.943833	135.4587	-25.02103
3.997166	136.1418	-19.95092
4.048834	136.6806	-15.92109
4.100500	137.1239	-12.66737
4.153834	137.5004	-10.00535
4.203833	137.7951	-8.038116
4.257167	138.0576	-6.397662
4.307167	138.2652	-5.200840
4.360500	138.4525	-4.208252
4.412167	138.6066	-3.467113
4.463834	138.7394	-2.893172
4.517166	138.8569	-2.438226
4.567167	138.9513	-2.104924
4.620500	139.0390	-1.829644
4.672167	139.1134	-1.622620
4.723834	139.1786	-1.465880
4.775500	139.2356	-1.342989
4.827167	139.2849	-1.249748
4.880500	139.3316	-1.177858
4.930500	139.3696	-1.124957
4.983834	139.4049	-1.083042
5.035500	139.4357	-1.054659
5.087167	139.4636	-1.035490
5.140500	139.4884	-1.021231
5.190500	139.5096	-1.012486
5.243834	139.5305	-1.006521
5.295500	139.5484	-1.002877
5.347168	139.5654	-0.9993582
5.398834	139.5795	-0.9957845
5.450500	139.5926	-0.9922257
5.503834	139.6060	-0.9886824
5.553834	139.6168	-0.9854694
5.607168	139.6265	-0.9821524
5.658832	139.6354	-0.9790688
5.710500	139.6432	-0.9760791
5.763834	139.6513	-0.9731340
5.813832	139.6588	-0.9704363
5.867168	139.6654	-0.9675938
5.917168	139.6708	-0.9649749
5.970500	139.6777	-0.9622466
6.022168	139.6824	-0.9595978
6.073834	139.6872	-0.9569220
6.127168	139.6917	-0.9541749
6.177166	139.6960	-0.9515362
6.230500	139.7001	-0.9486371
6.282166	139.7030	-0.9456801
6.333832	139.7078	-0.9426539
6.387168	139.7101	-0.9393747
6.437168	139.7136	-0.9361484
6.490500	139.7160	-0.9325675
6.540500	139.7193	-0.9290097
6.593832	139.7216	-0.9250309
6.645500	139.7250	-0.9210051
6.697168	139.7270	-0.9167736
6.750500	139.7297	-0.9122109
6.800500	139.7315	-0.9076837
6.853832	139.7345	-0.9026216
6.905500	139.7367	-0.8975258
6.957168	139.7378	-0.8921270
7.010500	139.7414	-0.8863444
7.060500	139.7428	-0.8807105
7.113834	139.7447	-0.8743553
7.163832	139.7461	-0.8681749
7.217168	139.7480	-0.8613770
7.268832	139.7494	-0.8544608
7.320500	139.7514	-0.8471851
7.373834	139.7527	-0.8391212
7.423834	139.7545	-0.8313349
7.477168	139.7566	-0.8222668
7.528832	139.7573	-0.8134824
7.580500	139.7586	-0.8040799
7.633832	139.7604	-0.7945681
7.683832	139.7620	-0.7847056
7.737168	139.7639	-0.7729492
7.787168	139.7657	-0.7614908
7.840500	139.7671	-0.7484918
7.892168	139.7688	-0.7350312
7.943832	139.7696	-0.7203476
7.997168	139.7714	-0.7047806
8.047168	139.7727	-0.6890272
8.100500	139.7754	-0.6710881
8.152168	139.7759	-0.6533491
8.203834	139.7774	-0.6349446
8.255500	139.7788	-0.6151184
8.307168	139.7808	-0.5955240
8.360500	139.7821	-0.5740200
8.410499	139.7830	-0.5550524
8.463834	139.7857	-0.5337441
8.515500	139.7871	-0.5120832
8.567166	139.7883	-0.4899604
8.620499	139.7902	-0.4663476
8.670500	139.7933	-0.4436154
8.723832	139.7948	-0.4208123
8.775499	139.7952	-0.3957395
8.827168	139.7978	-0.3717224
8.878834	139.7994	-0.3470246
8.930500	139.8014	-0.3207246
8.983832	139.8032	-0.2925082
9.033832	139.8052	-0.2672056
9.087168	139.8064	-0.2386295
9.138834	139.8083	-0.2114267
9.190500	139.8099	-0.1821524
9.243834	139.8118	-0.1531870
9.293834	139.8134	-0.1247826
9.347168	139.8152	-.09376938
9.398834	139.8180	-.06416306
9.450500	139.8194	-.03270225
9.502168	139.8218	-1.3198E-3
9.553832	139.8233	0.03010515
9.607166	139.8264	0.06312661
9.657166	139.8286	0.09287957
9.710499	139.8304	0.1267025
9.762168	139.8326	0.1586776
9.813834	139.8357	0.1914383
9.867166	139.8371	0.2273973
9.917168	139.8396	0.2605636
9.970500	139.8423	0.2987748
10.02050	139.8444	0.3354977
10.07383	139.8468	0.3786851
10.12550	139.8509	0.4216802
10.17717	139.8521	0.4692539
10.23050	139.8569	0.5211139
10.28050	139.8594	0.5793715
10.33383	139.8641	0.6497255
10.38550	139.8688	0.7288328
10.43717	139.8751	0.8224038
10.49050	139.8815	0.9339380
10.54050	139.8880	1.053387
10.59383	139.8981	1.195547
10.64383	139.9062	1.343693
10.69717	139.9184	1.511513
10.74883	139.9293	1.685691
10.80050	139.9413	1.866134
10.85383	139.9551	2.052047
10.90383	139.9657	2.232462
10.95717	139.9781	2.415924
11.00883	139.9895	2.585552
11.06050	140.0015	2.743119
11.11383	140.0113	2.898056
11.16383	140.0210	3.029918
11.21717	140.0302	3.163010
11.26717	140.0386	3.275302
11.32050	140.0456	3.387287
11.37217	140.0526	3.485896
11.42383	140.0595	3.578911
11.47717	140.0663	3.668800
11.52717	140.0720	3.752203
11.58050	140.0779	3.835590
11.63216	140.0833	3.915949
11.68383	140.0890	3.996242
11.73717	140.0938	4.076544
11.78717	140.0996	4.150450
11.84050	140.1047	4.228862
11.89050	140.1105	4.300894
11.94383	140.1159	4.378786
11.99550	140.1207	4.453164
12.04717	140.1254	4.526285
12.10050	140.1317	4.603917
12.15050	140.1357	4.675735
12.20384	140.1405	4.754759
12.25550	140.1465	4.832376
12.30717	140.1523	4.913734
12.35883	140.1576	4.996032
12.41050	140.1633	5.080166
12.46383	140.1687	5.172630
12.51383	140.1761	5.259980
12.56716	140.1816	5.358863
12.61884	140.1881	5.455278
12.67050	140.1952	5.554722
12.72383	140.2016	5.660130
12.77383	140.2085	5.762272
12.82717	140.2150	5.871109
12.87883	140.2229	5.975000
12.93050	140.2301	6.080884
12.98216	140.2371	6.185950
13.03383	140.2434	6.290149
13.08717	140.2511	6.394259
13.13717	140.2573	6.490899
13.19050	140.2640	6.589438
13.24216	140.2699	6.683650
13.29384	140.2768	6.774859
13.34717	140.2834	6.865024
13.39717	140.2887	6.947016
13.45050	140.2938	7.031631
13.50050	140.3003	7.115814
13.55383	140.3056	7.190079
13.60550	140.3094	7.255718
13.65717	140.3149	7.315579
13.71050	140.3182	7.371011
13.76050	140.3221	7.416139
13.81383	140.3252	7.456250
13.86550	140.3275	7.488662
13.91716	140.3296	7.511072
13.97050	140.3307	7.528451
14.02050	140.3324	7.540142
14.07384	140.3331	7.547436
14.12384	140.3337	7.551269
14.17717	140.3332	7.555018
14.22884	140.3332	7.558240
14.28050	140.3329	7.560803
14.33383	140.3322	7.562636
14.38383	140.3314	7.563491
14.43716	140.3293	7.563048
14.48883	140.3288	7.559903
14.54050	140.3274	7.553648
14.59383	140.3259	7.543481
14.64383	140.3240	7.531113
14.69717	140.3226	7.516145
14.74717	140.3213	7.500206
14.80050	140.3200	7.481897
14.85217	140.3173	7.458271
14.90383	140.3154	7.427475
14.95717	140.3150	7.414848
15.00717	140.3146	7.409588
15.06050	140.3147	7.404453
15.11217	140.3147	7.399742
15.16383	140.3149	7.395411
15.21716	140.3160	7.391491
15.26717	140.3168	7.388429
15.32050	140.3169	7.385791
15.37050	140.3171	7.383861
15.42383	140.3176	7.382284
15.47550	140.3178	7.381064
15.52717	140.3174	7.379960
15.58050	140.3180	7.378562
15.63050	140.3168	7.376694
15.68383	140.3153	7.372491
15.73550	140.3132	7.358920
15.78717	140.3091	7.329078
15.83883	140.3067	7.276389
15.89050	140.3031	7.210968
15.94384	140.2987	7.135310
15.99383	140.2950	7.053066
16.04716	140.2892	6.963040
16.09883	140.2838	6.874506
16.15050	140.2785	6.782574
16.20383	140.2723	6.689330
16.25383	140.2655	6.600935
16.30716	140.2601	6.505663
16.35883	140.2537	6.420092
16.41050	140.2475	6.327696
16.46216	140.2411	6.238613
16.51383	140.2359	6.148674
16.56716	140.2303	6.059475
16.61716	140.2240	5.979702
16.67050	140.2183	5.895461
16.72216	140.2135	5.817376
16.77383	140.2083	5.740738
16.82716	140.2029	5.665547
16.87716	140.1982	5.596562
16.93050	140.1942	5.523271
16.98216	140.1889	5.457190
17.03383	140.1843	5.391508
17.08550	140.1800	5.327693
17.13716	140.1750	5.266087
17.19050	140.1711	5.204880
17.24050	140.1677	5.147576
17.29383	140.1641	5.088716
17.34550	140.1592	5.030689
17.39716	140.1564	4.972876
17.45050	140.1525	4.917470
17.50050	140.1491	4.866826
17.55383	140.1448	4.814129
17.60383	140.1416	4.761612
17.65716	140.1370	4.705086
17.70883	140.1334	4.652038
17.76050	140.1310	4.598803
17.81383	140.1265	4.544574
17.86383	140.1226	4.495160
17.91716	140.1190	4.442670
17.96883	140.1165	4.391760
18.02050	140.1127	4.340846
18.07383	140.1092	4.289128
18.12383	140.1063	4.239900
18.17716	140.1024	4.188500
18.22716	140.0992	4.141714
18.28050	140.0952	4.091364
18.33216	140.0926	4.042495
18.38383	140.0894	3.993637
18.43716	140.0856	3.943000
18.48716	140.0818	3.897055
18.54050	140.0799	3.848734
18.59216	140.0761	3.802122
18.64383	140.0732	3.756309
18.69716	140.0701	3.707962
18.74716	140.0673	3.662882
18.80050	140.0641	3.615552
18.85050	140.0609	3.572522
18.90383	140.0577	3.526478
18.95550	140.0551	3.480716
19.00716	140.0509	3.437485
19.06050	140.0483	3.391890
19.11050	140.0460	3.349526
19.16383	140.0423	3.303187
19.21550	140.0393	3.258702
19.26716	140.0360	3.214640
19.32050	140.0338	3.167127
19.37050	140.0301	3.124756
19.42383	140.0269	3.079036
19.47383	140.0243	3.035357
19.52716	140.0204	2.991252
19.57883	140.0176	2.946464
19.63050	140.0160	2.900112
19.68383	140.0120	2.853170
19.73383	140.0082	2.809545
19.78717	140.0057	2.761116
19.83883	140.0022	2.713180
19.89050	139.9988	2.664764
19.94216	139.9964	2.615946
19.99383	139.9927	2.567274
20.04716	139.9900	2.516318
20.09716	139.9860	2.468016
20.15050	139.9836	2.415403
20.20216	139.9794	2.365865
20.25383	139.9760	2.314402
20.30716	139.9724	2.260762
20.35716	139.9688	2.208919
20.41050	139.9663	2.153575
20.46216	139.9616	2.099043
20.51383	139.9580	2.043518
20.56550	139.9546	1.986978
20.61716	139.9505	1.932000
20.67050	139.9472	1.871720
20.72050	139.9436	1.814662
20.77383	139.9391	1.752633
20.82550	139.9347	1.693218
20.87716	139.9314	1.631709
20.93050	139.9265	1.568982
20.98050	139.9221	1.506956
21.03383	139.9186	1.441449
21.08383	139.9142	1.378600
21.13716	139.9102	1.312820
21.18883	139.9064	1.245750
21.24050	139.9008	1.181051
21.29383	139.8968	1.111425
21.34383	139.8924	1.046080
21.39716	139.8886	0.9757000
21.44883	139.8830	0.9075269
21.50050	139.8789	0.8405399
21.55383	139.8733	0.7698906
21.60383	139.8696	0.7036068
21.65716	139.8656	0.6348424
21.70717	139.8616	0.5700412
21.76050	139.8556	0.5029400
21.81216	139.8516	0.4360688
21.86383	139.8466	0.3709406
21.91716	139.8429	0.3044231
21.96716	139.8384	0.2436218
22.02050	139.8342	0.1801711
22.07216	139.8302	0.1196503
22.12383	139.8254	0.06181500
22.17717	139.8220	.001327072
22.22716	139.8176	-.05134968
22.28050	139.8144	-0.1074255
22.33050	139.8117	-0.1593715
22.38383	139.8073	-0.2117328
22.43550	139.8034	-0.2589558
22.48716	139.8004	-0.3061107
22.54050	139.7974	-0.3532654
22.59050	139.7946	-0.3961579
22.64383	139.7914	-0.4387593
22.69550	139.7884	-0.4785475
22.74716	139.7853	-0.5152319
22.80050	139.7837	-0.5524107
22.85050	139.7801	-0.5862888
22.90383	139.7786	-0.6190560
22.95383	139.7770	-0.6479873
23.00716	139.7735	-0.6780393
23.05883	139.7715	-0.7051200
23.11050	139.7694	-0.7313428
23.16383	139.7680	-0.7567401
23.21383	139.7662	-0.7791891
23.26716	139.7651	-0.8019156
23.31883	139.7627	-0.8225074
23.37050	139.7611	-0.8415884
23.42216	139.7596	-0.8595399
23.47383	139.7577	-0.8761334
23.52717	139.7575	-0.8924088
23.57716	139.7561	-0.9061837
23.63050	139.7545	-0.9206652
23.68216	139.7536	-0.9322778
23.73383	139.7526	-0.9442826
23.78717	139.7509	-0.9549952
23.83716	139.7508	-0.9649268
23.89050	139.7501	-0.9746478
23.94216	139.7494	-0.9836481
23.99383	139.7482	-0.9919874
24.04550	139.7474	-1.000462
24.09716	139.7468	-1.008948
24.15050	139.7464	-1.017808
24.20050	139.7452	-1.025959
24.25383	139.7442	-1.034717
24.30550	139.7440	-1.043166
24.35716	139.7430	-1.051642
24.41050	139.7430	-1.060364
24.46050	139.7421	-1.068518
24.51383	139.7415	-1.077159
24.56550	139.7414	-1.085424
24.61716	139.7406	-1.093610
24.66883	139.7399	-1.101688
24.72050	139.7396	-1.109657
24.77383	139.7395	-1.117811
24.82383	139.7392	-1.125389
24.87716	139.7387	-1.133289
24.92883	139.7382	-1.140773
24.98050	139.7382	-1.148127
25.03383	139.7366	-1.155534
25.08383	139.7377	-1.162362
25.13716	139.7372	-1.169482
25.18716	139.7369	-1.176018
25.24050	139.7354	-1.182829
25.29216	139.7358	-1.189298
25.34383	139.7353	-1.195593
25.39716	139.7360	-1.201968
25.44716	139.7351	-1.207769
25.50050	139.7343	-1.213780
25.55217	139.7348	-1.219478
25.60383	139.7338	-1.225019
25.65716	139.7342	-1.230626
25.70716	139.7341	-1.235748
25.76050	139.7342	-1.241040
25.81050	139.7332	-1.245880
25.86383	139.7340	-1.250887
25.91550	139.7335	-1.255587
25.96716	139.7329	-1.260156
26.02050	139.7331	-1.264712
26.07050	139.7327	-1.268888
26.12383	139.7324	-1.273279
26.17550	139.7322	-1.277376
26.22717	139.7326	-1.281405
26.28050	139.7328	-1.285398
26.33050	139.7320	-1.289029
26.38383	139.7325	-1.292754
26.43383	139.7314	-1.296175
26.48716	139.7318	-1.299732
26.53883	139.7312	-1.303086
26.59050	139.7320	-1.306392
26.64383	139.7316	-1.309706
26.69383	139.7316	-1.312719
26.74716	139.7314	-1.315851
26.79883	139.7316	-1.318810
26.85050	139.7311	-1.321649
26.90383	139.7311	-1.324553
26.95383	139.7316	-1.327196
27.00716	139.7314	-1.329978
27.05716	139.7308	-1.332476
27.11050	139.7313	-1.335093
27.16217	139.7304	-1.337522
27.21383	139.7302	-1.339884
27.26716	139.7306	-1.342246
27.31716	139.7307	-1.344426
27.37050	139.7300	-1.346620
27.42216	139.7302	-1.348709
27.47383	139.7305	-1.350765
27.52550	139.7298	-1.352785
27.57717	139.7307	-1.354793
27.63050	139.7301	-1.356750
27.68050	139.7305	-1.358544
27.73383	139.7303	-1.360401
27.78550	139.7306	-1.362193
27.83716	139.7294	-1.363933
27.89050	139.7293	-1.365648
27.94050	139.7291	-1.367206
27.99383	139.7300	-1.368856
28.04550	139.7303	-1.370454
28.09716	139.7302	-1.371989
28.14883	139.7298	-1.373500
28.20050	139.7291	-1.374960
28.25383	139.7302	-1.376431
28.30383	139.7298	-1.377742
28.35716	139.7292	-1.379128
28.40883	139.7287	-1.380398
28.46050	139.7291	-1.381692
28.51383	139.7289	-1.382963
28.56383	139.7298	-1.384114
28.61716	139.7286	-1.385377
28.66716	139.7289	-1.386514
28.72050	139.7289	-1.387715
28.77216	139.7290	-1.388848
28.82383	139.7292	-1.389975
28.87716	139.7296	-1.391123
28.92717	139.7291	-1.392151
28.98050	139.7294	-1.393241
29.03216	139.7286	-1.394298
29.08383	139.7290	-1.395340
29.13716	139.7288	-1.396340
29.18717	139.7289	-1.397273
29.24050	139.7288	-1.398256
29.29050	139.7285	-1.399138
29.34383	139.7283	-1.400048
29.39550	139.7280	-1.400907
29.44717	139.7281	-1.401738
29.50050	139.7289	-1.402532
29.55050	139.7295	-1.403295
29.60383	139.7287	-1.404084
29.65550	139.7276	-1.404836
29.70716	139.7283	-1.405584
29.76050	139.7278	-1.406309
29.81050	139.7278	-1.407003
29.86383	139.7282	-1.407754
29.91383	139.7278	-1.408434
29.96716	139.7280	-1.409149
30.01883	139.7276	-1.409836
30.07050	139.7273	-1.410504
30.12383	139.7274	-1.411202
30.17383	139.7284	-1.411865
30.22717	139.7274	-1.412549
30.27883	139.7276	-1.413213
30.33050	139.7276	-1.413832
30.38383	139.7282	-1.414543
30.43383	139.7286	-1.415158
30.48716	139.7280	-1.415802
30.53717	139.7275	-1.416410
30.59050	139.7276	-1.416995
30.64216	139.7280	-1.417586
30.69383	139.7273	-1.418198
30.74716	139.7278	-1.418794
30.79716	139.7280	-1.419347
30.85050	139.7274	-1.419869
30.90216	139.7282	-1.420358
30.95383	139.7283	-1.420864
31.00550	139.7275	-1.421311
31.05716	139.7286	-1.421768
31.11050	139.7272	-1.422217
31.16050	139.7282	-1.422523
31.21383	139.7285	-1.422894
31.26550	139.7275	-1.423274
31.31716	139.7273	-1.423698
31.37050	139.7276	-1.424160
31.42050	139.7274	-1.424546
31.47383	139.7271	-1.424954
31.52550	139.7272	-1.425356
31.57717	139.7274	-1.425762
31.62883	139.7273	-1.426152
31.68050	139.7280	-1.426551
31.73383	139.7276	-1.426894
31.78383	139.7270	-1.427206
31.83716	139.7275	-1.427573
31.88883	139.7269	-1.427928
31.94050	139.7269	-1.428273
31.99383	139.7274	-1.428649
32.04383	139.7274	-1.429012
32.09716	139.7273	-1.429435
32.14883	139.7274	-1.429819
32.20050	139.7261	-1.430180
32.25217	139.7272	-1.430576
32.30383	139.7273	-1.430923
32.35716	139.7270	-1.431272
32.40716	139.7273	-1.431584
32.46050	139.7264	-1.431905
32.51216	139.7272	-1.432231
32.56383	139.7273	-1.432534
32.61716	139.7265	-1.432876
32.66716	139.7267	-1.433154
32.72050	139.7270	-1.433479
32.77050	139.7273	-1.433766
32.82383	139.7273	-1.434091
32.87550	139.7272	-1.434381
32.92717	139.7270	-1.434650
32.98050	139.7266	-1.434941
33.03050	139.7271	-1.435180
33.08383	139.7264	-1.435416
33.13550	139.7259	-1.435616
33.18716	139.7271	-1.435902
33.24050	139.7271	-1.436186
33.29050	139.7270	-1.436412
33.34384	139.7262	-1.436621
33.39383	139.7268	-1.436812
33.44717	139.7259	-1.436998
33.49883	139.7269	-1.437215
33.55050	139.7262	-1.437419
33.60383	139.7270	-1.437651
33.65383	139.7264	-1.437897
33.70716	139.7266	-1.438191
33.75883	139.7272	-1.438469
33.81050	139.7266	-1.438745
33.86383	139.7276	-1.438990
33.91383	139.7265	-1.439242
33.96716	139.7272	-1.439474
34.01716	139.7269	-1.439696
34.07050	139.7274	-1.439914
34.12216	139.7274	-1.440160
34.17383	139.7263	-1.440394
34.22717	139.7272	-1.440629
34.27716	139.7264	-1.440839
34.33050	139.7261	-1.441034
34.38216	139.7269	-1.441241
34.43384	139.7257	-1.441453
34.48717	139.7262	-1.441706
34.53717	139.7268	-1.441993
34.59050	139.7272	-1.442304
34.64050	139.7274	-1.442564
34.69383	139.7262	-1.442787
34.74550	139.7268	-1.442985
34.79716	139.7263	-1.443186
34.85050	139.7260	-1.443396
34.90050	139.7263	-1.443584
34.95383	139.7264	-1.443786
35.00550	139.7260	-1.443963
35.05716	139.7268	-1.444194
35.10883	139.7260	-1.444371
35.16050	139.7264	-1.444591
35.21383	139.7268	-1.444834
35.26383	139.7270	-1.445002
35.31716	139.7264	-1.445197
35.36883	139.7265	-1.445367
35.42050	139.7261	-1.445534
35.47383	139.7266	-1.445722
35.52383	139.7262	-1.445928
35.57717	139.7261	-1.446125
35.62883	139.7263	-1.446321
35.68050	139.7264	-1.446521
35.73216	139.7259	-1.446654
35.78383	139.7268	-1.446821
35.83716	139.7268	-1.446998
35.88716	139.7260	-1.447157
35.94050	139.7261	-1.447297
35.99216	139.7262	-1.447418
36.04383	139.7261	-1.447628
36.09716	139.7257	-1.447769
36.14717	139.7263	-1.447955
36.20050	139.7260	-1.448164
36.25050	139.7262	-1.448332
36.30383	139.7262	-1.448514
36.35550	139.7259	-1.448663
36.40716	139.7263	-1.448816
36.46050	139.7262	-1.448937
36.51050	139.7263	-1.449038
36.56383	139.7251	-1.449146
36.61550	139.7265	-1.449275
36.66716	139.7261	-1.449370
36.72050	139.7257	-1.449449
36.77050	139.7259	-1.449544
36.82383	139.7253	-1.449647
36.87383	139.7249	-1.449726
36.92717	139.7251	-1.449815
36.97883	139.7258	-1.449944
37.03050	139.7266	-1.450089
37.08383	139.7264	-1.450243
37.13383	139.7261	-1.450356
37.18716	139.7260	-1.450539
37.23883	139.7256	-1.450752
37.29050	139.7260	-1.450968
37.34384	139.7264	-1.451236
37.39383	139.7268	-1.451468
37.44717	139.7262	-1.451732
37.49716	139.7274	-1.451939
37.55050	139.7269	-1.452084
37.60217	139.7260	-1.452258
37.65383	139.7263	-1.452408
37.70716	139.7259	-1.452566
37.75716	139.7252	-1.452697
37.81050	139.7256	-1.452818
37.86217	139.7261	-1.452912
37.91383	139.7266	-1.453015
37.96716	139.7263	-1.453135
38.01716	139.7260	-1.453311
38.07050	139.7259	-1.453436
38.12050	139.7273	-1.453584
38.17383	139.7261	-1.453757
38.22550	139.7261	-1.453883
38.27716	139.7268	-1.454004
38.33050	139.7266	-1.454175
38.38050	139.7262	-1.454276
38.43384	139.7261	-1.454353
38.48550	139.7261	-1.454474
38.53717	139.7270	-1.454588
38.58883	139.7264	-1.454676
38.64050	139.7258	-1.454748
38.69383	139.7257	-1.454846
38.74383	139.7267	-1.454958
38.79716	139.7255	-1.455038
38.84883	139.7260	-1.455122
38.90050	139.7261	-1.455223
38.95383	139.7256	-1.455325
39.00383	139.7247	-1.455395
39.05716	139.7263	-1.455503
39.10883	139.7264	-1.455658
39.16050	139.7258	-1.455752
39.21216	139.7264	-1.455853
39.26383	139.7263	-1.455911
39.31716	139.7258	-1.455998
39.36716	139.7258	-1.456058
39.42050	139.7257	-1.456120
39.47217	139.7252	-1.456158
39.52383	139.7252	-1.456194
39.57717	139.7262	-1.456256
39.62717	139.7258	-1.456355
39.68050	139.7251	-1.456415
39.73216	139.7249	-1.456455
39.78383	139.7254	-1.456501
39.83550	139.7253	-1.456558
39.88716	139.7251	-1.456622
39.94050	139.7248	-1.456671
39.99050	139.7252	-1.456755
40.04383	139.7261	-1.456882
40.09550	139.7258	-1.457018
40.14717	139.7252	-1.457173
40.20050	139.7259	-1.457327
40.25050	139.7254	-1.457431
40.30383	139.7264	-1.457537
40.35383	139.7259	-1.457687
40.40716	139.7255	-1.457802
40.45883	139.7261	-1.457944
40.51050	139.7260	-1.458098
40.56383	139.7258	-1.458222
40.61383	139.7250	-1.458312
40.66716	139.7250	-1.458367
40.71884	139.7254	-1.458377
40.77050	139.7256	-1.458402
40.82383	139.7260	-1.458448
40.87383	139.7258	-1.458429
40.92717	139.7249	-1.458453
40.97717	139.7254	-1.458512
41.03050	139.7256	-1.458598
41.08217	139.7262	-1.458670
41.13383	139.7254	-1.458786
41.18716	139.7251	-1.458880
41.23717	139.7250	-1.458984
41.29050	139.7253	-1.459076
41.34217	139.7260	-1.459187
41.39383	139.7255	-1.459235
41.44717	139.7256	-1.459309
41.49716	139.7254	-1.459356
41.55050	139.7257	-1.459414
41.60050	139.7256	-1.459495
41.65383	139.7264	-1.459606
41.70550	139.7257	-1.459712
41.75717	139.7259	-1.459805
41.81050	139.7264	-1.459850
41.86050	139.7255	-1.459892
41.91383	139.7250	-1.459913
41.96550	139.7259	-1.459925
42.01717	139.7261	-1.459978
42.07050	139.7256	-1.460033
42.12050	139.7255	-1.460086
42.17383	139.7260	-1.460134
42.22383	139.7257	-1.460208
42.27716	139.7261	-1.460288
42.32883	139.7262	-1.460408
42.38050	139.7261	-1.460454
42.43383	139.7255	-1.460517
42.48383	139.7252	-1.460561
42.53717	139.7258	-1.460634
42.58883	139.7250	-1.460648
42.64050	139.7258	-1.460704
42.69217	139.7258	-1.460752
42.74383	139.7255	-1.460778
42.79716	139.7260	-1.460824
42.84716	139.7257	-1.460815
42.90050	139.7255	-1.460854
42.95216	139.7256	-1.460861
43.00050	139.7258	-1.460882
43.05383	139.7670	-1.500990
43.10550	140.1403	-2.738547
43.15717	140.7246	-4.555790
43.21050	141.4396	-6.506705
43.26050	142.1837	-8.139066
43.31383	143.0360	-9.553814
43.36550	143.9041	-10.65649
43.41716	144.8040	-11.52241
43.47050	145.7595	-12.21098
43.52050	146.6724	-12.71450
43.57383	147.6627	-13.13626
43.62383	148.6021	-13.44054
43.67717	149.6142	-13.69623
43.72883	150.6018	-13.89290
43.78050	151.5952	-14.05381
43.83383	152.6263	-14.19836
43.88383	153.5968	-14.30777
43.93716	154.6342	-14.42004
43.98883	155.6419	-14.51254
44.04050	156.6525	-14.60476
44.09384	157.6958	-14.69473
44.14383	158.6775	-14.77846
44.19717	159.7256	-14.86103
44.24716	160.7076	-14.94455
44.30050	161.7570	-15.03562
44.35217	162.7753	-15.12483
44.40383	163.7938	-15.21267
44.45717	164.8461	-15.30856
44.50717	165.8332	-15.40352
44.56050	166.8870	-15.50327
44.61217	167.9084	-15.59786
44.66383	168.9302	-15.69554
44.71717	169.9852	-15.80020
44.76717	170.9742	-15.90520
44.82050	172.0305	-16.01871
44.87050	173.0192	-16.12540
44.92383	174.0759	-16.23688
44.97550	175.0985	-16.35771
45.02716	176.1221	-16.47450
45.08050	177.1778	-16.60420
45.13050	178.1688	-16.72815
45.18383	179.2245	-16.87235
45.23550	180.2474	-17.02494
45.28717	181.2700	-17.16788
45.33883	182.2924	-17.33031
45.39050	183.3162	-17.49706
45.44383	184.3699	-17.69035
45.49383	185.3579	-17.86256
45.54716	186.4115	-18.06411
45.59883	187.4327	-18.26687
45.65050	188.4533	-18.49130
45.70383	189.5058	-18.71806
45.75383	190.4923	-18.95700
45.80717	191.5439	-19.21553
45.85883	192.5614	-19.49384
45.91050	193.5778	-19.76687
45.96216	194.5937	-20.08434
46.01383	195.6090	-20.40854
46.06717	196.6554	-20.76731
46.11716	197.6356	-21.13193
46.17050	198.6783	-21.55465
46.22217	199.6876	-21.99992
46.27383	200.6949	-22.47266
46.32717	201.7324	-23.01575
46.37717	202.7028	-23.55798
46.43050	203.7349	-24.21996
46.48217	204.7318	-24.91114
46.53383	205.7249	-25.68186
46.58550	206.7127	-26.56447
46.63716	207.6958	-27.56808
46.69050	208.7013	-28.77054
46.74050	209.6364	-30.08081
46.79383	210.6214	-31.73672
46.84550	211.5638	-33.61278
46.89717	212.4890	-35.80408
46.95050	213.4256	-38.41028
47.00050	214.2866	-41.12590
47.05383	215.1866	-44.30866
47.10383	216.0162	-47.49481
47.15717	216.8904	-50.83226
47.20883	217.7406	-53.55766
47.26050	218.6138	-55.69526
47.31383	219.5451	-57.09806
47.36383	220.4809	-55.98428
47.41716	221.6169	-51.69093
47.46884	222.8057	-47.64250
47.52050	224.0606	-42.14470
47.57383	225.4502	-34.71705
47.62383	226.7784	-30.10063
47.67717	228.1311	-27.05158
47.72717	229.3364	-24.98354
47.78050	230.5705	-23.32816
47.83217	231.7244	-22.12930
47.88383	232.8480	-21.23784
47.93716	233.9842	-20.53703
47.98717	235.0337	-20.04736
48.04050	236.1396	-19.65632
48.09217	237.2020	-19.37538
48.14383	238.2573	-19.17269
48.19717	239.3401	-19.02783
48.24716	240.3518	-18.93390
48.30050	241.4269	-18.86364
48.35050	242.4331	-18.82372
48.40383	243.5038	-18.79668
48.45550	244.5402	-18.78120
48.50717	245.5762	-18.77409
48.56050	246.6458	-18.77251
48.61050	247.6466	-18.77136
48.66383	248.7142	-18.77094
48.71550	249.7478	-18.77104
48.76717	250.7823	-18.77275
48.82050	251.8484	-18.77789
48.87050	252.8474	-18.78622
48.92383	253.9138	-18.79841
48.97383	254.9140	-18.81592
49.02716	255.9791	-18.84522
49.07883	257.0087	-18.94703
49.13050	258.0397	-18.96321
49.18383	259.1039	-18.98804
49.23383	260.1014	-19.02649
49.28717	261.1659	-19.06748
49.33883	262.1970	-19.11394
49.39050	263.2295	-19.16168
49.44217	264.2609	-19.20530
49.49383	265.2930	-19.24508
49.54716	266.3588	-19.28559
49.59716	267.3576	-19.32162
49.65050	268.4218	-19.35689
49.70216	269.4532	-19.40116
49.75383	270.4852	-19.43750
49.80717	271.5496	-19.47187
49.85717	272.5482	-19.51155
49.91050	273.6136	-19.54633
49.96216	274.6450	-19.56837
50.01050	275.6105	-19.59129
50.06050	276.4542	-19.74759
50.11383	276.6152	-18.42379
50.16550	276.4168	-13.84961
50.21717	276.0081	-8.722090
50.27050	275.4375	-3.999500
50.32050	274.8021	-0.3796073
50.37383	274.0431	2.670872
50.42550	273.2469	4.916811
50.47717	272.4053	6.644093
50.53050	271.5009	8.001768
50.58050	270.6264	8.959241
50.63383	269.6708	9.740222
50.68383	268.7606	10.28995
50.73717	267.7722	10.73943
50.78883	266.8056	11.06712
50.84050	265.8297	11.32055
50.89383	264.8150	11.51456
50.94383	263.8581	11.66223
50.99716	262.8316	11.77553
51.04883	261.8333	11.85946
51.10050	260.8318	11.92651
51.15383	259.7944	11.98118
51.20383	258.8203	12.01768
51.25717	257.7787	12.05179
51.30717	256.7996	12.07712
51.36050	255.7544	12.09706
51.41216	254.7390	12.11556
51.46383	253.7234	12.13043
51.51716	252.6732	12.14208
51.56716	251.6871	12.15000
51.62050	250.6339	12.15642
51.67217	249.6142	12.16231
51.72383	248.5941	12.16808
51.77550	247.5734	12.17340
51.82717	246.5517	12.17881
51.88050	245.4964	12.18447
51.93050	244.5072	12.18991
51.98383	243.4492	12.19564
52.03550	242.4261	12.20097
52.08716	241.4028	12.20618
52.14050	240.3439	12.21140
52.19050	239.3540	12.21617
52.24383	238.2958	12.22118
52.29550	237.2711	12.22600
52.34716	236.2454	12.23094
52.39883	235.2211	12.23562
52.45050	234.1949	12.24024
52.50383	233.1384	12.24484
52.55383	232.1459	12.24918
52.60717	231.0872	12.25398
52.65883	230.0602	12.25872
52.71050	229.0335	12.26335
52.76382	227.9742	12.26823
52.81382	226.9806	12.27286
52.86716	225.9214	12.27768
52.91716	224.9286	12.28240
52.97050	223.8685	12.28737
53.02217	222.8422	12.29224
53.07383	221.8150	12.29714
53.12717	220.7556	12.30210
53.17717	219.7614	12.30683
53.23050	218.7010	12.31190
53.28217	217.6728	12.31655
53.33383	216.6461	12.32096
53.38716	215.5856	12.32542
53.43716	214.5920	12.32957
53.49050	213.5305	12.33378
53.54050	212.5369	12.33764
53.59384	211.4760	12.34164
53.64550	210.4491	12.34547
53.69717	209.4206	12.34927
53.75050	208.3607	12.35292
53.80050	207.3656	12.35634
53.85383	206.3052	12.35986
53.90550	205.2773	12.36321
53.95717	204.2501	12.36657
54.01050	203.1889	12.37000
54.06050	202.1968	12.37304
54.11382	201.1364	12.37639
54.16382	200.1413	12.37971
54.21717	199.0804	12.38330
54.26884	198.0539	12.38679
54.32050	197.0262	12.39026
54.37383	195.9656	12.39430
54.42383	194.9714	12.39785
54.47717	193.9103	12.40219
54.52883	192.8823	12.40628
54.58050	191.8532	12.41044
54.63383	190.7919	12.41456
54.68383	189.7967	12.41821
54.73717	188.7367	12.42194
54.78716	187.7410	12.42539
54.84050	186.6795	12.42892
54.89216	185.6517	12.43231
54.94384	184.6248	12.43562
54.99717	183.5638	12.43891
55.04717	182.5706	12.44206
55.10050	181.5086	12.44560
55.15217	180.4816	12.44912
55.20383	179.4540	12.45289
55.25550	178.4266	12.45709
55.30717	177.3989	12.46145
55.36050	176.3371	12.46614
55.41050	175.3432	12.47060
55.46382	174.2821	12.47559
55.51550	173.2544	12.48051
55.56716	172.2266	12.48528
55.62050	171.1662	12.49026
55.67050	170.1715	12.49492
55.72382	169.1106	12.50032
55.77550	168.0835	12.50618
55.82717	167.0558	12.51794
55.87883	166.0295	12.55760
55.93050	165.0045	12.70438
55.98383	163.9508	12.98119
56.03383	162.9686	13.37104
56.08716	161.9331	14.03606
56.13882	160.9486	15.06418
56.19050	159.9873	16.60008
56.24382	159.0262	18.73450
56.29382	158.1576	21.19049
56.34716	157.2570	24.03733
56.39883	156.3983	26.75000
56.45050	155.5384	29.15240
56.50217	154.6642	31.09689
56.55383	153.7626	32.42350
56.60717	152.7946	33.10070
56.65717	151.8495	33.10669
56.71050	150.7992	32.67735
56.76216	149.7441	31.46096
56.81382	148.6594	30.07257
56.86716	147.5142	28.43310
56.91716	146.4259	26.81561
56.97050	145.2566	25.08800
57.02050	144.1591	23.52248
57.07383	142.9889	21.97516
57.12550	141.8609	20.60761
57.17717	140.7410	19.40356
57.23050	139.5958	18.30548
57.28050	138.5318	17.45812
57.33383	137.4051	16.68061
57.38550	136.3243	16.05274
57.43716	135.2508	15.53312
57.49050	134.1499	15.09204
57.54050	133.1246	14.74006
57.59384	132.0370	14.46462
57.64384	131.0250	14.24259
57.69717	129.9420	13.96011
57.74883	128.8965	13.79151
57.80050	127.8524	13.59695
57.85383	126.7768	13.41498
57.90383	125.7698	13.26866
57.95717	124.6979	13.15544
58.00883	123.6595	13.04429
58.06050	122.6237	12.94315
58.11382	121.5544	12.84363
58.16382	120.5531	12.76080
58.21717	119.4845	12.68523
58.26716	118.4833	12.62151
58.32050	117.4163	12.55277
58.37217	116.3829	12.49293
58.42383	115.3500	12.43754
58.47717	114.2839	12.37696
58.52717	113.2833	12.32609
58.58050	112.2170	12.26767
58.63217	111.1824	12.20410
58.68383	110.1492	12.13665
58.73717	109.0832	12.09575
58.78716	108.0837	12.05527
58.84050	107.0180	11.99931
58.89050	106.0194	11.95241
58.94384	104.9546	11.90423
58.99550	103.9223	11.86206
59.04717	102.8899	11.81923
59.10050	101.8242	11.77479
59.15050	100.8257	11.72895
59.20383	99.76088	11.68572
59.25550	98.72800	11.63380
59.30717	97.69538	11.59366
59.35883	96.66272	11.55454
59.41050	95.62975	11.51042
59.46382	94.56636	11.46463
59.51382	93.56795	11.42953
59.56716	92.50090	11.33958
59.61882	91.46801	11.31116
59.67050	90.43511	11.27833
59.72382	89.36993	11.23692
59.77383	88.37078	11.19159
59.82717	87.30676	11.13430
59.87883	86.27371	11.10430
59.93050	85.24219	11.04194
59.98217	84.21003	11.01008
60.03383	83.17712	10.97045
60.08716	82.11210	10.93782
60.13716	81.11343	10.90463
60.19050	80.04745	10.86448
60.24216	79.01556	10.82066
60.29382	77.98347	10.77616
60.34716	76.91811	10.72302
60.39717	75.91924	10.68458
60.45050	74.85339	10.64999
60.50050	73.85540	10.62073
60.55383	72.79044	10.58238
60.60550	71.75764	10.53733
60.65717	70.72550	10.50496
60.71050	69.65994	10.47046
60.76050	68.65972	10.41063
60.81382	67.59326	10.36193
60.86550	66.56048	10.29977
60.91716	65.52876	10.26921
60.97050	64.46230	10.23921
61.02050	63.46326	10.20792
61.07383	62.39641	10.15327
61.12383	61.39691	10.10539
61.17717	60.33062	10.06349
61.22883	59.29737	10.00450
61.28050	58.26416	9.962524
61.33383	57.19941	9.934305
61.38383	56.19976	9.904056
61.43716	55.13491	9.867298
61.48882	54.10130	9.822458
61.54050	53.06890	9.768436
61.59384	52.00174	9.725861
61.64384	51.00125	9.650462
61.69717	49.93496	9.619164
61.74717	48.93484	9.589191
61.80050	47.86953	9.543156
61.85217	46.83622	9.495328
61.90383	45.80426	9.457547
61.95717	44.73825	9.414718
62.00717	43.73831	9.375892
62.06050	42.67064	9.333054
62.11217	41.63914	9.276313
62.16382	40.60656	9.230920
62.21717	39.54020	9.183759
62.26716	38.53928	9.140061
62.32050	37.47240	9.088972
62.37050	36.47012	8.954516
62.42383	35.40381	8.939095
62.47550	34.36954	8.894582
62.52717	33.33632	8.844191
62.58050	32.26981	8.791495
62.63050	31.26852	8.741424
62.68383	30.20074	8.682382
62.73550	29.16744	8.632672
62.78716	28.13315	8.575207
62.83882	27.09868	8.505890
62.89050	26.06345	8.445789
62.94384	24.99543	8.382402
62.99382	23.99284	8.384726
63.04550	23.00770	8.232750
63.09716	22.68138	8.160552
63.15050	22.85114	7.116172
63.20050	23.21037	5.229231
63.25383	23.74344	2.978140
63.30550	24.36875	0.9380234
63.35717	25.07310	-0.8304124
63.41050	25.86783	-2.354218
63.46050	26.66078	-3.530881
63.51382	27.54428	-4.550023
63.56550	28.43264	-5.344238
63.61716	29.34541	-5.989584
63.66882	30.27776	-6.508101
63.72050	31.22622	-6.934958
63.77383	32.21658	-7.292114
63.82383	33.15794	-7.572063
63.87716	34.16912	-7.803832
63.92883	35.15600	-7.995734
63.98050	36.15004	-8.144390
64.03384	37.17756	-8.284984
64.08384	38.14584	-8.387360
64.13717	39.18305	-8.482558
64.18717	40.15847	-8.561030
64.24050	41.20108	-8.630255
64.29218	42.21296	-8.686871
64.34384	43.22644	-8.745382
64.39717	44.27574	-8.799311
64.44717	45.26039	-8.846005
64.50050	46.31181	-8.897091
64.55218	47.33072	-8.937532
64.60383	48.35028	-8.982062
64.65718	49.40396	-9.031124
64.70717	50.39180	-9.078606
64.76050	51.44758	-9.129503
64.81050	52.43724	-9.177574
64.86384	53.49405	-9.230141
64.91550	54.51736	-9.278656
64.96717	55.54242	-9.322511
65.02050	56.60064	-9.373215
65.07050	57.59285	-9.417656
65.12383	58.65250	-9.466032
65.17550	59.67828	-9.511466
65.22718	60.70367	-9.559131
65.28050	61.76201	-9.614790
65.33050	62.75610	-9.665663
65.38384	63.81621	-9.721212
65.43384	64.81068	-9.773116
65.48717	65.87168	-9.823188
65.53882	66.89912	-9.873772
65.59050	67.92640	-9.982160
65.64384	68.98902	-10.01364
65.69384	69.98355	-10.05129
65.74718	71.04530	-10.09628
65.79884	72.07482	-10.15334
65.85050	73.10253	-10.21364
65.90384	74.16562	-10.26238
65.95384	75.16095	-10.31177
66.00718	76.22456	-10.37511
66.05718	77.22139	-10.43079
66.11050	78.28370	-10.48844
66.16218	79.31269	-10.55298
66.21384	80.34004	-10.63014
66.26716	81.40230	-10.68230
66.31718	82.39710	-10.73886
66.37050	83.46000	-10.80227
66.42218	84.48925	-10.87594
66.47384	85.51806	-10.94187
66.52550	86.54694	-11.00672
66.57718	87.57516	-11.06694
66.63050	88.63800	-11.13317
66.68050	89.63391	-11.20382
66.73384	90.69686	-11.27164
66.78550	91.72656	-11.33780
66.83716	92.75656	-11.40498
66.89050	93.81939	-11.47914
66.94050	94.81609	-11.54190
66.99384	95.87888	-11.61254
67.04550	96.90912	-11.67453
67.09718	97.93845	-11.73475
67.14884	98.96803	-11.79808
67.20050	99.99882	-11.86738
67.25384	101.0609	-11.93631
67.30384	102.0580	-12.00146
67.35718	103.1208	-12.07555
67.40884	104.1510	-12.14689
67.46050	105.1809	-12.21946
67.51384	106.2431	-12.29267
67.56384	107.2399	-12.37223
67.61718	108.3022	-12.43293
67.66718	109.2993	-12.49822
67.72050	110.3615	-12.57044
67.77218	111.3916	-12.64439
67.82384	112.4207	-12.71714
67.87718	113.4833	-12.79030
67.92718	114.4790	-12.85824
67.98050	115.5410	-12.93846
68.03218	116.5705	-13.01008
68.08384	117.6004	-13.08259
68.13718	118.6634	-13.15892
68.18718	119.6597	-13.24018
68.24050	120.7226	-13.31810
68.29050	121.7177	-13.39116
68.34384	122.7794	-13.47821
68.39550	123.8086	-13.55278
68.44718	124.8365	-13.64926
68.50050	125.8984	-13.72299
68.55050	126.8948	-13.81286
68.60384	127.9580	-13.89569
68.65550	128.9875	-13.98560
68.70718	130.0156	-14.08318
68.76050	131.0781	-14.16410
68.81050	132.0736	-14.23937
68.86384	133.1346	-14.33050
68.91382	134.1288	-14.41824
68.96718	135.1910	-14.50128
69.01882	136.2198	-14.59642
69.07050	137.2470	-14.69317
69.12384	138.3088	-14.80138
69.17384	139.3026	-14.89937
69.22718	140.3629	-15.05009
69.27884	141.3912	-15.10789
69.33050	142.4206	-15.20531
69.38384	143.4826	-15.30524
69.43384	144.4779	-15.39878
69.48718	145.5399	-15.48888
69.53718	146.5346	-15.58588
69.59050	147.5964	-15.68577
69.64216	148.6241	-15.79013
69.69384	149.6523	-15.87996
69.74718	150.7137	-15.98934
69.79718	151.7080	-16.07499
69.85050	152.7692	-16.18104
69.90218	153.7974	-16.27908
69.95384	154.8253	-16.37624
70.00550	155.8528	-16.46992
70.05718	156.8806	-16.55744
70.11050	157.9422	-16.64230
70.16050	158.9388	-16.70278
70.21384	160.0024	-16.76160
70.26550	161.0330	-16.80490
70.31718	162.0652	-16.83390
70.37050	163.1309	-16.84940
70.42050	164.1305	-16.86322
70.47384	165.1973	-16.87576
70.52550	166.2302	-16.88822
70.57718	167.2630	-16.91475
70.62884	168.2948	-16.95156
70.68050	169.3268	-16.99508
70.73384	170.3919	-17.04906
70.78384	171.3899	-17.10447
70.83716	172.4539	-17.19406
70.88884	173.4840	-17.28404
70.94050	174.5141	-17.37869
70.99384	175.5759	-17.47929
71.04384	176.5729	-17.59328
71.09718	177.6336	-17.71318
71.14884	178.6596	-17.84634
71.20050	179.6862	-18.00173
71.25218	180.7120	-18.17223
71.30384	181.7366	-18.36051
71.35718	182.7926	-18.57035
71.40718	183.7821	-18.79386
71.46050	184.8340	-19.05701
71.51218	185.8533	-19.34264
71.56384	186.8694	-19.66925
71.61718	187.9168	-20.03529
71.66718	188.8976	-20.40648
71.72050	189.9409	-20.83480
71.77050	190.9178	-21.26213
71.82384	191.9580	-21.72238
71.87550	192.9639	-22.20353
71.92718	193.9699	-22.67685
71.98050	195.0058	-23.21252
72.03050	195.9754	-23.76139
72.08384	197.0073	-24.40041
72.13550	198.0038	-25.08912
72.18718	198.9972	-25.84141
72.24050	200.0172	-26.69813
72.29050	200.9718	-27.54746
72.34384	201.9851	-28.47898
72.39384	202.9356	-29.37467
72.44718	203.9469	-30.26599
72.49884	204.9289	-31.04142
72.55050	205.9182	-31.59150
72.60384	206.9525	-31.71156
72.65384	207.9480	-31.25835
72.70718	209.0522	-29.54492
72.75884	210.1711	-27.12697
72.81050	211.3285	-24.53779
72.86384	212.5350	-22.38893
72.91382	213.6494	-21.04619
72.96718	214.8114	-20.04728
73.01716	215.8806	-19.29973
73.07050	217.0030	-18.70882
73.12218	218.0772	-18.28434
73.17384	219.1427	-17.95672
73.22718	220.2332	-17.71232
73.27718	221.2511	-17.54035
73.33050	222.3315	-17.41567
73.38218	223.3744	-17.32401
73.43384	224.4148	-17.26087
73.48718	225.4878	-17.21430
73.53718	226.4905	-17.19422
73.59050	227.5594	-17.17805
73.64050	228.5613	-17.17215
73.69384	229.6289	-17.17024
73.74550	230.6629	-17.16955
73.79718	231.6956	-17.16968
73.85050	232.7622	-17.17091
73.90050	233.7619	-17.17577
73.95384	234.8275	-17.18432
74.00550	235.8593	-17.19624
74.05718	236.8922	-17.20948
74.10884	237.9238	-17.22778
74.16050	238.9561	-17.24871
74.21384	240.0204	-17.27722
74.26384	241.0194	-17.30608
74.31718	242.0847	-17.34862
74.36884	243.1158	-17.38246
74.42050	244.1482	-17.41558
74.47384	245.2134	-17.44736
74.52384	246.2122	-17.47724
74.57718	247.2773	-17.50501
74.62884	248.3094	-17.52887
74.68050	249.3416	-17.55501
74.73218	250.3734	-17.58027
74.78384	251.4050	-17.61189
74.83716	252.4705	-17.64168
74.88718	253.4686	-17.67243
74.94050	254.5330	-17.70104
74.99218	255.5658	-17.73630
75.04384	256.5976	-17.77527
75.09718	257.6627	-17.81104
75.14718	258.6604	-17.84638
75.20050	259.7256	-17.88623
75.25050	260.7231	-17.92086
75.30384	261.7871	-17.96035
75.35550	262.8188	-18.00524
75.40718	263.8499	-18.04643
75.46050	264.9140	-18.08533
75.51050	265.9119	-18.12659
75.56384	266.9780	-18.16716
75.61550	268.0085	-18.20564
75.66718	269.0402	-18.24322
75.72050	270.1043	-18.27958
75.77050	271.1014	-18.31245
75.82384	272.1650	-18.35282
-2.000000	5.000000	0.0000000