File: 9-C1(1.2mol%)+C20(1.0mol%)/matlab/140-1.txt
CLOSED
Version	1.0
Language	English
Mode	Standard
Run	3
RunSerial	12271
Instrument	DSC Q2000 V24.11 Build 124
Module	DSC Standard Cell RC
Operator
File	\\AE520-1454\Users\dsc\Desktop\Data\29-08-17\140-1.001
ProcName
InstSerial	2000-0883
AutoSerial	1293
Sample	140-1
Size	21.9000	mg
PanMass	Not available
PanResist	Automatic Automatic  K/W
PanFactor	Default Default
Method
Comment
Xcomment	Pan: Tzero Aluminum Hermetic
Xcomment	Gas1: Nitrogen 50.0 ml/min
Xcomment	Gas2: Nitrogen 50.0 ml/min
Text
Exotherm	UP
Kcell	1.05230
Cpconst	Standard: 0.938
Calib	-38.6961
TempCal	1	pts	157.46	156.60
TzeroDt	-87.6168 -0.0009 -1.4231
TzeroDtz	-87.6168 0.0057 6.9570
InstCalFile	Tzero: \\Ae520-1454\ta\Data\DSC\Calibration\2017\CALIBRATION\1562_RCS (90)_05_18_2017 10_50_44.TZR
InstCalFile	Baseline: \\Ae520-1454\ta\Data\DSC\Calibration\2017\2017-05-17_Calibration.001
InstCalFile	Sapphire: \\Ae520-1454\ta\Data\DSC\Calibration\2017\2017-05-17_Saphire.001
InstCalDate	Tzero 2017-05-18 Time 10:50:44
TempRange	-87.39 to 398.39 °C at 10.00 °C/min Heat Only
AutoZero	Delta T Offset 0.000 uV
AutoZero	Delta T0 Offset 0.000 uV
MultiptCal	0
MultiPtDesc	0) Not set
AutoCellConst	Calibration Date 2017-05-18 16:59:28
Controls	Gas 1  Event Off  Sampling 0.2
Cell#	RC-01562
CoolingUnit	RCS (90)
SelHeatFlow	Heat Flow T4P (mW)
AutoLidII	Installed
AutoAnalysis	Off
MacroFile
Nsig	3
Sig1	Time (min)
Sig2	Temperature (°C)
Sig3	Heat Flow (mW)
Date	2017-08-29
Time	14:03:41
OrgMethod	1: Equilibrate at 80.00 °C
OrgMethod	2: Isothermal for 3.00 min
OrgMethod	3: Jump to 140.00 °C
OrgMethod	4: Mark end of cycle 1
OrgMethod	5: Isothermal for 40.00 min
OrgMethod	6: Mark end of cycle 2
OrgMethod	7: Ramp 20.00 °C/min to 280.00 °C
OrgMethod	8: Mark end of cycle 3
OrgMethod	9: Ramp 20.00 °C/min to 20.00 °C
OrgMethod	10: Mark end of cycle 4
OrgMethod	11: Ramp 20.00 °C/min to 280.00 °C
OrgMethod	12: Mark end of cycle 5
OrgFile	C:\Users\jarra\Desktop\DSC\9-C1(1.2mol%)+C20(1.0mol%)\140-1.001
StartOfData
4.99994E-4	78.95218	-13.19795
0.05383332	79.12724	-10.92752
0.1055000	79.26624	-9.105321
0.1571666	79.38170	-7.599201
0.2105000	79.47949	-6.316171
0.2605000	79.55509	-5.321357
0.3138333	79.62157	-4.441080
0.3655000	79.67536	-3.739246
0.4171667	79.71858	-3.155330
0.4705000	79.75546	-2.658308
0.5205000	79.78276	-2.277056
0.5738334	79.80882	-1.936302
0.6238334	79.82856	-1.672776
0.6771668	79.84482	-1.441028
0.7288332	79.85816	-1.256571
0.7805000	79.86886	-1.105771
0.8338332	79.87776	-0.9789530
0.8838332	79.88441	-0.8805374
0.9371668	79.89049	-0.7944146
0.9888332	79.89529	-0.7263001
1.040500	79.89900	-0.6718402
1.093833	79.90220	-0.6259296
1.143833	79.90424	-0.5914705
1.197166	79.90538	-0.5631026
1.247166	79.90598	-0.5421190
1.300500	79.90845	-0.5260492
1.352166	79.90870	-0.5136040
1.403833	79.90899	-0.5043904
1.457167	79.91032	-0.4970540
1.507167	79.90857	-0.4918263
1.560500	79.90972	-0.4870785
1.612166	79.90915	-0.4823638
1.663834	79.90870	-0.4775250
1.717167	79.90924	-0.4725710
1.767167	79.90894	-0.4679276
1.820500	79.90884	-0.4630050
1.870500	79.90684	-0.4584517
1.923834	79.90672	-0.4537234
1.975500	79.90662	-0.4493433
2.027166	79.90634	-0.4451422
2.080500	79.90566	-0.4409766
2.130500	79.90419	-0.4372376
2.183833	79.90378	-0.4334466
2.235500	79.90430	-0.4299826
2.287166	79.90338	-0.4267188
2.338833	79.90282	-0.4235944
2.390500	79.90344	-0.4206402
2.443833	79.90182	-0.4178504
2.493833	79.90222	-0.4153964
2.547166	79.90134	-0.4129320
2.598834	79.90097	-0.4106896
2.650500	79.90079	-0.4086508
2.703833	79.90011	-0.4066826
2.753833	79.89968	-0.4049817
2.807167	79.89981	-0.4033006
2.858833	79.89875	-0.4017458
2.910500	79.89794	-0.4003392
2.962167	79.89780	-0.3990290
3.010500	79.90094	-0.4225230
3.060500	80.92738	0.8874158
3.113833	84.15406	0.4169163
3.165500	87.53914	-4.372064
3.217166	91.17764	-10.55430
3.270500	95.14391	-17.45491
3.320500	99.01992	-23.78737
3.373834	103.2837	-30.07112
3.425500	107.5152	-35.55288
3.477167	111.8238	-40.37965
3.530500	116.3373	-44.67074
3.580500	120.6073	-48.17363
3.633833	125.1759	-51.26887
3.683833	128.5685	-55.09200
3.737167	130.3806	-56.59082
3.788833	131.7626	-53.86004
3.840500	132.8637	-49.10874
3.893833	133.8307	-43.30980
3.943833	134.6016	-37.84168
3.997166	135.3066	-32.39898
4.048834	135.8916	-27.68322
4.100500	136.3949	-23.56796
4.153834	136.8417	-19.92020
4.203833	137.2030	-17.00862
4.257167	137.5362	-14.39022
4.307167	137.8059	-12.32551
4.360500	138.0546	-10.47546
4.412167	138.2630	-8.973366
4.463834	138.4431	-7.716088
4.517166	138.6055	-6.625947
4.567167	138.7366	-5.766163
4.620500	138.8585	-4.996266
4.672167	138.9622	-4.370450
4.723834	139.0530	-3.840479
4.775500	139.1322	-3.392805
4.827167	139.2018	-3.013232
4.880500	139.2634	-2.678876
4.930500	139.3163	-2.417506
4.983834	139.3650	-2.178607
5.035500	139.4060	-1.988976
5.087167	139.4430	-1.826508
5.140500	139.4767	-1.680580
5.190500	139.5041	-1.564969
5.243834	139.5302	-1.460101
5.295500	139.5534	-1.373796
5.347168	139.5742	-1.298336
5.398834	139.5926	-1.235711
5.450500	139.6093	-1.180420
5.503834	139.6231	-1.131798
5.553834	139.6372	-1.092865
5.607168	139.6493	-1.057778
5.658832	139.6599	-1.027998
5.710500	139.6691	-1.002163
5.763834	139.6794	-0.9796715
5.813832	139.6870	-0.9601945
5.867168	139.6938	-0.9422675
5.917168	139.7012	-0.9272747
5.970500	139.7065	-0.9137674
6.022168	139.7135	-0.9019949
6.073834	139.7185	-0.8917274
6.127168	139.7240	-0.8817597
6.177166	139.7283	-0.8728470
6.230500	139.7320	-0.8637413
6.282166	139.7358	-0.8548316
6.333832	139.7398	-0.8463139
6.387168	139.7438	-0.8383512
6.437168	139.7466	-0.8308478
6.490500	139.7497	-0.8222147
6.540500	139.7518	-0.8138292
6.593832	139.7551	-0.8046090
6.645500	139.7576	-0.7960176
6.697168	139.7610	-0.7868200
6.750500	139.7620	-0.7773444
6.800500	139.7651	-0.7685064
6.853832	139.7669	-0.7587869
6.905500	139.7701	-0.7490562
6.957168	139.7720	-0.7389563
7.010500	139.7734	-0.7287116
7.060500	139.7755	-0.7184170
7.113834	139.7791	-0.7069158
7.163832	139.7790	-0.6959463
7.217168	139.7808	-0.6838816
7.268832	139.7831	-0.6719129
7.320500	139.7842	-0.6600238
7.373834	139.7860	-0.6467996
7.423834	139.7881	-0.6338184
7.477168	139.7898	-0.6206140
7.528832	139.7921	-0.6075766
7.580500	139.7929	-0.5935241
7.633832	139.7949	-0.5789793
7.683832	139.7957	-0.5654614
7.737168	139.7976	-0.5493793
7.787168	139.7988	-0.5338074
7.840500	139.8009	-0.5172592
7.892168	139.8024	-0.5008679
7.943832	139.8040	-0.4832621
7.997168	139.8063	-0.4635210
8.047168	139.8077	-0.4460686
8.100500	139.8082	-0.4248800
8.152168	139.8103	-0.4039563
8.203834	139.8113	-0.3835476
8.255500	139.8138	-0.3639733
8.307168	139.8152	-0.3430498
8.360500	139.8164	-0.3201395
8.410499	139.8183	-0.2983196
8.463834	139.8200	-0.2756048
8.515500	139.8213	-0.2539166
8.567166	139.8236	-0.2302580
8.620499	139.8252	-0.2060814
8.670500	139.8260	-0.1833867
8.723832	139.8286	-0.1566031
8.775499	139.8303	-0.1312036
8.827168	139.8319	-0.1047263
8.878834	139.8337	-.07914221
8.930500	139.8355	-.05346645
8.983832	139.8371	-.02576192
9.033832	139.8388	6.57212E-4
9.087168	139.8407	0.02888655
9.138834	139.8432	0.05709960
9.190500	139.8449	0.08569982
9.243834	139.8462	0.1159780
9.293834	139.8486	0.1438034
9.347168	139.8510	0.1745599
9.398834	139.8526	0.2052740
9.450500	139.8551	0.2357017
9.502168	139.8568	0.2663640
9.553832	139.8594	0.2971150
9.607166	139.8605	0.3308685
9.657166	139.8639	0.3626467
9.710499	139.8659	0.3970070
9.762168	139.8681	0.4317830
9.813834	139.8704	0.4674414
9.867166	139.8717	0.5038059
9.917168	139.8744	0.5383284
9.970500	139.8773	0.5767489
10.02050	139.8797	0.6154551
10.07383	139.8824	0.6568334
10.12550	139.8851	0.6980688
10.17717	139.8874	0.7444746
10.23050	139.8909	0.7972076
10.28050	139.8947	0.8501116
10.33383	139.8975	0.9156590
10.38550	139.9036	0.9875041
10.43717	139.9076	1.069357
10.49050	139.9143	1.166048
10.54050	139.9203	1.267563
10.59383	139.9285	1.388237
10.64383	139.9355	1.514139
10.69717	139.9448	1.656464
10.74883	139.9554	1.805236
10.80050	139.9648	1.961027
10.85383	139.9775	2.125380
10.90383	139.9877	2.283478
10.95717	139.9992	2.459192
11.00883	140.0113	2.624034
11.06050	140.0221	2.790174
11.11383	140.0341	2.958654
11.16383	140.0443	3.113227
11.21717	140.0551	3.274966
11.26717	140.0651	3.422370
11.32050	140.0755	3.571685
11.37217	140.0856	3.708889
11.42383	140.0946	3.839071
11.47717	140.1033	3.964505
11.52717	140.1114	4.079085
11.58050	140.1189	4.194047
11.63216	140.1261	4.299234
11.68383	140.1334	4.398365
11.73717	140.1394	4.495204
11.78717	140.1465	4.582006
11.84050	140.1517	4.673201
11.89050	140.1581	4.754144
11.94383	140.1636	4.839670
11.99550	140.1689	4.921097
12.04717	140.1748	5.001594
12.10050	140.1808	5.084411
12.15050	140.1858	5.162390
12.20384	140.1912	5.247207
12.25550	140.1970	5.328434
12.30717	140.2024	5.411386
12.35883	140.2082	5.493310
12.41050	140.2134	5.575871
12.46383	140.2204	5.663286
12.51383	140.2246	5.747238
12.56716	140.2321	5.835668
12.61884	140.2379	5.922218
12.67050	140.2428	6.012535
12.72383	140.2501	6.104492
12.77383	140.2558	6.190803
12.82717	140.2624	6.284250
12.87883	140.2684	6.374756
12.93050	140.2746	6.467246
12.98216	140.2807	6.559505
13.03383	140.2864	6.651891
13.08717	140.2936	6.747269
13.13717	140.2988	6.837975
13.19050	140.3062	6.932484
13.24216	140.3120	7.026288
13.29384	140.3190	7.118785
13.34717	140.3258	7.211094
13.39717	140.3304	7.298770
13.45050	140.3372	7.387531
13.50050	140.3426	7.467669
13.55383	140.3480	7.551500
13.60550	140.3537	7.636650
13.65717	140.3594	7.710849
13.71050	140.3642	7.783850
13.76050	140.3687	7.845568
13.81383	140.3731	7.907810
13.86550	140.3771	7.962788
13.91716	140.3805	8.009928
13.97050	140.3841	8.052491
14.02050	140.3862	8.085895
14.07384	140.3894	8.114869
14.12384	140.3908	8.133754
14.17717	140.3912	8.147519
14.22884	140.3928	8.155270
14.28050	140.3939	8.159440
14.33383	140.3933	8.163095
14.38383	140.3931	8.166187
14.43716	140.3936	8.168984
14.48883	140.3924	8.170976
14.54050	140.3909	8.171972
14.59383	140.3898	8.171485
14.64383	140.3886	8.167845
14.69717	140.3861	8.159318
14.74717	140.3849	8.145126
14.80050	140.3834	8.124606
14.85217	140.3806	8.099694
14.90383	140.3788	8.071632
14.95717	140.3772	8.038179
15.00717	140.3742	8.007402
15.06050	140.3720	7.973728
15.11217	140.3698	7.943306
15.16383	140.3691	7.913174
15.21716	140.3667	7.885684
15.26717	140.3644	7.861997
15.32050	140.3631	7.839366
15.37050	140.3616	7.821662
15.42383	140.3600	7.805588
15.47550	140.3592	7.794293
15.52717	140.3580	7.786429
15.58050	140.3574	7.779868
15.63050	140.3576	7.774169
15.68383	140.3570	7.768272
15.73550	140.3568	7.762942
15.78717	140.3575	7.758111
15.83883	140.3586	7.753880
15.89050	140.3588	7.750352
15.94384	140.3599	7.747553
15.99383	140.3601	7.745686
16.04716	140.3614	7.744472
16.09883	140.3616	7.743890
16.15050	140.3622	7.743772
16.20383	140.3617	7.743866
16.25383	140.3619	7.743897
16.30716	140.3617	7.743592
16.35883	140.3614	7.742575
16.41050	140.3596	7.739966
16.46216	140.3582	7.731328
16.51383	140.3558	7.711238
16.56716	140.3524	7.673060
16.61716	140.3502	7.628594
16.67050	140.3470	7.570062
16.72216	140.3417	7.494656
16.77383	140.3371	7.413024
16.82716	140.3336	7.329995
16.87716	140.3280	7.253540
16.93050	140.3228	7.170460
16.98216	140.3173	7.091858
17.03383	140.3120	7.005440
17.08550	140.3056	6.918800
17.13716	140.3010	6.832011
17.19050	140.2955	6.742813
17.24050	140.2898	6.659918
17.29383	140.2828	6.573831
17.34550	140.2777	6.490050
17.39716	140.2716	6.406074
17.45050	140.2661	6.322020
17.50050	140.2618	6.242290
17.55383	140.2561	6.164172
17.60383	140.2506	6.091694
17.65716	140.2455	6.015192
17.70883	140.2405	5.943280
17.76050	140.2359	5.873669
17.81383	140.2308	5.803511
17.86383	140.2274	5.741792
17.91716	140.2226	5.675639
17.96883	140.2183	5.612901
18.02050	140.2136	5.551800
18.07383	140.2093	5.491729
18.12383	140.2054	5.436840
18.17716	140.2022	5.379218
18.22716	140.1976	5.326919
18.28050	140.1950	5.271800
18.33216	140.1909	5.219300
18.38383	140.1868	5.168696
18.43716	140.1832	5.118168
18.48716	140.1798	5.070778
18.54050	140.1762	5.021424
18.59216	140.1726	4.976002
18.64383	140.1704	4.929243
18.69716	140.1675	4.881500
18.74716	140.1628	4.840668
18.80050	140.1610	4.794946
18.85050	140.1571	4.753526
18.90383	140.1549	4.708234
18.95550	140.1521	4.669844
19.00716	140.1489	4.627804
19.06050	140.1454	4.583560
19.11050	140.1430	4.542182
19.16383	140.1406	4.498584
19.21550	140.1376	4.457216
19.26716	140.1341	4.417092
19.32050	140.1317	4.375781
19.37050	140.1300	4.334990
19.42383	140.1264	4.293518
19.47383	140.1243	4.255826
19.52716	140.1213	4.214096
19.57883	140.1182	4.175266
19.63050	140.1159	4.135968
19.68383	140.1138	4.095944
19.73383	140.1102	4.057706
19.78717	140.1084	4.018100
19.83883	140.1050	3.980069
19.89050	140.1030	3.941121
19.94216	140.1000	3.902966
19.99383	140.0976	3.863374
20.04716	140.0941	3.824372
20.09716	140.0927	3.786862
20.15050	140.0901	3.747080
20.20216	140.0861	3.709180
20.25383	140.0849	3.669964
20.30716	140.0814	3.629193
20.35716	140.0789	3.591413
20.41050	140.0761	3.550947
20.46216	140.0729	3.510582
20.51383	140.0703	3.471971
20.56550	140.0682	3.431766
20.61716	140.0647	3.392056
20.67050	140.0620	3.351277
20.72050	140.0596	3.312606
20.77383	140.0575	3.268955
20.82550	140.0542	3.226874
20.87716	140.0523	3.186303
20.93050	140.0489	3.143392
20.98050	140.0459	3.104296
21.03383	140.0434	3.060531
21.08383	140.0399	3.019614
21.13716	140.0376	2.975389
21.18883	140.0345	2.933004
21.24050	140.0314	2.890010
21.29383	140.0298	2.844308
21.34383	140.0260	2.800720
21.39716	140.0230	2.754726
21.44883	140.0197	2.709732
21.50050	140.0165	2.664099
21.55383	140.0137	2.615673
21.60383	140.0102	2.570392
21.65716	140.0070	2.520795
21.70717	140.0042	2.475168
21.76050	140.0012	2.424155
21.81216	139.9974	2.375027
21.86383	139.9954	2.325037
21.91716	139.9908	2.270844
21.96716	139.9872	2.220780
22.02050	139.9842	2.166602
22.07216	139.9807	2.112617
22.12383	139.9766	2.060429
22.17717	139.9726	2.004955
22.22716	139.9698	1.950868
22.28050	139.9652	1.894217
22.33050	139.9616	1.840518
22.38383	139.9579	1.780541
22.43550	139.9547	1.723523
22.48716	139.9505	1.665630
22.54050	139.9469	1.604710
22.59050	139.9425	1.548714
22.64383	139.9396	1.487191
22.69550	139.9354	1.428226
22.74716	139.9314	1.369208
22.80050	139.9273	1.308208
22.85050	139.9232	1.251926
22.90383	139.9194	1.190066
22.95383	139.9154	1.132857
23.00716	139.9108	1.072219
23.05883	139.9067	1.014404
23.11050	139.9032	0.9573162
23.16383	139.8983	0.8972553
23.21383	139.8950	0.8429386
23.26716	139.8913	0.7850638
23.31883	139.8872	0.7297043
23.37050	139.8836	0.6746332
23.42216	139.8796	0.6208171
23.47383	139.8760	0.5678222
23.52717	139.8721	0.5143411
23.57716	139.8697	0.4635335
23.63050	139.8658	0.4127784
23.68216	139.8620	0.3641262
23.73383	139.8588	0.3169005
23.78717	139.8552	0.2697427
23.83716	139.8526	0.2249822
23.89050	139.8490	0.1793832
23.94216	139.8465	0.1365321
23.99383	139.8434	0.09531912
24.04550	139.8410	0.05473524
24.09716	139.8377	0.01585904
24.15050	139.8357	-.02315245
24.20050	139.8328	-.05900470
24.25383	139.8303	-.09494080
24.30550	139.8275	-0.1287969
24.35716	139.8256	-0.1616140
24.41050	139.8223	-0.1943000
24.46050	139.8207	-0.2237564
24.51383	139.8184	-0.2539423
24.56550	139.8158	-0.2826184
24.61716	139.8139	-0.3096988
24.66883	139.8120	-0.3358813
24.72050	139.8103	-0.3605098
24.77383	139.8081	-0.3839458
24.82383	139.8068	-0.4055176
24.87716	139.8056	-0.4280824
24.92883	139.8037	-0.4496358
24.98050	139.8014	-0.4689697
25.03383	139.8020	-0.4887587
25.08383	139.7988	-0.5063980
25.13716	139.7970	-0.5247745
25.18716	139.7970	-0.5404114
25.24050	139.7958	-0.5562494
25.29216	139.7940	-0.5708770
25.34383	139.7934	-0.5845284
25.39716	139.7917	-0.5980918
25.44716	139.7917	-0.6095356
25.50050	139.7898	-0.6211811
25.55217	139.7890	-0.6323180
25.60383	139.7883	-0.6434955
25.65716	139.7870	-0.6539442
25.70716	139.7869	-0.6636298
25.76050	139.7851	-0.6733588
25.81050	139.7844	-0.6826782
25.86383	139.7844	-0.6926862
25.91550	139.7834	-0.7019538
25.96716	139.7825	-0.7108259
26.02050	139.7816	-0.7200434
26.07050	139.7818	-0.7287422
26.12383	139.7802	-0.7380326
26.17550	139.7803	-0.7470575
26.22717	139.7788	-0.7560942
26.28050	139.7795	-0.7654087
26.33050	139.7783	-0.7741200
26.38383	139.7775	-0.7833892
26.43383	139.7770	-0.7919571
26.48716	139.7757	-0.8010625
26.53883	139.7758	-0.8097769
26.59050	139.7756	-0.8184000
26.64383	139.7750	-0.8271714
26.69383	139.7744	-0.8352968
26.74716	139.7741	-0.8437895
26.79883	139.7734	-0.8519379
26.85050	139.7737	-0.8599618
26.90383	139.7729	-0.8681118
26.95383	139.7724	-0.8755340
27.00716	139.7721	-0.8833012
27.05716	139.7716	-0.8904349
27.11050	139.7713	-0.8979140
27.16217	139.7711	-0.9050136
27.21383	139.7709	-0.9119776
27.26716	139.7705	-0.9189364
27.31716	139.7710	-0.9253449
27.37050	139.7697	-0.9319952
27.42216	139.7697	-0.9383144
27.47383	139.7691	-0.9444247
27.52550	139.7690	-0.9504891
27.57717	139.7689	-0.9563895
27.63050	139.7688	-0.9623144
27.68050	139.7686	-0.9677657
27.73383	139.7692	-0.9734445
27.78550	139.7676	-0.9787978
27.83716	139.7681	-0.9840500
27.89050	139.7686	-0.9893414
27.94050	139.7679	-0.9941852
27.99383	139.7677	-0.9992384
28.04550	139.7669	-1.003998
28.09716	139.7670	-1.008605
28.14883	139.7666	-1.013160
28.20050	139.7663	-1.017526
28.25383	139.7672	-1.021973
28.30383	139.7662	-1.025979
28.35716	139.7666	-1.030197
28.40883	139.7658	-1.034168
28.46050	139.7658	-1.038016
28.51383	139.7655	-1.041880
28.56383	139.7657	-1.045383
28.61716	139.7655	-1.049011
28.66716	139.7654	-1.052342
28.72050	139.7659	-1.055856
28.77216	139.7651	-1.059180
28.82383	139.7654	-1.062449
28.87716	139.7648	-1.065700
28.92717	139.7654	-1.068660
28.98050	139.7646	-1.071734
29.03216	139.7649	-1.074630
29.08383	139.7647	-1.077428
29.13716	139.7636	-1.080218
29.18717	139.7642	-1.082729
29.24050	139.7640	-1.085338
29.29050	139.7644	-1.087753
29.34383	139.7646	-1.090296
29.39550	139.7640	-1.092708
29.44717	139.7638	-1.095022
29.50050	139.7637	-1.097378
29.55050	139.7637	-1.099483
29.60383	139.7639	-1.101704
29.65550	139.7635	-1.103744
29.70716	139.7632	-1.105746
29.76050	139.7629	-1.107792
29.81050	139.7634	-1.109670
29.86383	139.7638	-1.111669
29.91383	139.7641	-1.113481
29.96716	139.7635	-1.115363
30.01883	139.7629	-1.117153
30.07050	139.7639	-1.118838
30.12383	139.7633	-1.120572
30.17383	139.7633	-1.122192
30.22717	139.7630	-1.123846
30.27883	139.7636	-1.125438
30.33050	139.7632	-1.126982
30.38383	139.7623	-1.128477
30.43383	139.7631	-1.129907
30.48716	139.7623	-1.131366
30.53717	139.7628	-1.132666
30.59050	139.7625	-1.134021
30.64216	139.7624	-1.135244
30.69383	139.7624	-1.136495
30.74716	139.7624	-1.137744
30.79716	139.7617	-1.138915
30.85050	139.7618	-1.140102
30.90216	139.7618	-1.141213
30.95383	139.7617	-1.142316
31.00550	139.7618	-1.143440
31.05716	139.7622	-1.144510
31.11050	139.7619	-1.145618
31.16050	139.7614	-1.146599
31.21383	139.7615	-1.147623
31.26550	139.7612	-1.148584
31.31716	139.7619	-1.149595
31.37050	139.7611	-1.150610
31.42050	139.7616	-1.151539
31.47383	139.7623	-1.152521
31.52550	139.7616	-1.153433
31.57717	139.7617	-1.154364
31.62883	139.7614	-1.155257
31.68050	139.7624	-1.156132
31.73383	139.7618	-1.156992
31.78383	139.7620	-1.157724
31.83716	139.7618	-1.158531
31.88883	139.7616	-1.159302
31.94050	139.7607	-1.160045
31.99383	139.7612	-1.160809
32.04383	139.7612	-1.161540
32.09716	139.7610	-1.162326
32.14883	139.7611	-1.163061
32.20050	139.7611	-1.163706
32.25217	139.7607	-1.164357
32.30383	139.7614	-1.165020
32.35716	139.7605	-1.165678
32.40716	139.7611	-1.166308
32.46050	139.7617	-1.166917
32.51216	139.7606	-1.167528
32.56383	139.7611	-1.168153
32.61716	139.7611	-1.168791
32.66716	139.7617	-1.169330
32.72050	139.7606	-1.169890
32.77050	139.7600	-1.170404
32.82383	139.7611	-1.170982
32.87550	139.7608	-1.171531
32.92717	139.7610	-1.172068
32.98050	139.7606	-1.172648
33.03050	139.7606	-1.173184
33.08383	139.7615	-1.173760
33.13550	139.7612	-1.174313
33.18716	139.7610	-1.174866
33.24050	139.7607	-1.175427
33.29050	139.7606	-1.175928
33.34384	139.7610	-1.176475
33.39383	139.7607	-1.176957
33.44717	139.7608	-1.177473
33.49883	139.7610	-1.177976
33.55050	139.7605	-1.178471
33.60383	139.7602	-1.178917
33.65383	139.7600	-1.179346
33.70716	139.7605	-1.179787
33.75883	139.7604	-1.180228
33.81050	139.7604	-1.180668
33.86383	139.7600	-1.181130
33.91383	139.7603	-1.181551
33.96716	139.7599	-1.181970
34.01716	139.7605	-1.182370
34.07050	139.7599	-1.182812
34.12216	139.7603	-1.183248
34.17383	139.7601	-1.183680
34.22717	139.7594	-1.184146
34.27716	139.7602	-1.184586
34.33050	139.7602	-1.185028
34.38216	139.7602	-1.185472
34.43384	139.7599	-1.185874
34.48717	139.7594	-1.186308
34.53717	139.7606	-1.186727
34.59050	139.7599	-1.187161
34.64050	139.7595	-1.187524
34.69383	139.7599	-1.187916
34.74550	139.7602	-1.188306
34.79716	139.7602	-1.188662
34.85050	139.7600	-1.188993
34.90050	139.7602	-1.189298
34.95383	139.7595	-1.189663
35.00550	139.7606	-1.189953
35.05716	139.7595	-1.190282
35.10883	139.7605	-1.190611
35.16050	139.7601	-1.190940
35.21383	139.7604	-1.191270
35.26383	139.7609	-1.191572
35.31716	139.7601	-1.191825
35.36883	139.7601	-1.192092
35.42050	139.7601	-1.192355
35.47383	139.7604	-1.192617
35.52383	139.7600	-1.192877
35.57717	139.7600	-1.193143
35.62883	139.7596	-1.193404
35.68050	139.7593	-1.193652
35.73216	139.7605	-1.193893
35.78383	139.7599	-1.194178
35.83716	139.7603	-1.194456
35.88716	139.7587	-1.194708
35.94050	139.7598	-1.194960
35.99216	139.7593	-1.195218
36.04383	139.7592	-1.195523
36.09716	139.7592	-1.195809
36.14717	139.7598	-1.196070
36.20050	139.7599	-1.196343
36.25050	139.7591	-1.196600
36.30383	139.7596	-1.196885
36.35550	139.7590	-1.197171
36.40716	139.7604	-1.197456
36.46050	139.7593	-1.197759
36.51050	139.7586	-1.198000
36.56383	139.7598	-1.198243
36.61550	139.7594	-1.198465
36.66716	139.7596	-1.198689
36.72050	139.7592	-1.198948
36.77050	139.7590	-1.199168
36.82383	139.7586	-1.199402
36.87383	139.7599	-1.199634
36.92717	139.7594	-1.199878
36.97883	139.7594	-1.200130
37.03050	139.7600	-1.200406
37.08383	139.7592	-1.200652
37.13383	139.7587	-1.200865
37.18716	139.7588	-1.201124
37.23883	139.7594	-1.201354
37.29050	139.7592	-1.201621
37.34384	139.7593	-1.201845
37.39383	139.7586	-1.202071
37.44717	139.7592	-1.202339
37.49716	139.7595	-1.202592
37.55050	139.7588	-1.202838
37.60217	139.7598	-1.203086
37.65383	139.7590	-1.203341
37.70716	139.7588	-1.203549
37.75716	139.7586	-1.203793
37.81050	139.7597	-1.204066
37.86217	139.7600	-1.204328
37.91383	139.7582	-1.204539
37.96716	139.7600	-1.204739
38.01716	139.7598	-1.204918
38.07050	139.7589	-1.205109
38.12050	139.7592	-1.205297
38.17383	139.7592	-1.205488
38.22550	139.7591	-1.205644
38.27716	139.7583	-1.205808
38.33050	139.7596	-1.206005
38.38050	139.7581	-1.206142
38.43384	139.7582	-1.206310
38.48550	139.7587	-1.206501
38.53717	139.7588	-1.206676
38.58883	139.7583	-1.206799
38.64050	139.7590	-1.206964
38.69383	139.7586	-1.207124
38.74383	139.7579	-1.207262
38.79716	139.7584	-1.207396
38.84883	139.7589	-1.207575
38.90050	139.7589	-1.207732
38.95383	139.7588	-1.207893
39.00383	139.7590	-1.208098
39.05716	139.7591	-1.208250
39.10883	139.7584	-1.208424
39.16050	139.7590	-1.208609
39.21216	139.7584	-1.208781
39.26383	139.7591	-1.208931
39.31716	139.7590	-1.209072
39.36716	139.7595	-1.209213
39.42050	139.7591	-1.209430
39.47217	139.7584	-1.209626
39.52383	139.7588	-1.209831
39.57717	139.7591	-1.210066
39.62717	139.7591	-1.210268
39.68050	139.7581	-1.210492
39.73216	139.7588	-1.210685
39.78383	139.7593	-1.210897
39.83550	139.7582	-1.211049
39.88716	139.7586	-1.211172
39.94050	139.7585	-1.211268
39.99050	139.7587	-1.211381
40.04383	139.7588	-1.211458
40.09550	139.7584	-1.211535
40.14717	139.7592	-1.211625
40.20050	139.7588	-1.211692
40.25050	139.7585	-1.211724
40.30383	139.7590	-1.211788
40.35383	139.7588	-1.211860
40.40716	139.7587	-1.211951
40.45883	139.7592	-1.212078
40.51050	139.7592	-1.212222
40.56383	139.7589	-1.212350
40.61383	139.7593	-1.212434
40.66716	139.7592	-1.212512
40.71884	139.7590	-1.212598
40.77050	139.7588	-1.212726
40.82383	139.7591	-1.212813
40.87383	139.7593	-1.212934
40.92717	139.7596	-1.213053
40.97717	139.7585	-1.213161
41.03050	139.7594	-1.213321
41.08217	139.7584	-1.213494
41.13383	139.7592	-1.213664
41.18716	139.7596	-1.213838
41.23717	139.7584	-1.213956
41.29050	139.7586	-1.214025
41.34217	139.7581	-1.214104
41.39383	139.7581	-1.214212
41.44717	139.7588	-1.214264
41.49716	139.7591	-1.214313
41.55050	139.7574	-1.214387
41.60050	139.7581	-1.214453
41.65383	139.7591	-1.214550
41.70550	139.7581	-1.214601
41.75717	139.7591	-1.214654
41.81050	139.7587	-1.214707
41.86050	139.7579	-1.214788
41.91383	139.7586	-1.214891
41.96550	139.7585	-1.215014
42.01717	139.7598	-1.215114
42.07050	139.7578	-1.215241
42.12050	139.7590	-1.215368
42.17383	139.7582	-1.215442
42.22383	139.7578	-1.215528
42.27716	139.7588	-1.215676
42.32883	139.7586	-1.215838
42.38050	139.7589	-1.215958
42.43383	139.7585	-1.216064
42.48383	139.7576	-1.216155
42.53717	139.7588	-1.216276
42.58883	139.7580	-1.216410
42.64050	139.7581	-1.216505
42.69217	139.7581	-1.216642
42.74383	139.7577	-1.216741
42.79716	139.7586	-1.216847
42.84716	139.7584	-1.216935
42.90050	139.7583	-1.217008
42.95216	139.7586	-1.217127
43.00050	139.7578	-1.217227
43.05383	139.8066	-1.196484
43.10550	140.2371	-0.9011938
43.15717	140.8781	-1.999727
43.21050	141.6249	-3.663083
43.26050	142.3800	-5.320653
43.31383	143.2272	-6.948534
43.36550	144.0843	-8.331114
43.41716	144.9668	-9.507403
43.47050	145.9028	-10.53311
43.52050	146.7987	-11.33413
43.57383	147.7708	-12.04768
43.62383	148.6932	-12.61090
43.67717	149.6889	-13.11520
43.72883	150.6635	-13.52776
43.78050	151.6441	-13.88296
43.83383	152.6647	-14.20185
43.88383	153.6260	-14.45758
43.93716	154.6570	-14.69957
43.98883	155.6591	-14.90717
44.04050	156.6636	-15.09029
44.09384	157.7051	-15.26559
44.14383	158.6826	-15.42013
44.19717	159.7278	-15.56051
44.24716	160.7070	-15.70127
44.30050	161.7558	-15.83569
44.35217	162.7721	-15.96785
44.40383	163.7892	-16.08289
44.45717	164.8404	-16.20894
44.50717	165.8270	-16.32625
44.56050	166.8803	-16.44151
44.61217	167.9005	-16.56138
44.66383	168.9215	-16.67734
44.71717	169.9755	-16.79175
44.76717	170.9642	-16.90819
44.82050	172.0200	-17.03526
44.87050	173.0089	-17.14558
44.92383	174.0641	-17.27263
44.97550	175.0878	-17.38916
45.02716	176.1122	-17.52622
45.08050	177.1670	-17.65103
45.13050	178.1584	-17.77180
45.18383	179.2144	-17.91063
45.23550	180.2378	-18.05460
45.28717	181.2606	-18.20096
45.33883	182.2827	-18.34999
45.39050	183.3053	-18.52159
45.44383	184.3596	-18.70227
45.49383	185.3484	-18.87228
45.54716	186.4044	-19.06378
45.59883	187.4254	-19.25430
45.65050	188.4458	-19.45984
45.70383	189.5002	-19.69382
45.75383	190.4866	-19.91186
45.80717	191.5389	-20.15944
45.85883	192.5575	-20.42184
45.91050	193.5749	-20.69330
45.96216	194.5904	-20.97748
46.01383	195.6064	-21.29011
46.06717	196.6542	-21.63002
46.11716	197.6355	-21.97293
46.17050	198.6796	-22.36961
46.22217	199.6902	-22.77471
46.27383	200.7003	-23.20598
46.32717	201.7390	-23.70400
46.37717	202.7122	-24.19465
46.43050	203.7465	-24.78743
46.48217	204.7472	-25.40315
46.53383	205.7433	-26.09846
46.58550	206.7368	-26.83878
46.63716	207.7256	-27.68296
46.69050	208.7421	-28.65889
46.74050	209.6892	-29.68063
46.79383	210.6917	-30.91998
46.84550	211.6544	-32.29932
46.89717	212.6072	-33.87937
46.95050	213.5795	-35.72441
47.00050	214.4794	-37.69244
47.05383	215.4258	-40.02576
47.10383	216.2998	-42.44261
47.15717	217.2175	-45.21265
47.20883	218.0953	-48.05466
47.26050	218.9664	-50.88703
47.31383	219.8664	-53.42634
47.36383	220.7293	-55.24465
47.41716	221.6708	-56.90045
47.46884	222.6088	-57.66518
47.52050	223.6021	-56.88005
47.57383	224.7026	-54.65871
47.62383	225.7895	-51.95657
47.67717	227.0122	-47.82274
47.72717	228.2321	-42.32170
47.78050	229.5944	-36.94941
47.83217	230.8952	-33.47636
47.88383	232.1502	-30.84231
47.93716	233.4037	-28.66904
47.98717	234.5427	-27.03990
48.04050	235.7320	-25.62236
48.09217	236.8606	-24.51726
48.14383	237.9709	-23.62163
48.19717	239.1011	-22.87961
48.24716	240.1496	-22.32560
48.30050	241.2576	-21.85412
48.35050	242.2896	-21.48754
48.40383	243.3820	-21.18046
48.45550	244.4367	-20.94978
48.50717	245.4861	-20.76635
48.56050	246.5680	-20.61268
48.61050	247.5780	-20.50074
48.66383	248.6542	-20.39312
48.71550	249.6947	-20.32406
48.76717	250.7340	-20.27595
48.82050	251.8045	-20.23353
48.87050	252.8075	-20.20554
48.92383	253.8766	-20.18534
48.97383	254.8785	-20.17641
49.02716	255.9458	-20.17272
49.07883	256.9804	-20.17097
49.13050	258.0132	-20.16953
49.18383	259.0805	-20.16881
49.23383	260.0803	-20.16927
49.28717	261.1452	-20.17174
49.33883	262.1773	-20.17692
49.39050	263.2097	-20.18994
49.44217	264.2428	-20.20349
49.49383	265.2737	-20.22599
49.54716	266.3398	-20.25394
49.59716	267.3384	-20.28311
49.65050	268.4035	-20.31154
49.70216	269.4358	-20.34161
49.75383	270.4678	-20.36999
49.80717	271.5320	-20.39368
49.85717	272.5310	-20.42280
49.91050	273.5960	-20.45202
49.96216	274.6280	-20.47981
50.01050	275.5931	-20.51026
50.06050	276.4138	-20.09802
50.11383	276.4487	-21.25877
50.16550	276.1602	-19.01515
50.21717	275.7045	-14.86818
50.27050	275.1265	-10.23353
50.32050	274.5062	-6.228562
50.37383	273.7775	-2.552092
50.42550	273.0182	0.4245770
50.47717	272.2162	2.882654
50.53050	271.3512	4.951640
50.58050	270.5105	6.539060
50.63383	269.5902	7.914609
50.68383	268.7072	8.970092
50.73717	267.7485	9.890258
50.78883	266.8060	10.61362
50.84050	265.8513	11.20840
50.89383	264.8542	11.71671
50.94383	263.9120	12.10962
50.99716	262.9002	12.45223
51.04883	261.9126	12.73173
51.10050	260.9196	12.96661
51.15383	259.8912	13.15661
51.20383	258.9237	13.31616
51.25717	257.8878	13.45660
51.30717	256.9138	13.56645
51.36050	255.8738	13.66138
51.41216	254.8625	13.74560
51.46383	253.8502	13.82104
51.51716	252.8042	13.88462
51.56716	251.8211	13.93420
51.62050	250.7713	13.98154
51.67217	249.7542	14.02370
51.72383	248.7350	14.06040
51.77550	247.7156	14.09100
51.82717	246.6947	14.11590
51.88050	245.6407	14.13462
51.93050	244.6508	14.15112
51.98383	243.5953	14.16466
52.03550	242.5715	14.17317
52.08716	241.5484	14.17910
52.14050	240.4909	14.18439
52.19050	239.4990	14.18907
52.24383	238.4423	14.19425
52.29550	237.4176	14.19934
52.34716	236.3927	14.20535
52.39883	235.3672	14.21077
52.45050	234.3413	14.21614
52.50383	233.2835	14.22145
52.55383	232.2901	14.22612
52.60717	231.2312	14.23102
52.65883	230.2047	14.23551
52.71050	229.1790	14.23984
52.76382	228.1205	14.24429
52.81382	227.1258	14.24859
52.86716	226.0661	14.25311
52.91716	225.0720	14.25739
52.97050	224.0119	14.26191
53.02217	222.9846	14.26617
53.07383	221.9565	14.27017
53.12717	220.8965	14.27410
53.17717	219.9028	14.27759
53.23050	218.8422	14.28098
53.28217	217.8149	14.28402
53.33383	216.7862	14.28681
53.38716	215.7256	14.28948
53.43716	214.7320	14.29161
53.49050	213.6726	14.29362
53.54050	212.6775	14.29522
53.59384	211.6183	14.29691
53.64550	210.5908	14.29830
53.69717	209.5632	14.29987
53.75050	208.5022	14.30148
53.80050	207.5076	14.30297
53.85383	206.4463	14.30444
53.90550	205.4187	14.30560
53.95717	204.3906	14.30669
54.01050	203.3290	14.30764
54.06050	202.3346	14.30831
54.11382	201.2726	14.30867
54.16382	200.2781	14.30898
54.21717	199.2167	14.30924
54.26884	198.1881	14.30938
54.32050	197.1604	14.30933
54.37383	196.0996	14.30917
54.42383	195.1045	14.30886
54.47717	194.0439	14.30884
54.52883	193.0156	14.30866
54.58050	191.9876	14.30841
54.63383	190.9255	14.30809
54.68383	189.9306	14.30760
54.73717	188.8691	14.30706
54.78716	187.8742	14.30641
54.84050	186.8130	14.30558
54.89216	185.7835	14.30470
54.94384	184.7551	14.30369
54.99717	183.6926	14.30232
55.04717	182.6974	14.30101
55.10050	181.6352	14.29928
55.15217	180.6076	14.29766
55.20383	179.5785	14.29605
55.25550	178.5506	14.29447
55.30717	177.5230	14.29315
55.36050	176.4618	14.29185
55.41050	175.4666	14.29092
55.46382	174.4051	14.29005
55.51550	173.3766	14.28942
55.56716	172.3487	14.28862
55.62050	171.2872	14.28784
55.67050	170.2908	14.28711
55.72382	169.2299	14.28659
55.77550	168.2016	14.28650
55.82717	167.1735	14.28712
55.87883	166.1468	14.29682
55.93050	165.1236	14.40778
55.98383	164.0701	14.74266
56.03383	163.0941	15.24294
56.08716	162.0661	16.11663
56.13882	161.0939	17.39469
56.19050	160.1467	19.12584
56.24382	159.1966	21.32222
56.29382	158.3305	23.63116
56.34716	157.4214	26.16694
56.39883	156.5488	28.52775
56.45050	155.6694	30.61853
56.50217	154.7790	32.35118
56.55383	153.8675	33.67220
56.60717	152.8999	34.54670
56.65717	151.9661	34.90764
56.71050	150.9372	34.82539
56.76216	149.9109	34.34785
56.81382	148.8574	33.38032
56.86716	147.7426	32.13058
56.91716	146.6781	30.77825
56.97050	145.5287	29.21716
57.02050	144.4444	27.73963
57.07383	143.2812	26.20047
57.12550	142.1565	24.78350
57.17717	141.0344	23.47140
57.23050	139.8817	22.23615
57.28050	138.8080	21.20498
57.33383	137.6706	20.22458
57.38550	136.5775	19.38862
57.43716	135.4905	18.66608
57.49050	134.3775	18.01996
57.54050	133.3390	17.49310
57.59384	132.2373	17.01444
57.64384	131.2087	16.61116
57.69717	130.1162	16.24949
57.74883	129.0627	15.93351
57.80050	128.0124	15.65810
57.85383	126.9292	15.41544
57.90383	125.9170	15.20584
57.95717	124.8382	15.00261
58.00883	123.7951	14.83690
58.06050	122.7539	14.68649
58.11382	121.6803	14.52827
58.16382	120.6745	14.40184
58.21717	119.6031	14.27656
58.26716	118.5988	14.17316
58.32050	117.5287	14.06869
58.37217	116.4924	13.97464
58.42383	115.4567	13.88076
58.47717	114.3875	13.80314
58.52717	113.3861	13.71968
58.58050	112.3184	13.64567
58.63217	111.2826	13.56922
58.68383	110.2502	13.49114
58.73717	109.1816	13.41944
58.78716	108.1812	13.35459
58.84050	107.1141	13.29232
58.89050	106.1124	13.23047
58.94384	105.0461	13.16478
58.99550	104.0126	13.10576
59.04717	102.9789	13.04833
59.10050	101.9120	12.99282
59.15050	100.9130	12.93812
59.20383	99.84637	12.87848
59.25550	98.81428	12.82585
59.30717	97.78084	12.77457
59.35883	96.74775	12.71982
59.41050	95.71431	12.66430
59.46382	94.64895	12.60582
59.51382	93.64863	12.55886
59.56716	92.58390	12.50200
59.61882	91.55072	12.45123
59.67050	90.51715	12.40272
59.72382	89.45097	12.34699
59.77383	88.45056	12.29680
59.82717	87.38468	12.24670
59.87883	86.35301	12.19259
59.93050	85.31925	12.13959
59.98217	84.28719	12.09048
60.03383	83.25414	12.05124
60.08716	82.18725	12.01003
60.13716	81.18840	11.96147
60.19050	80.12226	11.91091
60.24216	79.08901	11.85984
60.29382	78.05551	11.81455
60.34716	76.98972	11.76534
60.39717	75.99102	11.72410
60.45050	74.92402	11.67635
60.50050	73.92566	11.63345
60.55383	72.85968	11.58671
60.60550	71.82696	11.54325
60.65717	70.79480	11.49900
60.71050	69.72735	11.45024
60.76050	68.72842	11.40442
60.81382	67.66240	11.36220
60.86550	66.62993	11.30766
60.91716	65.59703	11.26096
60.97050	64.53160	11.21468
61.02050	63.53114	11.16847
61.07383	62.46430	11.12091
61.12383	61.46424	11.06814
61.17717	60.39822	11.01564
61.22883	59.36482	10.97031
61.28050	58.33130	10.92184
61.33383	57.26401	10.86627
61.38383	56.26496	10.81259
61.43716	55.19800	10.76312
61.48882	54.16554	10.71166
61.54050	53.13264	10.66314
61.59384	52.06556	10.61554
61.64384	51.06579	10.56784
61.69717	49.99868	10.51652
61.74717	48.99886	10.46792
61.80050	47.93344	10.41662
61.85217	46.89954	10.37007
61.90383	45.86560	10.32317
61.95717	44.79936	10.27716
62.00717	43.79816	10.23286
62.06050	42.73258	10.18024
62.11217	41.69856	10.12695
62.16382	40.66299	10.07517
62.21717	39.59616	10.01845
62.26716	38.59543	9.960218
62.32050	37.52740	9.895709
62.37050	36.52674	9.838782
62.42383	35.45922	9.773071
62.47550	34.42406	9.707657
62.52717	33.39007	9.645594
62.58050	32.32289	9.574100
62.63050	31.32088	9.517495
62.68383	30.25308	9.450078
62.73550	29.21762	9.387531
62.78716	28.18332	9.313412
62.83882	27.14814	9.244608
62.89050	26.11163	9.173140
62.94384	25.04280	9.113601
62.99382	24.04094	9.117494
63.04550	23.06114	8.733749
63.09716	22.81334	9.428806
63.15050	23.07791	10.01604
63.20050	23.49586	8.948426
63.25383	24.05930	6.991669
63.30550	24.68940	4.910171
63.35717	25.38427	2.915358
63.41050	26.15811	1.065202
63.46050	26.92598	-0.4538111
63.51382	27.78278	-1.843644
63.56550	28.64368	-2.982832
63.61716	29.53158	-3.945470
63.66882	30.43834	-4.761266
63.72050	31.36392	-5.448914
63.77383	32.33326	-6.053046
63.82383	33.25546	-6.539834
63.87716	34.24874	-6.977890
63.92883	35.21987	-7.333710
63.98050	36.19915	-7.642034
64.03384	37.21516	-7.920106
64.08384	38.17533	-8.140797
64.13717	39.20309	-8.350144
64.18717	40.16992	-8.518518
64.24050	41.20446	-8.668503
64.29218	42.20964	-8.802006
64.34384	43.21822	-8.919194
64.39717	44.26193	-9.033381
64.44717	45.24219	-9.123091
64.50050	46.28950	-9.214947
64.55218	47.30404	-9.303061
64.60383	48.32117	-9.381894
64.65718	49.37192	-9.462965
64.70717	50.35946	-9.534606
64.76050	51.41284	-9.607499
64.81050	52.40034	-9.674316
64.86384	53.45566	-9.745301
64.91550	54.47828	-9.808304
64.96717	55.50250	-9.873484
65.02050	56.56018	-9.941098
65.07050	57.55087	-10.00119
65.12383	58.60900	-10.06339
65.17550	59.63352	-10.12298
65.22718	60.65981	-10.18265
65.28050	61.71878	-10.24924
65.33050	62.71215	-10.30817
65.38384	63.77221	-10.36855
65.43384	64.76570	-10.42228
65.48717	65.82595	-10.47769
65.53882	66.85310	-10.53307
65.59050	67.87993	-10.58734
65.64384	68.94134	-10.64706
65.69384	69.93724	-10.70541
65.74718	70.99790	-10.75981
65.79884	72.02698	-10.82386
65.85050	73.05519	-10.87934
65.90384	74.11749	-10.94006
65.95384	75.11245	-10.99276
66.00718	76.17475	-11.05652
66.05718	77.17016	-11.11450
66.11050	78.23132	-11.17964
66.16218	79.26114	-11.24757
66.21384	80.29065	-11.31188
66.26716	81.35253	-11.38009
66.31718	82.34812	-11.44185
66.37050	83.41144	-11.50601
66.42218	84.44028	-11.57515
66.47384	85.46929	-11.64244
66.52550	86.49754	-11.70960
66.57718	87.52601	-11.77150
66.63050	88.58899	-11.84321
66.68050	89.58475	-11.91435
66.73384	90.64657	-11.98469
66.78550	91.67559	-12.05222
66.83716	92.70516	-12.11792
66.89050	93.76739	-12.19307
66.94050	94.76254	-12.25916
66.99384	95.82582	-12.33130
67.04550	96.85452	-12.39887
67.09718	97.88392	-12.46709
67.14884	98.91368	-12.53580
67.20050	99.94254	-12.60885
67.25384	101.0060	-12.68174
67.30384	102.0023	-12.75145
67.35718	103.0652	-12.82542
67.40884	104.0942	-12.89640
67.46050	105.1228	-12.96858
67.51384	106.1852	-13.04591
67.56384	107.1806	-13.11766
67.61718	108.2436	-13.19824
67.66718	109.2389	-13.27348
67.72050	110.3012	-13.35091
67.77218	111.3295	-13.42866
67.82384	112.3588	-13.50306
67.87718	113.4208	-13.58478
67.92718	114.4163	-13.65344
67.98050	115.4788	-13.73697
68.03218	116.5072	-13.81478
68.08384	117.5366	-13.89252
68.13718	118.5984	-13.97548
68.18718	119.5940	-14.05707
68.24050	120.6573	-14.14482
68.29050	121.6513	-14.22621
68.34384	122.7141	-14.32203
68.39550	123.7425	-14.40828
68.44718	124.7704	-14.49480
68.50050	125.8325	-14.58207
68.55050	126.8279	-14.66634
68.60384	127.8900	-14.75225
68.65550	128.9184	-14.83757
68.70718	129.9467	-14.92965
68.76050	131.0076	-15.02449
68.81050	132.0032	-15.12001
68.86384	133.0637	-15.21173
68.91382	134.0591	-15.30882
68.96718	135.1199	-15.40982
69.01882	136.1484	-15.51467
69.07050	137.1760	-15.61717
69.12384	138.2370	-15.71716
69.17384	139.2309	-15.81510
69.22718	140.2921	-15.92520
69.27884	141.3196	-16.02681
69.33050	142.3472	-16.13037
69.38384	143.4082	-16.23989
69.43384	144.4031	-16.34089
69.48718	145.4628	-16.44698
69.53718	146.4574	-16.55683
69.59050	147.5183	-16.66980
69.64216	148.5446	-16.77567
69.69384	149.5718	-16.88841
69.74718	150.6314	-17.00566
69.79718	151.6259	-17.11449
69.85050	152.6855	-17.23854
69.90218	153.7122	-17.35503
69.95384	154.7388	-17.46487
70.00550	155.7665	-17.58868
70.05718	156.7925	-17.69452
70.11050	157.8521	-17.81809
70.16050	158.8466	-17.92564
70.21384	159.9081	-18.04028
70.26550	160.9348	-18.14248
70.31718	161.9635	-18.23036
70.37050	163.0245	-18.31316
70.42050	164.0200	-18.38374
70.47384	165.0842	-18.44927
70.52550	166.1136	-18.50216
70.57718	167.1452	-18.54367
70.62884	168.1758	-18.57815
70.68050	169.2088	-18.60584
70.73384	170.2736	-18.64250
70.78384	171.2722	-18.68445
70.83716	172.3368	-18.73914
70.88884	173.3679	-18.80747
70.94050	174.3978	-18.87618
70.99384	175.4612	-18.95961
71.04384	176.4583	-19.06119
71.09718	177.5202	-19.16289
71.14884	178.5484	-19.27972
71.20050	179.5768	-19.40350
71.25218	180.6035	-19.54718
71.30384	181.6295	-19.69544
71.35718	182.6874	-19.87228
71.40718	183.6778	-20.06058
71.46050	184.7342	-20.27406
71.51218	185.7552	-20.50801
71.56384	186.7766	-20.77130
71.61718	187.8269	-21.05928
71.66718	188.8114	-21.36493
71.72050	189.8586	-21.73706
71.77050	190.8392	-22.11333
71.82384	191.8842	-22.55270
71.87550	192.8918	-23.00902
71.92718	193.8996	-23.48932
71.98050	194.9362	-24.01094
72.03050	195.9084	-24.52593
72.08384	196.9433	-25.09184
72.13550	197.9437	-25.66742
72.18718	198.9425	-26.27495
72.24050	199.9705	-26.97305
72.29050	200.9322	-27.64485
72.34384	201.9554	-28.46515
72.39384	202.9119	-29.25504
72.44718	203.9285	-30.15772
72.49884	204.9107	-31.04824
72.55050	205.8915	-31.92876
72.60384	206.9056	-32.79199
72.65384	207.8586	-33.47848
72.70718	208.8829	-33.95079
72.75884	209.8904	-33.96287
72.81050	210.9228	-33.27040
72.86384	212.0326	-31.61769
72.91382	213.1136	-29.51178
72.96718	214.2961	-27.20428
73.01716	215.4120	-25.41010
73.07050	216.5904	-23.97151
73.12218	217.7148	-22.89304
73.17384	218.8228	-22.00667
73.22718	219.9513	-21.27836
73.27718	220.9986	-20.72924
73.33050	222.1076	-20.25396
73.38218	223.1728	-19.88391
73.43384	224.2323	-19.58334
73.48718	225.3208	-19.34564
73.53718	226.3372	-19.16653
73.59050	227.4192	-19.01548
73.64050	228.4295	-18.90388
73.69384	229.5060	-18.81930
73.74550	230.5462	-18.76260
73.79718	231.5848	-18.72047
73.85050	232.6563	-18.69733
73.90050	233.6596	-18.68477
73.95384	234.7283	-18.67831
74.00550	235.7640	-18.67608
74.05718	236.8004	-18.67415
74.10884	237.8356	-18.67279
74.16050	238.8707	-18.67189
74.21384	239.9372	-18.67170
74.26384	240.9377	-18.67267
74.31718	242.0026	-18.67606
74.36884	243.0350	-18.68469
74.42050	244.0688	-18.69846
74.47384	245.1339	-18.71777
74.52384	246.1341	-18.74200
74.57718	247.2006	-18.76827
74.62884	248.2325	-18.79064
74.68050	249.2664	-18.81662
74.73218	250.2982	-18.84275
74.78384	251.3316	-18.87129
74.83716	252.3972	-18.89653
74.88718	253.3970	-18.92624
74.94050	254.4621	-18.95375
74.99218	255.4938	-18.98642
75.04384	256.5269	-19.02505
75.09718	257.5927	-19.06827
75.14718	258.5916	-19.10383
75.20050	259.6579	-19.15241
75.25050	260.6564	-19.18430
75.30384	261.7228	-19.21968
75.35550	262.7556	-19.25490
75.40718	263.7870	-19.29026
75.46050	264.8531	-19.33225
75.51050	265.8508	-19.36718
75.56384	266.9163	-19.40369
75.61550	267.9480	-19.44339
75.66718	268.9796	-19.48720
75.72050	270.0440	-19.53429
75.77050	271.0425	-19.55829
75.82384	272.1064	-19.59356
-2.000000	5.000000	0.0000000