File: 9-C1(1.2mol%)+C20(1.0mol%)/matlab/150-3.txt
CLOSED
Version	1.0
Language	English
Mode	Standard
Run	7
RunSerial	12275
Instrument	DSC Q2000 V24.11 Build 124
Module	DSC Standard Cell RC
Operator
File	\\AE520-1454\Users\dsc\Desktop\Data\29-08-17\150-3.001
ProcName
InstSerial	2000-0883
AutoSerial	1293
Sample	150-3
Size	27.7000	mg
PanMass	Not available
PanResist	Automatic Automatic  K/W
PanFactor	Default Default
Method
Comment
Xcomment	Pan: Tzero Aluminum Hermetic
Xcomment	Gas1: Nitrogen 50.0 ml/min
Xcomment	Gas2: Nitrogen 50.0 ml/min
Text
Exotherm	UP
Kcell	1.05230
Cpconst	Standard: 0.938
Calib	-38.6961
TempCal	1	pts	157.46	156.60
TzeroDt	-87.6168 -0.0009 -1.4231
TzeroDtz	-87.6168 0.0057 6.9570
InstCalFile	Tzero: \\Ae520-1454\ta\Data\DSC\Calibration\2017\CALIBRATION\1562_RCS (90)_05_18_2017 10_50_44.TZR
InstCalFile	Baseline: \\Ae520-1454\ta\Data\DSC\Calibration\2017\2017-05-17_Calibration.001
InstCalFile	Sapphire: \\Ae520-1454\ta\Data\DSC\Calibration\2017\2017-05-17_Saphire.001
InstCalDate	Tzero 2017-05-18 Time 10:50:44
TempRange	-87.39 to 398.39 °C at 10.00 °C/min Heat Only
AutoZero	Delta T Offset 0.000 uV
AutoZero	Delta T0 Offset 0.000 uV
MultiptCal	0
MultiPtDesc	0) Not set
AutoCellConst	Calibration Date 2017-05-18 16:59:28
Controls	Gas 1  Event Off  Sampling 0.2
Cell#	RC-01562
CoolingUnit	RCS (90)
SelHeatFlow	Heat Flow T4P (mW)
AutoLidII	Installed
AutoAnalysis	Off
MacroFile
Nsig	3
Sig1	Time (min)
Sig2	Temperature (°C)
Sig3	Heat Flow (mW)
Date	2017-08-29
Time	19:32:18
OrgMethod	1: Equilibrate at 80.00 °C
OrgMethod	2: Isothermal for 3.00 min
OrgMethod	3: Jump to 150.00 °C
OrgMethod	4: Mark end of cycle 1
OrgMethod	5: Isothermal for 40.00 min
OrgMethod	6: Mark end of cycle 2
OrgMethod	7: Ramp 20.00 °C/min to 280.00 °C
OrgMethod	8: Mark end of cycle 3
OrgMethod	9: Ramp 20.00 °C/min to 20.00 °C
OrgMethod	10: Mark end of cycle 4
OrgMethod	11: Ramp 20.00 °C/min to 280.00 °C
OrgMethod	12: Mark end of cycle 5
OrgFile	C:\Users\jarra\Desktop\DSC\9-C1(1.2mol%)+C20(1.0mol%)\150-3.001
StartOfData
4.99994E-4	78.68658	-16.65142
0.05383332	78.91778	-13.65013
0.1038333	79.09582	-11.34098
0.1571666	79.25195	-9.322656
0.2071666	79.36958	-7.768126
0.2605000	79.47372	-6.413639
0.3105000	79.55284	-5.371074
0.3638334	79.62200	-4.464612
0.4138333	79.67524	-3.766688
0.4671667	79.71990	-3.157480
0.5171667	79.75519	-2.689518
0.5705000	79.78530	-2.282308
0.6205000	79.80862	-1.967854
0.6721668	79.82794	-1.702433
0.7238332	79.84361	-1.486944
0.7755000	79.85664	-1.315506
0.8271668	79.86650	-1.169657
0.8788332	79.87395	-1.057198
0.9305000	79.88124	-0.9629366
0.9821668	79.88591	-0.8868309
1.033833	79.89042	-0.8276264
1.083833	79.89272	-0.7806996
1.137166	79.89612	-0.7419480
1.187166	79.89712	-0.7130079
1.240500	79.89906	-0.6908875
1.290500	79.90001	-0.6750306
1.343833	79.90124	-0.6618158
1.393833	79.90197	-0.6534754
1.447166	79.90188	-0.6464310
1.497166	79.90175	-0.6418128
1.550500	79.90174	-0.6372641
1.600500	79.90241	-0.6328967
1.653833	79.90175	-0.6281214
1.703833	79.90100	-0.6236443
1.755500	79.90032	-0.6191059
1.807167	79.89978	-0.6146464
1.858834	79.89991	-0.6103367
1.910500	79.89975	-0.6062216
1.962166	79.89922	-0.6022861
2.013833	79.89878	-0.5985011
2.065500	79.89788	-0.5949325
2.117167	79.89778	-0.5915060
2.167167	79.89644	-0.5883745
2.220500	79.89703	-0.5853008
2.270500	79.89592	-0.5825902
2.323833	79.89581	-0.5799104
2.373834	79.89503	-0.5775866
2.427167	79.89458	-0.5752910
2.477167	79.89453	-0.5732789
2.530500	79.89375	-0.5713230
2.580500	79.89265	-0.5696497
2.633833	79.89225	-0.5680576
2.683833	79.89178	-0.5667302
2.737167	79.89168	-0.5654629
2.787167	79.89122	-0.5643845
2.838833	79.89038	-0.5633526
2.890500	79.88970	-0.5624356
2.942167	79.88890	-0.5616358
2.993833	79.88932	-0.5609178
3.040500	80.12942	-1.115416
3.093834	82.48386	-6.770150
3.143833	85.32766	-14.59349
3.197167	88.70038	-24.19027
3.247166	92.13919	-33.25525
3.300500	96.03839	-42.35400
3.350500	99.86469	-50.08881
3.403833	104.0924	-57.36572
3.453833	108.1618	-63.29594
3.505500	112.4528	-68.52710
3.557167	116.8078	-72.96562
3.608833	121.2069	-76.81406
3.660500	125.6347	-80.05750
3.712167	130.0837	-82.82644
3.763833	134.3850	-85.35594
3.815500	137.3200	-83.86182
3.867166	139.2432	-77.86419
3.917167	140.7800	-70.04312
3.970500	142.1177	-60.92830
4.020500	143.1712	-52.63084
4.073834	144.1138	-44.55304
4.123833	144.8618	-37.89233
4.177166	145.5367	-31.78480
4.227167	146.0735	-26.92080
4.280500	146.5628	-22.55750
4.330500	146.9533	-19.13838
4.383834	147.3112	-16.09101
4.433834	147.6008	-13.71165
4.487167	147.8675	-11.59984
4.537167	148.0835	-9.948829
4.588834	148.2769	-8.516968
4.640500	148.4458	-7.323770
4.692166	148.5925	-6.320768
4.743834	148.7199	-5.479189
4.795500	148.8326	-4.771716
4.847166	148.9314	-4.172833
4.898834	149.0171	-3.663644
4.950500	149.0932	-3.234310
5.000500	149.1589	-2.871613
5.053834	149.2217	-2.547144
5.103833	149.2725	-2.279260
5.157166	149.3212	-2.034434
5.207167	149.3621	-1.837406
5.260500	149.4024	-1.657134
5.310500	149.4348	-1.504620
5.363834	149.4658	-1.359376
5.413832	149.4923	-1.239580
5.467168	149.5186	-1.124932
5.517168	149.5399	-1.025628
5.570500	149.5615	-0.9301474
5.620500	149.5808	-0.8466391
5.672168	149.5978	-0.7669484
5.723834	149.6145	-0.6929340
5.775500	149.6292	-0.6202326
5.827168	149.6433	-0.5519578
5.878834	149.6563	-0.4836512
5.930500	149.6684	-0.4175930
5.982168	149.6812	-0.3519796
6.033832	149.6914	-0.2867510
6.083832	149.7016	-0.2224171
6.137168	149.7115	-0.1527367
6.187168	149.7218	-.08875171
6.240500	149.7303	-.01894766
6.290500	149.7395	0.04780392
6.343834	149.7497	0.1209071
6.393832	149.7573	0.1913993
6.447168	149.7660	0.2690879
6.497168	149.7745	0.3414372
6.550500	149.7827	0.4233550
6.600500	149.7903	0.5032887
6.653832	149.7989	0.5884486
6.703832	149.8073	0.6727918
6.755500	149.8152	0.7622238
6.807166	149.8219	0.8552075
6.858832	149.8310	0.9475497
6.910500	149.8394	1.043224
6.962168	149.8474	1.143784
7.013834	149.8559	1.244209
7.065500	149.8644	1.349528
7.117166	149.8736	1.457143
7.167168	149.8810	1.566848
7.220500	149.8911	1.684638
7.270500	149.8998	1.798266
7.323834	149.9087	1.922628
7.373834	149.9181	2.040884
7.427168	149.9273	2.174997
7.477168	149.9372	2.301475
7.530500	149.9468	2.441034
7.580500	149.9563	2.572862
7.633832	149.9664	2.719705
7.683832	149.9763	2.857908
7.737168	149.9877	3.008594
7.787168	149.9978	3.156008
7.838834	150.0089	3.309390
7.890500	150.0197	3.468512
7.942168	150.0302	3.628456
7.993834	150.0418	3.790110
8.045500	150.0540	3.955830
8.097168	150.0660	4.126236
8.148834	150.0772	4.302310
8.200500	150.0901	4.487558
8.250500	150.1034	4.681876
8.303832	150.1188	4.926568
8.353832	150.1370	5.214106
8.407166	150.1611	5.602116
8.457168	150.1902	6.054547
8.510499	150.2280	6.635956
8.560500	150.2680	7.257858
8.613834	150.3146	7.961578
8.663834	150.3602	8.647238
8.717168	150.4090	9.372366
8.767168	150.4540	10.03503
8.820500	150.4990	10.71639
8.870499	150.5398	11.30782
8.922168	150.5792	11.88300
8.973832	150.6157	12.40248
9.025499	150.6474	12.87953
9.077168	150.6769	13.29614
9.128834	150.7021	13.66736
9.180500	150.7247	13.98261
9.232166	150.7432	14.24930
9.283832	150.7596	14.46214
9.333832	150.7714	14.62239
9.387168	150.7804	14.74910
9.437166	150.7873	14.82332
9.490500	150.7905	14.86613
9.540500	150.7921	14.87868
9.593832	150.7918	14.87888
9.643832	150.7893	14.87531
9.697168	150.7849	14.83469
9.747168	150.7802	14.73853
9.800500	150.7748	14.61538
9.850500	150.7679	14.50284
9.903832	150.7606	14.38463
9.953834	150.7534	14.27348
10.00550	150.7467	14.16085
10.05717	150.7392	14.05231
10.10883	150.7324	13.94719
10.16050	150.7257	13.84813
10.21217	150.7196	13.75640
10.26383	150.7147	13.66948
10.31550	150.7093	13.59056
10.36717	150.7037	13.52152
10.41717	150.7006	13.46190
10.47050	150.6964	13.40625
10.52050	150.6936	13.36151
10.57383	150.6902	13.32151
10.62383	150.6882	13.29127
10.67717	150.6860	13.26726
10.72717	150.6843	13.25083
10.78050	150.6832	13.23981
10.83050	150.6833	13.23480
10.88383	150.6837	13.23151
10.93383	150.6845	13.22906
10.98717	150.6856	13.22761
11.03717	150.6869	13.22944
11.08883	150.6913	13.25014
11.14050	150.6955	13.31319
11.19217	150.7016	13.42573
11.24384	150.7096	13.57092
11.29550	150.7204	13.74861
11.34717	150.7335	13.96237
11.39883	150.7489	14.21786
11.45050	150.7675	14.52039
11.50050	150.7888	14.85271
11.55383	150.8146	15.24450
11.60383	150.8399	15.64391
11.65717	150.8706	16.09157
11.70717	150.8987	16.53141
11.76050	150.9312	17.00768
11.81050	150.9603	17.45980
11.86383	150.9922	17.94256
11.91383	151.0208	18.38698
11.96717	151.0531	18.84640
12.01717	151.0805	19.26708
12.07050	151.1089	19.69114
12.12050	151.1350	20.06403
12.17217	151.1592	20.42273
12.22383	151.1809	20.74160
12.27550	151.2000	21.01543
12.32717	151.2159	21.23638
12.37884	151.2281	21.40116
12.43050	151.2366	21.50694
12.48217	151.2414	21.55647
12.53383	151.2408	21.55845
12.58383	151.2373	21.54912
12.63717	151.2286	21.36715
12.68716	151.2151	21.10418
12.74050	151.1957	20.76941
12.79050	151.1735	20.40491
12.84383	151.1408	19.83038
12.89383	151.1024	19.30363
12.94717	151.0648	18.70521
12.99717	151.0250	18.09611
13.05050	150.9805	17.41838
13.10050	150.9384	16.77225
13.15383	150.8916	16.06513
13.20383	150.8482	15.41721
13.25550	150.8040	14.74417
13.30717	150.7593	14.06602
13.35883	150.7146	13.40534
13.41050	150.6714	12.74722
13.46217	150.6285	12.10461
13.51383	150.5868	11.47481
13.56550	150.5452	10.85826
13.61716	150.5047	10.25922
13.66716	150.4673	9.688087
13.72050	150.4276	9.092195
13.77050	150.3908	8.546001
13.82384	150.3522	7.974762
13.87384	150.3180	7.454628
13.92717	150.2818	6.917666
13.97717	150.2490	6.429283
14.03050	150.2158	5.926816
14.08050	150.1848	5.472826
14.13383	150.1532	5.010142
14.18383	150.1250	4.588426
14.23716	150.0966	4.163364
14.28717	150.0713	3.780102
14.33883	150.0455	3.405544
14.39050	150.0215	3.050641
14.44217	149.9992	2.715353
14.49384	149.9778	2.401683
14.54550	149.9574	2.102512
14.59717	149.9382	1.821676
14.64883	149.9215	1.566446
14.70050	149.9049	1.321182
14.75050	149.8904	1.108902
14.80383	149.8761	0.8926522
14.85383	149.8634	0.7072955
14.90717	149.8505	0.5284846
14.95717	149.8399	0.3715613
15.01050	149.8299	0.2200082
15.06050	149.8200	0.09000836
15.11383	149.8123	-.03871921
15.16383	149.8045	-0.1509783
15.21716	149.7970	-0.2563269
15.26717	149.7905	-0.3478097
15.32050	149.7848	-0.4387482
15.37050	149.7788	-0.5150352
15.42217	149.7737	-0.5865592
15.47383	149.7690	-0.6512183
15.52550	149.7652	-0.7118447
15.57717	149.7612	-0.7674555
15.62883	149.7577	-0.8172012
15.68050	149.7540	-0.8620706
15.73216	149.7516	-0.8959438
15.78383	149.7488	-0.9229694
15.83383	149.7469	-0.9485602
15.88716	149.7448	-0.9757794
15.93717	149.7426	-0.9992152
15.99050	149.7402	-1.024350
16.04050	149.7394	-1.046941
16.09383	149.7373	-1.069103
16.14383	149.7356	-1.088400
16.19717	149.7344	-1.107695
16.24716	149.7333	-1.124037
16.30050	149.7309	-1.139553
16.35050	149.7305	-1.153559
16.40383	149.7292	-1.168042
16.45383	149.7271	-1.179764
16.50550	149.7270	-1.192440
16.55716	149.7264	-1.202644
16.60883	149.7251	-1.212440
16.66050	149.7233	-1.221452
16.71216	149.7228	-1.229638
16.76383	149.7212	-1.237786
16.81550	149.7211	-1.245918
16.86716	149.7211	-1.254039
16.91716	149.7198	-1.262004
16.97050	149.7192	-1.270553
17.02050	149.7193	-1.278611
17.07383	149.7174	-1.287195
17.12383	149.7174	-1.295334
17.17716	149.7164	-1.303976
17.22716	149.7151	-1.312110
17.28050	149.7156	-1.320748
17.33050	149.7141	-1.328778
17.38383	149.7144	-1.337370
17.43383	149.7140	-1.345364
17.48716	149.7132	-1.353745
17.53717	149.7134	-1.361532
17.58883	149.7134	-1.369561
17.64050	149.7122	-1.377462
17.69216	149.7128	-1.385288
17.74383	149.7127	-1.392952
17.79550	149.7124	-1.400526
17.84716	149.7117	-1.407909
17.89883	149.7114	-1.415160
17.95050	149.7108	-1.422301
18.00050	149.7108	-1.429035
18.05383	149.7105	-1.436028
18.10383	149.7110	-1.442472
18.15716	149.7106	-1.449203
18.20716	149.7104	-1.455333
18.26050	149.7098	-1.461716
18.31050	149.7092	-1.467566
18.36383	149.7093	-1.473663
18.41383	149.7101	-1.479257
18.46716	149.7090	-1.485062
18.51716	149.7082	-1.490391
18.57050	149.7094	-1.495947
18.62050	149.7087	-1.500988
18.67216	149.7079	-1.506076
18.72383	149.7078	-1.511091
18.77550	149.7080	-1.516008
18.82716	149.7079	-1.520784
18.87883	149.7076	-1.525453
18.93050	149.7069	-1.529948
18.98216	149.7069	-1.534379
19.03383	149.7074	-1.538650
19.08383	149.7068	-1.542724
19.13716	149.7066	-1.547009
19.18716	149.7066	-1.550933
19.24050	149.7060	-1.555013
19.29050	149.7061	-1.558768
19.34383	149.7059	-1.562634
19.39383	149.7060	-1.566166
19.44716	149.7050	-1.569830
19.49716	149.7052	-1.573167
19.55050	149.7052	-1.576663
19.60050	149.7046	-1.579834
19.65383	149.7051	-1.583166
19.70383	149.7048	-1.586194
19.75550	149.7048	-1.589228
19.80716	149.7052	-1.592253
19.85883	149.7042	-1.595237
19.91050	149.7050	-1.598189
19.96216	149.7041	-1.601052
20.01383	149.7046	-1.603895
20.06550	149.7044	-1.606632
20.11716	149.7050	-1.609354
20.16716	149.7036	-1.611897
20.22050	149.7038	-1.614580
20.27050	149.7031	-1.617012
20.32383	149.7041	-1.619546
20.37383	149.7047	-1.621873
20.42716	149.7039	-1.624258
20.47716	149.7031	-1.626472
20.53050	149.7031	-1.628790
20.58050	149.7038	-1.630941
20.63383	149.7037	-1.633110
20.68383	149.7037	-1.635119
20.73716	149.7037	-1.637128
20.78717	149.7032	-1.639002
20.83883	149.7034	-1.640942
20.89050	149.7036	-1.642800
20.94216	149.7030	-1.644583
20.99383	149.7033	-1.646359
21.04550	149.7030	-1.648091
21.09716	149.7024	-1.649722
21.14883	149.7026	-1.651372
21.20050	149.7032	-1.653009
21.25050	149.7027	-1.654538
21.30383	149.7028	-1.656153
21.35383	149.7027	-1.657641
21.40716	149.7020	-1.659152
21.45717	149.7029	-1.660543
21.51050	149.7024	-1.661985
21.56050	149.7018	-1.663341
21.61383	149.7020	-1.664714
21.66383	149.7017	-1.665942
21.71716	149.7016	-1.667228
21.76716	149.7030	-1.668476
21.82050	149.7011	-1.669729
21.87050	149.7026	-1.670882
21.92216	149.7021	-1.672053
21.97383	149.7020	-1.673202
22.02550	149.7013	-1.674262
22.07716	149.7028	-1.675340
22.12883	149.7022	-1.676360
22.18050	149.7018	-1.677356
22.23216	149.7016	-1.678280
22.28383	149.7020	-1.679147
22.33383	149.7014	-1.679884
22.38716	149.7015	-1.680588
22.43716	149.7014	-1.681185
22.49050	149.7025	-1.681710
22.54050	149.7031	-1.681939
22.59383	149.7046	-1.678312
22.64383	149.7057	-1.669707
22.69716	149.7059	-1.667773
22.74716	149.7053	-1.666614
22.80050	149.7047	-1.665908
22.85050	149.7046	-1.665686
22.90383	149.7031	-1.665780
22.95383	149.7022	-1.666156
23.00550	149.7034	-1.666815
23.05716	149.7029	-1.667637
23.10883	149.7018	-1.668588
23.16050	149.7022	-1.669656
23.21216	149.7022	-1.670879
23.26383	149.7013	-1.672101
23.31550	149.7018	-1.673409
23.36716	149.7019	-1.674720
23.41716	149.7018	-1.676022
23.47050	149.7021	-1.677402
23.52050	149.7019	-1.678656
23.57383	149.7002	-1.679970
23.62383	149.7019	-1.681213
23.67717	149.7010	-1.682499
23.72716	149.7020	-1.683699
23.78050	149.7023	-1.684995
23.83050	149.7017	-1.686163
23.88383	149.7016	-1.687400
23.93383	149.7019	-1.688542
23.98716	149.7016	-1.689714
24.03717	149.7017	-1.690800
24.08883	149.7018	-1.691868
24.14050	149.7006	-1.692883
24.19216	149.7015	-1.693882
24.24383	149.7009	-1.694754
24.29550	149.7016	-1.695594
24.34716	149.7014	-1.696422
24.39883	149.7016	-1.697270
24.45050	149.7017	-1.698092
24.50050	149.7006	-1.698832
24.55383	149.7008	-1.699651
24.60383	149.7013	-1.700408
24.65716	149.7004	-1.701189
24.70717	149.7000	-1.701883
24.76050	149.7005	-1.702645
24.81050	149.7004	-1.703371
24.86383	149.7019	-1.704140
24.91383	149.7008	-1.704832
24.96716	149.7016	-1.705545
25.01716	149.7006	-1.706194
25.07050	149.7003	-1.706884
25.12050	149.7008	-1.707459
25.17216	149.7002	-1.708045
25.22383	149.7011	-1.708633
25.27550	149.7011	-1.709198
25.32716	149.7004	-1.709774
25.37883	149.7012	-1.710312
25.43050	149.7014	-1.710879
25.48216	149.7014	-1.711393
25.53383	149.7010	-1.711939
25.58383	149.7004	-1.712378
25.63716	149.7013	-1.712851
25.68717	149.6998	-1.713304
25.74050	149.7016	-1.713790
25.79050	149.7004	-1.714205
25.84383	149.7006	-1.714591
25.89383	149.7016	-1.715036
25.94717	149.7000	-1.715440
25.99716	149.7006	-1.715784
26.05050	149.7007	-1.716198
26.10050	149.7008	-1.716613
26.15383	149.7004	-1.716952
26.20383	149.7010	-1.717292
26.25550	149.6998	-1.717608
26.30716	149.7000	-1.717952
26.35883	149.7007	-1.718275
26.41050	149.7000	-1.718610
26.46216	149.7004	-1.718966
26.51383	149.6998	-1.719337
26.56550	149.7008	-1.719711
26.61716	149.7010	-1.720061
26.66716	149.7008	-1.720391
26.72050	149.7002	-1.720723
26.77050	149.6996	-1.721018
26.82383	149.7000	-1.721327
26.87383	149.7013	-1.721690
26.92717	149.7010	-1.722051
26.97717	149.6999	-1.722368
27.03050	149.7008	-1.722758
27.08050	149.7008	-1.723064
27.13383	149.6993	-1.723363
27.18383	149.7009	-1.723630
27.23716	149.7002	-1.723906
27.28717	149.7000	-1.724133
27.33883	149.6992	-1.724391
27.39050	149.7005	-1.724705
27.44216	149.6994	-1.724998
27.49383	149.6996	-1.725272
27.54550	149.6996	-1.725524
27.59716	149.6988	-1.725812
27.64883	149.6996	-1.726112
27.70050	149.6997	-1.726428
27.75050	149.6998	-1.726750
27.80383	149.6996	-1.727057
27.85383	149.7001	-1.727363
27.90716	149.7009	-1.727751
27.95716	149.6999	-1.728046
28.01050	149.6998	-1.728310
28.06050	149.7008	-1.728631
28.11383	149.6997	-1.728945
28.16383	149.7004	-1.729316
28.21716	149.7000	-1.729676
28.26716	149.7002	-1.730037
28.32050	149.7001	-1.730402
28.37050	149.6995	-1.730728
28.42216	149.7001	-1.731038
28.47383	149.6999	-1.731374
28.52550	149.7001	-1.731670
28.57717	149.7000	-1.731942
28.62883	149.7003	-1.732213
28.68050	149.6998	-1.732460
28.73216	149.7006	-1.732697
28.78383	149.6993	-1.732884
28.83383	149.7013	-1.733153
28.88716	149.7003	-1.733370
28.93717	149.7006	-1.733611
28.99050	149.6996	-1.733808
29.04050	149.6994	-1.733995
29.09383	149.7002	-1.734228
29.14383	149.7005	-1.734457
29.19717	149.7004	-1.734709
29.24716	149.7004	-1.734972
29.30050	149.7003	-1.735206
29.35050	149.7002	-1.735445
29.40383	149.7004	-1.735652
29.45383	149.7001	-1.735888
29.50550	149.7006	-1.736083
29.55716	149.6995	-1.736260
29.60883	149.6999	-1.736458
29.66050	149.7000	-1.736678
29.71216	149.7006	-1.736884
29.76383	149.7002	-1.737052
29.81550	149.6997	-1.737180
29.86716	149.7005	-1.737320
29.91716	149.7002	-1.737469
29.97050	149.7003	-1.737663
30.02050	149.6996	-1.737818
30.07383	149.6993	-1.737984
30.12383	149.7004	-1.738148
30.17717	149.7000	-1.738349
30.22717	149.6996	-1.738538
30.28050	149.6997	-1.738716
30.33050	149.7000	-1.738934
30.38383	149.6995	-1.739170
30.43383	149.7007	-1.739418
30.48716	149.7000	-1.739625
30.53717	149.7004	-1.739796
30.58883	149.6993	-1.739976
30.64050	149.6999	-1.740122
30.69216	149.7000	-1.740265
30.74383	149.6997	-1.740408
30.79550	149.7000	-1.740565
30.84716	149.6999	-1.740710
30.89883	149.6996	-1.740844
30.95050	149.6996	-1.740913
31.00050	149.6993	-1.741019
31.05383	149.6995	-1.741165
31.10383	149.7002	-1.741357
31.15716	149.7000	-1.741493
31.20716	149.7006	-1.741658
31.26050	149.6997	-1.741835
31.31050	149.6994	-1.741977
31.36383	149.7005	-1.742142
31.41383	149.6996	-1.742296
31.46716	149.6994	-1.742430
31.51716	149.7002	-1.742576
31.57050	149.6994	-1.742730
31.62050	149.6989	-1.742826
31.67216	149.6992	-1.742951
31.72383	149.6998	-1.743097
31.77550	149.6994	-1.743225
31.82717	149.7002	-1.743368
31.87883	149.6993	-1.743475
31.93050	149.6993	-1.743622
31.98216	149.7003	-1.743745
32.03383	149.6995	-1.743874
32.08383	149.6997	-1.744031
32.13716	149.6997	-1.744209
32.18716	149.7000	-1.744377
32.24050	149.6992	-1.744509
32.29050	149.6991	-1.744599
32.34384	149.6994	-1.744737
32.39383	149.6997	-1.744879
32.44717	149.6997	-1.745051
32.49716	149.6991	-1.745187
32.55050	149.6994	-1.745345
32.60050	149.6992	-1.745534
32.65383	149.6991	-1.745641
32.70383	149.7001	-1.745776
32.75550	149.6998	-1.745866
32.80716	149.6997	-1.745977
32.85883	149.6992	-1.746071
32.91050	149.6985	-1.746165
32.96216	149.6992	-1.746271
33.01383	149.6989	-1.746361
33.06550	149.6995	-1.746482
33.11716	149.6989	-1.746586
33.16716	149.6994	-1.746730
33.22050	149.6995	-1.746892
33.27050	149.6985	-1.747085
33.32383	149.6997	-1.747256
33.37383	149.6990	-1.747410
33.42717	149.6996	-1.747646
33.47717	149.6997	-1.747867
33.53050	149.6995	-1.748077
33.58050	149.6996	-1.748273
33.63383	149.6995	-1.748483
33.68384	149.6994	-1.748672
33.73717	149.7004	-1.748832
33.78717	149.7000	-1.748953
33.83883	149.6999	-1.749089
33.89050	149.6998	-1.749198
33.94216	149.6998	-1.749278
33.99383	149.6998	-1.749330
34.04550	149.6999	-1.749371
34.09716	149.6987	-1.749405
34.14883	149.6997	-1.749487
34.20050	149.6994	-1.749612
34.25050	149.7001	-1.749723
34.30383	149.6996	-1.749835
34.35383	149.6997	-1.749908
34.40716	149.6991	-1.749939
34.45716	149.6999	-1.750011
34.51050	149.6991	-1.750088
34.56050	149.6998	-1.750134
34.61383	149.6995	-1.750206
34.66383	149.6995	-1.750218
34.71716	149.6990	-1.750259
34.76716	149.6995	-1.750288
34.82050	149.6995	-1.750358
34.87050	149.7004	-1.750484
34.92216	149.6992	-1.750575
34.97383	149.6995	-1.750667
35.02550	149.6994	-1.750759
35.07717	149.6996	-1.750844
35.12883	149.6994	-1.750927
35.18050	149.6996	-1.751034
35.23216	149.6999	-1.751156
35.28383	149.6992	-1.751201
35.33383	149.7000	-1.751289
35.38716	149.7000	-1.751391
35.43716	149.7000	-1.751496
35.49050	149.6999	-1.751592
35.54050	149.6994	-1.751682
35.59384	149.7000	-1.751750
35.64383	149.6994	-1.751794
35.69717	149.6988	-1.751792
35.74716	149.6992	-1.751840
35.80050	149.7001	-1.751906
35.85050	149.7005	-1.752004
35.90383	149.6997	-1.752092
35.95383	149.7004	-1.752255
36.00550	149.6994	-1.752321
36.05716	149.6994	-1.752450
36.10883	149.6992	-1.752506
36.16050	149.6995	-1.752552
36.21216	149.6998	-1.752600
36.26383	149.6995	-1.752613
36.31550	149.6992	-1.752603
36.36716	149.7001	-1.752619
36.41716	149.6987	-1.752628
36.47050	149.6998	-1.753063
36.52050	149.6987	-1.753350
36.57383	149.6994	-1.753587
36.62383	149.6997	-1.753742
36.67717	149.6999	-1.753861
36.72717	149.6986	-1.753877
36.78050	149.6990	-1.753915
36.83050	149.6994	-1.753924
36.88383	149.6992	-1.753940
36.93384	149.6984	-1.753993
36.98717	149.6995	-1.754003
37.03717	149.6993	-1.754034
37.08883	149.6991	-1.754070
37.14050	149.6999	-1.754104
37.19216	149.6989	-1.754123
37.24383	149.6992	-1.754156
37.29550	149.6995	-1.754229
37.34716	149.6998	-1.754230
37.39883	149.6988	-1.754206
37.45050	149.6990	-1.754164
37.50050	149.6994	-1.754161
37.55383	149.6996	-1.754156
37.60383	149.6994	-1.754164
37.65716	149.6995	-1.754161
37.70716	149.6994	-1.754136
37.76050	149.7001	-1.754155
37.81050	149.6990	-1.754163
37.86383	149.6996	-1.754181
37.91383	149.6990	-1.754194
37.96716	149.6992	-1.754229
38.01716	149.6989	-1.754256
38.07050	149.6989	-1.754304
38.12050	149.6988	-1.754340
38.17216	149.6992	-1.754378
38.22383	149.6995	-1.754424
38.27550	149.7001	-1.754476
38.32717	149.7002	-1.754522
38.37883	149.6994	-1.754502
38.43050	149.7000	-1.754525
38.48216	149.6996	-1.754529
38.53383	149.6994	-1.754550
38.58383	149.6999	-1.754535
38.63716	149.6995	-1.754544
38.68716	149.7002	-1.754560
38.74050	149.6990	-1.754575
38.79050	149.6986	-1.754584
38.84384	149.6998	-1.754641
38.89383	149.7001	-1.754714
38.94717	149.7001	-1.754804
38.99716	149.6998	-1.754863
39.05050	149.6997	-1.754879
39.10050	149.6997	-1.754891
39.15383	149.6995	-1.754864
39.20383	149.6995	-1.754854
39.25550	149.6993	-1.754807
39.30716	149.6989	-1.754742
39.35883	149.6990	-1.754680
39.41050	149.6993	-1.754600
39.46216	149.6992	-1.754553
39.51383	149.6986	-1.754510
39.56550	149.6988	-1.754441
39.61716	149.6998	-1.754393
39.66716	149.6994	-1.754362
39.72050	149.6992	-1.754347
39.77050	149.6998	-1.754377
39.82383	149.6991	-1.754424
39.87383	149.6990	-1.754476
39.92717	149.6994	-1.754539
39.97717	149.6996	-1.754594
40.03050	149.6990	-1.754673
40.08050	149.6996	-1.754674
40.13383	149.6998	-1.754715
40.18384	149.6992	-1.754742
40.23717	149.6988	-1.754717
40.28717	149.6996	-1.754710
40.33883	149.6989	-1.754684
40.39050	149.6991	-1.754668
40.44216	149.6997	-1.754634
40.49383	149.6987	-1.754658
40.54550	149.6988	-1.754665
40.59716	149.6998	-1.754749
40.64883	149.6988	-1.754843
40.70050	149.6995	-1.754915
40.75050	149.6996	-1.754990
40.80383	149.6991	-1.755047
40.85383	149.6986	-1.755110
40.90716	149.6990	-1.755226
40.95716	149.6998	-1.755306
41.01050	149.6979	-1.755362
41.06050	149.6990	-1.755373
41.11383	149.6996	-1.755410
41.16383	149.6989	-1.755428
41.21717	149.6989	-1.755456
41.26717	149.6990	-1.755455
41.32050	149.6987	-1.755452
41.37050	149.6994	-1.755457
41.42216	149.6991	-1.755475
41.47383	149.6997	-1.755509
41.52550	149.6984	-1.755536
41.57717	149.6990	-1.755604
41.62883	149.6988	-1.755648
41.68050	149.6990	-1.755736
41.73217	149.6992	-1.755867
41.78383	149.6992	-1.755955
41.83383	149.6994	-1.756116
41.88716	149.6996	-1.756216
41.93716	149.6996	-1.756311
41.99050	149.6996	-1.756429
42.04050	149.6996	-1.756530
42.09384	149.6992	-1.756606
42.14383	149.6998	-1.756712
42.19717	149.6991	-1.756794
42.24716	149.6996	-1.756868
42.30050	149.6987	-1.756927
42.35050	149.6998	-1.756991
42.40383	149.6998	-1.757010
42.45383	149.6996	-1.757066
42.50550	149.6989	-1.757129
42.55717	149.6994	-1.757223
42.60883	149.6988	-1.757341
42.66050	149.6988	-1.757446
42.71216	149.6999	-1.757561
42.76383	149.7005	-1.757611
42.81550	149.6991	-1.757640
42.86716	149.6992	-1.757617
42.91716	149.6993	-1.757665
42.97050	149.6987	-1.757682
43.01717	149.7000	-1.757808
43.07050	149.8176	-2.140638
43.12050	150.2586	-3.932722
43.17216	150.8481	-6.434692
43.22383	151.5295	-9.035949
43.27550	152.2732	-11.38202
43.32717	153.0673	-13.40937
43.37883	153.9028	-15.11372
43.43050	154.7706	-16.53644
43.48217	155.6654	-17.71992
43.53383	156.5824	-18.68844
43.58383	157.4860	-19.48791
43.63716	158.4644	-20.19873
43.68716	159.3941	-20.75086
43.74050	160.3955	-21.26154
43.79050	161.3427	-21.67218
43.84384	162.3603	-22.05882
43.89383	163.3199	-22.37199
43.94717	164.3466	-22.67303
43.99716	165.3150	-22.92985
44.05050	166.3492	-23.18521
44.10050	167.3215	-23.40294
44.15383	168.3614	-23.62815
44.20383	169.3389	-23.83398
44.25550	170.3488	-24.04138
44.30717	171.3608	-24.25284
44.35883	172.3747	-24.45438
44.41050	173.3896	-24.64853
44.46216	174.4041	-24.83537
44.51383	175.4210	-25.04798
44.56550	176.4376	-25.23724
44.61716	177.4544	-25.44461
44.66716	178.4386	-25.63328
44.72050	179.4898	-25.80549
44.77050	180.4763	-25.98300
44.82383	181.5272	-26.18614
44.87383	182.5135	-26.40476
44.92717	183.5637	-26.65056
44.97717	184.5489	-26.88916
45.03050	185.5995	-27.16406
45.08050	186.5832	-27.43032
45.13383	187.6308	-27.73400
45.18383	188.6122	-28.02982
45.23717	189.6580	-28.38635
45.28717	190.6375	-28.72238
45.33883	191.6510	-29.08475
45.39050	192.6621	-29.46592
45.44217	193.6724	-29.87141
45.49383	194.6824	-30.29590
45.54550	195.6900	-30.72644
45.59716	196.6968	-31.19300
45.64883	197.7018	-31.67560
45.70050	198.7067	-32.16878
45.75050	199.6771	-32.67688
45.80383	200.7123	-33.24569
45.85383	201.6801	-33.80310
45.90717	202.7110	-34.45715
45.95717	203.6744	-35.11195
46.01050	204.6982	-35.91539
46.06050	205.6546	-36.77383
46.11383	206.6685	-37.79594
46.16383	207.6124	-38.92006
46.21717	208.6099	-40.30108
46.26717	209.5354	-41.80881
46.32050	210.5083	-43.70913
46.37050	211.4053	-45.78664
46.42216	212.3152	-48.25761
46.47383	213.2072	-50.97032
46.52550	214.0856	-53.78850
46.57717	214.9568	-56.56602
46.62883	215.8285	-59.24840
46.68050	216.7004	-62.02172
46.73217	217.5691	-64.88445
46.78383	218.4356	-67.74688
46.83383	219.2787	-70.04962
46.88716	220.2167	-70.57220
46.93716	221.2192	-66.85866
46.99050	222.4118	-63.43315
47.04050	223.5690	-60.07560
47.09384	224.8412	-55.74551
47.14383	226.0748	-50.97611
47.19717	227.4264	-45.78691
47.24716	228.6868	-42.12387
47.30050	229.9915	-39.15437
47.35050	231.1759	-36.97072
47.40383	232.4045	-35.10425
47.45383	233.5258	-33.68122
47.50550	234.6622	-32.49508
47.55717	235.7780	-31.53281
47.60883	236.8787	-30.76746
47.66050	237.9661	-30.14266
47.71216	239.0432	-29.64439
47.76383	240.1116	-29.25443
47.81550	241.1736	-28.93968
47.86716	242.2296	-28.68480
47.91716	243.2480	-28.49721
47.97050	244.3301	-28.34554
48.02050	245.3414	-28.22832
48.07383	246.4187	-28.13150
48.12383	247.4266	-28.05694
48.17717	248.4996	-28.00435
48.22717	249.5056	-27.96841
48.28050	250.5766	-27.94435
48.33050	251.5797	-27.93258
48.38383	252.6486	-27.92474
48.43383	253.6514	-27.92175
48.48717	254.7200	-27.91980
48.53717	255.7214	-27.91864
48.58883	256.7537	-27.91863
48.64050	257.7872	-27.92117
48.69217	258.8206	-27.93159
48.74383	259.8540	-27.95200
48.79550	260.8852	-27.98137
48.84716	261.9170	-28.01722
48.89883	262.9494	-28.06184
48.95050	263.9822	-28.10788
49.00050	264.9802	-28.15964
49.05383	266.0458	-28.20718
49.10383	267.0432	-28.25537
49.15717	268.1077	-28.30050
49.20717	269.1060	-28.35244
49.26050	270.1734	-28.39650
49.31050	271.1706	-28.42958
49.36383	272.2360	-28.46815
49.41383	273.2348	-28.50492
49.46717	274.2990	-28.52601
49.51383	275.2308	-28.57918
49.56550	276.0414	-28.56540
49.61716	276.1186	-27.82015
49.66716	275.9221	-23.32208
49.72050	275.5300	-17.17805
49.77050	275.0500	-11.53490
49.82383	274.4430	-6.201928
49.87383	273.8037	-1.946735
49.92717	273.0616	1.839796
49.97717	272.3154	4.776700
50.03050	271.4791	7.350996
50.08050	270.6639	9.346040
50.13383	269.7640	11.07442
50.18383	268.8982	12.40940
50.23717	267.9544	13.59425
50.28717	267.0539	14.50755
50.33883	266.1103	15.29456
50.39050	265.1533	15.94270
50.44217	264.1880	16.48396
50.49383	263.2142	16.93328
50.54550	262.2334	17.31025
50.59716	261.2460	17.63191
50.64883	260.2555	17.89522
50.70050	259.2603	18.12102
50.75050	258.2923	18.30576
50.80383	257.2580	18.46737
50.85383	256.2855	18.60548
50.90717	255.2445	18.73174
50.95717	254.2682	18.83934
51.01050	253.2238	18.93761
51.06050	252.2434	19.01895
51.11383	251.1969	19.09059
51.16383	250.2142	19.15198
51.21717	249.1639	19.21199
51.26716	248.1792	19.25820
51.32050	247.1261	19.30020
51.37050	246.1397	19.33355
51.42217	245.1192	19.36159
51.47383	244.0983	19.38612
51.52550	243.0765	19.40371
51.57717	242.0553	19.41846
51.62883	241.0327	19.43176
51.68050	240.0102	19.44437
51.73217	238.9871	19.46086
51.78383	237.9650	19.47378
51.83383	236.9748	19.48714
51.88716	235.9173	19.49934
51.93716	234.9266	19.50755
51.99050	233.8685	19.51474
52.04050	232.8766	19.52114
52.09384	231.8182	19.52749
52.14384	230.8255	19.53357
52.19717	229.7677	19.54013
52.24717	228.7758	19.54622
52.30050	227.7170	19.55328
52.35050	226.7244	19.55975
52.40383	225.6654	19.56767
52.45383	224.6728	19.57574
52.50550	223.6466	19.58283
52.55717	222.6206	19.58984
52.60883	221.5939	19.59699
52.66050	220.5682	19.60372
52.71216	219.5423	19.61047
52.76382	218.5156	19.61714
52.81550	217.4892	19.62347
52.86716	216.4634	19.62979
52.91716	215.4703	19.63577
52.97050	214.4103	19.64204
53.02050	213.4159	19.64774
53.07383	212.3560	19.65352
53.12383	211.3616	19.65871
53.17717	210.3028	19.66401
53.22717	209.3089	19.66894
53.28050	208.2498	19.67392
53.33050	207.2546	19.67848
53.38383	206.1950	19.68323
53.43383	205.2004	19.68742
53.48717	204.1405	19.69174
53.53716	203.1464	19.69553
53.58882	202.1190	19.69903
53.64050	201.0921	19.70229
53.69216	200.0651	19.70541
53.74382	199.0381	19.70846
53.79550	198.0115	19.71151
53.84716	196.9830	19.71446
53.89883	195.9574	19.71752
53.95050	194.9292	19.72068
54.00050	193.9365	19.72388
54.05383	192.8762	19.72718
54.10383	191.8808	19.73027
54.15717	190.8209	19.73352
54.20717	189.8260	19.73642
54.26050	188.7636	19.73926
54.31050	187.7691	19.74155
54.36382	186.7083	19.74370
54.41382	185.7129	19.74552
54.46717	184.6514	19.74703
54.51716	183.6584	19.74792
54.57050	182.5963	19.74864
54.62050	181.6025	19.74902
54.67217	180.5735	19.74946
54.72382	179.5468	19.75013
54.77550	178.5198	19.75098
54.82717	177.4914	19.75220
54.87883	176.4649	19.75361
54.93050	175.4374	19.75532
54.98217	174.4110	19.75731
55.03383	173.3828	19.75945
55.08383	172.3887	19.76145
55.13716	171.3266	19.76357
55.18716	170.3328	19.76552
55.24050	169.2706	19.76756
55.29050	168.2754	19.76962
55.34384	167.2140	19.77146
55.39384	166.2194	19.77320
55.44717	165.1598	19.77739
55.49717	164.1675	19.83399
55.55050	163.1124	20.03005
55.60050	162.1280	20.32722
55.65383	161.0871	20.83392
55.70383	160.1239	21.62484
55.75550	159.1501	22.89574
55.80717	158.2054	24.79763
55.85883	157.2969	27.33993
55.91050	156.4274	30.40980
55.96216	155.5892	33.72199
56.01382	154.7674	37.02679
56.06550	153.9472	40.00692
56.11716	153.1105	42.45516
56.16716	152.2734	44.19891
56.22050	151.3419	45.31562
56.27050	150.4246	45.64876
56.32383	149.4031	45.40008
56.37383	148.4062	44.66550
56.42717	147.3066	43.47076
56.47717	146.2525	42.14731
56.53050	145.1100	40.61516
56.58050	144.0259	39.11274
56.63383	142.8646	37.55319
56.68383	141.7759	36.12220
56.73717	140.6149	34.66818
56.78716	139.5309	33.38705
56.83882	138.4140	32.13546
56.89050	137.3030	30.98554
56.94216	136.1977	29.91148
56.99382	135.0975	28.93568
57.04550	134.0030	28.06337
57.09716	132.9144	27.27232
57.14883	131.8304	26.56556
57.20050	130.7535	25.94797
57.25050	129.7158	25.41596
57.30383	128.6136	24.93236
57.35383	127.5868	24.52994
57.40717	126.4943	24.15385
57.45717	125.4742	23.85957
57.51050	124.3902	23.56892
57.56050	123.3763	23.35720
57.61382	122.2984	23.14170
57.66382	121.2895	22.98059
57.71717	120.2154	22.80434
57.76716	119.2093	22.61290
57.82050	118.1298	22.20928
57.87050	117.1150	21.97477
57.92217	116.0690	21.78545
57.97382	115.0259	21.61423
58.02550	113.9850	21.48266
58.07717	112.9459	21.33773
58.12883	111.9076	21.21506
58.18050	110.8695	21.07573
58.23217	109.8319	20.93677
58.28383	108.7926	20.76161
58.33383	107.7881	20.65336
58.38716	106.7192	20.57232
58.43716	105.7157	20.45174
58.49050	104.6478	20.38433
58.54050	103.6457	20.32057
58.59384	102.5776	20.23133
58.64384	101.5783	20.15841
58.69717	100.5105	20.06587
58.74717	99.51134	20.00601
58.80050	98.44449	19.93084
58.85050	97.44462	19.87022
58.90383	96.37699	19.81099
58.95383	95.37809	19.73641
59.00550	94.34570	19.67725
59.05717	93.31332	19.61367
59.10883	92.28106	19.56444
59.16050	91.24889	19.50688
59.21216	90.21632	19.43910
59.26382	89.18475	19.39242
59.31550	88.15144	19.34554
59.36716	87.11944	19.30647
59.41716	86.11938	19.24868
59.47050	85.05363	19.19248
59.52050	84.05476	19.13924
59.57383	82.98710	19.06932
59.62383	81.98798	19.01275
59.67717	80.92141	18.95525
59.72717	79.92231	18.89921
59.78050	78.85582	18.84513
59.83050	77.85702	18.79097
59.88383	76.79124	18.73713
59.93383	75.79356	18.69335
59.98717	74.72786	18.64623
60.03716	73.73050	18.60509
60.08882	72.69825	18.56143
60.14050	71.66755	18.51739
60.19216	70.63457	18.47343
60.24382	69.60205	18.42858
60.29550	68.57007	18.37602
60.34716	67.53744	18.32827
60.39883	66.50619	18.28134
60.45050	65.47360	18.23966
60.50050	64.47578	18.19452
60.55383	63.41011	18.14142
60.60383	62.41070	18.08747
60.65717	61.34542	18.03348
60.70717	60.34638	17.98250
60.76050	59.28066	17.93519
60.81050	58.28188	17.88573
60.86382	57.21477	17.83215
60.91382	56.21742	17.78580
60.96717	55.15192	17.74082
61.01716	54.15255	17.68877
61.07050	53.08650	17.63525
61.12050	52.08728	17.58446
61.17217	51.05528	17.52899
61.22382	50.02306	17.47742
61.27550	48.99124	17.43226
61.32717	47.95854	17.38452
61.37883	46.92554	17.33520
61.43050	45.89216	17.28190
61.48217	44.85941	17.22870
61.53383	43.82547	17.17386
61.58383	42.82658	17.10582
61.63716	41.75870	17.01854
61.68716	40.75844	16.90816
61.74050	39.69050	16.82354
61.79050	38.68834	16.74948
61.84384	37.61929	16.64720
61.89384	36.61758	16.57114
61.94717	35.54916	16.48416
61.99717	34.54772	16.40251
62.05050	33.47770	16.31909
62.10050	32.47680	16.22505
62.15383	31.40576	16.12988
62.20383	30.40556	16.04428
62.25550	29.36805	15.97307
62.30717	28.33356	15.87701
62.35883	27.29773	15.78660
62.41050	26.26050	15.68258
62.46216	25.22344	15.63476
62.51050	24.25416	15.64516
62.56050	23.38186	15.71614
62.61382	23.11014	13.28100
62.66382	23.16388	9.313738
62.71717	23.44936	4.966967
62.76716	23.86802	1.373198
62.82050	24.43950	-1.850796
62.87050	25.06846	-4.319621
62.92217	25.78836	-6.403012
62.97382	26.56786	-8.079804
63.02550	27.39216	-9.441891
63.07717	28.25381	-10.55007
63.12883	29.14375	-11.45358
63.18050	30.05842	-12.18580
63.23217	30.99135	-12.79143
63.28383	31.93873	-13.29866
63.33383	32.86618	-13.70964
63.38716	33.86594	-14.08038
63.43716	34.81296	-14.37742
63.49050	35.82843	-14.64430
63.54050	36.78638	-14.87240
63.59384	37.81271	-15.07482
63.64384	38.77893	-15.23389
63.69717	39.81500	-15.40169
63.74717	40.78609	-15.52977
63.80050	41.82589	-15.66304
63.85050	42.80261	-15.77281
63.90383	43.84652	-15.88350
63.95383	44.82685	-15.97681
64.00550	45.84235	-16.05456
64.05717	46.85981	-16.13251
64.10884	47.87806	-16.21785
64.16050	48.89654	-16.30284
64.21217	49.91769	-16.38651
64.26384	50.93792	-16.47222
64.31550	51.95908	-16.55625
64.36718	52.98075	-16.63854
64.41717	53.96946	-16.71759
64.47050	55.02504	-16.80287
64.52050	56.01484	-16.88342
64.57384	57.07109	-16.96796
64.62383	58.06290	-17.05135
64.67718	59.11950	-17.13547
64.72718	60.11105	-17.21844
64.78050	61.16936	-17.30691
64.83050	62.16150	-17.38606
64.88384	63.21948	-17.47469
64.93384	64.21254	-17.54592
64.98717	65.27289	-17.62664
65.03717	66.26566	-17.70426
65.08884	67.29286	-17.78540
65.14050	68.31906	-17.86311
65.19217	69.34595	-17.94705
65.24384	70.37295	-18.02509
65.29550	71.40040	-18.11389
65.34717	72.42806	-18.19194
65.39883	73.45502	-18.27670
65.45050	74.48366	-18.36400
65.50050	75.47794	-18.44193
65.55384	76.53882	-18.52876
65.60384	77.53328	-18.61410
65.65718	78.59446	-18.70933
65.70718	79.58922	-18.79597
65.76050	80.65082	-18.88933
65.81050	81.64554	-18.97792
65.86384	82.70686	-19.07086
65.91382	83.70094	-19.15812
65.96718	84.76155	-19.26173
66.01716	85.75578	-19.36037
66.07050	86.81484	-19.47182
66.12050	87.80946	-19.57900
66.17218	88.83674	-19.68913
66.22384	89.86353	-19.80694
66.27550	90.89194	-19.91817
66.32718	91.91876	-20.02765
66.37884	92.94681	-20.14516
66.43050	93.97344	-20.24866
66.48218	95.00101	-20.36827
66.53384	96.02899	-20.48494
66.58384	97.02166	-20.59484
66.63718	98.08026	-20.72471
66.68718	99.07418	-20.84752
66.74050	100.1308	-20.97914
66.79050	101.1241	-21.11820
66.84384	102.1830	-21.25918
66.89384	103.1761	-21.38619
66.94718	104.2352	-21.53259
66.99718	105.2286	-21.59830
67.05050	106.2926	-21.60811
67.10050	107.2909	-21.67507
67.15384	108.3539	-21.75785
67.20384	109.3497	-21.85347
67.25550	110.3790	-21.96150
67.30718	111.4068	-22.05359
67.35884	112.4366	-22.16115
67.41050	113.4652	-22.25635
67.46218	114.4942	-22.35496
67.51384	115.5220	-22.47110
67.56550	116.5494	-22.57444
67.61718	117.5798	-22.59572
67.66718	118.5845	-22.47129
67.72050	119.6588	-22.35985
67.77050	120.6637	-22.34154
67.82384	121.7341	-22.33869
67.87384	122.7359	-22.33896
67.92718	123.8034	-22.34308
67.97718	124.8037	-22.36183
68.03050	125.8709	-22.40053
68.08050	126.8709	-22.45231
68.13384	127.9372	-22.51950
68.18384	128.9352	-22.58476
68.23718	130.0001	-22.65926
68.28718	130.9961	-22.74129
68.33884	132.0270	-22.81570
68.39050	133.0578	-22.89702
68.44218	134.0872	-22.98004
68.49384	135.1178	-23.07132
68.54550	136.1476	-23.15316
68.59718	137.1770	-23.24645
68.64884	138.2062	-23.34111
68.70050	139.2356	-23.43286
68.75050	140.2325	-23.53066
68.80384	141.2936	-23.62485
68.85384	142.2894	-23.72235
68.90718	143.3514	-23.82102
68.95718	144.3472	-23.92418
69.01050	145.4084	-24.02040
69.06050	146.4039	-24.11972
69.11384	147.4669	-24.22316
69.16382	148.4608	-24.32284
69.21718	149.5226	-24.42994
69.26716	150.5184	-24.52284
69.32050	151.5796	-24.62600
69.37050	152.5741	-24.73516
69.42218	153.6034	-24.84336
69.47384	154.6307	-24.94775
69.52550	155.6587	-25.05581
69.57718	156.6874	-25.15861
69.62884	157.7162	-25.25643
69.68050	158.7455	-25.33352
69.73218	159.7756	-25.40086
69.78384	160.8056	-25.45816
69.83384	161.8055	-25.49719
69.88718	162.8698	-25.52496
69.93718	163.8690	-25.54712
69.99050	164.9352	-25.57199
70.04050	165.9347	-25.60129
70.09384	166.9990	-25.64885
70.14384	167.9978	-25.71168
70.19718	169.0621	-25.78895
70.24718	170.0594	-25.88336
70.30050	171.1222	-25.99266
70.35050	172.1195	-26.10850
70.40384	173.1805	-26.23777
70.45384	174.1756	-26.36906
70.50550	175.2023	-26.50829
70.55718	176.2281	-26.67606
70.60884	177.2530	-26.85634
70.66050	178.2762	-27.06959
70.71218	179.2983	-27.29247
70.76384	180.3179	-27.54728
70.81550	181.3371	-27.83171
70.86718	182.3547	-28.13572
70.91718	183.3390	-28.46228
70.97050	184.3855	-28.84022
71.02050	185.3657	-29.24701
71.07384	186.4084	-29.70737
71.12384	187.3836	-30.17474
71.17718	188.4214	-30.71705
71.22718	189.3915	-31.27639
71.28050	190.4238	-31.91000
71.33050	191.3893	-32.53975
71.38384	192.4188	-33.22204
71.43384	193.3802	-33.88272
71.48718	194.4055	-34.61588
71.53718	195.3646	-35.34880
71.58884	196.3539	-36.15234
71.64050	197.3409	-37.00403
71.69218	198.3226	-37.92986
71.74384	199.3019	-38.94529
71.79550	200.2764	-40.02238
71.84718	201.2463	-41.16034
71.89884	202.2134	-42.34119
71.95050	203.1804	-43.50034
72.00050	204.1145	-44.56883
72.05384	205.1165	-45.55550
72.10384	206.0625	-46.22037
72.15718	207.0904	-46.38310
72.20718	208.0826	-45.85587
72.26050	209.1911	-43.90265
72.31050	210.2806	-41.41152
72.36384	211.4832	-38.61890
72.41382	212.6264	-36.19068
72.46718	213.8421	-34.05072
72.51716	214.9644	-32.51016
72.57050	216.1410	-31.23429
72.62050	217.2242	-30.28380
72.67218	218.3273	-29.50485
72.72384	219.4154	-28.87167
72.77550	220.4944	-28.38391
72.82718	221.5632	-27.99326
72.87884	222.6250	-27.68964
72.93050	223.6817	-27.44214
72.98218	224.7332	-27.24487
73.03384	225.7813	-27.11435
73.08384	226.7918	-27.00285
73.13718	227.8674	-26.92400
73.18718	228.8740	-26.87789
73.24050	229.9463	-26.85110
73.29050	230.9506	-26.83270
73.34384	232.0200	-26.82700
73.39384	233.0228	-26.82571
73.44718	234.0908	-26.82494
73.49718	235.0923	-26.82501
73.55050	236.1596	-26.82598
73.60050	237.1598	-26.82876
73.65384	238.2258	-26.83692
73.70384	239.2240	-26.85580
73.75550	240.2569	-26.88474
73.80718	241.2886	-26.92863
73.85884	242.3222	-26.97869
73.91050	243.3546	-27.02563
73.96218	244.3873	-27.06562
74.01384	245.4203	-27.10451
74.06550	246.4524	-27.14286
74.11718	247.4837	-27.17523
74.16718	248.4826	-27.20920
74.22050	249.5472	-27.25066
74.27050	250.5470	-27.28978
74.32384	251.6130	-27.33602
74.37384	252.6116	-27.37398
74.42718	253.6785	-27.41220
74.47718	254.6763	-27.44604
74.53050	255.7416	-27.49532
74.58050	256.7401	-27.54115
74.63384	257.8050	-27.58660
74.68384	258.8016	-27.63836
74.73718	259.8668	-27.70175
74.78718	260.8639	-27.75810
74.83884	261.8945	-27.81196
74.89050	262.9263	-27.87474
74.94218	263.9579	-27.93432
74.99384	264.9883	-27.98742
75.04550	266.0213	-28.04612
75.09718	267.0517	-28.11138
75.14884	268.0826	-28.18015
75.20050	269.1139	-28.21912
75.25050	270.1119	-28.26144
75.30384	271.1763	-28.31401
-2.000000	5.000000	0.0000000