File: 9-C1(1.2mol%)+C20(1.0mol%)/matlab/150-2.txt
CLOSED
Version	1.0
Language	English
Mode	Standard
Run	6
RunSerial	12274
Instrument	DSC Q2000 V24.11 Build 124
Module	DSC Standard Cell RC
Operator
File	\\AE520-1454\Users\dsc\Desktop\Data\29-08-17\150-2.001
ProcName
InstSerial	2000-0883
AutoSerial	1293
Sample	150-2
Size	29.4000	mg
PanMass	Not available
PanResist	Automatic Automatic  K/W
PanFactor	Default Default
Method
Comment
Xcomment	Pan: Tzero Aluminum Hermetic
Xcomment	Gas1: Nitrogen 50.0 ml/min
Xcomment	Gas2: Nitrogen 50.0 ml/min
Text
Exotherm	UP
Kcell	1.05230
Cpconst	Standard: 0.938
Calib	-38.6961
TempCal	1	pts	157.46	156.60
TzeroDt	-87.6168 -0.0009 -1.4231
TzeroDtz	-87.6168 0.0057 6.9570
InstCalFile	Tzero: \\Ae520-1454\ta\Data\DSC\Calibration\2017\CALIBRATION\1562_RCS (90)_05_18_2017 10_50_44.TZR
InstCalFile	Baseline: \\Ae520-1454\ta\Data\DSC\Calibration\2017\2017-05-17_Calibration.001
InstCalFile	Sapphire: \\Ae520-1454\ta\Data\DSC\Calibration\2017\2017-05-17_Saphire.001
InstCalDate	Tzero 2017-05-18 Time 10:50:44
TempRange	-87.39 to 398.39 °C at 10.00 °C/min Heat Only
AutoZero	Delta T Offset 0.000 uV
AutoZero	Delta T0 Offset 0.000 uV
MultiptCal	0
MultiPtDesc	0) Not set
AutoCellConst	Calibration Date 2017-05-18 16:59:28
Controls	Gas 1  Event Off  Sampling 0.2
Cell#	RC-01562
CoolingUnit	RCS (90)
SelHeatFlow	Heat Flow T4P (mW)
AutoLidII	Installed
AutoAnalysis	Off
MacroFile
Nsig	3
Sig1	Time (min)
Sig2	Temperature (°C)
Sig3	Heat Flow (mW)
Date	2017-08-29
Time	18:10:25
OrgMethod	1: Equilibrate at 80.00 °C
OrgMethod	2: Isothermal for 3.00 min
OrgMethod	3: Jump to 150.00 °C
OrgMethod	4: Mark end of cycle 1
OrgMethod	5: Isothermal for 40.00 min
OrgMethod	6: Mark end of cycle 2
OrgMethod	7: Ramp 20.00 °C/min to 280.00 °C
OrgMethod	8: Mark end of cycle 3
OrgMethod	9: Ramp 20.00 °C/min to 20.00 °C
OrgMethod	10: Mark end of cycle 4
OrgMethod	11: Ramp 20.00 °C/min to 280.00 °C
OrgMethod	12: Mark end of cycle 5
OrgFile	C:\Users\jarra\Desktop\DSC\9-C1(1.2mol%)+C20(1.0mol%)\150-2.001
StartOfData
4.99994E-4	79.64076	-4.423521
0.05383332	79.70081	-3.615958
0.1038333	79.74460	-3.013652
0.1571666	79.78085	-2.499974
0.2071666	79.80939	-2.120455
0.2605000	79.83206	-1.797830
0.3105000	79.85025	-1.560840
0.3638334	79.86362	-1.356965
0.4138333	79.87364	-1.207054
0.4671667	79.88180	-1.084240
0.5171667	79.88750	-0.9915600
0.5705000	79.89232	-0.9153332
0.6205000	79.89651	-0.8623649
0.6721668	79.89962	-0.8192325
0.7238332	79.90124	-0.7855704
0.7755000	79.90265	-0.7619910
0.8271668	79.90276	-0.7448803
0.8788332	79.90358	-0.7331287
0.9305000	79.90418	-0.7251850
0.9821668	79.90396	-0.7198247
1.033833	79.90371	-0.7158850
1.083833	79.90339	-0.7122470
1.137166	79.90332	-0.7083501
1.187166	79.90191	-0.7047124
1.240500	79.90126	-0.7009005
1.290500	79.90089	-0.6974918
1.343833	79.89998	-0.6939871
1.393833	79.89970	-0.6908450
1.447166	79.89924	-0.6877194
1.497166	79.89838	-0.6849547
1.550500	79.89761	-0.6822510
1.600500	79.89714	-0.6799387
1.653833	79.89688	-0.6776618
1.703833	79.89556	-0.6757318
1.755500	79.89588	-0.6740103
1.807167	79.89444	-0.6724452
1.858834	79.89344	-0.6710082
1.910500	79.89280	-0.6697860
1.962166	79.89253	-0.6687036
2.013833	79.89284	-0.6678064
2.065500	79.89181	-0.6670666
2.117167	79.89161	-0.6664240
2.167167	79.89114	-0.6658891
2.220500	79.88985	-0.6654457
2.270500	79.88910	-0.6651795
2.323833	79.88805	-0.6650300
2.373834	79.88813	-0.6650056
2.427167	79.88762	-0.6650116
2.477167	79.88626	-0.6651192
2.530500	79.88616	-0.6653380
2.580500	79.88547	-0.6656070
2.633833	79.88504	-0.6659082
2.683833	79.88484	-0.6663356
2.737167	79.88416	-0.6667844
2.787167	79.88262	-0.6672698
2.838833	79.88303	-0.6678551
2.890500	79.88189	-0.6685188
2.942167	79.88189	-0.6692544
2.993833	79.88197	-0.6700401
3.040500	80.15844	-1.302670
3.093834	82.56861	-6.984124
3.143833	85.43511	-14.56171
3.197167	88.85569	-23.54654
3.247166	92.35492	-31.78619
3.300500	96.32836	-39.85532
3.350500	100.2278	-46.54304
3.403833	104.5317	-52.68888
3.453833	108.6704	-57.57011
3.505500	113.0271	-61.76384
3.557167	117.4405	-65.24175
3.608833	121.8926	-68.17851
3.660500	126.3721	-70.56762
3.712167	130.8664	-72.55274
3.763833	135.2220	-73.82388
3.815500	138.1396	-71.67813
3.867166	140.0670	-65.35033
3.917167	141.5800	-57.63788
3.970500	142.8734	-49.04011
4.020500	143.8733	-41.50582
4.073834	144.7526	-34.42612
4.123833	145.4376	-28.77040
4.177166	146.0480	-23.74735
4.227167	146.5286	-19.86922
4.280500	146.9606	-16.50428
4.330500	147.3045	-13.93899
4.383834	147.6161	-11.72325
4.433834	147.8656	-10.03844
4.487167	148.0937	-8.585178
4.537167	148.2800	-7.477121
4.588834	148.4445	-6.540246
4.640500	148.5886	-5.771976
4.692166	148.7128	-5.134431
4.743834	148.8224	-4.611282
4.795500	148.9182	-4.175186
4.847166	149.0017	-3.809094
4.898834	149.0752	-3.505262
4.950500	149.1405	-3.249444
5.000500	149.1968	-3.037068
5.053834	149.2493	-2.842314
5.103833	149.2943	-2.686317
5.157166	149.3361	-2.542917
5.207167	149.3723	-2.422439
5.260500	149.4051	-2.313070
5.310500	149.4334	-2.219454
5.363834	149.4610	-2.130021
5.413832	149.4852	-2.054651
5.467168	149.5068	-1.978248
5.517168	149.5266	-1.913016
5.570500	149.5451	-1.848761
5.620500	149.5606	-1.792750
5.672168	149.5764	-1.738194
5.723834	149.5898	-1.686971
5.775500	149.6034	-1.637314
5.827168	149.6142	-1.588603
5.878834	149.6262	-1.540329
5.930500	149.6362	-1.490824
5.982168	149.6465	-1.442499
6.033832	149.6560	-1.393224
6.083832	149.6638	-1.346671
6.137168	149.6734	-1.293383
6.187168	149.6796	-1.245517
6.240500	149.6882	-1.194344
6.290500	149.6953	-1.146354
6.343834	149.7024	-1.092925
6.393832	149.7089	-1.040533
6.447168	149.7154	-0.9845626
6.497168	149.7218	-0.9308570
6.550500	149.7281	-0.8713431
6.600500	149.7349	-0.8165850
6.653832	149.7404	-0.7542884
6.703832	149.7465	-0.6953806
6.755500	149.7528	-0.6352559
6.807166	149.7583	-0.5691032
6.858832	149.7645	-0.5031672
6.910500	149.7705	-0.4369633
6.962168	149.7764	-0.3692722
7.013834	149.7818	-0.2990575
7.065500	149.7879	-0.2269134
7.117166	149.7944	-0.1537086
7.167168	149.8005	-.08123059
7.220500	149.8064	4.30213E-4
7.270500	149.8128	0.07707129
7.323834	149.8191	0.1601492
7.373834	149.8258	0.2420728
7.427168	149.8320	0.3292014
7.477168	149.8378	0.4135857
7.530500	149.8454	0.5049574
7.580500	149.8525	0.5958832
7.633832	149.8586	0.6936892
7.683832	149.8653	0.7863446
7.737168	149.8737	0.8872593
7.787168	149.8792	0.9842212
7.838834	149.8874	1.085542
7.890500	149.8939	1.192262
7.942168	149.9022	1.297043
7.993834	149.9098	1.406447
8.045500	149.9176	1.517950
8.097168	149.9262	1.635658
8.148834	149.9338	1.748048
8.200500	149.9418	1.863690
8.250500	149.9501	1.977335
8.303832	149.9589	2.102742
8.353832	149.9669	2.227486
8.407166	149.9769	2.364803
8.457168	149.9856	2.511139
8.510499	149.9972	2.681972
8.560500	150.0099	2.880039
8.613834	150.0266	3.140273
8.663834	150.0452	3.442053
8.717168	150.0706	3.838309
8.767168	150.0983	4.280742
8.820500	150.1336	4.818504
8.870499	150.1698	5.368676
8.922168	150.2086	5.959070
8.973832	150.2479	6.549704
9.025499	150.2868	7.121020
9.077168	150.3231	7.667230
9.128834	150.3584	8.174912
9.180500	150.3905	8.644266
9.232166	150.4198	9.073884
9.283832	150.4468	9.460094
9.333832	150.4699	9.794046
9.387168	150.4925	10.11002
9.437166	150.5102	10.36856
9.490500	150.5264	10.60098
9.540500	150.5398	10.78124
9.593832	150.5508	10.93139
9.643832	150.5592	11.03268
9.697168	150.5648	11.10602
9.747168	150.5680	11.14076
9.800500	150.5682	11.14951
9.850500	150.5674	11.14861
9.903832	150.5638	11.13505
9.953834	150.5591	11.05416
10.00550	150.5522	10.91646
10.05717	150.5444	10.77500
10.10883	150.5361	10.63403
10.16050	150.5271	10.48554
10.21217	150.5174	10.33765
10.26383	150.5073	10.18635
10.31550	150.4975	10.03489
10.36717	150.4877	9.886562
10.41717	150.4786	9.744005
10.47050	150.4694	9.599631
10.52050	150.4601	9.468818
10.57383	150.4515	9.334913
10.62383	150.4442	9.215331
10.67717	150.4353	9.097489
10.72717	150.4285	8.991584
10.78050	150.4213	8.886124
10.83050	150.4151	8.791788
10.88383	150.4081	8.697282
10.93383	150.4026	8.614458
10.98717	150.3965	8.531837
11.03717	150.3917	8.458007
11.08883	150.3868	8.389605
11.14050	150.3833	8.324715
11.19217	150.3792	8.265174
11.24384	150.3757	8.211598
11.29550	150.3717	8.164501
11.34717	150.3687	8.123199
11.39883	150.3660	8.087843
11.45050	150.3645	8.059259
11.50050	150.3625	8.039239
11.55383	150.3606	8.024650
11.60383	150.3614	8.016624
11.65717	150.3604	8.012930
11.70717	150.3604	8.009930
11.76050	150.3614	8.007553
11.81050	150.3639	8.006347
11.86383	150.3644	8.008697
11.91383	150.3668	8.023676
11.96717	150.3706	8.067872
12.01717	150.3760	8.135858
12.07050	150.3808	8.232989
12.12050	150.3862	8.337559
12.17217	150.3941	8.457781
12.22383	150.4024	8.597446
12.27550	150.4119	8.755676
12.32717	150.4238	8.933175
12.37884	150.4358	9.134766
12.43050	150.4501	9.352272
12.48217	150.4646	9.583805
12.53383	150.4802	9.810712
12.58383	150.4949	10.03029
12.63717	150.5099	10.24102
12.68716	150.5215	10.39531
12.74050	150.5302	10.52296
12.79050	150.5367	10.59755
12.84383	150.5397	10.62417
12.89383	150.5395	10.62043
12.94717	150.5341	10.60807
12.99717	150.5251	10.44552
13.05050	150.5134	10.21378
13.10050	150.5004	9.984606
13.15383	150.4828	9.721134
13.20383	150.4657	9.449218
13.25550	150.4470	9.158113
13.30717	150.4282	8.853445
13.35883	150.4067	8.552715
13.41050	150.3861	8.243950
13.46217	150.3663	7.939274
13.51383	150.3471	7.641876
13.56550	150.3264	7.351663
13.61716	150.3073	7.058392
13.66716	150.2896	6.785235
13.72050	150.2704	6.503880
13.77050	150.2533	6.241010
13.82384	150.2347	5.971268
13.87384	150.2183	5.719055
13.92717	150.2007	5.458486
13.97717	150.1850	5.217700
14.03050	150.1680	4.964557
14.08050	150.1515	4.729390
14.13383	150.1357	4.481278
14.18383	150.1204	4.249661
14.23716	150.1044	4.005840
14.28717	150.0888	3.776851
14.33883	150.0737	3.540335
14.39050	150.0574	3.314696
14.44217	150.0428	3.084415
14.49384	150.0271	2.854016
14.54550	150.0126	2.629642
14.59717	149.9974	2.410744
14.64883	149.9832	2.190237
14.70050	149.9677	1.978345
14.75050	149.9541	1.775200
14.80383	149.9401	1.565568
14.85383	149.9280	1.373267
14.90717	149.9142	1.174575
14.95717	149.9031	0.9971391
15.01050	149.8908	0.8148444
15.06050	149.8788	0.6534668
15.11383	149.8683	0.4868576
15.16383	149.8579	0.3358470
15.21716	149.8479	0.1860048
15.26717	149.8380	0.05426574
15.32050	149.8301	-.08088692
15.37050	149.8217	-0.1987933
15.42217	149.8138	-0.3145757
15.47383	149.8064	-0.4222706
15.52550	149.7992	-0.5236213
15.57717	149.7925	-0.6175800
15.62883	149.7870	-0.7058821
15.68050	149.7811	-0.7867962
15.73216	149.7764	-0.8626358
15.78383	149.7708	-0.9324157
15.83383	149.7666	-0.9961305
15.88716	149.7627	-1.058818
15.93717	149.7589	-1.112210
15.99050	149.7542	-1.165179
16.04050	149.7510	-1.213352
16.09383	149.7482	-1.260238
16.14383	149.7455	-1.300352
16.19717	149.7416	-1.340426
16.24716	149.7388	-1.373218
16.30050	149.7366	-1.407684
16.35050	149.7354	-1.437383
16.40383	149.7323	-1.466068
16.45383	149.7313	-1.490202
16.50550	149.7289	-1.512034
16.55716	149.7276	-1.531538
16.60883	149.7269	-1.547460
16.66050	149.7266	-1.552391
16.71216	149.7243	-1.565376
16.76383	149.7230	-1.585186
16.81550	149.7214	-1.605783
16.86716	149.7192	-1.624678
16.91716	149.7189	-1.641605
16.97050	149.7177	-1.657485
17.02050	149.7162	-1.669583
17.07383	149.7151	-1.681758
17.12383	149.7151	-1.692438
17.17716	149.7134	-1.701736
17.22716	149.7120	-1.709303
17.28050	149.7116	-1.717749
17.33050	149.7110	-1.725490
17.38383	149.7104	-1.733611
17.43383	149.7098	-1.741331
17.48716	149.7088	-1.749628
17.53717	149.7089	-1.757477
17.58883	149.7081	-1.765685
17.64050	149.7072	-1.773950
17.69216	149.7068	-1.782194
17.74383	149.7068	-1.790417
17.79550	149.7058	-1.798620
17.84716	149.7053	-1.806761
17.89883	149.7052	-1.814902
17.95050	149.7044	-1.822884
18.00050	149.7036	-1.830592
18.05383	149.7036	-1.838733
18.10383	149.7034	-1.846327
18.15716	149.7024	-1.854318
18.20716	149.7021	-1.861753
18.26050	149.7018	-1.869555
18.31050	149.7017	-1.876739
18.36383	149.7004	-1.884303
18.41383	149.7004	-1.891345
18.46716	149.6992	-1.898739
18.51716	149.6999	-1.905616
18.57050	149.6999	-1.912804
18.62050	149.6989	-1.919422
18.67216	149.6989	-1.926167
18.72383	149.6986	-1.932785
18.77550	149.6983	-1.939267
18.82716	149.6989	-1.945628
18.87883	149.6983	-1.951874
18.93050	149.6974	-1.957945
18.98216	149.6982	-1.963986
19.03383	149.6969	-1.969896
19.08383	149.6970	-1.975457
19.13716	149.6968	-1.981297
19.18716	149.6971	-1.986668
19.24050	149.6961	-1.992238
19.29050	149.6958	-1.997341
19.34383	149.6954	-2.002656
19.39383	149.6957	-2.007523
19.44716	149.6958	-2.012581
19.49716	149.6946	-2.017228
19.55050	149.6948	-2.022030
19.60050	149.6955	-2.026448
19.65383	149.6952	-2.031012
19.70383	149.6940	-2.035202
19.75550	149.6944	-2.039450
19.80716	149.6940	-2.043616
19.85883	149.6942	-2.047685
19.91050	149.6942	-2.051637
19.96216	149.6942	-2.055459
20.01383	149.6942	-2.059215
20.06550	149.6940	-2.062875
20.11716	149.6933	-2.066454
20.16716	149.6932	-2.069859
20.22050	149.6937	-2.073422
20.27050	149.6932	-2.076684
20.32383	149.6930	-2.080020
20.37383	149.6931	-2.083088
20.42716	149.6924	-2.086215
20.47716	149.6930	-2.089149
20.53050	149.6928	-2.092173
20.58050	149.6920	-2.094961
20.63383	149.6926	-2.097883
20.68383	149.6926	-2.100570
20.73716	149.6919	-2.103375
20.78717	149.6925	-2.105945
20.83883	149.6921	-2.108540
20.89050	149.6923	-2.111064
20.94216	149.6920	-2.113513
20.99383	149.6921	-2.115879
21.04550	149.6916	-2.118217
21.09716	149.6918	-2.120520
21.14883	149.6919	-2.122764
21.20050	149.6914	-2.124936
21.25050	149.6915	-2.127016
21.30383	149.6914	-2.129214
21.35383	149.6916	-2.131240
21.40716	149.6906	-2.133293
21.45717	149.6916	-2.135272
21.51050	149.6908	-2.137351
21.56050	149.6907	-2.139250
21.61383	149.6905	-2.141230
21.66383	149.6908	-2.143061
21.71716	149.6910	-2.144973
21.76716	149.6907	-2.146718
21.82050	149.6909	-2.148508
21.87050	149.6901	-2.150138
21.92216	149.6902	-2.151886
21.97383	149.6898	-2.153590
22.02550	149.6898	-2.155275
22.07716	149.6899	-2.156950
22.12883	149.6908	-2.158647
22.18050	149.6897	-2.160288
22.23216	149.6898	-2.161925
22.28383	149.6900	-2.163556
22.33383	149.6898	-2.165092
22.38716	149.6898	-2.166734
22.43716	149.6894	-2.168249
22.49050	149.6894	-2.169840
22.54050	149.6900	-2.171325
22.59383	149.6896	-2.172886
22.64383	149.6889	-2.174316
22.69716	149.6894	-2.175870
22.74716	149.6902	-2.177300
22.80050	149.6891	-2.178852
22.85050	149.6896	-2.180210
22.90383	149.6892	-2.181625
22.95383	149.6894	-2.182962
23.00550	149.6886	-2.184307
23.05716	149.6890	-2.185660
23.10883	149.6890	-2.187010
23.16050	149.6892	-2.188272
23.21216	149.6892	-2.189535
23.26383	149.6878	-2.190674
23.31550	149.6881	-2.191869
23.36716	149.6891	-2.192980
23.41716	149.6892	-2.194087
23.47050	149.6888	-2.195226
23.52050	149.6880	-2.196244
23.57383	149.6885	-2.197388
23.62383	149.6879	-2.198416
23.67717	149.6887	-2.199455
23.72716	149.6882	-2.200424
23.78050	149.6880	-2.201428
23.83050	149.6872	-2.202386
23.88383	149.6877	-2.203385
23.93383	149.6872	-2.204300
23.98716	149.6882	-2.205246
24.03717	149.6879	-2.206095
24.08883	149.6874	-2.206931
24.14050	149.6873	-2.207764
24.19216	149.6874	-2.208611
24.24383	149.6875	-2.209434
24.29550	149.6876	-2.210216
24.34716	149.6869	-2.210997
24.39883	149.6879	-2.211816
24.45050	149.6875	-2.212578
24.50050	149.6868	-2.213263
24.55383	149.6872	-2.214039
24.60383	149.6880	-2.214751
24.65716	149.6878	-2.215486
24.70717	149.6874	-2.216154
24.76050	149.6875	-2.216866
24.81050	149.6875	-2.217520
24.86383	149.6873	-2.218231
24.91383	149.6888	-2.218915
24.96716	149.6879	-2.219606
25.01716	149.6872	-2.220249
25.07050	149.6875	-2.220914
25.12050	149.6878	-2.221526
25.17216	149.6882	-2.222112
25.22383	149.6878	-2.222667
25.27550	149.6878	-2.223206
25.32716	149.6870	-2.223722
25.37883	149.6881	-2.224204
25.43050	149.6874	-2.224670
25.48216	149.6869	-2.225140
25.53383	149.6884	-2.225644
25.58383	149.6874	-2.226134
25.63716	149.6880	-2.226636
25.68717	149.6872	-2.227100
25.74050	149.6877	-2.227617
25.79050	149.6874	-2.228065
25.84383	149.6873	-2.228592
25.89383	149.6873	-2.229023
25.94717	149.6869	-2.229480
25.99716	149.6870	-2.229835
26.05050	149.6873	-2.230262
26.10050	149.6871	-2.230664
26.15383	149.6868	-2.231058
26.20383	149.6883	-2.231495
26.25550	149.6868	-2.231967
26.30716	149.6868	-2.232408
26.35883	149.6878	-2.232858
26.41050	149.6880	-2.233278
26.46216	149.6873	-2.233637
26.51383	149.6880	-2.234047
26.56550	149.6878	-2.234443
26.61716	149.6876	-2.234806
26.66716	149.6871	-2.235194
26.72050	149.6874	-2.235536
26.77050	149.6873	-2.235916
26.82383	149.6876	-2.236267
26.87383	149.6875	-2.236600
26.92717	149.6875	-2.236955
26.97717	149.6874	-2.237214
27.03050	149.6877	-2.237582
27.08050	149.6877	-2.237902
27.13383	149.6880	-2.238221
27.18383	149.6879	-2.238515
27.23716	149.6876	-2.238756
27.28717	149.6876	-2.239034
27.33883	149.6867	-2.239252
27.39050	149.6870	-2.239492
27.44216	149.6872	-2.239695
27.49383	149.6870	-2.239912
27.54550	149.6873	-2.240070
27.59716	149.6866	-2.240260
27.64883	149.6869	-2.240492
27.70050	149.6872	-2.240720
27.75050	149.6868	-2.240875
27.80383	149.6871	-2.241066
27.85383	149.6865	-2.241242
27.90716	149.6872	-2.241423
27.95716	149.6868	-2.241627
28.01050	149.6864	-2.241806
28.06050	149.6873	-2.242045
28.11383	149.6873	-2.242281
28.16383	149.6866	-2.242482
28.21716	149.6869	-2.242670
28.26716	149.6874	-2.242918
28.32050	149.6866	-2.243187
28.37050	149.6872	-2.243454
28.42216	149.6863	-2.243686
28.47383	149.6869	-2.243896
28.52550	149.6864	-2.244089
28.57717	149.6872	-2.244302
28.62883	149.6871	-2.244451
28.68050	149.6870	-2.244702
28.73216	149.6866	-2.244900
28.78383	149.6868	-2.245104
28.83383	149.6867	-2.245268
28.88716	149.6864	-2.245479
28.93717	149.6860	-2.245664
28.99050	149.6865	-2.245870
29.04050	149.6872	-2.246053
29.09383	149.6870	-2.246275
29.14383	149.6864	-2.246418
29.19717	149.6868	-2.246574
29.24716	149.6865	-2.246726
29.30050	149.6866	-2.246925
29.35050	149.6864	-2.247128
29.40383	149.6866	-2.247380
29.45383	149.6866	-2.247602
29.50550	149.6862	-2.247806
29.55716	149.6870	-2.248018
29.60883	149.6866	-2.248202
29.66050	149.6875	-2.248377
29.71216	149.6866	-2.248517
29.76383	149.6866	-2.248658
29.81550	149.6864	-2.248775
29.86716	149.6868	-2.248964
29.91716	149.6867	-2.249166
29.97050	149.6866	-2.249385
30.02050	149.6867	-2.249612
30.07383	149.6871	-2.249833
30.12383	149.6867	-2.250056
30.17717	149.6866	-2.250279
30.22717	149.6866	-2.250506
30.28050	149.6873	-2.250752
30.33050	149.6865	-2.250995
30.38383	149.6866	-2.251189
30.43383	149.6873	-2.251377
30.48716	149.6869	-2.251511
30.53717	149.6868	-2.251670
30.58883	149.6861	-2.251762
30.64050	149.6863	-2.251860
30.69216	149.6871	-2.252044
30.74383	149.6866	-2.252230
30.79550	149.6870	-2.252416
30.84716	149.6862	-2.252545
30.89883	149.6879	-2.252684
30.95050	149.6861	-2.252772
31.00050	149.6871	-2.252927
31.05383	149.6862	-2.253098
31.10383	149.6866	-2.253273
31.15716	149.6864	-2.253457
31.20716	149.6878	-2.253630
31.26050	149.6860	-2.253773
31.31050	149.6865	-2.253940
31.36383	149.6867	-2.254098
31.41383	149.6868	-2.254258
31.46716	149.6871	-2.254434
31.51716	149.6869	-2.254579
31.57050	149.6864	-2.254698
31.62050	149.6868	-2.254840
31.67216	149.6861	-2.254950
31.72383	149.6874	-2.255049
31.77550	149.6868	-2.255095
31.82717	149.6861	-2.255092
31.87883	149.6867	-2.255168
31.93050	149.6871	-2.255280
31.98216	149.6864	-2.255333
32.03383	149.6864	-2.255369
32.08383	149.6862	-2.255394
32.13716	149.6856	-2.255428
32.18716	149.6869	-2.255468
32.24050	149.6860	-2.255507
32.29050	149.6861	-2.255497
32.34384	149.6856	-2.255537
32.39383	149.6865	-2.255619
32.44717	149.6856	-2.255684
32.49716	149.6872	-2.255788
32.55050	149.6861	-2.255884
32.60050	149.6868	-2.255964
32.65383	149.6871	-2.256070
32.70383	149.6858	-2.256163
32.75550	149.6868	-2.256322
32.80716	149.6864	-2.256479
32.85883	149.6859	-2.256638
32.91050	149.6869	-2.256791
32.96216	149.6869	-2.256957
33.01383	149.6865	-2.257053
33.06550	149.6869	-2.257176
33.11716	149.6864	-2.257300
33.16716	149.6874	-2.257420
33.22050	149.6868	-2.257497
33.27050	149.6858	-2.257586
33.32383	149.6865	-2.257672
33.37383	149.6864	-2.257713
33.42717	149.6866	-2.257766
33.47717	149.6857	-2.257832
33.53050	149.6860	-2.257892
33.58050	149.6861	-2.257990
33.63383	149.6874	-2.258101
33.68384	149.6865	-2.258205
33.73717	149.6870	-2.258324
33.78717	149.6866	-2.258383
33.83883	149.6868	-2.258467
33.89050	149.6870	-2.258573
33.94216	149.6864	-2.258632
33.99383	149.6867	-2.258738
34.04550	149.6866	-2.258827
34.09716	149.6864	-2.258904
34.14883	149.6865	-2.259012
34.20050	149.6867	-2.259075
34.25050	149.6874	-2.259148
34.30383	149.6864	-2.259218
34.35383	149.6864	-2.259309
34.40716	149.6867	-2.259411
34.45716	149.6858	-2.259485
34.51050	149.6865	-2.259578
34.56050	149.6861	-2.259688
34.61383	149.6872	-2.259778
34.66383	149.6865	-2.259862
34.71716	149.6863	-2.259949
34.76716	149.6869	-2.260030
34.82050	149.6865	-2.260105
34.87050	149.6862	-2.260169
34.92216	149.6860	-2.260205
34.97383	149.6864	-2.260262
35.02550	149.6859	-2.260289
35.07717	149.6854	-2.260281
35.12883	149.6861	-2.260308
35.18050	149.6863	-2.260324
35.23216	149.6864	-2.260335
35.28383	149.6864	-2.260358
35.33383	149.6858	-2.260404
35.38716	149.6859	-2.260402
35.43716	149.6860	-2.260468
35.49050	149.6861	-2.260479
35.54050	149.6852	-2.260501
35.59384	149.6872	-2.260567
35.64383	149.6859	-2.260598
35.69717	149.6862	-2.260659
35.74716	149.6866	-2.260740
35.80050	149.6857	-2.260791
35.85050	149.6859	-2.260862
35.90383	149.6865	-2.260960
35.95383	149.6857	-2.261060
36.00550	149.6866	-2.261142
36.05716	149.6859	-2.261186
36.10883	149.6862	-2.261280
36.16050	149.6864	-2.261384
36.21216	149.6858	-2.261435
36.26383	149.6864	-2.261475
36.31550	149.6865	-2.261528
36.36716	149.6862	-2.261574
36.41716	149.6862	-2.261627
36.47050	149.6862	-2.261689
36.52050	149.6860	-2.261770
36.57383	149.6858	-2.261847
36.62383	149.6871	-2.261924
36.67717	149.6861	-2.261933
36.72717	149.6857	-2.261946
36.78050	149.6864	-2.261981
36.83050	149.6858	-2.261985
36.88383	149.6859	-2.261982
36.93384	149.6866	-2.262037
36.98717	149.6863	-2.262070
37.03717	149.6864	-2.262097
37.08883	149.6861	-2.262134
37.14050	149.6860	-2.262116
37.19216	149.6865	-2.262113
37.24383	149.6872	-2.262094
37.29550	149.6859	-2.262096
37.34716	149.6862	-2.262130
37.39883	149.6862	-2.262218
37.45050	149.6863	-2.262292
37.50050	149.6859	-2.262323
37.55383	149.6858	-2.262344
37.60383	149.6852	-2.262424
37.65716	149.6858	-2.262461
37.70716	149.6859	-2.262484
37.76050	149.6866	-2.262493
37.81050	149.6865	-2.262488
37.86383	149.6860	-2.262478
37.91383	149.6867	-2.262516
37.96716	149.6862	-2.262596
38.01716	149.6857	-2.262605
38.07050	149.6855	-2.262596
38.12050	149.6857	-2.262636
38.17216	149.6866	-2.262702
38.22383	149.6866	-2.262769
38.27550	149.6856	-2.262808
38.32717	149.6866	-2.262911
38.37883	149.6862	-2.262958
38.43050	149.6871	-2.263066
38.48216	149.6861	-2.263125
38.53383	149.6859	-2.263210
38.58383	149.6863	-2.263235
38.63716	149.6863	-2.263272
38.68716	149.6859	-2.263318
38.74050	149.6857	-2.263338
38.79050	149.6861	-2.263398
38.84384	149.6864	-2.263477
38.89383	149.6860	-2.263537
38.94717	149.6869	-2.263648
38.99716	149.6867	-2.263735
39.05050	149.6864	-2.263795
39.10050	149.6864	-2.263876
39.15383	149.6865	-2.263925
39.20383	149.6859	-2.263978
39.25550	149.6864	-2.264029
39.30716	149.6865	-2.264045
39.35883	149.6868	-2.264119
39.41050	149.6868	-2.264198
39.46216	149.6864	-2.264234
39.51383	149.6869	-2.264266
39.56550	149.6870	-2.264333
39.61716	149.6861	-2.264353
39.66716	149.6870	-2.264380
39.72050	149.6874	-2.264438
39.77050	149.6865	-2.264456
39.82383	149.6869	-2.264466
39.87383	149.6869	-2.264452
39.92717	149.6869	-2.264391
39.97717	149.6860	-2.264402
40.03050	149.6868	-2.264355
40.08050	149.6870	-2.264404
40.13383	149.6860	-2.264439
40.18384	149.6861	-2.264460
40.23717	149.6867	-2.264466
40.28717	149.6866	-2.264471
40.33883	149.6869	-2.264467
40.39050	149.6859	-2.264480
40.44216	149.6865	-2.264555
40.49383	149.6864	-2.264553
40.54550	149.6868	-2.264618
40.59716	149.6861	-2.264710
40.64883	149.6860	-2.264738
40.70050	149.6866	-2.264797
40.75050	149.6867	-2.264828
40.80383	149.6864	-2.264864
40.85383	149.6871	-2.264922
40.90716	149.6855	-2.264966
40.95716	149.6866	-2.265026
41.01050	149.6858	-2.265127
41.06050	149.6860	-2.265178
41.11383	149.6862	-2.265242
41.16383	149.6864	-2.265306
41.21717	149.6862	-2.265421
41.26717	149.6866	-2.265532
41.32050	149.6871	-2.265629
41.37050	149.6858	-2.265668
41.42216	149.6862	-2.265744
41.47383	149.6858	-2.265795
41.52550	149.6858	-2.265861
41.57717	149.6863	-2.265890
41.62883	149.6858	-2.265916
41.68050	149.6859	-2.265936
41.73217	149.6863	-2.265979
41.78383	149.6856	-2.265999
41.83383	149.6860	-2.266054
41.88716	149.6856	-2.266103
41.93716	149.6858	-2.266131
41.99050	149.6856	-2.266146
42.04050	149.6869	-2.266201
42.09384	149.6866	-2.266245
42.14383	149.6862	-2.266294
42.19717	149.6866	-2.266353
42.24716	149.6861	-2.266352
42.30050	149.6861	-2.266383
42.35050	149.6865	-2.266420
42.40383	149.6856	-2.266410
42.45383	149.6860	-2.266430
42.50550	149.6862	-2.266471
42.55717	149.6858	-2.266525
42.60883	149.6862	-2.266602
42.66050	149.6864	-2.266660
42.71216	149.6861	-2.266734
42.76383	149.6867	-2.266750
42.81550	149.6865	-2.266786
42.86716	149.6868	-2.266781
42.91716	149.6866	-2.266777
42.97050	149.6861	-2.266767
43.01717	149.6866	-2.266880
43.07050	149.8157	-2.645637
43.12050	150.2663	-4.370992
43.17216	150.8674	-6.693676
43.22383	151.5631	-9.021048
43.27550	152.3263	-11.07002
43.32717	153.1402	-12.78614
43.37883	153.9944	-14.20900
43.43050	154.8810	-15.35708
43.48217	155.7918	-16.29260
43.53383	156.7243	-17.06148
43.58383	157.6417	-17.66975
43.63716	158.6341	-18.19337
43.68716	159.5756	-18.60599
43.74050	160.5884	-18.97781
43.79050	161.5447	-19.27669
43.84384	162.5704	-19.55012
43.89383	163.5371	-19.76844
43.94717	164.5702	-19.97889
43.99716	165.5441	-20.16104
44.05050	166.5844	-20.34581
44.10050	167.5625	-20.50092
44.15383	168.6063	-20.65865
44.20383	169.5882	-20.80255
44.25550	170.6028	-20.95990
44.30717	171.6198	-21.11237
44.35883	172.6368	-21.25548
44.41050	173.6553	-21.40434
44.46216	174.6736	-21.54742
44.51383	175.6940	-21.69081
44.56550	176.7144	-21.82802
44.61716	177.7345	-21.95902
44.66716	178.7234	-22.10998
44.72050	179.7765	-22.27276
44.77050	180.7654	-22.43232
44.82383	181.8186	-22.61844
44.87383	182.8071	-22.78230
44.92717	183.8612	-22.98326
44.97717	184.8490	-23.16602
45.03050	185.9030	-23.37598
45.08050	186.8894	-23.58247
45.13383	187.9426	-23.80892
45.18383	188.9278	-24.02648
45.23717	189.9801	-24.28808
45.28717	190.9651	-24.51601
45.33883	191.9828	-24.78312
45.39050	192.9991	-25.05987
45.44217	194.0161	-25.34260
45.49383	195.0326	-25.63020
45.54550	196.0465	-25.93361
45.59716	197.0612	-26.25862
45.64883	198.0760	-26.57764
45.70050	199.0878	-26.92507
45.75050	200.0670	-27.33094
45.80383	201.1092	-27.75336
45.85383	202.0858	-28.17694
45.90717	203.1251	-28.66334
45.95717	204.0990	-29.18025
46.01050	205.1322	-29.82512
46.06050	206.0967	-30.52650
46.11383	207.1186	-31.43032
46.16383	208.0682	-32.48178
46.21717	209.0687	-33.86601
46.26717	209.9930	-35.46097
46.32050	210.9606	-37.49131
46.37050	211.8520	-39.71709
46.42216	212.7547	-42.27022
46.47383	213.6419	-45.01940
46.52550	214.5177	-47.84126
46.57717	215.3924	-50.40396
46.62883	216.2778	-52.46697
46.68050	217.1770	-54.54193
46.73217	218.0793	-56.74505
46.78383	218.9877	-58.54014
46.83383	219.8955	-59.01134
46.88716	220.9550	-56.18799
46.93716	222.0880	-51.07211
46.99050	223.4278	-43.64588
47.04050	224.7508	-38.50152
47.09384	226.1122	-35.09125
47.14383	227.3310	-32.65598
47.19717	228.5814	-30.63938
47.24716	229.7167	-29.15867
47.30050	230.8960	-27.93952
47.35050	231.9798	-27.02770
47.40383	233.1161	-26.28634
47.45383	234.1667	-25.73072
47.50550	235.2413	-25.29672
47.55717	236.3081	-24.94667
47.60883	237.3660	-24.68154
47.66050	238.4187	-24.48161
47.71216	239.4670	-24.33478
47.76383	240.5117	-24.23610
47.81550	241.5540	-24.22876
47.86716	242.5933	-24.13290
47.91716	243.6005	-24.09638
47.97050	244.6634	-24.40201
48.02050	245.6672	-24.24537
48.07383	246.7384	-24.19711
48.12383	247.7395	-24.17767
48.17717	248.8082	-24.17011
48.22717	249.8093	-24.16584
48.28050	250.8774	-24.16231
48.33050	251.8770	-24.15989
48.38383	252.9440	-24.15812
48.43383	253.9438	-24.15877
48.48717	255.0104	-24.16353
48.53717	256.0100	-24.17781
48.58883	257.0438	-24.20104
48.64050	258.0754	-24.22322
48.69217	259.1079	-24.25472
48.74383	260.1404	-24.29138
48.79550	261.1714	-24.32451
48.84716	262.2040	-24.36745
48.89883	263.2358	-24.40870
48.95050	264.2675	-24.46241
49.00050	265.2663	-24.50322
49.05383	266.3318	-24.54684
49.10383	267.3307	-24.58242
49.15717	268.3958	-24.62020
49.20717	269.3935	-24.65574
49.26050	270.4584	-24.69192
49.31050	271.4579	-24.72224
49.36383	272.5232	-24.76400
49.41383	273.5217	-24.79701
49.46717	274.5875	-24.81552
49.51383	275.5194	-24.88266
49.56550	276.3083	-24.84790
49.61716	276.3671	-23.93714
49.66716	276.1531	-19.56058
49.72050	275.7337	-13.89815
49.77050	275.2217	-8.898569
49.82383	274.5747	-4.340744
49.87383	273.8956	-0.8271466
49.92717	273.1091	2.202470
49.97717	272.3265	4.460762
50.03050	271.4518	6.384609
50.08050	270.6023	7.819925
50.13383	269.6720	9.037210
50.18383	268.7804	9.947225
50.23717	267.8112	10.73670
50.28717	266.8898	11.32829
50.33883	265.9269	11.83011
50.39050	264.9545	12.23160
50.44217	263.9744	12.57681
50.49383	262.9864	12.84592
50.54550	261.9940	13.07364
50.59716	260.9971	13.26083
50.64883	259.9981	13.41559
50.70050	258.9938	13.55431
50.75050	258.0215	13.65704
50.80383	256.9804	13.76600
50.85383	256.0034	13.84437
50.90717	254.9587	13.93268
50.95717	253.9787	14.00158
51.01050	252.9295	14.06612
51.06050	251.9466	14.11422
51.11383	250.8953	14.16202
51.16383	249.9102	14.20468
51.21717	248.8582	14.24200
51.26716	247.8712	14.27669
51.32050	246.8180	14.31358
51.37050	245.8299	14.34346
51.42217	244.8075	14.36928
51.47383	243.7856	14.39058
51.52550	242.7632	14.40886
51.57717	241.7402	14.42100
51.62883	240.7175	14.43763
51.68050	239.6933	14.45442
51.73217	238.6701	14.47277
51.78383	237.6456	14.49160
51.83383	236.6536	14.51359
51.88716	235.5951	14.53303
51.93716	234.6038	14.54741
51.99050	233.5467	14.56004
52.04050	232.5540	14.57338
52.09384	231.4960	14.58770
52.14384	230.5042	14.61285
52.19717	229.4454	14.62644
52.24717	228.4530	14.63799
52.30050	227.3938	14.65540
52.35050	226.4012	14.66835
52.40383	225.3432	14.68452
52.45383	224.3508	14.69939
52.50550	223.3250	14.71710
52.55717	222.2990	14.73474
52.60883	221.2739	14.75392
52.66050	220.2474	14.77432
52.71216	219.2216	14.79570
52.76382	218.1950	14.81299
52.81550	217.1686	14.82689
52.86716	216.1431	14.84062
52.91716	215.1499	14.85495
52.97050	214.0904	14.87080
53.02050	213.0963	14.88547
53.07383	212.0361	14.89875
53.12383	211.0432	14.91156
53.17717	209.9834	14.92278
53.22717	208.9892	14.93328
53.28050	207.9301	14.94428
53.33050	206.9363	14.95476
53.38383	205.8762	14.96696
53.43383	204.8830	14.98014
53.48717	203.8218	14.99524
53.53716	202.8296	15.00574
53.58882	201.8020	15.01800
53.64050	200.7752	15.02987
53.69216	199.7492	15.04288
53.74382	198.7228	15.05798
53.79550	197.6959	15.07327
53.84716	196.6693	15.09166
53.89883	195.6418	15.10860
53.95050	194.6150	15.12652
54.00050	193.6214	15.14118
54.05383	192.5592	15.15437
54.10383	191.5668	15.16611
54.15717	190.5066	15.17700
54.20717	189.5138	15.18893
54.26050	188.4534	15.20442
54.31050	187.4598	15.21719
54.36382	186.3988	15.23487
54.41382	185.4059	15.24807
54.46717	184.3444	15.26062
54.51716	183.3496	15.27125
54.57050	182.2896	15.28159
54.62050	181.2945	15.29121
54.67217	180.2680	15.30330
54.72382	179.2404	15.31435
54.77550	178.2124	15.33174
54.82717	177.1860	15.34835
54.87883	176.1583	15.36581
54.93050	175.1307	15.38293
54.98217	174.1029	15.39742
55.03383	173.0750	15.41151
55.08383	172.0800	15.42275
55.13716	171.0195	15.43352
55.18716	170.0254	15.44415
55.24050	168.9657	15.45845
55.29050	167.9706	15.47930
55.34384	166.9099	15.50694
55.39384	165.9167	15.56047
55.44717	164.8580	15.67086
55.49717	163.8667	15.84805
55.55050	162.8134	16.08780
55.60050	161.8313	16.42999
55.65383	160.7912	17.00994
55.70383	159.8314	17.86484
55.75550	158.8612	19.17808
55.80717	157.9179	21.01280
55.85883	157.0044	23.28046
55.91050	156.1167	25.82586
55.96216	155.2455	28.38021
56.01382	154.3763	30.71600
56.06550	153.4977	32.62863
56.11716	152.5968	34.02881
56.16716	151.6950	34.79325
56.22050	150.6951	35.00332
56.27050	149.7238	34.69899
56.32383	148.6524	33.91700
56.37383	147.6216	32.93069
56.42717	146.5015	31.72168
56.47717	145.4376	30.51911
56.53050	144.2983	29.22158
56.58050	143.2244	28.03822
56.63383	142.0800	26.81627
56.68383	141.0096	25.71044
56.73717	139.8698	24.61704
56.78716	138.8047	23.68025
56.83882	137.7106	22.77795
56.89050	136.6212	21.98746
56.94216	135.5382	21.28518
56.99382	134.4614	20.67695
57.04550	133.3904	20.17578
57.09716	132.3258	19.73858
57.14883	131.2664	19.38640
57.20050	130.2116	19.08174
57.25050	129.1953	18.84306
57.30383	128.1144	18.65014
57.35383	127.1052	18.48767
57.40717	126.0296	18.34696
57.45717	125.0245	18.22966
57.51050	123.9517	18.13876
57.56050	122.9489	18.05533
57.61382	121.8816	17.98582
57.66382	120.8826	17.93732
57.71717	119.8159	17.89579
57.76716	118.8173	17.86796
57.82050	117.7520	17.84890
57.87050	116.7552	17.83421
57.92217	115.7245	17.81979
57.97382	114.6949	17.81171
58.02550	113.6651	17.80522
58.07717	112.6353	17.80093
58.12883	111.6052	17.79704
58.18050	110.5750	17.79268
58.23217	109.5457	17.78880
58.28383	108.5180	17.78510
58.33383	107.5213	17.78105
58.38716	106.4588	17.77688
58.43716	105.4621	17.77228
58.49050	104.3967	17.62948
58.54050	103.3942	17.41912
58.59384	102.3238	17.33120
58.64384	101.3221	17.27626
58.69717	100.2546	17.21216
58.74717	99.25394	17.16369
58.80050	98.18814	17.12533
58.85050	97.19093	17.11795
58.90383	96.12644	17.10603
58.95383	95.12840	17.08835
59.00550	94.09762	17.05193
59.05717	93.06613	17.02249
59.10883	92.03472	16.96476
59.16050	91.00170	16.90864
59.21216	89.96930	16.82910
59.26382	88.93509	16.76096
59.31550	87.90288	16.71214
59.36716	86.87186	16.66204
59.41716	85.87163	16.62036
59.47050	84.80680	16.57725
59.52050	83.80824	16.54516
59.57383	82.74278	16.50894
59.62383	81.74390	16.47744
59.67717	80.67828	16.44004
59.72717	79.67968	16.40216
59.78050	78.61462	16.36208
59.83050	77.61762	16.33739
59.88383	76.55431	16.31547
59.93383	75.55670	16.29205
59.98717	74.49256	16.26151
60.03716	73.49450	16.23244
60.08882	72.46256	16.20058
60.14050	71.43188	16.16861
60.19216	70.40042	16.13374
60.24382	69.36889	16.10113
60.29550	68.33630	16.06141
60.34716	67.30408	16.02203
60.39883	66.27358	15.99080
60.45050	65.24292	15.96645
60.50050	64.24360	15.93374
60.55383	63.17960	15.88649
60.60383	62.17984	15.83930
60.65717	61.11487	15.79110
60.70717	60.11563	15.75005
60.76050	59.05019	15.71709
60.81050	58.05371	15.67534
60.86382	56.98772	15.64168
60.91382	55.99112	15.60518
60.96717	54.92537	15.57061
61.01716	53.92678	15.53916
61.07050	52.86195	15.50186
61.12050	51.86118	15.45467
61.17217	50.82946	15.40563
61.22382	49.79754	15.34906
61.27550	48.76513	15.30475
61.32717	47.73290	15.26204
61.37883	46.70140	15.23713
61.43050	45.66884	15.18634
61.48217	44.63545	15.13498
61.53383	43.60217	15.09269
61.58383	42.60350	15.04984
61.63716	41.53766	14.99960
61.68716	40.53768	14.95088
61.74050	39.47114	14.88965
61.79050	38.47058	14.84462
61.84384	37.40420	14.76511
61.89384	36.40415	14.70358
61.94717	35.33591	14.64275
61.99717	34.33477	14.57346
62.05050	33.26717	14.50438
62.10050	32.26680	14.47304
62.15383	31.19912	14.36336
62.20383	30.19849	14.32520
62.25550	29.16368	14.24206
62.30717	28.12926	14.17237
62.35883	27.10594	14.53423
62.41050	26.06966	14.14530
62.46216	25.03333	14.08582
62.51050	24.06340	14.09503
62.56050	23.20296	14.23946
62.61382	22.93477	11.40903
62.66382	22.99460	7.408870
62.71717	23.30140	3.289631
62.76716	23.74252	0.02466811
62.82050	24.34358	-2.830114
62.87050	25.00039	-4.964312
62.92217	25.75056	-6.724794
62.97382	26.55725	-8.111840
63.02550	27.40726	-9.218692
63.07717	28.29093	-10.09281
63.12883	29.20090	-10.78134
63.18050	30.13332	-11.33637
63.23217	31.08003	-11.78619
63.28383	32.04135	-12.15254
63.33383	32.98115	-12.43440
63.38716	33.99075	-12.68695
63.43716	34.94524	-12.89387
63.49050	35.96814	-13.06314
63.54050	36.93186	-13.20804
63.59384	37.96471	-13.33951
63.64384	38.93592	-13.45482
63.69717	39.97487	-13.55412
63.74717	40.95059	-13.62836
63.80050	41.99490	-13.70994
63.85050	42.97467	-13.77954
63.90383	44.02184	-13.84578
63.95383	45.00447	-13.90198
64.00550	46.02174	-13.96347
64.05717	47.04032	-14.02602
64.10884	48.05903	-14.09553
64.16050	49.07752	-14.15146
64.21217	50.09754	-14.21640
64.26384	51.11972	-14.27712
64.31550	52.14109	-14.34474
64.36718	53.16022	-14.47962
64.41717	54.15090	-14.49932
64.47050	55.20710	-14.60658
64.52050	56.19910	-14.62922
64.57384	57.25728	-14.67507
64.62383	58.24840	-14.72864
64.67718	59.30656	-14.79197
64.72718	60.29938	-14.85285
64.78050	61.35832	-14.92828
64.83050	62.35268	-14.97720
64.88384	63.41310	-15.02567
64.93384	64.40606	-15.09471
64.98717	65.46700	-15.15068
65.03717	66.46257	-15.20590
65.08884	67.48968	-15.27601
65.14050	68.51753	-15.34408
65.19217	69.54556	-15.40038
65.24384	70.57376	-15.47083
65.29550	71.60250	-15.53428
65.34717	72.63156	-15.59082
65.39883	73.66000	-15.65168
65.45050	74.68880	-15.70791
65.50050	75.68556	-15.76940
65.55384	76.74770	-15.84124
65.60384	77.74450	-15.89830
65.65718	78.80750	-15.96134
65.70718	79.80450	-16.02208
65.76050	80.86554	-16.09546
65.81050	81.86138	-16.15964
65.86384	82.92361	-16.23025
65.91382	83.92012	-16.28636
65.96718	84.98251	-16.34826
66.01716	85.97978	-16.41227
66.07050	87.04225	-16.48115
66.12050	88.03836	-16.54440
66.17218	89.06849	-16.60970
66.22384	90.09793	-16.67880
66.27550	91.12759	-16.74488
66.32718	92.15805	-16.82975
66.37884	93.18745	-16.88225
66.43050	94.21703	-16.94103
66.48218	95.24725	-17.00513
66.53384	96.27776	-17.06603
66.58384	97.27531	-17.11666
66.63718	98.33961	-17.17398
66.68718	99.33528	-17.25671
66.74050	100.3984	-17.33652
66.79050	101.3952	-17.39566
66.84384	102.4583	-17.45927
66.89384	103.4547	-17.51232
66.94718	104.5177	-17.59597
66.99718	105.5136	-17.69885
67.05050	106.5766	-17.78233
67.10050	107.5718	-17.83330
67.15384	108.6370	-17.87897
67.20384	109.6294	-18.14812
67.25550	110.6589	-18.11480
67.30718	111.6899	-18.14702
67.35884	112.7209	-18.20069
67.41050	113.7523	-18.24844
67.46218	114.7833	-18.31100
67.51384	115.8157	-18.35492
67.56550	116.8465	-18.40124
67.61718	117.8788	-18.45551
67.66718	118.8765	-18.51439
67.72050	119.9398	-18.62066
67.77050	120.9376	-18.66191
67.82384	121.9999	-18.78328
67.87384	122.9973	-18.81835
67.92718	124.0598	-18.91097
67.97718	125.0583	-18.95610
68.03050	126.1219	-19.07268
68.08050	127.1194	-19.10830
68.13384	128.1827	-19.16542
68.18384	129.1802	-19.26158
68.23718	130.2432	-19.31345
68.28718	131.2408	-19.39791
68.33884	132.2708	-19.47178
68.39050	133.3005	-19.55391
68.44218	134.3310	-19.63090
68.49384	135.3617	-19.73062
68.54550	136.3911	-19.81760
68.59718	137.4162	-19.99864
68.64884	138.4456	-20.06287
68.70050	139.4759	-20.11885
68.75050	140.4720	-20.19882
68.80384	141.5334	-20.33868
68.85384	142.5301	-20.40623
68.90718	143.5914	-20.50413
68.95718	144.5875	-20.59549
69.01050	145.6491	-20.69239
69.06050	146.6451	-20.77417
69.11384	147.7049	-20.93015
69.16382	148.6996	-21.00438
69.21718	149.7636	-21.04180
69.26716	150.7611	-21.08940
69.32050	151.8242	-21.14896
69.37050	152.8218	-21.22784
69.42218	153.8525	-21.30275
69.47384	154.8825	-21.39121
69.52550	155.9121	-21.46656
69.57718	156.9435	-21.53454
69.62884	157.9741	-21.59846
69.68050	159.0052	-21.65110
69.73218	160.0368	-21.69134
69.78384	161.0694	-21.72718
69.83384	162.0676	-21.75318
69.88718	163.1342	-21.77774
69.93718	164.1338	-21.80459
69.99050	165.1993	-21.83710
70.04050	166.1988	-21.88553
70.09384	167.2642	-21.94898
70.14384	168.2620	-22.01514
70.19718	169.3268	-22.10223
70.24718	170.3242	-22.18798
70.30050	171.3876	-22.28847
70.35050	172.3839	-22.38806
70.40384	173.4468	-22.49883
70.45384	174.4411	-22.61081
70.50550	175.4686	-22.74470
70.55718	176.4945	-22.88458
70.60884	177.5206	-23.04019
70.66050	178.5464	-23.22046
70.71218	179.5703	-23.40148
70.76384	180.5939	-23.60872
70.81550	181.6167	-23.84140
70.86718	182.6377	-24.09005
70.91718	183.6244	-24.36177
70.97050	184.6751	-24.68136
71.02050	185.6586	-24.99616
71.07384	186.7066	-25.38272
71.12384	187.6860	-25.75716
71.17718	188.7305	-26.19758
71.22718	189.7064	-26.65480
71.28050	190.7455	-27.13504
71.33050	191.7182	-27.62802
71.38384	192.7546	-28.17057
71.43384	193.7254	-28.68326
71.48718	194.7601	-29.26797
71.53718	195.7279	-29.86081
71.58884	196.7244	-30.54037
71.64050	197.7194	-31.28951
71.69218	198.7085	-32.10026
71.74384	199.6956	-32.98431
71.79550	200.6783	-33.91289
71.84718	201.6576	-34.86783
71.89884	202.6349	-35.83291
71.95050	203.6127	-36.71672
72.00050	204.5643	-37.44754
72.05384	205.5866	-37.92569
72.10384	206.5608	-37.90231
72.15718	207.6326	-37.01090
72.20718	208.6816	-35.12090
72.26050	209.8568	-32.22784
72.31050	210.9928	-29.70434
72.36384	212.2000	-27.89717
72.41382	213.3075	-26.72695
72.46718	214.4633	-25.79394
72.51716	215.5284	-25.12434
72.57050	216.6480	-24.58302
72.62050	217.6869	-24.19260
72.67218	218.7506	-23.88107
72.72384	219.8068	-23.65664
72.77550	220.8576	-23.48926
72.82718	221.9035	-23.38031
72.87884	222.9476	-23.29534
72.93050	223.9888	-23.23809
72.98218	225.0284	-23.19917
73.03384	226.0657	-23.17905
73.08384	227.0676	-23.17053
73.13718	228.1363	-23.16740
73.18718	229.1383	-23.16672
73.24050	230.2048	-23.16704
73.29050	231.2053	-23.17024
73.34384	232.2705	-23.18365
73.39384	233.2698	-23.20629
73.44718	234.3372	-23.23358
73.49718	235.3363	-23.26453
73.55050	236.4035	-23.29166
73.60050	237.4024	-23.32268
73.65384	238.4679	-23.35672
73.70384	239.4663	-23.39537
73.75550	240.4981	-23.43465
73.80718	241.5295	-23.48921
73.85884	242.5600	-23.53381
73.91050	243.5919	-23.58744
73.96218	244.6239	-23.63510
74.01384	245.6551	-23.67980
74.06550	246.6866	-23.76276
74.11718	247.7179	-23.78781
74.16718	248.7174	-23.80853
74.22050	249.7817	-23.83535
74.27050	250.7812	-23.86972
74.32384	251.8461	-23.90814
74.37384	252.8458	-23.93920
74.42718	253.9102	-23.97282
74.47718	254.9094	-24.00419
74.53050	255.9751	-24.05104
74.58050	256.9726	-24.09150
74.63384	258.0380	-24.15192
74.68384	259.0354	-24.20816
74.73718	260.1004	-24.24751
74.78718	261.0978	-24.28323
74.83884	262.1297	-24.33515
74.89050	263.1610	-24.38200
74.94218	264.1926	-24.42765
74.99384	265.2246	-24.46847
75.04550	266.2570	-24.52510
75.09718	267.2866	-24.57249
75.14884	268.3176	-24.61530
75.20050	269.3485	-24.66434
75.25050	270.3466	-24.70880
75.30384	271.4110	-24.74676
-2.000000	5.000000	0.0000000