File: 9-C1(1.2mol%)+C20(1.0mol%)/matlab/150-1.txt
CLOSED
Version	1.0
Language	English
Mode	Standard
Run	5
RunSerial	12273
Instrument	DSC Q2000 V24.11 Build 124
Module	DSC Standard Cell RC
Operator
File	\\AE520-1454\Users\dsc\Desktop\Data\29-08-17\150-1.001
ProcName
InstSerial	2000-0883
AutoSerial	1293
Sample	150-1
Size	15.2000	mg
PanMass	Not available
PanResist	Automatic Automatic  K/W
PanFactor	Default Default
Method
Comment
Xcomment	Pan: Tzero Aluminum Hermetic
Xcomment	Gas1: Nitrogen 50.0 ml/min
Xcomment	Gas2: Nitrogen 50.0 ml/min
Text
Exotherm	UP
Kcell	1.05230
Cpconst	Standard: 0.938
Calib	-38.6961
TempCal	1	pts	157.46	156.60
TzeroDt	-87.6168 -0.0009 -1.4231
TzeroDtz	-87.6168 0.0057 6.9570
InstCalFile	Tzero: \\Ae520-1454\ta\Data\DSC\Calibration\2017\CALIBRATION\1562_RCS (90)_05_18_2017 10_50_44.TZR
InstCalFile	Baseline: \\Ae520-1454\ta\Data\DSC\Calibration\2017\2017-05-17_Calibration.001
InstCalFile	Sapphire: \\Ae520-1454\ta\Data\DSC\Calibration\2017\2017-05-17_Saphire.001
InstCalDate	Tzero 2017-05-18 Time 10:50:44
TempRange	-87.39 to 398.39 °C at 10.00 °C/min Heat Only
AutoZero	Delta T Offset 0.000 uV
AutoZero	Delta T0 Offset 0.000 uV
MultiptCal	0
MultiPtDesc	0) Not set
AutoCellConst	Calibration Date 2017-05-18 16:59:28
Controls	Gas 1  Event Off  Sampling 0.2
Cell#	RC-01562
CoolingUnit	RCS (90)
SelHeatFlow	Heat Flow T4P (mW)
AutoLidII	Installed
AutoAnalysis	Off
MacroFile
Nsig	3
Sig1	Time (min)
Sig2	Temperature (°C)
Sig3	Heat Flow (mW)
Date	2017-08-29
Time	16:48:32
OrgMethod	1: Equilibrate at 80.00 °C
OrgMethod	2: Isothermal for 3.00 min
OrgMethod	3: Jump to 150.00 °C
OrgMethod	4: Mark end of cycle 1
OrgMethod	5: Isothermal for 40.00 min
OrgMethod	6: Mark end of cycle 2
OrgMethod	7: Ramp 20.00 °C/min to 280.00 °C
OrgMethod	8: Mark end of cycle 3
OrgMethod	9: Ramp 20.00 °C/min to 20.00 °C
OrgMethod	10: Mark end of cycle 4
OrgMethod	11: Ramp 20.00 °C/min to 280.00 °C
OrgMethod	12: Mark end of cycle 5
OrgFile	C:\Users\jarra\Desktop\DSC\9-C1(1.2mol%)+C20(1.0mol%)\150-1.001
StartOfData
4.99994E-4	79.78580	-2.547381
0.05383332	79.81572	-2.120406
0.1038333	79.83624	-1.816454
0.1571666	79.85225	-1.560436
0.2071666	79.86450	-1.383489
0.2605000	79.87299	-1.238720
0.3105000	79.87910	-1.137028
0.3638334	79.88311	-1.054385
0.4138333	79.88658	-0.9992866
0.4671667	79.88881	-0.9559181
0.5171667	79.88978	-0.9268768
0.5705000	79.88989	-0.9052766
0.6205000	79.88965	-0.8916447
0.6721668	79.88990	-0.8828670
0.7238332	79.88922	-0.8772278
0.7755000	79.88921	-0.8739790
0.8271668	79.88824	-0.8706874
0.8788332	79.88728	-0.8673476
0.9305000	79.88658	-0.8639918
0.9821668	79.88575	-0.8606709
1.033833	79.88526	-0.8574969
1.083833	79.88390	-0.8546051
1.137166	79.88312	-0.8517164
1.187166	79.88196	-0.8492160
1.240500	79.88080	-0.8467356
1.290500	79.88032	-0.8446656
1.343833	79.87944	-0.8426392
1.393833	79.87872	-0.8409476
1.447166	79.87776	-0.8393482
1.497166	79.87747	-0.8380047
1.550500	79.87636	-0.8368194
1.600500	79.87612	-0.8358368
1.653833	79.87607	-0.8349344
1.703833	79.87507	-0.8342282
1.755500	79.87430	-0.8336114
1.807167	79.87205	-0.8330682
1.858834	79.87172	-0.8326031
1.910500	79.87148	-0.8322532
1.962166	79.87078	-0.8319980
2.013833	79.87120	-0.8318576
2.065500	79.86884	-0.8317589
2.117167	79.86818	-0.8317901
2.167167	79.86890	-0.8319230
2.220500	79.86778	-0.8321747
2.270500	79.86663	-0.8324297
2.323833	79.86612	-0.8327603
2.373834	79.86557	-0.8331178
2.427167	79.86574	-0.8336368
2.477167	79.86478	-0.8340994
2.530500	79.86421	-0.8347116
2.580500	79.86425	-0.8353244
2.633833	79.86297	-0.8360005
2.683833	79.86225	-0.8366834
2.737167	79.86176	-0.8374462
2.787167	79.86162	-0.8382152
2.838833	79.86176	-0.8390158
2.890500	79.86106	-0.8397732
2.942167	79.86116	-0.8405841
2.993833	79.85889	-0.8413663
3.040500	80.09766	-1.159538
3.093834	82.49803	-5.154350
3.143833	85.47702	-10.83387
3.197167	89.03066	-17.68557
3.247166	92.66163	-23.94785
3.300500	96.77072	-30.02095
3.350500	100.7921	-34.99489
3.403833	105.2116	-39.51317
3.453833	109.4437	-43.07033
3.505500	113.8822	-46.15042
3.557167	118.3531	-48.91194
3.608833	122.8548	-51.19712
3.660500	127.3745	-53.07424
3.712167	131.8979	-54.76871
3.763833	136.2917	-56.02625
3.815500	139.2451	-55.20451
3.867166	141.0827	-50.71884
3.917167	142.4802	-45.26212
3.970500	143.6190	-39.36548
4.020500	144.4649	-34.29770
4.073834	145.1866	-29.64573
4.123833	145.7314	-26.05844
4.177166	146.2059	-22.97824
4.227167	146.5731	-20.68643
4.280500	146.8982	-18.78123
4.330500	147.1530	-17.39094
4.383834	147.3823	-16.24240
4.433834	147.5658	-15.41134
4.487167	147.7322	-14.72669
4.537167	147.8667	-14.23192
4.588834	147.9884	-13.81677
4.640500	148.0944	-13.47571
4.692166	148.1894	-13.19189
4.743834	148.2728	-12.95186
4.795500	148.3485	-12.74787
4.847166	148.4155	-12.55939
4.898834	148.4768	-12.38861
4.950500	148.5319	-12.22501
5.000500	148.5818	-12.07272
5.053834	148.6292	-11.91296
5.103833	148.6712	-11.76340
5.157166	148.7114	-11.60256
5.207167	148.7486	-11.45336
5.260500	148.7838	-11.28848
5.310500	148.8154	-11.13499
5.363834	148.8468	-10.96980
5.413832	148.8745	-10.81433
5.467168	148.9028	-10.65164
5.517168	148.9263	-10.49547
5.570500	148.9518	-10.33387
5.620500	148.9738	-10.18404
5.672168	148.9968	-10.03199
5.723834	149.0154	-9.878458
5.775500	149.0362	-9.730438
5.827168	149.0537	-9.579489
5.878834	149.0725	-9.435809
5.930500	149.0901	-9.288889
5.982168	149.1059	-9.143072
6.033832	149.1217	-8.999236
6.083832	149.1365	-8.861841
6.137168	149.1520	-8.710718
6.187168	149.1652	-8.571769
6.240500	149.1802	-8.421699
6.290500	149.1938	-8.279179
6.343834	149.2083	-8.127520
6.393832	149.2214	-7.980055
6.447168	149.2356	-7.819622
6.497168	149.2481	-7.663647
6.550500	149.2622	-7.493286
6.600500	149.2760	-7.323501
6.653832	149.2904	-7.135147
6.703832	149.3066	-6.941913
6.755500	149.3214	-6.725140
6.807166	149.3386	-6.492162
6.858832	149.3561	-6.253661
6.910500	149.3730	-6.012520
6.962168	149.3908	-5.768115
7.013834	149.4081	-5.528348
7.065500	149.4259	-5.281914
7.117166	149.4441	-5.031050
7.167168	149.4618	-4.784496
7.220500	149.4796	-4.525452
7.270500	149.4966	-4.284594
7.323834	149.5150	-4.029056
7.373834	149.5319	-3.793166
7.427168	149.5487	-3.543685
7.477168	149.5653	-3.324686
7.530500	149.5808	-3.100644
7.580500	149.5936	-2.910391
7.633832	149.6075	-2.731380
7.683832	149.6190	-2.581131
7.737168	149.6296	-2.435760
7.787168	149.6389	-2.317126
7.838834	149.6466	-2.208455
7.890500	149.6546	-2.114098
7.942168	149.6618	-2.028508
7.993834	149.6676	-1.952842
8.045500	149.6732	-1.882633
8.097168	149.6791	-1.819454
8.148834	149.6832	-1.762369
8.200500	149.6876	-1.709592
8.250500	149.6916	-1.661830
8.303832	149.6958	-1.614586
8.353832	149.6990	-1.573584
8.407166	149.7031	-1.532131
8.457168	149.7060	-1.495730
8.510499	149.7093	-1.458358
8.560500	149.7124	-1.424038
8.613834	149.7146	-1.389875
8.663834	149.7178	-1.358295
8.717168	149.7213	-1.325465
8.767168	149.7234	-1.295535
8.820500	149.7259	-1.263186
8.870499	149.7289	-1.233041
8.922168	149.7304	-1.202051
8.973832	149.7341	-1.171447
9.025499	149.7355	-1.140256
9.077168	149.7382	-1.108646
9.128834	149.7404	-1.078606
9.180500	149.7429	-1.048331
9.232166	149.7447	-1.016631
9.283832	149.7475	-0.9851725
9.333832	149.7489	-0.9537819
9.387168	149.7517	-0.9208900
9.437166	149.7545	-0.8896512
9.490500	149.7567	-0.8563509
9.540500	149.7588	-0.8234340
9.593832	149.7612	-0.7890886
9.643832	149.7641	-0.7570732
9.697168	149.7667	-0.7218179
9.747168	149.7694	-0.6899331
9.800500	149.7715	-0.6543320
9.850500	149.7730	-0.6221904
9.903832	149.7765	-0.5861111
9.953834	149.7786	-0.5524473
10.00550	149.7813	-0.5150383
10.05717	149.7839	-0.4777604
10.10883	149.7864	-0.4412454
10.16050	149.7894	-0.4028717
10.21217	149.7915	-0.3631854
10.26383	149.7940	-0.3214106
10.31550	149.7978	-0.2758718
10.36717	149.8003	-0.2243004
10.41717	149.8039	-0.1652068
10.47050	149.8084	-.08947700
10.52050	149.8140	-8.0009E-3
10.57383	149.8194	0.09848426
10.62383	149.8266	0.2086867
10.67717	149.8352	0.3435155
10.72717	149.8434	0.4841928
10.78050	149.8546	0.6430020
10.83050	149.8655	0.8017064
10.88383	149.8760	0.9807376
10.93383	149.8864	1.149577
10.98717	149.8987	1.327408
11.03717	149.9099	1.490053
11.08883	149.9213	1.654778
11.14050	149.9324	1.813692
11.19217	149.9421	1.961270
11.24384	149.9524	2.103287
11.29550	149.9613	2.234795
11.34717	149.9704	2.358127
11.39883	149.9782	2.474588
11.45050	149.9858	2.583580
11.50050	149.9928	2.682448
11.55383	149.9990	2.781975
11.60383	150.0046	2.868711
11.65717	150.0109	2.955379
11.70717	150.0164	3.030406
11.76050	150.0220	3.104613
11.81050	150.0260	3.171948
11.86383	150.0308	3.236510
11.91383	150.0347	3.290781
11.96717	150.0382	3.343110
12.01717	150.0418	3.386302
12.07050	150.0453	3.428132
12.12050	150.0481	3.459900
12.17217	150.0497	3.488007
12.22383	150.0517	3.508858
12.27550	150.0540	3.523869
12.32717	150.0542	3.534332
12.37884	150.0556	3.539880
12.43050	150.0552	3.543761
12.48217	150.0557	3.547435
12.53383	150.0553	3.550640
12.58383	150.0554	3.553070
12.63717	150.0538	3.554722
12.68716	150.0526	3.555318
12.74050	150.0519	3.553842
12.79050	150.0505	3.548854
12.84383	150.0482	3.538310
12.89383	150.0468	3.522808
12.94717	150.0460	3.500156
12.99717	150.0435	3.473938
13.05050	150.0411	3.441122
13.10050	150.0387	3.408543
13.15383	150.0358	3.371992
13.20383	150.0337	3.337969
13.25550	150.0316	3.300264
13.30717	150.0293	3.262970
13.35883	150.0269	3.225934
13.41050	150.0245	3.188361
13.46217	150.0217	3.153382
13.51383	150.0201	3.116941
13.56550	150.0174	3.082012
13.61716	150.0152	3.047861
13.66716	150.0135	3.014714
13.72050	150.0114	2.981041
13.77050	150.0082	2.950846
13.82384	150.0065	2.918592
13.87384	150.0044	2.888478
13.92717	150.0025	2.857668
13.97717	150.0001	2.829323
14.03050	149.9983	2.799104
14.08050	149.9967	2.770630
14.13383	149.9936	2.741375
14.18383	149.9933	2.714651
14.23716	149.9904	2.687582
14.28717	149.9891	2.662000
14.33883	149.9874	2.636246
14.39050	149.9860	2.611778
14.44217	149.9840	2.587876
14.49384	149.9819	2.564268
14.54550	149.9807	2.541460
14.59717	149.9797	2.518004
14.64883	149.9775	2.495389
14.70050	149.9759	2.473539
14.75050	149.9748	2.452918
14.80383	149.9733	2.430446
14.85383	149.9722	2.409822
14.90717	149.9710	2.388648
14.95717	149.9690	2.369219
15.01050	149.9676	2.348296
15.06050	149.9664	2.328838
15.11383	149.9642	2.309962
15.16383	149.9642	2.291740
15.21716	149.9623	2.273363
15.26717	149.9617	2.254934
15.32050	149.9589	2.234983
15.37050	149.9575	2.217297
15.42217	149.9571	2.199619
15.47383	149.9557	2.181422
15.52550	149.9549	2.163133
15.57717	149.9535	2.145459
15.62883	149.9519	2.128310
15.68050	149.9501	2.111308
15.73216	149.9496	2.094969
15.78383	149.9479	2.078223
15.83383	149.9468	2.062247
15.88716	149.9460	2.045479
15.93717	149.9442	2.029873
15.99050	149.9442	2.012950
16.04050	149.9429	1.998452
16.09383	149.9412	1.982138
16.14383	149.9415	1.966931
16.19717	149.9392	1.953238
16.24716	149.9394	1.939216
16.30050	149.9379	1.925495
16.35050	149.9359	1.912733
16.40383	149.9344	1.899791
16.45383	149.9355	1.886418
16.50550	149.9339	1.873794
16.55716	149.9329	1.862325
16.60883	149.9319	1.851062
16.66050	149.9309	1.840135
16.71216	149.9305	1.829270
16.76383	149.9296	1.818878
16.81550	149.9285	1.808558
16.86716	149.9278	1.797999
16.91716	149.9274	1.787957
16.97050	149.9266	1.777569
17.02050	149.9255	1.767654
17.07383	149.9251	1.757272
17.12383	149.9241	1.747567
17.17716	149.9240	1.737201
17.22716	149.9233	1.727559
17.28050	149.9232	1.717313
17.33050	149.9224	1.707890
17.38383	149.9224	1.697964
17.43383	149.9221	1.688831
17.48716	149.9214	1.679340
17.53717	149.9208	1.670708
17.58883	149.9208	1.662108
17.64050	149.9214	1.653839
17.69216	149.9214	1.645998
17.74383	149.9209	1.638685
17.79550	149.9204	1.631881
17.84716	149.9209	1.625656
17.89883	149.9219	1.620031
17.95050	149.9224	1.615134
18.00050	149.9228	1.611191
18.05383	149.9235	1.607796
18.10383	149.9236	1.605475
18.15716	149.9257	1.603830
18.20716	149.9248	1.603190
18.26050	149.9276	1.603717
18.31050	149.9280	1.605708
18.36383	149.9296	1.609555
18.41383	149.9310	1.615004
18.46716	149.9330	1.622657
18.51716	149.9341	1.631398
18.57050	149.9350	1.642030
18.62050	149.9367	1.652212
18.67216	149.9373	1.663208
18.72383	149.9389	1.674176
18.77550	149.9388	1.684306
18.82716	149.9397	1.692868
18.87883	149.9409	1.699694
18.93050	149.9412	1.706344
18.98216	149.9417	1.712869
19.03383	149.9414	1.719104
19.08383	149.9416	1.724651
19.13716	149.9404	1.729848
19.18716	149.9402	1.733847
19.24050	149.9391	1.737115
19.29050	149.9380	1.739673
19.34383	149.9369	1.740672
19.39383	149.9353	1.738088
19.44716	149.9330	1.729072
19.49716	149.9310	1.714686
19.55050	149.9287	1.692994
19.60050	149.9271	1.667056
19.65383	149.9251	1.634386
19.70383	149.9224	1.601818
19.75550	149.9199	1.565565
19.80716	149.9178	1.528436
19.85883	149.9152	1.490624
19.91050	149.9126	1.452099
19.96216	149.9103	1.415130
20.01383	149.9084	1.377942
20.06550	149.9058	1.340615
20.11716	149.9037	1.304075
20.16716	149.9009	1.269438
20.22050	149.8989	1.231636
20.27050	149.8961	1.198873
20.32383	149.8940	1.163468
20.37383	149.8911	1.130953
20.42716	149.8887	1.095232
20.47716	149.8871	1.061556
20.53050	149.8851	1.026767
20.58050	149.8832	0.9938070
20.63383	149.8804	0.9583751
20.68383	149.8785	0.9274276
20.73716	149.8753	0.8936542
20.78717	149.8736	0.8607091
20.83883	149.8713	0.8277024
20.89050	149.8693	0.7948670
20.94216	149.8670	0.7628012
20.99383	149.8646	0.7304043
21.04550	149.8624	0.6982650
21.09716	149.8608	0.6650756
21.14883	149.8586	0.6337405
21.20050	149.8558	0.6019600
21.25050	149.8545	0.5711158
21.30383	149.8519	0.5392709
21.35383	149.8492	0.5097206
21.40716	149.8479	0.4776226
21.45717	149.8455	0.4476977
21.51050	149.8440	0.4137984
21.56050	149.8415	0.3845650
21.61383	149.8388	0.3532250
21.66383	149.8385	0.3233498
21.71716	149.8358	0.2925184
21.76716	149.8341	0.2630191
21.82050	149.8317	0.2321575
21.87050	149.8298	0.2035870
21.92216	149.8276	0.1750462
21.97383	149.8256	0.1456576
22.02550	149.8257	0.1315284
22.07716	149.8242	0.1231777
22.12883	149.8224	0.1005612
22.18050	149.8196	0.06785524
22.23216	149.8176	0.03245497
22.28383	149.8154	-1.8179E-3
22.33383	149.8138	-.03032894
22.38716	149.8120	-.06020932
22.43716	149.8096	-.08773202
22.49050	149.8073	-0.1175066
22.54050	149.8062	-0.1431181
22.59383	149.8039	-0.1711002
22.64383	149.8022	-0.1931869
22.69716	149.8012	-0.2092222
22.74716	149.7991	-0.2320432
22.80050	149.7974	-0.2582635
22.85050	149.7959	-0.2839007
22.90383	149.7941	-0.3084452
22.95383	149.7927	-0.3318158
23.00550	149.7910	-0.3559708
23.05716	149.7889	-0.3805680
23.10883	149.7874	-0.4042718
23.16050	149.7849	-0.4270088
23.21216	149.7844	-0.4498203
23.26383	149.7841	-0.4652396
23.31550	149.7824	-0.4793048
23.36716	149.7814	-0.4986414
23.41716	149.7794	-0.5196700
23.47050	149.7787	-0.5444688
23.52050	149.7769	-0.5643918
23.57383	149.7756	-0.5825139
23.62383	149.7736	-0.5988938
23.67717	149.7732	-0.6200895
23.72716	149.7720	-0.6414537
23.78050	149.7695	-0.6639666
23.83050	149.7684	-0.6841910
23.88383	149.7672	-0.7049718
23.93383	149.7656	-0.7228545
23.98716	149.7650	-0.7424856
24.03717	149.7628	-0.7594666
24.08883	149.7622	-0.7784900
24.14050	149.7603	-0.7965656
24.19216	149.7601	-0.8147344
24.24383	149.7584	-0.8321484
24.29550	149.7570	-0.8499211
24.34716	149.7567	-0.8681982
24.39883	149.7547	-0.8849172
24.45050	149.7529	-0.9019906
24.50050	149.7523	-0.9183165
24.55383	149.7507	-0.9364038
24.60383	149.7505	-0.9534538
24.65716	149.7481	-0.9712144
24.70717	149.7466	-0.9876108
24.76050	149.7459	-1.004791
24.81050	149.7449	-1.020773
24.86383	149.7443	-1.036410
24.91383	149.7425	-1.051437
24.96716	149.7416	-1.067198
25.01716	149.7407	-1.081736
25.07050	149.7392	-1.097304
25.12050	149.7387	-1.111238
25.17216	149.7372	-1.125400
25.22383	149.7361	-1.139309
25.27550	149.7347	-1.152402
25.32716	149.7345	-1.165994
25.37883	149.7336	-1.179268
25.43050	149.7320	-1.192087
25.48216	149.7312	-1.203539
25.53383	149.7304	-1.215512
25.58383	149.7290	-1.227169
25.63716	149.7283	-1.238732
25.68717	149.7266	-1.249700
25.74050	149.7266	-1.261606
25.79050	149.7258	-1.272592
25.84383	149.7248	-1.283910
25.89383	149.7240	-1.294043
25.94717	149.7237	-1.304767
25.99716	149.7223	-1.315237
26.05050	149.7224	-1.326202
26.10050	149.7212	-1.336233
26.15383	149.7208	-1.347078
26.20383	149.7201	-1.357163
26.25550	149.7196	-1.367554
26.30716	149.7184	-1.377887
26.35883	149.7186	-1.388196
26.41050	149.7177	-1.398399
26.46216	149.7175	-1.408583
26.51383	149.7170	-1.418706
26.56550	149.7155	-1.428727
26.61716	149.7146	-1.438628
26.66716	149.7139	-1.448150
26.72050	149.7143	-1.458235
26.77050	149.7122	-1.467509
26.82383	149.7122	-1.477352
26.87383	149.7128	-1.486456
26.92717	149.7121	-1.496031
26.97717	149.7119	-1.504899
27.03050	149.7115	-1.514258
27.08050	149.7116	-1.522931
27.13383	149.7100	-1.532052
27.18383	149.7098	-1.540510
27.23716	149.7094	-1.549405
27.28717	149.7093	-1.557605
27.33883	149.7089	-1.565894
27.39050	149.7072	-1.574023
27.44216	149.7086	-1.582035
27.49383	149.7079	-1.589894
27.54550	149.7070	-1.597606
27.59716	149.7066	-1.605169
27.64883	149.7061	-1.612594
27.70050	149.7063	-1.619873
27.75050	149.7065	-1.626810
27.80383	149.7056	-1.634020
27.85383	149.7056	-1.640742
27.90716	149.7051	-1.647789
27.95716	149.7043	-1.654262
28.01050	149.7046	-1.661026
28.06050	149.7051	-1.667234
28.11383	149.7037	-1.673687
28.16383	149.7036	-1.679574
28.21716	149.7039	-1.685742
28.26716	149.7036	-1.691392
28.32050	149.7028	-1.697280
28.37050	149.7039	-1.702712
28.42216	149.7029	-1.708191
28.47383	149.7034	-1.713541
28.52550	149.7026	-1.718804
28.57717	149.7024	-1.723964
28.62883	149.7018	-1.729023
28.68050	149.7018	-1.733902
28.73216	149.7015	-1.738744
28.78383	149.7011	-1.743459
28.83383	149.7010	-1.747943
28.88716	149.7010	-1.752563
28.93717	149.7005	-1.756789
28.99050	149.7000	-1.761242
29.04050	149.7000	-1.765410
29.09383	149.7002	-1.769711
29.14383	149.7001	-1.773675
29.19717	149.6988	-1.777781
29.24716	149.6990	-1.781578
29.30050	149.6994	-1.785525
29.35050	149.6992	-1.789168
29.40383	149.6994	-1.792947
29.45383	149.6986	-1.796466
29.50550	149.6986	-1.800010
29.55716	149.6983	-1.803546
29.60883	149.6987	-1.806936
29.66050	149.6977	-1.810287
29.71216	149.6985	-1.813587
29.76383	149.6980	-1.816816
29.81550	149.6979	-1.819977
29.86716	149.6975	-1.823052
29.91716	149.6974	-1.825957
29.97050	149.6972	-1.829025
30.02050	149.6976	-1.831870
30.07383	149.6971	-1.834820
30.12383	149.6968	-1.837554
30.17717	149.6968	-1.840351
30.22717	149.6958	-1.842918
30.28050	149.6969	-1.845610
30.33050	149.6969	-1.848110
30.38383	149.6961	-1.850744
30.43383	149.6965	-1.853161
30.48716	149.6972	-1.855742
30.53717	149.6963	-1.858107
30.58883	149.6959	-1.860451
30.64050	149.6956	-1.862768
30.69216	149.6965	-1.865054
30.74383	149.6963	-1.867260
30.79550	149.6957	-1.869441
30.84716	149.6959	-1.871603
30.89883	149.6956	-1.873742
30.95050	149.6952	-1.875844
31.00050	149.6957	-1.877865
31.05383	149.6954	-1.879972
31.10383	149.6953	-1.881940
31.15716	149.6951	-1.884002
31.20716	149.6949	-1.885889
31.26050	149.6950	-1.887842
31.31050	149.6944	-1.889644
31.36383	149.6948	-1.891528
31.41383	149.6950	-1.893245
31.46716	149.6948	-1.895072
31.51716	149.6938	-1.896700
31.57050	149.6946	-1.898468
31.62050	149.6954	-1.900140
31.67216	149.6939	-1.901812
31.72383	149.6945	-1.903462
31.77550	149.6941	-1.905076
31.82717	149.6946	-1.906686
31.87883	149.6944	-1.908262
31.93050	149.6939	-1.909870
31.98216	149.6941	-1.911488
32.03383	149.6944	-1.913066
32.08383	149.6931	-1.914605
32.13716	149.6930	-1.916201
32.18716	149.6940	-1.917696
32.24050	149.6936	-1.919225
32.29050	149.6933	-1.920646
32.34384	149.6938	-1.922174
32.39383	149.6936	-1.923526
32.44717	149.6940	-1.924962
32.49716	149.6935	-1.926256
32.55050	149.6936	-1.927654
32.60050	149.6934	-1.928959
32.65383	149.6924	-1.930353
32.70383	149.6928	-1.931692
32.75550	149.6929	-1.933046
32.80716	149.6925	-1.934389
32.85883	149.6930	-1.935732
32.91050	149.6923	-1.937014
32.96216	149.6928	-1.938312
33.01383	149.6926	-1.939615
33.06550	149.6921	-1.940884
33.11716	149.6924	-1.942163
33.16716	149.6924	-1.943430
33.22050	149.6923	-1.944750
33.27050	149.6916	-1.945925
33.32383	149.6924	-1.947189
33.37383	149.6921	-1.948396
33.42717	149.6922	-1.949632
33.47717	149.6918	-1.950767
33.53050	149.6914	-1.951982
33.58050	149.6918	-1.953080
33.63383	149.6918	-1.954276
33.68384	149.6921	-1.955376
33.73717	149.6918	-1.956550
33.78717	149.6918	-1.957591
33.83883	149.6913	-1.958665
33.89050	149.6914	-1.959742
33.94216	149.6912	-1.960767
33.99383	149.6906	-1.961816
34.04550	149.6914	-1.962892
34.09716	149.6911	-1.963970
34.14883	149.6909	-1.965052
34.20050	149.6914	-1.966101
34.25050	149.6899	-1.967090
34.30383	149.6911	-1.968144
34.35383	149.6910	-1.969136
34.40716	149.6904	-1.970178
34.45716	149.6902	-1.971118
34.51050	149.6909	-1.972174
34.56050	149.6907	-1.973113
34.61383	149.6904	-1.974097
34.66383	149.6920	-1.975017
34.71716	149.6909	-1.976000
34.76716	149.6904	-1.976919
34.82050	149.6905	-1.977909
34.87050	149.6915	-1.978821
34.92216	149.6905	-1.979709
34.97383	149.6898	-1.980570
35.02550	149.6901	-1.981432
35.07717	149.6906	-1.982252
35.12883	149.6904	-1.983051
35.18050	149.6896	-1.983845
35.23216	149.6903	-1.984642
35.28383	149.6902	-1.985394
35.33383	149.6901	-1.986149
35.38716	149.6902	-1.986937
35.43716	149.6904	-1.987705
35.49050	149.6903	-1.988536
35.54050	149.6902	-1.989306
35.59384	149.6904	-1.990115
35.64383	149.6900	-1.990872
35.69717	149.6898	-1.991661
35.74716	149.6891	-1.992383
35.80050	149.6895	-1.993165
35.85050	149.6893	-1.993941
35.90383	149.6896	-1.994713
35.95383	149.6898	-1.995407
36.00550	149.6890	-1.996108
36.05716	149.6904	-1.996843
36.10883	149.6892	-1.997537
36.16050	149.6889	-1.998223
36.21216	149.6893	-1.998870
36.26383	149.6895	-1.999509
36.31550	149.6892	-2.000127
36.36716	149.6889	-2.000694
36.41716	149.6886	-2.001279
36.47050	149.6891	-2.001879
36.52050	149.6890	-2.002484
36.57383	149.6889	-2.003082
36.62383	149.6890	-2.003667
36.67717	149.6885	-2.004307
36.72717	149.6884	-2.004889
36.78050	149.6885	-2.005545
36.83050	149.6893	-2.006200
36.88383	149.6889	-2.006817
36.93384	149.6890	-2.007362
36.98717	149.6892	-2.007882
37.03717	149.6892	-2.008411
37.08883	149.6890	-2.008923
37.14050	149.6892	-2.009405
37.19216	149.6887	-2.009954
37.24383	149.6904	-2.010502
37.29550	149.6896	-2.011038
37.34716	149.6886	-2.011551
37.39883	149.6893	-2.012095
37.45050	149.6886	-2.012611
37.50050	149.6894	-2.013161
37.55383	149.6894	-2.013682
37.60383	149.6888	-2.014234
37.65716	149.6887	-2.014741
37.70716	149.6899	-2.015236
37.76050	149.6894	-2.015764
37.81050	149.6886	-2.016212
37.86383	149.6888	-2.016690
37.91383	149.6892	-2.017134
37.96716	149.6896	-2.017600
38.01716	149.6888	-2.018020
38.07050	149.6882	-2.018457
38.12050	149.6889	-2.018831
38.17216	149.6884	-2.019199
38.22383	149.6888	-2.019550
38.27550	149.6885	-2.019902
38.32717	149.6886	-2.020302
38.37883	149.6885	-2.020723
38.43050	149.6885	-2.021156
38.48216	149.6882	-2.021545
38.53383	149.6884	-2.021966
38.58383	149.6885	-2.022318
38.63716	149.6879	-2.022709
38.68716	149.6879	-2.023059
38.74050	149.6884	-2.023463
38.79050	149.6892	-2.023775
38.84384	149.6887	-2.024063
38.89383	149.6886	-2.024324
38.94717	149.6880	-2.024672
38.99716	149.6888	-2.024971
39.05050	149.6884	-2.025290
39.10050	149.6878	-2.025531
39.15383	149.6885	-2.025806
39.20383	149.6882	-2.026067
39.25550	149.6884	-2.026346
39.30716	149.6886	-2.026604
39.35883	149.6880	-2.026899
39.41050	149.6882	-2.027184
39.46216	149.6880	-2.027525
39.51383	149.6884	-2.027884
39.56550	149.6880	-2.028215
39.61716	149.6883	-2.028545
39.66716	149.6886	-2.028855
39.72050	149.6879	-2.029186
39.77050	149.6880	-2.029504
39.82383	149.6883	-2.029839
39.87383	149.6882	-2.030138
39.92717	149.6882	-2.030478
39.97717	149.6885	-2.030770
40.03050	149.6876	-2.031002
40.08050	149.6884	-2.031235
40.13383	149.6872	-2.031432
40.18384	149.6880	-2.031686
40.23717	149.6875	-2.031951
40.28717	149.6875	-2.032169
40.33883	149.6883	-2.032421
40.39050	149.6875	-2.032628
40.44216	149.6878	-2.032849
40.49383	149.6883	-2.033104
40.54550	149.6876	-2.033298
40.59716	149.6877	-2.033557
40.64883	149.6874	-2.033772
40.70050	149.6879	-2.034015
40.75050	149.6875	-2.034170
40.80383	149.6881	-2.034396
40.85383	149.6876	-2.034604
40.90716	149.6878	-2.034811
40.95716	149.6879	-2.035038
41.01050	149.6885	-2.035288
41.06050	149.6879	-2.035468
41.11383	149.6872	-2.035645
41.16383	149.6871	-2.035847
41.21717	149.6881	-2.036067
41.26717	149.6880	-2.036244
41.32050	149.6873	-2.036416
41.37050	149.6876	-2.036583
41.42216	149.6883	-2.036827
41.47383	149.6881	-2.037054
41.52550	149.6875	-2.037258
41.57717	149.6873	-2.037475
41.62883	149.6876	-2.037717
41.68050	149.6886	-2.037981
41.73217	149.6879	-2.038227
41.78383	149.6887	-2.038480
41.83383	149.6885	-2.038720
41.88716	149.6880	-2.038939
41.93716	149.6875	-2.039126
41.99050	149.6880	-2.039364
42.04050	149.6872	-2.039469
42.09384	149.6879	-2.039602
42.14383	149.6878	-2.039724
42.19717	149.6877	-2.039866
42.24716	149.6874	-2.039998
42.30050	149.6868	-2.040114
42.35050	149.6882	-2.040268
42.40383	149.6872	-2.040415
42.45383	149.6874	-2.040547
42.50550	149.6880	-2.040725
42.55717	149.6874	-2.040862
42.60883	149.6880	-2.040973
42.66050	149.6884	-2.041148
42.71216	149.6876	-2.041268
42.76383	149.6884	-2.041447
42.81550	149.6876	-2.041577
42.86716	149.6883	-2.041761
42.91716	149.6878	-2.041896
42.97050	149.6880	-2.042000
43.01717	149.6879	-2.042175
43.07050	149.8096	-2.280662
43.12050	150.2696	-3.600472
43.17216	150.9006	-5.211613
43.22383	151.6371	-6.750000
43.27550	152.4451	-8.025474
43.32717	153.3047	-9.042921
43.37883	154.2019	-9.844562
43.43050	155.1267	-10.44539
43.48217	156.0730	-10.92132
43.53383	157.0363	-11.28629
43.58383	157.9793	-11.56374
43.63716	158.9951	-11.80048
43.68716	159.9552	-11.97111
43.74050	160.9846	-12.12388
43.79050	161.9551	-12.24355
43.84384	162.9926	-12.35680
43.89383	163.9691	-12.45124
43.94717	165.0122	-12.54970
43.99716	165.9935	-12.64424
44.05050	167.0397	-12.73186
44.10050	168.0234	-12.80939
44.15383	169.0731	-12.89128
44.20383	170.0598	-12.97696
44.25550	171.0778	-13.06143
44.30717	172.0986	-13.15505
44.35883	173.1190	-13.24391
44.41050	174.1405	-13.33199
44.46216	175.1629	-13.42480
44.51383	176.1864	-13.52726
44.56550	177.2085	-13.62993
44.61716	178.2327	-13.73002
44.66716	179.2222	-13.84061
44.72050	180.2794	-13.96126
44.77050	181.2700	-14.07375
44.82383	182.3255	-14.20787
44.87383	183.3158	-14.33680
44.92717	184.3727	-14.46329
44.97717	185.3630	-14.59082
45.03050	186.4205	-14.73208
45.08050	187.4117	-14.86604
45.13383	188.4691	-15.01860
45.18383	189.4606	-15.16736
45.23717	190.5165	-15.32863
45.28717	191.5072	-15.49094
45.33883	192.5304	-15.67198
45.39050	193.5521	-15.85454
45.44217	194.5745	-16.05495
45.49383	195.5946	-16.29506
45.54550	196.6146	-16.57068
45.59716	197.6333	-16.82236
45.64883	198.6496	-17.16330
45.70050	199.6642	-17.48608
45.75050	200.6463	-17.77695
45.80383	201.6946	-18.10166
45.85383	202.6759	-18.46298
45.90717	203.7201	-18.90331
45.95717	204.6978	-19.33997
46.01050	205.7345	-19.89076
46.06050	206.7044	-20.49092
46.11383	207.7327	-21.25846
46.16383	208.6915	-22.12211
46.21717	209.7036	-23.27092
46.26717	210.6414	-24.63670
46.32050	211.6250	-26.41759
46.37050	212.5285	-28.42514
46.42216	213.4438	-30.79078
46.47383	214.3416	-33.41295
46.52550	215.2254	-36.13452
46.57717	216.1030	-38.77513
46.62883	216.9876	-40.96676
46.68050	217.8897	-42.76708
46.73217	218.8082	-44.37110
46.78383	219.7491	-45.21382
46.83383	220.7072	-44.49148
46.88716	221.8394	-40.24670
46.93716	223.0280	-34.93552
46.99050	224.3814	-28.64152
47.04050	225.6726	-24.53856
47.09384	226.9877	-21.94292
47.14383	228.1618	-20.21744
47.19717	229.3665	-18.86594
47.24716	230.4638	-17.93222
47.30050	231.6054	-17.21058
47.35050	232.6570	-16.68942
47.40383	233.7634	-16.31061
47.45383	234.7920	-16.04346
47.50550	235.8473	-15.84093
47.55717	236.8963	-15.70876
47.60883	237.9402	-15.61296
47.66050	238.9831	-15.55116
47.71216	240.0220	-15.52032
47.76383	241.0594	-15.50277
47.81550	242.0949	-15.49702
47.86716	243.1300	-15.49530
47.91716	244.1302	-15.49494
47.97050	245.1967	-15.49538
48.02050	246.1965	-15.49730
48.07383	247.2635	-15.50256
48.12383	248.2628	-15.51165
48.17717	249.3291	-15.52642
48.22717	250.3286	-15.54677
48.28050	251.3956	-15.57037
48.33050	252.3950	-15.59641
48.38383	253.4611	-15.62442
48.43383	254.4586	-15.65026
48.48717	255.5238	-15.67985
48.53717	256.5215	-15.72527
48.58883	257.5536	-15.76599
48.64050	258.5853	-15.80721
48.69217	259.6168	-15.85322
48.74383	260.6494	-15.89277
48.79550	261.6797	-15.92879
48.84716	262.7106	-15.96406
48.89883	263.7425	-16.00122
48.95050	264.7736	-16.05222
49.00050	265.7696	-16.16150
49.05383	266.8338	-16.20972
49.10383	267.8305	-16.24274
49.15717	268.8951	-16.29014
49.20717	269.8919	-16.33971
49.26050	270.9568	-16.37595
49.31050	271.9555	-16.40718
49.36383	273.0217	-16.43576
49.41383	274.0201	-16.45334
49.46717	275.0850	-16.46384
49.51383	276.0170	-16.49611
49.56550	276.8206	-16.32108
49.61716	276.8490	-16.25316
49.66716	276.5676	-13.44507
49.72050	276.0620	-9.692655
49.77050	275.4633	-6.406740
49.82383	274.7294	-3.490635
49.87383	273.9736	-1.320783
49.92717	273.1133	0.4709030
49.97717	272.2681	1.761900
50.03050	271.3358	2.802990
50.08050	270.4382	3.553595
50.13383	269.4645	4.157382
50.18383	268.5367	4.592381
50.23717	267.5362	4.960390
50.28717	266.5884	5.222049
50.33883	265.6032	5.438818
50.39050	264.6113	5.612488
50.44217	263.6150	5.744735
50.49383	262.6139	5.860429
50.54550	261.6102	5.958008
50.59716	260.6039	6.039512
50.64883	259.5953	6.105787
50.70050	258.5830	6.169492
50.75050	257.6036	6.222336
50.80383	256.5570	6.274482
50.85383	255.5742	6.318208
50.90717	254.5234	6.360965
50.95717	253.5388	6.400696
51.01050	252.4876	6.438564
51.06050	251.4990	6.471776
51.11383	250.4465	6.504062
51.16383	249.4596	6.533718
51.21717	248.4051	6.567755
51.26716	247.4166	6.599019
51.32050	246.3615	6.631026
51.37050	245.3718	6.658812
51.42217	244.3481	6.690124
51.47383	243.3252	6.715561
51.52550	242.3016	6.740528
51.57717	241.2762	6.764344
51.62883	240.2530	6.789663
51.68050	239.2275	6.813932
51.73217	238.2030	6.837390
51.78383	237.1780	6.859330
51.83383	236.1869	6.881792
51.88716	235.1289	6.904010
51.93716	234.1367	6.928769
51.99050	233.0784	6.951765
52.04050	232.0860	6.973199
52.09384	231.0282	6.995220
52.14384	230.0363	7.017157
52.19717	228.9779	7.043843
52.24717	227.9854	7.070376
52.30050	226.9260	7.097387
52.35050	225.9334	7.122687
52.40383	224.8745	7.148032
52.45383	223.8826	7.170650
52.50550	222.8553	7.195063
52.55717	221.8293	7.220069
52.60883	220.8018	7.242626
52.66050	219.7768	7.264261
52.71216	218.7505	7.285375
52.76382	217.7230	7.306664
52.81550	216.6961	7.328670
52.86716	215.6682	7.349149
52.91716	214.6748	7.366470
52.97050	213.6136	7.382830
53.02050	212.6194	7.398584
53.07383	211.5594	7.415645
53.12383	210.5650	7.429849
53.17717	209.5052	7.446021
53.22717	208.5116	7.461418
53.28050	207.4510	7.477156
53.33050	206.4569	7.494302
53.38383	205.3964	7.511485
53.43383	204.4017	7.527703
53.48717	203.3417	7.545069
53.53716	202.3462	7.560054
53.58882	201.3194	7.572352
53.64050	200.2919	7.584488
53.69216	199.2644	7.600562
53.74382	198.2376	7.614084
53.79550	197.2101	7.630606
53.84716	196.1814	7.647032
53.89883	195.1546	7.664108
53.95050	194.1266	7.684492
54.00050	193.1317	7.702088
54.05383	192.0714	7.718442
54.10383	191.0765	7.734045
54.15717	190.0157	7.748919
54.20717	189.0205	7.764362
54.26050	187.9604	7.778706
54.31050	186.9664	7.792715
54.36382	185.9044	7.809900
54.41382	184.9091	7.825012
54.46717	183.8477	7.839358
54.51716	182.8514	7.850552
54.57050	181.7910	7.862139
54.62050	180.7952	7.872324
54.67217	179.7670	7.883170
54.72382	178.7402	7.895761
54.77550	177.7126	7.912064
54.82717	176.6848	7.933816
54.87883	175.6576	7.958151
54.93050	174.6306	7.995700
54.98217	173.6037	8.050361
55.03383	172.5777	8.125152
55.08383	171.5846	8.222901
55.13716	170.5266	8.341000
55.18716	169.5366	8.462460
55.24050	168.4809	8.592606
55.29050	167.4916	8.728303
55.34384	166.4382	8.928238
55.39384	165.4543	9.180152
55.44717	164.4097	9.603538
55.49717	163.4394	10.17838
55.55050	162.4180	11.10837
55.60050	161.4795	12.34184
55.65383	160.5014	14.07873
55.70383	159.6082	16.04866
55.75550	158.7060	18.25623
55.80717	157.8138	20.42867
55.85883	156.9207	22.36308
55.91050	156.0140	23.90419
55.96216	155.0863	24.92664
56.01382	154.1290	25.39457
56.06550	153.1366	25.29989
56.11716	152.1083	24.72343
56.16716	151.0825	23.68695
56.22050	149.9605	22.30192
56.27050	148.8870	20.85659
56.32383	147.7303	19.26896
56.37383	146.6407	17.84206
56.42717	145.4804	16.43323
56.47717	144.3975	15.26666
56.53050	143.2540	14.22650
56.58050	142.1905	13.40565
56.63383	141.0675	12.69437
56.68383	140.0244	12.15571
56.73717	138.9219	11.70735
56.78716	137.8949	11.36184
56.83882	136.8394	11.07556
56.89050	135.7905	10.85018
56.94216	134.7441	10.67313
56.99382	133.7014	10.52979
57.04550	132.6615	10.41599
57.09716	131.6226	10.32330
57.14883	130.5860	10.24297
57.20050	129.5498	10.18480
57.25050	128.5498	10.13864
57.30383	127.4820	10.09698
57.35383	126.4826	10.06596
57.40717	125.4168	10.03637
57.45717	124.4181	10.01250
57.51050	123.3535	9.990918
57.56050	122.3570	9.969709
57.61382	121.2912	9.953824
57.66382	120.2932	9.935131
57.71717	119.2297	9.923756
57.76716	118.2322	9.908644
57.82050	117.1663	9.813915
57.87050	116.1657	9.759253
57.92217	115.1329	9.722124
57.97382	114.1009	9.694103
58.02550	113.0681	9.674399
58.07717	112.0364	9.655954
58.12883	111.0045	9.634141
58.18050	109.9726	9.611632
58.23217	108.9403	9.585456
58.28383	107.9082	9.555047
58.33383	106.9106	9.530634
58.38716	105.8458	9.511574
58.43716	104.8476	9.494789
58.49050	103.7828	9.477914
58.54050	102.7847	9.465222
58.59384	101.7209	9.451000
58.64384	100.7226	9.438894
58.69717	99.65924	9.426522
58.74717	98.66108	9.416762
58.80050	97.59699	9.406455
58.85050	96.60072	9.396742
58.90383	95.53700	9.386000
58.95383	94.53852	9.377012
59.00550	93.50741	9.365699
59.05717	92.47687	9.356434
59.10883	91.44394	9.345001
59.16050	90.41269	9.331652
59.21216	89.38212	9.314300
59.26382	88.35113	9.299445
59.31550	87.31951	9.282962
59.36716	86.28718	9.266931
59.41716	85.28978	9.247820
59.47050	84.22582	9.225439
59.52050	83.22850	9.204925
59.57383	82.16353	9.186195
59.62383	81.16553	9.172281
59.67717	80.10141	9.157709
59.72717	79.10434	9.144132
59.78050	78.04084	9.133270
59.83050	77.04266	9.121793
59.88383	75.97790	9.111042
59.93383	74.98050	9.100138
59.98717	73.91605	9.085375
60.03716	72.91837	9.074406
60.08882	71.88712	9.060889
60.14050	70.85651	9.049820
60.19216	69.82470	9.037798
60.24382	68.79394	9.024026
60.29550	67.76362	9.009340
60.34716	66.73297	8.996168
60.39883	65.70124	8.983192
60.45050	64.67011	8.967988
60.50050	63.67110	8.953781
60.55383	62.60704	8.936545
60.60383	61.60735	8.916671
60.65717	60.54366	8.893863
60.70717	59.54566	8.874931
60.76050	58.48192	8.853014
60.81050	57.48400	8.837368
60.86382	56.42124	8.816499
60.91382	55.42288	8.798018
60.96717	54.35813	8.783319
61.01716	53.35928	8.761824
61.07050	52.29452	8.742019
61.12050	51.29566	8.716952
61.17217	50.26418	8.688618
61.22382	49.23198	8.669845
61.27550	48.20068	8.645924
61.32717	47.16874	8.626334
61.37883	46.13783	8.605785
61.43050	45.10634	8.583081
61.48217	44.07438	8.562334
61.53383	43.04203	8.543407
61.58383	42.04378	8.521137
61.63716	40.97943	8.495689
61.68716	39.97913	8.470306
61.74050	38.91460	8.437905
61.79050	37.91440	8.402579
61.84384	36.84963	8.354100
61.89384	35.84963	8.316438
61.94717	34.78366	8.274586
61.99717	33.78332	8.230461
62.05050	32.71634	8.189895
62.10050	31.71735	8.146613
62.15383	30.64930	8.103306
62.20383	29.64920	8.061638
62.25550	28.61464	8.020029
62.30717	27.58198	7.984806
62.35883	26.54880	7.930313
62.41050	25.51520	7.877888
62.46216	24.48116	7.848119
62.51050	23.51408	7.846150
62.56050	22.65030	7.854956
62.61382	22.42767	5.867796
62.66382	22.56920	3.274053
62.71717	22.97536	0.7461785
62.76716	23.51470	-1.137412
62.82050	24.21564	-2.695994
62.87050	24.95723	-3.805458
62.92217	25.78574	-4.673466
62.97382	26.66013	-5.328132
63.02550	27.56992	-5.826324
63.07717	28.50412	-6.193285
63.12883	29.45750	-6.483204
63.18050	30.42473	-6.703682
63.23217	31.40242	-6.869245
63.28383	32.38887	-6.999116
63.33383	33.34884	-7.098919
63.38716	34.37738	-7.182171
63.43716	35.34852	-7.250132
63.49050	36.38575	-7.307555
63.54050	37.35986	-7.353220
63.59384	38.40347	-7.396930
63.64384	39.38380	-7.431176
63.69717	40.42905	-7.464308
63.74717	41.41120	-7.491265
63.80050	42.46050	-7.521376
63.85050	43.44512	-7.547768
63.90383	44.49700	-7.581726
63.95383	45.48365	-7.609759
64.00550	46.50581	-7.642600
64.05717	47.52816	-7.676410
64.10884	48.55034	-7.711765
64.16050	49.57381	-7.746164
64.21217	50.59634	-7.781669
64.26384	51.62000	-7.820344
64.31550	52.64410	-7.858426
64.36718	53.66899	-7.902685
64.41717	54.66078	-7.937826
64.47050	55.72002	-7.979900
64.52050	56.71320	-8.019634
64.57384	57.77270	-8.061235
64.62383	58.76584	-8.102813
64.67718	59.82586	-8.144818
64.72718	60.82029	-8.186515
64.78050	61.87934	-8.233500
64.83050	62.87339	-8.278766
64.88384	63.93308	-8.327775
64.93384	64.92795	-8.371358
64.98717	65.98828	-8.416930
65.03717	66.98270	-8.466637
65.08884	68.01064	-8.516991
65.14050	69.03993	-8.567609
65.19217	70.06892	-8.611965
65.24384	71.09780	-8.658468
65.29550	72.12699	-8.704913
65.34717	73.15578	-8.751593
65.39883	74.18439	-8.800219
65.45050	75.21215	-8.849049
65.50050	76.20884	-8.900793
65.55384	77.27056	-8.955179
65.60384	78.26674	-9.004762
65.65718	79.32657	-9.061103
65.70718	80.32319	-9.115324
65.76050	81.38432	-9.174120
65.81050	82.38038	-9.226449
65.86384	83.44232	-9.285535
65.91382	84.43778	-9.338319
65.96718	85.50089	-9.402704
66.01716	86.49776	-9.455429
66.07050	87.55976	-9.509619
66.12050	88.55728	-9.565294
66.17218	89.58687	-9.619869
66.22384	90.61676	-9.677512
66.27550	91.64666	-9.735089
66.32718	92.67618	-9.787480
66.37884	93.70614	-9.843468
66.43050	94.73626	-9.905251
66.48218	95.76641	-9.964106
66.53384	96.79638	-10.01745
66.58384	97.79374	-10.06914
66.63718	98.85636	-10.12729
66.68718	99.85430	-10.18282
66.74050	100.9180	-10.23546
66.79050	101.9143	-10.29190
66.84384	102.9780	-10.35312
66.89384	103.9742	-10.40857
66.94718	105.0366	-10.47098
66.99718	106.0346	-10.53169
67.05050	107.0972	-10.59135
67.10050	108.0948	-10.65127
67.15384	109.1588	-10.70613
67.20384	110.1573	-10.76291
67.25550	111.1879	-10.82072
67.30718	112.2188	-10.87978
67.35884	113.2498	-10.93572
67.41050	114.2796	-10.98972
67.46218	115.3090	-11.04983
67.51384	116.3384	-11.11146
67.56550	117.3678	-11.17543
67.61718	118.3979	-11.23873
67.66718	119.3947	-11.30030
67.72050	120.4576	-11.37550
67.77050	121.4535	-11.43456
67.82384	122.5156	-11.51036
67.87384	123.5114	-11.57736
67.92718	124.5734	-11.65246
67.97718	125.5705	-11.72310
68.03050	126.6325	-11.79818
68.08050	127.6294	-11.86556
68.13384	128.6922	-11.93399
68.18384	129.6894	-11.99982
68.23718	130.7524	-12.07516
68.28718	131.7497	-12.13985
68.33884	132.7796	-12.20325
68.39050	133.8082	-12.27836
68.44218	134.8373	-12.35676
68.49384	135.8658	-12.43538
68.54550	136.8940	-12.51810
68.59718	137.9216	-12.60254
68.64884	138.9509	-12.68963
68.70050	139.9789	-12.77178
68.75050	140.9746	-12.85675
68.80384	142.0354	-12.94667
68.85384	143.0302	-13.03570
68.90718	144.0920	-13.12759
68.95718	145.0864	-13.21496
69.01050	146.1472	-13.30211
69.06050	147.1423	-13.39033
69.11384	148.2045	-13.47881
69.16382	149.2001	-13.55563
69.21718	150.2626	-13.64610
69.26716	151.2583	-13.73313
69.32050	152.3202	-13.81211
69.37050	153.3150	-13.89748
69.42218	154.3441	-13.98429
69.47384	155.3725	-14.06457
69.52550	156.4003	-14.15890
69.57718	157.4294	-14.22913
69.62884	158.4588	-14.29868
69.68050	159.4883	-14.34839
69.73218	160.5178	-14.38752
69.78384	161.5482	-14.42409
69.83384	162.5464	-14.45099
69.88718	163.6115	-14.47136
69.93718	164.6108	-14.48522
69.99050	165.6769	-14.49776
70.04050	166.6763	-14.51424
70.09384	167.7427	-14.53547
70.14384	168.7426	-14.56481
70.19718	169.8067	-14.61075
70.24718	170.8036	-14.67727
70.30050	171.8683	-14.76107
70.35050	172.8653	-14.84160
70.40384	173.9281	-14.92865
70.45384	174.9254	-15.01304
70.50550	175.9528	-15.11104
70.55718	176.9808	-15.21431
70.60884	178.0085	-15.32746
70.66050	179.0360	-15.46685
70.71218	180.0621	-15.60662
70.76384	181.0879	-15.76148
70.81550	182.1123	-15.93135
70.86718	183.1356	-16.11991
70.91718	184.1244	-16.32868
70.97050	185.1785	-16.58177
71.02050	186.1647	-16.84360
71.07384	187.2144	-17.16248
71.12384	188.1973	-17.45856
71.17718	189.2451	-17.81787
71.22718	190.2247	-18.17045
71.28050	191.2692	-18.57356
71.33050	192.2472	-18.96251
71.38384	193.2885	-19.39914
71.43384	194.2645	-19.80490
71.48718	195.3047	-20.26662
71.53718	196.2793	-20.73856
71.58884	197.2820	-21.28562
71.64050	198.2844	-21.89076
71.69218	199.2822	-22.56096
71.74384	200.2767	-23.29901
71.79550	201.2671	-24.08746
71.84718	202.2539	-24.91487
71.89884	203.2380	-25.75162
71.95050	204.2215	-26.56164
72.00050	205.1744	-27.28634
72.05384	206.1975	-27.84200
72.10384	207.1682	-28.01856
72.15718	208.2262	-27.72410
72.20718	209.2542	-26.20762
72.26050	210.3995	-23.78758
72.31050	211.5166	-21.17296
72.36384	212.7204	-19.12283
72.41382	213.8296	-17.93312
72.46718	214.9830	-17.08790
72.51716	216.0430	-16.53491
72.57050	217.1542	-16.12029
72.62050	218.1851	-15.85456
72.67218	219.2405	-15.64788
72.72384	220.2885	-15.53093
72.77550	221.3340	-15.44765
72.82718	222.3744	-15.39287
72.87884	223.4123	-15.36787
72.93050	224.4489	-15.35559
72.98218	225.4841	-15.35070
73.03384	226.5172	-15.34994
73.08384	227.5176	-15.35025
73.13718	228.5844	-15.35194
73.18718	229.5833	-15.35772
73.24050	230.6487	-15.36964
73.29050	231.6478	-15.38740
73.34384	232.7120	-15.41519
73.39384	233.7108	-15.44790
73.44718	234.7754	-15.48535
73.49718	235.7733	-15.52072
73.55050	236.8379	-15.55640
73.60050	237.8357	-15.59320
73.65384	238.9008	-15.62814
73.70384	239.8982	-15.66455
73.75550	240.9294	-15.70376
73.80718	241.9610	-15.75011
73.85884	242.9914	-15.79380
73.91050	244.0238	-15.83523
73.96218	245.0551	-15.87518
74.01384	246.0866	-15.91047
74.06550	247.1182	-15.94646
74.11718	248.1489	-15.98163
74.16718	249.1472	-16.01503
74.22050	250.2116	-16.05757
74.27050	251.2086	-16.09323
74.32384	252.2736	-16.13673
74.37384	253.2720	-16.17545
74.42718	254.3358	-16.21319
74.47718	255.3333	-16.25152
74.53050	256.3982	-16.30320
74.58050	257.3947	-16.34658
74.63384	258.4587	-16.39116
74.68384	259.4566	-16.44619
74.73718	260.5198	-16.50208
74.78718	261.5163	-16.55451
74.83884	262.5476	-16.62158
74.89050	263.5776	-16.66759
74.94218	264.6079	-16.72267
74.99384	265.6378	-16.78314
75.04550	266.6682	-16.85132
75.09718	267.6978	-16.92248
75.14884	268.7271	-17.00123
75.20050	269.7570	-17.11413
75.25050	270.7529	-17.18882
75.30384	271.8103	-17.76870
-2.000000	5.000000	0.0000000