File: 9-C1(1.2mol%)+C20(1.0mol%)/matlab/160-1.txt
CLOSED
Version	1.0
Language	English
Mode	Standard
Run	8
RunSerial	12276
Instrument	DSC Q2000 V24.11 Build 124
Module	DSC Standard Cell RC
Operator
File	\\AE520-1454\Users\dsc\Desktop\Data\29-08-17\160-1.001
ProcName
InstSerial	2000-0883
AutoSerial	1293
Sample	160-1
Size	13.4000	mg
PanMass	Not available
PanResist	Automatic Automatic  K/W
PanFactor	Default Default
Method
Comment
Xcomment	Pan: Tzero Aluminum Hermetic
Xcomment	Gas1: Nitrogen 50.0 ml/min
Xcomment	Gas2: Nitrogen 50.0 ml/min
Text
Exotherm	UP
Kcell	1.05230
Cpconst	Standard: 0.938
Calib	-38.6961
TempCal	1	pts	157.46	156.60
TzeroDt	-87.6168 -0.0009 -1.4231
TzeroDtz	-87.6168 0.0057 6.9570
InstCalFile	Tzero: \\Ae520-1454\ta\Data\DSC\Calibration\2017\CALIBRATION\1562_RCS (90)_05_18_2017 10_50_44.TZR
InstCalFile	Baseline: \\Ae520-1454\ta\Data\DSC\Calibration\2017\2017-05-17_Calibration.001
InstCalFile	Sapphire: \\Ae520-1454\ta\Data\DSC\Calibration\2017\2017-05-17_Saphire.001
InstCalDate	Tzero 2017-05-18 Time 10:50:44
TempRange	-87.39 to 398.39 °C at 10.00 °C/min Heat Only
AutoZero	Delta T Offset 0.000 uV
AutoZero	Delta T0 Offset 0.000 uV
MultiptCal	0
MultiPtDesc	0) Not set
AutoCellConst	Calibration Date 2017-05-18 16:59:28
Controls	Gas 1  Event Off  Sampling 0.2
Cell#	RC-01562
CoolingUnit	RCS (90)
SelHeatFlow	Heat Flow T4P (mW)
AutoLidII	Installed
AutoAnalysis	Off
MacroFile
Nsig	3
Sig1	Time (min)
Sig2	Temperature (°C)
Sig3	Heat Flow (mW)
Date	2017-08-29
Time	20:54:11
OrgMethod	1: Equilibrate at 80.00 °C
OrgMethod	2: Isothermal for 3.00 min
OrgMethod	3: Jump to 160.00 °C
OrgMethod	4: Mark end of cycle 1
OrgMethod	5: Isothermal for 40.00 min
OrgMethod	6: Mark end of cycle 2
OrgMethod	7: Ramp 20.00 °C/min to 280.00 °C
OrgMethod	8: Mark end of cycle 3
OrgMethod	9: Ramp 20.00 °C/min to 20.00 °C
OrgMethod	10: Mark end of cycle 4
OrgMethod	11: Ramp 20.00 °C/min to 280.00 °C
OrgMethod	12: Mark end of cycle 5
OrgFile	C:\Users\jarra\Desktop\DSC\9-C1(1.2mol%)+C20(1.0mol%)\160-1.001
StartOfData
4.99994E-4	79.87242	-1.585522
0.05383332	79.89063	-1.306627
0.1038333	79.90118	-1.108485
0.1555000	79.90964	-0.9533888
0.2071666	79.91516	-0.8362640
0.2571667	79.91853	-0.7524668
0.3105000	79.92162	-0.6878000
0.3605000	79.92343	-0.6432221
0.4121666	79.92341	-0.6095960
0.4638333	79.92461	-0.5863907
0.5138333	79.92299	-0.5706283
0.5655000	79.92329	-0.5606239
0.6171668	79.92255	-0.5541100
0.6671668	79.92035	-0.5497982
0.7205000	79.91987	-0.5463274
0.7705000	79.91944	-0.5430146
0.8221666	79.91822	-0.5395331
0.8738332	79.91690	-0.5360595
0.9238334	79.91584	-0.5327294
0.9755000	79.91482	-0.5293865
1.027167	79.91301	-0.5261494
1.077166	79.91186	-0.5231861
1.130500	79.91128	-0.5202002
1.180500	79.91032	-0.5175666
1.232166	79.91040	-0.5149545
1.283834	79.90820	-0.5124538
1.333833	79.90793	-0.5102492
1.385500	79.90734	-0.5080904
1.437167	79.90570	-0.5060965
1.487166	79.90522	-0.5042456
1.540500	79.90463	-0.5024598
1.590500	79.90353	-0.5008683
1.642166	79.90306	-0.4993694
1.693833	79.90156	-0.4979566
1.743833	79.90072	-0.4966614
1.795500	79.90078	-0.4954648
1.847167	79.89970	-0.4943180
1.897167	79.89991	-0.4932957
1.950500	79.89903	-0.4923132
2.000500	79.89788	-0.4915019
2.052166	79.89786	-0.4907084
2.103833	79.89660	-0.4899368
2.153833	79.89564	-0.4892732
2.205500	79.89496	-0.4886711
2.257167	79.89452	-0.4881933
2.307167	79.89466	-0.4877512
2.360500	79.89372	-0.4873425
2.410500	79.89275	-0.4870109
2.462167	79.89250	-0.4867588
2.513833	79.89307	-0.4865680
2.563833	79.89249	-0.4864853
2.617167	79.89188	-0.4864019
2.667167	79.88999	-0.4863176
2.717167	79.89040	-0.4863250
2.770500	79.88905	-0.4863511
2.820500	79.88965	-0.4863990
2.872167	79.88944	-0.4864748
2.923834	79.88849	-0.4865693
2.973833	79.88838	-0.4867319
3.020500	79.92226	-0.6889438
3.073833	81.53044	-3.743484
3.123834	84.39164	-8.974603
3.175500	87.71337	-15.22877
3.227167	91.39369	-21.44173
3.277167	95.20528	-26.90250
3.328833	99.34218	-31.77729
3.380500	103.6220	-35.87824
3.430500	107.8650	-39.12640
3.483833	112.4684	-41.90606
3.533833	116.8293	-43.92504
3.585500	121.3647	-45.67247
3.637167	125.9185	-47.07852
3.687167	130.3365	-48.05776
3.738834	134.8997	-48.91440
3.790500	139.4555	-49.59892
3.840500	143.8642	-49.83391
3.893833	148.0925	-49.26652
3.943833	150.4377	-45.33585
3.995500	152.1928	-39.59761
4.047167	153.5348	-33.29749
4.097166	154.5583	-27.44948
4.150500	155.4268	-22.02623
4.200500	156.0808	-17.71669
4.250500	156.6156	-14.18748
4.303834	157.0818	-11.19173
4.353833	157.4435	-8.957524
4.405500	157.7544	-7.155380
4.457167	158.0155	-5.754636
4.507167	158.2292	-4.685761
4.560500	158.4220	-3.809976
4.610500	158.5778	-3.169625
4.660500	158.7131	-2.669498
4.713834	158.8374	-2.240596
4.763834	158.9378	-1.928562
4.815500	159.0299	-1.656542
4.867166	159.1096	-1.441089
4.917167	159.1785	-1.270635
4.970500	159.2421	-1.114145
5.020500	159.2962	-0.9860908
5.070500	159.3452	-0.8731522
5.123833	159.3915	-0.7644394
5.173834	159.4302	-0.6651675
5.225500	159.4678	-0.5702280
5.277168	159.4996	-0.4754280
5.327168	159.5294	-0.3850936
5.380500	159.5580	-0.2880164
5.430500	159.5837	-0.1939965
5.480500	159.6068	-.09623984
5.533832	159.6304	0.01195022
5.583832	159.6500	0.1133147
5.635500	159.6699	0.2275402
5.687168	159.6892	0.3404197
5.737168	159.7072	0.4609524
5.790500	159.7258	0.5910024
5.840500	159.7417	0.7197694
5.890500	159.7581	0.8494412
5.943832	159.7753	0.9984725
5.993834	159.7902	1.140530
6.045500	159.8070	1.293898
6.097168	159.8223	1.457736
6.147168	159.8380	1.618882
6.200500	159.8548	1.797661
6.250500	159.8699	1.974876
6.300500	159.8855	2.157452
6.353832	159.9022	2.359533
6.403832	159.9189	2.554424
6.455500	159.9353	2.762884
6.507168	159.9517	2.982708
6.557166	159.9683	3.200150
6.610500	159.9866	3.441718
6.660500	160.0030	3.669883
6.712168	160.0210	3.911596
6.763834	160.0394	4.156570
6.813834	160.0569	4.398847
6.865500	160.0747	4.647490
6.917168	160.0918	4.899148
6.967168	160.1105	5.139222
7.020500	160.1276	5.394828
7.070500	160.1442	5.620719
7.122168	160.1611	5.849259
7.173834	160.1754	6.069368
7.223834	160.1910	6.267370
7.275500	160.2052	6.475432
7.327168	160.2203	6.688187
7.377168	160.2361	6.924221
7.430500	160.2558	7.230225
7.480500	160.2783	7.563770
7.532166	160.3036	7.967859
7.583832	160.3342	8.425774
7.633832	160.3643	8.908180
7.685500	160.3994	9.421991
7.737168	160.4329	9.933576
7.787168	160.4651	10.40580
7.840500	160.4962	10.85827
7.890500	160.5221	11.22532
7.942168	160.5442	11.53259
7.993834	160.5610	11.76132
8.043834	160.5724	11.91228
8.095500	160.5801	12.00051
8.147168	160.5832	12.03030
8.197168	160.5839	12.02896
8.250500	160.5810	12.02447
8.300500	160.5772	11.96540
8.352168	160.5712	11.82922
8.403832	160.5641	11.70194
8.453834	160.5576	11.57992
8.505500	160.5501	11.45830
8.557168	160.5432	11.33781
8.607166	160.5357	11.21176
8.660499	160.5283	11.09325
8.710499	160.5198	10.97418
8.762168	160.5121	10.84847
8.813834	160.5049	10.73673
8.863834	160.4980	10.61853
8.917168	160.4901	10.49630
8.967168	160.4832	10.38175
9.017168	160.4766	10.28594
9.070500	160.4694	10.17855
9.120499	160.4641	10.08000
9.172168	160.4580	9.991434
9.223832	160.4526	9.905812
9.273834	160.4464	9.833253
9.327168	160.4432	9.763489
9.377168	160.4385	9.704658
9.427168	160.4355	9.652362
9.480500	160.4322	9.605157
9.530500	160.4291	9.564347
9.582168	160.4266	9.524231
9.633832	160.4244	9.484931
9.683832	160.4213	9.446298
9.737168	160.4194	9.401425
9.787168	160.4161	9.357941
9.837168	160.4142	9.311105
9.890500	160.4109	9.261818
9.940500	160.4074	9.216040
9.992166	160.4048	9.170541
10.04383	160.4025	9.128098
10.09383	160.4001	9.092499
10.14717	160.3981	9.063981
10.19717	160.3969	9.048788
10.24717	160.3961	9.042066
10.30050	160.3970	9.039047
10.35050	160.3977	9.036788
10.40217	160.3977	9.035004
10.45383	160.3974	9.033189
10.50384	160.3955	9.029644
10.55717	160.3925	8.992949
10.60717	160.3871	8.865958
10.65717	160.3775	8.676151
10.71050	160.3647	8.446591
10.76050	160.3495	8.183974
10.81216	160.3299	7.854642
10.86383	160.3058	7.484594
10.91383	160.2806	7.076259
10.96717	160.2502	6.600546
11.01717	160.2202	6.124156
11.06716	160.1881	5.628162
11.12050	160.1532	5.077622
11.17050	160.1194	4.562426
11.22217	160.0842	4.033795
11.27383	160.0513	3.514328
11.32383	160.0186	3.030096
11.37717	159.9861	2.537232
11.42717	159.9568	2.106070
11.47884	159.9298	1.693542
11.53050	159.9032	1.320193
11.58050	159.8822	0.9870034
11.63216	159.8619	0.6862558
11.68383	159.8436	0.4127120
11.73383	159.8281	0.1887546
11.78717	159.8140	-.02304859
11.83717	159.8014	-0.1960553
11.88883	159.7910	-0.3514892
11.94050	159.7814	-0.4888723
11.99050	159.7730	-0.6055176
12.04217	159.7657	-0.7125864
12.09383	159.7598	-0.8057728
12.14383	159.7539	-0.8850570
12.19717	159.7486	-0.9597914
12.24717	159.7441	-1.023548
12.29884	159.7404	-1.081448
12.35050	159.7366	-1.131354
12.40050	159.7338	-1.175402
12.45217	159.7304	-1.215306
12.50384	159.7285	-1.251572
12.55383	159.7267	-1.282699
12.60717	159.7242	-1.312266
12.65717	159.7214	-1.336482
12.70883	159.7203	-1.359104
12.76050	159.7186	-1.378926
12.81050	159.7161	-1.396947
12.86217	159.7154	-1.412965
12.91383	159.7142	-1.427329
12.96383	159.7130	-1.440792
13.01717	159.7114	-1.453140
13.06716	159.7109	-1.464740
13.11884	159.7099	-1.474990
13.17050	159.7090	-1.484675
13.22050	159.7091	-1.492282
13.27217	159.7084	-1.500283
13.32384	159.7060	-1.507909
13.37384	159.7062	-1.514916
13.42717	159.7046	-1.522715
13.47717	159.7047	-1.529988
13.52883	159.7045	-1.537746
13.58050	159.7032	-1.545507
13.63050	159.7037	-1.553043
13.68383	159.7030	-1.561124
13.73383	159.7025	-1.568644
13.78383	159.7014	-1.576094
13.83717	159.7014	-1.584017
13.88717	159.7013	-1.591386
13.93883	159.7010	-1.598907
13.99050	159.7010	-1.606342
14.04050	159.6997	-1.613473
14.09383	159.6990	-1.620969
14.14383	159.7000	-1.627888
14.19384	159.6990	-1.634718
14.24717	159.6994	-1.641828
14.29717	159.6989	-1.648363
14.34883	159.6988	-1.655035
14.40050	159.6979	-1.661506
14.45050	159.6978	-1.667666
14.50383	159.6984	-1.674156
14.55383	159.6973	-1.680079
14.60383	159.6974	-1.685844
14.65717	159.6976	-1.691892
14.70717	159.6974	-1.697367
14.75883	159.6967	-1.702956
14.81050	159.6977	-1.708436
14.86050	159.6974	-1.713635
14.91383	159.6959	-1.718906
14.96383	159.6969	-1.723766
15.01383	159.6960	-1.728547
15.06716	159.6965	-1.733547
15.11716	159.6963	-1.738065
15.16883	159.6961	-1.742597
15.22050	159.6966	-1.747034
15.27050	159.6959	-1.751189
15.32384	159.6961	-1.755512
15.37384	159.6956	-1.759456
15.42383	159.6960	-1.763294
15.47717	159.6949	-1.767258
15.52717	159.6948	-1.770863
15.57883	159.6948	-1.774463
15.63050	159.6948	-1.778016
15.68050	159.6939	-1.781306
15.73383	159.6946	-1.784830
15.78383	159.6952	-1.788025
15.83383	159.6944	-1.791132
15.88716	159.6941	-1.794376
15.93717	159.6941	-1.797311
15.98883	159.6940	-1.800291
16.04050	159.6944	-1.803210
16.09050	159.6939	-1.806000
16.14383	159.6942	-1.808890
16.19383	159.6931	-1.811564
16.24550	159.6942	-1.814274
16.29716	159.6935	-1.816830
16.34717	159.6933	-1.819289
16.39883	159.6936	-1.821772
16.45050	159.6939	-1.824164
16.50050	159.6936	-1.826425
16.55383	159.6942	-1.828791
16.60383	159.6937	-1.830944
16.65550	159.6938	-1.833120
16.70716	159.6937	-1.835203
16.75716	159.6941	-1.837201
16.80883	159.6937	-1.839176
16.86050	159.6936	-1.841093
16.91050	159.6936	-1.842926
16.96383	159.6938	-1.844824
17.01383	159.6936	-1.846500
17.06550	159.6931	-1.848247
17.11716	159.6934	-1.849938
17.16716	159.6932	-1.851534
17.21883	159.6933	-1.853171
17.27050	159.6919	-1.854719
17.32050	159.6929	-1.856194
17.37383	159.6930	-1.857682
17.42383	159.6921	-1.859094
17.47550	159.6929	-1.860554
17.52716	159.6920	-1.861906
17.57716	159.6932	-1.863196
17.62883	159.6922	-1.864528
17.68050	159.6933	-1.865838
17.73050	159.6931	-1.867119
17.78383	159.6926	-1.868425
17.83383	159.6923	-1.869616
17.88550	159.6927	-1.870831
17.93716	159.6932	-1.872028
17.98716	159.6930	-1.873140
18.03883	159.6922	-1.874244
18.09050	159.6935	-1.875388
18.14050	159.6928	-1.876453
18.19383	159.6924	-1.877544
18.24383	159.6924	-1.878543
18.29550	159.6926	-1.879537
18.34716	159.6929	-1.880551
18.39716	159.6922	-1.881489
18.45050	159.6923	-1.882504
18.50050	159.6930	-1.883411
18.55050	159.6920	-1.884251
18.60383	159.6918	-1.885125
18.65383	159.6923	-1.885933
18.70550	159.6924	-1.886769
18.75716	159.6924	-1.887627
18.80716	159.6916	-1.888404
18.86050	159.6921	-1.889225
18.91050	159.6915	-1.889983
18.96050	159.6928	-1.890773
19.01383	159.6919	-1.891566
19.06383	159.6922	-1.892304
19.11550	159.6911	-1.893028
19.16716	159.6920	-1.893774
19.21716	159.6924	-1.894488
19.27050	159.6916	-1.895191
19.32050	159.6922	-1.895871
19.37050	159.6919	-1.896552
19.42383	159.6920	-1.897248
19.47383	159.6910	-1.897926
19.52550	159.6919	-1.898593
19.57716	159.6918	-1.899239
19.62716	159.6913	-1.899849
19.68050	159.6926	-1.900474
19.73050	159.6921	-1.901059
19.78050	159.6928	-1.901616
19.83383	159.6919	-1.902236
19.88383	159.6919	-1.902819
19.93550	159.6920	-1.903424
19.98716	159.6925	-1.904022
20.03717	159.6920	-1.904573
20.09050	159.6925	-1.905136
20.14050	159.6922	-1.905566
20.19050	159.6923	-1.906004
20.24383	159.6920	-1.906448
20.29383	159.6920	-1.906916
20.34550	159.6919	-1.907379
20.39716	159.6924	-1.907811
20.44716	159.6928	-1.908244
20.50050	159.6919	-1.908719
20.55050	159.6919	-1.909170
20.60050	159.6919	-1.909545
20.65383	159.6911	-1.909985
20.70383	159.6921	-1.910422
20.75550	159.6918	-1.910810
20.80716	159.6921	-1.911203
20.85716	159.6914	-1.911586
20.91050	159.6917	-1.912009
20.96050	159.6925	-1.912426
21.01216	159.6921	-1.912859
21.06383	159.6921	-1.913280
21.11383	159.6922	-1.913669
21.16550	159.6924	-1.914080
21.21716	159.6924	-1.914481
21.26716	159.6922	-1.914829
21.32050	159.6916	-1.915159
21.37050	159.6921	-1.915535
21.42216	159.6919	-1.915869
21.47383	159.6921	-1.916175
21.52383	159.6919	-1.916501
21.57550	159.6911	-1.916803
21.62716	159.6911	-1.917173
21.67717	159.6917	-1.917510
21.73050	159.6923	-1.917865
21.78050	159.6925	-1.918185
21.83216	159.6918	-1.918530
21.88383	159.6923	-1.918865
21.93383	159.6931	-1.919218
21.98550	159.6922	-1.919565
22.03717	159.6924	-1.919888
22.08716	159.6918	-1.920170
22.14050	159.6922	-1.920431
22.19050	159.6909	-1.920649
22.24216	159.6922	-1.920901
22.29383	159.6920	-1.921152
22.34383	159.6916	-1.921402
22.39550	159.6923	-1.921638
22.44716	159.6914	-1.921826
22.49716	159.6922	-1.922027
22.55050	159.6917	-1.922229
22.60050	159.6920	-1.922408
22.65216	159.6917	-1.922642
22.70383	159.6916	-1.922852
22.75383	159.6918	-1.923122
22.80550	159.6916	-1.923381
22.85716	159.6918	-1.923657
22.90716	159.6926	-1.923976
22.96050	159.6919	-1.924286
23.01050	159.6929	-1.924591
23.06216	159.6929	-1.924927
23.11383	159.6928	-1.925261
23.16383	159.6924	-1.925562
23.21716	159.6923	-1.925897
23.26716	159.6922	-1.926161
23.31716	159.6925	-1.926399
23.37050	159.6926	-1.926672
23.42050	159.6921	-1.926859
23.47216	159.6924	-1.927056
23.52383	159.6919	-1.927206
23.57383	159.6928	-1.927401
23.62716	159.6919	-1.927608
23.67717	159.6917	-1.927787
23.72716	159.6922	-1.927992
23.78050	159.6916	-1.928141
23.83050	159.6920	-1.928336
23.88216	159.6921	-1.928514
23.93383	159.6921	-1.928683
23.98383	159.6914	-1.928871
24.03717	159.6924	-1.929103
24.08716	159.6918	-1.929219
24.13716	159.6913	-1.929351
24.19050	159.6915	-1.929431
24.24050	159.6916	-1.929498
24.29216	159.6918	-1.929610
24.34383	159.6906	-1.929734
24.39383	159.6915	-1.929866
24.44716	159.6915	-1.930048
24.49716	159.6922	-1.930219
24.54716	159.6914	-1.930368
24.60050	159.6913	-1.930532
24.65050	159.6916	-1.930619
24.70216	159.6917	-1.930761
24.75383	159.6918	-1.930889
24.80383	159.6913	-1.931036
24.85716	159.6920	-1.931205
24.90716	159.6919	-1.931352
24.95717	159.6913	-1.931478
25.01050	159.6907	-1.931628
25.06050	159.6909	-1.931744
25.11216	159.6914	-1.931842
25.16383	159.6909	-1.931963
25.21383	159.6924	-1.932101
25.26716	159.6916	-1.932254
25.31716	159.6919	-1.932402
25.36716	159.6921	-1.932564
25.42050	159.6916	-1.932686
25.47050	159.6922	-1.932839
25.52216	159.6914	-1.932948
25.57383	159.6913	-1.933043
25.62383	159.6913	-1.933170
25.67717	159.6911	-1.933300
25.72717	159.6920	-1.933474
25.77883	159.6916	-1.933623
25.83050	159.6916	-1.933794
25.88050	159.6910	-1.933966
25.93216	159.6921	-1.934166
25.98383	159.6921	-1.934341
26.03383	159.6924	-1.934551
26.08716	159.6922	-1.934774
26.13716	159.6915	-1.934981
26.18883	159.6921	-1.935220
26.24050	159.6924	-1.935412
26.29050	159.6919	-1.935604
26.34216	159.6923	-1.935812
26.39383	159.6919	-1.935957
26.44383	159.6930	-1.936128
26.49716	159.6926	-1.936225
26.54716	159.6924	-1.936330
26.59883	159.6917	-1.936384
26.65050	159.6923	-1.936522
26.70050	159.6914	-1.936599
26.75217	159.6918	-1.936740
26.80383	159.6927	-1.936905
26.85383	159.6926	-1.937024
26.90716	159.6928	-1.937155
26.95716	159.6918	-1.937263
27.00883	159.6927	-1.937376
27.06050	159.6924	-1.937488
27.11050	159.6924	-1.937578
27.16217	159.6923	-1.937634
27.21383	159.6920	-1.937681
27.26383	159.6921	-1.937714
27.31716	159.6918	-1.937744
27.36716	159.6918	-1.937790
27.41883	159.6922	-1.937821
27.47050	159.6919	-1.937939
27.52050	159.6916	-1.938012
27.57217	159.6916	-1.938129
27.62383	159.6920	-1.938253
27.67383	159.6926	-1.938377
27.72717	159.6924	-1.938496
27.77717	159.6922	-1.938562
27.82883	159.6922	-1.938619
27.88050	159.6927	-1.938685
27.93050	159.6918	-1.938716
27.98383	159.6921	-1.938780
28.03383	159.6924	-1.938849
28.08383	159.6913	-1.938911
28.13716	159.6916	-1.939013
28.18717	159.6918	-1.939111
28.23883	159.6916	-1.939221
28.29050	159.6923	-1.939345
28.34050	159.6918	-1.939440
28.39383	159.6913	-1.939531
28.44383	159.6923	-1.939652
28.49383	159.6914	-1.939751
28.54716	159.6920	-1.939816
28.59716	159.6914	-1.939828
28.64883	159.6915	-1.939850
28.70050	159.6909	-1.939892
28.75050	159.6914	-1.939924
28.80383	159.6916	-1.939971
28.85383	159.6920	-1.940048
28.90383	159.6913	-1.940149
28.95716	159.6917	-1.940258
29.00716	159.6914	-1.940326
29.05883	159.6929	-1.940445
29.11050	159.6918	-1.940589
29.16050	159.6916	-1.940664
29.21383	159.6923	-1.940786
29.26383	159.6915	-1.940857
29.31383	159.6916	-1.940911
29.36716	159.6918	-1.940958
29.41716	159.6919	-1.940965
29.46883	159.6918	-1.940979
29.52050	159.6918	-1.941024
29.57050	159.6920	-1.941071
29.62383	159.6922	-1.941103
29.67383	159.6911	-1.941167
29.72383	159.6922	-1.941215
29.77717	159.6923	-1.941231
29.82717	159.6916	-1.941271
29.87883	159.6921	-1.941338
29.93050	159.6925	-1.941368
29.98050	159.6920	-1.941417
30.03383	159.6922	-1.941512
30.08383	159.6919	-1.941587
30.13383	159.6932	-1.941669
30.18717	159.6927	-1.941702
30.23716	159.6926	-1.941736
30.28883	159.6919	-1.941796
30.34050	159.6918	-1.941879
30.39050	159.6928	-1.941877
30.44383	159.6919	-1.941882
30.49383	159.6918	-1.941880
30.54550	159.6918	-1.941851
30.59716	159.6917	-1.941848
30.64716	159.6926	-1.941847
30.69883	159.6922	-1.941838
30.75050	159.6918	-1.941836
30.80050	159.6921	-1.941891
30.85383	159.6912	-1.941888
30.90383	159.6916	-1.941942
30.95550	159.6919	-1.941962
31.00716	159.6924	-1.942041
31.05716	159.6917	-1.942116
31.10883	159.6920	-1.942222
31.16050	159.6920	-1.942334
31.21050	159.6915	-1.942402
31.26383	159.6924	-1.942551
31.31383	159.6921	-1.942696
31.36550	159.6921	-1.942795
31.41716	159.6926	-1.942927
31.46716	159.6925	-1.943005
31.51883	159.6920	-1.943094
31.57050	159.6913	-1.943132
31.62050	159.6918	-1.943185
31.67383	159.6925	-1.943270
31.72383	159.6915	-1.943294
31.77550	159.6923	-1.943322
31.82717	159.6926	-1.943379
31.87717	159.6919	-1.943422
31.92883	159.6927	-1.943500
31.98050	159.6926	-1.943589
32.03050	159.6914	-1.943639
32.08383	159.6921	-1.943710
32.13383	159.6927	-1.943794
32.18550	159.6925	-1.943795
32.23717	159.6924	-1.943791
32.28717	159.6926	-1.943852
32.33883	159.6918	-1.943867
32.39050	159.6927	-1.943923
32.44050	159.6916	-1.943952
32.49383	159.6917	-1.944028
32.54383	159.6918	-1.944051
32.59550	159.6920	-1.944067
32.64717	159.6921	-1.944058
32.69717	159.6921	-1.944097
32.75050	159.6913	-1.944073
32.80050	159.6922	-1.944091
32.85050	159.6913	-1.944100
32.90383	159.6923	-1.944147
32.95383	159.6924	-1.944204
33.00550	159.6916	-1.944280
33.05716	159.6919	-1.944315
33.10716	159.6917	-1.944370
33.16050	159.6917	-1.944476
33.21050	159.6916	-1.944558
33.26050	159.6923	-1.944656
33.31383	159.6924	-1.944775
33.36383	159.6923	-1.944862
33.41550	159.6927	-1.944960
33.46716	159.6926	-1.945026
33.51716	159.6918	-1.945101
33.57050	159.6929	-1.945151
33.62050	159.6928	-1.945233
33.67050	159.6927	-1.945237
33.72383	159.6920	-1.945243
33.77383	159.6922	-1.945202
33.82550	159.6918	-1.945144
33.87717	159.6919	-1.945142
33.92717	159.6919	-1.945111
33.98050	159.6925	-1.945105
34.03050	159.6923	-1.945167
34.08050	159.6916	-1.945146
34.13383	159.6916	-1.945200
34.18384	159.6911	-1.945241
34.23550	159.6918	-1.945334
34.28717	159.6927	-1.945444
34.33716	159.6922	-1.945506
34.39050	159.6918	-1.945549
34.44050	159.6919	-1.945612
34.49050	159.6916	-1.945639
34.54383	159.6913	-1.945636
34.59384	159.6919	-1.945677
34.64550	159.6917	-1.945731
34.69717	159.6919	-1.945745
34.74716	159.6914	-1.945747
34.80050	159.6916	-1.945805
34.85050	159.6923	-1.945891
34.90050	159.6917	-1.945918
34.95383	159.6927	-1.945958
35.00383	159.6925	-1.945992
35.05550	159.6921	-1.946039
35.10716	159.6923	-1.946097
35.15716	159.6918	-1.946082
35.21050	159.6926	-1.946144
35.26050	159.6921	-1.946184
35.31216	159.6920	-1.946231
35.36383	159.6919	-1.946237
35.41383	159.6920	-1.946257
35.46550	159.6920	-1.946273
35.51716	159.6923	-1.946247
35.56716	159.6927	-1.946296
35.62050	159.6917	-1.946304
35.67050	159.6926	-1.946349
35.72217	159.6921	-1.946380
35.77383	159.6915	-1.946413
35.82383	159.6921	-1.946431
35.87550	159.6919	-1.946482
35.92717	159.6923	-1.946500
35.97717	159.6920	-1.946452
36.03050	159.6918	-1.946415
36.08050	159.6921	-1.946384
36.13216	159.6924	-1.946366
36.18384	159.6924	-1.946342
36.23383	159.6913	-1.946282
36.28550	159.6919	-1.946261
36.33716	159.6923	-1.946251
36.38716	159.6920	-1.946271
36.44050	159.6921	-1.946297
36.49050	159.6926	-1.946316
36.54217	159.6925	-1.946339
36.59384	159.6914	-1.946390
36.64383	159.6921	-1.946441
36.69550	159.6929	-1.946506
36.74716	159.6911	-1.946575
36.79716	159.6922	-1.946623
36.85050	159.6926	-1.946684
36.90050	159.6924	-1.946741
36.95216	159.6931	-1.946830
37.00383	159.6927	-1.946864
37.05383	159.6922	-1.946889
37.10550	159.6922	-1.946905
37.15716	159.6927	-1.946949
37.20716	159.6926	-1.946906
37.26050	159.6921	-1.946924
37.31050	159.6936	-1.946908
37.36217	159.6922	-1.946934
37.41383	159.6931	-1.946925
37.46383	159.6916	-1.946902
37.51716	159.6925	-1.946913
37.56716	159.6922	-1.946922
37.61716	159.6919	-1.946928
37.67050	159.6921	-1.946931
37.72050	159.6925	-1.946941
37.77217	159.6915	-1.946928
37.82383	159.6920	-1.946938
37.87383	159.6934	-1.946959
37.92717	159.6923	-1.947001
37.97717	159.6926	-1.947038
38.02716	159.6926	-1.947094
38.08050	159.6926	-1.947139
38.13050	159.6915	-1.947172
38.18216	159.6924	-1.947222
38.23383	159.6926	-1.947224
38.28383	159.6922	-1.947175
38.33716	159.6923	-1.947146
38.38716	159.6924	-1.947174
38.43716	159.6931	-1.947175
38.49050	159.6912	-1.947214
38.54050	159.6925	-1.947282
38.59216	159.6918	-1.947351
38.64383	159.6918	-1.947405
38.69383	159.6926	-1.947494
38.74716	159.6923	-1.947579
38.79716	159.6914	-1.947610
38.84716	159.6926	-1.947645
38.90050	159.6927	-1.947701
38.95050	159.6920	-1.947711
39.00217	159.6922	-1.947764
39.05383	159.6921	-1.947780
39.10383	159.6918	-1.947739
39.15716	159.6918	-1.947679
39.20716	159.6921	-1.947659
39.25716	159.6923	-1.947638
39.31050	159.6918	-1.947654
39.36050	159.6921	-1.947693
39.41217	159.6918	-1.947712
39.46383	159.6913	-1.947673
39.51383	159.6923	-1.947695
39.56716	159.6919	-1.947695
39.61716	159.6914	-1.947717
39.66716	159.6923	-1.947731
39.72050	159.6920	-1.947764
39.77050	159.6922	-1.947805
39.82217	159.6920	-1.947829
39.87383	159.6919	-1.947859
39.92383	159.6915	-1.947881
39.97717	159.6924	-1.947930
40.02716	159.6927	-1.947931
40.07883	159.6924	-1.947991
40.13050	159.6924	-1.948072
40.18050	159.6924	-1.948149
40.23216	159.6926	-1.948220
40.28383	159.6925	-1.948280
40.33383	159.6922	-1.948332
40.38716	159.6917	-1.948361
40.43716	159.6920	-1.948411
40.48883	159.6923	-1.948448
40.54050	159.6918	-1.948469
40.59050	159.6920	-1.948450
40.64216	159.6918	-1.948463
40.69383	159.6923	-1.948489
40.74383	159.6924	-1.948509
40.79716	159.6921	-1.948500
40.84716	159.6921	-1.948529
40.89883	159.6922	-1.948541
40.95050	159.6923	-1.948577
41.00050	159.6920	-1.948560
41.05217	159.6926	-1.948579
41.10383	159.6921	-1.948629
41.15383	159.6920	-1.948635
41.20717	159.6926	-1.948678
41.25717	159.6923	-1.948725
41.30883	159.6926	-1.948783
41.36050	159.6928	-1.948880
41.41050	159.6926	-1.948950
41.46216	159.6932	-1.949090
41.51383	159.6933	-1.949170
41.56383	159.6922	-1.949271
41.61716	159.6923	-1.949404
41.66716	159.6928	-1.949492
41.71884	159.6927	-1.949531
41.77050	159.6919	-1.949509
41.82050	159.6920	-1.949466
41.87216	159.6925	-1.949396
41.92383	159.6922	-1.949325
41.97383	159.6916	-1.949255
42.02716	159.6918	-1.949154
42.07717	159.6921	-1.949088
42.12883	159.6921	-1.949044
42.18050	159.6926	-1.949044
42.23050	159.6919	-1.948980
42.28383	159.6918	-1.948970
42.33383	159.6923	-1.948952
42.38383	159.6913	-1.948931
42.43716	159.6920	-1.948984
42.48717	159.6922	-1.949000
42.53883	159.6923	-1.948966
42.59050	159.6919	-1.948928
42.64050	159.6921	-1.948889
42.69383	159.6918	-1.948837
42.74383	159.6923	-1.948858
42.79383	159.6924	-1.948841
42.84716	159.6920	-1.948831
42.89717	159.6920	-1.948814
42.94883	159.6920	-1.948818
-2.000000	2.000000	0.0000000
43.05050	159.7281	-2.010609
43.10050	160.0639	-3.390494
43.15050	160.6158	-5.235989
43.20383	161.3240	-7.163108
43.25383	162.0738	-8.695241
43.30550	162.9074	-9.951555
43.35717	163.7849	-10.92896
43.40717	164.6657	-11.65256
43.46050	165.6329	-12.24593
43.51050	166.5571	-12.65930
43.56050	167.4941	-12.99433
43.61383	168.5060	-13.25453
43.66383	169.4625	-13.45993
43.71550	170.4566	-13.61510
43.76717	171.4564	-13.75369
43.81717	172.4291	-13.88136
43.87050	173.4683	-13.98294
43.92050	174.4459	-14.07430
43.97050	175.4263	-14.16292
44.02383	176.4750	-14.24952
44.07383	177.4573	-14.33471
44.12550	178.4736	-14.42609
44.17717	179.4914	-14.51454
44.22717	180.4766	-14.61136
44.28050	181.5282	-14.74195
44.33050	182.5158	-14.83750
44.38050	183.5028	-14.95017
44.43383	184.5558	-15.11683
44.48383	185.5424	-15.23037
44.53550	186.5624	-15.40521
44.58716	187.5819	-15.56169
44.63716	188.5673	-15.71364
44.69050	189.6199	-15.92925
44.74050	190.6046	-16.12032
44.79050	191.5891	-16.33532
44.84384	192.6379	-16.63246
44.89383	193.6208	-16.90246
44.94550	194.6343	-17.19200
44.99716	195.6459	-17.57830
45.04716	196.6235	-17.93856
45.10050	197.6631	-18.41546
45.15050	198.6338	-18.95235
45.20050	199.6006	-19.56027
45.25383	200.6256	-20.30096
45.30383	201.5839	-21.13577
45.35550	202.5661	-22.10898
45.40717	203.5392	-23.28546
45.45717	204.4696	-24.67522
45.51050	205.4472	-26.49602
45.56050	206.3516	-28.27523
45.61217	207.2748	-30.23391
45.66383	208.1931	-32.16736
45.71383	209.0816	-34.04776
45.76550	210.0050	-35.98037
45.81717	210.9282	-37.43942
45.86716	211.8324	-38.85239
45.92050	212.7982	-40.13675
45.97050	213.7237	-41.04316
46.02217	214.7100	-41.01889
46.07383	215.7597	-38.97912
46.12383	216.8606	-35.00712
46.17550	218.0945	-29.96438
46.22717	219.3844	-25.56384
46.27716	220.6099	-22.79480
46.33050	221.8618	-20.83193
46.38050	222.9928	-19.44446
46.43217	224.1276	-18.44662
46.48383	225.2375	-17.79091
46.53383	226.2927	-17.15560
46.58550	227.3683	-16.74915
46.63716	228.4352	-16.40141
46.68716	229.4580	-16.14739
46.74050	230.5414	-15.99402
46.79050	231.5530	-15.85096
46.84217	232.5945	-15.79307
46.89383	233.6332	-15.70634
46.94383	234.6373	-15.73281
46.99550	235.6730	-15.72275
47.04716	236.7092	-15.66736
47.09716	237.7110	-15.67147
47.15050	238.7778	-15.67291
47.20050	239.7781	-15.67458
47.25217	240.8106	-15.67679
47.30383	241.8418	-15.68879
47.35383	242.8416	-15.74000
47.40550	243.8725	-15.74539
47.45717	244.9060	-15.75092
47.50717	245.9039	-15.77640
47.56050	246.9700	-15.78431
47.61050	247.9690	-15.79563
47.66217	249.0015	-15.80764
47.71383	250.0333	-15.81871
47.76383	251.0316	-15.83487
47.81717	252.0974	-15.86725
47.86716	253.0959	-15.87967
47.91716	254.0956	-15.89262
47.97050	255.1610	-15.92054
48.02050	256.1581	-16.07496
48.07217	257.1888	-16.10442
48.12383	258.2221	-16.05128
48.17383	259.2194	-16.12402
48.22717	260.2842	-16.11279
48.27716	261.2828	-16.18355
48.32717	262.2818	-16.15445
48.38050	263.3469	-16.23628
48.43050	264.3461	-16.15146
48.48217	265.3765	-16.30104
48.53383	266.4077	-16.27860
48.58383	267.4070	-16.25345
48.63716	268.4720	-16.29474
48.68716	269.4695	-16.39468
48.73717	270.4692	-16.32468
48.79050	271.5322	-16.46191
48.84050	272.5337	-16.34248
48.89217	273.5649	-16.35735
48.94383	274.5944	-16.58266
48.99383	275.5930	-16.51724
49.04550	276.5641	-16.28136
49.09716	276.8484	-16.46506
49.14717	276.6682	-14.17587
49.19883	276.2623	-10.26292
49.25050	275.7076	-6.313542
49.30050	275.0702	-3.008274
49.35383	274.3074	-0.1655964
49.40383	273.5332	1.920576
49.45550	272.6895	3.593235
49.50717	271.8103	4.865364
49.55717	270.9316	5.809030
49.60883	270.0036	6.554516
49.66050	269.0576	7.120830
49.71050	268.1294	7.536150
49.76383	267.1276	7.879844
49.81383	266.1819	8.121355
49.86550	265.1954	8.325652
49.91716	264.2032	8.474197
49.96717	263.2390	8.585745
50.01883	262.2383	8.678946
50.07050	261.2342	8.753956
50.12050	260.2595	8.812022
50.17383	259.2189	8.857155
50.22383	258.2390	8.889843
50.27550	257.2260	8.917650
50.32717	256.2131	8.939494
50.37717	255.2297	8.958386
50.42883	254.2126	8.976887
50.48050	253.1949	8.994605
50.53050	252.2090	9.008238
50.58383	251.1548	9.022152
50.63383	250.1665	9.032062
50.68550	249.1460	9.040872
50.73717	248.1245	9.049757
50.78717	247.1359	9.058938
50.83883	246.1132	9.066924
50.89050	245.0904	9.075222
50.94050	244.0996	9.084220
50.99383	243.0427	9.092689
51.04383	242.0520	9.101078
51.09550	241.0274	9.107820
51.14717	240.0027	9.115484
51.19717	239.0112	9.123462
51.25050	237.9525	9.130731
51.30050	236.9604	9.138481
51.35050	235.9681	9.146188
51.40383	234.9096	9.155258
51.45383	233.9158	9.161891
51.50550	232.8895	9.169647
51.55717	231.8628	9.176360
51.60717	230.8701	9.183376
51.66050	229.8106	9.190704
51.71050	228.8178	9.197272
51.76050	227.8260	9.205336
51.81383	226.7666	9.212950
51.86383	225.7731	9.221816
51.91550	224.7470	9.231182
51.96717	223.7203	9.241242
52.01716	222.7270	9.253547
52.07050	221.6660	9.263647
52.12050	220.6716	9.271870
52.17050	219.6787	9.280122
52.22383	218.6185	9.289169
52.27383	217.6250	9.296522
52.32550	216.5980	9.305789
52.37717	215.5692	9.314960
52.42717	214.5743	9.322547
52.48050	213.5128	9.330539
52.53050	212.5176	9.337747
52.58050	211.5230	9.344628
52.63383	210.4617	9.352038
52.68383	209.4678	9.358528
52.73550	208.4411	9.365536
52.78716	207.4143	9.372882
52.83716	206.4202	9.381914
52.89050	205.3593	9.389871
52.94050	204.3657	9.396476
52.99050	203.3702	9.403219
53.04382	202.3112	9.411475
53.09384	201.3162	9.419501
53.14550	200.2887	9.427444
53.19717	199.2609	9.435681
53.24717	198.2649	9.443305
53.30050	197.2036	9.451171
53.35050	196.2088	9.457798
53.40050	195.2139	9.465045
53.45383	194.1535	9.474288
53.50383	193.1588	9.481812
53.55550	192.1310	9.491088
53.60717	191.1024	9.499586
53.65717	190.1078	9.506181
53.71050	189.0468	9.515512
53.76050	188.0530	9.521976
53.81216	187.0258	9.528726
53.86382	185.9966	9.538422
53.91382	185.0015	9.547509
53.96550	183.9725	9.555147
54.01716	182.9438	9.561655
54.06716	181.9486	9.567797
54.12050	180.8873	9.574672
54.17050	179.8934	9.582208
54.22217	178.8656	9.590187
54.27383	177.8380	9.597069
54.32383	176.8431	9.607892
54.37550	175.8152	9.617921
54.42717	174.7859	9.626791
54.47717	173.7905	9.636191
54.53050	172.7289	9.643597
54.58050	171.7341	9.650689
54.63217	170.7048	9.656976
54.68383	169.6776	9.665436
54.73383	168.6821	9.673870
54.78550	167.6539	9.680701
54.83716	166.6251	9.688211
54.88716	165.6301	9.699788
54.94050	164.5698	9.717082
54.99050	163.5776	9.789680
55.04217	162.5519	9.967403
55.09384	161.5318	10.21537
55.14384	160.5501	10.60236
55.19550	159.5433	11.20176
55.24717	158.5547	12.12133
55.29717	157.6164	13.43242
55.35050	156.6428	15.25054
55.40050	155.7552	17.30527
55.45216	154.8560	19.55022
55.50383	153.9661	21.69442
55.55383	153.1042	23.53455
55.60550	152.1988	25.05742
55.65717	151.2684	26.06810
55.70717	150.3422	26.52068
55.76050	149.3206	26.50705
55.81050	148.3299	26.19785
55.86217	147.2803	25.21392
55.91382	146.2063	24.16693
55.96382	145.1523	22.96258
56.01716	144.0138	21.68253
56.06716	142.9409	20.45779
56.11716	141.8682	19.29328
56.17050	140.7224	18.11912
56.22050	139.6543	17.09507
56.27217	138.5551	16.14834
56.32383	137.4615	15.28908
56.37383	136.4106	14.61255
56.42717	135.2958	13.96844
56.47717	134.2580	13.45627
56.52717	133.2260	13.03479
56.58050	132.1308	12.64859
56.63050	131.1083	12.36353
56.68217	130.0575	12.10864
56.73383	129.0100	11.91730
56.78383	127.9999	11.75477
56.83716	126.9236	11.62370
56.88716	125.9165	11.50498
56.93716	124.9123	11.42347
56.99050	123.8416	11.32940
57.04050	122.8397	11.25911
57.09217	121.8048	11.20224
57.14384	120.7709	11.13374
57.19384	119.7711	11.11142
57.24717	118.7056	11.06841
57.29717	117.7068	11.04284
57.34716	116.7080	11.01299
57.40050	115.6432	10.99342
57.45050	114.6451	10.97550
57.50217	113.6134	10.96525
57.55383	112.5822	10.94718
57.60383	111.5860	10.93701
57.65717	110.5220	10.92304
57.70717	109.5241	10.90972
57.75717	108.5258	10.90349
57.81050	107.4614	10.89142
57.86050	106.4646	10.88439
57.91216	105.4345	10.87588
57.96382	104.4044	10.87025
58.01382	103.4066	10.86058
58.06716	102.3438	10.85182
58.11716	101.3462	10.84474
58.16716	100.3503	10.83690
58.22050	99.28778	10.83096
58.27050	98.28925	10.82424
58.32217	97.25976	10.81873
58.37383	96.22911	10.81045
58.42383	95.23201	10.80391
58.47717	94.16912	10.79783
58.52717	93.17291	10.79206
58.57883	92.14178	10.78583
58.63050	91.11158	10.77978
58.68050	90.11591	10.77381
58.73217	89.08722	10.76780
58.78383	88.05647	10.76193
58.83383	87.06061	10.75604
58.88716	85.99757	10.74950
58.93716	85.00097	10.74357
58.98882	83.97132	10.73761
59.04050	82.94074	10.73184
59.09050	81.94412	10.72629
59.14216	80.91450	10.72066
59.19384	79.88435	10.71520
59.24382	78.88832	10.71026
59.29717	77.82522	10.70541
59.34716	76.82734	10.70098
59.39883	75.79930	10.69695
59.45050	74.76912	10.69285
59.50050	73.77080	10.66634
59.55217	72.73278	10.34240
59.60383	71.69478	10.29248
59.65383	70.69296	10.23899
59.70717	69.62515	10.18312
59.75717	68.62432	10.13950
59.80883	67.59103	10.10028
59.86050	66.55774	10.06614
59.91050	65.55932	10.03453
59.96216	64.52576	10.00706
60.01382	63.49361	9.964766
60.06382	62.49460	9.927481
60.11716	61.42690	9.885835
60.16716	60.42846	9.849164
60.21884	59.39522	9.812965
60.27050	58.36270	9.773788
60.32050	57.36338	9.738616
60.37217	56.33067	9.708147
60.42383	55.29934	9.674765
60.47382	54.30049	9.639774
60.52717	53.23470	9.608350
60.57717	52.23644	9.576343
60.62883	51.20446	9.543339
60.68050	50.17084	9.514743
60.73050	49.17152	9.482949
60.78383	48.10609	9.454601
60.83383	47.10660	9.398891
60.88383	46.10694	9.354012
60.93716	45.04054	9.313843
60.98717	44.04204	9.277709
61.03882	43.00930	9.239775
61.09050	41.97684	9.197648
61.14050	40.97770	9.160524
61.19384	39.91175	9.117255
61.24382	38.91174	9.086251
61.29382	37.91069	9.025530
61.34716	36.84274	8.969371
61.39717	35.84334	8.913116
61.44883	34.80838	8.860749
61.50050	33.77582	8.804286
61.55050	32.77468	8.752851
61.60383	31.70729	8.695321
61.65383	30.70652	8.646676
61.70383	29.70591	8.596008
61.75717	28.63694	8.538202
61.80717	27.63540	8.475379
61.85883	26.60100	8.416541
61.91050	25.56604	8.351551
61.96050	24.56373	8.327205
62.01050	23.56268	8.326394
62.06050	22.71255	8.337360
62.11217	22.50663	6.396145
62.16382	22.64790	3.622664
62.21382	23.01809	1.091776
62.26716	23.58122	-1.105580
62.31716	24.22312	-2.739754
62.36716	24.94808	-4.005970
62.42050	25.78912	-5.035072
62.47050	26.62234	-5.767224
62.52217	27.51960	-6.350757
62.57383	28.44268	-6.807570
62.62383	29.35538	-7.136614
62.67717	30.34688	-7.406600
62.72717	31.28700	-7.608130
62.77883	32.26862	-7.760218
62.83050	33.25634	-7.881458
62.88050	34.21731	-7.979161
62.93217	35.21729	-8.056700
62.98383	36.21890	-8.123032
63.03383	37.19025	-8.180792
63.08716	38.23054	-8.231566
63.13716	39.20925	-8.271652
63.18882	40.22104	-8.309899
63.24050	41.23604	-8.343039
63.29050	42.21972	-8.372655
63.34217	43.23818	-8.401314
63.39384	44.25684	-8.430956
63.44384	45.24230	-8.463006
63.49717	46.29680	-8.501519
63.54717	47.28420	-8.535351
63.59882	48.30781	-8.577195
63.65050	49.33103	-8.609074
63.70050	50.32276	-8.642120
63.75217	51.34724	-8.675207
63.80383	52.37194	-8.715592
63.85383	53.36300	-8.753309
63.90718	54.42160	-8.797344
63.95717	55.41413	-8.839570
64.00884	56.44054	-8.886034
64.06050	57.46640	-8.933711
64.11050	58.45908	-8.974428
64.16217	59.48634	-9.021308
64.21384	60.51410	-9.068632
64.26384	61.50694	-9.118312
64.31717	62.56866	-9.170196
64.36718	63.56430	-9.214070
64.41884	64.59244	-9.259491
64.47050	65.62265	-9.304116
64.52050	66.61756	-9.349145
64.57218	67.64743	-9.393306
64.62383	68.67556	-9.439301
64.67383	69.67093	-9.488272
64.72718	70.73389	-9.541796
64.77717	71.72893	-9.591704
64.82885	72.75896	-9.643147
64.88050	73.78830	-9.695250
64.93050	74.78400	-9.746728
64.98383	75.84832	-9.796020
65.03384	76.84426	-9.847340
65.08384	77.84032	-9.894403
65.13717	78.90364	-9.946397
65.18717	79.90007	-9.996032
65.23882	80.92984	-10.04656
65.29050	81.96012	-10.10209
65.34050	82.95701	-10.15438
65.39384	84.02086	-10.20821
65.44384	85.01799	-10.26159
65.49384	86.01470	-10.31549
65.54718	87.07890	-10.36881
65.59718	88.07462	-10.41826
65.64884	89.10626	-10.47240
65.70050	90.13582	-10.53397
65.75050	91.13249	-10.58490
65.80384	92.19739	-10.64055
65.85384	93.19445	-10.69147
65.90384	94.19082	-10.74098
65.95718	95.25468	-10.79806
66.00718	96.25201	-10.85069
66.05884	97.28226	-10.90307
66.11050	98.31281	-10.95923
66.16050	99.30926	-11.01215
66.21384	100.3736	-11.07420
66.26384	101.3704	-11.12403
66.31384	102.3678	-11.17815
66.36718	103.4322	-11.23824
66.41718	104.4281	-11.29449
66.46884	105.4577	-11.35388
66.52050	106.4884	-11.41023
66.57050	107.4854	-11.47670
66.62384	108.5484	-11.53466
66.67384	109.5441	-11.59306
66.72384	110.5410	-11.66085
66.77718	111.6051	-11.71925
66.82718	112.6018	-11.77614
66.87884	113.6320	-11.83867
66.93050	114.6617	-11.89877
66.98050	115.6592	-11.95958
67.03384	116.7216	-12.02319
67.08384	117.7193	-12.09019
67.13384	118.7154	-12.15550
67.18718	119.7803	-12.22022
67.23718	120.7779	-12.27887
67.28882	121.8098	-12.34319
67.34050	122.8392	-12.40758
67.39050	123.8371	-12.47140
67.44384	124.9010	-12.54278
67.49384	125.8969	-12.61127
67.54550	126.9258	-12.67744
67.59718	127.9556	-12.75171
67.64718	128.9520	-12.82300
67.69884	129.9824	-12.89415
67.75050	131.0124	-12.97241
67.80050	132.0092	-13.04319
67.85384	133.0721	-13.11363
67.90384	134.0676	-13.19332
67.95550	135.0960	-13.27589
68.00718	136.1246	-13.36487
68.05718	137.1202	-13.44624
68.10884	138.1492	-13.52533
68.16050	139.1778	-13.61678
68.21050	140.1742	-13.69994
68.26384	141.2363	-13.78807
68.31384	142.2314	-13.87206
68.36550	143.2601	-13.96383
68.41718	144.2888	-14.04468
68.46718	145.2842	-14.12264
68.51882	146.3125	-14.20864
68.57050	147.3415	-14.29851
68.62050	148.3370	-14.36802
68.67384	149.3992	-14.46082
68.72384	150.3952	-14.52442
68.77550	151.4246	-14.60480
68.82718	152.4544	-14.67028
68.87718	153.4501	-14.73752
68.92884	154.4798	-14.80770
68.98050	155.5105	-14.85770
69.03050	156.5080	-14.91039
69.08384	157.5718	-14.94288
69.13384	158.5705	-14.96616
69.18550	159.6020	-14.99340
69.23718	160.6342	-15.00380
69.28718	161.6334	-15.03403
69.33884	162.6661	-15.04225
69.39050	163.6990	-15.05393
69.44050	164.6986	-15.08107
69.49384	165.7637	-15.13882
69.54384	166.7612	-15.18794
69.59550	167.7925	-15.25797
69.64718	168.8245	-15.35091
69.69718	169.8199	-15.41841
69.75050	170.8825	-15.51861
69.80050	171.8782	-15.60878
69.85050	172.8733	-15.71916
69.90384	173.9352	-15.82203
69.95384	174.9296	-15.93004
70.00550	175.9570	-16.06843
70.05718	176.9833	-16.19671
70.10718	177.9765	-16.34109
70.16050	179.0344	-16.51300
70.21050	180.0252	-16.69259
70.26050	181.0153	-16.89380
70.31384	182.0694	-17.12208
70.36384	183.0578	-17.36070
70.41550	184.0772	-17.64215
70.46718	185.0952	-17.93938
70.51716	186.0779	-18.25328
70.57050	187.1241	-18.61844
70.62050	188.1032	-18.99016
70.67050	189.0806	-19.38330
70.72384	190.1233	-19.82240
70.77384	191.0990	-20.24978
70.82550	192.1062	-20.71264
70.87718	193.1116	-21.19970
70.92718	194.0840	-21.69414
70.98050	195.1187	-22.28260
71.03050	196.0852	-22.89922
71.08050	197.0498	-23.56252
71.13384	198.0751	-24.34456
71.18384	199.0323	-25.09354
71.23550	200.0194	-25.91756
71.28718	201.0058	-26.73108
71.33716	201.9580	-27.50818
71.39050	202.9785	-28.16623
71.44050	203.9408	-28.57904
71.49050	204.9177	-28.60290
71.54384	205.9862	-27.91784
71.59384	207.0247	-26.37330
71.64550	208.1460	-23.98419
71.69718	209.3037	-21.47502
71.74718	210.4288	-19.70200
71.80050	211.6067	-18.50675
71.85050	212.6845	-17.72256
71.90050	213.7426	-17.16713
71.95384	214.8543	-16.74146
72.00384	215.8870	-16.45492
72.05550	216.9428	-16.23424
72.10718	217.9876	-16.19328
72.15718	219.0002	-16.03324
72.21050	220.0752	-15.95326
72.26050	221.0820	-15.91046
72.31216	222.1189	-15.89067
72.36384	223.1549	-15.88186
72.41382	224.1571	-15.87849
72.46550	225.1910	-15.87713
72.51716	226.2252	-15.87666
72.56718	227.2244	-15.87683
72.62050	228.2908	-15.87797
72.67050	229.2887	-15.89145
72.72218	230.3215	-15.90324
72.77384	231.3529	-15.91947
72.82384	232.3513	-15.94256
72.87550	233.3826	-15.96852
72.92718	234.4141	-15.99707
72.97718	235.4108	-16.02848
73.03050	236.4769	-16.05957
73.08050	237.4760	-16.08670
73.13218	238.5074	-16.11899
73.18384	239.5384	-16.14980
73.23384	240.5369	-16.18669
73.28550	241.5678	-16.22592
73.33716	242.5982	-16.34141
73.38718	243.5966	-16.35395
73.44050	244.6626	-16.36550
73.49050	245.6624	-16.38272
73.54218	246.6945	-16.40023
73.59384	247.7270	-16.41565
73.64384	248.7244	-16.43530
73.69550	249.7563	-16.45912
73.74718	250.7878	-16.52462
73.79718	251.7852	-16.54331
73.85050	252.8506	-16.56857
73.90050	253.8496	-16.59004
73.95216	254.8809	-16.61411
74.00384	255.9121	-16.64856
74.05384	256.9099	-16.68600
74.10550	257.9425	-16.72139
74.15718	258.9731	-16.75896
74.20718	259.9724	-16.79955
74.26050	261.0365	-16.83512
74.31050	262.0346	-16.87092
74.36218	263.0656	-16.91365
74.41382	264.0973	-16.95743
74.46384	265.0954	-16.99737
74.51716	266.1596	-17.04052
74.56718	267.1590	-17.08159
74.61718	268.1549	-17.11620
74.67050	269.2186	-17.16340
74.72050	270.2160	-17.20775
74.77218	271.2452	-17.25047
74.82384	272.2753	-17.31027
-2.000000	5.000000	0.0000000