File: 9-C1(1.2mol%)+C20(1.0mol%)/matlab/160-2.txt
CLOSED
Version	1.0
Language	English
Mode	Standard
Run	9
RunSerial	12277
Instrument	DSC Q2000 V24.11 Build 124
Module	DSC Standard Cell RC
Operator
File	\\AE520-1454\Users\dsc\Desktop\Data\29-08-17\160-2.001
ProcName
InstSerial	2000-0883
AutoSerial	1293
Sample	160-2
Size	19.4000	mg
PanMass	Not available
PanResist	Automatic Automatic  K/W
PanFactor	Default Default
Method
Comment
Xcomment	Pan: Tzero Aluminum Hermetic
Xcomment	Gas1: Nitrogen 50.0 ml/min
Xcomment	Gas2: Nitrogen 50.0 ml/min
Text
Exotherm	UP
Kcell	1.05230
Cpconst	Standard: 0.938
Calib	-38.6961
TempCal	1	pts	157.46	156.60
TzeroDt	-87.6168 -0.0009 -1.4231
TzeroDtz	-87.6168 0.0057 6.9570
InstCalFile	Tzero: \\Ae520-1454\ta\Data\DSC\Calibration\2017\CALIBRATION\1562_RCS (90)_05_18_2017 10_50_44.TZR
InstCalFile	Baseline: \\Ae520-1454\ta\Data\DSC\Calibration\2017\2017-05-17_Calibration.001
InstCalFile	Sapphire: \\Ae520-1454\ta\Data\DSC\Calibration\2017\2017-05-17_Saphire.001
InstCalDate	Tzero 2017-05-18 Time 10:50:44
TempRange	-87.39 to 398.39 °C at 10.00 °C/min Heat Only
AutoZero	Delta T Offset 0.000 uV
AutoZero	Delta T0 Offset 0.000 uV
MultiptCal	0
MultiPtDesc	0) Not set
AutoCellConst	Calibration Date 2017-05-18 16:59:28
Controls	Gas 1  Event Off  Sampling 0.2
Cell#	RC-01562
CoolingUnit	RCS (90)
SelHeatFlow	Heat Flow T4P (mW)
AutoLidII	Installed
AutoAnalysis	Off
MacroFile
Nsig	3
Sig1	Time (min)
Sig2	Temperature (°C)
Sig3	Heat Flow (mW)
Date	2017-08-29
Time	22:15:34
OrgMethod	1: Equilibrate at 80.00 °C
OrgMethod	2: Isothermal for 3.00 min
OrgMethod	3: Jump to 160.00 °C
OrgMethod	4: Mark end of cycle 1
OrgMethod	5: Isothermal for 40.00 min
OrgMethod	6: Mark end of cycle 2
OrgMethod	7: Ramp 20.00 °C/min to 280.00 °C
OrgMethod	8: Mark end of cycle 3
OrgMethod	9: Ramp 20.00 °C/min to 20.00 °C
OrgMethod	10: Mark end of cycle 4
OrgMethod	11: Ramp 20.00 °C/min to 280.00 °C
OrgMethod	12: Mark end of cycle 5
OrgFile	C:\Users\jarra\Desktop\DSC\9-C1(1.2mol%)+C20(1.0mol%)\160-2.001
StartOfData
4.99994E-4	79.66122	-4.153047
0.05383332	79.71810	-3.368773
0.1038333	79.76049	-2.797333
0.1555000	79.79450	-2.328619
0.2071666	79.81998	-1.963818
0.2571667	79.83875	-1.685970
0.3105000	79.85504	-1.455848
0.3605000	79.86515	-1.290046
0.4121666	79.87324	-1.159480
0.4638333	79.87984	-1.055408
0.5138333	79.88452	-0.9810962
0.5655000	79.88730	-0.9214074
0.6171668	79.88962	-0.8786556
0.6671668	79.89072	-0.8482499
0.7205000	79.89126	-0.8266411
0.7705000	79.89290	-0.8130576
0.8221666	79.89206	-0.8031061
0.8738332	79.89160	-0.7972509
0.9238334	79.89197	-0.7938066
0.9755000	79.89030	-0.7904907
1.027167	79.88895	-0.7871238
1.077166	79.88834	-0.7839630
1.130500	79.88658	-0.7806946
1.180500	79.88736	-0.7778288
1.232166	79.88522	-0.7749772
1.283834	79.88540	-0.7723595
1.333833	79.88447	-0.7700828
1.385500	79.88275	-0.7679202
1.437167	79.88160	-0.7659750
1.487166	79.88040	-0.7643275
1.540500	79.87964	-0.7628012
1.590500	79.87863	-0.7616129
1.642166	79.87781	-0.7606458
1.693833	79.87659	-0.7599059
1.743833	79.87599	-0.7594086
1.795500	79.87574	-0.7590999
1.847167	79.87410	-0.7589135
1.897167	79.87324	-0.7589078
1.950500	79.87285	-0.7591089
2.000500	79.87158	-0.7593994
2.052166	79.87115	-0.7598701
2.103833	79.87008	-0.7605025
2.153833	79.86976	-0.7611682
2.205500	79.86882	-0.7619876
2.257167	79.86920	-0.7629562
2.307167	79.86775	-0.7639522
2.360500	79.86679	-0.7651069
2.410500	79.86637	-0.7662711
2.462167	79.86602	-0.7675650
2.513833	79.86494	-0.7688852
2.563833	79.86430	-0.7702153
2.617167	79.86450	-0.7717062
2.667167	79.86201	-0.7730859
2.717167	79.86311	-0.7745775
2.770500	79.86194	-0.7761838
2.820500	79.86142	-0.7777329
2.872167	79.86053	-0.7794256
2.923834	79.85962	-0.7810914
2.973833	79.85971	-0.7827669
3.020500	79.89318	-0.9977955
3.073833	81.47329	-4.372598
3.123834	84.26900	-10.58950
3.175500	87.49311	-18.24344
3.227167	91.05732	-26.03331
3.277167	94.75372	-33.06854
3.328833	98.76894	-39.54625
3.380500	102.9366	-45.17768
3.430500	107.0771	-49.87352
3.483833	111.5809	-54.05266
3.533833	115.8668	-57.26176
3.585500	120.3336	-60.10594
3.637167	124.8238	-62.50842
3.687167	129.1766	-64.49180
3.738834	133.6766	-66.31574
3.790500	138.1719	-67.94832
3.840500	142.5170	-69.25674
3.893833	146.6714	-69.54726
3.943833	148.9732	-66.06188
3.995500	150.7274	-59.91204
4.047167	152.0929	-52.77574
4.097166	153.1516	-45.97991
4.150500	154.0662	-39.39672
4.200500	154.7658	-34.09524
4.250500	155.3464	-29.63477
4.303834	155.8595	-25.76218
4.353833	156.2610	-22.82691
4.405500	156.6122	-20.38681
4.457167	156.9110	-18.42434
4.507167	157.1592	-16.89383
4.560500	157.3893	-15.57769
4.610500	157.5758	-14.57208
4.660500	157.7411	-13.73430
4.713834	157.8963	-12.97026
4.763834	158.0263	-12.35099
4.815500	158.1476	-11.78660
4.867166	158.2556	-11.28051
4.917167	158.3506	-10.83972
4.970500	158.4451	-10.41778
5.020500	158.5225	-10.05016
5.070500	158.5947	-9.713624
5.123833	158.6641	-9.380746
5.173834	158.7236	-9.088019
5.225500	158.7806	-8.804550
5.277168	158.8320	-8.535259
5.327168	158.8790	-8.284746
5.380500	158.9247	-8.030308
5.430500	158.9627	-7.798919
5.480500	159.0019	-7.579724
5.533832	159.0389	-7.339856
5.583832	159.0710	-7.118907
5.635500	159.1032	-6.883671
5.687168	159.1349	-6.644444
5.737168	159.1650	-6.411224
5.790500	159.1946	-6.154253
5.840500	159.2228	-5.911989
5.890500	159.2490	-5.664795
5.943832	159.2770	-5.394749
5.993834	159.3032	-5.125798
6.045500	159.3305	-4.833908
6.097168	159.3592	-4.521520
6.147168	159.3862	-4.205087
6.200500	159.4156	-3.864823
6.250500	159.4430	-3.544440
6.300500	159.4684	-3.230963
6.353832	159.4952	-2.920406
6.403832	159.5184	-2.658119
6.455500	159.5392	-2.413844
6.507168	159.5591	-2.192770
6.557166	159.5762	-1.994855
6.610500	159.5929	-1.801636
6.660500	159.6083	-1.635835
6.712168	159.6211	-1.469927
6.763834	159.6360	-1.318093
6.813834	159.6477	-1.175157
6.865500	159.6605	-1.032237
6.917168	159.6715	-0.8938403
6.967168	159.6832	-0.7616650
7.020500	159.6945	-0.6235688
7.070500	159.7054	-0.4957230
7.122168	159.7157	-0.3617204
7.173834	159.7269	-0.2287547
7.223834	159.7368	-0.1004448
7.275500	159.7474	0.03364116
7.327168	159.7568	0.1692096
7.377168	159.7670	0.2985130
7.430500	159.7777	0.4379343
7.480500	159.7878	0.5706984
7.532166	159.7984	0.7095282
7.583832	159.8078	0.8494749
7.633832	159.8190	0.9843452
7.685500	159.8291	1.126146
7.737168	159.8386	1.267550
7.787168	159.8491	1.406914
7.840500	159.8593	1.555694
7.890500	159.8696	1.694017
7.942168	159.8796	1.838571
7.993834	159.8898	1.980467
8.043834	159.8996	2.118914
8.095500	159.9091	2.260873
8.147168	159.9195	2.401086
8.197168	159.9290	2.535275
8.250500	159.9389	2.674884
8.300500	159.9478	2.803692
8.352168	159.9575	2.931600
8.403832	159.9664	3.063611
8.453834	159.9755	3.193151
8.505500	159.9858	3.335169
8.557168	159.9959	3.485191
8.607166	160.0068	3.640991
8.660499	160.0178	3.823547
8.710499	160.0308	4.012340
8.762168	160.0438	4.222924
8.813834	160.0594	4.457916
8.863834	160.0754	4.705036
8.917168	160.0944	4.991729
8.967168	160.1135	5.284351
9.017168	160.1333	5.592930
9.070500	160.1548	5.931232
9.120499	160.1771	6.249066
9.172168	160.1987	6.573538
9.223832	160.2192	6.879776
9.273834	160.2383	7.155655
9.327168	160.2560	7.418399
9.377168	160.2713	7.630368
9.427168	160.2836	7.811124
9.480500	160.2953	7.966376
9.530500	160.3030	8.079235
9.582168	160.3095	8.164401
9.633832	160.3147	8.216500
9.683832	160.3177	8.243222
9.737168	160.3182	8.253106
9.787168	160.3182	8.254264
9.837168	160.3156	8.252925
9.890500	160.3134	8.236374
9.940500	160.3096	8.183900
9.992166	160.3054	8.097687
10.04383	160.3016	8.003287
10.09383	160.2970	7.911780
10.14717	160.2908	7.816439
10.19717	160.2853	7.727990
10.24717	160.2801	7.635944
10.30050	160.2742	7.540478
10.35050	160.2677	7.451991
10.40217	160.2620	7.358934
10.45383	160.2563	7.268944
10.50384	160.2514	7.182870
10.55717	160.2452	7.091744
10.60717	160.2399	7.009175
10.65717	160.2349	6.930063
10.71050	160.2299	6.849730
10.76050	160.2252	6.776538
10.81216	160.2203	6.707212
10.86383	160.2152	6.638974
10.91383	160.2107	6.577228
10.96717	160.2073	6.514903
11.01717	160.2038	6.459246
11.06716	160.2001	6.405346
11.12050	160.1972	6.351259
11.17050	160.1936	6.302005
11.22217	160.1898	6.253050
11.27383	160.1869	6.205614
11.32383	160.1845	6.159783
11.37717	160.1814	6.112934
11.42717	160.1786	6.070178
11.47884	160.1758	6.028016
11.53050	160.1730	5.987312
11.58050	160.1698	5.948656
11.63216	160.1675	5.907920
11.68383	160.1649	5.868210
11.73383	160.1626	5.830852
11.78717	160.1594	5.791155
11.83717	160.1568	5.755282
11.88883	160.1549	5.718076
11.94050	160.1531	5.680908
11.99050	160.1497	5.645955
12.04217	160.1480	5.610712
12.09383	160.1451	5.577011
12.14383	160.1439	5.543730
12.19717	160.1411	5.508745
12.24717	160.1395	5.479350
12.29884	160.1375	5.450016
12.35050	160.1350	5.421980
12.40050	160.1344	5.396093
12.45217	160.1326	5.371714
12.50384	160.1310	5.349368
12.55383	160.1290	5.331172
12.60717	160.1283	5.314312
12.65717	160.1276	5.302205
12.70883	160.1263	5.293120
12.76050	160.1266	5.287026
12.81050	160.1263	5.281624
12.86217	160.1256	5.276295
12.91383	160.1258	5.271360
12.96383	160.1274	5.267193
13.01717	160.1272	5.263563
13.06716	160.1293	5.261093
13.11884	160.1301	5.259211
13.17050	160.1311	5.259370
13.22050	160.1329	5.263443
13.27217	160.1352	5.272529
13.32384	160.1373	5.285637
13.37384	160.1372	5.302761
13.42717	160.1412	5.320204
13.47717	160.1414	5.335801
13.52883	160.1436	5.348057
13.58050	160.1443	5.355122
13.63050	160.1431	5.360061
13.68383	160.1436	5.364530
13.73383	160.1422	5.367700
13.78383	160.1406	5.370576
13.83717	160.1380	5.366550
13.88717	160.1342	5.338867
13.93883	160.1299	5.277418
13.99050	160.1256	5.188706
14.04050	160.1202	5.092572
14.09383	160.1129	4.981050
14.14383	160.1068	4.871498
14.19384	160.1005	4.754292
14.24717	160.0911	4.622830
14.29717	160.0823	4.493976
14.34883	160.0739	4.357191
14.40050	160.0654	4.216920
14.45050	160.0564	4.078848
14.50383	160.0468	3.925899
14.55383	160.0371	3.781598
14.60383	160.0286	3.632888
14.65717	160.0176	3.474644
14.70717	160.0075	3.320300
14.75883	159.9971	3.161385
14.81050	159.9869	2.998476
14.86050	159.9759	2.837310
14.91383	159.9655	2.663001
14.96383	159.9552	2.498976
15.01383	159.9446	2.333862
15.06716	159.9335	2.161291
15.11716	159.9220	1.998394
15.16883	159.9116	1.829184
15.22050	159.9003	1.666935
15.27050	159.8907	1.510999
15.32384	159.8795	1.347700
15.37384	159.8692	1.200074
15.42383	159.8598	1.051868
15.47717	159.8497	0.8991226
15.52717	159.8406	0.7588970
15.57883	159.8313	0.6182971
15.63050	159.8217	0.4841384
15.68050	159.8137	0.3570071
15.73383	159.8049	0.2234845
15.78383	159.7966	0.1036093
15.83383	159.7896	-.01327767
15.88716	159.7814	-0.1306612
15.93717	159.7744	-0.2356920
15.98883	159.7672	-0.3400022
16.04050	159.7609	-0.4404242
16.09050	159.7549	-0.5328138
16.14383	159.7481	-0.6258375
16.19383	159.7425	-0.7092416
16.24550	159.7368	-0.7905902
16.29716	159.7316	-0.8673536
16.34717	159.7274	-0.9385568
16.39883	159.7219	-1.007485
16.45050	159.7186	-1.073737
16.50050	159.7144	-1.133288
16.55383	159.7098	-1.194330
16.60383	159.7068	-1.249461
16.65550	159.7028	-1.299851
16.70716	159.6992	-1.348122
16.75716	159.6970	-1.391929
16.80883	159.6936	-1.434507
16.86050	159.6908	-1.474056
16.91050	159.6884	-1.511462
16.96383	159.6856	-1.547514
17.01383	159.6837	-1.579875
17.06550	159.6806	-1.610714
17.11716	159.6791	-1.639094
17.16716	159.6766	-1.665835
17.21883	159.6749	-1.690325
17.27050	159.6723	-1.713307
17.32050	159.6716	-1.735581
17.37383	159.6708	-1.758543
17.42383	159.6686	-1.777481
17.47550	159.6675	-1.793986
17.52716	159.6658	-1.811258
17.57716	159.6648	-1.826233
17.62883	159.6635	-1.840745
17.68050	159.6626	-1.853480
17.73050	159.6609	-1.864752
17.78383	159.6604	-1.877252
17.83383	159.6596	-1.886453
17.88550	159.6584	-1.894068
17.93716	159.6583	-1.901475
17.98716	159.6575	-1.908419
18.03883	159.6570	-1.915691
18.09050	159.6566	-1.923375
18.14050	159.6551	-1.931020
18.19383	159.6552	-1.939280
18.24383	159.6534	-1.947178
18.29550	159.6528	-1.955484
18.34716	159.6524	-1.964002
18.39716	159.6524	-1.972292
18.45050	159.6513	-1.981258
18.50050	159.6514	-1.989754
18.55050	159.6499	-1.998246
18.60383	159.6498	-2.007375
18.65383	159.6486	-2.015891
18.70550	159.6486	-2.024653
18.75716	159.6479	-2.033373
18.80716	159.6477	-2.041736
18.86050	159.6467	-2.050564
18.91050	159.6470	-2.058781
18.96050	159.6467	-2.066856
19.01383	159.6471	-2.075349
19.06383	159.6453	-2.083163
19.11550	159.6449	-2.091062
19.16716	159.6455	-2.098866
19.21716	159.6445	-2.106258
19.27050	159.6439	-2.114022
19.32050	159.6438	-2.121140
19.37050	159.6438	-2.128065
19.42383	159.6434	-2.135310
19.47383	159.6438	-2.142002
19.52550	159.6427	-2.148723
19.57716	159.6429	-2.155305
19.62716	159.6429	-2.161527
19.68050	159.6424	-2.167988
19.73050	159.6418	-2.173910
19.78050	159.6415	-2.179690
19.83383	159.6412	-2.185708
19.88383	159.6412	-2.191199
19.93550	159.6416	-2.196770
19.98716	159.6416	-2.202207
20.03717	159.6409	-2.207312
20.09050	159.6413	-2.212640
20.14050	159.6413	-2.217548
20.19050	159.6402	-2.222276
20.24383	159.6407	-2.227186
20.29383	159.6407	-2.231644
20.34550	159.6398	-2.236131
20.39716	159.6402	-2.240544
20.44716	159.6401	-2.244704
20.50050	159.6399	-2.249030
20.55050	159.6396	-2.253070
20.60050	159.6399	-2.256966
20.65383	159.6391	-2.261028
20.70383	159.6392	-2.264777
20.75550	159.6395	-2.268561
20.80716	159.6402	-2.272258
20.85716	159.6393	-2.275756
20.91050	159.6387	-2.279362
20.96050	159.6387	-2.282605
21.01216	159.6384	-2.285855
21.06383	159.6388	-2.289023
21.11383	159.6384	-2.292014
21.16550	159.6380	-2.295030
21.21716	159.6380	-2.297956
21.26716	159.6385	-2.300766
21.32050	159.6379	-2.303661
21.37050	159.6381	-2.306410
21.42216	159.6379	-2.309137
21.47383	159.6378	-2.311810
21.52383	159.6385	-2.314285
21.57550	159.6382	-2.316776
21.62716	159.6379	-2.319156
21.67717	159.6372	-2.321371
21.73050	159.6373	-2.323699
21.78050	159.6371	-2.325846
21.83216	159.6373	-2.327924
21.88383	159.6368	-2.329982
21.93383	159.6368	-2.331965
21.98550	159.6371	-2.333976
22.03717	159.6367	-2.335966
22.08716	159.6371	-2.337840
22.14050	159.6369	-2.339768
22.19050	159.6360	-2.341526
22.24216	159.6366	-2.343345
22.29383	159.6360	-2.345129
22.34383	159.6366	-2.346830
22.39550	159.6370	-2.348515
22.44716	159.6369	-2.350162
22.49716	159.6364	-2.351738
22.55050	159.6365	-2.353376
22.60050	159.6362	-2.354886
22.65216	159.6364	-2.356363
22.70383	159.6363	-2.357846
22.75383	159.6365	-2.359222
22.80550	159.6363	-2.360644
22.85716	159.6366	-2.362012
22.90716	159.6369	-2.363369
22.96050	159.6358	-2.364755
23.01050	159.6359	-2.366028
23.06216	159.6364	-2.367330
23.11383	159.6363	-2.368620
23.16383	159.6359	-2.369827
23.21716	159.6366	-2.371061
23.26716	159.6359	-2.372204
23.31716	159.6360	-2.373354
23.37050	159.6356	-2.374539
23.42050	159.6364	-2.375660
23.47216	159.6355	-2.376752
23.52383	159.6365	-2.377838
23.57383	159.6360	-2.378832
23.62716	159.6351	-2.379890
23.67717	159.6361	-2.380869
23.72716	159.6360	-2.381853
23.78050	159.6350	-2.382837
23.83050	159.6363	-2.383725
23.88216	159.6356	-2.384619
23.93383	159.6356	-2.385504
23.98383	159.6358	-2.386330
24.03717	159.6353	-2.387284
24.08716	159.6358	-2.388155
24.13716	159.6349	-2.389034
24.19050	159.6358	-2.389933
24.24050	159.6356	-2.390763
24.29216	159.6353	-2.391604
24.34383	159.6350	-2.392457
24.39383	159.6345	-2.393204
24.44716	159.6362	-2.394014
24.49716	159.6356	-2.394771
24.54716	159.6356	-2.395523
24.60050	159.6361	-2.396368
24.65050	159.6357	-2.397078
24.70216	159.6361	-2.397844
24.75383	159.6359	-2.398540
24.80383	159.6352	-2.399175
24.85716	159.6354	-2.399890
24.90716	159.6356	-2.400520
24.95717	159.6357	-2.401144
25.01050	159.6349	-2.401747
25.06050	159.6358	-2.402300
25.11216	159.6352	-2.402896
25.16383	159.6350	-2.403460
25.21383	159.6354	-2.404038
25.26716	159.6343	-2.404594
25.31716	159.6356	-2.405142
25.36716	159.6358	-2.405663
25.42050	159.6351	-2.406216
25.47050	159.6346	-2.406751
25.52216	159.6354	-2.407273
25.57383	159.6357	-2.407822
25.62383	159.6355	-2.408316
25.67717	159.6348	-2.408831
25.72717	159.6344	-2.409356
25.77883	159.6351	-2.409852
25.83050	159.6353	-2.410347
25.88050	159.6345	-2.410752
25.93216	159.6341	-2.411152
25.98383	159.6350	-2.411624
26.03383	159.6346	-2.412042
26.08716	159.6346	-2.412518
26.13716	159.6349	-2.412944
26.18883	159.6339	-2.413387
26.24050	159.6343	-2.413865
26.29050	159.6360	-2.414363
26.34216	159.6346	-2.414818
26.39383	159.6352	-2.415232
26.44383	159.6345	-2.415614
26.49716	159.6351	-2.415999
26.54716	159.6358	-2.416379
26.59883	159.6353	-2.416704
26.65050	159.6338	-2.417003
26.70050	159.6348	-2.417291
26.75217	159.6348	-2.417650
26.80383	159.6346	-2.417960
26.85383	159.6344	-2.418308
26.90716	159.6340	-2.418652
26.95716	159.6352	-2.419016
27.00883	159.6350	-2.419353
27.06050	159.6348	-2.419725
27.11050	159.6347	-2.420057
27.16217	159.6355	-2.420413
27.21383	159.6346	-2.420749
27.26383	159.6351	-2.421077
27.31716	159.6348	-2.421461
27.36716	159.6333	-2.421728
27.41883	159.6338	-2.422023
27.47050	159.6339	-2.422350
27.52050	159.6336	-2.422627
27.57217	159.6341	-2.422914
27.62383	159.6350	-2.423234
27.67383	159.6346	-2.423560
27.72717	159.6348	-2.423900
27.77717	159.6356	-2.424224
27.82883	159.6353	-2.424560
27.88050	159.6348	-2.424852
27.93050	159.6346	-2.425180
27.98383	159.6339	-2.425531
28.03383	159.6344	-2.425855
28.08383	159.6338	-2.426174
28.13716	159.6343	-2.426518
28.18717	159.6349	-2.426806
28.23883	159.6346	-2.427136
28.29050	159.6349	-2.427422
28.34050	159.6337	-2.427689
28.39383	159.6342	-2.428026
28.44383	159.6347	-2.428354
28.49383	159.6344	-2.428642
28.54716	159.6352	-2.428980
28.59716	159.6346	-2.429270
28.64883	159.6349	-2.429580
28.70050	159.6348	-2.429861
28.75050	159.6354	-2.430148
28.80383	159.6347	-2.430452
28.85383	159.6346	-2.430753
28.90383	159.6351	-2.431061
28.95716	159.6342	-2.431383
29.00716	159.6345	-2.431636
29.05883	159.6345	-2.431892
29.11050	159.6338	-2.432127
29.16050	159.6337	-2.432349
29.21383	159.6343	-2.432596
29.26383	159.6341	-2.432824
29.31383	159.6336	-2.433040
29.36716	159.6341	-2.433289
29.41716	159.6346	-2.433593
29.46883	159.6351	-2.433928
29.52050	159.6342	-2.434255
29.57050	159.6343	-2.434588
29.62383	159.6346	-2.434959
29.67383	159.6338	-2.435224
29.72383	159.6350	-2.435606
29.77717	159.6342	-2.435963
29.82717	159.6347	-2.436235
29.87883	159.6336	-2.436501
29.93050	159.6343	-2.436763
29.98050	159.6339	-2.437015
30.03383	159.6336	-2.437203
30.08383	159.6346	-2.437392
30.13383	159.6330	-2.437575
30.18717	159.6340	-2.437783
30.23716	159.6336	-2.437949
30.28883	159.6329	-2.438106
30.34050	159.6329	-2.438322
30.39050	159.6334	-2.438509
30.44383	159.6334	-2.438688
30.49383	159.6342	-2.438872
30.54550	159.6338	-2.439041
30.59716	159.6337	-2.439246
30.64716	159.6338	-2.439451
30.69883	159.6332	-2.439615
30.75050	159.6337	-2.439863
30.80050	159.6336	-2.440067
30.85383	159.6342	-2.440325
30.90383	159.6334	-2.440539
30.95550	159.6340	-2.440788
31.00716	159.6338	-2.441004
31.05716	159.6341	-2.441228
31.10883	159.6338	-2.441449
31.16050	159.6344	-2.441672
31.21050	159.6345	-2.441851
31.26383	159.6337	-2.442010
31.31383	159.6341	-2.442126
31.36550	159.6340	-2.442263
31.41716	159.6342	-2.442428
31.46716	159.6344	-2.442553
31.51883	159.6340	-2.442730
31.57050	159.6344	-2.442858
31.62050	159.6337	-2.443046
31.67383	159.6347	-2.443166
31.72383	159.6342	-2.443302
31.77550	159.6342	-2.443472
31.82717	159.6341	-2.443639
31.87717	159.6341	-2.443813
31.92883	159.6342	-2.444021
31.98050	159.6337	-2.444250
32.03050	159.6342	-2.444432
32.08383	159.6340	-2.444592
32.13383	159.6346	-2.444771
32.18550	159.6338	-2.444918
32.23717	159.6334	-2.445064
32.28717	159.6346	-2.445238
32.33883	159.6332	-2.445314
32.39050	159.6332	-2.445453
32.44050	159.6333	-2.445603
32.49383	159.6336	-2.445782
32.54383	159.6337	-2.445941
32.59550	159.6342	-2.446120
32.64717	159.6339	-2.446263
32.69717	159.6336	-2.446341
32.75050	159.6332	-2.446499
32.80050	159.6340	-2.446623
32.85050	159.6339	-2.446724
32.90383	159.6339	-2.446858
32.95383	159.6342	-2.446968
33.00550	159.6334	-2.447080
33.05716	159.6336	-2.447206
33.10716	159.6344	-2.447343
33.16050	159.6344	-2.447485
33.21050	159.6335	-2.447602
33.26050	159.6346	-2.447681
33.31383	159.6335	-2.447741
33.36383	159.6338	-2.447790
33.41550	159.6338	-2.447840
33.46716	159.6336	-2.447923
33.51716	159.6342	-2.448047
33.57050	159.6342	-2.448140
33.62050	159.6341	-2.448280
33.67050	159.6339	-2.448437
33.72383	159.6337	-2.448576
33.77383	159.6345	-2.448732
33.82550	159.6345	-2.448888
33.87717	159.6348	-2.449010
33.92717	159.6337	-2.449044
33.98050	159.6348	-2.449106
34.03050	159.6346	-2.449188
34.08050	159.6343	-2.449183
34.13383	159.6338	-2.449193
34.18384	159.6340	-2.449187
34.23550	159.6342	-2.449184
34.28717	159.6337	-2.449164
34.33716	159.6342	-2.449222
34.39050	159.6344	-2.449324
34.44050	159.6342	-2.449422
34.49050	159.6348	-2.449524
34.54383	159.6341	-2.449650
34.59384	159.6348	-2.449796
34.64550	159.6342	-2.449930
34.69717	159.6341	-2.450044
34.74716	159.6346	-2.450110
34.80050	159.6348	-2.450198
34.85050	159.6345	-2.450273
34.90050	159.6344	-2.450369
34.95383	159.6339	-2.450389
35.00383	159.6334	-2.450436
35.05550	159.6339	-2.450490
35.10716	159.6344	-2.450578
35.15716	159.6343	-2.450613
35.21050	159.6331	-2.450620
35.26050	159.6331	-2.450592
35.31216	159.6335	-2.450613
35.36383	159.6335	-2.450632
35.41383	159.6337	-2.450636
35.46550	159.6339	-2.450684
35.51716	159.6334	-2.450744
35.56716	159.6336	-2.450807
35.62050	159.6342	-2.450901
35.67050	159.6337	-2.450950
35.72217	159.6335	-2.450981
35.77383	159.6332	-2.451087
35.82383	159.6335	-2.451173
35.87550	159.6338	-2.451274
35.92717	159.6340	-2.451381
35.97717	159.6340	-2.451512
36.03050	159.6337	-2.451673
36.08050	159.6339	-2.451814
36.13216	159.6340	-2.452000
36.18384	159.6344	-2.452164
36.23383	159.6339	-2.452362
36.28550	159.6338	-2.452534
36.33716	159.6339	-2.452696
36.38716	159.6341	-2.452820
36.44050	159.6338	-2.452970
36.49050	159.6333	-2.453066
36.54217	159.6341	-2.453169
36.59384	159.6348	-2.453252
36.64383	159.6346	-2.453337
36.69550	159.6343	-2.453410
36.74716	159.6337	-2.453457
36.79716	159.6346	-2.453520
36.85050	159.6336	-2.453533
36.90050	159.6329	-2.453530
36.95216	159.6339	-2.453572
37.00383	159.6355	-2.453661
37.05383	159.6344	-2.453742
37.10550	159.6341	-2.453786
37.15716	159.6346	-2.453870
37.20716	159.6342	-2.453887
37.26050	159.6336	-2.453910
37.31050	159.6341	-2.453947
37.36217	159.6332	-2.453975
37.41383	159.6341	-2.454001
37.46383	159.6336	-2.454024
37.51716	159.6333	-2.454090
37.56716	159.6342	-2.454130
37.61716	159.6337	-2.454156
37.67050	159.6332	-2.454179
37.72050	159.6336	-2.454241
37.77217	159.6337	-2.454314
37.82383	159.6342	-2.454416
37.87383	159.6341	-2.454450
37.92717	159.6339	-2.454557
37.97717	159.6336	-2.454653
38.02716	159.6339	-2.454744
38.08050	159.6344	-2.454834
38.13050	159.6341	-2.454930
38.18216	159.6345	-2.455046
38.23383	159.6340	-2.455114
38.28383	159.6343	-2.455204
38.33716	159.6333	-2.455290
38.38716	159.6340	-2.455366
38.43716	159.6348	-2.455421
38.49050	159.6344	-2.455523
38.54050	159.6339	-2.455563
38.59216	159.6346	-2.455613
38.64383	159.6335	-2.455680
38.69383	159.6339	-2.455727
38.74716	159.6341	-2.455733
38.79716	159.6337	-2.455748
38.84716	159.6334	-2.455732
38.90050	159.6337	-2.455773
38.95050	159.6342	-2.455814
39.00217	159.6342	-2.455874
39.05383	159.6332	-2.455891
39.10383	159.6337	-2.455919
39.15716	159.6342	-2.455984
39.20716	159.6342	-2.456081
39.25716	159.6337	-2.456143
39.31050	159.6341	-2.456184
39.36050	159.6336	-2.456264
39.41217	159.6346	-2.456354
39.46383	159.6338	-2.456405
39.51383	159.6340	-2.456438
39.56716	159.6341	-2.456466
39.61716	159.6342	-2.456510
39.66716	159.6338	-2.456550
39.72050	159.6342	-2.456528
39.77050	159.6342	-2.456544
39.82217	159.6340	-2.456565
39.87383	159.6336	-2.456565
39.92383	159.6340	-2.456626
39.97717	159.6337	-2.456698
40.02716	159.6338	-2.456764
40.07883	159.6330	-2.456772
40.13050	159.6338	-2.456836
40.18050	159.6338	-2.456826
40.23216	159.6334	-2.456828
40.28383	159.6330	-2.456818
40.33383	159.6344	-2.456863
40.38716	159.6336	-2.456883
40.43716	159.6339	-2.456950
40.48883	159.6332	-2.457035
40.54050	159.6338	-2.457110
40.59050	159.6338	-2.457189
40.64216	159.6347	-2.457372
40.69383	159.6344	-2.457486
40.74383	159.6342	-2.457596
40.79716	159.6342	-2.457715
40.84716	159.6345	-2.457806
40.89883	159.6339	-2.457915
40.95050	159.6341	-2.457971
41.00050	159.6339	-2.458058
41.05217	159.6335	-2.458066
41.10383	159.6332	-2.458110
41.15383	159.6350	-2.458194
41.20717	159.6334	-2.458258
41.25717	159.6343	-2.458324
41.30883	159.6346	-2.458408
41.36050	159.6337	-2.458415
41.41050	159.6346	-2.458472
41.46216	159.6333	-2.458510
41.51383	159.6336	-2.458626
41.56383	159.6339	-2.458742
41.61716	159.6340	-2.458826
41.66716	159.6337	-2.458890
41.71884	159.6345	-2.458930
41.77050	159.6338	-2.458979
41.82050	159.6336	-2.458990
41.87216	159.6338	-2.459026
41.92383	159.6339	-2.459062
41.97383	159.6326	-2.459116
42.02716	159.6335	-2.459230
42.07717	159.6342	-2.459332
42.12883	159.6335	-2.459465
42.18050	159.6338	-2.459549
42.23050	159.6344	-2.459601
42.28383	159.6345	-2.459671
42.33383	159.6348	-2.459740
42.38383	159.6345	-2.459793
42.43716	159.6340	-2.459870
42.48717	159.6342	-2.459961
42.53883	159.6336	-2.460036
42.59050	159.6346	-2.460133
42.64050	159.6334	-2.460187
42.69383	159.6338	-2.460237
42.74383	159.6336	-2.460312
42.79383	159.6335	-2.460315
42.84716	159.6331	-2.460342
42.89717	159.6336	-2.460384
42.94883	159.6338	-2.460391
-2.000000	2.000000	0.0000000
43.05050	159.6696	-2.528476
43.10050	160.0033	-4.008658
43.15050	160.5447	-6.083033
43.20383	161.2395	-8.301960
43.25383	161.9713	-10.10771
43.30550	162.7872	-11.63346
43.35717	163.6490	-12.83909
43.40717	164.5155	-13.76759
43.46050	165.4679	-14.53910
43.51050	166.3817	-15.10583
43.56050	167.3080	-15.55560
43.61383	168.3114	-15.93962
43.66383	169.2600	-16.22725
43.71550	170.2487	-16.47217
43.76717	171.2436	-16.68256
43.81717	172.2100	-16.86134
43.87050	173.2464	-17.01576
43.92050	174.2204	-17.15019
43.97050	175.1980	-17.27915
44.02383	176.2422	-17.40136
44.07383	177.2225	-17.51046
44.12550	178.2370	-17.62208
44.17717	179.2519	-17.74262
44.22717	180.2369	-17.85092
44.28050	181.2866	-17.97650
44.33050	182.2716	-18.09158
44.38050	183.2574	-18.21686
44.43383	184.3104	-18.34563
44.48383	185.2972	-18.46377
44.53550	186.3178	-18.59131
44.58716	187.3377	-18.73131
44.63716	188.3249	-18.88784
44.69050	189.3775	-19.05098
44.74050	190.3644	-19.22748
44.79050	191.3500	-19.41002
44.84384	192.4015	-19.64508
44.89383	193.3857	-19.87244
44.94550	194.4028	-20.13052
44.99716	195.4178	-20.41419
45.04716	196.3992	-20.71544
45.10050	197.4460	-21.06080
45.15050	198.4244	-21.43605
45.20050	199.4015	-21.83125
45.25383	200.4403	-22.30008
45.30383	201.4119	-22.84982
45.35550	202.4116	-23.48024
45.40717	203.4061	-24.22926
45.45717	204.3628	-25.05896
45.51050	205.3753	-26.13408
45.56050	206.3149	-27.34870
45.61217	207.2728	-28.88453
45.66383	208.2158	-30.71709
45.71383	209.1139	-32.72756
45.76550	210.0270	-34.99040
45.81717	210.9291	-37.30155
45.86716	211.7992	-39.48070
45.92050	212.7283	-41.67757
45.97050	213.6053	-43.59016
46.02217	214.5174	-45.43746
46.07383	215.4386	-47.12428
46.12383	216.3404	-48.45496
46.17550	217.2965	-48.87231
46.22717	218.3243	-46.64322
46.27716	219.4392	-41.79242
46.33050	220.7511	-35.63917
46.38050	222.0280	-31.00050
46.43217	223.3150	-28.02795
46.48383	224.5494	-25.84896
46.53383	225.7003	-24.24610
46.58550	226.8550	-22.95502
46.63716	227.9810	-21.96360
46.68716	229.0511	-21.22919
46.74050	230.1739	-20.64291
46.79050	231.2150	-20.21578
46.84217	232.2797	-19.88228
46.89383	233.3372	-19.64366
46.94383	234.3553	-19.46232
46.99550	235.4022	-19.32701
47.04716	236.4450	-19.22986
47.09716	237.4543	-19.17209
47.15050	238.5254	-19.12999
47.20050	239.5300	-19.10468
47.25217	240.5653	-19.09448
47.30383	241.6006	-19.09184
47.35383	242.6015	-19.09098
47.40550	243.6346	-19.09068
47.45717	244.6668	-19.09128
47.50717	245.6665	-19.09295
47.56050	246.7316	-19.09850
47.61050	247.7311	-19.10663
47.66217	248.7630	-19.11996
47.71383	249.7946	-19.13860
47.76383	250.7928	-19.16107
47.81717	251.8576	-19.19388
47.86716	252.8566	-19.22348
47.91716	253.8552	-19.25289
47.97050	254.9191	-19.28201
48.02050	255.9185	-19.33138
48.07217	256.9489	-19.37664
48.12383	257.9804	-19.41835
48.17383	258.9782	-19.46125
48.22717	260.0427	-19.50951
48.27716	261.0402	-19.55214
48.32717	262.0364	-19.59254
48.38050	263.1024	-19.64364
48.43050	264.0993	-19.68573
48.48217	265.1308	-19.73332
48.53383	266.1604	-19.78073
48.58383	267.1590	-19.83224
48.63716	268.2207	-19.90935
48.68716	269.2122	-20.22903
48.73717	270.2053	-20.25465
48.79050	271.2691	-20.26010
48.84050	272.2678	-20.26198
48.89217	273.3000	-20.26370
48.94383	274.3333	-20.26538
48.99383	275.3318	-20.26858
49.04550	276.3022	-20.02392
49.09716	276.5681	-20.58737
49.14717	276.3793	-18.57439
49.19883	275.9810	-14.51862
49.25050	275.4457	-10.18000
49.30050	274.8313	-6.427396
49.35383	274.0960	-3.084850
49.40383	273.3480	-0.5591259
49.45550	272.5285	1.526612
49.50717	271.6718	3.168140
49.55717	270.8130	4.429789
49.60883	269.9044	5.461880
49.66050	268.9752	6.276466
49.71050	268.0613	6.901380
49.76383	267.0727	7.434063
49.81383	266.1343	7.741086
49.86550	265.1568	8.108232
49.91716	264.1758	8.410551
49.96717	263.2207	8.653394
50.01883	262.2285	8.871350
50.07050	261.2320	9.045812
50.12050	260.2646	9.189328
50.17383	259.2290	9.322762
50.22383	258.2564	9.422609
50.27550	257.2478	9.512129
50.32717	256.2378	9.593515
50.37717	255.2595	9.658805
50.42883	254.2459	9.724915
50.48050	253.2306	9.783720
50.53050	252.2479	9.831988
50.58383	251.1970	9.880468
50.63383	250.2128	9.921451
50.68550	249.1942	9.961392
50.73717	248.1740	10.00004
50.78717	247.1875	10.03242
50.83883	246.1662	10.05865
50.89050	245.1454	10.08458
50.94050	244.1576	10.10590
50.99383	243.1034	10.12943
51.04383	242.1137	10.15182
51.09550	241.0902	10.17626
51.14717	240.0674	10.19751
51.19717	239.0775	10.21916
51.25050	238.0196	10.24661
51.30050	237.0291	10.27003
51.35050	236.0374	10.29246
51.40383	234.9788	10.31414
51.45383	233.9878	10.33121
51.50550	232.9630	10.34566
51.55717	231.9373	10.35911
51.60717	230.9445	10.37284
51.66050	229.8866	10.38770
51.71050	228.8936	10.40246
51.76050	227.9015	10.41830
51.81383	226.8425	10.43510
51.86383	225.8488	10.45088
51.91550	224.8242	10.46788
51.96717	223.7982	10.48209
52.01716	222.8063	10.49839
52.07050	221.7468	10.51540
52.12050	220.7540	10.53095
52.17050	219.7617	10.54928
52.22383	218.7022	10.56999
52.27383	217.7077	10.58997
52.32550	216.6816	10.60445
52.37717	215.6550	10.61758
52.42717	214.6620	10.62696
52.48050	213.6013	10.63681
52.53050	212.6080	10.64776
52.58050	211.6130	10.65862
52.63383	210.5539	10.66912
52.68383	209.5605	10.67953
52.73550	208.5333	10.69168
52.78716	207.5053	10.70532
52.83716	206.5118	10.71786
52.89050	205.4516	10.73069
52.94050	204.4573	10.74197
52.99050	203.4629	10.75280
53.04382	202.4026	10.76422
53.09384	201.4092	10.77306
53.14550	200.3821	10.78377
53.19717	199.3544	10.79586
53.24717	198.3603	10.80902
53.30050	197.2999	10.82150
53.35050	196.3054	10.83465
53.40050	195.3120	10.84581
53.45383	194.2504	10.85985
53.50383	193.2565	10.87217
53.55550	192.2299	10.88227
53.60717	191.2024	10.89442
53.65717	190.2082	10.90433
53.71050	189.1481	10.91709
53.76050	188.1544	10.92876
53.81216	187.1268	10.94015
53.86382	186.0988	10.95327
53.91382	185.1054	10.96524
53.96550	184.0766	10.97611
54.01716	183.0484	10.98782
54.06716	182.0532	10.99727
54.12050	180.9912	11.00751
54.17050	179.9973	11.01713
54.22217	178.9699	11.02886
54.27383	177.9423	11.04196
54.32383	176.9489	11.05576
54.37550	175.9209	11.07257
54.42717	174.8929	11.08716
54.47717	173.8978	11.10182
54.53050	172.8367	11.11644
54.58050	171.8407	11.12824
54.63217	170.8130	11.13985
54.68383	169.7865	11.15737
54.73383	168.7923	11.18564
54.78550	167.7657	11.24840
54.83716	166.7404	11.35266
54.88716	165.7510	11.51998
54.94050	164.6966	11.75077
54.99050	163.7137	12.05928
55.04217	162.7044	12.53956
55.09384	161.7074	13.31925
55.14384	160.7614	14.41839
55.19550	159.8048	16.00009
55.24717	158.8761	18.00820
55.29717	158.0028	20.25501
55.35050	157.0896	22.79240
55.40050	156.2429	25.09686
55.45216	155.3646	27.18606
55.50383	154.4712	28.85691
55.55383	153.5842	29.97638
55.60550	152.6382	30.61373
55.65717	151.6584	30.70183
55.70717	150.6789	30.42288
55.76050	149.6006	29.51256
55.81050	148.5646	28.45048
55.86217	147.4722	27.10902
55.91382	146.3648	25.67725
55.96382	145.2829	24.24554
56.01716	144.1253	22.74492
56.06716	143.0394	21.41143
56.11716	141.9562	20.19008
56.17050	140.8066	19.01286
56.22050	139.7367	18.06089
56.27217	138.6409	17.21278
56.32383	137.5535	16.50753
56.37383	136.5104	15.92580
56.42717	135.4037	15.41469
56.47717	134.3734	15.02212
56.52717	133.3504	14.69813
56.58050	132.2618	14.39739
56.63050	131.2467	14.16629
56.68217	130.1997	13.97916
56.73383	129.1566	13.81209
56.78383	128.1492	13.67648
56.83716	127.0761	13.56301
56.88716	126.0723	13.46247
56.93716	125.0690	13.38056
56.99050	124.0009	13.30199
57.04050	123.0004	13.24319
57.09217	121.9666	13.18652
57.14384	120.9340	13.14372
57.19384	119.9354	13.10562
57.24717	118.8711	13.07760
57.29717	117.8730	13.05504
57.34716	116.8760	13.03602
57.40050	115.8113	13.01852
57.45050	114.8142	13.00532
57.50217	113.7833	12.99142
57.55383	112.7526	12.97793
57.60383	111.7555	12.96504
57.65717	110.6911	12.95298
57.70717	109.6943	12.94243
57.75717	108.6986	12.93456
57.81050	107.6360	12.92344
57.86050	106.6400	12.91595
57.91216	105.6101	12.90924
57.96382	104.5805	12.90236
58.01382	103.5842	12.89608
58.06716	102.5214	12.88948
58.11716	101.5254	12.88328
58.16716	100.5294	12.87714
58.22050	99.46718	12.87066
58.27050	98.47158	12.86461
58.32217	97.44257	12.85880
58.37383	96.41222	12.85304
58.42383	95.41570	12.84756
58.47717	94.35297	12.84170
58.52717	93.35792	12.83624
58.57883	92.32689	12.83055
58.63050	91.29687	12.82504
58.68050	90.30119	12.81964
58.73217	89.27251	12.81407
58.78383	88.24350	12.80878
58.83383	87.24759	12.80381
58.88716	86.18496	12.79868
58.93716	85.18884	12.79399
58.98882	84.16047	12.78959
59.04050	83.13172	12.78552
59.09050	82.13612	12.78179
59.14216	81.10779	12.77822
59.19384	80.07779	12.77506
59.24382	79.08212	12.77210
59.29717	78.02019	12.76925
59.34716	77.02478	12.76681
59.39883	75.99540	12.76468
59.45050	74.96632	12.76272
59.50050	73.97012	12.76134
59.55217	72.94222	12.75980
59.60383	71.91269	12.75878
59.65383	70.91542	12.75780
59.70717	69.85316	12.75645
59.75717	68.85731	12.75652
59.80883	67.82876	12.75676
59.86050	66.79869	12.75156
59.91050	65.79650	12.53192
59.96216	64.75937	12.39919
60.01382	63.72240	12.32176
60.06382	62.71954	12.25865
60.11716	61.65106	12.19490
60.16716	60.65003	12.14205
60.21884	59.61616	12.09605
60.27050	58.58259	12.05363
60.32050	57.58300	12.00764
60.37217	56.55028	11.96930
60.42383	55.51738	11.93284
60.47382	54.51704	11.90121
60.52717	53.45074	11.85899
60.57717	52.45232	11.82425
60.62883	51.42050	11.78623
60.68050	50.38734	11.74472
60.73050	49.38924	11.70802
60.78383	48.32333	11.66846
60.83383	47.32407	11.63333
60.88383	46.32625	11.60447
60.93716	45.26135	11.56411
60.98717	44.26382	11.52974
61.03882	43.23105	11.49680
61.09050	42.20016	11.45740
61.14050	41.20062	11.41678
61.19384	40.13574	11.37113
61.24382	39.13669	11.32632
61.29382	38.13689	11.27494
61.34716	37.06984	11.22226
61.39717	36.07132	11.17201
61.44883	35.03748	11.11942
61.50050	34.00336	11.06756
61.55050	33.00391	11.00965
61.60383	31.93713	10.94695
61.65383	30.93721	10.89516
61.70383	29.93760	10.84038
61.75717	28.86996	10.77866
61.80717	27.86945	10.71633
61.85883	26.83330	10.64974
61.91050	25.79881	10.58234
61.96050	24.79644	10.55579
62.01050	23.79528	10.55549
62.06050	22.94383	10.58242
62.11217	22.72619	8.601318
62.16382	22.84304	5.440064
62.21382	23.18176	2.424923
62.26716	23.70587	-0.3025472
62.31716	24.31432	-2.376578
62.36716	25.00626	-4.030256
62.42050	25.81576	-5.425528
62.47050	26.62426	-6.451274
62.52217	27.49754	-7.281950
62.57383	28.40172	-7.938325
62.62383	29.29829	-8.438797
62.67717	30.27359	-8.854150
62.72717	31.20231	-9.173402
62.77883	32.17105	-9.448124
62.83050	33.14856	-9.665235
62.88050	34.10310	-9.843344
62.93217	35.09418	-9.985186
62.98383	36.08856	-10.10555
63.03383	37.05650	-10.21166
63.08716	38.09030	-10.30812
63.13716	39.06300	-10.38538
63.18882	40.07090	-10.45508
63.24050	41.08118	-10.51636
63.29050	42.05947	-10.57478
63.34217	43.07258	-10.62729
63.39384	44.08682	-10.67954
63.44384	45.06900	-10.73013
63.49717	46.11811	-10.78088
63.54717	47.10217	-10.82957
63.59882	48.11996	-10.88342
63.65050	49.13959	-10.93880
63.70050	50.12500	-10.99128
63.75217	51.14587	-11.04989
63.80383	52.16729	-11.10348
63.85383	53.15632	-11.15772
63.90718	54.21226	-11.21205
63.95717	55.20056	-11.26502
64.00884	56.22374	-11.31985
64.06050	57.24763	-11.37359
64.11050	58.23746	-11.42974
64.16217	59.26262	-11.48307
64.21384	60.28717	-11.54336
64.26384	61.27695	-11.60321
64.31717	62.33482	-11.67161
64.36718	63.32779	-11.73074
64.41884	64.35288	-11.78719
64.47050	65.37943	-11.84351
64.52050	66.37134	-11.90097
64.57218	67.39760	-11.96391
64.62383	68.42439	-12.03032
64.67383	69.41706	-12.09291
64.72718	70.47485	-12.15770
64.77717	71.46970	-12.21880
64.82885	72.49636	-12.28373
64.88050	73.52355	-12.34572
64.93050	74.51750	-12.40832
64.98383	75.57856	-12.47919
65.03384	76.57180	-12.53840
65.08384	77.56705	-12.60657
65.13717	78.62766	-12.67250
65.18717	79.62250	-12.73924
65.23882	80.64918	-12.81529
65.29050	81.67811	-12.89047
65.34050	82.67163	-12.95140
65.39384	83.73320	-13.02842
65.44384	84.72816	-13.10357
65.49384	85.72266	-13.16992
65.54718	86.78441	-13.24718
65.59718	87.77902	-13.31194
65.64884	88.80719	-13.38779
65.70050	89.83491	-13.46837
65.75050	90.83088	-13.53944
65.80384	91.89226	-13.61314
65.85384	92.88699	-13.68444
65.90384	93.88368	-13.75378
65.95718	94.94507	-13.83369
66.00718	95.93999	-13.90745
66.05884	96.96892	-13.97505
66.11050	97.99793	-14.05015
66.16050	98.99400	-14.11902
66.21384	100.0554	-14.20082
66.26384	101.0513	-14.27405
66.31384	102.0477	-14.34372
66.36718	103.1109	-14.42134
66.41718	104.1048	-14.49844
66.46884	105.1349	-14.57664
66.52050	106.1642	-14.64051
66.57050	107.1593	-14.71381
66.62384	108.2214	-14.79504
66.67384	109.2178	-14.85830
66.72384	110.2137	-14.93562
66.77718	111.2767	-15.00360
66.82718	112.2738	-15.07755
66.87884	113.3025	-15.13525
66.93050	114.3325	-15.20744
66.98050	115.3307	-15.24251
67.03384	116.3957	-15.25387
67.08384	117.3950	-15.26220
67.13384	118.3968	-15.26240
67.18718	119.4627	-15.26703
67.23718	120.4615	-15.28122
67.28882	121.4935	-15.31846
67.34050	122.5257	-15.36864
67.39050	123.5231	-15.41739
67.44384	124.5884	-15.47569
67.49384	125.5867	-15.53379
67.54550	126.6177	-15.58962
67.59718	127.6484	-15.63892
67.64718	128.6445	-15.69140
67.69884	129.6750	-15.75673
67.75050	130.7052	-15.82260
67.80050	131.7025	-15.88876
67.85384	132.7648	-15.95018
67.90384	133.7609	-16.01586
67.95550	134.7907	-16.09081
68.00718	135.8214	-16.16334
68.05718	136.8178	-16.23563
68.10884	137.8466	-16.30260
68.16050	138.8764	-16.38227
68.21050	139.8731	-16.45195
68.26384	140.9346	-16.53083
68.31384	141.9308	-16.61239
68.36550	142.9612	-16.69092
68.41718	143.9898	-16.76928
68.46718	144.9860	-16.84988
68.51882	146.0148	-16.92927
68.57050	147.0436	-17.01756
68.62050	148.0377	-17.09555
68.67384	149.0997	-17.18320
68.72384	150.0945	-17.26836
68.77550	151.1224	-17.35374
68.82718	152.1509	-17.44548
68.87718	153.1456	-17.53672
68.92884	154.1734	-17.62131
68.98050	155.2015	-17.71990
69.03050	156.1968	-17.80413
69.08384	157.2595	-17.88839
69.13384	158.2550	-17.97371
69.18550	159.2840	-18.04336
69.23718	160.3125	-18.10411
69.28718	161.3099	-18.15676
69.33884	162.3408	-18.20353
69.39050	163.3718	-18.23627
69.44050	164.3712	-18.26292
69.49384	165.4372	-18.28575
69.54384	166.4353	-18.31015
69.59550	167.4670	-18.34604
69.64718	168.4982	-18.39301
69.69718	169.4962	-18.45153
69.75050	170.5578	-18.53676
69.80050	171.5550	-18.62670
69.85050	172.5512	-18.72547
69.90384	173.6132	-18.82800
69.95384	174.6087	-18.93248
70.00550	175.6354	-19.04967
70.05718	176.6639	-19.18469
70.10718	177.6577	-19.31420
70.16050	178.7152	-19.47668
70.21050	179.7081	-19.63634
70.26050	180.6978	-19.81860
70.31384	181.7533	-20.03876
70.36384	182.7424	-20.26006
70.41550	183.7630	-20.52168
70.46718	184.7811	-20.79538
70.51716	185.7656	-21.10654
70.57050	186.8122	-21.46196
70.62050	187.7933	-21.84644
70.67050	188.7709	-22.24675
70.72384	189.8115	-22.73946
70.77384	190.7856	-23.20865
70.82550	191.7905	-23.72279
70.87718	192.7934	-24.25311
70.92718	193.7631	-24.75938
70.98050	194.7967	-25.31620
71.03050	195.7646	-25.86444
71.08050	196.7330	-26.44636
71.13384	197.7630	-27.13224
71.18384	198.7244	-27.83185
71.23550	199.7150	-28.63430
71.28718	200.7022	-29.50630
71.33716	201.6521	-30.40235
71.39050	202.6630	-31.38642
71.44050	203.6094	-32.30812
71.49050	204.5560	-33.19290
71.54384	205.5683	-33.98619
71.59384	206.5239	-34.48455
71.64550	207.5293	-34.51739
71.69718	208.5602	-33.78214
71.74718	209.6002	-32.09196
71.80050	210.7629	-29.34252
71.85050	211.8935	-26.61762
71.90050	213.0316	-24.56856
71.95384	214.2245	-23.12352
72.00384	215.3174	-22.17350
72.05550	216.4230	-21.44559
72.10718	217.5122	-20.91581
72.15718	218.5524	-20.50547
72.21050	219.6514	-20.18792
72.26050	220.6739	-19.98645
72.31216	221.7258	-19.81374
72.36384	222.7730	-19.70054
72.41382	223.7808	-19.62947
72.46550	224.8205	-19.56942
72.51716	225.8586	-19.54152
72.56718	226.8606	-19.52804
72.62050	227.9300	-19.52062
72.67050	228.9308	-19.51891
72.72218	229.9658	-19.51879
72.77384	230.9989	-19.51974
72.82384	231.9976	-19.52369
72.87550	233.0302	-19.53300
72.92718	234.0623	-19.55046
72.97718	235.0606	-19.57272
73.03050	236.1262	-19.59945
73.08050	237.1234	-19.62610
73.13218	238.1561	-19.65618
73.18384	239.1881	-19.69142
73.23384	240.1866	-19.72202
73.28550	241.2171	-19.75778
73.33716	242.2492	-19.80002
73.38718	243.2484	-19.83836
73.44050	244.3125	-19.87880
73.49050	245.3117	-19.91294
73.54218	246.3428	-19.94623
73.59384	247.3742	-19.97418
73.64384	248.3719	-20.00538
73.69550	249.4038	-20.03685
73.74718	250.4356	-20.06912
73.79718	251.4338	-20.10945
73.85050	252.4974	-20.14873
73.90050	253.4971	-20.18252
73.95216	254.5290	-20.21055
74.00384	255.5612	-20.24103
74.05384	256.5597	-20.27918
74.10550	257.5908	-20.31255
74.15718	258.6235	-20.35231
74.20718	259.6217	-20.38922
74.26050	260.6862	-20.42370
74.31050	261.6830	-20.46010
74.36218	262.7145	-20.51210
74.41382	263.7446	-20.56044
74.46384	264.7422	-20.60276
74.51716	265.8078	-20.64867
74.56718	266.8054	-20.68674
74.61718	267.8026	-20.72562
74.67050	268.8659	-20.77075
74.72050	269.8646	-20.81473
74.77218	270.8958	-20.85372
74.82384	271.9261	-20.89572
-2.000000	5.000000	0.0000000