File: 9-C1(1.2mol%)+C20(1.0mol%)/matlab/160-3.txt
CLOSED
Version	1.0
Language	English
Mode	Standard
Run	10
RunSerial	12278
Instrument	DSC Q2000 V24.11 Build 124
Module	DSC Standard Cell RC
Operator
File	\\AE520-1454\Users\dsc\Desktop\Data\29-08-17\160-3.001
ProcName
InstSerial	2000-0883
AutoSerial	1293
Sample	160-3
Size	26.0000	mg
PanMass	Not available
PanResist	Automatic Automatic  K/W
PanFactor	Default Default
Method
Comment
Xcomment	Pan: Tzero Aluminum Hermetic
Xcomment	Gas1: Nitrogen 50.0 ml/min
Xcomment	Gas2: Nitrogen 50.0 ml/min
Text
Exotherm	UP
Kcell	1.05230
Cpconst	Standard: 0.938
Calib	-38.6961
TempCal	1	pts	157.46	156.60
TzeroDt	-87.6168 -0.0009 -1.4231
TzeroDtz	-87.6168 0.0057 6.9570
InstCalFile	Tzero: \\Ae520-1454\ta\Data\DSC\Calibration\2017\CALIBRATION\1562_RCS (90)_05_18_2017 10_50_44.TZR
InstCalFile	Baseline: \\Ae520-1454\ta\Data\DSC\Calibration\2017\2017-05-17_Calibration.001
InstCalFile	Sapphire: \\Ae520-1454\ta\Data\DSC\Calibration\2017\2017-05-17_Saphire.001
InstCalDate	Tzero 2017-05-18 Time 10:50:44
TempRange	-87.39 to 398.39 °C at 10.00 °C/min Heat Only
AutoZero	Delta T Offset 0.000 uV
AutoZero	Delta T0 Offset 0.000 uV
MultiptCal	0
MultiPtDesc	0) Not set
AutoCellConst	Calibration Date 2017-05-18 16:59:28
Controls	Gas 1  Event Off  Sampling 0.2
Cell#	RC-01562
CoolingUnit	RCS (90)
SelHeatFlow	Heat Flow T4P (mW)
AutoLidII	Installed
AutoAnalysis	Off
MacroFile
Nsig	3
Sig1	Time (min)
Sig2	Temperature (°C)
Sig3	Heat Flow (mW)
Date	2017-08-29
Time	23:36:56
OrgMethod	1: Equilibrate at 80.00 °C
OrgMethod	2: Isothermal for 3.00 min
OrgMethod	3: Jump to 160.00 °C
OrgMethod	4: Mark end of cycle 1
OrgMethod	5: Isothermal for 40.00 min
OrgMethod	6: Mark end of cycle 2
OrgMethod	7: Ramp 20.00 °C/min to 280.00 °C
OrgMethod	8: Mark end of cycle 3
OrgMethod	9: Ramp 20.00 °C/min to 20.00 °C
OrgMethod	10: Mark end of cycle 4
OrgMethod	11: Ramp 20.00 °C/min to 280.00 °C
OrgMethod	12: Mark end of cycle 5
OrgFile	C:\Users\jarra\Desktop\DSC\9-C1(1.2mol%)+C20(1.0mol%)\160-3.001
StartOfData
4.99994E-4	79.00725	-12.59303
0.05383332	79.18896	-10.21869
0.1038333	79.32782	-8.416226
0.1555000	79.44306	-6.905072
0.2071666	79.53637	-5.683960
0.2571667	79.60965	-4.724946
0.3105000	79.67151	-3.895593
0.3605000	79.71851	-3.270222
0.4121666	79.75720	-2.744880
0.4638333	79.78832	-2.321003
0.5138333	79.81272	-1.989778
0.5655000	79.83250	-1.712793
0.6171668	79.84747	-1.488887
0.6671668	79.86100	-1.316980
0.7205000	79.87122	-1.170839
0.7705000	79.87863	-1.062108
0.8221666	79.88542	-0.9695293
0.8738332	79.88974	-0.8968759
0.9238334	79.89320	-0.8422772
0.9755000	79.89556	-0.7987408
1.027167	79.89847	-0.7647832
1.077166	79.89957	-0.7397181
1.130500	79.90056	-0.7205888
1.180500	79.90251	-0.7075626
1.232166	79.90126	-0.6972170
1.283834	79.90282	-0.6907266
1.333833	79.90180	-0.6860451
1.385500	79.90265	-0.6820812
1.437167	79.90160	-0.6779594
1.487166	79.90198	-0.6739588
1.540500	79.90126	-0.6697068
1.590500	79.89986	-0.6657678
1.642166	79.90004	-0.6617939
1.693833	79.89978	-0.6579381
1.743833	79.89891	-0.6543664
1.795500	79.89819	-0.6508812
1.847167	79.89639	-0.6475900
1.897167	79.89722	-0.6446128
1.950500	79.89572	-0.6416382
2.000500	79.89532	-0.6390925
2.052166	79.89442	-0.6366840
2.103833	79.89407	-0.6344866
2.153833	79.89350	-0.6325672
2.205500	79.89359	-0.6308048
2.257167	79.89282	-0.6292439
2.307167	79.89145	-0.6278867
2.360500	79.89099	-0.6265324
2.410500	79.89050	-0.6254490
2.462167	79.88980	-0.6244721
2.513833	79.88925	-0.6236119
2.563833	79.88946	-0.6229319
2.617167	79.88910	-0.6223293
2.667167	79.88769	-0.6218645
2.717167	79.88745	-0.6214906
2.770500	79.88638	-0.6212112
2.820500	79.88722	-0.6210238
2.872167	79.88670	-0.6209356
2.923834	79.88640	-0.6208848
2.973833	79.88574	-0.6209174
3.020500	79.91332	-0.8268194
3.073833	81.25180	-6.979332
3.123834	83.81270	-15.90706
3.175500	86.83616	-25.96686
3.227167	90.21522	-36.11240
3.277167	93.74621	-45.32638
3.328833	97.60578	-53.92974
3.380500	101.6326	-61.49634
3.430500	105.6534	-67.85978
3.483833	110.0466	-73.63481
3.533833	114.2366	-78.17089
3.585500	118.6205	-82.15758
3.637167	123.0398	-85.63812
3.687167	127.3403	-88.46902
3.738834	131.7973	-91.03447
3.790500	136.2651	-93.19103
3.840500	140.6022	-94.80697
3.893833	144.8982	-94.33670
3.943833	147.4997	-87.90462
3.995500	149.5014	-78.81432
4.047167	151.1131	-68.68394
4.097166	152.3892	-59.10585
4.150500	153.5170	-49.76656
4.200500	154.3927	-42.08516
4.250500	155.1297	-35.47490
4.303834	155.7881	-29.51212
4.353833	156.3090	-24.83833
4.405500	156.7657	-20.81473
4.457167	157.1547	-17.48596
4.507167	157.4751	-14.81285
4.560500	157.7693	-12.46025
4.610500	158.0054	-10.62757
4.660500	158.2106	-9.105170
4.713834	158.4010	-7.750102
4.763834	158.5536	-6.693452
4.815500	158.6930	-5.776320
4.867166	158.8131	-5.001362
4.917167	158.9158	-4.368222
4.970500	159.0112	-3.793942
5.020500	159.0893	-3.337959
5.070500	159.1597	-2.944775
5.123833	159.2257	-2.581416
5.173834	159.2808	-2.284159
5.225500	159.3314	-2.017198
5.277168	159.3762	-1.780508
5.327168	159.4161	-1.578043
5.380500	159.4541	-1.381611
5.430500	159.4864	-1.214260
5.480500	159.5151	-1.057036
5.533832	159.5434	-0.9053749
5.583832	159.5688	-0.7667180
5.635500	159.5917	-0.6323430
5.687168	159.6133	-0.5009838
5.737168	159.6332	-0.3790520
5.790500	159.6523	-0.2535158
5.840500	159.6692	-0.1312401
5.890500	159.6863	-.01216844
5.943832	159.7021	0.1152156
5.993834	159.7175	0.2343412
6.045500	159.7327	0.3588090
6.097168	159.7477	0.4871719
6.147168	159.7613	0.6141888
6.200500	159.7750	0.7521345
6.250500	159.7880	0.8848731
6.300500	159.8019	1.020037
6.353832	159.8142	1.171644
6.403832	159.8276	1.313148
6.455500	159.8416	1.470475
6.507168	159.8540	1.630704
6.557166	159.8674	1.784558
6.610500	159.8818	1.958618
6.660500	159.8936	2.126175
6.712168	159.9083	2.304160
6.763834	159.9226	2.487956
6.813834	159.9369	2.670910
6.865500	159.9511	2.864055
6.917168	159.9659	3.061749
6.967168	159.9801	3.258577
7.020500	159.9962	3.474674
7.070500	160.0108	3.683946
7.122168	160.0260	3.898612
7.173834	160.0419	4.117496
7.223834	160.0577	4.332467
7.275500	160.0725	4.558774
7.327168	160.0876	4.783880
7.377168	160.1037	4.998928
7.430500	160.1201	5.235972
7.480500	160.1351	5.453966
7.532166	160.1517	5.673458
7.583832	160.1646	5.898130
7.633832	160.1809	6.110008
7.685500	160.1956	6.333062
7.737168	160.2099	6.553668
7.787168	160.2262	6.767280
7.840500	160.2418	7.009225
7.890500	160.2573	7.243828
7.942168	160.2741	7.502156
7.993834	160.2930	7.778103
8.043834	160.3121	8.066946
8.095500	160.3338	8.389413
8.147168	160.3557	8.731003
8.197168	160.3788	9.080535
8.250500	160.4039	9.461000
8.300500	160.4282	9.819341
8.352168	160.4517	10.18484
8.403832	160.4759	10.53420
8.453834	160.4972	10.85775
8.505500	160.5178	11.16755
8.557168	160.5377	11.45085
8.607166	160.5548	11.70551
8.660499	160.5725	11.94216
8.710499	160.5858	12.14646
8.762168	160.5992	12.33364
8.813834	160.6110	12.50080
8.863834	160.6218	12.64363
8.917168	160.6298	12.77696
8.967168	160.6378	12.88368
9.017168	160.6452	12.97571
9.070500	160.6510	13.05733
9.120499	160.6560	13.12006
9.172168	160.6600	13.17105
9.223832	160.6638	13.21036
9.273834	160.6656	13.23710
9.327168	160.6684	13.25526
9.377168	160.6694	13.26552
9.427168	160.6708	13.27080
9.480500	160.6705	13.27369
9.530500	160.6698	13.27610
9.582168	160.6707	13.27814
9.633832	160.6694	13.27957
9.683832	160.6694	13.28029
9.737168	160.6686	13.28022
9.787168	160.6683	13.27915
9.837168	160.6666	13.27647
9.890500	160.6653	13.27086
9.940500	160.6641	13.26117
9.992166	160.6630	13.24453
10.04383	160.6604	13.21772
10.09383	160.6585	13.18167
10.14717	160.6561	13.13081
10.19717	160.6522	13.07637
10.24717	160.6499	13.01418
10.30050	160.6463	12.94832
10.35050	160.6424	12.88667
10.40217	160.6395	12.82495
10.45383	160.6345	12.76481
10.50384	160.6319	12.70910
10.55717	160.6279	12.65041
10.60717	160.6245	12.59757
10.65717	160.6219	12.54701
10.71050	160.6184	12.49723
10.76050	160.6154	12.45135
10.81216	160.6132	12.40869
10.86383	160.6095	12.36850
10.91383	160.6068	12.33143
10.96717	160.6060	12.29377
11.01717	160.6032	12.26258
11.06716	160.6006	12.23228
11.12050	160.5985	12.20186
11.17050	160.5968	12.17490
11.22217	160.5946	12.14738
11.27383	160.5921	12.11897
11.32383	160.5906	12.08852
11.37717	160.5886	12.05158
11.42717	160.5852	12.01360
11.47884	160.5824	11.96524
11.53050	160.5790	11.90798
11.58050	160.5770	11.84495
11.63216	160.5727	11.77176
11.68383	160.5678	11.69167
11.73383	160.5637	11.60720
11.78717	160.5573	11.51414
11.83717	160.5517	11.41838
11.88883	160.5449	11.31258
11.94050	160.5378	11.19983
11.99050	160.5310	11.08502
12.04217	160.5227	10.96290
12.09383	160.5161	10.83065
12.14383	160.5070	10.70366
12.19717	160.4979	10.56388
12.24717	160.4897	10.42609
12.29884	160.4806	10.28468
12.35050	160.4714	10.14119
12.40050	160.4624	9.998445
12.45217	160.4528	9.853039
12.50384	160.4431	9.708501
12.55383	160.4341	9.566389
12.60717	160.4249	9.415345
12.65717	160.4153	9.272762
12.70883	160.4054	9.129012
12.76050	160.3969	8.986278
12.81050	160.3876	8.851731
12.86217	160.3790	8.713910
12.91383	160.3698	8.582114
12.96383	160.3625	8.454726
13.01717	160.3526	8.323344
13.06716	160.3453	8.206281
13.11884	160.3377	8.086578
13.17050	160.3294	7.970722
13.22050	160.3224	7.861880
13.27217	160.3161	7.752192
13.32384	160.3092	7.645794
13.37384	160.3017	7.545290
13.42717	160.2947	7.436652
13.47717	160.2881	7.333674
13.52883	160.2806	7.223974
13.58050	160.2748	7.107750
13.63050	160.2662	7.000550
13.68383	160.2593	6.878266
13.73383	160.2512	6.762161
13.78383	160.2438	6.638970
13.83717	160.2350	6.503486
13.88717	160.2266	6.366806
13.93883	160.2162	6.218402
13.99050	160.2064	6.055958
14.04050	160.1961	5.891021
14.09383	160.1838	5.703734
14.14383	160.1733	5.522986
14.19384	160.1608	5.330695
14.24717	160.1462	5.119343
14.29717	160.1340	4.913596
14.34883	160.1201	4.696620
14.40050	160.1056	4.475660
14.45050	160.0916	4.258014
14.50383	160.0756	4.022221
14.55383	160.0609	3.797234
14.60383	160.0462	3.571522
14.65717	160.0311	3.333362
14.70717	160.0160	3.110497
14.75883	160.0012	2.880315
14.81050	159.9869	2.656047
14.86050	159.9729	2.447992
14.91383	159.9587	2.225431
14.96383	159.9453	2.029787
15.01383	159.9326	1.839692
15.06716	159.9201	1.643449
15.11716	159.9081	1.468214
15.16883	159.8962	1.292518
15.22050	159.8848	1.121981
15.27050	159.8744	0.9610332
15.32384	159.8628	0.7967315
15.37384	159.8527	0.6452332
15.42383	159.8436	0.5016297
15.47717	159.8348	0.3534360
15.52717	159.8258	0.2224437
15.57883	159.8174	0.09393303
15.63050	159.8092	-.02666406
15.68050	159.8022	-0.1396836
15.73383	159.7945	-0.2533830
15.78383	159.7874	-0.3497436
15.83383	159.7816	-0.4449328
15.88716	159.7749	-0.5385674
15.93717	159.7695	-0.6208565
15.98883	159.7642	-0.6978202
16.04050	159.7595	-0.7714252
16.09050	159.7548	-0.8371218
16.14383	159.7498	-0.9034005
16.19383	159.7469	-0.9637662
16.24550	159.7423	-1.017931
16.29716	159.7398	-1.070136
16.34717	159.7351	-1.116900
16.39883	159.7325	-1.162274
16.45050	159.7295	-1.205428
16.50050	159.7269	-1.243203
16.55383	159.7230	-1.281430
16.60383	159.7214	-1.315094
16.65550	159.7186	-1.348249
16.70716	159.7168	-1.378544
16.75716	159.7156	-1.406472
16.80883	159.7129	-1.433192
16.86050	159.7106	-1.458321
16.91050	159.7096	-1.479974
16.96383	159.7076	-1.501281
17.01383	159.7065	-1.520959
17.06550	159.7045	-1.539277
17.11716	159.7032	-1.555934
17.16716	159.7025	-1.572664
17.21883	159.7013	-1.586851
17.27050	159.7000	-1.600341
17.32050	159.6984	-1.612530
17.37383	159.6972	-1.624619
17.42383	159.6963	-1.635055
17.47550	159.6960	-1.645500
17.52716	159.6944	-1.654581
17.57716	159.6944	-1.664056
17.62883	159.6925	-1.672634
17.68050	159.6922	-1.681396
17.73050	159.6914	-1.689732
17.78383	159.6914	-1.698221
17.83383	159.6897	-1.706409
17.88550	159.6889	-1.714801
17.93716	159.6888	-1.723319
17.98716	159.6891	-1.731588
18.03883	159.6878	-1.740147
18.09050	159.6871	-1.748633
18.14050	159.6868	-1.756847
18.19383	159.6860	-1.765520
18.24383	159.6849	-1.773638
18.29550	159.6846	-1.781980
18.34716	159.6849	-1.790292
18.39716	159.6852	-1.798262
18.45050	159.6835	-1.806645
18.50050	159.6832	-1.814382
18.55050	159.6834	-1.821978
18.60383	159.6824	-1.829914
18.65383	159.6816	-1.837218
18.70550	159.6820	-1.844694
18.75716	159.6808	-1.851990
18.80716	159.6810	-1.858960
18.86050	159.6812	-1.866277
18.91050	159.6811	-1.873012
18.96050	159.6804	-1.879646
19.01383	159.6804	-1.886566
19.06383	159.6799	-1.892920
19.11550	159.6803	-1.899310
19.16716	159.6796	-1.905554
19.21716	159.6790	-1.911483
19.27050	159.6788	-1.917654
19.32050	159.6787	-1.923360
19.37050	159.6779	-1.928895
19.42383	159.6784	-1.934678
19.47383	159.6782	-1.939961
19.52550	159.6776	-1.945316
19.57716	159.6780	-1.950534
19.62716	159.6778	-1.955532
19.68050	159.6771	-1.960738
19.73050	159.6778	-1.965511
19.78050	159.6776	-1.970140
19.83383	159.6766	-1.974984
19.88383	159.6766	-1.979406
19.93550	159.6770	-1.983862
19.98716	159.6769	-1.988146
20.03717	159.6758	-1.992220
20.09050	159.6758	-1.996463
20.14050	159.6761	-2.000342
20.19050	159.6758	-2.004151
20.24383	159.6753	-2.008117
20.29383	159.6759	-2.011759
20.34550	159.6753	-2.015418
20.39716	159.6755	-2.018947
20.44716	159.6749	-2.022244
20.50050	159.6758	-2.025707
20.55050	159.6747	-2.028835
20.60050	159.6747	-2.031875
20.65383	159.6743	-2.035062
20.70383	159.6747	-2.037979
20.75550	159.6747	-2.040950
20.80716	159.6741	-2.043820
20.85716	159.6750	-2.046659
20.91050	159.6735	-2.049578
20.96050	159.6741	-2.052270
21.01216	159.6742	-2.054995
21.06383	159.6744	-2.057657
21.11383	159.6741	-2.060183
21.16550	159.6746	-2.062768
21.21716	159.6745	-2.065279
21.26716	159.6748	-2.067644
21.32050	159.6738	-2.070099
21.37050	159.6740	-2.072308
21.42216	159.6728	-2.074500
21.47383	159.6730	-2.076652
21.52383	159.6730	-2.078676
21.57550	159.6737	-2.080722
21.62716	159.6730	-2.082722
21.67717	159.6731	-2.084645
21.73050	159.6739	-2.086655
21.78050	159.6731	-2.088520
21.83216	159.6728	-2.090466
21.88383	159.6730	-2.092369
21.93383	159.6726	-2.094179
21.98550	159.6730	-2.095949
22.03717	159.6728	-2.097655
22.08716	159.6730	-2.099260
22.14050	159.6725	-2.100947
22.19050	159.6730	-2.102485
22.24216	159.6724	-2.104068
22.29383	159.6728	-2.105568
22.34383	159.6716	-2.106968
22.39550	159.6718	-2.108465
22.44716	159.6724	-2.110018
22.49716	159.6728	-2.111555
22.55050	159.6722	-2.113069
22.60050	159.6721	-2.114494
22.65216	159.6718	-2.115904
22.70383	159.6722	-2.117300
22.75383	159.6724	-2.118629
22.80550	159.6722	-2.119918
22.85716	159.6722	-2.121236
22.90716	159.6718	-2.122475
22.96050	159.6722	-2.123766
23.01050	159.6724	-2.124913
23.06216	159.6708	-2.126034
23.11383	159.6715	-2.127205
23.16383	159.6711	-2.128287
23.21716	159.6717	-2.129410
23.26716	159.6716	-2.130430
23.31716	159.6713	-2.131462
23.37050	159.6714	-2.132517
23.42050	159.6716	-2.133534
23.47216	159.6713	-2.134534
23.52383	159.6709	-2.135530
23.57383	159.6713	-2.136480
23.62716	159.6704	-2.137458
23.67717	159.6715	-2.138361
23.72716	159.6714	-2.139233
23.78050	159.6703	-2.140155
23.83050	159.6706	-2.141067
23.88216	159.6714	-2.142048
23.93383	159.6705	-2.142952
23.98383	159.6711	-2.143856
24.03717	159.6705	-2.144782
24.08716	159.6711	-2.145640
24.13716	159.6708	-2.146479
24.19050	159.6703	-2.147256
24.24050	159.6697	-2.147990
24.29216	159.6713	-2.148746
24.34383	159.6712	-2.149482
24.39383	159.6711	-2.150226
24.44716	159.6704	-2.151060
24.49716	159.6708	-2.151825
24.54716	159.6715	-2.152666
24.60050	159.6714	-2.153536
24.65050	159.6708	-2.154396
24.70216	159.6708	-2.155251
24.75383	159.6710	-2.156125
24.80383	159.6717	-2.156905
24.85716	159.6713	-2.157669
24.90716	159.6713	-2.158321
24.95717	159.6708	-2.158949
25.01050	159.6708	-2.159617
25.06050	159.6710	-2.160232
25.11216	159.6710	-2.160901
25.16383	159.6706	-2.161551
25.21383	159.6701	-2.162116
25.26716	159.6704	-2.162739
25.31716	159.6708	-2.163332
25.36716	159.6706	-2.163930
25.42050	159.6704	-2.164556
25.47050	159.6704	-2.165123
25.52216	159.6698	-2.165700
25.57383	159.6707	-2.166308
25.62383	159.6702	-2.166765
25.67717	159.6711	-2.167285
25.72717	159.6702	-2.167798
25.77883	159.6698	-2.168257
25.83050	159.6710	-2.168786
25.88050	159.6697	-2.169254
25.93216	159.6696	-2.169660
25.98383	159.6693	-2.170066
26.03383	159.6694	-2.170519
26.08716	159.6698	-2.170942
26.13716	159.6702	-2.171404
26.18883	159.6695	-2.171791
26.24050	159.6695	-2.172227
26.29050	159.6695	-2.172654
26.34216	159.6692	-2.173100
26.39383	159.6699	-2.173591
26.44383	159.6691	-2.174042
26.49716	159.6695	-2.174606
26.54716	159.6694	-2.175098
26.59883	159.6692	-2.175609
26.65050	159.6694	-2.176188
26.70050	159.6692	-2.176770
26.75217	159.6701	-2.177344
26.80383	159.6699	-2.177852
26.85383	159.6689	-2.178339
26.90716	159.6695	-2.178810
26.95716	159.6698	-2.179247
27.00883	159.6698	-2.179631
27.06050	159.6705	-2.180028
27.11050	159.6702	-2.180360
27.16217	159.6694	-2.180690
27.21383	159.6684	-2.181036
27.26383	159.6692	-2.181482
27.31716	159.6690	-2.181898
27.36716	159.6703	-2.182293
27.41883	159.6696	-2.182708
27.47050	159.6705	-2.183111
27.52050	159.6694	-2.183432
27.57217	159.6701	-2.183836
27.62383	159.6697	-2.184134
27.67383	159.6698	-2.184469
27.72717	159.6695	-2.184839
27.77717	159.6702	-2.185148
27.82883	159.6699	-2.185480
27.88050	159.6697	-2.185792
27.93050	159.6698	-2.186153
27.98383	159.6705	-2.186557
28.03383	159.6696	-2.186818
28.08383	159.6695	-2.187169
28.13716	159.6697	-2.187576
28.18717	159.6694	-2.187920
28.23883	159.6700	-2.188303
28.29050	159.6700	-2.188668
28.34050	159.6694	-2.188903
28.39383	159.6696	-2.189210
28.44383	159.6696	-2.189435
28.49383	159.6700	-2.189716
28.54716	159.6692	-2.189938
28.59716	159.6694	-2.190168
28.64883	159.6697	-2.190403
28.70050	159.6684	-2.190609
28.75050	159.6690	-2.190866
28.80383	159.6696	-2.191080
28.85383	159.6681	-2.191277
28.90383	159.6690	-2.191499
28.95716	159.6691	-2.191812
29.00716	159.6692	-2.192115
29.05883	159.6693	-2.192411
29.11050	159.6692	-2.192720
29.16050	159.6681	-2.192974
29.21383	159.6694	-2.193290
29.26383	159.6692	-2.193553
29.31383	159.6696	-2.193796
29.36716	159.6682	-2.194090
29.41716	159.6698	-2.194336
29.46883	159.6692	-2.194604
29.52050	159.6696	-2.194869
29.57050	159.6698	-2.195125
29.62383	159.6696	-2.195431
29.67383	159.6691	-2.195652
29.72383	159.6698	-2.195926
29.77717	159.6700	-2.196198
29.82717	159.6696	-2.196370
29.87883	159.6692	-2.196553
29.93050	159.6699	-2.196802
29.98050	159.6694	-2.197009
30.03383	159.6692	-2.197193
30.08383	159.6686	-2.197342
30.13383	159.6694	-2.197487
30.18717	159.6691	-2.197584
30.23716	159.6689	-2.197680
30.28883	159.6690	-2.197754
30.34050	159.6684	-2.197893
30.39050	159.6686	-2.197978
30.44383	159.6694	-2.198103
30.49383	159.6686	-2.198221
30.54550	159.6684	-2.198348
30.59716	159.6687	-2.198501
30.64716	159.6684	-2.198592
30.69883	159.6682	-2.198688
30.75050	159.6694	-2.198870
30.80050	159.6683	-2.198990
30.85383	159.6675	-2.199116
30.90383	159.6684	-2.199308
30.95550	159.6690	-2.199510
31.00716	159.6682	-2.199756
31.05716	159.6689	-2.200006
31.10883	159.6687	-2.200289
31.16050	159.6684	-2.200496
31.21050	159.6697	-2.200735
31.26383	159.6690	-2.200932
31.31383	159.6685	-2.201171
31.36550	159.6697	-2.201502
31.41716	159.6692	-2.201791
31.46716	159.6696	-2.202065
31.51883	159.6694	-2.202272
31.57050	159.6685	-2.202486
31.62050	159.6699	-2.202696
31.67383	159.6686	-2.202873
31.72383	159.6692	-2.203056
31.77550	159.6694	-2.203188
31.82717	159.6694	-2.203348
31.87717	159.6687	-2.203480
31.92883	159.6692	-2.203653
31.98050	159.6691	-2.203857
32.03050	159.6691	-2.204044
32.08383	159.6694	-2.204288
32.13383	159.6691	-2.204470
32.18550	159.6685	-2.204642
32.23717	159.6692	-2.204834
32.28717	159.6690	-2.204946
32.33883	159.6687	-2.205066
32.39050	159.6684	-2.205168
32.44050	159.6680	-2.205288
32.49383	159.6687	-2.205520
32.54383	159.6684	-2.205641
32.59550	159.6681	-2.205792
32.64717	159.6685	-2.205960
32.69717	159.6688	-2.206144
32.75050	159.6691	-2.206320
32.80050	159.6689	-2.206484
32.85050	159.6692	-2.206600
32.90383	159.6687	-2.206750
32.95383	159.6689	-2.206892
33.00550	159.6690	-2.207035
33.05716	159.6692	-2.207158
33.10716	159.6686	-2.207276
33.16050	159.6688	-2.207369
33.21050	159.6692	-2.207492
33.26050	159.6680	-2.207623
33.31383	159.6689	-2.207790
33.36383	159.6689	-2.207977
33.41550	159.6691	-2.208186
33.46716	159.6689	-2.208342
33.51716	159.6692	-2.208516
33.57050	159.6685	-2.208682
33.62050	159.6683	-2.208866
33.67050	159.6692	-2.209006
33.72383	159.6689	-2.209182
33.77383	159.6692	-2.209352
33.82550	159.6691	-2.209476
33.87717	159.6693	-2.209561
33.92717	159.6695	-2.209623
33.98050	159.6686	-2.209662
34.03050	159.6684	-2.209688
34.08050	159.6690	-2.209684
34.13383	159.6694	-2.209688
34.18384	159.6691	-2.209652
34.23550	159.6687	-2.209594
34.28717	159.6687	-2.209610
34.33716	159.6682	-2.209668
34.39050	159.6684	-2.209734
34.44050	159.6683	-2.209768
34.49050	159.6686	-2.209874
34.54383	159.6681	-2.209929
34.59384	159.6676	-2.209999
34.64550	159.6684	-2.210109
34.69717	159.6683	-2.210182
34.74716	159.6676	-2.210242
34.80050	159.6681	-2.210346
34.85050	159.6684	-2.210454
34.90050	159.6675	-2.210545
34.95383	159.6688	-2.210675
35.00383	159.6687	-2.210813
35.05550	159.6683	-2.210904
35.10716	159.6675	-2.211008
35.15716	159.6688	-2.211114
35.21050	159.6692	-2.211214
35.26050	159.6684	-2.211344
35.31216	159.6689	-2.211517
35.36383	159.6690	-2.211650
35.41383	159.6681	-2.211830
35.46550	159.6691	-2.212043
35.51716	159.6691	-2.212256
35.56716	159.6689	-2.212397
35.62050	159.6688	-2.212577
35.67050	159.6688	-2.212738
35.72217	159.6694	-2.212876
35.77383	159.6688	-2.212998
35.82383	159.6692	-2.213094
35.87550	159.6686	-2.213220
35.92717	159.6688	-2.213325
35.97717	159.6679	-2.213401
36.03050	159.6686	-2.213487
36.08050	159.6694	-2.213556
36.13216	159.6687	-2.213667
36.18384	159.6684	-2.213718
36.23383	159.6686	-2.213797
36.28550	159.6683	-2.213814
36.33716	159.6675	-2.213776
36.38716	159.6682	-2.213728
36.44050	159.6682	-2.213637
36.49050	159.6678	-2.213608
36.54217	159.6678	-2.213583
36.59384	159.6680	-2.213577
36.64383	159.6680	-2.213598
36.69550	159.6676	-2.213630
36.74716	159.6674	-2.213719
36.79716	159.6674	-2.213792
36.85050	159.6670	-2.213884
36.90050	159.6683	-2.214058
36.95216	159.6677	-2.214211
37.00383	159.6686	-2.214380
37.05383	159.6673	-2.214552
37.10550	159.6680	-2.214732
37.15716	159.6681	-2.214922
37.20716	159.6686	-2.215074
37.26050	159.6680	-2.215202
37.31050	159.6678	-2.215331
37.36217	159.6671	-2.215416
37.41383	159.6678	-2.215505
37.46383	159.6684	-2.215614
37.51716	159.6680	-2.215711
37.56716	159.6678	-2.215830
37.61716	159.6683	-2.215946
37.67050	159.6681	-2.216063
37.72050	159.6675	-2.216159
37.77217	159.6672	-2.216222
37.82383	159.6680	-2.216342
37.87383	159.6685	-2.216409
37.92717	159.6677	-2.216555
37.97717	159.6675	-2.216623
38.02716	159.6675	-2.216771
38.08050	159.6678	-2.216930
38.13050	159.6686	-2.217128
38.18216	159.6678	-2.217267
38.23383	159.6684	-2.217400
38.28383	159.6680	-2.217545
38.33716	159.6679	-2.217640
38.38716	159.6678	-2.217714
38.43716	159.6681	-2.217797
38.49050	159.6686	-2.217974
38.54050	159.6687	-2.218123
38.59216	159.6681	-2.218230
38.64383	159.6684	-2.218413
38.69383	159.6687	-2.218594
38.74716	159.6684	-2.218772
38.79716	159.6681	-2.218930
38.84716	159.6687	-2.219003
38.90050	159.6682	-2.219054
38.95050	159.6682	-2.219072
39.00217	159.6682	-2.219063
39.05383	159.6683	-2.219021
39.10383	159.6686	-2.218953
39.15716	159.6678	-2.218855
39.20716	159.6668	-2.218787
39.25716	159.6675	-2.218797
39.31050	159.6678	-2.218874
39.36050	159.6676	-2.218940
39.41217	159.6682	-2.219028
39.46383	159.6680	-2.219155
39.51383	159.6685	-2.219292
39.56716	159.6682	-2.219398
39.61716	159.6675	-2.219546
39.66716	159.6675	-2.219676
39.72050	159.6683	-2.219822
39.77050	159.6679	-2.219927
39.82217	159.6681	-2.219996
39.87383	159.6681	-2.220034
39.92383	159.6678	-2.220046
39.97717	159.6675	-2.220091
40.02716	159.6682	-2.220038
40.07883	159.6676	-2.219995
40.13050	159.6686	-2.220004
40.18050	159.6676	-2.219974
40.23216	159.6683	-2.220007
40.28383	159.6678	-2.220020
40.33383	159.6675	-2.220058
40.38716	159.6676	-2.220103
40.43716	159.6680	-2.220175
40.48883	159.6678	-2.220277
40.54050	159.6674	-2.220327
40.59050	159.6672	-2.220406
40.64216	159.6679	-2.220522
40.69383	159.6678	-2.220585
40.74383	159.6676	-2.220644
40.79716	159.6680	-2.220677
40.84716	159.6688	-2.220728
40.89883	159.6673	-2.220762
40.95050	159.6682	-2.220924
41.00050	159.6677	-2.221039
41.05217	159.6684	-2.221142
41.10383	159.6681	-2.221290
41.15383	159.6675	-2.221372
41.20717	159.6680	-2.221498
41.25717	159.6686	-2.221516
41.30883	159.6680	-2.221556
41.36050	159.6680	-2.221561
41.41050	159.6684	-2.221601
41.46216	159.6688	-2.221632
41.51383	159.6681	-2.221611
41.56383	159.6680	-2.221586
41.61716	159.6677	-2.221625
41.66716	159.6677	-2.221580
41.71884	159.6678	-2.221548
41.77050	159.6677	-2.221510
41.82050	159.6687	-2.221586
41.87216	159.6678	-2.221646
41.92383	159.6670	-2.221780
41.97383	159.6684	-2.221944
42.02716	159.6681	-2.222080
42.07717	159.6682	-2.222189
42.12883	159.6681	-2.222312
42.18050	159.6688	-2.222437
42.23050	159.6680	-2.222541
42.28383	159.6676	-2.222672
42.33383	159.6684	-2.222765
42.38383	159.6681	-2.222844
42.43716	159.6691	-2.223000
42.48717	159.6684	-2.223068
42.53883	159.6678	-2.223107
42.59050	159.6677	-2.223157
42.64050	159.6682	-2.223174
42.69383	159.6680	-2.223148
42.74383	159.6682	-2.223154
42.79383	159.6678	-2.223122
42.84716	159.6684	-2.223150
42.89717	159.6671	-2.223147
42.94883	159.6684	-2.223168
-2.000000	2.000000	0.0000000
43.05050	159.6969	-2.387350
43.10050	159.9913	-4.452694
43.15050	160.4885	-7.310011
43.20383	161.1303	-10.42776
43.25383	161.8126	-13.04211
43.30550	162.5799	-15.34013
43.35717	163.3950	-17.25340
43.40717	164.2208	-18.77188
43.46050	165.1349	-20.09764
43.51050	166.0168	-21.12558
43.56050	166.9160	-21.97976
43.61383	167.8932	-22.72737
43.66383	168.8215	-23.32382
43.71550	169.7930	-23.83580
43.76717	170.7714	-24.28855
43.81717	171.7259	-24.66355
43.87050	172.7489	-25.02188
43.92050	173.7134	-25.31449
43.97050	174.6812	-25.60380
44.02383	175.7165	-25.89695
44.07383	176.6883	-26.14306
44.12550	177.6955	-26.40788
44.17717	178.7046	-26.68081
44.22717	179.6814	-26.93779
44.28050	180.7238	-27.20001
44.33050	181.7009	-27.48239
44.38050	182.6802	-27.75932
44.43383	183.7228	-28.09168
44.48383	184.7000	-28.39913
44.53550	185.7113	-28.70628
44.58716	186.7230	-29.06770
44.63716	187.6987	-29.52072
44.69050	188.7314	-30.29202
44.74050	189.6962	-30.58370
44.79050	190.6680	-31.04833
44.84384	191.7023	-31.52815
44.89383	192.6700	-32.35008
44.94550	193.6633	-33.28013
44.99716	194.6464	-33.71270
45.04716	195.6073	-34.39384
45.10050	196.6274	-35.23435
45.15050	197.5871	-35.77854
45.20050	198.5520	-36.22183
45.25383	199.5777	-37.06352
45.30383	200.5317	-37.99390
45.35550	201.5074	-39.16585
45.40717	202.4703	-40.59480
45.45717	203.3937	-42.08326
45.51050	204.3625	-44.01331
45.56050	205.2563	-46.10406
45.61217	206.1637	-48.53418
45.66383	207.0566	-51.17924
45.71383	207.9115	-53.70593
45.76550	208.7906	-56.34413
45.81717	209.6691	-58.86376
45.86716	210.5222	-61.27370
45.92050	211.4352	-63.73657
45.97050	212.2986	-65.92034
46.02217	213.1987	-67.92780
46.07383	214.1126	-69.52556
46.12383	215.0239	-70.34619
46.17550	216.0115	-69.77575
46.22717	217.0832	-66.97599
46.27716	218.2081	-63.41254
46.33050	219.4694	-58.99146
46.38050	220.7031	-54.09644
46.43217	222.0213	-48.69389
46.48383	223.3416	-44.53044
46.53383	224.5821	-41.52340
46.58550	225.8170	-39.17608
46.63716	227.0127	-37.31742
46.68716	228.1370	-35.90918
46.74050	229.3084	-34.73978
46.79050	230.3862	-33.88044
46.84217	231.4830	-33.19276
46.89383	232.5662	-32.65090
46.94383	233.6036	-32.23879
46.99550	234.6675	-31.92851
47.04716	235.7246	-31.66294
47.09716	236.7429	-31.49072
47.15050	237.8251	-31.34298
47.20050	238.8356	-31.23830
47.25217	239.8768	-31.17336
47.30383	240.9172	-31.13218
47.35383	241.9210	-31.10878
47.40550	242.9580	-31.09389
47.45717	243.9944	-31.08802
47.50717	244.9948	-31.08553
47.56050	246.0630	-31.08436
47.61050	247.0639	-31.08388
47.66217	248.0977	-31.08404
47.71383	249.1311	-31.08516
47.76383	250.1311	-31.08900
47.81717	251.1970	-31.09683
47.86716	252.1957	-31.10880
47.91716	253.1956	-31.12702
47.97050	254.2614	-31.15129
48.02050	255.2599	-31.18034
48.07217	256.2924	-31.22461
48.12383	257.3240	-31.26982
48.17383	258.3231	-31.31794
48.22717	259.3875	-31.37702
48.27716	260.3863	-31.42358
48.32717	261.3840	-31.46924
48.38050	262.4492	-31.52648
48.43050	263.4476	-31.56526
48.48217	264.4804	-31.61228
48.53383	265.5118	-31.66119
48.58383	266.5112	-31.70361
48.63716	267.5752	-31.74783
48.68716	268.5738	-31.79722
48.73717	269.5713	-31.84396
48.79050	270.6360	-31.88790
48.84050	271.6350	-31.92725
48.89217	272.6659	-31.97258
48.94383	273.6974	-32.00743
48.99383	274.6950	-32.01921
49.04550	275.6818	-32.33808
49.09716	276.1045	-31.21060
49.14717	276.0808	-25.36845
49.19883	275.8274	-18.19384
49.25050	275.4150	-11.38096
49.30050	274.9019	-5.675105
49.35383	274.2604	-0.6297900
49.40383	273.5861	3.215951
49.45550	272.8325	6.438110
49.50717	272.0315	9.026975
49.55717	271.2182	11.06466
49.60883	270.3480	12.76386
49.66050	269.4526	14.13699
49.71050	268.5659	15.21559
49.76383	267.6016	16.11415
49.81383	266.6814	16.74220
49.86550	265.7185	17.26150
49.91716	264.7436	17.37251
49.96717	263.6162	14.80094
50.01883	262.6491	15.77964
50.07050	261.6782	16.36112
50.12050	260.7294	16.80319
50.17383	259.7117	17.22196
50.22383	258.7526	17.54047
50.27550	257.7570	17.81831
50.32717	256.7588	18.05775
50.37717	255.7887	18.25504
50.42883	254.7817	18.43635
50.48050	253.7748	18.58485
50.53050	252.7965	18.71176
50.58383	251.7499	18.83166
50.63383	250.7682	18.90569
50.68550	249.7532	19.00213
50.73717	248.7358	19.06510
50.78717	247.7500	19.13251
50.83883	246.7316	19.20042
50.89050	245.7109	19.24481
50.94050	244.7239	19.28119
50.99383	243.6690	19.31844
51.04383	242.6802	19.35799
51.09550	241.6570	19.36392
51.14717	240.6328	19.36736
51.19717	239.6413	19.37796
51.25050	238.5847	19.38888
51.30050	237.5932	19.40149
51.35050	236.6028	19.41428
51.40383	235.5458	19.42548
51.45383	234.5537	19.43369
51.50550	233.5299	19.44111
51.55717	232.5054	19.44523
51.60717	231.5128	19.44948
51.66050	230.4544	19.45575
51.71050	229.4621	19.45994
51.76050	228.4694	19.46663
51.81383	227.4108	19.47550
51.86383	226.4179	19.48266
51.91550	225.3926	19.48824
51.96717	224.3658	19.49487
52.01716	223.3724	19.50179
52.07050	222.3134	19.50836
52.12050	221.3196	19.51384
52.17050	220.3265	19.51935
52.22383	219.2668	19.52579
52.27383	218.2724	19.53168
52.32550	217.2463	19.53789
52.37717	216.2192	19.54368
52.42717	215.2252	19.54923
52.48050	214.1646	19.55511
52.53050	213.1718	19.56045
52.58050	212.1771	19.56562
52.63383	211.1169	19.57155
52.68383	210.1242	19.57723
52.73550	209.0963	19.58267
52.78716	208.0700	19.58746
52.83716	207.0755	19.59198
52.89050	206.0156	19.59674
52.94050	205.0209	19.60121
52.99050	204.0265	19.60607
53.04382	202.9664	19.61078
53.09384	201.9708	19.61486
53.14550	200.9434	19.61840
53.19717	199.9164	19.62195
53.24717	198.9215	19.62665
53.30050	197.8616	19.62953
53.35050	196.8679	19.63340
53.40050	195.8736	19.63567
53.45383	194.8137	19.63870
53.50383	193.8183	19.64956
53.55550	192.7922	19.65601
53.60717	191.7641	19.66191
53.65717	190.7698	19.66946
53.71050	189.7084	19.67037
53.76050	188.7133	19.67189
53.81216	187.6867	19.67687
53.86382	186.6596	19.67873
53.91382	185.6634	19.68021
53.96550	184.6364	19.68248
54.01716	183.6084	19.68285
54.06716	182.6134	19.68261
54.12050	181.5522	19.68306
54.17050	180.5568	19.68209
54.22217	179.5288	19.68099
54.27383	178.5016	19.68112
54.32383	177.5067	19.68134
54.37550	176.4792	19.67778
54.42717	175.4416	19.23716
54.47717	174.4441	19.39468
54.53050	173.3835	19.40941
54.58050	172.3886	19.41484
54.63217	171.3591	19.42255
54.68383	170.3326	19.43458
54.73383	169.3376	19.44110
54.78550	168.3106	19.45228
54.83716	167.2852	19.48978
54.88716	166.2904	19.52634
54.94050	165.2344	19.71349
54.99050	164.2474	19.92899
55.04217	163.2313	20.25216
55.09384	162.2241	20.72511
55.14384	161.2599	21.42902
55.19550	160.2799	22.50400
55.24717	159.3209	23.99525
55.29717	158.4193	25.90311
55.35050	157.4874	28.48775
55.40050	156.6430	31.15454
55.45216	155.7916	34.10308
55.50383	154.9489	36.96903
55.55383	154.1305	39.46761
55.60550	153.2709	41.61182
55.65717	152.3855	43.20822
55.70717	151.4974	44.18812
55.76050	150.5141	44.63074
55.81050	149.5562	44.52160
55.86217	148.5336	44.03160
55.91382	147.4790	42.98502
55.96382	146.4335	41.77972
56.01716	145.2968	40.27616
56.06716	144.2163	38.74691
56.11716	143.1267	37.16246
56.17050	141.9587	35.50899
56.22050	140.8630	33.99515
56.27217	139.7328	32.50990
56.32383	138.6073	31.17510
56.37383	137.5239	29.96020
56.42717	136.3762	28.80050
56.47717	135.3070	27.82520
56.52717	134.2451	26.96211
56.58050	133.1189	26.15210
56.63050	132.0721	25.47891
56.68217	130.9964	24.87923
56.73383	129.9255	24.35947
56.78383	128.8952	23.92587
56.83716	127.7997	23.52250
56.88716	126.7794	23.18865
56.93716	125.7599	22.90732
56.99050	124.6766	22.63374
57.04050	123.6629	22.40830
57.09217	122.6190	22.20056
57.14384	121.5757	22.03496
57.19384	120.5686	21.88179
57.24717	119.4951	21.70678
57.29717	118.4886	21.55878
57.34716	117.4830	21.47055
57.40050	116.4145	21.33754
57.45050	115.4074	21.11244
57.50217	114.3703	21.05701
57.55383	113.3346	21.02674
57.60383	112.3929	22.43384
57.65717	111.3555	22.66899
57.70717	110.3860	23.16374
57.75717	109.4225	23.68533
57.81050	108.3575	22.79555
57.86050	107.3395	22.23850
57.91216	106.2857	21.83264
57.96382	105.2298	22.26211
58.01382	104.2262	21.55941
58.06716	103.1523	21.38892
58.11716	102.1461	21.29689
58.16716	101.1392	21.10470
58.22050	100.0657	20.97069
58.27050	99.06088	20.88656
58.32217	98.02286	20.75254
58.37383	96.98774	20.69309
58.42383	95.98478	20.54549
58.47717	94.91639	20.48026
58.52717	93.91641	20.45070
58.57883	92.87968	20.26046
58.63050	91.84758	20.28155
58.68050	90.84680	20.21437
58.73217	89.81242	20.07037
58.78383	88.77863	20.04985
58.83383	87.77944	19.98432
58.88716	86.71275	19.88313
58.93716	85.71212	19.84024
58.98882	84.68016	19.76704
59.04050	83.64856	19.74691
59.09050	82.64722	19.65044
59.14216	81.61450	19.61168
59.19384	80.58222	19.56126
59.24382	79.58300	19.51465
59.29717	78.51413	19.39358
59.34716	77.51637	19.33068
59.39883	76.48431	19.30978
59.45050	75.45262	19.26569
59.50050	74.45386	19.18385
59.55217	73.42206	19.15346
59.60383	72.39074	19.10231
59.65383	71.39124	19.06299
59.70717	70.32410	18.95448
59.75717	69.32515	18.90626
59.80883	68.29311	18.82768
59.86050	67.26171	18.82766
59.91050	66.26157	18.69878
59.96216	65.22850	18.67220
60.01382	64.19609	18.61481
60.06382	63.19670	18.56949
60.11716	62.11678	18.10254
60.16716	61.12034	18.28891
60.21884	60.09223	18.29621
60.27050	59.06184	18.27736
60.32050	58.06062	18.11844
60.37217	57.02768	18.12623
60.42383	55.99672	18.11625
60.47382	54.99660	18.04416
60.52717	53.92966	17.98879
60.57717	52.93023	17.92343
60.62883	51.89541	17.79334
60.68050	50.86240	17.75975
60.73050	49.86336	17.73785
60.78383	48.79757	17.68634
60.83383	47.79910	17.64139
60.88383	46.80008	17.57864
60.93716	45.73291	17.49354
60.98717	44.73156	17.37999
61.03882	43.69692	17.35872
61.09050	42.66502	17.30764
61.14050	41.66535	17.25941
61.19384	40.59947	17.17711
61.24382	39.59826	17.11625
61.29382	38.59783	17.01614
61.34716	37.53080	16.96046
61.39717	36.52834	16.86190
61.44883	35.49852	16.74356
61.50050	34.45802	16.66298
61.55050	33.45660	16.57322
61.60383	32.38806	16.51274
61.65383	31.38258	16.22438
61.70383	30.37946	16.27531
61.75717	29.31033	16.20135
61.80717	28.30672	16.06236
61.85883	27.27033	16.02822
61.91050	26.23947	16.00230
61.96050	25.23590	15.93760
62.01050	24.23148	15.93791
62.06050	23.35646	15.96000
62.11217	23.08710	13.61302
62.16382	23.14522	9.642179
62.21382	23.41452	5.634320
62.26716	23.86098	1.803035
62.31716	24.39632	-1.254241
62.36716	25.01946	-3.794724
62.42050	25.76002	-6.002326
62.47050	26.51133	-7.694640
62.52217	27.33369	-9.123148
62.57383	28.19354	-10.28402
62.62383	29.05459	-11.19946
62.67717	29.99669	-12.00210
62.72717	30.89683	-12.62571
62.77883	31.84199	-13.16272
62.83050	32.80118	-13.62242
62.88050	33.73752	-13.97358
62.93217	34.71425	-14.30841
62.98383	35.69863	-14.57344
63.03383	36.65561	-14.82714
63.08716	37.68239	-15.03429
63.13716	38.64710	-15.21078
63.18882	39.64966	-15.39024
63.24050	40.65435	-15.53583
63.29050	41.62937	-15.66492
63.34217	42.63919	-15.80358
63.39384	43.64990	-15.92522
63.44384	44.63202	-16.03064
63.49717	45.67852	-16.12827
63.54717	46.66120	-16.22562
63.59882	47.67926	-16.33929
63.65050	48.69732	-16.43321
63.70050	49.68325	-16.51889
63.75217	50.70361	-16.61655
63.80383	51.72457	-16.71020
63.85383	52.71310	-16.79492
63.90718	53.76989	-16.89246
63.95717	54.75930	-16.95413
64.00884	55.78344	-17.04542
64.06050	56.80671	-17.15118
64.11050	57.79794	-17.22070
64.16217	58.82306	-17.30914
64.21384	59.84820	-17.39486
64.26384	60.84064	-17.48787
64.31717	61.89990	-17.56684
64.36718	62.89218	-17.65784
64.41884	63.91924	-17.72752
64.47050	64.94555	-17.80363
64.52050	65.94020	-17.88804
64.57218	66.96568	-17.99666
64.62383	67.99335	-18.04682
64.67383	68.98690	-18.18385
64.72718	70.04772	-18.24344
64.77717	71.04266	-18.29111
64.82885	72.07106	-18.37912
64.88050	73.09963	-18.46170
64.93050	74.09356	-18.52325
64.98383	75.15506	-18.58797
65.03384	76.14891	-18.71350
65.08384	77.14391	-18.77059
65.13717	78.20450	-18.89081
65.18717	79.19741	-18.97763
65.23882	80.22593	-19.09744
65.29050	81.25371	-19.16284
65.34050	82.24976	-19.23538
65.39384	83.30996	-19.33655
65.44384	84.30538	-19.40443
65.49384	85.30101	-19.50738
65.54718	86.36188	-19.58623
65.59718	87.35880	-19.66170
65.64884	88.38634	-19.79494
65.70050	89.41475	-19.87594
65.75050	90.40869	-20.02168
65.80384	91.47092	-20.09158
65.85384	92.46769	-20.10051
65.90384	93.46366	-20.24074
65.95718	94.52403	-20.32013
66.00718	95.52069	-20.41287
66.05884	96.54878	-20.50316
66.11050	97.57772	-20.60748
66.16050	98.57430	-20.63994
66.21384	99.63556	-20.77666
66.26384	100.6322	-20.82165
66.31384	101.6286	-20.89808
66.36718	102.6905	-21.03780
66.41718	103.6858	-21.11841
66.46884	104.7155	-21.19869
66.52050	105.7440	-21.29668
66.57050	106.7401	-21.44209
66.62384	107.8169	-20.87690
66.67384	108.7946	-21.73844
66.72384	109.7915	-21.68534
66.77718	110.8545	-21.76667
66.82718	111.8495	-21.90176
66.87884	112.8800	-22.01406
66.93050	113.9084	-22.04872
66.98050	114.9071	-22.09704
67.03384	115.9686	-22.24351
67.08384	116.9631	-22.37186
67.13384	117.9592	-22.40791
67.18718	119.0209	-22.60652
67.23718	120.0122	-22.71836
67.28882	121.0415	-22.76824
67.34050	122.0705	-22.85542
67.39050	123.0696	-22.86332
67.44384	124.1311	-23.10738
67.49384	125.1294	-23.21652
67.54550	126.1546	-23.29013
67.59718	127.1820	-23.38389
67.64718	128.1765	-23.73888
67.69884	129.2072	-23.66137
67.75050	130.2341	-23.81266
67.80050	131.2308	-23.83694
67.85384	132.2879	-23.97502
67.90384	133.2825	-24.06050
67.95550	134.3080	-24.25348
68.00718	135.3379	-24.26888
68.05718	136.3312	-24.49382
68.10884	137.3569	-24.59389
68.16050	138.3866	-24.64579
68.21050	139.3821	-24.80318
68.26384	140.4411	-24.91758
68.31384	141.4366	-25.03232
68.36550	142.4636	-25.22862
68.41718	143.4916	-25.30285
68.46718	144.4867	-25.44757
68.51882	145.5119	-25.57937
68.57050	146.5420	-25.61570
68.62050	147.5341	-25.85713
68.67384	148.5949	-25.88594
68.72384	149.5886	-26.11932
68.77550	150.6157	-26.21228
68.82718	151.6445	-26.30103
68.87718	152.6363	-26.60016
68.92884	153.6647	-26.55161
68.98050	154.6936	-26.65190
69.03050	155.6843	-26.85048
69.08384	156.7463	-27.19852
69.13384	157.7388	-27.10772
69.18550	158.7694	-27.12412
69.23718	159.7973	-27.56772
69.28718	160.7916	-27.45490
69.33884	161.8234	-27.51804
69.39050	162.8524	-27.47310
69.44050	163.8551	-27.62046
69.49384	164.9140	-27.70974
69.54384	165.9170	-27.61953
69.59550	166.9452	-27.80765
69.64718	167.9808	-27.73828
69.69718	168.9780	-27.92582
69.75050	170.0436	-27.88583
69.80050	171.0401	-28.11180
69.85050	172.0374	-28.11887
69.90384	173.0994	-28.28044
69.95384	174.0957	-28.26455
70.00550	175.1230	-28.52390
70.05718	176.1509	-28.53632
70.10718	177.1440	-28.85130
70.16050	178.2012	-28.85775
70.21050	179.1918	-29.15632
70.26050	180.1807	-29.32420
70.31384	181.2341	-29.84276
70.36384	182.2208	-29.86808
70.41550	183.2387	-30.14010
70.46718	184.2613	-30.37775
70.51716	185.2369	-30.75150
70.57050	186.2783	-31.45642
70.62050	187.2591	-31.69929
70.67050	188.2318	-32.32120
70.72384	189.2679	-32.81513
70.77384	190.2396	-33.28374
70.82550	191.2370	-34.13705
70.87718	192.2383	-34.71582
70.92718	193.1933	-35.46919
70.98050	194.2248	-36.22981
71.03050	195.1839	-36.64866
71.08050	196.1382	-37.84231
71.13384	197.1610	-38.60715
71.18384	198.1105	-39.30224
71.23550	199.0898	-40.59183
71.28718	200.0683	-41.59436
71.33716	201.0079	-42.31694
71.39050	202.0043	-43.65622
71.44050	202.9403	-44.93791
71.49050	203.8759	-45.89411
71.54384	204.8718	-47.11114
71.59384	205.8142	-47.83230
71.64550	206.8029	-48.43324
71.69718	207.8146	-48.36417
71.74718	208.8293	-46.63149
71.80050	209.9524	-45.26208
71.85050	211.0477	-43.09224
71.90050	212.1744	-39.89065
71.95384	213.3932	-37.78428
72.00384	214.5342	-35.81987
72.05550	215.6960	-34.11964
72.10718	216.8323	-32.64830
72.15718	217.9122	-31.93203
72.21050	219.0494	-31.01000
72.26050	220.1030	-30.62620
72.31216	221.1815	-30.00391
72.36384	222.2491	-29.46506
72.41382	223.2762	-29.31906
72.46550	224.3304	-28.99556
72.51716	225.3840	-29.07882
72.56718	226.3980	-28.70829
72.62050	227.4730	-28.74689
72.67050	228.4800	-28.71348
72.72218	229.5270	-28.55262
72.77384	230.5600	-28.80002
72.82384	231.5620	-28.63572
72.87550	232.6011	-28.76786
72.92718	233.6386	-28.44756
72.97718	234.6412	-28.27344
73.03050	235.7067	-28.68909
73.08050	236.7098	-28.52367
73.13218	237.7441	-28.58436
73.18384	238.7766	-28.75318
73.23384	239.7756	-28.75608
73.28550	240.8076	-28.78241
73.33716	241.8413	-28.67172
73.38718	242.8403	-28.77217
73.44050	243.9044	-29.00364
73.49050	244.9018	-29.07792
73.54218	246.0323	-26.89832
73.59384	247.0806	-26.01884
73.64384	248.0788	-27.34164
73.69550	249.0989	-27.51636
73.74718	250.1220	-27.64805
73.79718	251.1145	-27.76858
73.85050	252.1742	-27.87285
73.90050	253.1675	-27.97586
73.95216	254.1964	-28.08688
74.00384	255.2255	-28.15254
74.05384	256.2234	-28.19865
74.10550	257.2530	-28.27965
74.15718	258.2806	-28.47626
74.20718	259.2752	-28.60796
74.26050	260.3369	-28.68381
74.31050	261.3322	-28.71128
74.36218	262.3621	-28.78529
74.41382	263.3932	-28.84041
74.46384	264.3920	-28.82632
74.51716	265.4596	-28.54782
74.56718	266.4570	-28.65113
74.61718	267.4547	-28.90026
74.67050	268.5176	-29.04022
74.72050	269.5104	-29.31114
74.77218	270.5382	-29.33343
74.82384	271.5680	-29.37730
-2.000000	5.000000	0.0000000