File: 9-C1(1.2mol%)+C20(1.0mol%)/matlab/170-1.txt
CLOSED
Version	1.0
Language	English
Mode	Standard
Run	11
RunSerial	12279
Instrument	DSC Q2000 V24.11 Build 124
Module	DSC Standard Cell RC
Operator
File	\\AE520-1454\Users\dsc\Desktop\Data\29-08-17\170-1.001
ProcName
InstSerial	2000-0883
AutoSerial	1293
Sample	170-1
Size	12.0000	mg
PanMass	Not available
PanResist	Automatic Automatic  K/W
PanFactor	Default Default
Method
Comment
Xcomment	Pan: Tzero Aluminum Hermetic
Xcomment	Gas1: Nitrogen 50.0 ml/min
Xcomment	Gas2: Nitrogen 50.0 ml/min
Text
Exotherm	UP
Kcell	1.05230
Cpconst	Standard: 0.938
Calib	-38.6961
TempCal	1	pts	157.46	156.60
TzeroDt	-87.6168 -0.0009 -1.4231
TzeroDtz	-87.6168 0.0057 6.9570
InstCalFile	Tzero: \\Ae520-1454\ta\Data\DSC\Calibration\2017\CALIBRATION\1562_RCS (90)_05_18_2017 10_50_44.TZR
InstCalFile	Baseline: \\Ae520-1454\ta\Data\DSC\Calibration\2017\2017-05-17_Calibration.001
InstCalFile	Sapphire: \\Ae520-1454\ta\Data\DSC\Calibration\2017\2017-05-17_Saphire.001
InstCalDate	Tzero 2017-05-18 Time 10:50:44
TempRange	-87.39 to 398.39 °C at 10.00 °C/min Heat Only
AutoZero	Delta T Offset 0.000 uV
AutoZero	Delta T0 Offset 0.000 uV
MultiptCal	0
MultiPtDesc	0) Not set
AutoCellConst	Calibration Date 2017-05-18 16:59:28
Controls	Gas 1  Event Off  Sampling 0.2
Cell#	RC-01562
CoolingUnit	RCS (90)
SelHeatFlow	Heat Flow T4P (mW)
AutoLidII	Installed
AutoAnalysis	Off
MacroFile
Nsig	3
Sig1	Time (min)
Sig2	Temperature (°C)
Sig3	Heat Flow (mW)
Date	2017-08-30
Time	00:58:21
OrgMethod	1: Equilibrate at 80.00 °C
OrgMethod	2: Isothermal for 3.00 min
OrgMethod	3: Jump to 170.00 °C
OrgMethod	4: Mark end of cycle 1
OrgMethod	5: Isothermal for 40.00 min
OrgMethod	6: Mark end of cycle 2
OrgMethod	7: Ramp 20.00 °C/min to 280.00 °C
OrgMethod	8: Mark end of cycle 3
OrgMethod	9: Ramp 20.00 °C/min to 20.00 °C
OrgMethod	10: Mark end of cycle 4
OrgMethod	11: Ramp 20.00 °C/min to 280.00 °C
OrgMethod	12: Mark end of cycle 5
OrgFile	C:\Users\jarra\Desktop\DSC\9-C1(1.2mol%)+C20(1.0mol%)\170-1.001
StartOfData
4.99994E-4	79.91899	-0.8797595
0.05383332	79.92374	-0.7696299
0.1038333	79.92559	-0.6948674
0.1538333	79.92786	-0.6430500
0.2055000	79.92821	-0.6078242
0.2571667	79.92750	-0.5842388
0.3071666	79.92726	-0.5697149
0.3571666	79.92569	-0.5614372
0.4105000	79.92339	-0.5565731
0.4605000	79.92363	-0.5539326
0.5105000	79.92095	-0.5513396
0.5621668	79.92026	-0.5486802
0.6138334	79.91816	-0.5460956
0.6638332	79.91666	-0.5437512
0.7138332	79.91662	-0.5416050
0.7655000	79.91432	-0.5395338
0.8171668	79.91225	-0.5376629
0.8671666	79.91155	-0.5359985
0.9171668	79.91138	-0.5345085
0.9705000	79.91044	-0.5331023
1.020500	79.90888	-0.5319663
1.070500	79.90824	-0.5309901
1.122166	79.90732	-0.5301354
1.173834	79.90669	-0.5294180
1.223833	79.90569	-0.5288656
1.273834	79.90482	-0.5283744
1.325500	79.90399	-0.5280370
1.377166	79.90345	-0.5277546
1.427167	79.90295	-0.5275822
1.477166	79.90150	-0.5274482
1.530500	79.90064	-0.5274170
1.580500	79.90066	-0.5274703
1.630500	79.89950	-0.5275350
1.682167	79.90014	-0.5276942
1.733833	79.89899	-0.5279246
1.783833	79.89774	-0.5281574
1.833833	79.89830	-0.5284802
1.885500	79.89663	-0.5288654
1.937166	79.89637	-0.5292890
1.987166	79.89572	-0.5297281
2.037166	79.89478	-0.5301944
2.090500	79.89500	-0.5307304
2.140500	79.89434	-0.5312161
2.190500	79.89370	-0.5317650
2.242166	79.89320	-0.5323889
2.293833	79.89243	-0.5330088
2.343834	79.89105	-0.5336250
2.393833	79.89078	-0.5342726
2.447166	79.89080	-0.5350310
2.497166	79.89130	-0.5357880
2.547166	79.89050	-0.5365014
2.598834	79.88953	-0.5372770
2.650500	79.89032	-0.5380625
2.700500	79.88897	-0.5388628
2.750500	79.88925	-0.5396810
2.802166	79.88866	-0.5405092
2.853833	79.88836	-0.5413222
2.903833	79.88750	-0.5421406
2.953833	79.88746	-0.5429729
3.000500	79.88549	-0.5438282
3.053833	80.51881	-3.784450
3.103833	82.96140	-10.95658
3.153833	85.94524	-17.41444
3.205500	89.47045	-23.76892
3.257167	93.32916	-29.28223
3.307167	97.28945	-33.75250
3.357167	101.4168	-37.41641
3.410500	105.9454	-40.53100
3.460500	110.2742	-42.81898
3.510500	114.6574	-44.61358
3.562167	119.2199	-46.09463
3.613834	123.8006	-47.31389
3.663833	128.2413	-48.18175
3.713833	132.6832	-48.89041
3.765500	137.2706	-49.40911
3.817166	141.8488	-49.69714
3.867166	146.2752	-49.71944
3.917167	150.6900	-49.64390
3.970500	155.3604	-49.50813
4.020500	159.0136	-46.22486
4.070500	161.2534	-39.49090
4.122166	162.9702	-32.56660
4.173834	164.2404	-25.96010
4.223834	165.1859	-20.47471
4.273834	165.9256	-15.97756
4.325500	166.5323	-12.29350
4.377167	167.0164	-9.440262
4.427166	167.3981	-7.324610
4.477167	167.7144	-5.709936
4.530500	167.9934	-4.398574
4.580500	168.2124	-3.468105
4.630500	168.4006	-2.747058
4.682167	168.5669	-2.162027
4.733834	168.7116	-1.689813
4.783834	168.8342	-1.310991
4.833834	168.9431	-0.9856949
4.885500	169.0436	-0.6816980
4.937167	169.1334	-0.4045418
4.987167	169.2114	-0.1469671
5.037167	169.2840	0.1047742
5.090500	169.3538	0.3749588
5.140500	169.4144	0.6322454
5.190500	169.4707	0.8933501
5.242167	169.5252	1.176233
5.293832	169.5762	1.473738
5.343834	169.6231	1.768161
5.393832	169.6686	2.080950
5.447168	169.7143	2.426155
5.497168	169.7558	2.767963
5.547168	169.7971	3.126707
5.598832	169.8396	3.515453
5.650500	169.8810	3.925378
5.700500	169.9205	4.334972
5.750500	169.9600	4.759781
5.802168	169.9998	5.211100
5.853832	170.0394	5.670651
5.903834	170.0775	6.116200
5.953832	170.1140	6.556508
6.007168	170.1513	7.004941
6.057168	170.1836	7.405078
6.107168	170.2138	7.760226
6.158832	170.2414	8.085538
6.210500	170.2644	8.357620
6.260500	170.2826	8.558830
6.310500	170.2974	8.703970
6.362168	170.3092	8.798226
6.413832	170.3168	8.846640
6.463834	170.3220	8.860428
6.513834	170.3244	8.861622
6.567168	170.3263	8.860507
6.617166	170.3278	8.858668
6.667168	170.3294	8.856449
6.718832	170.3324	8.854786
6.770500	170.3368	8.857475
6.820500	170.3430	8.900811
6.870500	170.3519	9.021762
6.922168	170.3618	9.181170
6.973834	170.3723	9.351218
7.023834	170.3853	9.524746
7.073834	170.3980	9.709731
7.127168	170.4118	9.901157
7.177168	170.4250	10.08223
7.227168	170.4364	10.25009
7.278832	170.4481	10.40792
7.330500	170.4578	10.54614
7.380500	170.4669	10.65717
7.430500	170.4732	10.74040
7.483832	170.4792	10.79796
7.533832	170.4823	10.82146
7.583832	170.4826	10.82530
7.635500	170.4811	10.82310
7.687168	170.4765	10.77593
7.737168	170.4706	10.63652
7.787168	170.4635	10.47046
7.838834	170.4536	10.29401
7.890500	170.4421	10.10141
7.940500	170.4312	9.894549
7.990500	170.4173	9.676920
8.043834	170.4030	9.432550
8.093832	170.3882	9.193649
8.143832	170.3729	8.946254
8.195500	170.3563	8.687450
8.247168	170.3398	8.418659
8.297168	170.3235	8.155796
8.347168	170.3064	7.895288
8.398834	170.2902	7.634388
8.450500	170.2744	7.390593
8.500500	170.2592	7.166381
8.550500	170.2475	6.965632
8.603832	170.2363	6.793824
8.653832	170.2275	6.675380
8.703834	170.2209	6.594353
8.755500	170.2181	6.550010
8.807168	170.2171	6.533540
8.857166	170.2166	6.531837
8.907166	170.2184	6.532455
8.958832	170.2201	6.534428
9.010499	170.2223	6.540396
9.060500	170.2233	6.545846
9.110500	170.2231	6.549204
9.163834	170.2208	6.551593
9.213834	170.2201	6.548959
9.263832	170.2154	6.500630
9.315500	170.2092	6.363047
9.367166	170.1996	6.186368
9.417168	170.1882	5.981800
9.467168	170.1745	5.747363
9.520500	170.1574	5.456912
9.570500	170.1384	5.151163
9.620499	170.1180	4.821044
9.672168	170.0947	4.452880
9.723832	170.0709	4.069299
9.773834	170.0459	3.686622
9.823834	170.0210	3.300578
9.875500	169.9972	2.902066
9.927168	169.9709	2.513511
9.977168	169.9482	2.146643
10.02717	169.9249	1.789304
10.08050	169.9015	1.432395
10.13050	169.8807	1.113645
10.18050	169.8618	0.8172415
10.23217	169.8434	0.5318508
10.28383	169.8261	0.2723740
10.33383	169.8102	0.04434654
10.38383	169.7964	-0.1682381
10.43550	169.7840	-0.3652424
10.48717	169.7725	-0.5412156
10.53717	169.7616	-0.6912328
10.58717	169.7525	-0.8289384
10.64050	169.7443	-0.9578392
10.69050	169.7374	-1.065459
10.74050	169.7306	-1.158329
10.79217	169.7250	-1.245135
10.84383	169.7190	-1.319352
10.89383	169.7146	-1.383696
10.94383	169.7119	-1.439126
10.99550	169.7079	-1.490254
11.04717	169.7055	-1.535619
11.09717	169.7012	-1.572624
11.14717	169.6998	-1.606152
11.20050	169.6928	-1.789591
11.25050	169.6814	-1.938105
11.30050	169.6815	-1.925284
11.35217	169.6826	-1.920906
11.40383	169.6824	-1.920330
11.45384	169.6822	-1.920352
11.50384	169.6819	-1.920849
11.55717	169.6811	-1.921918
11.60717	169.6809	-1.923529
11.65717	169.6806	-1.925676
11.70883	169.6797	-1.928518
11.76050	169.6788	-1.931999
11.81050	169.6779	-1.935725
11.86050	169.6780	-1.939834
11.91217	169.6774	-1.944449
11.96383	169.6773	-1.949375
12.01383	169.6762	-1.954341
12.06383	169.6748	-1.959527
12.11716	169.6742	-1.965292
12.16717	169.6740	-1.970892
12.21717	169.6741	-1.976616
12.26883	169.6734	-1.982694
12.32050	169.6729	-1.988825
12.37050	169.6738	-1.994918
12.42050	169.6721	-2.000977
12.47217	169.6731	-2.007388
12.52383	169.6716	-2.013751
12.57383	169.6716	-2.019894
12.62383	169.6714	-2.026037
12.67717	169.6715	-2.032490
12.72717	169.6703	-2.038515
12.77717	169.6710	-2.044498
12.82883	169.6694	-2.050575
12.88050	169.6699	-2.056591
12.93050	169.6701	-2.062410
12.98050	169.6692	-2.068028
13.03217	169.6688	-2.073746
13.08383	169.6685	-2.079369
13.13383	169.6686	-2.084825
13.18383	169.6684	-2.090095
13.23716	169.6680	-2.095601
13.28717	169.6674	-2.100720
13.33717	169.6684	-2.105739
13.38883	169.6675	-2.110810
13.44050	169.6685	-2.115805
13.49050	169.6670	-2.120455
13.54050	169.6670	-2.125064
13.59383	169.6663	-2.129817
13.64383	169.6666	-2.134240
13.69384	169.6666	-2.138492
13.74550	169.6674	-2.142778
13.79717	169.6668	-2.146979
13.84717	169.6664	-2.150944
13.89717	169.6665	-2.154762
13.94884	169.6663	-2.158698
14.00050	169.6653	-2.162510
14.05050	169.6658	-2.166140
14.10050	169.6669	-2.169712
14.15383	169.6655	-2.173370
14.20383	169.6661	-2.176813
14.25383	169.6661	-2.180102
14.30550	169.6650	-2.183396
14.35716	169.6658	-2.186638
14.40717	169.6657	-2.189658
14.45717	169.6662	-2.192602
14.50883	169.6654	-2.195512
14.56050	169.6655	-2.198460
14.61050	169.6655	-2.201219
14.66050	169.6653	-2.203966
14.71383	169.6660	-2.206824
14.76383	169.6659	-2.209444
14.81383	169.6660	-2.211985
14.86550	169.6650	-2.214503
14.91716	169.6655	-2.216958
14.96716	169.6656	-2.219312
15.01717	169.6662	-2.221630
15.06884	169.6653	-2.223920
15.12050	169.6659	-2.226244
15.17050	169.6654	-2.228358
15.22050	169.6648	-2.230404
15.27383	169.6645	-2.232536
15.32384	169.6658	-2.234562
15.37384	169.6653	-2.236480
15.42550	169.6654	-2.238414
15.47717	169.6653	-2.240303
15.52717	169.6653	-2.242080
15.57717	169.6661	-2.243765
15.63050	169.6646	-2.245492
15.68050	169.6646	-2.247055
15.73050	169.6650	-2.248583
15.78217	169.6650	-2.250120
15.83383	169.6646	-2.251610
15.88383	169.6654	-2.253062
15.93383	169.6651	-2.254447
15.98550	169.6653	-2.255864
16.03717	169.6646	-2.257224
16.08716	169.6641	-2.258580
16.13716	169.6651	-2.259970
16.19050	169.6655	-2.261380
16.24050	169.6651	-2.262666
16.29050	169.6648	-2.263842
16.34216	169.6650	-2.265044
16.39383	169.6655	-2.266234
16.44383	169.6651	-2.267371
16.49383	169.6647	-2.268498
16.54550	169.6655	-2.269634
16.59716	169.6653	-2.270718
16.64716	169.6644	-2.271733
16.69716	169.6647	-2.272746
16.75050	169.6646	-2.273783
16.80050	169.6646	-2.274858
16.85050	169.6646	-2.275916
16.90216	169.6655	-2.276988
16.95383	169.6651	-2.277996
17.00383	169.6647	-2.278956
17.05383	169.6657	-2.279893
17.10550	169.6651	-2.280773
17.15716	169.6654	-2.281644
17.20716	169.6650	-2.282430
17.25716	169.6642	-2.283206
17.31050	169.6648	-2.283987
17.36050	169.6644	-2.284721
17.41050	169.6644	-2.285522
17.46216	169.6639	-2.286302
17.51383	169.6646	-2.287053
17.56383	169.6648	-2.287760
17.61383	169.6647	-2.288438
17.66716	169.6651	-2.289154
17.71716	169.6651	-2.289821
17.76716	169.6639	-2.290459
17.81883	169.6644	-2.291112
17.87050	169.6639	-2.291760
17.92050	169.6653	-2.292363
17.97050	169.6652	-2.292977
18.02216	169.6642	-2.293531
18.07383	169.6645	-2.294050
18.12383	169.6652	-2.294540
18.17383	169.6647	-2.295056
18.22716	169.6646	-2.295616
18.27716	169.6641	-2.296112
18.32716	169.6637	-2.296550
18.37883	169.6646	-2.297010
18.43050	169.6638	-2.297361
18.48050	169.6642	-2.297736
18.53050	169.6639	-2.298128
18.58216	169.6648	-2.298563
18.63383	169.6642	-2.298963
18.68383	169.6641	-2.299345
18.73383	169.6650	-2.299748
18.78717	169.6643	-2.300159
18.83716	169.6643	-2.300570
18.88716	169.6641	-2.300972
18.93883	169.6649	-2.301438
18.99050	169.6644	-2.301838
19.04050	169.6647	-2.302167
19.09050	169.6651	-2.302526
19.14216	169.6648	-2.302846
19.19383	169.6652	-2.303176
19.24383	169.6650	-2.303506
19.29383	169.6642	-2.303766
19.34716	169.6647	-2.304137
19.39716	169.6644	-2.304435
19.44716	169.6650	-2.304763
19.49883	169.6644	-2.305038
19.55050	169.6651	-2.305376
19.60050	169.6641	-2.305609
19.65050	169.6642	-2.305848
19.70383	169.6642	-2.306130
19.75383	169.6636	-2.306418
19.80383	169.6644	-2.306712
19.85550	169.6647	-2.307021
19.90716	169.6653	-2.307326
19.95716	169.6646	-2.307550
20.00716	169.6644	-2.307900
20.05883	169.6644	-2.308198
20.11050	169.6652	-2.308551
20.16050	169.6644	-2.308898
20.21050	169.6649	-2.309213
20.26383	169.6646	-2.309534
20.31383	169.6651	-2.309890
20.36383	169.6651	-2.310166
20.41550	169.6646	-2.310451
20.46716	169.6649	-2.310727
20.51716	169.6656	-2.311054
20.56716	169.6648	-2.311317
20.61883	169.6654	-2.311635
20.67050	169.6647	-2.311924
20.72050	169.6655	-2.312158
20.77050	169.6649	-2.312366
20.82383	169.6648	-2.312649
20.87383	169.6647	-2.312890
20.92383	169.6656	-2.313127
20.97550	169.6653	-2.313334
21.02717	169.6658	-2.313574
21.07716	169.6654	-2.313755
21.12716	169.6637	-2.313934
21.17883	169.6652	-2.314197
21.23050	169.6652	-2.314362
21.28050	169.6644	-2.314526
21.33050	169.6641	-2.314652
21.38383	169.6644	-2.314831
21.43383	169.6646	-2.315027
21.48383	169.6648	-2.315218
21.53550	169.6646	-2.315446
21.58716	169.6650	-2.315627
21.63716	169.6647	-2.315800
21.68716	169.6646	-2.315972
21.74050	169.6650	-2.316138
21.79050	169.6654	-2.316265
21.84050	169.6640	-2.316410
21.89216	169.6648	-2.316572
21.94383	169.6645	-2.316749
21.99383	169.6642	-2.316888
22.04383	169.6652	-2.317114
22.09550	169.6642	-2.317266
22.14716	169.6646	-2.317516
22.19716	169.6658	-2.317785
22.24716	169.6652	-2.318028
22.30050	169.6651	-2.318306
22.35050	169.6656	-2.318555
22.40050	169.6659	-2.318739
22.45216	169.6660	-2.318916
22.50383	169.6655	-2.319077
22.55383	169.6658	-2.319276
22.60383	169.6658	-2.319408
22.65550	169.6663	-2.319575
22.70717	169.6658	-2.319687
22.75716	169.6665	-2.319886
22.80716	169.6660	-2.320004
22.86050	169.6661	-2.320101
22.91050	169.6658	-2.320186
22.96050	169.6656	-2.320236
23.01216	169.6663	-2.320310
23.06383	169.6652	-2.320392
23.11383	169.6660	-2.320464
23.16383	169.6659	-2.320566
23.21550	169.6661	-2.320658
23.26716	169.6656	-2.320756
23.31716	169.6653	-2.320898
23.36716	169.6655	-2.321035
23.42050	169.6653	-2.321197
23.47050	169.6653	-2.321278
23.52050	169.6652	-2.321335
23.57216	169.6646	-2.321398
23.62383	169.6649	-2.321484
23.67383	169.6648	-2.321601
23.72383	169.6653	-2.321713
23.77717	169.6649	-2.321776
23.82716	169.6654	-2.321842
23.87716	169.6648	-2.321912
23.92883	169.6649	-2.321992
23.98050	169.6649	-2.322017
24.03050	169.6647	-2.322044
24.08050	169.6651	-2.322105
24.13216	169.6645	-2.322127
24.18383	169.6652	-2.322228
24.23383	169.6649	-2.322296
24.28383	169.6649	-2.322414
24.33716	169.6646	-2.322511
24.38716	169.6654	-2.322677
24.43716	169.6642	-2.322793
24.48883	169.6655	-2.322942
24.54050	169.6644	-2.323018
24.59050	169.6645	-2.323126
24.64050	169.6651	-2.323250
24.69216	169.6646	-2.323356
24.74383	169.6654	-2.323514
24.79383	169.6658	-2.323647
24.84383	169.6655	-2.323751
24.89716	169.6653	-2.323801
24.94716	169.6661	-2.323910
24.99716	169.6655	-2.323974
25.04883	169.6652	-2.324038
25.10050	169.6664	-2.324119
25.15050	169.6654	-2.324129
25.20050	169.6652	-2.324174
25.25217	169.6647	-2.324172
25.30383	169.6656	-2.324176
25.35383	169.6648	-2.324151
25.40383	169.6653	-2.324150
25.45717	169.6648	-2.324166
25.50716	169.6650	-2.324187
25.55716	169.6652	-2.324290
25.60883	169.6656	-2.324402
25.66050	169.6658	-2.324522
25.71050	169.6660	-2.324594
25.76050	169.6656	-2.324685
25.81383	169.6656	-2.324767
25.86383	169.6658	-2.324806
25.91383	169.6657	-2.324875
25.96550	169.6660	-2.324894
26.01716	169.6659	-2.324934
26.06716	169.6656	-2.324912
26.11716	169.6663	-2.324946
26.16883	169.6655	-2.325008
26.22050	169.6661	-2.325080
26.27050	169.6655	-2.325124
26.32050	169.6656	-2.325238
26.37383	169.6656	-2.325340
26.42383	169.6659	-2.325408
26.47383	169.6667	-2.325471
26.52550	169.6657	-2.325454
26.57717	169.6646	-2.325460
26.62716	169.6657	-2.325360
26.67717	169.6652	-2.325302
26.72883	169.6659	-2.325274
26.78050	169.6657	-2.325268
26.83050	169.6654	-2.325316
26.88050	169.6660	-2.325358
26.93383	169.6658	-2.325460
26.98383	169.6654	-2.325535
27.03383	169.6654	-2.325610
27.08550	169.6659	-2.325615
27.13716	169.6656	-2.325664
27.18717	169.6661	-2.325660
27.23716	169.6662	-2.325731
27.28883	169.6660	-2.325800
27.34050	169.6656	-2.325818
27.39050	169.6654	-2.325901
27.44050	169.6663	-2.325994
27.49383	169.6650	-2.326048
27.54383	169.6666	-2.326118
27.59383	169.6658	-2.326142
27.64550	169.6654	-2.326122
27.69717	169.6658	-2.326155
27.74716	169.6650	-2.326076
27.79716	169.6654	-2.326079
27.85050	169.6653	-2.326027
27.90050	169.6656	-2.326057
27.95050	169.6648	-2.326004
28.00217	169.6651	-2.326020
28.05383	169.6653	-2.326058
28.10383	169.6651	-2.326163
28.15383	169.6651	-2.326214
28.20550	169.6652	-2.326276
28.25716	169.6659	-2.326373
28.30716	169.6647	-2.326473
28.35716	169.6650	-2.326599
28.41050	169.6656	-2.326724
28.46050	169.6654	-2.326895
28.51050	169.6654	-2.326952
28.56217	169.6656	-2.327053
28.61383	169.6656	-2.327155
28.66383	169.6662	-2.327270
28.71383	169.6649	-2.327329
28.76550	169.6663	-2.327442
28.81716	169.6658	-2.327554
28.86716	169.6651	-2.327651
28.91716	169.6650	-2.327734
28.97050	169.6658	-2.327807
29.02050	169.6655	-2.327852
29.07050	169.6656	-2.327838
29.12216	169.6660	-2.327927
29.17383	169.6662	-2.327991
29.22383	169.6657	-2.327990
29.27383	169.6664	-2.328006
29.32550	169.6658	-2.328041
29.37716	169.6663	-2.328156
29.42717	169.6663	-2.328213
29.47717	169.6653	-2.328268
29.53050	169.6661	-2.328303
29.58050	169.6659	-2.328299
29.63050	169.6656	-2.328336
29.68216	169.6658	-2.328319
29.73383	169.6656	-2.328251
29.78383	169.6658	-2.328217
29.83383	169.6652	-2.328180
29.88716	169.6662	-2.328178
29.93717	169.6660	-2.328120
29.98716	169.6658	-2.328054
30.03883	169.6654	-2.327999
30.09050	169.6658	-2.328005
30.14050	169.6655	-2.328019
30.19050	169.6657	-2.327997
30.24216	169.6654	-2.328003
30.29383	169.6654	-2.328056
30.34383	169.6653	-2.328071
30.39383	169.6656	-2.328067
30.44717	169.6658	-2.328031
30.49716	169.6659	-2.327978
30.54716	169.6649	-2.327935
30.59883	169.6654	-2.327839
30.65050	169.6656	-2.327786
30.70050	169.6657	-2.327744
30.75050	169.6664	-2.327683
30.80217	169.6658	-2.327622
30.85383	169.6655	-2.327556
30.90383	169.6665	-2.327548
30.95383	169.6665	-2.327549
31.00716	169.6662	-2.327598
31.05716	169.6665	-2.327598
31.10716	169.6656	-2.327614
31.15883	169.6662	-2.327638
31.21050	169.6662	-2.327661
31.26050	169.6660	-2.327730
31.31050	169.6664	-2.327780
31.36216	169.6658	-2.327793
31.41383	169.6665	-2.327830
31.46383	169.6656	-2.327847
31.51383	169.6660	-2.327920
31.56716	169.6663	-2.327957
31.61716	169.6665	-2.327963
31.66716	169.6654	-2.327975
31.71883	169.6655	-2.328008
31.77050	169.6656	-2.328030
31.82050	169.6656	-2.328020
31.87050	169.6658	-2.328130
31.92383	169.6671	-2.328247
31.97383	169.6660	-2.328295
32.02383	169.6669	-2.328416
32.07550	169.6660	-2.328491
32.12717	169.6665	-2.328631
32.17717	169.6655	-2.328655
32.22717	169.6664	-2.328705
32.27883	169.6659	-2.328688
32.33050	169.6662	-2.328678
32.38050	169.6659	-2.328655
32.43050	169.6656	-2.328680
32.48383	169.6659	-2.328673
32.53383	169.6665	-2.328712
32.58383	169.6664	-2.328756
32.63550	169.6660	-2.328789
32.68716	169.6666	-2.328835
32.73717	169.6667	-2.328914
32.78717	169.6663	-2.328911
32.83883	169.6659	-2.328892
32.89050	169.6666	-2.328876
32.94050	169.6662	-2.328825
32.99050	169.6664	-2.328829
33.04383	169.6656	-2.328776
33.09384	169.6662	-2.328742
33.14383	169.6666	-2.328700
33.19550	169.6662	-2.328690
33.24716	169.6658	-2.328652
33.29716	169.6662	-2.328676
33.34716	169.6659	-2.328663
33.39883	169.6658	-2.328686
33.45050	169.6658	-2.328696
33.50050	169.6666	-2.328728
33.55050	169.6666	-2.328746
33.60383	169.6659	-2.328739
33.65383	169.6662	-2.328803
33.70383	169.6662	-2.328789
33.75550	169.6658	-2.328792
33.80716	169.6663	-2.328831
33.85716	169.6664	-2.328852
33.90716	169.6661	-2.328833
33.96050	169.6662	-2.328848
34.01050	169.6656	-2.328830
34.06050	169.6661	-2.328860
34.11217	169.6658	-2.328843
34.16383	169.6666	-2.328837
34.21383	169.6655	-2.328817
34.26383	169.6658	-2.328884
34.31550	169.6663	-2.328991
34.36716	169.6665	-2.329070
34.41716	169.6661	-2.329143
34.46716	169.6657	-2.329211
34.52050	169.6667	-2.329300
34.57050	169.6667	-2.329393
34.62050	169.6665	-2.329381
34.67216	169.6662	-2.329396
34.72383	169.6666	-2.329405
34.77383	169.6660	-2.329430
34.82383	169.6656	-2.329402
34.87550	169.6664	-2.329429
34.92717	169.6666	-2.329440
34.97717	169.6659	-2.329402
35.02716	169.6662	-2.329357
35.08050	169.6669	-2.329319
35.13050	169.6652	-2.329265
35.18050	169.6652	-2.329214
35.23216	169.6659	-2.329211
35.28383	169.6661	-2.329276
35.33383	169.6653	-2.329260
35.38383	169.6660	-2.329321
35.43550	169.6662	-2.329385
35.48717	169.6659	-2.329383
35.53717	169.6663	-2.329385
35.58716	169.6660	-2.329456
35.64050	169.6669	-2.329523
35.69050	169.6669	-2.329561
35.74050	169.6668	-2.329588
35.79217	169.6660	-2.329570
35.84384	169.6663	-2.329582
35.89383	169.6654	-2.329556
35.94383	169.6661	-2.329524
35.99716	169.6666	-2.329492
36.04716	169.6660	-2.329398
36.09716	169.6659	-2.329350
36.14883	169.6658	-2.329320
36.20050	169.6660	-2.329328
36.25050	169.6667	-2.329340
36.30050	169.6660	-2.329358
36.35217	169.6660	-2.329326
36.40383	169.6660	-2.329333
36.45383	169.6657	-2.329295
36.50383	169.6660	-2.329234
36.55716	169.6661	-2.329202
36.60716	169.6661	-2.329184
36.65716	169.6668	-2.329186
36.70883	169.6654	-2.329143
36.76050	169.6662	-2.329170
36.81050	169.6668	-2.329158
36.86050	169.6661	-2.329138
36.91217	169.6664	-2.329161
36.96383	169.6662	-2.329148
37.01383	169.6661	-2.329157
37.06383	169.6659	-2.329153
37.11716	169.6669	-2.329107
37.16716	169.6667	-2.329066
37.21716	169.6658	-2.329031
37.26883	169.6662	-2.329008
37.32050	169.6656	-2.328987
37.37050	169.6665	-2.328958
37.42050	169.6660	-2.328912
37.47217	169.6660	-2.328958
37.52383	169.6663	-2.329004
37.57383	169.6659	-2.329026
37.62383	169.6658	-2.329050
37.67717	169.6661	-2.329075
37.72717	169.6665	-2.329020
37.77716	169.6658	-2.329028
37.82883	169.6662	-2.329061
37.88050	169.6663	-2.329090
37.93050	169.6666	-2.329113
37.98050	169.6663	-2.329112
38.03383	169.6663	-2.329082
38.08383	169.6652	-2.328980
38.13383	169.6649	-2.328873
38.18550	169.6652	-2.328802
38.23717	169.6656	-2.328705
38.28717	169.6658	-2.328640
38.33716	169.6659	-2.328600
38.38883	169.6657	-2.328588
38.44050	169.6660	-2.328630
38.49050	169.6658	-2.328641
38.54050	169.6656	-2.328661
38.59384	169.6659	-2.328654
38.64383	169.6652	-2.328631
38.69383	169.6664	-2.328709
38.74550	169.6659	-2.328802
38.79716	169.6665	-2.328860
38.84716	169.6666	-2.328910
38.89717	169.6670	-2.328996
38.94883	169.6663	-2.329048
39.00050	169.6663	-2.329093
39.05050	169.6674	-2.329120
39.10050	169.6666	-2.329114
39.15383	169.6663	-2.329125
39.20383	169.6660	-2.329170
39.25383	169.6667	-2.329214
39.30550	169.6670	-2.329196
39.35716	169.6659	-2.329172
39.40716	169.6662	-2.329144
39.45716	169.6672	-2.329175
39.50883	169.6662	-2.329114
39.56050	169.6661	-2.329017
39.61050	169.6660	-2.329033
39.66050	169.6656	-2.329036
39.71383	169.6654	-2.329078
39.76383	169.6656	-2.329080
39.81383	169.6666	-2.329094
39.86550	169.6660	-2.329075
39.91716	169.6669	-2.329130
39.96716	169.6667	-2.329176
40.01716	169.6671	-2.329218
40.07050	169.6659	-2.329218
40.12050	169.6661	-2.329236
40.17050	169.6658	-2.329268
40.22217	169.6666	-2.329266
40.27383	169.6663	-2.329318
40.32383	169.6661	-2.329350
40.37383	169.6671	-2.329417
40.42550	169.6666	-2.329425
40.47717	169.6670	-2.329440
40.52716	169.6671	-2.329440
40.57717	169.6670	-2.329410
40.63050	169.6661	-2.329396
40.68050	169.6669	-2.329455
40.73050	169.6658	-2.329456
40.78216	169.6659	-2.329487
40.83383	169.6662	-2.329446
40.88383	169.6656	-2.329375
40.93384	169.6661	-2.329258
40.98550	169.6659	-2.329197
41.03717	169.6660	-2.329152
41.08716	169.6666	-2.329106
41.13716	169.6659	-2.329035
41.19050	169.6658	-2.328993
41.24050	169.6658	-2.328958
41.29050	169.6660	-2.328981
41.34217	169.6661	-2.328980
41.39383	169.6669	-2.329031
41.44383	169.6666	-2.329015
41.49383	169.6663	-2.329031
41.54550	169.6669	-2.329040
41.59716	169.6666	-2.329065
41.64717	169.6658	-2.329028
41.69717	169.6662	-2.329106
41.75050	169.6663	-2.329170
41.80050	169.6663	-2.329174
41.85050	169.6671	-2.329222
41.90216	169.6666	-2.329219
41.95383	169.6664	-2.329238
42.00383	169.6664	-2.329220
42.05383	169.6665	-2.329272
42.10717	169.6658	-2.329243
42.15717	169.6666	-2.329277
42.20717	169.6654	-2.329250
42.25883	169.6656	-2.329271
42.31050	169.6662	-2.329238
42.36050	169.6653	-2.329224
42.41050	169.6652	-2.329254
42.46216	169.6664	-2.329342
42.51383	169.6666	-2.329427
42.56383	169.6661	-2.329502
42.61383	169.6660	-2.329515
42.66716	169.6655	-2.329566
42.71717	169.6667	-2.329657
42.76717	169.6662	-2.329716
42.81883	169.6662	-2.329743
42.87050	169.6662	-2.329736
42.92050	169.6657	-2.329764
42.97050	169.6664	-2.329784
43.02050	169.6667	-2.330070
43.07217	169.7850	-3.460283
43.12383	170.2183	-5.938622
43.17383	170.8019	-8.035855
43.22383	171.5005	-9.774275
43.27716	172.3306	-11.16617
43.32717	173.1666	-12.14420
43.37717	174.0404	-12.87479
43.42883	174.9747	-13.43822
43.48050	175.9302	-13.86702
43.53050	176.8703	-14.18402
43.58050	177.8206	-14.44040
43.63217	178.8116	-14.65989
43.68383	179.8102	-14.83491
43.73383	180.7805	-14.98468
43.78383	181.7558	-15.12109
43.83716	182.7984	-15.22419
43.88716	183.7789	-15.31147
43.93716	184.7616	-15.40232
43.98883	185.7774	-15.56762
44.04050	186.7941	-15.63012
44.09050	187.7795	-15.73813
44.14050	188.7641	-15.88102
44.19383	189.8153	-16.03541
44.24383	190.7987	-16.21414
44.29383	191.7828	-16.42519
44.34550	192.7976	-16.65135
44.39717	193.8128	-16.91289
44.44717	194.7928	-17.22893
44.49716	195.7694	-17.60884
44.54883	196.7755	-18.09806
44.60050	197.7756	-18.69992
44.65050	198.7373	-19.43449
44.70050	199.6909	-20.33589
44.75383	200.6976	-21.48628
44.80383	201.6312	-22.73400
44.85383	202.5538	-24.12047
44.90550	203.5021	-25.66594
44.95717	204.4401	-27.42834
45.00717	205.3359	-29.34763
45.05717	206.2222	-31.42728
45.10883	207.1276	-33.71258
45.16050	208.0262	-35.93954
45.21050	208.9000	-37.90587
45.26050	209.7810	-39.64567
45.31383	210.7392	-40.91902
45.36383	211.6706	-41.24960
45.41383	212.6528	-40.35767
45.46550	213.7498	-37.16176
45.51717	214.9513	-32.27798
45.56717	216.1976	-26.93452
45.61716	217.4594	-23.20531
45.66883	218.7088	-20.96346
45.72050	219.8982	-19.47640
45.77050	221.0068	-18.46380
45.82050	222.0841	-17.74761
45.87383	223.2078	-17.21945
45.92383	224.2467	-16.87454
45.97383	225.2732	-16.62945
46.02550	226.3253	-16.47332
46.07717	227.3712	-16.36382
46.12717	228.3793	-16.30503
46.17717	229.3842	-16.28535
46.23050	230.4540	-16.27270
46.28050	231.4555	-16.27081
46.33050	232.4544	-16.27108
46.38217	233.4880	-16.27300
46.43383	234.5199	-16.27788
46.48383	235.5190	-16.29176
46.53383	236.5182	-16.30542
46.58550	237.5501	-16.32765
46.63716	238.5811	-16.35359
46.68716	239.5803	-16.38078
46.73717	240.5774	-16.41150
46.79050	241.6414	-16.45218
46.84050	242.6402	-16.48799
46.89050	243.6378	-16.52005
46.94217	244.6700	-16.55458
46.99383	245.7013	-16.58309
47.04383	246.6984	-16.61640
47.09384	247.6970	-16.63866
47.14550	248.7283	-16.65976
47.19717	249.7596	-16.68074
47.24716	250.7585	-16.70154
47.29716	251.7560	-16.72406
47.35050	252.8203	-16.74855
47.40050	253.8196	-16.77212
47.45050	254.8177	-16.79420
47.50217	255.8480	-16.82347
47.55383	256.8804	-16.86061
47.60383	257.8773	-16.89286
47.65383	258.8750	-16.92921
47.70550	259.9063	-16.96768
47.75717	260.9380	-17.00573
47.80717	261.9346	-17.03554
47.85717	262.9329	-17.07733
47.91050	263.9989	-17.11397
47.96050	264.9977	-17.15270
48.01050	265.9954	-17.18686
48.06216	267.0281	-17.21646
48.11383	268.0586	-17.24365
48.16383	269.0568	-17.27501
48.21383	270.0548	-17.30501
48.26717	271.1192	-17.33231
48.31717	272.1160	-17.35819
48.36716	273.1146	-17.38707
48.41883	274.1450	-17.41681
48.47050	275.1754	-17.43397
48.51717	276.1056	-17.51110
48.56717	276.8726	-17.76527
48.62050	276.9784	-14.36944
48.67050	276.7517	-9.678150
48.72050	276.3084	-5.335513
48.77217	275.7012	-1.745587
48.82383	274.9863	0.9770996
48.87383	274.2209	2.921518
48.92383	273.4015	4.366280
48.97550	272.5154	5.443033
49.02716	271.5984	6.229822
49.07717	270.6889	6.781046
49.12717	269.7636	7.188922
49.18050	268.7636	7.501553
49.23050	267.8164	7.723321
49.28050	266.8611	7.891355
49.33217	265.8690	8.021837
49.38383	264.8698	8.125430
49.43383	263.8994	8.192469
49.48383	262.9259	8.254832
49.53717	261.8860	8.301856
49.58716	260.9078	8.342130
49.63716	259.9271	8.373290
49.68883	258.9134	8.407061
49.74050	257.8971	8.426419
49.79050	256.9131	8.445080
49.84050	255.9280	8.463001
49.89217	254.9106	8.483470
49.94383	253.8902	8.508488
49.99383	252.9037	8.530558
50.04383	251.9154	8.550457
50.09716	250.8600	8.571618
50.14717	249.8706	8.587859
50.19717	248.8811	8.605111
50.24883	247.8578	8.623632
50.30050	246.8345	8.638726
50.35050	245.8438	8.653958
50.40050	244.8517	8.668975
50.45216	243.8279	8.683540
50.50383	242.8035	8.695401
50.55383	241.8105	8.708922
50.60383	240.8182	8.720799
50.65717	239.7604	8.732819
50.70717	238.7675	8.745407
50.75717	237.7749	8.757374
50.80883	236.7483	8.770245
50.86050	235.7232	8.782894
50.91050	234.7298	8.793499
50.96050	233.7363	8.804620
51.01216	232.7104	8.815536
51.06383	231.6848	8.827344
51.11383	230.6911	8.840499
51.16383	229.6961	8.854626
51.21717	228.6366	8.864530
51.26716	227.6436	8.877801
51.31716	226.6498	8.890405
51.36883	225.6230	8.902851
51.42050	224.5967	8.916754
51.47050	223.6025	8.929803
51.52050	222.6083	8.943224
51.57383	221.5485	8.954648
51.62383	220.5542	8.966182
51.67383	219.5612	8.982866
51.72550	218.5332	8.998832
51.77717	217.5067	9.012125
51.82717	216.5124	9.025519
51.87717	215.5185	9.039402
51.92883	214.4920	9.052018
51.98050	213.4651	9.063921
52.03050	212.4712	9.076612
52.08050	211.4761	9.091881
52.13383	210.4158	9.103884
52.18383	209.4211	9.116469
52.23383	208.4266	9.127225
52.28550	207.3992	9.138496
52.33716	206.3717	9.149295
52.38716	205.3770	9.160590
52.43716	204.3824	9.172082
52.48882	203.3535	9.183068
52.54050	202.3256	9.193702
52.59050	201.3318	9.204845
52.64050	200.3380	9.217918
52.69384	199.2760	9.229542
52.74382	198.2818	9.239181
52.79382	197.2874	9.249182
52.84550	196.2594	9.260316
52.89717	195.2309	9.271389
52.94717	194.2372	9.283341
52.99717	193.2418	9.296047
53.04883	192.2137	9.309374
53.10050	191.1861	9.321075
53.15050	190.1908	9.332209
53.20050	189.1960	9.342668
53.25383	188.1354	9.354534
53.30383	187.1408	9.364314
53.35383	186.1454	9.378478
53.40550	185.1159	9.389282
53.45717	184.0877	9.399162
53.50717	183.0923	9.408595
53.55717	182.0969	9.418689
53.61050	181.0338	9.429035
53.66050	180.0397	9.438499
53.71050	179.0441	9.447839
53.76216	178.0164	9.457614
53.81382	176.9880	9.470204
53.86382	175.9934	9.481981
53.91382	174.9985	9.495236
53.96550	173.9706	9.509325
54.01716	172.9414	9.523414
54.06716	171.9470	9.533798
54.11716	170.9522	9.550714
54.17050	169.8908	9.593968
54.22050	168.8973	9.691366
54.27050	167.9055	9.876030
54.32217	166.8836	10.09716
54.37383	165.8656	10.37339
54.42383	164.8864	10.71657
54.47382	163.9112	11.14454
54.52550	162.9088	11.65780
54.57717	161.9138	12.27281
54.62717	160.9548	12.94698
54.67717	160.0022	13.72770
54.73050	158.9951	14.68042
54.78050	158.0575	15.73439
54.83050	157.1295	16.93906
54.88217	156.1806	18.34701
54.93383	155.2418	19.82198
54.98383	154.3366	21.21968
55.03383	153.4291	22.44774
55.08550	152.4826	23.44728
55.13716	151.5187	24.05968
55.18716	150.5644	24.27970
55.23717	149.5871	24.09645
55.29050	148.5177	23.51230
55.34050	147.4925	22.66640
55.39050	146.4484	21.61738
55.44216	145.3558	20.43219
55.49382	144.2532	19.23530
55.54382	143.1854	18.12689
55.59384	142.1181	17.11885
55.64717	140.9851	16.15773
55.69717	139.9294	15.39028
55.74717	138.8804	14.73128
55.79883	137.8039	14.14150
55.85050	136.7332	13.65013
55.90050	135.7036	13.25928
55.95050	134.6787	12.92565
56.00217	133.6258	12.64048
56.05383	132.5757	12.40381
56.10383	131.5625	12.22760
56.15383	130.5537	12.07768
56.20717	129.4785	11.88470
56.25717	128.4691	11.66786
56.30717	127.4592	11.48499
56.35883	126.4189	11.35670
56.41050	125.3791	11.24851
56.46050	124.3750	11.16809
56.51050	123.3712	11.09294
56.56216	122.3363	11.02510
56.61382	121.3022	10.96676
56.66382	120.3014	10.91870
56.71382	119.3019	10.87897
56.76716	118.2356	10.84081
56.81716	117.2369	10.81332
56.86716	116.2374	10.78406
56.91882	115.2046	10.75396
56.97050	114.1716	10.72298
57.02050	113.1743	10.69662
57.07050	112.1745	10.67274
57.12217	111.1431	10.64697
57.17383	110.1102	10.62143
57.22382	109.1118	10.60176
57.27383	108.1122	10.57798
57.32717	107.0487	10.55128
57.37717	106.0509	10.53060
57.42717	105.0529	10.51375
57.47883	104.0219	10.49889
57.53050	102.9916	10.48788
57.58050	101.9938	10.47891
57.63050	100.9961	10.47002
57.68383	99.93314	10.46344
57.73383	98.93556	10.44916
57.78383	97.93722	10.42530
57.83550	96.90516	10.39886
57.88716	95.87332	10.37712
57.93716	94.87569	10.35793
57.98717	93.87882	10.34368
58.03882	92.84814	10.33220
58.09050	91.81871	10.32245
58.14050	90.82134	10.31722
58.19050	89.82408	10.30633
58.24382	88.75837	10.23888
58.29382	87.76059	10.21975
58.34384	86.76186	10.18854
58.39550	85.73076	10.16842
58.44717	84.70162	10.16496
58.49717	83.70580	10.15836
58.54717	82.70714	10.13117
58.59882	81.67485	10.10787
58.65050	80.64312	10.08016
58.70050	79.64418	10.03505
58.75050	78.64399	9.991818
58.80383	77.57854	9.964062
58.85383	76.58039	9.942051
58.90383	75.58313	9.930411
58.95550	74.55216	9.923278
59.00717	73.52168	9.915909
59.05717	72.52418	9.894422
59.10717	71.52660	9.876814
59.15883	70.49321	9.836532
59.21050	69.46125	9.801924
59.26050	68.46308	9.778659
59.31050	67.46415	9.753584
59.36382	66.39978	9.728600
59.41382	65.40172	9.710845
59.46382	64.40190	9.689684
59.51550	63.37112	9.665412
59.56716	62.33921	9.641644
59.61716	61.34119	9.626451
59.66716	60.34301	9.594819
59.72050	59.27756	9.540091
59.77050	58.27882	9.494621
59.82050	57.28043	9.466101
59.87217	56.24816	9.437347
59.92383	55.21491	9.392206
59.97382	54.21568	9.363692
60.02383	53.21789	9.336054
60.07550	52.18612	9.311418
60.12717	51.15306	9.279519
60.17717	50.15535	9.249581
60.22717	49.15506	9.218734
60.28050	48.09049	9.179222
60.33050	47.09020	9.152770
60.38050	46.09242	9.122484
60.43217	45.05938	9.097421
60.48383	44.02666	9.068493
60.53383	43.02703	9.039262
60.58383	42.02812	9.006647
60.63550	40.99500	8.966844
60.68716	39.96282	8.922174
60.73717	38.96362	8.890874
60.78716	37.96453	8.849800
60.84050	36.89759	8.805658
60.89050	35.89672	8.761295
60.94050	34.89636	8.719621
60.99216	33.86334	8.673243
61.04382	32.83032	8.628519
61.09384	31.82936	8.592395
61.14384	30.83120	8.554298
61.19550	29.79702	8.518366
61.24717	28.76302	8.466293
61.29717	27.76222	8.424159
61.34716	26.76084	8.364863
61.40050	25.69402	8.315207
61.45050	24.69170	8.278191
-2.000000	4.000000	0.0000000
61.54883	22.78196	8.425988
61.60050	22.35927	6.181699
61.65050	22.39044	2.696077
61.70050	22.68669	-0.1076881
61.75383	23.21611	-2.282050
61.80383	23.84725	-3.754840
61.85383	24.57290	-4.869247
61.90550	25.39327	-5.664944
61.95717	26.26817	-6.244431
62.00717	27.14947	-6.665268
62.05717	28.05427	-6.984194
62.10883	29.00944	-7.227080
62.16050	29.98172	-7.417090
62.21050	30.92984	-7.554540
62.26050	31.88704	-7.675693
62.31382	32.91322	-7.771311
62.36382	33.88108	-7.848144
62.41382	34.85303	-7.916668
62.46550	35.86076	-7.970840
62.51716	36.86988	-8.020512
62.56716	37.85045	-8.068897
62.61716	38.83112	-8.110178
62.66882	39.84699	-8.152650
62.72050	40.86280	-8.192081
62.77050	41.84809	-8.236026
62.82050	42.83558	-8.277545
62.87383	43.88896	-8.316750
62.92383	44.87884	-8.355272
62.97382	45.86772	-8.393326
63.02550	46.89121	-8.436934
63.07717	47.91498	-8.480278
63.12717	48.90586	-8.523641
63.17717	49.89844	-8.567938
63.22883	50.92328	-8.617968
63.28050	51.94950	-8.669874
63.33050	52.94211	-8.716476
63.38050	53.93588	-8.763703
63.43383	54.99597	-8.814599
63.48383	55.98994	-8.859282
63.53383	56.98445	-8.911222
63.58550	58.01149	-8.956499
63.63716	59.03975	-9.006906
63.68716	60.03458	-9.056054
63.73717	61.02790	-9.108298
63.79050	62.09000	-9.169016
63.84050	63.08454	-9.222130
63.89050	64.08038	-9.276249
63.94216	65.10906	-9.329449
63.99382	66.13840	-9.379630
64.04384	67.13530	-9.433719
64.09384	68.13136	-9.483109
64.14550	69.16054	-9.535118
64.19717	70.18936	-9.589055
64.24717	71.18494	-9.646191
64.29718	72.18096	-9.702478
64.35050	73.24390	-9.763724
64.40050	74.23935	-9.808806
64.45050	75.23510	-9.861187
64.50217	76.26407	-9.920111
64.55383	77.29452	-9.979794
64.60383	78.29019	-10.03524
64.65384	79.28639	-10.09453
64.70550	80.31613	-10.15836
64.75718	81.34553	-10.21776
64.80717	82.34120	-10.27856
64.85718	83.33722	-10.33750
64.91050	84.39926	-10.40725
64.96050	85.39741	-10.46726
65.01050	86.39376	-10.52708
65.06216	87.42293	-10.59185
65.11384	88.45275	-10.65601
65.16382	89.44794	-10.72335
65.21384	90.44432	-10.79068
65.26550	91.47355	-10.85313
65.31717	92.50351	-10.91953
65.36718	93.50053	-10.97916
65.41717	94.49695	-11.04183
65.47050	95.55949	-11.11023
65.52050	96.55649	-11.17782
65.57050	97.55282	-11.23276
65.62218	98.58224	-11.29813
65.67384	99.61249	-11.36472
65.72384	100.6095	-11.41766
65.77384	101.6054	-11.48523
65.82718	102.6693	-11.55529
65.87718	103.6658	-11.61781
65.92718	104.6619	-11.67913
65.97884	105.6924	-11.75302
66.03050	106.7213	-11.81449
66.08050	107.7175	-11.88423
66.13050	108.7144	-11.94371
66.18218	109.7450	-12.00247
66.23384	110.7770	-12.01997
66.28384	111.7756	-12.03444
66.33384	112.7739	-12.07045
66.38718	113.8380	-12.14754
66.43718	114.8367	-12.17315
66.48718	115.8339	-12.24315
66.53882	116.8636	-12.31148
66.59050	117.8942	-12.35360
66.64050	118.8916	-12.42295
66.69050	119.8880	-12.48273
66.74218	120.9184	-12.56154
66.79384	121.9475	-12.62718
66.84384	122.9431	-12.69301
66.89384	123.9398	-12.76918
66.94718	125.0030	-12.84403
66.99718	125.9978	-12.90538
67.04718	126.9950	-12.97506
67.09882	128.0243	-13.05049
67.15050	129.0545	-13.11803
67.20050	130.0502	-13.18376
67.25050	131.0468	-13.26238
67.30218	132.0762	-13.33576
67.35384	133.1047	-13.40235
67.40384	134.1016	-13.48198
67.45384	135.0968	-13.56389
67.50718	136.1601	-13.64636
67.55718	137.1554	-13.71901
67.60718	138.1515	-13.80169
67.65884	139.1804	-13.88274
67.71050	140.2091	-13.96551
67.76050	141.2055	-14.04634
67.81050	142.2001	-14.12239
67.86384	143.2630	-14.21028
67.91382	144.2584	-14.28784
67.96384	145.2539	-14.36194
68.01550	146.2831	-14.45017
68.06718	147.3122	-14.52846
68.11718	148.3076	-14.59857
68.16718	149.3039	-14.67836
68.21884	150.3326	-14.74306
68.27050	151.3616	-14.81295
68.32050	152.3593	-14.88013
68.37050	153.3547	-14.93666
68.42384	154.4187	-14.99976
68.47384	155.4161	-15.04349
68.52384	156.4126	-15.08629
68.57550	157.4442	-15.12101
68.62718	158.4766	-15.15532
68.67718	159.4763	-15.17952
68.72718	160.4737	-15.20610
68.77884	161.5060	-15.23442
68.83050	162.5382	-15.27287
68.88050	163.5368	-15.30179
68.93050	164.5348	-15.36425
68.98384	165.6008	-15.41207
69.03384	166.5991	-15.48055
69.08384	167.5950	-15.55090
69.13550	168.6259	-15.62544
69.18718	169.6554	-15.71971
69.23718	170.6515	-15.80237
69.28718	171.6467	-15.91870
69.33884	172.6749	-16.00544
69.39050	173.7023	-16.14432
69.44050	174.6959	-16.23929
69.49050	175.6885	-16.38531
69.54384	176.7484	-16.52259
69.59384	177.7395	-16.68533
69.64384	178.7306	-16.85813
69.69550	179.7542	-17.04323
69.74718	180.7758	-17.26691
69.79718	181.7632	-17.48844
69.84718	182.7504	-17.75173
69.90050	183.8007	-18.04323
69.95050	184.7846	-18.35887
70.00050	185.7661	-18.68685
70.05218	186.7800	-19.06136
70.10384	187.7909	-19.45819
70.15384	188.7686	-19.86103
70.20384	189.7449	-20.27127
70.25550	190.7518	-20.73216
70.30718	191.7578	-21.21220
70.35718	192.7308	-21.68801
70.40718	193.7019	-22.20648
70.46050	194.7352	-22.80280
70.51050	195.7020	-23.42607
70.56050	196.6648	-24.09830
70.61218	197.6586	-24.81492
70.66382	198.6480	-25.56252
70.71384	199.6052	-26.29033
70.76384	200.5638	-26.93604
70.81550	201.5573	-27.49905
70.86718	202.5600	-27.76790
70.91718	203.5452	-27.61809
70.96718	204.5579	-26.78508
71.02050	205.6767	-25.06960
71.07050	206.7622	-22.98652
71.12050	207.8712	-20.99998
71.17218	209.0168	-19.36967
71.22384	210.1466	-18.20920
71.27384	211.2186	-17.49213
71.32384	212.2708	-17.02459
71.37550	213.3417	-16.69992
71.42718	214.4002	-16.50401
71.47718	215.4180	-16.37868
71.52718	216.4292	-16.28374
71.58050	217.5034	-16.24119
71.63050	218.5088	-16.21949
71.68050	219.5117	-16.20388
71.73218	220.5469	-16.20108
71.78384	221.5814	-16.20104
71.83384	222.5802	-16.20217
71.88384	223.5796	-16.20504
71.93718	224.6467	-16.21493
71.98718	225.6452	-16.22407
72.03718	226.6436	-16.24588
72.08884	227.6763	-16.26672
72.14050	228.7083	-16.29436
72.19050	229.7067	-16.33374
72.24050	230.7048	-16.36386
72.29218	231.7358	-16.40013
72.34384	232.7678	-16.44556
72.39384	233.7650	-16.48967
72.44384	234.7629	-16.52721
72.49718	235.8279	-16.57209
72.54718	236.8259	-16.59906
72.59718	237.8236	-16.63606
72.64884	238.8550	-16.67034
72.70050	239.8864	-16.70688
72.75050	240.8835	-16.74788
72.80050	241.8814	-16.79621
72.85218	242.9132	-16.83979
72.90384	243.9451	-16.87636
72.95384	244.9429	-16.90653
73.00384	245.9414	-16.94293
73.05718	247.0061	-16.97936
73.10718	248.0032	-17.01447
73.15718	249.0017	-17.05005
73.20884	250.0337	-17.07996
73.26050	251.0660	-17.12088
73.31050	252.0638	-17.16048
73.36050	253.0620	-17.19678
73.41218	254.0932	-17.22754
73.46384	255.1246	-17.26712
73.51384	256.1222	-17.31153
73.56384	257.1204	-17.35822
73.61718	258.1852	-17.40242
73.66718	259.1821	-17.44454
73.71718	260.1786	-17.49716
73.76882	261.2100	-17.54894
73.82050	262.2405	-17.60210
73.87050	263.2387	-17.64549
73.92050	264.2357	-17.68522
73.97384	265.3005	-17.73878
74.02384	266.2964	-17.78712
74.07384	267.2956	-17.83827
74.12550	268.3254	-17.88774
74.17718	269.3554	-17.93872
74.22718	270.3526	-17.99176
74.27718	271.3499	-18.04008
74.32884	272.3797	-18.09286
-2.000000	5.000000	0.0000000