File: 9-C1(1.2mol%)+C20(1.0mol%)/matlab/170-2.txt
CLOSED
Version	1.0
Language	English
Mode	Standard
Run	12
RunSerial	12280
Instrument	DSC Q2000 V24.11 Build 124
Module	DSC Standard Cell RC
Operator
File	\\AE520-1454\Users\dsc\Desktop\Data\29-08-17\170-2.001
ProcName
InstSerial	2000-0883
AutoSerial	1293
Sample	170-2
Size	25.8000	mg
PanMass	Not available
PanResist	Automatic Automatic  K/W
PanFactor	Default Default
Method
Comment
Xcomment	Pan: Tzero Aluminum Hermetic
Xcomment	Gas1: Nitrogen 50.0 ml/min
Xcomment	Gas2: Nitrogen 50.0 ml/min
Text
Exotherm	UP
Kcell	1.05230
Cpconst	Standard: 0.938
Calib	-38.6961
TempCal	1	pts	157.46	156.60
TzeroDt	-87.6168 -0.0009 -1.4231
TzeroDtz	-87.6168 0.0057 6.9570
InstCalFile	Tzero: \\Ae520-1454\ta\Data\DSC\Calibration\2017\CALIBRATION\1562_RCS (90)_05_18_2017 10_50_44.TZR
InstCalFile	Baseline: \\Ae520-1454\ta\Data\DSC\Calibration\2017\2017-05-17_Calibration.001
InstCalFile	Sapphire: \\Ae520-1454\ta\Data\DSC\Calibration\2017\2017-05-17_Saphire.001
InstCalDate	Tzero 2017-05-18 Time 10:50:44
TempRange	-87.39 to 398.39 °C at 10.00 °C/min Heat Only
AutoZero	Delta T Offset 0.000 uV
AutoZero	Delta T0 Offset 0.000 uV
MultiptCal	0
MultiPtDesc	0) Not set
AutoCellConst	Calibration Date 2017-05-18 16:59:28
Controls	Gas 1  Event Off  Sampling 0.2
Cell#	RC-01562
CoolingUnit	RCS (90)
SelHeatFlow	Heat Flow T4P (mW)
AutoLidII	Installed
AutoAnalysis	Off
MacroFile
Nsig	3
Sig1	Time (min)
Sig2	Temperature (°C)
Sig3	Heat Flow (mW)
Date	2017-08-30
Time	02:19:12
OrgMethod	1: Equilibrate at 80.00 °C
OrgMethod	2: Isothermal for 3.00 min
OrgMethod	3: Jump to 170.00 °C
OrgMethod	4: Mark end of cycle 1
OrgMethod	5: Isothermal for 40.00 min
OrgMethod	6: Mark end of cycle 2
OrgMethod	7: Ramp 20.00 °C/min to 280.00 °C
OrgMethod	8: Mark end of cycle 3
OrgMethod	9: Ramp 20.00 °C/min to 20.00 °C
OrgMethod	10: Mark end of cycle 4
OrgMethod	11: Ramp 20.00 °C/min to 280.00 °C
OrgMethod	12: Mark end of cycle 5
OrgFile	C:\Users\jarra\Desktop\DSC\9-C1(1.2mol%)+C20(1.0mol%)\170-2.001
StartOfData
4.99994E-4	79.28432	-8.832953
0.05383332	79.41316	-7.158062
0.1038333	79.50891	-5.911365
0.1538333	79.58579	-4.907608
0.2055000	79.64885	-4.083216
0.2571667	79.69805	-3.428418
0.3071666	79.73638	-2.920004
0.3571666	79.76722	-2.515984
0.4105000	79.79174	-2.174067
0.4605000	79.81122	-1.917366
0.5105000	79.82526	-1.717326
0.5621668	79.83762	-1.555387
0.6138334	79.84619	-1.425277
0.6638332	79.85382	-1.330172
0.7138332	79.85910	-1.253265
0.7655000	79.86345	-1.192209
0.8171668	79.86651	-1.146015
0.8671666	79.86894	-1.113902
0.9171668	79.87078	-1.089173
0.9705000	79.87128	-1.070066
1.020500	79.87116	-1.057361
1.070500	79.87216	-1.049427
1.122166	79.87191	-1.043579
1.173834	79.87256	-1.039604
1.223833	79.87131	-1.035973
1.273834	79.87168	-1.032297
1.325500	79.87103	-1.028506
1.377166	79.87086	-1.024812
1.427167	79.87058	-1.021402
1.477166	79.86931	-1.018179
1.530500	79.86851	-1.014921
1.580500	79.86790	-1.012041
1.630500	79.86849	-1.009422
1.682167	79.86745	-1.006934
1.733833	79.86676	-1.004716
1.783833	79.86524	-1.002759
1.833833	79.86536	-1.001015
1.885500	79.86448	-0.9993970
1.937166	79.86450	-0.9980001
1.987166	79.86280	-0.9967776
2.037166	79.86356	-0.9958192
2.090500	79.86212	-0.9949610
2.140500	79.86165	-0.9943719
2.190500	79.86144	-0.9939285
2.242166	79.86066	-0.9936400
2.293833	79.86025	-0.9934524
2.343834	79.85956	-0.9933751
2.393833	79.85944	-0.9933895
2.447166	79.85900	-0.9935822
2.497166	79.85818	-0.9938007
2.547166	79.85711	-0.9941184
2.598834	79.85593	-0.9944986
2.650500	79.85668	-0.9950476
2.700500	79.85587	-0.9955703
2.750500	79.85484	-0.9962207
2.802166	79.85481	-0.9969875
2.853833	79.85430	-0.9978188
2.903833	79.85313	-0.9986481
2.953833	79.85376	-0.9995512
3.000500	79.85224	-1.000500
3.053833	80.45191	-4.640194
3.103833	82.72940	-14.21122
3.153833	85.46672	-24.19097
3.205500	88.69000	-34.75574
3.257167	92.22965	-44.66967
3.307167	95.89038	-53.31510
3.357167	99.72895	-60.95309
3.410500	103.9778	-68.02884
3.460500	108.0730	-73.67418
3.510500	112.2484	-78.43225
3.562167	116.6206	-82.60800
3.613834	121.0320	-86.26652
3.663833	125.3229	-89.31571
3.713833	129.6254	-92.05087
3.765500	134.0795	-94.62214
3.817166	138.5331	-96.96249
3.867166	142.8427	-98.95937
3.917167	147.1264	-101.3792
3.970500	151.6796	-102.8323
4.020500	155.2995	-101.4404
4.070500	157.5864	-94.11028
4.122166	159.4266	-85.40589
4.173834	160.8694	-76.23880
4.223834	162.0014	-68.00350
4.273834	162.9250	-60.71511
4.325500	163.7106	-54.28516
4.377167	164.3586	-48.91440
4.427166	164.8804	-44.63194
4.477167	165.3195	-41.13117
4.530500	165.7136	-38.10086
4.580500	166.0274	-35.78195
4.630500	166.2969	-33.86175
4.682167	166.5380	-32.21990
4.733834	166.7474	-30.84980
4.783834	166.9261	-29.72430
4.833834	167.0846	-28.75160
4.885500	167.2306	-27.86164
4.937167	167.3611	-27.05672
4.987167	167.4772	-26.34209
5.037167	167.5809	-25.66353
5.090500	167.6835	-24.97333
5.140500	167.7720	-24.35445
5.190500	167.8540	-23.74828
5.242167	167.9338	-23.12121
5.293832	168.0091	-22.49268
5.343834	168.0784	-21.88192
5.393832	168.1449	-21.26431
5.447168	168.2144	-20.58474
5.497168	168.2780	-19.91437
5.547168	168.3412	-19.22445
5.598832	168.4068	-18.49372
5.650500	168.4698	-17.73746
5.700500	168.5320	-16.98390
5.750500	168.5954	-16.18017
5.802168	168.6639	-15.28362
5.853832	168.7352	-14.31621
5.903834	168.8082	-13.31062
5.953832	168.8836	-12.22795
6.007168	168.9691	-11.00653
6.057168	169.0509	-9.821362
6.107168	169.1344	-8.624095
6.158832	169.2190	-7.381566
6.210500	169.3024	-6.158415
6.260500	169.3815	-5.014617
6.310500	169.4558	-3.934264
6.362168	169.5281	-2.897461
6.413832	169.5936	-1.952342
6.463834	169.6515	-1.128475
6.513834	169.7040	-0.3901424
6.567168	169.7542	0.3107867
6.617166	169.7963	0.8976938
6.667168	169.8332	1.426399
6.718832	169.8691	1.925271
6.770500	169.9019	2.375050
6.820500	169.9312	2.768611
6.870500	169.9578	3.128255
6.922168	169.9816	3.462164
6.973834	170.0030	3.760910
7.023834	170.0227	4.012753
7.073834	170.0390	4.229732
7.127168	170.0551	4.421192
7.177168	170.0664	4.577402
7.227168	170.0766	4.701412
7.278832	170.0860	4.800212
7.330500	170.0920	4.876413
7.380500	170.0980	4.926834
7.430500	170.1018	4.961067
7.483832	170.1044	4.979840
7.533832	170.1061	4.987144
7.583832	170.1074	4.989465
7.635500	170.1075	4.990658
7.687168	170.1086	4.991154
7.737168	170.1086	4.991034
7.787168	170.1092	4.990276
7.838834	170.1091	4.988986
7.890500	170.1092	4.987509
7.940500	170.1108	4.986147
7.990500	170.1104	4.985153
8.043834	170.1120	4.984574
8.093832	170.1134	4.984804
8.143832	170.1149	4.986247
8.195500	170.1175	4.991059
8.247168	170.1194	5.000088
8.297168	170.1219	5.013574
8.347168	170.1230	5.030884
8.398834	170.1255	5.051575
8.450500	170.1273	5.073242
8.500500	170.1297	5.094430
8.550500	170.1308	5.114065
8.603832	170.1332	5.132935
8.653832	170.1344	5.146504
8.703834	170.1352	5.157160
8.755500	170.1362	5.165611
8.807168	170.1378	5.171933
8.857166	170.1384	5.177788
8.907166	170.1380	5.183318
8.958832	170.1382	5.188554
9.010499	170.1378	5.193000
9.060500	170.1378	5.196558
9.110500	170.1376	5.199169
9.163834	170.1359	5.201172
9.213834	170.1359	5.201710
9.263832	170.1339	5.199205
9.315500	170.1328	5.191496
9.367166	170.1308	5.178058
9.417168	170.1294	5.158134
9.467168	170.1272	5.131909
9.520500	170.1249	5.098068
9.570500	170.1231	5.061522
9.620499	170.1200	5.023340
9.672168	170.1185	4.980804
9.723832	170.1164	4.937892
9.773834	170.1139	4.895859
9.823834	170.1108	4.853369
9.875500	170.1089	4.809511
9.927168	170.1072	4.765497
9.977168	170.1045	4.723560
10.02717	170.1027	4.682693
10.08050	170.1000	4.639649
10.13050	170.0971	4.600144
10.18050	170.0947	4.559002
10.23217	170.0922	4.517231
10.28383	170.0894	4.475283
10.33383	170.0869	4.433661
10.38383	170.0844	4.392884
10.43550	170.0816	4.350398
10.48717	170.0790	4.307248
10.53717	170.0769	4.264582
10.58717	170.0743	4.221454
10.64050	170.0710	4.177158
10.69050	170.0683	4.132403
10.74050	170.0666	4.088562
10.79217	170.0632	4.043890
10.84383	170.0609	3.998987
10.89383	170.0584	3.954935
10.94383	170.0559	3.908881
10.99550	170.0528	3.861920
11.04717	170.0498	3.814657
11.09717	170.0465	3.768332
11.14717	170.0442	3.722157
11.20050	170.0404	3.673234
11.25050	170.0380	3.625592
11.30050	170.0356	3.577662
11.35217	170.0322	3.526750
11.40383	170.0297	3.478503
11.45384	170.0255	3.430340
11.50384	170.0246	3.382407
11.55717	170.0203	3.333202
11.60717	170.0168	3.287537
11.65717	170.0141	3.241566
11.70883	170.0112	3.194801
11.76050	170.0087	3.148832
11.81050	170.0046	3.105245
11.86050	170.0030	3.059991
11.91217	170.0005	3.016814
11.96383	169.9970	2.976411
12.01383	169.9948	2.934747
12.06383	169.9914	2.893687
12.11716	169.9893	2.852259
12.16717	169.9866	2.816511
12.21717	169.9850	2.783003
12.26883	169.9827	2.751444
12.32050	169.9801	2.720903
12.37050	169.9784	2.692881
12.42050	169.9768	2.665626
12.47217	169.9756	2.637593
12.52383	169.9729	2.611615
12.57383	169.9711	2.586984
12.62383	169.9695	2.563207
12.67717	169.9679	2.538308
12.72717	169.9662	2.515334
12.77717	169.9653	2.491317
12.82883	169.9630	2.468355
12.88050	169.9608	2.444008
12.93050	169.9590	2.420406
12.98050	169.9587	2.395642
13.03217	169.9564	2.369871
13.08383	169.9540	2.344294
13.13383	169.9526	2.316163
13.18383	169.9516	2.287540
13.23716	169.9494	2.255820
13.28717	169.9474	2.223511
13.33717	169.9461	2.189570
13.38883	169.9439	2.152042
13.44050	169.9422	2.113516
13.49050	169.9389	2.074531
13.54050	169.9370	2.031877
13.59383	169.9344	1.985152
13.64383	169.9316	1.943075
13.69384	169.9291	1.895495
13.74550	169.9258	1.846364
13.79717	169.9232	1.796182
13.84717	169.9197	1.747356
13.89717	169.9169	1.696231
13.94884	169.9137	1.643062
14.00050	169.9099	1.590672
14.05050	169.9072	1.538175
14.10050	169.9041	1.485505
14.15383	169.9006	1.429838
14.20383	169.8972	1.377501
14.25383	169.8946	1.325318
14.30550	169.8909	1.270167
14.35716	169.8872	1.216175
14.40717	169.8842	1.162975
14.45717	169.8808	1.110361
14.50883	169.8776	1.058341
14.56050	169.8737	1.006455
14.61050	169.8703	0.9576855
14.66050	169.8685	0.9093842
14.71383	169.8647	0.8599476
14.76383	169.8614	0.8136840
14.81383	169.8589	0.7685482
14.86550	169.8562	0.7226897
14.91716	169.8534	0.6786022
14.96716	169.8500	0.6383520
15.01717	169.8479	0.5981488
15.06884	169.8448	0.5580368
15.12050	169.8423	0.5200136
15.17050	169.8402	0.4834850
15.22050	169.8375	0.4489738
15.27383	169.8352	0.4125062
15.32384	169.8321	0.3787902
15.37384	169.8305	0.3454495
15.42550	169.8272	0.3125436
15.47717	169.8256	0.2777308
15.52717	169.8242	0.2453499
15.57717	169.8224	0.2130100
15.63050	169.8195	0.1798321
15.68050	169.8171	0.1479031
15.73050	169.8149	0.1155817
15.78217	169.8130	0.08105180
15.83383	169.8106	0.04649425
15.88383	169.8079	0.01214751
15.93383	169.8067	-.02250088
15.98550	169.8038	-.05957188
16.03717	169.8016	-.09643741
16.08716	169.7984	-0.1346489
16.13716	169.7973	-0.1750820
16.19050	169.7946	-0.2180406
16.24050	169.7916	-0.2584089
16.29050	169.7890	-0.3007184
16.34216	169.7863	-0.3449255
16.39383	169.7834	-0.3898660
16.44383	169.7814	-0.4331119
16.49383	169.7780	-0.4769219
16.54550	169.7756	-0.5222014
16.59716	169.7725	-0.5692432
16.64716	169.7702	-0.6138611
16.69716	169.7669	-0.6594639
16.75050	169.7640	-0.7072350
16.80050	169.7610	-0.7521472
16.85050	169.7581	-0.7966574
16.90216	169.7557	-0.8418532
16.95383	169.7526	-0.8869101
17.00383	169.7508	-0.9328528
17.05383	169.7472	-0.9751309
17.10550	169.7448	-1.018806
17.15716	169.7416	-1.061294
17.20716	169.7390	-1.102390
17.25716	169.7362	-1.142651
17.31050	169.7336	-1.183332
17.36050	169.7305	-1.221319
17.41050	169.7282	-1.259148
17.46216	169.7256	-1.297859
17.51383	169.7241	-1.337394
17.56383	169.7209	-1.371974
17.61383	169.7190	-1.407509
17.66716	169.7170	-1.442540
17.71716	169.7148	-1.473976
17.76716	169.7125	-1.505762
17.81883	169.7101	-1.537505
17.87050	169.7089	-1.567717
17.92050	169.7061	-1.595268
17.97050	169.7043	-1.621384
18.02216	169.7025	-1.649497
18.07383	169.7006	-1.676604
18.12383	169.6985	-1.700847
18.17383	169.6964	-1.724233
18.22716	169.6949	-1.747959
18.27716	169.6938	-1.769866
18.32716	169.6926	-1.790721
18.37883	169.6902	-1.811398
18.43050	169.6891	-1.832955
18.48050	169.6877	-1.853102
18.53050	169.6865	-1.870941
18.58216	169.6852	-1.888933
18.63383	169.6834	-1.907248
18.68383	169.6826	-1.925227
18.73383	169.6811	-1.941721
18.78717	169.6798	-1.958184
18.83716	169.6794	-1.973066
18.88716	169.6783	-1.986369
18.93883	169.6774	-2.000299
18.99050	169.6759	-2.013211
19.04050	169.6748	-2.024906
19.09050	169.6754	-2.037868
19.14216	169.6724	-2.049823
19.19383	169.6726	-2.062275
19.24383	169.6717	-2.074184
19.29383	169.6708	-2.082926
19.34716	169.6692	-2.093132
19.39716	169.6684	-2.102956
19.44716	169.6686	-2.112036
19.49883	169.6673	-2.121092
19.55050	169.6665	-2.130262
19.60050	169.6659	-2.139194
19.65050	169.6654	-2.148236
19.70383	169.6642	-2.157834
19.75383	169.6645	-2.167062
19.80383	169.6631	-2.176208
19.85550	169.6625	-2.185877
19.90716	169.6617	-2.195550
19.95716	169.6614	-2.204842
20.00716	169.6612	-2.214104
20.05883	169.6599	-2.223628
20.11050	169.6594	-2.233123
20.16050	169.6583	-2.242260
20.21050	169.6587	-2.251342
20.26383	169.6580	-2.260958
20.31383	169.6586	-2.269910
20.36383	169.6579	-2.278792
20.41550	169.6567	-2.287777
20.46716	169.6573	-2.296690
20.51716	169.6564	-2.305180
20.56716	169.6559	-2.313533
20.61883	169.6552	-2.322048
20.67050	169.6551	-2.330460
20.72050	169.6548	-2.338468
20.77050	169.6541	-2.346359
20.82383	169.6538	-2.354622
20.87383	169.6536	-2.362297
20.92383	169.6539	-2.369892
20.97550	169.6534	-2.377541
21.02717	169.6525	-2.385066
21.07716	169.6519	-2.392219
21.12716	169.6517	-2.399204
21.17883	169.6519	-2.406272
21.23050	169.6516	-2.413190
21.28050	169.6500	-2.419704
21.33050	169.6499	-2.426039
21.38383	169.6500	-2.432668
21.43383	169.6505	-2.438721
21.48383	169.6486	-2.444682
21.53550	169.6489	-2.450782
21.58716	169.6487	-2.456720
21.63716	169.6485	-2.462395
21.68716	169.6488	-2.468037
21.74050	169.6488	-2.474019
21.79050	169.6472	-2.479441
21.84050	169.6485	-2.484851
21.89216	169.6475	-2.490233
21.94383	169.6485	-2.495532
21.99383	169.6470	-2.500482
22.04383	169.6475	-2.505334
22.09550	169.6472	-2.510280
22.14716	169.6475	-2.515182
22.19716	169.6464	-2.519845
22.24716	169.6465	-2.524391
22.30050	169.6465	-2.529212
22.35050	169.6459	-2.533705
22.40050	169.6450	-2.538119
22.45216	169.6464	-2.542617
22.50383	169.6454	-2.547034
22.55383	169.6460	-2.551225
22.60383	169.6454	-2.555336
22.65550	169.6443	-2.559501
22.70717	169.6448	-2.563664
22.75716	169.6444	-2.567615
22.80716	169.6442	-2.571525
22.86050	169.6451	-2.575625
22.91050	169.6440	-2.579459
22.96050	169.6442	-2.583272
23.01216	169.6436	-2.587165
23.06383	169.6439	-2.591053
23.11383	169.6431	-2.594738
23.16383	169.6426	-2.598348
23.21550	169.6430	-2.602081
23.26716	169.6424	-2.605744
23.31716	169.6420	-2.609202
23.36716	169.6428	-2.612684
23.42050	169.6422	-2.616400
23.47050	169.6416	-2.619840
23.52050	169.6422	-2.623336
23.57216	169.6425	-2.626964
23.62383	169.6414	-2.630459
23.67383	169.6418	-2.633856
23.72383	169.6413	-2.637186
23.77717	169.6411	-2.640712
23.82716	169.6407	-2.643939
23.87716	169.6396	-2.647080
23.92883	169.6405	-2.650298
23.98050	169.6402	-2.653470
24.03050	169.6410	-2.656593
24.08050	169.6400	-2.659651
24.13216	169.6398	-2.662732
24.18383	169.6397	-2.665796
24.23383	169.6390	-2.668776
24.28383	169.6392	-2.671652
24.33716	169.6391	-2.674669
24.38716	169.6386	-2.677469
24.43716	169.6392	-2.680206
24.48883	169.6389	-2.682957
24.54050	169.6382	-2.685670
24.59050	169.6377	-2.688248
24.64050	169.6384	-2.690826
24.69216	169.6377	-2.693404
24.74383	169.6374	-2.695947
24.79383	169.6375	-2.698334
24.84383	169.6375	-2.700723
24.89716	169.6381	-2.703206
24.94716	169.6378	-2.705479
24.99716	169.6374	-2.707764
25.04883	169.6377	-2.710091
25.10050	169.6383	-2.712322
25.15050	169.6376	-2.714456
25.20050	169.6382	-2.716549
25.25217	169.6377	-2.718665
25.30383	169.6381	-2.720650
25.35383	169.6374	-2.722493
25.40383	169.6374	-2.724286
25.45717	169.6376	-2.726138
25.50716	169.6381	-2.727800
25.55716	169.6378	-2.729382
25.60883	169.6381	-2.731002
25.66050	169.6372	-2.732490
25.71050	169.6376	-2.733867
25.76050	169.6366	-2.735174
25.81383	169.6377	-2.736524
25.86383	169.6371	-2.737806
25.91383	169.6364	-2.738975
25.96550	169.6367	-2.740142
26.01716	169.6369	-2.741252
26.06716	169.6372	-2.742344
26.11716	169.6373	-2.743371
26.16883	169.6370	-2.744516
26.22050	169.6371	-2.745610
26.27050	169.6374	-2.746678
26.32050	169.6371	-2.747688
26.37383	169.6368	-2.748702
26.42383	169.6374	-2.749662
26.47383	169.6368	-2.750575
26.52550	169.6368	-2.751480
26.57717	169.6366	-2.752388
26.62716	169.6364	-2.753220
26.67717	169.6359	-2.754050
26.72883	169.6366	-2.754885
26.78050	169.6366	-2.755712
26.83050	169.6365	-2.756440
26.88050	169.6352	-2.757219
26.93383	169.6361	-2.758104
26.98383	169.6359	-2.758936
27.03383	169.6355	-2.759725
27.08550	169.6359	-2.760543
27.13716	169.6362	-2.761394
27.18717	169.6354	-2.762168
27.23716	169.6350	-2.762966
27.28883	169.6361	-2.763784
27.34050	169.6360	-2.764654
27.39050	169.6356	-2.765486
27.44050	169.6361	-2.766436
27.49383	169.6364	-2.767373
27.54383	169.6359	-2.768290
27.59383	169.6364	-2.769205
27.64550	169.6364	-2.770118
27.69717	169.6359	-2.771070
27.74716	169.6361	-2.772052
27.79716	169.6359	-2.773059
27.85050	169.6360	-2.774152
27.90050	169.6354	-2.775187
27.95050	169.6358	-2.776200
28.00217	169.6363	-2.777291
28.05383	169.6360	-2.778413
28.10383	169.6358	-2.779521
28.15383	169.6358	-2.780596
28.20550	169.6356	-2.781693
28.25716	169.6352	-2.782796
28.30716	169.6356	-2.783894
28.35716	169.6346	-2.785004
28.41050	169.6348	-2.786262
28.46050	169.6349	-2.787418
28.51050	169.6342	-2.788534
28.56217	169.6351	-2.789788
28.61383	169.6342	-2.790965
28.66383	169.6339	-2.792106
28.71383	169.6344	-2.793265
28.76550	169.6338	-2.794522
28.81716	169.6335	-2.795782
28.86716	169.6336	-2.797054
28.91716	169.6322	-2.798391
28.97050	169.6331	-2.799900
29.02050	169.6334	-2.801361
29.07050	169.6329	-2.802843
29.12216	169.6325	-2.804412
29.17383	169.6324	-2.806062
29.22383	169.6323	-2.807714
29.27383	169.6318	-2.809414
29.32550	169.6321	-2.811194
29.37716	169.6322	-2.812954
29.42717	169.6311	-2.814639
29.47717	169.6325	-2.816391
29.53050	169.6310	-2.818265
29.58050	169.6308	-2.820033
29.63050	169.6304	-2.821847
29.68216	169.6312	-2.823776
29.73383	169.6308	-2.825728
29.78383	169.6307	-2.827632
29.83383	169.6305	-2.829628
29.88716	169.6308	-2.831778
29.93717	169.6297	-2.833801
29.98716	169.6303	-2.835846
30.03883	169.6304	-2.837988
30.09050	169.6294	-2.840144
30.14050	169.6294	-2.842190
30.19050	169.6300	-2.844296
30.24216	169.6300	-2.846367
30.29383	169.6302	-2.848556
30.34383	169.6300	-2.850665
30.39383	169.6292	-2.852716
30.44717	169.6292	-2.854908
30.49716	169.6297	-2.856947
30.54716	169.6296	-2.858987
30.59883	169.6290	-2.861140
30.65050	169.6291	-2.863286
30.70050	169.6284	-2.865380
30.75050	169.6279	-2.867512
30.80217	169.6289	-2.869698
30.85383	169.6285	-2.871938
30.90383	169.6289	-2.874071
30.95383	169.6277	-2.876150
31.00716	169.6280	-2.878350
31.05716	169.6280	-2.880352
31.10716	169.6276	-2.882400
31.15883	169.6280	-2.884456
31.21050	169.6280	-2.886529
31.26050	169.6270	-2.888519
31.31050	169.6271	-2.890471
31.36216	169.6269	-2.892486
31.41383	169.6270	-2.894439
31.46383	169.6266	-2.896344
31.51383	169.6262	-2.898240
31.56716	169.6260	-2.900258
31.61716	169.6258	-2.902190
31.66716	169.6261	-2.904106
31.71883	169.6258	-2.906112
31.77050	169.6261	-2.908140
31.82050	169.6258	-2.910101
31.87050	169.6258	-2.912047
31.92383	169.6255	-2.914131
31.97383	169.6254	-2.916045
32.02383	169.6248	-2.917964
32.07550	169.6254	-2.919913
32.12717	169.6257	-2.921890
32.17717	169.6253	-2.923833
32.22717	169.6256	-2.925784
32.27883	169.6244	-2.927737
32.33050	169.6248	-2.929748
32.38050	169.6251	-2.931661
32.43050	169.6248	-2.933610
32.48383	169.6244	-2.935692
32.53383	169.6232	-2.937588
32.58383	169.6238	-2.939496
32.63550	169.6236	-2.941426
32.68716	169.6244	-2.943346
32.73717	169.6234	-2.945165
32.78717	169.6236	-2.947012
32.83883	169.6236	-2.948940
32.89050	169.6241	-2.950904
32.94050	169.6235	-2.952768
32.99050	169.6229	-2.954632
33.04383	169.6228	-2.956642
33.09384	169.6233	-2.958527
33.14383	169.6227	-2.960358
33.19550	169.6226	-2.962259
33.24716	169.6228	-2.964121
33.29716	169.6219	-2.965841
33.34716	169.6217	-2.967558
33.39883	169.6220	-2.969300
33.45050	169.6214	-2.970974
33.50050	169.6212	-2.972586
33.55050	169.6206	-2.974222
33.60383	169.6216	-2.976037
33.65383	169.6209	-2.977740
33.70383	169.6222	-2.979495
33.75550	169.6219	-2.981251
33.80716	169.6220	-2.982974
33.85716	169.6214	-2.984631
33.90716	169.6222	-2.986267
33.96050	169.6206	-2.987956
34.01050	169.6207	-2.989576
34.06050	169.6222	-2.991205
34.11217	169.6212	-2.992795
34.16383	169.6213	-2.994311
34.21383	169.6206	-2.995754
34.26383	169.6211	-2.997218
34.31550	169.6208	-2.998670
34.36716	169.6211	-3.000159
34.41716	169.6209	-3.001566
34.46716	169.6205	-3.002988
34.52050	169.6208	-3.004515
34.57050	169.6211	-3.005910
34.62050	169.6201	-3.007334
34.67216	169.6201	-3.008778
34.72383	169.6201	-3.010233
34.77383	169.6209	-3.011685
34.82383	169.6200	-3.013075
34.87550	169.6205	-3.014550
34.92717	169.6205	-3.015930
34.97717	169.6214	-3.017302
35.02716	169.6208	-3.018574
35.08050	169.6200	-3.019834
35.13050	169.6203	-3.021063
35.18050	169.6197	-3.022266
35.23216	169.6205	-3.023509
35.28383	169.6196	-3.024733
35.33383	169.6200	-3.025900
35.38383	169.6197	-3.027078
35.43550	169.6205	-3.028278
35.48717	169.6200	-3.029456
35.53717	169.6200	-3.030544
35.58716	169.6194	-3.031637
35.64050	169.6194	-3.032817
35.69050	169.6194	-3.033934
35.74050	169.6196	-3.035030
35.79217	169.6191	-3.036110
35.84384	169.6197	-3.037228
35.89383	169.6192	-3.038290
35.94383	169.6187	-3.039286
35.99716	169.6196	-3.040338
36.04716	169.6182	-3.041300
36.09716	169.6194	-3.042256
36.14883	169.6187	-3.043226
36.20050	169.6177	-3.044252
36.25050	169.6182	-3.045296
36.30050	169.6183	-3.046350
36.35217	169.6190	-3.047420
36.40383	169.6191	-3.048498
36.45383	169.6182	-3.049506
36.50383	169.6188	-3.050484
36.55716	169.6176	-3.051470
36.60716	169.6179	-3.052352
36.65716	169.6172	-3.053222
36.70883	169.6180	-3.054132
36.76050	169.6177	-3.055067
36.81050	169.6180	-3.055960
36.86050	169.6180	-3.056838
36.91217	169.6179	-3.057667
36.96383	169.6183	-3.058546
37.01383	169.6180	-3.059386
37.06383	169.6180	-3.060226
37.11716	169.6168	-3.061099
37.16716	169.6181	-3.061951
37.21716	169.6175	-3.062796
37.26883	169.6178	-3.063684
37.32050	169.6179	-3.064495
37.37050	169.6177	-3.065266
37.42050	169.6181	-3.065988
37.47217	169.6178	-3.066806
37.52383	169.6178	-3.067654
37.57383	169.6181	-3.068440
37.62383	169.6169	-3.069159
37.67717	169.6177	-3.069940
37.72717	169.6178	-3.070668
37.77716	169.6178	-3.071372
37.82883	169.6174	-3.072058
37.88050	169.6177	-3.072808
37.93050	169.6168	-3.073542
37.98050	169.6170	-3.074213
38.03383	169.6175	-3.074906
38.08383	169.6172	-3.075570
38.13383	169.6173	-3.076258
38.18550	169.6172	-3.076985
38.23717	169.6176	-3.077756
38.28717	169.6172	-3.078482
38.33716	169.6163	-3.079237
38.38883	169.6174	-3.080054
38.44050	169.6170	-3.080775
38.49050	169.6170	-3.081398
38.54050	169.6162	-3.082059
38.59384	169.6162	-3.082730
38.64383	169.6170	-3.083300
38.69383	169.6169	-3.083893
38.74550	169.6167	-3.084426
38.79716	169.6152	-3.084934
38.84716	169.6165	-3.085423
38.89717	169.6162	-3.085945
38.94883	169.6160	-3.086516
39.00050	169.6170	-3.087129
39.05050	169.6164	-3.087726
39.10050	169.6169	-3.088296
39.15383	169.6159	-3.088870
39.20383	169.6156	-3.089331
39.25383	169.6158	-3.089792
39.30550	169.6156	-3.090254
39.35716	169.6162	-3.090744
39.40716	169.6156	-3.091182
39.45716	169.6149	-3.091560
39.50883	169.6154	-3.091952
39.56050	169.6147	-3.092326
39.61050	169.6156	-3.092736
39.66050	169.6155	-3.093142
39.71383	169.6156	-3.093601
39.76383	169.6159	-3.094100
39.81383	169.6166	-3.094632
39.86550	169.6158	-3.095210
39.91716	169.6163	-3.095838
39.96716	169.6156	-3.096380
40.01716	169.6154	-3.096929
40.07050	169.6160	-3.097476
40.12050	169.6156	-3.097928
40.17050	169.6160	-3.098384
40.22217	169.6158	-3.098828
40.27383	169.6160	-3.099340
40.32383	169.6156	-3.099783
40.37383	169.6159	-3.100216
40.42550	169.6159	-3.100713
40.47717	169.6170	-3.101227
40.52716	169.6158	-3.101681
40.57717	169.6154	-3.102091
40.63050	169.6167	-3.102552
40.68050	169.6160	-3.102926
40.73050	169.6158	-3.103390
40.78216	169.6161	-3.103888
40.83383	169.6162	-3.104347
40.88383	169.6156	-3.104761
40.93384	169.6154	-3.105215
40.98550	169.6159	-3.105738
41.03717	169.6158	-3.106198
41.08716	169.6148	-3.106565
41.13716	169.6158	-3.106935
41.19050	169.6150	-3.107264
41.24050	169.6154	-3.107564
41.29050	169.6146	-3.107836
41.34217	169.6154	-3.108150
41.39383	169.6144	-3.108414
41.44383	169.6154	-3.108797
41.49383	169.6151	-3.109154
41.54550	169.6150	-3.109506
41.59716	169.6146	-3.109832
41.64717	169.6146	-3.110219
41.69717	169.6146	-3.110620
41.75050	169.6151	-3.111100
41.80050	169.6153	-3.111545
41.85050	169.6154	-3.112033
41.90216	169.6153	-3.112518
41.95383	169.6161	-3.112995
42.00383	169.6154	-3.113388
42.05383	169.6152	-3.113818
42.10717	169.6164	-3.114314
42.15717	169.6152	-3.114769
42.20717	169.6131	-3.115085
42.25883	169.6151	-3.115482
42.31050	169.6151	-3.115830
42.36050	169.6148	-3.116162
42.41050	169.6149	-3.116475
42.46216	169.6148	-3.116832
42.51383	169.6141	-3.117194
42.56383	169.6152	-3.117531
42.61383	169.6146	-3.117882
42.66716	169.6141	-3.118213
42.71717	169.6137	-3.118540
42.76717	169.6144	-3.118894
42.81883	169.6144	-3.119290
42.87050	169.6144	-3.119652
42.92050	169.6138	-3.120007
42.97050	169.6137	-3.120327
43.02050	169.6162	-3.121080
43.07217	169.7377	-4.127754
43.12383	170.1679	-6.853278
43.17383	170.7260	-9.623901
43.22383	171.3839	-12.17493
43.27716	172.1636	-14.42576
43.32717	172.9517	-16.13342
43.37717	173.7819	-17.50875
43.42883	174.6716	-18.64738
43.48050	175.5898	-19.56454
43.53050	176.4981	-20.27670
43.58050	177.4210	-20.86782
43.63217	178.3878	-21.39922
43.68383	179.3641	-21.82692
43.73383	180.3168	-22.19444
43.78383	181.2760	-22.52358
43.83716	182.3022	-22.83698
43.88716	183.2706	-23.12594
43.93716	184.2410	-23.38888
43.98883	185.2464	-23.64753
44.04050	186.2514	-23.90705
44.09050	187.2267	-24.16498
44.14050	188.2020	-24.43088
44.19383	189.2435	-24.73275
44.24383	190.2183	-25.03969
44.29383	191.1937	-25.37012
44.34550	192.2018	-25.74723
44.39717	193.2048	-26.18022
44.44717	194.1763	-26.63636
44.49716	195.1442	-27.16146
44.54883	196.1415	-27.80105
44.60050	197.1322	-28.57444
44.65050	198.0844	-29.44522
44.70050	199.0283	-30.51000
44.75383	200.0236	-31.84490
44.80383	200.9470	-33.29858
44.85383	201.8602	-34.87762
44.90550	202.7949	-36.63852
44.95717	203.7226	-38.47565
45.00717	204.6132	-40.41134
45.05717	205.4938	-42.62958
45.10883	206.3963	-44.84890
45.16050	207.2892	-47.35778
45.21050	208.1456	-49.77658
45.26050	209.0037	-52.05960
45.31383	209.9251	-54.28494
45.36383	210.7981	-56.19598
45.41383	211.6810	-57.80510
45.46550	212.6178	-58.82911
45.51717	213.5936	-58.74221
45.56717	214.6000	-56.95524
45.61716	215.7016	-52.90986
45.66883	216.9543	-46.97686
45.72050	218.2895	-40.94032
45.77050	219.5837	-36.92195
45.82050	220.8268	-34.19353
45.87383	222.0940	-32.03963
45.92383	223.2370	-30.52790
45.97383	224.3473	-29.36648
46.02550	225.4668	-28.45770
46.07717	226.5652	-27.78592
46.12717	227.6140	-27.26935
46.17717	228.6498	-26.91384
46.23050	229.7453	-26.63342
46.28050	230.7655	-26.44787
46.33050	231.7810	-26.31889
46.38217	232.8250	-26.22738
46.43383	233.8651	-26.17966
46.48383	234.8697	-26.15427
46.53383	235.8725	-26.14849
46.58550	236.9077	-26.14570
46.63716	237.9421	-26.14542
46.68716	238.9412	-26.14668
46.73717	239.9410	-26.15352
46.79050	241.0051	-26.17540
46.84050	242.0029	-26.21432
46.89050	243.0020	-26.25650
46.94217	244.0330	-26.31075
46.99383	245.0648	-26.35386
47.04383	246.0629	-26.39666
47.09384	247.0622	-26.44208
47.14550	248.0925	-26.47914
47.19717	249.1246	-26.51069
47.24716	250.1238	-26.54802
47.29716	251.1207	-26.59205
47.35050	252.1852	-26.65228
47.40050	253.1834	-26.69565
47.45050	254.1808	-26.73848
47.50217	255.2120	-26.79248
47.55383	256.2434	-26.83935
47.60383	257.2408	-26.88142
47.65383	258.2394	-26.93875
47.70550	259.2694	-26.99126
47.75717	260.2999	-27.05217
47.80717	261.2966	-27.10269
47.85717	262.2943	-27.16580
47.91050	263.3586	-27.23130
47.96050	264.3558	-27.28708
48.01050	265.3522	-27.33720
48.06216	266.3832	-27.39436
48.11383	267.4133	-27.44610
48.16383	268.4100	-27.51544
48.21383	269.4068	-27.57150
48.26717	270.4701	-27.61416
48.31717	271.4673	-27.65858
48.36716	272.4641	-27.73076
48.41883	273.4936	-27.78820
48.47050	274.5246	-27.80175
48.51717	275.4535	-27.91576
48.56717	276.2200	-28.22652
48.62050	276.3464	-24.79406
48.67050	276.1723	-18.95973
48.72050	275.8041	-13.01492
48.77217	275.2860	-7.636409
48.82383	274.6603	-3.227192
48.87383	273.9748	0.1675806
48.92383	273.2300	2.850494
48.97550	272.4114	5.036278
49.02716	271.5558	6.762646
49.07717	270.6970	8.121542
49.12717	269.8174	9.188459
49.18050	268.8576	10.10471
49.23050	267.9430	10.79661
49.28050	267.0159	11.35597
49.33217	266.0480	11.82787
49.38383	265.0710	12.23200
49.43383	264.1200	12.55336
49.48383	263.1628	12.83173
49.53717	262.1372	13.07070
49.58716	261.1692	13.26792
49.63716	260.1998	13.43044
49.68883	259.1963	13.58664
49.74050	258.1896	13.71199
49.79050	257.2129	13.83091
49.84050	256.2348	13.93529
49.89217	255.2228	14.03878
49.94383	254.2078	14.13473
49.99383	253.2266	14.21402
50.04383	252.2426	14.29552
50.09716	251.1915	14.36000
50.14717	250.2070	14.42155
50.19717	249.2205	14.48521
50.24883	248.2002	14.54316
50.30050	247.1791	14.59676
50.35050	246.1912	14.64015
50.40050	245.2036	14.68058
50.45216	244.1819	14.72483
50.50383	243.1600	14.76249
50.55383	242.1699	14.79570
50.60383	241.1806	14.82820
50.65717	240.1236	14.86311
50.70717	239.1339	14.89656
50.75717	238.1433	14.93272
50.80883	237.1206	14.96392
50.86050	236.0957	15.00164
50.91050	235.1045	15.03217
50.96050	234.1135	15.05808
51.01216	233.0884	15.08490
51.06383	232.0642	15.10596
51.11383	231.0724	15.13092
51.16383	230.0816	15.15516
51.21717	229.0224	15.18330
51.26716	228.0309	15.21350
51.31716	227.0385	15.24443
51.36883	226.0122	15.27263
51.42050	224.9881	15.30225
51.47050	223.9955	15.32792
51.52050	223.0024	15.35477
51.57383	221.9440	15.37968
51.62383	220.9512	15.40106
51.67383	219.9576	15.42366
51.72550	218.9324	15.44604
51.77717	217.9071	15.46430
51.82717	216.9132	15.48267
51.87717	215.9197	15.49920
51.92883	214.8936	15.51874
51.98050	213.8680	15.53661
52.03050	212.8749	15.55210
52.08050	211.8816	15.56902
52.13383	210.8218	15.58815
52.18383	209.8293	15.60525
52.23383	208.8351	15.62356
52.28550	207.8090	15.63808
52.33716	206.7818	15.65468
52.38716	205.7881	15.66656
52.43716	204.7947	15.68144
52.48882	203.7667	15.69327
52.54050	202.7404	15.70505
52.59050	201.7472	15.71437
52.64050	200.7530	15.72854
52.69384	199.6936	15.74394
52.74382	198.6994	15.76089
52.79382	197.7058	15.77619
52.84550	196.6788	15.79246
52.89717	195.6524	15.80856
52.94717	194.6586	15.82743
52.99717	193.6641	15.84549
53.04883	192.6370	15.86326
53.10050	191.6092	15.88148
53.15050	190.6151	15.89318
53.20050	189.6209	15.90418
53.25383	188.5598	15.91563
53.30383	187.5661	15.92638
53.35383	186.5714	15.93827
53.40550	185.5437	15.95167
53.45717	184.5166	15.96324
53.50717	183.5209	15.97305
53.55717	182.5270	15.98255
53.61050	181.4653	15.99242
53.66050	180.4710	16.00189
53.71050	179.4774	16.01308
53.76216	178.4497	16.02961
53.81382	177.4228	16.04593
53.86382	176.4291	16.06939
53.91382	175.4348	16.09985
53.96550	174.4083	16.13611
54.01716	173.3824	16.17856
54.06716	172.3887	16.22677
54.11716	171.3960	16.29012
54.17050	170.3370	16.38016
54.22050	169.3457	16.47796
54.27050	168.3562	16.60180
54.32217	167.3336	16.75774
54.37383	166.3155	16.98120
54.42383	165.3338	17.30316
54.47382	164.3579	17.75816
54.52550	163.3595	18.44788
54.57717	162.3774	19.46203
54.62717	161.4449	20.82216
54.67717	160.5373	22.60501
54.73050	159.5972	24.92883
54.78050	158.7393	27.42178
54.83050	157.9009	30.04014
54.88217	157.0423	32.66883
54.93383	156.1820	35.02840
54.98383	155.3337	36.89783
55.03383	154.4636	38.26375
55.08550	153.5317	39.06588
55.13716	152.5639	39.29350
55.18716	151.5918	38.98380
55.23717	150.5859	38.20361
55.29050	149.4824	37.01115
55.34050	148.4209	35.62734
55.39050	147.3425	34.05975
55.44216	146.2157	32.38618
55.49382	145.0816	30.70094
55.54382	143.9824	29.11438
55.59384	142.8843	27.62753
55.64717	141.7190	26.16945
55.69717	140.6326	24.95924
55.74717	139.5558	23.86923
55.79883	138.4509	22.89648
55.85050	137.3548	22.06008
55.90050	136.3037	21.37176
55.95050	135.2604	20.77733
56.00217	134.1886	20.26119
56.05383	133.1230	19.83030
56.10383	132.0978	19.46502
56.15383	131.0763	19.15592
56.20717	129.9901	18.88295
56.25717	128.9772	18.67324
56.30717	127.9654	18.48479
56.35883	126.9221	18.32970
56.41050	125.8812	18.17788
56.46050	124.8746	18.04604
56.51050	123.8700	17.93823
56.56216	122.8325	17.83184
56.61382	121.7966	17.74158
56.66382	120.7941	17.66019
56.71382	119.7923	17.58965
56.76716	118.7240	17.52012
56.81716	117.7240	17.46404
56.86716	116.7237	17.40992
56.91882	115.6908	17.35714
56.97050	114.6580	17.30630
57.02050	113.6590	17.26386
57.07050	112.6604	17.21492
57.12217	111.6280	17.17151
57.17383	110.5952	17.12884
57.22382	109.5970	17.08851
57.27383	108.5980	17.04917
57.32717	107.5333	17.00981
57.37717	106.5340	16.97210
57.42717	105.5354	16.93423
57.47883	104.5038	16.89478
57.53050	103.4720	16.86276
57.58050	102.4749	16.83287
57.63050	101.4772	16.80298
57.68383	100.4118	16.77242
57.73383	99.41391	16.74459
57.78383	98.41532	16.71596
57.83550	97.38438	16.68829
57.88716	96.35298	16.65659
57.93716	95.35516	16.61990
57.98717	94.35704	16.59095
58.03882	93.32580	16.55812
58.09050	92.29416	16.52679
58.14050	91.29514	16.49690
58.19050	90.29520	16.46151
58.24382	89.23120	16.41697
58.29382	88.23336	16.37692
58.34384	87.23549	16.34313
58.39550	86.20216	16.30123
58.44717	85.16910	16.25580
58.49717	84.17199	16.23328
58.54717	83.17382	16.21104
58.59882	82.14160	16.12063
58.65050	81.10875	16.04871
58.70050	80.10918	16.00145
58.75050	79.10938	15.95164
58.80383	78.04404	15.90525
58.85383	77.04398	15.87163
58.90383	76.04745	15.83587
58.95550	75.01407	15.80058
59.00717	73.98394	15.76304
59.05717	72.98334	15.73285
59.10717	71.98559	15.69696
59.15883	70.95390	15.67198
59.21050	69.92325	15.62874
59.26050	68.92413	15.58945
59.31050	67.92492	15.55280
59.36382	66.86059	15.50575
59.41382	65.86226	15.47229
59.46382	64.86307	15.43969
59.51550	63.83182	15.39391
59.56716	62.79982	15.35313
59.61716	61.80010	15.30816
59.66716	60.80240	15.26889
59.72050	59.73760	15.22679
59.77050	58.73904	15.18912
59.82050	57.73993	15.15262
59.87217	56.70765	15.11434
59.92383	55.67580	15.07208
59.97382	54.67720	15.03895
60.02383	53.67780	15.00036
60.07550	52.64531	14.95608
60.12717	51.61339	14.91483
60.17717	50.61417	14.87434
60.22717	49.61567	14.83467
60.28050	48.54887	14.79260
60.33050	47.55056	14.75106
60.38050	46.55094	14.71325
60.43217	45.51853	14.67464
60.48383	44.48606	14.63106
60.53383	43.48637	14.59239
60.58383	42.48837	14.54473
60.63550	41.45464	14.49933
60.68716	40.42256	14.44544
60.73717	39.42254	14.40187
60.78716	38.42276	14.34137
60.84050	37.35562	14.27872
60.89050	36.35623	14.21574
60.94050	35.35660	14.19401
60.99216	34.32222	14.12694
61.04382	33.28898	14.04971
61.09384	32.28744	13.97954
61.14384	31.28561	13.91765
61.19550	30.25260	13.85860
61.24717	29.21787	13.77721
61.29717	28.21604	13.69714
61.34716	27.21202	13.62225
61.40050	26.14211	13.53729
61.45050	25.13930	13.48332
-2.000000	4.000000	0.0000000
61.54883	23.22708	13.57165
61.60050	22.80554	11.50225
61.65050	22.80032	7.462390
61.70050	23.03220	3.594065
61.75383	23.47690	0.1263923
61.80383	24.02558	-2.485183
61.85383	24.67343	-4.564074
61.90550	25.42146	-6.252521
61.95717	26.22974	-7.571630
62.00717	27.05550	-8.588970
62.05717	27.91417	-9.396170
62.10883	28.82938	-10.06905
62.16050	29.76569	-10.60430
62.21050	30.68682	-11.02445
62.26050	31.61944	-11.37961
62.31382	32.62486	-11.68511
62.36382	33.57566	-11.94283
62.41382	34.53274	-12.13994
62.46550	35.52778	-12.32876
62.51716	36.52513	-12.49369
62.56716	37.49589	-12.63786
62.61716	38.46800	-12.76354
62.66882	39.47552	-12.87652
62.72050	40.48720	-12.98027
62.77050	41.46676	-13.08235
62.82050	42.44780	-13.17211
62.87383	43.49456	-13.26575
62.92383	44.47736	-13.34184
62.97382	45.46274	-13.42878
63.02550	46.48150	-13.50795
63.07717	47.50050	-13.58916
63.12717	48.48843	-13.66634
63.17717	49.47711	-13.74339
63.22883	50.49752	-13.82749
63.28050	51.51864	-13.90159
63.33050	52.50732	-13.97487
63.38050	53.49883	-14.05230
63.43383	54.55448	-14.12627
63.48383	55.54638	-14.20674
63.53383	56.53760	-14.27434
63.58550	57.56220	-14.35075
63.63716	58.58762	-14.42409
63.68716	59.57926	-14.50098
63.73717	60.56980	-14.57272
63.79050	61.62959	-14.65970
63.84050	62.62240	-14.73698
63.89050	63.61550	-14.80698
63.94216	64.64238	-14.87820
63.99382	65.66924	-14.94856
64.04384	66.66332	-15.02002
64.09384	67.65876	-15.09601
64.14550	68.68650	-15.15777
64.19717	69.71504	-15.23048
64.24717	70.70976	-15.29127
64.29718	71.70422	-15.36563
64.35050	72.76474	-15.44221
64.40050	73.76007	-15.50910
64.45050	74.75663	-15.58420
64.50217	75.78358	-15.65372
64.55383	76.81276	-15.73333
64.60383	77.80785	-15.80527
64.65384	78.80246	-15.88032
64.70550	79.83142	-15.96026
64.75718	80.85965	-16.04045
64.80717	81.85510	-16.11983
64.85718	82.85140	-16.19398
64.91050	83.91251	-16.27626
64.96050	84.90672	-16.35381
65.01050	85.90226	-16.43632
65.06216	86.93000	-16.51970
65.11384	87.95995	-16.60379
65.16382	88.95576	-16.68224
65.21384	89.95109	-16.76987
65.26550	90.97953	-16.84879
65.31717	92.00851	-16.93631
65.36718	93.00403	-17.01379
65.41717	93.99926	-17.09476
65.47050	95.06102	-17.18393
65.52050	96.05543	-17.27138
65.57050	97.05236	-17.34814
65.62218	98.08075	-17.42651
65.67384	99.10949	-17.50785
65.72384	100.1048	-17.59308
65.77384	101.1000	-17.67525
65.82718	102.1634	-17.76076
65.87718	103.1584	-17.83912
65.92718	104.1544	-17.92517
65.97884	105.1832	-18.01309
66.03050	106.2115	-18.09624
66.08050	107.2069	-18.18980
66.13050	108.2020	-18.27241
66.18218	109.2309	-18.35512
66.23384	110.2598	-18.44530
66.28384	111.2564	-18.53428
66.33384	112.2516	-18.61306
66.38718	113.3134	-18.70644
66.43718	114.3098	-18.78634
66.48718	115.3052	-18.87515
66.53882	116.3338	-18.96043
66.59050	117.3632	-19.04644
66.64050	118.3578	-19.13860
66.69050	119.3527	-19.22873
66.74218	120.3812	-19.32658
66.79384	121.4090	-19.42169
66.84384	122.4042	-19.51750
66.89384	123.3996	-19.61364
66.94718	124.4612	-19.71661
66.99718	125.4553	-19.81337
67.04718	126.4498	-19.90509
67.09882	127.4784	-20.00318
67.15050	128.5066	-20.09612
67.20050	129.5009	-20.19555
67.25050	130.4955	-20.30466
67.30218	131.5242	-20.40732
67.35384	132.5519	-20.50937
67.40384	133.5461	-20.62300
67.45384	134.5414	-20.72234
67.50718	135.6018	-20.84259
67.55718	136.5961	-20.95345
67.60718	137.5904	-21.06536
67.65884	138.6184	-21.17989
67.71050	139.6454	-21.30918
67.76050	140.6398	-21.41215
67.81050	141.6338	-21.52226
67.86384	142.6948	-21.65806
67.91382	143.6882	-21.75191
67.96384	144.6816	-21.87925
68.01550	145.7089	-21.98752
68.06718	146.7312	-22.31722
68.11718	147.7258	-22.27098
68.16718	148.7200	-22.38582
68.21884	149.7484	-22.49320
68.27050	150.7768	-22.59568
68.32050	151.7703	-22.70483
68.37050	152.7652	-22.81689
68.42384	153.8257	-22.93011
68.47384	154.8204	-23.04060
68.52384	155.8133	-23.15956
68.57550	156.8416	-23.25712
68.62718	157.8692	-23.35428
68.67718	158.8652	-23.44094
68.72718	159.8614	-23.50661
68.77884	160.8912	-23.57532
68.83050	161.9227	-23.62082
68.88050	162.9215	-23.65614
68.93050	163.9189	-23.69076
68.98384	164.9844	-23.72008
69.03384	165.9844	-23.75642
69.08384	166.9818	-23.80028
69.13550	168.0130	-23.85092
69.18718	169.0448	-23.92750
69.23718	170.0420	-23.99571
69.28718	171.0379	-24.09609
69.33884	172.0674	-24.20545
69.39050	173.0964	-24.31137
69.44050	174.0908	-24.42480
69.49050	175.0852	-24.54988
69.54384	176.1450	-24.69511
69.59384	177.1374	-24.84884
69.64384	178.1291	-25.02030
69.69550	179.1531	-25.20641
69.74718	180.1751	-25.41968
69.79718	181.1629	-25.66335
69.84718	182.1504	-25.90320
69.90050	183.2018	-26.21139
69.95050	184.1855	-26.53270
70.00050	185.1690	-26.86186
70.05218	186.1826	-27.24842
70.10384	187.1930	-27.67932
70.15384	188.1693	-28.13031
70.20384	189.1438	-28.61789
70.25550	190.1472	-29.16922
70.30718	191.1484	-29.74991
70.35718	192.1157	-30.33332
70.40718	193.0812	-30.94080
70.46050	194.1093	-31.60115
70.51050	195.0721	-32.26006
70.56050	196.0327	-32.96143
70.61218	197.0236	-33.74625
70.66382	198.0095	-34.60276
70.71384	198.9601	-35.50448
70.76384	199.9082	-36.47171
70.81550	200.8826	-37.53886
70.86718	201.8546	-38.63400
70.91718	202.7938	-39.68112
70.96718	203.7317	-40.66079
71.02050	204.7381	-41.56332
71.07050	205.6908	-42.10780
71.12050	206.6595	-42.20150
71.17218	207.6866	-41.63299
71.22384	208.7567	-39.93592
71.27384	209.8440	-37.40962
71.32384	210.9762	-34.49608
71.37550	212.1658	-31.91291
71.42718	213.3442	-29.98733
71.47718	214.4623	-28.65129
71.52718	215.5548	-27.65694
71.58050	216.6976	-26.86910
71.63050	217.7532	-26.31175
71.68050	218.7934	-25.89356
71.73218	219.8599	-25.57814
71.78384	220.9179	-25.34796
71.83384	221.9354	-25.18928
71.88384	222.9477	-25.07664
71.93718	224.0244	-25.00307
71.98718	225.0304	-24.94191
72.03718	226.0350	-24.91998
72.08884	227.0718	-24.91168
72.14050	228.1058	-24.90807
72.19050	229.1072	-24.90827
72.24050	230.1085	-24.90975
72.29218	231.1408	-24.91521
72.34384	232.1734	-24.93566
72.39384	233.1712	-24.96810
72.44384	234.1715	-25.00668
72.49718	235.2360	-25.05682
72.54718	236.2350	-25.09405
72.59718	237.2337	-25.13682
72.64884	238.2654	-25.17916
72.70050	239.2969	-25.22004
72.75050	240.2946	-25.26955
72.80050	241.2937	-25.32530
72.85218	242.3244	-25.37892
72.90384	243.3548	-25.43230
72.95384	244.3534	-25.48050
73.00384	245.3506	-25.52588
73.05718	246.4144	-25.59066
73.10718	247.4114	-25.63691
73.15718	248.4091	-25.68296
73.20884	249.4396	-25.73399
73.26050	250.4699	-25.78580
73.31050	251.4668	-25.89885
73.36050	252.4630	-25.94281
73.41218	253.4938	-25.98118
73.46384	254.5243	-26.02454
73.51384	255.5216	-26.09163
73.56384	256.5186	-26.17425
73.61718	257.5820	-26.22377
73.66718	258.5792	-26.27752
73.71718	259.5771	-26.33580
73.76882	260.6074	-26.38845
73.82050	261.6372	-26.44448
73.87050	262.6342	-26.50994
73.92050	263.6324	-26.56497
73.97384	264.6962	-26.62474
74.02384	265.6926	-26.69798
74.07384	266.6899	-26.75740
74.12550	267.7195	-26.84902
74.17718	268.7483	-26.94487
74.22718	269.7442	-26.99898
74.27718	270.7402	-27.06289
74.32884	271.7704	-27.10041
-2.000000	5.000000	0.0000000