File: 5-C1(1.4mol%)+C20(0.6mol%)/matlab/130-1.txt
CLOSED
Version	1.0
Language	English
Mode	Standard
Run	15
RunSerial	12317
Instrument	DSC Q2000 V24.11 Build 124
Module	DSC Standard Cell RC
Operator
File	\\AE520-1454\Users\dsc\Desktop\Data\31-08-17-2\130-1.001
ProcName
InstSerial	2000-0883
AutoSerial	1293
Sample	130-1
Size	18.9000	mg
PanMass	Not available
PanResist	Automatic Automatic  K/W
PanFactor	Default Default
Method
Comment
Xcomment	Pan: Tzero Aluminum Hermetic
Xcomment	Gas1: Nitrogen 50.0 ml/min
Xcomment	Gas2: Nitrogen 50.0 ml/min
Text
Exotherm	UP
Kcell	1.05230
Cpconst	Standard: 0.938
Calib	-38.6961
TempCal	1	pts	157.46	156.60
TzeroDt	-87.6168 -0.0009 -1.4231
TzeroDtz	-87.6168 0.0057 6.9570
InstCalFile	Tzero: \\Ae520-1454\ta\Data\DSC\Calibration\2017\CALIBRATION\1562_RCS (90)_05_18_2017 10_50_44.TZR
InstCalFile	Baseline: \\Ae520-1454\ta\Data\DSC\Calibration\2017\2017-05-17_Calibration.001
InstCalFile	Sapphire: \\Ae520-1454\ta\Data\DSC\Calibration\2017\2017-05-17_Saphire.001
InstCalDate	Tzero 2017-05-18 Time 10:50:44
TempRange	-87.39 to 398.39 °C at 10.00 °C/min Heat Only
AutoZero	Delta T Offset 0.000 uV
AutoZero	Delta T0 Offset 0.000 uV
MultiptCal	0
MultiPtDesc	0) Not set
AutoCellConst	Calibration Date 2017-05-18 16:59:28
Controls	Gas 1  Event Off  Sampling 0.2
Cell#	RC-01562
CoolingUnit	RCS (90)
SelHeatFlow	Heat Flow T4P (mW)
AutoLidII	Installed
AutoAnalysis	Off
MacroFile
Nsig	3
Sig1	Time (min)
Sig2	Temperature (°C)
Sig3	Heat Flow (mW)
Date	2017-09-01
Time	04:47:05
OrgMethod	1: Equilibrate at 80.00 °C
OrgMethod	2: Isothermal for 3.00 min
OrgMethod	3: Jump to 130.00 °C
OrgMethod	4: Mark end of cycle 1
OrgMethod	5: Isothermal for 40.00 min
OrgMethod	6: Mark end of cycle 2
OrgMethod	7: Ramp 20.00 °C/min to 280.00 °C
OrgMethod	8: Mark end of cycle 3
OrgMethod	9: Ramp 20.00 °C/min to 20.00 °C
OrgMethod	10: Mark end of cycle 4
OrgMethod	11: Ramp 20.00 °C/min to 280.00 °C
OrgMethod	12: Mark end of cycle 5
OrgFile	C:\Users\jarra\Desktop\DSC\5-C1(1.4mol%)+C20(0.6mol%)\130-1.001
StartOfData
4.99994E-4	79.87688	-1.402304
0.05383332	79.88946	-1.195962
0.1071666	79.89838	-1.050430
0.1588333	79.90326	-0.9498749
0.2105000	79.90650	-0.8797388
0.2638334	79.90818	-0.8322524
0.3155000	79.90870	-0.7994870
0.3671667	79.90838	-0.7809700
0.4205000	79.90929	-0.7691336
0.4721666	79.90748	-0.7615394
0.5238333	79.90699	-0.7584712
0.5771668	79.90536	-0.7558735
0.6305000	79.90457	-0.7533366
0.6805000	79.90419	-0.7509712
0.7338332	79.90356	-0.7486506
0.7871668	79.90216	-0.7464761
0.8371668	79.90084	-0.7446656
0.8904999	79.90043	-0.7430246
0.9438332	79.89900	-0.7415343
0.9955000	79.89760	-0.7403962
1.047167	79.89697	-0.7394124
1.100500	79.89644	-0.7385564
1.152167	79.89520	-0.7379310
1.203834	79.89518	-0.7376124
1.257166	79.89438	-0.7373491
1.308833	79.89265	-0.7372634
1.360500	79.89234	-0.7372803
1.413834	79.89104	-0.7374176
1.465500	79.89150	-0.7376862
1.517167	79.89028	-0.7380274
1.570500	79.88918	-0.7385034
1.623833	79.88868	-0.7391342
1.673834	79.88830	-0.7398624
1.727167	79.88838	-0.7407550
1.780500	79.88700	-0.7417245
1.830500	79.88726	-0.7426985
1.883833	79.88624	-0.7437028
1.937166	79.88512	-0.7447745
1.988833	79.88462	-0.7458401
2.040500	79.88435	-0.7470853
2.093834	79.88464	-0.7483872
2.145500	79.88355	-0.7496503
2.197166	79.88351	-0.7510122
2.250500	79.88266	-0.7523761
2.302166	79.88199	-0.7536701
2.353833	79.88132	-0.7549426
2.407167	79.88149	-0.7563599
2.458833	79.88006	-0.7577412
2.510500	79.87945	-0.7591560
2.563833	79.87962	-0.7606500
2.617167	79.87844	-0.7620903
2.667167	79.87847	-0.7636376
2.720500	79.87808	-0.7652316
2.773833	79.87719	-0.7668832
2.823833	79.87719	-0.7683472
2.877167	79.87710	-0.7699884
2.930500	79.87588	-0.7715924
2.982167	79.87588	-0.7731720
3.030500	79.93235	-1.936241
3.082167	81.18760	-16.06383
3.133833	83.59171	-28.12930
3.187167	86.69332	-39.01277
3.238834	90.16468	-47.92136
3.290500	93.96892	-55.22851
3.343834	98.14621	-61.28346
3.397167	102.4998	-66.11818
3.447167	106.7002	-69.67874
3.500500	111.2676	-72.63091
3.553833	115.7792	-73.10595
3.603833	119.0116	-63.63571
3.657167	121.3901	-52.83628
3.710500	123.1464	-43.67728
3.762167	124.4375	-34.69964
3.813833	125.4444	-27.51021
3.867166	126.2425	-21.57593
3.918833	126.8414	-17.09122
3.970500	127.3144	-13.59004
4.023834	127.7023	-10.82520
4.075500	128.0032	-8.789188
4.127167	128.2483	-7.245141
4.180500	128.4551	-6.031826
4.232167	128.6212	-5.140243
4.283834	128.7607	-4.461679
4.337167	128.8831	-3.923009
4.390500	128.9865	-3.513272
4.440500	129.0700	-3.216770
4.493834	129.1474	-2.970566
4.547167	129.2138	-2.776205
4.597166	129.2681	-2.635088
4.650500	129.3193	-2.513462
4.703833	129.3642	-2.416850
4.755500	129.4013	-2.340426
4.807167	129.4356	-2.283067
4.860500	129.4658	-2.230649
4.912167	129.4930	-2.192146
4.963834	129.5157	-2.157958
5.017166	129.5367	-2.130925
5.068833	129.5551	-2.111060
5.120500	129.5712	-2.092427
5.173834	129.5870	-2.078424
5.225500	129.5998	-2.068202
5.277168	129.6109	-2.058238
5.330500	129.6217	-2.051405
5.383832	129.6307	-2.045626
5.433832	129.6386	-2.040578
5.487168	129.6470	-2.035217
5.540500	129.6540	-2.029620
5.590500	129.6601	-2.024307
5.643832	129.6672	-2.018542
5.697168	129.6700	-2.012742
5.748834	129.6759	-2.007241
5.800500	129.6799	-2.001622
5.853832	129.6854	-1.995975
5.905500	129.6877	-1.990456
5.957168	129.6918	-1.985029
6.010500	129.6943	-1.979459
6.062168	129.6978	-1.974101
6.113834	129.6997	-1.968766
6.167168	129.7026	-1.963256
6.220500	129.7047	-1.957809
6.270500	129.7064	-1.952674
6.323834	129.7081	-1.947271
6.377168	129.7104	-1.941896
6.427168	129.7118	-1.936895
6.480500	129.7143	-1.931504
6.533832	129.7143	-1.926165
6.585500	129.7159	-1.921088
6.637168	129.7180	-1.916073
6.690500	129.7193	-1.910788
6.742166	129.7203	-1.905692
6.793832	129.7218	-1.900647
6.847168	129.7231	-1.895422
6.898834	129.7237	-1.890397
6.950500	129.7251	-1.885430
7.003832	129.7259	-1.880359
7.055500	129.7259	-1.875432
7.107168	129.7275	-1.870614
7.160500	129.7291	-1.865606
7.213834	129.7296	-1.860616
7.263834	129.7301	-1.856033
7.317168	129.7314	-1.851095
7.370500	129.7327	-1.846190
7.420500	129.7333	-1.841552
7.473834	129.7343	-1.836583
7.527168	129.7344	-1.831506
7.578834	129.7349	-1.826606
7.630500	129.7363	-1.821756
7.683832	129.7363	-1.816647
7.735500	129.7366	-1.811704
7.787168	129.7373	-1.806765
7.840500	129.7383	-1.801703
7.892168	129.7379	-1.796746
7.943832	129.7390	-1.791825
7.997168	129.7392	-1.786821
8.048834	129.7396	-1.782038
8.100500	129.7407	-1.777279
8.153832	129.7408	-1.772312
8.207168	129.7414	-1.767416
8.257168	129.7422	-1.762839
8.310500	129.7421	-1.757934
8.363834	129.7432	-1.753004
8.413834	129.7429	-1.748450
8.467168	129.7446	-1.743528
8.520500	129.7444	-1.738580
8.572168	129.7446	-1.733862
8.623834	129.7450	-1.729138
8.677168	129.7470	-1.724366
8.728834	129.7460	-1.719587
8.780500	129.7466	-1.714874
8.833832	129.7466	-1.709978
8.885499	129.7477	-1.705259
8.937166	129.7487	-1.700568
8.990500	129.7486	-1.695675
9.042168	129.7493	-1.691062
9.093832	129.7494	-1.686316
9.147168	129.7501	-1.681497
9.200500	129.7510	-1.676639
9.250500	129.7518	-1.672064
9.303832	129.7516	-1.667100
9.357166	129.7522	-1.662091
9.407166	129.7526	-1.657360
9.460499	129.7536	-1.652252
9.513832	129.7527	-1.647043
9.565500	129.7538	-1.642043
9.617166	129.7544	-1.637051
9.670500	129.7534	-1.631841
9.722168	129.7550	-1.626936
9.773834	129.7551	-1.621906
9.827168	129.7558	-1.616816
9.878834	129.7560	-1.611882
9.930500	129.7566	-1.606928
9.983832	129.7566	-1.601618
10.03550	129.7575	-1.596532
10.08717	129.7578	-1.591301
10.14050	129.7584	-1.586039
10.19383	129.7586	-1.580719
10.24383	129.7594	-1.575787
10.29717	129.7604	-1.570516
10.35050	129.7607	-1.565186
10.40050	129.7606	-1.560226
10.45383	129.7617	-1.554913
10.50717	129.7617	-1.549531
10.55884	129.7624	-1.544185
10.61050	129.7629	-1.538766
10.66383	129.7630	-1.533089
10.71550	129.7635	-1.527529
10.76717	129.7646	-1.521903
10.82050	129.7643	-1.516093
10.87217	129.7639	-1.510322
10.92383	129.7652	-1.504596
10.97717	129.7664	-1.498661
11.03050	129.7660	-1.492592
11.08050	129.7663	-1.486853
11.13383	129.7666	-1.480656
11.18716	129.7680	-1.474466
11.23717	129.7678	-1.468590
11.29050	129.7689	-1.462312
11.34383	129.7701	-1.455949
11.39550	129.7700	-1.449688
11.44717	129.7710	-1.443396
11.50050	129.7713	-1.436630
11.55216	129.7722	-1.430013
11.60383	129.7720	-1.423275
11.65717	129.7736	-1.416111
11.70883	129.7742	-1.408932
11.76050	129.7752	-1.401484
11.81383	129.7756	-1.393108
11.86550	129.7762	-1.385252
11.91717	129.7773	-1.377051
11.97050	129.7787	-1.367338
12.02383	129.7798	-1.357501
12.07383	129.7803	-1.344913
12.12717	129.7821	-1.329614
12.18050	129.7826	-1.312405
12.23050	129.7838	-1.293056
12.28383	129.7863	-1.268500
12.33717	129.7882	-1.239830
12.38883	129.7901	-1.207535
12.44050	129.7920	-1.172964
12.49384	129.7934	-1.132078
12.54550	129.7956	-1.090456
12.59717	129.7986	-1.050971
12.65050	129.7993	-1.006470
12.70217	129.8026	-0.9635124
12.75384	129.8053	-0.9189574
12.80717	129.8071	-0.8738456
12.85883	129.8101	-0.8296739
12.91050	129.8129	-0.7858603
12.96383	129.8157	-0.7385794
13.01717	129.8189	-0.6935989
13.06716	129.8207	-0.6494918
13.12050	129.8248	-0.6088613
13.17383	129.8278	-0.5619199
13.22383	129.8296	-0.5216291
13.27717	129.8329	-0.4795166
13.33050	129.8351	-0.4379186
13.38216	129.8389	-0.3989060
13.43383	129.8414	-0.3608720
13.48716	129.8432	-0.3225235
13.53883	129.8466	-0.2875536
13.59050	129.8487	-0.2541736
13.64383	129.8511	-0.2210754
13.69550	129.8529	-0.1895470
13.74717	129.8560	-0.1621434
13.80050	129.8567	-0.1334272
13.85217	129.8601	-0.1082004
13.90383	129.8617	-.08230400
13.95717	129.8634	-.05952374
14.01050	129.8656	-.03650345
14.06050	129.8671	-.01796242
14.11383	129.8686	.003237533
14.16716	129.8706	0.02240795
14.21716	129.8724	0.04055792
14.27050	129.8738	0.05914822
14.32384	129.8746	0.07906951
14.37550	129.8762	0.09562672
14.42717	129.8774	0.1123720
14.48050	129.8789	0.1286526
14.53217	129.8800	0.1441375
14.58383	129.8805	0.1602156
14.63717	129.8824	0.1757241
14.68883	129.8833	0.1894650
14.74050	129.8848	0.2031517
14.79384	129.8856	0.2177340
14.84550	129.8881	0.2328155
14.89717	129.8886	0.2484562
14.95050	129.8906	0.2635290
15.00383	129.8916	0.2782795
15.05383	129.8929	0.2928343
15.10716	129.8942	0.3092978
15.16050	129.8953	0.3254638
15.21050	129.8962	0.3419210
15.26383	129.8979	0.3597605
15.31716	129.8993	0.3782938
15.36884	129.8997	0.3977388
15.42050	129.9005	0.4171390
15.47383	129.9031	0.4357298
15.52550	129.9039	0.4539322
15.57717	129.9049	0.4739518
15.63050	129.9064	0.4938730
15.68217	129.9076	0.5136578
15.73383	129.9087	0.5329350
15.78717	129.9097	0.5537850
15.84050	129.9118	0.5734120
15.89050	129.9122	0.5917993
15.94384	129.9140	0.6113681
15.99717	129.9157	0.6316440
16.04716	129.9172	0.6518930
16.10050	129.9188	0.6726114
16.15383	129.9206	0.6949096
16.20550	129.9218	0.7157032
16.25716	129.9228	0.7366516
16.31050	129.9249	0.7590193
16.36216	129.9262	0.7816487
16.41383	129.9281	0.8051968
16.46716	129.9292	0.8300218
16.51883	129.9306	0.8548791
16.57050	129.9318	0.8778934
16.62383	129.9329	0.9032297
16.67550	129.9346	0.9270499
16.72716	129.9359	0.9483992
16.78050	129.9381	0.9716144
16.83383	129.9394	0.9951244
16.88383	129.9416	1.018536
16.93716	129.9430	1.044663
16.99050	129.9445	1.070748
17.04050	129.9459	1.096272
17.09383	129.9470	1.123772
17.14716	129.9487	1.148637
17.19884	129.9506	1.172504
17.25050	129.9522	1.197928
17.30383	129.9525	1.223733
17.35550	129.9557	1.246732
17.40716	129.9573	1.270000
17.46050	129.9584	1.295555
17.51216	129.9610	1.319978
17.56383	129.9620	1.345852
17.61716	129.9646	1.372992
17.66883	129.9662	1.400312
17.72050	129.9670	1.426782
17.77383	129.9704	1.453294
17.82716	129.9722	1.483848
17.87716	129.9735	1.511323
17.93050	129.9762	1.537707
17.98383	129.9775	1.565716
18.03383	129.9778	1.592193
18.08716	129.9811	1.619272
18.14050	129.9818	1.647382
18.19216	129.9847	1.674419
18.24383	129.9859	1.700464
18.29716	129.9880	1.729754
18.34883	129.9902	1.758709
18.40050	129.9915	1.787416
18.45383	129.9941	1.817024
18.50550	129.9959	1.847016
18.55716	129.9972	1.875862
18.61050	130.0000	1.904409
18.66217	130.0010	1.935519
18.71383	130.0021	1.965375
18.76716	130.0058	1.995818
18.82050	130.0069	2.024295
18.87050	130.0087	2.049836
18.92383	130.0105	2.078014
18.97716	130.0126	2.107234
19.02716	130.0145	2.134162
19.08050	130.0171	2.163040
19.13383	130.0190	2.191842
19.18550	130.0208	2.221138
19.23716	130.0228	2.249203
19.29050	130.0253	2.278748
19.34216	130.0274	2.308086
19.39383	130.0293	2.337448
19.44716	130.0313	2.366349
19.49883	130.0331	2.393448
19.55050	130.0348	2.422880
19.60383	130.0365	2.449549
19.65550	130.0383	2.475828
19.70716	130.0395	2.502533
19.76050	130.0414	2.527617
19.81383	130.0437	2.552723
19.86383	130.0446	2.577838
19.91716	130.0471	2.603193
19.97050	130.0485	2.628015
20.02050	130.0498	2.650444
20.07383	130.0510	2.672184
20.12716	130.0527	2.694524
20.17883	130.0549	2.713950
20.23050	130.0554	2.731531
20.28383	130.0586	2.749258
20.33550	130.0588	2.766900
20.38716	130.0615	2.781648
20.44050	130.0611	2.798002
20.49216	130.0626	2.812040
20.54383	130.0642	2.827036
20.59716	130.0651	2.839548
20.65050	130.0651	2.850648
20.70050	130.0669	2.859768
20.75383	130.0675	2.868382
20.80716	130.0688	2.876604
20.85716	130.0689	2.884432
20.91050	130.0693	2.892841
20.96383	130.0699	2.901202
21.01550	130.0711	2.909188
21.06716	130.0706	2.916963
21.12050	130.0711	2.924777
21.17216	130.0717	2.931979
21.22383	130.0718	2.938945
21.27717	130.0718	2.945736
21.32883	130.0724	2.951849
21.38050	130.0720	2.957708
21.43383	130.0718	2.963178
21.48550	130.0716	2.968039
21.53717	130.0710	2.972325
21.59050	130.0715	2.976170
21.64383	130.0692	2.979494
21.69383	130.0700	2.982064
21.74716	130.0690	2.984234
21.80050	130.0681	2.985578
21.85050	130.0668	2.986157
21.90383	130.0665	2.985982
21.95717	130.0661	2.984873
22.00883	130.0643	2.982844
22.06050	130.0635	2.979985
22.11383	130.0629	2.975287
22.16550	130.0616	2.969675
22.21716	130.0600	2.963684
22.27050	130.0600	2.954336
22.32216	130.0581	2.943124
22.37383	130.0563	2.931985
22.42717	130.0558	2.918627
22.47883	130.0549	2.905398
22.53050	130.0530	2.891206
22.58383	130.0523	2.874094
22.63716	130.0516	2.857242
22.68716	130.0499	2.838726
22.74050	130.0480	2.819430
22.79383	130.0467	2.799449
22.84383	130.0454	2.778171
22.89716	130.0428	2.755932
22.95050	130.0424	2.731681
23.00217	130.0397	2.710346
23.05383	130.0384	2.686558
23.10716	130.0366	2.664368
23.15883	130.0344	2.641783
23.21050	130.0328	2.616200
23.26383	130.0305	2.588694
23.31550	130.0293	2.561067
23.36716	130.0274	2.535197
23.42050	130.0260	2.508052
23.47216	130.0250	2.484516
23.52383	130.0245	2.462810
23.57716	130.0224	2.442427
23.63050	130.0204	2.422021
23.68050	130.0199	2.403364
23.73383	130.0178	2.381595
23.78717	130.0160	2.358690
23.83716	130.0148	2.336502
23.89050	130.0135	2.315727
23.94383	130.0115	2.293595
23.99550	130.0100	2.272034
24.04716	130.0086	2.252312
24.10050	130.0069	2.229805
24.15216	130.0054	2.208164
24.20383	130.0047	2.186663
24.25716	130.0024	2.166266
24.30883	130.0013	2.148345
24.36050	129.9998	2.129638
24.41383	129.9981	2.109414
24.46550	129.9973	2.090836
24.51716	129.9969	2.073834
24.57050	129.9948	2.057144
24.62383	129.9941	2.039952
24.67383	129.9928	2.024339
24.72716	129.9922	2.008264
24.78050	129.9896	1.993286
24.83050	129.9894	1.979296
24.88383	129.9880	1.965277
24.93716	129.9868	1.951085
24.98883	129.9857	1.938126
25.04050	129.9841	1.926162
25.09383	129.9830	1.912901
25.14550	129.9820	1.898884
25.19716	129.9808	1.886774
25.25050	129.9795	1.872162
25.30217	129.9786	1.857215
25.35383	129.9775	1.843122
25.40716	129.9769	1.828182
25.46050	129.9751	1.813844
25.51050	129.9744	1.801488
25.56383	129.9729	1.788733
25.61716	129.9720	1.775881
25.66716	129.9703	1.765670
25.72050	129.9710	1.753281
25.77383	129.9697	1.740645
25.82550	129.9689	1.729238
25.87716	129.9674	1.717836
25.93050	129.9674	1.705701
25.98216	129.9665	1.693264
26.03383	129.9660	1.682058
26.08716	129.9645	1.670414
26.13883	129.9645	1.659299
26.19050	129.9638	1.648754
26.24383	129.9619	1.637232
26.29550	129.9621	1.626061
26.34716	129.9617	1.615278
26.40050	129.9604	1.603967
26.45383	129.9593	1.592333
26.50383	129.9577	1.581381
26.55716	129.9576	1.569909
26.61050	129.9569	1.558461
26.66050	129.9570	1.547654
26.71383	129.9558	1.536524
26.76716	129.9557	1.525175
26.81883	129.9548	1.514306
26.87050	129.9542	1.503337
26.92383	129.9537	1.492184
26.97550	129.9524	1.481145
27.02717	129.9516	1.470380
27.08050	129.9510	1.459244
27.13216	129.9502	1.448420
27.18383	129.9491	1.437771
27.23716	129.9486	1.426840
27.28883	129.9476	1.416348
27.34050	129.9461	1.405934
27.39383	129.9464	1.395255
27.44717	129.9442	1.384458
27.49716	129.9438	1.374407
27.55050	129.9430	1.363621
27.60383	129.9426	1.352877
27.65383	129.9421	1.342674
27.70716	129.9412	1.331856
27.76050	129.9405	1.321044
27.81217	129.9401	1.310704
27.86383	129.9397	1.300361
27.91716	129.9394	1.289824
27.96883	129.9382	1.279678
28.02050	129.9374	1.269626
28.07383	129.9371	1.259298
28.12550	129.9369	1.249228
28.17717	129.9359	1.239214
28.23050	129.9352	1.229022
28.28216	129.9344	1.219102
28.33383	129.9350	1.209199
28.38716	129.9336	1.199158
28.44050	129.9331	1.189123
28.49050	129.9321	1.179820
28.54383	129.9316	1.169954
28.59716	129.9319	1.160237
28.64716	129.9307	1.151267
28.70050	129.9303	1.141636
28.75383	129.9298	1.132058
28.80550	129.9294	1.122714
28.85716	129.9285	1.113474
28.91050	129.9281	1.103958
28.96216	129.9268	1.094748
29.01383	129.9261	1.085634
29.06716	129.9245	1.076201
29.11883	129.9247	1.067028
29.17050	129.9249	1.057837
29.22383	129.9233	1.048530
29.27550	129.9234	1.039483
29.32717	129.9224	1.030448
29.38050	129.9222	1.021135
29.43383	129.9210	1.011817
29.48383	129.9211	1.003125
29.53717	129.9206	0.9938738
29.59050	129.9199	0.9847351
29.64050	129.9195	0.9761358
29.69383	129.9182	0.9670055
29.74716	129.9177	0.9579500
29.79883	129.9176	0.9491290
29.85050	129.9177	0.9403438
29.90383	129.9166	0.9313453
29.95550	129.9159	0.9226532
30.00716	129.9159	0.9139442
30.06050	129.9149	0.9050301
30.11216	129.9141	0.8963765
30.16383	129.9138	0.8877155
30.21716	129.9129	0.8788996
30.27050	129.9129	0.8700981
30.32050	129.9116	0.8618975
30.37383	129.9116	0.8532374
30.42717	129.9111	0.8444928
30.47717	129.9106	0.8363400
30.53050	129.9092	0.8275928
30.58383	129.9092	0.8189101
30.63550	129.9089	0.8104118
30.68717	129.9083	0.8019760
30.74050	129.9072	0.7932420
30.79216	129.9076	0.7848504
30.84383	129.9064	0.7764831
30.89716	129.9061	0.7679482
30.94883	129.9062	0.7595922
31.00050	129.9052	0.7514122
31.05383	129.9048	0.7428858
31.10550	129.9040	0.7346886
31.15716	129.9032	0.7264972
31.21050	129.9030	0.7181141
31.26383	129.9020	0.7096985
31.31383	129.9023	0.7019054
31.36716	129.9011	0.6935499
31.42050	129.9011	0.6852062
31.47050	129.9006	0.6774082
31.52383	129.8999	0.6691428
31.57717	129.8996	0.6609588
31.62883	129.8984	0.6529934
31.68050	129.8984	0.6451056
31.73383	129.8971	0.6370106
31.78550	129.8966	0.6291912
31.83716	129.8955	0.6214490
31.89050	129.8947	0.6134606
31.94216	129.8943	0.6056666
31.99383	129.8934	0.5979070
32.04716	129.8937	0.5897702
32.09883	129.8929	0.5819584
32.15050	129.8927	0.5740236
32.20383	129.8923	0.5658199
32.25716	129.8910	0.5576310
32.30716	129.8911	0.5498752
32.36050	129.8916	0.5416337
32.41383	129.8904	0.5334500
32.46383	129.8899	0.5257439
32.51716	129.8895	0.5175944
32.57050	129.8890	0.5094564
32.62216	129.8890	0.5015446
32.67383	129.8880	0.4937613
32.72717	129.8871	0.4856403
32.77883	129.8872	0.4779031
32.83050	129.8865	0.4700728
32.88383	129.8851	0.4619876
32.93550	129.8856	0.4541994
32.98717	129.8850	0.4464548
33.04050	129.8838	0.4386570
33.09216	129.8833	0.4310156
33.14383	129.8828	0.4234670
33.19717	129.8824	0.4156960
33.25050	129.8815	0.4078314
33.30050	129.8803	0.4004038
33.35383	129.8799	0.3923682
33.40716	129.8796	0.3842317
33.45716	129.8797	0.3765588
33.51050	129.8785	0.3684040
33.56383	129.8780	0.3602955
33.61550	129.8780	0.3523714
33.66716	129.8773	0.3445186
33.72050	129.8769	0.3363455
33.77217	129.8757	0.3284418
33.82383	129.8759	0.3204350
33.87717	129.8753	0.3121143
33.92883	129.8751	0.3041334
33.98050	129.8739	0.2961128
34.03383	129.8733	0.2878514
34.08550	129.8727	0.2798580
34.13716	129.8724	0.2718142
34.19050	129.8720	0.2636427
34.24383	129.8710	0.2554718
34.29383	129.8706	0.2476912
34.34716	129.8697	0.2394095
34.40050	129.8702	0.2310285
34.45050	129.8689	0.2232969
34.50383	129.8680	0.2150028
34.55716	129.8679	0.2066622
34.60883	129.8673	0.1985247
34.66050	129.8664	0.1903340
34.71383	129.8658	0.1817989
34.76550	129.8656	0.1736215
34.81716	129.8646	0.1654161
34.87050	129.8649	0.1569770
34.92216	129.8646	0.1488350
34.97383	129.8635	0.1407164
35.02716	129.8626	0.1323296
35.08050	129.8622	0.1238462
35.13050	129.8607	0.1158633
35.18384	129.8608	0.1072995
35.23717	129.8595	0.09867095
35.28717	129.8586	0.09054542
35.34050	129.8579	0.08183775
35.39383	129.8562	0.07295656
35.44550	129.8562	0.06417883
35.49716	129.8561	0.05525682
35.55050	129.8550	0.04605243
35.60217	129.8545	0.03701005
35.65383	129.8544	0.02769128
35.70716	129.8538	0.01819584
35.75883	129.8528	.008954516
35.81050	129.8526	-3.6829E-4
35.86383	129.8511	-.01001852
35.91550	129.8504	-.01946446
35.96716	129.8498	-.02909490
36.02050	129.8498	-.03896210
36.07383	129.8487	-.04892946
36.12383	129.8476	-.05839215
36.17717	129.8472	-.06883465
36.23050	129.8472	-.07935676
36.28050	129.8459	-.08894934
36.33383	129.8445	-.09962128
36.38716	129.8439	-0.1099659
36.43883	129.8427	-0.1200233
36.49050	129.8422	-0.1306496
36.54383	129.8415	-0.1429510
36.59550	129.8407	-0.1544121
36.64717	129.8395	-0.1662239
36.70050	129.8384	-0.1780809
36.75217	129.8368	-0.1907652
36.80383	129.8357	-0.2026778
36.85716	129.8350	-0.2156780
36.90883	129.8333	-0.2288418
36.96050	129.8332	-0.2449712
37.01383	129.8321	-0.2594226
37.06716	129.8306	-0.2761569
37.11716	129.8296	-0.2913162
37.17050	129.8285	-0.3084656
37.22383	129.8282	-0.3220660
37.27383	129.8273	-0.3360648
37.32717	129.8257	-0.3561722
37.38050	129.8246	-0.3766866
37.43216	129.8233	-0.3947519
37.48383	129.8226	-0.4151856
37.53717	129.8213	-0.4345261
37.58883	129.8201	-0.4549268
37.64050	129.8187	-0.4742562
37.69383	129.8179	-0.4970574
37.74550	129.8165	-0.5176948
37.79716	129.8164	-0.5388451
37.85050	129.8138	-0.5577139
37.90216	129.8135	-0.5788516
37.95383	129.8121	-0.5990174
38.00716	129.8107	-0.6200106
38.06050	129.8087	-0.6407379
38.11050	129.8076	-0.6596750
38.16383	129.8062	-0.6809930
38.21716	129.8054	-0.7013884
38.26716	129.8028	-0.7203226
38.32050	129.8021	-0.7452600
38.37383	129.8009	-0.7669701
38.42550	129.7991	-0.7859932
38.47717	129.7972	-0.8068080
38.53050	129.7968	-0.8300125
38.58216	129.7953	-0.8505972
38.63383	129.7926	-0.8725206
38.68716	129.7919	-0.8962282
38.73883	129.7904	-0.9175980
38.79050	129.7896	-0.9386556
38.84384	129.7887	-0.9612812
38.89550	129.7872	-0.9816161
38.94717	129.7857	-1.000887
39.00050	129.7836	-1.018916
39.05383	129.7826	-1.036328
39.10383	129.7807	-1.054090
39.15716	129.7796	-1.073111
39.21050	129.7780	-1.093776
39.26050	129.7770	-1.113885
39.31383	129.7755	-1.133048
39.36716	129.7742	-1.150605
39.41883	129.7734	-1.169338
39.47050	129.7721	-1.185434
39.52383	129.7705	-1.202647
39.57550	129.7692	-1.217982
39.62717	129.7679	-1.234299
39.68050	129.7676	-1.251668
39.73216	129.7662	-1.267004
39.78383	129.7651	-1.282347
39.83716	129.7646	-1.298435
39.89050	129.7635	-1.312368
39.94050	129.7622	-1.325362
39.99383	129.7613	-1.338151
40.04716	129.7599	-1.348713
40.09716	129.7595	-1.359907
40.15050	129.7583	-1.371268
40.20383	129.7572	-1.382158
40.25550	129.7561	-1.393654
40.30716	129.7551	-1.404169
40.36050	129.7551	-1.414885
40.41217	129.7537	-1.424806
40.46383	129.7527	-1.435078
40.51716	129.7520	-1.445767
40.56883	129.7512	-1.456384
40.62050	129.7511	-1.466876
40.67383	129.7499	-1.477396
40.72550	129.7493	-1.487559
40.77716	129.7492	-1.497713
40.83050	129.7482	-1.508220
40.88383	129.7474	-1.518714
40.93384	129.7463	-1.528472
40.98717	129.7455	-1.538814
41.04050	129.7454	-1.549116
41.09050	129.7450	-1.558650
41.14383	129.7446	-1.568765
41.19717	129.7430	-1.578678
41.24883	129.7428	-1.588164
41.30050	129.7429	-1.597498
41.35383	129.7419	-1.606987
41.40550	129.7416	-1.616161
41.45717	129.7406	-1.625163
41.51050	129.7398	-1.634361
41.56216	129.7402	-1.643185
41.61383	129.7396	-1.651839
41.66716	129.7398	-1.660687
41.71884	129.7400	-1.669139
41.77050	129.7390	-1.677321
41.82383	129.7386	-1.685755
41.87717	129.7384	-1.694015
41.92717	129.7373	-1.701552
41.98050	129.7374	-1.709522
42.03383	129.7363	-1.717154
42.08383	129.7362	-1.724230
42.13716	129.7356	-1.731554
42.19050	129.7354	-1.738811
42.24216	129.7350	-1.745634
42.29383	129.7351	-1.752407
42.34716	129.7339	-1.759300
42.39883	129.7346	-1.765875
42.45050	129.7336	-1.772349
42.50383	129.7338	-1.778885
42.55550	129.7336	-1.785042
42.60717	129.7339	-1.790936
42.66050	129.7336	-1.796885
42.71216	129.7324	-1.802576
42.76383	129.7334	-1.808199
42.81717	129.7324	-1.813818
42.87050	129.7312	-1.819334
42.92050	129.7320	-1.824322
42.97383	129.7320	-1.829481
43.02217	129.7334	-1.834883
43.07383	129.8230	-3.640193
43.12717	130.2035	-7.265359
43.17883	130.7494	-10.11350
43.23050	131.4256	-12.40886
43.28383	132.2173	-14.16407
43.33550	133.0514	-15.42673
43.38716	133.9327	-16.37109
43.44050	134.8784	-17.09043
43.49216	135.8217	-17.61783
43.54383	136.7830	-18.00734
43.59716	137.7902	-18.32218
43.65050	138.8087	-18.57199
43.70050	139.7689	-18.76568
43.75383	140.7992	-18.92509
43.80717	141.8354	-19.05376
43.85717	142.8109	-19.18074
43.91050	143.8537	-19.28898
43.96383	144.9004	-19.39752
44.01550	145.9148	-19.48672
44.06717	146.9327	-19.58143
44.12050	147.9850	-19.65787
44.17216	149.0042	-19.74244
44.22383	150.0258	-19.82544
44.27716	151.0792	-19.91451
44.32883	152.1016	-20.01377
44.38050	153.1244	-20.10071
44.43383	154.1797	-20.19200
44.48550	155.2040	-20.28400
44.53717	156.2280	-20.37885
44.59050	157.2859	-20.48444
44.64383	158.3428	-20.60725
44.69383	159.3339	-20.71444
44.74716	160.3912	-20.82278
44.80050	161.4478	-20.96509
44.85050	162.4396	-21.11121
44.90383	163.4975	-21.15900
44.95717	164.5574	-21.28494
45.00883	165.5822	-21.40698
45.06050	166.6077	-21.52882
45.11383	167.6594	-22.08074
45.16550	168.6844	-21.86168
45.21717	169.7108	-21.97435
45.27050	170.7702	-22.09027
45.32217	171.7966	-22.22516
45.37383	172.8220	-22.36151
45.42717	173.8810	-22.50275
45.48050	174.9341	-22.95620
45.53050	175.9259	-22.89075
45.58383	176.9848	-23.01330
45.63716	178.0421	-23.17154
45.68716	179.0333	-23.33345
45.74050	180.0904	-23.52292
45.79383	181.1454	-23.74754
45.84550	182.1641	-24.08945
45.89717	183.1835	-24.29211
45.95050	184.2341	-24.57800
46.00217	185.2522	-24.89910
46.05383	186.2696	-25.14592
46.10717	187.3194	-25.44888
46.15883	188.3356	-25.80238
46.21050	189.3490	-26.12816
46.26383	190.3952	-26.49462
46.31550	191.4084	-26.87189
46.36716	192.4198	-27.30022
46.42050	193.4594	-27.81889
46.47383	194.4992	-28.28924
46.52383	195.4724	-28.77424
46.57717	196.5084	-29.33785
46.63050	197.5410	-30.02970
46.68050	198.5036	-30.68766
46.73383	199.5311	-31.42444
46.78717	200.5537	-32.22338
46.83883	201.5411	-33.09903
46.89050	202.5222	-34.12746
46.94383	203.5270	-35.34059
46.99550	204.4916	-36.69515
47.04716	205.4452	-38.26741
47.10050	206.4168	-40.14370
47.15216	207.3431	-42.23276
47.20383	208.2561	-44.59596
47.25717	209.1789	-47.34360
47.30883	210.0556	-50.32541
47.36050	210.9161	-53.57801
47.41383	211.7879	-57.15928
47.46717	212.6468	-60.79190
47.51717	213.4540	-63.76274
47.57050	214.3433	-65.93882
47.62383	215.2727	-67.51949
47.67383	216.1762	-68.28326
47.72717	217.2200	-66.13080
47.78050	218.4120	-60.79506
47.83217	219.7178	-53.22808
47.88383	221.1499	-44.34321
47.93716	222.6635	-37.96998
47.98883	224.0442	-34.34546
48.04050	225.3354	-31.81230
48.09384	226.5962	-29.94168
48.14550	227.7661	-28.62751
48.19717	228.8992	-27.68225
48.25050	230.0405	-26.98150
48.30217	231.1263	-26.49167
48.35383	232.1980	-26.14478
48.40717	233.2930	-25.89206
48.46050	234.3792	-25.71584
48.51050	235.3942	-25.61183
48.56383	236.4712	-25.50656
48.61716	237.5457	-25.47167
48.66716	238.5503	-25.44482
48.72050	239.6207	-25.43321
48.77383	240.6894	-25.42976
48.82550	241.7244	-25.42999
48.87717	242.7584	-25.43108
48.93050	243.8252	-25.43719
48.98217	244.8574	-25.44682
49.03383	245.8912	-25.46852
49.08716	246.9566	-25.49251
49.13883	247.9888	-25.52406
49.19050	249.0220	-25.55856
49.24383	250.0874	-25.60104
49.29550	251.1197	-25.64466
49.34716	252.1523	-25.68539
49.40050	253.2180	-25.73211
49.45383	254.2816	-25.77276
49.50383	255.2797	-25.82400
49.55717	256.3440	-25.89450
49.61050	257.4080	-25.95004
49.66050	258.4070	-26.00715
49.71383	259.4716	-26.06129
49.76717	260.5373	-26.11114
49.81883	261.5672	-26.16464
49.87050	262.5984	-26.22854
49.92383	263.6632	-26.27621
49.97550	264.6934	-26.34050
50.02716	265.7240	-26.39158
50.08050	266.7890	-26.45060
50.13217	267.8190	-26.49883
50.18383	268.8495	-26.55781
50.23717	269.9144	-26.60394
50.29050	270.9790	-26.65058
50.34050	271.9766	-26.69965
50.39383	273.0418	-26.75418
50.44717	274.1066	-26.78970
50.49716	275.1050	-26.79801
50.54716	276.0606	-27.54505
50.59716	276.5415	-24.93163
50.65050	276.5691	-16.84230
50.70383	276.3006	-9.313594
50.75550	275.8415	-3.438447
50.80717	275.2425	1.073384
50.86050	274.5183	4.550229
50.91217	273.7407	7.051868
50.96383	272.9077	8.910114
51.01717	272.0066	10.32467
51.06883	271.1003	11.34708
51.12050	270.1715	12.11118
51.17383	269.1937	12.71296
51.22550	268.2318	13.14682
51.27717	267.2595	13.48316
51.33050	266.2465	13.75758
51.38383	265.2266	13.96996
51.43383	264.2648	14.12666
51.48717	263.2350	14.26852
51.54050	262.1992	14.37849
51.59050	261.2276	14.46408
51.64384	260.1860	14.54008
51.69717	259.1424	14.60713
51.74883	258.1306	14.66205
51.80050	257.1170	14.70922
51.85383	256.0679	14.75407
51.90550	255.0517	14.79149
51.95717	254.0344	14.83122
52.01050	252.9829	14.86428
52.06216	251.9622	14.90173
52.11383	250.9426	14.92788
52.16716	249.8883	14.95920
52.21884	248.8669	14.98315
52.27050	247.8459	15.00971
52.32383	246.7906	15.03371
52.37717	245.7353	15.05598
52.42717	244.7458	15.07617
52.48050	243.6898	15.09598
52.53383	242.6340	15.11623
52.58383	241.6427	15.13022
52.63716	240.5856	15.14651
52.69050	239.5275	15.16432
52.74216	238.5022	15.17815
52.79382	237.4772	15.18854
52.84716	236.4192	15.20377
52.89883	235.3922	15.21424
52.95050	234.3674	15.22221
53.00383	233.3074	15.23089
53.05550	232.2833	15.23911
53.10717	231.2580	15.25090
53.16050	230.1992	15.26706
53.21216	229.1734	15.28132
53.26382	228.1485	15.29936
53.31716	227.0880	15.32686
53.37050	226.0290	15.34125
53.42050	225.0365	15.35636
53.47382	223.9755	15.37210
53.52717	222.9166	15.38149
53.57717	221.9224	15.39388
53.63050	220.8624	15.40406
53.68383	219.8032	15.41780
53.73550	218.7771	15.43450
53.78716	217.7496	15.44540
53.84050	216.6898	15.45752
53.89216	215.6627	15.46742
53.94384	214.6357	15.47896
53.99717	213.5766	15.48930
54.04883	212.5494	15.50129
54.10050	211.5223	15.51292
54.15383	210.4628	15.52432
54.20550	209.4348	15.53584
54.25717	208.4075	15.54525
54.31050	207.3470	15.55504
54.36382	206.2859	15.56546
54.41382	205.2915	15.57423
54.46717	204.2324	15.58366
54.52050	203.1705	15.59550
54.57050	202.1780	15.60402
54.62383	201.1175	15.61540
54.67717	200.0578	15.62690
54.72883	199.0296	15.63806
54.78050	198.0026	15.64858
54.83383	196.9422	15.65827
54.88550	195.9147	15.66906
54.93716	194.8879	15.67928
54.99050	193.8275	15.69094
55.04217	192.8012	15.70159
55.09384	191.7746	15.71512
55.14717	190.7140	15.72679
55.20050	189.6540	15.74162
55.25050	188.6590	15.75159
55.30383	187.5981	15.76244
55.35717	186.5380	15.77372
55.40717	185.5428	15.78394
55.46050	184.4820	15.79426
55.51382	183.4218	15.80474
55.56550	182.3951	15.81740
55.61716	181.3661	15.82851
55.67050	180.3058	15.83856
55.72217	179.2791	15.85017
55.77383	178.2515	15.86372
55.82717	177.1915	15.87878
55.87883	176.1644	15.89410
55.93050	175.1364	15.91037
55.98383	174.0753	15.92450
56.03550	173.0474	15.93820
56.08716	172.0196	15.94807
56.14050	170.9586	15.95833
56.19384	169.8983	15.97111
56.24382	168.9039	15.99579
56.29717	167.8442	16.05422
56.35050	166.7869	16.24292
56.40050	165.7998	16.56031
56.45383	164.7582	17.11984
56.50717	163.7358	18.14829
56.55883	162.7758	19.83519
56.61050	161.8565	22.30056
56.66382	160.9566	25.62166
56.71550	160.1270	29.28558
56.76716	159.3217	32.93592
56.82050	158.4918	36.23526
56.87217	157.6619	38.65265
56.92383	156.7933	40.20025
56.97717	155.8409	40.85205
57.02883	154.8651	40.65768
57.08050	153.8375	39.78216
57.13383	152.7320	38.34993
57.18716	151.5894	36.60856
57.23717	150.4988	34.81802
57.29050	149.3204	32.86028
57.34384	148.1370	30.98572
57.39384	147.0302	29.31371
57.44717	145.8539	27.70030
57.50050	144.6847	26.23500
57.55217	143.5630	24.98867
57.60383	142.4498	23.88439
57.65717	141.3098	22.89098
57.70883	140.2159	22.06562
57.76050	139.1288	21.34548
57.81382	138.0131	20.68245
57.86550	136.9448	20.21695
57.91716	135.8800	19.77476
57.97050	134.7858	19.39347
58.02217	133.7317	19.09297
58.07383	132.6820	18.84323
58.12717	131.6009	18.62276
58.18050	130.5228	18.44612
58.23050	129.5169	18.31118
58.28383	128.4429	18.20022
58.33716	127.3726	18.09603
58.38716	126.3710	18.02755
58.44050	125.3027	17.95244
58.49382	124.2355	17.89618
58.54550	123.2017	17.81279
58.59716	122.1684	17.72125
58.65050	121.1000	17.66474
58.70216	120.0680	17.60267
58.75383	119.0344	17.56474
58.80717	117.9698	17.51125
58.85883	116.9372	17.48294
58.91050	115.9060	17.45466
58.96382	114.8418	17.42670
59.01550	113.8107	17.39988
59.06716	112.7793	17.37299
59.12050	111.7154	17.35074
59.17383	110.6512	17.31894
59.22382	109.6516	17.28276
59.27717	108.5876	17.24452
59.33050	107.5240	17.21464
59.38050	106.5255	17.17998
59.43383	105.4619	17.14806
59.48717	104.3979	17.11796
59.53882	103.3654	17.02741
59.59050	102.3321	16.96979
59.64384	101.2690	16.95720
59.69550	100.2398	16.95377
59.74717	99.20929	16.95002
59.80050	98.14778	16.94816
59.85217	97.11969	16.95461
59.90383	96.08660	16.75402
59.95717	95.01618	16.63482
60.01050	93.94686	16.56235
60.06050	92.94582	16.51540
60.11382	91.88012	16.45976
60.16716	90.81219	16.38724
60.21717	89.80826	16.16225
60.27050	88.73636	16.07313
60.32383	87.66842	16.02226
60.37550	86.63380	15.95364
60.42717	85.59992	15.88822
60.48050	84.53264	15.82430
60.53217	83.49901	15.77353
60.58383	82.46590	15.71311
60.63716	81.39972	15.65850
60.68882	80.36657	15.60552
60.74050	79.33231	15.55024
60.79382	78.26588	15.48348
60.84550	77.23257	15.42733
60.89717	76.19876	15.37599
60.95050	75.13345	15.32267
61.00383	74.06770	15.27734
61.05383	73.06750	15.22751
61.10717	72.00124	15.17402
61.16050	70.93507	15.11976
61.21050	69.93481	15.06784
61.26382	68.86852	15.00429
61.31716	67.80295	14.95292
61.36882	66.77082	14.89646
61.42050	65.73825	14.85918
61.47382	64.67160	14.80584
61.52550	63.63822	14.74368
61.57717	62.60564	14.68946
61.63050	61.53879	14.62754
61.68217	60.50490	14.57269
61.73383	59.47260	14.52049
61.78716	58.40666	14.46425
61.83882	57.37387	14.41184
61.89050	56.34129	14.35743
61.94384	55.27478	14.30843
61.99717	54.20805	14.24930
62.04717	53.20887	14.19582
62.10050	52.14160	14.13722
62.15383	51.07382	14.08694
62.20383	50.07585	14.02955
62.25717	49.00815	13.97885
62.31050	47.94104	13.91754
62.36217	46.90792	13.87108
62.41382	45.87408	13.81314
62.46717	44.80734	13.75642
62.51884	43.77375	13.70261
62.57050	42.73953	13.64445
62.62383	41.67224	13.58793
62.67550	40.63858	13.52396
62.72717	39.60517	13.46179
62.78050	38.53641	13.38904
62.83217	37.50211	13.32619
62.88383	36.46676	13.25266
62.93716	35.39983	13.17900
62.99050	34.33206	13.11148
63.04050	33.33089	13.03752
63.09384	32.26279	12.96164
63.14717	31.19507	12.88696
63.19717	30.19300	12.82525
63.25050	29.12420	12.74365
63.30383	28.05580	12.66281
63.35550	27.02075	12.58166
63.40717	25.98453	12.50845
63.46050	24.91527	12.45326
63.51050	23.91306	12.45905
63.56216	22.97374	12.93059
63.61382	22.56325	7.813490
63.66716	22.55484	2.446358
63.71884	22.84123	-1.567302
63.77050	23.32788	-4.375451
63.82383	23.98210	-6.461640
63.87550	24.72063	-7.889918
63.92717	25.53112	-8.941946
63.98050	26.42332	-9.725580
64.03384	27.35516	-10.32810
64.08384	28.25400	-10.75123
64.13717	29.23297	-11.10200
64.19050	30.22758	-11.37720
64.24050	31.17158	-11.58411
64.29384	32.18522	-11.76114
64.34717	33.20834	-11.93163
64.39883	34.20163	-12.04992
64.45050	35.20075	-12.16105
64.50384	36.23639	-12.27064
64.55550	37.24114	-12.36489
64.60718	38.24910	-12.44958
64.66050	39.29274	-12.52500
64.71217	40.30398	-12.60448
64.76384	41.31809	-12.67991
64.81717	42.36506	-12.74084
64.87050	43.41504	-12.81332
64.92050	44.39900	-12.87459
64.97384	45.45008	-12.94404
65.02717	46.50221	-13.01030
65.07718	47.49019	-13.08141
65.13050	48.54374	-13.14812
65.18384	49.59778	-13.22120
65.23550	50.61952	-13.28982
65.28717	51.64120	-13.36246
65.34050	52.69550	-13.43688
65.39216	53.71922	-13.51041
65.44384	54.74247	-13.57826
65.49717	55.79934	-13.65070
65.54884	56.82455	-13.72734
65.60050	57.85068	-13.79719
65.65384	58.90950	-13.86928
65.70550	59.93521	-13.94143
65.75718	60.96128	-14.01278
65.81050	62.02070	-14.09293
65.86384	63.08115	-14.17199
65.91382	64.07500	-14.23655
65.96718	65.13649	-14.30716
66.02050	66.19599	-14.38074
66.07050	67.18945	-14.45676
66.12384	68.25014	-14.53755
66.17718	69.31000	-14.61366
66.22884	70.33798	-14.68956
66.28050	71.36732	-14.76133
66.33384	72.42810	-14.83730
66.38550	73.45688	-14.91800
66.43718	74.48438	-14.98790
66.49050	75.54584	-15.06593
66.54218	76.57470	-15.14560
66.59384	77.60338	-15.22404
66.64718	78.66412	-15.31734
66.69884	79.69232	-15.39162
66.75050	80.72034	-15.48668
66.80384	81.78122	-15.56556
66.85718	82.84325	-15.66679
66.90718	83.83929	-15.73701
66.96050	84.90186	-15.82624
67.01384	85.96349	-15.91842
67.06384	86.95796	-16.00403
67.11718	88.01965	-16.09738
67.17050	89.08094	-16.19235
67.22218	90.10780	-16.29081
67.27384	91.13649	-16.37955
67.32718	92.19572	-16.47444
67.37884	93.22528	-16.56776
67.43050	94.25319	-16.65735
67.48384	95.31459	-16.75122
67.53550	96.34329	-16.83684
67.58716	97.37020	-16.93130
67.64050	98.43181	-17.02396
67.69218	99.46085	-17.11874
67.74384	100.4892	-17.20326
67.79718	101.5507	-17.30593
67.85050	102.6126	-17.39645
67.90050	103.6077	-17.48851
67.95384	104.6691	-17.58973
68.00718	105.7318	-17.68264
68.05718	106.7263	-17.77564
68.11050	107.7886	-17.87845
68.16382	108.8507	-17.97273
68.21550	109.8787	-18.08141
68.26716	110.9080	-18.18165
68.32050	111.9687	-18.27936
68.37218	112.9977	-18.38172
68.42384	114.0264	-18.48319
68.47718	115.0876	-18.58575
68.52884	116.1164	-18.68769
68.58050	117.1447	-18.78994
68.63384	118.2060	-18.90381
68.68550	119.2338	-19.01670
68.73718	120.2614	-19.12788
68.79050	121.3222	-19.25973
68.84384	122.3834	-19.37097
68.89384	123.3780	-19.49165
68.94718	124.4389	-19.60745
69.00050	125.4991	-19.73886
69.05050	126.4944	-19.85631
69.10384	127.5534	-19.97002
69.15718	128.6135	-20.11556
69.20884	129.6405	-20.24108
69.26050	130.6678	-20.37709
69.31384	131.7277	-20.51810
69.36550	132.7535	-20.64480
69.41718	133.7794	-20.78668
69.47050	134.8395	-20.93001
69.52218	135.8646	-21.06618
69.57384	136.8900	-21.20131
69.62718	137.9520	-21.28649
69.68050	139.0135	-21.38860
69.73050	140.0088	-21.49826
69.78384	141.0704	-21.60581
69.83716	142.1318	-21.71276
69.88718	143.1278	-21.89475
69.94050	144.1880	-21.93982
69.99384	145.2494	-22.05283
70.04550	146.2765	-22.17383
70.09718	147.3053	-22.29627
70.15050	148.3649	-22.42488
70.20216	149.3937	-22.54500
70.25384	150.4209	-22.65053
70.30718	151.4824	-22.77612
70.35884	152.5097	-22.88588
70.41050	153.5378	-22.99985
70.46384	154.5998	-23.11216
70.51550	155.6279	-23.21606
70.56718	156.6582	-23.31984
70.62050	157.7201	-23.39917
70.67384	158.7849	-23.46854
70.72384	159.7816	-23.52081
70.77718	160.8468	-23.57525
70.83050	161.9128	-23.61142
70.88050	162.9126	-23.63140
70.93384	163.9783	-23.65794
70.98718	165.0448	-23.69297
71.03882	166.0764	-23.74166
71.09050	167.1080	-23.82501
71.14384	168.1710	-23.92509
71.19550	169.2017	-24.02453
71.24718	170.2300	-24.14399
71.30050	171.2922	-24.27876
71.35218	172.3199	-24.41024
71.40384	173.3468	-24.55730
71.45718	174.4066	-24.71606
71.50884	175.4313	-24.88682
71.56050	176.4562	-25.07813
71.61384	177.5124	-25.28695
71.66718	178.5674	-25.53696
71.71718	179.5558	-25.78008
71.77050	180.6070	-26.08262
71.82384	181.6559	-26.41096
71.87384	182.6383	-26.74816
71.92718	183.6852	-27.15523
71.98050	184.7294	-27.59041
72.03218	185.7382	-28.06240
72.08384	186.7455	-28.56847
72.13718	187.7820	-29.14398
72.18884	188.7841	-29.71661
72.24050	189.7824	-30.35737
72.29384	190.8130	-31.03046
72.34550	191.8080	-31.68965
72.39718	192.8022	-32.39000
72.45050	193.8266	-33.13460
72.50218	194.8177	-33.92239
72.55384	195.8054	-34.77331
72.60718	196.8210	-35.72992
72.66050	197.8313	-36.77148
72.71050	198.7754	-37.80312
72.76384	199.7783	-38.92976
72.81718	200.7795	-40.07156
72.86718	201.7184	-41.07124
72.92050	202.7234	-41.96789
72.97384	203.7425	-42.49550
73.02550	204.7480	-42.43802
73.07718	205.7892	-41.44110
73.13050	206.9199	-39.12722
73.18218	208.0800	-35.76997
73.23384	209.2898	-32.22648
73.28718	210.5461	-29.47178
73.33884	211.7324	-27.85064
73.39050	212.8784	-26.81160
73.44384	214.0282	-26.07569
73.49550	215.1198	-25.58255
73.54718	216.1938	-25.25023
73.60050	217.2890	-25.01668
73.65384	218.3762	-24.86494
73.70384	219.3884	-24.78356
73.75718	220.4654	-24.73980
73.81050	221.5387	-24.71116
73.86050	222.5444	-24.70360
73.91382	223.6131	-24.70239
73.96718	224.6813	-24.70325
74.01882	225.7156	-24.70656
74.07050	226.7476	-24.72196
74.12384	227.8144	-24.74859
74.17550	228.8477	-24.79789
74.22718	229.8805	-24.84180
74.28050	230.9455	-24.88816
74.33218	231.9770	-24.95550
74.38384	233.0089	-25.02324
74.43718	234.0738	-25.08152
74.49050	235.1382	-25.13934
74.54050	236.1367	-25.19129
74.59384	237.2021	-25.23641
74.64718	238.2680	-25.28566
74.69718	239.2658	-25.33432
74.75050	240.3307	-25.39475
74.80384	241.3948	-25.46094
74.85550	242.4270	-25.52307
74.90718	243.4593	-25.58158
74.96050	244.5246	-25.64166
75.01218	245.5557	-25.69072
75.06384	246.5877	-25.74152
75.11718	247.6527	-25.79360
75.16884	248.6838	-25.84658
75.22050	249.7151	-25.90595
75.27384	250.7804	-25.95349
75.32550	251.8120	-26.01742
75.37718	252.8434	-26.07480
75.43050	253.9082	-26.12777
75.48384	254.9733	-26.18167
75.53384	255.9710	-26.25000
75.58716	257.0348	-26.32448
75.64050	258.0989	-26.39515
75.69050	259.0961	-26.45852
75.74384	260.1595	-26.53635
75.79718	261.2228	-26.59980
75.84882	262.2536	-26.67178
75.90050	263.2860	-26.72654
75.95384	264.3500	-26.78745
76.00550	265.3809	-26.85073
76.05718	266.4129	-26.90894
76.11050	267.4762	-26.97153
76.16218	268.5061	-27.04802
76.21384	269.5378	-27.10842
76.26716	270.6015	-27.16256
76.31884	271.6326	-27.22044
-2.000000	5.000000	0.0000000