File: 5-C1(1.4mol%)+C20(0.6mol%)/matlab/130-2.txt
CLOSED
Version	1.0
Language	English
Mode	Standard
Run	16
RunSerial	12318
Instrument	DSC Q2000 V24.11 Build 124
Module	DSC Standard Cell RC
Operator
File	\\AE520-1454\Users\dsc\Desktop\Data\31-08-17-2\130-2.001
ProcName
InstSerial	2000-0883
AutoSerial	1293
Sample	130-2
Size	29.4000	mg
PanMass	Not available
PanResist	Automatic Automatic  K/W
PanFactor	Default Default
Method
Comment
Xcomment	Pan: Tzero Aluminum Hermetic
Xcomment	Gas1: Nitrogen 50.0 ml/min
Xcomment	Gas2: Nitrogen 50.0 ml/min
Text
Exotherm	UP
Kcell	1.05230
Cpconst	Standard: 0.938
Calib	-38.6961
TempCal	1	pts	157.46	156.60
TzeroDt	-87.6168 -0.0009 -1.4231
TzeroDtz	-87.6168 0.0057 6.9570
InstCalFile	Tzero: \\Ae520-1454\ta\Data\DSC\Calibration\2017\CALIBRATION\1562_RCS (90)_05_18_2017 10_50_44.TZR
InstCalFile	Baseline: \\Ae520-1454\ta\Data\DSC\Calibration\2017\2017-05-17_Calibration.001
InstCalFile	Sapphire: \\Ae520-1454\ta\Data\DSC\Calibration\2017\2017-05-17_Saphire.001
InstCalDate	Tzero 2017-05-18 Time 10:50:44
TempRange	-87.39 to 398.39 °C at 10.00 °C/min Heat Only
AutoZero	Delta T Offset 0.000 uV
AutoZero	Delta T0 Offset 0.000 uV
MultiptCal	0
MultiPtDesc	0) Not set
AutoCellConst	Calibration Date 2017-05-18 16:59:28
Controls	Gas 1  Event Off  Sampling 0.2
Cell#	RC-01562
CoolingUnit	RCS (90)
SelHeatFlow	Heat Flow T4P (mW)
AutoLidII	Installed
AutoAnalysis	Off
MacroFile
Nsig	3
Sig1	Time (min)
Sig2	Temperature (°C)
Sig3	Heat Flow (mW)
Date	2017-09-01
Time	06:09:59
OrgMethod	1: Equilibrate at 80.00 °C
OrgMethod	2: Isothermal for 3.00 min
OrgMethod	3: Jump to 130.00 °C
OrgMethod	4: Mark end of cycle 1
OrgMethod	5: Isothermal for 40.00 min
OrgMethod	6: Mark end of cycle 2
OrgMethod	7: Ramp 20.00 °C/min to 280.00 °C
OrgMethod	8: Mark end of cycle 3
OrgMethod	9: Ramp 20.00 °C/min to 20.00 °C
OrgMethod	10: Mark end of cycle 4
OrgMethod	11: Ramp 20.00 °C/min to 280.00 °C
OrgMethod	12: Mark end of cycle 5
OrgFile	C:\Users\jarra\Desktop\DSC\5-C1(1.4mol%)+C20(0.6mol%)\130-2.001
StartOfData
4.99994E-4	79.47320	-6.455505
0.05383332	79.56863	-5.215502
0.1071666	79.64179	-4.253544
0.1588333	79.69590	-3.527043
0.2105000	79.73784	-2.959740
0.2638334	79.77235	-2.509455
0.3155000	79.79687	-2.168708
0.3671667	79.81606	-1.905098
0.4205000	79.83080	-1.695864
0.4721666	79.84187	-1.539910
0.5238333	79.85029	-1.424321
0.5771668	79.85595	-1.333686
0.6305000	79.86145	-1.265341
0.6805000	79.86365	-1.218886
0.7338332	79.86595	-1.182354
0.7871668	79.86740	-1.158322
0.8371668	79.86872	-1.143299
0.8904999	79.86845	-1.133240
0.9438332	79.86780	-1.127196
0.9955000	79.86901	-1.123448
1.047167	79.86812	-1.120237
1.100500	79.86761	-1.116941
1.152167	79.86670	-1.113912
1.203834	79.86691	-1.111112
1.257166	79.86644	-1.108416
1.308833	79.86532	-1.106042
1.360500	79.86462	-1.103882
1.413834	79.86458	-1.102046
1.465500	79.86275	-1.100390
1.517167	79.86187	-1.099094
1.570500	79.86116	-1.097961
1.623833	79.86118	-1.097111
1.673834	79.85992	-1.096565
1.727167	79.85850	-1.096215
1.780500	79.85772	-1.096141
1.830500	79.85738	-1.096266
1.883833	79.85672	-1.096655
1.937166	79.85432	-1.097178
1.988833	79.85570	-1.097859
2.040500	79.85585	-1.098698
2.093834	79.85336	-1.099634
2.145500	79.85306	-1.100834
2.197166	79.85332	-1.102117
2.250500	79.85220	-1.103590
2.302166	79.85250	-1.105162
2.353833	79.85038	-1.106722
2.407167	79.85005	-1.108517
2.458833	79.84976	-1.110418
2.510500	79.84930	-1.112339
2.563833	79.84850	-1.114424
2.617167	79.84747	-1.116565
2.667167	79.84759	-1.118651
2.720500	79.84644	-1.121045
2.773833	79.84722	-1.123442
2.823833	79.84605	-1.125774
2.877167	79.84568	-1.128187
2.930500	79.84438	-1.130647
2.982167	79.84426	-1.133090
3.030500	79.91114	-2.454526
3.082167	81.20698	-16.74926
3.133833	83.54266	-30.13802
3.187167	86.50099	-43.32944
3.238834	89.78576	-54.99840
3.290500	93.38269	-65.24817
3.343834	97.35110	-74.29430
3.397167	101.5111	-81.90500
3.447167	105.5406	-87.89751
3.500500	109.9413	-93.23090
3.553833	114.2883	-95.65512
3.603833	117.3624	-87.55614
3.657167	119.6808	-76.90955
3.710500	121.4838	-66.02705
3.762167	122.8565	-56.11213
3.813833	123.9624	-47.26410
3.867166	124.8871	-39.41666
3.918833	125.6174	-33.04724
3.970500	126.2182	-27.78175
4.023834	126.7290	-23.34476
4.075500	127.1394	-19.87048
4.127167	127.4822	-17.04012
4.180500	127.7796	-14.68320
4.232167	128.0226	-12.82614
4.283834	128.2279	-11.31453
4.337167	128.4080	-10.03380
4.390500	128.5625	-8.991720
4.440500	128.6866	-8.177728
4.493834	128.8016	-7.458449
4.547167	128.8995	-6.857258
4.597166	128.9796	-6.379365
4.650500	129.0546	-5.950644
4.703833	129.1201	-5.581720
4.755500	129.1752	-5.276255
4.807167	129.2249	-5.012910
4.860500	129.2688	-4.772139
4.912167	129.3076	-4.575617
4.963834	129.3410	-4.396942
5.017166	129.3732	-4.236874
5.068833	129.4002	-4.103375
5.120500	129.4241	-3.979191
5.173834	129.4469	-3.865623
5.225500	129.4668	-3.770249
5.277168	129.4847	-3.681814
5.330500	129.5005	-3.599894
5.383832	129.5155	-3.526814
5.433832	129.5283	-3.465698
5.487168	129.5390	-3.406544
5.540500	129.5505	-3.356758
5.590500	129.5593	-3.313844
5.643832	129.5681	-3.272596
5.697168	129.5771	-3.236020
5.748834	129.5840	-3.205417
5.800500	129.5910	-3.176565
5.853832	129.5970	-3.151580
5.905500	129.6017	-3.129130
5.957168	129.6070	-3.108142
6.010500	129.6116	-3.089838
6.062168	129.6157	-3.071801
6.113834	129.6194	-3.057478
6.167168	129.6230	-3.042282
6.220500	129.6261	-3.030068
6.270500	129.6290	-3.021482
6.323834	129.6311	-3.012204
6.377168	129.6345	-3.003318
6.427168	129.6374	-2.994108
6.480500	129.6385	-2.983369
6.533832	129.6414	-2.972575
6.585500	129.6433	-2.962970
6.637168	129.6440	-2.954646
6.690500	129.6470	-2.946669
6.742166	129.6487	-2.938814
6.793832	129.6498	-2.930815
6.847168	129.6516	-2.922300
6.898834	129.6532	-2.914104
6.950500	129.6546	-2.905959
7.003832	129.6562	-2.897522
7.055500	129.6572	-2.889320
7.107168	129.6588	-2.881004
7.160500	129.6598	-2.872276
7.213834	129.6613	-2.863150
7.263834	129.6624	-2.854581
7.317168	129.6642	-2.845060
7.370500	129.6662	-2.835720
7.420500	129.6672	-2.826526
7.473834	129.6686	-2.816731
7.527168	129.6699	-2.807089
7.578834	129.6708	-2.797476
7.630500	129.6714	-2.787813
7.683832	129.6732	-2.777872
7.735500	129.6734	-2.768138
7.787168	129.6740	-2.758480
7.840500	129.6754	-2.748535
7.892168	129.6757	-2.738970
7.943832	129.6766	-2.729453
7.997168	129.6770	-2.719752
8.048834	129.6780	-2.710492
8.100500	129.6790	-2.701341
8.153832	129.6800	-2.692037
8.207168	129.6806	-2.682770
8.257168	129.6814	-2.674290
8.310500	129.6814	-2.665335
8.363834	129.6818	-2.656614
8.413834	129.6826	-2.648614
8.467168	129.6832	-2.640258
8.520500	129.6840	-2.632138
8.572168	129.6843	-2.624503
8.623834	129.6837	-2.617027
8.677168	129.6850	-2.609492
8.728834	129.6859	-2.602438
8.780500	129.6858	-2.595443
8.833832	129.6860	-2.588498
8.885499	129.6871	-2.581900
8.937166	129.6870	-2.575426
8.990500	129.6877	-2.568922
9.042168	129.6874	-2.562724
9.093832	129.6876	-2.556698
9.147168	129.6888	-2.550604
9.200500	129.6891	-2.544566
9.250500	129.6890	-2.539108
9.303832	129.6899	-2.533324
9.357166	129.6899	-2.527612
9.407166	129.6900	-2.522338
9.460499	129.6909	-2.516773
9.513832	129.6910	-2.511246
9.565500	129.6919	-2.505863
9.617166	129.6925	-2.500498
9.670500	129.6921	-2.494877
9.722168	129.6938	-2.489485
9.773834	129.6943	-2.484050
9.827168	129.6942	-2.478378
9.878834	129.6952	-2.472888
9.930500	129.6959	-2.467373
9.983832	129.6965	-2.461582
10.03550	129.6972	-2.455929
10.08717	129.6979	-2.450249
10.14050	129.6980	-2.444319
10.19383	129.6993	-2.438408
10.24383	129.6986	-2.432812
10.29717	129.6998	-2.426734
10.35050	129.6999	-2.420586
10.40050	129.7002	-2.414794
10.45383	129.7009	-2.408566
10.50717	129.7016	-2.402315
10.55884	129.7018	-2.396262
10.61050	129.7022	-2.390152
10.66383	129.7029	-2.383938
10.71550	129.7031	-2.377842
10.76717	129.7039	-2.371854
10.82050	129.7036	-2.365698
10.87217	129.7049	-2.359813
10.92383	129.7052	-2.353931
10.97717	129.7055	-2.347878
11.03050	129.7050	-2.341698
11.08050	129.7053	-2.336096
11.13383	129.7062	-2.330211
11.18716	129.7063	-2.324314
11.23717	129.7072	-2.318882
11.29050	129.7073	-2.313041
11.34383	129.7085	-2.307146
11.39550	129.7090	-2.301324
11.44717	129.7088	-2.295463
11.50050	129.7092	-2.289332
11.55216	129.7101	-2.283346
11.60383	129.7100	-2.277265
11.65717	129.7112	-2.270933
11.70883	129.7104	-2.264769
11.76050	129.7115	-2.258553
11.81383	129.7126	-2.252108
11.86550	129.7134	-2.245741
11.91717	129.7135	-2.239334
11.97050	129.7146	-2.232670
12.02383	129.7156	-2.225956
12.07383	129.7160	-2.219498
12.12717	129.7169	-2.212544
12.18050	129.7169	-2.205494
12.23050	129.7172	-2.198762
12.28383	129.7188	-2.191544
12.33717	129.7190	-2.184054
12.38883	129.7200	-2.176780
12.44050	129.7210	-2.169372
12.49384	129.7209	-2.161566
12.54550	129.7212	-2.153904
12.59717	129.7222	-2.146145
12.65050	129.7233	-2.138052
12.70217	129.7239	-2.130036
12.75384	129.7251	-2.121938
12.80717	129.7256	-2.113265
12.85883	129.7266	-2.104810
12.91050	129.7272	-2.096016
12.96383	129.7279	-2.086646
13.01717	129.7294	-2.077323
13.06716	129.7301	-2.066954
13.12050	129.7313	-2.055471
13.17383	129.7313	-2.041680
13.22383	129.7334	-2.028200
13.27717	129.7336	-2.010510
13.33050	129.7350	-1.992892
13.38216	129.7366	-1.974973
13.43383	129.7371	-1.953915
13.48716	129.7385	-1.932849
13.53883	129.7404	-1.911776
13.59050	129.7413	-1.890713
13.64383	129.7426	-1.868152
13.69550	129.7448	-1.845275
13.74717	129.7466	-1.817442
13.80050	129.7486	-1.787358
13.85217	129.7498	-1.758667
13.90383	129.7522	-1.729465
13.95717	129.7526	-1.695737
14.01050	129.7554	-1.666306
14.06050	129.7565	-1.634401
14.11383	129.7583	-1.602836
14.16716	129.7600	-1.570829
14.21716	129.7623	-1.543794
14.27050	129.7636	-1.513812
14.32384	129.7651	-1.485251
14.37550	129.7678	-1.456582
14.42717	129.7700	-1.427474
14.48050	129.7708	-1.400519
14.53217	129.7728	-1.373032
14.58383	129.7739	-1.349396
14.63717	129.7760	-1.326332
14.68883	129.7777	-1.303827
14.74050	129.7790	-1.281696
14.79384	129.7815	-1.260288
14.84550	129.7832	-1.240308
14.89717	129.7838	-1.220433
14.95050	129.7861	-1.200656
15.00383	129.7870	-1.183022
15.05383	129.7876	-1.167551
15.10716	129.7892	-1.150138
15.16050	129.7901	-1.133675
15.21050	129.7910	-1.119955
15.26383	129.7925	-1.106537
15.31716	129.7941	-1.093779
15.36884	129.7946	-1.082405
15.42050	129.7950	-1.072073
15.47383	129.7961	-1.062259
15.52550	129.7978	-1.052781
15.57717	129.7990	-1.043850
15.63050	129.7999	-1.034680
15.68217	129.8010	-1.025161
15.73383	129.8021	-1.015265
15.78717	129.8016	-1.005820
15.84050	129.8018	-0.9955871
15.89050	129.8041	-0.9864344
15.94384	129.8046	-0.9766849
15.99717	129.8050	-0.9665328
16.04716	129.8056	-0.9572648
16.10050	129.8068	-0.9473375
16.15383	129.8068	-0.9373212
16.20550	129.8081	-0.9276170
16.25716	129.8080	-0.9179306
16.31050	129.8101	-0.9080162
16.36216	129.8101	-0.8983275
16.41383	129.8110	-0.8886590
16.46716	129.8114	-0.8787368
16.51883	129.8121	-0.8691216
16.57050	129.8130	-0.8595363
16.62383	129.8138	-0.8497028
16.67550	129.8148	-0.8401728
16.72716	129.8151	-0.8305910
16.78050	129.8160	-0.8207366
16.83383	129.8170	-0.8108730
16.88383	129.8175	-0.8016010
16.93716	129.8178	-0.7915679
16.99050	129.8190	-0.7815400
17.04050	129.8200	-0.7720764
17.09383	129.8204	-0.7617856
17.14716	129.8206	-0.7515892
17.19884	129.8215	-0.7417011
17.25050	129.8220	-0.7316387
17.30383	129.8224	-0.7212390
17.35550	129.8231	-0.7111895
17.40716	129.8242	-0.7011404
17.46050	129.8245	-0.6907446
17.51216	129.8250	-0.6806503
17.56383	129.8262	-0.6705676
17.61716	129.8267	-0.6599747
17.66883	129.8284	-0.6497776
17.72050	129.8288	-0.6389879
17.77383	129.8296	-0.6277948
17.82716	129.8286	-0.6166372
17.87716	129.8311	-0.6065496
17.93050	129.8320	-0.5956368
17.98383	129.8331	-0.5842440
18.03383	129.8330	-0.5734420
18.08716	129.8351	-0.5624178
18.14050	129.8357	-0.5506942
18.19216	129.8363	-0.5394971
18.24383	129.8370	-0.5283897
18.29716	129.8386	-0.5165116
18.34883	129.8388	-0.5049938
18.40050	129.8404	-0.4932050
18.45383	129.8413	-0.4811703
18.50550	129.8418	-0.4695344
18.55716	129.8430	-0.4571426
18.61050	129.8436	-0.4446060
18.66217	129.8436	-0.4303144
18.71383	129.8451	-0.4177930
18.76716	129.8458	-0.4053050
18.82050	129.8470	-0.3919084
18.87050	129.8470	-0.3792807
18.92383	129.8484	-0.3654606
18.97716	129.8493	-0.3533790
19.02716	129.8495	-0.3417366
19.08050	129.8507	-0.3292933
19.13383	129.8521	-0.3162712
19.18550	129.8525	-0.3027603
19.23716	129.8546	-0.2901434
19.29050	129.8544	-0.2764939
19.34216	129.8556	-0.2639804
19.39383	129.8567	-0.2512396
19.44716	129.8581	-0.2366208
19.49883	129.8591	-0.2232282
19.55050	129.8602	-0.2100662
19.60383	129.8610	-0.1954404
19.65550	129.8615	-0.1825042
19.70716	129.8623	-0.1680994
19.76050	129.8634	-0.1543483
19.81383	129.8642	-0.1367776
19.86383	129.8658	-0.1235171
19.91716	129.8657	-0.1081562
19.97050	129.8666	-.09375340
20.02050	129.8675	-.08065034
20.07383	129.8683	-.06701260
20.12716	129.8691	-.05204288
20.17883	129.8710	-.03967432
20.23050	129.8708	-.02566754
20.28383	129.8722	-.01245062
20.33550	129.8729	1.37111E-4
20.38716	129.8745	0.01198310
20.44050	129.8752	0.02403732
20.49216	129.8755	0.03763606
20.54383	129.8778	0.04981498
20.59716	129.8780	0.06263695
20.65050	129.8795	0.07512493
20.70050	129.8803	0.08857219
20.75383	129.8808	0.1015185
20.80716	129.8821	0.1145839
20.85716	129.8818	0.1271584
20.91050	129.8843	0.1393187
20.96383	129.8852	0.1540027
21.01550	129.8855	0.1668163
21.06716	129.8865	0.1789459
21.12050	129.8874	0.1914667
21.17216	129.8882	0.2033870
21.22383	129.8886	0.2150762
21.27717	129.8896	0.2278892
21.32883	129.8901	0.2400518
21.38050	129.8916	0.2520730
21.43383	129.8921	0.2646134
21.48550	129.8929	0.2763532
21.53717	129.8938	0.2877572
21.59050	129.8942	0.3002592
21.64383	129.8950	0.3121036
21.69383	129.8958	0.3232200
21.74716	129.8964	0.3350842
21.80050	129.8974	0.3467260
21.85050	129.8979	0.3576370
21.90383	129.8989	0.3691531
21.95717	129.8992	0.3806206
22.00883	129.9002	0.3915430
22.06050	129.9009	0.4024861
22.11383	129.9023	0.4137063
22.16550	129.9030	0.4245215
22.21716	129.9033	0.4353296
22.27050	129.9042	0.4464743
22.32216	129.9045	0.4571898
22.37383	129.9054	0.4677994
22.42717	129.9059	0.4786676
22.47883	129.9058	0.4893531
22.53050	129.9065	0.4998750
22.58383	129.9074	0.5105694
22.63716	129.9077	0.5212084
22.68716	129.9082	0.5309997
22.74050	129.9086	0.5413285
22.79383	129.9089	0.5515136
22.84383	129.9093	0.5609360
22.89716	129.9101	0.5709626
22.95050	129.9104	0.5808494
23.00217	129.9109	0.5903115
23.05383	129.9114	0.5995962
23.10716	129.9116	0.6089880
23.15883	129.9134	0.6179821
23.21050	129.9128	0.6268291
23.26383	129.9140	0.6357763
23.31550	129.9146	0.6442094
23.36716	129.9155	0.6524692
23.42050	129.9152	0.6609226
23.47216	129.9160	0.6688513
23.52383	129.9160	0.6767080
23.57716	129.9167	0.6846634
23.63050	129.9165	0.6924866
23.68050	129.9170	0.6996299
23.73383	129.9165	0.7071151
23.78717	129.9166	0.7143212
23.83716	129.9181	0.7208838
23.89050	129.9175	0.7277945
23.94383	129.9184	0.7343497
23.99550	129.9193	0.7404929
24.04716	129.9187	0.7465630
24.10050	129.9190	0.7526016
24.15216	129.9194	0.7583062
24.20383	129.9204	0.7639044
24.25716	129.9194	0.7695180
24.30883	129.9204	0.7746955
24.36050	129.9204	0.7797179
24.41383	129.9203	0.7846711
24.46550	129.9204	0.7892679
24.51716	129.9198	0.7936294
24.57050	129.9200	0.7978780
24.62383	129.9203	0.8018922
24.67383	129.9206	0.8054508
24.72716	129.9205	0.8090771
24.78050	129.9197	0.8125589
24.83050	129.9203	0.8157097
24.88383	129.9195	0.8188574
24.93716	129.9196	0.8217261
24.98883	129.9195	0.8243241
25.04050	129.9188	0.8266952
25.09383	129.9193	0.8289819
25.14550	129.9191	0.8309061
25.19716	129.9192	0.8326379
25.25050	129.9184	0.8341485
25.30217	129.9191	0.8353492
25.35383	129.9179	0.8363094
25.40716	129.9193	0.8369219
25.46050	129.9183	0.8373650
25.51050	129.9179	0.8376961
25.56383	129.9175	0.8379191
25.61716	129.9187	0.8378847
25.66716	129.9181	0.8377194
25.72050	129.9177	0.8373668
25.77383	129.9177	0.8367939
25.82550	129.9175	0.8360374
25.87716	129.9167	0.8350460
25.93050	129.9156	0.8338484
25.98216	129.9156	0.8325225
26.03383	129.9150	0.8309632
26.08716	129.9139	0.8291625
26.13883	129.9140	0.8272216
26.19050	129.9128	0.8250218
26.24383	129.9126	0.8224394
26.29550	129.9126	0.8196343
26.34716	129.9125	0.8165947
26.40050	129.9116	0.8132199
26.45383	129.9120	0.8096103
26.50383	129.9110	0.8060970
26.55716	129.9109	0.8020331
26.61050	129.9105	0.7978904
26.66050	129.9099	0.7937405
26.71383	129.9096	0.7891345
26.76716	129.9090	0.7844178
26.81883	129.9086	0.7797194
26.87050	129.9078	0.7749180
26.92383	129.9066	0.7698468
26.97550	129.9059	0.7646880
27.02717	129.9058	0.7593653
27.08050	129.9052	0.7536944
27.13216	129.9045	0.7480028
27.18383	129.9039	0.7421810
27.23716	129.9032	0.7360247
27.28883	129.9022	0.7299655
27.34050	129.9026	0.7236865
27.39383	129.9015	0.7171226
27.44717	129.9013	0.7103976
27.49716	129.9001	0.7039880
27.55050	129.9007	0.6970482
27.60383	129.9005	0.6900982
27.65383	129.8998	0.6835547
27.70716	129.8998	0.6763936
27.76050	129.8984	0.6692299
27.81217	129.8981	0.6622024
27.86383	129.8976	0.6551938
27.91716	129.8969	0.6479475
27.96883	129.8968	0.6409479
28.02050	129.8958	0.6339125
28.07383	129.8952	0.6264843
28.12550	129.8952	0.6192722
28.17717	129.8945	0.6119444
28.23050	129.8939	0.6043311
28.28216	129.8925	0.5969220
28.33383	129.8919	0.5893930
28.38716	129.8918	0.5816298
28.44050	129.8912	0.5737510
28.49050	129.8905	0.5663410
28.54383	129.8902	0.5583550
28.59716	129.8895	0.5504430
28.64716	129.8891	0.5429916
28.70050	129.8878	0.5350700
28.75383	129.8871	0.5272060
28.80550	129.8872	0.5195205
28.85716	129.8861	0.5119650
28.91050	129.8850	0.5040918
28.96216	129.8848	0.4964511
29.01383	129.8846	0.4888049
29.06716	129.8840	0.4808950
29.11883	129.8835	0.4731746
29.17050	129.8835	0.4654812
29.22383	129.8827	0.4575108
29.27550	129.8826	0.4497950
29.32717	129.8822	0.4421126
29.38050	129.8812	0.4342276
29.43383	129.8808	0.4263942
29.48383	129.8811	0.4190872
29.53717	129.8805	0.4114168
29.59050	129.8802	0.4036910
29.64050	129.8795	0.3966775
29.69383	129.8783	0.3891906
29.74716	129.8784	0.3817578
29.79883	129.8774	0.3745874
29.85050	129.8776	0.3674551
29.90383	129.8773	0.3601853
29.95550	129.8763	0.3531280
30.00716	129.8762	0.3460970
30.06050	129.8765	0.3388412
30.11216	129.8759	0.3319402
30.16383	129.8754	0.3251262
30.21716	129.8749	0.3181570
30.27050	129.8734	0.3113037
30.32050	129.8731	0.3048792
30.37383	129.8727	0.2982105
30.42717	129.8723	0.2915127
30.47717	129.8717	0.2852913
30.53050	129.8708	0.2786950
30.58383	129.8705	0.2720658
30.63550	129.8706	0.2656570
30.68717	129.8699	0.2592406
30.74050	129.8705	0.2526306
30.79216	129.8700	0.2462216
30.84383	129.8690	0.2398384
30.89716	129.8690	0.2332401
30.94883	129.8687	0.2269264
31.00050	129.8675	0.2206392
31.05383	129.8679	0.2142197
31.10550	129.8679	0.2079422
31.15716	129.8675	0.2017837
31.21050	129.8662	0.1955370
31.26383	129.8660	0.1892055
31.31383	129.8659	0.1833034
31.36716	129.8656	0.1770666
31.42050	129.8648	0.1708306
31.47050	129.8651	0.1650620
31.52383	129.8640	0.1588614
31.57717	129.8646	0.1527067
31.62883	129.8640	0.1469247
31.68050	129.8638	0.1411476
31.73383	129.8636	0.1351924
31.78550	129.8630	0.1295803
31.83716	129.8618	0.1239884
31.89050	129.8621	0.1183050
31.94216	129.8611	0.1128296
31.99383	129.8609	0.1073077
32.04716	129.8604	0.1017598
32.09883	129.8599	0.09637824
32.15050	129.8600	0.09093736
32.20383	129.8595	0.08540559
32.25716	129.8592	0.07980972
32.30716	129.8582	0.07461929
32.36050	129.8576	0.06891989
32.41383	129.8574	0.06327055
32.46383	129.8577	0.05788399
32.51716	129.8570	0.05227680
32.57050	129.8566	0.04650754
32.62216	129.8568	0.04096298
32.67383	129.8569	0.03542380
32.72717	129.8560	0.02976201
32.77883	129.8563	0.02425428
32.83050	129.8559	0.01884425
32.88383	129.8548	0.01326961
32.93550	129.8547	.007903110
32.98717	129.8548	.002571212
33.04050	129.8538	-2.9122E-3
33.09216	129.8533	-8.1339E-3
33.14383	129.8538	-.01332898
33.19717	129.8531	-.01866970
33.25050	129.8523	-.02397034
33.30050	129.8517	-.02895802
33.35383	129.8510	-.03429491
33.40716	129.8509	-.03967929
33.45716	129.8511	-.04476030
33.51050	129.8510	-.05026712
33.56383	129.8499	-.05574114
33.61550	129.8500	-.06112854
33.66716	129.8494	-.06656540
33.72050	129.8490	-.07214294
33.77217	129.8498	-.07755390
33.82383	129.8488	-.08289758
33.87717	129.8482	-.08844837
33.92883	129.8488	-.09392208
33.98050	129.8478	-.09932965
34.03383	129.8472	-0.1049014
34.08550	129.8470	-0.1102886
34.13716	129.8467	-0.1156615
34.19050	129.8467	-0.1211531
34.24383	129.8461	-0.1266256
34.29383	129.8462	-0.1318104
34.34716	129.8455	-0.1372619
34.40050	129.8453	-0.1428232
34.45050	129.8447	-0.1479916
34.50383	129.8435	-0.1534136
34.55716	129.8438	-0.1588463
34.60883	129.8424	-0.1640311
34.66050	129.8424	-0.1691834
34.71383	129.8414	-0.1746314
34.76550	129.8411	-0.1798920
34.81716	129.8413	-0.1852743
34.87050	129.8400	-0.1908622
34.92216	129.8400	-0.1962134
34.97383	129.8395	-0.2016708
35.02716	129.8387	-0.2072849
35.08050	129.8386	-0.2130420
35.13050	129.8388	-0.2184066
35.18384	129.8387	-0.2241917
35.23717	129.8380	-0.2299688
35.28717	129.8381	-0.2354092
35.34050	129.8374	-0.2412110
35.39383	129.8375	-0.2469869
35.44550	129.8363	-0.2526157
35.49716	129.8354	-0.2582164
35.55050	129.8362	-0.2640942
35.60217	129.8362	-0.2697230
35.65383	129.8353	-0.2753222
35.70716	129.8348	-0.2810580
35.75883	129.8345	-0.2866412
35.81050	129.8341	-0.2922330
35.86383	129.8342	-0.2979035
35.91550	129.8325	-0.3033764
35.96716	129.8314	-0.3088498
36.02050	129.8320	-0.3144430
36.07383	129.8311	-0.3200559
36.12383	129.8314	-0.3253266
36.17717	129.8300	-0.3309240
36.23050	129.8299	-0.3366903
36.28050	129.8302	-0.3421289
36.33383	129.8296	-0.3480017
36.38716	129.8285	-0.3538990
36.43883	129.8280	-0.3596738
36.49050	129.8288	-0.3654678
36.54383	129.8279	-0.3714982
36.59550	129.8279	-0.3773220
36.64717	129.8268	-0.3831124
36.70050	129.8274	-0.3890503
36.75217	129.8270	-0.3948405
36.80383	129.8266	-0.4005638
36.85716	129.8259	-0.4065416
36.90883	129.8259	-0.4123138
36.96050	129.8260	-0.4180689
37.01383	129.8255	-0.4239934
37.06716	129.8244	-0.4298200
37.11716	129.8246	-0.4352890
37.17050	129.8240	-0.4411264
37.22383	129.8234	-0.4468822
37.27383	129.8228	-0.4523222
37.32717	129.8229	-0.4581029
37.38050	129.8230	-0.4639282
37.43216	129.8219	-0.4695523
37.48383	129.8209	-0.4752060
37.53717	129.8218	-0.4810482
37.58883	129.8209	-0.4866852
37.64050	129.8203	-0.4923740
37.69383	129.8208	-0.4983221
37.74550	129.8198	-0.5039559
37.79716	129.8195	-0.5096216
37.85050	129.8186	-0.5154976
37.90216	129.8188	-0.5212546
37.95383	129.8186	-0.5270480
38.00716	129.8183	-0.5329400
38.06050	129.8180	-0.5387674
38.11050	129.8171	-0.5441965
38.16383	129.8159	-0.5499110
38.21716	129.8152	-0.5556028
38.26716	129.8150	-0.5609298
38.32050	129.8151	-0.5667504
38.37383	129.8142	-0.5724674
38.42550	129.8153	-0.5780807
38.47717	129.8143	-0.5836672
38.53050	129.8137	-0.5894191
38.58216	129.8130	-0.5950086
38.63383	129.8120	-0.6005440
38.68716	129.8123	-0.6062875
38.73883	129.8122	-0.6118500
38.79050	129.8116	-0.6174086
38.84384	129.8111	-0.6231887
38.89550	129.8109	-0.6288165
38.94717	129.8101	-0.6344507
39.00050	129.8101	-0.6402989
39.05383	129.8098	-0.6459985
39.10383	129.8096	-0.6514150
39.15716	129.8088	-0.6571240
39.21050	129.8087	-0.6628752
39.26050	129.8093	-0.6682168
39.31383	129.8085	-0.6739389
39.36716	129.8079	-0.6796036
39.41883	129.8076	-0.6851885
39.47050	129.8061	-0.6907022
39.52383	129.8072	-0.6964510
39.57550	129.8066	-0.7019482
39.62717	129.8062	-0.7073638
39.68050	129.8058	-0.7129800
39.73216	129.8048	-0.7183921
39.78383	129.8054	-0.7238898
39.83716	129.8047	-0.7295020
39.89050	129.8045	-0.7349988
39.94050	129.8032	-0.7402088
39.99383	129.8028	-0.7457070
40.04716	129.8032	-0.7511928
40.09716	129.8024	-0.7564278
40.15050	129.8013	-0.7619282
40.20383	129.8019	-0.7673960
40.25550	129.8008	-0.7726389
40.30716	129.8011	-0.7778834
40.36050	129.8003	-0.7831829
40.41217	129.7998	-0.7884085
40.46383	129.7984	-0.7936487
40.51716	129.7992	-0.7991641
40.56883	129.7991	-0.8045235
40.62050	129.7977	-0.8098829
40.67383	129.7984	-0.8154219
40.72550	129.7981	-0.8207516
40.77716	129.7973	-0.8259451
40.83050	129.7964	-0.8312100
40.88383	129.7974	-0.8365024
40.93384	129.7961	-0.8415031
40.98717	129.7960	-0.8468015
41.04050	129.7956	-0.8522175
41.09050	129.7955	-0.8572460
41.14383	129.7958	-0.8626728
41.19717	129.7949	-0.8680335
41.24883	129.7948	-0.8732126
41.30050	129.7944	-0.8784288
41.35383	129.7941	-0.8837450
41.40550	129.7942	-0.8888601
41.45717	129.7934	-0.8939960
41.51050	129.7932	-0.8992076
41.56216	129.7929	-0.9042188
41.61383	129.7931	-0.9091869
41.66716	129.7920	-0.9142908
41.71884	129.7920	-0.9191986
41.77050	129.7903	-0.9240131
41.82383	129.7911	-0.9290582
41.87717	129.7899	-0.9340699
41.92717	129.7896	-0.9387192
41.98050	129.7893	-0.9437153
42.03383	129.7887	-0.9487319
42.08383	129.7884	-0.9534699
42.13716	129.7880	-0.9586024
42.19050	129.7881	-0.9638474
42.24216	129.7881	-0.9688818
42.29383	129.7876	-0.9739191
42.34716	129.7875	-0.9791121
42.39883	129.7876	-0.9840580
42.45050	129.7877	-0.9890112
42.50383	129.7872	-0.9940151
42.55550	129.7864	-0.9988101
42.60717	129.7866	-1.003592
42.66050	129.7850	-1.008412
42.71216	129.7853	-1.013084
42.76383	129.7859	-1.017642
42.81717	129.7840	-1.022305
42.87050	129.7845	-1.026993
42.92050	129.7843	-1.031453
42.97383	129.7833	-1.036169
43.02217	129.7845	-1.042628
43.07383	129.8802	-2.979370
43.12717	130.2549	-6.962599
43.17883	130.7752	-10.48124
43.23050	131.4105	-13.56140
43.28383	132.1564	-16.10430
43.33550	132.9446	-18.06956
43.38716	133.7816	-19.63885
43.44050	134.6857	-20.92733
43.49216	135.5925	-21.91574
43.54383	136.5211	-22.70538
43.59716	137.5010	-23.37031
43.65050	138.4950	-23.90750
43.70050	139.4386	-24.31580
43.75383	140.4551	-24.68016
43.80717	141.4781	-24.99458
43.85717	142.4425	-25.25474
43.91050	143.4770	-25.50008
43.96383	144.5139	-25.73075
44.01550	145.5214	-25.93937
44.06717	146.5303	-26.18774
44.12050	147.5733	-26.41615
44.17216	148.5846	-26.64063
44.22383	149.5968	-26.87800
44.27716	150.6421	-27.12980
44.32883	151.6555	-27.38824
44.38050	152.6676	-27.66451
44.43383	153.7132	-27.95955
44.48550	154.7257	-28.24454
44.53717	155.7389	-28.49585
44.59050	156.7860	-28.75404
44.64383	157.8354	-28.98419
44.69383	158.8192	-29.16750
44.74716	159.8735	-29.28536
44.80050	160.9326	-29.31742
44.85050	161.9300	-29.30394
44.90383	162.9994	-29.25859
44.95717	164.0727	-29.04024
45.00883	165.1167	-28.79373
45.06050	166.1616	-28.56066
45.11383	167.2436	-28.29645
45.16550	168.2946	-28.03462
45.21717	169.3453	-27.75183
45.27050	170.4304	-27.48781
45.32217	171.4818	-27.23577
45.37383	172.5334	-26.97217
45.42717	173.6185	-26.71564
45.48050	174.7020	-26.48479
45.53050	175.7201	-26.26599
45.58383	176.8006	-26.06870
45.63716	177.8807	-25.89781
45.68716	178.8934	-25.77131
45.74050	179.9694	-25.66338
45.79383	181.0454	-25.59922
45.84550	182.0836	-25.57248
45.89717	183.1215	-25.56662
45.95050	184.1897	-25.56922
46.00217	185.2211	-25.61768
46.05383	186.2519	-25.76570
46.10717	187.3123	-25.94766
46.15883	188.3374	-26.15249
46.21050	189.3606	-26.41045
46.26383	190.4125	-26.72455
46.31550	191.4296	-27.09408
46.36716	192.4428	-27.50244
46.42050	193.4851	-28.00545
46.47383	194.5241	-28.57459
46.52383	195.4938	-29.18120
46.57717	196.5236	-29.91960
46.63050	197.5485	-30.74964
46.68050	198.5022	-31.62754
46.73383	199.5139	-32.68438
46.78717	200.5191	-33.85359
46.83883	201.4851	-35.15024
46.89050	202.4427	-36.58015
46.94383	203.4220	-38.26110
46.99550	204.3589	-40.06552
47.04716	205.2869	-42.12024
47.10050	206.2311	-44.34892
47.15216	207.1358	-46.70531
47.20383	208.0299	-49.27644
47.25717	208.9423	-52.06213
47.30883	209.8154	-55.03335
47.36050	210.6799	-57.86738
47.41383	211.5745	-60.68790
47.46717	212.4731	-63.41144
47.51717	213.3291	-65.36089
47.57050	214.2741	-66.57245
47.62383	215.2615	-67.18096
47.67383	216.2192	-67.17786
47.72717	217.2819	-66.48689
47.78050	218.3843	-65.13689
47.83217	219.4886	-63.26305
47.88383	220.6312	-60.59418
47.93716	221.8645	-56.44422
47.98883	223.1373	-50.86629
48.04050	224.4477	-46.42738
48.09384	225.7630	-43.41421
48.14550	226.9882	-41.29985
48.19717	228.1686	-39.71817
48.25050	229.3514	-38.50335
48.30217	230.4698	-37.62213
48.35383	231.5682	-36.97110
48.40717	232.6857	-36.46808
48.46050	233.7903	-36.11223
48.51050	234.8168	-35.87222
48.56383	235.9059	-35.68262
48.61716	236.9876	-35.56897
48.66716	237.9973	-35.51629
48.72050	239.0724	-35.48120
48.77383	240.1433	-35.47293
48.82550	241.1785	-35.47392
48.87717	242.2134	-35.47961
48.93050	243.2798	-35.51824
48.98217	244.3127	-35.56951
49.03383	245.3457	-35.65554
49.08716	246.4118	-35.73145
49.13883	247.4430	-35.78210
49.19050	248.4753	-35.85004
49.24383	249.5404	-35.91199
49.29550	250.5720	-35.98782
49.34716	251.6028	-36.05963
49.40050	252.6670	-36.12707
49.45383	253.7306	-36.20400
49.50383	254.7296	-36.25449
49.55717	255.7932	-36.36291
49.61050	256.8564	-36.43212
49.66050	257.8531	-36.52384
49.71383	258.9176	-36.60182
49.76717	259.9811	-36.69770
49.81883	261.0111	-36.77610
49.87050	262.0417	-36.85514
49.92383	263.1052	-36.94495
49.97550	264.1352	-37.02074
50.02716	265.1654	-37.10669
50.08050	266.2279	-37.25870
50.13217	267.2586	-37.29649
50.18383	268.2895	-37.38858
50.23717	269.3528	-37.46387
50.29050	270.4175	-37.50713
50.34050	271.4150	-37.58662
50.39383	272.4775	-37.76883
50.44717	273.5428	-37.74581
50.49716	274.5386	-37.77275
50.54716	275.4876	-38.62160
50.59716	275.9674	-35.63854
50.65050	276.0374	-26.50076
50.70383	275.8345	-17.38507
50.75550	275.4536	-9.814274
50.80717	274.9400	-3.635156
50.86050	274.2990	1.440961
50.91217	273.5977	5.314654
50.96383	272.8336	8.367059
51.01717	271.9917	10.85054
51.06883	271.1384	12.74722
51.12050	270.2537	14.25156
51.17383	269.3150	15.48572
51.22550	268.3854	16.44866
51.27717	267.4397	17.22161
51.33050	266.4494	17.87489
51.38383	265.4495	18.40315
51.43383	264.5032	18.80634
51.48717	263.4854	19.17114
51.54050	262.4619	19.46808
51.59050	261.4978	19.70329
51.64384	260.4660	19.92453
51.69717	259.4294	20.10099
51.74883	258.4226	20.25549
51.80050	257.4132	20.38894
51.85383	256.3695	20.50403
51.90550	255.3568	20.61389
51.95717	254.3422	20.70530
52.01050	253.2937	20.79589
52.06216	252.2776	20.86678
52.11383	251.2605	20.94332
52.16716	250.2089	21.00576
52.21884	249.1898	21.06881
52.27050	248.1692	21.12251
52.32383	247.1156	21.17617
52.37717	246.0624	21.21809
52.42717	245.0729	21.26108
52.48050	244.0190	21.29982
52.53383	242.9630	21.33704
52.58383	241.9727	21.36383
52.63716	240.9167	21.39713
52.69050	239.8603	21.42217
52.74216	238.8361	21.45060
52.79382	237.8123	21.47408
52.84716	236.7555	21.50146
52.89883	235.7308	21.52476
52.95050	234.7062	21.54670
53.00383	233.6497	21.56756
53.05550	232.6246	21.58844
53.10717	231.6005	21.60596
53.16050	230.5420	21.63024
53.21216	229.5172	21.65337
53.26382	228.4927	21.67918
53.31716	227.4345	21.71362
53.37050	226.3745	21.73980
53.42050	225.3828	21.76167
53.47382	224.3242	21.78540
53.52717	223.2656	21.80408
53.57717	222.2724	21.81995
53.63050	221.2131	21.84037
53.68383	220.1556	21.85688
53.73550	219.1290	21.88188
53.78716	218.1032	21.90298
53.84050	217.0437	21.91982
53.89216	216.0180	21.93711
53.94384	214.9920	21.95508
53.99717	213.9325	21.96906
54.04883	212.9059	21.98216
54.10050	211.8795	21.99458
54.15383	210.8180	22.00711
54.20550	209.7916	22.01855
54.25717	208.7649	22.02728
54.31050	207.7068	22.03770
54.36382	206.6480	22.05310
54.41382	205.6562	22.06792
54.46717	204.5956	22.09354
54.52050	203.5365	22.11540
54.57050	202.5425	22.12866
54.62383	201.4826	22.14216
54.67717	200.4237	22.15406
54.72883	199.3961	22.16770
54.78050	198.3695	22.18158
54.83383	197.3102	22.19170
54.88550	196.2826	22.20238
54.93716	195.2551	22.21525
54.99050	194.1953	22.22838
55.04217	193.1684	22.23982
55.09384	192.1415	22.25098
55.14717	191.0806	22.26184
55.20050	190.0208	22.27214
55.25050	189.0273	22.28387
55.30383	187.9676	22.29825
55.35717	186.9078	22.31152
55.40717	185.9149	22.32720
55.46050	184.8541	22.34212
55.51382	183.7949	22.35442
55.56550	182.7676	22.36854
55.61716	181.7403	22.37938
55.67050	180.6805	22.39212
55.72217	179.6528	22.40848
55.77383	178.6268	22.42818
55.82717	177.5663	22.45026
55.87883	176.5392	22.47035
55.93050	175.5110	22.49475
55.98383	174.4514	22.50815
56.03550	173.4228	22.52238
56.08716	172.3958	22.53470
56.14050	171.3356	22.55222
56.19384	170.2764	22.58695
56.24382	169.2833	22.67156
56.29717	168.2278	22.82570
56.35050	167.1726	23.04473
56.40050	166.1897	23.28833
56.45383	165.1459	23.71482
56.50717	164.1121	24.33588
56.55883	163.1268	25.31363
56.61050	162.1636	26.84408
56.66382	161.2080	29.22776
56.71550	160.3312	32.45362
56.76716	159.5078	36.50861
56.82050	158.7058	41.19608
56.87217	157.9592	45.72850
56.92383	157.2098	49.67384
56.97717	156.4046	52.73742
57.02883	155.5696	54.52449
57.08050	154.6669	55.10572
57.13383	153.6589	54.58996
57.18716	152.5823	53.15136
57.23717	151.5172	51.17500
57.29050	150.3374	48.71616
57.34384	149.1302	46.15157
57.39384	147.9890	43.83183
57.44717	146.7700	41.46949
57.50050	145.5575	39.31245
57.55217	144.3934	37.44388
57.60383	143.2405	35.76806
57.65717	142.0628	34.23352
57.70883	140.9333	32.92614
57.76050	139.8165	31.79006
57.81382	138.6731	30.75689
57.86550	137.5761	29.88813
57.91716	136.4870	29.13735
57.97050	135.3742	28.49095
58.02217	134.3012	27.92404
58.07383	133.2342	27.44718
58.12717	132.1386	27.00015
58.18050	131.0464	26.63879
58.23050	130.0268	26.32370
58.28383	128.9418	26.04276
58.33716	127.8622	25.85437
58.38716	126.8510	25.62326
58.44050	125.7745	25.43326
58.49382	124.7001	25.27316
58.54550	123.6612	25.13648
58.59716	122.6240	25.01969
58.65050	121.5530	24.91611
58.70216	120.5180	24.81049
58.75383	119.4823	24.72638
58.80717	118.4152	24.65127
58.85883	117.3802	24.56044
58.91050	116.3458	24.49746
58.96382	115.2803	24.41854
59.01550	114.2475	24.35400
59.06716	113.2064	24.02408
59.12050	112.1340	23.86967
59.17383	111.0643	23.77977
59.22382	110.0599	23.67987
59.27717	108.9924	23.59589
59.33050	107.9318	23.75539
59.38050	106.9498	24.15631
59.43383	105.9001	24.25371
59.48717	104.8467	24.28840
59.53882	103.8196	24.15992
59.59050	102.7796	23.84820
59.64384	101.7066	23.71988
59.69550	100.6686	23.59648
59.74717	99.63184	23.51895
59.80050	98.56389	23.43414
59.85217	97.53036	23.37434
59.90383	96.49649	23.31242
59.95717	95.43163	23.25364
60.01050	94.36584	23.20506
60.06050	93.36629	23.15260
60.11382	92.30152	23.10654
60.16716	91.23579	23.05806
60.21717	90.23574	22.99343
60.27050	89.17106	22.94465
60.32383	88.10505	22.89118
60.37550	87.07301	22.83844
60.42717	86.04184	22.79310
60.48050	84.97559	22.72190
60.53217	83.94397	22.63906
60.58383	82.90986	22.56201
60.63716	81.84399	22.48674
60.68882	80.81063	22.42845
60.74050	79.77662	22.35754
60.79382	78.70905	22.26728
60.84550	77.67474	22.17770
60.89717	76.64031	22.09475
60.95050	75.57320	22.02058
61.00383	74.50670	21.94551
61.05383	73.50738	21.89074
61.10717	72.44251	21.85630
61.16050	71.37605	21.78179
61.21050	70.37525	21.71448
61.26382	69.31015	21.64402
61.31716	68.24474	21.58700
61.36882	67.21070	21.51840
61.42050	66.17688	21.45562
61.47382	65.11036	21.36666
61.52550	64.07701	21.28999
61.57717	63.04340	21.21503
61.63050	61.97750	21.16280
61.68217	60.94648	21.11215
61.73383	59.91432	21.05874
61.78716	58.84848	20.98436
61.83882	57.81467	20.90449
61.89050	56.78172	20.82690
61.94384	55.71441	20.76867
61.99717	54.64743	20.68352
62.04717	53.64812	20.62040
62.10050	52.58057	20.55629
62.15383	51.51470	20.49104
62.20383	50.51484	20.42203
62.25717	49.44797	20.34435
62.31050	48.38012	20.26045
62.36217	47.34562	20.19223
62.41382	46.31143	20.10085
62.46717	45.24462	20.04432
62.51884	44.21234	19.98309
62.57050	43.17856	19.90398
62.62383	42.11060	19.81354
62.67550	41.07542	19.74011
62.72717	40.04092	19.64730
62.78050	38.97119	19.56171
62.83217	37.93631	19.46581
62.88383	36.90144	19.36317
62.93716	35.83313	19.27670
62.99050	34.76425	19.17090
63.04050	33.76128	19.08508
63.09384	32.69235	18.97760
63.14717	31.62180	18.86856
63.19717	30.61862	18.78028
63.25050	29.54871	18.68491
63.30383	28.47936	18.58108
63.35550	27.44118	18.46074
63.40717	26.40555	18.39187
63.46050	25.33464	18.30996
63.51050	24.33230	18.32695
63.56216	23.39620	18.77661
63.61382	22.96292	12.89800
63.66716	22.89363	6.398506
63.71884	23.10169	1.090854
63.77050	23.50572	-2.965080
63.82383	24.07782	-6.181432
63.87550	24.74265	-8.549049
63.92717	25.48999	-10.38549
63.98050	26.32365	-11.84996
64.03384	27.20862	-12.99009
64.08384	28.06956	-13.85656
64.13717	29.01540	-14.58666
64.19050	29.98469	-15.19186
64.24050	30.90723	-15.65682
64.29384	31.90291	-16.06529
64.34717	32.90950	-16.43106
64.39883	33.89187	-16.73074
64.45050	34.88072	-17.00008
64.50384	35.90688	-17.23802
64.55550	36.90338	-17.46542
64.60718	37.90382	-17.65958
64.66050	38.94070	-17.86277
64.71217	39.94680	-18.03116
64.76384	40.95592	-18.19791
64.81717	42.00020	-18.34553
64.87050	43.04426	-18.51141
64.92050	44.02629	-18.63588
64.97384	45.07503	-18.77376
65.02717	46.12548	-18.90430
65.07718	47.11013	-19.02743
65.13050	48.16156	-19.15160
65.18384	49.21300	-19.29936
65.23550	50.23340	-19.40443
65.28717	51.25426	-19.55703
65.34050	52.30731	-19.68403
65.39216	53.32874	-19.79509
65.44384	54.35032	-19.90489
65.49717	55.40466	-20.04922
65.54884	56.42762	-20.16219
65.60050	57.45110	-20.28021
65.65384	58.50735	-20.43676
65.70550	59.53168	-20.53835
65.75718	60.55557	-20.62294
65.81050	61.61489	-20.77240
65.86384	62.67432	-20.88945
65.91382	63.66713	-20.99416
65.96718	64.72607	-21.11994
66.02050	65.78510	-21.21593
66.07050	66.77869	-21.31982
66.12384	67.83766	-21.47446
66.17718	68.89719	-21.58071
66.22884	69.92339	-21.66339
66.28050	70.94874	-21.82235
66.33384	72.00768	-21.94272
66.38550	73.03422	-22.04347
66.43718	74.06084	-22.18121
66.49050	75.12110	-22.32184
66.54218	76.14666	-22.41114
66.59384	77.17263	-22.56765
66.64718	78.23210	-22.68535
66.69884	79.25860	-22.80992
66.75050	80.28592	-22.90334
66.80384	81.34581	-23.03262
66.85718	82.40686	-23.16472
66.90718	83.39881	-23.29052
66.96050	84.46046	-23.42463
67.01384	85.51986	-23.53516
67.06384	86.51400	-23.64021
67.11718	87.57426	-23.76936
67.17050	88.63410	-23.91789
67.22218	89.66000	-24.04904
67.27384	90.68751	-24.17833
67.32718	91.74689	-24.30936
67.37884	92.77424	-24.42974
67.43050	93.80171	-24.57388
67.48384	94.86014	-24.70671
67.53550	95.88774	-24.82483
67.58716	96.91411	-24.94917
67.64050	97.97501	-25.06970
67.69218	99.00235	-25.17185
67.74384	100.0301	-25.29785
67.79718	101.0914	-25.42266
67.85050	102.1528	-25.56216
67.90050	103.1457	-25.69200
67.95384	104.2049	-25.82170
68.00718	105.2646	-25.94698
68.05718	106.2585	-26.08351
68.11050	107.3181	-26.21390
68.16382	108.3776	-26.35194
68.21550	109.4064	-26.47670
68.26716	110.4345	-26.59057
68.32050	111.4949	-26.73574
68.37218	112.5229	-26.86430
68.42384	113.5494	-27.00115
68.47718	114.6084	-27.15405
68.52884	115.6350	-27.28550
68.58050	116.6613	-27.42237
68.63384	117.7211	-27.55764
68.68550	118.7483	-27.68574
68.73718	119.7763	-27.82154
68.79050	120.8372	-27.97506
68.84384	121.8970	-28.11969
68.89384	122.8907	-28.25126
68.94718	123.9498	-28.40230
69.00050	125.0103	-28.55706
69.05050	126.0036	-28.72083
69.10384	127.0609	-28.86952
69.15718	128.1199	-29.02196
69.20884	129.1471	-29.14106
69.26050	130.1725	-29.30894
69.31384	131.2324	-29.44047
69.36550	132.2598	-29.56435
69.41718	133.2872	-29.72087
69.47050	134.3491	-29.80666
69.52218	135.3784	-29.91075
69.57384	136.4056	-30.05892
69.62718	137.4674	-30.21497
69.68050	138.5284	-30.36886
69.73050	139.5226	-30.45018
69.78384	140.5862	-30.51203
69.83716	141.6552	-30.50115
69.88718	142.6561	-30.50535
69.94050	143.7280	-30.49532
69.99384	144.7940	-30.50008
70.04550	145.8245	-30.73137
70.09718	146.8495	-30.95698
70.15050	147.8993	-31.40292
70.20216	148.9144	-31.73680
70.25384	149.9318	-31.90076
70.30718	150.9943	-31.81600
70.35884	152.0234	-31.88890
70.41050	153.0537	-32.00144
70.46384	154.1166	-32.10040
70.51550	155.1450	-32.23367
70.56718	156.1731	-32.36025
70.62050	157.2340	-32.47646
70.67384	158.2976	-32.58725
70.72384	159.2918	-32.71794
70.77718	160.3558	-32.79065
70.83050	161.4204	-32.86697
70.88050	162.4191	-32.91534
70.93384	163.4849	-32.96984
70.98718	164.5499	-33.03814
71.03882	165.5809	-33.11605
71.09050	166.6120	-33.20163
71.14384	167.6756	-33.29434
71.19550	168.7054	-33.40897
71.24718	169.7349	-33.52933
71.30050	170.7949	-33.69998
71.35218	171.8223	-33.86203
71.40384	172.8482	-34.03898
71.45718	173.9053	-34.23897
71.50884	174.9297	-34.46040
71.56050	175.9521	-34.69068
71.61384	177.0062	-34.95416
71.66718	178.0587	-35.25009
71.71718	179.0430	-35.56746
71.77050	180.0916	-35.94292
71.82384	181.1382	-36.36390
71.87384	182.1162	-36.79131
71.92718	183.1579	-37.31118
71.98050	184.1961	-37.88586
72.03218	185.1981	-38.48986
72.08384	186.1962	-39.14292
72.13718	187.2236	-39.90686
72.18884	188.2148	-40.66080
72.24050	189.2040	-41.49176
72.29384	190.2218	-42.35790
72.34550	191.2068	-43.23066
72.39718	192.1910	-44.11912
72.45050	193.2041	-45.04990
72.50218	194.1846	-46.03310
72.55384	195.1619	-47.03354
72.60718	196.1682	-48.17648
72.66050	197.1690	-49.41346
72.71050	198.1019	-50.62676
72.76384	199.0944	-51.98764
72.81718	200.0808	-53.39756
72.86718	201.0045	-54.71996
72.92050	201.9919	-55.98830
72.97384	202.9861	-57.02963
73.02550	203.9662	-57.55120
73.07718	204.9721	-57.32016
73.13050	206.0544	-56.20215
73.18218	207.1554	-53.96894
73.23384	208.3121	-51.02490
73.28718	209.5477	-47.70538
73.33884	210.7630	-44.52678
73.39050	211.9778	-41.89790
73.44384	213.2059	-40.01496
73.49550	214.3606	-38.69964
73.54718	215.4880	-37.71475
73.60050	216.6286	-36.99658
73.65384	217.7494	-36.45966
73.70384	218.7874	-36.04929
73.75718	219.8863	-35.79876
73.81050	220.9760	-35.59165
73.86050	221.9916	-35.44444
73.91382	223.0697	-35.41420
73.96718	224.1460	-35.34700
74.01882	225.1848	-35.31802
74.07050	226.2218	-35.31943
74.12384	227.2925	-35.31336
74.17550	228.3264	-35.32224
74.22718	229.3611	-35.34910
74.28050	230.4281	-35.40352
74.33218	231.4606	-35.43562
74.38384	232.4923	-35.54987
74.43718	233.5578	-35.58164
74.49050	234.6229	-35.69644
74.54050	235.6211	-35.72446
74.59384	236.6865	-35.79819
74.64718	237.7503	-35.87594
74.69718	238.7509	-35.92745
74.75050	239.8134	-36.02020
74.80384	240.8788	-36.07109
74.85550	241.9095	-36.18334
74.90718	242.9414	-36.22114
74.96050	244.0064	-36.31869
75.01218	245.0382	-36.35883
75.06384	246.0695	-36.43069
75.11718	247.1336	-36.50988
75.16884	248.1654	-36.55110
75.22050	249.1953	-36.63238
75.27384	250.2602	-36.69022
75.32550	251.2916	-36.77089
75.37718	252.3221	-36.83363
75.43050	253.3870	-36.89238
75.48384	254.4513	-36.97113
75.53384	255.4494	-37.03972
75.58716	256.5132	-37.13226
75.64050	257.5766	-37.20262
75.69050	258.5728	-37.29366
75.74384	259.6368	-37.36937
75.79718	260.6999	-37.45945
75.84882	261.7317	-37.52958
75.90050	262.7628	-37.59998
75.95384	263.8274	-37.66371
76.00550	264.8580	-37.73885
76.05718	265.8898	-37.81598
76.11050	266.9472	-38.34745
76.16218	267.9724	-38.34734
76.21384	268.9988	-38.42471
76.26716	270.0222	-41.22067
76.31884	271.0294	-39.69744
-2.000000	5.000000	0.0000000