File: 5-C1(1.4mol%)+C20(0.6mol%)/matlab/140-1.txt
CLOSED
Version	1.0
Language	English
Mode	Standard
Run	17
RunSerial	12319
Instrument	DSC Q2000 V24.11 Build 124
Module	DSC Standard Cell RC
Operator
File	\\AE520-1454\Users\dsc\Desktop\Data\31-08-17-2\140-1.001
ProcName
InstSerial	2000-0883
AutoSerial	1293
Sample	140-1
Size	27.2000	mg
PanMass	Not available
PanResist	Automatic Automatic  K/W
PanFactor	Default Default
Method
Comment
Xcomment	Pan: Tzero Aluminum Hermetic
Xcomment	Gas1: Nitrogen 50.0 ml/min
Xcomment	Gas2: Nitrogen 50.0 ml/min
Text
Exotherm	UP
Kcell	1.05230
Cpconst	Standard: 0.938
Calib	-38.6961
TempCal	1	pts	157.46	156.60
TzeroDt	-87.6168 -0.0009 -1.4231
TzeroDtz	-87.6168 0.0057 6.9570
InstCalFile	Tzero: \\Ae520-1454\ta\Data\DSC\Calibration\2017\CALIBRATION\1562_RCS (90)_05_18_2017 10_50_44.TZR
InstCalFile	Baseline: \\Ae520-1454\ta\Data\DSC\Calibration\2017\2017-05-17_Calibration.001
InstCalFile	Sapphire: \\Ae520-1454\ta\Data\DSC\Calibration\2017\2017-05-17_Saphire.001
InstCalDate	Tzero 2017-05-18 Time 10:50:44
TempRange	-87.39 to 398.39 °C at 10.00 °C/min Heat Only
AutoZero	Delta T Offset 0.000 uV
AutoZero	Delta T0 Offset 0.000 uV
MultiptCal	0
MultiPtDesc	0) Not set
AutoCellConst	Calibration Date 2017-05-18 16:59:28
Controls	Gas 1  Event Off  Sampling 0.2
Cell#	RC-01562
CoolingUnit	RCS (90)
SelHeatFlow	Heat Flow T4P (mW)
AutoLidII	Installed
AutoAnalysis	Off
MacroFile
Nsig	3
Sig1	Time (min)
Sig2	Temperature (°C)
Sig3	Heat Flow (mW)
Date	2017-09-01
Time	07:32:49
OrgMethod	1: Equilibrate at 80.00 °C
OrgMethod	2: Isothermal for 3.00 min
OrgMethod	3: Jump to 140.00 °C
OrgMethod	4: Mark end of cycle 1
OrgMethod	5: Isothermal for 40.00 min
OrgMethod	6: Mark end of cycle 2
OrgMethod	7: Ramp 20.00 °C/min to 280.00 °C
OrgMethod	8: Mark end of cycle 3
OrgMethod	9: Ramp 20.00 °C/min to 20.00 °C
OrgMethod	10: Mark end of cycle 4
OrgMethod	11: Ramp 20.00 °C/min to 280.00 °C
OrgMethod	12: Mark end of cycle 5
OrgFile	C:\Users\jarra\Desktop\DSC\5-C1(1.4mol%)+C20(0.6mol%)\140-1.001
StartOfData
4.99994E-4	79.60995	-4.667947
0.05383332	79.67750	-3.764909
0.1055000	79.72824	-3.096297
0.1571666	79.76712	-2.577094
0.2105000	79.79616	-2.165566
0.2605000	79.81782	-1.868556
0.3138333	79.83487	-1.622237
0.3655000	79.84775	-1.443514
0.4171667	79.85735	-1.307704
0.4705000	79.86422	-1.202488
0.5205000	79.86872	-1.126128
0.5738334	79.87194	-1.065896
0.6238334	79.87446	-1.027780
0.6771668	79.87538	-0.9961486
0.7288332	79.87793	-0.9775586
0.7805000	79.87790	-0.9633332
0.8338332	79.87774	-0.9544813
0.8838332	79.87861	-0.9501924
0.9371668	79.87916	-0.9466022
0.9888332	79.87802	-0.9432564
1.040500	79.87739	-0.9398769
1.093833	79.87745	-0.9364082
1.143833	79.87631	-0.9333062
1.197166	79.87548	-0.9301551
1.247166	79.87444	-0.9274126
1.300500	79.87406	-0.9246139
1.352166	79.87368	-0.9221972
1.403833	79.87253	-0.9200046
1.457167	79.87181	-0.9181326
1.507167	79.87166	-0.9165564
1.560500	79.87038	-0.9150811
1.612166	79.86988	-0.9138944
1.663834	79.86948	-0.9129249
1.717167	79.86788	-0.9120599
1.767167	79.86695	-0.9114461
1.820500	79.86722	-0.9109586
1.870500	79.86668	-0.9106320
1.923834	79.86562	-0.9104157
1.975500	79.86562	-0.9104575
2.027166	79.86484	-0.9105012
2.080500	79.86330	-0.9106964
2.130500	79.86339	-0.9110116
2.183833	79.86210	-0.9114314
2.235500	79.86218	-0.9120509
2.287166	79.86094	-0.9127332
2.338833	79.86071	-0.9135387
2.390500	79.85985	-0.9144184
2.443833	79.86034	-0.9154816
2.493833	79.85958	-0.9164368
2.547166	79.85920	-0.9175366
2.598834	79.85834	-0.9186361
2.650500	79.85870	-0.9198053
2.703833	79.85741	-0.9210738
2.753833	79.85738	-0.9222930
2.807167	79.85589	-0.9236451
2.858833	79.85572	-0.9249828
2.910500	79.85593	-0.9264306
2.962167	79.85522	-0.9278507
3.010500	79.86172	-0.9854100
3.060500	80.48794	-9.497141
3.113833	82.67081	-23.62752
3.165500	85.39464	-35.81174
3.217166	88.58119	-47.19506
3.270500	92.23914	-57.50960
3.320500	95.92812	-65.81320
3.373834	100.0700	-73.24972
3.425500	104.2318	-79.21897
3.477167	108.5016	-84.16774
3.530500	112.9907	-88.36541
3.580500	117.2499	-91.64772
3.633833	121.8171	-94.60475
3.683833	125.7064	-91.98782
3.737167	128.5410	-80.38834
3.788833	130.6211	-69.66962
3.840500	132.2422	-58.90137
3.893833	133.5682	-48.99127
3.943833	134.5626	-40.94081
3.997166	135.4222	-33.72273
4.048834	136.0961	-27.95077
4.100500	136.6474	-23.22756
4.153834	137.1153	-19.27427
4.203833	137.4784	-16.27640
4.257167	137.8019	-13.69472
4.307167	138.0546	-11.73595
4.360500	138.2816	-10.05049
4.412167	138.4673	-8.728326
4.463834	138.6241	-7.652588
4.517166	138.7612	-6.754104
4.567167	138.8732	-6.065484
4.620500	138.9739	-5.467758
4.672167	139.0578	-4.990032
4.723834	139.1303	-4.596387
4.775500	139.1939	-4.271263
4.827167	139.2493	-3.998570
4.880500	139.2984	-3.764319
4.930500	139.3402	-3.581722
4.983834	139.3771	-3.411344
5.035500	139.4091	-3.273407
5.087167	139.4373	-3.153809
5.140500	139.4641	-3.048363
5.190500	139.4857	-2.963706
5.243834	139.5063	-2.883287
5.295500	139.5242	-2.818708
5.347168	139.5408	-2.760108
5.398834	139.5547	-2.707312
5.450500	139.5677	-2.660139
5.503834	139.5805	-2.616543
5.553834	139.5898	-2.580010
5.607168	139.6004	-2.543627
5.658832	139.6086	-2.511783
5.710500	139.6169	-2.482400
5.763834	139.6238	-2.453610
5.813832	139.6303	-2.429295
5.867168	139.6358	-2.402480
5.917168	139.6414	-2.381106
5.970500	139.6471	-2.359577
6.022168	139.6511	-2.338960
6.073834	139.6559	-2.320338
6.127168	139.6602	-2.299606
6.177166	139.6646	-2.282152
6.230500	139.6675	-2.263045
6.282166	139.6709	-2.245369
6.333832	139.6746	-2.227090
6.387168	139.6773	-2.208856
6.437168	139.6806	-2.190726
6.490500	139.6831	-2.171945
6.540500	139.6868	-2.154828
6.593832	139.6888	-2.136380
6.645500	139.6912	-2.118427
6.697168	139.6933	-2.100590
6.750500	139.6961	-2.081950
6.800500	139.6987	-2.064685
6.853832	139.7011	-2.045422
6.905500	139.7039	-2.027385
6.957168	139.7066	-2.007560
7.010500	139.7079	-1.986408
7.060500	139.7102	-1.966994
7.113834	139.7134	-1.945555
7.163832	139.7148	-1.923012
7.217168	139.7170	-1.899232
7.268832	139.7192	-1.875980
7.320500	139.7216	-1.850245
7.373834	139.7230	-1.823769
7.423834	139.7250	-1.799941
7.477168	139.7261	-1.773020
7.528832	139.7289	-1.748505
7.580500	139.7306	-1.720973
7.633832	139.7324	-1.693892
7.683832	139.7351	-1.668573
7.737168	139.7366	-1.640397
7.787168	139.7392	-1.614441
7.840500	139.7415	-1.585883
7.892168	139.7428	-1.556362
7.943832	139.7460	-1.527664
7.997168	139.7479	-1.495044
8.047168	139.7495	-1.464618
8.100500	139.7511	-1.432246
8.152168	139.7548	-1.402536
8.203834	139.7569	-1.367541
8.255500	139.7586	-1.333592
8.307168	139.7609	-1.300722
8.360500	139.7631	-1.265981
8.410499	139.7660	-1.232366
8.463834	139.7678	-1.195557
8.515500	139.7712	-1.160988
8.567166	139.7734	-1.125677
8.620499	139.7760	-1.085602
8.670500	139.7786	-1.049257
8.723832	139.7817	-1.008939
8.775499	139.7846	-0.9694034
8.827168	139.7879	-0.9274444
8.878834	139.7910	-0.8843937
8.930500	139.7938	-0.8398039
8.983832	139.7971	-0.7945822
9.033832	139.7997	-0.7501300
9.087168	139.8020	-0.7024219
9.138834	139.8057	-0.6566597
9.190500	139.8086	-0.6086872
9.243834	139.8117	-0.5607500
9.293834	139.8156	-0.5149594
9.347168	139.8184	-0.4640659
9.398834	139.8221	-0.4128970
9.450500	139.8247	-0.3570284
9.502168	139.8283	-0.3039024
9.553832	139.8327	-0.2474120
9.607166	139.8370	-0.1814726
9.657166	139.8407	-0.1135988
9.710499	139.8464	-.03209086
9.762168	139.8519	0.06605686
9.813834	139.8589	0.1794394
9.867166	139.8686	0.3202822
9.917168	139.8771	0.4776611
9.970500	139.8897	0.6681614
10.02050	139.9027	0.8667158
10.07383	139.9177	1.097747
10.12550	139.9333	1.332069
10.17717	139.9497	1.575500
10.23050	139.9667	1.828567
10.28050	139.9827	2.068482
10.33383	139.9999	2.321064
10.38550	140.0163	2.561211
10.43717	140.0326	2.802180
10.49050	140.0492	3.041542
10.54050	140.0647	3.262748
10.59383	140.0797	3.495735
10.64383	140.0942	3.701964
10.69717	140.1082	3.923396
10.74883	140.1228	4.126742
10.80050	140.1364	4.319424
10.85383	140.1500	4.506144
10.90383	140.1606	4.676864
10.95717	140.1722	4.842564
11.00883	140.1823	4.990837
11.06050	140.1916	5.125730
11.11383	140.2011	5.253523
11.16383	140.2083	5.361644
11.21717	140.2158	5.466035
11.26717	140.2223	5.554768
11.32050	140.2290	5.640048
11.37217	140.2336	5.716542
11.42383	140.2402	5.786919
11.47717	140.2444	5.855586
11.52717	140.2486	5.917164
11.58050	140.2527	5.977878
11.63216	140.2575	6.035454
11.68383	140.2612	6.087772
11.73717	140.2648	6.139118
11.78717	140.2678	6.185992
11.84050	140.2714	6.229022
11.89050	140.2744	6.266318
11.94383	140.2769	6.300282
11.99550	140.2781	6.327790
12.04717	140.2806	6.348458
12.10050	140.2813	6.366058
12.15050	140.2820	6.375432
12.20384	140.2826	6.381876
12.25550	140.2838	6.385966
12.30717	140.2830	6.389712
12.35883	140.2834	6.392848
12.41050	140.2815	6.395084
12.46383	140.2818	6.396435
12.51383	140.2801	6.395722
12.56716	140.2781	6.389810
12.61884	140.2758	6.373896
12.67050	140.2730	6.348922
12.72383	140.2706	6.313359
12.77383	140.2676	6.271356
12.82717	140.2652	6.220252
12.87883	140.2621	6.172836
12.93050	140.2596	6.131250
12.98216	140.2556	6.077954
13.03383	140.2528	6.017715
13.08717	140.2499	5.965620
13.13717	140.2467	5.904387
13.19050	140.2428	5.842114
13.24216	140.2389	5.786123
13.29384	140.2354	5.732934
13.34717	140.2316	5.679459
13.39717	140.2284	5.630150
13.45050	140.2253	5.580634
13.50050	140.2219	5.534464
13.55383	140.2194	5.487441
13.60550	140.2157	5.445675
13.65717	140.2129	5.405836
13.71050	140.2096	5.365137
13.76050	140.2068	5.325590
13.81383	140.2036	5.290551
13.86550	140.2012	5.258375
13.91716	140.1987	5.226274
13.97050	140.1969	5.196308
14.02050	140.1944	5.169002
14.07384	140.1923	5.140312
14.12384	140.1904	5.117033
14.17717	140.1888	5.094512
14.22884	140.1869	5.076635
14.28050	140.1860	5.060153
14.33383	140.1832	5.044876
14.38383	140.1819	5.032761
14.43716	140.1818	5.021170
14.48883	140.1809	5.011570
14.54050	140.1805	5.003238
14.59383	140.1793	4.995770
14.64383	140.1798	4.989368
14.69717	140.1783	4.982575
14.74717	140.1784	4.976122
14.80050	140.1778	4.969324
14.85217	140.1776	4.963053
14.90383	140.1784	4.957024
14.95717	140.1781	4.951168
15.00717	140.1765	4.946152
15.06050	140.1779	4.941200
15.11217	140.1781	4.936898
15.16383	140.1786	4.933100
15.21716	140.1800	4.929799
15.26717	140.1796	4.927353
15.32050	140.1807	4.925406
15.37050	140.1806	4.924287
15.42383	140.1816	4.923740
15.47550	140.1826	4.923886
15.52717	140.1836	4.924747
15.58050	140.1850	4.926430
15.63050	140.1865	4.929354
15.68383	140.1880	4.933808
15.73550	140.1885	4.940174
15.78717	140.1896	4.948616
15.83883	140.1917	4.959072
15.89050	140.1932	4.972314
15.94384	140.1954	4.987951
15.99383	140.1963	5.005772
16.04716	140.1984	5.026059
16.09883	140.2008	5.049922
16.15050	140.2019	5.079308
16.20383	140.2053	5.107742
16.25383	140.2063	5.140430
16.30716	140.2074	5.176290
16.35883	140.2104	5.213684
16.41050	140.2124	5.251191
16.46216	140.2144	5.290879
16.51383	140.2161	5.330191
16.56716	140.2184	5.368772
16.61716	140.2203	5.402753
16.67050	140.2223	5.438138
16.72216	140.2244	5.469234
16.77383	140.2263	5.498410
16.82716	140.2280	5.525982
16.87716	140.2305	5.546402
16.93050	140.2311	5.565044
16.98216	140.2320	5.578126
17.03383	140.2327	5.586198
17.08550	140.2337	5.591648
17.13716	140.2338	5.596634
17.19050	140.2336	5.601368
17.24050	140.2327	5.605087
17.29383	140.2319	5.607988
17.34550	140.2297	5.610130
17.39716	140.2287	5.609165
17.45050	140.2258	5.598300
17.50050	140.2233	5.574707
17.55383	140.2197	5.533991
17.60383	140.2172	5.481584
17.65716	140.2134	5.422324
17.70883	140.2094	5.361494
17.76050	140.2048	5.298332
17.81383	140.2008	5.229473
17.86383	140.1973	5.164228
17.91716	140.1930	5.096385
17.96883	140.1886	5.029144
18.02050	140.1837	4.960470
18.07383	140.1796	4.893042
18.12383	140.1756	4.829640
18.17716	140.1713	4.765121
18.22716	140.1672	4.705463
18.28050	140.1637	4.641289
18.33216	140.1586	4.583964
18.38383	140.1546	4.524360
18.43716	140.1511	4.465832
18.48716	140.1471	4.409769
18.54050	140.1433	4.353279
18.59216	140.1396	4.300676
18.64383	140.1362	4.249082
18.69716	140.1329	4.199836
18.74716	140.1302	4.154592
18.80050	140.1262	4.106446
18.85050	140.1238	4.063868
18.90383	140.1203	4.019834
18.95550	140.1180	3.978450
19.00716	140.1146	3.939450
19.06050	140.1113	3.899219
19.11050	140.1089	3.860593
19.16383	140.1061	3.822689
19.21550	140.1028	3.787256
19.26716	140.1007	3.751826
19.32050	140.0986	3.717698
19.37050	140.0960	3.684206
19.42383	140.0940	3.643619
19.47383	140.0912	3.607740
19.52716	140.0893	3.572136
19.57883	140.0858	3.537476
19.63050	140.0835	3.503442
19.68383	140.0811	3.471430
19.73383	140.0806	3.440694
19.78717	140.0774	3.410037
19.83883	140.0746	3.379974
19.89050	140.0722	3.349597
19.94216	140.0707	3.317912
19.99383	140.0671	3.287216
20.04716	140.0646	3.255143
20.09716	140.0628	3.224970
20.15050	140.0604	3.192191
20.20216	140.0589	3.161276
20.25383	140.0568	3.129582
20.30716	140.0538	3.096770
20.35716	140.0524	3.066678
20.41050	140.0496	3.033307
20.46216	140.0483	3.000270
20.51383	140.0451	2.968035
20.56550	140.0443	2.934756
20.61716	140.0417	2.901512
20.67050	140.0401	2.866348
20.72050	140.0380	2.834872
20.77383	140.0366	2.800240
20.82550	140.0342	2.768637
20.87716	140.0320	2.737668
20.93050	140.0301	2.705194
20.98050	140.0276	2.674960
21.03383	140.0247	2.641033
21.08383	140.0225	2.609125
21.13716	140.0209	2.574354
21.18883	140.0181	2.539288
21.24050	140.0166	2.502444
21.29383	140.0136	2.465574
21.34383	140.0110	2.428108
21.39716	140.0096	2.391271
21.44883	140.0068	2.353859
21.50050	140.0042	2.315582
21.55383	140.0026	2.276502
21.60383	139.9999	2.239936
21.65716	139.9962	2.202880
21.70717	139.9951	2.163482
21.76050	139.9916	2.123428
21.81216	139.9885	2.082302
21.86383	139.9872	2.040266
21.91716	139.9838	1.998917
21.96716	139.9817	1.957581
22.02050	139.9786	1.914655
22.07216	139.9761	1.871150
22.12383	139.9728	1.827792
22.17717	139.9691	1.783670
22.22716	139.9670	1.743798
22.28050	139.9638	1.701373
22.33050	139.9606	1.653334
22.38383	139.9568	1.599763
22.43550	139.9539	1.546703
22.48716	139.9498	1.497121
22.54050	139.9464	1.444886
22.59050	139.9429	1.396028
22.64383	139.9400	1.341392
22.69550	139.9354	1.289318
22.74716	139.9313	1.234966
22.80050	139.9277	1.178994
22.85050	139.9232	1.126058
22.90383	139.9206	1.067294
22.95383	139.9171	1.013202
23.00716	139.9138	0.9503619
23.05883	139.9096	0.8930076
23.11050	139.9065	0.8306715
23.16383	139.9016	0.7719745
23.21383	139.8974	0.7120790
23.26716	139.8938	0.6482840
23.31883	139.8891	0.5860999
23.37050	139.8851	0.5222442
23.42216	139.8812	0.4581590
23.47383	139.8771	0.3932000
23.52717	139.8721	0.3256388
23.57716	139.8683	0.2627348
23.63050	139.8647	0.1950553
23.68216	139.8606	0.1291894
23.73383	139.8564	0.06281794
23.78717	139.8517	-2.5512E-3
23.83716	139.8470	-.06776984
23.89050	139.8428	-0.1356018
23.94216	139.8384	-0.1985399
23.99383	139.8332	-0.2646865
24.04550	139.8291	-0.3280778
24.09716	139.8239	-0.3929200
24.15050	139.8198	-0.4611572
24.20050	139.8152	-0.5268800
24.25383	139.8121	-0.5948692
24.30550	139.8070	-0.6557019
24.35716	139.8031	-0.7199225
24.41050	139.7989	-0.7840799
24.46050	139.7949	-0.8427350
24.51383	139.7904	-0.9044705
24.56550	139.7863	-0.9620845
24.61716	139.7826	-1.018895
24.66883	139.7787	-1.073827
24.72050	139.7741	-1.127569
24.77383	139.7710	-1.182695
24.82383	139.7675	-1.232019
24.87716	139.7633	-1.284164
24.92883	139.7602	-1.335534
24.98050	139.7562	-1.383298
25.03383	139.7526	-1.431674
25.08383	139.7492	-1.476568
25.13716	139.7468	-1.521376
25.18716	139.7447	-1.563996
25.24050	139.7420	-1.607566
25.29216	139.7390	-1.646864
25.34383	139.7360	-1.683619
25.39716	139.7334	-1.719803
25.44716	139.7312	-1.755448
25.50050	139.7288	-1.789914
25.55217	139.7269	-1.819822
25.60383	139.7242	-1.848905
25.65716	139.7232	-1.879416
25.70716	139.7209	-1.905099
25.76050	139.7181	-1.931038
25.81050	139.7161	-1.953772
25.86383	139.7152	-1.976864
25.91550	139.7130	-1.998230
25.96716	139.7117	-2.018965
26.02050	139.7089	-2.039291
26.07050	139.7078	-2.058451
26.12383	139.7062	-2.079437
26.17550	139.7056	-2.097101
26.22717	139.7041	-2.115275
26.28050	139.7029	-2.132636
26.33050	139.7016	-2.147542
26.38383	139.7003	-2.162847
26.43383	139.6984	-2.176762
26.48716	139.6984	-2.189826
26.53883	139.6978	-2.201098
26.59050	139.6964	-2.210622
26.64383	139.6957	-2.221211
26.69383	139.6944	-2.230114
26.74716	139.6945	-2.239823
26.79883	139.6928	-2.248058
26.85050	139.6916	-2.256546
26.90383	139.6908	-2.265167
26.95383	139.6894	-2.273346
27.00716	139.6885	-2.282200
27.05716	139.6884	-2.290558
27.11050	139.6877	-2.299513
27.16217	139.6866	-2.308295
27.21383	139.6863	-2.317290
27.26716	139.6859	-2.326547
27.31716	139.6861	-2.335232
27.37050	139.6846	-2.344406
27.42216	139.6844	-2.353274
27.47383	139.6837	-2.362000
27.52550	139.6832	-2.370694
27.57717	139.6832	-2.379292
27.63050	139.6823	-2.388089
27.68050	139.6826	-2.396218
27.73383	139.6811	-2.404702
27.78550	139.6810	-2.412787
27.83716	139.6812	-2.420714
27.89050	139.6802	-2.428662
27.94050	139.6798	-2.435994
27.99383	139.6802	-2.443678
28.04550	139.6798	-2.450944
28.09716	139.6793	-2.458112
28.14883	139.6789	-2.465184
28.20050	139.6784	-2.472198
28.25383	139.6785	-2.479273
28.30383	139.6784	-2.485801
28.35716	139.6782	-2.492522
28.40883	139.6776	-2.498920
28.46050	139.6776	-2.505173
28.51383	139.6779	-2.511477
28.56383	139.6784	-2.517226
28.61716	139.6768	-2.523217
28.66716	139.6776	-2.528751
28.72050	139.6764	-2.534427
28.77216	139.6766	-2.539764
28.82383	139.6760	-2.544952
28.87716	139.6763	-2.550168
28.92717	139.6761	-2.554888
28.98050	139.6758	-2.559800
29.03216	139.6752	-2.564428
29.08383	139.6756	-2.568951
29.13716	139.6749	-2.573450
29.18717	139.6761	-2.577637
29.24050	139.6750	-2.581953
29.29050	139.6755	-2.585776
29.34383	139.6741	-2.589770
29.39550	139.6729	-2.593498
29.44717	139.6736	-2.597111
29.50050	139.6737	-2.600703
29.55050	139.6728	-2.603982
29.60383	139.6722	-2.607445
29.65550	139.6733	-2.610749
29.70716	139.6729	-2.614041
29.76050	139.6725	-2.617380
29.81050	139.6738	-2.620506
29.86383	139.6717	-2.623745
29.91383	139.6724	-2.626710
29.96716	139.6731	-2.629800
30.01883	139.6728	-2.632704
30.07050	139.6730	-2.635540
30.12383	139.6720	-2.638387
30.17383	139.6724	-2.640952
30.22717	139.6731	-2.643626
30.27883	139.6721	-2.646043
30.33050	139.6719	-2.648370
30.38383	139.6725	-2.650717
30.43383	139.6710	-2.652780
30.48716	139.6717	-2.654864
30.53717	139.6706	-2.656795
30.59050	139.6710	-2.658773
30.64216	139.6708	-2.660636
30.69383	139.6706	-2.662475
30.74716	139.6706	-2.664355
30.79716	139.6703	-2.666112
30.85050	139.6700	-2.667922
30.90216	139.6701	-2.669614
30.95383	139.6698	-2.671256
31.00550	139.6703	-2.672990
31.05716	139.6701	-2.674724
31.11050	139.6706	-2.676660
31.16050	139.6709	-2.678458
31.21383	139.6710	-2.680379
31.26550	139.6706	-2.682191
31.31716	139.6711	-2.683967
31.37050	139.6700	-2.685717
31.42050	139.6712	-2.687372
31.47383	139.6703	-2.689025
31.52550	139.6704	-2.690574
31.57717	139.6717	-2.692068
31.62883	139.6714	-2.693489
31.68050	139.6712	-2.694831
31.73383	139.6709	-2.696108
31.78383	139.6710	-2.697304
31.83716	139.6704	-2.698556
31.88883	139.6708	-2.699778
31.94050	139.6708	-2.700970
31.99383	139.6709	-2.702131
32.04383	139.6706	-2.703221
32.09716	139.6704	-2.704309
32.14883	139.6701	-2.705330
32.20050	139.6697	-2.706312
32.25217	139.6699	-2.707234
32.30383	139.6701	-2.708098
32.35716	139.6690	-2.708856
32.40716	139.6695	-2.709524
32.46050	139.6686	-2.710245
32.51216	139.6684	-2.710955
32.56383	139.6675	-2.711642
32.61716	139.6682	-2.712420
32.66716	139.6677	-2.713131
32.72050	139.6684	-2.714003
32.77050	139.6682	-2.714864
32.82383	139.6683	-2.715865
32.87550	139.6686	-2.716868
32.92717	139.6699	-2.717905
32.98050	139.6692	-2.718938
33.03050	139.6686	-2.719849
33.08383	139.6696	-2.720791
33.13550	139.6692	-2.721692
33.18716	139.6684	-2.722553
33.24050	139.6691	-2.723420
33.29050	139.6690	-2.724162
33.34384	139.6689	-2.725002
33.39383	139.6694	-2.725710
33.44717	139.6690	-2.726424
33.49883	139.6692	-2.727130
33.55050	139.6692	-2.727760
33.60383	139.6686	-2.728430
33.65383	139.6687	-2.729038
33.70716	139.6678	-2.729578
33.75883	139.6675	-2.729981
33.81050	139.6682	-2.730453
33.86383	139.6681	-2.730887
33.91383	139.6680	-2.731256
33.96716	139.6681	-2.731718
34.01716	139.6681	-2.732108
34.07050	139.6677	-2.732712
34.12216	139.6672	-2.733286
34.17383	139.6680	-2.733879
34.22717	139.6674	-2.734463
34.27716	139.6678	-2.735005
34.33050	139.6669	-2.735562
34.38216	139.6674	-2.736211
34.43384	139.6678	-2.736916
34.48717	139.6687	-2.737568
34.53717	139.6689	-2.738192
34.59050	139.6684	-2.738803
34.64050	139.6678	-2.739336
34.69383	139.6686	-2.739982
34.74550	139.6676	-2.740515
34.79716	139.6690	-2.741134
34.85050	139.6686	-2.741763
34.90050	139.6687	-2.742307
34.95383	139.6686	-2.742844
35.00550	139.6689	-2.743352
35.05716	139.6682	-2.743780
35.10883	139.6680	-2.744178
35.16050	139.6675	-2.744541
35.21383	139.6680	-2.744848
35.26383	139.6668	-2.745094
35.31716	139.6672	-2.745354
35.36883	139.6675	-2.745699
35.42050	139.6670	-2.746060
35.47383	139.6672	-2.746510
35.52383	139.6672	-2.746982
35.57717	139.6666	-2.747504
35.62883	139.6672	-2.748007
35.68050	139.6670	-2.748448
35.73216	139.6679	-2.748872
35.78383	139.6670	-2.749336
35.83716	139.6677	-2.749864
35.88716	139.6673	-2.750356
35.94050	139.6669	-2.750789
35.99216	139.6674	-2.751198
36.04383	139.6667	-2.751484
36.09716	139.6664	-2.751828
36.14717	139.6666	-2.752205
36.20050	139.6674	-2.752587
36.25050	139.6671	-2.752972
36.30383	139.6671	-2.753417
36.35550	139.6671	-2.753740
36.40716	139.6665	-2.754148
36.46050	139.6682	-2.754502
36.51050	139.6671	-2.754808
36.56383	139.6674	-2.755136
36.61550	139.6670	-2.755386
36.66716	139.6676	-2.755648
36.72050	139.6668	-2.755781
36.77050	139.6664	-2.755982
36.82383	139.6665	-2.756211
36.87383	139.6663	-2.756402
36.92717	139.6663	-2.756614
36.97883	139.6666	-2.756846
37.03050	139.6667	-2.757197
37.08383	139.6675	-2.757566
37.13383	139.6669	-2.757932
37.18716	139.6672	-2.758369
37.23883	139.6671	-2.758818
37.29050	139.6669	-2.759312
37.34384	139.6683	-2.759802
37.39383	139.6675	-2.760250
37.44717	139.6679	-2.760704
37.49716	139.6671	-2.761045
37.55050	139.6664	-2.761405
37.60217	139.6667	-2.761743
37.65383	139.6660	-2.761964
37.70716	139.6666	-2.762169
37.75716	139.6663	-2.762412
37.81050	139.6671	-2.762670
37.86217	139.6664	-2.762914
37.91383	139.6670	-2.763312
37.96716	139.6675	-2.763654
38.01716	139.6671	-2.764045
38.07050	139.6680	-2.764423
38.12050	139.6663	-2.764712
38.17383	139.6668	-2.765050
38.22550	139.6671	-2.765280
38.27716	139.6666	-2.765552
38.33050	139.6661	-2.765760
38.38050	139.6663	-2.765932
38.43384	139.6660	-2.766022
38.48550	139.6664	-2.766064
38.53717	139.6664	-2.766128
38.58883	139.6669	-2.766268
38.64050	139.6661	-2.766481
38.69383	139.6656	-2.766814
38.74383	139.6660	-2.767141
38.79716	139.6665	-2.767532
38.84883	139.6669	-2.767902
38.90050	139.6662	-2.768283
38.95383	139.6665	-2.768616
39.00383	139.6665	-2.768946
39.05716	139.6664	-2.769315
39.10883	139.6666	-2.769684
39.16050	139.6664	-2.770013
39.21216	139.6663	-2.770351
39.26383	139.6666	-2.770660
39.31716	139.6668	-2.770939
39.36716	139.6666	-2.771182
39.42050	139.6652	-2.771396
39.47217	139.6662	-2.771693
39.52383	139.6656	-2.771958
39.57717	139.6649	-2.772128
39.62717	139.6655	-2.772294
39.68050	139.6657	-2.772496
39.73216	139.6646	-2.772625
39.78383	139.6655	-2.772856
39.83550	139.6655	-2.773060
39.88716	139.6646	-2.773282
39.94050	139.6644	-2.773659
39.99050	139.6652	-2.774034
40.04383	139.6650	-2.774409
40.09550	139.6653	-2.774828
40.14717	139.6652	-2.775339
40.20050	139.6656	-2.775852
40.25050	139.6653	-2.776263
40.30383	139.6652	-2.776713
40.35383	139.6656	-2.777185
40.40716	139.6660	-2.777682
40.45883	139.6656	-2.778094
40.51050	139.6663	-2.778475
40.56383	139.6646	-2.778725
40.61383	139.6653	-2.778924
40.66716	139.6650	-2.779047
40.71884	139.6650	-2.779127
40.77050	139.6648	-2.779308
40.82383	139.6651	-2.779422
40.87383	139.6641	-2.779685
40.92717	139.6644	-2.779980
40.97717	139.6650	-2.780364
41.03050	139.6652	-2.780772
41.08217	139.6654	-2.781210
41.13383	139.6660	-2.781670
41.18716	139.6655	-2.782125
41.23717	139.6659	-2.782440
41.29050	139.6654	-2.782766
41.34217	139.6661	-2.783012
41.39383	139.6650	-2.783228
41.44717	139.6650	-2.783504
41.49716	139.6655	-2.783723
41.55050	139.6651	-2.784010
41.60050	139.6652	-2.784312
41.65383	139.6656	-2.784596
41.70550	139.6657	-2.784894
41.75717	139.6660	-2.785192
41.81050	139.6655	-2.785358
41.86050	139.6650	-2.785561
41.91383	139.6650	-2.785704
41.96550	139.6652	-2.785834
42.01717	139.6656	-2.785960
42.07050	139.6652	-2.786083
42.12050	139.6648	-2.786184
42.17383	139.6652	-2.786254
42.22383	139.6654	-2.786303
42.27716	139.6649	-2.786333
42.32883	139.6647	-2.786378
42.38050	139.6652	-2.786488
42.43383	139.6641	-2.786465
42.48383	139.6646	-2.786510
42.53717	139.6653	-2.786590
42.58883	139.6644	-2.786582
42.64050	139.6638	-2.786580
42.69217	139.6642	-2.786552
42.74383	139.6638	-2.786590
42.79716	139.6635	-2.786656
42.84716	139.6642	-2.786808
42.90050	139.6634	-2.787086
42.95216	139.6650	-2.787407
43.00050	139.6654	-2.787696
43.05383	139.6964	-3.399424
43.10550	139.9798	-6.638260
43.15717	140.4654	-10.01552
43.21050	141.0981	-13.18101
43.26050	141.7827	-15.61826
43.31383	142.5848	-17.72793
43.36550	143.4159	-19.34208
43.41716	144.2873	-20.61881
43.47050	145.2208	-21.66002
43.52050	146.1184	-22.44854
43.57383	147.0960	-23.12685
43.62383	148.0264	-23.64980
43.67717	149.0309	-24.11717
43.72883	150.0139	-24.48407
43.78050	151.0038	-24.80257
43.83383	152.0315	-25.09902
43.88383	153.0000	-25.35217
43.93716	154.0372	-25.59250
43.98883	155.0436	-25.80469
44.04050	156.0530	-26.01736
44.09384	157.0977	-26.21176
44.14383	158.0769	-26.40314
44.19717	159.1227	-26.59203
44.24716	160.1066	-26.78813
44.30050	161.1537	-26.97415
44.35217	162.1706	-27.15714
44.40383	163.1880	-27.34677
44.45717	164.2392	-27.53544
44.50717	165.2254	-27.71020
44.56050	166.2767	-27.90446
44.61217	167.2960	-28.08850
44.66383	168.3158	-28.26700
44.71717	169.3683	-28.46060
44.76717	170.3549	-28.64880
44.82050	171.4088	-28.85708
44.87050	172.3952	-29.04035
44.92383	173.4483	-29.24560
44.97550	174.4692	-29.40088
45.02716	175.4918	-29.56261
45.08050	176.5458	-29.73944
45.13050	177.5347	-29.92020
45.18383	178.5886	-30.14007
45.23550	179.6101	-30.33710
45.28717	180.6311	-30.56187
45.33883	181.6510	-30.80077
45.39050	182.6702	-31.03940
45.44383	183.7209	-31.30205
45.49383	184.7072	-31.54650
45.54716	185.7565	-31.84787
45.59883	186.7732	-32.14604
45.65050	187.7888	-32.46122
45.70383	188.8369	-32.80269
45.75383	189.8187	-33.12890
45.80717	190.8654	-33.50683
45.85883	191.8774	-33.91941
45.91050	192.8882	-34.30666
45.96216	193.8980	-34.73852
46.01383	194.9057	-35.20859
46.06717	195.9427	-35.73955
46.11716	196.9145	-36.29521
46.17050	197.9464	-36.90667
46.22217	198.9435	-37.58994
46.27383	199.9366	-38.33342
46.32717	200.9581	-39.20580
46.37717	201.9104	-40.12813
46.43050	202.9200	-41.24611
46.48217	203.8897	-42.46930
46.53383	204.8515	-43.88150
46.58550	205.8031	-45.45242
46.63716	206.7445	-47.27792
46.69050	207.7012	-49.42768
46.74050	208.5844	-51.67283
46.79383	209.5132	-54.21356
46.84550	210.4062	-56.60376
46.89717	211.3025	-58.76544
46.95050	212.2363	-60.86234
47.00050	213.1160	-62.85904
47.05383	214.0516	-65.22597
47.10383	214.9202	-67.62259
47.15717	215.8396	-70.31616
47.20883	216.7235	-72.90547
47.26050	217.6117	-75.15532
47.31383	218.5535	-76.34150
47.36383	219.5038	-75.29796
47.41716	220.6230	-72.25007
47.46884	221.7909	-68.45625
47.52050	223.0289	-63.62526
47.57383	224.3779	-57.36769
47.62383	225.7092	-50.80310
47.67717	227.1308	-45.81441
47.72717	228.4076	-42.63292
47.78050	229.7049	-40.10869
47.83217	230.9097	-38.27910
47.88383	232.0747	-36.89627
47.93716	233.2451	-35.80431
47.98717	234.3208	-35.02969
48.04050	235.4486	-34.39050
48.09217	236.5264	-33.93242
48.14383	237.5940	-33.58188
48.19717	238.6880	-33.31595
48.24716	239.7062	-33.14728
48.30050	240.7886	-33.01000
48.35050	241.7981	-32.93225
48.40383	242.8743	-32.88270
48.45550	243.9136	-32.85480
48.50717	244.9506	-32.83700
48.56050	246.0208	-32.83406
48.61050	247.0228	-32.83340
48.66383	248.0907	-32.83326
48.71550	249.1247	-32.83539
48.76717	250.1588	-32.84046
48.82050	251.2252	-32.86200
48.87050	252.2232	-32.88536
48.92383	253.2897	-32.92978
48.97383	254.2892	-32.95872
49.02716	255.3555	-33.00623
49.07883	256.3881	-33.06334
49.13050	257.4204	-33.11113
49.18383	258.4850	-33.18224
49.23383	259.4838	-33.25038
49.28717	260.5473	-33.30180
49.33883	261.5798	-33.35989
49.39050	262.6111	-33.42487
49.44217	263.6420	-33.47880
49.49383	264.6741	-33.53544
49.54716	265.7380	-33.59258
49.59716	266.7362	-33.64766
49.65050	267.7998	-33.70108
49.70216	268.8315	-33.76422
49.75383	269.8634	-33.80844
49.80717	270.9275	-33.85212
49.85717	271.9262	-33.90042
49.91050	272.9900	-33.94678
49.96216	274.0232	-33.97312
50.01050	274.9870	-34.01888
50.06050	275.8504	-34.83708
50.11383	276.1525	-29.84689
50.16550	276.0935	-21.69658
50.21717	275.8050	-13.86089
50.27050	275.3389	-7.042899
50.32050	274.7863	-1.875326
50.37383	274.0984	2.502969
50.42550	273.3615	5.833894
50.47717	272.5696	8.453736
50.53050	271.7041	10.58109
50.58050	270.8598	12.14968
50.63383	269.9306	13.48174
50.68383	269.0398	14.47640
50.73717	268.0697	15.32345
50.78883	267.1162	15.99136
50.84050	266.1516	16.53500
50.89383	265.1441	16.98316
50.94383	264.1942	17.33600
50.99716	263.1725	17.65440
51.04883	262.1792	17.90099
51.10050	261.1808	18.11757
51.15383	260.1464	18.30770
51.20383	259.1722	18.44815
51.25717	258.1304	18.57687
51.30717	257.1534	18.68516
51.36050	256.1090	18.78388
51.41216	255.0959	18.87819
51.46383	254.0811	18.97058
51.51716	253.0335	19.05203
51.56716	252.0503	19.12064
51.62050	250.9992	19.18946
51.67217	249.9794	19.25014
51.72383	248.9599	19.30599
51.77550	247.9397	19.35549
51.82717	246.9188	19.40416
51.88050	245.8641	19.44732
51.93050	244.8748	19.48421
51.98383	243.8195	19.51794
52.03550	242.7969	19.54699
52.08716	241.7735	19.56896
52.14050	240.7172	19.59561
52.19050	239.7270	19.61914
52.24383	238.6694	19.64682
52.29550	237.6462	19.66936
52.34716	236.6222	19.69830
52.39883	235.5973	19.71976
52.45050	234.5736	19.73974
52.50383	233.5166	19.75863
52.55383	232.5246	19.77669
52.60717	231.4666	19.79145
52.65883	230.4406	19.80815
52.71050	229.4168	19.81944
52.76382	228.3577	19.84074
52.81382	227.3651	19.86091
52.86716	226.3067	19.88060
52.91716	225.3142	19.90191
52.97050	224.2554	19.92549
53.02217	223.2303	19.94446
53.07383	222.2047	19.96502
53.12717	221.1464	19.98367
53.17717	220.1531	20.00788
53.23050	219.0953	20.03683
53.28217	218.0680	20.05558
53.33383	217.0424	20.07217
53.38716	215.9827	20.09067
53.43716	214.9906	20.10414
53.49050	213.9314	20.11750
53.54050	212.9385	20.13024
53.59384	211.8784	20.14506
53.64550	210.8521	20.15473
53.69717	209.8260	20.16634
53.75050	208.7674	20.17710
53.80050	207.7740	20.19024
53.85383	206.7144	20.20499
53.90550	205.6883	20.21679
53.95717	204.6630	20.23074
54.01050	203.6012	20.24775
54.06050	202.6094	20.25656
54.11382	201.5487	20.26830
54.16382	200.5551	20.27973
54.21717	199.4952	20.29041
54.26884	198.4684	20.30199
54.32050	197.4413	20.31354
54.37383	196.3827	20.32434
54.42383	195.3883	20.33750
54.47717	194.3284	20.35450
54.52883	193.3018	20.37142
54.58050	192.2755	20.38406
54.63383	191.2152	20.39812
54.68383	190.2215	20.40797
54.73717	189.1620	20.42241
54.78716	188.1679	20.43306
54.84050	187.1076	20.44730
54.89216	186.0804	20.46083
54.94384	185.0534	20.47104
54.99717	183.9932	20.48069
55.04717	183.0001	20.49184
55.10050	181.9385	20.50242
55.15217	180.9111	20.51206
55.20383	179.8839	20.52422
55.25550	178.8573	20.53903
55.30717	177.8308	20.55585
55.36050	176.7711	20.57774
55.41050	175.7775	20.59896
55.46382	174.7177	20.62254
55.51550	173.6904	20.64047
55.56716	172.6627	20.65297
55.62050	171.6026	20.66473
55.67050	170.6091	20.67777
55.72382	169.5504	20.70450
55.77550	168.5235	20.76616
55.82717	167.4981	20.86488
55.87883	166.4761	21.04744
55.93050	165.4574	21.34543
55.98383	164.4141	21.85795
56.03383	163.4525	22.69798
56.08716	162.4527	24.24617
56.13882	161.5269	26.61718
56.19050	160.6502	29.86322
56.24382	159.7966	33.85422
56.29382	159.0316	37.71980
56.34716	158.2220	41.42738
56.39883	157.4168	44.24244
56.45050	156.5711	46.11836
56.50217	155.6709	47.02707
56.55383	154.7137	47.07620
56.60717	153.6704	46.57510
56.65717	152.6495	45.27684
56.71050	151.5261	43.78937
56.76216	150.4148	42.19127
56.81382	149.2911	40.55824
56.86716	148.1254	38.90295
56.91716	147.0315	37.42359
56.97050	145.8686	35.94751
57.02050	144.7822	34.66272
57.07383	143.6302	33.38891
57.12550	142.5200	32.26439
57.17717	141.4170	31.21961
57.23050	140.2827	30.25882
57.28050	139.2267	29.42538
57.33383	138.1058	28.62471
57.38550	137.0246	27.93056
57.43716	135.9488	27.30392
57.49050	134.8436	26.71790
57.54050	133.8115	26.23422
57.59384	132.7146	25.76370
57.64384	131.6895	25.36826
57.69717	130.5982	24.97782
57.74883	129.5458	24.65142
57.80050	128.4944	24.35772
57.85383	127.4121	24.06454
57.90383	126.3998	23.84102
57.95717	125.3185	23.59474
58.00883	124.2730	23.37902
58.06050	123.2292	23.18832
58.11382	122.1532	22.99748
58.16382	121.1462	22.85476
58.21717	120.0737	22.70990
58.26716	119.0686	22.57892
58.32050	117.9978	22.46252
58.37217	116.9616	22.36203
58.42383	115.9278	22.27494
58.47717	114.8604	22.20801
58.52717	113.8591	22.13345
58.58050	112.7923	22.03342
58.63217	111.7587	21.96306
58.68383	110.7265	21.92369
58.73717	109.6605	21.83752
58.78716	108.6599	21.77844
58.84050	107.5940	21.71657
58.89050	106.5944	21.67060
58.94384	105.5294	21.61609
58.99550	104.4963	21.56731
59.04717	103.4642	21.52088
59.10050	102.3985	21.46853
59.15050	101.4007	21.43248
59.20383	100.3358	21.38861
59.25550	99.30478	21.35017
59.30717	98.27326	21.31788
59.35883	97.24390	21.28641
59.41050	96.21250	21.25249
59.46382	95.14843	21.21602
59.51382	94.15168	21.18387
59.56716	93.08895	21.15440
59.61882	92.05809	21.12073
59.67050	91.02716	21.08902
59.72382	89.96251	21.04125
59.77383	88.96569	21.00872
59.82717	87.90032	20.97302
59.87883	86.86934	20.94030
59.93050	85.83872	20.90281
59.98217	84.80906	20.87352
60.03383	83.77843	20.84683
60.08716	82.71382	20.81584
60.13716	81.71562	20.78844
60.19050	80.65203	20.75916
60.24216	79.62132	20.73116
60.29382	78.59003	20.70429
60.34716	77.52739	20.66850
60.39717	76.53100	20.65009
60.45050	75.46878	20.62804
60.50050	74.47051	20.60830
60.55383	73.40881	20.58305
60.60550	72.37760	20.56364
60.65717	71.34724	20.53573
60.71050	70.28451	20.50891
60.76050	69.28670	20.48274
60.81382	68.22238	20.45621
60.86550	67.19322	20.41880
60.91716	66.16181	20.39424
60.97050	65.09662	20.29412
61.02050	64.09918	20.23445
61.07383	63.03326	20.17905
61.12383	62.03508	20.12529
61.17717	60.97099	20.08115
61.22883	59.93990	20.04653
61.28050	58.90943	20.00784
61.33383	57.84449	19.96808
61.38383	56.84893	19.94084
61.43716	55.78558	19.90644
61.48882	54.75398	19.88421
61.54050	53.72390	19.85301
61.59384	52.66018	19.82961
61.64384	51.66458	19.80055
61.69717	50.60031	19.77249
61.74717	49.60162	19.73790
61.80050	48.53750	19.70215
61.85217	47.50644	19.66402
61.90383	46.47606	19.62313
61.95717	45.40537	19.39798
62.00717	44.40296	19.27377
62.06050	43.33241	19.16161
62.11217	42.29540	19.04709
62.16382	41.25894	18.95746
62.21717	40.18731	18.84724
62.26716	39.18546	18.73670
62.32050	38.11563	18.65406
62.37050	37.11208	18.55236
62.42383	36.04375	18.45698
62.47550	35.00641	18.35832
62.52717	33.97150	18.25928
62.58050	32.90109	18.16954
62.63050	31.89798	18.07241
62.68383	30.82859	17.97659
62.73550	29.79451	17.88633
62.78716	28.75862	17.79479
62.83882	27.72190	17.69078
62.89050	26.68470	17.59333
62.94384	25.61384	17.50082
62.99382	24.60991	17.51407
63.04550	23.60018	18.14099
63.09716	22.95578	14.03166
63.15050	22.76489	6.768602
63.20050	22.88081	1.238855
63.25383	23.24689	-3.149361
63.30550	23.77142	-6.303434
63.35717	24.41848	-8.637836
63.41050	25.18269	-10.45084
63.46050	25.96188	-11.73464
63.51382	26.84506	-12.81307
63.56550	27.73678	-13.61139
63.61716	28.65616	-14.25361
63.66882	29.59611	-14.75983
63.72050	30.55100	-15.18698
63.77383	31.54993	-15.56066
63.82383	32.49380	-15.85359
63.87716	33.51059	-16.13215
63.92883	34.50043	-16.35454
63.98050	35.49610	-16.56094
64.03384	36.52659	-16.75794
64.08384	37.49627	-16.92776
64.13717	38.53315	-17.08630
64.18717	39.50742	-17.24114
64.24050	40.54856	-17.38780
64.29218	41.55838	-17.52904
64.34384	42.57072	-17.66166
64.39717	43.61632	-17.78428
64.44717	44.59815	-17.91188
64.50050	45.64740	-18.03971
64.55218	46.66394	-18.15248
64.60383	47.68157	-18.26931
64.65718	48.73492	-18.38102
64.70717	49.72212	-18.48812
64.76050	50.77653	-18.59776
64.81050	51.76407	-18.69551
64.86384	52.82088	-18.78304
64.91550	53.84505	-18.86183
64.96717	54.86921	-18.94066
65.02050	55.92860	-18.98480
65.07050	56.92344	-19.04170
65.12383	57.98105	-19.12439
65.17550	59.00898	-19.21127
65.22718	60.03463	-19.29835
65.28050	61.09394	-19.41332
65.33050	62.08597	-19.50062
65.38384	63.14495	-19.59603
65.43384	64.13904	-19.68936
65.48717	65.19854	-19.77604
65.53882	66.22574	-19.87169
65.59050	67.25159	-19.96426
65.64384	68.31182	-20.06533
65.69384	69.30612	-20.15284
65.74718	70.36539	-20.24301
65.79884	71.39337	-20.34448
65.85050	72.42174	-20.43798
65.90384	73.48300	-20.52746
65.95384	74.47815	-20.61306
66.00718	75.53897	-20.70870
66.05718	76.53464	-20.79493
66.11050	77.59511	-20.89417
66.16218	78.62338	-20.98976
66.21384	79.65215	-21.08826
66.26716	80.71387	-21.19392
66.31718	81.70782	-21.28882
66.37050	82.76762	-21.38912
66.42218	83.79701	-21.49056
66.47384	84.82508	-21.59497
66.52550	85.85374	-21.69430
66.57718	86.88056	-21.79275
66.63050	87.94318	-21.90476
66.68050	88.93951	-21.99644
66.73384	90.00079	-22.11035
66.78550	91.02957	-22.19944
66.83716	92.05769	-22.29702
66.89050	93.11890	-22.40798
66.94050	94.11534	-22.50409
66.99384	95.17536	-22.61236
67.04550	96.20482	-22.69211
67.09718	97.23582	-22.75849
67.14884	98.26539	-22.85030
67.20050	99.29294	-22.93544
67.25384	100.3551	-23.03943
67.30384	101.3510	-23.13602
67.35718	102.4139	-23.22932
67.40884	103.4417	-23.32303
67.46050	104.4711	-23.43565
67.51384	105.5327	-23.52938
67.56384	106.5279	-23.63213
67.61718	107.5895	-23.73797
67.66718	108.5849	-23.83331
67.72050	109.6467	-23.94292
67.77218	110.6753	-24.03966
67.82384	111.7043	-24.13854
67.87718	112.7657	-24.24381
67.92718	113.7615	-24.33956
67.98050	114.8242	-24.44161
68.03218	115.8529	-24.54002
68.08384	116.8828	-24.63638
68.13718	117.9449	-24.73761
68.18718	118.9418	-24.83038
68.24050	120.0044	-24.93652
68.29050	120.9988	-25.04164
68.34384	122.0613	-25.16084
68.39550	123.0890	-25.26896
68.44718	124.1169	-25.38589
68.50050	125.1790	-25.49566
68.55050	126.1740	-25.60283
68.60384	127.2344	-25.71486
68.65550	128.2618	-25.83078
68.70718	129.2891	-25.93848
68.76050	130.3506	-26.07216
68.81050	131.3456	-26.17886
68.86384	132.4059	-26.29998
68.91382	133.4009	-26.41483
68.96718	134.4626	-26.53629
69.01882	135.4902	-26.65805
69.07050	136.5174	-26.78478
69.12384	137.5790	-26.91494
69.17384	138.5728	-27.03735
69.22718	139.6332	-27.16574
69.27884	140.6620	-27.28717
69.33050	141.6901	-27.40756
69.38384	142.7510	-27.53842
69.43384	143.7451	-27.64944
69.48718	144.8054	-27.78040
69.53718	145.7996	-27.90254
69.59050	146.8600	-28.02885
69.64216	147.8880	-28.14994
69.69384	148.9155	-28.28208
69.74718	149.9756	-28.39941
69.79718	150.9698	-28.52622
69.85050	152.0304	-28.65007
69.90218	153.0573	-28.77859
69.95384	154.0840	-28.90076
70.00550	155.1125	-29.03245
70.05718	156.1394	-29.15242
70.11050	157.2002	-29.27318
70.16050	158.1954	-29.38508
70.21384	159.2567	-29.47672
70.26550	160.2863	-29.57406
70.31718	161.3165	-29.64344
70.37050	162.3799	-29.72126
70.42050	163.3776	-29.77589
70.47384	164.4438	-29.83384
70.52550	165.4753	-29.88112
70.57718	166.5066	-29.94870
70.62884	167.5372	-30.03159
70.68050	168.5680	-30.12737
70.73384	169.6316	-30.23000
70.78384	170.6272	-30.35603
70.83716	171.6896	-30.49315
70.88884	172.7165	-30.63732
70.94050	173.7425	-30.82614
70.99384	174.8009	-30.99688
71.04384	175.7949	-31.19519
71.09718	176.8498	-31.40674
71.14884	177.8708	-31.66096
71.20050	178.8900	-31.93716
71.25218	179.9084	-32.23988
71.30384	180.9247	-32.57718
71.35718	181.9718	-32.96597
71.40718	182.9511	-33.34907
71.46050	183.9946	-33.81700
71.51218	185.0022	-34.29524
71.56384	186.0084	-34.82760
71.61718	187.0424	-35.42595
71.66718	188.0124	-36.04447
71.72050	189.0409	-36.73310
71.77050	190.0042	-37.43777
71.82384	191.0282	-38.22192
71.87550	192.0177	-38.99440
71.92718	193.0062	-39.80164
71.98050	194.0237	-40.64075
72.03050	194.9766	-41.47559
72.08384	195.9901	-42.41920
72.13550	196.9700	-43.39363
72.18718	197.9469	-44.43410
72.24050	198.9508	-45.54989
72.29050	199.8903	-46.63643
72.34384	200.8885	-47.82641
72.39384	201.8250	-48.87280
72.44718	202.8277	-49.85608
72.49884	203.8064	-50.56810
72.55050	204.8004	-50.90277
72.60384	205.8482	-50.67390
72.65384	206.8648	-49.66528
72.70718	207.9923	-47.64852
72.75884	209.1365	-44.94630
72.81050	210.3157	-41.99463
72.86384	211.5519	-39.14425
72.91382	212.7018	-37.12341
72.96718	213.9038	-35.58298
73.01716	215.0031	-34.51696
73.07050	216.1519	-33.69057
73.12218	217.2452	-33.07343
73.17384	218.3242	-32.62796
73.22718	219.4255	-32.29068
73.27718	220.4516	-32.05836
73.33050	221.5380	-31.88432
73.38218	222.5855	-31.78078
73.43384	223.6300	-31.70528
73.48718	224.7040	-31.65015
73.53718	225.7086	-31.63659
73.59050	226.7781	-31.63354
73.64050	227.7806	-31.63289
73.69384	228.8484	-31.63486
73.74550	229.8825	-31.64421
73.79718	230.9160	-31.66628
73.85050	231.9822	-31.72740
73.90050	232.9794	-31.79080
73.95384	234.0448	-31.86152
74.00550	235.0758	-31.92902
74.05718	236.1086	-31.98814
74.10884	237.1399	-32.04093
74.16050	238.1720	-32.10453
74.21384	239.2370	-32.16025
74.26384	240.2358	-32.22518
74.31718	241.3008	-32.29550
74.36884	242.3324	-32.36040
74.42050	243.3643	-32.42126
74.47384	244.4291	-32.47615
74.52384	245.4268	-32.52991
74.57718	246.4920	-32.59247
74.62884	247.5226	-32.64621
74.68050	248.5541	-32.69710
74.73218	249.5855	-32.75239
74.78384	250.6168	-32.81894
74.83716	251.6813	-32.88492
74.88718	252.6786	-32.93689
74.94050	253.7437	-32.99806
74.99218	254.7748	-33.05051
75.04384	255.8061	-33.12410
75.09718	256.8690	-33.19231
75.14718	257.8670	-33.26637
75.20050	258.9306	-33.33844
75.25050	259.9290	-33.39649
75.30384	260.9926	-33.46404
75.35550	262.0244	-33.53016
75.40718	263.0556	-33.58904
75.46050	264.1192	-33.65782
75.51050	265.1167	-33.72561
75.56384	266.1804	-33.80244
75.61550	267.2106	-33.86374
75.66718	268.2410	-33.94332
75.72050	269.3050	-34.01399
75.77050	270.3028	-34.07612
75.82384	271.3668	-34.11920
-2.000000	5.000000	0.0000000