File: 5-C1(1.4mol%)+C20(0.6mol%)/matlab/140-2.txt
CLOSED
Version	1.0
Language	English
Mode	Standard
Run	18
RunSerial	12320
Instrument	DSC Q2000 V24.11 Build 124
Module	DSC Standard Cell RC
Operator
File	\\AE520-1454\Users\dsc\Desktop\Data\31-08-17-2\140-2.001
ProcName
InstSerial	2000-0883
AutoSerial	1293
Sample	140-2
Size	27.6000	mg
PanMass	Not available
PanResist	Automatic Automatic  K/W
PanFactor	Default Default
Method
Comment
Xcomment	Pan: Tzero Aluminum Hermetic
Xcomment	Gas1: Nitrogen 50.0 ml/min
Xcomment	Gas2: Nitrogen 50.0 ml/min
Text
Exotherm	UP
Kcell	1.05230
Cpconst	Standard: 0.938
Calib	-38.6961
TempCal	1	pts	157.46	156.60
TzeroDt	-87.6168 -0.0009 -1.4231
TzeroDtz	-87.6168 0.0057 6.9570
InstCalFile	Tzero: \\Ae520-1454\ta\Data\DSC\Calibration\2017\CALIBRATION\1562_RCS (90)_05_18_2017 10_50_44.TZR
InstCalFile	Baseline: \\Ae520-1454\ta\Data\DSC\Calibration\2017\2017-05-17_Calibration.001
InstCalFile	Sapphire: \\Ae520-1454\ta\Data\DSC\Calibration\2017\2017-05-17_Saphire.001
InstCalDate	Tzero 2017-05-18 Time 10:50:44
TempRange	-87.39 to 398.39 °C at 10.00 °C/min Heat Only
AutoZero	Delta T Offset 0.000 uV
AutoZero	Delta T0 Offset 0.000 uV
MultiptCal	0
MultiPtDesc	0) Not set
AutoCellConst	Calibration Date 2017-05-18 16:59:28
Controls	Gas 1  Event Off  Sampling 0.2
Cell#	RC-01562
CoolingUnit	RCS (90)
SelHeatFlow	Heat Flow T4P (mW)
AutoLidII	Installed
AutoAnalysis	Off
MacroFile
Nsig	3
Sig1	Time (min)
Sig2	Temperature (°C)
Sig3	Heat Flow (mW)
Date	2017-09-01
Time	08:55:15
OrgMethod	1: Equilibrate at 80.00 °C
OrgMethod	2: Isothermal for 3.00 min
OrgMethod	3: Jump to 140.00 °C
OrgMethod	4: Mark end of cycle 1
OrgMethod	5: Isothermal for 40.00 min
OrgMethod	6: Mark end of cycle 2
OrgMethod	7: Ramp 20.00 °C/min to 280.00 °C
OrgMethod	8: Mark end of cycle 3
OrgMethod	9: Ramp 20.00 °C/min to 20.00 °C
OrgMethod	10: Mark end of cycle 4
OrgMethod	11: Ramp 20.00 °C/min to 280.00 °C
OrgMethod	12: Mark end of cycle 5
OrgFile	C:\Users\jarra\Desktop\DSC\5-C1(1.4mol%)+C20(0.6mol%)\140-2.001
StartOfData
4.99994E-4	79.53062	-5.573679
0.05383332	79.61372	-4.475279
0.1055000	79.67614	-3.656925
0.1571666	79.72293	-3.024445
0.2105000	79.76022	-2.526734
0.2605000	79.78662	-2.168145
0.3138333	79.80799	-1.869405
0.3655000	79.82281	-1.648514
0.4171667	79.83484	-1.489690
0.4705000	79.84299	-1.360736
0.5205000	79.84926	-1.273231
0.5738334	79.85339	-1.201621
0.6238334	79.85663	-1.151505
0.6771668	79.85852	-1.113459
0.7288332	79.85978	-1.088106
0.7805000	79.86026	-1.070604
0.8338332	79.86170	-1.060148
0.8838332	79.85971	-1.053879
0.9371668	79.86100	-1.049640
0.9888332	79.85974	-1.046381
1.040500	79.85847	-1.043145
1.093833	79.85924	-1.039843
1.143833	79.85829	-1.036759
1.197166	79.85681	-1.033700
1.247166	79.85755	-1.030961
1.300500	79.85686	-1.028206
1.352166	79.85513	-1.025812
1.403833	79.85369	-1.023661
1.457167	79.85318	-1.021710
1.507167	79.85294	-1.020104
1.560500	79.85284	-1.018632
1.612166	79.85206	-1.017369
1.663834	79.85068	-1.016255
1.717167	79.84990	-1.015311
1.767167	79.84854	-1.014512
1.820500	79.84810	-1.013906
1.870500	79.84710	-1.013496
1.923834	79.84728	-1.013112
1.975500	79.84502	-1.012847
2.027166	79.84530	-1.012817
2.080500	79.84400	-1.012762
2.130500	79.84424	-1.012816
2.183833	79.84210	-1.012958
2.235500	79.84175	-1.013284
2.287166	79.84192	-1.013770
2.338833	79.84165	-1.014300
2.390500	79.84120	-1.014957
2.443833	79.84003	-1.015634
2.493833	79.83978	-1.016436
2.547166	79.83838	-1.017226
2.598834	79.83820	-1.018052
2.650500	79.83796	-1.018918
2.703833	79.83741	-1.019854
2.753833	79.83722	-1.020800
2.807167	79.83668	-1.021762
2.858833	79.83625	-1.022781
2.910500	79.83560	-1.023819
2.962167	79.83532	-1.024863
3.010500	79.83828	-1.053481
3.060500	80.40308	-9.599699
3.113833	82.53912	-24.31162
3.165500	85.23191	-36.77324
3.217166	88.39835	-48.41140
3.270500	92.04118	-58.92622
3.320500	95.71858	-67.37249
3.373834	99.84851	-75.00926
3.425500	104.0027	-81.20702
3.477167	108.2658	-86.40421
3.530500	112.7449	-90.89942
3.580500	116.9878	-94.55243
3.633833	121.5242	-98.04485
3.683833	125.3746	-95.30272
3.737167	128.2044	-83.02145
3.788833	130.2791	-71.79772
3.840500	131.8788	-60.74760
3.893833	133.1730	-50.81104
3.943833	134.1308	-42.96375
3.997166	134.9482	-36.11311
4.048834	135.5820	-30.78052
4.100500	136.0972	-26.53900
4.153834	136.5308	-23.09006
4.203833	136.8647	-20.53956
4.257167	137.1635	-18.41188
4.307167	137.3976	-16.84276
4.360500	137.6086	-15.52677
4.412167	137.7822	-14.52388
4.463834	137.9332	-13.72917
4.517166	138.0652	-13.07166
4.567167	138.1733	-12.59061
4.620500	138.2739	-12.16821
4.672167	138.3590	-11.84688
4.723834	138.4322	-11.58581
4.775500	138.4969	-11.38236
4.827167	138.5539	-11.22188
4.880500	138.6057	-11.08004
4.930500	138.6502	-10.96796
4.983834	138.6920	-10.86330
5.035500	138.7290	-10.77613
5.087167	138.7626	-10.70037
5.140500	138.7938	-10.62745
5.190500	138.8201	-10.56783
5.243834	138.8471	-10.50876
5.295500	138.8688	-10.45052
5.347168	138.8896	-10.40227
5.398834	138.9094	-10.35187
5.450500	138.9266	-10.30403
5.503834	138.9446	-10.25554
5.553834	138.9588	-10.20901
5.607168	138.9734	-10.16266
5.658832	138.9861	-10.11666
5.710500	138.9989	-10.07034
5.763834	139.0103	-10.02209
5.813832	139.0212	-9.975937
5.867168	139.0318	-9.929664
5.917168	139.0401	-9.883570
5.970500	139.0504	-9.834665
6.022168	139.0598	-9.786022
6.073834	139.0674	-9.736459
6.127168	139.0760	-9.685457
6.177166	139.0833	-9.636410
6.230500	139.0915	-9.583697
6.282166	139.0990	-9.530024
6.333832	139.1062	-9.476659
6.387168	139.1135	-9.421997
6.437168	139.1200	-9.367071
6.490500	139.1264	-9.308803
6.540500	139.1321	-9.253819
6.593832	139.1407	-9.195160
6.645500	139.1461	-9.134106
6.697168	139.1517	-9.073250
6.750500	139.1581	-9.009765
6.800500	139.1647	-8.950174
6.853832	139.1710	-8.883926
6.905500	139.1771	-8.819856
6.957168	139.1825	-8.756066
7.010500	139.1891	-8.688053
7.060500	139.1938	-8.624926
7.113834	139.2001	-8.556572
7.163832	139.2059	-8.490516
7.217168	139.2109	-8.420665
7.268832	139.2174	-8.354613
7.320500	139.2227	-8.287609
7.373834	139.2286	-8.216285
7.423834	139.2336	-8.152390
7.477168	139.2396	-8.084320
7.528832	139.2442	-8.019040
7.580500	139.2500	-7.953882
7.633832	139.2547	-7.884872
7.683832	139.2594	-7.822309
7.737168	139.2652	-7.756980
7.787168	139.2695	-7.692221
7.840500	139.2750	-7.625087
7.892168	139.2804	-7.557562
7.943832	139.2849	-7.490066
7.997168	139.2904	-7.420926
8.047168	139.2956	-7.350743
8.100500	139.3007	-7.274850
8.152168	139.3059	-7.200976
8.203834	139.3118	-7.120387
8.255500	139.3174	-7.036793
8.307168	139.3234	-6.952478
8.360500	139.3300	-6.856662
8.410499	139.3364	-6.764380
8.463834	139.3444	-6.664053
8.515500	139.3501	-6.559588
8.567166	139.3579	-6.455036
8.620499	139.3664	-6.340010
8.670500	139.3738	-6.228458
8.723832	139.3824	-6.101059
8.775499	139.3915	-5.969921
8.827168	139.4007	-5.830514
8.878834	139.4108	-5.680508
8.930500	139.4210	-5.521690
8.983832	139.4326	-5.348644
9.033832	139.4438	-5.177656
9.087168	139.4563	-4.983348
9.138834	139.4690	-4.790239
9.190500	139.4824	-4.585826
9.243834	139.4965	-4.372150
9.293834	139.5106	-4.161694
9.347168	139.5254	-3.935647
9.398834	139.5406	-3.710552
9.450500	139.5554	-3.482303
9.502168	139.5704	-3.266438
9.553832	139.5847	-3.055158
9.607166	139.5984	-2.850151
9.657166	139.6104	-2.674518
9.710499	139.6228	-2.509491
9.762168	139.6318	-2.363080
9.813834	139.6424	-2.236150
9.867166	139.6499	-2.118574
9.917168	139.6560	-2.020954
9.970500	139.6638	-1.929362
10.02050	139.6692	-1.851434
10.07383	139.6744	-1.779266
10.12550	139.6792	-1.715489
10.17717	139.6842	-1.659380
10.23050	139.6872	-1.605270
10.28050	139.6912	-1.560952
10.33383	139.6944	-1.515582
10.38550	139.6964	-1.474681
10.43717	139.7002	-1.439334
10.49050	139.7031	-1.402694
10.54050	139.7053	-1.369235
10.59383	139.7090	-1.333876
10.64383	139.7113	-1.302864
10.69717	139.7141	-1.270294
10.74883	139.7166	-1.238957
10.80050	139.7183	-1.206211
10.85383	139.7212	-1.171602
10.90383	139.7234	-1.140042
10.95717	139.7257	-1.105924
11.00883	139.7285	-1.072496
11.06050	139.7309	-1.039443
11.11383	139.7327	-0.9999422
11.16383	139.7352	-0.9633874
11.21717	139.7378	-0.9232736
11.26717	139.7410	-0.8840353
11.32050	139.7437	-0.8400441
11.37217	139.7471	-0.7952035
11.42383	139.7499	-0.7472098
11.47717	139.7525	-0.6981886
11.52717	139.7564	-0.6492524
11.58050	139.7594	-0.5958064
11.63216	139.7630	-0.5431783
11.68383	139.7669	-0.4878248
11.73717	139.7713	-0.4284826
11.78717	139.7758	-0.3690815
11.84050	139.7797	-0.3030264
11.89050	139.7840	-0.2359462
11.94383	139.7887	-0.1620598
11.99550	139.7941	-.08568950
12.04717	139.7991	-4.6366E-3
12.10050	139.8047	0.08074143
12.15050	139.8104	0.1644188
12.20384	139.8164	0.2598040
12.25550	139.8226	0.3510944
12.30717	139.8284	0.4465574
12.35883	139.8352	0.5420401
12.41050	139.8417	0.6393272
12.46383	139.8480	0.7387642
12.51383	139.8554	0.8348676
12.56716	139.8619	0.9331024
12.61884	139.8685	1.028029
12.67050	139.8746	1.121456
12.72383	139.8821	1.217791
12.77383	139.8883	1.304463
12.82717	139.8939	1.399561
12.87883	139.9000	1.481896
12.93050	139.9064	1.561315
12.98216	139.9110	1.641670
13.03383	139.9167	1.714231
13.08717	139.9211	1.790172
13.13717	139.9258	1.856272
13.19050	139.9301	1.922467
13.24216	139.9346	1.984631
13.29384	139.9380	2.043229
13.34717	139.9416	2.098354
13.39717	139.9451	2.146992
13.45050	139.9493	2.199298
13.50050	139.9523	2.244326
13.55383	139.9545	2.288857
13.60550	139.9578	2.332528
13.65717	139.9604	2.372711
13.71050	139.9631	2.411938
13.76050	139.9659	2.449114
13.81383	139.9689	2.487756
13.86550	139.9716	2.523109
13.91716	139.9745	2.557031
13.97050	139.9762	2.593346
14.02050	139.9786	2.624539
14.07384	139.9824	2.656611
14.12384	139.9845	2.685744
14.17717	139.9869	2.717683
14.22884	139.9890	2.748393
14.28050	139.9907	2.776780
14.33383	139.9933	2.804649
14.38383	139.9952	2.829968
14.43716	139.9977	2.858368
14.48883	139.9997	2.882502
14.54050	140.0015	2.908700
14.59383	140.0032	2.932922
14.64383	140.0052	2.954854
14.69717	140.0063	2.976770
14.74717	140.0080	2.996025
14.80050	140.0095	3.015660
14.85217	140.0110	3.033278
14.90383	140.0131	3.050454
14.95717	140.0143	3.067853
15.00717	140.0152	3.081918
15.06050	140.0159	3.095406
15.11217	140.0170	3.107010
15.16383	140.0182	3.117411
15.21716	140.0189	3.127647
15.26717	140.0193	3.135534
15.32050	140.0196	3.143992
15.37050	140.0192	3.151548
15.42383	140.0202	3.159401
15.47550	140.0205	3.166987
15.52717	140.0202	3.174380
15.58050	140.0212	3.181840
15.63050	140.0204	3.188494
15.68383	140.0206	3.195068
15.73550	140.0218	3.200941
15.78717	140.0215	3.206584
15.83883	140.0212	3.211559
15.89050	140.0212	3.215912
15.94384	140.0202	3.219870
15.99383	140.0198	3.222918
16.04716	140.0193	3.225445
16.09883	140.0180	3.227086
16.15050	140.0172	3.227908
16.20383	140.0164	3.228020
16.25383	140.0153	3.227466
16.30716	140.0153	3.225987
16.35883	140.0136	3.222917
16.41050	140.0122	3.218528
16.46216	140.0112	3.211706
16.51383	140.0102	3.203019
16.56716	140.0090	3.192934
16.61716	140.0081	3.181530
16.67050	140.0078	3.167285
16.72216	140.0064	3.155186
16.77383	140.0056	3.141248
16.82716	140.0042	3.122226
16.87716	140.0032	3.104850
16.93050	140.0016	3.088192
16.98216	140.0001	3.071167
17.03383	140.0000	3.053666
17.08550	139.9981	3.037722
17.13716	139.9965	3.023103
17.19050	139.9951	3.005336
17.24050	139.9942	2.989035
17.29383	139.9932	2.971293
17.34550	139.9920	2.955363
17.39716	139.9911	2.938906
17.45050	139.9906	2.925552
17.50050	139.9886	2.914220
17.55383	139.9878	2.902010
17.60383	139.9862	2.890444
17.65716	139.9854	2.878986
17.70883	139.9840	2.867766
17.76050	139.9829	2.856128
17.81383	139.9814	2.842274
17.86383	139.9811	2.831516
17.91716	139.9800	2.819726
17.96883	139.9793	2.809165
18.02050	139.9780	2.798569
18.07383	139.9772	2.787818
18.12383	139.9763	2.778550
18.17716	139.9752	2.768553
18.22716	139.9752	2.758912
18.28050	139.9730	2.748667
18.33216	139.9734	2.738026
18.38383	139.9728	2.727281
18.43716	139.9712	2.716494
18.48716	139.9715	2.706642
18.54050	139.9701	2.696110
18.59216	139.9700	2.685982
18.64383	139.9691	2.675924
18.69716	139.9688	2.665667
18.74716	139.9681	2.656150
18.80050	139.9666	2.646116
18.85050	139.9656	2.636715
18.90383	139.9661	2.626619
18.95550	139.9658	2.617015
19.00716	139.9649	2.607512
19.06050	139.9636	2.597716
19.11050	139.9640	2.588522
19.16383	139.9628	2.578836
19.21550	139.9626	2.569474
19.26716	139.9621	2.560148
19.32050	139.9618	2.550578
19.37050	139.9616	2.541545
19.42383	139.9604	2.531904
19.47383	139.9598	2.522895
19.52716	139.9598	2.513300
19.57883	139.9597	2.504056
19.63050	139.9598	2.494881
19.68383	139.9585	2.485427
19.73383	139.9580	2.476642
19.78717	139.9584	2.467296
19.83883	139.9575	2.458312
19.89050	139.9566	2.449348
19.94216	139.9562	2.440390
19.99383	139.9558	2.431520
20.04716	139.9549	2.422344
20.09716	139.9546	2.413666
20.15050	139.9544	2.404504
20.20216	139.9532	2.395644
20.25383	139.9521	2.386730
20.30716	139.9520	2.377570
20.35716	139.9505	2.368942
20.41050	139.9500	2.359755
20.46216	139.9487	2.350852
20.51383	139.9494	2.341886
20.56550	139.9480	2.332916
20.61716	139.9471	2.323884
20.67050	139.9462	2.314544
20.72050	139.9451	2.305694
20.77383	139.9452	2.296214
20.82550	139.9439	2.286969
20.87716	139.9432	2.277733
20.93050	139.9415	2.267933
20.98050	139.9416	2.258762
21.03383	139.9398	2.248844
21.08383	139.9398	2.239184
21.13716	139.9396	2.229002
21.18883	139.9390	2.217925
21.24050	139.9380	2.208048
21.29383	139.9384	2.197523
21.34383	139.9378	2.187900
21.39716	139.9358	2.177523
21.44883	139.9354	2.167541
21.50050	139.9353	2.157536
21.55383	139.9344	2.147123
21.60383	139.9338	2.136714
21.65716	139.9327	2.125892
21.70717	139.9320	2.115064
21.76050	139.9311	2.103913
21.81216	139.9309	2.093584
21.86383	139.9303	2.083181
21.91716	139.9289	2.072334
21.96716	139.9275	2.062194
22.02050	139.9276	2.050604
22.07216	139.9266	2.039781
22.12383	139.9264	2.028549
22.17717	139.9254	2.017463
22.22716	139.9244	2.006970
22.28050	139.9240	1.995865
22.33050	139.9229	1.985427
22.38383	139.9214	1.974381
22.43550	139.9201	1.963740
22.48716	139.9202	1.952240
22.54050	139.9192	1.941211
22.59050	139.9180	1.930330
22.64383	139.9175	1.918370
22.69550	139.9168	1.906168
22.74716	139.9160	1.893073
22.80050	139.9155	1.879925
22.85050	139.9152	1.868112
22.90383	139.9150	1.856596
22.95383	139.9130	1.845676
23.00716	139.9127	1.834267
23.05883	139.9120	1.823082
23.11050	139.9113	1.812055
23.16383	139.9103	1.800735
23.21383	139.9096	1.789938
23.26716	139.9074	1.778511
23.31883	139.9062	1.767272
23.37050	139.9057	1.755818
23.42216	139.9049	1.743711
23.47383	139.9044	1.732195
23.52717	139.9028	1.719301
23.57716	139.9013	1.708154
23.63050	139.9013	1.695333
23.68216	139.9013	1.683483
23.73383	139.8998	1.671516
23.78717	139.8989	1.656133
23.83716	139.8984	1.642278
23.89050	139.8973	1.625158
23.94216	139.8971	1.610328
23.99383	139.8961	1.596719
24.04550	139.8962	1.583651
24.09716	139.8957	1.570716
24.15050	139.8954	1.557420
24.20050	139.8928	1.545182
24.25383	139.8928	1.530874
24.30550	139.8922	1.516708
24.35716	139.8911	1.502911
24.41050	139.8895	1.487182
24.46050	139.8884	1.472906
24.51383	139.8868	1.457162
24.56550	139.8871	1.441228
24.61716	139.8856	1.427215
24.66883	139.8844	1.412278
24.72050	139.8824	1.396499
24.77383	139.8818	1.377234
24.82383	139.8799	1.362678
24.87716	139.8795	1.345488
24.92883	139.8772	1.329405
24.98050	139.8762	1.309154
25.03383	139.8753	1.289981
25.08383	139.8750	1.269205
25.13716	139.8728	1.250552
25.18716	139.8720	1.231588
25.24050	139.8711	1.209161
25.29216	139.8693	1.191258
25.34383	139.8685	1.174281
25.39716	139.8672	1.157059
25.44716	139.8663	1.141235
25.50050	139.8647	1.122506
25.55217	139.8641	1.105797
25.60383	139.8630	1.088070
25.65716	139.8624	1.072137
25.70716	139.8606	1.057132
25.76050	139.8604	1.040613
25.81050	139.8587	1.025891
25.86383	139.8577	1.007376
25.91550	139.8573	0.9912430
25.96716	139.8560	0.9749878
26.02050	139.8556	0.9585222
26.07050	139.8542	0.9455181
26.12383	139.8534	0.9324851
26.17550	139.8528	0.9207801
26.22717	139.8510	0.9093543
26.28050	139.8500	0.8963219
26.33050	139.8497	0.8816695
26.38383	139.8487	0.8679312
26.43383	139.8487	0.8547553
26.48716	139.8470	0.8418176
26.53883	139.8464	0.8270850
26.59050	139.8449	0.8151514
26.64383	139.8450	0.8009144
26.69383	139.8437	0.7898075
26.74716	139.8421	0.7770751
26.79883	139.8413	0.7663054
26.85050	139.8410	0.7543163
26.90383	139.8397	0.7428489
26.95383	139.8382	0.7318634
27.00716	139.8377	0.7198538
27.05716	139.8372	0.7092915
27.11050	139.8359	0.6977131
27.16217	139.8351	0.6850848
27.21383	139.8349	0.6734600
27.26716	139.8342	0.6610999
27.31716	139.8340	0.6499291
27.37050	139.8320	0.6383419
27.42216	139.8321	0.6267230
27.47383	139.8317	0.6153209
27.52550	139.8308	0.6041601
27.57717	139.8300	0.5931156
27.63050	139.8290	0.5818526
27.68050	139.8290	0.5711970
27.73383	139.8266	0.5599377
27.78550	139.8262	0.5489886
27.83716	139.8252	0.5381207
27.89050	139.8243	0.5270504
27.94050	139.8239	0.5166488
27.99383	139.8232	0.5055341
28.04550	139.8222	0.4943398
28.09716	139.8227	0.4827470
28.14883	139.8218	0.4717038
28.20050	139.8209	0.4608944
28.25383	139.8200	0.4497838
28.30383	139.8204	0.4394083
28.35716	139.8189	0.4284692
28.40883	139.8187	0.4178492
28.46050	139.8180	0.4073649
28.51383	139.8171	0.3967233
28.56383	139.8162	0.3867532
28.61716	139.8149	0.3761100
28.66716	139.8151	0.3662635
28.72050	139.8144	0.3557185
28.77216	139.8129	0.3454532
28.82383	139.8122	0.3347040
28.87716	139.8120	0.3240027
28.92717	139.8113	0.3141594
28.98050	139.8107	0.3036966
29.03216	139.8104	0.2935476
29.08383	139.8102	0.2834294
29.13716	139.8094	0.2730713
29.18717	139.8086	0.2633886
29.24050	139.8079	0.2530944
29.29050	139.8079	0.2435480
29.34383	139.8077	0.2333497
29.39550	139.8070	0.2236508
29.44717	139.8062	0.2140289
29.50050	139.8048	0.2040619
29.55050	139.8044	0.1947817
29.60383	139.8042	0.1849207
29.65550	139.8034	0.1754329
29.70716	139.8020	0.1659108
29.76050	139.8012	0.1561743
29.81050	139.7999	0.1470540
29.86383	139.7996	0.1373961
29.91383	139.7986	0.1282258
29.96716	139.7988	0.1184740
30.01883	139.7980	0.1090434
30.07050	139.7969	0.09959543
30.12383	139.7966	0.08990370
30.17383	139.7960	0.08076339
30.22717	139.7956	0.07120366
30.27883	139.7952	0.06200050
30.33050	139.7935	0.05287186
30.38383	139.7931	0.04355356
30.43383	139.7927	0.03484869
30.48716	139.7915	0.02559925
30.53717	139.7920	0.01684197
30.59050	139.7914	.007491525
30.64216	139.7907	-1.6745E-3
30.69383	139.7906	-.01090831
30.74716	139.7902	-.02044628
30.79716	139.7896	-.02937324
30.85050	139.7900	-.03891438
30.90216	139.7888	-.04811489
30.95383	139.7881	-.05726460
31.00550	139.7874	-.06642253
31.05716	139.7869	-.07559892
31.11050	139.7865	-.08488201
31.16050	139.7854	-.09358282
31.21383	139.7852	-0.1027544
31.26550	139.7848	-0.1115583
31.31716	139.7835	-0.1202283
31.37050	139.7831	-0.1293100
31.42050	139.7822	-0.1377546
31.47383	139.7814	-0.1467541
31.52550	139.7801	-0.1555957
31.57717	139.7808	-0.1645333
31.62883	139.7794	-0.1735130
31.68050	139.7791	-0.1825276
31.73383	139.7777	-0.1919642
31.78383	139.7786	-0.2008652
31.83716	139.7767	-0.2102258
31.88883	139.7770	-0.2193408
31.94050	139.7767	-0.2284238
31.99383	139.7758	-0.2377988
32.04383	139.7749	-0.2466055
32.09716	139.7745	-0.2560017
32.14883	139.7737	-0.2650678
32.20050	139.7732	-0.2741490
32.25217	139.7726	-0.2831765
32.30383	139.7726	-0.2921518
32.35716	139.7713	-0.3013102
32.40716	139.7701	-0.3099032
32.46050	139.7693	-0.3190696
32.51216	139.7691	-0.3279338
32.56383	139.7686	-0.3368385
32.61716	139.7663	-0.3460296
32.66716	139.7660	-0.3547029
32.72050	139.7659	-0.3640829
32.77050	139.7668	-0.3731572
32.82383	139.7653	-0.3826764
32.87550	139.7641	-0.3919849
32.92717	139.7642	-0.4013607
32.98050	139.7643	-0.4110124
33.03050	139.7627	-0.4200478
33.08383	139.7626	-0.4298319
33.13550	139.7627	-0.4391316
33.18716	139.7611	-0.4484054
33.24050	139.7605	-0.4579854
33.29050	139.7608	-0.4670016
33.34384	139.7595	-0.4764936
33.39383	139.7593	-0.4854702
33.44717	139.7585	-0.4949062
33.49883	139.7574	-0.5039830
33.55050	139.7556	-0.5131162
33.60383	139.7560	-0.5225246
33.65383	139.7545	-0.5313432
33.70716	139.7546	-0.5408560
33.75883	139.7544	-0.5501030
33.81050	139.7531	-0.5593440
33.86383	139.7528	-0.5692121
33.91383	139.7532	-0.5783201
33.96716	139.7518	-0.5880795
34.01716	139.7512	-0.5972860
34.07050	139.7506	-0.6070683
34.12216	139.7501	-0.6164624
34.17383	139.7486	-0.6258239
34.22717	139.7482	-0.6353840
34.27716	139.7474	-0.6442432
34.33050	139.7471	-0.6537387
34.38216	139.7464	-0.6629694
34.43384	139.7456	-0.6723620
34.48717	139.7452	-0.6822164
34.53717	139.7448	-0.6915332
34.59050	139.7437	-0.7015476
34.64050	139.7435	-0.7109313
34.69383	139.7423	-0.7209259
34.74550	139.7427	-0.7306644
34.79716	139.7404	-0.7402520
34.85050	139.7401	-0.7501265
34.90050	139.7408	-0.7594796
34.95383	139.7400	-0.7694056
35.00550	139.7392	-0.7791031
35.05716	139.7389	-0.7887920
35.10883	139.7377	-0.7985359
35.16050	139.7374	-0.8083111
35.21383	139.7368	-0.8184368
35.26383	139.7361	-0.8279339
35.31716	139.7354	-0.8380242
35.36883	139.7348	-0.8478512
35.42050	139.7353	-0.8575201
35.47383	139.7330	-0.8674051
35.52383	139.7341	-0.8767746
35.57717	139.7325	-0.8866309
35.62883	139.7317	-0.8961742
35.68050	139.7309	-0.9057684
35.73216	139.7304	-0.9153015
35.78383	139.7302	-0.9248590
35.83716	139.7299	-0.9346222
35.88716	139.7287	-0.9438754
35.94050	139.7276	-0.9537222
35.99216	139.7268	-0.9633126
36.04383	139.7266	-0.9729294
36.09716	139.7259	-0.9827625
36.14717	139.7251	-0.9919306
36.20050	139.7243	-1.001660
36.25050	139.7236	-1.010670
36.30383	139.7218	-1.020303
36.35550	139.7215	-1.029500
36.40716	139.7204	-1.038610
36.46050	139.7200	-1.048122
36.51050	139.7192	-1.056935
36.56383	139.7181	-1.066345
36.61550	139.7177	-1.075439
36.66716	139.7168	-1.084528
36.72050	139.7161	-1.093890
36.77050	139.7157	-1.102724
36.82383	139.7153	-1.112377
36.87383	139.7151	-1.121508
36.92717	139.7142	-1.131117
36.97883	139.7140	-1.140259
37.03050	139.7143	-1.149287
37.08383	139.7141	-1.158605
37.13383	139.7133	-1.167174
37.18716	139.7126	-1.176230
37.23883	139.7120	-1.184941
37.29050	139.7120	-1.193611
37.34384	139.7108	-1.202507
37.39383	139.7117	-1.210890
37.44717	139.7101	-1.219618
37.49716	139.7098	-1.227742
37.55050	139.7097	-1.236446
37.60217	139.7086	-1.244614
37.65383	139.7088	-1.252670
37.70716	139.7079	-1.260953
37.75716	139.7070	-1.268702
37.81050	139.7072	-1.276991
37.86217	139.7069	-1.284914
37.91383	139.7066	-1.292791
37.96716	139.7048	-1.300858
38.01716	139.7054	-1.308419
38.07050	139.7040	-1.316306
38.12050	139.7040	-1.323545
38.17383	139.7040	-1.331224
38.22550	139.7036	-1.338668
38.27716	139.7028	-1.346054
38.33050	139.7014	-1.353631
38.38050	139.7012	-1.360687
38.43384	139.7020	-1.368218
38.48550	139.7013	-1.375318
38.53717	139.7013	-1.382376
38.58883	139.7005	-1.389241
38.64050	139.7000	-1.396035
38.69383	139.6988	-1.402900
38.74383	139.6989	-1.409247
38.79716	139.6986	-1.415974
38.84883	139.6975	-1.422458
38.90050	139.6976	-1.428974
38.95383	139.6980	-1.435679
39.00383	139.6978	-1.441962
39.05716	139.6974	-1.448568
39.10883	139.6966	-1.454946
39.16050	139.6961	-1.461279
39.21216	139.6961	-1.467524
39.26383	139.6958	-1.473700
39.31716	139.6958	-1.479961
39.36716	139.6954	-1.485819
39.42050	139.6951	-1.491946
39.47217	139.6958	-1.497831
39.52383	139.6942	-1.503511
39.57717	139.6953	-1.509322
39.62717	139.6938	-1.514656
39.68050	139.6935	-1.520230
39.73216	139.6939	-1.525556
39.78383	139.6939	-1.530740
39.83550	139.6926	-1.535878
39.88716	139.6919	-1.540941
39.94050	139.6919	-1.546074
39.99050	139.6913	-1.550779
40.04383	139.6915	-1.555778
40.09550	139.6904	-1.560509
40.14717	139.6903	-1.565240
40.20050	139.6898	-1.570176
40.25050	139.6895	-1.574754
40.30383	139.6897	-1.579670
40.35383	139.6906	-1.584254
40.40716	139.6894	-1.589104
40.45883	139.6895	-1.593693
40.51050	139.6898	-1.598176
40.56383	139.6887	-1.602632
40.61383	139.6884	-1.606849
40.66716	139.6894	-1.611281
40.71884	139.6886	-1.615428
40.77050	139.6887	-1.619529
40.82383	139.6879	-1.623751
40.87383	139.6882	-1.627630
40.92717	139.6885	-1.631740
40.97717	139.6874	-1.635507
41.03050	139.6867	-1.639346
41.08217	139.6868	-1.643010
41.13383	139.6862	-1.646564
41.18716	139.6862	-1.650169
41.23717	139.6854	-1.653632
41.29050	139.6855	-1.657282
41.34217	139.6848	-1.660828
41.39383	139.6851	-1.664443
41.44717	139.6851	-1.668172
41.49716	139.6848	-1.671703
41.55050	139.6842	-1.675312
41.60050	139.6847	-1.678770
41.65383	139.6852	-1.682329
41.70550	139.6849	-1.685718
41.75717	139.6844	-1.689064
41.81050	139.6850	-1.692516
41.86050	139.6845	-1.695663
41.91383	139.6844	-1.698980
41.96550	139.6842	-1.702089
42.01717	139.6844	-1.705160
42.07050	139.6842	-1.708256
42.12050	139.6841	-1.711157
42.17383	139.6845	-1.714133
42.22383	139.6828	-1.716880
42.27716	139.6842	-1.719823
42.32883	139.6835	-1.722632
42.38050	139.6833	-1.725414
42.43383	139.6838	-1.728233
42.48383	139.6832	-1.730746
42.53717	139.6822	-1.733475
42.58883	139.6830	-1.736091
42.64050	139.6818	-1.738634
42.69217	139.6824	-1.741170
42.74383	139.6820	-1.743629
42.79716	139.6818	-1.746104
42.84716	139.6816	-1.748373
42.90050	139.6814	-1.750725
42.95216	139.6808	-1.753025
43.00050	139.6810	-1.755188
43.05383	139.7048	-2.521409
43.10550	139.9573	-6.208230
43.15717	140.4285	-9.628282
43.21050	141.0600	-12.61570
43.26050	141.7547	-14.75040
43.31383	142.5722	-16.50037
43.36550	143.4210	-17.77724
43.41716	144.3093	-18.73466
43.47050	145.2577	-19.52189
43.52050	146.1669	-20.10940
43.57383	147.1535	-20.61142
43.62383	148.0916	-20.97257
43.67717	149.1015	-21.30582
43.72883	150.0886	-21.56709
43.78050	151.0806	-21.79327
43.83383	152.1119	-21.98006
43.88383	153.0816	-22.14440
43.93716	154.1202	-22.30093
43.98883	155.1284	-22.44125
44.04050	156.1392	-22.58268
44.09384	157.1832	-22.72235
44.14383	158.1629	-22.86945
44.19717	159.2095	-23.00564
44.24716	160.1907	-23.14670
44.30050	161.2380	-23.28528
44.35217	162.2545	-23.40568
44.40383	163.2714	-23.53237
44.45717	164.3228	-23.63228
44.50717	165.3115	-23.70295
44.56050	166.3669	-23.78022
44.61217	167.3911	-23.82595
44.66383	168.4162	-23.87308
44.71717	169.4735	-23.94538
44.76717	170.4648	-24.01717
44.82050	171.5233	-24.10440
44.87050	172.5141	-24.18174
44.92383	173.5736	-24.26206
44.97550	174.5984	-24.33136
45.02716	175.6242	-24.41908
45.08050	176.6822	-24.52173
45.13050	177.6734	-24.62312
45.18383	178.7314	-24.74677
45.23550	179.7567	-24.87008
45.28717	180.7794	-25.00230
45.33883	181.8033	-25.16817
45.39050	182.8248	-25.34896
45.44383	183.8804	-25.54665
45.49383	184.8669	-25.74547
45.54716	185.9204	-25.98604
45.59883	186.9390	-26.22191
45.65050	187.9568	-26.50737
45.70383	189.0050	-26.80377
45.75383	189.9876	-27.11346
45.80717	191.0340	-27.46821
45.85883	192.0454	-27.85889
45.91050	193.0570	-28.26706
45.96216	194.0644	-28.69790
46.01383	195.0729	-29.13530
46.06717	196.1099	-29.65966
46.11716	197.0809	-30.21141
46.17050	198.1124	-30.83970
46.22217	199.1088	-31.51235
46.27383	200.1019	-32.25045
46.32717	201.1234	-33.10837
46.37717	202.0758	-34.02520
46.43050	203.0860	-35.12891
46.48217	204.0565	-36.35850
46.53383	205.0162	-37.81080
46.58550	205.9658	-39.48712
46.63716	206.9014	-41.55008
46.69050	207.8499	-43.70912
46.74050	208.7283	-46.09678
46.79383	209.6492	-48.87776
46.84550	210.5275	-51.71418
46.89717	211.3970	-54.60383
46.95050	212.2924	-57.48187
47.00050	213.1340	-59.94963
47.05383	214.0439	-62.27626
47.10383	214.9095	-64.27821
47.15717	215.8433	-66.31328
47.20883	216.7598	-67.96407
47.26050	217.6988	-68.83468
47.31383	218.7170	-68.17024
47.36383	219.7493	-65.47888
47.41716	220.9486	-61.22439
47.46884	222.1851	-56.41660
47.52050	223.4750	-51.06602
47.57383	224.8562	-44.64416
47.62383	226.0520	-43.26078
47.67717	227.4530	-36.81945
47.72717	228.6953	-34.50840
47.78050	229.9546	-32.71075
47.83217	231.1237	-31.45986
47.88383	232.2564	-30.53012
47.93716	233.3990	-29.84911
47.98717	234.4510	-29.37844
48.04050	235.5571	-29.01013
48.09217	236.6196	-28.76862
48.14383	237.6735	-28.59490
48.19717	238.7568	-28.47912
48.24716	239.7660	-28.40538
48.30050	240.8408	-28.36652
48.35050	241.8457	-28.35176
48.40383	242.9139	-28.34490
48.45550	243.9494	-28.34484
48.50717	244.9838	-28.34588
48.56050	246.0489	-28.35135
48.61050	247.0494	-28.36840
48.66383	248.1158	-28.38855
48.71550	249.1482	-28.42131
48.76717	250.1794	-28.45865
48.82050	251.2450	-28.50468
48.87050	252.2430	-28.54859
48.92383	253.3088	-28.59778
48.97383	254.3074	-28.63151
49.02716	255.3730	-28.69041
49.07883	256.4036	-28.74796
49.13050	257.4354	-28.79608
49.18383	258.4993	-28.83738
49.23383	259.4973	-28.88100
49.28717	260.5608	-28.92394
49.33883	261.5912	-28.97018
49.39050	262.6228	-29.02785
49.44217	263.6544	-29.06250
49.49383	264.6844	-29.13489
49.54716	265.7482	-29.17758
49.59716	266.7472	-29.22135
49.65050	267.8119	-29.25268
49.70216	268.8442	-29.27385
49.75383	269.8760	-29.29021
49.80717	270.9409	-29.37216
49.85717	271.9384	-29.40723
49.91050	273.0035	-29.43013
49.96216	274.0356	-29.44278
50.01050	274.9998	-29.47052
50.06050	275.8912	-30.95760
50.11383	276.2544	-25.44103
50.16550	276.2076	-17.11068
50.21717	275.9054	-9.606600
50.27050	275.4137	-3.325032
50.32050	274.8307	1.316244
50.37383	274.1144	5.152207
50.42550	273.3508	7.989135
50.47717	272.5334	10.15033
50.53050	271.6451	11.78088
50.58050	270.7824	12.97865
50.63383	269.8390	13.95478
50.68383	268.9372	14.71318
50.73717	267.9613	15.33998
50.78883	267.0025	15.80086
50.84050	266.0344	16.15867
50.89383	265.0250	16.42197
50.94383	264.0700	16.61876
50.99716	263.0476	16.78687
51.04883	262.0514	16.91875
51.10050	261.0527	17.03664
51.15383	260.0168	17.13039
51.20383	259.0444	17.20211
51.25717	258.0046	17.27553
51.30717	257.0283	17.33131
51.36050	255.9850	17.38559
51.41216	254.9738	17.43746
51.46383	253.9603	17.49095
51.51716	252.9126	17.52984
51.56716	251.9291	17.56734
51.62050	250.8788	17.59738
51.67217	249.8618	17.62548
51.72383	248.8439	17.65719
51.77550	247.8252	17.68609
51.82717	246.8058	17.70877
51.88050	245.7527	17.73219
51.93050	244.7644	17.75303
51.98383	243.7106	17.77031
52.03550	242.6890	17.78781
52.08716	241.6679	17.79970
52.14050	240.6116	17.81574
52.19050	239.6228	17.82785
52.24383	238.5655	17.84224
52.29550	237.5414	17.85032
52.34716	236.5176	17.85991
52.39883	235.4938	17.86596
52.45050	234.4686	17.87206
52.50383	233.4108	17.87825
52.55383	232.4194	17.88388
52.60717	231.3610	17.89011
52.65883	230.3366	17.89623
52.71050	229.3114	17.90231
52.76382	228.2530	17.90979
52.81382	227.2600	17.91766
52.86716	226.2022	17.92476
52.91716	225.2105	17.93412
52.97050	224.1528	17.94729
53.02217	223.1271	17.95777
53.07383	222.1022	17.97000
53.12717	221.0434	17.98169
53.17717	220.0510	17.99168
53.23050	218.9926	18.00461
53.28217	217.9666	18.01461
53.33383	216.9406	18.02501
53.38716	215.8812	18.03434
53.43716	214.8877	18.04274
53.49050	213.8294	18.05179
53.54050	212.8355	18.06014
53.59384	211.7769	18.06870
53.64550	210.7496	18.07704
53.69717	209.7234	18.08526
53.75050	208.6627	18.09410
53.80050	207.6699	18.10204
53.85383	206.6108	18.11043
53.90550	205.5846	18.11838
53.95717	204.5589	18.12668
54.01050	203.4990	18.13495
54.06050	202.5059	18.14249
54.11382	201.4456	18.15100
54.16382	200.4528	18.15853
54.21717	199.3941	18.16682
54.26884	198.3672	18.17496
54.32050	197.3397	18.18296
54.37383	196.2808	18.19097
54.42383	195.2870	18.19888
54.47717	194.2277	18.20795
54.52883	193.2007	18.21619
54.58050	192.1750	18.22421
54.63383	191.1142	18.23243
54.68383	190.1208	18.23998
54.73717	189.0600	18.24789
54.78716	188.0664	18.25522
54.84050	187.0057	18.26346
54.89216	185.9797	18.27105
54.94384	184.9531	18.27841
54.99717	183.8918	18.28590
55.04717	182.8988	18.29285
55.10050	181.8380	18.30019
55.15217	180.8121	18.30706
55.20383	179.7852	18.31514
55.25550	178.7582	18.32247
55.30717	177.7302	18.33104
55.36050	176.6718	18.34150
55.41050	175.6782	18.35784
55.46382	174.6172	18.37228
55.51550	173.5902	18.38778
55.56716	172.5638	18.40633
55.62050	171.5024	18.43368
55.67050	170.5098	18.46914
55.72382	169.4524	18.54820
55.77550	168.4282	18.68391
55.82717	167.4066	18.89225
55.87883	166.3909	19.22971
55.93050	165.3859	19.81878
55.98383	164.3671	20.89093
56.03383	163.4404	22.55222
56.08716	162.4952	25.22406
56.13882	161.6338	28.71491
56.19050	160.8222	32.84300
56.24382	160.0206	37.18289
56.29382	159.2747	40.81695
56.34716	158.4543	43.80580
56.39883	157.6124	45.62088
56.45050	156.7117	46.39715
56.50217	155.7472	46.19484
56.55383	154.7231	45.19417
56.60717	153.6127	43.57363
56.65717	152.5343	41.71689
56.71050	151.3584	39.57645
56.76216	150.2041	37.48644
56.81382	149.0459	35.47203
56.86716	147.8525	33.53122
56.91716	146.7392	31.84814
56.97050	145.5595	30.23830
57.02050	144.4621	28.86339
57.07383	143.3038	27.56290
57.12550	142.1920	26.46452
57.17717	141.0894	25.50070
57.23050	139.9591	24.63512
57.28050	138.9091	23.92369
57.33383	137.7946	23.26520
57.38550	136.7236	22.71888
57.43716	135.6568	22.24453
57.49050	134.5606	21.82408
57.54050	133.5382	21.49202
57.59384	132.4516	21.18060
57.64384	131.4360	20.92706
57.69717	130.3566	20.71894
57.74883	129.3134	20.53567
57.80050	128.2720	20.38659
57.85383	127.2022	20.25864
57.90383	126.1966	20.14217
57.95717	125.1227	19.82124
58.00883	124.0797	19.63280
58.06050	123.0401	19.49620
58.11382	121.9678	19.35287
58.16382	120.9647	19.24257
58.21717	119.8947	19.14204
58.26716	118.8922	19.05858
58.32050	117.8237	18.96251
58.37217	116.7888	18.87959
58.42383	115.7537	18.80300
58.47717	114.6872	18.72700
58.52717	113.6880	18.66328
58.58050	112.6218	18.58951
58.63217	111.5896	18.54552
58.68383	110.5564	18.47206
58.73717	109.4904	18.39966
58.78716	108.4917	18.33582
58.84050	107.4238	18.26816
58.89050	106.4257	18.20671
58.94384	105.3593	18.14495
58.99550	104.3268	18.09009
59.04717	103.2947	18.04191
59.10050	102.2302	17.98614
59.15050	101.2332	17.94157
59.20383	100.1669	17.89148
59.25550	99.13528	17.83562
59.30717	98.10330	17.78122
59.35883	97.07149	17.72748
59.41050	96.03978	17.67611
59.46382	94.97528	17.61016
59.51382	93.97626	17.55943
59.56716	92.91132	17.51201
59.61882	91.87856	17.46386
59.67050	90.84716	17.39439
59.72382	89.78184	17.33525
59.77383	88.78442	17.28501
59.82717	87.71785	17.24166
59.87883	86.68578	17.18316
59.93050	85.65278	17.12420
59.98217	84.62053	17.06455
60.03383	83.58895	17.01414
60.08716	82.52300	16.96496
60.13716	81.52441	16.91096
60.19050	80.45896	16.85662
60.24216	79.42711	16.80600
60.29382	78.39456	16.75847
60.34716	77.32972	16.71000
60.39717	76.33176	16.66830
60.45050	75.26489	16.62626
60.50050	74.26747	16.57797
60.55383	73.20175	16.52795
60.60550	72.16950	16.47205
60.65717	71.13750	16.42424
60.71050	70.07288	16.36853
60.76050	69.07386	16.32446
60.81382	68.00845	16.26956
60.86550	66.97734	16.22158
60.91716	65.94450	16.14398
60.97050	64.87860	16.10690
61.02050	63.88000	16.05974
61.07383	62.81348	16.01042
61.12383	61.81385	15.95089
61.17717	60.74840	15.89527
61.22883	59.71612	15.84814
61.28050	58.68472	15.78830
61.33383	57.61719	15.72841
61.38383	56.61775	15.67296
61.43716	55.55317	15.63135
61.48882	54.52050	15.56758
61.54050	53.48724	15.50356
61.59384	52.42170	15.45182
61.64384	51.42280	15.39078
61.69717	50.35622	15.33257
61.74717	49.35768	15.28364
61.80050	48.29039	15.21156
61.85217	47.25644	15.10021
61.90383	46.22168	15.02723
61.95717	45.15437	14.96020
62.00717	44.15287	14.89830
62.06050	43.08548	14.82781
62.11217	42.05227	14.76279
62.16382	41.01783	14.69519
62.21717	39.95112	14.61720
62.26716	38.94982	14.54692
62.32050	37.88170	14.44238
62.37050	36.88061	14.36230
62.42383	35.81287	14.27350
62.47550	34.77698	14.19268
62.52717	33.74109	14.09994
62.58050	32.67128	14.01079
62.63050	31.66953	13.91828
62.68383	30.60082	13.83749
62.73550	29.56492	13.75237
62.78716	28.53040	13.66937
62.83882	27.49405	13.59994
62.89050	26.45904	13.49998
62.94384	25.38947	13.41542
62.99382	24.38590	13.42474
63.04550	23.37942	13.89402
63.09716	22.79341	11.08426
63.15050	22.68363	5.303818
63.20050	22.86552	0.8265068
63.25383	23.28605	-2.795275
63.30550	23.85151	-5.417455
63.35717	24.53268	-7.352121
63.41050	25.32092	-8.854003
63.46050	26.12162	-9.904804
63.51382	27.02150	-10.75253
63.56550	27.92682	-11.38699
63.61716	28.85515	-11.87165
63.66882	29.80358	-12.25998
63.72050	30.76516	-12.56566
63.77383	31.76736	-12.83185
63.82383	32.71674	-13.03016
63.87716	33.73530	-13.20861
63.92883	34.72790	-13.36178
63.98050	35.72335	-13.49046
64.03384	36.75504	-13.61102
64.08384	37.72534	-13.71542
64.13717	38.76087	-13.81156
64.18717	39.73750	-13.89506
64.24050	40.77984	-13.97004
64.29218	41.78963	-14.05396
64.34384	42.80160	-14.12976
64.39717	43.84750	-14.20457
64.44717	44.83063	-14.26500
64.50050	45.87984	-14.32192
64.55218	46.89776	-14.37571
64.60383	47.91714	-14.44176
64.65718	48.96939	-14.49926
64.70717	49.95563	-14.55818
64.76050	51.00946	-14.63461
64.81050	51.99724	-14.69819
64.86384	53.05164	-14.76455
64.91550	54.07466	-14.82751
64.96717	55.09693	-14.89667
65.02050	56.15224	-14.96176
65.07050	57.14232	-15.03115
65.12383	58.19810	-15.10132
65.17550	59.22218	-15.17119
65.22718	60.24526	-15.24124
65.28050	61.30346	-15.32519
65.33050	62.29490	-15.39046
65.38384	63.35261	-15.46740
65.43384	64.34430	-15.53416
65.48717	65.40317	-15.60131
65.53882	66.43116	-15.67674
65.59050	67.45722	-15.74149
65.64384	68.51678	-15.81479
65.69384	69.50989	-15.87976
65.74718	70.57134	-15.95477
65.79884	71.59708	-16.02809
65.85050	72.62397	-16.10272
65.90384	73.68472	-16.17657
65.95384	74.67821	-16.24724
66.00718	75.73960	-16.32107
66.05718	76.73279	-16.39616
66.11050	77.79294	-16.48611
66.16218	78.82081	-16.56452
66.21384	79.84714	-16.64337
66.26716	80.90684	-16.73214
66.31718	81.90218	-16.81378
66.37050	82.96174	-16.90644
66.42218	83.98934	-17.00562
66.47384	85.01689	-17.10393
66.52550	86.04462	-17.19731
66.57718	87.07197	-17.27446
66.63050	88.13344	-17.36286
66.68050	89.12676	-17.43496
66.73384	90.18851	-17.52523
66.78550	91.21656	-17.61002
66.83716	92.24374	-17.69049
66.89050	93.30499	-17.79009
66.94050	94.29882	-17.87321
66.99384	95.35918	-17.96263
67.04550	96.38869	-18.04614
67.09718	97.41785	-18.12697
67.14884	98.44590	-18.21996
67.20050	99.47330	-18.30291
67.25384	100.5357	-18.38751
67.30384	101.5289	-18.47513
67.35718	102.5907	-18.56894
67.40884	103.6187	-18.65460
67.46050	104.6462	-18.74974
67.51384	105.7069	-18.84939
67.56384	106.7009	-18.93869
67.61718	107.7619	-19.03429
67.66718	108.7564	-19.12708
67.72050	109.8171	-19.23338
67.77218	110.8448	-19.32502
67.82384	111.8727	-19.42810
67.87718	112.9336	-19.52068
67.92718	113.9284	-19.61360
67.98050	114.9894	-19.71648
68.03218	116.0174	-19.80815
68.08384	117.0455	-19.90206
68.13718	118.1067	-20.00498
68.18718	119.1024	-20.09042
68.24050	120.1643	-20.19615
68.29050	121.1582	-20.29244
68.34384	122.2193	-20.40901
68.39550	123.2472	-20.51369
68.44718	124.2738	-20.61879
68.50050	125.3342	-20.73293
68.55050	126.3295	-20.83017
68.60384	127.3898	-20.93646
68.65550	128.4167	-21.04594
68.70718	129.4447	-21.15185
68.76050	130.5049	-21.26016
68.81050	131.4998	-21.37464
68.86384	132.5590	-21.49320
68.91382	133.5527	-21.60398
68.96718	134.6115	-21.72756
69.01882	135.6396	-21.85779
69.07050	136.6645	-21.98101
69.12384	137.7258	-22.10652
69.17384	138.7196	-22.22739
69.22718	139.7789	-22.35242
69.27884	140.8064	-22.47791
69.33050	141.8349	-22.60290
69.38384	142.8937	-22.71994
69.43384	143.8879	-22.84074
69.48718	144.9476	-22.96486
69.53718	145.9413	-23.08360
69.59050	147.0008	-23.21180
69.64216	148.0267	-23.33925
69.69384	149.0522	-23.46274
69.74718	150.1109	-23.59156
69.79718	151.1040	-23.70868
69.85050	152.1624	-23.83434
69.90218	153.1895	-23.96556
69.95384	154.2150	-24.08848
70.00550	155.2418	-24.21347
70.05718	156.2693	-24.34297
70.11050	157.3280	-24.46202
70.16050	158.3206	-24.57974
70.21384	159.3804	-24.67952
70.26550	160.4083	-24.78034
70.31718	161.4372	-24.83834
70.37050	162.4992	-24.89882
70.42050	163.4954	-24.94631
70.47384	164.5602	-24.99061
70.52550	165.5920	-25.02035
70.57718	166.6227	-25.05992
70.62884	167.6544	-25.10922
70.68050	168.6855	-25.16776
70.73384	169.7482	-25.25201
70.78384	170.7455	-25.34755
70.83716	171.8076	-25.46782
70.88884	172.8352	-25.58696
70.94050	173.8607	-25.72234
70.99384	174.9207	-25.87665
71.04384	175.9134	-26.04352
71.09718	176.9700	-26.21838
71.14884	177.9935	-26.41974
71.20050	179.0168	-26.64639
71.25218	180.0359	-26.90881
71.30384	181.0546	-27.18595
71.35718	182.1044	-27.51700
71.40718	183.0869	-27.86621
71.46050	184.1320	-28.26712
71.51218	185.1432	-28.71111
71.56384	186.1520	-29.17505
71.61718	187.1880	-29.71820
71.66718	188.1581	-30.26858
71.72050	189.1907	-30.90984
71.77050	190.1562	-31.51378
71.82384	191.1841	-32.23209
71.87550	192.1776	-32.94108
71.92718	193.1690	-33.67273
71.98050	194.1905	-34.45148
72.03050	195.1475	-35.22382
72.08384	196.1650	-36.10753
72.13550	197.1478	-37.02774
72.18718	198.1277	-37.99922
72.24050	199.1348	-39.07480
72.29050	200.0767	-40.11447
72.34384	201.0768	-41.27008
72.39384	202.0149	-42.31453
72.44718	203.0166	-43.29934
72.49884	203.9932	-44.04834
72.55050	204.9826	-44.39340
72.60384	206.0304	-44.14140
72.65384	207.0444	-43.04111
72.70718	208.1713	-41.02153
72.75884	209.3075	-38.36682
72.81050	210.4828	-35.30944
72.86384	211.7194	-32.33044
72.91382	212.8720	-30.28376
72.96718	214.0733	-28.82759
73.01716	215.1697	-27.88230
73.07050	216.3132	-27.15316
73.12218	217.4023	-26.63780
73.17384	218.4758	-26.26083
73.22718	219.5740	-26.00752
73.27718	220.5947	-25.82134
73.33050	221.6777	-25.69609
73.38218	222.7224	-25.62741
73.43384	223.7624	-25.57812
73.48718	224.8342	-25.54389
73.53718	225.8366	-25.53594
73.59050	226.9053	-25.53536
73.64050	227.9070	-25.53559
73.69384	228.9733	-25.53828
73.74550	230.0061	-25.54708
73.79718	231.0381	-25.57621
73.85050	232.1028	-25.62607
73.90050	233.1008	-25.67846
73.95384	234.1660	-25.72547
74.00550	235.1977	-25.77932
74.05718	236.2286	-25.81770
74.10884	237.2596	-25.86433
74.16050	238.2914	-25.91320
74.21384	239.3549	-25.96320
74.26384	240.3530	-26.01734
74.31718	241.4168	-26.07146
74.36884	242.4492	-26.12500
74.42050	243.4806	-26.18325
74.47384	244.5434	-26.22996
74.52384	245.5423	-26.27914
74.57718	246.6055	-26.32991
74.62884	247.6363	-26.37334
74.68050	248.6676	-26.41519
74.73218	249.6994	-26.46091
74.78384	250.7304	-26.50532
74.83716	251.7952	-26.55905
74.88718	252.7917	-26.63108
74.94050	253.8557	-26.67263
74.99218	254.8856	-26.74965
75.04384	255.9164	-26.78716
75.09718	256.9789	-26.87036
75.14718	257.9760	-26.91602
75.20050	259.0394	-26.98265
75.25050	260.0362	-27.04904
75.30384	261.0997	-27.08728
75.35550	262.1289	-27.25058
75.40718	263.1550	-27.49070
75.46050	264.2124	-27.65014
75.51050	265.2042	-27.74241
75.56384	266.2656	-27.79140
75.61550	267.2975	-27.77724
75.66718	268.3286	-27.80651
75.72050	269.3940	-27.80398
75.77050	270.3930	-27.80286
75.82384	271.4584	-27.80427
-2.000000	5.000000	0.0000000