File: 5-C1(1.4mol%)+C20(0.6mol%)/matlab/150-2.txt
CLOSED
Version	1.0
Language	English
Mode	Standard
Run	20
RunSerial	12322
Instrument	DSC Q2000 V24.11 Build 124
Module	DSC Standard Cell RC
Operator
File	\\AE520-1454\Users\dsc\Desktop\Data\31-08-17-2\150-2.001
ProcName
InstSerial	2000-0883
AutoSerial	1293
Sample	150-2
Size	28.5000	mg
PanMass	Not available
PanResist	Automatic Automatic  K/W
PanFactor	Default Default
Method
Comment
Xcomment	Pan: Tzero Aluminum Hermetic
Xcomment	Gas1: Nitrogen 50.0 ml/min
Xcomment	Gas2: Nitrogen 50.0 ml/min
Text
Exotherm	UP
Kcell	1.05230
Cpconst	Standard: 0.938
Calib	-38.6961
TempCal	1	pts	157.46	156.60
TzeroDt	-87.6168 -0.0009 -1.4231
TzeroDtz	-87.6168 0.0057 6.9570
InstCalFile	Tzero: \\Ae520-1454\ta\Data\DSC\Calibration\2017\CALIBRATION\1562_RCS (90)_05_18_2017 10_50_44.TZR
InstCalFile	Baseline: \\Ae520-1454\ta\Data\DSC\Calibration\2017\2017-05-17_Calibration.001
InstCalFile	Sapphire: \\Ae520-1454\ta\Data\DSC\Calibration\2017\2017-05-17_Saphire.001
InstCalDate	Tzero 2017-05-18 Time 10:50:44
TempRange	-87.39 to 398.39 °C at 10.00 °C/min Heat Only
AutoZero	Delta T Offset 0.000 uV
AutoZero	Delta T0 Offset 0.000 uV
MultiptCal	0
MultiPtDesc	0) Not set
AutoCellConst	Calibration Date 2017-05-18 16:59:28
Controls	Gas 1  Event Off  Sampling 0.2
Cell#	RC-01562
CoolingUnit	RCS (90)
SelHeatFlow	Heat Flow T4P (mW)
AutoLidII	Installed
AutoAnalysis	Off
MacroFile
Nsig	3
Sig1	Time (min)
Sig2	Temperature (°C)
Sig3	Heat Flow (mW)
Date	2017-09-01
Time	11:39:33
OrgMethod	1: Equilibrate at 80.00 °C
OrgMethod	2: Isothermal for 3.00 min
OrgMethod	3: Jump to 150.00 °C
OrgMethod	4: Mark end of cycle 1
OrgMethod	5: Isothermal for 40.00 min
OrgMethod	6: Mark end of cycle 2
OrgMethod	7: Ramp 20.00 °C/min to 280.00 °C
OrgMethod	8: Mark end of cycle 3
OrgMethod	9: Ramp 20.00 °C/min to 20.00 °C
OrgMethod	10: Mark end of cycle 4
OrgMethod	11: Ramp 20.00 °C/min to 280.00 °C
OrgMethod	12: Mark end of cycle 5
OrgFile	C:\Users\jarra\Desktop\DSC\5-C1(1.4mol%)+C20(0.6mol%)\150-2.001
StartOfData
4.99994E-4	79.47644	-6.446250
0.05383332	79.56562	-5.262883
0.1038333	79.63001	-4.397835
0.1571666	79.68294	-3.672205
0.2071666	79.72165	-3.144963
0.2605000	79.75426	-2.705768
0.3105000	79.77738	-2.382810
0.3638334	79.79615	-2.118821
0.4138333	79.80966	-1.925303
0.4671667	79.82056	-1.764266
0.5171667	79.82706	-1.652364
0.5705000	79.83329	-1.562142
0.6205000	79.83638	-1.496194
0.6721668	79.83911	-1.445852
0.7238332	79.84036	-1.410045
0.7755000	79.84138	-1.384042
0.8271668	79.84254	-1.366972
0.8788332	79.84310	-1.355242
0.9305000	79.84130	-1.347853
0.9821668	79.84165	-1.343692
1.033833	79.84092	-1.340421
1.083833	79.84010	-1.337235
1.137166	79.83906	-1.333828
1.187166	79.83829	-1.330765
1.240500	79.83801	-1.327556
1.290500	79.83612	-1.324824
1.343833	79.83491	-1.322224
1.393833	79.83509	-1.320070
1.447166	79.83365	-1.318099
1.497166	79.83111	-1.316534
1.550500	79.83121	-1.315167
1.600500	79.83094	-1.314080
1.653833	79.82876	-1.313177
1.703833	79.82850	-1.312528
1.755500	79.82725	-1.312085
1.807167	79.82626	-1.311776
1.858834	79.82585	-1.311688
1.910500	79.82474	-1.311798
1.962166	79.82337	-1.312144
2.013833	79.82264	-1.312612
2.065500	79.82268	-1.313271
2.117167	79.82232	-1.314010
2.167167	79.81938	-1.314841
2.220500	79.81894	-1.315870
2.270500	79.81858	-1.316968
2.323833	79.81769	-1.318214
2.373834	79.81712	-1.319500
2.427167	79.81670	-1.320990
2.477167	79.81614	-1.322479
2.530500	79.81505	-1.324084
2.580500	79.81524	-1.325764
2.633833	79.81400	-1.327448
2.683833	79.81293	-1.329097
2.737167	79.81220	-1.330925
2.787167	79.81206	-1.332711
2.838833	79.81119	-1.334476
2.890500	79.81118	-1.336297
2.942167	79.81049	-1.338143
2.993833	79.80938	-1.340040
3.040500	79.98350	-3.484810
3.093834	81.78989	-16.57613
3.143833	84.25884	-28.18982
3.197167	87.37915	-40.37660
3.247166	90.66932	-50.88718
3.300500	94.47589	-60.79033
3.350500	98.25845	-68.76551
3.403833	102.4638	-76.02658
3.453833	106.5235	-81.79485
3.505500	110.8096	-86.86866
3.557167	115.1601	-91.15228
3.608833	119.5472	-94.96408
3.660500	123.9588	-98.33304
3.712167	128.3801	-101.2594
3.763833	132.7474	-103.2681
3.815500	136.1632	-97.35902
3.867166	138.4948	-87.03137
3.917167	140.2865	-76.71812
3.970500	141.7829	-66.11434
4.020500	142.9054	-57.30300
4.073834	143.8690	-49.25256
4.123833	144.6005	-42.97722
4.177166	145.2380	-37.50686
4.227167	145.7279	-33.36120
4.280500	146.1618	-29.79550
4.330500	146.4991	-27.12822
4.383834	146.8016	-24.83722
4.433834	147.0428	-23.11498
4.487167	147.2605	-21.63614
4.537167	147.4353	-20.52501
4.588834	147.5916	-19.59121
4.640500	147.7266	-18.82286
4.692166	147.8435	-18.19006
4.743834	147.9473	-17.65424
4.795500	148.0385	-17.20189
4.847166	148.1188	-16.81766
4.898834	148.1913	-16.48009
4.950500	148.2563	-16.18516
5.000500	148.3125	-15.92754
5.053834	148.3664	-15.68521
5.103833	148.4128	-15.47705
5.157166	148.4572	-15.27046
5.207167	148.4939	-15.09410
5.260500	148.5306	-14.91556
5.310500	148.5633	-14.76228
5.363834	148.5936	-14.60203
5.413832	148.6202	-14.46015
5.467168	148.6465	-14.31315
5.517168	148.6692	-14.18000
5.570500	148.6921	-14.04336
5.620500	148.7119	-13.91874
5.672168	148.7312	-13.79006
5.723834	148.7504	-13.66689
5.775500	148.7676	-13.54006
5.827168	148.7845	-13.41485
5.878834	148.8007	-13.28809
5.930500	148.8158	-13.16115
5.982168	148.8311	-13.03079
6.033832	148.8464	-12.90140
6.083832	148.8591	-12.77327
6.137168	148.8739	-12.64121
6.187168	148.8866	-12.51226
6.240500	148.9010	-12.37901
6.290500	148.9132	-12.25235
6.343834	148.9253	-12.11780
6.393832	148.9375	-11.99074
6.447168	148.9501	-11.85350
6.497168	148.9621	-11.72317
6.550500	148.9740	-11.58325
6.600500	148.9845	-11.45436
6.653832	148.9962	-11.31202
6.703832	149.0076	-11.17967
6.755500	149.0189	-11.04224
6.807166	149.0299	-10.90066
6.858832	149.0406	-10.76140
6.910500	149.0514	-10.61906
6.962168	149.0625	-10.47692
7.013834	149.0737	-10.33291
7.065500	149.0838	-10.18184
7.117166	149.0955	-10.03366
7.167168	149.1073	-9.885394
7.220500	149.1180	-9.720612
7.270500	149.1284	-9.565391
7.323834	149.1410	-9.394005
7.373834	149.1526	-9.226776
7.427168	149.1668	-9.045171
7.477168	149.1780	-8.865211
7.530500	149.1930	-8.671316
7.580500	149.2059	-8.482321
7.633832	149.2196	-8.275871
7.683832	149.2341	-8.079419
7.737168	149.2476	-7.870095
7.787168	149.2628	-7.668766
7.838834	149.2768	-7.460985
7.890500	149.2913	-7.255526
7.942168	149.3054	-7.051988
7.993834	149.3185	-6.843979
8.045500	149.3325	-6.644214
8.097168	149.3472	-6.445379
8.148834	149.3596	-6.238453
8.200500	149.3728	-6.038972
8.250500	149.3865	-5.837856
8.303832	149.4018	-5.606296
8.353832	149.4175	-5.374304
8.407166	149.4353	-5.105740
8.457168	149.4532	-4.829784
8.510499	149.4743	-4.512100
8.560500	149.4936	-4.192628
8.613834	149.5173	-3.838696
8.663834	149.5398	-3.510889
8.717168	149.5624	-3.172984
8.767168	149.5822	-2.874696
8.820500	149.6024	-2.584706
8.870499	149.6195	-2.339539
8.922168	149.6351	-2.120906
8.973832	149.6491	-1.920839
9.025499	149.6620	-1.743223
9.077168	149.6740	-1.585234
9.128834	149.6846	-1.435804
9.180500	149.6938	-1.298025
9.232166	149.7038	-1.170580
9.283832	149.7121	-1.044660
9.333832	149.7216	-0.9212868
9.387168	149.7317	-0.7792780
9.437166	149.7407	-0.6324484
9.490500	149.7522	-0.4610481
9.540500	149.7638	-0.2833871
9.593832	149.7774	-.07742094
9.643832	149.7909	0.1279910
9.697168	149.8055	0.3600199
9.747168	149.8207	0.5839097
9.800500	149.8366	0.8259400
9.850500	149.8519	1.052722
9.903832	149.8677	1.298456
9.953834	149.8828	1.521307
10.00550	149.8980	1.751936
10.05717	149.9132	1.973552
10.10883	149.9274	2.187166
10.16050	149.9426	2.397019
10.21217	149.9559	2.597152
10.26383	149.9682	2.784390
10.31550	149.9805	2.961866
10.36717	149.9915	3.127460
10.41717	150.0020	3.272045
10.47050	150.0120	3.412072
10.52050	150.0196	3.532200
10.57383	150.0276	3.638240
10.62383	150.0328	3.722983
10.67717	150.0378	3.796505
10.72717	150.0427	3.848767
10.78050	150.0449	3.890278
10.83050	150.0481	3.917530
10.88383	150.0490	3.934343
10.93383	150.0499	3.940678
10.98717	150.0502	3.943364
11.03717	150.0501	3.944890
11.08883	150.0486	3.945569
11.14050	150.0484	3.944636
11.19217	150.0460	3.939204
11.24384	150.0449	3.925390
11.29550	150.0417	3.902534
11.34717	150.0398	3.868799
11.39883	150.0369	3.829253
11.45050	150.0348	3.783709
11.50050	150.0314	3.738223
11.55383	150.0296	3.689148
11.60383	150.0259	3.647053
11.65717	150.0231	3.601818
11.70717	150.0216	3.560294
11.76050	150.0186	3.520736
11.81050	150.0158	3.480198
11.86383	150.0134	3.440242
11.91383	150.0111	3.401620
11.96717	150.0088	3.361976
12.01717	150.0060	3.325140
12.07050	150.0038	3.286983
12.12050	150.0006	3.251738
12.17217	149.9982	3.215243
12.22383	149.9966	3.180630
12.27550	149.9939	3.147394
12.32717	149.9917	3.112491
12.37884	149.9893	3.080002
12.43050	149.9876	3.048312
12.48217	149.9852	3.017018
12.53383	149.9838	2.986247
12.58383	149.9814	2.957542
12.63717	149.9792	2.927880
12.68716	149.9780	2.900975
12.74050	149.9755	2.872912
12.79050	149.9743	2.846890
12.84383	149.9732	2.821196
12.89383	149.9715	2.797034
12.94717	149.9685	2.772586
12.99717	149.9674	2.747646
13.05050	149.9662	2.721506
13.10050	149.9649	2.699288
13.15383	149.9641	2.676851
13.20383	149.9630	2.655866
13.25550	149.9610	2.637530
13.30717	149.9592	2.619647
13.35883	149.9581	2.601125
13.41050	149.9565	2.583402
13.46217	149.9550	2.566167
13.51383	149.9538	2.549532
13.56550	149.9524	2.534076
13.61716	149.9515	2.519066
13.66716	149.9496	2.503432
13.72050	149.9484	2.484306
13.77050	149.9467	2.469456
13.82384	149.9461	2.451091
13.87384	149.9446	2.434350
13.92717	149.9423	2.417732
13.97717	149.9424	2.399942
14.03050	149.9412	2.382580
14.08050	149.9394	2.367955
14.13383	149.9385	2.351766
14.18383	149.9376	2.336182
14.23716	149.9357	2.319412
14.28717	149.9342	2.304114
14.33883	149.9339	2.287192
14.39050	149.9331	2.272170
14.44217	149.9322	2.255711
14.49384	149.9310	2.239661
14.54550	149.9302	2.221446
14.59717	149.9304	2.203733
14.64883	149.9284	2.187450
14.70050	149.9286	2.170193
14.75050	149.9265	2.155208
14.80383	149.9267	2.138163
14.85383	149.9241	2.124014
14.90717	149.9238	2.107927
14.95717	149.9228	2.091922
15.01050	149.9216	2.076744
15.06050	149.9199	2.061612
15.11383	149.9194	2.044098
15.16383	149.9175	2.030079
15.21716	149.9163	2.014894
15.26717	149.9158	1.998578
15.32050	149.9137	1.983482
15.37050	149.9125	1.968994
15.42217	149.9117	1.952648
15.47383	149.9108	1.935716
15.52550	149.9088	1.919448
15.57717	149.9082	1.900744
15.62883	149.9073	1.881920
15.68050	149.9065	1.864449
15.73216	149.9052	1.846669
15.78383	149.9039	1.830636
15.83383	149.9026	1.814576
15.88716	149.9012	1.797816
15.93717	149.9013	1.781284
15.99050	149.8994	1.765038
16.04050	149.8986	1.749116
16.09383	149.8970	1.729581
16.14383	149.8966	1.711514
16.19717	149.8963	1.692312
16.24716	149.8942	1.676070
16.30050	149.8930	1.659892
16.35050	149.8913	1.643382
16.40383	149.8909	1.627836
16.45383	149.8892	1.612717
16.50550	149.8877	1.597097
16.55716	149.8863	1.581526
16.60883	149.8858	1.564427
16.66050	149.8842	1.548272
16.71216	149.8832	1.531324
16.76383	149.8816	1.514274
16.81550	149.8811	1.498402
16.86716	149.8799	1.481971
16.91716	149.8789	1.466224
16.97050	149.8780	1.449711
17.02050	149.8768	1.433449
17.07383	149.8754	1.418635
17.12383	149.8751	1.403556
17.17716	149.8731	1.389581
17.22716	149.8728	1.374057
17.28050	149.8724	1.357919
17.33050	149.8722	1.343808
17.38383	149.8702	1.328991
17.43383	149.8696	1.314854
17.48716	149.8693	1.300502
17.53717	149.8684	1.287813
17.58883	149.8683	1.275044
17.64050	149.8655	1.262866
17.69216	149.8656	1.249663
17.74383	149.8645	1.237054
17.79550	149.8630	1.226275
17.84716	149.8623	1.213916
17.89883	149.8608	1.201604
17.95050	149.8600	1.189592
18.00050	149.8597	1.178360
18.05383	149.8580	1.167443
18.10383	149.8581	1.156292
18.15716	149.8564	1.144530
18.20716	149.8569	1.132415
18.26050	149.8560	1.120525
18.31050	149.8558	1.109718
18.36383	149.8548	1.097980
18.41383	149.8546	1.087504
18.46716	149.8534	1.076431
18.51716	149.8534	1.066184
18.57050	149.8536	1.055268
18.62050	149.8530	1.045218
18.67216	149.8520	1.035019
18.72383	149.8520	1.025003
18.77550	149.8519	1.015186
18.82716	149.8518	1.005535
18.87883	149.8507	0.9961215
18.93050	149.8505	0.9869076
18.98216	149.8500	0.9779070
19.03383	149.8502	0.9690519
19.08383	149.8496	0.9605881
19.13716	149.8492	0.9517718
19.18716	149.8481	0.9437100
19.24050	149.8482	0.9351765
19.29050	149.8466	0.9272450
19.34383	149.8466	0.9188046
19.39383	149.8456	0.9110125
19.44716	149.8458	0.9027420
19.49716	149.8442	0.8950194
19.55050	149.8446	0.8867897
19.60050	149.8437	0.8791059
19.65383	149.8431	0.8709561
19.70383	149.8420	0.8633075
19.75550	149.8421	0.8553351
19.80716	149.8402	0.8474066
19.85883	149.8405	0.8393696
19.91050	149.8402	0.8312618
19.96216	149.8394	0.8230250
20.01383	149.8397	0.8148126
20.06550	149.8388	0.8066560
20.11716	149.8379	0.7984755
20.16716	149.8369	0.7905684
20.22050	149.8368	0.7820759
20.27050	149.8363	0.7741144
20.32383	149.8346	0.7655526
20.37383	149.8345	0.7574141
20.42716	149.8334	0.7485840
20.47716	149.8328	0.7401156
20.53050	149.8314	0.7306860
20.58050	149.8315	0.7208119
20.63383	149.8298	0.7104831
20.68383	149.8290	0.6988437
20.73716	149.8275	0.6847318
20.78717	149.8276	0.6681626
20.83883	149.8257	0.6511982
20.89050	149.8252	0.6337020
20.94216	149.8239	0.6170113
20.99383	149.8230	0.5986414
21.04550	149.8222	0.5768226
21.09716	149.8212	0.5583515
21.14883	149.8203	0.5393002
21.20050	149.8184	0.5226608
21.25050	149.8176	0.5026767
21.30383	149.8166	0.4809234
21.35383	149.8153	0.4614814
21.40716	149.8141	0.4395690
21.45717	149.8130	0.4180316
21.51050	149.8118	0.3962024
21.56050	149.8108	0.3754258
21.61383	149.8083	0.3533308
21.66383	149.8076	0.3314660
21.71716	149.8060	0.3101149
21.76716	149.8044	0.2924264
21.82050	149.8027	0.2693002
21.87050	149.8010	0.2484417
21.92216	149.7993	0.2268013
21.97383	149.7982	0.2047044
22.02550	149.7965	0.1825224
22.07716	149.7949	0.1595068
22.12883	149.7934	0.1337757
22.18050	149.7925	0.1105109
22.23216	149.7906	0.08764632
22.28383	149.7894	0.06794720
22.33383	149.7938	0.05796864
22.38716	149.7924	0.05404378
22.43716	149.7908	0.04881026
22.49050	149.7884	0.03236446
22.54050	149.7872	.006396255
22.59383	149.7852	-.02724295
22.64383	149.7830	-.06638019
22.69716	149.7812	-0.1091174
22.74716	149.7789	-0.1427564
22.80050	149.7768	-0.1732446
22.85050	149.7750	-0.2017806
22.90383	149.7732	-0.2264790
22.95383	149.7709	-0.2534652
23.00550	149.7702	-0.2794124
23.05716	149.7680	-0.3056468
23.10883	149.7662	-0.3326507
23.16050	149.7641	-0.3577635
23.21216	149.7624	-0.3827628
23.26383	149.7603	-0.4073206
23.31550	149.7584	-0.4327187
23.36716	149.7567	-0.4583687
23.41716	149.7554	-0.4849362
23.47050	149.7533	-0.5158721
23.52050	149.7522	-0.5411567
23.57383	149.7507	-0.5709285
23.62383	149.7484	-0.5954941
23.67717	149.7478	-0.6230215
23.72716	149.7453	-0.6480370
23.78050	149.7445	-0.6756938
23.83050	149.7418	-0.7004592
23.88383	149.7411	-0.7240216
23.93383	149.7385	-0.7434220
23.98716	149.7364	-0.7687538
24.03717	149.7352	-0.7945142
24.08883	149.7332	-0.8189289
24.14050	149.7308	-0.8445053
24.19216	149.7297	-0.8709232
24.24383	149.7283	-0.8975491
24.29550	149.7267	-0.9265603
24.34716	149.7252	-0.9546358
24.39883	149.7231	-0.9808600
24.45050	149.7217	-1.007509
24.50050	149.7202	-1.032371
24.55383	149.7192	-1.056745
24.60383	149.7172	-1.080533
24.65716	149.7161	-1.106105
24.70717	149.7148	-1.129807
24.76050	149.7128	-1.155291
24.81050	149.7111	-1.179096
24.86383	149.7099	-1.205185
24.91383	149.7086	-1.227327
24.96716	149.7061	-1.249673
25.01716	149.7048	-1.272369
25.07050	149.7032	-1.295296
25.12050	149.7012	-1.317716
25.17216	149.6997	-1.343074
25.22383	149.6979	-1.367691
25.27550	149.6963	-1.391542
25.32716	149.6944	-1.417327
25.37883	149.6932	-1.441783
25.43050	149.6909	-1.465483
25.48216	149.6898	-1.486322
25.53383	149.6882	-1.506677
25.58383	149.6867	-1.528650
25.63716	149.6845	-1.553758
25.68717	149.6828	-1.574025
25.74050	149.6806	-1.593686
25.79050	149.6794	-1.616135
25.84383	149.6770	-1.639079
25.89383	149.6753	-1.661686
25.94717	149.6746	-1.689375
25.99716	149.6722	-1.709836
26.05050	149.6704	-1.730280
26.10050	149.6686	-1.750286
26.15383	149.6679	-1.773356
26.20383	149.6667	-1.795562
26.25550	149.6646	-1.818058
26.30716	149.6644	-1.841180
26.35883	149.6628	-1.862216
26.41050	149.6600	-1.882025
26.46216	149.6598	-1.903523
26.51383	149.6576	-1.924396
26.56550	149.6577	-1.947230
26.61716	149.6569	-1.967938
26.66716	149.6566	-1.987649
26.72050	149.6543	-2.005329
26.77050	149.6532	-2.020897
26.82383	149.6524	-2.038709
26.87383	149.6506	-2.055638
26.92717	149.6496	-2.075444
26.97717	149.6478	-2.091066
27.03050	149.6466	-2.107185
27.08050	149.6457	-2.122773
27.13383	149.6442	-2.140862
27.18383	149.6433	-2.157766
27.23716	149.6418	-2.175906
27.28717	149.6398	-2.195778
27.33883	149.6395	-2.213200
27.39050	149.6382	-2.230183
27.44216	149.6374	-2.247870
27.49383	149.6369	-2.264577
27.54550	149.6350	-2.281362
27.59716	149.6330	-2.297508
27.64883	149.6326	-2.311353
27.70050	149.6308	-2.323796
27.75050	149.6303	-2.334734
27.80383	149.6284	-2.347940
27.85383	149.6274	-2.361313
27.90716	149.6258	-2.377932
27.95716	149.6248	-2.392413
28.01050	149.6245	-2.407252
28.06050	149.6232	-2.418945
28.11383	149.6220	-2.433376
28.16383	149.6207	-2.449294
28.21716	149.6194	-2.464531
28.26716	149.6188	-2.479184
28.32050	149.6176	-2.490850
28.37050	149.6167	-2.502575
28.42216	149.6157	-2.513896
28.47383	149.6153	-2.527232
28.52550	149.6141	-2.539304
28.57717	149.6137	-2.551218
28.62883	149.6127	-2.564266
28.68050	149.6126	-2.576617
28.73216	149.6116	-2.587561
28.78383	149.6119	-2.600556
28.83383	149.6113	-2.611797
28.88716	149.6097	-2.622918
28.93717	149.6096	-2.633052
28.99050	149.6087	-2.643945
29.04050	149.6082	-2.654585
29.09383	149.6073	-2.665854
29.14383	149.6064	-2.676092
29.19717	149.6060	-2.686941
29.24716	149.6040	-2.697080
29.30050	149.6048	-2.707943
29.35050	149.6043	-2.718096
29.40383	149.6028	-2.728805
29.45383	149.6026	-2.738836
29.50550	149.6012	-2.749122
29.55716	149.6000	-2.759292
29.60883	149.6000	-2.769388
29.66050	149.5992	-2.779455
29.71216	149.5984	-2.789471
29.76383	149.5973	-2.799467
29.81550	149.5965	-2.809455
29.86716	149.5963	-2.819333
29.91716	149.5963	-2.828809
29.97050	149.5951	-2.838838
30.02050	149.5956	-2.848188
30.07383	149.5946	-2.858070
30.12383	149.5944	-2.867304
30.17717	149.5934	-2.877076
30.22717	149.5930	-2.886174
30.28050	149.5926	-2.895854
30.33050	149.5921	-2.904780
30.38383	149.5917	-2.914234
30.43383	149.5907	-2.922915
30.48716	149.5907	-2.932013
30.53717	149.5893	-2.940206
30.58883	149.5890	-2.948566
30.64050	149.5874	-2.956840
30.69216	149.5881	-2.964972
30.74383	149.5881	-2.972995
30.79550	149.5875	-2.980996
30.84716	149.5873	-2.988928
30.89883	149.5866	-2.996844
30.95050	149.5865	-3.004643
31.00050	149.5861	-3.012117
31.05383	149.5860	-3.020000
31.10383	149.5860	-3.027247
31.15716	149.5856	-3.034805
31.20716	149.5859	-3.041803
31.26050	149.5854	-3.049068
31.31050	149.5840	-3.055758
31.36383	149.5843	-3.062940
31.41383	149.5833	-3.069643
31.46716	149.5842	-3.076685
31.51716	149.5837	-3.083066
31.57050	149.5825	-3.089727
31.62050	149.5832	-3.095818
31.67216	149.5828	-3.101828
31.72383	149.5817	-3.107690
31.77550	149.5819	-3.113466
31.82717	149.5806	-3.119181
31.87883	149.5813	-3.124622
31.93050	149.5806	-3.129874
31.98216	149.5799	-3.134917
32.03383	149.5803	-3.139925
32.08383	149.5796	-3.144852
32.13716	149.5795	-3.150210
32.18716	149.5795	-3.155214
32.24050	149.5794	-3.160584
32.29050	149.5792	-3.165514
32.34384	149.5789	-3.170669
32.39383	149.5792	-3.175540
32.44717	149.5790	-3.180627
32.49716	149.5781	-3.185253
32.55050	149.5783	-3.190120
32.60050	149.5778	-3.194623
32.65383	149.5773	-3.199310
32.70383	149.5779	-3.203651
32.75550	149.5770	-3.208111
32.80716	149.5770	-3.212611
32.85883	149.5766	-3.217246
32.91050	149.5768	-3.221808
32.96216	149.5763	-3.226189
33.01383	149.5751	-3.230440
33.06550	149.5750	-3.234547
33.11716	149.5756	-3.238568
33.16716	149.5758	-3.242424
33.22050	149.5749	-3.246490
33.27050	149.5750	-3.250255
33.32383	149.5748	-3.254263
33.37383	149.5738	-3.258000
33.42717	149.5750	-3.262074
33.47717	149.5746	-3.265787
33.53050	149.5745	-3.269656
33.58050	149.5744	-3.273169
33.63383	149.5742	-3.276891
33.68384	149.5728	-3.280200
33.73717	149.5739	-3.283632
33.78717	149.5734	-3.286803
33.83883	149.5733	-3.289894
33.89050	149.5732	-3.293008
33.94216	149.5725	-3.296031
33.99383	149.5718	-3.298867
34.04550	149.5715	-3.301770
34.09716	149.5706	-3.304697
34.14883	149.5719	-3.307582
34.20050	149.5709	-3.310500
34.25050	149.5708	-3.313340
34.30383	149.5707	-3.316362
34.35383	149.5701	-3.319038
34.40716	149.5699	-3.321817
34.45716	149.5692	-3.324414
34.51050	149.5698	-3.327203
34.56050	149.5692	-3.329746
34.61383	149.5690	-3.332520
34.66383	149.5691	-3.335107
34.71716	149.5699	-3.337852
34.76716	149.5698	-3.340406
34.82050	149.5702	-3.343037
34.87050	149.5698	-3.345444
34.92216	149.5697	-3.347961
34.97383	149.5694	-3.350606
35.02550	149.5696	-3.353138
35.07717	149.5692	-3.355520
35.12883	149.5694	-3.357814
35.18050	149.5700	-3.360039
35.23216	149.5697	-3.362216
35.28383	149.5695	-3.364416
35.33383	149.5695	-3.366491
35.38716	149.5696	-3.368732
35.43716	149.5696	-3.370850
35.49050	149.5701	-3.373056
35.54050	149.5691	-3.375004
35.59384	149.5698	-3.377072
35.64383	149.5691	-3.378955
35.69717	149.5692	-3.380966
35.74716	149.5699	-3.382830
35.80050	149.5697	-3.384749
35.85050	149.5690	-3.386438
35.90383	149.5694	-3.388176
35.95383	149.5693	-3.389603
36.00550	149.5691	-3.390999
36.05716	149.5686	-3.392322
36.10883	149.5684	-3.393650
36.16050	149.5681	-3.395130
36.21216	149.5669	-3.396500
36.26383	149.5668	-3.397808
36.31550	149.5667	-3.399104
36.36716	149.5668	-3.400344
36.41716	149.5672	-3.401588
36.47050	149.5676	-3.402942
36.52050	149.5665	-3.404217
36.57383	149.5675	-3.405810
36.62383	149.5680	-3.407308
36.67717	149.5674	-3.408902
36.72717	149.5680	-3.410476
36.78050	149.5682	-3.412167
36.83050	149.5671	-3.413730
36.88383	149.5674	-3.415325
36.93384	149.5677	-3.416775
36.98717	149.5671	-3.418222
37.03717	149.5666	-3.419506
37.08883	149.5670	-3.420756
37.14050	149.5666	-3.421937
37.19216	149.5662	-3.423028
37.24383	149.5659	-3.424022
37.29550	149.5663	-3.424773
37.34716	149.5652	-3.425578
37.39883	149.5656	-3.426415
37.45050	149.5664	-3.427231
37.50050	149.5655	-3.428118
37.55383	149.5655	-3.429182
37.60383	149.5656	-3.430379
37.65716	149.5662	-3.431680
37.70716	149.5656	-3.432937
37.76050	149.5664	-3.434261
37.81050	149.5656	-3.435422
37.86383	149.5666	-3.436668
37.91383	149.5656	-3.437760
37.96716	149.5669	-3.438809
38.01716	149.5664	-3.439666
38.07050	149.5666	-3.440572
38.12050	149.5655	-3.441369
38.17216	149.5648	-3.442035
38.22383	149.5649	-3.442710
38.27550	149.5652	-3.443367
38.32717	149.5646	-3.444175
38.37883	149.5651	-3.445076
38.43050	149.5661	-3.446011
38.48216	149.5654	-3.446988
38.53383	149.5657	-3.447966
38.58383	149.5656	-3.448680
38.63716	149.5663	-3.449410
38.68716	149.5654	-3.450082
38.74050	149.5662	-3.450822
38.79050	149.5655	-3.451519
38.84384	149.5660	-3.452248
38.89383	149.5650	-3.453030
38.94717	149.5645	-3.453813
38.99716	149.5647	-3.454580
39.05050	149.5658	-3.455347
39.10050	149.5648	-3.456046
39.15383	149.5654	-3.456800
39.20383	149.5644	-3.457442
39.25550	149.5657	-3.458105
39.30716	149.5650	-3.458771
39.35883	149.5652	-3.459267
39.41050	149.5655	-3.459721
39.46216	149.5651	-3.460224
39.51383	149.5642	-3.460826
39.56550	149.5637	-3.461402
39.61716	149.5642	-3.461958
39.66716	149.5646	-3.462233
39.72050	149.5647	-3.462525
39.77050	149.5640	-3.462856
39.82383	149.5649	-3.463352
39.87383	149.5641	-3.463878
39.92717	149.5641	-3.464526
39.97717	149.5653	-3.465154
40.03050	149.5649	-3.465760
40.08050	149.5642	-3.466320
40.13383	149.5656	-3.466910
40.18384	149.5644	-3.467385
40.23717	149.5654	-3.467876
40.28717	149.5647	-3.468328
40.33883	149.5643	-3.468766
40.39050	149.5649	-3.469247
40.44216	149.5646	-3.469620
40.49383	149.5645	-3.470000
40.54550	149.5650	-3.470322
40.59716	149.5642	-3.470652
40.64883	149.5638	-3.470982
40.70050	149.5646	-3.471344
40.75050	149.5632	-3.471668
40.80383	149.5635	-3.472249
40.85383	149.5630	-3.472553
40.90716	149.5638	-3.472795
40.95716	149.5631	-3.472982
41.01050	149.5634	-3.473159
41.06050	149.5627	-3.473397
41.11383	149.5628	-3.473750
41.16383	149.5626	-3.474134
41.21717	149.5631	-3.474568
41.26717	149.5629	-3.475109
41.32050	149.5638	-3.475792
41.37050	149.5634	-3.476500
41.42216	149.5638	-3.477200
41.47383	149.5640	-3.477852
41.52550	149.5641	-3.478503
41.57717	149.5645	-3.478981
41.62883	149.5641	-3.479412
41.68050	149.5637	-3.479812
41.73217	149.5638	-3.480098
41.78383	149.5632	-3.480389
41.83383	149.5634	-3.480674
41.88716	149.5639	-3.480958
41.93716	149.5638	-3.481190
41.99050	149.5643	-3.481517
42.04050	149.5635	-3.481626
42.09384	149.5642	-3.481800
42.14383	149.5635	-3.481968
42.19717	149.5628	-3.482392
42.24716	149.5631	-3.482708
42.30050	149.5630	-3.483024
42.35050	149.5636	-3.483222
42.40383	149.5620	-3.483239
42.45383	149.5625	-3.483365
42.50550	149.5627	-3.483520
42.55717	149.5624	-3.483780
42.60883	149.5624	-3.484200
42.66050	149.5620	-3.484547
42.71216	149.5624	-3.484906
42.76383	149.5624	-3.485159
42.81550	149.5630	-3.485463
42.86716	149.5620	-3.485494
42.91716	149.5620	-3.485698
42.97050	149.5629	-3.485961
43.01717	149.5624	-3.486394
43.07050	149.6491	-4.808114
43.12050	150.0050	-8.082650
43.17216	150.5398	-11.19848
43.22383	151.1945	-13.91578
43.27550	151.9360	-16.07781
43.32717	152.7419	-17.78748
43.37883	153.5963	-19.13051
43.43050	154.4876	-20.16627
43.48217	155.4064	-20.98331
43.53383	156.3458	-21.62430
43.58383	157.2709	-22.13754
43.63716	158.2688	-22.61302
43.68716	159.2148	-22.97138
43.74050	160.2304	-23.30394
43.79050	161.1891	-23.58322
43.84384	162.2167	-23.84963
43.89383	163.1841	-24.08502
43.94717	164.2190	-24.33510
43.99716	165.1922	-24.51808
44.05050	166.2322	-24.74487
44.10050	167.2076	-24.95443
44.15383	168.2511	-25.15434
44.20383	169.2300	-25.33871
44.25550	170.2435	-25.54183
44.30717	171.2584	-25.73208
44.35883	172.2724	-25.92430
44.41050	173.2875	-26.14190
44.46216	174.3026	-26.35144
44.51383	175.3187	-26.55886
44.56550	176.3356	-26.75754
44.61716	177.3520	-26.96506
44.66716	178.3356	-27.19377
44.72050	179.3848	-27.45305
44.77050	180.3683	-27.70938
44.82383	181.4162	-27.96887
44.87383	182.4004	-28.21868
44.92717	183.4507	-28.52024
44.97717	184.4326	-28.83362
45.03050	185.4800	-29.13040
45.08050	186.4614	-29.43794
45.13383	187.5086	-29.77715
45.18383	188.4900	-30.10694
45.23717	189.5346	-30.49305
45.28717	190.5138	-30.85795
45.33883	191.5244	-31.27521
45.39050	192.5338	-31.79626
45.44217	193.5413	-32.17486
45.49383	194.5486	-32.67820
45.54550	195.5527	-33.21168
45.59716	196.5554	-33.80801
45.64883	197.5542	-34.45872
45.70050	198.5494	-35.16504
45.75050	199.5089	-35.90183
45.80383	200.5288	-36.85900
45.85383	201.4775	-37.83274
45.90717	202.4823	-39.04030
45.95717	203.4187	-40.21284
46.01050	204.4116	-41.61428
46.06050	205.3318	-43.14399
46.11383	206.3054	-44.83722
46.16383	207.2139	-46.49275
46.21717	208.1766	-48.35138
46.26717	209.0762	-50.07922
46.32050	210.0342	-51.96359
46.37050	210.9367	-53.41490
46.42216	211.8718	-55.10655
46.47383	212.8025	-56.90142
46.52550	213.7313	-58.81648
46.57717	214.6549	-60.84039
46.62883	215.5724	-62.86607
46.68050	216.4870	-64.95771
46.73217	217.4120	-66.26920
46.78383	218.3743	-66.39029
46.83383	219.3698	-64.72605
46.88716	220.5163	-61.59205
46.93716	221.6602	-57.74657
46.99050	222.9461	-52.83209
47.04050	224.2066	-47.47996
47.09384	225.5859	-42.00324
47.14383	226.8518	-38.86310
47.19717	228.1344	-36.64052
47.24716	229.2885	-35.09703
47.30050	230.4784	-33.91597
47.35050	231.5640	-33.08318
47.40383	232.6990	-32.43596
47.45383	233.7459	-32.00608
47.50550	234.8149	-31.68267
47.55717	235.8752	-31.44352
47.60883	236.9279	-31.29144
47.66050	237.9735	-31.19966
47.71216	239.0166	-31.14600
47.76383	240.0570	-31.12265
47.81550	241.0937	-31.11486
47.86716	242.1294	-31.11599
47.91716	243.1317	-31.11775
47.97050	244.1978	-31.12502
48.02050	245.1982	-31.14898
48.07383	246.2634	-31.19045
48.12383	247.2612	-31.23758
48.17717	248.3262	-31.30711
48.22717	249.3232	-31.36626
48.28050	250.3872	-31.43664
48.33050	251.3855	-31.51064
48.38383	252.4487	-31.58700
48.43383	253.4476	-31.63996
48.48717	254.5121	-31.70151
48.53717	255.5087	-31.76976
48.58883	256.5384	-31.85391
48.64050	257.5664	-31.93902
48.69217	258.5961	-32.03838
48.74383	259.6249	-32.12245
48.79550	260.6536	-32.19702
48.84716	261.6830	-32.28294
48.89883	262.7122	-32.35717
48.95050	263.7414	-32.43435
49.00050	264.7380	-32.52789
49.05383	265.8014	-32.62942
49.10383	266.7969	-32.67966
49.15717	267.8601	-32.74246
49.20717	268.8562	-32.81631
49.26050	269.9196	-32.88149
49.31050	270.9156	-32.93980
49.36383	271.9776	-33.08220
49.41383	272.9730	-33.15838
49.46717	274.0345	-33.18263
49.51383	274.9651	-33.23727
49.56550	275.8382	-34.26668
49.61716	276.1191	-28.77970
49.66716	276.0482	-21.04056
49.72050	275.7244	-13.43791
49.77050	275.2580	-7.576363
49.82383	274.6341	-2.631090
49.87383	273.9606	0.9811059
49.92717	273.1702	3.954653
49.97717	272.3802	6.082004
50.03050	271.4949	7.861770
50.08050	270.6345	9.151887
50.13383	269.6930	10.25232
50.18383	268.7918	11.05672
50.23717	267.8163	11.75307
50.28717	266.8881	12.28242
50.33883	265.9216	12.72652
50.39050	264.9448	13.10899
50.44217	263.9622	13.41073
50.49383	262.9732	13.67502
50.54550	261.9808	13.90076
50.59716	260.9836	14.09234
50.64883	259.9845	14.26281
50.70050	258.9820	14.41680
50.75050	258.0090	14.54462
50.80383	256.9690	14.67048
50.85383	255.9925	14.77704
50.90717	254.9486	14.88644
50.95717	253.9699	14.97919
51.01050	252.9244	15.06855
51.06050	251.9430	15.15226
51.11383	250.8956	15.23153
51.16383	249.9119	15.30751
51.21717	248.8617	15.37822
51.26716	247.8786	15.44616
51.32050	246.8258	15.51292
51.37050	245.8408	15.57144
51.42217	244.8214	15.63334
51.47383	243.8014	15.67878
51.52550	242.7816	15.73069
51.57717	241.7606	15.77118
51.62883	240.7388	15.81909
51.68050	239.7168	15.86470
51.73217	238.6957	15.90922
51.78383	237.6734	15.95582
51.83383	236.6846	15.99811
51.88716	235.6282	16.03866
51.93716	234.6386	16.07144
51.99050	233.5832	16.10378
52.04050	232.5928	16.13765
52.09384	231.5343	16.16922
52.14384	230.5427	16.19556
52.19717	229.4854	16.21857
52.24717	228.4937	16.24454
52.30050	227.4364	16.27627
52.35050	226.4463	16.30823
52.40383	225.3898	16.34524
52.45383	224.3972	16.38029
52.50550	223.3730	16.40934
52.55717	222.3472	16.44146
52.60883	221.3223	16.46861
52.66050	220.2972	16.49356
52.71216	219.2716	16.52024
52.76382	218.2458	16.54684
52.81550	217.2211	16.56808
52.86716	216.1958	16.59571
52.91716	215.2034	16.61898
52.97050	214.1448	16.64163
53.02050	213.1520	16.66460
53.07383	212.0940	16.68963
53.12383	211.1020	16.71528
53.17717	210.0431	16.74606
53.22717	209.0501	16.76840
53.28050	207.9911	16.79016
53.33050	206.9978	16.80952
53.38383	205.9388	16.82952
53.43383	204.9463	16.85066
53.48717	203.8872	16.87342
53.53716	202.8936	16.89263
53.58882	201.8670	16.90741
53.64050	200.8416	16.92598
53.69216	199.8149	16.94780
53.74382	198.7886	16.97067
53.79550	197.7632	16.99397
53.84716	196.7381	17.02054
53.89883	195.7121	17.04886
53.95050	194.6859	17.07878
54.00050	193.6930	17.10196
54.05383	192.6328	17.11918
54.10383	191.6404	17.13671
54.15717	190.5813	17.15378
54.20717	189.5887	17.17408
54.26050	188.5308	17.19510
54.31050	187.5382	17.22139
54.36382	186.4792	17.25500
54.41382	185.4861	17.27884
54.46717	184.4275	17.30235
54.51716	183.4339	17.32341
54.57050	182.3734	17.34315
54.62050	181.3810	17.36139
54.67217	180.3555	17.38402
54.72382	179.3287	17.41025
54.77550	178.3022	17.43863
54.82717	177.2754	17.46563
54.87883	176.2500	17.49628
54.93050	175.2237	17.52964
54.98217	174.1977	17.55846
55.03383	173.1710	17.59384
55.08383	172.1777	17.63831
55.13716	171.1187	17.72448
55.18716	170.1287	17.88039
55.24050	169.0770	18.14150
55.29050	168.0972	18.52861
55.34384	167.0638	19.23114
55.39384	166.1134	20.33429
55.44717	165.1309	22.13313
55.49717	164.2460	24.53024
55.55050	163.3457	27.76711
55.60050	162.5390	31.27564
55.65383	161.7099	35.20210
55.70383	160.9406	38.65444
55.75550	160.1339	41.60865
55.80717	159.2933	43.67053
55.85883	158.4018	44.73356
55.91050	157.4533	44.82822
55.96216	156.4438	44.18089
56.01382	155.3779	42.46598
56.06550	154.2684	40.47946
56.11716	153.1267	38.28851
56.16716	152.0051	36.15456
56.22050	150.8041	34.02208
56.27050	149.6821	32.19606
56.32383	148.4944	30.46323
56.37383	147.3925	29.01980
56.42717	146.2279	27.67730
56.47717	145.1478	26.55593
56.53050	144.0054	25.52290
56.58050	142.9443	24.68560
56.63383	141.8206	23.90484
56.68383	140.7746	23.27512
56.73717	139.6677	22.68488
56.78716	138.6350	22.21228
56.83882	137.5735	21.79290
56.89050	136.5170	21.42365
56.94216	135.4629	21.11439
56.99382	134.4131	20.84129
57.04550	133.3660	20.61244
57.09716	132.3212	20.40572
57.14883	131.2784	20.22906
57.20050	130.2379	20.07080
57.25050	129.2327	19.95084
57.30383	128.1613	19.83134
57.35383	127.1589	19.72851
57.40717	126.0883	19.62890
57.45717	125.0876	19.55924
57.51050	124.0195	19.47082
57.56050	123.0190	19.39735
57.61382	121.9527	19.31777
57.66382	120.9533	19.26537
57.71717	119.8867	19.20319
57.76716	118.8937	19.41159
57.82050	117.8257	19.13494
57.87050	116.8249	19.03588
57.92217	115.7910	18.94330
57.97382	114.7559	18.85670
58.02550	113.7223	18.78648
58.07717	112.6886	18.72845
58.12883	111.6568	18.67221
58.18050	110.6238	18.61703
58.23217	109.5933	18.57358
58.28383	108.5614	18.52668
58.33383	107.5623	18.48523
58.38716	106.4975	18.43588
58.43716	105.4988	18.39277
58.49050	104.4341	18.34527
58.54050	103.4362	18.30470
58.59384	102.3723	18.26672
58.64384	101.3744	18.23080
58.69717	100.3088	18.19168
58.74717	99.31306	18.15079
58.80050	98.24876	18.11707
58.85050	97.25054	18.08890
58.90383	96.18782	18.04883
58.95383	95.18938	18.01306
59.00550	94.15832	17.97513
59.05717	93.12644	17.93191
59.10883	92.09500	17.88902
59.16050	91.06134	17.84358
59.21216	90.03022	17.78884
59.26382	88.99879	17.74475
59.31550	87.96803	17.70494
59.36716	86.93755	17.66688
59.41716	85.93989	17.63350
59.47050	84.87572	17.59726
59.52050	83.87939	17.56508
59.57383	82.81378	17.53382
59.62383	81.81662	17.49602
59.67717	80.75184	17.45466
59.72717	79.75412	17.41744
59.78050	78.68871	17.37563
59.83050	77.69121	17.33847
59.88383	76.62689	17.30009
59.93383	75.62806	17.26856
59.98717	74.56390	17.22920
60.03716	73.56565	17.19652
60.08882	72.53313	17.15753
60.14050	71.50122	17.11636
60.19216	70.46890	17.07181
60.24382	69.43769	17.02246
60.29550	68.40548	16.97625
60.34716	67.37350	16.92761
60.39883	66.34256	16.88611
60.45050	65.31037	16.84839
60.50050	64.31240	16.80409
60.55383	63.24749	16.75436
60.60383	62.24851	16.70521
60.65717	61.18342	16.65506
60.70717	60.18549	16.60911
60.76050	59.11921	16.56044
60.81050	58.12084	16.51512
60.86382	57.05595	16.46714
60.91382	56.05889	16.43003
60.96717	54.99358	16.38190
61.01716	53.99372	16.33993
61.07050	52.92856	16.28775
61.12050	51.92986	16.23875
61.17217	50.89714	16.19086
61.22382	49.86488	16.13594
61.27550	48.83200	16.09158
61.32717	47.80000	16.03876
61.37883	46.76789	15.99474
61.43050	45.73588	15.94832
61.48217	44.70379	15.90276
61.53383	43.67150	15.85678
61.58383	42.67111	15.80331
61.63716	41.60512	15.74949
61.68716	40.60620	15.69116
61.74050	39.53886	15.62593
61.79050	38.53902	15.56794
61.84384	37.47275	15.48684
61.89384	36.47199	15.43786
61.94717	35.40604	15.35829
61.99717	34.40488	15.29508
62.05050	33.33691	15.21983
62.10050	32.33664	15.14550
62.15383	31.26805	15.08394
62.20383	30.26890	15.01189
62.25550	29.23439	14.95299
62.30717	28.20118	14.86327
62.35883	27.16624	14.79891
62.41050	26.13064	14.72176
62.46216	25.09582	14.67692
62.51050	24.12812	14.67967
62.56050	23.22369	15.11989
62.61382	22.82644	10.71488
62.66382	22.81438	5.697467
62.71717	23.07584	1.127483
62.76716	23.50620	-2.154747
62.82050	24.11320	-4.843430
62.87050	24.78328	-6.747274
62.92217	25.55044	-8.271069
62.97382	26.37602	-9.435399
63.02550	27.24485	-10.35248
63.07717	28.14625	-11.06874
63.12883	29.07139	-11.64482
63.18050	30.01563	-12.10111
63.23217	30.97490	-12.49006
63.28383	31.94165	-12.81693
63.33383	32.88826	-13.09120
63.38716	33.90392	-13.33153
63.43716	34.86182	-13.53487
63.49050	35.88925	-13.73018
63.54050	36.85514	-13.89473
63.59384	37.88806	-14.05590
63.64384	38.85906	-14.19114
63.69717	39.89774	-14.33667
63.74717	40.87370	-14.45643
63.80050	41.91668	-14.58109
63.85050	42.89385	-14.69309
63.90383	43.94184	-14.79995
63.95383	44.92234	-14.90291
64.00550	45.93863	-15.00317
64.05717	46.95582	-15.10724
64.10884	47.97340	-15.20837
64.16050	48.99030	-15.30436
64.21217	50.00976	-15.40614
64.26384	51.02911	-15.50632
64.31550	52.04878	-15.60885
64.36718	53.06843	-15.70667
64.41717	54.05751	-15.80817
64.47050	55.11162	-15.90280
64.52050	56.10019	-16.00216
64.57384	57.15569	-16.09859
64.62383	58.14585	-16.19864
64.67718	59.20230	-16.28893
64.72718	60.19239	-16.38452
64.78050	61.24934	-16.49790
64.83050	62.24050	-16.58138
64.88384	63.29773	-16.68089
64.93384	64.28925	-16.77479
64.98717	65.34754	-16.86580
65.03717	66.33907	-16.95794
65.08884	67.36536	-17.05589
65.14050	68.39180	-17.14719
65.19217	69.41775	-17.23108
65.24384	70.44472	-17.32054
65.29550	71.47068	-17.41897
65.34717	72.49740	-17.51034
65.39883	73.52399	-17.59808
65.45050	74.55110	-17.69473
65.50050	75.54455	-17.78125
65.55384	76.60400	-17.87644
65.60384	77.59765	-17.97776
65.65718	78.65747	-18.07712
65.70718	79.65063	-18.16741
65.76050	80.71021	-18.27713
65.81050	81.70416	-18.37336
65.86384	82.76484	-18.47473
65.91382	83.75691	-18.57177
65.96718	84.81828	-18.67959
66.01716	85.81134	-18.77741
66.07050	86.87206	-18.88344
66.12050	87.86659	-18.98446
66.17218	88.89478	-19.08320
66.22384	89.92288	-19.18452
66.27550	90.95022	-19.27972
66.32718	91.97728	-19.37670
66.37884	93.00566	-19.48225
66.43050	94.03449	-19.57856
66.48218	95.06099	-19.67446
66.53384	96.08884	-19.78203
66.58384	97.08395	-19.87094
66.63718	98.14399	-19.97822
66.68718	99.13774	-20.08017
66.74050	100.1976	-20.17530
66.79050	101.1924	-20.28230
66.84384	102.2532	-20.38601
66.89384	103.2458	-20.48433
66.94718	104.3063	-20.60522
66.99718	105.3004	-20.70982
67.05050	106.3602	-20.82139
67.10050	107.3555	-20.92856
67.15384	108.4150	-21.02916
67.20384	109.4113	-21.14092
67.25550	110.4392	-21.24673
67.30718	111.4660	-21.34636
67.35884	112.4941	-21.45464
67.41050	113.5219	-21.56020
67.46218	114.5491	-21.67058
67.51384	115.5775	-21.77810
67.56550	116.6054	-21.87605
67.61718	117.6328	-21.98432
67.66718	118.6268	-22.08954
67.72050	119.6872	-22.21208
67.77050	120.6810	-22.33015
67.82384	121.7409	-22.44984
67.87384	122.7344	-22.56614
67.92718	123.7948	-22.69022
67.97718	124.7886	-22.80719
68.03050	125.8486	-22.92948
68.08050	126.8429	-23.03709
68.13384	127.9037	-23.15706
68.18384	128.8978	-23.26629
68.23718	129.9581	-23.39248
68.28718	130.9520	-23.51310
68.33884	131.9796	-23.63629
68.39050	133.0065	-23.75888
68.44218	134.0326	-23.88777
68.49384	135.0582	-24.02492
68.54550	136.0848	-24.15662
68.59718	137.1106	-24.30296
68.64884	138.1368	-24.43724
68.70050	139.1627	-24.57098
68.75050	140.1558	-24.70945
68.80384	141.2157	-24.85213
68.85384	142.2098	-24.98510
68.90718	143.2672	-25.13566
68.95718	144.2602	-25.27422
69.01050	145.3184	-25.41491
69.06050	146.3115	-25.55203
69.11384	147.3693	-25.68706
69.16382	148.3619	-25.82194
69.21718	149.4197	-25.95281
69.26716	150.4122	-26.07510
69.32050	151.4716	-26.21356
69.37050	152.4650	-26.35719
69.42218	153.4922	-26.48416
69.47384	154.5174	-26.62448
69.52550	155.5456	-26.72893
69.57718	156.5754	-26.77844
69.62884	157.6037	-26.88258
69.68050	158.6322	-26.99852
69.73218	159.6601	-27.10668
69.78384	160.6886	-27.21399
69.83384	161.6842	-27.30638
69.88718	162.7477	-27.39510
69.93718	163.7434	-27.47033
69.99050	164.8064	-27.53896
70.04050	165.8032	-27.61142
70.09384	166.8661	-27.69123
70.14384	167.8635	-27.76270
70.19718	168.9258	-27.84857
70.24718	169.9213	-27.93952
70.30050	170.9821	-28.06082
70.35050	171.9779	-28.18542
70.40384	173.0387	-28.31724
70.45384	174.0314	-28.45290
70.50550	175.0565	-28.61941
70.55718	176.0825	-28.78847
70.60884	177.1044	-28.98441
70.66050	178.1275	-29.21345
70.71218	179.1486	-29.46047
70.76384	180.1691	-29.72461
70.81550	181.1873	-30.03298
70.86718	182.2036	-30.34790
70.91718	183.1853	-30.70066
70.97050	184.2307	-31.12585
71.02050	185.2082	-31.55096
71.07384	186.2492	-32.05351
71.12384	187.2216	-32.56756
71.17718	188.2564	-33.17547
71.22718	189.2235	-33.78567
71.28050	190.2509	-34.49191
71.33050	191.2125	-35.20318
71.38384	192.2353	-35.97583
71.43384	193.1929	-36.71736
71.48718	194.2126	-37.52649
71.53718	195.1680	-38.28754
71.58884	196.1537	-39.11755
71.64050	197.1386	-39.96472
71.69218	198.1215	-40.86262
71.74384	199.1012	-41.81689
71.79550	200.0805	-42.83250
71.84718	201.0539	-43.88164
71.89884	202.0271	-44.92444
71.95050	203.0001	-45.91479
72.00050	203.9453	-46.70008
72.05384	204.9627	-47.27580
72.10384	205.9324	-47.35383
72.15718	206.9944	-46.82183
72.20718	208.0275	-45.32864
72.26050	209.1805	-42.75484
72.31050	210.3095	-39.66278
72.36384	211.5502	-36.45092
72.41382	212.7093	-34.27356
72.46718	213.9160	-32.76820
72.51716	215.0170	-31.79565
72.57050	216.1632	-31.05427
72.62050	217.2173	-30.54865
72.67218	218.2924	-30.16794
72.72384	219.3552	-29.91037
72.77550	220.4105	-29.73118
72.82718	221.4583	-29.62028
72.87884	222.5040	-29.55700
72.93050	223.5445	-29.51954
72.98218	224.5828	-29.50205
73.03384	225.6200	-29.49717
73.08384	226.6210	-29.49717
73.13718	227.6883	-29.49840
73.18718	228.6884	-29.50915
73.24050	229.7549	-29.54358
73.29050	230.7539	-29.58779
73.34384	231.8190	-29.65726
73.39384	232.8171	-29.72664
73.44718	233.8816	-29.80060
73.49718	234.8790	-29.86570
73.55050	235.9428	-29.93122
73.60050	236.9407	-29.98670
73.65384	238.0042	-30.05528
73.70384	239.0018	-30.11924
73.75550	240.0320	-30.19398
73.80718	241.0625	-30.25857
73.85884	242.0935	-30.33188
73.91050	243.1246	-30.40307
73.96218	244.1555	-30.45700
74.01384	245.1851	-30.52339
74.06550	246.2138	-30.59935
74.11718	247.2441	-30.66648
74.16718	248.2402	-30.73084
74.22050	249.3022	-30.80136
74.27050	250.2993	-30.87256
74.32384	251.3606	-30.94312
74.37384	252.3579	-31.01395
74.42718	253.4210	-31.07720
74.47718	254.4168	-31.14205
74.53050	255.4798	-31.22840
74.58050	256.4768	-31.30548
74.63384	257.5398	-31.37887
74.68384	258.5357	-31.46320
74.73718	259.5990	-31.54353
74.78718	260.5959	-31.60686
74.83884	261.6261	-31.68161
74.89050	262.6566	-31.75108
74.94218	263.6861	-31.82491
74.99384	264.7150	-31.90301
75.04550	265.7453	-31.98276
75.09718	266.7741	-32.04164
75.14884	267.8038	-32.12486
75.20050	268.8340	-32.19320
75.25050	269.8328	-32.25557
75.30384	270.8974	-32.30170
-2.000000	5.000000	0.0000000