File: 5-C1(1.4mol%)+C20(0.6mol%)/matlab/150-1.txt
CLOSED
Version	1.0
Language	English
Mode	Standard
Run	19
RunSerial	12321
Instrument	DSC Q2000 V24.11 Build 124
Module	DSC Standard Cell RC
Operator
File	\\AE520-1454\Users\dsc\Desktop\Data\31-08-17-2\150-1.001
ProcName
InstSerial	2000-0883
AutoSerial	1293
Sample	150-1
Size	23.6000	mg
PanMass	Not available
PanResist	Automatic Automatic  K/W
PanFactor	Default Default
Method
Comment
Xcomment	Pan: Tzero Aluminum Hermetic
Xcomment	Gas1: Nitrogen 50.0 ml/min
Xcomment	Gas2: Nitrogen 50.0 ml/min
Text
Exotherm	UP
Kcell	1.05230
Cpconst	Standard: 0.938
Calib	-38.6961
TempCal	1	pts	157.46	156.60
TzeroDt	-87.6168 -0.0009 -1.4231
TzeroDtz	-87.6168 0.0057 6.9570
InstCalFile	Tzero: \\Ae520-1454\ta\Data\DSC\Calibration\2017\CALIBRATION\1562_RCS (90)_05_18_2017 10_50_44.TZR
InstCalFile	Baseline: \\Ae520-1454\ta\Data\DSC\Calibration\2017\2017-05-17_Calibration.001
InstCalFile	Sapphire: \\Ae520-1454\ta\Data\DSC\Calibration\2017\2017-05-17_Saphire.001
InstCalDate	Tzero 2017-05-18 Time 10:50:44
TempRange	-87.39 to 398.39 °C at 10.00 °C/min Heat Only
AutoZero	Delta T Offset 0.000 uV
AutoZero	Delta T0 Offset 0.000 uV
MultiptCal	0
MultiPtDesc	0) Not set
AutoCellConst	Calibration Date 2017-05-18 16:59:28
Controls	Gas 1  Event Off  Sampling 0.2
Cell#	RC-01562
CoolingUnit	RCS (90)
SelHeatFlow	Heat Flow T4P (mW)
AutoLidII	Installed
AutoAnalysis	Off
MacroFile
Nsig	3
Sig1	Time (min)
Sig2	Temperature (°C)
Sig3	Heat Flow (mW)
Date	2017-09-01
Time	10:17:37
OrgMethod	1: Equilibrate at 80.00 °C
OrgMethod	2: Isothermal for 3.00 min
OrgMethod	3: Jump to 150.00 °C
OrgMethod	4: Mark end of cycle 1
OrgMethod	5: Isothermal for 40.00 min
OrgMethod	6: Mark end of cycle 2
OrgMethod	7: Ramp 20.00 °C/min to 280.00 °C
OrgMethod	8: Mark end of cycle 3
OrgMethod	9: Ramp 20.00 °C/min to 20.00 °C
OrgMethod	10: Mark end of cycle 4
OrgMethod	11: Ramp 20.00 °C/min to 280.00 °C
OrgMethod	12: Mark end of cycle 5
OrgFile	C:\Users\jarra\Desktop\DSC\5-C1(1.4mol%)+C20(0.6mol%)\150-1.001
StartOfData
4.99994E-4	79.81540	-2.159642
0.05383332	79.83579	-1.846172
0.1038333	79.85010	-1.628448
0.1571666	79.85989	-1.456403
0.2071666	79.86701	-1.341632
0.2605000	79.87100	-1.253443
0.3105000	79.87280	-1.195196
0.3638334	79.87424	-1.151166
0.4138333	79.87564	-1.124812
0.4671667	79.87594	-1.106165
0.5171667	79.87579	-1.096340
0.5705000	79.87456	-1.089649
0.6205000	79.87244	-1.086709
0.6721668	79.87212	-1.084148
0.7238332	79.87120	-1.081541
0.7755000	79.87000	-1.079148
0.8271668	79.86776	-1.076990
0.8788332	79.86722	-1.075023
0.9305000	79.86649	-1.073375
0.9821668	79.86475	-1.071960
1.033833	79.86322	-1.070792
1.083833	79.86309	-1.070031
1.137166	79.86114	-1.069386
1.187166	79.86064	-1.069108
1.240500	79.85852	-1.069104
1.290500	79.85888	-1.069241
1.343833	79.85716	-1.069582
1.393833	79.85650	-1.070123
1.447166	79.85522	-1.070867
1.497166	79.85503	-1.071743
1.550500	79.85321	-1.072734
1.600500	79.85334	-1.073909
1.653833	79.85239	-1.075237
1.703833	79.85110	-1.076656
1.755500	79.84984	-1.078246
1.807167	79.84868	-1.080026
1.858834	79.84834	-1.081850
1.910500	79.84812	-1.083761
1.962166	79.84731	-1.085801
2.013833	79.84636	-1.087894
2.065500	79.84588	-1.090019
2.117167	79.84522	-1.092262
2.167167	79.84545	-1.094606
2.220500	79.84425	-1.097014
2.270500	79.84335	-1.099301
2.323833	79.84238	-1.101761
2.373834	79.84160	-1.104104
2.427167	79.84124	-1.106684
2.477167	79.84144	-1.109138
2.530500	79.84014	-1.111733
2.580500	79.83988	-1.114262
2.633833	79.83911	-1.116906
2.683833	79.83851	-1.119476
2.737167	79.83718	-1.122088
2.787167	79.83780	-1.124698
2.838833	79.83726	-1.127310
2.890500	79.83645	-1.129908
2.942167	79.83576	-1.132525
2.993833	79.83594	-1.135170
3.040500	79.98386	-3.935878
3.093834	81.64316	-18.96263
3.143833	84.08293	-30.49488
3.197167	87.24881	-41.81030
3.247166	90.62186	-51.02891
3.300500	94.53936	-59.32850
3.350500	98.43438	-65.73865
3.403833	102.7562	-71.37240
3.453833	106.9276	-75.63040
3.505500	111.3178	-79.22759
3.557167	115.7609	-82.15260
3.608833	120.2355	-84.66171
3.660500	124.7298	-86.73632
3.712167	129.2373	-88.40880
3.763833	133.7030	-88.97249
3.815500	137.3262	-80.34306
3.867166	139.8072	-68.37424
3.917167	141.6610	-57.61584
3.970500	143.1685	-47.20856
4.020500	144.2692	-38.95231
4.073834	145.1881	-31.70818
4.123833	145.8730	-26.22832
4.177166	146.4547	-21.57875
4.227167	146.8954	-18.14260
4.280500	147.2789	-15.26013
4.330500	147.5734	-13.13421
4.383834	147.8369	-11.34427
4.433834	148.0424	-10.01696
4.487167	148.2295	-8.888500
4.537167	148.3786	-8.042055
4.588834	148.5107	-7.338525
4.640500	148.6256	-6.767074
4.692166	148.7255	-6.293850
4.743834	148.8127	-5.892510
4.795500	148.8899	-5.552874
4.847166	148.9586	-5.261897
4.898834	149.0191	-5.012820
4.950500	149.0737	-4.789324
5.000500	149.1193	-4.602876
5.053834	149.1642	-4.432763
5.103833	149.2020	-4.286104
5.157166	149.2387	-4.140820
5.207167	149.2698	-4.022290
5.260500	149.2988	-3.910264
5.310500	149.3250	-3.811401
5.363834	149.3489	-3.712744
5.413832	149.3692	-3.633620
5.467168	149.3899	-3.554059
5.517168	149.4067	-3.484715
5.570500	149.4234	-3.418904
5.620500	149.4372	-3.361428
5.672168	149.4506	-3.310680
5.723834	149.4634	-3.260924
5.775500	149.4743	-3.210341
5.827168	149.4850	-3.163802
5.878834	149.4954	-3.118613
5.930500	149.5046	-3.073828
5.982168	149.5122	-3.030436
6.033832	149.5201	-2.989112
6.083832	149.5268	-2.951086
6.137168	149.5354	-2.911434
6.187168	149.5413	-2.871852
6.240500	149.5478	-2.832214
6.290500	149.5536	-2.795094
6.343834	149.5598	-2.756292
6.393832	149.5655	-2.718633
6.447168	149.5707	-2.676692
6.497168	149.5766	-2.637411
6.550500	149.5822	-2.594128
6.600500	149.5866	-2.553619
6.653832	149.5912	-2.508042
6.703832	149.5974	-2.467190
6.755500	149.6016	-2.421626
6.807166	149.6062	-2.375266
6.858832	149.6108	-2.330367
6.910500	149.6161	-2.283256
6.962168	149.6201	-2.234890
7.013834	149.6250	-2.184938
7.065500	149.6297	-2.133762
7.117166	149.6344	-2.082920
7.167168	149.6390	-2.032334
7.220500	149.6426	-1.974723
7.270500	149.6482	-1.922344
7.323834	149.6533	-1.865962
7.373834	149.6562	-1.807008
7.427168	149.6624	-1.747656
7.477168	149.6659	-1.686441
7.530500	149.6719	-1.625308
7.580500	149.6759	-1.561478
7.633832	149.6820	-1.498223
7.683832	149.6859	-1.433200
7.737168	149.6917	-1.363316
7.787168	149.6953	-1.296322
7.838834	149.7013	-1.228319
7.890500	149.7065	-1.157574
7.942168	149.7124	-1.088078
7.993834	149.7177	-1.012115
8.045500	149.7233	-0.9396181
8.097168	149.7293	-0.8641920
8.148834	149.7340	-0.7845794
8.200500	149.7401	-0.7077594
8.250500	149.7457	-0.6292786
8.303832	149.7514	-0.5464020
8.353832	149.7567	-0.4691119
8.407166	149.7622	-0.3813011
8.457168	149.7685	-0.3011214
8.510499	149.7736	-0.2142078
8.560500	149.7801	-0.1331302
8.613834	149.7861	-.04327803
8.663834	149.7918	0.04497250
8.717168	149.8004	0.1463236
8.767168	149.8076	0.2580118
8.820500	149.8171	0.4080010
8.870499	149.8276	0.5738070
8.922168	149.8412	0.7802612
8.973832	149.8563	1.024481
9.025499	149.8739	1.294395
9.077168	149.8934	1.594561
9.128834	149.9143	1.910892
9.180500	149.9358	2.237338
9.232166	149.9574	2.570625
9.283832	149.9790	2.899463
9.333832	150.0008	3.215579
9.387168	150.0219	3.542680
9.437166	150.0416	3.835662
9.490500	150.0618	4.135810
9.540500	150.0793	4.394691
9.593832	150.0964	4.650161
9.643832	150.1117	4.864194
9.697168	150.1257	5.072217
9.747168	150.1379	5.237889
9.800500	150.1489	5.387318
9.850500	150.1572	5.505756
9.903832	150.1633	5.603540
9.953834	150.1701	5.669650
10.00550	150.1732	5.720745
10.05717	150.1766	5.750109
10.10883	150.1774	5.763224
10.16050	150.1780	5.766729
10.21217	150.1780	5.767527
10.26383	150.1760	5.766411
10.31550	150.1734	5.754551
10.36717	150.1705	5.716588
10.41717	150.1668	5.652130
10.47050	150.1622	5.564560
10.52050	150.1578	5.475120
10.57383	150.1510	5.378335
10.62383	150.1460	5.286980
10.67717	150.1399	5.186531
10.72717	150.1351	5.094063
10.78050	150.1275	4.994603
10.83050	150.1212	4.901686
10.88383	150.1154	4.801975
10.93383	150.1091	4.712652
10.98717	150.1035	4.615894
11.03717	150.0975	4.528559
11.08883	150.0919	4.440152
11.14050	150.0868	4.352131
11.19217	150.0817	4.269802
11.24384	150.0762	4.189420
11.29550	150.0716	4.112336
11.34717	150.0671	4.036690
11.39883	150.0622	3.964557
11.45050	150.0575	3.897011
11.50050	150.0536	3.833730
11.55383	150.0487	3.767624
11.60383	150.0449	3.710010
11.65717	150.0401	3.651036
11.70717	150.0361	3.594575
11.76050	150.0322	3.538654
11.81050	150.0282	3.486988
11.86383	150.0246	3.434561
11.91383	150.0214	3.387460
11.96717	150.0171	3.336617
12.01717	150.0141	3.291517
12.07050	150.0099	3.244098
12.12050	150.0070	3.200416
12.17217	150.0051	3.157293
12.22383	150.0014	3.119992
12.27550	149.9994	3.079082
12.32717	149.9965	3.041731
12.37884	149.9940	3.003657
12.43050	149.9912	2.966790
12.48217	149.9889	2.932152
12.53383	149.9864	2.898918
12.58383	149.9846	2.866465
12.63717	149.9826	2.834369
12.68716	149.9803	2.804741
12.74050	149.9780	2.775031
12.79050	149.9764	2.744701
12.84383	149.9757	2.713884
12.89383	149.9739	2.686302
12.94717	149.9717	2.659467
12.99717	149.9703	2.634798
13.05050	149.9680	2.609764
13.10050	149.9664	2.587507
13.15383	149.9648	2.563614
13.20383	149.9642	2.542650
13.25550	149.9613	2.522492
13.30717	149.9592	2.500152
13.35883	149.9586	2.478434
13.41050	149.9570	2.456301
13.46217	149.9551	2.431724
13.51383	149.9539	2.405975
13.56550	149.9523	2.382496
13.61716	149.9510	2.359020
13.66716	149.9497	2.337376
13.72050	149.9481	2.317575
13.77050	149.9459	2.296973
13.82384	149.9442	2.276960
13.87384	149.9434	2.256799
13.92717	149.9416	2.235539
13.97717	149.9408	2.215224
14.03050	149.9384	2.192600
14.08050	149.9372	2.172024
14.13383	149.9357	2.150862
14.18383	149.9341	2.128707
14.23716	149.9314	2.107521
14.28717	149.9310	2.086289
14.33883	149.9298	2.064573
14.39050	149.9280	2.042982
14.44217	149.9266	2.021388
14.49384	149.9264	1.997361
14.54550	149.9246	1.975364
14.59717	149.9242	1.953796
14.64883	149.9226	1.933419
14.70050	149.9211	1.914116
14.75050	149.9193	1.895244
14.80383	149.9188	1.875965
14.85383	149.9175	1.859121
14.90717	149.9158	1.839675
14.95717	149.9137	1.821752
15.01050	149.9124	1.801965
15.06050	149.9118	1.782703
15.11383	149.9096	1.762308
15.16383	149.9079	1.742251
15.21716	149.9068	1.717231
15.26717	149.9058	1.695394
15.32050	149.9048	1.674788
15.37050	149.9030	1.655900
15.42217	149.9015	1.634059
15.47383	149.9007	1.610264
15.52550	149.8992	1.589426
15.57717	149.8981	1.567626
15.62883	149.8969	1.546720
15.68050	149.8952	1.525839
15.73216	149.8943	1.506382
15.78383	149.8927	1.486654
15.83383	149.8906	1.467314
15.88716	149.8892	1.445356
15.93717	149.8879	1.424212
15.99050	149.8867	1.401541
16.04050	149.8849	1.381525
16.09383	149.8839	1.359712
16.14383	149.8830	1.339609
16.19717	149.8810	1.319491
16.24716	149.8800	1.300449
16.30050	149.8785	1.281048
16.35050	149.8770	1.263331
16.40383	149.8760	1.244177
16.45383	149.8757	1.225409
16.50550	149.8739	1.207448
16.55716	149.8735	1.188885
16.60883	149.8724	1.172899
16.66050	149.8717	1.158532
16.71216	149.8700	1.146207
16.76383	149.8691	1.132918
16.81550	149.8676	1.121587
16.86716	149.8671	1.109662
16.91716	149.8667	1.099524
16.97050	149.8656	1.088390
17.02050	149.8655	1.078667
17.07383	149.8634	1.068642
17.12383	149.8631	1.058786
17.17716	149.8617	1.048454
17.22716	149.8610	1.038849
17.28050	149.8604	1.028634
17.33050	149.8596	1.018897
17.38383	149.8584	1.008282
17.43383	149.8577	0.9987199
17.48716	149.8565	0.9877711
17.53717	149.8563	0.9779118
17.58883	149.8555	0.9672564
17.64050	149.8543	0.9565332
17.69216	149.8541	0.9457853
17.74383	149.8528	0.9351004
17.79550	149.8523	0.9232734
17.84716	149.8520	0.9118539
17.89883	149.8507	0.9007288
17.95050	149.8495	0.8885642
18.00050	149.8499	0.8775387
18.05383	149.8483	0.8652593
18.10383	149.8478	0.8522293
18.15716	149.8477	0.8362995
18.20716	149.8469	0.8247711
18.26050	149.8458	0.8128499
18.31050	149.8448	0.8007800
18.36383	149.8432	0.7864459
18.41383	149.8419	0.7730570
18.46716	149.8418	0.7558954
18.51716	149.8407	0.7398528
18.57050	149.8392	0.7228732
18.62050	149.8380	0.7043598
18.67216	149.8367	0.6850278
18.72383	149.8361	0.6648719
18.77550	149.8340	0.6459390
18.82716	149.8327	0.6243734
18.87883	149.8316	0.6004668
18.93050	149.8306	0.5761856
18.98216	149.8285	0.5484925
19.03383	149.8270	0.5181433
19.08383	149.8262	0.4904750
19.13716	149.8244	0.4623546
19.18716	149.8230	0.4371175
19.24050	149.8211	0.4098810
19.29050	149.8194	0.3815244
19.34383	149.8181	0.3502448
19.39383	149.8153	0.3237780
19.44716	149.8139	0.2918047
19.49716	149.8126	0.2592219
19.55050	149.8104	0.2275331
19.60050	149.8085	0.1974733
19.65383	149.8071	0.1600498
19.70383	149.8056	0.1273981
19.75550	149.8039	0.09135539
19.80716	149.8020	0.05798191
19.85883	149.7998	0.02469007
19.91050	149.7980	-6.4770E-3
19.96216	149.7960	-.03831958
20.01383	149.7931	-.06924674
20.06550	149.7911	-0.1010939
20.11716	149.7881	-0.1333028
20.16716	149.7866	-0.1659482
20.22050	149.7849	-0.2001477
20.27050	149.7820	-0.2332611
20.32383	149.7804	-0.2692258
20.37383	149.7778	-0.3000203
20.42716	149.7761	-0.3370698
20.47716	149.7734	-0.3695185
20.53050	149.7713	-0.4054502
20.58050	149.7683	-0.4373328
20.63383	149.7666	-0.4725268
20.68383	149.7649	-0.5040550
20.73716	149.7628	-0.5389220
20.78717	149.7607	-0.5699430
20.83883	149.7595	-0.6022857
20.89050	149.7567	-0.6348290
20.94216	149.7552	-0.6662056
20.99383	149.7537	-0.6964356
21.04550	149.7514	-0.7253416
21.09716	149.7486	-0.7542385
21.14883	149.7476	-0.7846068
21.20050	149.7456	-0.8128160
21.25050	149.7434	-0.8411575
21.30383	149.7423	-0.8708312
21.35383	149.7410	-0.8984447
21.40716	149.7383	-0.9261681
21.45717	149.7363	-0.9549944
21.51050	149.7349	-0.9834830
21.56050	149.7319	-1.009646
21.61383	149.7305	-1.039482
21.66383	149.7276	-1.066019
21.71716	149.7260	-1.094155
21.76716	149.7246	-1.120351
21.82050	149.7220	-1.146721
21.87050	149.7192	-1.175170
21.92216	149.7177	-1.203062
21.97383	149.7160	-1.230016
22.02550	149.7132	-1.256919
22.07716	149.7117	-1.283911
22.12883	149.7094	-1.311516
22.18050	149.7082	-1.338194
22.23216	149.7062	-1.365072
22.28383	149.7033	-1.391683
22.33383	149.7015	-1.416879
22.38716	149.7022	-1.448175
22.43716	149.6993	-1.471160
22.49050	149.6971	-1.497854
22.54050	149.6965	-1.525650
22.59383	149.6956	-1.551225
22.64383	149.6937	-1.574359
22.69716	149.6909	-1.597207
22.74716	149.6910	-1.620809
22.80050	149.6895	-1.645448
22.85050	149.6881	-1.665930
22.90383	149.6872	-1.688557
22.95383	149.6854	-1.709194
23.00550	149.6835	-1.732528
23.05716	149.6814	-1.754291
23.10883	149.6804	-1.776781
23.16050	149.6791	-1.796692
23.21216	149.6776	-1.816480
23.26383	149.6756	-1.835988
23.31550	149.6740	-1.856605
23.36716	149.6728	-1.876558
23.41716	149.6712	-1.895251
23.47050	149.6692	-1.916856
23.52050	149.6676	-1.939655
23.57383	149.6675	-1.963169
23.62383	149.6654	-1.982303
23.67717	149.6644	-2.003476
23.72716	149.6628	-2.020705
23.78050	149.6612	-2.040696
23.83050	149.6606	-2.057465
23.88383	149.6585	-2.076926
23.93383	149.6578	-2.093941
23.98716	149.6562	-2.110967
24.03717	149.6552	-2.126990
24.08883	149.6539	-2.143496
24.14050	149.6527	-2.160017
24.19216	149.6515	-2.175516
24.24383	149.6495	-2.191185
24.29550	149.6484	-2.207094
24.34716	149.6471	-2.223694
24.39883	149.6461	-2.238546
24.45050	149.6439	-2.253833
24.50050	149.6439	-2.269307
24.55383	149.6420	-2.285639
24.60383	149.6399	-2.300646
24.65716	149.6392	-2.316850
24.70717	149.6380	-2.330748
24.76050	149.6380	-2.345709
24.81050	149.6363	-2.359333
24.86383	149.6352	-2.375452
24.91383	149.6346	-2.388902
24.96716	149.6334	-2.402742
25.01716	149.6326	-2.416008
25.07050	149.6317	-2.430616
25.12050	149.6314	-2.445808
25.17216	149.6308	-2.459444
25.22383	149.6296	-2.472269
25.27550	149.6284	-2.484163
25.32716	149.6290	-2.497648
25.37883	149.6280	-2.508049
25.43050	149.6274	-2.519412
25.48216	149.6259	-2.529251
25.53383	149.6259	-2.539459
25.58383	149.6239	-2.549106
25.63716	149.6240	-2.559657
25.68717	149.6226	-2.569817
25.74050	149.6219	-2.580267
25.79050	149.6211	-2.590132
25.84383	149.6201	-2.600680
25.89383	149.6190	-2.610744
25.94717	149.6182	-2.621830
25.99716	149.6182	-2.632982
26.05050	149.6169	-2.644159
26.10050	149.6171	-2.655128
26.15383	149.6155	-2.666601
26.20383	149.6152	-2.676852
26.25550	149.6143	-2.687417
26.30716	149.6140	-2.697908
26.35883	149.6126	-2.708490
26.41050	149.6133	-2.719338
26.46216	149.6117	-2.729820
26.51383	149.6117	-2.740280
26.56550	149.6108	-2.750589
26.61716	149.6098	-2.760913
26.66716	149.6093	-2.770731
26.72050	149.6090	-2.781069
26.77050	149.6084	-2.790714
26.82383	149.6080	-2.800872
26.87383	149.6070	-2.810332
26.92717	149.6050	-2.820303
26.97717	149.6056	-2.829690
27.03050	149.6051	-2.839613
27.08050	149.6046	-2.848944
27.13383	149.6044	-2.858864
27.18383	149.6045	-2.868047
27.23716	149.6019	-2.877716
27.28717	149.6026	-2.886728
27.33883	149.6023	-2.895910
27.39050	149.6012	-2.904820
27.44216	149.6002	-2.913556
27.49383	149.6002	-2.922324
27.54550	149.5994	-2.930908
27.59716	149.5991	-2.939539
27.64883	149.5991	-2.948124
27.70050	149.5982	-2.956675
27.75050	149.5984	-2.964941
27.80383	149.5978	-2.973624
27.85383	149.5980	-2.981608
27.90716	149.5971	-2.990067
27.95716	149.5978	-2.997953
28.01050	149.5974	-3.006154
28.06050	149.5969	-3.013830
28.11383	149.5960	-3.021705
28.16383	149.5957	-3.029107
28.21716	149.5952	-3.036889
28.26716	149.5944	-3.044000
28.32050	149.5946	-3.051510
28.37050	149.5946	-3.058430
28.42216	149.5937	-3.065476
28.47383	149.5931	-3.072392
28.52550	149.5929	-3.079235
28.57717	149.5927	-3.085986
28.62883	149.5918	-3.092774
28.68050	149.5918	-3.099475
28.73216	149.5911	-3.105992
28.78383	149.5908	-3.112525
28.83383	149.5907	-3.118750
28.88716	149.5907	-3.125332
28.93717	149.5898	-3.131406
28.99050	149.5898	-3.137734
29.04050	149.5888	-3.143560
29.09383	149.5892	-3.149748
29.14383	149.5882	-3.155334
29.19717	149.5878	-3.161260
29.24716	149.5874	-3.166686
29.30050	149.5873	-3.172416
29.35050	149.5865	-3.177794
29.40383	149.5865	-3.183508
29.45383	149.5867	-3.188818
29.50550	149.5868	-3.194342
29.55716	149.5861	-3.199658
29.60883	149.5869	-3.205005
29.66050	149.5858	-3.210269
29.71216	149.5859	-3.215466
29.76383	149.5858	-3.220534
29.81550	149.5847	-3.225470
29.86716	149.5853	-3.230420
29.91716	149.5850	-3.235063
29.97050	149.5849	-3.240046
30.02050	149.5846	-3.244622
30.07383	149.5844	-3.249453
30.12383	149.5843	-3.253960
30.17717	149.5831	-3.258713
30.22717	149.5830	-3.263042
30.28050	149.5832	-3.267516
30.33050	149.5828	-3.271616
30.38383	149.5824	-3.275804
30.43383	149.5808	-3.279645
30.48716	149.5811	-3.283730
30.53717	149.5802	-3.287560
30.58883	149.5812	-3.291587
30.64050	149.5806	-3.295563
30.69216	149.5809	-3.299567
30.74383	149.5803	-3.303428
30.79550	149.5802	-3.307206
30.84716	149.5798	-3.310906
30.89883	149.5796	-3.314500
30.95050	149.5794	-3.318012
31.00050	149.5788	-3.321380
31.05383	149.5789	-3.324885
31.10383	149.5792	-3.328196
31.15716	149.5782	-3.331697
31.20716	149.5784	-3.335053
31.26050	149.5794	-3.338717
31.31050	149.5782	-3.342088
31.36383	149.5791	-3.345685
31.41383	149.5789	-3.348967
31.46716	149.5796	-3.352418
31.51716	149.5789	-3.355556
31.57050	149.5790	-3.358844
31.62050	149.5788	-3.361902
31.67216	149.5796	-3.365009
31.72383	149.5795	-3.367973
31.77550	149.5794	-3.370856
31.82717	149.5791	-3.373776
31.87883	149.5786	-3.376460
31.93050	149.5787	-3.379096
31.98216	149.5777	-3.381657
32.03383	149.5776	-3.384184
32.08383	149.5773	-3.386581
32.13716	149.5776	-3.389108
32.18716	149.5779	-3.391470
32.24050	149.5768	-3.393942
32.29050	149.5770	-3.396164
32.34384	149.5762	-3.398604
32.39383	149.5764	-3.400923
32.44717	149.5762	-3.403497
32.49716	149.5761	-3.405736
32.55050	149.5770	-3.408220
32.60050	149.5766	-3.410380
32.65383	149.5761	-3.412778
32.70383	149.5758	-3.414870
32.75550	149.5759	-3.417002
32.80716	149.5757	-3.419034
32.85883	149.5748	-3.421007
32.91050	149.5738	-3.422983
32.96216	149.5743	-3.424862
33.01383	149.5741	-3.426764
33.06550	149.5742	-3.428726
33.11716	149.5749	-3.430690
33.16716	149.5740	-3.432648
33.22050	149.5735	-3.434729
33.27050	149.5739	-3.436558
33.32383	149.5744	-3.438568
33.37383	149.5739	-3.440409
33.42717	149.5745	-3.442362
33.47717	149.5734	-3.444278
33.53050	149.5738	-3.446344
33.58050	149.5745	-3.448172
33.63383	149.5744	-3.450112
33.68384	149.5741	-3.451887
33.73717	149.5740	-3.453816
33.78717	149.5738	-3.455361
33.83883	149.5739	-3.456990
33.89050	149.5731	-3.458556
33.94216	149.5731	-3.460076
33.99383	149.5723	-3.461481
34.04550	149.5724	-3.462858
34.09716	149.5730	-3.464241
34.14883	149.5723	-3.465602
34.20050	149.5724	-3.467000
34.25050	149.5729	-3.468455
34.30383	149.5724	-3.469978
34.35383	149.5728	-3.471481
34.40716	149.5732	-3.473097
34.45716	149.5732	-3.474541
34.51050	149.5739	-3.476190
34.56050	149.5726	-3.477578
34.61383	149.5737	-3.479089
34.66383	149.5730	-3.480454
34.71716	149.5734	-3.481856
34.76716	149.5732	-3.483012
34.82050	149.5723	-3.484225
34.87050	149.5718	-3.485246
34.92216	149.5724	-3.486346
34.97383	149.5717	-3.487437
35.02550	149.5725	-3.488657
35.07717	149.5722	-3.489850
35.12883	149.5728	-3.491108
35.18050	149.5734	-3.492288
35.23216	149.5724	-3.493447
35.28383	149.5727	-3.494605
35.33383	149.5726	-3.495731
35.38716	149.5726	-3.496944
35.43716	149.5726	-3.498024
35.49050	149.5722	-3.499141
35.54050	149.5723	-3.500144
35.59384	149.5722	-3.501196
35.64383	149.5719	-3.502064
35.69717	149.5707	-3.502942
35.74716	149.5712	-3.503736
35.80050	149.5707	-3.504616
35.85050	149.5710	-3.505489
35.90383	149.5703	-3.506511
35.95383	149.5704	-3.507477
36.00550	149.5710	-3.508506
36.05716	149.5716	-3.509542
36.10883	149.5709	-3.510572
36.16050	149.5708	-3.511566
36.21216	149.5707	-3.512559
36.26383	149.5710	-3.513560
36.31550	149.5709	-3.514532
36.36716	149.5712	-3.515375
36.41716	149.5709	-3.516258
36.47050	149.5702	-3.517145
36.52050	149.5708	-3.517908
36.57383	149.5702	-3.518644
36.62383	149.5702	-3.519356
36.67717	149.5706	-3.520080
36.72717	149.5708	-3.520852
36.78050	149.5708	-3.521698
36.83050	149.5694	-3.522484
36.88383	149.5701	-3.523372
36.93384	149.5710	-3.524288
36.98717	149.5704	-3.525141
37.03717	149.5697	-3.525944
37.08883	149.5706	-3.526609
37.14050	149.5703	-3.527223
37.19216	149.5701	-3.527880
37.24383	149.5695	-3.528528
37.29550	149.5704	-3.529244
37.34716	149.5697	-3.529967
37.39883	149.5699	-3.530648
37.45050	149.5692	-3.531392
37.50050	149.5694	-3.532085
37.55383	149.5693	-3.532706
37.60383	149.5694	-3.533354
37.65716	149.5694	-3.533997
37.70716	149.5693	-3.534667
37.76050	149.5690	-3.535328
37.81050	149.5689	-3.536062
37.86383	149.5691	-3.536910
37.91383	149.5697	-3.537593
37.96716	149.5695	-3.538404
38.01716	149.5686	-3.539055
38.07050	149.5693	-3.539776
38.12050	149.5698	-3.540258
38.17216	149.5690	-3.540790
38.22383	149.5698	-3.541287
38.27550	149.5690	-3.541881
38.32717	149.5696	-3.542466
38.37883	149.5682	-3.543062
38.43050	149.5692	-3.543769
38.48216	149.5686	-3.544365
38.53383	149.5690	-3.545020
38.58383	149.5694	-3.545520
38.63716	149.5681	-3.546091
38.68716	149.5684	-3.546685
38.74050	149.5683	-3.547313
38.79050	149.5691	-3.547912
38.84384	149.5691	-3.548523
38.89383	149.5700	-3.549174
38.94717	149.5694	-3.549821
38.99716	149.5692	-3.550416
39.05050	149.5697	-3.551063
39.10050	149.5701	-3.551642
39.15383	149.5699	-3.552228
39.20383	149.5704	-3.552649
39.25550	149.5704	-3.553193
39.30716	149.5703	-3.553688
39.35883	149.5698	-3.554142
39.41050	149.5699	-3.554582
39.46216	149.5701	-3.554988
39.51383	149.5706	-3.555300
39.56550	149.5698	-3.555688
39.61716	149.5704	-3.556006
39.66716	149.5697	-3.556290
39.72050	149.5697	-3.556550
39.77050	149.5693	-3.556965
39.82383	149.5692	-3.557258
39.87383	149.5692	-3.557540
39.92717	149.5686	-3.557773
39.97717	149.5688	-3.558086
40.03050	149.5687	-3.558350
40.08050	149.5673	-3.558579
40.13383	149.5681	-3.558854
40.18384	149.5682	-3.559116
40.23717	149.5673	-3.559316
40.28717	149.5678	-3.559519
40.33883	149.5675	-3.559746
40.39050	149.5676	-3.559996
40.44216	149.5676	-3.560172
40.49383	149.5672	-3.560477
40.54550	149.5679	-3.560858
40.59716	149.5676	-3.561289
40.64883	149.5671	-3.561700
40.70050	149.5670	-3.562275
40.75050	149.5678	-3.562637
40.80383	149.5670	-3.563092
40.85383	149.5673	-3.563483
40.90716	149.5671	-3.563865
40.95716	149.5674	-3.564228
41.01050	149.5671	-3.564601
41.06050	149.5675	-3.564983
41.11383	149.5678	-3.565386
41.16383	149.5680	-3.565894
41.21717	149.5685	-3.566418
41.26717	149.5679	-3.566968
41.32050	149.5684	-3.567420
41.37050	149.5679	-3.567800
41.42216	149.5681	-3.568152
41.47383	149.5688	-3.568444
41.52550	149.5684	-3.568787
41.57717	149.5684	-3.569153
41.62883	149.5686	-3.569512
41.68050	149.5684	-3.569890
41.73217	149.5675	-3.570264
41.78383	149.5682	-3.570700
41.83383	149.5677	-3.571044
41.88716	149.5679	-3.571440
41.93716	149.5667	-3.571661
41.99050	149.5675	-3.571890
42.04050	149.5681	-3.572107
42.09384	149.5673	-3.572210
42.14383	149.5671	-3.572300
42.19717	149.5664	-3.572424
42.24716	149.5666	-3.572598
42.30050	149.5665	-3.572873
42.35050	149.5671	-3.573166
42.40383	149.5671	-3.573612
42.45383	149.5664	-3.573955
42.50550	149.5672	-3.574283
42.55717	149.5673	-3.574608
42.60883	149.5677	-3.574950
42.66050	149.5671	-3.575180
42.71216	149.5670	-3.575479
42.76383	149.5676	-3.575882
42.81550	149.5676	-3.576234
42.86716	149.5678	-3.576602
42.91716	149.5672	-3.577000
42.97050	149.5679	-3.577346
43.01717	149.5691	-3.577805
43.07050	149.6364	-5.436209
43.12050	149.9501	-9.428606
43.17216	150.4606	-12.77316
43.22383	151.1070	-15.47447
43.27550	151.8525	-17.48005
43.32717	152.6690	-18.94899
43.37883	153.5408	-19.98389
43.43050	154.4484	-20.84913
43.48217	155.3804	-21.52552
43.53383	156.3320	-22.06510
43.58383	157.2666	-22.48479
43.63716	158.2751	-22.86034
43.68716	159.2294	-23.14241
43.74050	160.2530	-23.41940
43.79050	161.2194	-23.63918
43.84384	162.2532	-23.85581
43.89383	163.2255	-24.04038
43.94717	164.2656	-24.23374
43.99716	165.2428	-24.40979
44.05050	166.2858	-24.58473
44.10050	167.2658	-24.75025
44.15383	168.3130	-24.92609
44.20383	169.2951	-25.09464
44.25550	170.3099	-25.26973
44.30717	171.3256	-25.45914
44.35883	172.3425	-25.65110
44.41050	173.3591	-25.83049
44.46216	174.3754	-26.04383
44.51383	175.3929	-26.21816
44.56550	176.4105	-26.40541
44.61716	177.4288	-26.61067
44.66716	178.4130	-26.83258
44.72050	179.4624	-27.03843
44.77050	180.4464	-27.28488
44.82383	181.4941	-27.55618
44.87383	182.4789	-27.80075
44.92717	183.5258	-28.10339
44.97717	184.5088	-28.37254
45.03050	185.5569	-28.67832
45.08050	186.5394	-28.99232
45.13383	187.5838	-29.33562
45.18383	188.5630	-29.69348
45.23717	189.6058	-30.07661
45.28717	190.5818	-30.45719
45.33883	191.5908	-30.89005
45.39050	192.5971	-31.46338
45.44217	193.6046	-31.75255
45.49383	194.6121	-32.19522
45.54550	195.6169	-32.82440
45.59716	196.6178	-33.32455
45.64883	197.6176	-33.94256
45.70050	198.6124	-34.70476
45.75050	199.5549	-36.49814
45.80383	200.5641	-36.87334
45.85383	201.5095	-37.88876
45.90717	202.5092	-39.20930
45.95717	203.4378	-40.57220
46.01050	204.4195	-42.20422
46.06050	205.3314	-43.89188
46.11383	206.2937	-45.78730
46.16383	207.1894	-47.68411
46.21717	208.1394	-49.70980
46.26717	209.0306	-51.49406
46.32050	209.9848	-53.20154
46.37050	210.8879	-54.68061
46.42216	211.8254	-56.20276
46.47383	212.7650	-57.85715
46.52550	213.7009	-59.62261
46.57717	214.6297	-61.51226
46.62883	215.5576	-63.28466
46.68050	216.4925	-64.58526
46.73217	217.4564	-64.96445
46.78383	218.4694	-64.11982
46.83383	219.5192	-61.29478
46.88716	220.7372	-56.77052
46.93716	221.9547	-51.67693
46.99050	223.3210	-45.29554
47.04050	224.6354	-40.34105
47.09384	225.9846	-37.23464
47.14383	227.1849	-35.24940
47.19717	228.4085	-33.74548
47.24716	229.5168	-32.72056
47.30050	230.6665	-31.93276
47.35050	231.7240	-31.44691
47.40383	232.8356	-31.03628
47.45383	233.8655	-30.76831
47.50550	234.9208	-30.57861
47.55717	235.9711	-30.46920
47.60883	237.0154	-30.38475
47.66050	238.0560	-30.34413
47.71216	239.0938	-30.34026
47.76383	240.1292	-30.33828
47.81550	241.1625	-30.34145
47.86716	242.1955	-30.36372
47.91716	243.1946	-30.38146
47.97050	244.2602	-30.45030
48.02050	245.2602	-30.48045
48.07383	246.3253	-30.52396
48.12383	247.3238	-30.62684
48.17717	248.3887	-30.65907
48.22717	249.3877	-30.68887
48.28050	250.4500	-30.78848
48.33050	251.4484	-30.89400
48.38383	252.5092	-31.06672
48.43383	253.5032	-31.15196
48.48717	254.5662	-31.19838
48.53717	255.5628	-31.25225
48.58883	256.5928	-31.29771
48.64050	257.6253	-31.29671
48.69217	258.6556	-31.34460
48.74383	259.6880	-31.37312
48.79550	260.7173	-31.48518
48.84716	261.7484	-31.51977
48.89883	262.7804	-31.56784
48.95050	263.8097	-31.65622
49.00050	264.8068	-31.69301
49.05383	265.8696	-31.83124
49.10383	266.8667	-31.85461
49.15717	267.9300	-31.92246
49.20717	268.9268	-31.97422
49.26050	269.9902	-32.07986
49.31050	270.9865	-32.10588
49.36383	272.0494	-32.20477
49.41383	273.0469	-32.26416
49.46717	274.1088	-32.28001
49.51383	275.0393	-32.36306
49.56550	275.9225	-33.43396
49.61716	276.2370	-27.20700
49.66716	276.1918	-18.84712
49.72050	275.8796	-10.99167
49.77050	275.4153	-5.149861
49.82383	274.7852	-0.3469314
49.87383	274.1028	3.058417
49.92717	273.3006	5.808151
49.97717	272.4966	7.731210
50.03050	271.5986	9.293930
50.08050	270.7258	10.41451
50.13383	269.7720	11.31925
50.18383	268.8596	11.97367
50.23717	267.8724	12.52551
50.28717	266.9360	12.93464
50.33883	265.9612	13.26984
50.39050	264.9770	13.54839
50.44217	263.9885	13.77211
50.49383	262.9946	13.96006
50.54550	261.9976	14.12009
50.59716	260.9963	14.26335
50.64883	259.9919	14.38375
50.70050	258.9844	14.48624
50.75050	258.0085	14.57435
50.80383	256.9650	14.65092
50.85383	255.9858	14.72175
50.90717	254.9396	14.80332
50.95717	253.9588	14.86723
51.01050	252.9116	14.93215
51.06050	251.9274	14.98826
51.11383	250.8776	15.04739
51.16383	249.8925	15.09712
51.21717	248.8408	15.15252
51.26716	247.8539	15.19951
51.32050	246.8016	15.24706
51.37050	245.8144	15.29072
51.42217	244.7934	15.33040
51.47383	243.7723	15.36813
51.52550	242.7503	15.41080
51.57717	241.7287	15.44033
51.62883	240.7068	15.47236
51.68050	239.6845	15.50572
51.73217	238.6620	15.54188
51.78383	237.6388	15.57910
51.83383	236.6487	15.61147
51.88716	235.5917	15.64654
51.93716	234.6014	15.66928
51.99050	233.5441	15.69444
52.04050	232.5534	15.71663
52.09384	231.4944	15.73862
52.14384	230.5030	15.75677
52.19717	229.4446	15.77574
52.24717	228.4531	15.79838
52.30050	227.3942	15.82340
52.35050	226.4028	15.84740
52.40383	225.3444	15.88020
52.45383	224.3540	15.90582
52.50550	223.3282	15.94050
52.55717	222.3046	15.96038
52.60883	221.2798	15.99150
52.66050	220.2555	16.02159
52.71216	219.2296	16.05775
52.76382	218.2040	16.08328
52.81550	217.1786	16.10294
52.86716	216.1530	16.12465
52.91716	215.1609	16.14452
52.97050	214.1018	16.16691
53.02050	213.1108	16.20739
53.07383	212.0514	16.22542
53.12383	211.0584	16.24474
53.17717	209.9996	16.26407
53.22717	209.0068	16.28296
53.28050	207.9496	16.30448
53.33050	206.9566	16.32497
53.38383	205.8968	16.34518
53.43383	204.9046	16.36743
53.48717	203.8456	16.39451
53.53716	202.8531	16.41460
53.58882	201.8278	16.43668
53.64050	200.8021	16.46105
53.69216	199.7759	16.47980
53.74382	198.7508	16.50713
53.79550	197.7256	16.53389
53.84716	196.7003	16.55663
53.89883	195.6746	16.59010
53.95050	194.6476	16.62247
54.00050	193.6551	16.64235
54.05383	192.5960	16.66255
54.10383	191.6025	16.68236
54.15717	190.5435	16.70037
54.20717	189.5519	16.72516
54.26050	188.4925	16.75014
54.31050	187.5008	16.77042
54.36382	186.4409	16.79461
54.41382	185.4472	16.81581
54.46717	184.3879	16.83384
54.51716	183.3941	16.84647
54.57050	182.3351	16.85973
54.62050	181.3414	16.87452
54.67217	180.3161	16.89894
54.72382	179.2895	16.92238
54.77550	178.2634	16.94470
54.82717	177.2369	16.97041
54.87883	176.2102	16.99211
54.93050	175.1837	17.02619
54.98217	174.1570	17.06998
55.03383	173.1312	17.10455
55.08383	172.1381	17.16210
55.13716	171.0799	17.28999
55.18716	170.0922	17.49191
55.24050	169.0439	17.84860
55.29050	168.0703	18.34912
55.34384	167.0433	19.14337
55.39384	166.0976	20.22195
55.44717	165.1110	21.79163
55.49717	164.2103	23.70890
55.55050	163.2794	26.27308
55.60050	162.4366	29.06591
55.65383	161.5614	32.26442
55.70383	160.7517	35.16574
55.75550	159.9088	37.67106
55.80717	159.0396	39.46040
55.85883	158.1294	40.42960
55.91050	157.1712	40.62585
55.96216	156.1681	40.19516
56.01382	155.1201	39.10578
56.06550	154.0390	37.73674
56.11716	152.9330	36.20180
56.16716	151.8498	34.68140
56.22050	150.6882	33.08241
56.27050	149.6000	31.68809
56.32383	148.4420	30.28457
56.37383	147.3622	29.06164
56.42717	146.2161	27.87642
56.47717	145.1466	26.86212
56.53050	144.0132	25.85734
56.58050	142.9551	25.00880
56.63383	141.8328	24.19810
56.68383	140.7869	23.51915
56.73717	139.6767	22.86059
56.78716	138.6401	22.32532
56.83882	137.5728	21.83397
56.89050	136.5116	21.41912
56.94216	135.4542	21.03155
56.99382	134.3993	20.67688
57.04550	133.3472	20.38560
57.09716	132.2994	20.14141
57.14883	131.2528	19.90286
57.20050	130.2076	19.69359
57.25050	129.1987	19.52902
57.30383	128.1248	19.37721
57.35383	127.1187	19.24113
57.40717	126.0476	19.12888
57.45717	125.0436	19.02065
57.51050	123.9745	18.92177
57.56050	122.9728	18.84820
57.61382	121.9058	18.78420
57.66382	120.9059	18.74122
57.71717	119.8409	18.70089
57.76716	118.8428	18.66045
57.82050	117.7785	18.63044
57.87050	116.7818	18.60794
57.92217	115.7508	18.58624
57.97382	114.7210	18.56782
58.02550	113.6913	18.54180
58.07717	112.6596	18.45787
58.12883	111.6280	18.38390
58.18050	110.5954	18.32269
58.23217	109.5624	18.25992
58.28383	108.5294	18.20746
58.33383	107.5306	18.15994
58.38716	106.4663	18.11585
58.43716	105.4677	18.07879
58.49050	104.4033	18.04572
58.54050	103.4061	18.02202
58.59384	102.3425	18.00126
58.64384	101.3466	17.97893
58.69717	100.2826	17.96305
58.74717	99.28668	17.94064
58.80050	98.22469	17.92252
58.85050	97.24098	18.30698
58.90383	96.17515	18.01639
58.95383	95.17519	17.90320
59.00550	94.14269	17.85675
59.05717	93.11034	17.80765
59.10883	92.07920	17.76951
59.16050	91.04712	17.74031
59.21216	90.01651	17.71617
59.26382	88.98728	17.69742
59.31550	87.95578	17.67611
59.36716	86.92592	17.64996
59.41716	85.92832	17.62744
59.47050	84.86547	17.60455
59.52050	83.86851	17.58860
59.57383	82.80535	17.57253
59.62383	81.80719	17.55932
59.67717	80.74444	17.54249
59.72717	79.74706	17.52383
59.78050	78.68330	17.50565
59.83050	77.68650	17.48364
59.88383	76.62329	17.46185
59.93383	75.62676	17.45111
59.98717	74.56520	17.43535
60.03716	73.56872	17.42024
60.08882	72.53863	17.40402
60.14050	71.50978	17.38691
60.19216	70.48015	17.37434
60.24382	69.44980	17.35122
60.29550	68.41968	17.33234
60.34716	67.39020	17.31150
60.39883	66.36035	17.28922
60.45050	65.32997	17.26698
60.50050	64.33172	17.23795
60.55383	63.26860	17.20402
60.60383	62.27212	17.18146
60.65717	61.20880	17.15445
60.70717	60.21204	17.13421
60.76050	59.14794	17.11100
60.81050	58.15019	17.08606
60.86382	57.08731	17.06162
60.91382	56.09010	17.03841
60.96717	55.02594	17.01900
61.01716	54.02799	16.99953
61.07050	52.96472	16.97568
61.12050	51.96874	16.95902
61.17217	50.93762	16.93108
61.22382	49.90210	16.63704
61.27550	48.86552	16.52152
61.32717	47.82840	16.44162
61.37883	46.79518	16.39139
61.43050	45.76025	16.33980
61.48217	44.72653	16.29234
61.53383	43.69415	16.24181
61.58383	42.69306	16.18961
61.63716	41.62711	16.14120
61.68716	40.62722	16.09839
61.74050	39.56268	16.06403
61.79050	38.56281	15.99695
61.84384	37.49569	15.92118
61.89384	36.49764	15.85108
61.94717	35.42980	15.80047
61.99717	34.43006	15.71786
62.05050	33.36212	15.64861
62.10050	32.35968	15.56512
62.15383	31.29229	15.47220
62.20383	30.29155	15.42168
62.25550	29.25736	15.36296
62.30717	28.22320	15.25969
62.35883	27.18796	15.16116
62.41050	26.15296	15.07297
62.46216	25.11640	15.02699
62.51050	24.14740	15.03400
62.56050	23.21669	15.71361
62.61382	22.71082	9.460848
62.66382	22.64048	3.459054
62.71717	22.87474	-1.439652
62.76716	23.30745	-4.627273
62.82050	23.92898	-7.071158
62.87050	24.61820	-8.717578
62.92217	25.40786	-9.966913
62.97382	26.25459	-10.89844
63.02550	27.14298	-11.61559
63.07717	28.05861	-12.16763
63.12883	28.99844	-12.61338
63.18050	29.95439	-12.96048
63.23217	30.92121	-13.26364
63.28383	31.89685	-13.50434
63.33383	32.85008	-13.70794
63.38716	33.87125	-13.90259
63.43716	34.83358	-14.05860
63.49050	35.86376	-14.21038
63.54050	36.83194	-14.34953
63.59384	37.86884	-14.48624
63.64384	38.84164	-14.60274
63.69717	39.88196	-14.71898
63.74717	40.85952	-14.82588
63.80050	41.90360	-14.93544
63.85050	42.88410	-15.03396
63.90383	43.93150	-15.13501
63.95383	44.91348	-15.22067
64.00550	45.92910	-15.32737
64.05717	46.94634	-15.42195
64.10884	47.96294	-15.53528
64.16050	48.98027	-15.62119
64.21217	49.99854	-15.72798
64.26384	51.01769	-15.82378
64.31550	52.03707	-15.92356
64.36718	53.05830	-16.02203
64.41717	54.04730	-16.09891
64.47050	55.10196	-16.20200
64.52050	56.09039	-16.30552
64.57384	57.14619	-16.42695
64.62383	58.13320	-16.54273
64.67718	59.18872	-16.62972
64.72718	60.17942	-16.72031
64.78050	61.23596	-16.82999
64.83050	62.22684	-16.93206
64.88384	63.28338	-17.03507
64.93384	64.27511	-17.13332
64.98717	65.33266	-17.22284
65.03717	66.32462	-17.31594
65.08884	67.35000	-17.42013
65.14050	68.37570	-17.49862
65.19217	69.40070	-17.61158
65.24384	70.42579	-17.70343
65.29550	71.45160	-17.80338
65.34717	72.47801	-17.90458
65.39883	73.50410	-18.00201
65.45050	74.53075	-18.10223
65.50050	75.52439	-18.18979
65.55384	76.58478	-18.29142
65.60384	77.57795	-18.38578
65.65718	78.63759	-18.47800
65.70718	79.63276	-18.58767
65.76050	80.69148	-18.70162
65.81050	81.68478	-18.79768
65.86384	82.74515	-18.90151
65.91382	83.73852	-18.99824
65.96718	84.79821	-19.11823
66.01716	85.79249	-19.21548
66.07050	86.85220	-19.34183
66.12050	87.84610	-19.44183
66.17218	88.87381	-19.55130
66.22384	89.90076	-19.68121
66.27550	90.92799	-19.75957
66.32718	91.95644	-19.84624
66.37884	92.98452	-19.90759
66.43050	94.01330	-19.99543
66.48218	95.04076	-20.11883
66.53384	96.06584	-20.26135
66.58384	97.06048	-20.35319
66.63718	98.12322	-20.40195
66.68718	99.11874	-20.43994
66.74050	100.1831	-20.53222
66.79050	101.1796	-20.61084
66.84384	102.2425	-20.69467
66.89384	103.2379	-20.78007
66.94718	104.2999	-20.87749
66.99718	105.2943	-20.97363
67.05050	106.3558	-21.07412
67.10050	107.3516	-21.17250
67.15384	108.4125	-21.26552
67.20384	109.4086	-21.36643
67.25550	110.4378	-21.45622
67.30718	111.4664	-21.55870
67.35884	112.4944	-21.65172
67.41050	113.5223	-21.74741
67.46218	114.5495	-21.84868
67.51384	115.5776	-21.95844
67.56550	116.6057	-22.04903
67.61718	117.6330	-22.14619
67.66718	118.6275	-22.24858
67.72050	119.6887	-22.36270
67.77050	120.6834	-22.46894
67.82384	121.7443	-22.58013
67.87384	122.7385	-22.68131
67.92718	123.7991	-22.79182
67.97718	124.7949	-22.90700
68.03050	125.8548	-23.00228
68.08050	126.8521	-23.10104
68.13384	127.9136	-23.19142
68.18384	128.9092	-23.30130
68.23718	129.9708	-23.40086
68.28718	130.9658	-23.51467
68.33884	131.9946	-23.62010
68.39050	133.0222	-23.73900
68.44218	134.0499	-23.84050
68.49384	135.0774	-23.96242
68.54550	136.1052	-24.08674
68.59718	137.1327	-24.21025
68.64884	138.1600	-24.33110
68.70050	139.1868	-24.45236
68.75050	140.1817	-24.56763
68.80384	141.2412	-24.70148
68.85384	142.2349	-24.82540
68.90718	143.2963	-24.94356
68.95718	144.2905	-25.06209
69.01050	145.3518	-25.19018
69.06050	146.3456	-25.32898
69.11384	147.4065	-25.42108
69.16382	148.4010	-25.54404
69.21718	149.4622	-25.66470
69.26716	150.4546	-25.79239
69.32050	151.5158	-25.91358
69.37050	152.5096	-26.04529
69.42218	153.5363	-26.12910
69.47384	154.5645	-26.24088
69.52550	155.5919	-26.37615
69.57718	156.6165	-26.64547
69.62884	157.6425	-26.66300
69.68050	158.6702	-26.78110
69.73218	159.6965	-26.86671
69.78384	160.7256	-26.96911
69.83384	161.7217	-27.04868
69.88718	162.7844	-27.12541
69.93718	163.7810	-27.22000
69.99050	164.8451	-27.30356
70.04050	165.8416	-27.33444
70.09384	166.9060	-27.40070
70.14384	167.9041	-27.45601
70.19718	168.9680	-27.54653
70.24718	169.9625	-27.69870
70.30050	171.0255	-27.77404
70.35050	172.0215	-27.90694
70.40384	173.0817	-28.04049
70.45384	174.0754	-28.17512
70.50550	175.1014	-28.32530
70.55718	176.1275	-28.49845
70.60884	177.1509	-28.70188
70.66050	178.1728	-28.93225
70.71218	179.1936	-29.18742
70.76384	180.2122	-29.48363
70.81550	181.2299	-29.77426
70.86718	182.2475	-30.08983
70.91718	183.2292	-30.43716
70.97050	184.2762	-30.84322
71.02050	185.2556	-31.24180
71.07384	186.2969	-31.72717
71.12384	187.2716	-32.23264
71.17718	188.3076	-32.79586
71.22718	189.2772	-33.39672
71.28050	190.3065	-34.07960
71.33050	191.2692	-34.75253
71.38384	192.2930	-35.52313
71.43384	193.2533	-36.23721
71.48718	194.2742	-37.01868
71.53718	195.2320	-37.77660
71.58884	196.2178	-38.60128
71.64050	197.2030	-39.49059
71.69218	198.1837	-40.44052
71.74384	199.1612	-41.45143
71.79550	200.1354	-42.52210
71.84718	201.1075	-43.62382
71.89884	202.0771	-44.68981
71.95050	203.0488	-45.64313
72.00050	203.9949	-46.35312
72.05384	205.0192	-46.73373
72.10384	205.9998	-46.52372
72.15718	207.0812	-45.40105
72.20718	208.1404	-43.35513
72.26050	209.3271	-40.23275
72.31050	210.4809	-37.11966
72.36384	211.7236	-34.36509
72.41382	212.8713	-32.61948
72.46718	214.0581	-31.42958
72.51716	215.1414	-30.68638
72.57050	216.2728	-30.08915
72.62050	217.3157	-29.72060
72.67218	218.3806	-29.44627
72.72384	219.4367	-29.26682
72.77550	220.4858	-29.16760
72.82718	221.5308	-29.08934
72.87884	222.5726	-29.05532
72.93050	223.6102	-29.04359
72.98218	224.6484	-29.04182
73.03384	225.6821	-29.04125
73.08384	226.6836	-29.04335
73.13718	227.7499	-29.05030
73.18718	228.7494	-29.07537
73.24050	229.8145	-29.13736
73.29050	230.8133	-29.19059
73.34384	231.8774	-29.26970
73.39384	232.8760	-29.33075
73.44718	233.9408	-29.39274
73.49718	234.9381	-29.45218
73.55050	236.0035	-29.50508
73.60050	237.0014	-29.55512
73.65384	238.0650	-29.61028
73.70384	239.0622	-29.67024
73.75550	240.0946	-29.75046
73.80718	241.1238	-29.82681
73.85884	242.1550	-29.88908
73.91050	243.1853	-29.94450
73.96218	244.2162	-30.00185
74.01384	245.2483	-30.06497
74.06550	246.2786	-30.11672
74.11718	247.3096	-30.17057
74.16718	248.3069	-30.22055
74.22050	249.3712	-30.28478
74.27050	250.3690	-30.34656
74.32384	251.4330	-30.42858
74.37384	252.4296	-30.46940
74.42718	253.4938	-30.55108
74.47718	254.4920	-30.58206
74.53050	255.5564	-30.64554
74.58050	256.5538	-30.70700
74.63384	257.6174	-30.77430
74.68384	258.6138	-30.84392
74.73718	259.6776	-30.94444
74.78718	260.6734	-30.97360
74.83884	261.7035	-31.05352
74.89050	262.7340	-31.12058
74.94218	263.7635	-31.19816
74.99384	264.7931	-31.27220
75.04550	265.8234	-31.37090
75.09718	266.8543	-31.39800
75.14884	267.8838	-31.46218
75.20050	268.9148	-31.52358
75.25050	269.9104	-31.63344
75.30384	270.9732	-31.67002
-2.000000	5.000000	0.0000000