File: 5-C1(1.4mol%)+C20(0.6mol%)/matlab/150-3.txt
CLOSED
Version	1.0
Language	English
Mode	Standard
Run	21
RunSerial	12323
Instrument	DSC Q2000 V24.11 Build 124
Module	DSC Standard Cell RC
Operator
File	\\AE520-1454\Users\dsc\Desktop\Data\31-08-17-2\150-3.001
ProcName
InstSerial	2000-0883
AutoSerial	1293
Sample	150-3
Size	18.9000	mg
PanMass	Not available
PanResist	Automatic Automatic  K/W
PanFactor	Default Default
Method
Comment
Xcomment	Pan: Tzero Aluminum Hermetic
Xcomment	Gas1: Nitrogen 50.0 ml/min
Xcomment	Gas2: Nitrogen 50.0 ml/min
Text
Exotherm	UP
Kcell	1.05230
Cpconst	Standard: 0.938
Calib	-38.6961
TempCal	1	pts	157.46	156.60
TzeroDt	-87.6168 -0.0009 -1.4231
TzeroDtz	-87.6168 0.0057 6.9570
InstCalFile	Tzero: \\Ae520-1454\ta\Data\DSC\Calibration\2017\CALIBRATION\1562_RCS (90)_05_18_2017 10_50_44.TZR
InstCalFile	Baseline: \\Ae520-1454\ta\Data\DSC\Calibration\2017\2017-05-17_Calibration.001
InstCalFile	Sapphire: \\Ae520-1454\ta\Data\DSC\Calibration\2017\2017-05-17_Saphire.001
InstCalDate	Tzero 2017-05-18 Time 10:50:44
TempRange	-87.39 to 398.39 °C at 10.00 °C/min Heat Only
AutoZero	Delta T Offset 0.000 uV
AutoZero	Delta T0 Offset 0.000 uV
MultiptCal	0
MultiPtDesc	0) Not set
AutoCellConst	Calibration Date 2017-05-18 16:59:28
Controls	Gas 1  Event Off  Sampling 0.2
Cell#	RC-01562
CoolingUnit	RCS (90)
SelHeatFlow	Heat Flow T4P (mW)
AutoLidII	Installed
AutoAnalysis	Off
MacroFile
Nsig	3
Sig1	Time (min)
Sig2	Temperature (°C)
Sig3	Heat Flow (mW)
Date	2017-09-01
Time	13:01:27
OrgMethod	1: Equilibrate at 80.00 °C
OrgMethod	2: Isothermal for 3.00 min
OrgMethod	3: Jump to 150.00 °C
OrgMethod	4: Mark end of cycle 1
OrgMethod	5: Isothermal for 40.00 min
OrgMethod	6: Mark end of cycle 2
OrgMethod	7: Ramp 20.00 °C/min to 280.00 °C
OrgMethod	8: Mark end of cycle 3
OrgMethod	9: Ramp 20.00 °C/min to 20.00 °C
OrgMethod	10: Mark end of cycle 4
OrgMethod	11: Ramp 20.00 °C/min to 280.00 °C
OrgMethod	12: Mark end of cycle 5
OrgFile	C:\Users\jarra\Desktop\DSC\5-C1(1.4mol%)+C20(0.6mol%)\150-3.001
StartOfData
4.99994E-4	79.80651	-2.159668
0.05383332	79.83550	-1.747109
0.1038333	79.85538	-1.456646
0.1571666	79.87090	-1.227082
0.2071666	79.88080	-1.071282
0.2605000	79.88938	-0.9493805
0.3105000	79.89310	-0.8620246
0.3638334	79.89610	-0.7967514
0.4138333	79.89812	-0.7541165
0.4671667	79.89989	-0.7243957
0.5171667	79.90034	-0.7048719
0.5705000	79.90038	-0.6908344
0.6205000	79.89940	-0.6828266
0.6721668	79.89929	-0.6787429
0.7238332	79.89864	-0.6756456
0.7755000	79.89739	-0.6725988
0.8271668	79.89676	-0.6695929
0.8788332	79.89615	-0.6666596
0.9305000	79.89580	-0.6638599
0.9821668	79.89420	-0.6611699
1.033833	79.89405	-0.6587554
1.083833	79.89268	-0.6565331
1.137166	79.89151	-0.6544199
1.187166	79.89197	-0.6526020
1.240500	79.89038	-0.6508416
1.290500	79.88988	-0.6494221
1.343833	79.88884	-0.6480220
1.393833	79.88745	-0.6469135
1.447166	79.88745	-0.6458878
1.497166	79.88686	-0.6450251
1.550500	79.88552	-0.6442988
1.600500	79.88578	-0.6437240
1.653833	79.88422	-0.6431744
1.703833	79.88356	-0.6427758
1.755500	79.88342	-0.6424941
1.807167	79.88184	-0.6422639
1.858834	79.88203	-0.6421991
1.910500	79.88144	-0.6422318
1.962166	79.88059	-0.6423560
2.013833	79.88082	-0.6426213
2.065500	79.87945	-0.6429337
2.117167	79.87940	-0.6433568
2.167167	79.87965	-0.6437816
2.220500	79.87822	-0.6442900
2.270500	79.87876	-0.6448282
2.323833	79.87737	-0.6453993
2.373834	79.87619	-0.6460280
2.427167	79.87639	-0.6467248
2.477167	79.87540	-0.6473332
2.530500	79.87579	-0.6480518
2.580500	79.87481	-0.6487978
2.633833	79.87451	-0.6496162
2.683833	79.87432	-0.6504518
2.737167	79.87370	-0.6513690
2.787167	79.87384	-0.6522768
2.838833	79.87330	-0.6532172
2.890500	79.87326	-0.6541722
2.942167	79.87212	-0.6551016
2.993833	79.87122	-0.6560250
3.040500	80.03174	-3.129228
3.093834	81.78770	-16.72180
3.143833	84.29361	-27.44205
3.197167	87.50459	-38.04406
3.247166	90.91259	-46.70722
3.300500	94.85942	-54.46566
3.350500	98.77641	-60.43639
3.403833	103.1186	-65.65032
3.453833	107.3026	-69.60878
3.505500	111.7031	-72.95611
3.557167	116.1572	-75.61705
3.608833	120.6396	-77.88982
3.660500	125.1401	-79.73015
3.712167	129.6533	-81.15688
3.763833	134.1323	-81.57812
3.815500	137.7558	-73.92235
3.867166	140.2024	-62.57569
3.917167	142.0398	-52.21494
3.970500	143.5380	-42.06778
4.020500	144.6347	-34.02490
4.073834	145.5515	-26.98864
4.123833	146.2308	-21.72577
4.177166	146.8069	-17.29719
4.227167	147.2431	-14.05649
4.280500	147.6219	-11.35895
4.330500	147.9102	-9.417306
4.383834	148.1667	-7.785121
4.433834	148.3670	-6.602442
4.487167	148.5464	-5.608934
4.537167	148.6884	-4.872160
4.588834	148.8141	-4.267456
4.640500	148.9216	-3.784318
4.692166	149.0154	-3.393763
4.743834	149.0967	-3.075528
4.795500	149.1667	-2.818293
4.847166	149.2278	-2.603890
4.898834	149.2819	-2.422702
4.950500	149.3299	-2.275753
5.000500	149.3702	-2.150347
5.053834	149.4088	-2.030291
5.103833	149.4410	-1.932948
5.157166	149.4722	-1.840593
5.207167	149.4983	-1.760739
5.260500	149.5226	-1.682091
5.310500	149.5426	-1.614619
5.363834	149.5625	-1.546735
5.413832	149.5800	-1.486341
5.467168	149.5959	-1.423421
5.517168	149.6100	-1.363992
5.570500	149.6244	-1.303010
5.620500	149.6367	-1.244335
5.672168	149.6486	-1.186190
5.723834	149.6593	-1.127904
5.775500	149.6697	-1.069695
5.827168	149.6796	-1.011599
5.878834	149.6881	-0.9555856
5.930500	149.6960	-0.9088532
5.982168	149.7039	-0.8646638
6.033832	149.7127	-0.8125697
6.083832	149.7194	-0.7533316
6.137168	149.7270	-0.6777080
6.187168	149.7352	-0.6083949
6.240500	149.7417	-0.5332584
6.290500	149.7497	-0.4664334
6.343834	149.7571	-0.3905839
6.393832	149.7631	-0.3150564
6.447168	149.7704	-0.2359594
6.497168	149.7776	-0.1562889
6.550500	149.7851	-.06984696
6.600500	149.7916	0.01276641
6.653832	149.7994	0.1035104
6.703832	149.8069	0.1909624
6.755500	149.8143	0.2841903
6.807166	149.8214	0.3785986
6.858832	149.8300	0.4787689
6.910500	149.8376	0.5848680
6.962168	149.8455	0.6924761
7.013834	149.8536	0.8066082
7.065500	149.8619	0.9195530
7.117166	149.8711	1.038738
7.167168	149.8785	1.157252
7.220500	149.8879	1.281207
7.270500	149.8965	1.403271
7.323834	149.9059	1.537540
7.373834	149.9140	1.669301
7.427168	149.9246	1.809766
7.477168	149.9334	1.945746
7.530500	149.9437	2.090120
7.580500	149.9545	2.232984
7.633832	149.9644	2.385322
7.683832	149.9746	2.530905
7.737168	149.9864	2.690074
7.787168	149.9970	2.839261
7.838834	150.0066	2.999096
7.890500	150.0172	3.157702
7.942168	150.0294	3.324478
7.993834	150.0408	3.494955
8.045500	150.0534	3.687340
8.097168	150.0673	3.911704
8.148834	150.0848	4.186871
8.200500	150.1066	4.522722
8.250500	150.1318	4.911148
8.303832	150.1611	5.390687
8.353832	150.1950	5.892411
8.407166	150.2333	6.484900
8.457168	150.2726	7.074895
8.510499	150.3165	7.736611
8.560500	150.3585	8.378222
8.613834	150.4029	9.051525
8.663834	150.4439	9.653960
8.717168	150.4838	10.25176
8.767168	150.5182	10.75906
8.820500	150.5521	11.23529
8.870499	150.5789	11.61548
8.922168	150.6008	11.93736
8.973832	150.6189	12.18220
9.025499	150.6321	12.35644
9.077168	150.6408	12.45896
9.128834	150.6450	12.49498
9.180500	150.6445	12.49470
9.232166	150.6417	12.48846
9.283832	150.6349	12.40764
9.333832	150.6277	12.22250
9.387168	150.6176	12.04191
9.437166	150.6066	11.87046
9.490500	150.5950	11.67791
9.540500	150.5838	11.49511
9.593832	150.5708	11.29996
9.643832	150.5579	11.11627
9.697168	150.5460	10.92553
9.747168	150.5342	10.75006
9.800500	150.5216	10.57275
9.850500	150.5115	10.41147
9.903832	150.5004	10.24903
9.953834	150.4918	10.10313
10.00550	150.4815	9.962421
10.05717	150.4723	9.825691
10.10883	150.4636	9.698162
10.16050	150.4551	9.578719
10.21217	150.4479	9.464220
10.26383	150.4407	9.357276
10.31550	150.4332	9.255887
10.36717	150.4267	9.159762
10.41717	150.4215	9.074111
10.47050	150.4156	8.992555
10.52050	150.4116	8.917797
10.57383	150.4066	8.847749
10.62383	150.4026	8.786295
10.67717	150.3980	8.724428
10.72717	150.3948	8.669220
10.78050	150.3919	8.613399
10.83050	150.3877	8.563076
10.88383	150.3839	8.510212
10.93383	150.3807	8.463616
10.98717	150.3770	8.416121
11.03717	150.3746	8.369042
11.08883	150.3714	8.326453
11.14050	150.3684	8.283255
11.19217	150.3661	8.243381
11.24384	150.3622	8.206000
11.29550	150.3602	8.171062
11.34717	150.3584	8.140015
11.39883	150.3566	8.111359
11.45050	150.3543	8.087256
11.50050	150.3534	8.065055
11.55383	150.3514	8.045093
11.60383	150.3496	8.027725
11.65717	150.3491	8.009426
11.70717	150.3474	7.991370
11.76050	150.3472	7.972589
11.81050	150.3448	7.955631
11.86383	150.3436	7.937086
11.91383	150.3420	7.918350
11.96717	150.3404	7.899098
12.01717	150.3396	7.883434
12.07050	150.3378	7.864584
12.12050	150.3369	7.847618
12.17217	150.3351	7.834714
12.22383	150.3337	7.822500
12.27550	150.3327	7.811614
12.32717	150.3321	7.802256
12.37884	150.3319	7.794825
12.43050	150.3318	7.787600
12.48217	150.3312	7.780664
12.53383	150.3318	7.774204
12.58383	150.3320	7.768335
12.63717	150.3315	7.762815
12.68716	150.3334	7.758304
12.74050	150.3337	7.754500
12.79050	150.3347	7.751540
12.84383	150.3380	7.749328
12.89383	150.3392	7.751931
12.94717	150.3416	7.764526
12.99717	150.3447	7.793875
13.05050	150.3479	7.846626
13.10050	150.3516	7.916448
13.15383	150.3572	8.005695
13.20383	150.3622	8.098384
13.25550	150.3685	8.203797
13.30717	150.3754	8.313824
13.35883	150.3836	8.434750
13.41050	150.3910	8.555397
13.46217	150.4000	8.682840
13.51383	150.4074	8.807022
13.56550	150.4154	8.926484
13.61716	150.4227	9.032329
13.66716	150.4285	9.117332
13.72050	150.4325	9.182676
13.77050	150.4356	9.214306
13.82384	150.4369	9.222411
13.87384	150.4348	9.222856
13.92717	150.4304	9.196059
13.97717	150.4228	9.068840
14.03050	150.4141	8.879859
14.08050	150.4028	8.693820
14.13383	150.3894	8.478444
14.18383	150.3758	8.262624
14.23716	150.3606	8.018379
14.28717	150.3456	7.784676
14.33883	150.3285	7.537361
14.39050	150.3129	7.290703
14.44217	150.2953	7.038650
14.49384	150.2792	6.787293
14.54550	150.2630	6.542907
14.59717	150.2462	6.305451
14.64883	150.2302	6.066379
14.70050	150.2152	5.833822
14.75050	150.2006	5.616860
14.80383	150.1851	5.383644
14.85383	150.1719	5.174703
14.90717	150.1670	5.178467
14.95717	150.1553	4.948770
15.01050	150.1402	4.696097
15.06050	150.1255	4.479908
15.11383	150.1107	4.255094
15.16383	150.0971	4.056364
15.21716	150.0828	3.848312
15.26717	150.0703	3.658881
15.32050	150.0580	3.455626
15.37050	150.0455	3.275921
15.42217	150.0327	3.090905
15.47383	150.0218	2.915212
15.52550	150.0094	2.733861
15.57717	149.9962	2.549898
15.62883	149.9842	2.367371
15.68050	149.9728	2.182510
15.73216	149.9611	2.004175
15.78383	149.9502	1.824102
15.83383	149.9384	1.654177
15.88716	149.9266	1.477236
15.93717	149.9159	1.315086
15.99050	149.9040	1.142754
16.04050	149.8942	0.9880484
16.09383	149.8825	0.8241657
16.14383	149.8730	0.6758413
16.19717	149.8615	0.5197094
16.24716	149.8535	0.3776150
16.30050	149.8431	0.2332225
16.35050	149.8346	0.1017890
16.40383	149.8259	-.02752030
16.45383	149.8187	-0.1458513
16.50550	149.8102	-0.2578862
16.55716	149.8026	-0.3658319
16.60883	149.7957	-0.4698387
16.66050	149.7891	-0.5675118
16.71216	149.7827	-0.6586826
16.76383	149.7760	-0.7445407
16.81550	149.7708	-0.8261493
16.86716	149.7657	-0.9012726
16.91716	149.7604	-0.9681074
16.97050	149.7558	-1.035162
17.02050	149.7519	-1.093114
17.07383	149.7482	-1.153494
17.12383	149.7453	-1.207388
17.17716	149.7414	-1.256790
17.22716	149.7385	-1.300878
17.28050	149.7352	-1.343149
17.33050	149.7336	-1.380698
17.38383	149.7298	-1.414380
17.43383	149.7278	-1.445215
17.48716	149.7254	-1.473947
17.53717	149.7227	-1.498736
17.58883	149.7209	-1.522400
17.64050	149.7189	-1.546121
17.69216	149.7170	-1.567569
17.74383	149.7152	-1.587550
17.79550	149.7142	-1.605591
17.84716	149.7125	-1.622588
17.89883	149.7109	-1.638190
17.95050	149.7112	-1.653040
18.00050	149.7100	-1.666026
18.05383	149.7084	-1.680025
18.10383	149.7075	-1.691391
18.15716	149.7070	-1.702067
18.20716	149.7073	-1.711542
18.26050	149.7059	-1.719391
18.31050	149.7056	-1.726792
18.36383	149.7044	-1.734426
18.41383	149.7030	-1.741733
18.46716	149.7026	-1.749685
18.51716	149.7019	-1.757263
18.57050	149.7023	-1.765397
18.62050	149.7019	-1.773036
18.67216	149.7009	-1.780856
18.72383	149.7000	-1.788607
18.77550	149.6996	-1.796339
18.82716	149.6990	-1.803998
18.87883	149.6981	-1.811535
18.93050	149.6975	-1.818995
18.98216	149.6975	-1.826410
19.03383	149.6970	-1.833725
19.08383	149.6964	-1.840714
19.13716	149.6958	-1.848090
19.18716	149.6954	-1.854919
19.24050	149.6960	-1.862119
19.29050	149.6958	-1.868742
19.34383	149.6951	-1.875659
19.39383	149.6943	-1.881937
19.44716	149.6936	-1.888422
19.49716	149.6943	-1.894444
19.55050	149.6934	-1.900568
19.60050	149.6925	-1.906150
19.65383	149.6924	-1.912041
19.70383	149.6930	-1.917479
19.75550	149.6922	-1.923021
19.80716	149.6922	-1.928570
19.85883	149.6926	-1.933967
19.91050	149.6919	-1.939235
19.96216	149.6928	-1.944416
20.01383	149.6931	-1.949464
20.06550	149.6921	-1.954314
20.11716	149.6919	-1.959049
20.16716	149.6924	-1.963440
20.22050	149.6916	-1.968039
20.27050	149.6920	-1.972245
20.32383	149.6910	-1.976588
20.37383	149.6909	-1.980584
20.42716	149.6911	-1.984676
20.47716	149.6915	-1.988323
20.53050	149.6906	-1.992065
20.58050	149.6898	-1.995464
20.63383	149.6899	-1.999018
20.68383	149.6896	-2.002247
20.73716	149.6894	-2.005548
20.78717	149.6896	-2.008673
20.83883	149.6888	-2.011756
20.89050	149.6896	-2.014933
20.94216	149.6889	-2.017988
20.99383	149.6892	-2.021064
21.04550	149.6891	-2.024034
21.09716	149.6893	-2.026961
21.14883	149.6891	-2.029796
21.20050	149.6896	-2.032585
21.25050	149.6896	-2.035284
21.30383	149.6895	-2.038059
21.35383	149.6893	-2.040541
21.40716	149.6897	-2.043101
21.45717	149.6899	-2.045429
21.51050	149.6888	-2.047723
21.56050	149.6892	-2.049812
21.61383	149.6884	-2.051876
21.66383	149.6883	-2.053762
21.71716	149.6885	-2.055742
21.76716	149.6878	-2.057529
21.82050	149.6877	-2.059313
21.87050	149.6873	-2.060959
21.92216	149.6878	-2.062676
21.97383	149.6884	-2.064388
22.02550	149.6878	-2.066125
22.07716	149.6880	-2.067880
22.12883	149.6874	-2.069655
22.18050	149.6881	-2.071442
22.23216	149.6873	-2.072987
22.28383	149.6874	-2.074583
22.33383	149.6877	-2.076062
22.38716	149.6880	-2.077690
22.43716	149.6876	-2.079116
22.49050	149.6867	-2.080692
22.54050	149.6877	-2.082089
22.59383	149.6876	-2.083521
22.64383	149.6871	-2.084770
22.69716	149.6875	-2.086082
22.74716	149.6878	-2.087217
22.80050	149.6862	-2.088398
22.85050	149.6874	-2.089501
22.90383	149.6875	-2.090730
22.95383	149.6872	-2.091904
23.00550	149.6874	-2.093174
23.05716	149.6869	-2.094392
23.10883	149.6877	-2.095576
23.16050	149.6875	-2.096736
23.21216	149.6878	-2.097902
23.26383	149.6874	-2.098962
23.31550	149.6882	-2.099982
23.36716	149.6869	-2.100891
23.41716	149.6874	-2.101715
23.47050	149.6884	-2.102556
23.52050	149.6874	-2.103188
23.57383	149.6868	-2.103796
23.62383	149.6866	-2.104376
23.67717	149.6863	-2.104891
23.72716	149.6857	-2.105456
23.78050	149.6856	-2.106011
23.83050	149.6857	-2.106662
23.88383	149.6861	-2.107380
23.93383	149.6854	-2.108094
23.98716	149.6859	-2.108967
24.03717	149.6854	-2.109850
24.08883	149.6858	-2.110684
24.14050	149.6861	-2.111464
24.19216	149.6856	-2.112172
24.24383	149.6856	-2.112880
24.29550	149.6858	-2.113560
24.34716	149.6854	-2.114241
24.39883	149.6855	-2.114988
24.45050	149.6871	-2.115852
24.50050	149.6868	-2.116687
24.55383	149.6869	-2.117494
24.60383	149.6867	-2.118334
24.65716	149.6874	-2.119236
24.70717	149.6871	-2.119967
24.76050	149.6869	-2.120737
24.81050	149.6872	-2.121398
24.86383	149.6869	-2.122060
24.91383	149.6868	-2.122568
24.96716	149.6862	-2.123094
25.01716	149.6866	-2.123491
25.07050	149.6864	-2.123890
25.12050	149.6863	-2.124324
25.17216	149.6868	-2.124776
25.22383	149.6871	-2.125284
25.27550	149.6867	-2.125789
25.32716	149.6868	-2.126378
25.37883	149.6869	-2.126972
25.43050	149.6865	-2.127486
25.48216	149.6870	-2.128050
25.53383	149.6868	-2.128472
25.58383	149.6861	-2.128806
25.63716	149.6866	-2.129106
25.68717	149.6862	-2.129499
25.74050	149.6860	-2.129782
25.79050	149.6856	-2.130016
25.84383	149.6853	-2.130262
25.89383	149.6853	-2.130489
25.94717	149.6862	-2.130723
25.99716	149.6856	-2.130966
26.05050	149.6860	-2.131352
26.10050	149.6855	-2.131744
26.15383	149.6849	-2.132158
26.20383	149.6861	-2.132575
26.25550	149.6854	-2.132964
26.30716	149.6852	-2.133315
26.35883	149.6854	-2.133688
26.41050	149.6857	-2.134051
26.46216	149.6859	-2.134468
26.51383	149.6854	-2.134920
26.56550	149.6854	-2.135452
26.61716	149.6863	-2.135962
26.66716	149.6860	-2.136490
26.72050	149.6864	-2.137049
26.77050	149.6865	-2.137526
26.82383	149.6855	-2.138044
26.87383	149.6866	-2.138512
26.92717	149.6854	-2.138940
26.97717	149.6866	-2.139312
27.03050	149.6858	-2.139612
27.08050	149.6865	-2.139906
27.13383	149.6868	-2.140215
27.18383	149.6865	-2.140474
27.23716	149.6864	-2.140775
27.28717	149.6862	-2.141066
27.33883	149.6863	-2.141442
27.39050	149.6862	-2.141805
27.44216	149.6860	-2.142133
27.49383	149.6857	-2.142488
27.54550	149.6860	-2.142756
27.59716	149.6856	-2.143030
27.64883	149.6854	-2.143234
27.70050	149.6856	-2.143505
27.75050	149.6856	-2.143742
27.80383	149.6856	-2.144014
27.85383	149.6859	-2.144290
27.90716	149.6862	-2.144585
27.95716	149.6859	-2.144834
28.01050	149.6856	-2.145109
28.06050	149.6852	-2.145349
28.11383	149.6854	-2.145632
28.16383	149.6849	-2.145797
28.21716	149.6849	-2.146105
28.26716	149.6852	-2.146383
28.32050	149.6854	-2.146652
28.37050	149.6852	-2.146876
28.42216	149.6842	-2.147063
28.47383	149.6843	-2.147250
28.52550	149.6851	-2.147551
28.57717	149.6845	-2.147752
28.62883	149.6850	-2.148028
28.68050	149.6848	-2.148221
28.73216	149.6844	-2.148383
28.78383	149.6841	-2.148588
28.83383	149.6846	-2.148806
28.88716	149.6838	-2.148920
28.93717	149.6841	-2.149111
28.99050	149.6840	-2.149384
29.04050	149.6848	-2.149666
29.09383	149.6842	-2.150015
29.14383	149.6847	-2.150320
29.19717	149.6848	-2.150642
29.24716	149.6854	-2.150994
29.30050	149.6841	-2.151326
29.35050	149.6855	-2.151682
29.40383	149.6856	-2.151966
29.45383	149.6850	-2.152197
29.50550	149.6848	-2.152461
29.55716	149.6846	-2.152655
29.60883	149.6861	-2.152904
29.66050	149.6854	-2.153125
29.71216	149.6859	-2.153335
29.76383	149.6857	-2.153564
29.81550	149.6855	-2.153818
29.86716	149.6854	-2.154080
29.91716	149.6860	-2.154311
29.97050	149.6862	-2.154516
30.02050	149.6855	-2.154670
30.07383	149.6862	-2.154860
30.12383	149.6853	-2.154976
30.17717	149.6853	-2.155089
30.22717	149.6859	-2.155208
30.28050	149.6850	-2.155332
30.33050	149.6853	-2.155490
30.38383	149.6860	-2.155617
30.43383	149.6850	-2.155662
30.48716	149.6846	-2.155786
30.53717	149.6847	-2.155789
30.58883	149.6843	-2.155813
30.64050	149.6839	-2.155810
30.69216	149.6843	-2.155800
30.74383	149.6846	-2.155740
30.79550	149.6832	-2.155679
30.84716	149.6834	-2.155758
30.89883	149.6840	-2.155978
30.95050	149.6842	-2.156192
31.00050	149.6839	-2.156482
31.05383	149.6836	-2.156816
31.10383	149.6842	-2.157114
31.15716	149.6845	-2.157385
31.20716	149.6839	-2.157587
31.26050	149.6832	-2.157780
31.31050	149.6839	-2.157918
31.36383	149.6843	-2.158126
31.41383	149.6833	-2.158270
31.46716	149.6842	-2.158533
31.51716	149.6837	-2.158808
31.57050	149.6848	-2.159137
31.62050	149.6839	-2.159413
31.67216	149.6834	-2.159639
31.72383	149.6839	-2.159808
31.77550	149.6833	-2.159956
31.82717	149.6834	-2.160075
31.87883	149.6830	-2.160268
31.93050	149.6841	-2.160591
31.98216	149.6839	-2.160945
32.03383	149.6840	-2.161342
32.08383	149.6841	-2.161666
32.13716	149.6853	-2.162100
32.18716	149.6841	-2.162422
32.24050	149.6844	-2.162810
32.29050	149.6837	-2.163062
32.34384	149.6844	-2.163294
32.39383	149.6846	-2.163404
32.44717	149.6844	-2.163552
32.49716	149.6847	-2.163739
32.55050	149.6850	-2.163908
32.60050	149.6836	-2.164004
32.65383	149.6852	-2.164146
32.70383	149.6844	-2.164266
32.75550	149.6841	-2.164453
32.80716	149.6840	-2.164562
32.85883	149.6844	-2.164702
32.91050	149.6837	-2.164682
32.96216	149.6836	-2.164680
33.01383	149.6836	-2.164589
33.06550	149.6840	-2.164530
33.11716	149.6834	-2.164528
33.16716	149.6838	-2.164590
33.22050	149.6841	-2.164748
33.27050	149.6840	-2.164998
33.32383	149.6832	-2.165262
33.37383	149.6849	-2.165457
33.42717	149.6840	-2.165584
33.47717	149.6840	-2.165690
33.53050	149.6850	-2.165901
33.58050	149.6852	-2.165996
33.63383	149.6837	-2.166041
33.68384	149.6831	-2.166019
33.73717	149.6845	-2.166039
33.78717	149.6846	-2.166187
33.83883	149.6842	-2.166224
33.89050	149.6836	-2.166302
33.94216	149.6841	-2.166390
33.99383	149.6842	-2.166490
34.04550	149.6838	-2.166582
34.09716	149.6849	-2.166708
34.14883	149.6842	-2.166810
34.20050	149.6844	-2.166959
34.25050	149.6845	-2.167185
34.30383	149.6848	-2.167475
34.35383	149.6839	-2.167656
34.40716	149.6846	-2.167868
34.45716	149.6844	-2.168074
34.51050	149.6838	-2.168248
34.56050	149.6844	-2.168309
34.61383	149.6843	-2.168360
34.66383	149.6834	-2.168384
34.71716	149.6844	-2.168432
34.76716	149.6836	-2.168396
34.82050	149.6844	-2.168375
34.87050	149.6832	-2.168418
34.92216	149.6843	-2.168577
34.97383	149.6842	-2.168706
35.02550	149.6844	-2.168876
35.07717	149.6845	-2.168957
35.12883	149.6840	-2.169131
35.18050	149.6850	-2.169275
35.23216	149.6842	-2.169320
35.28383	149.6844	-2.169312
35.33383	149.6836	-2.169245
35.38716	149.6847	-2.169314
35.43716	149.6838	-2.169366
35.49050	149.6844	-2.169500
35.54050	149.6843	-2.169640
35.59384	149.6845	-2.169854
35.64383	149.6838	-2.169979
35.69717	149.6842	-2.170150
35.74716	149.6846	-2.170274
35.80050	149.6840	-2.170416
35.85050	149.6847	-2.170487
35.90383	149.6842	-2.170547
35.95383	149.6837	-2.170517
36.00550	149.6840	-2.170540
36.05716	149.6845	-2.170498
36.10883	149.6834	-2.170390
36.16050	149.6833	-2.170347
36.21216	149.6831	-2.170298
36.26383	149.6837	-2.170287
36.31550	149.6839	-2.170290
36.36716	149.6844	-2.170260
36.41716	149.6836	-2.170270
36.47050	149.6829	-2.170369
36.52050	149.6834	-2.170386
36.57383	149.6835	-2.170433
36.62383	149.6831	-2.170442
36.67717	149.6834	-2.170410
36.72717	149.6816	-2.170356
36.78050	149.6824	-2.170366
36.83050	149.6827	-2.170410
36.88383	149.6825	-2.170582
36.93384	149.6829	-2.170789
36.98717	149.6828	-2.171076
37.03717	149.6834	-2.171186
37.08883	149.6839	-2.170859
37.14050	149.6834	-2.170364
37.19216	149.6842	-2.169625
37.24383	149.6842	-2.168754
37.29550	149.6848	-2.167818
37.34716	149.6846	-2.166898
37.39883	149.6845	-2.166000
37.45050	149.6856	-2.165099
37.50050	149.6848	-2.164190
37.55383	149.6850	-2.163256
37.60383	149.6843	-2.162441
37.65716	149.6851	-2.161660
37.70716	149.6847	-2.160905
37.76050	149.6846	-2.160119
37.81050	149.6836	-2.159426
37.86383	149.6842	-2.158785
37.91383	149.6843	-2.158204
37.96716	149.6847	-2.157629
38.01716	149.6839	-2.157068
38.07050	149.6845	-2.156440
38.12050	149.6842	-2.155890
38.17216	149.6836	-2.155296
38.22383	149.6836	-2.154776
38.27550	149.6837	-2.154367
38.32717	149.6848	-2.153988
38.37883	149.6848	-2.153758
38.43050	149.6847	-2.153539
38.48216	149.6852	-2.153388
38.53383	149.6848	-2.153216
38.58383	149.6851	-2.153092
38.63716	149.6854	-2.153016
38.68716	149.6853	-2.152994
38.74050	149.6860	-2.152928
38.79050	149.6854	-2.152794
38.84384	149.6854	-2.152692
38.89383	149.6856	-2.152507
38.94717	149.6850	-2.152303
38.99716	149.6853	-2.152087
39.05050	149.6848	-2.151856
39.10050	149.6856	-2.151648
39.15383	149.6851	-2.151414
39.20383	149.6849	-2.151134
39.25550	149.6843	-2.150894
39.30716	149.6834	-2.150611
39.35883	149.6844	-2.150516
39.41050	149.6845	-2.150381
39.46216	149.6848	-2.150372
39.51383	149.6843	-2.150472
39.56550	149.6845	-2.150647
39.61716	149.6851	-2.150916
39.66716	149.6851	-2.150994
39.72050	149.6846	-2.151028
39.77050	149.6846	-2.150999
39.82383	149.6843	-2.150880
39.87383	149.6844	-2.150787
39.92717	149.6832	-2.150664
39.97717	149.6844	-2.150604
40.03050	149.6841	-2.150605
40.08050	149.6840	-2.150657
40.13383	149.6849	-2.150782
40.18384	149.6848	-2.150889
40.23717	149.6843	-2.151035
40.28717	149.6853	-2.151207
40.33883	149.6848	-2.151356
40.39050	149.6844	-2.151387
40.44216	149.6846	-2.151467
40.49383	149.6853	-2.151535
40.54550	149.6848	-2.151458
40.59716	149.6853	-2.151293
40.64883	149.6838	-2.151072
40.70050	149.6838	-2.150982
40.75050	149.6842	-2.150862
40.80383	149.6839	-2.150826
40.85383	149.6848	-2.150834
40.90716	149.6858	-2.150946
40.95716	149.6848	-2.151052
41.01050	149.6845	-2.151150
41.06050	149.6846	-2.151266
41.11383	149.6850	-2.151347
41.16383	149.6854	-2.151398
41.21717	149.6853	-2.151382
41.26717	149.6851	-2.151402
41.32050	149.6848	-2.151456
41.37050	149.6856	-2.151469
41.42216	149.6849	-2.151538
41.47383	149.6856	-2.151623
41.52550	149.6851	-2.151635
41.57717	149.6848	-2.151633
41.62883	149.6855	-2.151678
41.68050	149.6852	-2.151616
41.73217	149.6851	-2.151610
41.78383	149.6856	-2.151586
41.83383	149.6854	-2.151538
41.88716	149.6852	-2.151463
41.93716	149.6846	-2.151421
41.99050	149.6854	-2.151377
42.04050	149.6853	-2.151368
42.09384	149.6838	-2.151340
42.14383	149.6851	-2.151514
42.19717	149.6849	-2.151734
42.24716	149.6843	-2.151865
42.30050	149.6852	-2.152013
42.35050	149.6848	-2.152080
42.40383	149.6847	-2.152207
42.45383	149.6850	-2.152284
42.50550	149.6854	-2.152385
42.55717	149.6850	-2.152450
42.60883	149.6848	-2.152502
42.66050	149.6847	-2.152503
42.71216	149.6848	-2.152534
42.76383	149.6847	-2.152563
42.81550	149.6851	-2.152560
42.86716	149.6856	-2.152626
42.91716	149.6844	-2.152670
42.97050	149.6853	-2.152744
43.01717	149.6848	-2.152822
43.07050	149.7684	-3.514402
43.12050	150.1205	-6.822587
43.17216	150.6554	-9.855338
43.22383	151.3170	-12.43672
43.27550	152.0694	-14.41781
43.32717	152.8895	-15.94726
43.37883	153.7577	-17.12228
43.43050	154.6604	-18.07154
43.48217	155.5916	-18.74582
43.53383	156.5424	-19.28297
43.58383	157.4781	-19.70896
43.63716	158.4891	-20.06989
43.68716	159.4450	-20.34879
43.74050	160.4701	-20.61012
43.79050	161.4384	-20.81191
43.84384	162.4742	-21.02168
43.89383	163.4492	-21.20384
43.94717	164.4911	-21.38377
43.99716	165.4707	-21.54760
44.05050	166.5174	-21.71726
44.10050	167.4989	-21.88278
44.15383	168.5477	-22.04782
44.20383	169.5316	-22.21092
44.25550	170.5478	-22.38245
44.30717	171.5656	-22.56252
44.35883	172.5837	-22.74790
44.41050	173.6016	-22.93593
44.46216	174.6196	-23.12825
44.51383	175.6372	-23.31976
44.56550	176.6561	-23.53153
44.61716	177.6738	-23.75116
44.66716	178.6588	-23.97462
44.72050	179.7083	-24.22072
44.77050	180.6935	-24.48007
44.82383	181.7420	-24.76436
44.87383	182.7250	-25.04594
44.92717	183.7730	-25.35996
44.97717	184.7550	-25.66473
45.03050	185.8001	-26.01176
45.08050	186.7793	-26.37421
45.13383	187.8238	-26.75333
45.18383	188.8019	-27.11400
45.23717	189.8444	-27.54690
45.28717	190.8204	-27.96295
45.33883	191.8266	-28.42894
45.39050	192.8317	-28.91890
45.44217	193.8358	-29.45217
45.49383	194.8369	-30.02463
45.54550	195.8364	-30.65058
45.59716	196.8320	-31.33972
45.64883	197.8244	-32.09615
45.70050	198.8123	-32.94199
45.75050	199.7633	-33.90208
45.80383	200.7715	-34.94504
45.85383	201.7107	-36.12370
45.90717	202.7077	-37.39625
45.95717	203.6344	-38.80265
46.01050	204.6122	-40.50098
46.06050	205.5189	-42.24235
46.11383	206.4782	-44.18591
46.16383	207.3722	-46.02143
46.21717	208.3260	-47.87000
46.26717	209.2253	-49.34297
46.32050	210.1980	-50.64585
46.37050	211.1170	-52.01332
46.42216	212.0587	-53.86111
46.47383	212.9837	-56.07807
46.52550	213.8910	-58.53840
46.57717	214.7855	-61.08394
46.62883	215.6762	-63.46801
46.68050	216.5785	-65.13544
46.73217	217.5320	-64.79892
46.78383	218.6013	-61.24787
46.83383	219.7670	-55.84356
46.88716	221.1670	-46.43336
46.93716	222.5812	-39.86648
46.99050	224.0120	-35.87960
47.04050	225.2706	-33.25980
47.09384	226.5419	-31.20408
47.14383	227.6836	-29.79219
47.19717	228.8605	-28.68522
47.24716	229.9388	-27.93941
47.30050	231.0655	-27.34334
47.35050	232.1075	-26.94126
47.40383	233.2064	-26.64708
47.45383	234.2278	-26.43236
47.50550	235.2781	-26.28328
47.55717	236.3245	-26.17588
47.60883	237.3665	-26.11339
47.66050	238.4066	-26.07420
47.71216	239.4438	-26.04852
47.76383	240.4808	-26.04147
47.81550	241.5140	-26.03975
47.86716	242.5485	-26.03966
47.91716	243.5501	-26.04119
47.97050	244.6156	-26.04440
48.02050	245.6160	-26.05224
48.07383	246.6822	-26.06345
48.12383	247.6818	-26.07902
48.17717	248.7466	-26.09917
48.22717	249.7467	-26.12386
48.28050	250.8111	-26.15539
48.33050	251.8104	-26.19012
48.38383	252.8746	-26.23060
48.43383	253.8734	-26.26358
48.48717	254.9380	-26.30474
48.53717	255.9366	-26.35739
48.58883	256.9683	-26.40747
48.64050	257.9992	-26.45712
48.69217	259.0297	-26.51348
48.74383	260.0606	-26.56390
48.79550	261.0908	-26.61012
48.84716	262.1223	-26.66385
48.89883	263.1534	-26.71187
48.95050	264.1843	-26.75519
49.00050	265.1830	-26.80465
49.05383	266.2480	-26.84730
49.10383	267.2470	-26.88200
49.15717	268.3111	-26.92261
49.20717	269.3093	-26.96618
49.26050	270.3736	-27.00376
49.31050	271.3717	-27.03696
49.36383	272.4358	-27.08208
49.41383	273.4333	-27.11559
49.46717	274.4990	-27.13884
49.51383	275.4306	-27.19332
49.56550	276.3022	-27.92640
49.61716	276.5698	-22.49440
49.66716	276.4899	-14.99452
49.72050	276.1534	-7.704751
49.77050	275.6746	-2.180094
49.82383	275.0322	2.403230
49.87383	274.3430	5.672787
49.92717	273.5339	8.325442
49.97717	272.7258	10.20324
50.03050	271.8224	11.71475
50.08050	270.9470	12.79631
50.13383	269.9878	13.67862
50.18383	269.0722	14.29514
50.23717	268.0789	14.81574
50.28717	267.1372	15.19054
50.33883	266.1566	15.49255
50.39050	265.1684	15.73906
50.44217	264.1746	15.92040
50.49383	263.1748	16.07511
50.54550	262.1727	16.19544
50.59716	261.1670	16.30218
50.64883	260.1584	16.37789
50.70050	259.1479	16.44584
50.75050	258.1688	16.51058
50.80383	257.1223	16.56582
50.85383	256.1400	16.61156
50.90717	255.0911	16.65747
50.95717	254.1070	16.69507
51.01050	253.0554	16.73325
51.06050	252.0680	16.75985
51.11383	251.0132	16.78223
51.16383	250.0256	16.79968
51.21717	248.9707	16.82026
51.26716	247.9806	16.83566
51.32050	246.9254	16.84974
51.37050	245.9346	16.86196
51.42217	244.9111	16.87196
51.47383	243.8876	16.88035
51.52550	242.8634	16.88742
51.57717	241.8384	16.89426
51.62883	240.8148	16.90068
51.68050	239.7888	16.90897
51.73217	238.7646	16.91660
51.78383	237.7394	16.92344
51.83383	236.7470	16.93184
51.88716	235.6886	16.93977
51.93716	234.6963	16.94720
51.99050	233.6370	16.95487
52.04050	232.6446	16.96200
52.09384	231.5854	16.96945
52.14384	230.5930	16.97646
52.19717	229.5325	16.98390
52.24717	228.5406	16.99082
52.30050	227.4803	17.00066
52.35050	226.4866	17.00775
52.40383	225.4270	17.01554
52.45383	224.4343	17.02284
52.50550	223.4072	17.03119
52.55717	222.3803	17.03875
52.60883	221.3539	17.04622
52.66050	220.3278	17.05365
52.71216	219.3006	17.06154
52.76382	218.2737	17.06909
52.81550	217.2463	17.07652
52.86716	216.2202	17.08380
52.91716	215.2270	17.09080
52.97050	214.1667	17.09821
53.02050	213.1735	17.10530
53.07383	212.1139	17.11293
53.12383	211.1196	17.12031
53.17717	210.0594	17.12784
53.22717	209.0647	17.13485
53.28050	208.0047	17.14206
53.33050	207.0101	17.14860
53.38383	205.9504	17.15548
53.43383	204.9558	17.16166
53.48717	203.8947	17.16822
53.53716	202.9005	17.17401
53.58882	201.8728	17.17970
53.64050	200.8452	17.18516
53.69216	199.8178	17.19064
53.74382	198.7908	17.19597
53.79550	197.7627	17.20140
53.84716	196.7357	17.20653
53.89883	195.7072	17.21164
53.95050	194.6796	17.21681
54.00050	193.6850	17.22166
54.05383	192.6244	17.22667
54.10383	191.6300	17.23150
54.15717	190.5689	17.23654
54.20717	189.5748	17.24130
54.26050	188.5134	17.24630
54.31050	187.5199	17.25677
54.36382	186.4577	17.26186
54.41382	185.4637	17.26638
54.46717	184.4019	17.27094
54.51716	183.4074	17.27484
54.57050	182.3465	17.27882
54.62050	181.3534	17.28234
54.67217	180.3250	17.28614
54.72382	179.2975	17.29010
54.77550	178.2710	17.29459
54.82717	177.2441	17.30124
54.87883	176.2168	17.30783
54.93050	175.1896	17.31614
54.98217	174.1619	17.32348
55.03383	173.1336	17.32966
55.08383	172.1379	17.33529
55.13716	171.0758	17.34078
55.18716	170.0794	17.34575
55.24050	169.0190	17.35082
55.29050	168.0242	17.35747
55.34384	166.9650	17.38470
55.39384	165.9720	17.53616
55.44717	164.9204	17.85712
55.49717	163.9425	18.34280
55.55050	162.9171	19.31297
55.60050	161.9832	20.88325
55.65383	161.0330	23.48628
55.70383	160.1938	26.78906
55.75550	159.3749	30.74478
55.80717	158.5875	34.68550
55.85883	157.7988	38.08870
55.91050	156.9820	40.55857
55.96216	156.1161	42.01790
56.01382	155.1906	42.48916
56.06550	154.2060	42.11280
56.11716	153.1719	41.13318
56.16716	152.1298	39.79890
56.22050	150.9895	38.16241
56.27050	149.9047	36.55656
56.32383	148.7378	34.86396
56.37383	147.6425	33.31530
56.42717	146.4754	31.78756
56.47717	145.3849	30.42319
56.53050	144.2277	29.06476
56.58050	143.1476	27.88528
56.63383	142.0010	26.71567
56.68383	140.9324	25.72444
56.73717	139.7983	24.74764
56.78716	138.7436	23.92256
56.83882	137.6559	23.15154
56.89050	136.5747	22.44302
56.94216	135.4982	21.81010
56.99382	134.4278	21.24989
57.04550	133.3597	20.75713
57.09716	132.2974	20.31775
57.14883	131.2390	19.94715
57.20050	130.1836	19.62267
57.25050	129.1677	19.35291
57.30383	128.0838	19.11912
57.35383	127.0724	18.92868
57.40717	125.9947	18.74901
57.45717	124.9887	18.59634
57.51050	123.9138	18.44936
57.56050	122.9098	18.31086
57.61382	121.8365	18.18422
57.66382	120.8329	18.07586
57.71717	119.7646	17.97705
57.76716	118.7624	17.89528
57.82050	117.6941	17.81782
57.87050	116.6929	17.74037
57.92217	115.6578	17.65935
57.97382	114.6251	17.59059
58.02550	113.5912	17.53560
58.07717	112.5575	17.47400
58.12883	111.5238	17.41736
58.18050	110.4923	17.37156
58.23217	109.4598	17.32295
58.28383	108.4276	17.27477
58.33383	107.4294	17.22886
58.38716	106.3640	17.16678
58.43716	105.3648	17.12666
58.49050	104.3030	17.11752
58.54050	103.3038	17.05498
58.59384	102.2378	16.99382
58.64384	101.2384	16.94867
58.69717	100.1738	16.90052
58.74717	99.17649	16.88214
58.80050	98.11158	16.84613
58.85050	97.11332	16.79610
58.90383	96.04914	16.74194
58.95383	95.05031	16.69328
59.00550	94.01906	16.65090
59.05717	92.98715	16.60927
59.10883	91.95505	16.56942
59.16050	90.92282	16.52064
59.21216	89.88985	16.47275
59.26382	88.85941	16.44386
59.31550	87.82720	16.41384
59.36716	86.79624	16.36342
59.41716	85.79741	16.31191
59.47050	84.73316	16.26537
59.52050	83.73426	16.22707
59.57383	82.66884	16.18421
59.62383	81.67075	16.14508
59.67717	80.60548	16.09947
59.72717	79.60687	16.05524
59.78050	78.54071	16.01198
59.83050	77.54209	15.96505
59.88383	76.47661	15.91941
59.93383	75.47708	15.87281
59.98717	74.41066	15.82907
60.03716	73.41282	15.78433
60.08882	72.37940	15.74160
60.14050	71.34730	15.69488
60.19216	70.31521	15.65122
60.24382	69.28171	15.60181
60.29550	68.24975	15.54621
60.34716	67.21478	15.49952
60.39883	66.18340	15.45014
60.45050	65.14941	15.40297
60.50050	64.14955	15.34240
60.55383	63.08318	15.29074
60.60383	62.08301	15.22622
60.65717	61.01609	15.17092
60.70717	60.01688	15.12358
60.76050	58.95090	15.07154
60.81050	57.95276	15.01539
60.86382	56.88739	14.96379
60.91382	55.88852	14.92059
60.96717	54.82418	14.87384
61.01716	53.82419	14.81809
61.07050	52.75898	14.77095
61.12050	51.75952	14.72235
61.17217	50.72640	14.66856
61.22382	49.69312	14.60611
61.27550	48.65958	14.55511
61.32717	47.62759	14.49554
61.37883	46.59450	14.44750
61.43050	45.56202	14.40213
61.48217	44.52963	14.34849
61.53383	43.49768	14.29388
61.58383	42.49772	14.24641
61.63716	41.43213	14.18840
61.68716	40.43394	14.12582
61.74050	39.36606	14.06410
61.79050	38.36518	13.98936
61.84384	37.29797	13.90100
61.89384	36.29560	13.83476
61.94717	35.22761	13.75633
61.99717	34.22570	13.66887
62.05050	33.15703	13.58692
62.10050	32.15396	13.50319
62.15383	31.08466	13.42036
62.20383	30.08338	13.34148
62.25550	29.04670	13.25739
62.30717	28.01137	13.16627
62.35883	26.97489	13.08591
62.41050	25.93762	12.99603
62.46216	24.90136	12.95140
62.51050	23.93225	12.95839
62.56050	23.02385	13.37784
62.61382	22.60764	8.572231
62.66382	22.59594	3.581009
62.71717	22.87308	-0.7184626
62.76716	23.32664	-3.637555
62.82050	23.95923	-5.946774
62.87050	24.65697	-7.525092
62.92217	25.45002	-8.736749
62.97382	26.30093	-9.646622
63.02550	27.19102	-10.33797
63.07717	28.11154	-10.86779
63.12883	29.05398	-11.27716
63.18050	30.01461	-11.59747
63.23217	30.98474	-11.85573
63.28383	31.96600	-12.07422
63.33383	32.92254	-12.24683
63.38716	33.94870	-12.40231
63.43716	34.91570	-12.52181
63.49050	35.95068	-12.63506
63.54050	36.92392	-12.73534
63.59384	37.96521	-12.83865
63.64384	38.94278	-12.91308
63.69717	39.98868	-12.99879
63.74717	40.97021	-13.06756
63.80050	42.01856	-13.14147
63.85050	43.00276	-13.20886
63.90383	44.05366	-13.27857
63.95383	45.04044	-13.33930
64.00550	46.06032	-13.40965
64.05717	47.07970	-13.47213
64.10884	48.10404	-13.54207
64.16050	49.12526	-13.59548
64.21217	50.14835	-13.66090
64.26384	51.17187	-13.72610
64.31550	52.19594	-13.80130
64.36718	53.22034	-13.86215
64.41717	54.21268	-13.92472
64.47050	55.27170	-13.98972
64.52050	56.26444	-14.04940
64.57384	57.32410	-14.11962
64.62383	58.31726	-14.18846
64.67718	59.37739	-14.25334
64.72718	60.36916	-14.31962
64.78050	61.42911	-14.39956
64.83050	62.42294	-14.46504
64.88384	63.48379	-14.54140
64.93384	64.47683	-14.60339
64.98717	65.53865	-14.67267
65.03717	66.53203	-14.74278
65.08884	67.56006	-14.81671
65.14050	68.58958	-14.88160
65.19217	69.61662	-14.94425
65.24384	70.64515	-15.01376
65.29550	71.67331	-15.07894
65.34717	72.70157	-15.15442
65.39883	73.73078	-15.22684
65.45050	74.75874	-15.28957
65.50050	75.75444	-15.36270
65.55384	76.81594	-15.43640
65.60384	77.81132	-15.50309
65.65718	78.87299	-15.58511
65.70718	79.86880	-15.66102
65.76050	80.93026	-15.73840
65.81050	81.92509	-15.81569
65.86384	82.98644	-15.89922
65.91382	83.98166	-15.98154
65.96718	85.04355	-16.06034
66.01716	86.03891	-16.13557
66.07050	87.10168	-16.21934
66.12050	88.09712	-16.29475
66.17218	89.12751	-16.36954
66.22384	90.15674	-16.44769
66.27550	91.18741	-16.51841
66.32718	92.21719	-16.59356
66.37884	93.24666	-16.67093
66.43050	94.27528	-16.74580
66.48218	95.30451	-16.82735
66.53384	96.33452	-16.90142
66.58384	97.33106	-16.96741
66.63718	98.39309	-17.04704
66.68718	99.38850	-17.11676
66.74050	100.4511	-17.20270
66.79050	101.4463	-17.27925
66.84384	102.5086	-17.36567
66.89384	103.5045	-17.44239
66.94718	104.5675	-17.52824
66.99718	105.5630	-17.60339
67.05050	106.6251	-17.69746
67.10050	107.6217	-17.77670
67.15384	108.6836	-17.85591
67.20384	109.6784	-17.94845
67.25550	110.7076	-18.02572
67.30718	111.7366	-18.11265
67.35884	112.7660	-18.20058
67.41050	113.7947	-18.27900
67.46218	114.8249	-18.36122
67.51384	115.8546	-18.44306
67.56550	116.8843	-18.51894
67.61718	117.9134	-18.60711
67.66718	118.9086	-18.69402
67.72050	119.9696	-18.79719
67.77050	120.9656	-18.88916
67.82384	122.0270	-18.99785
67.87384	123.0216	-19.09047
67.92718	124.0820	-19.19678
67.97718	125.0777	-19.29544
68.03050	126.1389	-19.39794
68.08050	127.1345	-19.48615
68.13384	128.1958	-19.58416
68.18384	129.1916	-19.68316
68.23718	130.2541	-19.78611
68.28718	131.2489	-19.88814
68.33884	132.2779	-19.98888
68.39050	133.3056	-20.08602
68.44218	134.3342	-20.19530
68.49384	135.3604	-20.30888
68.54550	136.3884	-20.43014
68.59718	137.4148	-20.54408
68.64884	138.4419	-20.66635
68.70050	139.4686	-20.78042
68.75050	140.4636	-20.89976
68.80384	141.5242	-21.02041
68.85384	142.5178	-21.13496
68.90718	143.5784	-21.25265
68.95718	144.5706	-21.36470
69.01050	145.6315	-21.48700
69.06050	146.6239	-21.61162
69.11384	147.6821	-21.73240
69.16382	148.6754	-21.85037
69.21718	149.7360	-21.96914
69.26716	150.7287	-22.09753
69.32050	151.7880	-22.22778
69.37050	152.7813	-22.34823
69.42218	153.8088	-22.44262
69.47384	154.8354	-22.55017
69.52550	155.8627	-22.66682
69.57718	156.8910	-22.76770
69.62884	157.9193	-22.87199
69.68050	158.9482	-22.95706
69.73218	159.9772	-23.02476
69.78384	161.0079	-23.09184
69.83384	162.0040	-23.13392
69.88718	163.0684	-23.17368
69.93718	164.0651	-23.21182
69.99050	165.1311	-23.25470
70.04050	166.1290	-23.29847
70.09384	167.1937	-23.36201
70.14384	168.1914	-23.43517
70.19718	169.2556	-23.50074
70.24718	170.2518	-23.58182
70.30050	171.3147	-23.69951
70.35050	172.3100	-23.82385
70.40384	173.3716	-23.96308
70.45384	174.3664	-24.09230
70.50550	175.3921	-24.26140
70.55718	176.4174	-24.43782
70.60884	177.4403	-24.63619
70.66050	178.4624	-24.87150
70.71218	179.4824	-25.11589
70.76384	180.5017	-25.40283
70.81550	181.5188	-25.70454
70.86718	182.5349	-26.04160
70.91718	183.5168	-26.40417
70.97050	184.5633	-26.79372
71.02050	185.5410	-27.20381
71.07384	186.5823	-27.69474
71.12384	187.5570	-28.19361
71.17718	188.5925	-28.77612
71.22718	189.5609	-29.37435
71.28050	190.5912	-30.03165
71.33050	191.5553	-30.68130
71.38384	192.5818	-31.38170
71.43384	193.5421	-32.08010
71.48718	194.5663	-32.85290
71.53718	195.5239	-33.61642
71.58884	196.5096	-34.46653
71.64050	197.4937	-35.38174
71.69218	198.4721	-36.37304
71.74384	199.4481	-37.40832
71.79550	200.4208	-38.47688
71.84718	201.3916	-39.52976
71.89884	202.3640	-40.51666
71.95050	203.3404	-41.32960
72.00050	204.2956	-41.81357
72.05384	205.3338	-41.78110
72.10384	206.3379	-40.97682
72.15718	207.4562	-39.06479
72.20718	208.5564	-36.32216
72.26050	209.7808	-32.93574
72.31050	210.9470	-30.21614
72.36384	212.1736	-28.29044
72.41382	213.2900	-27.07098
72.46718	214.4505	-26.13379
72.51716	215.5174	-25.48243
72.57050	216.6358	-24.98276
72.62050	217.6722	-24.64512
72.67218	218.7344	-24.36365
72.72384	219.7884	-24.18956
72.77550	220.8367	-24.06400
72.82718	221.8811	-23.96889
72.87884	222.9215	-23.92350
72.93050	223.9594	-23.89858
72.98218	224.9960	-23.87936
73.03384	226.0312	-23.87498
73.08384	227.0320	-23.87444
73.13718	228.0990	-23.87471
73.18718	229.0994	-23.87770
73.24050	230.1661	-23.88648
73.29050	231.1650	-23.90393
73.34384	232.2307	-23.94569
73.39384	233.2284	-23.98672
73.44718	234.2925	-24.03756
73.49718	235.2910	-24.08692
73.55050	236.3570	-24.13169
73.60050	237.3551	-24.17030
73.65384	238.4200	-24.21340
73.70384	239.4188	-24.25438
73.75550	240.4504	-24.30041
73.80718	241.4831	-24.35437
73.85884	242.5144	-24.39314
73.91050	243.5455	-24.45016
73.96218	244.5770	-24.49525
74.01384	245.6085	-24.54297
74.06550	246.6397	-24.58590
74.11718	247.6713	-24.63215
74.16718	248.6678	-24.67453
74.22050	249.7332	-24.72124
74.27050	250.7312	-24.76812
74.32384	251.7962	-24.81676
74.37384	252.7952	-24.86174
74.42718	253.8598	-24.89968
74.47718	254.8576	-24.94208
74.53050	255.9238	-25.00048
74.58050	256.9219	-25.04585
74.63384	257.9853	-25.09974
74.68384	258.9826	-25.15310
74.73718	260.0468	-25.21083
74.78718	261.0440	-25.26650
74.83884	262.0744	-25.32408
74.89050	263.1049	-25.38131
74.94218	264.1359	-25.43582
74.99384	265.1670	-25.49751
75.04550	266.1980	-25.55092
75.09718	267.2291	-25.60454
75.14884	268.2600	-25.66539
75.20050	269.2890	-25.72962
75.25050	270.2858	-25.78782
75.30384	271.3498	-25.84472
-2.000000	5.000000	0.0000000