File: 5-C1(1.4mol%)+C20(0.6mol%)/matlab/160-3.txt
CLOSED
Version	1.0
Language	English
Mode	Standard
Run	24
RunSerial	12326
Instrument	DSC Q2000 V24.11 Build 124
Module	DSC Standard Cell RC
Operator
File	\\AE520-1454\Users\dsc\Desktop\Data\31-08-17-2\160-3.001
ProcName
InstSerial	2000-0883
AutoSerial	1293
Sample	160-3
Size	19.5000	mg
PanMass	Not available
PanResist	Automatic Automatic  K/W
PanFactor	Default Default
Method
Comment
Xcomment	Pan: Tzero Aluminum Hermetic
Xcomment	Gas1: Nitrogen 50.0 ml/min
Xcomment	Gas2: Nitrogen 50.0 ml/min
Text
Exotherm	UP
Kcell	1.05230
Cpconst	Standard: 0.938
Calib	-38.6961
TempCal	1	pts	157.46	156.60
TzeroDt	-87.6168 -0.0009 -1.4231
TzeroDtz	-87.6168 0.0057 6.9570
InstCalFile	Tzero: \\Ae520-1454\ta\Data\DSC\Calibration\2017\CALIBRATION\1562_RCS (90)_05_18_2017 10_50_44.TZR
InstCalFile	Baseline: \\Ae520-1454\ta\Data\DSC\Calibration\2017\2017-05-17_Calibration.001
InstCalFile	Sapphire: \\Ae520-1454\ta\Data\DSC\Calibration\2017\2017-05-17_Saphire.001
InstCalDate	Tzero 2017-05-18 Time 10:50:44
TempRange	-87.39 to 398.39 °C at 10.00 °C/min Heat Only
AutoZero	Delta T Offset 0.000 uV
AutoZero	Delta T0 Offset 0.000 uV
MultiptCal	0
MultiPtDesc	0) Not set
AutoCellConst	Calibration Date 2017-05-18 16:59:28
Controls	Gas 1  Event Off  Sampling 0.2
Cell#	RC-01562
CoolingUnit	RCS (90)
SelHeatFlow	Heat Flow T4P (mW)
AutoLidII	Installed
AutoAnalysis	Off
MacroFile
Nsig	3
Sig1	Time (min)
Sig2	Temperature (°C)
Sig3	Heat Flow (mW)
Date	2017-09-01
Time	17:06:14
OrgMethod	1: Equilibrate at 80.00 °C
OrgMethod	2: Isothermal for 3.00 min
OrgMethod	3: Jump to 160.00 °C
OrgMethod	4: Mark end of cycle 1
OrgMethod	5: Isothermal for 40.00 min
OrgMethod	6: Mark end of cycle 2
OrgMethod	7: Ramp 20.00 °C/min to 280.00 °C
OrgMethod	8: Mark end of cycle 3
OrgMethod	9: Ramp 20.00 °C/min to 20.00 °C
OrgMethod	10: Mark end of cycle 4
OrgMethod	11: Ramp 20.00 °C/min to 280.00 °C
OrgMethod	12: Mark end of cycle 5
OrgFile	C:\Users\jarra\Desktop\DSC\5-C1(1.4mol%)+C20(0.6mol%)\160-3.001
StartOfData
4.99994E-4	79.88652	-1.045352
0.05383332	79.89285	-0.9195434
0.1038333	79.89526	-0.8350966
0.1555000	79.89613	-0.7768040
0.2071666	79.89746	-0.7377829
0.2571667	79.89685	-0.7144701
0.3105000	79.89606	-0.6989866
0.3605000	79.89526	-0.6913100
0.4121666	79.89288	-0.6873364
0.4638333	79.89148	-0.6850066
0.5138333	79.89024	-0.6827422
0.5655000	79.88855	-0.6804492
0.6171668	79.88616	-0.6782494
0.6671668	79.88519	-0.6762631
0.7205000	79.88394	-0.6743338
0.7705000	79.88145	-0.6728250
0.8221666	79.88052	-0.6712751
0.8738332	79.87862	-0.6700180
0.9238334	79.87839	-0.6690128
0.9755000	79.87743	-0.6681800
1.027167	79.87642	-0.6675310
1.077166	79.87478	-0.6670592
1.130500	79.87364	-0.6667580
1.180500	79.87346	-0.6666386
1.232166	79.87178	-0.6665924
1.283834	79.87072	-0.6667084
1.333833	79.86976	-0.6668500
1.385500	79.86919	-0.6670410
1.437167	79.86772	-0.6673164
1.487166	79.86768	-0.6675907
1.540500	79.86708	-0.6680115
1.590500	79.86604	-0.6684693
1.642166	79.86464	-0.6690060
1.693833	79.86419	-0.6696793
1.743833	79.86407	-0.6703265
1.795500	79.86319	-0.6710180
1.847167	79.86200	-0.6717511
1.897167	79.86145	-0.6725935
1.950500	79.86137	-0.6733707
2.000500	79.85925	-0.6741816
2.052166	79.85955	-0.6750608
2.103833	79.85881	-0.6759284
2.153833	79.85881	-0.6768308
2.205500	79.85750	-0.6777887
2.257167	79.85626	-0.6788025
2.307167	79.85612	-0.6797566
2.360500	79.85532	-0.6808236
2.410500	79.85432	-0.6817318
2.462167	79.85434	-0.6827116
2.513833	79.85426	-0.6837654
2.563833	79.85295	-0.6846582
2.617167	79.85235	-0.6856742
2.667167	79.85244	-0.6866804
2.717167	79.85006	-0.6876112
2.770500	79.85068	-0.6886962
2.820500	79.85038	-0.6897124
2.872167	79.84944	-0.6906874
2.923834	79.84920	-0.6917239
2.973833	79.84753	-0.6926618
3.020500	79.87140	-1.116150
3.073833	80.69915	-16.45161
3.123834	82.78478	-30.10331
3.175500	85.62664	-41.57113
3.227167	88.99785	-51.11418
3.277167	92.62489	-58.51882
3.328833	96.64514	-64.56928
3.380500	100.8583	-69.27194
3.430500	105.0619	-72.85076
3.483833	109.6401	-75.76886
3.533833	113.9896	-77.88826
3.585500	118.5151	-79.66104
3.637167	123.0583	-81.10950
3.687167	127.4681	-82.07730
3.738834	132.0316	-82.80878
3.790500	136.5934	-83.29784
3.840500	141.0029	-83.51182
3.893833	145.5262	-79.37744
3.943833	148.7117	-64.89512
3.995500	151.0668	-51.87293
4.047167	152.8186	-40.47148
4.097166	154.0842	-31.49534
4.150500	155.1091	-23.92943
4.200500	155.8444	-18.47311
4.250500	156.4196	-14.23990
4.303834	156.9046	-10.83967
4.353833	157.2694	-8.448902
4.405500	157.5770	-6.595782
4.457167	157.8296	-5.211529
4.507167	158.0367	-4.197368
4.560500	158.2233	-3.384096
4.610500	158.3742	-2.805766
4.660500	158.5049	-2.352378
4.713834	158.6267	-1.975692
4.763834	158.7273	-1.689347
4.815500	158.8212	-1.450569
4.867166	158.9039	-1.247726
4.917167	158.9756	-1.078876
4.970500	159.0460	-0.9131806
5.020500	159.1060	-0.7728156
5.070500	159.1621	-0.6342674
5.123833	159.2144	-0.4875054
5.173834	159.2615	-0.3582395
5.225500	159.3066	-0.2218367
5.277168	159.3472	-.07306470
5.327168	159.3838	0.06940840
5.380500	159.4206	0.2061395
5.430500	159.4548	0.3742822
5.480500	159.4871	0.5406916
5.533832	159.5189	0.7236468
5.583832	159.5478	0.8830782
5.635500	159.5779	1.085358
5.687168	159.6066	1.281761
5.737168	159.6329	1.495128
5.790500	159.6619	1.722037
5.840500	159.6881	1.948412
5.890500	159.7142	2.188816
5.943832	159.7423	2.452788
5.993834	159.7678	2.711371
6.045500	159.7944	2.993602
6.097168	159.8228	3.285894
6.147168	159.8484	3.586301
6.200500	159.8764	3.908997
6.250500	159.9036	4.226147
6.300500	159.9302	4.554883
6.353832	159.9594	4.913534
6.403832	159.9870	5.252060
6.455500	160.0149	5.608332
6.507168	160.0422	5.962184
6.557166	160.0696	6.297904
6.610500	160.0966	6.650874
6.660500	160.1214	6.962790
6.712168	160.1446	7.269708
6.763834	160.1667	7.543004
6.813834	160.1848	7.781568
6.865500	160.2024	7.987025
6.917168	160.2175	8.160182
6.967168	160.2288	8.294648
7.020500	160.2398	8.405806
7.070500	160.2482	8.489975
7.122168	160.2562	8.568384
7.173834	160.2644	8.652786
7.223834	160.2733	8.763241
7.275500	160.2839	8.925450
7.327168	160.2994	9.147241
7.377168	160.3173	9.429869
7.430500	160.3404	9.805429
7.480500	160.3693	10.22562
7.532166	160.4011	10.72071
7.583832	160.4369	11.25367
7.633832	160.4725	11.78124
7.685500	160.5072	12.30604
7.737168	160.5399	12.77556
7.787168	160.5679	13.15776
7.840500	160.5912	13.46909
7.890500	160.6055	13.65191
7.942168	160.6137	13.73484
7.993834	160.6167	13.73949
8.043834	160.6134	13.71686
8.095500	160.6052	13.58733
8.147168	160.5940	13.33760
8.197168	160.5813	13.11644
8.250500	160.5672	12.87615
8.300500	160.5538	12.64730
8.352168	160.5388	12.41788
8.403832	160.5251	12.19424
8.453834	160.5122	11.99083
8.505500	160.4996	11.78872
8.557168	160.4872	11.60212
8.607166	160.4756	11.42348
8.660499	160.4647	11.24818
8.710499	160.4544	11.08994
8.762168	160.4448	10.93594
8.813834	160.4368	10.78571
8.863834	160.4274	10.65299
8.917168	160.4194	10.51723
8.967168	160.4122	10.40174
9.017168	160.4045	10.29023
9.070500	160.3970	10.17781
9.120499	160.3915	10.08095
9.172168	160.3851	9.986786
9.223832	160.3799	9.897032
9.273834	160.3745	9.813828
9.327168	160.3690	9.730012
9.377168	160.3648	9.654131
9.427168	160.3592	9.583515
9.480500	160.3554	9.509226
9.530500	160.3511	9.444969
9.582168	160.3465	9.379852
9.633832	160.3429	9.317150
9.683832	160.3390	9.258121
9.737168	160.3353	9.196530
9.787168	160.3314	9.139136
9.837168	160.3287	9.086170
9.890500	160.3256	9.030819
9.940500	160.3229	8.979809
9.992166	160.3198	8.931602
10.04383	160.3177	8.884826
10.09383	160.3144	8.842584
10.14717	160.3119	8.803066
10.19717	160.3104	8.768598
10.24717	160.3075	8.739406
10.30050	160.3067	8.714772
10.35050	160.3063	8.697785
10.40217	160.3043	8.684219
10.45383	160.3033	8.675055
10.50384	160.3028	8.669746
10.55717	160.3030	8.665282
10.60717	160.3035	8.661197
10.65717	160.3021	8.657159
10.71050	160.3016	8.652718
10.76050	160.3011	8.648309
10.81216	160.3000	8.643338
10.86383	160.2986	8.635959
10.91383	160.2964	8.620332
10.96717	160.2946	8.590530
11.01717	160.2925	8.537026
11.06716	160.2883	8.459215
11.12050	160.2834	8.355111
11.17050	160.2774	8.244062
11.22217	160.2708	8.110119
11.27383	160.2620	7.961782
11.32383	160.2520	7.793544
11.37717	160.2390	7.593694
11.42717	160.2268	7.375788
11.47884	160.2110	7.125878
11.53050	160.1936	6.846432
11.58050	160.1750	6.557056
11.63216	160.1544	6.239334
11.68383	160.1333	5.891370
11.73383	160.1112	5.546048
11.78717	160.0864	5.166262
11.83717	160.0635	4.791359
11.88883	160.0382	4.403016
11.94050	160.0130	4.009358
11.99050	159.9879	3.631436
12.04217	159.9634	3.241330
12.09383	159.9390	2.863146
12.14383	159.9160	2.505422
12.19717	159.8912	2.134532
12.24717	159.8697	1.804140
12.29884	159.8483	1.478599
12.35050	159.8276	1.171408
12.40050	159.8094	0.8867887
12.45217	159.7913	0.6182078
12.50384	159.7747	0.3652828
12.55383	159.7591	0.1362494
12.60717	159.7446	-.07981212
12.65717	159.7317	-0.2725189
12.70883	159.7199	-0.4549288
12.76050	159.7080	-0.6184614
12.81050	159.6985	-0.7639222
12.86217	159.6892	-0.8987039
12.91383	159.6808	-1.021744
12.96383	159.6738	-1.129227
13.01717	159.6667	-1.230938
13.06716	159.6604	-1.316626
13.11884	159.6551	-1.395321
13.17050	159.6509	-1.466729
13.22050	159.6463	-1.529585
13.27217	159.6424	-1.584478
13.32384	159.6381	-1.636440
13.37384	159.6356	-1.683106
13.42717	159.6322	-1.722295
13.47717	159.6299	-1.756029
13.52883	159.6268	-1.787744
13.58050	159.6246	-1.815580
13.63050	159.6232	-1.842488
13.68383	159.6198	-1.866556
13.73383	159.6196	-1.887518
13.78383	159.6172	-1.906727
13.83717	159.6155	-1.927113
13.88717	159.6144	-1.944618
13.93883	159.6131	-1.960053
13.99050	159.6121	-1.976858
14.04050	159.6112	-1.990103
14.09383	159.6099	-2.003444
14.14383	159.6091	-2.015482
14.19384	159.6080	-2.026059
14.24717	159.6071	-2.037090
14.29717	159.6069	-2.045681
14.34883	159.6056	-2.053814
14.40050	159.6048	-2.061890
14.45050	159.6046	-2.069832
14.50383	159.6036	-2.077572
14.55383	159.6031	-2.085219
14.60383	159.6020	-2.092841
14.65717	159.6022	-2.101061
14.70717	159.6017	-2.108778
14.75883	159.6012	-2.116879
14.81050	159.6015	-2.125087
14.86050	159.6012	-2.133015
14.91383	159.6013	-2.141508
14.96383	159.6007	-2.149454
15.01383	159.6004	-2.157253
15.06716	159.6004	-2.165544
15.11716	159.5999	-2.173099
15.16883	159.5997	-2.180878
15.22050	159.5988	-2.188448
15.27050	159.5992	-2.195638
15.32384	159.5989	-2.203164
15.37384	159.5977	-2.210004
15.42383	159.5986	-2.216734
15.47717	159.5988	-2.223816
15.52717	159.5980	-2.230260
15.57883	159.5973	-2.236834
15.63050	159.5974	-2.243258
15.68050	159.5972	-2.249377
15.73383	159.5967	-2.255647
15.78383	159.5969	-2.261383
15.83383	159.5951	-2.266917
15.88716	159.5954	-2.272864
15.93717	159.5958	-2.278274
15.98883	159.5953	-2.283679
16.04050	159.5950	-2.288980
16.09050	159.5947	-2.293984
16.14383	159.5940	-2.299175
16.19383	159.5944	-2.303901
16.24550	159.5939	-2.308632
16.29716	159.5930	-2.313243
16.34717	159.5925	-2.317607
16.39883	159.5923	-2.322039
16.45050	159.5924	-2.326383
16.50050	159.5914	-2.330472
16.55383	159.5925	-2.334756
16.60383	159.5909	-2.338640
16.65550	159.5919	-2.342758
16.70716	159.5915	-2.346773
16.75716	159.5908	-2.350617
16.80883	159.5916	-2.354460
16.86050	159.5916	-2.358258
16.91050	159.5920	-2.361761
16.96383	159.5923	-2.365346
17.01383	159.5924	-2.368553
17.06550	159.5913	-2.371790
17.11716	159.5916	-2.374886
17.16716	159.5920	-2.377838
17.21883	159.5917	-2.380760
17.27050	159.5912	-2.383607
17.32050	159.5912	-2.386260
17.37383	159.5906	-2.388977
17.42383	159.5913	-2.391443
17.47550	159.5903	-2.393923
17.52716	159.5906	-2.396405
17.57716	159.5903	-2.398831
17.62883	159.5908	-2.401162
17.68050	159.5902	-2.403484
17.73050	159.5904	-2.405647
17.78383	159.5906	-2.407920
17.83383	159.5907	-2.410075
17.88550	159.5904	-2.412090
17.93716	159.5899	-2.414158
17.98716	159.5901	-2.415973
18.03883	159.5900	-2.417794
18.09050	159.5902	-2.419629
18.14050	159.5900	-2.421314
18.19383	159.5900	-2.423214
18.24383	159.5912	-2.425037
18.29550	159.5908	-2.426718
18.34716	159.5910	-2.428396
18.39716	159.5902	-2.429960
18.45050	159.5915	-2.431574
18.50050	159.5908	-2.433018
18.55050	159.5908	-2.434358
18.60383	159.5902	-2.435787
18.65383	159.5904	-2.437178
18.70550	159.5909	-2.438581
18.75716	159.5907	-2.439871
18.80716	159.5915	-2.441060
18.86050	159.5907	-2.442413
18.91050	159.5910	-2.443846
18.96050	159.5913	-2.445266
19.01383	159.5911	-2.446695
19.06383	159.5914	-2.448064
19.11550	159.5921	-2.449397
19.16716	159.5921	-2.450648
19.21716	159.5921	-2.451880
19.27050	159.5923	-2.453106
19.32050	159.5924	-2.454251
19.37050	159.5925	-2.455324
19.42383	159.5927	-2.456390
19.47383	159.5928	-2.457412
19.52550	159.5931	-2.458524
19.57716	159.5917	-2.459528
19.62716	159.5920	-2.460560
19.68050	159.5928	-2.461606
19.73050	159.5924	-2.462470
19.78050	159.5923	-2.463433
19.83383	159.5922	-2.464287
19.88383	159.5916	-2.465086
19.93550	159.5914	-2.465933
19.98716	159.5910	-2.466714
20.03717	159.5913	-2.467356
20.09050	159.5910	-2.468042
20.14050	159.5899	-2.468736
20.19050	159.5904	-2.469371
20.24383	159.5906	-2.470095
20.29383	159.5892	-2.470660
20.34550	159.5897	-2.471306
20.39716	159.5890	-2.471970
20.44716	159.5904	-2.472662
20.50050	159.5886	-2.473343
20.55050	159.5888	-2.474154
20.60050	159.5888	-2.474876
20.65383	159.5890	-2.475690
20.70383	159.5894	-2.476383
20.75550	159.5895	-2.477166
20.80716	159.5886	-2.477986
20.85716	159.5892	-2.478892
20.91050	159.5899	-2.479918
20.96050	159.5900	-2.480906
21.01216	159.5902	-2.481861
21.06383	159.5903	-2.482733
21.11383	159.5905	-2.483474
21.16550	159.5911	-2.484165
21.21716	159.5900	-2.484858
21.26716	159.5897	-2.485501
21.32050	159.5897	-2.486112
21.37050	159.5903	-2.486621
21.42216	159.5902	-2.486946
21.47383	159.5900	-2.487348
21.52383	159.5895	-2.487665
21.57550	159.5899	-2.488112
21.62716	159.5899	-2.488611
21.67717	159.5904	-2.489253
21.73050	159.5906	-2.489830
21.78050	159.5892	-2.490379
21.83216	159.5899	-2.491050
21.88383	159.5893	-2.491690
21.93383	159.5893	-2.492248
21.98550	159.5898	-2.492654
22.03717	159.5904	-2.493122
22.08716	159.5902	-2.493436
22.14050	159.5899	-2.493750
22.19050	159.5897	-2.494051
22.24216	159.5905	-2.494500
22.29383	159.5894	-2.494895
22.34383	159.5897	-2.495344
22.39550	159.5894	-2.495756
22.44716	159.5904	-2.496357
22.49716	159.5906	-2.496914
22.55050	159.5903	-2.497504
22.60050	159.5904	-2.498018
22.65216	159.5908	-2.498586
22.70383	159.5906	-2.499035
22.75383	159.5912	-2.499513
22.80550	159.5905	-2.499953
22.85716	159.5903	-2.500312
22.90716	159.5913	-2.500739
22.96050	159.5906	-2.501081
23.01050	159.5907	-2.501361
23.06216	159.5902	-2.501552
23.11383	159.5898	-2.501664
23.16383	159.5900	-2.501880
23.21716	159.5896	-2.502014
23.26716	159.5892	-2.502128
23.31716	159.5891	-2.502280
23.37050	159.5890	-2.502532
23.42050	159.5890	-2.502661
23.47216	159.5888	-2.502939
23.52383	159.5885	-2.503142
23.57383	159.5896	-2.503494
23.62716	159.5889	-2.503772
23.67717	159.5886	-2.504097
23.72716	159.5891	-2.504378
23.78050	159.5889	-2.504779
23.83050	159.5892	-2.505284
23.88216	159.5891	-2.505761
23.93383	159.5900	-2.506381
23.98383	159.5903	-2.506817
24.03717	159.5901	-2.507326
24.08716	159.5897	-2.507805
24.13716	159.5904	-2.508249
24.19050	159.5910	-2.508614
24.24050	159.5913	-2.508994
24.29216	159.5904	-2.509243
24.34383	159.5911	-2.509492
24.39383	159.5908	-2.509740
24.44716	159.5913	-2.510026
24.49716	159.5909	-2.510335
24.54716	159.5904	-2.510605
24.60050	159.5909	-2.510873
24.65050	159.5907	-2.511094
24.70216	159.5904	-2.511253
24.75383	159.5908	-2.511418
24.80383	159.5902	-2.511517
24.85716	159.5898	-2.511511
24.90716	159.5891	-2.511582
24.95717	159.5904	-2.511668
25.01050	159.5893	-2.511857
25.06050	159.5897	-2.512138
25.11216	159.5904	-2.512498
25.16383	159.5895	-2.512783
25.21383	159.5896	-2.513206
25.26716	159.5899	-2.513597
25.31716	159.5904	-2.513938
25.36716	159.5902	-2.514278
25.42050	159.5910	-2.514608
25.47050	159.5903	-2.514812
25.52216	159.5909	-2.515052
25.57383	159.5904	-2.515196
25.62383	159.5911	-2.515404
25.67717	159.5904	-2.515609
25.72717	159.5913	-2.515732
25.77883	159.5898	-2.515877
25.83050	159.5901	-2.516094
25.88050	159.5899	-2.516268
25.93216	159.5909	-2.516376
25.98383	159.5892	-2.516458
26.03383	159.5893	-2.516533
26.08716	159.5902	-2.516640
26.13716	159.5896	-2.516697
26.18883	159.5897	-2.516753
26.24050	159.5898	-2.516817
26.29050	159.5895	-2.516890
26.34216	159.5894	-2.516968
26.39383	159.5894	-2.517047
26.44383	159.5888	-2.517063
26.49716	159.5885	-2.517075
26.54716	159.5885	-2.517136
26.59883	159.5894	-2.517248
26.65050	159.5903	-2.517300
26.70050	159.5895	-2.517457
26.75217	159.5898	-2.517712
26.80383	159.5895	-2.517915
26.85383	159.5901	-2.518139
26.90716	159.5894	-2.518456
26.95716	159.5906	-2.518780
27.00883	159.5898	-2.519054
27.06050	159.5902	-2.519373
27.11050	159.5908	-2.519755
27.16217	159.5912	-2.520114
27.21383	159.5914	-2.520394
27.26383	159.5918	-2.520656
27.31716	159.5907	-2.520788
27.36716	159.5908	-2.520912
27.41883	159.5906	-2.520965
27.47050	159.5912	-2.521031
27.52050	159.5903	-2.520938
27.57217	159.5910	-2.520997
27.62383	159.5904	-2.520992
27.67383	159.5906	-2.521202
27.72717	159.5906	-2.521434
27.77717	159.5910	-2.521688
27.82883	159.5908	-2.521860
27.88050	159.5911	-2.522080
27.93050	159.5921	-2.522339
27.98383	159.5911	-2.522422
28.03383	159.5910	-2.522435
28.08383	159.5909	-2.522411
28.13716	159.5906	-2.522519
28.18717	159.5914	-2.522490
28.23883	159.5910	-2.522473
28.29050	159.5906	-2.522484
28.34050	159.5910	-2.522478
28.39383	159.5900	-2.522520
28.44383	159.5903	-2.522602
28.49383	159.5900	-2.522711
28.54716	159.5904	-2.522887
28.59716	159.5904	-2.523064
28.64883	159.5907	-2.523283
28.70050	159.5904	-2.523358
28.75050	159.5904	-2.523413
28.80383	159.5896	-2.523472
28.85383	159.5899	-2.523563
28.90383	159.5900	-2.523666
28.95716	159.5904	-2.523814
29.00716	159.5906	-2.523878
29.05883	159.5898	-2.523961
29.11050	159.5901	-2.524059
29.16050	159.5899	-2.524284
29.21383	159.5901	-2.524515
29.26383	159.5899	-2.524701
29.31383	159.5899	-2.524903
29.36716	159.5898	-2.525005
29.41716	159.5904	-2.525308
29.46883	159.5902	-2.525514
29.52050	159.5910	-2.525902
29.57050	159.5909	-2.526175
29.62383	159.5913	-2.526473
29.67383	159.5914	-2.526684
29.72383	159.5911	-2.526892
29.77717	159.5920	-2.527092
29.82717	159.5916	-2.527244
29.87883	159.5920	-2.527344
29.93050	159.5911	-2.527484
29.98050	159.5925	-2.527578
30.03383	159.5913	-2.527614
30.08383	159.5917	-2.527795
30.13383	159.5916	-2.527945
30.18717	159.5907	-2.527966
30.23716	159.5917	-2.527935
30.28883	159.5919	-2.527985
30.34050	159.5918	-2.527996
30.39050	159.5908	-2.528024
30.44383	159.5922	-2.528180
30.49383	159.5913	-2.528192
30.54550	159.5915	-2.528182
30.59716	159.5907	-2.528133
30.64716	159.5908	-2.528206
30.69883	159.5912	-2.528120
30.75050	159.5912	-2.527984
30.80050	159.5908	-2.527942
30.85383	159.5909	-2.528014
30.90383	159.5909	-2.528048
30.95550	159.5911	-2.528225
31.00716	159.5905	-2.528378
31.05716	159.5911	-2.528531
31.10883	159.5907	-2.528716
31.16050	159.5911	-2.528854
31.21050	159.5910	-2.528951
31.26383	159.5911	-2.529094
31.31383	159.5910	-2.529101
31.36550	159.5905	-2.529194
31.41716	159.5901	-2.529350
31.46716	159.5915	-2.529518
31.51883	159.5911	-2.529716
31.57050	159.5907	-2.529877
31.62050	159.5918	-2.530054
31.67383	159.5908	-2.530185
31.72383	159.5908	-2.530266
31.77550	159.5906	-2.530382
31.82717	159.5910	-2.530423
31.87717	159.5908	-2.530434
31.92883	159.5905	-2.530382
31.98050	159.5902	-2.530288
32.03050	159.5908	-2.530242
32.08383	159.5906	-2.530220
32.13383	159.5912	-2.530210
32.18550	159.5909	-2.530224
32.23717	159.5898	-2.530205
32.28717	159.5908	-2.530215
32.33883	159.5906	-2.530270
32.39050	159.5900	-2.530228
32.44050	159.5901	-2.530203
32.49383	159.5901	-2.530105
32.54383	159.5896	-2.530049
32.59550	159.5897	-2.530110
32.64717	159.5901	-2.530268
32.69717	159.5909	-2.530449
32.75050	159.5903	-2.530623
32.80050	159.5913	-2.530850
32.85050	159.5908	-2.531066
32.90383	159.5912	-2.531279
32.95383	159.5919	-2.531564
33.00550	159.5914	-2.531653
33.05716	159.5914	-2.531799
33.10716	159.5916	-2.531869
33.16050	159.5923	-2.531903
33.21050	159.5922	-2.532064
33.26050	159.5915	-2.531936
33.31383	159.5919	-2.531880
33.36383	159.5921	-2.531772
33.41550	159.5913	-2.531660
33.46716	159.5911	-2.531600
33.51716	159.5919	-2.531541
33.57050	159.5910	-2.531346
33.62050	159.5903	-2.531333
33.67050	159.5908	-2.531374
33.72383	159.5916	-2.531464
33.77383	159.5915	-2.531527
33.82550	159.5912	-2.531692
33.87717	159.5907	-2.531873
33.92717	159.5912	-2.532142
33.98050	159.5916	-2.532437
34.03050	159.5914	-2.532678
34.08050	159.5912	-2.532877
34.13383	159.5926	-2.533208
34.18384	159.5918	-2.533305
34.23550	159.5920	-2.533410
34.28717	159.5919	-2.533405
34.33716	159.5928	-2.533391
34.39050	159.5919	-2.533304
34.44050	159.5914	-2.533263
34.49050	159.5911	-2.533195
34.54383	159.5923	-2.533169
34.59384	159.5919	-2.533151
34.64550	159.5916	-2.533036
34.69717	159.5919	-2.532981
34.74716	159.5913	-2.532922
34.80050	159.5917	-2.532948
34.85050	159.5918	-2.532920
34.90050	159.5906	-2.532886
34.95383	159.5916	-2.532862
35.00383	159.5914	-2.532752
35.05550	159.5908	-2.532678
35.10716	159.5911	-2.532511
35.15716	159.5903	-2.532430
35.21050	159.5905	-2.532230
35.26050	159.5915	-2.532178
35.31216	159.5903	-2.532094
35.36383	159.5908	-2.532137
35.41383	159.5902	-2.532094
35.46550	159.5908	-2.532106
35.51716	159.5903	-2.532020
35.56716	159.5908	-2.532025
35.62050	159.5914	-2.532106
35.67050	159.5914	-2.532262
35.72217	159.5910	-2.532323
35.77383	159.5918	-2.532451
35.82383	159.5913	-2.532584
35.87550	159.5916	-2.532782
35.92717	159.5925	-2.532874
35.97717	159.5925	-2.533010
36.03050	159.5925	-2.533130
36.08050	159.5922	-2.533124
36.13216	159.5919	-2.533040
36.18384	159.5927	-2.533007
36.23383	159.5914	-2.532784
36.28550	159.5917	-2.532590
36.33716	159.5918	-2.532293
36.38716	159.5912	-2.532022
36.44050	159.5916	-2.531840
36.49050	159.5908	-2.531717
36.54217	159.5908	-2.531666
36.59384	159.5911	-2.531740
36.64383	159.5921	-2.531723
36.69550	159.5913	-2.531690
36.74716	159.5910	-2.531668
36.79716	159.5917	-2.531633
36.85050	159.5909	-2.531644
36.90050	159.5915	-2.531670
36.95216	159.5916	-2.531766
37.00383	159.5924	-2.531812
37.05383	159.5926	-2.531862
37.10550	159.5921	-2.531870
37.15716	159.5914	-2.531786
37.20716	159.5914	-2.531662
37.26050	159.5914	-2.531572
37.31050	159.5915	-2.531406
37.36217	159.5913	-2.531204
37.41383	159.5906	-2.530975
37.46383	159.5903	-2.530899
37.51716	159.5909	-2.530953
37.56716	159.5919	-2.531090
37.61716	159.5921	-2.531289
37.67050	159.5916	-2.531446
37.72050	159.5928	-2.531570
37.77217	159.5921	-2.531654
37.82383	159.5925	-2.531728
37.87383	159.5924	-2.531744
37.92717	159.5917	-2.531798
37.97717	159.5923	-2.531771
38.02716	159.5920	-2.531653
38.08050	159.5911	-2.531552
38.13050	159.5915	-2.531460
38.18216	159.5908	-2.531380
38.23383	159.5914	-2.531314
38.28383	159.5917	-2.531183
38.33716	159.5917	-2.531133
38.38716	159.5915	-2.531150
38.43716	159.5922	-2.531170
38.49050	159.5926	-2.531157
38.54050	159.5921	-2.531239
38.59216	159.5919	-2.531388
38.64383	159.5926	-2.531392
38.69383	159.5922	-2.531414
38.74716	159.5928	-2.531372
38.79716	159.5921	-2.531376
38.84716	159.5914	-2.531258
38.90050	159.5914	-2.531108
38.95050	159.5919	-2.531049
39.00217	159.5916	-2.530914
39.05383	159.5922	-2.531030
39.10383	159.5918	-2.531202
39.15716	159.5920	-2.531339
39.20716	159.5922	-2.531480
39.25716	159.5921	-2.531566
39.31050	159.5926	-2.531670
39.36050	159.5923	-2.531670
39.41217	159.5912	-2.531639
39.46383	159.5920	-2.531643
39.51383	159.5920	-2.531563
39.56716	159.5919	-2.531504
39.61716	159.5924	-2.531406
39.66716	159.5918	-2.531415
39.72050	159.5911	-2.531490
39.77050	159.5916	-2.531639
39.82217	159.5923	-2.531830
39.87383	159.5928	-2.531994
39.92383	159.5921	-2.532062
39.97717	159.5926	-2.532100
40.02716	159.5928	-2.532124
40.07883	159.5925	-2.532093
40.13050	159.5925	-2.532016
40.18050	159.5919	-2.531942
40.23216	159.5922	-2.531834
40.28383	159.5917	-2.531652
40.33383	159.5906	-2.531600
40.38716	159.5919	-2.531537
40.43716	159.5911	-2.531557
40.48883	159.5917	-2.531682
40.54050	159.5922	-2.531778
40.59050	159.5920	-2.531866
40.64216	159.5916	-2.531903
40.69383	159.5919	-2.531986
40.74383	159.5928	-2.532000
40.79716	159.5926	-2.531895
40.84716	159.5920	-2.531858
40.89883	159.5918	-2.531764
40.95050	159.5924	-2.531724
41.00050	159.5915	-2.531626
41.05217	159.5916	-2.531473
41.10383	159.5913	-2.531366
41.15383	159.5917	-2.531304
41.20717	159.5924	-2.531305
41.25717	159.5924	-2.531424
41.30883	159.5914	-2.531512
41.36050	159.5923	-2.531655
41.41050	159.5921	-2.531886
41.46216	159.5926	-2.532097
41.51383	159.5923	-2.532321
41.56383	159.5928	-2.532321
41.61716	159.5922	-2.532350
41.66716	159.5934	-2.532376
41.71884	159.5925	-2.532302
41.77050	159.5929	-2.532259
41.82050	159.5926	-2.532109
41.87216	159.5926	-2.532085
41.92383	159.5925	-2.532101
41.97383	159.5929	-2.532066
42.02716	159.5921	-2.531918
42.07717	159.5922	-2.531870
42.12883	159.5924	-2.531840
42.18050	159.5928	-2.531746
42.23050	159.5919	-2.531650
42.28383	159.5919	-2.531608
42.33383	159.5931	-2.531577
42.38383	159.5928	-2.531648
42.43716	159.5924	-2.531722
42.48717	159.5928	-2.531797
42.53883	159.5924	-2.531880
42.59050	159.5925	-2.532041
42.64050	159.5925	-2.532140
42.69383	159.5926	-2.532200
42.74383	159.5928	-2.532213
42.79383	159.5931	-2.532235
42.84716	159.5936	-2.532332
42.89717	159.5938	-2.532311
42.94883	159.5936	-2.532435
-2.000000	2.000000	0.0000000
43.05050	159.6081	-3.318832
43.10050	159.7996	-7.606491
43.15050	160.2159	-11.32416
43.20383	160.8276	-14.38657
43.25383	161.5199	-16.43986
43.30550	162.3198	-17.97005
43.35717	163.1787	-19.06594
43.40717	164.0502	-19.84561
43.46050	165.0123	-20.44439
43.51050	165.9351	-20.86144
43.56050	166.8734	-21.20122
43.61383	167.8839	-21.47434
43.66383	168.8416	-21.68328
43.71550	169.8362	-21.86802
43.76717	170.8346	-22.05418
43.81717	171.8051	-22.22324
43.87050	172.8435	-22.37337
43.92050	173.8194	-22.51759
43.97050	174.7983	-22.65318
44.02383	175.8438	-22.80994
44.07383	176.8245	-22.93334
44.12550	177.8396	-23.08779
44.17717	178.8556	-23.24883
44.22717	179.8377	-23.40708
44.28050	180.8872	-23.59159
44.33050	181.8700	-23.77926
44.38050	182.8524	-23.97784
44.43383	183.9010	-24.22606
44.48383	184.8820	-24.48221
44.53550	185.8966	-24.75904
44.58716	186.9084	-25.09894
44.63716	187.8854	-25.46164
44.69050	188.9252	-25.89588
44.74050	189.8966	-26.38410
44.79050	190.8660	-26.91763
44.84384	191.8946	-27.58139
44.89383	192.8570	-28.25678
44.94550	193.8458	-29.06623
44.99716	194.8296	-29.94266
45.04716	195.7775	-30.86885
45.10050	196.7850	-31.93434
45.15050	197.7242	-33.02857
45.20050	198.6556	-34.30765
45.25383	199.6396	-35.91006
45.30383	200.5494	-37.61829
45.35550	201.4796	-39.52828
45.40717	202.4000	-41.48928
45.45717	203.2901	-43.35398
45.51050	204.2384	-45.29035
45.56050	205.1271	-47.06168
45.61217	206.0505	-48.84596
45.66383	206.9747	-50.67020
45.71383	207.8694	-52.43088
45.76550	208.7929	-54.23645
45.81717	209.7184	-56.02683
45.86716	210.6182	-57.56388
45.92050	211.5940	-58.43897
45.97050	212.5581	-57.62714
46.02217	213.6646	-52.95141
46.07383	214.9442	-44.76316
46.12383	216.3179	-37.30296
46.17550	217.7056	-33.34898
46.22717	219.0038	-30.88087
46.27716	220.1894	-29.21098
46.33050	221.3982	-27.93112
46.38050	222.4933	-27.10375
46.43217	223.5969	-26.48378
46.48383	224.6808	-26.03226
46.53383	225.7170	-25.73407
46.58550	226.7752	-25.51641
46.63716	227.8259	-25.38133
46.68716	228.8369	-25.31465
46.74050	229.9114	-25.26212
46.79050	230.9156	-25.24574
46.84217	231.9509	-25.24331
46.89383	232.9858	-25.24393
46.94383	233.9850	-25.24519
46.99550	235.0183	-25.25176
47.04716	236.0504	-25.26462
47.09716	237.0492	-25.28307
47.15050	238.1147	-25.31276
47.20050	239.1130	-25.33857
47.25217	240.1460	-25.37849
47.30383	241.1779	-25.42016
47.35383	242.1766	-25.46016
47.40550	243.2087	-25.50302
47.45717	244.2408	-25.53620
47.50717	245.2390	-25.56657
47.56050	246.3044	-25.60186
47.61050	247.3018	-25.63138
47.66217	248.3327	-25.66887
47.71383	249.3647	-25.71025
47.76383	250.3619	-25.75025
47.81717	251.4284	-25.78604
47.86716	252.4268	-25.81504
47.91716	253.4258	-25.84582
47.97050	254.4908	-25.87890
48.02050	255.4886	-25.90807
48.07217	256.5214	-25.95300
48.12383	257.5527	-25.99258
48.17383	258.5498	-26.04564
48.22717	259.6150	-26.09790
48.27716	260.6124	-26.13734
48.32717	261.6096	-26.17746
48.38050	262.6736	-26.22922
48.43050	263.6712	-26.26722
48.48217	264.7028	-26.31587
48.53383	265.7345	-26.35352
48.58383	266.7335	-26.38256
48.63716	267.7979	-26.41769
48.68716	268.7946	-26.46245
48.73717	269.7925	-26.50166
48.79050	270.8575	-26.53537
48.84050	271.8540	-26.57485
48.89217	272.8864	-26.62006
48.94383	273.9180	-26.64409
48.99383	274.9157	-26.65252
49.04550	275.9139	-27.60227
49.09716	276.4543	-24.91149
49.14717	276.5228	-16.46555
49.19883	276.3019	-8.562562
49.25050	275.8674	-2.273405
49.30050	275.3030	2.322102
49.35383	274.5870	5.932074
49.40383	273.8400	8.409674
49.45550	273.0099	10.29326
49.50717	272.1373	11.66262
49.55717	271.2624	12.63999
49.60883	270.3350	13.38080
49.66050	269.3897	13.93293
49.71050	268.4594	14.33052
49.76383	267.4572	14.65341
49.81383	266.5108	14.87128
49.86550	265.5240	15.05307
49.91716	264.5318	15.18421
49.96717	263.5686	15.29580
50.01883	262.5675	15.37522
50.07050	261.5642	15.43776
50.12050	260.5904	15.49183
50.17383	259.5500	15.53324
50.22383	258.5720	15.56548
50.27550	257.5602	15.59723
50.32717	256.5480	15.62410
50.37717	255.5662	15.64682
50.42883	254.5522	15.67737
50.48050	253.5358	15.70672
50.53050	252.5520	15.72859
50.58383	251.5016	15.75236
50.63383	250.5157	15.76713
50.68550	249.4957	15.78511
50.73717	248.4766	15.79968
50.78717	247.4890	15.81614
50.83883	246.4678	15.83000
50.89050	245.4457	15.84054
50.94050	244.4560	15.84951
50.99383	243.4002	15.85589
51.04383	242.4104	15.86232
51.09550	241.3878	15.86871
51.14717	240.3646	15.87571
51.19717	239.3749	15.88478
51.25050	238.3176	15.89492
51.30050	237.3271	15.90569
51.35050	236.3362	15.91744
51.40383	235.2774	15.92758
51.45383	234.2873	15.93532
51.50550	233.2631	15.94462
51.55717	232.2385	15.95259
51.60717	231.2466	15.96101
51.66050	230.1881	15.96932
51.71050	229.1958	15.97716
51.76050	228.2036	15.98576
51.81383	227.1462	15.99974
51.86383	226.1540	16.01062
51.91550	225.1289	16.02373
51.96717	224.1030	16.03410
52.01716	223.1094	16.04480
52.07050	222.0506	16.05362
52.12050	221.0567	16.06172
52.17050	220.0642	16.07003
52.22383	219.0056	16.07933
52.27383	218.0133	16.08838
52.32550	216.9880	16.09834
52.37717	215.9620	16.10940
52.42717	214.9682	16.11909
52.48050	213.9085	16.12816
52.53050	212.9164	16.13640
52.58050	211.9228	16.14471
52.63383	210.8640	16.15352
52.68383	209.8706	16.16312
52.73550	208.8448	16.17292
52.78716	207.8181	16.18258
52.83716	206.8246	16.19111
52.89050	205.7651	16.20005
52.94050	204.7714	16.20831
52.99050	203.7768	16.21676
53.04382	202.7183	16.22538
53.09384	201.7253	16.23345
53.14550	200.6996	16.24293
53.19717	199.6740	16.25313
53.24717	198.6806	16.26405
53.30050	197.6209	16.27378
53.35050	196.6267	16.28284
53.40050	195.6323	16.29109
53.45383	194.5714	16.30060
53.50383	193.5775	16.30884
53.55550	192.5510	16.31732
53.60717	191.5245	16.32584
53.65717	190.5296	16.33373
53.71050	189.4695	16.34186
53.76050	188.4752	16.34960
53.81216	187.4489	16.35711
53.86382	186.4216	16.36495
53.91382	185.4284	16.37240
53.96550	184.4014	16.38025
54.01716	183.3742	16.38788
54.06716	182.3810	16.39518
54.12050	181.3185	16.40304
54.17050	180.3256	16.41094
54.22217	179.2992	16.41884
54.27383	178.2718	16.42730
54.32383	177.2787	16.43524
54.37550	176.2514	16.44459
54.42717	175.2244	16.45500
54.47717	174.2304	16.46505
54.53050	173.1701	16.47473
54.58050	172.1756	16.48275
54.63217	171.1483	16.49108
54.68383	170.1206	16.49930
54.73383	169.1260	16.50922
54.78550	168.0992	16.52161
54.83716	167.0726	16.54987
54.88716	166.0812	16.65121
54.94050	165.0260	16.90181
54.99050	164.0428	17.25391
55.04217	163.0382	17.88014
55.09384	162.0547	18.99658
55.14384	161.1316	20.75208
55.19550	160.2196	23.40095
55.24717	159.3588	26.79698
55.29717	158.5648	30.42062
55.35050	157.7376	34.08344
55.40050	156.9515	36.85601
55.45216	156.1054	38.78331
55.50383	155.2068	39.70773
55.55383	154.2808	39.72463
55.60550	153.2699	39.19934
55.65717	152.2133	37.78980
55.70717	151.1562	36.30701
55.76050	150.0049	34.61990
55.81050	148.9153	33.02597
55.86217	147.7860	31.47363
55.91382	146.6594	30.04036
55.96382	145.5728	28.75843
56.01716	144.4214	27.53130
56.06716	143.3494	26.48389
56.11716	142.2836	25.52970
56.17050	141.1539	24.60939
56.22050	140.1020	23.86272
56.27217	139.0194	23.14450
56.32383	137.9426	22.50196
56.37383	136.9064	21.95470
56.42717	135.8056	21.43303
56.47717	134.7770	21.00158
56.52717	133.7512	20.59775
56.58050	132.6602	20.22387
56.63050	131.6403	19.91578
56.68217	130.5899	19.61077
56.73383	129.5424	19.36268
56.78383	128.5298	19.15209
56.83716	127.4524	18.95373
56.88716	126.4440	18.77254
56.93716	125.4362	18.63184
56.99050	124.3639	18.48806
57.04050	123.3599	18.37406
57.09217	122.3230	18.26541
57.14384	121.2870	18.17578
57.19384	120.2857	18.08558
57.24717	119.2172	18.01361
57.29717	118.2175	17.94488
57.34716	117.2167	17.89537
57.40050	116.1508	17.84046
57.45050	115.1526	17.79528
57.50217	114.1210	17.74733
57.55383	113.0893	17.70785
57.60383	112.0905	17.65046
57.65717	111.0244	17.56894
57.70717	110.0217	17.38581
57.75717	109.0197	17.30992
57.81050	107.9538	17.27913
57.86050	106.9508	17.06184
57.91216	105.9142	16.96544
57.96382	104.8785	16.88164
58.01382	103.8766	16.80264
58.06716	102.8080	16.73735
58.11716	101.8086	16.67003
58.16716	100.8083	16.61622
58.22050	99.74353	16.56161
58.27050	98.74415	16.50630
58.32217	97.71195	16.45395
58.37383	96.67901	16.39552
58.42383	95.67986	16.34054
58.47717	94.61420	16.28093
58.52717	93.61457	16.22653
58.57883	92.58159	16.16992
58.63050	91.54972	16.11112
58.68050	90.55008	16.04792
58.73217	89.51715	15.95367
58.78383	88.48382	15.86328
58.83383	87.48299	15.80276
58.88716	86.41616	15.73364
58.93716	85.41624	15.67066
58.98882	84.38345	15.61145
59.04050	83.34968	15.55972
59.09050	82.35089	15.50672
59.14216	81.31816	15.44284
59.19384	80.28554	15.39448
59.24382	79.28574	15.33295
59.29717	78.21794	15.27325
59.34716	77.21907	15.21922
59.39883	76.18598	15.16420
59.45050	75.15434	15.11110
59.50050	74.15512	15.05845
59.55217	73.12340	15.00923
59.60383	72.09106	14.95412
59.65383	71.09172	14.90747
59.70717	70.02592	14.85768
59.75717	69.02664	14.79881
59.80883	67.99400	14.74127
59.86050	66.96116	14.68662
59.91050	65.96276	14.63664
59.96216	64.93047	14.58632
60.01382	63.89854	14.52472
60.06382	62.89978	14.47670
60.11716	61.83306	14.41471
60.16716	60.83416	14.36234
60.21884	59.80238	14.31048
60.27050	58.77012	14.25550
60.32050	57.77063	14.20341
60.37217	56.73894	14.15166
60.42383	55.70699	14.09674
60.47382	54.70625	14.04469
60.52717	53.64019	13.98475
60.57717	52.64112	13.92313
60.62883	51.60718	13.86846
60.68050	50.57333	13.80569
60.73050	49.57480	13.75820
60.78383	48.50980	13.69820
60.83383	47.50926	13.64264
60.88383	46.51032	13.59304
60.93716	45.44398	13.54323
60.98717	44.44421	13.48831
61.03882	43.41128	13.42959
61.09050	42.37784	13.36761
61.14050	41.37639	13.30472
61.19384	40.30972	13.23386
61.24382	39.30888	13.17988
61.29382	38.30772	13.09907
61.34716	37.23976	13.01834
61.39717	36.23904	12.95055
61.44883	35.20437	12.88368
61.50050	34.16924	12.80154
61.55050	33.16790	12.73431
61.60383	32.10048	12.64839
61.65383	31.09841	12.58187
61.70383	30.09562	12.50359
61.75717	29.02770	12.42774
61.80717	28.02500	12.33733
61.85883	26.99027	12.25741
61.91050	25.95513	12.18184
61.96050	24.95249	12.14496
62.01050	23.95212	12.14975
62.06050	23.04067	12.70604
62.11217	22.61825	7.962988
62.16382	22.59726	2.682295
62.21382	22.85469	-1.327814
62.26716	23.34264	-4.343292
62.31716	23.94366	-6.376648
62.36716	24.64461	-7.836506
62.42050	25.47197	-8.974114
62.47050	26.29945	-9.755637
62.52217	27.19414	-10.35516
62.57383	28.11694	-10.81238
62.62383	29.03045	-11.15005
62.67717	30.02086	-11.42526
62.72717	30.96090	-11.63902
62.77883	31.93965	-11.82069
62.83050	32.92566	-11.96301
62.88050	33.88572	-12.08640
62.93217	34.88007	-12.19711
62.98383	35.87938	-12.29966
63.03383	36.84970	-12.39267
63.08716	37.88728	-12.47523
63.13716	38.86200	-12.55230
63.18882	39.87133	-12.62134
63.24050	40.88164	-12.69022
63.29050	41.86424	-12.75133
63.34217	42.87836	-12.81047
63.39384	43.89338	-12.86970
63.44384	44.87790	-12.92426
63.49717	45.92774	-12.98673
63.54717	46.91296	-13.04575
63.59882	47.93078	-13.11392
63.65050	48.95112	-13.18239
63.70050	49.93844	-13.24545
63.75217	50.95870	-13.31340
63.80383	51.97930	-13.37710
63.85383	52.96888	-13.44290
63.90718	54.02522	-13.50616
63.95717	55.01456	-13.56738
64.00884	56.03879	-13.63268
64.06050	57.06230	-13.69375
64.11050	58.05395	-13.76385
64.16217	59.07666	-13.83122
64.21384	60.10160	-13.90984
64.26384	61.09210	-13.97810
64.31717	62.15088	-14.06012
64.36718	63.14295	-14.13010
64.41884	64.16870	-14.20155
64.47050	65.19476	-14.26085
64.52050	66.18859	-14.33495
64.57218	67.21478	-14.40949
64.62383	68.24036	-14.48088
64.67383	69.23402	-14.55484
64.72718	70.29390	-14.63064
64.77717	71.28759	-14.71041
64.82885	72.31406	-14.78412
64.88050	73.34094	-14.85979
64.93050	74.33470	-14.93626
64.98383	75.39493	-15.01388
65.03384	76.38868	-15.09164
65.08384	77.38196	-15.17169
65.13717	78.44151	-15.25710
65.18717	79.43535	-15.35362
65.23882	80.46034	-15.43642
65.29050	81.48768	-15.52768
65.34050	82.48132	-15.61106
65.39384	83.54110	-15.70261
65.44384	84.53424	-15.79710
65.49384	85.52957	-15.88418
65.54718	86.58970	-15.98044
65.59718	87.58540	-16.06451
65.64884	88.61228	-16.14892
65.70050	89.63982	-16.25754
65.75050	90.63384	-16.33990
65.80384	91.69518	-16.44036
65.85384	92.68918	-16.52544
65.90384	93.68282	-16.62576
65.95718	94.74274	-16.72663
66.00718	95.73584	-16.83012
66.05884	96.76313	-16.92024
66.11050	97.79064	-17.02534
66.16050	98.78509	-17.11810
66.21384	99.84551	-17.21665
66.26384	100.8409	-17.31056
66.31384	101.8358	-17.41420
66.36718	102.8965	-17.50638
66.41718	103.8893	-17.60002
66.46884	104.9174	-17.71424
66.52050	105.9438	-17.81746
66.57050	106.9386	-17.92531
66.62384	107.9990	-18.02452
66.67384	108.9934	-18.12920
66.72384	109.9874	-18.23041
66.77718	111.0480	-18.35147
66.82718	112.0422	-18.45678
66.87884	113.0687	-18.56328
66.93050	114.0949	-18.67841
66.98050	115.0890	-18.79221
67.03384	116.1477	-18.91086
67.08384	117.1411	-19.01544
67.13384	118.1336	-19.13981
67.18718	119.1932	-19.26054
67.23718	120.1864	-19.38955
67.28882	121.2114	-19.52201
67.34050	122.2380	-19.65325
67.39050	123.2302	-19.77970
67.44384	124.2887	-19.91541
67.49384	125.2827	-19.98802
67.54550	126.3111	-20.08661
67.59718	127.3394	-20.15574
67.64718	128.3345	-20.21406
67.69884	129.3696	-20.20772
67.75050	130.4026	-20.20504
67.80050	131.4026	-20.22104
67.85384	132.4656	-20.32794
67.90384	133.4614	-20.43330
67.95550	134.4898	-20.55478
68.00718	135.5180	-20.64906
68.05718	136.5123	-20.74325
68.10884	137.5399	-20.87112
68.16050	138.5698	-20.90152
68.21050	139.5640	-21.06427
68.26384	140.6235	-21.17282
68.31384	141.6185	-21.21538
68.36550	142.6483	-21.27328
68.41718	143.6776	-21.33902
68.46718	144.6736	-21.42696
68.51882	145.7020	-21.51680
68.57050	146.7302	-21.62392
68.62050	147.7254	-21.71831
68.67384	148.7870	-21.80681
68.72384	149.7809	-21.90306
68.77550	150.8098	-22.00145
68.82718	151.8385	-22.09030
68.87718	152.8328	-22.17661
68.92884	153.8628	-22.26675
68.98050	154.8911	-22.35362
69.03050	155.8860	-22.43419
69.08384	156.9482	-22.51001
69.13384	157.9441	-22.57480
69.18550	158.9754	-22.62726
69.23718	160.0056	-22.66855
69.28718	161.0044	-22.70415
69.33884	162.0374	-22.72530
69.39050	163.0694	-22.75289
69.44050	164.0680	-22.79406
69.49384	165.1324	-22.85593
69.54384	166.1287	-22.94009
69.59550	167.1589	-23.05713
69.64718	168.1875	-23.15978
69.69718	169.1828	-23.27014
69.75050	170.2439	-23.39650
69.80050	171.2373	-23.53602
69.85050	172.2308	-23.67910
69.90384	173.2882	-23.84984
69.95384	174.2797	-24.02706
70.00550	175.3026	-24.22010
70.05718	176.3250	-24.43366
70.10718	177.3122	-24.66125
70.16050	178.3653	-24.92086
70.21050	179.3505	-25.19053
70.26050	180.3362	-25.49221
70.31384	181.3834	-25.84021
70.36384	182.3646	-26.20715
70.41550	183.3752	-26.60774
70.46718	184.3859	-27.06304
70.51716	185.3602	-27.54294
70.57050	186.3953	-28.08498
70.62050	187.3652	-28.65062
70.67050	188.3329	-29.24475
70.72384	189.3619	-29.92230
70.77384	190.3253	-30.55975
70.82550	191.3186	-31.24154
70.87718	192.3112	-31.94860
70.92718	193.2695	-32.66880
70.98050	194.2912	-33.48664
71.03050	195.2455	-34.31350
71.08050	196.1964	-35.21295
71.13384	197.2076	-36.23730
71.18384	198.1515	-37.26251
71.23550	199.1233	-38.32300
71.28718	200.0937	-39.36132
71.33716	201.0347	-40.27566
71.39050	202.0455	-41.01967
71.44050	203.0059	-41.31949
71.49050	203.9878	-41.04809
71.54384	205.0757	-39.62567
71.59384	206.1489	-37.08780
71.64550	207.3250	-33.34531
71.69718	208.5463	-29.84986
71.74718	209.7177	-27.79339
71.80050	210.9241	-26.49698
71.85050	212.0182	-25.67758
71.90050	213.0870	-25.11469
71.95384	214.2038	-24.68711
72.00384	215.2374	-24.41193
72.05550	216.2948	-24.22014
72.10718	217.3455	-24.10845
72.15718	218.3562	-24.02306
72.21050	219.4304	-23.97974
72.26050	220.4365	-23.96896
72.31216	221.4722	-23.96106
72.36384	222.5090	-23.95930
72.41382	223.5098	-23.95920
72.46550	224.5446	-23.96024
72.51716	225.5786	-23.96254
72.56718	226.5769	-23.97276
72.62050	227.6427	-23.99011
72.67050	228.6411	-24.02390
72.72218	229.6733	-24.06358
72.77384	230.7044	-24.11345
72.82384	231.7018	-24.15994
72.87550	232.7341	-24.21833
72.92718	233.7650	-24.26652
72.97718	234.7636	-24.31553
73.03050	235.8290	-24.35862
73.08050	236.8268	-24.38872
73.13218	237.8580	-24.43154
73.18384	238.8894	-24.47844
73.23384	239.8873	-24.52864
73.28550	240.9178	-24.58251
73.33716	241.9486	-24.64180
73.38718	242.9467	-24.68923
73.44050	244.0102	-24.74650
73.49050	245.0086	-24.78978
73.54218	246.0400	-24.83259
73.59384	247.0717	-24.87189
73.64384	248.0696	-24.90766
73.69550	249.1010	-24.95351
73.74718	250.1320	-24.99578
73.79718	251.1302	-25.03785
73.85050	252.1946	-25.08774
73.90050	253.1916	-25.12784
73.95216	254.2234	-25.17730
74.00384	255.2537	-25.22073
74.05384	256.2516	-25.28726
74.10550	257.2822	-25.33976
74.15718	258.3127	-25.39506
74.20718	259.3108	-25.44652
74.26050	260.3750	-25.49913
74.31050	261.3711	-25.55372
74.36218	262.4018	-25.62696
74.41382	263.4320	-25.68194
74.46384	264.4284	-25.73926
74.51716	265.4931	-25.79638
74.56718	266.4908	-25.84445
74.61718	267.4882	-25.89430
74.67050	268.5508	-25.95736
74.72050	269.5492	-26.00879
74.77218	270.5794	-26.05665
74.82384	271.6092	-26.10782
-2.000000	5.000000	0.0000000