File: 5-C1(1.4mol%)+C20(0.6mol%)/matlab/160-1.txt
CLOSED
Version	1.0
Language	English
Mode	Standard
Run	22
RunSerial	12324
Instrument	DSC Q2000 V24.11 Build 124
Module	DSC Standard Cell RC
Operator
File	\\AE520-1454\Users\dsc\Desktop\Data\31-08-17-2\160-1.001
ProcName
InstSerial	2000-0883
AutoSerial	1293
Sample	160-1
Size	18.1000	mg
PanMass	Not available
PanResist	Automatic Automatic  K/W
PanFactor	Default Default
Method
Comment
Xcomment	Pan: Tzero Aluminum Hermetic
Xcomment	Gas1: Nitrogen 50.0 ml/min
Xcomment	Gas2: Nitrogen 50.0 ml/min
Text
Exotherm	UP
Kcell	1.05230
Cpconst	Standard: 0.938
Calib	-38.6961
TempCal	1	pts	157.46	156.60
TzeroDt	-87.6168 -0.0009 -1.4231
TzeroDtz	-87.6168 0.0057 6.9570
InstCalFile	Tzero: \\Ae520-1454\ta\Data\DSC\Calibration\2017\CALIBRATION\1562_RCS (90)_05_18_2017 10_50_44.TZR
InstCalFile	Baseline: \\Ae520-1454\ta\Data\DSC\Calibration\2017\2017-05-17_Calibration.001
InstCalFile	Sapphire: \\Ae520-1454\ta\Data\DSC\Calibration\2017\2017-05-17_Saphire.001
InstCalDate	Tzero 2017-05-18 Time 10:50:44
TempRange	-87.39 to 398.39 °C at 10.00 °C/min Heat Only
AutoZero	Delta T Offset 0.000 uV
AutoZero	Delta T0 Offset 0.000 uV
MultiptCal	0
MultiPtDesc	0) Not set
AutoCellConst	Calibration Date 2017-05-18 16:59:28
Controls	Gas 1  Event Off  Sampling 0.2
Cell#	RC-01562
CoolingUnit	RCS (90)
SelHeatFlow	Heat Flow T4P (mW)
AutoLidII	Installed
AutoAnalysis	Off
MacroFile
Nsig	3
Sig1	Time (min)
Sig2	Temperature (°C)
Sig3	Heat Flow (mW)
Date	2017-09-01
Time	14:23:23
OrgMethod	1: Equilibrate at 80.00 °C
OrgMethod	2: Isothermal for 3.00 min
OrgMethod	3: Jump to 160.00 °C
OrgMethod	4: Mark end of cycle 1
OrgMethod	5: Isothermal for 40.00 min
OrgMethod	6: Mark end of cycle 2
OrgMethod	7: Ramp 20.00 °C/min to 280.00 °C
OrgMethod	8: Mark end of cycle 3
OrgMethod	9: Ramp 20.00 °C/min to 20.00 °C
OrgMethod	10: Mark end of cycle 4
OrgMethod	11: Ramp 20.00 °C/min to 280.00 °C
OrgMethod	12: Mark end of cycle 5
OrgFile	C:\Users\jarra\Desktop\DSC\5-C1(1.4mol%)+C20(0.6mol%)\160-1.001
StartOfData
4.99994E-4	79.86437	-1.319217
0.05383332	79.87915	-1.094229
0.1038333	79.88828	-0.9448540
0.1555000	79.89431	-0.8294620
0.2071666	79.89782	-0.7527078
0.2571667	79.90125	-0.6986028
0.3105000	79.90180	-0.6601176
0.3605000	79.90311	-0.6368450
0.4121666	79.90318	-0.6215338
0.4638333	79.90311	-0.6120222
0.5138333	79.90311	-0.6078326
0.5655000	79.90196	-0.6048894
0.6171668	79.90089	-0.6021564
0.6671668	79.89970	-0.5995625
0.7205000	79.89890	-0.5968847
0.7705000	79.89844	-0.5945613
0.8221666	79.89798	-0.5923606
0.8738332	79.89672	-0.5902691
0.9238334	79.89514	-0.5884690
0.9755000	79.89556	-0.5867990
1.027167	79.89310	-0.5853020
1.077166	79.89261	-0.5840318
1.130500	79.89208	-0.5828793
1.180500	79.89199	-0.5820061
1.232166	79.89112	-0.5811280
1.283834	79.89040	-0.5804836
1.333833	79.88919	-0.5799070
1.385500	79.88853	-0.5794990
1.437167	79.88695	-0.5791924
1.487166	79.88745	-0.5790310
1.540500	79.88696	-0.5788820
1.590500	79.88560	-0.5788422
1.642166	79.88530	-0.5789140
1.693833	79.88461	-0.5791572
1.743833	79.88405	-0.5794048
1.795500	79.88355	-0.5798313
1.847167	79.88281	-0.5802832
1.897167	79.88316	-0.5808046
1.950500	79.88235	-0.5813579
2.000500	79.88179	-0.5819422
2.052166	79.88160	-0.5825818
2.103833	79.88128	-0.5832031
2.153833	79.88025	-0.5839149
2.205500	79.88012	-0.5846918
2.257167	79.87910	-0.5855064
2.307167	79.87861	-0.5863257
2.360500	79.87875	-0.5871818
2.410500	79.87761	-0.5880559
2.462167	79.87774	-0.5889690
2.513833	79.87708	-0.5898446
2.563833	79.87639	-0.5906556
2.617167	79.87686	-0.5915175
2.667167	79.87616	-0.5922671
2.717167	79.87468	-0.5931340
2.770500	79.87462	-0.5940674
2.820500	79.87366	-0.5949552
2.872167	79.87421	-0.5957980
2.923834	79.87352	-0.5966936
2.973833	79.87294	-0.5975764
3.020500	79.90151	-0.9779351
3.073833	81.02075	-12.18424
3.123834	83.34024	-23.31582
3.175500	86.30195	-33.50303
3.227167	89.72519	-42.42814
3.277167	93.36380	-49.67403
3.328833	97.37274	-55.82360
3.380500	101.5634	-60.75426
3.430500	105.7391	-64.59962
3.483833	110.2848	-67.87012
3.533833	114.6034	-70.28810
3.585500	119.1000	-72.37195
3.637167	123.6166	-74.12116
3.687167	127.9981	-75.44512
3.738834	132.5337	-76.44598
3.790500	137.0731	-77.17280
3.840500	141.4609	-77.61328
3.893833	145.9461	-75.33420
3.943833	148.9783	-64.68443
3.995500	151.2164	-53.62024
4.047167	152.9194	-43.34452
4.097166	154.1782	-34.79399
4.150500	155.2174	-27.26928
4.200500	155.9741	-21.60030
4.250500	156.5766	-17.09443
4.303834	157.0885	-13.35016
4.353833	157.4748	-10.63451
4.405500	157.8000	-8.459897
4.457167	158.0679	-6.785058
4.507167	158.2849	-5.530120
4.560500	158.4785	-4.493784
4.610500	158.6310	-3.730158
4.660500	158.7635	-3.128895
4.713834	158.8839	-2.619585
4.763834	158.9835	-2.233509
4.815500	159.0721	-1.898629
4.867166	159.1506	-1.625102
4.917167	159.2174	-1.394334
4.970500	159.2805	-1.176051
5.020500	159.3349	-1.001614
5.070500	159.3818	-0.8293997
5.123833	159.4285	-0.6630328
5.173834	159.4667	-0.5113075
5.225500	159.5051	-0.3571233
5.277168	159.5390	-0.2033520
5.327168	159.5700	-.05484113
5.380500	159.6016	0.1047169
5.430500	159.6281	0.2627921
5.480500	159.6535	0.4226122
5.533832	159.6810	0.5986022
5.583832	159.7042	0.7744275
5.635500	159.7281	0.9597453
5.687168	159.7507	1.156486
5.737168	159.7722	1.353068
5.790500	159.7959	1.570404
5.840500	159.8161	1.787994
5.890500	159.8386	2.010972
5.943832	159.8605	2.257618
5.993834	159.8820	2.501943
6.045500	159.9050	2.764408
6.097168	159.9266	3.039242
6.147168	159.9497	3.313792
6.200500	159.9729	3.620600
6.250500	159.9951	3.915378
6.300500	160.0182	4.218111
6.353832	160.0439	4.546635
6.403832	160.0674	4.864620
6.455500	160.0912	5.198876
6.507168	160.1163	5.531304
6.557166	160.1395	5.853355
6.610500	160.1635	6.188542
6.660500	160.1853	6.495971
6.712168	160.2073	6.796990
6.763834	160.2281	7.079360
6.813834	160.2470	7.335924
6.865500	160.2637	7.562821
6.917168	160.2793	7.763553
6.967168	160.2927	7.929500
7.020500	160.3030	8.080185
7.070500	160.3138	8.194269
7.122168	160.3215	8.303649
7.173834	160.3301	8.409226
7.223834	160.3384	8.527116
7.275500	160.3493	8.679078
7.327168	160.3621	8.879082
7.377168	160.3773	9.124328
7.430500	160.3984	9.454224
7.480500	160.4221	9.815462
7.532166	160.4500	10.24126
7.583832	160.4801	10.70674
7.633832	160.5110	11.17514
7.685500	160.5433	11.64983
7.737168	160.5731	12.09535
7.787168	160.5994	12.47383
7.840500	160.6231	12.80897
7.890500	160.6398	13.04056
7.942168	160.6524	13.19950
7.993834	160.6592	13.27624
8.043834	160.6620	13.29094
8.095500	160.6601	13.27854
8.147168	160.6544	13.24216
8.197168	160.6472	13.06148
8.250500	160.6376	12.86680
8.300500	160.6268	12.69458
8.352168	160.6159	12.51019
8.403832	160.6056	12.33023
8.453834	160.5947	12.16441
8.505500	160.5832	11.99266
8.557168	160.5727	11.83128
8.607166	160.5638	11.67746
8.660499	160.5526	11.52302
8.710499	160.5437	11.38630
8.762168	160.5358	11.24662
8.813834	160.5267	11.11442
8.863834	160.5184	10.98935
8.917168	160.5116	10.86567
8.967168	160.5036	10.75240
9.017168	160.4966	10.64637
9.070500	160.4892	10.53879
9.120499	160.4830	10.43954
9.172168	160.4771	10.34756
9.223832	160.4718	10.25926
9.273834	160.4662	10.17860
9.327168	160.4610	10.09830
9.377168	160.4554	10.03049
9.427168	160.4526	9.963350
9.480500	160.4489	9.900925
9.530500	160.4460	9.846650
9.582168	160.4417	9.790014
9.633832	160.4383	9.736239
9.683832	160.4347	9.686329
9.737168	160.4320	9.634769
9.787168	160.4285	9.587841
9.837168	160.4263	9.543042
9.890500	160.4227	9.498894
9.940500	160.4200	9.458496
9.992166	160.4170	9.417626
10.04383	160.4152	9.378539
10.09383	160.4129	9.342419
10.14717	160.4104	9.300493
10.19717	160.4084	9.260278
10.24717	160.4054	9.221791
10.30050	160.4033	9.178246
10.35050	160.4008	9.138172
10.40217	160.3984	9.096559
10.45383	160.3957	9.055312
10.50384	160.3932	9.019976
10.55717	160.3904	8.985338
10.60717	160.3894	8.958124
10.65717	160.3879	8.934778
10.71050	160.3864	8.916119
10.76050	160.3857	8.900766
10.81216	160.3850	8.889496
10.86383	160.3844	8.882749
10.91383	160.3843	8.878238
10.96717	160.3847	8.873859
11.01717	160.3844	8.870358
11.06716	160.3850	8.867657
11.12050	160.3859	8.865601
11.17050	160.3859	8.864112
11.22217	160.3857	8.862381
11.27383	160.3839	8.858828
11.32383	160.3818	8.832569
11.37717	160.3760	8.732975
11.42717	160.3691	8.576795
11.47884	160.3590	8.392460
11.53050	160.3458	8.173801
11.58050	160.3302	7.921837
11.63216	160.3118	7.626157
11.68383	160.2908	7.291894
11.73383	160.2667	6.935066
11.78717	160.2412	6.527843
11.83717	160.2157	6.125400
11.88883	160.1874	5.694409
11.94050	160.1586	5.252743
11.99050	160.1311	4.819908
12.04217	160.1017	4.373798
12.09383	160.0732	3.934826
12.14383	160.0462	3.520354
12.19717	160.0187	3.111227
12.24717	159.9941	2.728788
12.29884	159.9689	2.351232
12.35050	159.9459	1.994811
12.40050	159.9242	1.674576
12.45217	159.9037	1.368567
12.50384	159.8844	1.079804
12.55383	159.8668	0.8205466
12.60717	159.8499	0.5614880
12.65717	159.8354	0.3416559
12.70883	159.8206	0.1318843
12.76050	159.8083	-.06318611
12.81050	159.7962	-0.2298720
12.86217	159.7858	-0.3914444
12.91383	159.7756	-0.5341965
12.96383	159.7677	-0.6591918
13.01717	159.7591	-0.7780210
13.06716	159.7532	-0.8792006
13.11884	159.7461	-0.9705132
13.17050	159.7411	-1.054838
13.22050	159.7367	-1.125098
13.27217	159.7316	-1.190525
13.32384	159.7275	-1.247601
13.37384	159.7247	-1.299701
13.42717	159.7209	-1.347459
13.47717	159.7178	-1.388701
13.52883	159.7153	-1.425020
13.58050	159.7129	-1.459544
13.63050	159.7101	-1.488856
13.68383	159.7080	-1.517944
13.73383	159.7061	-1.542573
13.78383	159.7053	-1.564339
13.83717	159.7029	-1.587684
13.88717	159.7008	-1.606711
13.93883	159.6998	-1.625545
13.99050	159.6988	-1.643326
14.04050	159.6986	-1.658439
14.09383	159.6977	-1.672266
14.14383	159.6964	-1.683626
14.19384	159.6956	-1.694499
14.24717	159.6947	-1.704378
14.29717	159.6938	-1.712608
14.34883	159.6923	-1.721177
14.40050	159.6923	-1.728646
14.45050	159.6916	-1.735962
14.50383	159.6902	-1.743431
14.55383	159.6895	-1.750635
14.60383	159.6880	-1.757916
14.65717	159.6885	-1.765812
14.70717	159.6868	-1.773318
14.75883	159.6868	-1.781152
14.81050	159.6859	-1.788934
14.86050	159.6862	-1.796569
14.91383	159.6842	-1.804597
14.96383	159.6844	-1.812222
15.01383	159.6831	-1.819814
15.06716	159.6837	-1.827882
15.11716	159.6837	-1.835326
15.16883	159.6831	-1.842941
15.22050	159.6844	-1.850572
15.27050	159.6832	-1.857797
15.32384	159.6821	-1.865492
15.37384	159.6817	-1.872536
15.42383	159.6816	-1.879506
15.47717	159.6822	-1.886806
15.52717	159.6819	-1.893624
15.57883	159.6818	-1.900503
15.63050	159.6820	-1.907295
15.68050	159.6813	-1.913798
15.73383	159.6814	-1.920557
15.78383	159.6798	-1.926691
15.83383	159.6804	-1.932651
15.88716	159.6798	-1.938814
15.93717	159.6793	-1.944455
15.98883	159.6790	-1.950100
16.04050	159.6787	-1.955608
16.09050	159.6784	-1.960778
16.14383	159.6780	-1.966226
16.19383	159.6774	-1.971217
16.24550	159.6765	-1.976264
16.29716	159.6772	-1.981306
16.34717	159.6764	-1.986011
16.39883	159.6766	-1.990801
16.45050	159.6766	-1.995451
16.50050	159.6767	-1.999897
16.55383	159.6766	-2.004516
16.60383	159.6761	-2.008666
16.65550	159.6764	-2.012927
16.70716	159.6754	-2.017023
16.75716	159.6756	-2.020851
16.80883	159.6755	-2.024818
16.86050	159.6757	-2.028674
16.91050	159.6750	-2.032404
16.96383	159.6758	-2.036278
17.01383	159.6754	-2.039862
17.06550	159.6754	-2.043384
17.11716	159.6754	-2.046835
17.16716	159.6755	-2.050039
17.21883	159.6755	-2.053311
17.27050	159.6751	-2.056417
17.32050	159.6756	-2.059364
17.37383	159.6758	-2.062404
17.42383	159.6749	-2.065248
17.47550	159.6755	-2.068144
17.52716	159.6751	-2.071029
17.57716	159.6758	-2.073762
17.62883	159.6755	-2.076428
17.68050	159.6763	-2.079158
17.73050	159.6758	-2.081691
17.78383	159.6753	-2.084233
17.83383	159.6750	-2.086591
17.88550	159.6751	-2.088957
17.93716	159.6751	-2.091205
17.98716	159.6756	-2.093280
18.03883	159.6745	-2.095312
18.09050	159.6744	-2.097316
18.14050	159.6742	-2.099168
18.19383	159.6737	-2.101091
18.24383	159.6736	-2.102858
18.29550	159.6734	-2.104666
18.34716	159.6736	-2.106537
18.39716	159.6734	-2.108266
18.45050	159.6734	-2.110172
18.50050	159.6736	-2.111953
18.55050	159.6728	-2.113650
18.60383	159.6731	-2.115501
18.65383	159.6744	-2.117235
18.70550	159.6738	-2.118942
18.75716	159.6734	-2.120607
18.80716	159.6734	-2.122133
18.86050	159.6732	-2.123728
18.91050	159.6737	-2.125218
18.96050	159.6727	-2.126562
19.01383	159.6729	-2.128014
19.06383	159.6730	-2.129415
19.11550	159.6728	-2.130920
19.16716	159.6744	-2.132436
19.21716	159.6732	-2.133847
19.27050	159.6734	-2.135357
19.32050	159.6742	-2.136751
19.37050	159.6733	-2.138022
19.42383	159.6736	-2.139382
19.47383	159.6730	-2.140520
19.52550	159.6738	-2.141724
19.57716	159.6732	-2.142839
19.62716	159.6730	-2.143774
19.68050	159.6723	-2.144735
19.73050	159.6733	-2.145600
19.78050	159.6729	-2.146412
19.83383	159.6718	-2.147336
19.88383	159.6727	-2.148285
19.93550	159.6734	-2.149382
19.98716	159.6731	-2.150453
20.03717	159.6730	-2.151556
20.09050	159.6741	-2.152702
20.14050	159.6736	-2.153758
20.19050	159.6734	-2.154803
20.24383	159.6737	-2.155796
20.29383	159.6739	-2.156643
20.34550	159.6730	-2.157505
20.39716	159.6738	-2.158424
20.44716	159.6731	-2.159204
20.50050	159.6727	-2.160048
20.55050	159.6733	-2.160826
20.60050	159.6732	-2.161600
20.65383	159.6730	-2.162373
20.70383	159.6732	-2.163047
20.75550	159.6733	-2.163785
20.80716	159.6727	-2.164443
20.85716	159.6731	-2.165083
20.91050	159.6724	-2.165758
20.96050	159.6722	-2.166317
21.01216	159.6723	-2.166854
21.06383	159.6720	-2.167390
21.11383	159.6719	-2.167865
21.16550	159.6715	-2.168358
21.21716	159.6715	-2.168772
21.26716	159.6719	-2.169172
21.32050	159.6708	-2.169541
21.37050	159.6706	-2.169946
21.42216	159.6704	-2.170371
21.47383	159.6706	-2.170938
21.52383	159.6713	-2.171518
21.57550	159.6714	-2.172264
21.62716	159.6720	-2.173031
21.67717	159.6715	-2.173820
21.73050	159.6725	-2.174585
21.78050	159.6719	-2.175293
21.83216	159.6720	-2.175953
21.88383	159.6714	-2.176512
21.93383	159.6716	-2.177070
21.98550	159.6716	-2.177659
22.03717	159.6720	-2.178281
22.08716	159.6727	-2.178842
22.14050	159.6718	-2.179418
22.19050	159.6715	-2.179964
22.24216	159.6719	-2.180650
22.29383	159.6718	-2.181260
22.34383	159.6728	-2.181900
22.39550	159.6726	-2.182504
22.44716	159.6728	-2.183111
22.49716	159.6725	-2.183658
22.55050	159.6728	-2.184193
22.60050	159.6730	-2.184697
22.65216	159.6714	-2.185070
22.70383	159.6714	-2.185512
22.75383	159.6719	-2.185925
22.80550	159.6717	-2.186208
22.85716	159.6703	-2.186411
22.90716	159.6704	-2.186652
22.96050	159.6704	-2.186913
23.01050	159.6712	-2.187154
23.06216	159.6714	-2.187402
23.11383	159.6709	-2.187674
23.16383	159.6708	-2.188035
23.21716	159.6708	-2.188448
23.26716	159.6708	-2.188892
23.31716	159.6706	-2.189407
23.37050	159.6716	-2.189949
23.42050	159.6717	-2.190404
23.47216	159.6713	-2.190881
23.52383	159.6715	-2.191363
23.57383	159.6710	-2.191722
23.62716	159.6722	-2.192012
23.67717	159.6711	-2.192139
23.72716	159.6708	-2.192274
23.78050	159.6709	-2.192394
23.83050	159.6701	-2.192480
23.88216	159.6700	-2.192522
23.93383	159.6699	-2.192668
23.98383	159.6708	-2.192936
24.03717	159.6703	-2.193227
24.08716	159.6708	-2.193471
24.13716	159.6704	-2.193772
24.19050	159.6708	-2.194051
24.24050	159.6700	-2.194281
24.29216	159.6703	-2.194545
24.34383	159.6703	-2.194674
24.39383	159.6699	-2.194850
24.44716	159.6701	-2.195010
24.49716	159.6692	-2.195129
24.54716	159.6708	-2.195386
24.60050	159.6704	-2.195722
24.65050	159.6712	-2.196058
24.70216	159.6710	-2.196456
24.75383	159.6709	-2.196892
24.80383	159.6722	-2.197358
24.85716	159.6718	-2.197794
24.90716	159.6722	-2.198203
24.95717	159.6721	-2.198544
25.01050	159.6725	-2.198930
25.06050	159.6724	-2.199231
25.11216	159.6728	-2.199558
25.16383	159.6722	-2.199856
25.21383	159.6724	-2.200133
25.26716	159.6723	-2.200484
25.31716	159.6724	-2.200779
25.36716	159.6725	-2.201020
25.42050	159.6718	-2.201246
25.47050	159.6722	-2.201424
25.52216	159.6719	-2.201586
25.57383	159.6714	-2.201658
25.62383	159.6712	-2.201726
25.67717	159.6711	-2.201773
25.72717	159.6712	-2.201845
25.77883	159.6706	-2.201778
25.83050	159.6704	-2.201880
25.88050	159.6708	-2.202065
25.93216	159.6712	-2.202277
25.98383	159.6708	-2.202490
26.03383	159.6702	-2.202662
26.08716	159.6716	-2.202866
26.13716	159.6705	-2.203000
26.18883	159.6709	-2.203262
26.24050	159.6709	-2.203594
26.29050	159.6711	-2.203920
26.34216	159.6716	-2.204275
26.39383	159.6712	-2.204594
26.44383	159.6719	-2.204838
26.49716	159.6718	-2.205061
26.54716	159.6713	-2.205236
26.59883	159.6715	-2.205390
26.65050	159.6712	-2.205600
26.70050	159.6718	-2.205818
26.75217	159.6710	-2.206060
26.80383	159.6710	-2.206306
26.85383	159.6712	-2.206530
26.90716	159.6707	-2.206630
26.95716	159.6698	-2.206710
27.00883	159.6711	-2.206766
27.06050	159.6703	-2.206774
27.11050	159.6707	-2.206833
27.16217	159.6713	-2.206987
27.21383	159.6700	-2.207077
27.26383	159.6705	-2.207172
27.31716	159.6704	-2.207297
27.36716	159.6713	-2.207427
27.41883	159.6704	-2.207595
27.47050	159.6706	-2.207853
27.52050	159.6708	-2.208115
27.57217	159.6711	-2.208402
27.62383	159.6710	-2.208663
27.67383	159.6708	-2.208825
27.72717	159.6721	-2.209070
27.77717	159.6708	-2.209172
27.82883	159.6710	-2.209304
27.88050	159.6714	-2.209402
27.93050	159.6708	-2.209421
27.98383	159.6706	-2.209423
28.03383	159.6707	-2.209348
28.08383	159.6704	-2.209276
28.13716	159.6706	-2.209244
28.18717	159.6706	-2.209248
28.23883	159.6711	-2.209330
28.29050	159.6706	-2.209470
28.34050	159.6712	-2.209638
28.39383	159.6710	-2.209858
28.44383	159.6718	-2.210146
28.49383	159.6714	-2.210395
28.54716	159.6715	-2.210616
28.59716	159.6717	-2.210820
28.64883	159.6722	-2.210991
28.70050	159.6720	-2.211178
28.75050	159.6716	-2.211343
28.80383	159.6715	-2.211455
28.85383	159.6727	-2.211566
28.90383	159.6726	-2.211692
28.95716	159.6724	-2.211732
29.00716	159.6712	-2.211710
29.05883	159.6722	-2.211703
29.11050	159.6722	-2.211652
29.16050	159.6722	-2.211685
29.21383	159.6714	-2.211659
29.26383	159.6715	-2.211656
29.31383	159.6721	-2.211677
29.36716	159.6710	-2.211746
29.41716	159.6714	-2.211790
29.46883	159.6710	-2.211808
29.52050	159.6711	-2.211793
29.57050	159.6710	-2.211860
29.62383	159.6710	-2.211908
29.67383	159.6714	-2.211974
29.72383	159.6706	-2.212014
29.77717	159.6705	-2.211968
29.82717	159.6702	-2.211946
29.87883	159.6702	-2.211939
29.93050	159.6699	-2.211960
29.98050	159.6700	-2.211977
30.03383	159.6699	-2.212058
30.08383	159.6699	-2.212127
30.13383	159.6699	-2.212234
30.18717	159.6693	-2.212300
30.23716	159.6696	-2.212416
30.28883	159.6705	-2.212548
30.34050	159.6703	-2.212660
30.39050	159.6698	-2.212842
30.44383	159.6702	-2.213081
30.49383	159.6704	-2.213375
30.54550	159.6706	-2.213648
30.59716	159.6707	-2.213940
30.64716	159.6710	-2.214189
30.69883	159.6710	-2.214446
30.75050	159.6702	-2.214729
30.80050	159.6712	-2.215010
30.85383	159.6714	-2.215217
30.90383	159.6700	-2.215369
30.95550	159.6712	-2.215568
31.00716	159.6712	-2.215638
31.05716	159.6710	-2.215812
31.10883	159.6716	-2.215934
31.16050	159.6714	-2.216002
31.21050	159.6717	-2.216035
31.26383	159.6707	-2.216018
31.31383	159.6707	-2.216039
31.36550	159.6711	-2.216123
31.41716	159.6706	-2.216120
31.46716	159.6710	-2.216066
31.51883	159.6706	-2.215967
31.57050	159.6702	-2.215870
31.62050	159.6704	-2.215771
31.67383	159.6702	-2.215613
31.72383	159.6689	-2.215526
31.77550	159.6700	-2.215535
31.82717	159.6701	-2.215612
31.87717	159.6699	-2.215740
31.92883	159.6702	-2.215992
31.98050	159.6699	-2.216232
32.03050	159.6700	-2.216462
32.08383	159.6702	-2.216721
32.13383	159.6707	-2.216916
32.18550	159.6709	-2.217160
32.23717	159.6714	-2.217381
32.28717	159.6710	-2.217532
32.33883	159.6718	-2.217692
32.39050	159.6715	-2.217808
32.44050	159.6716	-2.217895
32.49383	159.6708	-2.218008
32.54383	159.6713	-2.218060
32.59550	159.6711	-2.218123
32.64717	159.6713	-2.218239
32.69717	159.6715	-2.218272
32.75050	159.6709	-2.218235
32.80050	159.6706	-2.218190
32.85050	159.6703	-2.218126
32.90383	159.6708	-2.217997
32.95383	159.6713	-2.217830
33.00550	159.6703	-2.217660
33.05716	159.6704	-2.217586
33.10716	159.6701	-2.217417
33.16050	159.6699	-2.217260
33.21050	159.6693	-2.217137
33.26050	159.6700	-2.217176
33.31383	159.6704	-2.217235
33.36383	159.6698	-2.217367
33.41550	159.6702	-2.217594
33.46716	159.6705	-2.217944
33.51716	159.6706	-2.218237
33.57050	159.6718	-2.218645
33.62050	159.6708	-2.218928
33.67050	159.6711	-2.219127
33.72383	159.6717	-2.219330
33.77383	159.6722	-2.219478
33.82550	159.6710	-2.219498
33.87717	159.6721	-2.219584
33.92717	159.6711	-2.219559
33.98050	159.6711	-2.219519
34.03050	159.6705	-2.219432
34.08050	159.6704	-2.219273
34.13383	159.6702	-2.219150
34.18384	159.6706	-2.218996
34.23550	159.6699	-2.218835
34.28717	159.6694	-2.218710
34.33716	159.6692	-2.218614
34.39050	159.6696	-2.218628
34.44050	159.6696	-2.218682
34.49050	159.6694	-2.218836
34.54383	159.6700	-2.219042
34.59384	159.6710	-2.219308
34.64550	159.6705	-2.219552
34.69717	159.6709	-2.219797
34.74716	159.6702	-2.219934
34.80050	159.6708	-2.220160
34.85050	159.6706	-2.220193
34.90050	159.6708	-2.220224
34.95383	159.6705	-2.220264
35.00383	159.6698	-2.220234
35.05550	159.6707	-2.220178
35.10716	159.6697	-2.220063
35.15716	159.6700	-2.219970
35.21050	159.6694	-2.219865
35.26050	159.6704	-2.219714
35.31216	159.6700	-2.219595
35.36383	159.6701	-2.219516
35.41383	159.6697	-2.219546
35.46550	159.6699	-2.219648
35.51716	159.6701	-2.219767
35.56716	159.6698	-2.219969
35.62050	159.6708	-2.220150
35.67050	159.6704	-2.220264
35.72217	159.6705	-2.220395
35.77383	159.6713	-2.220569
35.82383	159.6706	-2.220699
35.87550	159.6706	-2.220754
35.92717	159.6713	-2.220843
35.97717	159.6710	-2.220949
36.03050	159.6710	-2.220992
36.08050	159.6713	-2.220987
36.13216	159.6708	-2.220984
36.18384	159.6706	-2.221002
36.23383	159.6713	-2.221030
36.28550	159.6706	-2.221050
36.33716	159.6717	-2.221170
36.38716	159.6710	-2.221160
36.44050	159.6716	-2.221166
36.49050	159.6701	-2.221128
36.54217	159.6710	-2.221118
36.59384	159.6708	-2.221062
36.64383	159.6712	-2.220936
36.69550	159.6705	-2.220840
36.74716	159.6698	-2.220774
36.79716	159.6711	-2.220814
36.85050	159.6713	-2.220938
36.90050	159.6701	-2.221040
36.95216	159.6713	-2.221225
37.00383	159.6710	-2.221359
37.05383	159.6714	-2.221418
37.10550	159.6716	-2.221422
37.15716	159.6717	-2.221370
37.20716	159.6704	-2.221354
37.26050	159.6713	-2.221378
37.31050	159.6704	-2.221401
37.36217	159.6709	-2.221454
37.41383	159.6706	-2.221503
37.46383	159.6719	-2.221518
37.51716	159.6704	-2.221531
37.56716	159.6702	-2.221616
37.61716	159.6713	-2.221682
37.67050	159.6709	-2.221690
37.72050	159.6705	-2.221670
37.77217	159.6705	-2.221619
37.82383	159.6703	-2.221558
37.87383	159.6700	-2.221464
37.92717	159.6696	-2.221408
37.97717	159.6688	-2.221384
38.02716	159.6704	-2.221504
38.08050	159.6708	-2.221676
38.13050	159.6707	-2.221850
38.18216	159.6702	-2.222035
38.23383	159.6708	-2.222227
38.28383	159.6708	-2.222404
38.33716	159.6702	-2.222518
38.38716	159.6701	-2.222704
38.43716	159.6708	-2.222854
38.49050	159.6714	-2.222979
38.54050	159.6710	-2.223111
38.59216	159.6711	-2.223219
38.64383	159.6707	-2.223327
38.69383	159.6714	-2.223453
38.74716	159.6708	-2.223475
38.79716	159.6715	-2.223538
38.84716	159.6718	-2.223636
38.90050	159.6718	-2.223774
38.95050	159.6712	-2.223875
39.00217	159.6717	-2.224034
39.05383	159.6722	-2.224145
39.10383	159.6708	-2.224094
39.15716	159.6708	-2.224108
39.20716	159.6709	-2.224062
39.25716	159.6702	-2.223963
39.31050	159.6711	-2.223904
39.36050	159.6702	-2.223838
39.41217	159.6705	-2.223820
39.46383	159.6703	-2.223794
39.51383	159.6698	-2.223836
39.56716	159.6708	-2.223911
39.61716	159.6699	-2.223912
39.66716	159.6703	-2.223877
39.72050	159.6699	-2.223814
39.77050	159.6700	-2.223735
39.82217	159.6695	-2.223684
39.87383	159.6689	-2.223532
39.92383	159.6689	-2.223400
39.97717	159.6694	-2.223265
40.02716	159.6696	-2.223223
40.07883	159.6692	-2.223221
40.13050	159.6697	-2.223325
40.18050	159.6699	-2.223480
40.23216	159.6696	-2.223716
40.28383	159.6694	-2.223900
40.33383	159.6700	-2.224088
40.38716	159.6701	-2.224248
40.43716	159.6702	-2.224306
40.48883	159.6696	-2.224272
40.54050	159.6695	-2.224225
40.59050	159.6703	-2.224180
40.64216	159.6697	-2.224221
40.69383	159.6704	-2.224331
40.74383	159.6703	-2.224421
40.79716	159.6705	-2.224501
40.84716	159.6704	-2.224463
40.89883	159.6700	-2.224468
40.95050	159.6698	-2.224581
41.00050	159.6701	-2.224587
41.05217	159.6699	-2.224594
41.10383	159.6695	-2.224615
41.15383	159.6703	-2.224652
41.20717	159.6702	-2.224748
41.25717	159.6700	-2.224906
41.30883	159.6710	-2.225133
41.36050	159.6708	-2.225205
41.41050	159.6705	-2.225408
41.46216	159.6706	-2.225586
41.51383	159.6706	-2.225671
41.56383	159.6709	-2.225750
41.61716	159.6704	-2.225801
41.66716	159.6713	-2.225848
41.71884	159.6707	-2.225888
41.77050	159.6708	-2.225905
41.82050	159.6701	-2.225956
41.87216	159.6713	-2.225994
41.92383	159.6706	-2.225958
41.97383	159.6708	-2.225952
42.02716	159.6704	-2.225952
42.07717	159.6703	-2.225925
42.12883	159.6703	-2.225872
42.18050	159.6706	-2.225772
42.23050	159.6706	-2.225678
42.28383	159.6705	-2.225586
42.33383	159.6706	-2.225639
42.38383	159.6709	-2.225664
42.43716	159.6704	-2.225717
42.48717	159.6709	-2.225805
42.53883	159.6707	-2.225874
42.59050	159.6709	-2.225929
42.64050	159.6708	-2.226015
42.69383	159.6711	-2.226054
42.74383	159.6716	-2.226114
42.79383	159.6717	-2.226185
42.84716	159.6711	-2.226235
42.89717	159.6710	-2.226312
42.94883	159.6709	-2.226344
-2.000000	2.000000	0.0000000
43.05050	159.6974	-2.763894
43.10050	159.9490	-5.881688
43.15050	160.4153	-9.020800
43.20383	161.0570	-11.85126
43.25383	161.7633	-13.90144
43.30550	162.5675	-15.50808
43.35717	163.4263	-16.71617
43.40717	164.2964	-17.59840
43.46050	165.2548	-18.31174
43.51050	166.1752	-18.82685
43.56050	167.1096	-19.23394
43.61383	168.1189	-19.58468
43.66383	169.0734	-19.85106
43.71550	170.0678	-20.08397
43.76717	171.0676	-20.28037
43.81717	172.0391	-20.46683
43.87050	173.0794	-20.62705
43.92050	174.0566	-20.78395
43.97050	175.0356	-20.93984
44.02383	176.0809	-21.11038
44.07383	177.0619	-21.26083
44.12550	178.0761	-21.42956
44.17717	179.0906	-21.61794
44.22717	180.0741	-21.80551
44.28050	181.1208	-22.02716
44.33050	182.1050	-22.24967
44.38050	183.0875	-22.46544
44.43383	184.1351	-22.73336
44.48383	185.1163	-22.99623
44.53550	186.1298	-23.30600
44.58716	187.1421	-23.65194
44.63716	188.1185	-24.04515
44.69050	189.1588	-24.49622
44.74050	190.1299	-25.01910
44.79050	191.1009	-25.44756
44.84384	192.1375	-25.93675
44.89383	193.1062	-26.52278
44.94550	194.1033	-27.18790
44.99716	195.0960	-27.93498
45.04716	196.0514	-28.78209
45.10050	197.0657	-29.71959
45.15050	198.0130	-30.65905
45.20050	198.9525	-31.81051
45.25383	199.9456	-33.21515
45.30383	200.8675	-34.71910
45.35550	201.8100	-36.44272
45.40717	202.7422	-38.28439
45.45717	203.6375	-40.09972
45.51050	204.5900	-42.00772
45.56050	205.4819	-43.85262
45.61217	206.3991	-45.79103
45.66383	207.3174	-47.71070
45.71383	208.2066	-49.53428
45.76550	209.1272	-51.38996
45.81717	210.0490	-53.24387
45.86716	210.9438	-54.94127
45.92050	211.9072	-56.28627
45.97050	212.8432	-56.34858
46.02217	213.8882	-53.96858
46.07383	215.0700	-48.10274
46.12383	216.3757	-40.03984
46.17550	217.7824	-34.58004
46.22717	219.1148	-31.46588
46.27716	220.3294	-29.33804
46.33050	221.5653	-27.69649
46.38050	222.6797	-26.56722
46.43217	223.8011	-25.71666
46.48383	224.8992	-25.10035
46.53383	225.9428	-24.67461
46.58550	227.0100	-24.34442
46.63716	228.0674	-24.12781
46.68716	229.0834	-23.98606
46.74050	230.1634	-23.87728
46.79050	231.1714	-23.83030
46.84217	232.2097	-23.80402
46.89383	233.2467	-23.79180
46.94383	234.2492	-23.78786
46.99550	235.2842	-23.78745
47.04716	236.3178	-23.78782
47.09716	237.3180	-23.78924
47.15050	238.3860	-23.79294
47.20050	239.3849	-23.80069
47.25217	240.4174	-23.81779
47.30383	241.4485	-23.84074
47.35383	242.4482	-23.87008
47.40550	243.4792	-23.90409
47.45717	244.5124	-23.93788
47.50717	245.5112	-23.97100
47.56050	246.5764	-24.00390
47.61050	247.5754	-24.02926
47.66217	248.6060	-24.06528
47.71383	249.6385	-24.09435
47.76383	250.6354	-24.13296
47.81717	251.7012	-24.16877
47.86716	252.7000	-24.20038
47.91716	253.6988	-24.23888
47.97050	254.7627	-24.27158
48.02050	255.7620	-24.30693
48.07217	256.7939	-24.35270
48.12383	257.8262	-24.38889
48.17383	258.8240	-24.43375
48.22717	259.8890	-24.47188
48.27716	260.8888	-24.50634
48.32717	261.8859	-24.53998
48.38050	262.9507	-24.58012
48.43050	263.9487	-24.61770
48.48217	264.9808	-24.65765
48.53383	266.0116	-24.70633
48.58383	267.0110	-24.74214
48.63716	268.0756	-24.78027
48.68716	269.0736	-24.82058
48.73717	270.0711	-24.87393
48.79050	271.1360	-24.91444
48.84050	272.1325	-24.95678
48.89217	273.1648	-25.00274
48.94383	274.1966	-25.03510
48.99383	275.1943	-25.04417
49.04550	276.1798	-25.60428
49.09716	276.6385	-23.25160
49.14717	276.6389	-16.32361
49.19883	276.3734	-9.314926
49.25050	275.9152	-3.490848
49.30050	275.3403	0.9165816
49.35383	274.6204	4.483471
49.40383	273.8720	7.003684
49.45550	273.0432	8.962401
49.50717	272.1714	10.41483
49.55717	271.2961	11.48526
49.60883	270.3684	12.30833
49.66050	269.4213	12.93508
49.71050	268.4918	13.39087
49.76383	267.4873	13.76521
49.81383	266.5387	14.03759
49.86550	265.5486	14.26002
49.91716	264.5544	14.43149
49.96717	263.5858	14.56122
50.01883	262.5814	14.66111
50.07050	261.5749	14.74753
50.12050	260.5973	14.81562
50.17383	259.5536	14.86956
50.22383	258.5719	14.91916
50.27550	257.5574	14.95981
50.32717	256.5407	14.99488
50.37717	255.5566	15.02388
50.42883	254.5384	15.05648
50.48050	253.5192	15.08538
50.53050	252.5324	15.10709
50.58383	251.4785	15.13249
50.63383	250.4906	15.15354
50.68550	249.4687	15.17394
50.73717	248.4468	15.19480
50.78717	247.4567	15.21358
50.83883	246.4332	15.22891
50.89050	245.4100	15.24270
50.94050	244.4178	15.25666
50.99383	243.3610	15.26592
51.04383	242.3690	15.27291
51.09550	241.3437	15.27942
51.14717	240.3191	15.28554
51.19717	239.3274	15.29193
51.25050	238.2702	15.30279
51.30050	237.2781	15.31394
51.35050	236.2856	15.32556
51.40383	235.2265	15.33535
51.45383	234.2342	15.34258
51.50550	233.2070	15.35011
51.55717	232.1811	15.35753
51.60717	231.1886	15.36481
51.66050	230.1291	15.37273
51.71050	229.1368	15.38065
51.76050	228.1429	15.38932
51.81383	227.0836	15.40045
51.86383	226.0913	15.40902
51.91550	225.0648	15.42176
51.96717	224.0376	15.43232
52.01716	223.0425	15.44080
52.07050	221.9833	15.44972
52.12050	220.9899	15.45780
52.17050	219.9963	15.46589
52.22383	218.9356	15.47461
52.27383	217.9406	15.48345
52.32550	216.9144	15.49158
52.37717	215.8868	15.49968
52.42717	214.8920	15.50733
52.48050	213.8329	15.51536
52.53050	212.8380	15.52300
52.58050	211.8453	15.53059
52.63383	210.7852	15.53907
52.68383	209.7902	15.54708
52.73550	208.7631	15.55536
52.78716	207.7353	15.56326
52.83716	206.7406	15.57067
52.89050	205.6798	15.57846
52.94050	204.6863	15.58563
52.99050	203.6919	15.59368
53.04382	202.6316	15.60155
53.09384	201.6381	15.60861
53.14550	200.6098	15.61620
53.19717	199.5816	15.62359
53.24717	198.5867	15.63075
53.30050	197.5255	15.63826
53.35050	196.5307	15.64502
53.40050	195.5352	15.65157
53.45383	194.4744	15.65852
53.50383	193.4804	15.66486
53.55550	192.4521	15.67135
53.60717	191.4246	15.67789
53.65717	190.4294	15.68397
53.71050	189.3685	15.69027
53.76050	188.3748	15.69635
53.81216	187.3469	15.70263
53.86382	186.3198	15.70924
53.91382	185.3262	15.71522
53.96550	184.2971	15.72164
54.01716	183.2696	15.72795
54.06716	182.2759	15.73400
54.12050	181.2134	15.74051
54.17050	180.2202	15.74646
54.22217	179.1911	15.75282
54.27383	178.1639	15.75935
54.32383	177.1686	15.76715
54.37550	176.1420	15.77448
54.42717	175.1148	15.78253
54.47717	174.1204	15.79055
54.53050	173.0604	15.79880
54.58050	172.0652	15.80723
54.63217	171.0369	15.81549
54.68383	170.0094	15.82360
54.73383	169.0145	15.83194
54.78550	167.9863	15.84146
54.83716	166.9599	15.86002
54.88716	165.9660	15.94015
54.94050	164.9114	16.18091
54.99050	163.9266	16.52424
55.04217	162.9196	17.10090
55.09384	161.9308	18.10782
55.14384	161.0012	19.72226
55.19550	160.0816	22.16978
55.24717	159.2096	25.38888
55.29717	158.4055	28.90332
55.35050	157.5726	32.56326
55.40050	156.7865	35.42059
55.45216	155.9438	37.52234
55.50383	155.0540	38.64856
55.55383	154.1379	38.84424
55.60550	153.1365	38.32489
55.65717	152.0864	37.17364
55.70717	151.0354	35.74960
55.76050	149.8871	34.06435
55.81050	148.7986	32.47081
55.86217	147.6677	30.89939
55.91382	146.5386	29.41030
55.96382	145.4505	28.09108
56.01716	144.2968	26.82713
56.06716	143.2215	25.73553
56.11716	142.1522	24.73463
56.17050	141.0178	23.77307
56.22050	139.9597	22.96913
56.27217	138.8757	22.22580
56.32383	137.7960	21.56174
56.37383	136.7582	21.00830
56.42717	135.6562	20.47426
56.47717	134.6270	20.03848
56.52717	133.6005	19.65268
56.58050	132.5092	19.27494
56.63050	131.4905	18.96394
56.68217	130.4393	18.68713
56.73383	129.3904	18.42400
56.78383	128.3777	18.18456
56.83716	127.2976	17.92042
56.88716	126.2876	17.75148
56.93716	125.2788	17.59588
56.99050	124.2044	17.40801
57.04050	123.1962	17.25532
57.09217	122.1568	17.11951
57.14384	121.1190	17.00656
57.19384	120.1141	16.90897
57.24717	119.0451	16.81950
57.29717	118.0435	16.74825
57.34716	117.0436	16.69129
57.40050	115.9763	16.63561
57.45050	114.9770	16.59235
57.50217	113.9454	16.56038
57.55383	112.9134	16.52922
57.60383	111.9148	16.49070
57.65717	110.8495	16.44357
57.70717	109.8505	16.38433
57.75717	108.8516	16.33382
57.81050	107.7866	16.29293
57.86050	106.7890	16.26406
57.91216	105.7574	16.23547
57.96382	104.7264	16.20973
58.01382	103.7279	16.18255
58.06716	102.6646	16.15288
58.11716	101.6677	16.12456
58.16716	100.6693	16.10116
58.22050	99.60431	16.07815
58.27050	98.60574	16.03711
58.32217	97.57382	15.98302
58.37383	96.54136	15.92699
58.42383	95.54280	15.88946
58.47717	94.47941	15.86168
58.52717	93.48031	15.84431
58.57883	92.44913	15.83208
58.63050	91.41944	15.82423
58.68050	90.42175	15.81838
58.73217	89.39101	15.80192
58.78383	88.35837	15.69664
58.83383	87.35691	15.53692
58.88716	86.28621	15.36350
58.93716	85.28251	15.27981
58.98882	84.24749	15.20978
59.04050	83.21222	15.13810
59.09050	82.21099	15.07656
59.14216	81.17651	15.01709
59.19384	80.14163	14.96889
59.24382	79.14249	14.91003
59.29717	78.07622	14.85246
59.34716	77.07632	14.81161
59.39883	76.04447	14.77166
59.45050	75.01296	14.72552
59.50050	74.01306	14.67456
59.55217	72.98072	14.63347
59.60383	71.94793	14.57814
59.65383	70.94929	14.53569
59.70717	69.88309	14.48966
59.75717	68.88329	14.43954
59.80883	67.85108	14.39082
59.86050	66.81958	14.34460
59.91050	65.81970	14.29548
59.96216	64.78780	14.25043
60.01382	63.75349	14.19497
60.06382	62.75355	14.14711
60.11716	61.68896	14.08584
60.16716	60.69010	14.03965
60.21884	59.65716	13.99026
60.27050	58.62490	13.94656
60.32050	57.62524	13.91156
60.37217	56.59363	13.85096
60.42383	55.56068	13.80566
60.47382	54.56171	13.76206
60.52717	53.49613	13.72332
60.57717	52.49594	13.67321
60.62883	51.46409	13.62121
60.68050	50.43078	13.56479
60.73050	49.43080	13.51928
60.78383	48.36449	13.46462
60.83383	47.36519	13.40957
60.88383	46.36470	13.35922
60.93716	45.29730	13.30516
60.98717	44.29692	13.25540
61.03882	43.26341	13.20027
61.09050	42.22903	13.14315
61.14050	41.22938	13.07729
61.19384	40.16146	13.01705
61.24382	39.16106	12.97684
61.29382	38.16037	12.90122
61.34716	37.09285	12.82120
61.39717	36.09097	12.76342
61.44883	35.05588	12.69578
61.50050	34.02100	12.61940
61.55050	33.01946	12.54727
61.60383	31.95124	12.47990
61.65383	30.94995	12.40933
61.70383	29.94979	12.35282
61.75717	28.88168	12.27899
61.80717	27.87860	12.19618
61.85883	26.84434	12.12839
61.91050	25.80768	12.04736
61.96050	24.80501	12.01425
62.01050	23.80242	12.01572
62.06050	22.91070	12.35816
62.11217	22.54293	7.894497
62.16382	22.55690	3.104055
62.21382	22.83734	-0.6534780
62.26716	23.33948	-3.554964
62.31716	23.94717	-5.553686
62.36716	24.65242	-7.029009
62.42050	25.48116	-8.193137
62.47050	26.31116	-9.011765
62.52217	27.20653	-9.648947
62.57383	28.13171	-10.15263
62.62383	29.04750	-10.53072
62.67717	30.04094	-10.83808
62.72717	30.98420	-11.07618
62.77883	31.96703	-11.27392
62.83050	32.95728	-11.44510
62.88050	33.92070	-11.58666
62.93217	34.92178	-11.71256
62.98383	35.92536	-11.81975
63.03383	36.89994	-11.91570
63.08716	37.94159	-12.00815
63.13716	38.91965	-12.09326
63.18882	39.93252	-12.17071
63.24050	40.94790	-12.23626
63.29050	41.92986	-12.31669
63.34217	42.94726	-12.38360
63.39384	43.96542	-12.44995
63.44384	44.95178	-12.51125
63.49717	46.00516	-12.57868
63.54717	46.99236	-12.64431
63.59882	48.01391	-12.71066
63.65050	49.03740	-12.77777
63.70050	50.02628	-12.83698
63.75217	51.04960	-12.91182
63.80383	52.07328	-12.98039
63.85383	53.06452	-13.04830
63.90718	54.12342	-13.11440
63.95717	55.11475	-13.17668
64.00884	56.14074	-13.23988
64.06050	57.16644	-13.30468
64.11050	58.15830	-13.37633
64.16217	59.18467	-13.44591
64.21384	60.21074	-13.51638
64.26384	61.20502	-13.59174
64.31717	62.26434	-13.66791
64.36718	63.25799	-13.73396
64.41884	64.28606	-13.80148
64.47050	65.31290	-13.86547
64.52050	66.30895	-13.93384
64.57218	67.33560	-14.00662
64.62383	68.36460	-14.08539
64.67383	69.35876	-14.15256
64.72718	70.42064	-14.22182
64.77717	71.41564	-14.29514
64.82885	72.44531	-14.36431
64.88050	73.47407	-14.43786
64.93050	74.46986	-14.50138
64.98383	75.53189	-14.57953
65.03384	76.52730	-14.64995
65.08384	77.52094	-14.72916
65.13717	78.58222	-14.81420
65.18717	79.57740	-14.89944
65.23882	80.60550	-14.98280
65.29050	81.63372	-15.06164
65.34050	82.62820	-15.14339
65.39384	83.69012	-15.22786
65.44384	84.68609	-15.30621
65.49384	85.68150	-15.38670
65.54718	86.74321	-15.48164
65.59718	87.73765	-15.56550
65.64884	88.76684	-15.65492
65.70050	89.79474	-15.74072
65.75050	90.79070	-15.82529
65.80384	91.85226	-15.91384
65.85384	92.84866	-16.00756
65.90384	93.84342	-16.08514
65.95718	94.90481	-16.17902
66.00718	95.89978	-16.26146
66.05884	96.92866	-16.34252
66.11050	97.95719	-16.43590
66.16050	98.95188	-16.52373
66.21384	100.0144	-16.61469
66.26384	101.0094	-16.70358
66.31384	102.0043	-16.79896
66.36718	103.0659	-16.88930
66.41718	104.0611	-16.99076
66.46884	105.0893	-17.08730
66.52050	106.1185	-17.18861
66.57050	107.1119	-17.28628
66.62384	108.1736	-17.38684
66.67384	109.1680	-17.48446
66.72384	110.1636	-17.58875
66.77718	111.2253	-17.69094
66.82718	112.2198	-17.79261
66.87884	113.2484	-17.89071
66.93050	114.2756	-17.99522
66.98050	115.2706	-18.10764
67.03384	116.3327	-18.20857
67.08384	117.3275	-18.30382
67.13384	118.3219	-18.41465
67.18718	119.3818	-18.53354
67.23718	120.3761	-18.63764
67.28882	121.4031	-18.75116
67.34050	122.4313	-18.88938
67.39050	123.4240	-18.99722
67.44384	124.4851	-19.12083
67.49384	125.4818	-19.16927
67.54550	126.5109	-19.22839
67.59718	127.5449	-19.21521
67.64718	128.5454	-19.21901
67.69884	129.5773	-19.24722
67.75050	130.6085	-19.31420
67.80050	131.6074	-19.40023
67.85384	132.6708	-19.48176
67.90384	133.6667	-19.58058
67.95550	134.6969	-19.67955
68.00718	135.7248	-19.77982
68.05718	136.7196	-19.88405
68.10884	137.7489	-19.96970
68.16050	138.7775	-20.06021
68.21050	139.7728	-20.14791
68.26384	140.8358	-20.25394
68.31384	141.8317	-20.34701
68.36550	142.8604	-20.43604
68.41718	143.8898	-20.51462
68.46718	144.8854	-20.57750
68.51882	145.9161	-20.67169
68.57050	146.9451	-20.72949
68.62050	147.9416	-20.82804
68.67384	149.0045	-20.91854
68.72384	150.0000	-21.00378
68.77550	151.0283	-21.09468
68.82718	152.0580	-21.18211
68.87718	153.0527	-21.27620
68.92884	154.0811	-21.37176
68.98050	155.1093	-21.47212
69.03050	156.1042	-21.56032
69.08384	157.1668	-21.64598
69.13384	158.1630	-21.71645
69.18550	159.1933	-21.77508
69.23718	160.2237	-21.81637
69.28718	161.2230	-21.84947
69.33884	162.2542	-21.88108
69.39050	163.2869	-21.91544
69.44050	164.2842	-21.95684
69.49384	165.3506	-22.01394
69.54384	166.3474	-22.08362
69.59550	167.3791	-22.18211
69.64718	168.4094	-22.26604
69.69718	169.4054	-22.37387
69.75050	170.4668	-22.50025
69.80050	171.4604	-22.62584
69.85050	172.4554	-22.76045
69.90384	173.5148	-22.91947
69.95384	174.5082	-23.06758
70.00550	175.5324	-23.24996
70.05718	176.5574	-23.44216
70.10718	177.5472	-23.64725
70.16050	178.6006	-23.89961
70.21050	179.5883	-24.15306
70.26050	180.5730	-24.44130
70.31384	181.6213	-24.78180
70.36384	182.6047	-25.12456
70.41550	183.6170	-25.51242
70.46718	184.6281	-25.94707
70.51716	185.6040	-26.39916
70.57050	186.6431	-26.92564
70.62050	187.6138	-27.47040
70.67050	188.5825	-28.03194
70.72384	189.6126	-28.69166
70.77384	190.5776	-29.30608
70.82550	191.5725	-29.98520
70.87718	192.5658	-30.66182
70.92718	193.5266	-31.35720
70.98050	194.5480	-32.12775
71.03050	195.5052	-32.92938
71.08050	196.4578	-33.78166
71.13384	197.4723	-34.75884
71.18384	198.4184	-35.74079
71.23550	199.3924	-36.77546
71.28718	200.3662	-37.79564
71.33716	201.3080	-38.72383
71.39050	202.3175	-39.54468
71.44050	203.2751	-39.98872
71.49050	204.2512	-39.93642
71.54384	205.3262	-38.97415
71.59384	206.3818	-36.92391
71.64550	207.5356	-33.63556
71.69718	208.7422	-30.11786
71.74718	209.9162	-27.76373
71.80050	211.1304	-26.24118
71.85050	212.2326	-25.26694
71.90050	213.3075	-24.57383
71.95384	214.4323	-24.04006
72.00384	215.4718	-23.68907
72.05550	216.5336	-23.43400
72.10718	217.5877	-23.25578
72.15718	218.6018	-23.15843
72.21050	219.6782	-23.07360
72.26050	220.6858	-23.04402
72.31216	221.7242	-23.01937
72.36384	222.7608	-23.01268
72.41382	223.7639	-23.01092
72.46550	224.7996	-23.01064
72.51716	225.8350	-23.01111
72.56718	226.8345	-23.01430
72.62050	227.9003	-23.02180
72.67050	228.9000	-23.03897
72.72218	229.9327	-23.07516
72.77384	230.9660	-23.11261
72.82384	231.9643	-23.15965
72.87550	232.9975	-23.20556
72.92718	234.0302	-23.24933
72.97718	235.0279	-23.29525
73.03050	236.0942	-23.33733
73.08050	237.0918	-23.38316
73.13218	238.1230	-23.42382
73.18384	239.1544	-23.47160
73.23384	240.1523	-23.52512
73.28550	241.1848	-23.57846
73.33716	242.2156	-23.63686
73.38718	243.2138	-23.68781
73.44050	244.2788	-23.73328
73.49050	245.2780	-23.77916
73.54218	246.3101	-23.82053
73.59384	247.3414	-23.86367
73.64384	248.3404	-23.89906
73.69550	249.3727	-23.93877
73.74718	250.4047	-23.98319
73.79718	251.4024	-24.02798
73.85050	252.4662	-24.09099
73.90050	253.4650	-24.13970
73.95216	254.4959	-24.18492
74.00384	255.5269	-24.23235
74.05384	256.5252	-24.29524
74.10550	257.5563	-24.34408
74.15718	258.5871	-24.40830
74.20718	259.5848	-24.46338
74.26050	260.6499	-24.52970
74.31050	261.6466	-24.57578
74.36218	262.6781	-24.64127
74.41382	263.7088	-24.69919
74.46384	264.7072	-24.75473
74.51716	265.7722	-24.82321
74.56718	266.7695	-24.87010
74.61718	267.7666	-24.92656
74.67050	268.8308	-24.99310
74.72050	269.8276	-25.06098
74.77218	270.8575	-25.11457
74.82384	271.8876	-25.18548
-2.000000	5.000000	0.0000000