File: 5-C1(1.4mol%)+C20(0.6mol%)/matlab/160-2.txt
CLOSED
Version	1.0
Language	English
Mode	Standard
Run	23
RunSerial	12325
Instrument	DSC Q2000 V24.11 Build 124
Module	DSC Standard Cell RC
Operator
File	\\AE520-1454\Users\dsc\Desktop\Data\31-08-17-2\160-2.001
ProcName
InstSerial	2000-0883
AutoSerial	1293
Sample	160-2
Size	22.1000	mg
PanMass	Not available
PanResist	Automatic Automatic  K/W
PanFactor	Default Default
Method
Comment
Xcomment	Pan: Tzero Aluminum Hermetic
Xcomment	Gas1: Nitrogen 50.0 ml/min
Xcomment	Gas2: Nitrogen 50.0 ml/min
Text
Exotherm	UP
Kcell	1.05230
Cpconst	Standard: 0.938
Calib	-38.6961
TempCal	1	pts	157.46	156.60
TzeroDt	-87.6168 -0.0009 -1.4231
TzeroDtz	-87.6168 0.0057 6.9570
InstCalFile	Tzero: \\Ae520-1454\ta\Data\DSC\Calibration\2017\CALIBRATION\1562_RCS (90)_05_18_2017 10_50_44.TZR
InstCalFile	Baseline: \\Ae520-1454\ta\Data\DSC\Calibration\2017\2017-05-17_Calibration.001
InstCalFile	Sapphire: \\Ae520-1454\ta\Data\DSC\Calibration\2017\2017-05-17_Saphire.001
InstCalDate	Tzero 2017-05-18 Time 10:50:44
TempRange	-87.39 to 398.39 °C at 10.00 °C/min Heat Only
AutoZero	Delta T Offset 0.000 uV
AutoZero	Delta T0 Offset 0.000 uV
MultiptCal	0
MultiPtDesc	0) Not set
AutoCellConst	Calibration Date 2017-05-18 16:59:28
Controls	Gas 1  Event Off  Sampling 0.2
Cell#	RC-01562
CoolingUnit	RCS (90)
SelHeatFlow	Heat Flow T4P (mW)
AutoLidII	Installed
AutoAnalysis	Off
MacroFile
Nsig	3
Sig1	Time (min)
Sig2	Temperature (°C)
Sig3	Heat Flow (mW)
Date	2017-09-01
Time	15:44:47
OrgMethod	1: Equilibrate at 80.00 °C
OrgMethod	2: Isothermal for 3.00 min
OrgMethod	3: Jump to 160.00 °C
OrgMethod	4: Mark end of cycle 1
OrgMethod	5: Isothermal for 40.00 min
OrgMethod	6: Mark end of cycle 2
OrgMethod	7: Ramp 20.00 °C/min to 280.00 °C
OrgMethod	8: Mark end of cycle 3
OrgMethod	9: Ramp 20.00 °C/min to 20.00 °C
OrgMethod	10: Mark end of cycle 4
OrgMethod	11: Ramp 20.00 °C/min to 280.00 °C
OrgMethod	12: Mark end of cycle 5
OrgFile	C:\Users\jarra\Desktop\DSC\5-C1(1.4mol%)+C20(0.6mol%)\160-2.001
StartOfData
4.99994E-4	79.78241	-2.255720
0.05383332	79.81418	-1.820076
0.1038333	79.83579	-1.513993
0.1555000	79.85205	-1.273959
0.2071666	79.86450	-1.101093
0.2571667	79.87216	-0.9762332
0.3105000	79.87818	-0.8832587
0.3605000	79.88257	-0.8183240
0.4121666	79.88542	-0.7702771
0.4638333	79.88682	-0.7364111
0.5138333	79.88787	-0.7154761
0.5655000	79.88872	-0.7007947
0.6171668	79.88879	-0.6928316
0.6671668	79.88888	-0.6879269
0.7205000	79.88858	-0.6847608
0.7705000	79.88790	-0.6818896
0.8221666	79.88746	-0.6789024
0.8738332	79.88715	-0.6759692
0.9238334	79.88600	-0.6732376
0.9755000	79.88490	-0.6706388
1.027167	79.88426	-0.6681828
1.077166	79.88443	-0.6660196
1.130500	79.88205	-0.6638650
1.180500	79.88269	-0.6621759
1.232166	79.88200	-0.6606294
1.283834	79.88219	-0.6592695
1.333833	79.88087	-0.6580928
1.385500	79.87975	-0.6570554
1.437167	79.87956	-0.6561470
1.487166	79.87898	-0.6554458
1.540500	79.87793	-0.6548668
1.590500	79.87710	-0.6544174
1.642166	79.87694	-0.6541825
1.693833	79.87615	-0.6539449
1.743833	79.87665	-0.6538672
1.795500	79.87536	-0.6539028
1.847167	79.87413	-0.6539942
1.897167	79.87328	-0.6541671
1.950500	79.87412	-0.6545145
2.000500	79.87320	-0.6547716
2.052166	79.87200	-0.6551642
2.103833	79.87094	-0.6556028
2.153833	79.87119	-0.6561072
2.205500	79.87085	-0.6566592
2.257167	79.87015	-0.6571770
2.307167	79.86966	-0.6577832
2.360500	79.86926	-0.6584595
2.410500	79.86890	-0.6591285
2.462167	79.86828	-0.6598450
2.513833	79.86818	-0.6605782
2.563833	79.86782	-0.6613335
2.617167	79.86672	-0.6621324
2.667167	79.86658	-0.6629710
2.717167	79.86636	-0.6638506
2.770500	79.86559	-0.6647711
2.820500	79.86551	-0.6657476
2.872167	79.86447	-0.6666800
2.923834	79.86370	-0.6676788
2.973833	79.86480	-0.6686378
3.020500	79.89114	-1.110818
3.073833	80.89514	-14.57374
3.123834	83.06876	-27.64764
3.175500	85.90297	-39.60316
3.227167	89.21500	-50.11654
3.277167	92.75968	-58.68980
3.328833	96.68390	-66.02172
3.380500	100.8033	-71.96484
3.430500	104.9234	-76.64454
3.483833	109.4216	-80.66931
3.533833	113.7046	-83.71339
3.585500	118.1723	-86.33347
3.637167	122.6634	-88.58518
3.687167	127.0272	-90.25806
3.738834	131.5494	-91.60625
3.790500	136.0760	-92.60868
3.840500	140.4586	-93.24781
3.893833	144.9449	-90.48298
3.943833	148.0563	-77.82978
3.995500	150.4022	-65.12143
4.047167	152.2139	-53.32951
4.097166	153.5734	-43.47184
4.150500	154.7109	-34.71606
4.200500	155.5528	-28.03838
4.250500	156.2283	-22.63979
4.303834	156.8061	-18.04961
4.353833	157.2448	-14.64701
4.405500	157.6166	-11.86452
4.457167	157.9210	-9.665412
4.507167	158.1671	-7.983140
4.560500	158.3855	-6.552326
4.610500	158.5583	-5.485713
4.660500	158.7068	-4.614158
4.713834	158.8403	-3.861550
4.763834	158.9495	-3.278787
4.815500	159.0460	-2.774546
4.867166	159.1314	-2.354427
4.917167	159.2033	-1.999469
4.970500	159.2713	-1.664883
5.020500	159.3291	-1.387584
5.070500	159.3795	-1.135711
5.123833	159.4288	-0.8860926
5.173834	159.4728	-0.6626778
5.225500	159.5128	-0.4369966
5.277168	159.5495	-0.2187982
5.327168	159.5831	-9.4699E-3
5.380500	159.6172	0.2172577
5.430500	159.6470	0.4355398
5.480500	159.6756	0.6562830
5.533832	159.7053	0.8944129
5.583832	159.7308	1.133605
5.635500	159.7581	1.384381
5.687168	159.7842	1.643434
5.737168	159.8096	1.908720
5.790500	159.8361	2.200902
5.840500	159.8619	2.486192
5.890500	159.8878	2.786584
5.943832	159.9150	3.116669
5.993834	159.9407	3.439311
6.045500	159.9684	3.786525
6.097168	159.9956	4.146446
6.147168	160.0243	4.504816
6.200500	160.0536	4.900730
6.250500	160.0816	5.282222
6.300500	160.1092	5.668938
6.353832	160.1403	6.082193
6.403832	160.1677	6.477578
6.455500	160.1966	6.874975
6.507168	160.2246	7.268400
6.557166	160.2508	7.622921
6.610500	160.2765	7.984280
6.660500	160.2990	8.290468
6.712168	160.3195	8.571707
6.763834	160.3375	8.804356
6.813834	160.3524	8.997242
6.865500	160.3645	9.144103
6.917168	160.3737	9.260336
6.967168	160.3824	9.348576
7.020500	160.3889	9.428619
7.070500	160.3950	9.505004
7.122168	160.4024	9.603106
7.173834	160.4128	9.744999
7.223834	160.4239	9.933738
7.275500	160.4398	10.18608
7.327168	160.4591	10.50410
7.377168	160.4830	10.86373
7.430500	160.5105	11.29472
7.480500	160.5394	11.72988
7.532166	160.5701	12.19394
7.583832	160.6018	12.64820
7.633832	160.6295	13.06336
7.685500	160.6559	13.45489
7.737168	160.6803	13.78573
7.787168	160.6984	14.05451
7.840500	160.7149	14.26488
7.890500	160.7252	14.40841
7.942168	160.7313	14.48844
7.993834	160.7355	14.51653
8.043834	160.7350	14.51675
8.095500	160.7329	14.51232
8.147168	160.7286	14.45479
8.197168	160.7220	14.31096
8.250500	160.7136	14.16088
8.300500	160.7056	14.02103
8.352168	160.6977	13.87728
8.403832	160.6883	13.73468
8.453834	160.6804	13.59408
8.505500	160.6715	13.45609
8.557168	160.6628	13.32065
8.607166	160.6554	13.19125
8.660499	160.6471	13.06592
8.710499	160.6396	12.95014
8.762168	160.6316	12.83802
8.813834	160.6254	12.73164
8.863834	160.6184	12.63959
8.917168	160.6128	12.54703
8.967168	160.6083	12.46353
9.017168	160.6022	12.38709
9.070500	160.5980	12.31071
9.120499	160.5936	12.24476
9.172168	160.5894	12.17642
9.223832	160.5846	12.11549
9.273834	160.5821	12.05700
9.327168	160.5785	12.00103
9.377168	160.5747	11.94956
9.427168	160.5707	11.90106
9.480500	160.5683	11.84726
9.530500	160.5659	11.80134
9.582168	160.5629	11.75188
9.633832	160.5596	11.70208
9.683832	160.5566	11.65320
9.737168	160.5531	11.60398
9.787168	160.5507	11.55663
9.837168	160.5477	11.50895
9.890500	160.5451	11.45938
9.940500	160.5419	11.41618
9.992166	160.5388	11.37125
10.04383	160.5364	11.32734
10.09383	160.5344	11.28953
10.14717	160.5319	11.25241
10.19717	160.5290	11.22472
10.24717	160.5280	11.20069
10.30050	160.5269	11.18106
10.35050	160.5250	11.16776
10.40217	160.5247	11.15535
10.45383	160.5248	11.14760
10.50384	160.5237	11.14282
10.55717	160.5237	11.13800
10.60717	160.5239	11.13366
10.65717	160.5246	11.12996
10.71050	160.5256	11.12684
10.76050	160.5269	11.12485
10.81216	160.5279	11.12418
10.86383	160.5302	11.13049
10.91383	160.5341	11.15098
10.96717	160.5377	11.20049
11.01717	160.5409	11.26547
11.06716	160.5454	11.34056
11.12050	160.5492	11.41037
11.17050	160.5526	11.46340
11.22217	160.5557	11.49785
11.27383	160.5562	11.51083
11.32383	160.5544	11.51198
11.37717	160.5495	11.48120
11.42717	160.5413	11.30283
11.47884	160.5289	11.05636
11.53050	160.5109	10.75378
11.58050	160.4899	10.40162
11.63216	160.4636	9.975241
11.68383	160.4330	9.484272
11.73383	160.3996	8.962641
11.78717	160.3614	8.359539
11.83717	160.3228	7.766016
11.88883	160.2821	7.139936
11.94050	160.2412	6.512336
11.99050	160.2003	5.894538
12.04217	160.1598	5.271008
12.09383	160.1206	4.665352
12.14383	160.0833	4.103149
12.19717	160.0453	3.526903
12.24717	160.0128	3.042625
12.29884	159.9827	2.586165
12.35050	159.9531	2.132398
12.40050	159.9256	1.729211
12.45217	159.9004	1.343501
12.50384	159.8762	0.9909984
12.55383	159.8547	0.6818642
12.60717	159.8360	0.3863061
12.65717	159.8203	0.1416750
12.70883	159.8048	-.08093200
12.76050	159.7911	-0.2786288
12.81050	159.7796	-0.4497940
12.86217	159.7692	-0.6058726
12.91383	159.7602	-0.7422538
12.96383	159.7515	-0.8595262
13.01717	159.7434	-0.9723907
13.06716	159.7377	-1.064829
13.11884	159.7312	-1.151090
13.17050	159.7257	-1.229634
13.22050	159.7214	-1.298356
13.27217	159.7160	-1.359850
13.32384	159.7124	-1.416021
13.37384	159.7088	-1.464102
13.42717	159.7056	-1.515386
13.47717	159.7023	-1.557736
13.52883	159.7001	-1.601530
13.58050	159.6976	-1.639761
13.63050	159.6960	-1.671807
13.68383	159.6927	-1.701130
13.73383	159.6907	-1.727608
13.78383	159.6889	-1.750751
13.83717	159.6866	-1.773135
13.88717	159.6850	-1.793747
13.93883	159.6835	-1.812270
13.99050	159.6814	-1.830084
14.04050	159.6806	-1.845409
14.09383	159.6804	-1.861884
14.14383	159.6781	-1.875204
14.19384	159.6772	-1.889581
14.24717	159.6764	-1.901274
14.29717	159.6742	-1.911706
14.34883	159.6737	-1.922838
14.40050	159.6734	-1.931270
14.45050	159.6722	-1.939806
14.50383	159.6714	-1.951579
14.55383	159.6719	-1.961268
14.60383	159.6716	-1.969589
14.65717	159.6702	-1.978182
14.70717	159.6705	-1.986193
14.75883	159.6702	-1.994396
14.81050	159.6695	-2.002676
14.86050	159.6687	-2.010564
14.91383	159.6670	-2.018976
14.96383	159.6670	-2.026741
15.01383	159.6671	-2.034525
15.06716	159.6670	-2.042692
15.11716	159.6651	-2.050286
15.16883	159.6650	-2.058050
15.22050	159.6647	-2.065846
15.27050	159.6634	-2.073298
15.32384	159.6629	-2.081263
15.37384	159.6636	-2.088674
15.42383	159.6628	-2.096018
15.47717	159.6617	-2.103712
15.52717	159.6620	-2.110880
15.57883	159.6616	-2.118340
15.63050	159.6614	-2.125685
15.68050	159.6621	-2.132801
15.73383	159.6624	-2.140122
15.78383	159.6622	-2.146891
15.83383	159.6615	-2.153396
15.88716	159.6617	-2.160243
15.93717	159.6607	-2.166388
15.98883	159.6610	-2.172611
16.04050	159.6600	-2.178595
16.09050	159.6595	-2.184272
16.14383	159.6590	-2.190114
16.19383	159.6590	-2.195500
16.24550	159.6591	-2.200996
16.29716	159.6585	-2.206410
16.34717	159.6589	-2.211675
16.39883	159.6584	-2.217030
16.45050	159.6581	-2.222228
16.50050	159.6576	-2.227170
16.55383	159.6583	-2.232355
16.60383	159.6571	-2.237000
16.65550	159.6574	-2.241730
16.70716	159.6568	-2.246211
16.75716	159.6571	-2.250585
16.80883	159.6568	-2.255012
16.86050	159.6578	-2.259388
16.91050	159.6570	-2.263624
16.96383	159.6566	-2.268083
17.01383	159.6559	-2.272238
17.06550	159.6567	-2.276415
17.11716	159.6561	-2.280487
17.16716	159.6564	-2.284390
17.21883	159.6561	-2.288309
17.27050	159.6564	-2.292060
17.32050	159.6562	-2.295605
17.37383	159.6558	-2.299175
17.42383	159.6551	-2.302415
17.47550	159.6552	-2.305626
17.52716	159.6539	-2.308598
17.57716	159.6547	-2.311446
17.62883	159.6533	-2.314286
17.68050	159.6536	-2.317041
17.73050	159.6539	-2.319710
17.78383	159.6536	-2.322620
17.83383	159.6536	-2.325400
17.88550	159.6531	-2.328174
17.93716	159.6535	-2.330962
17.98716	159.6532	-2.333615
18.03883	159.6540	-2.336319
18.09050	159.6538	-2.338972
18.14050	159.6531	-2.341598
18.19383	159.6530	-2.344307
18.24383	159.6540	-2.346781
18.29550	159.6529	-2.349272
18.34716	159.6535	-2.351719
18.39716	159.6534	-2.353992
18.45050	159.6534	-2.356324
18.50050	159.6524	-2.358352
18.55050	159.6525	-2.360284
18.60383	159.6523	-2.362400
18.65383	159.6526	-2.364270
18.70550	159.6522	-2.366248
18.75716	159.6528	-2.368265
18.80716	159.6521	-2.370250
18.86050	159.6530	-2.372380
18.91050	159.6522	-2.374177
18.96050	159.6524	-2.375984
19.01383	159.6523	-2.377798
19.06383	159.6518	-2.379387
19.11550	159.6520	-2.381000
19.16716	159.6516	-2.382599
19.21716	159.6516	-2.384170
19.27050	159.6509	-2.385690
19.32050	159.6517	-2.387053
19.37050	159.6516	-2.388448
19.42383	159.6517	-2.389983
19.47383	159.6522	-2.391568
19.52550	159.6516	-2.393136
19.57716	159.6514	-2.394828
19.62716	159.6524	-2.396374
19.68050	159.6526	-2.397842
19.73050	159.6522	-2.399141
19.78050	159.6519	-2.400408
19.83383	159.6519	-2.401732
19.88383	159.6522	-2.402880
19.93550	159.6521	-2.404015
19.98716	159.6516	-2.405088
20.03717	159.6518	-2.406151
20.09050	159.6512	-2.407106
20.14050	159.6522	-2.408066
20.19050	159.6510	-2.409021
20.24383	159.6505	-2.410125
20.29383	159.6504	-2.411294
20.34550	159.6518	-2.412514
20.39716	159.6512	-2.413642
20.44716	159.6512	-2.414701
20.50050	159.6514	-2.415880
20.55050	159.6508	-2.416931
20.60050	159.6516	-2.418012
20.65383	159.6504	-2.419057
20.70383	159.6513	-2.420056
20.75550	159.6514	-2.421091
20.80716	159.6506	-2.422052
20.85716	159.6516	-2.422997
20.91050	159.6509	-2.423850
20.96050	159.6506	-2.424634
21.01216	159.6508	-2.425432
21.06383	159.6510	-2.426112
21.11383	159.6501	-2.426804
21.16550	159.6499	-2.427476
21.21716	159.6501	-2.428204
21.26716	159.6509	-2.428872
21.32050	159.6490	-2.429536
21.37050	159.6491	-2.430146
21.42216	159.6494	-2.430800
21.47383	159.6491	-2.431498
21.52383	159.6491	-2.432230
21.57550	159.6489	-2.433060
21.62716	159.6486	-2.433856
21.67717	159.6485	-2.434608
21.73050	159.6488	-2.435463
21.78050	159.6496	-2.436258
21.83216	159.6494	-2.437126
21.88383	159.6494	-2.437982
21.93383	159.6489	-2.438753
21.98550	159.6494	-2.439584
22.03717	159.6484	-2.440277
22.08716	159.6488	-2.440999
22.14050	159.6495	-2.441718
22.19050	159.6494	-2.442261
22.24216	159.6493	-2.442876
22.29383	159.6492	-2.443554
22.34383	159.6498	-2.444237
22.39550	159.6502	-2.445011
22.44716	159.6502	-2.445757
22.49716	159.6502	-2.446406
22.55050	159.6506	-2.447155
22.60050	159.6504	-2.447776
22.65216	159.6497	-2.448354
22.70383	159.6504	-2.448941
22.75383	159.6500	-2.449402
22.80550	159.6499	-2.449750
22.85716	159.6498	-2.450092
22.90716	159.6494	-2.450367
22.96050	159.6493	-2.450664
23.01050	159.6492	-2.450912
23.06216	159.6490	-2.451255
23.11383	159.6492	-2.451519
23.16383	159.6487	-2.451864
23.21716	159.6497	-2.452274
23.26716	159.6490	-2.452736
23.31716	159.6492	-2.453233
23.37050	159.6498	-2.453853
23.42050	159.6489	-2.454350
23.47216	159.6489	-2.454928
23.52383	159.6502	-2.455547
23.57383	159.6498	-2.456072
23.62716	159.6495	-2.456700
23.67717	159.6495	-2.457214
23.72716	159.6501	-2.457678
23.78050	159.6493	-2.458056
23.83050	159.6498	-2.458356
23.88216	159.6493	-2.458628
23.93383	159.6489	-2.458899
23.98383	159.6494	-2.459192
24.03717	159.6486	-2.459547
24.08716	159.6492	-2.459916
24.13716	159.6496	-2.460303
24.19050	159.6490	-2.460644
24.24050	159.6492	-2.460996
24.29216	159.6487	-2.461336
24.34383	159.6503	-2.461910
24.39383	159.6487	-2.462394
24.44716	159.6495	-2.462969
24.49716	159.6499	-2.463519
24.54716	159.6492	-2.463982
24.60050	159.6503	-2.464522
24.65050	159.6488	-2.464844
24.70216	159.6494	-2.465169
24.75383	159.6493	-2.465450
24.80383	159.6489	-2.465722
24.85716	159.6484	-2.465982
24.90716	159.6479	-2.466223
24.95717	159.6481	-2.466471
25.01050	159.6486	-2.466775
25.06050	159.6477	-2.467029
25.11216	159.6496	-2.467532
25.16383	159.6484	-2.468014
25.21383	159.6493	-2.468539
25.26716	159.6496	-2.469033
25.31716	159.6491	-2.469515
25.36716	159.6498	-2.469898
25.42050	159.6498	-2.470264
25.47050	159.6492	-2.470542
25.52216	159.6493	-2.470814
25.57383	159.6492	-2.471120
25.62383	159.6498	-2.471418
25.67717	159.6498	-2.471638
25.72717	159.6491	-2.471845
25.77883	159.6496	-2.472092
25.83050	159.6488	-2.472408
25.88050	159.6499	-2.472729
25.93216	159.6494	-2.473066
25.98383	159.6491	-2.473342
26.03383	159.6496	-2.473611
26.08716	159.6488	-2.473815
26.13716	159.6493	-2.474055
26.18883	159.6489	-2.474152
26.24050	159.6480	-2.474239
26.29050	159.6483	-2.474347
26.34216	159.6486	-2.474432
26.39383	159.6486	-2.474461
26.44383	159.6479	-2.474537
26.49716	159.6484	-2.474768
26.54716	159.6481	-2.475066
26.59883	159.6486	-2.475490
26.65050	159.6484	-2.475888
26.70050	159.6489	-2.476411
26.75217	159.6487	-2.476856
26.80383	159.6484	-2.477183
26.85383	159.6488	-2.477510
26.90716	159.6489	-2.477784
26.95716	159.6486	-2.478052
27.00883	159.6488	-2.478264
27.06050	159.6491	-2.478457
27.11050	159.6491	-2.478706
27.16217	159.6489	-2.478879
27.21383	159.6484	-2.479144
27.26383	159.6489	-2.479438
27.31716	159.6487	-2.479650
27.36716	159.6497	-2.479940
27.41883	159.6488	-2.480187
27.47050	159.6491	-2.480380
27.52050	159.6486	-2.480550
27.57217	159.6491	-2.480832
27.62383	159.6493	-2.480987
27.67383	159.6497	-2.481066
27.72717	159.6493	-2.481159
27.77717	159.6489	-2.481240
27.82883	159.6485	-2.481283
27.88050	159.6487	-2.481427
27.93050	159.6485	-2.481470
27.98383	159.6484	-2.481568
28.03383	159.6487	-2.481511
28.08383	159.6478	-2.481478
28.13716	159.6474	-2.481456
28.18717	159.6481	-2.481537
28.23883	159.6479	-2.481726
28.29050	159.6479	-2.481992
28.34050	159.6478	-2.482287
28.39383	159.6484	-2.482600
28.44383	159.6482	-2.482797
28.49383	159.6487	-2.482988
28.54716	159.6475	-2.483235
28.59716	159.6485	-2.483486
28.64883	159.6481	-2.483744
28.70050	159.6488	-2.484034
28.75050	159.6478	-2.484320
28.80383	159.6493	-2.484645
28.85383	159.6493	-2.484948
28.90383	159.6497	-2.485187
28.95716	159.6492	-2.485404
29.00716	159.6484	-2.485598
29.05883	159.6486	-2.485764
29.11050	159.6481	-2.485962
29.16050	159.6492	-2.486116
29.21383	159.6486	-2.486183
29.26383	159.6478	-2.486270
29.31383	159.6480	-2.486306
29.36716	159.6477	-2.486418
29.41716	159.6478	-2.486463
29.46883	159.6478	-2.486500
29.52050	159.6478	-2.486549
29.57050	159.6477	-2.486625
29.62383	159.6476	-2.486769
29.67383	159.6486	-2.487040
29.72383	159.6485	-2.487315
29.77717	159.6484	-2.487640
29.82717	159.6482	-2.488030
29.87883	159.6486	-2.488396
29.93050	159.6485	-2.488780
29.98050	159.6485	-2.489093
30.03383	159.6486	-2.489351
30.08383	159.6491	-2.489625
30.13383	159.6489	-2.489790
30.18717	159.6489	-2.489924
30.23716	159.6490	-2.490088
30.28883	159.6488	-2.490208
30.34050	159.6498	-2.490408
30.39050	159.6486	-2.490510
30.44383	159.6489	-2.490582
30.49383	159.6483	-2.490640
30.54550	159.6488	-2.490668
30.59716	159.6483	-2.490636
30.64716	159.6484	-2.490594
30.69883	159.6482	-2.490583
30.75050	159.6488	-2.490634
30.80050	159.6483	-2.490772
30.85383	159.6481	-2.490916
30.90383	159.6491	-2.491198
30.95550	159.6484	-2.491404
31.00716	159.6494	-2.491715
31.05716	159.6488	-2.491932
31.10883	159.6492	-2.492153
31.16050	159.6494	-2.492228
31.21050	159.6494	-2.492324
31.26383	159.6497	-2.492401
31.31383	159.6495	-2.492423
31.36550	159.6485	-2.492378
31.41716	159.6476	-2.492314
31.46716	159.6479	-2.492150
31.51883	159.6480	-2.492060
31.57050	159.6483	-2.491995
31.62050	159.6485	-2.492029
31.67383	159.6471	-2.492109
31.72383	159.6485	-2.492232
31.77550	159.6488	-2.492314
31.82717	159.6486	-2.492337
31.87717	159.6485	-2.492280
31.92883	159.6480	-2.492214
31.98050	159.6475	-2.492161
32.03050	159.6475	-2.492183
32.08383	159.6478	-2.492305
32.13383	159.6485	-2.492470
32.18550	159.6484	-2.492662
32.23717	159.6481	-2.492876
32.28717	159.6484	-2.493016
32.33883	159.6481	-2.493250
32.39050	159.6480	-2.493392
32.44050	159.6483	-2.493454
32.49383	159.6481	-2.493472
32.54383	159.6489	-2.493544
32.59550	159.6488	-2.493682
32.64717	159.6486	-2.493817
32.69717	159.6482	-2.493953
32.75050	159.6482	-2.493988
32.80050	159.6493	-2.494070
32.85050	159.6487	-2.494016
32.90383	159.6486	-2.493927
32.95383	159.6480	-2.493788
33.00550	159.6484	-2.493684
33.05716	159.6486	-2.493676
33.10716	159.6483	-2.493768
33.16050	159.6483	-2.493862
33.21050	159.6494	-2.494002
33.26050	159.6490	-2.494108
33.31383	159.6491	-2.494273
33.36383	159.6483	-2.494502
33.41550	159.6491	-2.494700
33.46716	159.6479	-2.494868
33.51716	159.6482	-2.494939
33.57050	159.6487	-2.495007
33.62050	159.6483	-2.495010
33.67050	159.6481	-2.494905
33.72383	159.6478	-2.494761
33.77383	159.6474	-2.494672
33.82550	159.6474	-2.494571
33.87717	159.6478	-2.494581
33.92717	159.6476	-2.494536
33.98050	159.6475	-2.494616
34.03050	159.6478	-2.494746
34.08050	159.6484	-2.494940
34.13383	159.6478	-2.495112
34.18384	159.6484	-2.495380
34.23550	159.6484	-2.495640
34.28717	159.6488	-2.495932
34.33716	159.6495	-2.496163
34.39050	159.6483	-2.496330
34.44050	159.6494	-2.496506
34.49050	159.6493	-2.496647
34.54383	159.6500	-2.496792
34.59384	159.6482	-2.496917
34.64550	159.6499	-2.497134
34.69717	159.6498	-2.497241
34.74716	159.6495	-2.497349
34.80050	159.6504	-2.497407
34.85050	159.6503	-2.497354
34.90050	159.6499	-2.497254
34.95383	159.6499	-2.497176
35.00383	159.6500	-2.497032
35.05550	159.6499	-2.496965
35.10716	159.6498	-2.496958
35.15716	159.6495	-2.496832
35.21050	159.6492	-2.496738
35.26050	159.6504	-2.496554
35.31216	159.6491	-2.496480
35.36383	159.6489	-2.496318
35.41383	159.6496	-2.496295
35.46550	159.6484	-2.496220
35.51716	159.6486	-2.496208
35.56716	159.6476	-2.496162
35.62050	159.6489	-2.496126
35.67050	159.6479	-2.496116
35.72217	159.6484	-2.496058
35.77383	159.6488	-2.496144
35.82383	159.6484	-2.496233
35.87550	159.6486	-2.496470
35.92717	159.6484	-2.496629
35.97717	159.6484	-2.496817
36.03050	159.6481	-2.497049
36.08050	159.6481	-2.497304
36.13216	159.6486	-2.497603
36.18384	159.6489	-2.497881
36.23383	159.6483	-2.498091
36.28550	159.6482	-2.498247
36.33716	159.6480	-2.498360
36.38716	159.6482	-2.498381
36.44050	159.6494	-2.498450
36.49050	159.6485	-2.498424
36.54217	159.6481	-2.498430
36.59384	159.6480	-2.498495
36.64383	159.6488	-2.498556
36.69550	159.6481	-2.498556
36.74716	159.6491	-2.498545
36.79716	159.6480	-2.498520
36.85050	159.6480	-2.498616
36.90050	159.6474	-2.498688
36.95216	159.6481	-2.498823
37.00383	159.6482	-2.499024
37.05383	159.6478	-2.499205
37.10550	159.6487	-2.499396
37.15716	159.6481	-2.499528
37.20716	159.6480	-2.499604
37.26050	159.6480	-2.499684
37.31050	159.6480	-2.499599
37.36217	159.6476	-2.499648
37.41383	159.6466	-2.499602
37.46383	159.6478	-2.499613
37.51716	159.6478	-2.499675
37.56716	159.6476	-2.499773
37.61716	159.6465	-2.500054
37.67050	159.6486	-2.500378
37.72050	159.6488	-2.500660
37.77217	159.6482	-2.500912
37.82383	159.6476	-2.501094
37.87383	159.6488	-2.501353
37.92717	159.6491	-2.501561
37.97717	159.6487	-2.501734
38.02716	159.6492	-2.501871
38.08050	159.6486	-2.501889
38.13050	159.6486	-2.501933
38.18216	159.6478	-2.501928
38.23383	159.6475	-2.501928
38.28383	159.6488	-2.501990
38.33716	159.6476	-2.501984
38.38716	159.6478	-2.502046
38.43716	159.6481	-2.502228
38.49050	159.6494	-2.502480
38.54050	159.6494	-2.502684
38.59216	159.6487	-2.502838
38.64383	159.6489	-2.502988
38.69383	159.6484	-2.503210
38.74716	159.6486	-2.503342
38.79716	159.6480	-2.503414
38.84716	159.6499	-2.503558
38.90050	159.6484	-2.503516
38.95050	159.6489	-2.503525
39.00217	159.6485	-2.503432
39.05383	159.6484	-2.503290
39.10383	159.6489	-2.503168
39.15716	159.6483	-2.502968
39.20716	159.6485	-2.502867
39.25716	159.6484	-2.502839
39.31050	159.6480	-2.502865
39.36050	159.6481	-2.502934
39.41217	159.6482	-2.503098
39.46383	159.6480	-2.503256
39.51383	159.6487	-2.503435
39.56716	159.6487	-2.503567
39.61716	159.6480	-2.503550
39.66716	159.6483	-2.503506
39.72050	159.6481	-2.503480
39.77050	159.6477	-2.503494
39.82217	159.6480	-2.503583
39.87383	159.6479	-2.503615
39.92383	159.6487	-2.503774
39.97717	159.6491	-2.503904
40.02716	159.6486	-2.504014
40.07883	159.6489	-2.504172
40.13050	159.6494	-2.504333
40.18050	159.6495	-2.504412
40.23216	159.6493	-2.504490
40.28383	159.6488	-2.504530
40.33383	159.6484	-2.504564
40.38716	159.6487	-2.504553
40.43716	159.6477	-2.504460
40.48883	159.6485	-2.504392
40.54050	159.6484	-2.504119
40.59050	159.6478	-2.503903
40.64216	159.6475	-2.503860
40.69383	159.6471	-2.503876
40.74383	159.6482	-2.503933
40.79716	159.6478	-2.503926
40.84716	159.6493	-2.503948
40.89883	159.6478	-2.503944
40.95050	159.6477	-2.503997
41.00050	159.6472	-2.504050
41.05217	159.6478	-2.504135
41.10383	159.6482	-2.504214
41.15383	159.6481	-2.504266
41.20717	159.6478	-2.504218
41.25717	159.6484	-2.504289
41.30883	159.6483	-2.504334
41.36050	159.6486	-2.504305
41.41050	159.6476	-2.504282
41.46216	159.6476	-2.504263
41.51383	159.6478	-2.504341
41.56383	159.6475	-2.504259
41.61716	159.6478	-2.504089
41.66716	159.6469	-2.503906
41.71884	159.6479	-2.503747
41.77050	159.6478	-2.503569
41.82050	159.6474	-2.503486
41.87216	159.6479	-2.503470
41.92383	159.6476	-2.503452
41.97383	159.6479	-2.503569
42.02716	159.6486	-2.503652
42.07717	159.6476	-2.503685
42.12883	159.6480	-2.503742
42.18050	159.6475	-2.503718
42.23050	159.6476	-2.503748
42.28383	159.6476	-2.503789
42.33383	159.6483	-2.503904
42.38383	159.6478	-2.504056
42.43716	159.6491	-2.504396
42.48717	159.6485	-2.504650
42.53883	159.6482	-2.504930
42.59050	159.6484	-2.505144
42.64050	159.6484	-2.505236
42.69383	159.6483	-2.505318
42.74383	159.6482	-2.505306
42.79383	159.6489	-2.505264
42.84716	159.6476	-2.505244
42.89717	159.6488	-2.505308
42.94883	159.6488	-2.505403
-2.000000	2.000000	0.0000000
43.05050	159.6705	-3.173318
43.10050	159.8944	-6.946359
43.15050	160.3252	-10.69760
43.20383	160.9338	-14.07748
43.25383	161.6123	-16.54673
43.30550	162.3911	-18.48584
43.35717	163.2294	-19.97946
43.40717	164.0822	-21.08740
43.46050	165.0235	-22.00234
43.51050	165.9311	-22.68624
43.56050	166.8551	-23.22162
43.61383	167.8569	-23.67789
43.66383	168.8076	-24.02996
43.71550	169.7975	-24.33767
43.76717	170.7921	-24.60315
43.81717	171.7611	-24.83659
43.87050	172.7978	-25.07083
43.92050	173.7723	-25.26341
43.97050	174.7493	-25.45748
44.02383	175.7926	-25.66707
44.07383	176.7708	-25.85432
44.12550	177.7834	-26.06797
44.17717	178.7957	-26.30392
44.22717	179.7767	-26.52260
44.28050	180.8222	-26.77380
44.33050	181.8033	-27.02910
44.38050	182.7842	-27.29760
44.43383	183.8305	-27.59282
44.48383	184.8104	-27.90126
44.53550	185.8212	-28.23164
44.58716	186.8326	-28.59647
44.63716	187.8086	-28.98400
44.69050	188.8496	-29.43792
44.74050	189.8210	-29.93440
44.79050	190.7910	-30.48473
44.84384	191.8206	-31.14688
44.89383	192.7816	-31.85791
44.94550	193.7708	-32.65922
44.99716	194.7549	-33.55899
45.04716	195.7026	-34.50017
45.10050	196.7096	-35.58421
45.15050	197.6477	-36.71376
45.20050	198.5795	-38.02732
45.25383	199.5601	-39.64739
45.30383	200.4716	-41.31881
45.35550	201.4026	-43.15472
45.40717	202.3286	-45.03688
45.45717	203.2202	-46.84535
45.51050	204.1742	-48.64533
45.56050	205.0740	-50.14098
45.61217	206.0026	-52.90215
45.66383	206.8994	-54.52566
45.71383	207.7880	-56.41552
45.76550	208.7007	-58.54220
45.81717	209.6104	-60.70585
45.86716	210.4886	-62.77878
45.92050	211.4304	-64.67074
45.97050	212.3344	-65.54715
46.02217	213.3275	-64.69739
46.07383	214.4284	-60.72343
46.12383	215.6348	-54.03745
46.17550	217.0280	-45.90287
46.22717	218.4406	-40.73704
46.27716	219.7357	-37.57024
46.33050	221.0399	-35.11838
46.38050	222.2065	-33.44511
46.43217	223.3684	-32.14826
46.48383	224.4987	-31.17476
46.53383	225.5684	-30.47728
46.58550	226.6555	-29.95887
46.63716	227.7283	-29.56565
46.68716	228.7568	-29.31436
46.74050	229.8449	-29.11132
46.79050	230.8591	-29.00556
46.84217	231.9033	-28.92902
46.89383	232.9440	-28.88976
46.94383	233.9482	-28.87013
46.99550	234.9844	-28.86210
47.04716	236.0211	-28.86112
47.09716	237.0213	-28.86073
47.15050	238.0898	-28.86138
47.20050	239.0899	-28.86295
47.25217	240.1234	-28.87107
47.30383	241.1562	-28.88862
47.35383	242.1548	-28.92508
47.40550	243.1874	-28.97059
47.45717	244.2188	-29.01216
47.50717	245.2186	-29.05534
47.56050	246.2840	-29.09692
47.61050	247.2828	-29.12932
47.66217	248.3155	-29.15980
47.71383	249.3482	-29.19463
47.76383	250.3475	-29.22363
47.81717	251.4128	-29.25808
47.86716	252.4115	-29.29459
47.91716	253.4107	-29.32518
47.97050	254.4754	-29.36377
48.02050	255.4736	-29.40662
48.07217	256.5058	-29.45996
48.12383	257.5377	-29.50787
48.17383	258.5350	-29.56238
48.22717	259.5992	-29.62541
48.27716	260.5966	-29.67614
48.32717	261.5942	-29.73402
48.38050	262.6588	-29.79985
48.43050	263.6571	-29.84781
48.48217	264.6880	-29.89588
48.53383	265.7197	-29.94763
48.58383	266.7178	-29.98456
48.63716	267.7839	-30.02915
48.68716	268.7818	-30.06630
48.73717	269.7805	-30.10476
48.79050	270.8452	-30.13789
48.84050	271.8433	-30.17912
48.89217	272.8753	-30.22420
48.94383	273.9068	-30.26613
48.99383	274.9048	-30.27789
49.04550	275.8936	-31.00748
49.09716	276.3935	-28.04010
49.14717	276.4485	-19.81854
49.19883	276.2374	-11.60166
49.25050	275.8305	-4.747319
49.30050	275.2985	0.5020310
49.35383	274.6203	4.813724
49.40383	273.9048	7.901195
49.45550	273.1065	10.35068
49.50717	272.2604	12.21614
49.55717	271.4058	13.60634
49.60883	270.4958	14.70152
49.66050	269.5630	15.56507
49.71050	268.6448	16.20383
49.76383	267.6515	16.74266
49.81383	266.7102	17.13969
49.86550	265.7270	17.47008
49.91716	264.7371	17.73209
49.96717	263.7740	17.93387
50.01883	262.7748	18.10102
50.07050	261.7710	18.24464
50.12050	260.7967	18.36017
50.17383	259.7563	18.46039
50.22383	258.7787	18.54968
50.27550	257.7656	18.61977
50.32717	256.7514	18.68566
50.37717	255.7683	18.73703
50.42883	254.7516	18.78942
50.48050	253.7343	18.83936
50.53050	252.7475	18.87963
50.58383	251.6948	18.91996
50.63383	250.7078	18.94669
50.68550	249.6854	18.97422
50.73717	248.6639	18.99786
50.78717	247.6744	19.02011
50.83883	246.6519	19.03916
50.89050	245.6289	19.05460
50.94050	244.6382	19.07404
50.99383	243.5814	19.08723
51.04383	242.5893	19.09858
51.09550	241.5650	19.10426
51.14717	240.5398	19.11063
51.19717	239.5483	19.11694
51.25050	238.4897	19.12500
51.30050	237.4985	19.13260
51.35050	236.5058	19.14261
51.40383	235.4465	19.15125
51.45383	234.4547	19.15796
51.50550	233.4281	19.16498
51.55717	232.4026	19.17178
51.60717	231.4090	19.17826
51.66050	230.3508	19.18524
51.71050	229.3573	19.19176
51.76050	228.3650	19.19853
51.81383	227.3050	19.20754
51.86383	226.3120	19.21510
51.91550	225.2859	19.22339
51.96717	224.2594	19.23168
52.01716	223.2656	19.24060
52.07050	222.2070	19.24882
52.12050	221.2132	19.25716
52.17050	220.2201	19.26490
52.22383	219.1599	19.27401
52.27383	218.1665	19.28236
52.32550	217.1404	19.29035
52.37717	216.1134	19.29943
52.42717	215.1214	19.30762
52.48050	214.0620	19.31724
52.53050	213.0676	19.32523
52.58050	212.0739	19.33355
52.63383	211.0135	19.34222
52.68383	210.0192	19.35019
52.73550	208.9923	19.35858
52.78716	207.9651	19.36640
52.83716	206.9710	19.37451
52.89050	205.9112	19.38246
52.94050	204.9166	19.39012
52.99050	203.9232	19.39745
53.04382	202.8634	19.40498
53.09384	201.8690	19.41176
53.14550	200.8416	19.41876
53.19717	199.8144	19.42571
53.24717	198.8197	19.43254
53.30050	197.7594	19.43965
53.35050	196.7646	19.44633
53.40050	195.7693	19.45262
53.45383	194.7098	19.45947
53.50383	193.7152	19.46586
53.55550	192.6882	19.47212
53.60717	191.6604	19.47848
53.65717	190.6661	19.48444
53.71050	189.6058	19.49084
53.76050	188.6112	19.49652
53.81216	187.5836	19.50225
53.86382	186.5561	19.50797
53.91382	185.5603	19.51317
53.96550	184.5325	19.51812
54.01716	183.5043	19.52301
54.06716	182.5108	19.52766
54.12050	181.4492	19.53250
54.17050	180.4540	19.53713
54.22217	179.4260	19.54188
54.27383	178.3969	19.54675
54.32383	177.4026	19.55134
54.37550	176.3745	19.55609
54.42717	175.3455	19.56110
54.47717	174.3502	19.56578
54.53050	173.2884	19.57048
54.58050	172.2934	19.57461
54.63217	171.2661	19.57860
54.68383	170.2386	19.58276
54.73383	169.2448	19.58697
54.78550	168.2172	19.59337
54.83716	167.1896	19.60434
54.88716	166.1957	19.63297
54.94050	165.1399	19.81793
54.99050	164.1533	20.15716
55.04217	163.1456	20.72956
55.09384	162.1576	21.80054
55.14384	161.2338	23.54949
55.19550	160.3248	26.26515
55.24717	159.4707	29.87637
55.29717	158.6906	33.85518
55.35050	157.8868	38.03106
55.40050	157.1314	41.35691
55.45216	156.3188	43.85852
55.50383	155.4537	45.29072
55.55383	154.5577	45.67918
55.60550	153.5703	45.22454
55.65717	152.5292	44.11431
55.70717	151.4809	42.62390
55.76050	150.3302	40.80648
55.81050	149.2338	39.04389
55.86217	148.0930	37.26504
55.91382	146.9528	35.60398
55.96382	145.8546	34.12640
56.01716	144.6885	32.68920
56.06716	143.6046	31.47392
56.11716	142.5268	30.34978
56.17050	141.3862	29.28741
56.22050	140.3243	28.38422
56.27217	139.2332	27.55175
56.32383	138.1469	26.79776
56.37383	137.1017	26.13792
56.42717	135.9919	25.49501
56.47717	134.9552	24.96147
56.52717	133.9230	24.47365
56.58050	132.8254	24.01362
56.63050	131.8011	23.60862
56.68217	130.7451	23.24501
56.73383	129.6916	22.91320
56.78383	128.6751	22.63503
56.83716	127.5920	22.35557
56.88716	126.5764	22.11104
56.93716	125.5653	21.89270
56.99050	124.4865	21.68492
57.04050	123.4783	21.51250
57.09217	122.4379	21.34732
57.14384	121.3991	21.21680
57.19384	120.3944	21.08906
57.24717	119.3234	20.98157
57.29717	118.3209	20.87948
57.34716	117.3186	20.80252
57.40050	116.2498	20.71104
57.45050	115.2489	20.63298
57.50217	114.2146	20.56071
57.55383	113.1796	20.48203
57.60383	112.1785	20.39754
57.65717	111.1118	20.31659
57.70717	110.1096	20.21232
57.75717	109.1090	20.17228
57.81050	108.0442	20.16461
57.86050	107.0470	20.15953
57.91216	106.0172	20.13524
57.96382	104.9797	19.81854
58.01382	103.9748	19.69122
58.06716	102.9035	19.57507
58.11716	101.9000	19.47897
58.16716	100.8990	19.39018
58.22050	99.82939	19.30414
58.27050	98.82681	19.22725
58.32217	97.79241	19.15241
58.37383	96.75761	19.07886
58.42383	95.75678	19.00740
58.47717	94.69040	18.93819
58.52717	93.69024	18.87562
58.57883	92.65692	18.80983
58.63050	91.62421	18.75044
58.68050	90.62426	18.69099
58.73217	89.59122	18.62054
58.78383	88.55797	18.57001
58.83383	87.55887	18.50703
58.88716	86.49031	18.44467
58.93716	85.49051	18.38049
58.98882	84.45714	18.31658
59.04050	83.42504	18.26383
59.09050	82.42408	18.20541
59.14216	81.39128	18.14394
59.19384	80.35863	18.08415
59.24382	79.35844	18.02572
59.29717	78.29306	17.97080
59.34716	77.29532	17.91488
59.39883	76.26266	17.87064
59.45050	75.23170	17.82778
59.50050	74.23340	17.78399
59.55217	73.20111	17.73520
59.60383	72.16788	17.67481
59.65383	71.16860	17.61452
59.70717	70.10249	17.55363
59.75717	69.10100	17.48686
59.80883	68.06949	17.42490
59.86050	67.03538	17.36018
59.91050	66.03581	17.30068
59.96216	65.00210	17.24343
60.01382	63.96922	17.18192
60.06382	62.96874	17.12330
60.11716	61.90282	17.05610
60.16716	60.90338	17.00183
60.21884	59.87126	16.94375
60.27050	58.83779	16.88701
60.32050	57.83830	16.82654
60.37217	56.80538	16.76562
60.42383	55.77210	16.70905
60.47382	54.77310	16.65903
60.52717	53.70666	16.60146
60.57717	52.70666	16.54582
60.62883	51.67377	16.48551
60.68050	50.64079	16.41884
60.73050	49.64227	16.36019
60.78383	48.57466	16.30231
60.83383	47.57664	16.24652
60.88383	46.57597	16.19374
60.93716	45.50810	16.12849
60.98717	44.50782	16.06785
61.03882	43.47432	16.00646
61.09050	42.44067	15.93935
61.14050	41.44100	15.85993
61.19384	40.37389	15.80336
61.24382	39.37301	15.73452
61.29382	38.37325	15.66021
61.34716	37.30485	15.57399
61.39717	36.30436	15.49458
61.44883	35.26835	15.40544
61.50050	34.23369	15.31309
61.55050	33.23152	15.23491
61.60383	32.16283	15.13869
61.65383	31.15996	15.05056
61.70383	30.15795	14.97145
61.75717	29.08719	14.88132
61.80717	28.08461	14.78851
61.85883	27.04802	14.69801
61.91050	26.01142	14.60045
61.96050	25.00770	14.56132
62.01050	24.00430	14.56967
62.06050	23.10162	14.96184
62.11217	22.69434	9.879181
62.16382	22.66206	4.348160
62.21382	22.89830	-.07474676
62.26716	23.35622	-3.565440
62.31716	23.92897	-6.023048
62.36716	24.60290	-7.872330
62.42050	25.40504	-9.361772
62.47050	26.21364	-10.41586
62.52217	27.09187	-11.26988
62.57383	28.00296	-11.93062
62.62383	28.90722	-12.43981
62.67717	29.89121	-12.86886
62.72717	30.82484	-13.19469
62.77883	31.80303	-13.48854
62.83050	32.78792	-13.72871
62.88050	33.74836	-13.92136
62.93217	34.74536	-14.09952
62.98383	35.74712	-14.25787
63.03383	36.71910	-14.39878
63.08716	37.75904	-14.53648
63.13716	38.73638	-14.65453
63.18882	39.74628	-14.76480
63.24050	40.76075	-14.86324
63.29050	41.74234	-14.95907
63.34217	42.75908	-15.06431
63.39384	43.77611	-15.15058
63.44384	44.76244	-15.24022
63.49717	45.81490	-15.32571
63.54717	46.80294	-15.41178
63.59882	47.82534	-15.49522
63.65050	48.84798	-15.56965
63.70050	49.83754	-15.65886
63.75217	50.86013	-15.74412
63.80383	51.88421	-15.82714
63.85383	52.87412	-15.90334
63.90718	53.93162	-15.99504
63.95717	54.92362	-16.07630
64.00884	55.94785	-16.15996
64.06050	56.97286	-16.24255
64.11050	57.96532	-16.32925
64.16217	58.99003	-16.41284
64.21384	60.01443	-16.49585
64.26384	61.00732	-16.58768
64.31717	62.06540	-16.67987
64.36718	63.05849	-16.77191
64.41884	64.08504	-16.84960
64.47050	65.11230	-16.92691
64.52050	66.10708	-17.00639
64.57218	67.13449	-17.09870
64.62383	68.16168	-17.17972
64.67383	69.15581	-17.26542
64.72718	70.21626	-17.35533
64.77717	71.21001	-17.43779
64.82885	72.23726	-17.52990
64.88050	73.26456	-17.62008
64.93050	74.25844	-17.70443
64.98383	75.31943	-17.78893
65.03384	76.31319	-17.88560
65.08384	77.30746	-17.98352
65.13717	78.36770	-18.07652
65.18717	79.36161	-18.16574
65.23882	80.38950	-18.25756
65.29050	81.41762	-18.34748
65.34050	82.41155	-18.43675
65.39384	83.47532	-18.53096
65.44384	84.46915	-18.62053
65.49384	85.46446	-18.72275
65.54718	86.52630	-18.82498
65.59718	87.51984	-18.92067
65.64884	88.54829	-19.02209
65.70050	89.57576	-19.12562
65.75050	90.57103	-19.22824
65.80384	91.63172	-19.32922
65.85384	92.62528	-19.42911
65.90384	93.62024	-19.52906
65.95718	94.68055	-19.63568
66.00718	95.67622	-19.74082
66.05884	96.70497	-19.83930
66.11050	97.73264	-19.93123
66.16050	98.72772	-20.02632
66.21384	99.78911	-20.13775
66.26384	100.7837	-20.24262
66.31384	101.7785	-20.34753
66.36718	102.8391	-20.45088
66.41718	103.8330	-20.54855
66.46884	104.8611	-20.66272
66.52050	105.8874	-20.77489
66.57050	106.8821	-20.88651
66.62384	107.9431	-20.99828
66.67384	108.9372	-21.10612
66.72384	109.9324	-21.20256
66.77718	110.9928	-21.32078
66.82718	111.9876	-21.42455
66.87884	113.0157	-21.53488
66.93050	114.0432	-21.64744
66.98050	115.0378	-21.75316
67.03384	116.0999	-21.77980
67.08384	117.0987	-21.79538
67.13384	118.0959	-21.82490
67.18718	119.1617	-21.90110
67.23718	120.1582	-21.99556
67.28882	121.1871	-22.11140
67.34050	122.2170	-22.22000
67.39050	123.2119	-22.31033
67.44384	124.2740	-22.41206
67.49384	125.2705	-22.51297
67.54550	126.2989	-22.62410
67.59718	127.3280	-22.72108
67.64718	128.3236	-22.82524
67.69884	129.3521	-22.93527
67.75050	130.3797	-23.04479
67.80050	131.3751	-23.16074
67.85384	132.4361	-23.27172
67.90384	133.4313	-23.38489
67.95550	134.4581	-23.50356
68.00718	135.4862	-23.63614
68.05718	136.4783	-23.76885
68.10884	137.5058	-23.89297
68.16050	138.5322	-24.02285
68.21050	139.5269	-24.14180
68.26384	140.5864	-24.28210
68.31384	141.5813	-24.38820
68.36550	142.6096	-24.47737
68.41718	143.6387	-24.55362
68.46718	144.6342	-24.64391
68.51882	145.6625	-24.75276
68.57050	146.6908	-24.87174
68.62050	147.6857	-24.92133
68.67384	148.7506	-24.96640
68.72384	149.7469	-25.05582
68.77550	150.7766	-25.15504
68.82718	151.8066	-25.24718
68.87718	152.8023	-25.35763
68.92884	153.8320	-25.46383
68.98050	154.8609	-25.56625
69.03050	155.8564	-25.66751
69.08384	156.9187	-25.78396
69.13384	157.9142	-25.87152
69.18550	158.9438	-25.95856
69.23718	159.9721	-26.03017
69.28718	160.9698	-26.09490
69.33884	162.0014	-26.14129
69.39050	163.0331	-26.18706
69.44050	164.0312	-26.23646
69.49384	165.0965	-26.30033
69.54384	166.0937	-26.38190
69.59550	167.1238	-26.48370
69.64718	168.1528	-26.59346
69.69718	169.1489	-26.70822
69.75050	170.2094	-26.84543
69.80050	171.2041	-26.98611
69.85050	172.1979	-27.14768
69.90384	173.2569	-27.32356
69.95384	174.2492	-27.49541
70.00550	175.2733	-27.69169
70.05718	176.2969	-27.91047
70.10718	177.2843	-28.14804
70.16050	178.3373	-28.43768
70.21050	179.3221	-28.72156
70.26050	180.3052	-29.04325
70.31384	181.3532	-29.42112
70.36384	182.3332	-29.80812
70.41550	183.3440	-30.24885
70.46718	184.3524	-30.73177
70.51716	185.3258	-31.22833
70.57050	186.3615	-31.81562
70.62050	187.3316	-32.40707
70.67050	188.2971	-33.04822
70.72384	189.3257	-33.76430
70.77384	190.2855	-34.47000
70.82550	191.2767	-35.22638
70.87718	192.2652	-35.99364
70.92718	193.2212	-36.76699
70.98050	194.2394	-37.62318
71.03050	195.1924	-38.48800
71.08050	196.1412	-39.40794
71.13384	197.1507	-40.46808
71.18384	198.0921	-41.51066
71.23550	199.0629	-42.63413
71.28718	200.0306	-43.75662
71.33716	200.9673	-44.79774
71.39050	201.9714	-45.74277
71.44050	202.9216	-46.34803
71.49050	203.8881	-46.50777
71.54384	204.9468	-46.12570
71.59384	205.9793	-44.45403
71.64550	207.1044	-41.73536
71.69718	208.2885	-38.19654
71.74718	209.4698	-34.98056
71.80050	210.7189	-32.65642
71.85050	211.8552	-31.19628
71.90050	212.9595	-30.14776
71.95384	214.1094	-29.33033
72.00384	215.1675	-28.76489
72.05550	216.2461	-28.32434
72.10718	217.3132	-28.02515
72.15718	218.3372	-27.79768
72.21050	219.4223	-27.63867
72.26050	220.4344	-27.53209
72.31216	221.4775	-27.47961
72.36384	222.5160	-27.44800
72.41382	223.5200	-27.43674
72.46550	224.5566	-27.43375
72.51716	225.5906	-27.43234
72.56718	226.5920	-27.43314
72.62050	227.6585	-27.43573
72.67050	228.6582	-27.44864
72.72218	229.6908	-27.48406
72.77384	230.7218	-27.53162
72.82384	231.7207	-27.58758
72.87550	232.7533	-27.65810
72.92718	233.7848	-27.70661
72.97718	234.7844	-27.75257
73.03050	235.8508	-27.79883
73.08050	236.8496	-27.83474
73.13218	237.8837	-27.87454
73.18384	238.9145	-27.90670
73.23384	239.9135	-27.96411
73.28550	240.9443	-28.01516
73.33716	241.9768	-28.08625
73.38718	242.9746	-28.14334
73.44050	244.0394	-28.19549
73.49050	245.0380	-28.24545
73.54218	246.0687	-28.32664
73.59384	247.1000	-28.36126
73.64384	248.0992	-28.40769
73.69550	249.1314	-28.45573
73.74718	250.1632	-28.50070
73.79718	251.1630	-28.54776
73.85050	252.2275	-28.59540
73.90050	253.2270	-28.64803
73.95216	254.2580	-28.69500
74.00384	255.2908	-28.74750
74.05384	256.2890	-28.80836
74.10550	257.3204	-28.86382
74.15718	258.3509	-28.92896
74.20718	259.3480	-28.99750
74.26050	260.4122	-29.06422
74.31050	261.4092	-29.12592
74.36218	262.4392	-29.20218
74.41382	263.4717	-29.25737
74.46384	264.4700	-29.31435
74.51716	265.5342	-29.36955
74.56718	266.5329	-29.43733
74.61718	267.5302	-29.49565
74.67050	268.5942	-29.56490
74.72050	269.5920	-29.62784
74.77218	270.6228	-29.68862
74.82384	271.6540	-29.74244
-2.000000	5.000000	0.0000000