File: 5-C1(1.4mol%)+C20(0.6mol%)/matlab/170-2.txt
CLOSED
Version	1.0
Language	English
Mode	Standard
Run	26
RunSerial	12328
Instrument	DSC Q2000 V24.11 Build 124
Module	DSC Standard Cell RC
Operator
File	\\AE520-1454\Users\dsc\Desktop\Data\31-08-17-2\170-2.001
ProcName
InstSerial	2000-0883
AutoSerial	1293
Sample	170-2
Size	23.5000	mg
PanMass	Not available
PanResist	Automatic Automatic  K/W
PanFactor	Default Default
Method
Comment
Xcomment	Pan: Tzero Aluminum Hermetic
Xcomment	Gas1: Nitrogen 50.0 ml/min
Xcomment	Gas2: Nitrogen 50.0 ml/min
Text
Exotherm	UP
Kcell	1.05230
Cpconst	Standard: 0.938
Calib	-38.6961
TempCal	1	pts	157.46	156.60
TzeroDt	-87.6168 -0.0009 -1.4231
TzeroDtz	-87.6168 0.0057 6.9570
InstCalFile	Tzero: \\Ae520-1454\ta\Data\DSC\Calibration\2017\CALIBRATION\1562_RCS (90)_05_18_2017 10_50_44.TZR
InstCalFile	Baseline: \\Ae520-1454\ta\Data\DSC\Calibration\2017\2017-05-17_Calibration.001
InstCalFile	Sapphire: \\Ae520-1454\ta\Data\DSC\Calibration\2017\2017-05-17_Saphire.001
InstCalDate	Tzero 2017-05-18 Time 10:50:44
TempRange	-87.39 to 398.39 °C at 10.00 °C/min Heat Only
AutoZero	Delta T Offset 0.000 uV
AutoZero	Delta T0 Offset 0.000 uV
MultiptCal	0
MultiPtDesc	0) Not set
AutoCellConst	Calibration Date 2017-05-18 16:59:28
Controls	Gas 1  Event Off  Sampling 0.2
Cell#	RC-01562
CoolingUnit	RCS (90)
SelHeatFlow	Heat Flow T4P (mW)
AutoLidII	Installed
AutoAnalysis	Off
MacroFile
Nsig	3
Sig1	Time (min)
Sig2	Temperature (°C)
Sig3	Heat Flow (mW)
Date	2017-09-01
Time	19:48:44
OrgMethod	1: Equilibrate at 80.00 °C
OrgMethod	2: Isothermal for 3.00 min
OrgMethod	3: Jump to 170.00 °C
OrgMethod	4: Mark end of cycle 1
OrgMethod	5: Isothermal for 40.00 min
OrgMethod	6: Mark end of cycle 2
OrgMethod	7: Ramp 20.00 °C/min to 280.00 °C
OrgMethod	8: Mark end of cycle 3
OrgMethod	9: Ramp 20.00 °C/min to 20.00 °C
OrgMethod	10: Mark end of cycle 4
OrgMethod	11: Ramp 20.00 °C/min to 280.00 °C
OrgMethod	12: Mark end of cycle 5
OrgFile	C:\Users\jarra\Desktop\DSC\5-C1(1.4mol%)+C20(0.6mol%)\170-2.001
StartOfData
4.99994E-4	79.58115	-5.002219
0.05383332	79.65738	-3.994789
0.1038333	79.71140	-3.265152
0.1538333	79.75461	-2.691785
0.2055000	79.78840	-2.231848
0.2571667	79.81366	-1.875273
0.3071666	79.83434	-1.606246
0.3571666	79.84860	-1.396008
0.4105000	79.86144	-1.228936
0.4605000	79.86934	-1.105930
0.5105000	79.87442	-1.011153
0.5621668	79.88050	-0.9413851
0.6138334	79.88301	-0.8824805
0.6638332	79.88624	-0.8446476
0.7138332	79.88750	-0.8155582
0.7655000	79.88902	-0.7941372
0.8171668	79.88964	-0.7795380
0.8671666	79.89068	-0.7706855
0.9171668	79.89028	-0.7643180
0.9705000	79.88938	-0.7601519
1.020500	79.88972	-0.7567747
1.070500	79.88984	-0.7532407
1.122166	79.88880	-0.7495513
1.173834	79.88826	-0.7459430
1.223833	79.88825	-0.7425757
1.273834	79.88740	-0.7393720
1.325500	79.88609	-0.7362156
1.377166	79.88636	-0.7333342
1.427167	79.88556	-0.7307010
1.477166	79.88470	-0.7283318
1.530500	79.88484	-0.7259057
1.580500	79.88489	-0.7238684
1.630500	79.88276	-0.7219274
1.682167	79.88250	-0.7201697
1.733833	79.88166	-0.7185852
1.783833	79.88199	-0.7172138
1.833833	79.88080	-0.7159876
1.885500	79.88022	-0.7149009
1.937166	79.88042	-0.7139747
1.987166	79.87944	-0.7131988
2.037166	79.87871	-0.7126460
2.090500	79.87751	-0.7120893
2.140500	79.87795	-0.7117616
2.190500	79.87822	-0.7115214
2.242166	79.87686	-0.7113570
2.293833	79.87610	-0.7112343
2.343834	79.87561	-0.7112182
2.393833	79.87603	-0.7113006
2.447166	79.87585	-0.7114696
2.497166	79.87434	-0.7116930
2.547166	79.87384	-0.7119968
2.598834	79.87436	-0.7123552
2.650500	79.87385	-0.7128006
2.700500	79.87305	-0.7132880
2.750500	79.87250	-0.7138849
2.802166	79.87224	-0.7144878
2.853833	79.87188	-0.7152054
2.903833	79.87146	-0.7158900
2.953833	79.87050	-0.7165784
3.000500	79.87030	-0.7173321
3.053833	80.29768	-6.292087
3.103833	82.24472	-19.03970
3.153833	84.82169	-30.09516
3.205500	87.95309	-41.08376
3.257167	91.44903	-50.94888
3.307167	95.09829	-59.25626
3.357167	98.94709	-66.34120
3.410500	103.2172	-72.70245
3.460500	107.3349	-77.63641
3.510500	111.5334	-81.71222
3.562167	115.9299	-85.19672
3.613834	120.3600	-88.22039
3.663833	124.6700	-90.63024
3.713833	128.9931	-92.59900
3.765500	133.4678	-94.27044
3.817166	137.9499	-95.56322
3.867166	142.2916	-96.42406
3.917167	146.6400	-96.89962
3.970500	151.2746	-97.02930
4.020500	155.2752	-93.34238
4.070500	158.0438	-82.09770
4.122166	160.1793	-70.55372
4.173834	161.8487	-59.13808
4.223834	163.1351	-49.23606
4.273834	164.1771	-40.65048
4.325500	165.0570	-33.16828
4.377167	165.7760	-26.98580
4.427166	166.3523	-22.08078
4.477167	166.8348	-18.05654
4.530500	167.2635	-14.55940
4.580500	167.6041	-11.87869
4.630500	167.8948	-9.653572
4.682167	168.1516	-7.738653
4.733834	168.3758	-6.128584
4.783834	168.5625	-4.791559
4.833834	168.7278	-3.627977
4.885500	168.8807	-2.557356
4.937167	169.0180	-1.584214
4.987167	169.1367	-0.7057040
5.037167	169.2479	0.1329092
5.090500	169.3570	0.9998856
5.140500	169.4523	1.807506
5.190500	169.5444	2.619581
5.242167	169.6359	3.474178
5.293832	169.7257	4.355786
5.343834	169.8092	5.244818
5.393832	169.8941	6.163660
5.447168	169.9832	7.187771
5.497168	170.0657	8.179478
5.547168	170.1501	9.198316
5.598832	170.2343	10.25091
5.650500	170.3159	11.28550
5.700500	170.3900	12.22622
5.750500	170.4594	13.08154
5.802168	170.5210	13.83014
5.853832	170.5724	14.41638
5.903834	170.6099	14.82026
5.953832	170.6367	15.06914
6.007168	170.6547	15.18224
6.057168	170.6620	15.18257
6.107168	170.6646	15.14558
6.158832	170.6618	15.03080
6.210500	170.6562	14.77852
6.260500	170.6488	14.57958
6.310500	170.6413	14.38826
6.362168	170.6334	14.20802
6.413832	170.6267	14.04271
6.463834	170.6209	13.91442
6.513834	170.6163	13.80627
6.567168	170.6135	13.72239
6.617166	170.6117	13.67159
6.667168	170.6121	13.64600
6.718832	170.6145	13.63946
6.770500	170.6181	13.63991
6.820500	170.6239	13.65916
6.870500	170.6313	13.75989
6.922168	170.6415	13.92883
6.973834	170.6533	14.11180
7.023834	170.6674	14.31335
7.073834	170.6819	14.54618
7.127168	170.7006	14.81776
7.177168	170.7185	15.10100
7.227168	170.7388	15.40446
7.278832	170.7615	15.72900
7.330500	170.7834	16.06101
7.380500	170.8047	16.38361
7.430500	170.8264	16.69139
7.483832	170.8467	17.00118
7.533832	170.8658	17.25847
7.583832	170.8808	17.47960
7.635500	170.8952	17.65744
7.687168	170.9051	17.77694
7.737168	170.9108	17.83775
7.787168	170.9123	17.85143
7.838834	170.9109	17.84314
7.890500	170.9049	17.73872
7.940500	170.8934	17.48562
7.990500	170.8793	17.21468
8.043834	170.8594	16.87079
8.093832	170.8375	16.49982
8.143832	170.8112	16.07921
8.195500	170.7812	15.60189
8.247168	170.7498	15.08323
8.297168	170.7170	14.55130
8.347168	170.6809	13.99846
8.398834	170.6446	13.41532
8.450500	170.6068	12.82532
8.500500	170.5719	12.25242
8.550500	170.5354	11.68909
8.603832	170.4977	11.10296
8.653832	170.4636	10.57320
8.703834	170.4308	10.06628
8.755500	170.3986	9.572364
8.807168	170.3697	9.115592
8.857166	170.3425	8.704094
8.907166	170.3181	8.336655
8.958832	170.2961	8.001570
9.010499	170.2773	7.714291
9.060500	170.2620	7.488353
9.110500	170.2502	7.314360
9.163834	170.2398	7.179078
9.213834	170.2342	7.099657
9.263832	170.2319	7.068976
9.315500	170.2320	7.066861
9.367166	170.2342	7.070700
9.417168	170.2409	7.132290
9.467168	170.2480	7.298434
9.520500	170.2576	7.481581
9.570500	170.2689	7.655390
9.620499	170.2804	7.845535
9.672168	170.2939	8.049152
9.723832	170.3063	8.261139
9.773834	170.3206	8.457512
9.823834	170.3338	8.655030
9.875500	170.3461	8.845181
9.927168	170.3581	9.015247
9.977168	170.3684	9.160811
10.02717	170.3766	9.280514
10.08050	170.3840	9.373389
10.13050	170.3880	9.428589
10.18050	170.3905	9.447950
10.23217	170.3884	9.448272
10.28383	170.3856	9.433891
10.33383	170.3798	9.309106
10.38383	170.3702	9.105186
10.43550	170.3573	8.877382
10.48717	170.3415	8.610709
10.53717	170.3236	8.315118
10.58717	170.3022	7.978266
10.64050	170.2765	7.590024
10.69050	170.2530	7.187329
10.74050	170.2255	6.758859
10.79217	170.1960	6.297610
10.84383	170.1655	5.817578
10.89383	170.1355	5.344500
10.94383	170.1052	4.869261
10.99550	170.0745	4.378672
11.04717	170.0443	3.895535
11.09717	170.0150	3.442518
11.14717	169.9854	3.002640
11.20050	169.9569	2.553561
11.25050	169.9318	2.155047
11.30050	169.9073	1.782171
11.35217	169.8823	1.421051
11.40383	169.8620	1.085557
11.45384	169.8410	0.7926722
11.50384	169.8226	0.5202668
11.55717	169.8059	0.2552666
11.60717	169.7904	0.03689728
11.65717	169.7777	-0.1621591
11.70883	169.7646	-0.3476767
11.76050	169.7539	-0.5114021
11.81050	169.7442	-0.6533954
11.86050	169.7351	-0.7818765
11.91217	169.7278	-0.8979121
11.96383	169.7212	-1.001659
12.01383	169.7148	-1.092017
12.06383	169.7090	-1.170244
12.11716	169.7044	-1.246780
12.16717	169.7008	-1.309714
12.21717	169.6969	-1.367551
12.26883	169.6927	-1.422236
12.32050	169.6899	-1.472661
12.37050	169.6867	-1.514677
12.42050	169.6849	-1.553165
12.47217	169.6816	-1.589038
12.52383	169.6799	-1.620569
12.57383	169.6773	-1.647705
12.62383	169.6754	-1.675254
12.67717	169.6738	-1.703041
12.72717	169.6710	-1.725412
12.77717	169.6694	-1.747167
12.82883	169.6681	-1.768410
12.88050	169.6660	-1.787949
12.93050	169.6649	-1.806492
12.98050	169.6642	-1.824689
13.03217	169.6623	-1.842273
13.08383	169.6607	-1.857124
13.13383	169.6599	-1.871970
13.18383	169.6583	-1.885733
13.23716	169.6573	-1.901584
13.28717	169.6555	-1.913002
13.33717	169.6560	-1.925428
13.38883	169.6543	-1.937305
13.44050	169.6528	-1.948911
13.49050	169.6521	-1.961859
13.54050	169.6517	-1.971875
13.59383	169.6508	-1.983067
13.64383	169.6504	-1.992589
13.69384	169.6496	-2.002981
13.74550	169.6500	-2.014222
13.79717	169.6499	-2.023470
13.84717	169.6487	-2.032834
13.89717	169.6482	-2.041700
13.94884	169.6482	-2.050764
14.00050	169.6466	-2.059704
14.05050	169.6459	-2.068389
14.10050	169.6467	-2.077224
14.15383	169.6456	-2.086561
14.20383	169.6442	-2.095314
14.25383	169.6454	-2.104080
14.30550	169.6439	-2.112994
14.35716	169.6442	-2.121875
14.40717	169.6435	-2.130370
14.45717	169.6426	-2.138908
14.50883	169.6425	-2.147633
14.56050	169.6426	-2.156381
14.61050	169.6419	-2.164720
14.66050	169.6416	-2.172968
14.71383	169.6401	-2.181736
14.76383	169.6406	-2.189886
14.81383	169.6392	-2.197850
14.86550	169.6398	-2.206049
14.91716	169.6383	-2.214078
14.96716	169.6388	-2.221721
15.01717	169.6378	-2.229270
15.06884	169.6372	-2.236966
15.12050	169.6370	-2.244576
15.17050	169.6364	-2.251890
15.22050	169.6364	-2.259135
15.27383	169.6352	-2.266608
15.32384	169.6352	-2.273512
15.37384	169.6351	-2.280372
15.42550	169.6346	-2.287306
15.47717	169.6348	-2.294205
15.52717	169.6338	-2.300820
15.57717	169.6336	-2.307259
15.63050	169.6336	-2.314026
15.68050	169.6332	-2.320466
15.73050	169.6330	-2.326785
15.78217	169.6319	-2.333095
15.83383	169.6316	-2.339417
15.88383	169.6308	-2.346182
15.93383	169.6310	-2.352479
15.98550	169.6299	-2.358790
16.03717	169.6304	-2.364944
16.08716	169.6305	-2.370682
16.13716	169.6297	-2.376266
16.19050	169.6294	-2.382168
16.24050	169.6299	-2.387482
16.29050	169.6294	-2.392717
16.34216	169.6291	-2.397955
16.39383	169.6286	-2.402992
16.44383	169.6290	-2.407824
16.49383	169.6291	-2.412471
16.54550	169.6288	-2.417192
16.59716	169.6284	-2.421805
16.64716	169.6281	-2.426252
16.69716	169.6282	-2.430669
16.75050	169.6281	-2.435377
16.80050	169.6284	-2.439802
16.85050	169.6284	-2.444209
16.90216	169.6290	-2.448620
16.95383	169.6283	-2.452967
17.00383	169.6291	-2.457083
17.05383	169.6283	-2.461062
17.10550	169.6278	-2.465080
17.15716	169.6287	-2.469090
17.20716	169.6288	-2.472905
17.25716	169.6281	-2.476650
17.31050	169.6284	-2.480648
17.36050	169.6290	-2.484264
17.41050	169.6275	-2.487651
17.46216	169.6279	-2.491177
17.51383	169.6286	-2.494570
17.56383	169.6278	-2.497710
17.61383	169.6280	-2.500688
17.66716	169.6262	-2.503727
17.71716	169.6262	-2.506460
17.76716	169.6265	-2.509247
17.81883	169.6256	-2.511976
17.87050	169.6249	-2.514688
17.92050	169.6256	-2.517321
17.97050	169.6252	-2.519940
18.02216	169.6256	-2.522588
18.07383	169.6245	-2.525125
18.12383	169.6248	-2.527633
18.17383	169.6255	-2.530077
18.22716	169.6245	-2.532655
18.27716	169.6240	-2.535086
18.32716	169.6243	-2.537514
18.37883	169.6241	-2.539986
18.43050	169.6242	-2.542430
18.48050	169.6246	-2.544819
18.53050	169.6237	-2.547112
18.58216	169.6236	-2.549520
18.63383	169.6240	-2.551883
18.68383	169.6241	-2.554156
18.73383	169.6242	-2.556364
18.78717	169.6239	-2.558642
18.83716	169.6236	-2.560750
18.88716	169.6238	-2.562870
18.93883	169.6226	-2.564958
18.99050	169.6232	-2.567024
19.04050	169.6234	-2.568940
19.09050	169.6235	-2.570792
19.14216	169.6237	-2.572658
19.19383	169.6224	-2.574500
19.24383	169.6224	-2.576320
19.29383	169.6226	-2.578216
19.34716	169.6231	-2.580265
19.39716	169.6228	-2.582087
19.44716	169.6232	-2.584013
19.49883	169.6241	-2.585910
19.55050	169.6236	-2.587774
19.60050	169.6239	-2.589538
19.65050	169.6243	-2.591257
19.70383	169.6238	-2.593002
19.75383	169.6239	-2.594617
19.80383	169.6240	-2.596108
19.85550	169.6226	-2.597591
19.90716	169.6238	-2.599086
19.95716	169.6234	-2.600449
20.00716	169.6238	-2.601747
20.05883	169.6227	-2.602985
20.11050	169.6226	-2.604240
20.16050	169.6220	-2.605463
20.21050	169.6216	-2.606697
20.26383	169.6218	-2.607958
20.31383	169.6228	-2.609140
20.36383	169.6226	-2.610363
20.41550	169.6223	-2.611572
20.46716	169.6222	-2.612835
20.51716	169.6224	-2.614116
20.56716	169.6229	-2.615320
20.61883	169.6227	-2.616635
20.67050	169.6228	-2.617968
20.72050	169.6232	-2.619290
20.77050	169.6232	-2.620686
20.82383	169.6224	-2.622218
20.87383	169.6236	-2.623620
20.92383	169.6230	-2.624934
20.97550	169.6238	-2.626326
21.02717	169.6231	-2.627628
21.07716	169.6234	-2.628788
21.12716	169.6227	-2.629969
21.17883	169.6233	-2.631105
21.23050	169.6225	-2.632088
21.28050	169.6230	-2.633042
21.33050	169.6230	-2.633920
21.38383	169.6228	-2.634790
21.43383	169.6221	-2.635672
21.48383	169.6219	-2.636598
21.53550	169.6226	-2.637621
21.58716	169.6224	-2.638585
21.63716	169.6225	-2.639503
21.68716	169.6225	-2.640382
21.74050	169.6225	-2.641332
21.79050	169.6215	-2.642260
21.84050	169.6223	-2.643197
21.89216	169.6220	-2.644112
21.94383	169.6227	-2.644953
21.99383	169.6212	-2.645714
22.04383	169.6222	-2.646498
22.09550	169.6222	-2.647317
22.14716	169.6229	-2.648096
22.19716	169.6217	-2.648896
22.24716	169.6226	-2.649737
22.30050	169.6218	-2.650630
22.35050	169.6222	-2.651420
22.40050	169.6219	-2.652178
22.45216	169.6224	-2.652928
22.50383	169.6220	-2.653614
22.55383	169.6219	-2.654290
22.60383	169.6220	-2.655016
22.65550	169.6215	-2.655693
22.70717	169.6220	-2.656380
22.75716	169.6221	-2.657099
22.80716	169.6224	-2.657666
22.86050	169.6221	-2.658303
22.91050	169.6214	-2.658796
22.96050	169.6214	-2.659313
23.01216	169.6209	-2.659853
23.06383	169.6205	-2.660534
23.11383	169.6210	-2.661253
23.16383	169.6216	-2.661996
23.21550	169.6210	-2.662714
23.26716	169.6205	-2.663407
23.31716	169.6211	-2.664064
23.36716	169.6215	-2.664614
23.42050	169.6210	-2.665182
23.47050	169.6221	-2.665657
23.52050	169.6222	-2.666258
23.57216	169.6206	-2.666866
23.62383	169.6214	-2.667600
23.67383	169.6214	-2.668300
23.72383	169.6208	-2.669040
23.77717	169.6216	-2.669792
23.82716	169.6212	-2.670508
23.87716	169.6218	-2.671217
23.92883	169.6217	-2.671871
23.98050	169.6214	-2.672392
24.03050	169.6204	-2.672842
24.08050	169.6204	-2.673172
24.13216	169.6209	-2.673516
24.18383	169.6193	-2.673749
24.23383	169.6194	-2.674076
24.28383	169.6202	-2.674437
24.33716	169.6202	-2.674794
24.38716	169.6199	-2.675174
24.43716	169.6195	-2.675494
24.48883	169.6189	-2.675838
24.54050	169.6199	-2.676265
24.59050	169.6197	-2.676731
24.64050	169.6198	-2.677259
24.69216	169.6203	-2.677868
24.74383	169.6202	-2.678488
24.79383	169.6200	-2.679020
24.84383	169.6193	-2.679678
24.89716	169.6201	-2.680322
24.94716	169.6201	-2.680838
24.99716	169.6199	-2.681330
25.04883	169.6199	-2.681770
25.10050	169.6200	-2.682248
25.15050	169.6198	-2.682634
25.20050	169.6195	-2.683006
25.25217	169.6207	-2.683500
25.30383	169.6199	-2.683985
25.35383	169.6202	-2.684514
25.40383	169.6205	-2.685060
25.45717	169.6210	-2.685716
25.50716	169.6206	-2.686312
25.55716	169.6208	-2.686924
25.60883	169.6210	-2.687524
25.66050	169.6209	-2.688094
25.71050	169.6209	-2.688594
25.76050	169.6216	-2.689028
25.81383	169.6213	-2.689472
25.86383	169.6214	-2.689789
25.91383	169.6213	-2.690163
25.96550	169.6215	-2.690564
26.01716	169.6208	-2.690818
26.06716	169.6214	-2.691062
26.11716	169.6218	-2.691318
26.16883	169.6212	-2.691662
26.22050	169.6216	-2.691971
26.27050	169.6213	-2.692242
26.32050	169.6219	-2.692538
26.37383	169.6208	-2.692766
26.42383	169.6208	-2.692980
26.47383	169.6206	-2.693166
26.52550	169.6205	-2.693360
26.57717	169.6208	-2.693568
26.62716	169.6203	-2.693736
26.67717	169.6196	-2.693837
26.72883	169.6198	-2.693976
26.78050	169.6198	-2.694077
26.83050	169.6202	-2.694260
26.88050	169.6194	-2.694401
26.93383	169.6189	-2.694626
26.98383	169.6196	-2.694845
27.03383	169.6194	-2.695024
27.08550	169.6195	-2.695284
27.13716	169.6186	-2.695433
27.18717	169.6183	-2.695672
27.23716	169.6183	-2.695836
27.28883	169.6188	-2.696104
27.34050	169.6183	-2.696312
27.39050	169.6193	-2.696459
27.44050	169.6188	-2.696753
27.49383	169.6187	-2.697162
27.54383	169.6191	-2.697594
27.59383	169.6191	-2.698133
27.64550	169.6198	-2.698673
27.69717	169.6203	-2.699188
27.74716	169.6201	-2.699700
27.79716	169.6202	-2.700250
27.85050	169.6201	-2.700685
27.90050	169.6209	-2.701094
27.95050	169.6202	-2.701339
28.00217	169.6204	-2.701605
28.05383	169.6213	-2.701859
28.10383	169.6208	-2.702018
28.15383	169.6203	-2.702211
28.20550	169.6211	-2.702537
28.25716	169.6212	-2.702857
28.30716	169.6215	-2.703194
28.35716	169.6214	-2.703526
28.41050	169.6217	-2.703780
28.46050	169.6203	-2.703980
28.51050	169.6213	-2.704244
28.56217	169.6213	-2.704398
28.61383	169.6211	-2.704394
28.66383	169.6204	-2.704364
28.71383	169.6201	-2.704337
28.76550	169.6206	-2.704268
28.81716	169.6196	-2.704209
28.86716	169.6201	-2.704260
28.91716	169.6208	-2.704399
28.97050	169.6204	-2.704626
29.02050	169.6207	-2.704844
29.07050	169.6198	-2.705066
29.12216	169.6205	-2.705341
29.17383	169.6212	-2.705590
29.22383	169.6202	-2.705738
29.27383	169.6206	-2.705890
29.32550	169.6203	-2.706082
29.37716	169.6207	-2.706343
29.42717	169.6199	-2.706522
29.47717	169.6213	-2.706726
29.53050	169.6194	-2.706886
29.58050	169.6204	-2.707028
29.63050	169.6201	-2.707148
29.68216	169.6198	-2.707371
29.73383	169.6201	-2.707586
29.78383	169.6199	-2.707668
29.83383	169.6193	-2.707774
29.88716	169.6189	-2.707791
29.93717	169.6192	-2.707878
29.98716	169.6188	-2.707886
30.03883	169.6194	-2.708055
30.09050	169.6188	-2.708118
30.14050	169.6194	-2.708199
30.19050	169.6192	-2.708328
30.24216	169.6192	-2.708502
30.29383	169.6199	-2.708680
30.34383	169.6199	-2.708880
30.39383	169.6198	-2.709122
30.44717	169.6189	-2.709406
30.49716	169.6202	-2.709817
30.54716	169.6203	-2.710133
30.59883	169.6202	-2.710411
30.65050	169.6196	-2.710648
30.70050	169.6209	-2.710812
30.75050	169.6199	-2.710879
30.80217	169.6201	-2.710862
30.85383	169.6197	-2.710865
30.90383	169.6201	-2.710904
30.95383	169.6199	-2.710998
31.00716	169.6193	-2.711160
31.05716	169.6192	-2.711312
31.10716	169.6202	-2.711531
31.15883	169.6191	-2.711740
31.21050	169.6193	-2.711976
31.26050	169.6193	-2.712140
31.31050	169.6195	-2.712264
31.36216	169.6194	-2.712432
31.41383	169.6196	-2.712574
31.46383	169.6195	-2.712622
31.51383	169.6194	-2.712700
31.56716	169.6194	-2.712828
31.61716	169.6198	-2.713032
31.66716	169.6194	-2.713325
31.71883	169.6202	-2.713689
31.77050	169.6207	-2.714010
31.82050	169.6204	-2.714308
31.87050	169.6202	-2.714544
31.92383	169.6202	-2.714869
31.97383	169.6199	-2.715111
32.02383	169.6208	-2.715432
32.07550	169.6208	-2.715598
32.12717	169.6208	-2.715770
32.17717	169.6208	-2.715873
32.22717	169.6209	-2.715946
32.27883	169.6208	-2.715945
32.33050	169.6201	-2.715991
32.38050	169.6202	-2.716017
32.43050	169.6201	-2.716070
32.48383	169.6202	-2.716118
32.53383	169.6207	-2.716050
32.58383	169.6199	-2.715864
32.63550	169.6201	-2.715740
32.68716	169.6201	-2.715654
32.73717	169.6199	-2.715570
32.78717	169.6200	-2.715508
32.83883	169.6198	-2.715469
32.89050	169.6190	-2.715463
32.94050	169.6196	-2.715500
32.99050	169.6201	-2.715686
33.04383	169.6201	-2.715820
33.09384	169.6206	-2.716061
33.14383	169.6202	-2.716259
33.19550	169.6199	-2.716437
33.24716	169.6205	-2.716606
33.29716	169.6202	-2.716730
33.34716	169.6200	-2.716913
33.39883	169.6203	-2.717064
33.45050	169.6193	-2.717198
33.50050	169.6201	-2.717364
33.55050	169.6208	-2.717455
33.60383	169.6194	-2.717560
33.65383	169.6194	-2.717628
33.70383	169.6196	-2.717672
33.75550	169.6201	-2.717781
33.80716	169.6197	-2.717810
33.85716	169.6197	-2.717847
33.90716	169.6200	-2.717882
33.96050	169.6185	-2.717816
34.01050	169.6198	-2.717775
34.06050	169.6198	-2.717704
34.11217	169.6200	-2.717741
34.16383	169.6196	-2.717852
34.21383	169.6195	-2.718061
34.26383	169.6202	-2.718312
34.31550	169.6200	-2.718571
34.36716	169.6206	-2.718868
34.41716	169.6206	-2.719087
34.46716	169.6198	-2.719292
34.52050	169.6206	-2.719515
34.57050	169.6206	-2.719607
34.62050	169.6212	-2.719714
34.67216	169.6197	-2.719786
34.72383	169.6199	-2.719889
34.77383	169.6210	-2.720042
34.82383	169.6198	-2.720165
34.87550	169.6206	-2.720294
34.92717	169.6204	-2.720374
34.97717	169.6206	-2.720532
35.02716	169.6195	-2.720596
35.08050	169.6201	-2.720672
35.13050	169.6201	-2.720577
35.18050	169.6186	-2.720463
35.23216	169.6192	-2.720444
35.28383	169.6196	-2.720355
35.33383	169.6189	-2.720243
35.38383	169.6196	-2.720082
35.43550	169.6188	-2.719969
35.48717	169.6191	-2.719932
35.53717	169.6189	-2.719990
35.58716	169.6192	-2.720078
35.64050	169.6186	-2.720190
35.69050	169.6195	-2.720350
35.74050	169.6196	-2.720467
35.79217	169.6192	-2.720619
35.84384	169.6197	-2.720758
35.89383	169.6192	-2.720947
35.94383	169.6195	-2.721062
35.99716	169.6195	-2.721112
36.04716	169.6194	-2.721201
36.09716	169.6194	-2.721173
36.14883	169.6198	-2.721172
36.20050	169.6193	-2.721230
36.25050	169.6198	-2.721400
36.30050	169.6199	-2.721530
36.35217	169.6206	-2.721730
36.40383	169.6189	-2.721812
36.45383	169.6202	-2.721953
36.50383	169.6199	-2.722069
36.55716	169.6202	-2.722230
36.60716	169.6201	-2.722339
36.65716	169.6206	-2.722555
36.70883	169.6203	-2.722651
36.76050	169.6208	-2.722678
36.81050	169.6210	-2.722698
36.86050	169.6202	-2.722654
36.91217	169.6201	-2.722644
36.96383	169.6208	-2.722601
37.01383	169.6196	-2.722566
37.06383	169.6198	-2.722528
37.11716	169.6194	-2.722545
37.16716	169.6197	-2.722501
37.21716	169.6201	-2.722464
37.26883	169.6200	-2.722417
37.32050	169.6194	-2.722417
37.37050	169.6201	-2.722524
37.42050	169.6204	-2.722578
37.47217	169.6200	-2.722580
37.52383	169.6202	-2.722656
37.57383	169.6201	-2.722649
37.62383	169.6196	-2.722563
37.67717	169.6198	-2.722569
37.72717	169.6195	-2.722626
37.77716	169.6199	-2.722796
37.82883	169.6196	-2.722913
37.88050	169.6200	-2.723070
37.93050	169.6200	-2.723213
37.98050	169.6201	-2.723342
38.03383	169.6202	-2.723423
38.08383	169.6196	-2.723422
38.13383	169.6201	-2.723435
38.18550	169.6196	-2.723373
38.23717	169.6199	-2.723350
38.28717	169.6200	-2.723370
38.33716	169.6198	-2.723328
38.38883	169.6194	-2.723314
38.44050	169.6201	-2.723350
38.49050	169.6192	-2.723412
38.54050	169.6198	-2.723603
38.59384	169.6199	-2.723832
38.64383	169.6199	-2.724020
38.69383	169.6206	-2.724226
38.74550	169.6205	-2.724390
38.79716	169.6195	-2.724580
38.84716	169.6195	-2.724710
38.89717	169.6204	-2.724878
38.94883	169.6200	-2.724863
39.00050	169.6206	-2.724960
39.05050	169.6202	-2.724934
39.10050	169.6207	-2.724909
39.15383	169.6201	-2.724851
39.20383	169.6201	-2.724848
39.25383	169.6203	-2.724850
39.30550	169.6202	-2.724840
39.35716	169.6201	-2.724932
39.40716	169.6201	-2.724886
39.45716	169.6199	-2.724876
39.50883	169.6201	-2.724878
39.56050	169.6199	-2.724846
39.61050	169.6196	-2.724902
39.66050	169.6198	-2.724948
39.71383	169.6198	-2.725056
39.76383	169.6205	-2.725083
39.81383	169.6196	-2.725062
39.86550	169.6196	-2.725010
39.91716	169.6190	-2.724938
39.96716	169.6188	-2.724815
40.01716	169.6184	-2.724674
40.07050	169.6191	-2.724627
40.12050	169.6193	-2.724561
40.17050	169.6189	-2.724585
40.22217	169.6192	-2.724702
40.27383	169.6194	-2.724966
40.32383	169.6200	-2.725144
40.37383	169.6198	-2.725307
40.42550	169.6194	-2.725464
40.47717	169.6198	-2.725525
40.52716	169.6202	-2.725570
40.57717	169.6196	-2.725563
40.63050	169.6198	-2.725542
40.68050	169.6197	-2.725572
40.73050	169.6204	-2.725696
40.78216	169.6197	-2.725782
40.83383	169.6201	-2.725896
40.88383	169.6200	-2.725945
40.93384	169.6199	-2.725972
40.98550	169.6201	-2.725976
41.03717	169.6202	-2.725985
41.08716	169.6205	-2.725863
41.13716	169.6196	-2.725735
41.19050	169.6192	-2.725580
41.24050	169.6194	-2.725438
41.29050	169.6196	-2.725416
41.34217	169.6192	-2.725500
41.39383	169.6196	-2.725641
41.44383	169.6196	-2.725832
41.49383	169.6214	-2.726051
41.54550	169.6196	-2.726206
41.59716	169.6201	-2.726443
41.64717	169.6209	-2.726632
41.69717	169.6208	-2.726822
41.75050	169.6206	-2.726864
41.80050	169.6201	-2.726930
41.85050	169.6198	-2.726956
41.90216	169.6208	-2.726942
41.95383	169.6206	-2.726843
42.00383	169.6199	-2.726824
42.05383	169.6201	-2.726885
42.10717	169.6203	-2.726978
42.15717	169.6203	-2.727044
42.20717	169.6203	-2.727092
42.25883	169.6196	-2.727200
42.31050	169.6202	-2.727348
42.36050	169.6202	-2.727394
42.41050	169.6202	-2.727477
42.46216	169.6204	-2.727492
42.51383	169.6202	-2.727502
42.56383	169.6199	-2.727532
42.61383	169.6211	-2.727637
42.66716	169.6212	-2.727745
42.71717	169.6198	-2.727824
42.76717	169.6200	-2.727880
42.81883	169.6206	-2.727947
42.87050	169.6203	-2.727990
42.92050	169.6202	-2.728035
42.97050	169.6208	-2.728065
43.02050	169.6209	-2.728308
43.07217	169.7025	-4.647354
43.12383	170.0453	-8.822926
43.17383	170.5425	-12.39142
43.22383	171.1580	-15.43804
43.27716	171.9095	-17.99007
43.32717	172.6818	-19.85951
43.37717	173.5007	-21.32595
43.42883	174.3876	-22.51344
43.48050	175.3042	-23.42504
43.53050	176.2139	-24.12388
43.58050	177.1377	-24.69724
43.63217	178.1066	-25.17819
43.68383	179.0860	-25.60959
43.73383	180.0400	-25.97170
43.78383	181.0004	-26.27016
43.83716	182.0287	-26.59902
43.88716	182.9964	-26.88102
43.93716	183.9666	-27.17084
43.98883	184.9716	-27.47571
44.04050	185.9766	-27.78652
44.09050	186.9501	-28.10578
44.14050	187.9221	-28.46220
44.19383	188.9589	-28.85400
44.24383	189.9298	-29.29932
44.29383	190.8984	-29.77487
44.34550	191.8960	-30.35000
44.39717	192.8909	-31.00193
44.44717	193.8492	-31.71212
44.49716	194.8011	-32.54674
44.54883	195.7798	-33.53640
44.60050	196.7503	-34.68120
44.65050	197.6829	-35.94202
44.70050	198.6044	-37.40284
44.75383	199.5764	-39.20688
44.80383	200.4747	-41.12461
44.85383	201.3590	-43.31041
44.90550	202.2581	-45.81387
44.95717	203.1421	-48.53220
45.00717	203.9877	-51.18883
45.05717	204.8318	-53.64991
45.10883	205.7126	-56.01100
45.16050	206.6016	-58.27576
45.21050	207.4636	-60.57049
45.26050	208.3252	-62.90825
45.31383	209.2474	-65.04975
45.36383	210.1346	-66.24240
45.41383	211.0666	-66.26946
45.46550	212.0940	-64.79492
45.51717	213.2085	-61.63404
45.56717	214.3675	-57.44730
45.61716	215.5959	-52.28736
45.66883	216.9256	-46.35648
45.72050	218.2710	-41.74110
45.77050	219.5280	-38.70047
45.82050	220.7307	-36.47558
45.87383	221.9640	-34.71000
45.92383	223.0824	-33.46307
45.97383	224.1734	-32.51478
46.02550	225.2758	-31.77460
46.07717	226.3613	-31.25135
46.12717	227.4004	-30.85503
46.17717	228.4297	-30.57721
46.23050	229.5190	-30.36536
46.28050	230.5344	-30.23237
46.33050	231.5462	-30.15376
46.38217	232.5865	-30.09897
46.43383	233.6250	-30.07619
46.48383	234.6296	-30.06932
46.53383	235.6302	-30.06774
46.58550	236.6655	-30.06776
46.63716	237.7005	-30.06904
46.68716	238.7002	-30.07214
46.73717	239.6995	-30.08709
46.79050	240.7642	-30.11711
46.84050	241.7628	-30.16243
46.89050	242.7620	-30.20688
46.94217	243.7934	-30.25820
46.99383	244.8244	-30.31130
47.04383	245.8238	-30.35930
47.09384	246.8230	-30.39169
47.14550	247.8551	-30.42444
47.19717	248.8872	-30.45185
47.24716	249.8851	-30.49000
47.29716	250.8844	-30.52570
47.35050	251.9482	-30.56814
47.40050	252.9470	-30.61294
47.45050	253.9454	-30.64934
47.50217	254.9773	-30.68140
47.55383	256.0088	-30.73511
47.60383	257.0065	-30.77883
47.65383	258.0062	-30.83045
47.70550	259.0367	-30.87830
47.75717	260.0689	-30.92281
47.80717	261.0653	-30.96760
47.85717	262.0642	-31.02570
47.91050	263.1275	-31.07618
47.96050	264.1244	-31.13045
48.01050	265.1230	-31.19104
48.06216	266.1546	-31.25095
48.11383	267.1860	-31.29855
48.16383	268.1836	-31.35684
48.21383	269.1805	-31.42393
48.26717	270.2451	-31.48262
48.31717	271.2414	-31.53308
48.36716	272.2382	-31.60215
48.41883	273.2698	-31.67374
48.47050	274.2988	-31.69728
48.51717	275.2278	-31.79954
48.56717	276.0518	-32.56575
48.62050	276.3252	-26.31016
48.67050	276.2573	-18.13603
48.72050	275.9717	-10.51083
48.77217	275.5160	-3.946260
48.82383	274.9366	1.289091
48.87383	274.2854	5.287414
48.92383	273.5666	8.413941
48.97550	272.7666	10.94080
49.02716	271.9222	12.89975
49.07717	271.0723	14.38364
49.12717	270.1963	15.54003
49.18050	269.2400	16.50230
49.23050	268.3260	17.22312
49.28050	267.3980	17.78720
49.33217	266.4292	18.24361
49.38383	265.4508	18.62804
49.43383	264.4961	18.90588
49.48383	263.5366	19.14463
49.53717	262.5078	19.34682
49.58716	261.5394	19.50256
49.63716	260.5684	19.63498
49.68883	259.5617	19.75159
49.74050	258.5520	19.84708
49.79050	257.5726	19.92160
49.84050	256.5915	19.98523
49.89217	255.5765	20.03692
49.94383	254.5602	20.08870
49.99383	253.5761	20.13131
50.04383	252.5914	20.17371
50.09716	251.5379	20.20909
50.14717	250.5516	20.23660
50.19717	249.5639	20.26708
50.24883	248.5439	20.29170
50.30050	247.5216	20.31575
50.35050	246.5314	20.33231
50.40050	245.5421	20.34640
50.45216	244.5200	20.36231
50.50383	243.4972	20.37424
50.55383	242.5071	20.38325
50.60383	241.5167	20.39168
50.65717	240.4597	20.40130
50.70717	239.4694	20.41090
50.75717	238.4776	20.42526
50.80883	237.4531	20.43503
50.86050	236.4277	20.44678
50.91050	235.4361	20.45496
50.96050	234.4430	20.46150
51.01216	233.4182	20.46815
51.06383	232.3919	20.47459
51.11383	231.4000	20.48068
51.16383	230.4068	20.48692
51.21717	229.3474	20.49329
51.26716	228.3555	20.49952
51.31716	227.3627	20.50705
51.36883	226.3376	20.51432
51.42050	225.3126	20.52671
51.47050	224.3180	20.53765
51.52050	223.3256	20.54534
51.57383	222.2648	20.55288
51.62383	221.2715	20.55997
51.67383	220.2778	20.56675
51.72550	219.2514	20.57360
51.77717	218.2254	20.58062
51.82717	217.2319	20.58713
51.87717	216.2390	20.59375
51.92883	215.2130	20.60040
51.98050	214.1860	20.60734
52.03050	213.1928	20.61369
52.08050	212.1992	20.62000
52.13383	211.1392	20.62674
52.18383	210.1450	20.63304
52.23383	209.1518	20.63922
52.28550	208.1242	20.64532
52.33716	207.0972	20.65132
52.38716	206.1023	20.65669
52.43716	205.1086	20.66173
52.48882	204.0813	20.66700
52.54050	203.0556	20.67187
52.59050	202.0617	20.67656
52.64050	201.0687	20.68130
52.69384	200.0084	20.68655
52.74382	199.0149	20.69156
52.79382	198.0207	20.69682
52.84550	196.9936	20.70199
52.89717	195.9663	20.70717
52.94717	194.9723	20.71215
52.99717	193.9777	20.71714
53.04883	192.9508	20.72223
53.10050	191.9244	20.72736
53.15050	190.9297	20.73225
53.20050	189.9355	20.73715
53.25383	188.8753	20.74235
53.30383	187.8808	20.74707
53.35383	186.8872	20.75177
53.40550	185.8596	20.75668
53.45717	184.8336	20.76123
53.50717	183.8388	20.76567
53.55717	182.8448	20.77000
53.61050	181.7833	20.77436
53.66050	180.7881	20.77811
53.71050	179.7937	20.78208
53.76216	178.7661	20.78619
53.81382	177.7392	20.79063
53.86382	176.7456	20.79580
53.91382	175.7508	20.80124
53.96550	174.7236	20.80696
54.01716	173.6973	20.81241
54.06716	172.7024	20.81784
54.11716	171.7084	20.82291
54.17050	170.6474	20.82808
54.22050	169.6530	20.83287
54.27050	168.6602	20.83795
54.32217	167.6325	20.84336
54.37383	166.6049	20.84890
54.42383	165.6124	20.86335
54.47382	164.6196	20.91772
54.52550	163.5966	21.11931
54.57717	162.5794	21.46247
54.62717	161.6040	22.03032
54.67717	160.6478	23.04720
54.73050	159.6610	24.88266
54.78050	158.7809	27.49660
54.83050	157.9509	30.95416
54.88217	157.1448	35.14985
54.93383	156.3719	39.39946
54.98383	155.6292	43.05616
55.03383	154.8645	45.87709
55.08550	154.0271	47.76309
55.13716	153.1294	48.57889
55.18716	152.1994	48.42680
55.23717	151.2123	47.52989
55.29050	150.1092	46.03220
55.34050	149.0370	44.29366
55.39050	147.9412	42.39856
55.44216	146.7967	40.46564
55.49382	145.6486	38.63068
55.54382	144.5410	37.01958
55.59384	143.4344	35.31711
55.64717	142.2620	33.83998
55.69717	141.1741	32.62654
55.74717	140.0963	31.55802
55.79883	138.9916	30.56648
55.85050	137.8950	29.67845
55.90050	136.8428	28.93533
55.95050	135.7965	28.26404
56.00217	134.7200	27.64225
56.05383	133.6492	27.09389
56.10383	132.6176	26.59344
56.15383	131.5862	26.04532
56.20717	130.4878	25.58500
56.25717	129.4643	25.19274
56.30717	128.4418	24.84582
56.35883	127.3903	24.48361
56.41050	126.3298	23.84720
56.46050	125.3030	23.45864
56.51050	124.2801	23.11666
56.56216	123.2262	22.77754
56.61382	122.1739	22.46238
56.66382	121.1583	22.20275
56.71382	120.1434	21.95820
56.76716	119.0645	21.72493
56.81716	118.0549	21.53430
56.86716	117.0464	21.36290
56.91882	116.0046	21.18755
56.97050	114.9672	21.07533
57.02050	113.9605	20.92672
57.07050	112.9569	20.79378
57.12217	111.9194	20.66469
57.17383	110.8827	20.53464
57.22382	109.8801	20.42071
57.27383	108.8768	20.32384
57.32717	107.8086	20.20960
57.37717	106.8050	20.11800
57.42717	105.8028	20.01362
57.47883	104.7685	19.92169
57.53050	103.7336	19.83149
57.58050	102.7318	19.74272
57.63050	101.7301	19.65898
57.68383	100.6619	19.57794
57.73383	99.66181	19.49039
57.78383	98.66045	19.41891
57.83550	97.62731	19.34256
57.88716	96.59306	19.26603
57.93716	95.59301	19.18663
57.98717	94.59387	19.12640
58.03882	93.55900	19.04778
58.09050	92.52528	18.96337
58.14050	91.52541	18.89897
58.19050	90.52437	18.81332
58.24382	89.45711	18.74028
58.29382	88.45653	18.66460
58.34384	87.45558	18.59726
58.39550	86.42259	18.52461
58.44717	85.38891	18.45438
58.49717	84.38892	18.39521
58.54717	83.38770	18.33502
58.59882	82.35478	18.26835
58.65050	81.32161	18.19562
58.70050	80.32179	18.13142
58.75050	79.32180	18.06420
58.80383	78.25593	17.99494
58.85383	77.25714	17.94591
58.90383	76.25835	17.89388
58.95550	75.22476	17.80781
59.00717	74.19090	17.74368
59.05717	73.19124	17.67061
59.10717	72.19001	17.60238
59.15883	71.15494	17.53052
59.21050	70.12100	17.45416
59.26050	69.12090	17.38376
59.31050	68.12088	17.31849
59.36382	67.05382	17.24272
59.41382	66.05399	17.19052
59.46382	65.05305	17.12533
59.51550	64.01864	17.05022
59.56716	62.98522	16.98268
59.61716	61.98562	16.91238
59.66716	60.98657	16.85224
59.72050	59.91978	16.78936
59.77050	58.92002	16.72616
59.82050	57.92003	16.66657
59.87217	56.88606	16.60172
59.92383	55.85368	16.53114
59.97382	54.85308	16.47873
60.02383	53.85318	16.42711
60.07550	52.82118	16.37283
60.12717	51.78795	16.30703
60.17717	50.78872	16.24154
60.22717	49.78854	16.18308
60.28050	48.72238	16.11579
60.33050	47.72239	16.05403
60.38050	46.72226	15.99842
60.43217	45.68980	15.93875
60.48383	44.65497	15.88069
60.53383	43.65535	15.81768
60.58383	42.65551	15.75546
60.63550	41.62136	15.68503
60.68716	40.58675	15.61139
60.73717	39.58536	15.54096
60.78716	38.58500	15.46289
60.84050	37.51591	15.36810
60.89050	36.51350	15.28704
60.94050	35.51208	15.20694
60.99216	34.47648	15.12940
61.04382	33.44108	15.03879
61.09384	32.43978	14.95544
61.14384	31.43773	14.90738
61.19550	30.40276	14.79916
61.24717	29.36721	14.70951
61.29717	28.36566	14.62233
61.34716	27.36212	14.53107
61.40050	26.29272	14.42470
61.45050	25.28956	14.35829
-2.000000	4.000000	0.0000000
61.54883	23.36076	14.62524
61.60050	22.86882	12.12329
61.65050	22.80957	7.320840
61.70050	22.99710	2.951542
61.75383	23.40866	-0.8600324
61.80383	23.93802	-3.676678
61.85383	24.57106	-5.868045
61.90550	25.30847	-7.642840
61.95717	26.11018	-9.016699
62.00717	26.93193	-10.05972
62.05717	27.78970	-10.88500
62.10883	28.70005	-11.57524
62.16050	29.63406	-12.12336
62.21050	30.55435	-12.55007
62.26050	31.48523	-12.91362
62.31382	32.48847	-13.27497
62.36382	33.43674	-13.52238
62.41382	34.39369	-13.73728
62.46550	35.38642	-13.93374
62.51716	36.38578	-14.10755
62.56716	37.35571	-14.26359
62.61716	38.32739	-14.39861
62.66882	39.33410	-14.53459
62.72050	40.34252	-14.64890
62.77050	41.32098	-14.76605
62.82050	42.29982	-14.87896
62.87383	43.34532	-14.98929
62.92383	44.32778	-15.08655
62.97382	45.31101	-15.19023
63.02550	46.32828	-15.28081
63.07717	47.34664	-15.37601
63.12717	48.33340	-15.47209
63.17717	49.31941	-15.55491
63.22883	50.33976	-15.64797
63.28050	51.36078	-15.74744
63.33050	52.34892	-15.83035
63.38050	53.33771	-15.92541
63.43383	54.39316	-16.01118
63.48383	55.38376	-16.10045
63.53383	56.37356	-16.18514
63.58550	57.39735	-16.27477
63.63716	58.42078	-16.36648
63.68716	59.41220	-16.45192
63.73717	60.40314	-16.53709
63.79050	61.46115	-16.64316
63.84050	62.45190	-16.72408
63.89050	63.44534	-16.81491
63.94216	64.47050	-16.90195
63.99382	65.49630	-16.98656
64.04384	66.48913	-17.06989
64.09384	67.48225	-17.16288
64.14550	68.50824	-17.25027
64.19717	69.53570	-17.33756
64.24717	70.52960	-17.42268
64.29718	71.52302	-17.51251
64.35050	72.58355	-17.60591
64.40050	73.57720	-17.69182
64.45050	74.57076	-17.79688
64.50217	75.59691	-17.88797
64.55383	76.62382	-17.98880
64.60383	77.61822	-18.08391
64.65384	78.60855	-18.33267
64.70550	79.63606	-18.30525
64.75718	80.66505	-18.38511
64.80717	81.65937	-18.47627
64.85718	82.65486	-18.56453
64.91050	83.71545	-18.66506
64.96050	84.71075	-18.76614
65.01050	85.70499	-18.85623
65.06216	86.73272	-18.96300
65.11384	87.76019	-19.06028
65.16382	88.75418	-19.16190
65.21384	89.74834	-19.27132
65.26550	90.77559	-19.37000
65.31717	91.80297	-19.48177
65.36718	92.79657	-19.58162
65.41717	93.79113	-19.68578
65.47050	94.85119	-19.79658
65.52050	95.84481	-19.91016
65.57050	96.83932	-20.01428
65.62218	97.86579	-20.11807
65.67384	98.89231	-20.22954
65.72384	99.88770	-20.33970
65.77384	100.8802	-20.44944
65.82718	101.9404	-20.55934
65.87718	102.9346	-20.67395
65.92718	103.9285	-20.78784
65.97884	104.9553	-20.90562
66.03050	105.9820	-21.02965
66.08050	106.9774	-21.14660
66.13050	107.9709	-21.26544
66.18218	108.9972	-21.38578
66.23384	110.0255	-21.50294
66.28384	111.0183	-21.62172
66.33384	112.0126	-21.74907
66.38718	113.0706	-21.88532
66.43718	114.0638	-22.01935
66.48718	115.0574	-22.12818
66.53882	116.0836	-22.28153
66.59050	117.1100	-22.39850
66.64050	118.1028	-22.52568
66.69050	119.0958	-22.67054
66.74218	120.1218	-22.80480
66.79384	121.1465	-22.95746
66.84384	122.1386	-23.09876
66.89384	123.1308	-23.24752
66.94718	124.1901	-23.40643
66.99718	125.1824	-23.55069
67.04718	126.1737	-23.68944
67.09882	127.1998	-23.82770
67.15050	128.2248	-23.96792
67.20050	129.2166	-24.11652
67.25050	130.2096	-24.26866
67.30218	131.2339	-24.41738
67.35384	132.2605	-24.55952
67.40384	133.2528	-24.71291
67.45384	134.2455	-24.86336
67.50718	135.3037	-25.02372
67.55718	136.2952	-25.18957
67.60718	137.2858	-25.34490
67.65884	138.3113	-25.46954
67.71050	139.3392	-25.52949
67.76050	140.3420	-25.47120
67.81050	141.3450	-25.45412
67.86384	142.4134	-25.45064
67.91382	143.4110	-25.45840
67.96384	144.4109	-25.47192
68.01550	145.4429	-25.49728
68.06718	146.4741	-25.59568
68.11718	147.4714	-25.70540
68.16718	148.4674	-25.80787
68.21884	149.4966	-25.91630
68.27050	150.5256	-26.01836
68.32050	151.5219	-26.13056
68.37050	152.5158	-26.24009
68.42384	153.5770	-26.34801
68.47384	154.5725	-26.44935
68.52384	155.5680	-26.54107
68.57550	156.5961	-26.62661
68.62718	157.6257	-26.71007
68.67718	158.6219	-26.77531
68.72718	159.6178	-26.83031
68.77884	160.6503	-26.88918
68.83050	161.6821	-26.93184
68.88050	162.6805	-26.98041
68.93050	163.6784	-27.03952
68.98384	164.7418	-27.12388
69.03384	165.7394	-27.22038
69.08384	166.7346	-27.33832
69.13550	167.7634	-27.45423
69.18718	168.7915	-27.58550
69.23718	169.7848	-27.72684
69.28718	170.7768	-27.89884
69.33884	171.8025	-28.08118
69.39050	172.8259	-28.27080
69.44050	173.8170	-28.47802
69.49050	174.8050	-28.70203
69.54384	175.8594	-28.96195
69.59384	176.8443	-29.21008
69.64384	177.8306	-29.50813
69.69550	178.8460	-29.83232
69.74718	179.8608	-30.20074
69.79718	180.8397	-30.58824
69.84718	181.8183	-31.01050
69.90050	182.8588	-31.49753
69.95050	183.8329	-32.00850
70.00050	184.8029	-32.55548
70.05218	185.8027	-33.17340
70.10384	186.7998	-33.84863
70.15384	187.7616	-34.54716
70.20384	188.7221	-35.26800
70.25550	189.7116	-36.05722
70.30718	190.6995	-36.86000
70.35718	191.6535	-37.64210
70.40718	192.6071	-38.47856
70.46050	193.6206	-39.38640
70.51050	194.5691	-40.29920
70.56050	195.5149	-41.26736
70.61218	196.4895	-42.33942
70.66382	197.4611	-43.44932
70.71384	198.3983	-44.55235
70.76384	199.3338	-45.64140
70.81550	200.3033	-46.67004
70.86718	201.2765	-47.53267
70.91718	202.2283	-48.06621
70.96718	203.1981	-48.14164
71.02050	204.2621	-47.46117
71.07050	205.3012	-45.82867
71.12050	206.3902	-43.31314
71.17218	207.5638	-40.16836
71.22384	208.7665	-37.08242
71.27384	209.9318	-34.69402
71.32384	211.0757	-32.99900
71.37550	212.2250	-31.74852
71.42718	213.3496	-30.82852
71.47718	214.4160	-30.17188
71.52718	215.4662	-29.67450
71.58050	216.5725	-29.29192
71.63050	217.6011	-29.03162
71.68050	218.6221	-28.83856
71.73218	219.6710	-28.70510
71.78384	220.7164	-28.61264
71.83384	221.7246	-28.56134
71.88384	222.7308	-28.53181
71.93718	223.8014	-28.52358
71.98718	224.8039	-28.52090
72.03718	225.8051	-28.52071
72.08884	226.8394	-28.52320
72.14050	227.8725	-28.53200
72.19050	228.8712	-28.56061
72.24050	229.8700	-28.61467
72.29218	230.9017	-28.67969
72.34384	231.9325	-28.75789
72.39384	232.9304	-28.82720
72.44384	233.9271	-28.89295
72.49718	234.9907	-28.95654
72.54718	235.9871	-29.01642
72.59718	236.9848	-29.07451
72.64884	238.0164	-29.13218
72.70050	239.0473	-29.18328
72.75050	240.0458	-29.23936
72.80050	241.0440	-29.28620
72.85218	242.0762	-29.32758
72.90384	243.1099	-29.37309
72.95384	244.1075	-29.40825
73.00384	245.1058	-29.45379
73.05718	246.1707	-29.50704
73.10718	247.1682	-29.56100
73.15718	248.1660	-29.61596
73.20884	249.1974	-29.66146
73.26050	250.2287	-29.72345
73.31050	251.2256	-29.78012
73.36050	252.2229	-29.84143
73.41218	253.2539	-29.90031
73.46384	254.2850	-29.95662
73.51384	255.2824	-30.01755
73.56384	256.2806	-30.08482
73.61718	257.3447	-30.15385
73.66718	258.3418	-30.22446
73.71718	259.3382	-30.28464
73.76882	260.3698	-30.35823
73.82050	261.3995	-30.41804
73.87050	262.3971	-30.49316
73.92050	263.3933	-30.55230
73.97384	264.4570	-30.63190
74.02384	265.4544	-30.70242
74.07384	266.4518	-30.76478
74.12550	267.4818	-30.83631
74.17718	268.5110	-30.91016
74.22718	269.5074	-30.99203
74.27718	270.5055	-31.06278
74.32884	271.5337	-31.13602
-2.000000	5.000000	0.0000000