File: 5-C1(1.4mol%)+C20(0.6mol%)/matlab/170-1.txt
CLOSED
Version	1.0
Language	English
Mode	Standard
Run	25
RunSerial	12327
Instrument	DSC Q2000 V24.11 Build 124
Module	DSC Standard Cell RC
Operator
File	\\AE520-1454\Users\dsc\Desktop\Data\31-08-17-2\170-1.001
ProcName
InstSerial	2000-0883
AutoSerial	1293
Sample	170-1
Size	17.7000	mg
PanMass	Not available
PanResist	Automatic Automatic  K/W
PanFactor	Default Default
Method
Comment
Xcomment	Pan: Tzero Aluminum Hermetic
Xcomment	Gas1: Nitrogen 50.0 ml/min
Xcomment	Gas2: Nitrogen 50.0 ml/min
Text
Exotherm	UP
Kcell	1.05230
Cpconst	Standard: 0.938
Calib	-38.6961
TempCal	1	pts	157.46	156.60
TzeroDt	-87.6168 -0.0009 -1.4231
TzeroDtz	-87.6168 0.0057 6.9570
InstCalFile	Tzero: \\Ae520-1454\ta\Data\DSC\Calibration\2017\CALIBRATION\1562_RCS (90)_05_18_2017 10_50_44.TZR
InstCalFile	Baseline: \\Ae520-1454\ta\Data\DSC\Calibration\2017\2017-05-17_Calibration.001
InstCalFile	Sapphire: \\Ae520-1454\ta\Data\DSC\Calibration\2017\2017-05-17_Saphire.001
InstCalDate	Tzero 2017-05-18 Time 10:50:44
TempRange	-87.39 to 398.39 °C at 10.00 °C/min Heat Only
AutoZero	Delta T Offset 0.000 uV
AutoZero	Delta T0 Offset 0.000 uV
MultiptCal	0
MultiPtDesc	0) Not set
AutoCellConst	Calibration Date 2017-05-18 16:59:28
Controls	Gas 1  Event Off  Sampling 0.2
Cell#	RC-01562
CoolingUnit	RCS (90)
SelHeatFlow	Heat Flow T4P (mW)
AutoLidII	Installed
AutoAnalysis	Off
MacroFile
Nsig	3
Sig1	Time (min)
Sig2	Temperature (°C)
Sig3	Heat Flow (mW)
Date	2017-09-01
Time	18:27:41
OrgMethod	1: Equilibrate at 80.00 °C
OrgMethod	2: Isothermal for 3.00 min
OrgMethod	3: Jump to 170.00 °C
OrgMethod	4: Mark end of cycle 1
OrgMethod	5: Isothermal for 40.00 min
OrgMethod	6: Mark end of cycle 2
OrgMethod	7: Ramp 20.00 °C/min to 280.00 °C
OrgMethod	8: Mark end of cycle 3
OrgMethod	9: Ramp 20.00 °C/min to 20.00 °C
OrgMethod	10: Mark end of cycle 4
OrgMethod	11: Ramp 20.00 °C/min to 280.00 °C
OrgMethod	12: Mark end of cycle 5
OrgFile	C:\Users\jarra\Desktop\DSC\5-C1(1.4mol%)+C20(0.6mol%)\170-1.001
StartOfData
4.99994E-4	79.90368	-1.083972
0.05383332	79.91000	-0.9530384
0.1038333	79.91228	-0.8645014
0.1538333	79.91368	-0.8065286
0.2055000	79.91275	-0.7607112
0.2571667	79.91181	-0.7354218
0.3071666	79.91098	-0.7193204
0.3571666	79.91084	-0.7105369
0.4105000	79.90796	-0.7037720
0.4605000	79.90528	-0.7010011
0.5105000	79.90337	-0.6985194
0.5621668	79.90196	-0.6959839
0.6138334	79.89974	-0.6935350
0.6638332	79.89800	-0.6913150
0.7138332	79.89618	-0.6892380
0.7655000	79.89482	-0.6872462
0.8171668	79.89301	-0.6854534
0.8671666	79.89234	-0.6839538
0.9171668	79.89124	-0.6825064
0.9705000	79.88941	-0.6810820
1.020500	79.88862	-0.6799598
1.070500	79.88603	-0.6789331
1.122166	79.88568	-0.6780429
1.173834	79.88416	-0.6773569
1.223833	79.88419	-0.6768186
1.273834	79.88178	-0.6763557
1.325500	79.88058	-0.6760582
1.377166	79.88019	-0.6757492
1.427167	79.87910	-0.6756366
1.477166	79.87920	-0.6755078
1.530500	79.87729	-0.6754481
1.580500	79.87634	-0.6755376
1.630500	79.87544	-0.6756426
1.682167	79.87507	-0.6757706
1.733833	79.87361	-0.6759408
1.783833	79.87334	-0.6761947
1.833833	79.87239	-0.6764643
1.885500	79.87142	-0.6768169
1.937166	79.87131	-0.6772295
1.987166	79.86980	-0.6776791
2.037166	79.86963	-0.6781247
2.090500	79.86842	-0.6786757
2.140500	79.86810	-0.6792549
2.190500	79.86834	-0.6798534
2.242166	79.86671	-0.6803406
2.293833	79.86528	-0.6809307
2.343834	79.86526	-0.6815978
2.393833	79.86488	-0.6822352
2.447166	79.86453	-0.6829595
2.497166	79.86347	-0.6836886
2.547166	79.86392	-0.6844329
2.598834	79.86295	-0.6852984
2.650500	79.86195	-0.6860832
2.700500	79.86240	-0.6869798
2.750500	79.86108	-0.6878879
2.802166	79.86036	-0.6888378
2.853833	79.85916	-0.6897474
2.903833	79.85850	-0.6906906
2.953833	79.85799	-0.6915622
3.000500	79.85732	-0.6924990
3.053833	80.24062	-8.991551
3.103833	82.05321	-23.92035
3.153833	84.62434	-34.95119
3.205500	87.84455	-44.79007
3.257167	91.48428	-52.78464
3.307167	95.29245	-58.98855
3.357167	99.30161	-63.94724
3.410500	103.7326	-68.08026
3.460500	107.9913	-71.06026
3.510500	112.3164	-73.34095
3.562167	116.8260	-75.23102
3.613834	121.3481	-76.99008
3.663833	125.7310	-78.25976
3.713833	130.1352	-79.10460
3.765500	134.6848	-79.81250
3.817166	139.2263	-80.36284
3.867166	143.6150	-80.65813
3.917167	148.0006	-80.65224
3.970500	152.6734	-80.23863
4.020500	156.6987	-73.35657
4.070500	159.5659	-59.05034
4.122166	161.7248	-46.96485
4.173834	163.3250	-36.34854
4.223834	164.4890	-28.13582
4.273834	165.3820	-21.63472
4.325500	166.0981	-16.44746
4.377167	166.6586	-12.50799
4.427166	167.0928	-9.622638
4.477167	167.4454	-7.428000
4.530500	167.7547	-5.661062
4.580500	167.9981	-4.390932
4.630500	168.2051	-3.398462
4.682167	168.3891	-2.575729
4.733834	168.5502	-1.899306
4.783834	168.6888	-1.339208
4.833834	168.8118	-0.8346782
4.885500	168.9268	-0.3543454
4.937167	169.0311	0.1081784
4.987167	169.1260	0.5442360
5.037167	169.2131	0.9923866
5.090500	169.2991	1.475574
5.140500	169.3776	1.944624
5.190500	169.4505	2.435644
5.242167	169.5244	2.965478
5.293832	169.5959	3.532246
5.343834	169.6631	4.109512
5.393832	169.7298	4.713714
5.447168	169.8009	5.393236
5.497168	169.8659	6.068127
5.547168	169.9310	6.764556
5.598832	169.9974	7.512245
5.650500	170.0626	8.258824
5.700500	170.1240	8.977399
5.750500	170.1825	9.674255
5.802168	170.2393	10.33565
5.853832	170.2910	10.91561
5.903834	170.3336	11.38175
5.953832	170.3667	11.73019
6.007168	170.3935	11.96214
6.057168	170.4104	12.05932
6.107168	170.4181	12.06358
6.158832	170.4208	12.03128
6.210500	170.4174	11.87179
6.260500	170.4120	11.61408
6.310500	170.4040	11.39172
6.362168	170.3936	11.15841
6.413832	170.3844	10.93204
6.463834	170.3742	10.73300
6.513834	170.3668	10.54607
6.567168	170.3596	10.38702
6.617166	170.3541	10.26376
6.667168	170.3510	10.17207
6.718832	170.3500	10.11907
6.770500	170.3505	10.09760
6.820500	170.3537	10.09689
6.870500	170.3589	10.10526
6.922168	170.3680	10.21722
6.973834	170.3802	10.41245
7.023834	170.3930	10.61699
7.073834	170.4081	10.84350
7.127168	170.4256	11.11349
7.177168	170.4439	11.38854
7.227168	170.4639	11.67510
7.278832	170.4847	11.97564
7.330500	170.5049	12.26661
7.380500	170.5240	12.53945
7.430500	170.5416	12.78658
7.483832	170.5592	13.01574
7.533832	170.5709	13.19542
7.583832	170.5818	13.32353
7.635500	170.5899	13.40470
7.687168	170.5934	13.43808
7.737168	170.5933	13.43583
7.787168	170.5912	13.42526
7.838834	170.5836	13.27890
7.890500	170.5735	13.04679
7.940500	170.5617	12.81850
7.990500	170.5460	12.55511
8.043834	170.5268	12.24498
8.093832	170.5083	11.92766
8.143832	170.4881	11.59356
8.195500	170.4657	11.23298
8.247168	170.4423	10.86469
8.297168	170.4201	10.49996
8.347168	170.3973	10.13953
8.398834	170.3744	9.770338
8.450500	170.3509	9.409408
8.500500	170.3291	9.061438
8.550500	170.3079	8.718732
8.603832	170.2847	8.367375
8.653832	170.2644	8.044812
8.703834	170.2455	7.739126
8.755500	170.2263	7.438150
8.807168	170.2078	7.147446
8.857166	170.1908	6.879524
8.907166	170.1751	6.630340
8.958832	170.1596	6.391325
9.010499	170.1446	6.169860
9.060500	170.1339	5.972037
9.110500	170.1215	5.798389
9.163834	170.1097	5.628692
9.213834	170.1014	5.490838
9.263832	170.0936	5.376419
9.315500	170.0867	5.275509
9.367166	170.0813	5.198637
9.417168	170.0782	5.143183
9.467168	170.0756	5.106475
9.520500	170.0725	5.087065
9.570500	170.0730	5.078284
9.620499	170.0746	5.076241
9.672168	170.0757	5.076330
9.723832	170.0776	5.080530
9.773834	170.0805	5.097844
9.823834	170.0840	5.134830
9.875500	170.0867	5.184684
9.927168	170.0897	5.240097
9.977168	170.0932	5.288495
10.02717	170.0965	5.330652
10.08050	170.0984	5.368645
10.13050	170.1008	5.390467
10.18050	170.1014	5.401524
10.23217	170.1010	5.405852
10.28383	170.1005	5.407882
10.33383	170.0982	5.407364
10.38383	170.0942	5.381921
10.43550	170.0906	5.287957
10.48717	170.0847	5.148956
10.53717	170.0757	4.997192
10.58717	170.0664	4.818889
10.64050	170.0540	4.605269
10.69050	170.0400	4.389736
10.74050	170.0259	4.144143
10.79217	170.0089	3.874131
10.84383	169.9905	3.580343
10.89383	169.9721	3.282718
10.94383	169.9517	2.974476
10.99550	169.9316	2.645802
11.04717	169.9104	2.315064
11.09717	169.8899	1.996667
11.14717	169.8692	1.684656
11.20050	169.8470	1.354096
11.25050	169.8289	1.053844
11.30050	169.8100	0.7709600
11.35217	169.7910	0.4868435
11.40383	169.7740	0.2217512
11.45384	169.7575	-.02050238
11.50384	169.7427	-0.2447730
11.55717	169.7273	-0.4673758
11.60717	169.7149	-0.6596897
11.65717	169.7042	-0.8347681
11.70883	169.6930	-0.9930382
11.76050	169.6834	-1.140551
11.81050	169.6760	-1.266554
11.86050	169.6673	-1.379009
11.91217	169.6608	-1.483114
11.96383	169.6541	-1.569034
12.01383	169.6499	-1.650401
12.06383	169.6451	-1.718789
12.11716	169.6399	-1.783621
12.16717	169.6369	-1.838406
12.21717	169.6342	-1.887623
12.26883	169.6306	-1.930592
12.32050	169.6277	-1.971384
12.37050	169.6266	-2.002981
12.42050	169.6243	-2.030079
12.47217	169.6222	-2.055191
12.52383	169.6202	-2.076630
12.57383	169.6192	-2.097334
12.62383	169.6168	-2.113980
12.67717	169.6149	-2.132695
12.72717	169.6141	-2.147980
12.77717	169.6128	-2.160498
12.82883	169.6109	-2.172506
12.88050	169.6094	-2.184817
12.93050	169.6093	-2.197546
12.98050	169.6088	-2.207773
13.03217	169.6069	-2.218158
13.08383	169.6052	-2.228639
13.13383	169.6057	-2.239164
13.18383	169.6036	-2.247432
13.23716	169.6041	-2.256478
13.28717	169.6028	-2.263981
13.33717	169.6022	-2.271656
13.38883	169.6019	-2.279922
13.44050	169.6018	-2.288096
13.49050	169.6014	-2.296272
13.54050	169.6004	-2.304804
13.59383	169.6003	-2.313697
13.64383	169.6005	-2.321984
13.69384	169.5997	-2.330242
13.74550	169.5994	-2.338684
13.79717	169.5988	-2.346970
13.84717	169.5985	-2.354973
13.89717	169.5981	-2.362900
13.94884	169.5975	-2.370914
14.00050	169.5959	-2.378808
14.05050	169.5965	-2.386368
14.10050	169.5958	-2.393840
14.15383	169.5955	-2.401698
14.20383	169.5952	-2.409052
14.25383	169.5944	-2.416258
14.30550	169.5949	-2.423698
14.35716	169.5941	-2.430952
14.40717	169.5944	-2.437950
14.45717	169.5936	-2.444725
14.50883	169.5925	-2.451670
14.56050	169.5930	-2.458528
14.61050	169.5925	-2.465112
14.66050	169.5926	-2.471588
14.71383	169.5922	-2.478318
14.76383	169.5923	-2.484606
14.81383	169.5931	-2.490514
14.86550	169.5924	-2.496702
14.91716	169.5920	-2.502791
14.96716	169.5930	-2.508666
15.01717	169.5929	-2.514416
15.06884	169.5929	-2.520152
15.12050	169.5925	-2.525752
15.17050	169.5923	-2.531014
15.22050	169.5921	-2.536100
15.27383	169.5920	-2.541396
15.32384	169.5920	-2.546305
15.37384	169.5916	-2.550948
15.42550	169.5918	-2.555762
15.47717	169.5913	-2.560330
15.52717	169.5918	-2.564680
15.57717	169.5908	-2.568856
15.63050	169.5907	-2.573145
15.68050	169.5888	-2.577202
15.73050	169.5899	-2.581128
15.78217	169.5895	-2.585144
15.83383	169.5888	-2.588998
15.88383	169.5892	-2.592780
15.93383	169.5890	-2.596338
15.98550	169.5889	-2.599947
16.03717	169.5891	-2.603397
16.08716	169.5879	-2.606737
16.13716	169.5888	-2.609904
16.19050	169.5875	-2.613294
16.24050	169.5882	-2.616454
16.29050	169.5875	-2.619582
16.34216	169.5882	-2.622876
16.39383	169.5888	-2.626166
16.44383	169.5886	-2.629292
16.49383	169.5888	-2.632373
16.54550	169.5882	-2.635450
16.59716	169.5884	-2.638397
16.64716	169.5884	-2.641160
16.69716	169.5888	-2.643800
16.75050	169.5882	-2.646407
16.80050	169.5879	-2.648812
16.85050	169.5872	-2.651113
16.90216	169.5882	-2.653400
16.95383	169.5882	-2.655678
17.00383	169.5874	-2.657938
17.05383	169.5875	-2.660264
17.10550	169.5881	-2.662677
17.15716	169.5874	-2.664980
17.20716	169.5874	-2.667219
17.25716	169.5888	-2.669422
17.31050	169.5886	-2.671770
17.36050	169.5889	-2.673855
17.41050	169.5892	-2.675882
17.46216	169.5890	-2.677791
17.51383	169.5882	-2.679648
17.56383	169.5881	-2.681345
17.61383	169.5887	-2.682982
17.66716	169.5875	-2.684615
17.71716	169.5878	-2.686026
17.76716	169.5874	-2.687480
17.81883	169.5872	-2.688909
17.87050	169.5869	-2.690390
17.92050	169.5869	-2.691939
17.97050	169.5870	-2.693525
18.02216	169.5875	-2.695213
18.07383	169.5867	-2.696662
18.12383	169.5869	-2.698030
18.17383	169.5864	-2.699459
18.22716	169.5870	-2.700894
18.27716	169.5868	-2.702108
18.32716	169.5862	-2.703306
18.37883	169.5863	-2.704423
18.43050	169.5856	-2.705569
18.48050	169.5858	-2.706647
18.53050	169.5862	-2.707748
18.58216	169.5851	-2.708782
18.63383	169.5855	-2.709938
18.68383	169.5853	-2.711020
18.73383	169.5846	-2.712105
18.78717	169.5849	-2.713274
18.83716	169.5847	-2.714461
18.88716	169.5854	-2.715568
18.93883	169.5853	-2.716696
18.99050	169.5862	-2.717824
19.04050	169.5848	-2.718811
19.09050	169.5857	-2.719870
19.14216	169.5851	-2.720898
19.19383	169.5856	-2.721919
19.24383	169.5860	-2.722958
19.29383	169.5852	-2.723890
19.34716	169.5861	-2.724842
19.39716	169.5851	-2.725699
19.44716	169.5861	-2.726578
19.49883	169.5862	-2.727595
19.55050	169.5852	-2.728674
19.60050	169.5866	-2.729722
19.65050	169.5858	-2.730528
19.70383	169.5861	-2.731360
19.75383	169.5859	-2.732136
19.80383	169.5864	-2.732850
19.85550	169.5854	-2.733519
19.90716	169.5861	-2.734235
19.95716	169.5864	-2.734969
20.00716	169.5870	-2.735751
20.05883	169.5863	-2.736569
20.11050	169.5866	-2.737344
20.16050	169.5869	-2.738121
20.21050	169.5874	-2.738972
20.26383	169.5872	-2.739693
20.31383	169.5871	-2.740388
20.36383	169.5878	-2.741077
20.41550	169.5870	-2.741602
20.46716	169.5870	-2.742182
20.51716	169.5870	-2.742832
20.56716	169.5858	-2.743390
20.61883	169.5872	-2.743982
20.67050	169.5866	-2.744547
20.72050	169.5867	-2.745001
20.77050	169.5871	-2.745368
20.82383	169.5860	-2.745697
20.87383	169.5859	-2.746031
20.92383	169.5872	-2.746429
20.97550	169.5861	-2.746816
21.02717	169.5861	-2.747176
21.07716	169.5850	-2.747460
21.12716	169.5860	-2.747720
21.17883	169.5856	-2.747975
21.23050	169.5849	-2.748272
21.28050	169.5849	-2.748579
21.33050	169.5850	-2.748875
21.38383	169.5851	-2.749165
21.43383	169.5850	-2.749420
21.48383	169.5852	-2.749780
21.53550	169.5849	-2.750170
21.58716	169.5851	-2.750719
21.63716	169.5862	-2.751313
21.68716	169.5853	-2.751930
21.74050	169.5857	-2.752661
21.79050	169.5861	-2.753240
21.84050	169.5863	-2.753736
21.89216	169.5860	-2.754082
21.94383	169.5867	-2.754494
21.99383	169.5860	-2.754857
22.04383	169.5866	-2.755176
22.09550	169.5856	-2.755415
22.14716	169.5853	-2.755706
22.19716	169.5860	-2.755940
22.24716	169.5856	-2.756176
22.30050	169.5854	-2.756410
22.35050	169.5852	-2.756716
22.40050	169.5853	-2.757122
22.45216	169.5859	-2.757641
22.50383	169.5858	-2.758091
22.55383	169.5862	-2.758610
22.60383	169.5866	-2.759111
22.65550	169.5862	-2.759524
22.70717	169.5874	-2.759927
22.75716	169.5866	-2.760212
22.80716	169.5866	-2.760584
22.86050	169.5863	-2.760848
22.91050	169.5867	-2.761222
22.96050	169.5869	-2.761578
23.01216	169.5866	-2.761960
23.06383	169.5871	-2.762260
23.11383	169.5864	-2.762506
23.16383	169.5853	-2.762661
23.21550	169.5864	-2.762890
23.26716	169.5859	-2.762998
23.31716	169.5862	-2.763180
23.36716	169.5858	-2.763409
23.42050	169.5861	-2.763683
23.47050	169.5868	-2.764036
23.52050	169.5859	-2.764341
23.57216	169.5861	-2.764621
23.62383	169.5860	-2.764948
23.67383	169.5863	-2.765194
23.72383	169.5864	-2.765402
23.77717	169.5853	-2.765620
23.82716	169.5851	-2.765771
23.87716	169.5860	-2.766070
23.92883	169.5853	-2.766288
23.98050	169.5853	-2.766648
24.03050	169.5860	-2.766998
24.08050	169.5852	-2.767304
24.13216	169.5857	-2.767523
24.18383	169.5854	-2.767668
24.23383	169.5849	-2.767851
24.28383	169.5854	-2.768090
24.33716	169.5854	-2.768241
24.38716	169.5858	-2.768524
24.43716	169.5865	-2.768810
24.48883	169.5857	-2.769056
24.54050	169.5857	-2.769381
24.59050	169.5856	-2.769578
24.64050	169.5860	-2.769791
24.69216	169.5859	-2.770009
24.74383	169.5858	-2.770203
24.79383	169.5858	-2.770327
24.84383	169.5861	-2.770486
24.89716	169.5844	-2.770527
24.94716	169.5848	-2.770557
24.99716	169.5846	-2.770620
25.04883	169.5843	-2.770608
25.10050	169.5839	-2.770634
25.15050	169.5844	-2.770644
25.20050	169.5848	-2.770747
25.25217	169.5838	-2.770826
25.30383	169.5844	-2.770985
25.35383	169.5838	-2.771152
25.40383	169.5842	-2.771367
25.45717	169.5840	-2.771763
25.50716	169.5844	-2.772129
25.55716	169.5852	-2.772606
25.60883	169.5854	-2.773076
25.66050	169.5853	-2.773524
25.71050	169.5854	-2.773863
25.76050	169.5863	-2.774210
25.81383	169.5859	-2.774465
25.86383	169.5858	-2.774752
25.91383	169.5861	-2.774946
25.96550	169.5857	-2.775064
26.01716	169.5856	-2.775214
26.06716	169.5862	-2.775328
26.11716	169.5862	-2.775350
26.16883	169.5860	-2.775331
26.22050	169.5846	-2.775225
26.27050	169.5853	-2.775147
26.32050	169.5848	-2.775095
26.37383	169.5846	-2.775156
26.42383	169.5848	-2.775182
26.47383	169.5851	-2.775306
26.52550	169.5844	-2.775471
26.57717	169.5848	-2.775850
26.62716	169.5852	-2.776071
26.67717	169.5854	-2.776434
26.72883	169.5865	-2.776908
26.78050	169.5856	-2.777267
26.83050	169.5858	-2.777578
26.88050	169.5869	-2.777888
26.93383	169.5862	-2.778020
26.98383	169.5867	-2.778146
27.03383	169.5864	-2.778238
27.08550	169.5862	-2.778264
27.13716	169.5856	-2.778268
27.18717	169.5855	-2.778285
27.23716	169.5856	-2.778389
27.28883	169.5858	-2.778342
27.34050	169.5854	-2.778309
27.39050	169.5855	-2.778340
27.44050	169.5856	-2.778358
27.49383	169.5860	-2.778310
27.54383	169.5846	-2.778216
27.59383	169.5851	-2.778172
27.64550	169.5844	-2.778160
27.69717	169.5847	-2.778185
27.74716	169.5846	-2.778272
27.79716	169.5842	-2.778391
27.85050	169.5842	-2.778565
27.90050	169.5843	-2.778706
27.95050	169.5841	-2.778790
28.00217	169.5844	-2.778911
28.05383	169.5854	-2.779170
28.10383	169.5853	-2.779324
28.15383	169.5859	-2.779568
28.20550	169.5848	-2.779732
28.25716	169.5855	-2.779984
28.30716	169.5851	-2.780108
28.35716	169.5846	-2.780072
28.41050	169.5850	-2.780165
28.46050	169.5851	-2.780148
28.51050	169.5849	-2.780232
28.56217	169.5854	-2.780333
28.61383	169.5846	-2.780487
28.66383	169.5858	-2.780703
28.71383	169.5862	-2.780960
28.76550	169.5857	-2.781196
28.81716	169.5861	-2.781366
28.86716	169.5854	-2.781550
28.91716	169.5856	-2.781640
28.97050	169.5857	-2.781777
29.02050	169.5858	-2.781919
29.07050	169.5861	-2.782080
29.12216	169.5855	-2.782146
29.17383	169.5858	-2.782194
29.22383	169.5866	-2.782364
29.27383	169.5869	-2.782517
29.32550	169.5866	-2.782739
29.37716	169.5859	-2.782811
29.42717	169.5859	-2.782860
29.47717	169.5859	-2.782852
29.53050	169.5864	-2.782906
29.58050	169.5859	-2.782949
29.63050	169.5866	-2.782915
29.68216	169.5864	-2.782856
29.73383	169.5862	-2.782758
29.78383	169.5853	-2.782813
29.83383	169.5856	-2.782781
29.88716	169.5856	-2.782766
29.93717	169.5859	-2.782790
29.98716	169.5862	-2.782719
30.03883	169.5859	-2.782725
30.09050	169.5854	-2.782697
30.14050	169.5854	-2.782626
30.19050	169.5847	-2.782498
30.24216	169.5844	-2.782369
30.29383	169.5854	-2.782175
30.34383	169.5856	-2.782086
30.39383	169.5844	-2.781914
30.44717	169.5846	-2.781819
30.49716	169.5851	-2.781811
30.54716	169.5858	-2.781780
30.59883	169.5843	-2.781743
30.65050	169.5849	-2.781829
30.70050	169.5850	-2.781871
30.75050	169.5844	-2.781792
30.80217	169.5852	-2.781761
30.85383	169.5845	-2.781778
30.90383	169.5849	-2.781786
30.95383	169.5850	-2.781770
31.00716	169.5848	-2.781744
31.05716	169.5851	-2.781746
31.10716	169.5841	-2.781836
31.15883	169.5851	-2.781898
31.21050	169.5851	-2.781910
31.26050	169.5849	-2.781976
31.31050	169.5844	-2.782046
31.36216	169.5856	-2.782286
31.41383	169.5854	-2.782572
31.46383	169.5862	-2.782871
31.51383	169.5859	-2.783136
31.56716	169.5865	-2.783482
31.61716	169.5869	-2.783734
31.66716	169.5863	-2.783846
31.71883	169.5869	-2.783909
31.77050	169.5873	-2.784024
31.82050	169.5869	-2.783982
31.87050	169.5869	-2.784086
31.92383	169.5864	-2.784153
31.97383	169.5861	-2.784224
32.02383	169.5872	-2.784357
32.07550	169.5869	-2.784432
32.12717	169.5869	-2.784421
32.17717	169.5873	-2.784424
32.22717	169.5870	-2.784497
32.27883	169.5870	-2.784442
32.33050	169.5870	-2.784424
32.38050	169.5869	-2.784356
32.43050	169.5864	-2.784271
32.48383	169.5866	-2.784141
32.53383	169.5868	-2.784094
32.58383	169.5861	-2.783943
32.63550	169.5858	-2.783834
32.68716	169.5853	-2.783654
32.73717	169.5850	-2.783494
32.78717	169.5843	-2.783362
32.83883	169.5851	-2.783289
32.89050	169.5853	-2.783235
32.94050	169.5843	-2.783191
32.99050	169.5846	-2.783306
33.04383	169.5863	-2.783502
33.09384	169.5849	-2.783535
33.14383	169.5845	-2.783548
33.19550	169.5849	-2.783625
33.24716	169.5850	-2.783778
33.29716	169.5850	-2.784032
33.34716	169.5853	-2.784237
33.39883	169.5861	-2.784424
33.45050	169.5857	-2.784544
33.50050	169.5856	-2.784676
33.55050	169.5863	-2.784823
33.60383	169.5859	-2.784975
33.65383	169.5859	-2.785066
33.70383	169.5860	-2.785176
33.75550	169.5854	-2.785197
33.80716	169.5853	-2.785166
33.85716	169.5856	-2.785118
33.90716	169.5852	-2.785050
33.96050	169.5860	-2.784955
34.01050	169.5858	-2.784778
34.06050	169.5853	-2.784619
34.11217	169.5856	-2.784591
34.16383	169.5851	-2.784569
34.21383	169.5850	-2.784668
34.26383	169.5856	-2.784784
34.31550	169.5856	-2.784991
34.36716	169.5851	-2.785079
34.41716	169.5858	-2.785092
34.46716	169.5860	-2.785066
34.52050	169.5860	-2.784981
34.57050	169.5864	-2.784978
34.62050	169.5861	-2.785037
34.67216	169.5858	-2.785058
34.72383	169.5868	-2.785115
34.77383	169.5859	-2.785080
34.82383	169.5854	-2.785046
34.87550	169.5859	-2.785113
34.92717	169.5869	-2.785044
34.97717	169.5862	-2.784876
35.02716	169.5860	-2.784846
35.08050	169.5854	-2.784861
35.13050	169.5856	-2.784908
35.18050	169.5866	-2.785139
35.23216	169.5867	-2.785175
35.28383	169.5866	-2.785194
35.33383	169.5866	-2.785230
35.38383	169.5862	-2.785169
35.43550	169.5866	-2.785208
35.48717	169.5862	-2.785166
35.53717	169.5858	-2.785211
35.58716	169.5866	-2.785303
35.64050	169.5864	-2.785418
35.69050	169.5866	-2.785504
35.74050	169.5871	-2.785580
35.79217	169.5867	-2.785541
35.84384	169.5866	-2.785421
35.89383	169.5865	-2.785181
35.94383	169.5851	-2.784960
35.99716	169.5859	-2.784851
36.04716	169.5848	-2.784662
36.09716	169.5852	-2.784538
36.14883	169.5854	-2.784580
36.20050	169.5856	-2.784528
36.25050	169.5850	-2.784604
36.30050	169.5852	-2.784686
36.35217	169.5851	-2.784834
36.40383	169.5864	-2.785060
36.45383	169.5855	-2.785167
36.50383	169.5856	-2.785266
36.55716	169.5862	-2.785268
36.60716	169.5854	-2.785268
36.65716	169.5854	-2.785280
36.70883	169.5860	-2.785298
36.76050	169.5864	-2.785341
36.81050	169.5855	-2.785318
36.86050	169.5853	-2.785281
36.91217	169.5854	-2.785256
36.96383	169.5856	-2.785208
37.01383	169.5861	-2.785193
37.06383	169.5852	-2.785124
37.11716	169.5854	-2.785269
37.16716	169.5864	-2.785298
37.21716	169.5858	-2.785396
37.26883	169.5856	-2.785468
37.32050	169.5854	-2.785488
37.37050	169.5856	-2.785620
37.42050	169.5857	-2.785600
37.47217	169.5859	-2.785689
37.52383	169.5855	-2.785814
37.57383	169.5862	-2.785980
37.62383	169.5855	-2.786124
37.67717	169.5868	-2.786183
37.72717	169.5860	-2.786156
37.77716	169.5861	-2.786125
37.82883	169.5866	-2.786070
37.88050	169.5861	-2.785900
37.93050	169.5861	-2.785722
37.98050	169.5859	-2.785550
38.03383	169.5858	-2.785486
38.08383	169.5857	-2.785468
38.13383	169.5856	-2.785389
38.18550	169.5854	-2.785368
38.23717	169.5858	-2.785280
38.28717	169.5864	-2.785240
38.33716	169.5866	-2.785241
38.38883	169.5861	-2.785248
38.44050	169.5867	-2.785280
38.49050	169.5860	-2.785349
38.54050	169.5861	-2.785482
38.59384	169.5866	-2.785512
38.64383	169.5867	-2.785515
38.69383	169.5865	-2.785562
38.74550	169.5863	-2.785653
38.79716	169.5861	-2.785631
38.84716	169.5869	-2.785616
38.89717	169.5866	-2.785459
38.94883	169.5867	-2.785385
39.00050	169.5852	-2.785268
39.05050	169.5867	-2.785278
39.10050	169.5868	-2.785169
39.15383	169.5859	-2.785230
39.20383	169.5864	-2.785207
39.25383	169.5867	-2.785211
39.30550	169.5858	-2.785183
39.35716	169.5860	-2.785193
39.40716	169.5858	-2.785072
39.45716	169.5860	-2.784888
39.50883	169.5856	-2.784790
39.56050	169.5860	-2.784619
39.61050	169.5847	-2.784321
39.66050	169.5860	-2.784222
39.71383	169.5856	-2.784160
39.76383	169.5857	-2.784192
39.81383	169.5858	-2.784239
39.86550	169.5860	-2.784350
39.91716	169.5858	-2.784509
39.96716	169.5867	-2.784636
40.01716	169.5866	-2.784778
40.07050	169.5864	-2.784857
40.12050	169.5866	-2.784997
40.17050	169.5865	-2.785079
40.22217	169.5861	-2.785159
40.27383	169.5862	-2.785262
40.32383	169.5866	-2.785350
40.37383	169.5867	-2.785320
40.42550	169.5862	-2.785266
40.47717	169.5867	-2.785176
40.52716	169.5866	-2.784986
40.57717	169.5856	-2.784793
40.63050	169.5855	-2.784570
40.68050	169.5856	-2.784463
40.73050	169.5861	-2.784470
40.78216	169.5862	-2.784566
40.83383	169.5863	-2.784719
40.88383	169.5864	-2.784868
40.93384	169.5869	-2.785062
40.98550	169.5869	-2.785204
41.03717	169.5869	-2.785337
41.08716	169.5866	-2.785412
41.13716	169.5874	-2.785456
41.19050	169.5862	-2.785400
41.24050	169.5864	-2.785390
41.29050	169.5872	-2.785380
41.34217	169.5854	-2.785181
41.39383	169.5867	-2.785031
41.44383	169.5858	-2.784882
41.49383	169.5848	-2.784765
41.54550	169.5852	-2.784741
41.59716	169.5857	-2.784702
41.64717	169.5856	-2.784842
41.69717	169.5859	-2.784968
41.75050	169.5870	-2.785096
41.80050	169.5866	-2.785144
41.85050	169.5854	-2.785039
41.90216	169.5858	-2.784984
41.95383	169.5857	-2.784857
42.00383	169.5864	-2.784763
42.05383	169.5860	-2.784622
42.10717	169.5858	-2.784638
42.15717	169.5851	-2.784558
42.20717	169.5855	-2.784610
42.25883	169.5863	-2.784712
42.31050	169.5863	-2.784829
42.36050	169.5861	-2.785084
42.41050	169.5864	-2.785170
42.46216	169.5861	-2.785243
42.51383	169.5866	-2.785340
42.56383	169.5873	-2.785400
42.61383	169.5859	-2.785444
42.66716	169.5867	-2.785562
42.71717	169.5867	-2.785550
42.76717	169.5867	-2.785516
42.81883	169.5861	-2.785420
42.87050	169.5863	-2.785292
42.92050	169.5859	-2.785260
42.97050	169.5857	-2.785218
43.02050	169.5862	-2.786008
43.07217	169.6577	-5.372540
43.12383	169.9829	-9.855405
43.17383	170.4882	-13.06492
43.22383	171.1284	-15.51991
43.27716	171.9156	-17.36209
43.32717	172.7241	-18.59991
43.37717	173.5802	-19.49344
43.42883	174.5009	-20.17146
43.48050	175.4464	-20.68312
43.53050	176.3782	-21.06698
43.58050	177.3225	-21.38518
43.63217	178.3076	-21.65582
43.68383	179.3003	-21.88890
43.73383	180.2649	-22.09152
43.78383	181.2336	-22.29705
43.83716	182.2676	-22.52304
43.88716	183.2410	-22.73166
43.93716	184.2148	-22.94031
43.98883	185.2229	-23.17390
44.04050	186.2304	-23.42718
44.09050	187.2064	-23.69179
44.14050	188.1826	-24.00789
44.19383	189.2205	-24.36125
44.24383	190.1934	-24.76022
44.29383	191.1642	-25.20342
44.34550	192.1632	-25.75630
44.39717	193.1570	-26.39053
44.44717	194.1162	-27.06865
44.49716	195.0711	-27.89386
44.54883	196.0475	-28.93376
44.60050	197.0173	-30.12660
44.65050	197.9472	-31.40074
44.70050	198.8684	-32.78561
44.75383	199.8394	-34.60207
44.80383	200.7362	-36.57080
44.85383	201.6167	-38.88537
44.90550	202.5072	-41.64274
44.95717	203.3787	-44.57541
45.00717	204.2151	-47.29120
45.05717	205.0520	-49.83844
45.10883	205.9256	-52.26272
45.16050	206.8066	-54.72791
45.21050	207.6602	-57.10544
45.26050	208.5211	-59.04504
45.31383	209.4765	-59.83203
45.36383	210.4361	-58.94256
45.41383	211.4956	-55.06721
45.46550	212.7516	-47.29360
45.51717	214.1850	-38.11523
45.56717	215.5756	-33.45496
45.61716	216.8690	-30.75620
45.66883	218.1187	-28.83840
45.72050	219.3035	-27.49261
45.77050	220.4064	-26.59554
45.82050	221.4810	-25.95955
45.87383	222.6014	-25.49524
45.92383	223.6357	-25.20580
45.97383	224.6602	-25.00834
46.02550	225.7094	-24.87813
46.07717	226.7527	-24.81968
46.12717	227.7588	-24.78589
46.17717	228.7622	-24.77917
46.23050	229.8303	-24.77984
46.28050	230.8312	-24.78095
46.33050	231.8299	-24.78614
46.38217	232.8614	-24.80584
46.43383	233.8932	-24.84221
46.48383	234.8905	-24.88961
46.53383	235.8881	-24.93104
46.58550	236.9196	-24.97595
46.63716	237.9506	-25.02051
46.68716	238.9496	-25.05687
46.73717	239.9460	-25.10262
46.79050	241.0108	-25.15958
46.84050	242.0086	-25.20245
46.89050	243.0058	-25.24623
46.94217	244.0376	-25.28342
46.99383	245.0686	-25.32112
47.04383	246.0664	-25.35670
47.09384	247.0637	-25.38904
47.14550	248.0948	-25.42133
47.19717	249.1263	-25.45240
47.24716	250.1244	-25.48424
47.29716	251.1242	-25.51314
47.35050	252.1889	-25.53808
47.40050	253.1881	-25.56218
47.45050	254.1855	-25.58236
47.50217	255.2174	-25.61830
47.55383	256.2476	-25.65618
47.60383	257.2444	-25.70219
47.65383	258.2418	-25.75474
47.70550	259.2718	-25.80476
47.75717	260.3018	-25.84729
47.80717	261.2976	-25.88942
47.85717	262.2960	-25.94694
47.91050	263.3604	-25.97966
47.96050	264.3590	-26.01434
48.01050	265.3563	-26.04900
48.06216	266.3881	-26.08315
48.11383	267.4191	-26.11244
48.16383	268.4154	-26.15092
48.21383	269.4143	-26.19625
48.26717	270.4791	-26.22695
48.31717	271.4752	-26.25680
48.36716	272.4726	-26.29388
48.41883	273.5035	-26.33206
48.47050	274.5332	-26.34791
48.51717	275.4638	-26.49026
48.56717	276.3008	-27.55192
48.62050	276.6074	-19.78891
48.67050	276.5324	-11.47247
48.72050	276.2066	-4.613161
48.77217	275.6884	0.7089532
48.82383	275.0366	4.594436
48.87383	274.3164	7.324576
48.92383	273.5310	9.322456
48.97550	272.6708	10.80571
49.02716	271.7744	11.88279
49.07717	270.8808	12.63197
49.12717	269.9698	13.18612
49.18050	268.9808	13.62566
49.23050	268.0420	13.92530
49.28050	267.0964	14.15390
49.33217	266.1115	14.33122
49.38383	265.1210	14.46896
49.43383	264.1575	14.56996
49.48383	263.1896	14.65975
49.53717	262.1548	14.73410
49.58716	261.1826	14.78581
49.63716	260.2064	14.83138
49.68883	259.1972	14.87136
49.74050	258.1856	14.90438
49.79050	257.2065	14.93157
49.84050	256.2246	14.95694
49.89217	255.2088	14.98212
49.94383	254.1921	15.00366
49.99383	253.2066	15.01981
50.04383	252.2212	15.03569
50.09716	251.1690	15.05182
50.14717	250.1824	15.06573
50.19717	249.1947	15.08097
50.24883	248.1745	15.09506
50.30050	247.1534	15.11195
50.35050	246.1650	15.12804
50.40050	245.1758	15.14475
50.45216	244.1527	15.15526
50.50383	243.1308	15.16290
50.55383	242.1401	15.17525
50.60383	241.1505	15.18222
50.65717	240.0934	15.19720
50.70717	239.1030	15.20921
50.75717	238.1115	15.21840
50.80883	237.0882	15.22774
50.86050	236.0634	15.24003
50.91050	235.0718	15.24841
50.96050	234.0808	15.25718
51.01216	233.0555	15.26552
51.06383	232.0303	15.27387
51.11383	231.0377	15.28296
51.16383	230.0456	15.29130
51.21717	228.9875	15.30038
51.26716	227.9951	15.31150
51.31716	227.0016	15.32245
51.36883	225.9755	15.33097
51.42050	224.9494	15.34031
51.47050	223.9567	15.34950
51.52050	222.9638	15.35958
51.57383	221.9050	15.37135
51.62383	220.9113	15.38043
51.67383	219.9174	15.39117
51.72550	218.8908	15.40029
51.77717	217.8642	15.40918
51.82717	216.8712	15.41759
51.87717	215.8775	15.42626
51.92883	214.8515	15.43647
51.98050	213.8258	15.44628
52.03050	212.8333	15.45702
52.08050	211.8402	15.46794
52.13383	210.7805	15.47877
52.18383	209.7879	15.48812
52.23383	208.7940	15.50100
52.28550	207.7673	15.51054
52.33716	206.7403	15.52105
52.38716	205.7464	15.52962
52.43716	204.7538	15.53907
52.48882	203.7263	15.54801
52.54050	202.6999	15.55718
52.59050	201.7073	15.56576
52.64050	200.7132	15.57481
52.69384	199.6533	15.58420
52.74382	198.6587	15.59484
52.79382	197.6643	15.60342
52.84550	196.6375	15.61198
52.89717	195.6104	15.62099
52.94717	194.6167	15.63022
52.99717	193.6230	15.63940
53.04883	192.5959	15.64886
53.10050	191.5682	15.65858
53.15050	190.5748	15.66704
53.20050	189.5808	15.67560
53.25383	188.5215	15.68441
53.30383	187.5262	15.69307
53.35383	186.5326	15.70306
53.40550	185.5057	15.71303
53.45717	184.4787	15.72184
53.50717	183.4836	15.72969
53.55717	182.4905	15.73756
53.61050	181.4282	15.74582
53.66050	180.4347	15.75359
53.71050	179.4405	15.76401
53.76216	178.4137	15.77479
53.81382	177.3865	15.78662
53.86382	176.3927	15.79912
53.91382	175.3988	15.81039
53.96550	174.3697	15.82211
54.01716	173.3427	15.83157
54.06716	172.3472	15.83997
54.11716	171.3524	15.84814
54.17050	170.2916	15.85648
54.22050	169.2977	15.86471
54.27050	168.3038	15.87444
54.32217	167.2782	15.88893
54.37383	166.2516	15.92938
54.42383	165.2611	16.03822
54.47382	164.2720	16.26799
54.52550	163.2551	16.61218
54.57717	162.2489	17.19709
54.62717	161.2913	18.21475
54.67717	160.3642	19.88187
54.73050	159.4200	22.53564
54.78050	158.5818	25.80333
54.83050	157.7879	29.50476
54.88217	156.9924	33.25730
54.93383	156.1923	36.36310
54.98383	155.3852	38.42130
55.03383	154.5264	39.45483
55.08550	153.5792	39.48712
55.13716	152.5689	38.89280
55.18716	151.5403	37.32261
55.23717	150.4734	35.62442
55.29050	149.3087	33.67438
55.34050	148.2046	31.88822
55.39050	147.0994	30.23628
55.44216	145.9611	28.68548
55.49382	144.8311	27.32830
55.54382	143.7502	26.19541
55.59384	142.6769	25.15902
55.64717	141.5412	24.13623
55.69717	140.4816	23.30504
55.74717	139.4297	22.57478
55.79883	138.3518	21.93919
55.85050	137.2776	21.34637
55.90050	136.2432	20.85622
55.95050	135.2131	20.39867
56.00217	134.1522	19.97996
56.05383	133.0944	19.60619
56.10383	132.0742	19.28386
56.15383	131.0567	18.99756
56.20717	129.9731	18.71830
56.25717	128.9603	18.49277
56.30717	127.9487	18.29294
56.35883	126.9064	18.11149
56.41050	125.8653	17.95518
56.46050	124.8592	17.81397
56.51050	123.8547	17.68250
56.56216	122.8175	17.56828
56.61382	121.7806	17.46096
56.66382	120.7779	17.37822
56.71382	119.7756	17.29726
56.76716	118.7082	17.21948
56.81716	117.7067	17.15449
56.86716	116.7072	17.09658
56.91882	115.6710	16.84628
56.97050	114.6310	16.69986
57.02050	113.6258	16.60243
57.07050	112.6218	16.49806
57.12217	111.5839	16.40688
57.17383	110.5495	16.31832
57.22382	109.5476	16.24652
57.27383	108.5468	16.17297
57.32717	107.4794	16.07916
57.37717	106.4770	15.99615
57.42717	105.4743	15.89914
57.47883	104.4398	15.81137
57.53050	103.4056	15.74384
57.58050	102.4043	15.66910
57.63050	101.4039	15.60312
57.68383	100.3367	15.53569
57.73383	99.33730	15.48772
57.78383	98.33902	15.44171
57.83550	97.30626	15.39558
57.88716	96.27374	15.33011
57.93716	95.27326	15.26725
57.98717	94.27432	15.21112
58.03882	93.24106	15.14066
58.09050	92.20806	15.09459
58.14050	91.20895	15.04180
58.19050	90.21001	14.97798
58.24382	89.14399	14.92089
58.29382	88.14431	14.87241
58.34384	87.14520	14.82779
58.39550	86.11212	14.76777
58.44717	85.07960	14.71139
58.49717	84.08101	14.66522
58.54717	83.08072	14.61446
58.59882	82.04819	14.55801
58.65050	81.01386	14.50548
58.70050	80.01549	14.44705
58.75050	79.01637	14.39651
58.80383	77.95080	14.34766
58.85383	76.95106	14.30790
58.90383	75.95244	14.25520
58.95550	74.92042	14.21506
59.00717	73.88930	14.16646
59.05717	72.88980	14.12678
59.10717	71.89110	14.07844
59.15883	70.85801	14.02963
59.21050	69.82543	13.97839
59.26050	68.82624	13.92837
59.31050	67.82710	13.88399
59.36382	66.76084	13.82372
59.41382	65.76374	13.78254
59.46382	64.76418	13.74300
59.51550	63.73072	13.68527
59.56716	62.69870	13.63464
59.61716	61.69898	13.57907
59.66716	60.69890	13.52469
59.72050	59.63265	13.47295
59.77050	58.63337	13.41748
59.82050	57.63374	13.37074
59.87217	56.60026	13.32049
59.92383	55.56850	13.26961
59.97382	54.56998	13.22516
60.02383	53.56955	13.17829
60.07550	52.53729	13.12700
60.12717	51.50362	13.07601
60.17717	50.50420	13.01853
60.22717	49.50488	12.97803
60.28050	48.43761	12.92214
60.33050	47.43860	12.86448
60.38050	46.43847	12.82216
60.43217	45.40458	12.77294
60.48383	44.37109	12.71099
60.53383	43.37091	12.66487
60.58383	42.37142	12.60778
60.63550	41.33790	12.55356
60.68716	40.30469	12.49624
60.73717	39.30406	12.43539
60.78716	38.30202	12.37202
60.84050	37.23407	12.29144
60.89050	36.23232	12.22388
60.94050	35.23035	12.15591
60.99216	34.19590	12.08120
61.04382	33.16134	12.01993
61.09384	32.15956	11.94546
61.14384	31.15887	11.87445
61.19550	30.12462	11.81469
61.24717	29.08870	11.74416
61.29717	28.08874	11.67049
61.34716	27.08805	11.61620
61.40050	26.02031	11.53905
61.45050	25.01814	11.49335
-2.000000	4.000000	0.0000000
61.54883	23.09244	12.03022
61.60050	22.56337	8.444581
61.65050	22.49122	3.246242
61.70050	22.70622	-0.7768198
61.75383	23.16903	-3.800585
61.80383	23.75755	-5.813828
61.85383	24.45105	-7.238797
61.90550	25.24889	-8.309074
61.95717	26.10380	-9.080949
62.00717	26.96908	-9.636929
62.05717	27.86366	-10.06486
62.10883	28.80914	-10.40845
62.16050	29.77100	-10.66023
62.21050	30.71175	-10.85797
62.26050	31.66115	-11.01787
62.31382	32.68212	-11.16137
62.36382	33.64505	-11.28430
62.41382	34.61018	-11.37960
62.46550	35.61230	-11.47181
62.51716	36.61612	-11.55517
62.56716	37.59146	-11.62944
62.61716	38.56784	-11.69778
62.66882	39.57813	-11.76238
62.72050	40.59153	-11.82692
62.77050	41.57244	-11.88269
62.82050	42.55421	-11.94251
62.87383	43.60392	-12.00211
62.92383	44.58894	-12.05452
62.97382	45.57466	-12.10554
63.02550	46.59314	-12.16045
63.07717	47.61319	-12.22318
63.12717	48.60066	-12.27803
63.17717	49.58790	-12.34107
63.22883	50.60834	-12.40783
63.28050	51.63064	-12.47785
63.33050	52.61894	-12.53838
63.38050	53.60972	-12.60145
63.43383	54.66568	-12.65737
63.48383	55.65687	-12.72146
63.53383	56.64707	-12.78986
63.58550	57.67024	-12.85831
63.63716	58.69414	-12.92501
63.68716	59.68493	-12.99716
63.73717	60.67546	-13.06094
63.79050	61.73242	-13.14739
63.84050	62.72660	-13.21016
63.89050	63.71792	-13.27828
63.94216	64.74360	-13.34359
63.99382	65.76972	-13.41158
64.04384	66.76356	-13.47700
64.09384	67.75579	-13.54629
64.14550	68.78301	-13.61504
64.19717	69.80925	-13.68864
64.24717	70.80356	-13.75128
64.29718	71.79852	-13.81995
64.35050	72.85868	-13.89129
64.40050	73.85194	-13.95782
64.45050	74.84692	-14.03434
64.50217	75.87320	-14.10712
64.55383	76.90030	-14.18984
64.60383	77.89434	-14.26872
64.65384	78.88715	-14.34760
64.70550	79.91487	-14.43400
64.75718	80.94239	-14.50913
64.80717	81.93676	-14.58656
64.85718	82.93046	-14.66972
64.91050	83.99080	-14.75930
64.96050	84.98481	-14.84256
65.01050	85.98028	-14.92367
65.06216	87.00793	-15.00735
65.11384	88.03416	-15.09436
65.16382	89.03009	-15.17880
65.21384	90.02350	-15.26723
65.26550	91.05209	-15.35146
65.31717	92.07874	-15.43849
65.36718	93.07381	-15.53588
65.41717	94.06681	-15.62126
65.47050	95.12720	-15.72134
65.52050	96.12078	-15.81524
65.57050	97.11580	-15.90075
65.62218	98.14178	-15.99371
65.67384	99.16955	-16.08742
65.72384	100.1637	-16.17858
65.77384	101.1582	-16.26754
65.82718	102.2184	-16.36988
65.87718	103.2122	-16.46219
65.92718	104.2066	-16.55660
65.97884	105.2327	-16.66018
66.03050	106.2590	-16.76200
66.08050	107.2524	-16.86483
66.13050	108.2467	-16.96010
66.18218	109.2736	-17.06513
66.23384	110.3019	-17.16426
66.28384	111.2957	-17.26886
66.33384	112.2908	-17.36248
66.38718	113.3512	-17.47183
66.43718	114.3446	-17.56939
66.48718	115.3381	-17.67992
66.53882	116.3644	-17.78459
66.59050	117.3908	-17.89468
66.64050	118.3834	-18.00954
66.69050	119.3755	-18.12778
66.74218	120.4017	-18.24850
66.79384	121.4274	-18.37375
66.84384	122.4195	-18.49402
66.89384	123.4130	-18.61227
66.94718	124.4723	-18.73720
66.99718	125.4646	-18.85598
67.04718	126.4587	-18.97917
67.09882	127.4848	-19.09344
67.15050	128.5122	-19.22262
67.20050	129.5051	-19.33178
67.25050	130.4971	-19.46269
67.30218	131.5242	-19.59566
67.35384	132.5494	-19.71641
67.40384	133.5419	-19.86140
67.45384	134.5345	-19.98968
67.50718	135.5926	-20.15253
67.55718	136.5840	-20.30308
67.60718	137.5762	-20.43609
67.65884	138.6015	-20.59101
67.71050	139.6254	-20.73268
67.76050	140.6182	-20.88403
67.81050	141.6108	-21.02988
67.86384	142.6688	-21.16367
67.91382	143.6616	-21.28919
67.96384	144.6537	-21.43474
68.01550	145.6786	-21.57888
68.06718	146.7033	-21.73866
68.11718	147.6962	-21.79840
68.16718	148.6906	-21.90078
68.21884	149.7186	-22.03531
68.27050	150.7454	-22.13016
68.32050	151.7378	-22.39158
68.37050	152.7318	-22.34319
68.42384	153.7936	-22.41554
68.47384	154.7903	-22.42778
68.52384	155.7918	-22.42576
68.57550	156.8254	-22.42494
68.62718	157.8587	-22.42572
68.67718	158.8592	-22.42962
68.72718	159.8589	-22.43420
68.77884	160.8926	-22.46706
68.83050	161.9267	-22.48656
68.88050	162.9249	-22.55474
68.93050	163.9238	-22.60717
68.98384	164.9886	-22.68052
69.03384	165.9852	-22.77050
69.08384	166.9809	-22.90059
69.13550	168.0094	-22.99926
69.18718	169.0373	-23.12337
69.23718	170.0305	-23.26316
69.28718	171.0221	-23.41884
69.33884	172.0473	-23.59402
69.39050	173.0712	-23.76678
69.44050	174.0619	-23.95467
69.49050	175.0508	-24.16289
69.54384	176.1062	-24.39100
69.59384	177.0931	-24.63165
69.64384	178.0798	-24.90284
69.69550	179.0957	-25.21016
69.74718	180.1117	-25.54353
69.79718	181.0929	-25.85705
69.84718	182.0722	-26.26694
69.90050	183.1150	-26.71464
69.95050	184.0898	-27.18994
70.00050	185.0623	-27.69260
70.05218	186.0656	-28.26334
70.10384	187.0646	-28.88209
70.15384	188.0297	-29.50906
70.20384	188.9938	-30.14610
70.25550	189.9873	-30.82212
70.30718	190.9814	-31.51144
70.35718	191.9404	-32.19963
70.40718	192.8991	-32.95854
70.46050	193.9183	-33.80455
70.51050	194.8714	-34.68609
70.56050	195.8183	-35.63160
70.61218	196.7941	-36.69687
70.66382	197.7665	-37.75524
70.71384	198.7052	-38.78542
70.76384	199.6458	-39.71994
70.81550	200.6228	-40.48842
70.86718	201.6117	-40.88909
70.91718	202.5904	-40.65486
70.96718	203.6053	-39.43164
71.02050	204.7478	-36.67648
71.07050	205.8878	-32.91895
71.12050	207.0774	-29.29375
71.17218	208.2956	-27.10945
71.22384	209.4681	-25.88652
71.27384	210.5625	-25.14236
71.32384	211.6288	-24.60670
71.37550	212.7090	-24.26076
71.42718	213.7740	-24.02476
71.47718	214.7953	-23.87926
71.52718	215.8084	-23.79174
71.58050	216.8853	-23.75064
71.63050	217.8914	-23.73104
71.68050	218.8955	-23.72054
71.73218	219.9313	-23.71854
71.78384	220.9666	-23.71862
71.83384	221.9670	-23.71956
71.88384	222.9676	-23.72477
71.93718	224.0342	-23.73765
71.98718	225.0340	-23.75315
72.03718	226.0333	-23.77873
72.08884	227.0665	-23.80836
72.14050	228.0992	-23.83213
72.19050	229.0974	-23.87790
72.24050	230.0962	-23.91794
72.29218	231.1266	-23.97423
72.34384	232.1583	-24.04472
72.39384	233.1561	-24.09218
72.44384	234.1547	-24.14930
72.49718	235.2194	-24.20266
72.54718	236.2171	-24.23601
72.59718	237.2150	-24.28123
72.64884	238.2465	-24.32655
72.70050	239.2770	-24.37383
72.75050	240.2749	-24.43012
72.80050	241.2714	-24.48808
72.85218	242.3020	-24.54285
72.90384	243.3333	-24.60909
72.95384	244.3300	-24.65367
73.00384	245.3276	-24.70983
73.05718	246.3926	-24.76119
73.10718	247.3890	-24.80623
73.15718	248.3868	-24.85020
73.20884	249.4181	-24.90566
73.26050	250.4479	-24.94464
73.31050	251.4463	-25.00563
73.36050	252.4445	-25.04968
73.41218	253.4755	-25.10117
73.46384	254.5072	-25.15055
73.51384	255.5034	-25.21326
73.56384	256.5008	-25.28142
73.61718	257.5644	-25.35711
73.66718	258.5611	-25.42398
73.71718	259.5565	-25.48982
73.76882	260.5874	-25.53806
73.82050	261.6173	-25.59720
73.87050	262.6151	-25.65711
73.92050	263.6110	-25.70022
73.97384	264.6752	-25.74879
74.02384	265.6727	-25.80213
74.07384	266.6698	-25.85260
74.12550	267.6996	-25.92061
74.17718	268.7294	-26.01287
74.22718	269.7270	-26.06449
74.27718	270.7228	-26.10854
74.32884	271.7530	-26.16383
-2.000000	5.000000	0.0000000