File: 2-C1(0.8mol%)+C20(0.6mol%)/matlab/140-1.txt
CLOSED
Version	1.0
Language	English
Mode	Standard
Run	1
RunSerial	11878
Instrument	DSC Q2000 V24.11 Build 124
Module	DSC Standard Cell RC
Operator	Jing
File	\\Ae520-1454\ta\Data\DSC\UQ Composites\Nan\C1(7.5)+C20P(3)+CL(Hotplate MixtureAB)\140-1
ProcName	Ramp
InstSerial	2000-0883
AutoSerial	1293
Sample	Iso140-1
Size	44.6000	mg
PanMass	Not available
PanResist	Automatic Automatic  K/W
PanFactor	Default Default
Method	Ramp
Comment
Xcomment	Pan: Tzero Aluminum Hermetic
Xcomment	Gas1: Nitrogen 50.0 ml/min
Xcomment	Gas2: Nitrogen 50.0 ml/min
Text
Exotherm	UP
Kcell	1.05230
Cpconst	Standard: 0.938
Calib	-38.6961
TempCal	1	pts	157.46	156.60
TzeroDt	-87.6168 -0.0009 -1.4231
TzeroDtz	-87.6168 0.0057 6.9570
InstCalFile	Tzero: \\Ae520-1454\ta\Data\DSC\Calibration\2017\CALIBRATION\1562_RCS (90)_05_18_2017 10_50_44.TZR
InstCalFile	Baseline: \\Ae520-1454\ta\Data\DSC\Calibration\2017\2017-05-17_Calibration.001
InstCalFile	Sapphire: \\Ae520-1454\ta\Data\DSC\Calibration\2017\2017-05-17_Saphire.001
InstCalDate	Tzero 2017-05-18 Time 10:50:44
TempRange	-87.39 to 398.39 °C at 10.00 °C/min Heat Only
AutoZero	Delta T Offset 0.000 uV
AutoZero	Delta T0 Offset 0.000 uV
MultiptCal	0
MultiPtDesc	0) Not set
AutoCellConst	Calibration Date 2017-05-18 16:59:28
Controls	Gas 1  Event Off  Sampling 0.2
Cell#	RC-01562
CoolingUnit	RCS (90)
SelHeatFlow	Heat Flow T4 (mW)
AutoLidII	Installed
AutoAnalysis	Off
MacroFile
Nsig	3
Sig1	Time (min)
Sig2	Temperature (°C)
Sig3	Heat Flow (mW)
Date	2017-06-22
Time	14:37:39
OrgMethod	1: Equilibrate at 20.00 °C
OrgMethod	2: Ramp 40.00 °C/min to 140.00 °C
OrgMethod	3: Mark end of cycle 1
OrgMethod	4: Isothermal for 40.00 min
OrgMethod	5: Mark end of cycle 2
OrgMethod	6: Ramp 20.00 °C/min to 280.00 °C
OrgMethod	7: Mark end of cycle 3
OrgMethod	8: Ramp 20.00 °C/min to 20.00 °C
OrgMethod	9: Mark end of cycle 4
OrgMethod	10: Ramp 20.00 °C/min to 280.00 °C
OrgMethod	11: Mark end of cycle 5
OrgFile	C:\Users\jarra\Desktop\DSC\2-C1(0.8mol%)+C20(0.6mol%)\140-1
StartOfData
4.99994E-4	19.98838	0.4812742
0.05383332	20.12058	0.1743775
0.1055000	21.00337	-1.977244
0.1571666	22.24626	-5.674169
0.2105000	23.71245	-10.12241
0.2605000	25.21290	-14.31446
0.3138333	26.90579	-18.45555
0.3655000	28.62192	-22.00996
0.4171667	30.39566	-25.07779
0.4705000	32.27706	-27.79955
0.5205000	34.07772	-29.97058
0.5738334	36.03032	-31.96235
0.6238334	37.88513	-33.60524
0.6771668	39.88171	-35.15232
0.7288332	41.83060	-36.51279
0.7805000	43.78861	-37.80370
0.8338332	45.82156	-38.97940
0.8838332	47.73950	-39.94473
0.9371668	49.79353	-40.93890
0.9888332	51.78742	-41.92000
1.040500	53.78334	-42.92376
1.092167	55.77851	-44.02378
1.143833	57.76797	-45.27422
1.197166	59.81769	-46.68750
1.247166	61.73596	-48.15420
1.300500	63.77209	-50.04447
1.352166	65.71650	-52.54500
1.403833	67.60578	-56.28678
1.457167	69.46100	-62.21514
1.507167	71.06587	-70.51660
1.560500	72.61197	-82.33400
1.610500	73.94205	-95.18134
1.663834	75.31574	-109.0205
1.715500	76.67955	-121.7340
1.767167	78.05195	-134.6846
1.820500	79.44593	-147.9014
1.870500	80.94453	-156.7441
1.923834	82.54170	-166.4339
1.975500	84.16358	-174.4717
2.027166	85.91088	-179.4206
2.078833	87.96472	-177.6148
2.130500	90.27574	-172.5418
2.183833	92.84598	-163.7795
2.233833	95.44876	-151.2454
2.287166	98.43303	-135.8395
2.338833	101.2233	-123.7241
2.390500	103.8881	-113.7339
2.443833	106.5277	-105.3148
2.493833	108.9195	-98.85600
2.547166	111.3954	-93.23241
2.597167	113.6576	-88.95304
2.650500	116.0192	-85.23505
2.702166	118.2645	-82.40934
2.753833	120.4749	-80.23080
2.807167	122.7258	-78.53160
2.857167	124.8117	-77.32166
2.910500	127.0170	-76.37534
2.962167	129.1389	-75.69874
3.010500	131.1127	-75.24750
3.060500	132.9612	-74.71032
3.113833	134.1484	-71.36464
3.165500	135.0037	-65.54699
3.217166	135.6820	-58.87140
3.270500	136.2579	-52.03950
3.320500	136.7071	-46.17299
3.373834	137.1084	-40.67340
3.425500	137.4347	-36.11304
3.477167	137.7084	-32.25023
3.528833	137.9399	-29.00625
3.580500	138.1351	-26.28706
3.633833	138.3048	-23.94321
3.683833	138.4401	-22.10390
3.737167	138.5625	-20.46339
3.788833	138.6632	-19.12529
3.840500	138.7496	-18.00871
3.893833	138.8242	-17.03105
3.943833	138.8842	-16.25746
3.997166	138.9400	-15.55724
4.047167	138.9846	-15.00254
4.100500	139.0259	-14.49262
4.152166	139.0601	-14.07504
4.203833	139.0895	-13.71184
4.257167	139.1161	-13.38885
4.307167	139.1371	-13.12182
4.360500	139.1571	-12.87785
4.412167	139.1754	-12.66815
4.463834	139.1905	-12.48081
4.515500	139.2041	-12.31836
4.567167	139.2163	-12.17020
4.620500	139.2270	-12.02882
4.670500	139.2370	-11.91446
4.723834	139.2455	-11.79782
4.775500	139.2537	-11.69690
4.827167	139.2608	-11.60218
4.880500	139.2681	-11.51060
4.930500	139.2739	-11.42914
4.983834	139.2803	-11.34864
5.033834	139.2850	-11.27372
5.087167	139.2906	-11.19380
5.138833	139.2952	-11.12549
5.190500	139.2992	-11.05652
5.243834	139.3043	-10.99044
5.293832	139.3092	-10.92848
5.347168	139.3128	-10.86171
5.398834	139.3169	-10.79780
5.450500	139.3213	-10.73320
5.503834	139.3246	-10.66876
5.553834	139.3286	-10.60874
5.607168	139.3325	-10.54092
5.657166	139.3360	-10.47716
5.710500	139.3398	-10.40987
5.762168	139.3433	-10.34006
5.813832	139.3480	-10.26228
5.867168	139.3530	-10.17583
5.917168	139.3577	-10.08822
5.970500	139.3625	-9.990299
6.020500	139.3674	-9.896789
6.073834	139.3733	-9.795792
6.125500	139.3790	-9.694032
6.177166	139.3837	-9.591219
6.230500	139.3899	-9.486859
6.280500	139.3956	-9.384657
6.333832	139.4010	-9.277912
6.385500	139.4069	-9.174676
6.437168	139.4119	-9.065996
6.490500	139.4179	-8.961441
6.540500	139.4234	-8.852169
6.593832	139.4299	-8.730878
6.643832	139.4362	-8.607098
6.697168	139.4432	-8.476330
6.748834	139.4502	-8.338856
6.800500	139.4573	-8.201706
6.853832	139.4654	-8.046614
6.903832	139.4726	-7.901887
6.957168	139.4808	-7.744837
7.008832	139.4884	-7.590186
7.060500	139.4971	-7.438003
7.112168	139.5042	-7.282970
7.163832	139.5120	-7.125899
7.217168	139.5208	-6.971626
7.267168	139.5286	-6.824019
7.320500	139.5366	-6.666084
7.372168	139.5441	-6.519094
7.423834	139.5508	-6.371551
7.477168	139.5593	-6.221403
7.527168	139.5666	-6.081890
7.580500	139.5743	-5.931178
7.630500	139.5820	-5.791492
7.683832	139.5897	-5.642693
7.735500	139.5973	-5.495396
7.787168	139.6051	-5.343850
7.840500	139.6122	-5.189672
7.890500	139.6197	-5.033377
7.943832	139.6292	-4.870114
7.995500	139.6368	-4.705428
8.047168	139.6459	-4.535180
8.098832	139.6538	-4.365572
8.150500	139.6628	-4.189304
8.203834	139.6712	-4.008015
8.253834	139.6809	-3.831124
8.307168	139.6902	-3.641956
8.358832	139.7004	-3.465500
8.410499	139.7091	-3.297438
8.463834	139.7180	-3.130906
8.513832	139.7250	-2.990496
8.567166	139.7325	-2.855044
8.617166	139.7388	-2.739800
8.670500	139.7446	-2.631246
8.722168	139.7496	-2.534731
8.773834	139.7543	-2.448703
8.827168	139.7590	-2.370908
8.877168	139.7627	-2.306544
8.930500	139.7665	-2.245162
8.982166	139.7689	-2.193713
9.033832	139.7723	-2.150742
9.085501	139.7739	-2.106892
9.137168	139.7764	-2.070168
9.190500	139.7777	-2.035070
9.240500	139.7799	-2.005293
9.293834	139.7811	-1.976213
9.345500	139.7837	-1.951467
9.397168	139.7833	-1.928240
9.450500	139.7852	-1.906229
9.500500	139.7866	-1.890710
9.553832	139.7880	-1.874678
9.603832	139.7888	-1.860055
9.657166	139.7895	-1.845652
9.708832	139.7905	-1.831133
9.760499	139.7914	-1.819479
9.813834	139.7920	-1.807139
9.863834	139.7933	-1.797690
9.917168	139.7941	-1.787505
9.968834	139.7946	-1.777090
10.02050	139.7949	-1.766968
10.07217	139.7961	-1.757158
10.12383	139.7972	-1.747068
10.17717	139.7982	-1.737366
10.22717	139.7982	-1.728400
10.28050	139.7984	-1.718713
10.33217	139.7997	-1.709453
10.38383	139.7999	-1.699744
10.43717	139.8005	-1.690082
10.48717	139.8010	-1.680870
10.54050	139.8014	-1.671031
10.59050	139.8019	-1.662154
10.64383	139.8021	-1.652884
10.69550	139.8025	-1.644335
10.74717	139.8025	-1.635790
10.80050	139.8031	-1.627252
10.85050	139.8038	-1.619152
10.90383	139.8044	-1.610960
10.95550	139.8046	-1.603101
11.00717	139.8048	-1.595391
11.05884	139.8057	-1.587986
11.11050	139.8065	-1.580830
11.16383	139.8066	-1.573751
11.21383	139.8077	-1.567268
11.26717	139.8080	-1.560358
11.31883	139.8076	-1.553476
11.37050	139.8082	-1.546236
11.42383	139.8084	-1.538585
11.47383	139.8087	-1.531071
11.52717	139.8093	-1.523460
11.57717	139.8093	-1.516389
11.63050	139.8099	-1.509113
11.68217	139.8102	-1.502276
11.73383	139.8102	-1.495677
11.78717	139.8104	-1.489032
11.83717	139.8109	-1.482747
11.89050	139.8120	-1.476340
11.94217	139.8116	-1.469911
11.99384	139.8125	-1.463550
12.04717	139.8122	-1.456878
12.09717	139.8125	-1.450366
12.15050	139.8127	-1.443570
12.20050	139.8133	-1.437030
12.25384	139.8144	-1.429884
12.30550	139.8143	-1.423155
12.35717	139.8147	-1.416433
12.41050	139.8154	-1.409938
12.46050	139.8151	-1.403772
12.51383	139.8158	-1.397211
12.56383	139.8167	-1.391216
12.61716	139.8171	-1.384881
12.66883	139.8176	-1.378401
12.72050	139.8176	-1.372031
12.77383	139.8186	-1.365636
12.82384	139.8186	-1.359533
12.87717	139.8190	-1.353143
12.92883	139.8197	-1.346825
12.98050	139.8197	-1.340370
13.03383	139.8197	-1.333376
13.08383	139.8199	-1.326696
13.13717	139.8209	-1.319448
13.18716	139.8214	-1.312552
13.24050	139.8213	-1.304983
13.29216	139.8225	-1.297811
13.34383	139.8228	-1.290639
13.39717	139.8232	-1.283264
13.44717	139.8234	-1.276516
13.50050	139.8231	-1.269174
13.55217	139.8244	-1.262307
13.60383	139.8249	-1.255560
13.65550	139.8250	-1.248614
13.70717	139.8261	-1.241601
13.76050	139.8269	-1.234427
13.81050	139.8274	-1.227668
13.86383	139.8281	-1.220720
13.91550	139.8284	-1.213766
13.96716	139.8290	-1.207019
14.02050	139.8291	-1.200013
14.07050	139.8290	-1.192961
14.12384	139.8302	-1.185227
14.17383	139.8302	-1.177827
14.22717	139.8305	-1.169844
14.27883	139.8311	-1.161666
14.33050	139.8314	-1.153331
14.38383	139.8312	-1.144646
14.43383	139.8311	-1.135865
14.48716	139.8312	-1.126968
14.53883	139.8320	-1.118444
14.59050	139.8316	-1.109734
14.64216	139.8330	-1.100932
14.69384	139.8321	-1.092064
14.74717	139.8330	-1.082854
14.79717	139.8334	-1.074501
14.85050	139.8334	-1.065683
14.90217	139.8337	-1.057429
14.95383	139.8344	-1.049477
15.00717	139.8359	-1.041455
15.05717	139.8357	-1.033953
15.11050	139.8366	-1.025731
15.16050	139.8366	-1.017884
15.21383	139.8370	-1.009475
15.26550	139.8381	-1.001622
15.31716	139.8389	-0.9932789
15.37050	139.8394	-0.9839991
15.42050	139.8398	-0.9755285
15.47383	139.8403	-0.9661291
15.52550	139.8413	-0.9572586
15.57717	139.8410	-0.9472379
15.62883	139.8429	-0.9380581
15.68050	139.8436	-0.9280834
15.73383	139.8447	-0.9189232
15.78383	139.8444	-0.9094093
15.83717	139.8457	-0.8989778
15.88883	139.8462	-0.8873126
15.94050	139.8464	-0.8738608
15.99383	139.8476	-0.8604470
16.04383	139.8474	-0.8471603
16.09717	139.8481	-0.8333400
16.14716	139.8488	-0.8200989
16.20050	139.8497	-0.8052939
16.25217	139.8504	-0.7905322
16.30383	139.8514	-0.7760778
16.35716	139.8520	-0.7579284
16.40716	139.8536	-0.7436831
16.46050	139.8536	-0.7246368
16.51216	139.8549	-0.7066524
16.56383	139.8572	-0.6873489
16.61550	139.8571	-0.6645484
16.66716	139.8589	-0.6410636
16.72050	139.8599	-0.6138072
16.77050	139.8604	-0.5884788
16.82383	139.8622	-0.5617497
16.87550	139.8629	-0.5313363
16.92716	139.8636	-0.5007160
16.98050	139.8648	-0.4719590
17.03050	139.8669	-0.4448258
17.08383	139.8675	-0.4136756
17.13383	139.8690	-0.3861354
17.18716	139.8711	-0.3560676
17.23883	139.8722	-0.3248236
17.29050	139.8741	-0.2940691
17.34383	139.8762	-0.2649114
17.39383	139.8780	-0.2309592
17.44716	139.8802	-0.1978654
17.49883	139.8823	-0.1621265
17.55050	139.8844	-0.1252432
17.60216	139.8862	-.09078199
17.65383	139.8876	-.04946846
17.70716	139.8894	-.01329530
17.75716	139.8912	0.02530333
17.81050	139.8925	0.06538791
17.86216	139.8946	0.1035740
17.91383	139.8958	0.1454563
17.96716	139.8986	0.1861475
18.01716	139.9005	0.2246276
18.07050	139.9020	0.2661522
18.12050	139.9040	0.3047562
18.17383	139.9064	0.3460816
18.22550	139.9086	0.3873483
18.27716	139.9105	0.4298016
18.33050	139.9131	0.4726056
18.38050	139.9147	0.5155187
18.43383	139.9177	0.5567810
18.48550	139.9198	0.6014865
18.53717	139.9216	0.6464508
18.59050	139.9246	0.6908226
18.64050	139.9265	0.7362915
18.69383	139.9295	0.7834076
18.74383	139.9311	0.8291634
18.79716	139.9336	0.8763126
18.84883	139.9361	0.9238848
18.90050	139.9384	0.9688031
18.95383	139.9404	1.018094
19.00383	139.9430	1.063413
19.05716	139.9458	1.113223
19.10716	139.9478	1.159473
19.16050	139.9508	1.207120
19.21216	139.9532	1.255084
19.26383	139.9551	1.304351
19.31716	139.9581	1.350390
19.36716	139.9609	1.396814
19.42050	139.9630	1.445763
19.47216	139.9661	1.491273
19.52383	139.9685	1.535676
19.57716	139.9720	1.585986
19.62716	139.9726	1.633613
19.68050	139.9759	1.680402
19.73050	139.9782	1.727274
19.78383	139.9799	1.779784
19.83550	139.9819	1.825541
19.88716	139.9842	1.872124
19.94050	139.9863	1.917646
19.99050	139.9886	1.961023
20.04383	139.9905	2.009464
20.09550	139.9932	2.050591
20.14716	139.9948	2.094431
20.19884	139.9968	2.135930
20.25050	139.9993	2.177055
20.30383	140.0022	2.220045
20.35383	140.0040	2.260341
20.40716	140.0056	2.303730
20.45883	140.0082	2.343406
20.51050	140.0100	2.385712
20.56383	140.0124	2.428724
20.61383	140.0140	2.466587
20.66716	140.0162	2.505656
20.71716	140.0182	2.544230
20.77050	140.0195	2.584150
20.82216	140.0231	2.621490
20.87383	140.0248	2.659492
20.92717	140.0264	2.698376
20.97716	140.0288	2.734116
21.03050	140.0310	2.771958
21.08216	140.0330	2.809590
21.13383	140.0353	2.847088
21.18550	140.0369	2.883125
21.23716	140.0397	2.920760
21.29050	140.0416	2.958912
21.34050	140.0434	2.996294
21.39383	140.0451	3.033358
21.44550	140.0464	3.072020
21.49716	140.0486	3.111933
21.55050	140.0510	3.148903
21.60050	140.0528	3.184954
21.65383	140.0547	3.221869
21.70383	140.0569	3.256504
21.75716	140.0591	3.296158
21.80883	140.0606	3.334733
21.86050	140.0623	3.374212
21.91383	140.0638	3.415739
21.96383	140.0651	3.450409
22.01716	140.0670	3.491036
22.06883	140.0688	3.528405
22.12050	140.0717	3.564297
22.17216	140.0732	3.602745
22.22383	140.0747	3.640106
22.27717	140.0782	3.677098
22.32716	140.0787	3.713667
22.38050	140.0814	3.752090
22.43216	140.0823	3.788920
22.48383	140.0849	3.826812
22.53717	140.0866	3.864186
22.58716	140.0880	3.901132
22.64050	140.0908	3.939285
22.69050	140.0919	3.974536
22.74383	140.0950	4.012394
22.79550	140.0963	4.051897
22.84716	140.0980	4.087894
22.90050	140.0997	4.125334
22.95050	140.1024	4.160308
23.00383	140.1033	4.198552
23.05550	140.1059	4.231372
23.10716	140.1073	4.269784
23.15883	140.1097	4.304088
23.21050	140.1113	4.338072
23.26383	140.1134	4.372638
23.31383	140.1154	4.405586
23.36716	140.1168	4.439976
23.41883	140.1186	4.474782
23.47050	140.1202	4.506464
23.52383	140.1218	4.539687
23.57383	140.1236	4.570286
23.62716	140.1254	4.602641
23.67717	140.1268	4.633306
23.73050	140.1276	4.666789
23.78216	140.1299	4.696770
23.83383	140.1314	4.725629
23.88716	140.1325	4.755197
23.93716	140.1343	4.781877
23.99050	140.1365	4.811735
24.04216	140.1373	4.838506
24.09383	140.1387	4.865948
24.14550	140.1401	4.893511
24.19716	140.1414	4.919394
24.25050	140.1424	4.945801
24.30050	140.1433	4.972238
24.35383	140.1452	4.997430
24.40550	140.1465	5.020766
24.45717	140.1477	5.044048
24.51050	140.1488	5.066892
24.56050	140.1500	5.089056
24.61383	140.1514	5.111504
24.66383	140.1527	5.132914
24.71716	140.1542	5.156206
24.76883	140.1549	5.179124
24.82050	140.1556	5.199985
24.87383	140.1565	5.223120
24.92383	140.1572	5.244039
24.97716	140.1580	5.263953
25.02883	140.1587	5.282908
25.08050	140.1598	5.301856
25.13383	140.1609	5.319580
25.18383	140.1622	5.333990
25.23716	140.1624	5.353943
25.28717	140.1635	5.366969
25.34050	140.1646	5.381540
25.39216	140.1648	5.397176
25.44383	140.1661	5.409160
25.49716	140.1673	5.425747
25.54716	140.1681	5.438422
25.60050	140.1690	5.451657
25.65050	140.1696	5.462566
25.70383	140.1706	5.474890
25.75550	140.1717	5.486934
25.80716	140.1718	5.498962
25.86050	140.1724	5.511034
25.91050	140.1740	5.522322
25.96383	140.1749	5.533202
26.01550	140.1756	5.543518
26.06716	140.1768	5.554664
26.12050	140.1775	5.566444
26.17050	140.1771	5.578225
26.22383	140.1784	5.589158
26.27383	140.1784	5.599185
26.32717	140.1784	5.612129
26.37883	140.1792	5.622740
26.43050	140.1798	5.633207
26.48383	140.1791	5.643703
26.53383	140.1794	5.652938
26.58716	140.1804	5.662208
26.63883	140.1803	5.670762
26.69050	140.1810	5.678910
26.74216	140.1814	5.686762
26.79383	140.1818	5.694201
26.84716	140.1820	5.701230
26.89716	140.1824	5.707920
26.95050	140.1820	5.714238
27.00217	140.1824	5.718294
27.05383	140.1828	5.721472
27.10716	140.1831	5.724270
27.15716	140.1838	5.726836
27.21050	140.1830	5.729550
27.26050	140.1842	5.731668
27.31383	140.1835	5.733765
27.36550	140.1834	5.735963
27.41716	140.1823	5.738324
27.47050	140.1824	5.740298
27.52050	140.1840	5.741755
27.57383	140.1830	5.743418
27.62550	140.1824	5.744610
27.67717	140.1822	5.745276
27.72883	140.1823	5.745346
27.78050	140.1823	5.744906
27.83383	140.1828	5.744232
27.88383	140.1824	5.743232
27.93717	140.1818	5.741703
27.98883	140.1819	5.739550
28.04050	140.1814	5.737318
28.09383	140.1818	5.734579
28.14383	140.1822	5.731697
28.19717	140.1821	5.728209
28.24716	140.1814	5.724760
28.30050	140.1812	5.720276
28.35217	140.1808	5.715660
28.40383	140.1808	5.710880
28.45716	140.1815	5.705582
28.50716	140.1800	5.700541
28.56050	140.1800	5.695028
28.61216	140.1791	5.689716
28.66383	140.1786	5.684277
28.71550	140.1783	5.678478
28.76716	140.1777	5.672430
28.82050	140.1782	5.666309
28.87050	140.1762	5.660458
28.92383	140.1763	5.653356
28.97550	140.1754	5.645686
29.02717	140.1751	5.636286
29.08050	140.1752	5.625878
29.13050	140.1741	5.616699
29.18383	140.1740	5.603865
29.23383	140.1729	5.591207
29.28717	140.1725	5.578015
29.33883	140.1720	5.564967
29.39050	140.1710	5.552122
29.44383	140.1718	5.537348
29.49383	140.1694	5.525112
29.54716	140.1687	5.511290
29.59883	140.1691	5.495050
29.65050	140.1685	5.479030
29.70217	140.1676	5.460406
29.75383	140.1668	5.441726
29.80716	140.1655	5.426016
29.85716	140.1646	5.408074
29.91050	140.1636	5.390630
29.96216	140.1630	5.371863
30.01383	140.1628	5.354926
30.06716	140.1606	5.336380
30.11716	140.1600	5.317695
30.17050	140.1592	5.298986
30.22050	140.1585	5.283000
30.27383	140.1569	5.263207
30.32550	140.1558	5.242354
30.37716	140.1540	5.221590
30.43050	140.1532	5.199341
30.48050	140.1525	5.178550
30.53383	140.1516	5.152515
30.58550	140.1500	5.132348
30.63716	140.1498	5.111780
30.68883	140.1478	5.088309
30.74050	140.1464	5.068218
30.79383	140.1461	5.043004
30.84383	140.1449	5.022770
30.89716	140.1435	4.999565
30.94883	140.1425	4.975344
31.00050	140.1414	4.950850
31.05383	140.1404	4.925884
31.10383	140.1394	4.904187
31.15716	140.1380	4.882096
31.20716	140.1372	4.857633
31.26050	140.1362	4.831772
31.31217	140.1357	4.806606
31.36383	140.1345	4.783141
31.41716	140.1336	4.759312
31.46716	140.1316	4.735910
31.52050	140.1309	4.715648
31.57217	140.1300	4.694206
31.62383	140.1283	4.669848
31.67717	140.1264	4.646613
31.72717	140.1256	4.623888
31.78050	140.1246	4.600216
31.83050	140.1236	4.576838
31.88383	140.1224	4.550133
31.93550	140.1212	4.527719
31.98717	140.1192	4.504476
32.04050	140.1181	4.477848
32.09050	140.1177	4.451780
32.14383	140.1163	4.427883
32.19383	140.1152	4.404703
32.24716	140.1138	4.379246
32.29883	140.1128	4.353326
32.35050	140.1119	4.328076
32.40383	140.1108	4.302330
32.45383	140.1092	4.280824
32.50716	140.1078	4.257984
32.55883	140.1072	4.236276
32.61050	140.1048	4.216119
32.66383	140.1039	4.194221
32.71383	140.1028	4.171341
32.76716	140.1018	4.145786
32.81716	140.1004	4.124216
32.87050	140.0992	4.097330
32.92216	140.0976	4.075840
32.97383	140.0969	4.053455
33.02716	140.0953	4.027357
33.07717	140.0947	4.003952
33.13050	140.0936	3.979035
33.18216	140.0917	3.956800
33.23383	140.0902	3.931434
33.28550	140.0892	3.907753
33.33716	140.0881	3.884223
33.39050	140.0874	3.861068
33.44050	140.0856	3.839328
33.49383	140.0844	3.814709
33.54550	140.0835	3.793140
33.59716	140.0818	3.771292
33.65050	140.0810	3.748649
33.70050	140.0804	3.725194
33.75383	140.0796	3.700310
33.80383	140.0781	3.679087
33.85716	140.0768	3.655185
33.90883	140.0758	3.632626
33.96050	140.0749	3.610124
34.01383	140.0741	3.586770
34.06383	140.0728	3.566294
34.11716	140.0717	3.541879
34.16883	140.0711	3.519003
34.22050	140.0701	3.498886
34.27217	140.0690	3.477034
34.32383	140.0670	3.459032
34.37717	140.0659	3.436402
34.42717	140.0641	3.415542
34.48050	140.0638	3.394442
34.53216	140.0622	3.372914
34.58383	140.0610	3.353370
34.63716	140.0601	3.332585
34.68716	140.0582	3.312070
34.74050	140.0570	3.288415
34.79050	140.0559	3.267824
34.84384	140.0550	3.244277
34.89550	140.0538	3.221546
34.94717	140.0531	3.199025
35.00050	140.0522	3.174816
35.05050	140.0512	3.153448
35.10383	140.0501	3.131736
35.15550	140.0484	3.110585
35.20716	140.0481	3.086615
35.25883	140.0472	3.066696
35.31050	140.0458	3.044879
35.36383	140.0446	3.022987
35.41383	140.0431	3.000256
35.46716	140.0436	2.976847
35.51883	140.0420	2.955696
35.57050	140.0415	2.934980
35.62383	140.0397	2.914099
35.67383	140.0396	2.894664
35.72717	140.0379	2.874269
35.77716	140.0366	2.854064
35.83050	140.0359	2.829652
35.88216	140.0349	2.807892
35.93384	140.0324	2.787054
35.98717	140.0322	2.764100
36.03717	140.0313	2.742848
36.09050	140.0299	2.721213
36.14216	140.0294	2.700422
36.19383	140.0281	2.680440
36.24550	140.0270	2.657406
36.29716	140.0259	2.634720
36.35050	140.0244	2.612679
36.40050	140.0233	2.590772
36.45383	140.0223	2.569862
36.50550	140.0209	2.547965
36.55716	140.0196	2.523634
36.61050	140.0186	2.501094
36.66050	140.0180	2.478514
36.71383	140.0162	2.453960
36.76383	140.0151	2.433164
36.81716	140.0135	2.409870
36.86883	140.0128	2.384750
36.92050	140.0112	2.364444
36.97383	140.0103	2.340866
37.02383	140.0093	2.317673
37.07717	140.0088	2.294868
37.12883	140.0071	2.270771
37.18050	140.0057	2.248903
37.23216	140.0047	2.225546
37.28383	140.0028	2.204684
37.33716	140.0020	2.180773
37.38716	140.0009	2.158126
37.44050	139.9993	2.131631
37.49216	139.9981	2.107680
37.54383	139.9971	2.083535
37.59716	139.9959	2.057617
37.64717	139.9949	2.034494
37.70050	139.9935	2.012213
37.75050	139.9916	1.987003
37.80383	139.9898	1.964566
37.85550	139.9892	1.941513
37.90716	139.9882	1.915878
37.96050	139.9872	1.888857
38.01050	139.9860	1.865610
38.06383	139.9847	1.838387
38.11550	139.9837	1.810400
38.16716	139.9823	1.784302
38.22050	139.9812	1.758615
38.27050	139.9806	1.735294
38.32383	139.9795	1.710734
38.37383	139.9769	1.686498
38.42717	139.9764	1.659824
38.47883	139.9752	1.635213
38.53050	139.9735	1.611090
38.58383	139.9730	1.585525
38.63383	139.9717	1.560692
38.68716	139.9702	1.534962
38.73717	139.9691	1.513357
38.79050	139.9679	1.488495
38.84216	139.9671	1.466636
38.89383	139.9664	1.441400
38.94717	139.9639	1.414661
38.99716	139.9624	1.384626
39.05050	139.9624	1.356728
39.10217	139.9606	1.328706
39.15383	139.9593	1.301843
39.20716	139.9582	1.276061
39.25716	139.9569	1.251635
39.31050	139.9558	1.225982
39.36050	139.9533	1.204496
39.41383	139.9520	1.175467
39.46550	139.9501	1.150181
39.51716	139.9492	1.124695
39.57050	139.9478	1.097498
39.62050	139.9460	1.072796
39.67383	139.9440	1.045321
39.72550	139.9430	1.019535
39.77716	139.9420	0.9948853
39.82883	139.9408	0.9672216
39.88050	139.9392	0.9398064
39.93384	139.9378	0.9126138
39.98383	139.9366	0.8873981
40.03717	139.9352	0.8598657
40.08883	139.9342	0.8354913
40.14050	139.9335	0.8093806
40.19383	139.9320	0.7785298
40.24383	139.9302	0.7539460
40.29716	139.9294	0.7263892
40.34716	139.9282	0.7010889
40.40050	139.9263	0.6761793
40.45216	139.9256	0.6531630
40.50383	139.9237	0.6289914
40.55716	139.9236	0.6199849
40.60716	139.9238	0.6081505
40.66050	139.9213	0.5818086
40.71216	139.9201	0.5473955
40.76383	139.9180	0.5201754
40.81550	139.9166	0.4901498
40.86716	139.9144	0.4605392
40.92050	139.9133	0.4335166
40.97050	139.9120	0.4090897
41.02383	139.9111	0.3827706
41.07550	139.9099	0.3556434
41.12717	139.9086	0.3299055
41.18050	139.9074	0.3032455
41.23050	139.9065	0.2782055
41.28383	139.9046	0.2538952
41.33383	139.9040	0.2297778
41.38716	139.9022	0.2046676
41.43883	139.9014	0.1821233
41.49050	139.9004	0.1581400
41.54383	139.8984	0.1331164
41.59384	139.8985	0.1102741
41.64717	139.8971	0.08721834
41.69883	139.8959	0.06281776
41.75050	139.8949	0.04128876
41.80217	139.8940	0.02158371
41.85383	139.8930	.001761289
41.90717	139.8908	-.01900004
41.95717	139.8908	-.03869880
42.01050	139.8893	-.05854026
42.06216	139.8883	-.07869703
42.11383	139.8874	-.09765041
42.16716	139.8865	-0.1168216
42.21717	139.8854	-0.1358621
42.27050	139.8849	-0.1570533
42.32050	139.8838	-0.1777059
42.37383	139.8820	-0.1981416
42.42550	139.8816	-0.2192253
42.47717	139.8803	-0.2394362
42.53050	139.8796	-0.2567715
42.58050	139.8793	-0.2753734
42.63383	139.8780	-0.2952248
42.68550	139.8760	-0.3117520
42.73717	139.8746	-0.3307250
42.78883	139.8729	-0.3523419
42.84050	139.8729	-0.3749611
42.89383	139.8716	-0.3949950
42.94383	139.8706	-0.4127200
42.99716	139.8696	-0.4336453
43.04550	139.9049	-0.4968163
43.09716	140.2751	-1.460303
43.15050	140.8833	-4.064484
43.20050	141.5425	-7.114576
43.25383	142.3159	-10.44337
43.30550	143.1166	-13.43181
43.35717	143.9561	-16.06428
43.41050	144.8569	-18.38500
43.46050	145.7258	-20.22366
43.51383	146.6754	-21.87432
43.56383	147.5836	-23.17305
43.61716	148.5684	-24.33181
43.66883	149.5348	-25.27814
43.72050	150.5117	-26.07273
43.77383	151.5280	-26.77144
43.82383	152.4874	-27.32891
43.87717	153.5167	-27.85002
43.92883	154.5194	-28.28427
43.98050	155.5257	-28.67425
44.03217	156.5356	-29.02430
44.08383	157.5491	-29.33121
44.13716	158.5964	-29.62126
44.18716	159.5815	-29.86928
44.24050	160.6316	-30.11500
44.29217	161.6521	-30.33808
44.34384	162.6731	-30.53244
44.39717	163.7265	-30.72994
44.44717	164.7158	-30.89855
44.50050	165.7727	-30.91809
44.55050	166.7623	-30.99959
44.60383	167.8197	-31.27766
44.65550	168.8424	-31.49190
44.70717	169.8666	-31.69753
44.76050	170.9236	-31.90799
44.81050	171.9139	-32.10336
44.86383	172.9705	-32.32531
44.91550	173.9934	-32.53854
44.96717	175.0161	-32.75709
45.01883	176.0399	-32.98334
45.07050	177.0634	-33.22060
45.12383	178.1184	-33.46863
45.17383	179.1072	-33.71387
45.22717	180.1618	-33.98416
45.27883	181.1826	-34.26742
45.33050	182.2034	-34.56305
45.38383	183.2556	-34.89314
45.43383	184.2413	-35.22815
45.48717	185.2938	-35.60250
45.53717	186.2794	-35.95505
45.59050	187.3298	-36.34202
45.64217	188.3479	-36.73422
45.69383	189.3639	-37.14030
45.74716	190.4122	-37.57990
45.79716	191.3948	-38.00329
45.85050	192.4424	-38.47438
45.90216	193.4553	-38.95174
45.95383	194.4680	-39.44706
46.00717	195.5104	-39.97504
46.05717	196.4896	-40.48830
46.11050	197.5316	-41.07190
46.16050	198.5078	-41.64261
46.21383	199.5474	-42.28354
46.26550	200.5516	-42.94490
46.31717	201.5557	-43.64124
46.37050	202.5901	-44.41959
46.42050	203.5577	-45.19158
46.47383	204.5857	-46.07762
46.52383	205.5480	-46.96563
46.57717	206.5713	-48.00041
46.62883	207.5569	-49.08787
46.68050	208.5406	-50.28264
46.73383	209.5492	-51.63136
46.78383	210.4908	-53.03210
46.83716	211.4854	-54.71086
46.88883	212.4396	-56.56132
46.94050	213.3835	-58.68328
46.99383	214.3415	-61.20662
47.04383	215.2241	-63.93296
47.09716	216.1478	-67.24346
47.14717	216.9970	-70.75774
47.20050	217.8817	-74.93625
47.25217	218.7232	-79.35950
47.30383	219.5483	-84.06976
47.35717	220.3908	-89.10908
47.40717	221.1799	-93.71061
47.46050	222.0503	-97.76370
47.51216	222.9624	-99.84576
47.56383	223.9658	-99.92297
47.61550	225.0564	-98.15832
47.66716	226.2142	-95.13074
47.72050	227.4541	-91.18445
47.77050	228.6469	-86.79184
47.82383	229.9506	-81.50702
47.87550	231.2398	-75.78466
47.92717	232.5508	-69.71753
47.98050	233.8914	-63.99690
48.03050	235.1138	-59.48138
48.08383	236.3756	-55.54190
48.13383	237.5240	-52.54150
48.18716	238.7192	-49.97512
48.23883	239.8520	-47.98267
48.29050	240.9664	-46.39135
48.34384	242.0994	-45.09042
48.39383	243.1497	-44.11204
48.44717	244.2605	-43.27981
48.49883	245.3281	-42.63036
48.55050	246.3890	-42.11016
48.60217	247.4452	-41.69615
48.65383	248.4971	-41.36504
48.70717	249.5784	-41.09440
48.75717	250.5900	-40.90487
48.81050	251.6673	-40.75128
48.86217	252.7085	-40.63838
48.91383	253.7475	-40.56482
48.96717	254.8199	-40.50719
49.01717	255.8226	-40.47410
49.07050	256.8929	-40.46964
49.12050	257.8949	-40.46906
49.17383	258.9634	-40.47444
49.22550	259.9975	-40.50931
49.27716	261.0312	-40.56228
49.33050	262.0970	-40.61696
49.38050	263.0967	-40.68601
49.43383	264.1620	-40.75770
49.48550	265.1943	-40.83450
49.53717	266.2268	-40.92030
49.58883	267.2601	-41.00586
49.64050	268.2910	-41.09861
49.69383	269.3568	-41.19146
49.74383	270.3549	-41.28946
49.79716	271.4190	-41.39107
49.84883	272.4512	-41.49394
49.90050	273.4810	-41.60670
49.95383	274.5455	-41.75008
50.00050	275.4778	-41.78045
50.05383	276.4058	-41.87824
50.10550	276.5625	-39.10802
50.15717	276.3717	-32.38350
50.21050	275.9676	-24.35130
50.26050	275.4675	-17.08043
50.31383	274.8320	-10.22062
50.36550	274.1400	-4.586296
50.41716	273.3876	0.1002389
50.47050	272.5606	4.085085
50.52050	271.7462	7.151297
50.57383	270.8444	9.837089
50.62383	269.9742	11.91145
50.67717	269.0220	13.68523
50.72883	268.0777	15.04291
50.78050	267.1230	16.27038
50.83383	266.1286	17.39890
50.88383	265.1880	18.33428
50.93716	264.1772	19.21852
50.98883	263.1930	19.97762
51.04050	262.2037	20.64618
51.09217	261.2079	21.24617
51.14383	260.2092	21.77398
51.19717	259.1737	22.25138
51.24717	258.2007	22.64358
51.30050	257.1596	23.00941
51.35217	256.1483	23.31854
51.40383	255.1355	23.59436
51.45717	254.0879	23.85583
51.50717	253.1039	24.07246
51.56050	252.0531	24.28047
51.61050	251.0666	24.46314
51.66383	250.0148	24.63512
51.71550	248.9927	24.79375
51.76716	247.9717	24.93790
51.82050	246.9164	25.07667
51.87050	245.9266	25.18527
51.92383	244.8705	25.30254
51.97550	243.8469	25.40746
52.02717	242.8235	25.49996
52.07883	241.7989	25.59150
52.13050	240.7740	25.67935
52.18383	239.7160	25.76424
52.23383	238.7239	25.84100
52.28716	237.6648	25.92190
52.33883	236.6392	25.99654
52.39050	235.6140	26.06340
52.44384	234.5553	26.12573
52.49382	233.5615	26.18501
52.54717	232.5033	26.24146
52.59716	231.5100	26.29319
52.65050	230.4500	26.35460
52.70216	229.4240	26.40803
52.75383	228.3977	26.46389
52.80717	227.3375	26.53128
52.85717	226.3432	26.57795
52.91050	225.2838	26.62990
52.96216	224.2569	26.68618
53.01382	223.2304	26.73047
53.06550	222.2019	26.77814
53.11716	221.1755	26.82334
53.17050	220.1145	26.86744
53.22050	219.1210	26.91820
53.27383	218.0602	26.96538
53.32550	217.0330	27.00124
53.37717	216.0054	27.03982
53.43050	214.9453	27.07874
53.48050	213.9501	27.11235
53.53383	212.8901	27.14624
53.58383	211.8940	27.18539
53.63716	210.8348	27.21900
53.68882	209.8060	27.25031
53.74050	208.7776	27.28150
53.79382	207.7174	27.30430
53.84384	206.7225	27.33172
53.89717	205.6617	27.35648
53.94883	204.6339	27.38030
54.00050	203.6056	27.40830
54.05217	202.5779	27.43148
54.10383	201.5491	27.44994
54.15717	200.4878	27.47422
54.20717	199.4920	27.49513
54.26050	198.4303	27.51457
54.31216	197.4028	27.53618
54.36382	196.3742	27.55512
54.41716	195.3133	27.58354
54.46717	194.3186	27.61188
54.52050	193.2554	27.64060
54.57050	192.2594	27.65618
54.62383	191.1975	27.66719
54.67550	190.1688	27.67925
54.72717	189.1402	27.68846
54.78050	188.0780	27.69996
54.83050	187.0835	27.71383
54.88383	186.0208	27.73518
54.93550	184.9916	27.75070
54.98717	183.9624	27.75916
55.03882	182.9332	27.76782
55.09050	181.9034	27.77672
55.14384	180.8404	27.78492
55.19384	179.8452	27.79277
55.24717	178.7834	27.80644
55.29883	177.7541	27.83084
55.35050	176.7252	27.86618
55.40383	175.6644	27.90882
55.45383	174.6698	27.96340
55.50717	173.6098	28.03206
55.55717	172.6159	28.10946
55.61050	171.5566	28.20702
55.66216	170.5320	28.32111
55.71382	169.5085	28.47992
55.76716	168.4551	28.67994
55.81716	167.4697	28.93200
55.87050	166.4242	29.30133
55.92217	165.4183	29.82456
55.97382	164.4219	30.60362
56.02717	163.4125	31.85421
56.07717	162.4924	33.63125
56.13050	161.5492	36.37535
56.18050	160.7072	39.80443
56.23383	159.8510	44.26670
56.28550	159.0514	49.04020
56.33716	158.2598	53.81418
56.39050	157.4282	58.26682
56.44050	156.6164	61.67255
56.49382	155.7023	64.24979
56.54382	154.7936	65.56138
56.59716	153.7671	65.80581
56.64883	152.7174	64.96708
56.70050	151.6207	63.25968
56.75383	150.4486	60.79355
56.80383	149.3246	58.07404
56.85717	148.1105	54.96106
56.90883	146.9320	51.96340
56.96050	145.7577	49.12776
57.01382	144.5574	46.45640
57.06382	143.4458	44.22970
57.11716	142.2726	42.14108
57.16716	141.1877	40.44168
57.22050	140.0417	38.86546
57.27217	138.9433	37.55956
57.32383	137.8540	36.42832
57.37717	136.7374	35.41330
57.42717	135.6976	34.59094
57.48050	134.5934	33.82732
57.53217	133.5301	33.19053
57.58383	132.4712	32.63723
57.63550	131.4157	32.14906
57.68716	130.3627	31.71142
57.74050	129.2794	31.32476
57.79050	128.2654	30.99607
57.84384	127.1856	30.68414
57.89550	126.1394	30.35492
57.94717	125.0941	30.06552
58.00050	124.0179	29.83611
58.05050	123.0111	29.63827
58.10383	121.9376	29.44928
58.15383	120.9325	29.25128
58.20717	119.8586	29.04442
58.25883	118.8206	28.90581
58.31050	117.7841	28.77502
58.36382	116.7148	28.65600
58.41382	115.7115	28.54228
58.46717	114.6430	28.42406
58.51884	113.6063	28.31377
58.57050	112.5704	28.20093
58.62217	111.5334	28.07488
58.67383	110.4985	27.97541
58.72717	109.4302	27.87345
58.77717	108.4288	27.78925
58.83050	107.3609	27.69064
58.88217	106.3261	27.59910
58.93383	105.2913	27.50970
58.98717	104.2241	27.41522
59.03716	103.2237	27.33499
59.09050	102.1556	27.23230
59.14050	101.1546	27.15585
59.19384	100.0869	27.08010
59.24550	99.05306	27.00442
59.29717	98.01930	26.92770
59.35050	96.95196	26.85902
59.40050	95.95181	26.78068
59.45383	94.88532	26.70470
59.50550	93.85168	26.63592
59.55717	92.81741	26.56755
59.60883	91.78436	26.50834
59.66050	90.74969	26.43376
59.71382	89.68344	26.34682
59.76382	88.68328	26.27238
59.81716	87.61601	26.19876
59.86882	86.58264	26.12284
59.92050	85.54835	26.03394
59.97382	84.48028	25.94506
60.02383	83.47879	25.86955
60.07717	82.41100	25.78601
60.12717	81.41174	25.70690
60.18050	80.34438	25.62588
60.23217	79.31058	25.54620
60.28383	78.27715	25.47633
60.33716	77.20868	25.40472
60.38716	76.20857	25.33942
60.44050	75.14285	25.28667
60.49216	74.10943	25.22734
60.54382	73.07574	25.15901
60.59550	72.04360	25.08436
60.64717	71.00853	25.01552
60.70050	69.94130	24.94838
60.75050	68.94045	24.88042
60.80383	67.87292	24.79710
60.85550	66.83848	24.72404
60.90717	65.80438	24.64574
60.96050	64.73700	24.57308
61.01050	63.73880	24.56840
61.06382	62.67226	24.46588
61.11382	61.67115	24.38060
61.16716	60.60346	24.28567
61.21884	59.56964	24.19611
61.27050	58.53555	24.11357
61.32383	57.46795	24.02692
61.37383	56.46693	23.94065
61.42717	55.39880	23.85926
61.47883	54.36462	23.78294
61.53050	53.32901	23.69853
61.58217	52.29516	23.61577
61.63383	51.26078	23.53152
61.68716	50.19374	23.43924
61.73717	49.19160	23.36362
61.79050	48.12466	23.28309
61.84217	47.08981	23.19949
61.89384	46.05518	23.12039
61.94717	44.98724	23.04294
61.99717	43.98531	22.96468
62.05050	42.91739	22.88087
62.10050	41.91562	22.80840
62.15383	40.84746	22.71317
62.20550	39.81240	22.62607
62.25717	38.77617	22.54074
62.31050	37.70804	22.43633
62.36050	36.70480	22.33486
62.41382	35.63678	22.23276
62.46550	34.60075	22.12963
62.51716	33.56481	22.02260
62.57050	32.49414	21.91544
62.62050	31.49380	21.80527
62.67383	30.42251	21.69489
62.72382	29.42005	21.59530
62.77717	28.34854	21.47992
62.82883	27.31206	21.36084
62.88050	26.27390	21.24561
62.93383	25.20280	21.12235
62.98383	24.19888	21.00304
63.03383	23.21983	20.89719
63.08550	22.78187	20.59894
63.13716	22.87484	17.64161
63.19050	23.19106	13.25166
63.24050	23.64123	8.772379
63.29382	24.23215	4.241440
63.34550	24.89344	0.3278425
63.39717	25.62348	-3.043397
63.45050	26.43323	-5.967964
63.50050	27.23598	-8.254822
63.55383	28.12802	-10.28240
63.60383	28.99148	-11.87059
63.65717	29.93713	-13.26752
63.70883	30.87234	-14.39484
63.76050	31.82125	-15.34200
63.81382	32.81572	-16.17052
63.86384	33.75652	-16.83278
63.91716	34.76888	-17.43466
63.96884	35.75825	-17.93310
64.02050	36.75296	-18.36646
64.07218	37.75225	-18.75252
64.12383	38.75629	-19.08990
64.17718	39.79556	-19.39753
64.22718	40.77326	-19.65974
64.28050	41.81910	-19.91054
64.33217	42.83312	-20.13263
64.38384	43.84976	-20.33559
64.43717	44.90072	-20.53128
64.48717	45.88748	-20.70388
64.54050	46.94104	-20.87747
64.59050	47.92989	-21.03306
64.64384	48.98580	-21.19315
64.69550	50.00900	-21.34202
64.74717	51.03360	-21.49026
64.80050	52.09194	-21.63498
64.85050	53.08418	-21.76314
64.90384	54.14360	-21.90054
64.95550	55.16991	-22.02499
65.00718	56.19766	-22.14858
65.05884	57.22422	-22.26694
65.11050	58.25156	-22.38642
65.16382	59.31217	-22.51219
65.21384	60.30606	-22.62325
65.26716	61.36716	-22.74672
65.31884	62.39588	-22.87558
65.37050	63.42418	-22.98418
65.42383	64.48780	-23.10316
65.47384	65.48328	-23.20874
65.52717	66.54489	-23.31384
65.57718	67.54102	-23.42360
65.63050	68.60382	-23.53100
65.68218	69.63350	-23.63998
65.73384	70.66284	-23.74226
65.78718	71.72601	-23.84829
65.83716	72.72212	-23.95249
65.89050	73.78539	-24.06423
65.94218	74.81484	-24.16253
65.99384	75.84449	-24.26417
66.04550	76.87353	-24.37188
66.09718	77.90315	-24.48133
66.15050	78.96651	-24.59542
66.20050	79.96335	-24.70196
66.25384	81.02628	-24.81740
66.30550	82.05546	-24.92604
66.35718	83.08524	-25.03494
66.41050	84.14759	-25.15372
66.46050	85.14364	-25.26879
66.51384	86.20598	-25.39388
66.56384	87.20194	-25.50591
66.61718	88.26489	-25.63164
66.66884	89.29361	-25.75224
66.72050	90.32281	-25.88167
66.77384	91.38566	-26.00809
66.82384	92.38205	-26.12940
66.87718	93.44482	-26.25556
66.92884	94.47316	-26.37430
66.98050	95.50359	-26.50671
67.03218	96.53224	-26.63610
67.08384	97.56092	-26.75735
67.13718	98.62372	-26.88920
67.18718	99.61862	-27.01696
67.24050	100.6801	-27.16298
67.29218	101.7078	-27.31142
67.34384	102.7353	-27.46772
67.39718	103.7946	-27.64240
67.44718	104.7883	-27.78972
67.50050	105.8509	-27.90299
67.55050	106.8480	-27.99312
67.60384	107.9126	-28.09142
67.65550	108.9429	-28.18652
67.70718	109.9732	-28.28344
67.76050	111.0358	-28.39256
67.81050	112.0332	-28.49424
67.86384	113.0970	-28.60708
67.91550	114.1272	-28.71912
67.96718	115.1565	-28.82444
68.02050	116.2202	-28.94612
68.07050	117.2163	-29.05023
68.12384	118.2798	-29.16902
68.17384	119.2756	-29.27834
68.22718	120.3384	-29.40923
68.27884	121.3668	-29.53441
68.33050	122.3965	-29.66100
68.38384	123.4589	-29.79915
68.43384	124.4553	-29.92669
68.48718	125.5178	-30.06250
68.53718	126.5131	-30.18675
68.59050	127.5759	-30.31680
68.64216	128.6053	-30.43851
68.69384	129.6336	-30.56959
68.74718	130.6965	-30.70081
68.79718	131.6916	-30.83688
68.85050	132.7534	-30.98038
68.90218	133.7822	-31.11719
68.95384	134.8106	-31.25919
69.00718	135.8724	-31.41350
69.05718	136.8677	-31.55569
69.11050	137.9286	-31.71565
69.16050	138.9240	-31.86094
69.21384	139.9849	-32.01940
69.26550	141.0148	-32.18018
69.31718	142.0416	-32.33424
69.37050	143.1040	-32.49736
69.42050	144.0988	-32.64782
69.47384	145.1589	-32.80957
69.52550	146.1862	-32.96362
69.57718	147.2136	-33.13000
69.62884	148.2402	-33.29675
69.68050	149.2673	-33.47019
69.73384	150.3277	-33.64990
69.78384	151.3218	-33.81997
69.83716	152.3823	-33.99616
69.88884	153.4097	-34.16425
69.94050	154.4369	-34.34111
69.99384	155.4969	-34.52203
70.04384	156.4913	-34.70264
70.09718	157.5514	-34.89260
70.14718	158.5449	-35.07716
70.20050	159.6038	-35.26972
70.25218	160.6314	-35.45844
70.30384	161.6590	-35.65454
70.35718	162.7195	-35.83944
70.40718	163.7136	-36.00464
70.46050	164.7744	-36.17280
70.51218	165.8039	-36.31528
70.56384	166.8330	-36.44388
70.61550	167.8627	-36.55980
70.66718	168.8937	-36.65660
70.72050	169.9577	-36.74812
70.77050	170.9558	-36.82925
70.82384	172.0213	-36.92222
70.87550	173.0522	-37.01722
70.92718	174.0831	-37.10989
70.98050	175.1476	-37.21370
71.03050	176.1446	-37.32763
71.08384	177.2078	-37.45725
71.13384	178.2028	-37.59330
71.18718	179.2638	-37.76288
71.23882	180.2907	-37.94385
71.29050	181.3154	-38.16028
71.34384	182.3738	-38.40724
71.39384	183.3634	-38.66041
71.44718	184.4199	-38.97090
71.49884	185.4409	-39.29560
71.55050	186.4604	-39.64404
71.60218	187.4780	-40.03416
71.65384	188.4939	-40.47114
71.70718	189.5408	-40.96431
71.75718	190.5189	-41.49954
71.81050	191.5595	-42.12152
71.86218	192.5644	-42.79639
71.91382	193.5666	-43.53326
71.96718	194.5973	-44.35354
72.01716	195.5625	-45.16016
72.07050	196.5901	-46.05778
72.12050	197.5532	-46.93000
72.17384	198.5778	-47.88415
72.22551	199.5688	-48.84742
72.27718	200.5570	-49.86198
72.33050	201.5766	-50.97548
72.38050	202.5270	-52.11084
72.43384	203.5383	-53.40416
72.48550	204.5139	-54.74463
72.53718	205.4871	-56.14097
72.58884	206.4570	-57.56921
72.64050	207.4282	-58.96422
72.69384	208.4348	-60.26293
72.74384	209.3892	-61.21026
72.79718	210.4272	-61.68858
72.84882	211.4658	-61.39898
72.90050	212.5425	-60.22034
72.95384	213.6966	-58.17292
73.00384	214.8034	-55.74951
73.05718	216.0025	-52.90528
73.10718	217.1286	-50.27082
73.16050	218.3178	-47.79346
73.21218	219.4524	-45.77400
73.26384	220.5708	-44.11222
73.31718	221.7083	-42.73338
73.36718	222.7647	-41.68516
73.42050	223.8774	-40.78726
73.47218	224.9480	-40.08413
73.52384	226.0110	-39.52274
73.57550	227.0670	-39.11489
73.62718	228.1181	-38.78587
73.68050	229.2002	-38.51718
73.73050	230.2129	-38.33469
73.78384	231.2900	-38.18156
73.83550	232.3311	-38.08252
73.88718	233.3718	-38.01844
73.94050	234.4431	-37.97706
73.99050	235.4479	-37.95641
74.04384	236.5170	-37.94783
74.09384	237.5196	-37.94183
74.14718	238.5876	-37.94150
74.19884	239.6228	-37.95075
74.25050	240.6561	-37.99160
74.30384	241.7232	-38.03956
74.35384	242.7240	-38.10609
74.40718	243.7902	-38.16879
74.45884	244.8235	-38.22848
74.51050	245.8568	-38.29133
74.56384	246.9218	-38.36422
74.61384	247.9206	-38.42639
74.66718	248.9856	-38.49837
74.71718	249.9842	-38.56898
74.77050	251.0490	-38.65305
74.82218	252.0798	-38.73740
74.87384	253.1110	-38.82354
74.92718	254.1759	-38.91091
74.97718	255.1738	-38.99883
75.03050	256.2392	-39.10510
75.08050	257.2374	-39.21240
75.13384	258.3016	-39.30838
75.18550	259.3320	-39.42122
75.23718	260.3623	-39.53563
75.29050	261.4261	-39.64700
75.34050	262.4232	-39.76152
75.39384	263.4878	-39.89322
75.44550	264.5176	-40.01362
75.49718	265.5479	-40.14366
75.55050	266.6116	-40.29779
75.60050	267.6068	-40.43632
75.65384	268.6692	-40.60339
75.70384	269.6633	-40.77808
75.75718	270.7246	-40.96936
75.80884	271.7525	-41.16581
-2.000000	5.000000	0.0000000