File: 2-C1(0.8mol%)+C20(0.6mol%)/matlab/140-2.txt
CLOSED
Version	1.0
Language	English
Mode	Standard
Run	2
RunSerial	11879
Instrument	DSC Q2000 V24.11 Build 124
Module	DSC Standard Cell RC
Operator	Jing
File	\\Ae520-1454\ta\Data\DSC\UQ Composites\Nan\C1(7.5)+C20P(3)+CL(Hotplate MixtureAB)\140-2
ProcName	Ramp
InstSerial	2000-0883
AutoSerial	1293
Sample	Iso140-2
Size	32.6000	mg
PanMass	Not available
PanResist	Automatic Automatic  K/W
PanFactor	Default Default
Method	Ramp
Comment
Xcomment	Pan: Tzero Aluminum Hermetic
Xcomment	Gas1: Nitrogen 50.0 ml/min
Xcomment	Gas2: Nitrogen 50.0 ml/min
Text
Exotherm	UP
Kcell	1.05230
Cpconst	Standard: 0.938
Calib	-38.6961
TempCal	1	pts	157.46	156.60
TzeroDt	-87.6168 -0.0009 -1.4231
TzeroDtz	-87.6168 0.0057 6.9570
InstCalFile	Tzero: \\Ae520-1454\ta\Data\DSC\Calibration\2017\CALIBRATION\1562_RCS (90)_05_18_2017 10_50_44.TZR
InstCalFile	Baseline: \\Ae520-1454\ta\Data\DSC\Calibration\2017\2017-05-17_Calibration.001
InstCalFile	Sapphire: \\Ae520-1454\ta\Data\DSC\Calibration\2017\2017-05-17_Saphire.001
InstCalDate	Tzero 2017-05-18 Time 10:50:44
TempRange	-87.39 to 398.39 °C at 10.00 °C/min Heat Only
AutoZero	Delta T Offset 0.000 uV
AutoZero	Delta T0 Offset 0.000 uV
MultiptCal	0
MultiPtDesc	0) Not set
AutoCellConst	Calibration Date 2017-05-18 16:59:28
Controls	Gas 1  Event Off  Sampling 0.2
Cell#	RC-01562
CoolingUnit	RCS (90)
SelHeatFlow	Heat Flow T4 (mW)
AutoLidII	Installed
AutoAnalysis	Off
MacroFile
Nsig	3
Sig1	Time (min)
Sig2	Temperature (°C)
Sig3	Heat Flow (mW)
Date	2017-06-22
Time	16:01:37
OrgMethod	1: Equilibrate at 20.00 °C
OrgMethod	2: Ramp 40.00 °C/min to 140.00 °C
OrgMethod	3: Mark end of cycle 1
OrgMethod	4: Isothermal for 40.00 min
OrgMethod	5: Mark end of cycle 2
OrgMethod	6: Ramp 20.00 °C/min to 280.00 °C
OrgMethod	7: Mark end of cycle 3
OrgMethod	8: Ramp 20.00 °C/min to 20.00 °C
OrgMethod	9: Mark end of cycle 4
OrgMethod	10: Ramp 20.00 °C/min to 280.00 °C
OrgMethod	11: Mark end of cycle 5
OrgFile	C:\Users\jarra\Desktop\DSC\2-C1(0.8mol%)+C20(0.6mol%)\140-2
StartOfData
4.99994E-4	20.03542	0.2811056
0.05383332	20.15536	0.5825344
0.1055000	21.03980	0.6744132
0.1571666	22.31286	-1.840156
0.2105000	23.82054	-5.291760
0.2605000	25.36544	-8.670749
0.3138333	27.10979	-11.96133
0.3655000	28.87518	-14.70848
0.4171667	30.69580	-16.98387
0.4705000	32.62155	-18.91066
0.5205000	34.46129	-20.37406
0.5738334	36.45138	-21.66500
0.6238334	38.33588	-22.67437
0.6771668	40.36402	-23.59659
0.7288332	42.33850	-24.41342
0.7805000	44.31646	-25.27772
0.8338332	46.36172	-26.13086
0.8838332	48.29236	-26.68804
0.9371668	50.36712	-27.17790
0.9888332	52.37859	-27.74870
1.040500	54.38622	-28.50874
1.092167	56.38105	-29.47510
1.143833	58.37656	-30.40096
1.197166	60.44504	-31.26234
1.247166	62.38075	-32.27212
1.300500	64.42961	-33.78850
1.352166	66.37772	-36.08928
1.403833	68.25806	-39.97548
1.457167	70.06715	-46.87991
1.507167	71.59512	-56.49692
1.560500	73.07368	-69.11294
1.610500	74.39588	-81.45969
1.663834	75.81678	-94.11493
1.715500	77.22964	-105.9016
1.767167	78.68890	-116.1211
1.820500	80.23260	-127.6201
1.870500	81.70786	-137.2963
1.923834	83.31939	-145.8767
1.975500	85.44351	-139.8904
2.027166	87.96799	-130.6181
2.078833	90.63351	-118.9777
2.130500	93.48158	-104.0689
2.183833	96.36819	-91.41094
2.233833	98.94103	-81.86669
2.287166	101.5623	-73.75660
2.338833	104.0026	-67.55132
2.390500	106.3648	-62.68732
2.443833	108.7380	-58.78382
2.493833	110.9136	-55.96238
2.547166	113.1935	-53.65618
2.597167	115.2987	-52.02629
2.650500	117.5189	-50.75862
2.702166	119.6458	-49.91474
2.753833	121.7570	-49.38750
2.807167	123.9225	-49.08094
2.857167	125.9439	-48.97628
2.910500	128.0903	-48.98172
2.962167	130.1647	-49.10360
3.010500	132.0984	-49.32471
3.060500	133.9262	-50.05136
3.113833	135.0625	-49.42239
3.165500	135.8434	-45.43634
3.217166	136.4474	-40.52572
3.270500	136.9458	-35.44694
3.320500	137.3247	-31.20029
3.373834	137.6558	-27.36224
3.425500	137.9194	-24.31440
3.477167	138.1373	-21.84298
3.528833	138.3190	-19.85616
3.580500	138.4702	-18.26357
3.633833	138.6010	-16.95071
3.683833	138.7042	-15.95862
3.737167	138.7966	-15.09878
3.788833	138.8723	-14.42520
3.840500	138.9366	-13.87198
3.893833	138.9932	-13.40499
3.943833	139.0379	-13.04044
3.997166	139.0792	-12.71552
4.047167	139.1131	-12.45902
4.100500	139.1432	-12.22593
4.152166	139.1690	-12.03174
4.203833	139.1917	-11.86804
4.257167	139.2104	-11.71678
4.307167	139.2278	-11.59848
4.360500	139.2425	-11.48293
4.412167	139.2557	-11.38728
4.463834	139.2672	-11.29690
4.515500	139.2779	-11.21875
4.567167	139.2866	-11.15022
4.620500	139.2941	-11.07989
4.670500	139.3020	-11.02130
4.723834	139.3088	-10.96276
4.775500	139.3153	-10.90834
4.827167	139.3199	-10.85548
4.880500	139.3253	-10.80386
4.930500	139.3299	-10.76004
4.983834	139.3348	-10.71024
5.033834	139.3385	-10.66784
5.087167	139.3427	-10.62224
5.138833	139.3460	-10.57361
5.190500	139.3495	-10.53027
5.243834	139.3532	-10.48301
5.293832	139.3565	-10.43899
5.347168	139.3594	-10.39038
5.398834	139.3629	-10.34329
5.450500	139.3655	-10.29698
5.503834	139.3692	-10.24461
5.553834	139.3719	-10.19708
5.607168	139.3759	-10.14678
5.657166	139.3794	-10.09786
5.710500	139.3819	-10.04363
5.762168	139.3850	-9.987712
5.813832	139.3880	-9.934575
5.867168	139.3918	-9.878322
5.917168	139.3949	-9.824399
5.970500	139.3980	-9.762055
6.020500	139.4011	-9.709382
6.073834	139.4048	-9.649828
6.125500	139.4076	-9.588734
6.177166	139.4111	-9.527858
6.230500	139.4144	-9.463549
6.280500	139.4175	-9.402434
6.333832	139.4211	-9.333153
6.385500	139.4251	-9.268725
6.437168	139.4282	-9.198509
6.490500	139.4320	-9.128109
6.540500	139.4356	-9.058578
6.593832	139.4392	-8.980254
6.643832	139.4436	-8.906632
6.697168	139.4471	-8.825545
6.748834	139.4518	-8.742608
6.800500	139.4558	-8.658931
6.853832	139.4611	-8.567188
6.903832	139.4655	-8.482642
6.957168	139.4710	-8.384293
7.008832	139.4757	-8.282111
7.060500	139.4810	-8.180043
7.112168	139.4869	-8.072316
7.163832	139.4923	-7.965196
7.217168	139.4978	-7.844535
7.267168	139.5042	-7.730563
7.320500	139.5110	-7.605190
7.372168	139.5168	-7.476688
7.423834	139.5240	-7.341894
7.477168	139.5299	-7.210358
7.527168	139.5360	-7.083256
7.580500	139.5437	-6.947719
7.630500	139.5502	-6.816426
7.683832	139.5567	-6.675247
7.735500	139.5642	-6.541472
7.787168	139.5715	-6.400961
7.840500	139.5789	-6.254030
7.890500	139.5859	-6.109080
7.943832	139.5946	-5.951954
7.995500	139.6021	-5.794709
8.047168	139.6103	-5.622446
8.098832	139.6187	-5.448318
8.150500	139.6284	-5.260043
8.203834	139.6375	-5.061500
8.253834	139.6473	-4.866852
8.307168	139.6587	-4.652143
8.358832	139.6706	-4.435998
8.410499	139.6805	-4.213266
8.463834	139.6935	-3.988156
8.513832	139.7029	-3.778994
8.567166	139.7140	-3.575612
8.617166	139.7233	-3.400950
8.670500	139.7317	-3.230308
8.722168	139.7397	-3.089254
8.773834	139.7467	-2.963336
8.827168	139.7517	-2.848115
8.877168	139.7577	-2.756217
8.930500	139.7623	-2.665440
8.982166	139.7665	-2.596885
9.033832	139.7697	-2.527292
9.085501	139.7736	-2.470713
9.137168	139.7762	-2.416710
9.190500	139.7786	-2.368578
9.240500	139.7806	-2.328171
9.293834	139.7833	-2.290539
9.345500	139.7854	-2.255114
9.397168	139.7872	-2.220512
9.450500	139.7890	-2.187580
9.500500	139.7905	-2.158961
9.553832	139.7918	-2.132118
9.603832	139.7934	-2.109734
9.657166	139.7950	-2.084923
9.708832	139.7966	-2.063641
9.760499	139.7978	-2.044619
9.813834	139.7990	-2.023848
9.863834	139.7997	-2.007094
9.917168	139.8010	-1.989885
9.968834	139.8024	-1.973318
10.02050	139.8030	-1.957519
10.07217	139.8038	-1.939245
10.12383	139.8048	-1.925604
10.17717	139.8050	-1.910184
10.22717	139.8060	-1.896529
10.28050	139.8064	-1.883716
10.33217	139.8079	-1.871893
10.38383	139.8078	-1.860188
10.43717	139.8095	-1.847718
10.48717	139.8099	-1.836299
10.54050	139.8106	-1.823724
10.59050	139.8113	-1.813447
10.64383	139.8114	-1.801811
10.69550	139.8124	-1.790117
10.74717	139.8131	-1.779554
10.80050	139.8138	-1.767078
10.85050	139.8139	-1.756108
10.90383	139.8151	-1.743741
10.95550	139.8152	-1.731880
11.00717	139.8159	-1.721487
11.05884	139.8168	-1.711428
11.11050	139.8170	-1.701860
11.16383	139.8175	-1.692344
11.21383	139.8188	-1.683762
11.26717	139.8194	-1.674737
11.31883	139.8191	-1.666270
11.37050	139.8194	-1.658074
11.42383	139.8196	-1.649950
11.47383	139.8208	-1.642683
11.52717	139.8208	-1.635252
11.57717	139.8212	-1.628504
11.63050	139.8218	-1.621463
11.68217	139.8219	-1.614864
11.73383	139.8229	-1.608212
11.78717	139.8228	-1.601334
11.83717	139.8236	-1.594978
11.89050	139.8228	-1.588019
11.94217	139.8235	-1.581066
11.99384	139.8241	-1.574142
12.04717	139.8240	-1.567058
12.09717	139.8238	-1.560109
12.15050	139.8246	-1.553036
12.20050	139.8245	-1.546517
12.25384	139.8254	-1.539494
12.30550	139.8256	-1.532682
12.35717	139.8252	-1.525896
12.41050	139.8255	-1.519352
12.46050	139.8265	-1.513369
12.51383	139.8263	-1.506756
12.56383	139.8257	-1.500506
12.61716	139.8277	-1.493931
12.66883	139.8281	-1.487754
12.72050	139.8275	-1.481334
12.77383	139.8281	-1.474972
12.82384	139.8292	-1.469059
12.87717	139.8288	-1.462652
12.92883	139.8296	-1.456661
12.98050	139.8301	-1.450715
13.03383	139.8300	-1.444378
13.08383	139.8299	-1.438393
13.13717	139.8309	-1.432058
13.18716	139.8312	-1.426153
13.24050	139.8312	-1.420028
13.29216	139.8317	-1.414034
13.34383	139.8312	-1.408032
13.39717	139.8327	-1.401592
13.44717	139.8331	-1.395798
13.50050	139.8325	-1.389642
13.55217	139.8330	-1.383530
13.60383	139.8333	-1.377584
13.65550	139.8337	-1.371706
13.70717	139.8340	-1.366042
13.76050	139.8351	-1.360337
13.81050	139.8359	-1.354855
13.86383	139.8351	-1.348967
13.91550	139.8356	-1.342972
13.96716	139.8358	-1.337137
14.02050	139.8363	-1.330974
14.07050	139.8368	-1.325383
14.12384	139.8369	-1.319310
14.17383	139.8366	-1.313737
14.22717	139.8380	-1.307574
14.27883	139.8382	-1.301787
14.33050	139.8377	-1.295750
14.38383	139.8387	-1.289694
14.43383	139.8389	-1.283961
14.48716	139.8381	-1.277976
14.53883	139.8392	-1.271950
14.59050	139.8396	-1.266128
14.64216	139.8394	-1.260133
14.69384	139.8404	-1.254190
14.74717	139.8410	-1.248335
14.79717	139.8417	-1.242712
14.85050	139.8420	-1.236498
14.90217	139.8417	-1.230360
14.95383	139.8427	-1.223860
15.00717	139.8429	-1.217143
15.05717	139.8430	-1.210636
15.11050	139.8438	-1.204012
15.16050	139.8443	-1.197664
15.21383	139.8434	-1.190595
15.26550	139.8449	-1.183523
15.31716	139.8444	-1.176568
15.37050	139.8452	-1.169027
15.42050	139.8453	-1.161735
15.47383	139.8466	-1.153812
15.52550	139.8464	-1.145886
15.57717	139.8470	-1.137673
15.62883	139.8479	-1.129135
15.68050	139.8477	-1.120578
15.73383	139.8489	-1.110984
15.78383	139.8485	-1.101702
15.83717	139.8498	-1.091066
15.88883	139.8500	-1.080264
15.94050	139.8508	-1.068877
15.99383	139.8512	-1.055532
16.04383	139.8524	-1.043253
16.09717	139.8534	-1.028331
16.14716	139.8541	-1.010903
16.20050	139.8545	-0.9931172
16.25217	139.8554	-0.9726736
16.30383	139.8568	-0.9532342
16.35716	139.8574	-0.9319138
16.40716	139.8582	-0.9120358
16.46050	139.8596	-0.8889844
16.51216	139.8611	-0.8657187
16.56383	139.8615	-0.8435006
16.61550	139.8632	-0.8184716
16.66716	139.8641	-0.7935328
16.72050	139.8652	-0.7678548
16.77050	139.8670	-0.7442048
16.82383	139.8676	-0.7156010
16.87550	139.8696	-0.6893237
16.92716	139.8712	-0.6648235
16.98050	139.8718	-0.6360000
17.03050	139.8737	-0.6081116
17.08383	139.8742	-0.5819843
17.13383	139.8761	-0.5534024
17.18716	139.8778	-0.5237656
17.23883	139.8788	-0.4953074
17.29050	139.8801	-0.4675442
17.34383	139.8819	-0.4392754
17.39383	139.8829	-0.4127678
17.44716	139.8844	-0.3820420
17.49883	139.8858	-0.3573466
17.55050	139.8874	-0.3287341
17.60216	139.8887	-0.3006646
17.65383	139.8900	-0.2747344
17.70716	139.8913	-0.2481431
17.75716	139.8925	-0.2198470
17.81050	139.8941	-0.1947469
17.86216	139.8958	-0.1688035
17.91383	139.8969	-0.1454709
17.96716	139.8978	-0.1218932
18.01716	139.8996	-.09697112
18.07050	139.9013	-.07239468
18.12050	139.9016	-.05022867
18.17383	139.9037	-.02409837
18.22550	139.9043	.001860411
18.27716	139.9062	0.02232736
18.33050	139.9067	0.04506480
18.38050	139.9077	0.06566566
18.43383	139.9088	0.08704640
18.48550	139.9101	0.1080558
18.53717	139.9118	0.1276110
18.59050	139.9124	0.1500162
18.64050	139.9132	0.1684814
18.69383	139.9144	0.1876882
18.74383	139.9152	0.2048381
18.79716	139.9168	0.2244704
18.84883	139.9171	0.2428248
18.90050	139.9183	0.2609193
18.95383	139.9188	0.2794043
19.00383	139.9201	0.2956700
19.05716	139.9204	0.3136496
19.10716	139.9217	0.3300472
19.16050	139.9220	0.3473122
19.21216	139.9231	0.3630000
19.26383	139.9252	0.3786519
19.31716	139.9252	0.3961670
19.36716	139.9259	0.4112553
19.42050	139.9269	0.4261500
19.47216	139.9276	0.4419952
19.52383	139.9289	0.4583872
19.57716	139.9297	0.4736338
19.62716	139.9297	0.4886762
19.68050	139.9309	0.5043483
19.73050	139.9320	0.5192738
19.78383	139.9324	0.5361440
19.83550	139.9332	0.5498958
19.88716	139.9335	0.5656788
19.94050	139.9349	0.5794341
19.99050	139.9358	0.5943248
20.04383	139.9357	0.6122092
20.09550	139.9371	0.6269117
20.14716	139.9384	0.6411485
20.19884	139.9394	0.6559662
20.25050	139.9394	0.6721792
20.30383	139.9401	0.6878151
20.35383	139.9411	0.7014634
20.40716	139.9419	0.7160811
20.45883	139.9420	0.7318604
20.51050	139.9430	0.7461944
20.56383	139.9436	0.7613765
20.61383	139.9451	0.7766142
20.66716	139.9460	0.7926521
20.71716	139.9461	0.8070220
20.77050	139.9480	0.8226924
20.82216	139.9484	0.8402081
20.87383	139.9494	0.8554422
20.92717	139.9508	0.8712401
20.97716	139.9519	0.8869637
21.03050	139.9524	0.9053540
21.08216	139.9538	0.9196722
21.13383	139.9546	0.9339163
21.18550	139.9558	0.9495697
21.23716	139.9564	0.9664181
21.29050	139.9573	0.9857525
21.34050	139.9576	1.002820
21.39383	139.9584	1.020777
21.44550	139.9601	1.036751
21.49716	139.9607	1.053606
21.55050	139.9625	1.071080
21.60050	139.9621	1.087380
21.65383	139.9634	1.106892
21.70383	139.9642	1.125622
21.75716	139.9647	1.145367
21.80883	139.9657	1.165076
21.86050	139.9654	1.183575
21.91383	139.9664	1.200927
21.96383	139.9674	1.220414
22.01716	139.9680	1.239364
22.06883	139.9684	1.258200
22.12050	139.9690	1.273200
22.17216	139.9699	1.292272
22.22383	139.9709	1.308705
22.27717	139.9717	1.325645
22.32716	139.9727	1.341910
22.38050	139.9738	1.361534
22.43216	139.9741	1.380803
22.48383	139.9752	1.400248
22.53717	139.9769	1.418290
22.58716	139.9778	1.437056
22.64050	139.9791	1.455898
22.69050	139.9792	1.475111
22.74383	139.9804	1.496233
22.79550	139.9824	1.513704
22.84716	139.9828	1.534991
22.90050	139.9836	1.554364
22.95050	139.9846	1.571706
23.00383	139.9861	1.590247
23.05550	139.9872	1.610228
23.10716	139.9889	1.628617
23.15883	139.9888	1.649477
23.21050	139.9897	1.670097
23.26383	139.9910	1.690794
23.31383	139.9914	1.711898
23.36716	139.9934	1.731346
23.41883	139.9940	1.751869
23.47050	139.9946	1.771326
23.52383	139.9956	1.791793
23.57383	139.9962	1.811497
23.62716	139.9971	1.831792
23.67717	139.9981	1.848275
23.73050	139.9994	1.866828
23.78216	140.0002	1.885442
23.83383	140.0006	1.906706
23.88716	140.0021	1.927008
23.93716	140.0034	1.946959
23.99050	140.0042	1.965156
24.04216	140.0056	1.981043
24.09383	140.0061	2.000967
24.14550	140.0086	2.019569
24.19716	140.0086	2.040594
24.25050	140.0103	2.062714
24.30050	140.0111	2.079672
24.35383	140.0130	2.096362
24.40550	140.0134	2.115004
24.45717	140.0144	2.133738
24.51050	140.0152	2.154034
24.56050	140.0171	2.171645
24.61383	140.0179	2.195615
24.66383	140.0186	2.214296
24.71716	140.0190	2.234499
24.76883	140.0200	2.254772
24.82050	140.0199	2.272898
24.87383	140.0217	2.292247
24.92383	140.0224	2.311031
24.97716	140.0230	2.332594
25.02883	140.0237	2.348909
25.08050	140.0249	2.365266
25.13383	140.0261	2.381971
25.18383	140.0268	2.398048
25.23716	140.0273	2.414560
25.28717	140.0282	2.431018
25.34050	140.0290	2.448600
25.39216	140.0304	2.463418
25.44383	140.0314	2.477930
25.49716	140.0321	2.493872
25.54716	140.0337	2.506944
25.60050	140.0346	2.521597
25.65050	140.0361	2.534319
25.70383	140.0369	2.547786
25.75550	140.0380	2.563210
25.80716	140.0383	2.582016
25.86050	140.0400	2.597780
25.91050	140.0397	2.613026
25.96383	140.0405	2.627360
26.01550	140.0413	2.638815
26.06716	140.0415	2.651210
26.12050	140.0429	2.663558
26.17050	140.0428	2.673902
26.22383	140.0422	2.685365
26.27383	140.0440	2.695398
26.32717	140.0443	2.705774
26.37883	140.0444	2.715206
26.43050	140.0448	2.724242
26.48383	140.0453	2.733075
26.53383	140.0459	2.740806
26.58716	140.0450	2.748894
26.63883	140.0458	2.756348
26.69050	140.0457	2.763498
26.74216	140.0462	2.770315
26.79383	140.0461	2.778490
26.84716	140.0469	2.786068
26.89716	140.0454	2.791862
26.95050	140.0471	2.796957
27.00217	140.0458	2.800830
27.05383	140.0463	2.803692
27.10716	140.0457	2.805904
27.15716	140.0472	2.806955
27.21050	140.0458	2.807554
27.26050	140.0462	2.807396
27.31383	140.0467	2.806410
27.36550	140.0470	2.805003
27.41716	140.0469	2.804466
27.47050	140.0463	2.803346
27.52050	140.0469	2.801610
27.57383	140.0472	2.799643
27.62550	140.0466	2.797046
27.67717	140.0457	2.793827
27.72883	140.0455	2.790278
27.78050	140.0448	2.786516
27.83383	140.0443	2.782328
27.88383	140.0438	2.777744
27.93717	140.0435	2.772237
27.98883	140.0427	2.766202
28.04050	140.0432	2.759742
28.09383	140.0425	2.752743
28.14383	140.0414	2.745987
28.19717	140.0408	2.738346
28.24716	140.0404	2.730972
28.30050	140.0395	2.722934
28.35217	140.0385	2.714910
28.40383	140.0384	2.706204
28.45716	140.0386	2.697200
28.50716	140.0374	2.688906
28.56050	140.0364	2.679911
28.61216	140.0363	2.670150
28.66383	140.0359	2.661195
28.71550	140.0354	2.651922
28.76716	140.0352	2.641998
28.82050	140.0342	2.631558
28.87050	140.0338	2.622142
28.92383	140.0339	2.611196
28.97550	140.0328	2.600950
29.02717	140.0330	2.589806
29.08050	140.0328	2.578952
29.13050	140.0318	2.569130
29.18383	140.0316	2.557729
29.23383	140.0308	2.546787
29.28717	140.0307	2.535261
29.33883	140.0304	2.523912
29.39050	140.0297	2.513785
29.44383	140.0298	2.503081
29.49383	140.0287	2.491810
29.54716	140.0284	2.479672
29.59883	140.0285	2.465510
29.65050	140.0282	2.454878
29.70217	140.0270	2.444265
29.75383	140.0272	2.433908
29.80716	140.0266	2.422013
29.85716	140.0266	2.412361
29.91050	140.0257	2.402026
29.96216	140.0259	2.391295
30.01383	140.0252	2.380131
30.06716	140.0238	2.368969
30.11716	140.0232	2.358713
30.17050	140.0233	2.347776
30.22050	140.0228	2.338348
30.27383	140.0210	2.327875
30.32550	140.0213	2.317718
30.37716	140.0207	2.308136
30.43050	140.0194	2.298244
30.48050	140.0195	2.289287
30.53383	140.0191	2.279396
30.58550	140.0174	2.269838
30.63716	140.0178	2.259640
30.68883	140.0170	2.251228
30.74050	140.0159	2.242412
30.79383	140.0157	2.231256
30.84383	140.0149	2.220426
30.89716	140.0130	2.210399
30.94883	140.0135	2.199955
31.00050	140.0124	2.188804
31.05383	140.0128	2.177960
31.10383	140.0115	2.166914
31.15716	140.0120	2.155731
31.20716	140.0114	2.145368
31.26050	140.0107	2.134629
31.31217	140.0104	2.124142
31.36383	140.0105	2.113333
31.41716	140.0094	2.101952
31.46716	140.0093	2.091706
31.52050	140.0097	2.080396
31.57217	140.0087	2.070462
31.62383	140.0080	2.060920
31.67717	140.0077	2.050919
31.72717	140.0070	2.041737
31.78050	140.0066	2.031420
31.83050	140.0061	2.022542
31.88383	140.0059	2.012656
31.93550	140.0055	2.002375
31.98717	140.0044	1.992639
32.04050	140.0035	1.982727
32.09050	140.0034	1.973558
32.14383	140.0022	1.963940
32.19383	140.0010	1.955136
32.24716	140.0010	1.945995
32.29883	140.0002	1.936711
32.35050	139.9992	1.927530
32.40383	139.9994	1.917672
32.45383	139.9983	1.908499
32.50716	139.9982	1.898586
32.55883	139.9977	1.888654
32.61050	139.9966	1.878725
32.66383	139.9968	1.868195
32.71383	139.9964	1.858502
32.76716	139.9960	1.848407
32.81716	139.9954	1.839080
32.87050	139.9960	1.828941
32.92216	139.9952	1.818584
32.97383	139.9949	1.808316
33.02716	139.9943	1.797771
33.07717	139.9940	1.788141
33.13050	139.9936	1.778196
33.18216	139.9934	1.768477
33.23383	139.9922	1.759320
33.28550	139.9912	1.750416
33.33716	139.9917	1.741483
33.39050	139.9908	1.732478
33.44050	139.9898	1.723913
33.49383	139.9889	1.714461
33.54550	139.9892	1.705454
33.59716	139.9885	1.696412
33.65050	139.9882	1.686724
33.70050	139.9869	1.678014
33.75383	139.9867	1.668509
33.80383	139.9858	1.659591
33.85716	139.9862	1.649753
33.90883	139.9858	1.640406
33.96050	139.9842	1.630895
34.01383	139.9843	1.621320
34.06383	139.9838	1.612385
34.11716	139.9832	1.602514
34.16883	139.9826	1.593026
34.22050	139.9822	1.582952
34.27217	139.9819	1.573703
34.32383	139.9810	1.564388
34.37717	139.9806	1.555121
34.42717	139.9801	1.546397
34.48050	139.9804	1.536687
34.53216	139.9796	1.526430
34.58383	139.9792	1.515090
34.63716	139.9796	1.505096
34.68716	139.9788	1.495832
34.74050	139.9789	1.486166
34.79050	139.9776	1.476948
34.84384	139.9785	1.466644
34.89550	139.9776	1.456961
34.94717	139.9774	1.447703
35.00050	139.9766	1.438141
35.05050	139.9764	1.429485
35.10383	139.9764	1.420545
35.15550	139.9750	1.412139
35.20716	139.9745	1.403696
35.25883	139.9743	1.394668
35.31050	139.9736	1.385697
35.36383	139.9736	1.376066
35.41383	139.9730	1.367066
35.46716	139.9717	1.357615
35.51883	139.9721	1.348126
35.57050	139.9714	1.338254
35.62383	139.9703	1.328346
35.67383	139.9702	1.319417
35.72717	139.9691	1.309923
35.77716	139.9682	1.300940
35.83050	139.9689	1.291583
35.88216	139.9677	1.282351
35.93384	139.9669	1.273448
35.98717	139.9661	1.264419
36.03717	139.9652	1.255909
36.09050	139.9651	1.246446
36.14216	139.9647	1.237089
36.19383	139.9641	1.226894
36.24550	139.9641	1.216766
36.29716	139.9639	1.206341
36.35050	139.9642	1.194892
36.40050	139.9638	1.184986
36.45383	139.9628	1.173551
36.50550	139.9627	1.163582
36.55716	139.9620	1.154094
36.61050	139.9616	1.144456
36.66050	139.9604	1.135464
36.71383	139.9602	1.126122
36.76383	139.9598	1.117274
36.81716	139.9587	1.107994
36.86883	139.9582	1.099044
36.92050	139.9573	1.089893
36.97383	139.9572	1.080346
37.02383	139.9574	1.071055
37.07717	139.9569	1.060989
37.12883	139.9561	1.050098
37.18050	139.9566	1.039562
37.23216	139.9556	1.029450
37.28383	139.9553	1.019382
37.33716	139.9548	1.008631
37.38716	139.9556	0.9990555
37.44050	139.9534	0.9890613
37.49216	139.9532	0.9796106
37.54383	139.9524	0.9702008
37.59716	139.9514	0.9607091
37.64717	139.9506	0.9517319
37.70050	139.9500	0.9422028
37.75050	139.9495	0.9331391
37.80383	139.9485	0.9231125
37.85550	139.9478	0.9134421
37.90716	139.9475	0.9040131
37.96050	139.9462	0.8943028
38.01050	139.9466	0.8848532
38.06383	139.9461	0.8739272
38.11550	139.9462	0.8626444
38.16716	139.9457	0.8523785
38.22050	139.9462	0.8416111
38.27050	139.9451	0.8318312
38.32383	139.9444	0.8206580
38.37383	139.9443	0.8105602
38.42717	139.9438	0.8010606
38.47883	139.9431	0.7916248
38.53050	139.9426	0.7815896
38.58383	139.9418	0.7720512
38.63383	139.9424	0.7631140
38.68716	139.9419	0.7532553
38.73717	139.9405	0.7437038
38.79050	139.9411	0.7321243
38.84216	139.9402	0.7218525
38.89383	139.9397	0.7118534
38.94717	139.9386	0.7016542
38.99716	139.9383	0.6921594
39.05050	139.9374	0.6821556
39.10217	139.9367	0.6726042
39.15383	139.9365	0.6628061
39.20716	139.9361	0.6525122
39.25716	139.9346	0.6433162
39.31050	139.9350	0.6329416
39.36050	139.9340	0.6230308
39.41383	139.9346	0.6121015
39.46550	139.9328	0.6019530
39.51716	139.9330	0.5916851
39.57050	139.9323	0.5809380
39.62050	139.9319	0.5700578
39.67383	139.9310	0.5597356
39.72550	139.9311	0.5493680
39.77716	139.9302	0.5394421
39.82883	139.9298	0.5297800
39.88050	139.9293	0.5203028
39.93384	139.9289	0.5100594
39.98383	139.9272	0.5009896
40.03717	139.9275	0.4911530
40.08883	139.9267	0.4815154
40.14050	139.9267	0.4716992
40.19383	139.9261	0.4610767
40.24383	139.9253	0.4517945
40.29716	139.9246	0.4418033
40.34716	139.9248	0.4318020
40.40050	139.9243	0.4212656
40.45216	139.9241	0.4113378
40.50383	139.9236	0.4012322
40.55716	139.9226	0.3909361
40.60716	139.9224	0.3814992
40.66050	139.9230	0.3724072
40.71216	139.9216	0.3623144
40.76383	139.9211	0.3527041
40.81550	139.9212	0.3413049
40.86716	139.9201	0.3312357
40.92050	139.9203	0.3205022
40.97050	139.9188	0.3109216
41.02383	139.9184	0.3011152
41.07550	139.9180	0.2915306
41.12717	139.9162	0.2820996
41.18050	139.9158	0.2725258
41.23050	139.9156	0.2629349
41.28383	139.9149	0.2527469
41.33383	139.9137	0.2434430
41.38716	139.9134	0.2336688
41.43883	139.9132	0.2228640
41.49050	139.9132	0.2126299
41.54383	139.9121	0.2024972
41.59384	139.9124	0.1928615
41.64717	139.9118	0.1823862
41.69883	139.9109	0.1709634
41.75050	139.9106	0.1609194
41.80217	139.9096	0.1513838
41.85383	139.9101	0.1417689
41.90717	139.9093	0.1311172
41.95717	139.9093	0.1214440
42.01050	139.9087	0.1113940
42.06216	139.9081	0.1011892
42.11383	139.9080	0.09106968
42.16716	139.9076	0.08060080
42.21717	139.9069	0.07141949
42.27050	139.9060	0.06156612
42.32050	139.9060	0.05215640
42.37383	139.9051	0.04194150
42.42550	139.9047	0.03257534
42.47717	139.9040	0.02305844
42.53050	139.9034	0.01341553
42.58050	139.9028	.004606664
42.63383	139.9020	-5.3343E-3
42.68550	139.9014	-.01452340
42.73717	139.9014	-.02458858
42.78883	139.9008	-.03441937
42.84050	139.9004	-.04440413
42.89383	139.8994	-.05492240
42.94383	139.8999	-.06494726
42.99716	139.8985	-.07481360
43.04550	139.9295	-.08467602
43.09716	140.2908	-0.4323322
43.15050	140.9059	-2.553485
43.20050	141.5835	-5.075989
43.25383	142.3882	-7.753347
43.30550	143.2226	-10.04368
43.35717	144.1001	-11.96316
43.41050	145.0381	-13.55830
43.46050	145.9411	-14.74587
43.51383	146.9245	-15.74904
43.56383	147.8609	-16.49159
43.61716	148.8714	-17.11399
43.66883	149.8610	-17.59244
43.72050	150.8575	-17.97426
43.77383	151.8922	-18.28966
43.82383	152.8674	-18.53198
43.87717	153.9117	-18.74478
43.92883	154.9276	-18.92379
43.98050	155.9448	-19.07059
44.03217	156.9646	-19.19642
44.08383	157.9872	-19.30953
44.13716	159.0432	-19.41463
44.18716	160.0355	-19.50126
44.24050	161.0936	-19.58179
44.29217	162.1204	-19.66024
44.34384	163.1467	-19.71972
44.39717	164.2083	-19.79056
44.44717	165.2035	-19.86037
44.50050	166.2659	-19.92322
44.55050	167.2610	-19.98733
44.60383	168.3234	-20.05786
44.65550	169.3524	-20.12207
44.70717	170.3820	-20.19316
44.76050	171.4438	-20.27798
44.81050	172.4402	-20.35679
44.86383	173.5022	-20.44926
44.91550	174.5316	-20.54495
44.96717	175.5594	-20.64610
45.01883	176.5891	-20.76496
45.07050	177.6158	-20.88934
45.12383	178.6764	-21.02606
45.17383	179.6706	-21.17570
45.22717	180.7306	-21.34717
45.27883	181.7555	-21.53102
45.33050	182.7808	-21.73768
45.38383	183.8372	-21.95926
45.43383	184.8270	-22.19902
45.48717	185.8823	-22.46759
45.53717	186.8716	-22.72532
45.59050	187.9256	-23.02354
45.64217	188.9459	-23.32892
45.69383	189.9658	-23.65008
45.74716	191.0165	-24.00722
45.79716	192.0016	-24.36087
45.85050	193.0516	-24.76086
45.90216	194.0676	-25.16785
45.95383	195.0825	-25.59861
46.00717	196.1280	-26.06851
46.05717	197.1081	-26.52554
46.11050	198.1526	-27.04500
46.16050	199.1309	-27.55581
46.21383	200.1721	-28.13325
46.26550	201.1795	-28.73329
46.31717	202.1842	-29.38922
46.37050	203.2199	-30.10458
46.42050	204.1888	-30.82378
46.47383	205.2188	-31.65902
46.52383	206.1826	-32.50760
46.57717	207.2067	-33.49404
46.62883	208.1944	-34.53776
46.68050	209.1773	-35.70728
46.73383	210.1859	-37.06250
46.78383	211.1240	-38.51911
46.83716	212.1134	-40.30557
46.88883	213.0594	-42.34446
46.94050	213.9904	-44.73044
46.99383	214.9340	-47.60537
47.04383	215.7997	-50.69638
47.09716	216.7063	-54.39001
47.14717	217.5390	-58.20566
47.20050	218.4120	-62.57492
47.25217	219.2504	-66.93848
47.30383	220.0877	-71.18022
47.35717	220.9778	-74.82851
47.40717	221.8736	-76.46538
47.46050	222.9536	-75.21046
47.51216	224.1241	-71.47624
47.56383	225.3744	-66.36288
47.61550	226.6685	-60.43638
47.66716	227.9957	-53.82201
47.72050	229.3688	-47.38606
47.77050	230.6080	-42.62128
47.82383	231.8716	-38.73796
47.87550	233.0492	-35.92528
47.92717	234.1919	-33.80160
47.98050	235.3435	-32.16142
48.03050	236.4032	-31.01075
48.08383	237.5166	-30.08818
48.13383	238.5519	-29.44455
48.18716	239.6456	-28.93418
48.23883	240.6992	-28.58328
48.29050	241.7467	-28.32559
48.34384	242.8252	-28.14432
48.39383	243.8334	-28.02148
48.44717	244.9059	-27.93864
48.49883	245.9431	-27.88230
48.55050	246.9800	-27.85430
48.60217	248.0162	-27.84067
48.65383	249.0505	-27.83340
48.70717	250.1191	-27.83106
48.75717	251.1192	-27.83436
48.81050	252.1877	-27.85302
48.86217	253.2213	-27.88160
48.91383	254.2540	-27.91966
48.96717	255.3209	-27.95357
49.01717	256.3208	-27.99815
49.07050	257.3874	-28.05058
49.12050	258.3873	-28.09484
49.17383	259.4533	-28.15846
49.22550	260.4851	-28.21568
49.27716	261.5176	-28.27575
49.33050	262.5819	-28.33820
49.38050	263.5822	-28.41331
49.43383	264.6466	-28.48045
49.48550	265.6785	-28.55650
49.53717	266.7109	-28.63258
49.58883	267.7422	-28.71516
49.64050	268.7725	-28.80732
49.69383	269.8360	-28.90370
49.74383	270.8338	-28.99085
49.79716	271.8973	-29.09992
49.84883	272.9260	-29.21590
49.90050	273.9564	-29.33070
49.95383	275.0192	-29.47925
50.00050	275.9482	-29.61396
50.05383	276.8790	-30.06274
50.10550	277.0432	-28.02840
50.15717	276.8222	-22.48540
50.21050	276.3660	-16.03841
50.26050	275.8032	-10.42812
50.31383	275.0974	-5.351757
50.36550	274.3380	-1.364703
50.41716	273.5232	1.819078
50.47050	272.6372	4.407498
50.52050	271.7753	6.341084
50.57383	270.8290	8.011493
50.62383	269.9228	9.274426
50.67717	268.9391	10.36796
50.72883	267.9746	11.23773
50.78050	266.9990	11.96500
50.83383	265.9844	12.59462
50.88383	265.0250	13.09364
50.93716	263.9961	13.54527
50.98883	262.9950	13.92340
51.04050	261.9901	14.24590
51.09217	260.9813	14.53036
51.14383	259.9706	14.77846
51.19717	258.9244	15.00094
51.24717	257.9408	15.18912
51.30050	256.8912	15.37253
51.35217	255.8730	15.52489
51.40383	254.8530	15.66881
51.45717	253.7996	15.80814
51.50717	252.8112	15.91848
51.56050	251.7558	16.03724
51.61050	250.7662	16.13379
51.66383	249.7102	16.23163
51.71550	248.6854	16.32395
51.76716	247.6606	16.40954
51.82050	246.6030	16.48713
51.87050	245.6108	16.55075
51.92383	244.5520	16.61779
51.97550	243.5265	16.67630
52.02717	242.4988	16.73271
52.07883	241.4728	16.78295
52.13050	240.4460	16.83050
52.18383	239.3856	16.87619
52.23383	238.3920	16.92258
52.28716	237.3304	16.96223
52.33883	236.3031	17.00819
52.39050	235.2752	17.04242
52.44384	234.2144	17.07341
52.49382	233.2201	17.10167
52.54717	232.1595	17.13226
52.59716	231.1642	17.15834
52.65050	230.1036	17.19376
52.70216	229.0760	17.22545
52.75383	228.0480	17.25551
52.80717	226.9863	17.29882
52.85717	225.9902	17.32468
52.91050	224.9281	17.35649
52.96216	223.9001	17.38384
53.01382	222.8709	17.40628
53.06550	221.8418	17.42808
53.11716	220.8133	17.45166
53.17050	219.7508	17.47189
53.22050	218.7545	17.49837
53.27383	217.6918	17.51703
53.32550	216.6637	17.52989
53.37717	215.6348	17.54540
53.43050	214.5729	17.56499
53.48050	213.5766	17.58314
53.53383	212.5136	17.60028
53.58383	211.5184	17.61792
53.63716	210.4568	17.63623
53.68882	209.4274	17.65755
53.74050	208.3980	17.67499
53.79382	207.3350	17.69009
53.84384	206.3399	17.70436
53.89717	205.2764	17.71772
53.94883	204.2467	17.73219
54.00050	203.2163	17.74354
54.05217	202.1864	17.75503
54.10383	201.1572	17.76370
54.15717	200.0939	17.77409
54.20717	199.0985	17.78359
54.26050	198.0358	17.79706
54.31216	197.0059	17.80877
54.36382	195.9752	17.82040
54.41716	194.9133	17.83314
54.46717	193.9161	17.85031
54.52050	192.8537	17.86363
54.57050	191.8570	17.87583
54.62383	190.7940	17.88994
54.67550	189.7650	17.90008
54.72717	188.7351	17.91217
54.78050	187.6716	17.92332
54.83050	186.6763	17.93324
54.88383	185.6136	17.94594
54.93550	184.5836	17.95914
54.98717	183.5527	17.96940
55.03882	182.5234	17.97979
55.09050	181.4918	17.98998
55.14384	180.4291	17.99959
55.19384	179.4316	18.00939
55.24717	178.3689	18.01944
55.29883	177.3389	18.03274
55.35050	176.3094	18.05654
55.40383	175.2466	18.08950
55.45383	174.2522	18.14559
55.50717	173.1912	18.22007
55.55717	172.1976	18.30665
55.61050	171.1399	18.42868
55.66216	170.1161	18.59246
55.71382	169.0965	18.85065
55.76716	168.0520	19.31928
55.81716	167.0852	20.09033
55.87050	166.0784	21.45464
55.92217	165.1355	23.46180
55.97382	164.2244	26.12601
56.02717	163.3141	29.38558
56.07717	162.4732	32.60986
56.13050	161.5762	35.95292
56.18050	160.7260	38.80380
56.23383	159.7992	41.41359
56.28550	158.8780	43.39425
56.33716	157.9270	44.73123
56.39050	156.9109	45.36980
56.44050	155.9210	45.22644
56.49382	154.8278	44.28839
56.54382	153.7668	42.75360
56.59716	152.6049	40.55266
56.64883	151.4587	38.08479
56.70050	150.3021	35.51225
56.75383	149.1100	32.96234
56.80383	148.0025	30.80754
56.85717	146.8346	28.82781
56.90883	145.7192	27.22530
56.96050	144.6178	25.90096
57.01382	143.4940	24.78481
57.06382	142.4506	23.91714
57.11716	141.3471	23.15664
57.16716	140.3172	22.56373
57.22050	139.2250	22.04527
57.27217	138.1712	21.61942
57.32383	137.1212	21.25560
57.37717	136.0416	20.94430
57.42717	135.0312	20.68608
57.48050	133.9564	20.46107
57.53217	132.9164	20.26847
57.58383	131.8762	20.10151
57.63550	130.8376	19.94957
57.68716	129.7998	19.81678
57.74050	128.7295	19.69368
57.79050	127.7272	19.58745
57.84384	126.6575	19.48326
57.89550	125.6155	19.23470
57.94717	124.5796	19.17201
58.00050	123.5130	19.10027
58.05050	122.5120	19.03266
58.10383	121.4439	18.96154
58.15383	120.4440	18.89779
58.20717	119.3772	18.82850
58.25883	118.3425	18.77528
58.31050	117.3083	18.71807
58.36382	116.2416	18.66288
58.41382	115.2408	18.60634
58.46717	114.1744	18.55177
58.51884	113.1417	18.49704
58.57050	112.1072	18.44666
58.62217	111.0743	18.39139
58.67383	110.0403	18.33848
58.72717	108.9741	18.28148
58.77717	107.9731	18.23475
58.83050	106.9066	18.17793
58.88217	105.8726	18.12953
58.93383	104.8395	18.07478
58.98717	103.7740	18.02320
59.03716	102.7738	17.98257
59.09050	101.7080	17.93766
59.14050	100.7082	17.89241
59.19384	99.64176	17.84219
59.24550	98.60892	17.79929
59.29717	97.57622	17.75665
59.35050	96.50845	17.67614
59.40050	95.50626	17.61498
59.45383	94.43968	17.58006
59.50550	93.40632	17.54892
59.55717	92.37247	17.50559
59.60883	91.33993	17.46393
59.66050	90.30559	17.42395
59.71382	89.23920	17.37192
59.76382	88.23945	17.32792
59.81716	87.17304	17.28056
59.86882	86.14016	17.23014
59.92050	85.10648	17.18558
59.97382	84.04181	17.13587
60.02383	83.04134	17.09955
60.07717	81.97566	17.05822
60.12717	80.97554	17.01814
60.18050	79.91015	16.97726
60.23217	78.87500	16.83787
60.28383	77.84152	16.81716
60.33716	76.77594	16.79219
60.38716	75.77563	16.76372
60.44050	74.70924	16.72935
60.49216	73.67759	16.69069
60.54382	72.64413	16.64754
60.59550	71.61201	16.60285
60.64717	70.57900	16.56301
60.70050	69.51311	16.52154
60.75050	68.51439	16.47780
60.80383	67.44728	16.43409
60.85550	66.41402	16.38483
60.90717	65.38178	16.34664
60.96050	64.31587	16.30354
61.01050	63.31546	16.26019
61.06382	62.24885	16.20853
61.11382	61.24895	16.15800
61.16716	60.18354	16.10477
61.21884	59.14975	16.05856
61.27050	58.11566	16.01044
61.32383	57.04876	15.95876
61.37383	56.04861	15.90849
61.42717	54.98230	15.85852
61.47883	53.94929	15.81193
61.53050	52.91465	15.74748
61.58217	51.88125	15.70209
61.63383	50.84698	15.65191
61.68716	49.78033	15.59542
61.73717	48.77892	15.54774
61.79050	47.71126	15.49475
61.84217	46.67791	15.44098
61.89384	45.64328	15.39009
61.94717	44.57626	15.33300
61.99717	43.57584	15.28478
62.05050	42.50805	15.23178
62.10050	41.50798	15.18145
62.15383	40.43945	15.11964
62.20550	39.40606	15.06050
62.25717	38.37161	14.99862
62.31050	37.30418	14.92521
62.36050	36.30253	14.86267
62.41382	35.23546	14.79268
62.46550	34.20023	14.72372
62.51716	33.16572	14.65449
62.57050	32.09755	14.58636
62.62050	31.09728	14.54096
62.67383	30.02829	14.47236
62.72382	29.02672	14.39521
62.77717	27.95742	14.30983
62.82883	26.92251	14.22955
62.88050	25.88583	14.15039
62.93383	24.81622	14.06301
62.98383	23.81404	13.98085
63.03383	22.83022	13.90370
63.08550	22.36580	13.90595
63.13716	22.46640	11.50144
63.19050	22.81508	7.979355
63.24050	23.31617	4.496065
63.29382	23.97029	1.103435
63.34550	24.69775	-1.700510
63.39717	25.49250	-3.997717
63.45050	26.36734	-5.906463
63.50050	27.22306	-7.322016
63.55383	28.16688	-8.516586
63.60383	29.07363	-9.398978
63.65717	30.05858	-10.14595
63.70883	31.02704	-10.71725
63.76050	32.00568	-11.18121
63.81382	33.02397	-11.57342
63.86384	33.98718	-11.87570
63.91716	35.01804	-12.14429
63.96884	36.02113	-12.36466
64.02050	37.02876	-12.55856
64.07218	38.03856	-12.72996
64.12383	39.05095	-12.88378
64.17718	40.09943	-13.02370
64.22718	41.08258	-13.14696
64.28050	42.13357	-13.26630
64.33217	43.15351	-13.37274
64.38384	44.17440	-13.46985
64.43717	45.22959	-13.56739
64.48717	46.21706	-13.65580
64.54050	47.27418	-13.74836
64.59050	48.26460	-13.83693
64.64384	49.32309	-13.92490
64.69550	50.34615	-14.01078
64.74717	51.37216	-14.09913
64.80050	52.43084	-14.18848
64.85050	53.42411	-14.27402
64.90384	54.48403	-14.36108
64.95550	55.51100	-14.44074
65.00718	56.53918	-14.52079
65.05884	57.56703	-14.60375
65.11050	58.59631	-14.68678
65.16382	59.65782	-14.76832
65.21384	60.65363	-14.84596
65.26716	61.71560	-14.92485
65.31884	62.74545	-15.01042
65.37050	63.77402	-15.08711
65.42383	64.83766	-15.16858
65.47384	65.83472	-15.23972
65.52717	66.89662	-15.31787
65.57718	67.89448	-15.39689
65.63050	68.95805	-15.47594
65.68218	69.98829	-15.55327
65.73384	71.01830	-15.62646
65.78718	72.08225	-15.70724
65.83716	73.07871	-15.78516
65.89050	74.14215	-15.86604
65.94218	75.17187	-15.94329
65.99384	76.20288	-16.02112
66.04550	77.23316	-16.10326
66.09718	78.26382	-16.18449
66.15050	79.32789	-16.26709
66.20050	80.32512	-16.34752
66.25384	81.38984	-16.43149
66.30550	82.42006	-16.51202
66.35718	83.45181	-16.59046
66.41050	84.51530	-16.67319
66.46050	85.51306	-16.75212
66.51384	86.57632	-16.83670
66.56384	87.57366	-16.92183
66.61718	88.63694	-17.00743
66.66884	89.66812	-17.09438
66.72050	90.69819	-17.18458
66.77384	91.76226	-17.26790
66.82384	92.76078	-17.34999
66.87718	93.82406	-17.43780
66.92884	94.85566	-17.51974
66.98050	95.88571	-17.60619
67.03218	96.91618	-17.68980
67.08384	97.94708	-17.76971
67.13718	99.01129	-17.86171
67.18718	100.0085	-17.94336
67.24050	101.0720	-18.03346
67.29218	102.1027	-18.12178
67.34384	103.1345	-18.21263
67.39718	104.1974	-18.30503
67.44718	105.1956	-18.40070
67.50050	106.2577	-18.50757
67.55050	107.2555	-18.61060
67.60384	108.3179	-18.74061
67.65550	109.3456	-18.87974
67.70718	110.3761	-18.95845
67.76050	111.4425	-19.02528
67.81050	112.4401	-19.09334
67.86384	113.5046	-19.16496
67.91550	114.5363	-19.24302
67.96718	115.5667	-19.32251
68.02050	116.6311	-19.40974
68.07050	117.6284	-19.48556
68.12384	118.6925	-19.57753
68.17384	119.6907	-19.65851
68.22718	120.7548	-19.75569
68.27884	121.7855	-19.85064
68.33050	122.8157	-19.94312
68.38384	123.8792	-20.04135
68.43384	124.8767	-20.14027
68.48718	125.9396	-20.23782
68.53718	126.9370	-20.33052
68.59050	128.0007	-20.42783
68.64216	129.0306	-20.52335
68.69384	130.0611	-20.61861
68.74718	131.1251	-20.72644
68.79718	132.1224	-20.82484
68.85050	133.1862	-20.92751
68.90218	134.2159	-21.03252
68.95384	135.2462	-21.13844
69.00718	136.3092	-21.24944
69.05718	137.3062	-21.35882
69.11050	138.3690	-21.47004
69.16050	139.3656	-21.57848
69.21384	140.4286	-21.69835
69.26550	141.4573	-21.81602
69.31718	142.4874	-21.93440
69.37050	143.5501	-22.05537
69.42050	144.5464	-22.16917
69.47384	145.6095	-22.28627
69.52550	146.6385	-22.40467
69.57718	147.6677	-22.52562
69.62884	148.6971	-22.64315
69.68050	149.7261	-22.76640
69.73384	150.7885	-22.88838
69.78384	151.7842	-23.01239
69.83716	152.8466	-23.14320
69.88884	153.8749	-23.27878
69.94050	154.9035	-23.41482
69.99384	155.9662	-23.55488
70.04384	156.9613	-23.69236
70.09718	158.0231	-23.83820
70.14718	159.0188	-23.97246
70.20050	160.0803	-24.11510
70.25218	161.1099	-24.24394
70.30384	162.1396	-24.37280
70.35718	163.2027	-24.49062
70.40718	164.1988	-24.59448
70.46050	165.2633	-24.69980
70.51218	166.2944	-24.79002
70.56384	167.3256	-24.87026
70.61550	168.3575	-24.93947
70.66718	169.3898	-25.00218
70.72050	170.4559	-25.05858
70.77050	171.4542	-25.12212
70.82384	172.5200	-25.18652
70.87550	173.5520	-25.25630
70.92718	174.5833	-25.33289
70.98050	175.6476	-25.42154
71.03050	176.6450	-25.52249
71.08384	177.7083	-25.63928
71.13384	178.7039	-25.76001
71.18718	179.7654	-25.90814
71.23882	180.7937	-26.07142
71.29050	181.8198	-26.25180
71.34384	182.8782	-26.46633
71.39384	183.8716	-26.68545
71.44718	184.9279	-26.94278
71.49884	185.9510	-27.22345
71.55050	186.9714	-27.52780
71.60218	187.9910	-27.87041
71.65384	189.0096	-28.26044
71.70718	190.0564	-28.70035
71.75718	191.0377	-29.17829
71.81050	192.0801	-29.74595
71.86218	193.0882	-30.35128
71.91382	194.0934	-31.00447
71.96718	195.1290	-31.71391
72.01716	196.0976	-32.40869
72.07050	197.1316	-33.17218
72.12050	198.0996	-33.90326
72.17384	199.1313	-34.69844
72.22551	200.1302	-35.49766
72.27718	201.1268	-36.35538
72.33050	202.1524	-37.31759
72.38050	203.1097	-38.28870
72.43384	204.1271	-39.39650
72.48550	205.1119	-40.51054
72.53718	206.0959	-41.63222
72.58884	207.0815	-42.65967
72.64050	208.0762	-43.45520
72.69384	209.1207	-43.82940
72.74384	210.1287	-43.47159
72.79718	211.2449	-42.11228
72.84882	212.3691	-39.89350
72.90050	213.5230	-37.20696
72.95384	214.7203	-34.47198
73.00384	215.8297	-32.30475
73.05718	216.9895	-30.49224
73.10718	218.0572	-29.20992
73.16050	219.1788	-28.17459
73.21218	220.2515	-27.42853
73.26384	221.3148	-26.88467
73.31718	222.4035	-26.47135
73.36718	223.4206	-26.18931
73.42050	224.5003	-25.97656
73.47218	225.5436	-25.82393
73.52384	226.5837	-25.72090
73.57550	227.6222	-25.66010
73.62718	228.6593	-25.62068
73.68050	229.7283	-25.60690
73.73050	230.7298	-25.60569
73.78384	231.7980	-25.60918
73.83550	232.8313	-25.63570
73.88718	233.8650	-25.68033
73.94050	234.9326	-25.72489
73.99050	235.9326	-25.77230
74.04384	236.9999	-25.81184
74.09384	237.9990	-25.85066
74.14718	239.0650	-25.90143
74.19884	240.0984	-25.95026
74.25050	241.1312	-26.00149
74.30384	242.1970	-26.06180
74.35384	243.1960	-26.11694
74.40718	244.2630	-26.17927
74.45884	245.2954	-26.22824
74.51050	246.3287	-26.27942
74.56384	247.3947	-26.34350
74.61384	248.3924	-26.38576
74.66718	249.4590	-26.43478
74.71718	250.4577	-26.48306
74.77050	251.5232	-26.53717
74.82218	252.5558	-26.59410
74.87384	253.5886	-26.64412
74.92718	254.6539	-26.69605
74.97718	255.6532	-26.74446
75.03050	256.7190	-26.80855
75.08050	257.7187	-26.86250
75.13384	258.7844	-26.91593
75.18550	259.8159	-26.98024
75.23718	260.8480	-27.04057
75.29050	261.9131	-27.10358
75.34050	262.9110	-27.16742
75.39384	263.9766	-27.23469
75.44550	265.0087	-27.31139
75.49718	266.0396	-27.38838
75.55050	267.1061	-27.46905
75.60050	268.1034	-27.54517
75.65384	269.1674	-27.63200
75.70384	270.1662	-27.72115
75.75718	271.2289	-27.81546
75.80884	272.2595	-27.90660
-2.000000	5.000000	0.0000000