File: 2-C1(0.8mol%)+C20(0.6mol%)/matlab/140-3.txt
CLOSED
Version	1.0
Language	English
Mode	Standard
Run	3
RunSerial	11880
Instrument	DSC Q2000 V24.11 Build 124
Module	DSC Standard Cell RC
Operator	Jing
File	\\Ae520-1454\ta\Data\DSC\UQ Composites\Nan\C1(7.5)+C20P(3)+CL(Hotplate MixtureAB)\140-3
ProcName	Ramp
InstSerial	2000-0883
AutoSerial	1293
Sample	Iso140-3
Size	41.6000	mg
PanMass	Not available
PanResist	Automatic Automatic  K/W
PanFactor	Default Default
Method	Ramp
Comment
Xcomment	Pan: Tzero Aluminum Hermetic
Xcomment	Gas1: Nitrogen 50.0 ml/min
Xcomment	Gas2: Nitrogen 50.0 ml/min
Text
Exotherm	UP
Kcell	1.05230
Cpconst	Standard: 0.938
Calib	-38.6961
TempCal	1	pts	157.46	156.60
TzeroDt	-87.6168 -0.0009 -1.4231
TzeroDtz	-87.6168 0.0057 6.9570
InstCalFile	Tzero: \\Ae520-1454\ta\Data\DSC\Calibration\2017\CALIBRATION\1562_RCS (90)_05_18_2017 10_50_44.TZR
InstCalFile	Baseline: \\Ae520-1454\ta\Data\DSC\Calibration\2017\2017-05-17_Calibration.001
InstCalFile	Sapphire: \\Ae520-1454\ta\Data\DSC\Calibration\2017\2017-05-17_Saphire.001
InstCalDate	Tzero 2017-05-18 Time 10:50:44
TempRange	-87.39 to 398.39 °C at 10.00 °C/min Heat Only
AutoZero	Delta T Offset 0.000 uV
AutoZero	Delta T0 Offset 0.000 uV
MultiptCal	0
MultiPtDesc	0) Not set
AutoCellConst	Calibration Date 2017-05-18 16:59:28
Controls	Gas 1  Event Off  Sampling 0.2
Cell#	RC-01562
CoolingUnit	RCS (90)
SelHeatFlow	Heat Flow T4 (mW)
AutoLidII	Installed
AutoAnalysis	Off
MacroFile
Nsig	3
Sig1	Time (min)
Sig2	Temperature (°C)
Sig3	Heat Flow (mW)
Date	2017-06-22
Time	17:25:36
OrgMethod	1: Equilibrate at 20.00 °C
OrgMethod	2: Ramp 40.00 °C/min to 140.00 °C
OrgMethod	3: Mark end of cycle 1
OrgMethod	4: Isothermal for 40.00 min
OrgMethod	5: Mark end of cycle 2
OrgMethod	6: Ramp 20.00 °C/min to 280.00 °C
OrgMethod	7: Mark end of cycle 3
OrgMethod	8: Ramp 20.00 °C/min to 20.00 °C
OrgMethod	9: Mark end of cycle 4
OrgMethod	10: Ramp 20.00 °C/min to 280.00 °C
OrgMethod	11: Mark end of cycle 5
OrgFile	C:\Users\jarra\Desktop\DSC\2-C1(0.8mol%)+C20(0.6mol%)\140-3
StartOfData
4.99994E-4	20.05255	0.4519341
0.05383332	20.16906	0.7167124
0.1055000	21.03754	0.5748435
0.1571666	22.28871	-2.360443
0.2105000	23.76178	-6.408844
0.2605000	25.27034	-10.42952
0.3138333	26.97435	-14.44040
0.3655000	28.69983	-17.87103
0.4171667	30.48248	-20.79941
0.4705000	32.37325	-23.34334
0.5205000	34.18247	-25.33502
0.5738334	36.14294	-27.12000
0.6238334	38.00546	-28.54143
0.6771668	40.01003	-29.84122
0.7288332	41.96753	-30.96631
0.7805000	43.93274	-32.07909
0.8338332	45.96069	-33.34836
0.8838332	47.86892	-34.34917
0.9371668	49.92002	-35.21260
0.9888332	51.91710	-36.01948
1.040500	53.91113	-37.05310
1.092167	55.88310	-38.53828
1.143833	57.84296	-40.14500
1.197166	59.87809	-41.52518
1.247166	61.79795	-42.72363
1.300500	63.84396	-44.21506
1.352166	65.80071	-46.28562
1.403833	67.70576	-49.60766
1.457167	69.56602	-55.35160
1.507167	71.16808	-63.53784
1.560500	72.73253	-74.66597
1.610500	74.09820	-86.72112
1.663834	75.50562	-99.85425
1.715500	76.91238	-111.7041
1.767167	78.35356	-122.8379
1.820500	79.84201	-135.2139
1.870500	81.25991	-145.4563
1.923834	82.93722	-152.2695
1.975500	84.81160	-154.7300
2.027166	86.86264	-153.8186
2.078833	89.05899	-151.8740
2.130500	91.22199	-150.5480
2.183833	93.53534	-146.6837
2.233833	95.88399	-138.7767
2.287166	98.70158	-125.0737
2.338833	101.4428	-113.4337
2.390500	104.0861	-103.6936
2.443833	106.7125	-95.48314
2.493833	109.0899	-89.24218
2.547166	111.5443	-84.02828
2.597167	113.7737	-80.44815
2.650500	116.0907	-77.48274
2.702166	118.3251	-74.59350
2.753833	120.5383	-72.31582
2.807167	122.7926	-70.53735
2.857167	124.8821	-69.27906
2.910500	127.0907	-68.27220
2.962167	129.2146	-67.55370
3.010500	131.1891	-67.09876
3.060500	133.0544	-67.14732
3.113833	134.2452	-65.47075
3.165500	135.0861	-60.37713
3.217166	135.7511	-54.31702
3.270500	136.3127	-48.01728
3.320500	136.7496	-42.62715
3.373834	137.1419	-37.62775
3.425500	137.4618	-33.52720
3.477167	137.7312	-30.08597
3.528833	137.9595	-27.21176
3.580500	138.1537	-24.81601
3.633833	138.3232	-22.75800
3.683833	138.4593	-21.14289
3.737167	138.5831	-19.70030
3.788833	138.6852	-18.52544
3.840500	138.7732	-17.53069
3.893833	138.8503	-16.66220
3.943833	138.9122	-15.96590
3.997166	138.9694	-15.32806
4.047167	139.0156	-14.81750
4.100500	139.0582	-14.34262
4.152166	139.0936	-13.94783
4.203833	139.1256	-13.60293
4.257167	139.1518	-13.29339
4.307167	139.1738	-13.04121
4.360500	139.1958	-12.80571
4.412167	139.2129	-12.60149
4.463834	139.2277	-12.42247
4.515500	139.2425	-12.26430
4.567167	139.2538	-12.12040
4.620500	139.2652	-11.98659
4.670500	139.2741	-11.86898
4.723834	139.2838	-11.74712
4.775500	139.2919	-11.63789
4.827167	139.3000	-11.53236
4.880500	139.3079	-11.41924
4.930500	139.3139	-11.32187
4.983834	139.3206	-11.21887
5.033834	139.3268	-11.12357
5.087167	139.3333	-11.02144
5.138833	139.3391	-10.91936
5.190500	139.3456	-10.81760
5.243834	139.3516	-10.71412
5.293832	139.3575	-10.61800
5.347168	139.3623	-10.52275
5.398834	139.3683	-10.42655
5.450500	139.3736	-10.33306
5.503834	139.3786	-10.23493
5.553834	139.3846	-10.14612
5.607168	139.3891	-10.04548
5.657166	139.3947	-9.959212
5.710500	139.3997	-9.863859
5.762168	139.4048	-9.775578
5.813832	139.4098	-9.684512
5.867168	139.4149	-9.588778
5.917168	139.4190	-9.501725
5.970500	139.4240	-9.406742
6.020500	139.4302	-9.319395
6.073834	139.4337	-9.224055
6.125500	139.4392	-9.129132
6.177166	139.4450	-9.040262
6.230500	139.4495	-8.944472
6.280500	139.4535	-8.861259
6.333832	139.4587	-8.768124
6.385500	139.4639	-8.679931
6.437168	139.4690	-8.586061
6.490500	139.4734	-8.485905
6.540500	139.4786	-8.394851
6.593832	139.4834	-8.296951
6.643832	139.4877	-8.202991
6.697168	139.4939	-8.105988
6.748834	139.4983	-8.010454
6.800500	139.5032	-7.915045
6.853832	139.5089	-7.815278
6.903832	139.5138	-7.723062
6.957168	139.5181	-7.622724
7.008832	139.5237	-7.526970
7.060500	139.5284	-7.432910
7.112168	139.5336	-7.339304
7.163832	139.5377	-7.245397
7.217168	139.5442	-7.147843
7.267168	139.5482	-7.057628
7.320500	139.5536	-6.960395
7.372168	139.5583	-6.868688
7.423834	139.5626	-6.775766
7.477168	139.5684	-6.677835
7.527168	139.5726	-6.589708
7.580500	139.5779	-6.492572
7.630500	139.5825	-6.397426
7.683832	139.5881	-6.303238
7.735500	139.5925	-6.208316
7.787168	139.5973	-6.107849
7.840500	139.6025	-6.010547
7.890500	139.6068	-5.923160
7.943832	139.6124	-5.819618
7.995500	139.6166	-5.728871
8.047168	139.6215	-5.636998
8.098832	139.6256	-5.546329
8.150500	139.6314	-5.454040
8.203834	139.6358	-5.355480
8.253834	139.6414	-5.269164
8.307168	139.6457	-5.171144
8.358832	139.6512	-5.077246
8.410499	139.6557	-4.979764
8.463834	139.6610	-4.875804
8.513832	139.6654	-4.780474
8.567166	139.6711	-4.680872
8.617166	139.6763	-4.582431
8.670500	139.6818	-4.482922
8.722168	139.6862	-4.379711
8.773834	139.6915	-4.282172
8.827168	139.6972	-4.175726
8.877168	139.7020	-4.068558
8.930500	139.7077	-3.963912
8.982166	139.7130	-3.850930
9.033832	139.7190	-3.738394
9.085501	139.7245	-3.620694
9.137168	139.7299	-3.496230
9.190500	139.7370	-3.371885
9.240500	139.7436	-3.248225
9.293834	139.7492	-3.116364
9.345500	139.7565	-3.000309
9.397168	139.7628	-2.881549
9.450500	139.7681	-2.762625
9.500500	139.7741	-2.655780
9.553832	139.7793	-2.546272
9.603832	139.7853	-2.448625
9.657166	139.7894	-2.348030
9.708832	139.7939	-2.260577
9.760499	139.7984	-2.179594
9.813834	139.8024	-2.100858
9.863834	139.8056	-2.033901
9.917168	139.8097	-1.968989
9.968834	139.8123	-1.911484
10.02050	139.8152	-1.861088
10.07217	139.8176	-1.813553
10.12383	139.8198	-1.771418
10.17717	139.8218	-1.733247
10.22717	139.8238	-1.701862
10.28050	139.8260	-1.671741
10.33217	139.8277	-1.643002
10.38383	139.8290	-1.616709
10.43717	139.8309	-1.592941
10.48717	139.8318	-1.571634
10.54050	139.8334	-1.552126
10.59050	139.8339	-1.534398
10.64383	139.8356	-1.517158
10.69550	139.8363	-1.505434
10.74717	139.8380	-1.490153
10.80050	139.8383	-1.476899
10.85050	139.8389	-1.463921
10.90383	139.8397	-1.451956
10.95550	139.8401	-1.439565
11.00717	139.8410	-1.428505
11.05884	139.8413	-1.417401
11.11050	139.8418	-1.406675
11.16383	139.8432	-1.395906
11.21383	139.8435	-1.385567
11.26717	139.8435	-1.374834
11.31883	139.8440	-1.364439
11.37050	139.8456	-1.354462
11.42383	139.8452	-1.344293
11.47383	139.8454	-1.334732
11.52717	139.8464	-1.324354
11.57717	139.8471	-1.315312
11.63050	139.8461	-1.305808
11.68217	139.8470	-1.296745
11.73383	139.8469	-1.287840
11.78717	139.8478	-1.278737
11.83717	139.8485	-1.270468
11.89050	139.8482	-1.261847
11.94217	139.8490	-1.253866
11.99384	139.8493	-1.246174
12.04717	139.8499	-1.238231
12.09717	139.8513	-1.230858
12.15050	139.8508	-1.223471
12.20050	139.8520	-1.216440
12.25384	139.8520	-1.209041
12.30550	139.8529	-1.202279
12.35717	139.8533	-1.195290
12.41050	139.8538	-1.187854
12.46050	139.8538	-1.180690
12.51383	139.8534	-1.173056
12.56383	139.8544	-1.165756
12.61716	139.8550	-1.157854
12.66883	139.8544	-1.150163
12.72050	139.8559	-1.142739
12.77383	139.8552	-1.135221
12.82384	139.8561	-1.128200
12.87717	139.8556	-1.120807
12.92883	139.8565	-1.113571
12.98050	139.8570	-1.106474
13.03383	139.8566	-1.099142
13.08383	139.8579	-1.092288
13.13717	139.8584	-1.084930
13.18716	139.8584	-1.078139
13.24050	139.8591	-1.070906
13.29216	139.8595	-1.063980
13.34383	139.8606	-1.057073
13.39717	139.8599	-1.049853
13.44717	139.8605	-1.043040
13.50050	139.8605	-1.035444
13.55217	139.8611	-1.028086
13.60383	139.8619	-1.020643
13.65550	139.8624	-1.013109
13.70717	139.8633	-1.005773
13.76050	139.8636	-0.9980994
13.81050	139.8636	-0.9908809
13.86383	139.8656	-0.9831269
13.91550	139.8655	-0.9757179
13.96716	139.8653	-0.9684091
14.02050	139.8664	-0.9610619
14.07050	139.8668	-0.9538803
14.12384	139.8680	-0.9463022
14.17383	139.8676	-0.9391512
14.22717	139.8685	-0.9312020
14.27883	139.8683	-0.9229941
14.33050	139.8689	-0.9145613
14.38383	139.8692	-0.9057207
14.43383	139.8694	-0.8971264
14.48716	139.8705	-0.8878876
14.53883	139.8710	-0.8791618
14.59050	139.8701	-0.8703734
14.64216	139.8706	-0.8607032
14.69384	139.8708	-0.8514801
14.74717	139.8710	-0.8418999
14.79717	139.8702	-0.8322310
14.85050	139.8719	-0.8227258
14.90217	139.8722	-0.8134024
14.95383	139.8721	-0.8038234
15.00717	139.8728	-0.7942058
15.05717	139.8736	-0.7853381
15.11050	139.8738	-0.7755761
15.16050	139.8739	-0.7664848
15.21383	139.8740	-0.7566834
15.26550	139.8752	-0.7472311
15.31716	139.8756	-0.7377580
15.37050	139.8764	-0.7274798
15.42050	139.8769	-0.7183179
15.47383	139.8782	-0.7080795
15.52550	139.8792	-0.6977807
15.57717	139.8795	-0.6866505
15.62883	139.8798	-0.6759430
15.68050	139.8814	-0.6643906
15.73383	139.8816	-0.6514191
15.78383	139.8818	-0.6393137
15.83717	139.8831	-0.6264894
15.88883	139.8844	-0.6135449
15.94050	139.8854	-0.5948695
15.99383	139.8862	-0.5762603
16.04383	139.8874	-0.5604285
16.09717	139.8878	-0.5343037
16.14716	139.8889	-0.5148716
16.20050	139.8898	-0.4936129
16.25217	139.8912	-0.4713880
16.30383	139.8924	-0.4476436
16.35716	139.8939	-0.4203266
16.40716	139.8942	-0.3937933
16.46050	139.8958	-0.3598148
16.51216	139.8972	-0.3293100
16.56383	139.8986	-0.2960484
16.61550	139.9000	-0.2621040
16.66716	139.9008	-0.2275580
16.72050	139.9033	-0.1900634
16.77050	139.9044	-0.1571474
16.82383	139.9074	-0.1188449
16.87550	139.9088	-.07667050
16.92716	139.9116	-.03898964
16.98050	139.9132	.005486588
17.03050	139.9162	0.04961252
17.08383	139.9178	0.09634601
17.13383	139.9200	0.1399464
17.18716	139.9222	0.1924008
17.23883	139.9241	0.2405388
17.29050	139.9264	0.2892200
17.34383	139.9292	0.3397375
17.39383	139.9316	0.3887976
17.44716	139.9342	0.4407972
17.49883	139.9363	0.4866283
17.55050	139.9389	0.5363412
17.60216	139.9418	0.5852227
17.65383	139.9436	0.6337446
17.70716	139.9464	0.6838182
17.75716	139.9499	0.7290664
17.81050	139.9516	0.7837739
17.86216	139.9546	0.8304397
17.91383	139.9577	0.8812606
17.96716	139.9604	0.9308516
18.01716	139.9624	0.9764847
18.07050	139.9651	1.026722
18.12050	139.9670	1.074930
18.17383	139.9699	1.122282
18.22550	139.9725	1.169934
18.27716	139.9753	1.219184
18.33050	139.9772	1.265679
18.38050	139.9794	1.311728
18.43383	139.9820	1.358334
18.48550	139.9850	1.405925
18.53717	139.9874	1.451842
18.59050	139.9897	1.500781
18.64050	139.9913	1.545825
18.69383	139.9944	1.594394
18.74383	139.9956	1.638508
18.79716	139.9980	1.683283
18.84883	139.9999	1.729323
18.90050	140.0014	1.776325
18.95383	140.0044	1.820978
19.00383	140.0069	1.860552
19.05716	140.0094	1.906160
19.10716	140.0116	1.947928
19.16050	140.0134	1.991870
19.21216	140.0159	2.035325
19.26383	140.0180	2.077135
19.31716	140.0208	2.121796
19.36716	140.0231	2.161902
19.42050	140.0255	2.204838
19.47216	140.0276	2.245542
19.52383	140.0297	2.288893
19.57716	140.0318	2.332483
19.62716	140.0344	2.373712
19.68050	140.0361	2.416832
19.73050	140.0391	2.455508
19.78383	140.0409	2.495824
19.83550	140.0428	2.535936
19.88716	140.0452	2.575192
19.94050	140.0473	2.615894
19.99050	140.0492	2.655566
20.04383	140.0514	2.693720
20.09550	140.0526	2.736574
20.14716	140.0542	2.778254
20.19884	140.0569	2.816756
20.25050	140.0576	2.855764
20.30383	140.0602	2.893508
20.35383	140.0616	2.931872
20.40716	140.0626	2.969377
20.45883	140.0655	3.005516
20.51050	140.0669	3.040390
20.56383	140.0687	3.077588
20.61383	140.0709	3.109014
20.66716	140.0726	3.143385
20.71716	140.0744	3.176505
20.77050	140.0767	3.214115
20.82216	140.0772	3.247050
20.87383	140.0799	3.279153
20.92717	140.0815	3.313547
20.97716	140.0832	3.345320
21.03050	140.0847	3.378941
21.08216	140.0868	3.410241
21.13383	140.0890	3.439084
21.18550	140.0906	3.469765
21.23716	140.0927	3.501283
21.29050	140.0934	3.534850
21.34050	140.0956	3.564930
21.39383	140.0960	3.596667
21.44550	140.0983	3.625952
21.49716	140.0998	3.655316
21.55050	140.1016	3.686719
21.60050	140.1026	3.714067
21.65383	140.1047	3.742860
21.70383	140.1056	3.769202
21.75716	140.1077	3.798688
21.80883	140.1089	3.825372
21.86050	140.1104	3.855674
21.91383	140.1117	3.885670
21.96383	140.1135	3.911588
22.01716	140.1145	3.939742
22.06883	140.1155	3.967152
22.12050	140.1169	3.995268
22.17216	140.1180	4.020320
22.22383	140.1192	4.048388
22.27717	140.1210	4.075170
22.32716	140.1214	4.099746
22.38050	140.1229	4.128418
22.43216	140.1239	4.154314
22.48383	140.1260	4.179764
22.53717	140.1264	4.205254
22.58716	140.1278	4.228324
22.64050	140.1299	4.252617
22.69050	140.1308	4.278697
22.74383	140.1327	4.300496
22.79550	140.1346	4.323332
22.84716	140.1352	4.348935
22.90050	140.1364	4.375336
22.95050	140.1383	4.397675
23.00383	140.1400	4.425830
23.05550	140.1407	4.451149
23.10716	140.1424	4.479954
23.15883	140.1429	4.504102
23.21050	140.1434	4.529606
23.26383	140.1450	4.556690
23.31383	140.1470	4.581873
23.36716	140.1478	4.607346
23.41883	140.1492	4.631448
23.47050	140.1501	4.655997
23.52383	140.1521	4.679484
23.57383	140.1535	4.703290
23.62716	140.1542	4.729191
23.67717	140.1564	4.750592
23.73050	140.1572	4.773974
23.78216	140.1584	4.797867
23.83383	140.1602	4.824035
23.88716	140.1616	4.851734
23.93716	140.1625	4.876190
23.99050	140.1635	4.903698
24.04216	140.1652	4.930530
24.09383	140.1658	4.954714
24.14550	140.1670	4.982026
24.19716	140.1691	5.006713
24.25050	140.1698	5.034934
24.30050	140.1703	5.057792
24.35383	140.1722	5.082328
24.40550	140.1729	5.108093
24.45717	140.1748	5.133200
24.51050	140.1759	5.155044
24.56050	140.1768	5.178094
24.61383	140.1785	5.203758
24.66383	140.1789	5.227214
24.71716	140.1800	5.253130
24.76883	140.1814	5.279970
24.82050	140.1823	5.302904
24.87383	140.1835	5.329920
24.92383	140.1850	5.351770
24.97716	140.1851	5.374484
25.02883	140.1871	5.397988
25.08050	140.1877	5.419774
25.13383	140.1893	5.438262
25.18383	140.1906	5.457668
25.23716	140.1927	5.478164
25.28717	140.1928	5.497574
25.34050	140.1937	5.521091
25.39216	140.1954	5.537218
25.44383	140.1956	5.557238
25.49716	140.1973	5.578070
25.54716	140.1987	5.596201
25.60050	140.2001	5.616050
25.65050	140.2000	5.632870
25.70383	140.2014	5.647812
25.75550	140.2030	5.676590
25.80716	140.2044	5.688284
25.86050	140.2051	5.699562
25.91050	140.2059	5.711038
25.96383	140.2058	5.724325
26.01550	140.2070	5.734832
26.06716	140.2078	5.745222
26.12050	140.2078	5.756244
26.17050	140.2088	5.768582
26.22383	140.2095	5.806195
26.27383	140.2105	5.813748
26.32717	140.2101	5.819488
26.37883	140.2109	5.825274
26.43050	140.2110	5.830882
26.48383	140.2102	5.836204
26.53383	140.2105	5.841289
26.58716	140.2100	5.844659
26.63883	140.2101	5.846907
26.69050	140.2109	5.848442
26.74216	140.2103	5.849384
26.79383	140.2105	5.849602
26.84716	140.2102	5.849127
26.89716	140.2093	5.847843
26.95050	140.2103	5.845821
27.00217	140.2094	5.843014
27.05383	140.2095	5.839615
27.10716	140.2094	5.835140
27.15716	140.2078	5.830510
27.21050	140.2080	5.824574
27.26050	140.2072	5.818158
27.31383	140.2064	5.810559
27.36550	140.2059	5.802092
27.41716	140.2052	5.791184
27.47050	140.2051	5.778206
27.52050	140.2040	5.764863
27.57383	140.2037	5.749765
27.62550	140.2028	5.731562
27.67717	140.2022	5.714120
27.72883	140.2024	5.693253
27.78050	140.2008	5.673772
27.83383	140.2001	5.651169
27.88383	140.1988	5.630598
27.93717	140.1980	5.606746
27.98883	140.1974	5.584608
28.04050	140.1959	5.562861
28.09383	140.1952	5.538046
28.14383	140.1934	5.514395
28.19717	140.1916	5.490875
28.24716	140.1897	5.469934
28.30050	140.1897	5.443461
28.35217	140.1881	5.416458
28.40383	140.1856	5.390011
28.45716	140.1851	5.362236
28.50716	140.1840	5.334766
28.56050	140.1823	5.307688
28.61216	140.1813	5.278150
28.66383	140.1795	5.249860
28.71550	140.1782	5.220847
28.76716	140.1762	5.193057
28.82050	140.1748	5.161619
28.87050	140.1738	5.133254
28.92383	140.1718	5.102753
28.97550	140.1702	5.071298
29.02717	140.1692	5.043924
29.08050	140.1674	5.010836
29.13050	140.1656	4.981492
29.18383	140.1645	4.952097
29.23383	140.1634	4.920972
29.28717	140.1612	4.889683
29.33883	140.1600	4.857906
29.39050	140.1583	4.824936
29.44383	140.1571	4.793190
29.49383	140.1553	4.760398
29.54716	140.1532	4.728687
29.59883	140.1524	4.696720
29.65050	140.1507	4.666200
29.70217	140.1485	4.637949
29.75383	140.1470	4.608196
29.80716	140.1451	4.577484
29.85716	140.1430	4.547832
29.91050	140.1421	4.514878
29.96216	140.1401	4.483219
30.01383	140.1399	4.451138
30.06716	140.1374	4.421266
30.11716	140.1358	4.388246
30.17050	140.1339	4.356600
30.22050	140.1326	4.325934
30.27383	140.1312	4.292756
30.32550	140.1296	4.263690
30.37716	140.1288	4.230537
30.43050	140.1270	4.199788
30.48050	140.1250	4.171272
30.53383	140.1240	4.139019
30.58550	140.1223	4.111748
30.63716	140.1198	4.080630
30.68883	140.1194	4.049060
30.74050	140.1174	4.021167
30.79383	140.1161	3.991268
30.84383	140.1148	3.963756
30.89716	140.1132	3.933784
30.94883	140.1113	3.904025
31.00050	140.1101	3.874684
31.05383	140.1090	3.844330
31.10383	140.1077	3.816240
31.15716	140.1063	3.789812
31.20716	140.1042	3.760307
31.26050	140.1030	3.731091
31.31217	140.1014	3.702081
31.36383	140.1001	3.672028
31.41716	140.0984	3.642606
31.46716	140.0975	3.615802
31.52050	140.0949	3.591739
31.57217	140.0934	3.563771
31.62383	140.0924	3.536295
31.67717	140.0905	3.506731
31.72717	140.0896	3.477305
31.78050	140.0884	3.450144
31.83050	140.0868	3.426404
31.88383	140.0854	3.396174
31.93550	140.0842	3.369511
31.98717	140.0826	3.337800
32.04050	140.0816	3.311440
32.09050	140.0805	3.283613
32.14383	140.0783	3.257144
32.19383	140.0781	3.231328
32.24716	140.0761	3.202754
32.29883	140.0745	3.177854
32.35050	140.0732	3.152358
32.40383	140.0723	3.127094
32.45383	140.0698	3.103052
32.50716	140.0691	3.076519
32.55883	140.0671	3.049983
32.61050	140.0662	3.022534
32.66383	140.0651	2.995538
32.71383	140.0635	2.970871
32.76716	140.0619	2.945434
32.81716	140.0612	2.919126
32.87050	140.0596	2.891725
32.92216	140.0587	2.868226
32.97383	140.0579	2.841106
33.02716	140.0572	2.812792
33.07717	140.0556	2.788340
33.13050	140.0545	2.760674
33.18216	140.0531	2.736230
33.23383	140.0519	2.712094
33.28550	140.0499	2.688508
33.33716	140.0493	2.664466
33.39050	140.0478	2.639970
33.44050	140.0464	2.616492
33.49383	140.0450	2.594236
33.54550	140.0434	2.568963
33.59716	140.0422	2.545504
33.65050	140.0408	2.519407
33.70050	140.0400	2.495284
33.75383	140.0382	2.469836
33.80383	140.0379	2.447936
33.85716	140.0361	2.424718
33.90883	140.0349	2.399752
33.96050	140.0341	2.375638
34.01383	140.0338	2.348252
34.06383	140.0310	2.326031
34.11716	140.0306	2.301377
34.16883	140.0285	2.278052
34.22050	140.0280	2.255691
34.27217	140.0266	2.232608
34.32383	140.0252	2.210495
34.37717	140.0236	2.192085
34.42717	140.0223	2.170144
34.48050	140.0210	2.146298
34.53216	140.0193	2.124109
34.58383	140.0186	2.100395
34.63716	140.0176	2.074204
34.68716	140.0166	2.049518
34.74050	140.0145	2.026716
34.79050	140.0144	2.003932
34.84384	140.0130	1.981185
34.89550	140.0115	1.961542
34.94717	140.0111	1.938043
35.00050	140.0096	1.915486
35.05050	140.0087	1.894108
35.10383	140.0085	1.871688
35.15550	140.0069	1.848237
35.20716	140.0057	1.825345
35.25883	140.0052	1.800604
35.31050	140.0042	1.780465
35.36383	140.0030	1.758754
35.41383	140.0016	1.741179
35.46716	140.0000	1.721860
35.51883	139.9992	1.701244
35.57050	139.9984	1.676698
35.62383	139.9964	1.658225
35.67383	139.9962	1.638329
35.72717	139.9951	1.617543
35.77716	139.9940	1.596948
35.83050	139.9929	1.576653
35.88216	139.9917	1.554990
35.93384	139.9907	1.533028
35.98717	139.9890	1.513629
36.03717	139.9888	1.492880
36.09050	139.9874	1.472932
36.14216	139.9859	1.453313
36.19383	139.9860	1.431679
36.24550	139.9846	1.411121
36.29716	139.9845	1.389516
36.35050	139.9831	1.370384
36.40050	139.9823	1.357994
36.45383	139.9818	1.341972
36.50550	139.9806	1.319808
36.55716	139.9805	1.299062
36.61050	139.9788	1.277676
36.66050	139.9781	1.257193
36.71383	139.9759	1.239493
36.76383	139.9754	1.219606
36.81716	139.9742	1.202004
36.86883	139.9731	1.184476
36.92050	139.9720	1.166163
36.97383	139.9706	1.147050
37.02383	139.9702	1.128464
37.07717	139.9690	1.108927
37.12883	139.9685	1.091369
37.18050	139.9678	1.069556
37.23216	139.9666	1.051584
37.28383	139.9650	1.033839
37.33716	139.9650	1.016276
37.38716	139.9631	1.000040
37.44050	139.9621	0.9828588
37.49216	139.9609	0.9666218
37.54383	139.9608	0.9495450
37.59716	139.9589	0.9317882
37.64717	139.9580	0.9175351
37.70050	139.9576	0.8980909
37.75050	139.9567	0.8772794
37.80383	139.9559	0.8601851
37.85550	139.9544	0.8441180
37.90716	139.9543	0.8243900
37.96050	139.9535	0.8052456
38.01050	139.9524	0.7892654
38.06383	139.9519	0.7724376
38.11550	139.9512	0.7546819
38.16716	139.9504	0.7381349
38.22050	139.9496	0.7206750
38.27050	139.9486	0.7070641
38.32383	139.9481	0.6885436
38.37383	139.9480	0.6713734
38.42717	139.9467	0.6533370
38.47883	139.9458	0.6407329
38.53050	139.9448	0.6266491
38.58383	139.9434	0.6095801
38.63383	139.9428	0.5947520
38.68716	139.9426	0.5772988
38.73717	139.9408	0.5624473
38.79050	139.9404	0.5477844
38.84216	139.9395	0.5318299
38.89383	139.9386	0.5158554
38.94717	139.9380	0.4986026
38.99716	139.9370	0.4839210
39.05050	139.9360	0.4669543
39.10217	139.9361	0.4484500
39.15383	139.9346	0.4350816
39.20716	139.9337	0.4207510
39.25716	139.9333	0.4062933
39.31050	139.9321	0.3889776
39.36050	139.9312	0.3747580
39.41383	139.9308	0.3594148
39.46550	139.9298	0.3446179
39.51716	139.9290	0.3299606
39.57050	139.9277	0.3155591
39.62050	139.9264	0.2998910
39.67383	139.9264	0.2851004
39.72550	139.9258	0.2689385
39.77716	139.9252	0.2539330
39.82883	139.9240	0.2385044
39.88050	139.9238	0.2216400
39.93384	139.9236	0.2049568
39.98383	139.9227	0.1909255
40.03717	139.9219	0.1767882
40.08883	139.9206	0.1612358
40.14050	139.9203	0.1463231
40.19383	139.9197	0.1325206
40.24383	139.9197	0.1185792
40.29716	139.9181	0.1042084
40.34716	139.9173	0.09195766
40.40050	139.9175	0.07540097
40.45216	139.9164	0.06058941
40.50383	139.9153	0.04608438
40.55716	139.9151	0.03193271
40.60716	139.9131	0.01582549
40.66050	139.9134	.001739815
40.71216	139.9126	-.01112136
40.76383	139.9117	-.02337090
40.81550	139.9102	-.03644390
40.86716	139.9094	-.04977558
40.92050	139.9084	-.06488678
40.97050	139.9089	-.07784331
41.02383	139.9074	-.09394413
41.07550	139.9068	-0.1094550
41.12717	139.9059	-0.1230373
41.18050	139.9056	-0.1381657
41.23050	139.9049	-0.1517166
41.28383	139.9033	-0.1640461
41.33383	139.9032	-0.1773356
41.38716	139.9022	-0.1910506
41.43883	139.9011	-0.2055350
41.49050	139.9006	-0.2194826
41.54383	139.8995	-0.2356484
41.59384	139.8987	-0.2493973
41.64717	139.8982	-0.2633528
41.69883	139.8981	-0.2780900
41.75050	139.8969	-0.2923172
41.80217	139.8966	-0.3060935
41.85383	139.8954	-0.3196754
41.90717	139.8956	-0.3344754
41.95717	139.8948	-0.3486383
42.01050	139.8939	-0.3621709
42.06216	139.8936	-0.3775998
42.11383	139.8925	-0.3934106
42.16716	139.8921	-0.4066819
42.21717	139.8915	-0.4186228
42.27050	139.8906	-0.4321360
42.32050	139.8899	-0.4450907
42.37383	139.8891	-0.4587780
42.42550	139.8888	-0.4725716
42.47717	139.8874	-0.4848064
42.53050	139.8867	-0.4992154
42.58050	139.8863	-0.5114143
42.63383	139.8848	-0.5258193
42.68550	139.8844	-0.5390772
42.73717	139.8844	-0.5518499
42.78883	139.8837	-0.5655974
42.84050	139.8832	-0.5785654
42.89383	139.8828	-0.5926828
42.94383	139.8810	-0.6056743
42.99716	139.8799	-0.6184235
43.04550	139.9117	-0.6297626
43.09716	140.2749	-0.9133088
43.15050	140.8860	-3.162334
43.20050	141.5516	-6.011000
43.25383	142.3347	-9.174308
43.30550	143.1434	-12.00212
43.35717	143.9925	-14.47352
43.41050	144.9033	-16.62341
43.46050	145.7814	-18.29940
43.51383	146.7399	-19.77943
43.56383	147.6560	-20.93305
43.61716	148.6461	-21.94478
43.66883	149.6185	-22.76265
43.72050	150.5998	-23.44514
43.77383	151.6212	-24.04001
43.82383	152.5844	-24.51433
43.87717	153.6178	-24.95046
43.92883	154.6227	-25.32164
43.98050	155.6300	-25.65310
44.03217	156.6419	-25.94714
44.08383	157.6561	-26.21276
44.13716	158.7054	-26.47446
44.18716	159.6911	-26.69674
44.24050	160.7419	-26.91847
44.29217	161.7633	-27.13048
44.34384	162.7852	-27.32854
44.39717	163.8400	-27.52868
44.44717	164.8294	-27.71582
44.50050	165.8865	-27.90814
44.55050	166.8770	-28.09392
44.60383	167.9351	-28.29070
44.65550	168.9605	-28.47588
44.70717	169.9852	-28.65726
44.76050	171.0434	-28.85065
44.81050	172.0368	-29.02668
44.86383	173.0944	-29.22986
44.91550	174.1198	-29.41975
44.96717	175.1452	-29.61211
45.01883	176.1694	-29.81540
45.07050	177.1946	-30.02607
45.12383	178.2521	-30.25336
45.17383	179.2422	-30.47732
45.22717	180.2994	-30.72494
45.27883	181.3215	-30.98030
45.33050	182.3436	-31.25206
45.38383	183.3993	-31.54138
45.43383	184.3888	-31.83075
45.48717	185.4422	-32.14942
45.53717	186.4298	-32.46187
45.59050	187.4821	-32.81308
45.64217	188.5014	-33.16505
45.69383	189.5196	-33.53304
45.74716	190.5704	-33.94130
45.79716	191.5561	-34.32712
45.85050	192.6044	-34.75903
45.90216	193.6202	-35.19474
45.95383	194.6354	-35.64304
46.00717	195.6815	-36.11807
46.05717	196.6619	-36.58804
46.11050	197.7058	-37.11681
46.16050	198.6841	-37.63096
46.21383	199.7268	-38.21723
46.26550	200.7356	-38.82488
46.31717	201.7422	-39.46509
46.37050	202.7778	-40.18522
46.42050	203.7480	-40.92317
46.47383	204.7777	-41.76824
46.52383	205.7420	-42.61050
46.57717	206.7688	-43.58870
46.62883	207.7590	-44.62055
46.68050	208.7439	-45.75894
46.73383	209.7568	-47.05810
46.78383	210.6992	-48.40960
46.83716	211.6970	-50.04794
46.88883	212.6532	-51.85324
46.94050	213.5984	-53.94995
46.99383	214.5580	-56.46154
47.04383	215.4414	-59.18157
47.09716	216.3652	-62.51704
47.14717	217.2139	-66.03852
47.20050	218.1000	-70.16991
47.25217	218.9442	-74.48516
47.30383	219.7766	-78.99160
47.35717	220.6335	-83.64413
47.40717	221.4498	-87.55368
47.46050	222.3689	-90.32812
47.51216	223.3406	-91.12989
47.56383	224.3885	-90.43316
47.61550	225.4944	-88.55078
47.66716	226.6458	-85.78062
47.72050	227.8754	-82.00719
47.77050	229.0683	-77.53458
47.82383	230.3908	-71.65066
47.87550	231.7127	-65.24197
47.92717	233.0223	-59.51175
47.98050	234.3291	-54.64361
48.03050	235.5128	-50.97188
48.08383	236.7357	-47.83756
48.13383	237.8535	-45.50054
48.18716	239.0196	-43.52744
48.23883	240.1298	-42.01672
48.29050	241.2246	-40.82172
48.34384	242.3424	-39.86376
48.39383	243.3794	-39.14326
48.44717	244.4785	-38.55031
48.49883	245.5368	-38.08964
48.55050	246.5900	-37.73685
48.60217	247.6402	-37.44995
48.65383	248.6857	-37.23956
48.70717	249.7638	-37.06521
48.75717	250.7724	-36.94460
48.81050	251.8460	-36.86033
48.86217	252.8848	-36.79546
48.91383	253.9228	-36.75437
48.96717	254.9941	-36.72880
49.01717	255.9968	-36.71844
49.07050	257.0667	-36.71662
49.12050	258.0677	-36.71812
49.17383	259.1353	-36.72861
49.22550	260.1696	-36.76540
49.27716	261.2040	-36.81240
49.33050	262.2710	-36.86466
49.38050	263.2699	-36.92822
49.43383	264.3354	-36.97970
49.48550	265.3691	-37.04568
49.53717	266.4021	-37.10672
49.58883	267.4354	-37.15872
49.64050	268.4684	-37.21147
49.69383	269.5350	-37.27378
49.74383	270.5340	-37.31860
49.79716	271.6003	-37.35656
49.84883	272.6332	-37.40662
49.90050	273.6666	-37.45682
49.95383	274.7332	-37.50644
50.00050	275.6677	-37.56854
50.05383	276.6091	-37.72484
50.10550	276.7750	-35.61778
50.15717	276.5693	-29.58110
50.21050	276.1453	-22.21209
50.26050	275.6255	-15.42698
50.31383	274.9763	-8.944657
50.36550	274.2711	-3.579411
50.41716	273.5098	0.9371848
50.47050	272.6731	4.735546
50.52050	271.8459	7.501645
50.57383	270.9285	9.909984
50.62383	270.0465	11.75271
50.67717	269.0836	13.38214
50.72883	268.1354	14.70162
50.78050	267.1747	15.81971
50.83383	266.1725	16.78150
50.88383	265.2220	17.51163
50.93716	264.2014	18.19558
50.98883	263.2076	18.78418
51.04050	262.2094	19.30330
51.09217	261.2077	19.76878
51.14383	260.2031	20.18254
51.19717	259.1626	20.55833
51.24717	258.1856	20.86919
51.30050	257.1401	21.17547
51.35217	256.1258	21.43205
51.40383	255.1090	21.66586
51.45717	254.0590	21.88626
51.50717	253.0728	22.07214
51.56050	252.0204	22.25894
51.61050	251.0322	22.41662
51.66383	249.9784	22.57199
51.71550	248.9566	22.71580
51.76716	247.9350	22.84705
51.82050	246.8789	22.97876
51.87050	245.8878	23.08786
51.92383	244.8311	23.20346
51.97550	243.8072	23.30678
52.02717	242.7821	23.39733
52.07883	241.7568	23.48008
52.13050	240.7314	23.56416
52.18383	239.6736	23.64233
52.23383	238.6812	23.72659
52.28716	237.6219	23.80598
52.33883	236.5961	23.88012
52.39050	235.5696	23.95144
52.44384	234.5099	24.01531
52.49382	233.5160	24.07385
52.54717	232.4579	24.12852
52.59716	231.4647	24.18203
52.65050	230.4050	24.24514
52.70216	229.3777	24.30376
52.75383	228.3507	24.36393
52.80717	227.2900	24.42902
52.85717	226.2956	24.47386
52.91050	225.2349	24.52949
52.96216	224.2076	24.57965
53.01382	223.1794	24.62242
53.06550	222.1516	24.66304
53.11716	221.1230	24.70125
53.17050	220.0624	24.74084
53.22050	219.0668	24.78142
53.27383	218.0052	24.82042
53.32550	216.9777	24.84622
53.37717	215.9492	24.87984
53.43050	214.8886	24.91408
53.48050	213.8940	24.94121
53.53383	212.8325	24.97720
53.58383	211.8379	25.00845
53.63716	210.7760	25.04076
53.68882	209.7464	25.07060
53.74050	208.7180	25.09724
53.79382	207.6555	25.11693
53.84384	206.6602	25.13882
53.89717	205.5985	25.15850
53.94883	204.5698	25.17438
54.00050	203.5401	25.19490
54.05217	202.5114	25.21338
54.10383	201.4832	25.22502
54.15717	200.4196	25.24184
54.20717	199.4244	25.25730
54.26050	198.3629	25.27122
54.31216	197.3342	25.28592
54.36382	196.3055	25.30158
54.41716	195.2434	25.32303
54.46717	194.2468	25.34536
54.52050	193.1850	25.36288
54.57050	192.1894	25.37308
54.62383	191.1256	25.38489
54.67550	190.0981	25.39650
54.72717	189.0690	25.40877
54.78050	188.0063	25.42281
54.83050	187.0106	25.43637
54.88383	185.9475	25.45446
54.93550	184.9188	25.46719
54.98717	183.8890	25.47641
55.03882	182.8599	25.48475
55.09050	181.8293	25.49378
55.14384	180.7668	25.50254
55.19384	179.7706	25.51088
55.24717	178.7069	25.52084
55.29883	177.6775	25.53554
55.35050	176.6471	25.55522
55.40383	175.5851	25.58225
55.45383	174.5894	25.62373
55.50717	173.5277	25.67860
55.55717	172.5327	25.73778
55.61050	171.4722	25.81394
55.66216	170.4461	25.90192
55.71382	169.4206	26.01410
55.76716	168.3636	26.16320
55.81716	167.3741	26.32312
55.87050	166.3207	26.55646
55.92217	165.3072	26.90887
55.97382	164.3005	27.48201
56.02717	163.2796	28.47759
56.07717	162.3470	30.00346
56.13050	161.3911	32.50402
56.18050	160.5411	35.80946
56.23383	159.6823	40.29253
56.28550	158.8872	45.22860
56.33716	158.1060	50.22594
56.39050	157.2860	54.93063
56.44050	156.4834	58.51545
56.49382	155.5759	61.18896
56.54382	154.6669	62.46332
56.59716	153.6326	62.52620
56.64883	152.5694	61.38080
56.70050	151.4531	59.27661
56.75383	150.2592	56.38014
56.80383	149.1160	53.29334
56.85717	147.8865	49.91713
56.90883	146.6986	46.79135
56.96050	145.5234	43.95652
57.01382	144.3246	41.38198
57.06382	143.2184	39.29610
57.11716	142.0541	37.39032
57.16716	140.9762	35.86667
57.22050	139.8388	34.47612
57.27217	138.7482	33.32746
57.32383	137.6653	32.33894
57.37717	136.5568	31.45237
57.42717	135.5222	30.74714
57.48050	134.4234	30.09315
57.53217	133.3640	29.53708
57.58383	132.3078	29.05480
57.63550	131.2558	28.63787
57.68716	130.2064	28.24141
57.74050	129.1250	27.93075
57.79050	128.1155	27.67808
57.84384	127.0385	27.42850
57.89550	125.9952	27.20835
57.94717	124.9550	27.01166
58.00050	123.8814	26.83139
58.05050	122.8760	26.66953
58.10383	121.8043	26.50822
58.15383	120.8006	26.36454
58.20717	119.7290	26.21969
58.25883	118.6926	26.09370
58.31050	117.6561	25.97342
58.36382	116.5859	25.86431
58.41382	115.5835	25.75012
58.46717	114.5140	25.63194
58.51884	113.4768	25.53192
58.57050	112.4413	25.43949
58.62217	111.4070	25.34656
58.67383	110.3720	25.26049
58.72717	109.3033	25.16689
58.77717	108.3022	25.09524
58.83050	107.2342	25.00804
58.88217	106.1983	24.92588
58.93383	105.1636	24.82977
58.98717	104.0943	24.73266
59.03716	103.0924	24.64219
59.09050	102.0230	24.56336
59.14050	101.0229	24.48770
59.19384	99.95514	24.41233
59.24550	98.92089	24.34039
59.29717	97.88603	24.26460
59.35050	96.81978	24.20009
59.40050	95.81882	24.12905
59.45383	94.75124	24.05420
59.50550	93.71720	23.98461
59.55717	92.68342	23.91234
59.60883	91.64866	23.83570
59.66050	90.61486	23.77269
59.71382	89.54722	23.69368
59.76382	88.54701	23.62797
59.81716	87.47961	23.55594
59.86882	86.44556	23.48439
59.92050	85.41188	23.41352
59.97382	84.34491	23.34142
60.02383	83.34280	23.27580
60.07717	82.27652	23.20815
60.12717	81.27504	23.14324
60.18050	80.20824	23.07227
60.23217	79.17444	23.01035
60.28383	78.14011	22.94276
60.33716	77.07325	22.87275
60.38716	76.07299	22.81401
60.44050	75.00681	22.75220
60.49216	73.97270	22.69281
60.54382	72.93918	22.62822
60.59550	71.90553	22.56346
60.64717	70.87239	22.49546
60.70050	69.80378	22.43683
60.75050	68.80390	22.37202
60.80383	67.73495	22.30125
60.85550	66.70010	22.22858
60.90717	65.66616	22.15876
60.96050	64.59894	22.08516
61.01050	63.59855	22.01989
61.06382	62.53060	21.93818
61.11382	61.52937	21.86462
61.16716	60.46274	21.79010
61.21884	59.42848	21.71720
61.27050	58.39346	21.64480
61.32383	57.32666	21.57090
61.37383	56.32605	21.49744
61.42717	55.25758	21.42456
61.47883	54.22460	21.35453
61.53050	53.18950	21.28178
61.58217	52.15619	21.20849
61.63383	51.12092	21.13830
61.68716	50.05408	21.05462
61.73717	49.05238	20.98112
61.79050	47.98462	20.90879
61.84217	46.94922	20.83254
61.89384	45.91507	20.76534
61.94717	44.84417	20.60389
61.99717	43.84119	20.52609
62.05050	42.77160	20.44547
62.10050	41.76986	20.36610
62.15383	40.69925	20.26046
62.20550	39.66370	20.18329
62.25717	38.62848	20.08997
62.31050	37.55934	19.96826
62.36050	36.55634	19.87878
62.41382	35.48808	19.78439
62.46550	34.45185	19.69819
62.51716	33.41714	19.59757
62.57050	32.34639	19.50286
62.62050	31.34367	19.40468
62.67383	30.27405	19.30265
62.72382	29.27192	19.21193
62.77717	28.20212	19.10155
62.82883	27.16480	18.99309
62.88050	26.12682	18.88668
62.93383	25.05625	18.76946
62.98383	24.05064	18.66020
63.03383	23.06694	18.55580
63.08550	22.60294	18.51402
63.13716	22.69244	15.82768
63.19050	23.01374	11.70972
63.24050	23.47723	7.504863
63.29382	24.08725	3.270434
63.34550	24.77010	-0.3387824
63.39717	25.52178	-3.405977
63.45050	26.35489	-6.028198
63.50050	27.17737	-8.045111
63.55383	28.08862	-9.805020
63.60383	28.96935	-11.15069
63.65717	29.93134	-12.32509
63.70883	30.87929	-13.25833
63.76050	31.84199	-14.03300
63.81382	32.84637	-14.70573
63.86384	33.79778	-15.23852
63.91716	34.81995	-15.71883
63.96884	35.81609	-16.12404
64.02050	36.81814	-16.46811
64.07218	37.82354	-16.78278
64.12383	38.83265	-17.05155
64.17718	39.87818	-17.28831
64.22718	40.86056	-17.48868
64.28050	41.91040	-17.68129
64.33217	42.92832	-17.85176
64.38384	43.94814	-18.00908
64.43717	45.00235	-18.16534
64.48717	45.99199	-18.30527
64.54050	47.04817	-18.44212
64.59050	48.03886	-18.56687
64.64384	49.09760	-18.69374
64.69550	50.12420	-18.81688
64.74717	51.15021	-18.93837
64.80050	52.20906	-19.05516
64.85050	53.20389	-19.16546
64.90384	54.26338	-19.27818
64.95550	55.29179	-19.38195
65.00718	56.32011	-19.48715
65.05884	57.34912	-19.59230
65.11050	58.37839	-19.69468
65.16382	59.44014	-19.79892
65.21384	60.43747	-19.89739
65.26716	61.49928	-19.99564
65.31884	62.52905	-20.09955
65.37050	63.55879	-20.20022
65.42383	64.62104	-20.29554
65.47384	65.61790	-20.38820
65.52717	66.68140	-20.48115
65.57718	67.67730	-20.57629
65.63050	68.74161	-20.67280
65.68218	69.77237	-20.76258
65.73384	70.80254	-20.85270
65.78718	71.86590	-20.94405
65.83716	72.86262	-21.02967
65.89050	73.92672	-21.12092
65.94218	74.95642	-21.21205
65.99384	75.98647	-21.30263
66.04550	77.01788	-21.39580
66.09718	78.04850	-21.48857
66.15050	79.11168	-21.58334
66.20050	80.10891	-21.67400
66.25384	81.17306	-21.77289
66.30550	82.20350	-21.86510
66.35718	83.23428	-21.95856
66.41050	84.29755	-22.05620
66.46050	85.29550	-22.15017
66.51384	86.35965	-22.25316
66.56384	87.35626	-22.35081
66.61718	88.42035	-22.45112
66.66884	89.45025	-22.54852
66.72050	90.48126	-22.65416
66.77384	91.54514	-22.75635
66.82384	92.54179	-22.85166
66.87718	93.60535	-22.95158
66.92884	94.63531	-23.05715
66.98050	95.66495	-23.16171
67.03218	96.69482	-23.27101
67.08384	97.72532	-23.36888
67.13718	98.78814	-23.48260
67.18718	99.78509	-23.58680
67.24050	100.8474	-23.70683
67.29218	101.8765	-23.83038
67.34384	102.9048	-23.96460
67.39718	103.9668	-24.11087
67.44718	104.9610	-24.27152
67.50050	106.0209	-24.46782
67.55050	107.0135	-24.68277
67.60384	108.0676	-24.96448
67.65550	109.0869	-25.30299
67.70718	110.1041	-25.69538
67.76050	111.1621	-25.74362
67.81050	112.1651	-25.74056
67.86384	113.2332	-25.74613
67.91550	114.2670	-25.77056
67.96718	115.3000	-25.82434
68.02050	116.3666	-25.89862
68.07050	117.3654	-25.96586
68.12384	118.4313	-26.05042
68.17384	119.4296	-26.13182
68.22718	120.4941	-26.23404
68.27884	121.5251	-26.33072
68.33050	122.5565	-26.43804
68.38384	123.6199	-26.55254
68.43384	124.6160	-26.65561
68.48718	125.6801	-26.77350
68.53718	126.6767	-26.88388
68.59050	127.7399	-27.00054
68.64216	128.7698	-27.11532
68.69384	129.7996	-27.23047
68.74718	130.8635	-27.35527
68.79718	131.8602	-27.47688
68.85050	132.9227	-27.60400
68.90218	133.9518	-27.72752
68.95384	134.9812	-27.85367
69.00718	136.0432	-27.99030
69.05718	137.0383	-28.12219
69.11050	138.1006	-28.26437
69.16050	139.0966	-28.40568
69.21384	140.1585	-28.54480
69.26550	141.1870	-28.69477
69.31718	142.2158	-28.83960
69.37050	143.2789	-28.99170
69.42050	144.2736	-29.13491
69.47384	145.3355	-29.28204
69.52550	146.3641	-29.42105
69.57718	147.3925	-29.57235
69.62884	148.4213	-29.71944
69.68050	149.4500	-29.87002
69.73384	150.5125	-30.02598
69.78384	151.5067	-30.17100
69.83716	152.5683	-30.32851
69.88884	153.5962	-30.49102
69.94050	154.6238	-30.65396
69.99384	155.6847	-30.83313
70.04384	156.6796	-30.99524
70.09718	157.7403	-31.16947
70.14718	158.7351	-31.33795
70.20050	159.7952	-31.50872
70.25218	160.8238	-31.67065
70.30384	161.8520	-31.83515
70.35718	162.9138	-31.99085
70.40718	163.9101	-32.12382
70.46050	164.9725	-32.25368
70.51218	166.0035	-32.35338
70.56384	167.0349	-32.44610
70.61550	168.0670	-32.52283
70.66718	169.0989	-32.58091
70.72050	170.1656	-32.63889
70.77050	171.1643	-32.69864
70.82384	172.2318	-32.76271
70.87550	173.2634	-32.84094
70.92718	174.2954	-32.92160
70.98050	175.3595	-33.01680
71.03050	176.3571	-33.12022
71.08384	177.4198	-33.24857
71.13384	178.4148	-33.38563
71.18718	179.4755	-33.55508
71.23882	180.5021	-33.73381
71.29050	181.5285	-33.94591
71.34384	182.5865	-34.18592
71.39384	183.5773	-34.43006
71.44718	184.6330	-34.72784
71.49884	185.6547	-35.03992
71.55050	186.6745	-35.37960
71.60218	187.6924	-35.76714
71.65384	188.7100	-36.19468
71.70718	189.7556	-36.68496
71.75718	190.7343	-37.22100
71.81050	191.7752	-37.83572
71.86218	192.7801	-38.50159
71.91382	193.7824	-39.21978
71.96718	194.8156	-39.99824
72.01716	195.7817	-40.76594
72.07050	196.8124	-41.60772
72.12050	197.7768	-42.41730
72.17384	198.8044	-43.30022
72.22551	199.7992	-44.20961
72.27718	200.7899	-45.18432
72.33050	201.8097	-46.28272
72.38050	202.7614	-47.39864
72.43384	203.7722	-48.68806
72.48550	204.7484	-50.01610
72.53718	205.7207	-51.40234
72.58884	206.6926	-52.80049
72.64050	207.6645	-54.14151
72.69384	208.6761	-55.34101
72.74384	209.6373	-56.10285
72.79718	210.6897	-56.22481
72.84882	211.7513	-55.37608
72.90050	212.8594	-53.45372
72.95384	214.0498	-50.59716
73.00384	215.1875	-47.59809
73.05718	216.3997	-44.61826
73.10718	217.5172	-42.27963
73.16050	218.6879	-40.27075
73.21218	219.7996	-38.70732
73.26384	220.8978	-37.47344
73.31718	222.0167	-36.46829
73.36718	223.0557	-35.72833
73.42050	224.1556	-35.10587
73.47218	225.2136	-34.63798
73.52384	226.2674	-34.26754
73.57550	227.3174	-33.99060
73.62718	228.3640	-33.77297
73.68050	229.4398	-33.61042
73.73050	230.4484	-33.50358
73.78384	231.5216	-33.42564
73.83550	232.5600	-33.38420
73.88718	233.5976	-33.36348
73.94050	234.6666	-33.35798
73.99050	235.6698	-33.35552
74.04384	236.7374	-33.35632
74.09384	237.7380	-33.36251
74.14718	238.8062	-33.39269
74.19884	239.8404	-33.42898
74.25050	240.8743	-33.48724
74.30384	241.9411	-33.54022
74.35384	242.9422	-33.59620
74.40718	244.0080	-33.65470
74.45884	245.0407	-33.70396
74.51050	246.0738	-33.75870
74.56384	247.1405	-33.82446
74.61384	248.1403	-33.86815
74.66718	249.2066	-33.92094
74.71718	250.2054	-33.97397
74.77050	251.2721	-34.03559
74.82218	252.3040	-34.10194
74.87384	253.3350	-34.16168
74.92718	254.4015	-34.23053
74.97718	255.4006	-34.29306
75.03050	256.4668	-34.37189
75.08050	257.4653	-34.44889
75.13384	258.5303	-34.52100
75.18550	259.5620	-34.60350
75.23718	260.5933	-34.69187
75.29050	261.6574	-34.77290
75.34050	262.6553	-34.86784
75.39384	263.7202	-34.97184
75.44550	264.7514	-35.08256
75.49718	265.7820	-35.16459
75.55050	266.8464	-35.31580
75.60050	267.8418	-35.46718
75.65384	268.9031	-35.63210
75.70384	269.8974	-35.82319
75.75718	270.9564	-36.06716
75.80884	271.9808	-36.31187
-2.000000	5.000000	0.0000000