File: 2-C1(0.8mol%)+C20(0.6mol%)/matlab/150-3.txt
CLOSED
Version	1.0
Language	English
Mode	Standard
Run	6
RunSerial	11883
Instrument	DSC Q2000 V24.11 Build 124
Module	DSC Standard Cell RC
Operator	Jing
File	\\Ae520-1454\ta\Data\DSC\UQ Composites\Nan\C1(7.5)+C20P(3)+CL(Hotplate MixtureAB)\150-3
ProcName	Ramp
InstSerial	2000-0883
AutoSerial	1293
Sample	Iso150-3
Size	42.8000	mg
PanMass	Not available
PanResist	Automatic Automatic  K/W
PanFactor	Default Default
Method	Ramp
Comment
Xcomment	Pan: Tzero Aluminum Hermetic
Xcomment	Gas1: Nitrogen 50.0 ml/min
Xcomment	Gas2: Nitrogen 50.0 ml/min
Text
Exotherm	UP
Kcell	1.05230
Cpconst	Standard: 0.938
Calib	-38.6961
TempCal	1	pts	157.46	156.60
TzeroDt	-87.6168 -0.0009 -1.4231
TzeroDtz	-87.6168 0.0057 6.9570
InstCalFile	Tzero: \\Ae520-1454\ta\Data\DSC\Calibration\2017\CALIBRATION\1562_RCS (90)_05_18_2017 10_50_44.TZR
InstCalFile	Baseline: \\Ae520-1454\ta\Data\DSC\Calibration\2017\2017-05-17_Calibration.001
InstCalFile	Sapphire: \\Ae520-1454\ta\Data\DSC\Calibration\2017\2017-05-17_Saphire.001
InstCalDate	Tzero 2017-05-18 Time 10:50:44
TempRange	-87.39 to 398.39 °C at 10.00 °C/min Heat Only
AutoZero	Delta T Offset 0.000 uV
AutoZero	Delta T0 Offset 0.000 uV
MultiptCal	0
MultiPtDesc	0) Not set
AutoCellConst	Calibration Date 2017-05-18 16:59:28
Controls	Gas 1  Event Off  Sampling 0.2
Cell#	RC-01562
CoolingUnit	RCS (90)
SelHeatFlow	Heat Flow T4 (mW)
AutoLidII	Installed
AutoAnalysis	Off
MacroFile
Nsig	3
Sig1	Time (min)
Sig2	Temperature (°C)
Sig3	Heat Flow (mW)
Date	2017-06-22
Time	21:37:08
OrgMethod	1: Equilibrate at 20.00 °C
OrgMethod	2: Ramp 40.00 °C/min to 150.00 °C
OrgMethod	3: Mark end of cycle 1
OrgMethod	4: Isothermal for 40.00 min
OrgMethod	5: Mark end of cycle 2
OrgMethod	6: Ramp 20.00 °C/min to 280.00 °C
OrgMethod	7: Mark end of cycle 3
OrgMethod	8: Ramp 20.00 °C/min to 20.00 °C
OrgMethod	9: Mark end of cycle 4
OrgMethod	10: Ramp 20.00 °C/min to 280.00 °C
OrgMethod	11: Mark end of cycle 5
OrgFile	C:\Users\jarra\Desktop\DSC\2-C1(0.8mol%)+C20(0.6mol%)\150-3
StartOfData
4.99994E-4	20.08468	0.2986176
0.05383332	20.20060	0.6206057
0.1055000	21.08547	0.7640582
0.1571666	22.35153	-2.027326
0.2088333	23.78402	-5.884956
0.2605000	25.34490	-10.05948
0.3121666	26.99271	-14.01095
0.3638334	28.71067	-17.54070
0.4171667	30.54387	-20.66448
0.4671667	32.30679	-23.15592
0.5205000	34.22458	-25.38396
0.5705000	36.05390	-27.14072
0.6238334	38.03156	-28.74298
0.6738334	39.90536	-30.01889
0.7271668	41.92055	-31.22052
0.7771668	43.82010	-32.27972
0.8305000	45.84872	-33.47157
0.8804999	47.75556	-34.47663
0.9338332	49.80346	-35.39426
0.9854999	51.79600	-36.27792
1.037167	53.78555	-37.37706
1.088833	55.75224	-39.04712
1.140500	57.69438	-41.05623
1.192167	59.64200	-42.78954
1.243833	61.61004	-44.21672
1.295500	63.59184	-45.57765
1.347166	65.56182	-47.36392
1.400500	67.55203	-50.28650
1.450500	69.33876	-54.76240
1.503833	71.11499	-62.25500
1.553833	72.63076	-72.02026
1.607167	74.11609	-84.48644
1.657167	75.45455	-96.61358
1.710500	76.89306	-109.1031
1.760500	78.27636	-120.4122
1.813834	79.73150	-132.8170
1.863834	81.17931	-142.8154
1.917167	82.73064	-153.0796
1.968833	84.35321	-160.7666
2.020500	86.11922	-165.1993
2.072166	88.14321	-164.3101
2.123834	90.39709	-160.6245
2.175500	92.69966	-156.4137
2.227167	95.08262	-150.0964
2.280500	97.77455	-137.8400
2.330500	100.4848	-125.1180
2.383833	103.2866	-113.7580
2.433833	105.8142	-104.9263
2.487166	108.4129	-97.13325
2.537166	110.7737	-91.13066
2.590500	113.2257	-85.88525
2.640500	115.4705	-81.88312
2.693833	117.8149	-78.44038
2.743833	119.9750	-75.90266
2.797167	122.2468	-73.79084
2.848834	124.4206	-72.22075
2.900500	126.5726	-71.01293
2.952166	128.7092	-70.07960
3.003833	130.8303	-69.39251
3.055500	132.9406	-68.93750
3.107167	135.0394	-68.65140
3.158834	137.1300	-68.56581
3.210500	139.2127	-68.63915
3.260500	141.2206	-68.85997
3.310500	143.0505	-69.66076
3.363834	144.1874	-68.97272
3.413833	144.9560	-64.59170
3.467166	145.6071	-58.65810
3.518833	146.1242	-52.68018
3.570500	146.5582	-47.15637
3.622166	146.9228	-42.28946
3.673834	147.2322	-38.11386
3.725500	147.4941	-34.59118
3.777167	147.7168	-31.63059
3.828833	147.9066	-29.14775
3.880500	148.0677	-27.06565
3.933833	148.2103	-25.27085
3.983833	148.3240	-23.84792
4.037167	148.4290	-22.57300
4.087167	148.5139	-21.55492
4.140500	148.5914	-20.62776
4.190500	148.6541	-19.88357
4.243834	148.7125	-19.20335
4.293833	148.7604	-18.63855
4.347166	148.8050	-18.12433
4.397167	148.8419	-17.69835
4.450500	148.8754	-17.29877
4.502167	148.9046	-16.95258
4.553834	148.9309	-16.64244
4.605500	148.9542	-16.35812
4.657166	148.9755	-16.10128
4.708834	148.9950	-15.86142
4.760500	149.0121	-15.62567
4.813834	149.0299	-15.38064
4.863834	149.0473	-15.14671
4.917167	149.0635	-14.89746
4.967167	149.0787	-14.66346
5.020500	149.0947	-14.41994
5.070500	149.1082	-14.19910
5.123833	149.1233	-13.97168
5.173834	149.1364	-13.76381
5.227167	149.1493	-13.55270
5.277168	149.1610	-13.35229
5.330500	149.1730	-13.15254
5.382168	149.1839	-12.95758
5.433832	149.1955	-12.76964
5.485500	149.2058	-12.58379
5.537168	149.2164	-12.39897
5.588832	149.2264	-12.21504
5.640500	149.2357	-12.02873
5.692166	149.2474	-11.84426
5.743834	149.2565	-11.65668
5.797168	149.2682	-11.46046
5.847168	149.2784	-11.26553
5.900500	149.2894	-11.05668
5.950500	149.3002	-10.85297
6.003834	149.3121	-10.62200
6.053834	149.3232	-10.40313
6.107168	149.3349	-10.15607
6.157166	149.3478	-9.921793
6.210500	149.3612	-9.659786
6.260500	149.3737	-9.407509
6.313832	149.3880	-9.130659
6.365500	149.4023	-8.849403
6.417168	149.4175	-8.561414
6.468832	149.4318	-8.264526
6.520500	149.4466	-7.964578
6.572168	149.4626	-7.657608
6.623834	149.4783	-7.353535
6.677168	149.4942	-7.036422
6.727168	149.5090	-6.747161
6.780500	149.5251	-6.434840
6.830500	149.5393	-6.149141
6.883832	149.5561	-5.837818
6.933832	149.5692	-5.547686
6.987168	149.5856	-5.236152
7.037168	149.6009	-4.940798
7.090500	149.6170	-4.622810
7.140500	149.6315	-4.324703
7.193832	149.6474	-4.009932
7.245500	149.6623	-3.702462
7.297168	149.6777	-3.410340
7.348832	149.6921	-3.126417
7.400500	149.7058	-2.868240
7.452168	149.7181	-2.632914
7.503832	149.7300	-2.422925
7.555500	149.7396	-2.237610
7.607168	149.7488	-2.072462
7.660500	149.7561	-1.925388
7.710500	149.7634	-1.801101
7.763834	149.7693	-1.688461
7.813834	149.7754	-1.590721
7.867166	149.7796	-1.503219
7.917168	149.7832	-1.429384
7.970500	149.7882	-1.361572
8.020500	149.7912	-1.301134
8.073834	149.7944	-1.246051
8.123834	149.7965	-1.199106
8.177168	149.8000	-1.156301
8.228834	149.8016	-1.117118
8.280500	149.8035	-1.080387
8.332168	149.8058	-1.048691
8.383832	149.8073	-1.018761
8.435499	149.8099	-0.9898811
8.487168	149.8117	-0.9631858
8.540500	149.8124	-0.9382697
8.590500	149.8144	-0.9164126
8.643832	149.8160	-0.8929476
8.693832	149.8163	-0.8711887
8.747168	149.8179	-0.8480913
8.797168	149.8196	-0.8300506
8.850500	149.8198	-0.8081060
8.900500	149.8213	-0.7872353
8.953834	149.8226	-0.7689651
9.003834	149.8234	-0.7504724
9.057168	149.8250	-0.7322011
9.108832	149.8261	-0.7141913
9.160499	149.8263	-0.6947866
9.212168	149.8278	-0.6777985
9.263832	149.8288	-0.6603705
9.315500	149.8290	-0.6412792
9.367166	149.8306	-0.6249776
9.418832	149.8310	-0.6078349
9.470500	149.8324	-0.5900705
9.523834	149.8329	-0.5688704
9.573834	149.8347	-0.5528540
9.627168	149.8345	-0.5333915
9.677168	149.8364	-0.5157804
9.730500	149.8371	-0.4946004
9.780500	149.8381	-0.4753786
9.833832	149.8391	-0.4591128
9.883832	149.8406	-0.4394362
9.937166	149.8412	-0.4198315
9.987168	149.8425	-0.4017182
10.04050	149.8432	-0.3811980
10.09217	149.8444	-0.3606609
10.14383	149.8452	-0.3410563
10.19550	149.8468	-0.3199414
10.24717	149.8471	-0.2990394
10.29883	149.8489	-0.2820290
10.35050	149.8505	-0.2616248
10.40383	149.8509	-0.2381947
10.45383	149.8525	-0.2171211
10.50717	149.8534	-0.1936017
10.55717	149.8541	-0.1738987
10.61050	149.8551	-0.1513670
10.66050	149.8570	-0.1318379
10.71383	149.8577	-0.1090389
10.76383	149.8587	-.08841126
10.81716	149.8600	-.06428515
10.86716	149.8620	-.04329735
10.92050	149.8629	-.01929974
10.97217	149.8638	.007075482
11.02383	149.8648	0.02984362
11.07550	149.8662	0.05414226
11.12717	149.8668	0.07843039
11.17883	149.8688	0.1007746
11.23050	149.8698	0.1237765
11.28217	149.8716	0.1481273
11.33383	149.8723	0.1737178
11.38717	149.8730	0.2041703
11.43716	149.8752	0.2259720
11.49050	149.8770	0.2522780
11.54050	149.8778	0.2752020
11.59383	149.8794	0.3038259
11.64383	149.8803	0.3283326
11.69717	149.8820	0.3559228
11.74717	149.8837	0.3787015
11.80050	149.8856	0.4050139
11.85050	149.8859	0.4340772
11.90383	149.8873	0.4601080
11.95550	149.8885	0.4876560
12.00717	149.8903	0.5183520
12.05884	149.8916	0.5436991
12.11050	149.8940	0.5735974
12.16217	149.8944	0.6016324
12.21383	149.8962	0.6301118
12.26717	149.8965	0.6606716
12.31716	149.8981	0.6896270
12.37050	149.9006	0.7200176
12.42050	149.9016	0.7491922
12.47383	149.9037	0.7800437
12.52383	149.9049	0.8068306
12.57717	149.9062	0.8409476
12.62717	149.9078	0.8701246
12.68050	149.9101	0.9017700
12.73050	149.9104	0.9307952
12.78383	149.9127	0.9644259
12.83550	149.9149	0.9933388
12.88717	149.9168	1.024855
12.93883	149.9177	1.057841
12.99050	149.9198	1.090415
13.04216	149.9218	1.122848
13.09383	149.9227	1.157103
13.14550	149.9248	1.188737
13.19717	149.9262	1.224164
13.25050	149.9282	1.259169
13.30050	149.9301	1.289992
13.35383	149.9308	1.327026
13.40383	149.9332	1.361515
13.45717	149.9350	1.398301
13.50717	149.9370	1.430750
13.56050	149.9389	1.467911
13.61050	149.9398	1.501002
13.66383	149.9419	1.540726
13.71383	149.9436	1.573549
13.76717	149.9452	1.611612
13.81884	149.9476	1.649950
13.87050	149.9495	1.686720
13.92217	149.9514	1.726756
13.97383	149.9536	1.763892
14.02550	149.9559	1.803876
14.07717	149.9575	1.847723
14.13050	149.9599	1.893144
14.18050	149.9622	1.941453
14.23383	149.9642	1.996732
14.28383	149.9673	2.054154
14.33717	149.9708	2.120463
14.38717	149.9740	2.197524
14.44050	149.9782	2.285400
14.49050	149.9830	2.380957
14.54384	149.9884	2.503367
14.59383	149.9945	2.631817
14.64717	150.0018	2.783539
14.69884	150.0101	2.951294
14.75050	150.0192	3.127024
14.80217	150.0274	3.321511
14.85383	150.0383	3.523664
14.90550	150.0483	3.737701
14.95717	150.0599	3.959900
15.00883	150.0709	4.181637
15.06050	150.0816	4.405735
15.11383	150.0939	4.636880
15.16383	150.1044	4.849726
15.21716	150.1158	5.069840
15.26717	150.1265	5.276142
15.32050	150.1368	5.486678
15.37050	150.1466	5.675715
15.42383	150.1564	5.874553
15.47383	150.1652	6.052942
15.52717	150.1744	6.237043
15.57717	150.1826	6.404294
15.63050	150.1914	6.572999
15.68217	150.1996	6.732756
15.73383	150.2074	6.887374
15.78550	150.2148	7.041748
15.83717	150.2223	7.188316
15.88883	150.2300	7.334176
15.94050	150.2374	7.477612
15.99383	150.2446	7.620325
16.04383	150.2514	7.752786
16.09717	150.2586	7.891648
16.14716	150.2654	8.021469
16.20050	150.2727	8.162275
16.25050	150.2783	8.290108
16.30383	150.2854	8.428788
16.35383	150.2923	8.556538
16.40716	150.2981	8.693086
16.45716	150.3050	8.817255
16.51050	150.3126	8.951751
16.56216	150.3184	9.084142
16.61383	150.3248	9.208851
16.66550	150.3308	9.337976
16.71716	150.3380	9.466051
16.76883	150.3439	9.591484
16.82050	150.3507	9.713863
16.87216	150.3568	9.838363
16.92383	150.3622	9.955079
16.97716	150.3687	10.07954
17.02716	150.3745	10.19211
17.08050	150.3806	10.31146
17.13050	150.3867	10.42879
17.18383	150.3919	10.54538
17.23383	150.3981	10.64737
17.28717	150.4032	10.74422
17.33716	150.4070	10.83500
17.39050	150.4115	10.92646
17.44050	150.4159	11.01285
17.49383	150.4199	11.09986
17.54550	150.4249	11.17788
17.59716	150.4279	11.25314
17.64883	150.4321	11.32408
17.70050	150.4360	11.39024
17.75216	150.4388	11.45770
17.80383	150.4425	11.51226
17.85716	150.4454	11.56690
17.90716	150.4469	11.60980
17.96050	150.4491	11.64837
18.01050	150.4512	11.67746
18.06383	150.4520	11.70406
18.11383	150.4539	11.71986
18.16716	150.4541	11.73136
18.21716	150.4548	11.73734
18.27050	150.4549	11.74231
18.32050	150.4549	11.74503
18.37383	150.4539	11.74426
18.42550	150.4530	11.73299
18.47716	150.4512	11.70741
18.52883	150.4501	11.66549
18.58050	150.4482	11.61588
18.63216	150.4460	11.56345
18.68383	150.4431	11.50611
18.73550	150.4404	11.44379
18.78717	150.4376	11.37495
18.84050	150.4340	11.30592
18.89050	150.4305	11.23489
18.94383	150.4269	11.15214
18.99383	150.4221	11.07480
19.04716	150.4183	10.98832
19.09716	150.4139	10.90340
19.15050	150.4095	10.81320
19.20050	150.4056	10.72618
19.25383	150.4007	10.63499
19.30383	150.3962	10.54694
19.35716	150.3913	10.45260
19.40883	150.3860	10.35886
19.46050	150.3825	10.26634
19.51216	150.3773	10.17265
19.56383	150.3729	10.07767
19.61550	150.3678	9.984680
19.66716	150.3631	9.890553
19.72050	150.3582	9.794681
19.77050	150.3536	9.706255
19.82383	150.3491	9.609291
19.87383	150.3446	9.518314
19.92716	150.3396	9.421038
19.97716	150.3352	9.333658
20.03050	150.3303	9.241222
20.08050	150.3256	9.151014
20.13383	150.3209	9.058441
20.18383	150.3175	8.969559
20.23716	150.3124	8.879094
20.28883	150.3086	8.792862
20.34050	150.3040	8.705741
20.39216	150.2996	8.621476
20.44383	150.2955	8.538486
20.49550	150.2916	8.452851
20.54716	150.2871	8.369319
20.59883	150.2829	8.286853
20.65050	150.2785	8.205790
20.70383	150.2753	8.122888
20.75383	150.2710	8.044024
20.80716	150.2662	7.960602
20.85716	150.2631	7.887702
20.91050	150.2593	7.805587
20.96050	150.2554	7.730494
21.01383	150.2518	7.649934
21.06383	150.2471	7.561724
21.11716	150.2434	7.488569
21.16716	150.2400	7.424918
21.22050	150.2358	7.353918
21.27216	150.2321	7.279522
21.32383	150.2292	7.209150
21.37550	150.2252	7.139220
21.42717	150.2221	7.067847
21.47883	150.2184	6.998508
21.53050	150.2154	6.929922
21.58383	150.2110	6.862998
21.63383	150.2080	6.797551
21.68716	150.2052	6.730150
21.73716	150.2029	6.667807
21.79050	150.1986	6.602120
21.84050	150.1954	6.542465
21.89383	150.1924	6.478318
21.94383	150.1895	6.419244
21.99716	150.1863	6.359252
22.04716	150.1836	6.298175
22.10050	150.1806	6.240492
22.15216	150.1774	6.185532
22.20383	150.1746	6.128796
22.25550	150.1726	6.073018
22.30716	150.1694	6.018916
22.35883	150.1670	5.966818
22.41050	150.1647	5.916314
22.46216	150.1617	5.866928
22.51383	150.1612	5.816279
22.56716	150.1578	5.766882
22.61716	150.1565	5.720850
22.67050	150.1533	5.676476
22.72050	150.1512	5.635800
22.77383	150.1484	5.592646
22.82383	150.1469	5.550666
22.87716	150.1440	5.508968
22.92717	150.1422	5.471467
22.98050	150.1401	5.426509
23.03050	150.1383	5.387957
23.08383	150.1351	5.344446
23.13550	150.1332	5.301694
23.18716	150.1301	5.261036
23.23883	150.1274	5.216950
23.29050	150.1260	5.174205
23.34216	150.1234	5.130278
23.39383	150.1209	5.086300
23.44716	150.1192	5.038212
23.49716	150.1164	4.993128
23.55050	150.1141	4.945600
23.60050	150.1123	4.897002
23.65383	150.1095	4.846090
23.70383	150.1071	4.800989
23.75716	150.1050	4.746616
23.80716	150.1036	4.696900
23.86050	150.1013	4.641234
23.91050	150.0987	4.582666
23.96383	150.0958	4.526033
24.01550	150.0930	4.480426
24.06716	150.0908	4.429694
24.11883	150.0881	4.377688
24.17050	150.0846	4.317747
24.22216	150.0822	4.259128
24.27383	150.0788	4.204056
24.32550	150.0757	4.146580
24.37716	150.0727	4.089544
24.43050	150.0695	4.031375
24.48050	150.0671	3.975556
24.53383	150.0640	3.915020
24.58383	150.0607	3.858875
24.63716	150.0578	3.802812
24.68716	150.0551	3.749100
24.74050	150.0522	3.690081
24.79050	150.0504	3.640240
24.84383	150.0474	3.584522
24.89383	150.0450	3.536167
24.94716	150.0424	3.479158
24.99883	150.0402	3.428131
25.05050	150.0388	3.379425
25.10216	150.0358	3.332576
25.15383	150.0331	3.287659
25.20550	150.0310	3.240661
25.25716	150.0284	3.197270
25.31050	150.0266	3.151449
25.36050	150.0240	3.112980
25.41383	150.0215	3.071163
25.46383	150.0192	3.030731
25.51716	150.0175	2.989184
25.56716	150.0147	2.951860
25.62050	150.0131	2.908970
25.67050	150.0106	2.873873
25.72383	150.0084	2.833801
25.77383	150.0066	2.796095
25.82717	150.0046	2.757900
25.87883	150.0032	2.721487
25.93050	150.0014	2.682750
25.98216	150.0000	2.648122
26.03383	149.9980	2.613910
26.08550	149.9969	2.579810
26.13716	149.9956	2.543635
26.18883	149.9941	2.508376
26.24050	149.9927	2.471722
26.29383	149.9907	2.438080
26.34383	149.9895	2.408806
26.39716	149.9884	2.375920
26.44717	149.9861	2.344603
26.50050	149.9839	2.313456
26.55050	149.9826	2.285947
26.60383	149.9811	2.253590
26.65383	149.9793	2.227316
26.70716	149.9770	2.197052
26.75716	149.9756	2.167415
26.81050	149.9739	2.137556
26.86216	149.9726	2.108576
26.91383	149.9715	2.075705
26.96550	149.9692	2.046990
27.01716	149.9670	2.017086
27.06883	149.9662	1.985604
27.12050	149.9649	1.955821
27.17383	149.9641	1.922958
27.22383	149.9625	1.891298
27.27717	149.9610	1.859663
27.32717	149.9593	1.828950
27.38050	149.9579	1.799985
27.43050	149.9572	1.771986
27.48383	149.9553	1.745816
27.53383	149.9539	1.719377
27.58716	149.9526	1.689891
27.63716	149.9498	1.660510
27.69050	149.9488	1.634497
27.74216	149.9471	1.604146
27.79383	149.9456	1.575610
27.84550	149.9438	1.546038
27.89716	149.9426	1.515994
27.94883	149.9418	1.486278
28.00050	149.9398	1.458664
28.05217	149.9392	1.427215
28.10383	149.9371	1.397237
28.15716	149.9361	1.368699
28.20716	149.9353	1.342545
28.26050	149.9332	1.311076
28.31050	149.9322	1.283227
28.36383	149.9311	1.256154
28.41383	149.9286	1.230600
28.46716	149.9271	1.204030
28.51716	149.9270	1.176120
28.57050	149.9246	1.146254
28.62050	149.9227	1.120888
28.67383	149.9207	1.093081
28.72550	149.9198	1.065446
28.77717	149.9174	1.040520
28.82883	149.9171	1.014157
28.88050	149.9149	0.9862414
28.93216	149.9140	0.9582416
28.98383	149.9132	0.9273087
29.03717	149.9114	0.8964950
29.08716	149.9097	0.8680069
29.14050	149.9098	0.8378166
29.19050	149.9080	0.8108108
29.24383	149.9068	0.7802304
29.29383	149.9055	0.7529069
29.34716	149.9036	0.7298800
29.39716	149.9026	0.7056355
29.45050	149.9019	0.6826280
29.50050	149.9004	0.6667296
29.55383	149.8988	0.6382112
29.60550	149.8971	0.6129937
29.65716	149.8956	0.5874068
29.70883	149.8947	0.5593745
29.76050	149.8932	0.5328396
29.81217	149.8922	0.5058243
29.86383	149.8912	0.4798396
29.91550	149.8902	0.4529172
29.96716	149.8892	0.4244200
30.02050	149.8883	0.3998869
30.07050	149.8870	0.3724309
30.12383	149.8858	0.3461453
30.17383	149.8843	0.3245878
30.22717	149.8825	0.3002846
30.27717	149.8818	0.2771320
30.33050	149.8794	0.2554136
30.38050	149.8785	0.2346588
30.43383	149.8774	0.2107470
30.48383	149.8764	0.1899159
30.53717	149.8750	0.1676189
30.58883	149.8738	0.1449254
30.64050	149.8731	0.1195443
30.69216	149.8712	0.09478809
30.74383	149.8710	0.07191187
30.79550	149.8697	0.04734236
30.84716	149.8683	0.02579960
30.90050	149.8672	.003275280
30.95050	149.8655	-.01600853
31.00383	149.8642	-.03723991
31.05383	149.8642	-.05751924
31.10716	149.8622	-.07784272
31.15716	149.8606	-.09497407
31.21050	149.8607	-0.1182269
31.26050	149.8592	-0.1398357
31.31383	149.8587	-0.1594980
31.36383	149.8576	-0.1794074
31.41716	149.8564	-0.1982145
31.46883	149.8550	-0.2162320
31.52050	149.8547	-0.2373436
31.57217	149.8531	-0.2552214
31.62383	149.8517	-0.2727966
31.67550	149.8510	-0.2914606
31.72717	149.8505	-0.3093840
31.77883	149.8495	-0.3257488
31.83050	149.8482	-0.3421631
31.88383	149.8470	-0.3613035
31.93384	149.8472	-0.3797316
31.98717	149.8458	-0.3965992
32.03717	149.8457	-0.4119802
32.09050	149.8449	-0.4291025
32.14050	149.8434	-0.4469759
32.19383	149.8432	-0.4631622
32.24383	149.8428	-0.4785992
32.29716	149.8418	-0.4948334
32.34716	149.8416	-0.5103433
32.40050	149.8408	-0.5251037
32.45216	149.8395	-0.5402031
32.50383	149.8404	-0.5555400
32.55550	149.8390	-0.5696113
32.60716	149.8383	-0.5833096
32.65883	149.8379	-0.5976873
32.71050	149.8368	-0.6125965
32.76383	149.8365	-0.6259380
32.81383	149.8356	-0.6379370
32.86716	149.8347	-0.6503596
32.91716	149.8345	-0.6623546
32.97050	149.8334	-0.6775156
33.02050	149.8321	-0.6873569
33.07383	149.8319	-0.7002712
33.12383	149.8320	-0.7131878
33.17717	149.8299	-0.7256868
33.22717	149.8296	-0.7365094
33.28050	149.8279	-0.7483326
33.33216	149.8278	-0.7604756
33.38383	149.8274	-0.7715951
33.43550	149.8270	-0.7846963
33.48717	149.8264	-0.7968280
33.53883	149.8259	-0.8097578
33.59050	149.8254	-0.8209319
33.64216	149.8246	-0.8323516
33.69383	149.8247	-0.8453863
33.74716	149.8240	-0.8587141
33.79716	149.8240	-0.8703094
33.85050	149.8231	-0.8809894
33.90050	149.8226	-0.8922562
33.95383	149.8217	-0.9026244
34.00383	149.8216	-0.9129042
34.05716	149.8203	-0.9230606
34.10716	149.8201	-0.9323180
34.16050	149.8192	-0.9417681
34.21050	149.8180	-0.9510330
34.26383	149.8178	-0.9602391
34.31550	149.8170	-0.9693871
34.36716	149.8153	-0.9782611
34.41883	149.8161	-0.9875492
34.47050	149.8151	-0.9975738
34.52217	149.8148	-1.007327
34.57383	149.8146	-1.016443
34.62717	149.8138	-1.026150
34.67717	149.8144	-1.035143
34.73050	149.8136	-1.045420
34.78050	149.8144	-1.055003
34.83383	149.8128	-1.064874
34.88383	149.8144	-1.073641
34.93716	149.8130	-1.083074
34.98717	149.8126	-1.091432
35.04050	149.8121	-1.100375
35.09050	149.8122	-1.108790
35.14383	149.8116	-1.117405
35.19550	149.8112	-1.125427
35.24716	149.8110	-1.133361
35.29883	149.8105	-1.140911
35.35050	149.8103	-1.148126
35.40216	149.8099	-1.155127
35.45383	149.8088	-1.161717
35.50550	149.8090	-1.168154
35.55716	149.8075	-1.174775
35.61050	149.8079	-1.181357
35.66050	149.8074	-1.187561
35.71383	149.8066	-1.193863
35.76383	149.8056	-1.199902
35.81716	149.8063	-1.206235
35.86716	149.8052	-1.212436
35.92050	149.8051	-1.218874
35.97050	149.8048	-1.225154
36.02383	149.8046	-1.232000
36.07383	149.8040	-1.238383
36.12717	149.8046	-1.245606
36.17883	149.8040	-1.252334
36.23050	149.8041	-1.258962
36.28216	149.8037	-1.265391
36.33383	149.8042	-1.271680
36.38550	149.8041	-1.277923
36.43716	149.8031	-1.283783
36.49050	149.8030	-1.289538
36.54050	149.8036	-1.294899
36.59384	149.8024	-1.300356
36.64383	149.8020	-1.305035
36.69717	149.8017	-1.309971
36.74716	149.8011	-1.314639
36.80050	149.8012	-1.319295
36.85050	149.8006	-1.323624
36.90383	149.7996	-1.328146
36.95383	149.8001	-1.332296
37.00716	149.7998	-1.336634
37.05883	149.7990	-1.341101
37.11050	149.7994	-1.345660
37.16217	149.7985	-1.350109
37.21383	149.7982	-1.354587
37.26550	149.7984	-1.359339
37.31716	149.7986	-1.364597
37.36883	149.7982	-1.369532
37.42050	149.7994	-1.374413
37.47383	149.7984	-1.379429
37.52383	149.7984	-1.384038
37.57717	149.7976	-1.388816
37.62717	149.7980	-1.393066
37.68050	149.7974	-1.397166
37.73050	149.7975	-1.401127
37.78383	149.7978	-1.405235
37.83383	149.7975	-1.408987
37.88716	149.7975	-1.413052
37.93716	149.7971	-1.416892
37.99050	149.7964	-1.420876
38.04217	149.7973	-1.424496
38.09384	149.7965	-1.427982
38.14550	149.7959	-1.431466
38.19717	149.7960	-1.434668
38.24883	149.7949	-1.437538
38.30050	149.7943	-1.440344
38.35383	149.7940	-1.443162
38.40383	149.7948	-1.445679
38.45716	149.7949	-1.448236
38.50716	149.7940	-1.450858
38.56050	149.7946	-1.454052
38.61050	149.7946	-1.457679
38.66383	149.7945	-1.461734
38.71383	149.7949	-1.465613
38.76716	149.7946	-1.469956
38.81716	149.7948	-1.473677
38.87050	149.7941	-1.477489
38.92216	149.7941	-1.480811
38.97383	149.7940	-1.483642
39.02550	149.7926	-1.486220
39.07717	149.7937	-1.488524
39.12883	149.7934	-1.490991
39.18050	149.7933	-1.493502
39.23216	149.7928	-1.495941
39.28383	149.7928	-1.498388
39.33716	149.7917	-1.500916
39.38716	149.7925	-1.503251
39.44050	149.7924	-1.505624
39.49050	149.7916	-1.507665
39.54383	149.7912	-1.509707
39.59384	149.7918	-1.511859
39.64717	149.7914	-1.514004
39.69717	149.7911	-1.516290
39.75050	149.7914	-1.518646
39.80050	149.7916	-1.521009
39.85383	149.7919	-1.523410
39.90550	149.7914	-1.525944
39.95716	149.7910	-1.528704
40.00883	149.7912	-1.531440
40.06050	149.7911	-1.534416
40.11217	149.7914	-1.537250
40.16383	149.7911	-1.539842
40.21716	149.7904	-1.542505
40.26716	149.7916	-1.544960
40.32050	149.7912	-1.547164
40.37050	149.7915	-1.549350
40.42383	149.7909	-1.551689
40.47383	149.7907	-1.553846
40.52716	149.7910	-1.555890
40.57717	149.7911	-1.557769
40.63050	149.7898	-1.559533
40.68050	149.7902	-1.560762
40.73383	149.7900	-1.562058
40.78550	149.7893	-1.563338
40.83716	149.7897	-1.564437
40.88883	149.7888	-1.565453
40.94050	149.7890	-1.566563
40.99216	149.7890	-1.568120
41.04383	149.7885	-1.569655
41.09550	149.7891	-1.571369
41.14717	149.7892	-1.573527
41.20050	149.7892	-1.575682
41.25050	149.7893	-1.577760
41.30383	149.7894	-1.580118
41.35383	149.7894	-1.582234
41.40717	149.7897	-1.584275
41.45717	149.7898	-1.586368
41.51050	149.7891	-1.588622
41.56050	149.7894	-1.590394
41.61383	149.7900	-1.592464
41.66383	149.7892	-1.593831
41.71717	149.7889	-1.595256
41.76883	149.7889	-1.596624
41.82050	149.7886	-1.597826
41.87216	149.7884	-1.598890
41.92383	149.7876	-1.599711
41.97550	149.7884	-1.600582
42.02716	149.7881	-1.601452
42.08050	149.7881	-1.602204
42.13050	149.7869	-1.602981
42.18383	149.7871	-1.603953
42.23383	149.7869	-1.604950
42.28717	149.7866	-1.606111
42.33716	149.7869	-1.607346
42.39050	149.7867	-1.608974
42.44050	149.7869	-1.610568
42.49383	149.7865	-1.612555
42.54383	149.7870	-1.614395
42.59716	149.7868	-1.616653
42.64883	149.7875	-1.618736
42.70050	149.7870	-1.620832
42.75217	149.7872	-1.622647
42.80383	149.7864	-1.623782
42.85550	149.7868	-1.624846
42.90717	149.7865	-1.625445
42.95883	149.7860	-1.625958
43.01050	149.7863	-1.626737
43.06383	149.7854	-1.627456
43.11383	149.7860	-1.628166
43.16716	149.7860	-1.629364
43.21717	149.7865	-1.630369
43.26717	149.7869	-1.631966
43.32050	149.9474	-1.385888
43.37050	150.4496	-2.431392
43.42383	151.1148	-5.171378
43.47383	151.8177	-8.188061
43.52716	152.6232	-11.37585
43.57717	153.4214	-14.07000
43.63050	154.3085	-16.56218
43.68050	155.1680	-18.54725
43.73383	156.1079	-20.31904
43.78550	157.0397	-21.75294
43.83716	157.9857	-22.95308
43.88883	158.9456	-23.96605
43.94050	159.9148	-24.82223
43.99216	160.8936	-25.54891
44.04383	161.8811	-26.18469
44.09716	162.9052	-26.74801
44.14717	163.8707	-27.21264
44.20050	164.9054	-27.66244
44.25050	165.8795	-28.03232
44.30383	166.9205	-28.39420
44.35383	167.8990	-28.71431
44.40717	168.9436	-29.02084
44.45717	169.9266	-29.30190
44.51050	170.9744	-29.58551
44.56050	171.9588	-29.84060
44.61383	173.0103	-30.11604
44.66550	174.0284	-30.36748
44.71717	175.0475	-30.61403
44.76883	176.0664	-30.85702
44.82050	177.0861	-31.10161
44.87216	178.1055	-31.35140
44.92383	179.1247	-31.60485
44.97550	180.1450	-31.86545
45.02716	181.1655	-32.13204
45.08050	182.2179	-32.42552
45.13050	183.2045	-32.70271
45.18383	184.2578	-33.01206
45.23383	185.2445	-33.31358
45.28717	186.2980	-33.63843
45.33716	187.2836	-33.95136
45.39050	188.3361	-34.29733
45.44050	189.3219	-34.62918
45.49383	190.3734	-34.99733
45.54383	191.3576	-35.34366
45.59716	192.4072	-35.73104
45.64883	193.4238	-36.12883
45.70050	194.4391	-36.54288
45.75217	195.4544	-36.95874
45.80383	196.4689	-37.39332
45.85550	197.4823	-37.85641
45.90717	198.4950	-38.33850
45.96050	199.5395	-38.86269
46.01050	200.5159	-39.38428
46.06383	201.5570	-39.98280
46.11383	202.5296	-40.59933
46.16716	203.5682	-41.27026
46.21717	204.5394	-41.94384
46.27050	205.5742	-42.71194
46.32050	206.5410	-43.49402
46.37383	207.5688	-44.40080
46.42383	208.5305	-45.32410
46.47717	209.5500	-46.41135
46.52883	210.5338	-47.58134
46.58050	211.5123	-48.88569
46.63217	212.4832	-50.34389
46.68383	213.4459	-52.00578
46.73550	214.3979	-53.92431
46.78717	215.3352	-56.17547
46.83883	216.2549	-58.83863
46.89050	217.1545	-61.97000
46.94383	218.0587	-65.72378
46.99383	218.8881	-69.66288
47.04716	219.7541	-74.22700
47.09716	220.5548	-78.71356
47.15050	221.4050	-83.45402
47.20050	222.2170	-87.46828
47.25383	223.1225	-90.67147
47.30383	224.0331	-92.21655
47.35717	225.0770	-92.26969
47.40717	226.1232	-90.80665
47.46050	227.3050	-87.96051
47.51216	228.5007	-84.14476
47.56383	229.7376	-79.45647
47.61550	231.0171	-73.80114
47.66716	232.3334	-67.50474
47.71884	233.6438	-61.72949
47.77050	234.9153	-56.89464
47.82383	236.1825	-52.83884
47.87383	237.3360	-49.75104
47.92717	238.5350	-47.11097
47.97717	239.6333	-45.11701
48.03050	240.7858	-43.42356
48.08050	241.8517	-42.15322
48.13383	242.9738	-41.06733
48.18383	244.0166	-40.25664
48.23717	245.1198	-39.55240
48.28717	246.1482	-39.03199
48.34050	247.2384	-38.58408
48.39217	248.2905	-38.24042
48.44383	249.3395	-37.95917
48.49550	250.3854	-37.74575
48.54716	251.4292	-37.58324
48.59883	252.4711	-37.45860
48.65050	253.5100	-37.36156
48.70216	254.5483	-37.29013
48.75383	255.5855	-37.24502
48.80717	256.6556	-37.22906
48.85717	257.6581	-37.22600
48.91050	258.7269	-37.22441
48.96050	259.7278	-37.23298
49.01383	260.7950	-37.27164
49.06383	261.7945	-37.32034
49.11716	262.8600	-37.39296
49.16716	263.8599	-37.45356
49.22050	264.9255	-37.53803
49.27050	265.9235	-37.62594
49.32383	266.9891	-37.72275
49.37550	268.0201	-37.82048
49.42717	269.0513	-37.94290
49.47883	270.0810	-38.08337
49.53050	271.1108	-38.22074
49.58217	272.1394	-38.36391
49.63383	273.1691	-38.51836
49.68716	274.2310	-38.68881
49.73717	275.2260	-38.87624
49.78717	276.1932	-39.07800
49.84050	276.5805	-39.04506
49.89050	276.4143	-34.72093
49.94383	276.0166	-28.12100
49.99383	275.5120	-21.60262
50.04716	274.8733	-15.21731
50.09716	274.2031	-10.00165
50.15050	273.4307	-5.215449
50.20050	272.6638	-1.413954
50.25383	271.8054	1.969160
50.30550	270.9414	4.690818
50.35717	270.0514	6.958952
50.40883	269.1400	8.859695
50.46050	268.2106	10.43488
50.51216	267.2615	11.72572
50.56383	266.3062	12.93921
50.61550	265.3428	14.03489
50.66716	264.3722	15.01596
50.72050	263.3628	15.90931
50.77050	262.4121	16.65080
50.82383	261.3916	17.36624
50.87383	260.4301	17.95978
50.92717	259.4014	18.52775
50.97717	258.4344	19.00420
51.03050	257.3978	19.45747
51.08050	256.4246	19.83483
51.13383	255.3821	20.19540
51.18383	254.4040	20.50381
51.23717	253.3582	20.80262
51.28883	252.3438	21.05724
51.34050	251.3278	21.29043
51.39216	250.3117	21.51266
51.44384	249.2947	21.71206
51.49550	248.2752	21.90531
51.54717	247.2558	22.07861
51.60050	246.2018	22.25186
51.65050	245.2142	22.39878
51.70383	244.1589	22.54903
51.75383	243.1694	22.67201
51.80717	242.1136	22.79841
51.85717	241.1247	22.90657
51.91050	240.0681	23.02468
51.96050	239.0775	23.13191
52.01383	238.0211	23.23565
52.06383	237.0297	23.32808
52.11716	235.9720	23.43178
52.16883	234.9474	23.51963
52.22050	233.9224	23.60976
52.27217	232.8969	23.69418
52.32383	231.8732	23.76541
52.37550	230.8469	23.84397
52.42717	229.8219	23.92300
52.47883	228.7967	23.99476
52.53050	227.7717	24.07249
52.58383	226.7120	24.15316
52.63383	225.7192	24.21994
52.68716	224.6612	24.29980
52.73717	223.6672	24.36074
52.79050	222.6069	24.42782
52.84050	221.6138	24.48662
52.89384	220.5544	24.54977
52.94384	219.5596	24.60520
52.99717	218.5001	24.67034
53.04717	217.5064	24.71844
53.10050	216.4464	24.76525
53.15217	215.4190	24.81462
53.20383	214.3928	24.85938
53.25550	213.3658	24.90558
53.30717	212.3384	24.94760
53.35883	211.3110	24.99498
53.41050	210.2838	25.03870
53.46382	209.2240	25.08169
53.51382	208.2300	25.11644
53.56716	207.1687	25.15756
53.61716	206.1749	25.19102
53.67050	205.1139	25.22339
53.72050	204.1201	25.25638
53.77383	203.0580	25.29017
53.82383	202.0637	25.31826
53.87717	201.0032	25.34202
53.92717	200.0079	25.37268
53.98050	198.9459	25.39858
54.03217	197.9180	25.42115
54.08383	196.8898	25.44280
54.13550	195.8618	25.46386
54.18716	194.8343	25.49082
54.23882	193.8065	25.52536
54.29050	192.7792	25.55236
54.34217	191.7502	25.58087
54.39384	190.7219	25.60535
54.44717	189.6605	25.62338
54.49717	188.6656	25.64778
54.55050	187.6037	25.66885
54.60050	186.6078	25.68435
54.65383	185.5462	25.70641
54.70383	184.5511	25.72304
54.75717	183.4891	25.73306
54.80717	182.4934	25.74820
54.86050	181.4309	25.76266
54.91050	180.4352	25.77574
54.96382	179.3731	25.79716
55.01550	178.3450	25.82116
55.06716	177.3165	25.85613
55.11882	176.2899	25.90134
55.17050	175.2618	25.95846
55.22217	174.2348	26.02806
55.27383	173.2088	26.11210
55.32717	172.1514	26.22248
55.37717	171.1608	26.36370
55.43050	170.1059	26.53276
55.48050	169.1181	26.73092
55.53383	168.0666	27.00306
55.58383	167.0847	27.33335
55.63716	166.0445	27.82220
55.68716	165.0781	28.50664
55.74050	164.0613	29.57385
55.79050	163.1262	31.01428
55.84384	162.1576	33.13475
55.89550	161.2514	35.83995
55.94717	160.3754	39.15793
55.99883	159.5263	42.95929
56.05050	158.6920	46.95234
56.10217	157.8587	50.82104
56.15383	157.0108	54.28618
56.20550	156.1342	57.10479
56.25717	155.2210	59.11982
56.31050	154.2342	60.27152
56.36050	153.2652	60.47715
56.41382	152.1885	59.80850
56.46382	151.1394	58.44164
56.51716	149.9844	56.34185
56.56716	148.8771	53.94562
56.62050	147.6805	51.15572
56.67050	146.5526	48.50504
56.72382	145.3548	45.81638
56.77383	144.2386	43.49522
56.82717	143.0599	41.28726
56.87883	141.9332	39.41578
56.93050	140.8172	37.79184
56.98217	139.7132	36.36936
57.03383	138.6189	35.13962
57.08550	137.5327	34.08423
57.13716	136.4562	33.16415
57.19050	135.3505	32.33982
57.24050	134.3182	31.67898
57.29382	133.2226	31.05986
57.34384	132.1995	30.55740
57.39717	131.1117	30.08195
57.44717	130.0946	29.68881
57.50050	129.0121	29.32462
57.55050	127.9984	29.02063
57.60383	126.9202	28.71523
57.65383	125.9100	28.47160
57.70717	124.8354	28.23157
57.75883	123.7945	28.02186
57.81050	122.7556	27.83196
57.86217	121.7170	27.65629
57.91382	120.6785	27.48930
57.96550	119.6418	27.33900
58.01716	118.6039	27.20539
58.06884	117.5681	27.08182
58.12050	116.5316	26.96670
58.17383	115.4614	26.84122
58.22382	114.4584	26.72736
58.27717	113.3898	26.61016
58.32717	112.3869	26.50955
58.38050	111.3182	26.39992
58.43050	110.3156	26.30175
58.48383	109.2484	26.19787
58.53383	108.2450	26.11135
58.58716	107.1769	26.01568
58.63716	106.1762	25.92599
58.69050	105.1066	25.83402
58.74216	104.0733	25.74277
58.79382	103.0388	25.66000
58.84550	102.0047	25.57930
58.89717	100.9691	25.49344
58.94883	99.93634	25.41391
59.00050	98.90232	25.33534
59.05383	97.83482	25.25177
59.10383	96.83394	25.18861
59.15717	95.76780	25.10623
59.20717	94.76847	25.03204
59.26050	93.70050	24.95603
59.31050	92.70059	24.88856
59.36382	91.63371	24.80672
59.41382	90.63285	24.73772
59.46717	89.56609	24.64080
59.51716	88.56581	24.57315
59.57050	87.49916	24.49635
59.62217	86.46454	24.42033
59.67383	85.43153	24.34890
59.72550	84.39792	24.27362
59.77717	83.36472	24.20440
59.82883	82.33088	24.13391
59.88050	81.29668	24.06871
59.93217	80.26300	23.99092
59.98383	79.22964	23.91650
60.03716	78.16124	23.83756
60.08716	77.16020	23.76315
60.14050	76.09308	23.68866
60.19050	75.09242	23.62192
60.24382	74.02518	23.54634
60.29382	73.02465	23.46725
60.34716	71.95692	23.37509
60.39717	70.95375	23.26410
60.45050	69.88369	23.14036
60.50050	68.87981	22.98572
60.55383	67.80774	22.85180
60.60550	66.77103	22.73908
60.65717	65.73569	22.63713
60.70883	64.70037	22.54267
60.76050	63.66440	22.44697
60.81216	62.63014	22.35134
60.86382	61.59630	22.24538
60.91716	60.52666	22.14746
60.96717	59.52535	22.07993
61.02050	58.45896	22.01999
61.07050	57.45951	21.98364
61.12383	56.39313	21.93943
61.17383	55.39450	21.89945
61.22717	54.32803	21.85617
61.27717	53.32837	21.81366
61.33050	52.26203	21.76546
61.38050	51.26380	21.71649
61.43383	50.19769	21.65402
61.48550	49.16502	22.18754
61.53716	48.17816	22.30864
61.58882	47.13678	22.11130
61.64050	46.09672	21.95369
61.69216	45.05800	21.80840
61.74382	44.01986	21.67869
61.79550	42.98172	21.55897
61.84716	41.94488	21.44251
61.90050	40.87464	21.32841
61.95050	39.87207	21.22168
62.00383	38.80258	21.11560
62.05383	37.80050	21.00724
62.10717	36.72981	20.89630
62.15717	35.72692	20.79395
62.21050	34.65747	20.68542
62.26050	33.65510	20.58238
62.31382	32.58496	20.47276
62.36382	31.58216	20.36686
62.41716	30.51110	20.25418
62.46884	29.47411	20.15519
62.52050	28.43822	20.04179
62.57217	27.40094	19.92820
62.62383	26.36380	19.81776
62.67550	25.32538	19.70367
62.72717	24.28818	19.58124
62.77550	23.32312	19.46492
62.82717	22.72734	19.69080
62.88050	22.79212	17.50757
62.93050	23.07059	13.83878
62.98383	23.54629	9.355491
63.03383	24.09885	5.239100
63.08716	24.77962	1.269053
63.13716	25.48548	-1.954452
63.19050	26.29434	-4.851631
63.24050	27.09584	-7.121374
63.29382	27.98767	-9.120868
63.34384	28.85206	-10.66871
63.39717	29.79656	-12.03516
63.44883	30.73250	-13.12646
63.50050	31.68154	-14.04133
63.55217	32.64324	-14.81076
63.60383	33.61632	-15.46494
63.65550	34.59668	-16.02451
63.70717	35.58434	-16.50747
63.75883	36.57710	-16.92758
63.81050	37.57428	-17.29762
63.86384	38.60952	-17.63861
63.91382	39.58265	-17.92134
63.96717	40.62407	-18.19264
64.01716	41.60239	-18.42207
64.07050	42.64910	-18.64487
64.12050	43.63258	-18.83925
64.17383	44.68109	-19.02692
64.22384	45.66670	-19.19568
64.27717	46.71954	-19.36172
64.32718	47.70720	-19.51496
64.38050	48.76236	-19.67113
64.43218	49.78484	-19.81651
64.48383	50.80784	-19.95615
64.53550	51.83213	-20.09443
64.58716	52.85735	-20.22666
64.63884	53.88209	-20.35400
64.69050	54.90746	-20.47483
64.74384	55.96739	-20.60136
64.79384	56.96098	-20.71938
64.84717	58.02076	-20.83816
64.89717	59.01460	-20.95320
64.95050	60.07505	-21.06620
65.00050	61.06926	-21.17614
65.05383	62.13052	-21.29905
65.10383	63.12558	-21.40362
65.15718	64.18750	-21.51926
65.20717	65.18310	-21.61919
65.26050	66.24478	-21.72644
65.31216	67.27384	-21.84006
65.36384	68.30310	-21.94274
65.41550	69.33196	-22.04258
65.46717	70.36136	-22.14485
65.51882	71.39024	-22.24381
65.57050	72.41890	-22.34886
65.62218	73.44812	-22.45154
65.67384	74.47735	-22.55151
65.72718	75.54015	-22.65769
65.77718	76.53701	-22.75337
65.83050	77.60007	-22.86133
65.88050	78.59630	-22.95936
65.93384	79.65928	-23.06780
65.98384	80.65492	-23.16822
66.03718	81.71834	-23.27819
66.08716	82.71347	-23.37712
66.14050	83.77628	-23.48639
66.19050	84.77250	-23.59293
66.24384	85.83482	-23.70522
66.29550	86.86408	-23.81762
66.34718	87.89399	-23.92992
66.39884	88.92406	-24.03783
66.45050	89.95353	-24.14979
66.50218	90.98292	-24.25854
66.55384	92.01242	-24.36720
66.60718	93.07522	-24.47866
66.65718	94.07188	-24.58434
66.71050	95.13541	-24.69553
66.76050	96.13025	-24.79886
66.81384	97.19361	-24.90731
66.86384	98.18993	-25.00987
66.91718	99.25251	-25.12222
66.96718	100.2496	-25.22966
67.02050	101.3125	-25.33733
67.07050	102.3093	-25.44047
67.12384	103.3733	-25.55004
67.17550	104.4028	-25.65386
67.22718	105.4328	-25.75957
67.27884	106.4624	-25.87312
67.33050	107.4920	-25.98331
67.38218	108.5216	-26.09318
67.43384	109.5504	-26.19951
67.48550	110.5815	-26.31750
67.53718	111.6117	-26.42625
67.59050	112.6747	-26.54059
67.64050	113.6719	-26.64568
67.69384	114.7332	-26.75606
67.74384	115.7300	-26.86200
67.79718	116.7927	-26.97746
67.84718	117.7891	-27.08179
67.90050	118.8518	-27.19720
67.95050	119.8487	-27.31283
68.00384	120.9111	-27.43494
68.05384	121.9073	-27.54979
68.10718	122.9706	-27.67456
68.15884	123.9996	-27.79675
68.21050	125.0294	-27.92150
68.26218	126.0576	-28.04450
68.31384	127.0869	-28.15845
68.36550	128.1166	-28.27885
68.41718	129.1464	-28.39914
68.47050	130.2085	-28.52168
68.52050	131.2050	-28.64890
68.57384	132.2676	-28.78394
68.62384	133.2634	-28.89879
68.67718	134.3255	-29.03204
68.72718	135.3206	-29.15530
68.78050	136.3825	-29.29961
68.83050	137.3782	-29.43970
68.88384	138.4402	-29.58433
68.93384	139.4346	-29.72323
68.98718	140.4964	-29.87238
69.03882	141.5244	-30.01982
69.09050	142.5518	-30.16373
69.14216	143.5803	-30.31635
69.19384	144.6085	-30.46294
69.24550	145.6362	-30.61846
69.29718	146.6646	-30.76986
69.34882	147.6922	-30.92380
69.40050	148.7200	-31.07463
69.45384	149.7806	-31.23445
69.50384	150.7745	-31.38460
69.55718	151.8348	-31.55249
69.60718	152.8283	-31.71173
69.66050	153.8889	-31.89408
69.71050	154.8836	-32.06030
69.76384	155.9430	-32.24670
69.81384	156.9376	-32.42117
69.86718	157.9967	-32.60922
69.91718	158.9900	-32.78843
69.97050	160.0494	-32.98428
70.02218	161.0763	-33.17296
70.07384	162.1026	-33.36255
70.12550	163.1294	-33.54620
70.17718	164.1560	-33.72059
70.22884	165.1848	-33.89130
70.28050	166.2125	-34.03748
70.33384	167.2751	-34.17640
70.38384	168.2730	-34.28468
70.43718	169.3366	-34.38361
70.48718	170.3342	-34.46198
70.54050	171.3983	-34.54834
70.59050	172.3976	-34.62510
70.64384	173.4619	-34.71665
70.69384	174.4596	-34.79935
70.74718	175.5239	-34.89385
70.79718	176.5214	-34.99650
70.85050	177.5831	-35.12076
70.90218	178.6133	-35.25177
70.95384	179.6410	-35.41345
71.00550	180.6677	-35.58132
71.05718	181.6935	-35.78314
71.10884	182.7190	-36.00834
71.16050	183.7428	-36.24978
71.21218	184.7666	-36.51804
71.26384	185.7889	-36.80535
71.31718	186.8429	-37.12949
71.36718	187.8296	-37.47712
71.42050	188.8799	-37.88559
71.47050	189.8629	-38.30281
71.52384	190.9083	-38.81697
71.57384	191.8865	-39.34578
71.62718	192.9262	-39.97844
71.67718	193.8984	-40.63044
71.73050	194.9326	-41.37442
71.78050	195.9002	-42.12448
71.83384	196.9306	-42.97016
71.88550	197.9272	-43.81356
71.93718	198.9230	-44.67289
71.98882	199.9176	-45.56300
72.04050	200.9111	-46.49007
72.09216	201.9017	-47.47295
72.14384	202.8894	-48.53447
72.19718	203.9056	-49.70996
72.24718	204.8549	-50.88907
72.30050	205.8632	-52.24140
72.35050	206.8062	-53.55556
72.40384	207.8108	-54.96671
72.45384	208.7535	-56.23961
72.50718	209.7654	-57.40620
72.55718	210.7274	-58.15363
72.61050	211.7777	-58.36110
72.66050	212.7942	-57.79656
72.71384	213.9206	-56.26992
72.76550	215.0510	-53.94895
72.81718	216.2122	-51.10507
72.86884	217.3824	-48.24411
72.92050	218.5396	-45.73490
72.97218	219.6778	-43.64424
73.02384	220.7974	-41.95113
73.07550	221.9025	-40.57555
73.12718	222.9928	-39.46452
73.18050	224.1076	-38.55534
73.23050	225.1436	-37.86670
73.28384	226.2416	-37.27237
73.33384	227.2651	-36.84412
73.38718	228.3521	-36.46707
73.43718	229.3674	-36.19917
73.49050	230.4467	-35.98816
73.54050	231.4569	-35.83784
73.59384	232.5318	-35.72992
73.64384	233.5366	-35.65748
73.69718	234.6089	-35.60912
73.74884	235.6463	-35.58760
73.80050	236.6824	-35.58008
73.85218	237.7176	-35.57310
73.90384	238.7526	-35.57285
73.95550	239.7868	-35.58280
74.00718	240.8211	-35.62817
74.06050	241.8889	-35.68381
74.11050	242.8888	-35.74192
74.16382	243.9558	-35.80361
74.21384	244.9550	-35.86090
74.26716	246.0207	-35.92574
74.31718	247.0205	-35.99336
74.37050	248.0858	-36.05877
74.42050	249.0852	-36.12870
74.47384	250.1506	-36.20903
74.52384	251.1488	-36.29433
74.57718	252.2130	-36.40433
74.62884	253.2433	-36.50552
74.68050	254.2746	-36.59656
74.73218	255.3052	-36.69027
74.78384	256.3354	-36.79857
74.83550	257.3662	-36.91399
74.88718	258.3961	-37.03128
74.93884	259.4258	-37.16054
74.99050	260.4556	-37.29942
75.04384	261.5168	-37.44808
75.09384	262.5136	-37.58880
75.14718	263.5753	-37.76370
75.19718	264.5697	-37.93616
75.25050	265.6319	-38.10637
75.30050	266.6274	-38.27359
75.35384	267.6886	-38.43128
75.40384	268.6843	-38.58397
75.45718	269.7452	-38.76280
75.50718	270.7388	-38.94275
75.56050	271.7985	-39.14850
-2.000000	5.000000	0.0000000