File: 2-C1(0.8mol%)+C20(0.6mol%)/matlab/150-2.txt
CLOSED
Version	1.0
Language	English
Mode	Standard
Run	5
RunSerial	11882
Instrument	DSC Q2000 V24.11 Build 124
Module	DSC Standard Cell RC
Operator	Jing
File	\\Ae520-1454\ta\Data\DSC\UQ Composites\Nan\C1(7.5)+C20P(3)+CL(Hotplate MixtureAB)\150-2
ProcName	Ramp
InstSerial	2000-0883
AutoSerial	1293
Sample	Iso150-2
Size	45.7000	mg
PanMass	Not available
PanResist	Automatic Automatic  K/W
PanFactor	Default Default
Method	Ramp
Comment
Xcomment	Pan: Tzero Aluminum Hermetic
Xcomment	Gas1: Nitrogen 50.0 ml/min
Xcomment	Gas2: Nitrogen 50.0 ml/min
Text
Exotherm	UP
Kcell	1.05230
Cpconst	Standard: 0.938
Calib	-38.6961
TempCal	1	pts	157.46	156.60
TzeroDt	-87.6168 -0.0009 -1.4231
TzeroDtz	-87.6168 0.0057 6.9570
InstCalFile	Tzero: \\Ae520-1454\ta\Data\DSC\Calibration\2017\CALIBRATION\1562_RCS (90)_05_18_2017 10_50_44.TZR
InstCalFile	Baseline: \\Ae520-1454\ta\Data\DSC\Calibration\2017\2017-05-17_Calibration.001
InstCalFile	Sapphire: \\Ae520-1454\ta\Data\DSC\Calibration\2017\2017-05-17_Saphire.001
InstCalDate	Tzero 2017-05-18 Time 10:50:44
TempRange	-87.39 to 398.39 °C at 10.00 °C/min Heat Only
AutoZero	Delta T Offset 0.000 uV
AutoZero	Delta T0 Offset 0.000 uV
MultiptCal	0
MultiPtDesc	0) Not set
AutoCellConst	Calibration Date 2017-05-18 16:59:28
Controls	Gas 1  Event Off  Sampling 0.2
Cell#	RC-01562
CoolingUnit	RCS (90)
SelHeatFlow	Heat Flow T4 (mW)
AutoLidII	Installed
AutoAnalysis	Off
MacroFile
Nsig	3
Sig1	Time (min)
Sig2	Temperature (°C)
Sig3	Heat Flow (mW)
Date	2017-06-22
Time	20:13:22
OrgMethod	1: Equilibrate at 20.00 °C
OrgMethod	2: Ramp 40.00 °C/min to 150.00 °C
OrgMethod	3: Mark end of cycle 1
OrgMethod	4: Isothermal for 40.00 min
OrgMethod	5: Mark end of cycle 2
OrgMethod	6: Ramp 20.00 °C/min to 280.00 °C
OrgMethod	7: Mark end of cycle 3
OrgMethod	8: Ramp 20.00 °C/min to 20.00 °C
OrgMethod	9: Mark end of cycle 4
OrgMethod	10: Ramp 20.00 °C/min to 280.00 °C
OrgMethod	11: Mark end of cycle 5
OrgFile	C:\Users\jarra\Desktop\DSC\2-C1(0.8mol%)+C20(0.6mol%)\150-2
StartOfData
4.99994E-4	20.07866	0.3766120
0.05383332	20.20929	0.6684680
0.1055000	21.10574	0.4605018
0.1571666	22.36391	-2.602110
0.2088333	23.79065	-6.664429
0.2605000	25.34297	-11.01282
0.3121666	26.98298	-15.11928
0.3638334	28.69580	-18.79388
0.4171667	30.52332	-22.05261
0.4671667	32.28216	-24.65582
0.5205000	34.19756	-26.99230
0.5705000	36.02350	-28.83582
0.6238334	37.99774	-30.51240
0.6738334	39.86814	-31.85883
0.7271668	41.87809	-33.13525
0.7771668	43.77298	-34.27258
0.8305000	45.79532	-35.57158
0.8804999	47.69415	-36.76824
0.9338332	49.73079	-37.82214
0.9854999	51.72246	-38.64045
1.037167	53.72256	-39.42194
1.088833	55.72336	-40.30472
1.140500	57.71590	-41.40231
1.192167	59.69802	-42.68097
1.243833	61.67941	-44.05824
1.295500	63.65435	-45.57512
1.347166	65.61548	-47.47346
1.400500	67.60044	-50.42624
1.450500	69.38176	-55.12572
1.503833	71.11831	-63.58996
1.553833	72.57253	-74.52150
1.607167	73.99639	-87.97318
1.657167	75.30194	-100.6204
1.710500	76.69758	-114.0456
1.760500	78.03739	-126.3697
1.813834	79.39174	-140.3793
1.863834	80.79568	-150.5377
1.917167	82.41528	-159.3165
1.968833	84.14674	-164.9258
2.020500	85.96931	-168.6697
2.072166	87.99226	-168.6060
2.123834	90.12291	-167.4183
2.175500	92.33481	-164.6071
2.227167	94.64653	-159.5015
2.280500	97.30941	-147.3641
2.330500	100.0563	-133.6920
2.383833	102.9013	-121.6142
2.433833	105.4576	-112.2300
2.487166	108.0854	-103.9693
2.537166	110.4658	-97.57035
2.590500	112.9366	-91.96014
2.640500	115.1976	-87.64655
2.693833	117.5582	-83.91620
2.743833	119.7339	-81.11036
2.797167	122.0179	-78.74219
2.848834	124.2036	-76.94564
2.900500	126.3656	-75.54145
2.952166	128.5101	-74.45556
3.003833	130.6364	-73.67211
3.055500	132.7496	-73.15828
3.107167	134.8514	-72.84102
3.158834	136.9405	-72.75696
3.210500	139.0233	-72.80988
3.260500	141.0319	-72.99959
3.310500	142.8472	-73.68881
3.363834	143.9785	-72.44293
3.413833	144.7596	-67.67679
3.467166	145.4210	-61.40706
3.518833	145.9514	-55.17654
3.570500	146.3958	-49.44806
3.622166	146.7734	-44.43072
3.673834	147.0926	-40.13718
3.725500	147.3648	-36.51725
3.777167	147.5956	-33.47160
3.828833	147.7929	-30.91099
3.880500	147.9624	-28.75371
3.933833	148.1112	-26.87950
3.983833	148.2301	-25.39320
4.037167	148.3403	-24.04736
4.087167	148.4285	-22.96777
4.140500	148.5088	-21.99096
4.190500	148.5753	-21.20252
4.243834	148.6362	-20.47946
4.293833	148.6858	-19.89742
4.347166	148.7324	-19.35606
4.397167	148.7692	-18.91348
4.450500	148.8054	-18.50111
4.502167	148.8344	-18.14967
4.553834	148.8611	-17.84340
4.605500	148.8841	-17.56342
4.657166	148.9058	-17.31366
4.708834	148.9242	-17.09155
4.760500	148.9403	-16.89139
4.813834	148.9558	-16.69542
4.863834	148.9698	-16.52393
4.917167	148.9828	-16.35977
4.967167	148.9941	-16.21055
5.020500	149.0056	-16.06166
5.070500	149.0152	-15.92668
5.123833	149.0255	-15.79006
5.173834	149.0337	-15.66495
5.227167	149.0440	-15.53402
5.277168	149.0513	-15.40939
5.330500	149.0596	-15.28313
5.382168	149.0677	-15.15797
5.433832	149.0754	-15.03372
5.485500	149.0829	-14.90552
5.537168	149.0908	-14.77681
5.588832	149.0984	-14.64445
5.640500	149.1062	-14.50275
5.692166	149.1150	-14.35292
5.743834	149.1240	-14.19358
5.797168	149.1331	-14.01853
5.847168	149.1426	-13.84366
5.900500	149.1528	-13.65846
5.950500	149.1624	-13.47598
6.003834	149.1729	-13.28074
6.053834	149.1820	-13.09219
6.107168	149.1929	-12.89956
6.157166	149.2028	-12.73450
6.210500	149.2118	-12.55079
6.260500	149.2207	-12.38379
6.313832	149.2297	-12.19698
6.365500	149.2391	-12.00819
6.417168	149.2499	-11.81170
6.468832	149.2604	-11.60874
6.520500	149.2704	-11.40444
6.572168	149.2812	-11.19241
6.623834	149.2924	-10.97427
6.677168	149.3040	-10.75168
6.727168	149.3139	-10.53336
6.780500	149.3261	-10.30515
6.830500	149.3381	-10.08091
6.883832	149.3503	-9.844170
6.933832	149.3603	-9.619249
6.987168	149.3743	-9.376722
7.037168	149.3854	-9.149149
7.090500	149.3976	-8.908551
7.140500	149.4088	-8.681043
7.193832	149.4214	-8.435004
7.245500	149.4335	-8.203418
7.297168	149.4442	-7.972812
7.348832	149.4566	-7.747395
7.400500	149.4670	-7.518111
7.452168	149.4797	-7.295262
7.503832	149.4900	-7.071480
7.555500	149.5014	-6.846894
7.607168	149.5124	-6.624488
7.660500	149.5254	-6.388348
7.710500	149.5362	-6.160282
7.763834	149.5488	-5.906256
7.813834	149.5606	-5.646213
7.867166	149.5752	-5.355913
7.917168	149.5903	-5.064896
7.970500	149.6058	-4.740490
8.020500	149.6212	-4.430570
8.073834	149.6379	-4.106096
8.123834	149.6532	-3.804775
8.177168	149.6677	-3.496312
8.228834	149.6834	-3.219886
8.280500	149.6969	-2.964313
8.332168	149.7084	-2.733792
8.383832	149.7195	-2.530603
8.435499	149.7298	-2.346841
8.487168	149.7387	-2.182813
8.540500	149.7464	-2.033864
8.590500	149.7531	-1.909178
8.643832	149.7587	-1.787312
8.693832	149.7652	-1.690382
8.747168	149.7702	-1.594804
8.797168	149.7748	-1.512894
8.850500	149.7785	-1.439256
8.900500	149.7832	-1.371632
8.953834	149.7861	-1.307116
9.003834	149.7899	-1.256030
9.057168	149.7919	-1.204661
9.108832	149.7944	-1.157604
9.160499	149.7958	-1.115952
9.212168	149.7986	-1.075456
9.263832	149.8006	-1.038766
9.315500	149.8034	-1.006360
9.367166	149.8051	-0.9732872
9.418832	149.8066	-0.9416930
9.470500	149.8082	-0.9161732
9.523834	149.8093	-0.8874603
9.573834	149.8110	-0.8624688
9.627168	149.8131	-0.8387728
9.677168	149.8142	-0.8137961
9.730500	149.8148	-0.7879708
9.780500	149.8168	-0.7639155
9.833832	149.8173	-0.7437228
9.883832	149.8184	-0.7220439
9.937166	149.8194	-0.6981009
9.987168	149.8208	-0.6791474
10.04050	149.8223	-0.6582232
10.09217	149.8236	-0.6367974
10.14383	149.8249	-0.6157332
10.19550	149.8256	-0.5974941
10.24717	149.8262	-0.5767918
10.29883	149.8279	-0.5568379
10.35050	149.8288	-0.5388360
10.40383	149.8296	-0.5186211
10.45383	149.8316	-0.4997984
10.50717	149.8326	-0.4786515
10.55717	149.8337	-0.4607408
10.61050	149.8344	-0.4389362
10.66050	149.8350	-0.4205936
10.71383	149.8364	-0.3964428
10.76383	149.8375	-0.3777381
10.81716	149.8389	-0.3560960
10.86716	149.8392	-0.3381756
10.92050	149.8412	-0.3186445
10.97217	149.8422	-0.2986442
11.02383	149.8423	-0.2784627
11.07550	149.8446	-0.2559573
11.12717	149.8444	-0.2339652
11.17883	149.8467	-0.2130376
11.23050	149.8482	-0.1932190
11.28217	149.8479	-0.1711429
11.33383	149.8492	-0.1503865
11.38717	149.8507	-0.1312368
11.43716	149.8514	-0.1098493
11.49050	149.8531	-.08598797
11.54050	149.8546	-.06637496
11.59383	149.8556	-.04379566
11.64383	149.8576	-.02154428
11.69717	149.8581	.001502560
11.74717	149.8587	0.02376512
11.80050	149.8597	0.04606256
11.85050	149.8614	0.07230956
11.90383	149.8623	0.09573301
11.95550	149.8631	0.1196863
12.00717	149.8648	0.1429891
12.05884	149.8664	0.1654321
12.11050	149.8666	0.1906414
12.16217	149.8681	0.2137596
12.21383	149.8700	0.2352075
12.26717	149.8709	0.2607892
12.31716	149.8722	0.2849596
12.37050	149.8743	0.3098354
12.42050	149.8747	0.3350878
12.47383	149.8750	0.3633690
12.52383	149.8771	0.3851085
12.57717	149.8784	0.4129844
12.62717	149.8798	0.4354902
12.68050	149.8800	0.4627629
12.73050	149.8824	0.4859434
12.78383	149.8833	0.5142332
12.83550	149.8849	0.5417668
12.88717	149.8869	0.5682752
12.93883	149.8868	0.5950608
12.99050	149.8898	0.6216187
13.04216	149.8902	0.6493851
13.09383	149.8922	0.6762518
13.14550	149.8937	0.7030306
13.19717	149.8944	0.7321619
13.25050	149.8964	0.7623743
13.30050	149.8977	0.7896069
13.35383	149.8989	0.8205518
13.40383	149.9004	0.8465694
13.45717	149.9021	0.8750812
13.50717	149.9034	0.9035399
13.56050	149.9046	0.9343281
13.61050	149.9066	0.9615474
13.66383	149.9077	0.9941384
13.71383	149.9096	1.022247
13.76717	149.9110	1.052198
13.81884	149.9120	1.083164
13.87050	149.9146	1.113476
13.92217	149.9152	1.143005
13.97383	149.9176	1.173196
14.02550	149.9186	1.205221
14.07717	149.9211	1.236043
14.13050	149.9223	1.268920
14.18050	149.9234	1.300400
14.23383	149.9248	1.333918
14.28383	149.9262	1.365164
14.33717	149.9282	1.401913
14.38717	149.9301	1.432710
14.44050	149.9320	1.466400
14.49050	149.9339	1.501154
14.54384	149.9355	1.534094
14.59383	149.9372	1.568594
14.64717	149.9384	1.605454
14.69884	149.9409	1.640649
14.75050	149.9423	1.675362
14.80217	149.9439	1.712109
14.85383	149.9459	1.747134
14.90550	149.9479	1.785736
14.95717	149.9500	1.822460
15.00883	149.9513	1.861028
15.06050	149.9540	1.898814
15.11383	149.9563	1.938176
15.16383	149.9580	1.978032
15.21716	149.9598	2.018140
15.26717	149.9604	2.060640
15.32050	149.9641	2.103766
15.37050	149.9652	2.143420
15.42383	149.9678	2.189750
15.47383	149.9695	2.230325
15.52717	149.9724	2.277882
15.57717	149.9752	2.327994
15.63050	149.9772	2.383403
15.68217	149.9808	2.443665
15.73383	149.9837	2.507339
15.78550	149.9874	2.581197
15.83717	149.9904	2.663448
15.88883	149.9956	2.755116
15.94050	150.0010	2.858159
15.99383	150.0064	2.982968
16.04383	150.0116	3.106819
16.09717	150.0195	3.257619
16.14716	150.0263	3.411717
16.20050	150.0354	3.595213
16.25050	150.0454	3.777125
16.30383	150.0554	3.989640
16.35383	150.0648	4.205156
16.40716	150.0774	4.442131
16.45716	150.0885	4.679169
16.51050	150.1013	4.941346
16.56216	150.1151	5.202691
16.61383	150.1289	5.472476
16.66550	150.1419	5.748952
16.71716	150.1559	6.026765
16.76883	150.1704	6.305761
16.82050	150.1844	6.584880
16.87216	150.1981	6.861297
16.92383	150.2121	7.132344
16.97716	150.2261	7.405556
17.02716	150.2386	7.655249
17.08050	150.2516	7.912356
17.13050	150.2636	8.145900
17.18383	150.2753	8.386811
17.23383	150.2862	8.600994
17.28717	150.2977	8.823009
17.33716	150.3071	9.021332
17.39050	150.3179	9.226952
17.44050	150.3262	9.406381
17.49383	150.3362	9.595719
17.54550	150.3453	9.770672
17.59716	150.3536	9.943428
17.64883	150.3623	10.10826
17.70050	150.3704	10.27012
17.75216	150.3783	10.42717
17.80383	150.3860	10.58520
17.85716	150.3942	10.73750
17.90716	150.4014	10.88500
17.96050	150.4095	11.03161
18.01050	150.4159	11.17629
18.06383	150.4230	11.32298
18.11383	150.4308	11.45906
18.16716	150.4376	11.60132
18.21716	150.4445	11.73750
18.27050	150.4509	11.88096
18.32050	150.4581	12.00466
18.37383	150.4646	12.14122
18.42550	150.4717	12.27200
18.47716	150.4784	12.41399
18.52883	150.4854	12.53604
18.58050	150.4912	12.65398
18.63216	150.4976	12.77271
18.68383	150.5037	12.89283
18.73550	150.5094	13.00462
18.78717	150.5156	13.11100
18.84050	150.5206	13.22206
18.89050	150.5262	13.32276
18.94383	150.5302	13.42414
18.99383	150.5358	13.51492
19.04716	150.5400	13.60786
19.09716	150.5437	13.69266
19.15050	150.5483	13.77786
19.20050	150.5525	13.85580
19.25383	150.5562	13.93744
19.30383	150.5601	14.01052
19.35716	150.5628	14.07937
19.40883	150.5665	14.14406
19.46050	150.5697	14.20427
19.51216	150.5722	14.26025
19.56383	150.5752	14.30449
19.61550	150.5777	14.35370
19.66716	150.5794	14.39449
19.72050	150.5808	14.43290
19.77050	150.5827	14.45951
19.82383	150.5846	14.48416
19.87383	150.5863	14.50198
19.92716	150.5860	14.51352
19.97716	150.5864	14.52014
20.03050	150.5871	14.52600
20.08050	150.5870	14.52992
20.13383	150.5864	14.53098
20.18383	150.5866	14.52712
20.23716	150.5848	14.50881
20.28883	150.5828	14.47457
20.34050	150.5820	14.42627
20.39216	150.5790	14.37083
20.44383	150.5759	14.31481
20.49550	150.5736	14.24690
20.54716	150.5712	14.16848
20.59883	150.5674	14.08808
20.65050	150.5638	14.00025
20.70383	150.5589	13.90480
20.75383	150.5539	13.80991
20.80716	150.5490	13.70104
20.85716	150.5438	13.59159
20.91050	150.5377	13.46998
20.96050	150.5315	13.34804
21.01383	150.5241	13.21731
21.06383	150.5180	13.08891
21.11716	150.5109	12.94701
21.16716	150.5043	12.81016
21.22050	150.4970	12.65581
21.27216	150.4886	12.50694
21.32383	150.4811	12.35638
21.37550	150.4733	12.19881
21.42717	150.4657	12.03995
21.47883	150.4573	11.88198
21.53050	150.4498	11.72118
21.58383	150.4409	11.55514
21.63383	150.4330	11.39691
21.68716	150.4248	11.23033
21.73716	150.4165	11.06748
21.79050	150.4079	10.89924
21.84050	150.4004	10.73808
21.89383	150.3925	10.57615
21.94383	150.3844	10.41194
21.99716	150.3752	10.23919
22.04716	150.3669	10.07858
22.10050	150.3592	9.907989
22.15216	150.3510	9.746569
22.20383	150.3432	9.589706
22.25550	150.3348	9.429975
22.30716	150.3269	9.271639
22.35883	150.3192	9.117699
22.41050	150.3120	8.965038
22.46216	150.3037	8.809553
22.51383	150.2961	8.661734
22.56716	150.2886	8.508125
22.61716	150.2808	8.365939
22.67050	150.2736	8.214820
22.72050	150.2670	8.073006
22.77383	150.2592	7.926926
22.82383	150.2533	7.789239
22.87716	150.2460	7.647114
22.92717	150.2399	7.515972
22.98050	150.2326	7.377145
23.03050	150.2269	7.243060
23.08383	150.2193	7.103126
23.13550	150.2139	6.972200
23.18716	150.2074	6.842190
23.23883	150.2011	6.712044
23.29050	150.1945	6.586009
23.34216	150.1878	6.463711
23.39383	150.1818	6.339942
23.44716	150.1750	6.216145
23.49716	150.1692	6.104415
23.55050	150.1625	5.983061
23.60050	150.1568	5.869497
23.65383	150.1499	5.753360
23.70383	150.1448	5.640216
23.75716	150.1385	5.523718
23.80716	150.1330	5.418257
23.86050	150.1274	5.301758
23.91050	150.1224	5.197175
23.96383	150.1166	5.085982
24.01550	150.1116	4.977984
24.06716	150.1066	4.873678
24.11883	150.1017	4.769044
24.17050	150.0972	4.666914
24.22216	150.0919	4.566284
24.27383	150.0870	4.469112
24.32550	150.0825	4.371231
24.37716	150.0774	4.276712
24.43050	150.0722	4.180860
24.48050	150.0681	4.091742
24.53383	150.0632	3.999493
24.58383	150.0587	3.913250
24.63716	150.0532	3.819519
24.68716	150.0499	3.736821
24.74050	150.0449	3.644620
24.79050	150.0411	3.564710
24.84383	150.0360	3.480096
24.89383	150.0322	3.396667
24.94716	150.0278	3.312836
24.99883	150.0238	3.233070
25.05050	150.0196	3.154492
25.10216	150.0157	3.076731
25.15383	150.0114	2.999282
25.20550	150.0078	2.922967
25.25716	150.0035	2.849432
25.31050	149.9995	2.774360
25.36050	149.9960	2.702141
25.41383	149.9918	2.631812
25.46383	149.9883	2.561480
25.51716	149.9852	2.489944
25.56716	149.9813	2.422236
25.62050	149.9783	2.354345
25.67050	149.9749	2.287734
25.72383	149.9714	2.220397
25.77383	149.9684	2.157870
25.82717	149.9653	2.092344
25.87883	149.9625	2.030559
25.93050	149.9589	1.967811
25.98216	149.9556	1.910321
26.03383	149.9531	1.850654
26.08550	149.9506	1.791164
26.13716	149.9476	1.731650
26.18883	149.9447	1.676172
26.24050	149.9419	1.618150
26.29383	149.9404	1.561608
26.34383	149.9370	1.506451
26.39716	149.9344	1.455079
26.44717	149.9316	1.404528
26.50050	149.9293	1.350346
26.55050	149.9270	1.299356
26.60383	149.9251	1.249152
26.65383	149.9230	1.201939
26.70716	149.9203	1.150768
26.75716	149.9184	1.104305
26.81050	149.9161	1.057364
26.86216	149.9136	1.012446
26.91383	149.9111	0.9688476
26.96550	149.9090	0.9284265
27.01716	149.9059	0.8872548
27.06883	149.9040	0.8475871
27.12050	149.9012	0.8068901
27.17383	149.8990	0.7657426
27.22383	149.8972	0.7261931
27.27717	149.8947	0.6847071
27.32717	149.8936	0.6483506
27.38050	149.8914	0.6103043
27.43050	149.8891	0.5725550
27.48383	149.8884	0.5320751
27.53383	149.8854	0.4973124
27.58716	149.8850	0.4605516
27.63716	149.8823	0.4242699
27.69050	149.8805	0.3940039
27.74216	149.8785	0.3598820
27.79383	149.8772	0.3283911
27.84550	149.8754	0.2963205
27.89716	149.8738	0.2661620
27.94883	149.8721	0.2364130
28.00050	149.8701	0.2062669
28.05217	149.8693	0.1776817
28.10383	149.8679	0.1486604
28.15716	149.8663	0.1191709
28.20716	149.8648	0.09087556
28.26050	149.8634	0.06628875
28.31050	149.8614	0.04116694
28.36383	149.8614	0.01452802
28.41383	149.8599	-.01146622
28.46716	149.8590	-.03773247
28.51716	149.8583	-.06351728
28.57050	149.8564	-.09169416
28.62050	149.8564	-0.1140596
28.67383	149.8548	-0.1351086
28.72550	149.8539	-0.1555024
28.77717	149.8524	-0.1747796
28.82883	149.8513	-0.1919626
28.88050	149.8500	-0.2105258
28.93216	149.8494	-0.2276886
28.98383	149.8483	-0.2452217
29.03717	149.8473	-0.2623018
29.08716	149.8466	-0.2778820
29.14050	149.8460	-0.2947565
29.19050	149.8448	-0.3102861
29.24383	149.8440	-0.3265889
29.29383	149.8434	-0.3420460
29.34716	149.8427	-0.3572956
29.39716	149.8413	-0.3693616
29.45050	149.8405	-0.3826306
29.50050	149.8390	-0.3945752
29.55383	149.8384	-0.4069068
29.60550	149.8381	-0.4196274
29.65716	149.8375	-0.4325623
29.70883	149.8364	-0.4441086
29.76050	149.8355	-0.4572542
29.81217	149.8354	-0.4720472
29.86383	149.8341	-0.4836674
29.91550	149.8333	-0.4963679
29.96716	149.8327	-0.5074956
30.02050	149.8318	-0.5199436
30.07050	149.8312	-0.5315246
30.12383	149.8303	-0.5448507
30.17383	149.8297	-0.5578574
30.22717	149.8295	-0.5703360
30.27717	149.8285	-0.5833569
30.33050	149.8282	-0.5954014
30.38050	149.8270	-0.6099859
30.43383	149.8267	-0.6225996
30.48383	149.8262	-0.6349415
30.53717	149.8264	-0.6497645
30.58883	149.8258	-0.6642546
30.64050	149.8259	-0.6787903
30.69216	149.8250	-0.6903386
30.74383	149.8240	-0.7033191
30.79550	149.8242	-0.7166653
30.84716	149.8240	-0.7289761
30.90050	149.8225	-0.7405738
30.95050	149.8233	-0.7523600
31.00383	149.8217	-0.7636799
31.05383	149.8212	-0.7740688
31.10716	149.8208	-0.7866074
31.15716	149.8202	-0.7975937
31.21050	149.8189	-0.8083382
31.26050	149.8179	-0.8182343
31.31383	149.8178	-0.8291549
31.36383	149.8170	-0.8393082
31.41716	149.8158	-0.8496816
31.46883	149.8155	-0.8599042
31.52050	149.8152	-0.8701488
31.57217	149.8148	-0.8805519
31.62383	149.8144	-0.8914956
31.67550	149.8147	-0.9033299
31.72717	149.8148	-0.9148422
31.77883	149.8140	-0.9263182
31.83050	149.8134	-0.9370746
31.88383	149.8135	-0.9478508
31.93384	149.8129	-0.9579347
31.98717	149.8129	-0.9685912
32.03717	149.8122	-0.9776869
32.09050	149.8118	-0.9871738
32.14050	149.8114	-0.9955245
32.19383	149.8101	-1.004084
32.24383	149.8101	-1.011862
32.29716	149.8087	-1.019684
32.34716	149.8074	-1.026799
32.40050	149.8079	-1.034626
32.45216	149.8074	-1.042142
32.50383	149.8063	-1.049216
32.55550	149.8061	-1.056164
32.60716	149.8059	-1.062981
32.65883	149.8053	-1.069958
32.71050	149.8057	-1.077088
32.76383	149.8050	-1.084666
32.81383	149.8045	-1.092018
32.86716	149.8032	-1.099697
32.91716	149.8037	-1.106926
32.97050	149.8042	-1.115064
33.02050	149.8042	-1.122980
33.07383	149.8036	-1.131208
33.12383	149.8030	-1.138855
33.17717	149.8030	-1.146820
33.22717	149.8034	-1.153993
33.28050	149.8028	-1.161263
33.33216	149.8026	-1.167956
33.38383	149.8022	-1.174294
33.43550	149.8021	-1.180212
33.48717	149.8018	-1.186071
33.53883	149.8012	-1.191934
33.59050	149.8008	-1.197862
33.64216	149.8005	-1.203754
33.69383	149.8007	-1.209589
33.74716	149.8000	-1.215426
33.79716	149.7991	-1.220678
33.85050	149.7990	-1.226172
33.90050	149.7983	-1.231232
33.95383	149.7984	-1.236478
34.00383	149.7981	-1.241511
34.05716	149.7984	-1.246920
34.10716	149.7977	-1.251809
34.16050	149.7978	-1.257071
34.21050	149.7965	-1.261948
34.26383	149.7967	-1.266761
34.31550	149.7960	-1.271581
34.36716	149.7955	-1.276488
34.41883	149.7956	-1.281473
34.47050	149.7955	-1.286322
34.52217	149.7952	-1.291218
34.57383	149.7954	-1.296276
34.62717	149.7961	-1.301846
34.67717	149.7955	-1.307066
34.73050	149.7959	-1.312466
34.78050	149.7955	-1.317539
34.83383	149.7948	-1.322426
34.88383	149.7947	-1.326772
34.93716	149.7943	-1.331249
34.98717	149.7941	-1.335161
35.04050	149.7944	-1.339028
35.09050	149.7939	-1.342554
35.14383	149.7938	-1.346072
35.19550	149.7941	-1.349669
35.24716	149.7926	-1.353233
35.29883	149.7926	-1.356817
35.35050	149.7929	-1.360660
35.40216	149.7922	-1.364142
35.45383	149.7927	-1.367624
35.50550	149.7916	-1.371045
35.55716	149.7918	-1.374595
35.61050	149.7914	-1.377936
35.66050	149.7912	-1.380804
35.71383	149.7901	-1.384009
35.76383	149.7902	-1.387164
35.81716	149.7908	-1.390718
35.86716	149.7901	-1.394060
35.92050	149.7904	-1.397560
35.97050	149.7901	-1.400895
36.02383	149.7908	-1.404446
36.07383	149.7902	-1.407675
36.12717	149.7904	-1.411312
36.17883	149.7894	-1.414878
36.23050	149.7890	-1.418310
36.28216	149.7895	-1.421480
36.33383	149.7899	-1.424573
36.38550	149.7898	-1.427646
36.43716	149.7900	-1.430851
36.49050	149.7906	-1.434426
36.54050	149.7894	-1.437692
36.59384	149.7901	-1.441360
36.64383	149.7891	-1.444583
36.69717	149.7890	-1.447702
36.74716	149.7890	-1.450379
36.80050	149.7880	-1.453001
36.85050	149.7883	-1.455062
36.90383	149.7878	-1.457228
36.95383	149.7876	-1.459084
37.00716	149.7875	-1.461142
37.05883	149.7867	-1.463054
37.11050	149.7875	-1.465050
37.16217	149.7865	-1.467145
37.21383	149.7865	-1.469178
37.26550	149.7864	-1.471601
37.31716	149.7868	-1.474171
37.36883	149.7864	-1.476923
37.42050	149.7865	-1.479830
37.47383	149.7867	-1.482784
37.52383	149.7867	-1.485778
37.57717	149.7864	-1.488510
37.62717	149.7871	-1.491406
37.68050	149.7866	-1.494606
37.73050	149.7868	-1.497584
37.78383	149.7866	-1.500758
37.83383	149.7872	-1.503649
37.88716	149.7866	-1.506650
37.93716	149.7865	-1.509223
37.99050	149.7866	-1.511650
38.04217	149.7860	-1.513736
38.09384	149.7854	-1.515616
38.14550	149.7857	-1.517390
38.19717	149.7862	-1.519054
38.24883	149.7855	-1.520766
38.30050	149.7859	-1.522758
38.35383	149.7861	-1.524876
38.40383	149.7858	-1.527052
38.45716	149.7856	-1.529355
38.50716	149.7852	-1.531378
38.56050	149.7849	-1.533337
38.61050	149.7852	-1.535071
38.66383	149.7847	-1.536660
38.71383	149.7842	-1.538172
38.76716	149.7836	-1.539797
38.81716	149.7839	-1.541406
38.87050	149.7836	-1.543228
38.92216	149.7839	-1.545239
38.97383	149.7842	-1.547529
39.02550	149.7834	-1.549770
39.07717	149.7841	-1.552065
39.12883	149.7836	-1.554519
39.18050	149.7831	-1.556767
39.23216	149.7827	-1.558632
39.28383	149.7836	-1.560855
39.33716	149.7832	-1.563025
39.38716	149.7839	-1.565082
39.44050	149.7828	-1.567426
39.49050	149.7830	-1.569236
39.54383	149.7830	-1.571360
39.59384	149.7824	-1.573326
39.64717	149.7822	-1.575340
39.69717	149.7826	-1.577247
39.75050	149.7829	-1.579387
39.80050	149.7832	-1.581396
39.85383	149.7821	-1.583528
39.90550	149.7825	-1.585515
39.95716	149.7820	-1.587216
40.00883	149.7820	-1.588944
40.06050	149.7816	-1.590710
40.11217	149.7814	-1.592334
40.16383	149.7819	-1.593787
40.21716	149.7805	-1.595427
40.26716	149.7806	-1.596735
40.32050	149.7801	-1.597972
40.37050	149.7801	-1.598980
40.42383	149.7790	-1.600028
40.47383	149.7796	-1.600978
40.52716	149.7797	-1.602374
40.57717	149.7790	-1.603846
40.63050	149.7798	-1.605534
40.68050	149.7789	-1.607388
40.73383	149.7794	-1.609500
40.78550	149.7794	-1.611538
40.83716	149.7794	-1.613982
40.88883	149.7797	-1.616666
40.94050	149.7802	-1.619463
40.99216	149.7798	-1.622108
41.04383	149.7800	-1.624558
41.09550	149.7801	-1.626584
41.14717	149.7804	-1.628486
41.20050	149.7792	-1.630176
41.25050	149.7790	-1.631374
41.30383	149.7796	-1.632969
41.35383	149.7794	-1.634210
41.40717	149.7794	-1.635649
41.45717	149.7784	-1.637041
41.51050	149.7789	-1.638209
41.56050	149.7794	-1.639553
41.61383	149.7786	-1.641068
41.66383	149.7789	-1.642491
41.71717	149.7787	-1.644160
41.76883	149.7792	-1.645764
41.82050	149.7786	-1.647500
41.87216	149.7793	-1.649346
41.92383	149.7788	-1.651594
41.97550	149.7794	-1.653841
42.02716	149.7789	-1.656064
42.08050	149.7789	-1.658096
42.13050	149.7794	-1.659976
42.18383	149.7790	-1.661734
42.23383	149.7791	-1.662833
42.28717	149.7784	-1.663898
42.33716	149.7782	-1.664633
42.39050	149.7782	-1.665278
42.44050	149.7770	-1.665689
42.49383	149.7778	-1.666096
42.54383	149.7767	-1.666908
42.59716	149.7770	-1.667824
42.64883	149.7774	-1.669130
42.70050	149.7773	-1.670617
42.75217	149.7771	-1.671903
42.80383	149.7774	-1.673423
42.85550	149.7776	-1.674965
42.90717	149.7778	-1.676515
42.95883	149.7782	-1.678365
43.01050	149.7770	-1.680454
43.06383	149.7781	-1.682455
43.11383	149.7781	-1.684358
43.16716	149.7775	-1.686290
43.21717	149.7777	-1.687802
43.26717	149.7784	-1.689508
43.32050	149.9480	-1.515823
43.37050	150.4516	-2.723921
43.42383	151.1159	-5.544401
43.47383	151.8186	-8.616743
43.52716	152.6239	-11.84112
43.57717	153.4201	-14.57808
43.63050	154.3067	-17.10614
43.68050	155.1657	-19.11949
43.73383	156.1043	-20.92348
43.78550	157.0338	-22.37942
43.83716	157.9785	-23.60198
43.88883	158.9360	-24.64060
43.94050	159.9050	-25.51570
43.99216	160.8824	-26.26340
44.04383	161.8670	-26.91450
44.09716	162.8909	-27.49358
44.14717	163.8547	-27.97011
44.20050	164.8879	-28.42919
44.25050	165.8595	-28.80635
44.30383	166.8984	-29.18381
44.35383	167.8759	-29.50912
44.40717	168.9194	-29.82870
44.45717	169.9001	-30.11113
44.51050	170.9481	-30.39708
44.56050	171.9309	-30.65644
44.61383	172.9802	-30.93468
44.66550	173.9974	-31.18930
44.71717	175.0148	-31.44168
44.76883	176.0340	-31.69252
44.82050	177.0527	-31.94352
44.87216	178.0719	-32.19434
44.92383	179.0911	-32.44844
44.97550	180.1104	-32.70975
45.02716	181.1296	-32.98472
45.08050	182.1817	-33.27952
45.13050	183.1678	-33.55535
45.18383	184.2206	-33.86398
45.23383	185.2062	-34.16612
45.28717	186.2574	-34.48550
45.33716	187.2431	-34.79330
45.39050	188.2938	-35.13765
45.44050	189.2782	-35.47380
45.49383	190.3284	-35.84958
45.54383	191.3121	-36.21090
45.59716	192.3601	-36.61124
45.64883	193.3758	-37.02101
45.70050	194.3898	-37.44553
45.75217	195.4037	-37.88618
45.80383	196.4168	-38.34586
45.85550	197.4282	-38.84450
45.90717	198.4384	-39.38691
45.96050	199.4790	-39.97956
46.01050	200.4528	-40.55926
46.06383	201.4914	-41.21492
46.11383	202.4634	-41.87364
46.16716	203.4973	-42.61375
46.21717	204.4651	-43.35118
46.27050	205.4964	-44.17008
46.32050	206.4608	-44.99407
46.37383	207.4866	-45.94042
46.42383	208.4448	-46.89653
46.47717	209.4637	-48.00256
46.52883	210.4466	-49.16205
46.58050	211.4243	-50.44562
46.63217	212.3952	-51.88910
46.68383	213.3581	-53.55232
46.73550	214.3066	-55.50830
46.78717	215.2410	-57.84534
46.83883	216.1556	-60.65443
46.89050	217.0467	-63.96543
46.94383	217.9412	-67.94616
46.99383	218.7588	-72.14450
47.04716	219.6100	-77.02214
47.09716	220.3964	-81.79119
47.15050	221.2343	-86.78946
47.20050	222.0379	-90.93091
47.25383	222.9483	-93.85074
47.30383	223.8847	-94.65822
47.35717	224.9713	-93.69580
47.40717	226.0590	-91.38059
47.46050	227.2738	-87.88384
47.51216	228.4912	-83.63639
47.56383	229.7420	-78.70244
47.61550	231.0253	-73.01582
47.66716	232.3377	-66.85662
47.71884	233.6399	-61.23992
47.77050	234.9042	-56.53775
47.82383	236.1647	-52.60757
47.87383	237.3130	-49.62396
47.92717	238.5056	-47.08530
47.97717	239.6008	-45.17418
48.03050	240.7485	-43.56053
48.08050	241.8095	-42.35750
48.13383	242.9279	-41.33842
48.18383	243.9670	-40.57555
48.23717	245.0680	-39.92524
48.28717	246.0939	-39.43617
48.34050	247.1822	-39.00878
48.39217	248.2343	-38.67925
48.44383	249.2820	-38.41192
48.49550	250.3264	-38.20872
48.54716	251.3686	-38.07138
48.59883	252.4076	-37.97180
48.65050	253.4456	-37.89619
48.70216	254.4830	-37.84492
48.75383	255.5202	-37.80979
48.80717	256.5892	-37.79718
48.85717	257.5906	-37.79419
48.91050	258.6587	-37.79244
48.96050	259.6594	-37.79661
49.01383	260.7261	-37.82062
49.06383	261.7249	-37.85356
49.11716	262.7912	-37.90601
49.16716	263.7908	-37.96314
49.22050	264.8552	-38.03997
49.27050	265.8540	-38.11130
49.32383	266.9194	-38.18090
49.37550	267.9506	-38.25142
49.42717	268.9822	-38.33093
49.47883	270.0140	-38.41348
49.53050	271.0467	-38.48988
49.58217	272.0766	-38.56384
49.63383	273.1084	-38.66255
49.68716	274.1725	-38.73352
49.73717	275.1701	-38.83864
49.78717	276.1343	-38.91760
49.84050	276.5192	-37.91055
49.89050	276.3814	-32.62350
49.94383	276.0090	-25.27464
49.99383	275.5252	-18.19380
50.04716	274.9094	-11.27229
50.09716	274.2606	-5.626763
50.15050	273.5052	-0.5199976
50.20050	272.7512	3.491795
50.25383	271.9070	7.066604
50.30550	271.0554	9.943384
50.35717	270.1769	12.33361
50.40883	269.2750	14.32781
50.46050	268.3544	15.99300
50.51216	267.4173	17.40119
50.56383	266.4678	18.58217
50.61550	265.5060	19.58283
50.66716	264.5356	20.44270
50.72050	263.5252	21.19797
50.77050	262.5710	21.81070
50.82383	261.5464	22.37544
50.87383	260.5818	22.82898
50.92717	259.5488	23.24696
50.97717	258.5777	23.58729
51.03050	257.5370	23.91132
51.08050	256.5613	24.17705
51.13383	255.5166	24.42951
51.18383	254.5358	24.64496
51.23717	253.4878	24.85257
51.28883	252.4700	25.03259
51.34050	251.4520	25.19063
51.39216	250.4333	25.33368
51.44384	249.4130	25.46785
51.49550	248.3915	25.58896
51.54717	247.3699	25.69324
51.60050	246.3140	25.79091
51.65050	245.3244	25.87606
51.70383	244.2684	25.95696
51.75383	243.2765	26.02654
51.80717	242.2190	26.09524
51.85717	241.2280	26.14526
51.91050	240.1699	26.20676
51.96050	239.1775	26.26227
52.01383	238.1194	26.31782
52.06383	237.1266	26.36728
52.11716	236.0678	26.42134
52.16883	235.0420	26.46243
52.22050	234.0154	26.50197
52.27217	232.9890	26.53506
52.32383	231.9624	26.56541
52.37550	230.9350	26.59607
52.42717	229.9088	26.62815
52.47883	228.8816	26.65084
52.53050	227.8553	26.68303
52.58383	226.7946	26.72854
52.63383	225.8015	26.75709
52.68716	224.7408	26.79862
52.73717	223.7466	26.82718
52.79050	222.6856	26.85064
52.84050	221.6910	26.87332
52.89384	220.6308	26.89594
52.94384	219.6365	26.91959
52.99717	218.5752	26.95234
53.04717	217.5803	26.97274
53.10050	216.5205	26.98829
53.15217	215.4912	27.00820
53.20383	214.4626	27.02175
53.25550	213.4344	27.03218
53.30717	212.4068	27.04475
53.35883	211.3778	27.05514
53.41050	210.3498	27.06611
53.46382	209.2878	27.07782
53.51382	208.2929	27.08873
53.56716	207.2319	27.10013
53.61716	206.2364	27.10972
53.67050	205.1752	27.12004
53.72050	204.1797	27.13262
53.77383	203.1186	27.14289
53.82383	202.1224	27.15314
53.87717	201.0613	27.16169
53.92717	200.0662	27.17036
53.98050	199.0031	27.17986
54.03217	197.9753	27.18887
54.08383	196.9468	27.19754
54.13550	195.9181	27.20565
54.18716	194.8886	27.21499
54.23882	193.8601	27.22632
54.29050	192.8322	27.23490
54.34217	191.8025	27.24290
54.39384	190.7733	27.25066
54.44717	189.7115	27.25816
54.49717	188.7161	27.26484
54.55050	187.6547	27.27128
54.60050	186.6582	27.27698
54.65383	185.5959	27.28353
54.70383	184.6012	27.28919
54.75717	183.5385	27.29400
54.80717	182.5439	27.29846
54.86050	181.4816	27.30375
54.91050	180.4860	27.30870
54.96382	179.4240	27.31596
55.01550	178.3952	27.32315
55.06716	177.3666	27.33470
55.11882	176.3382	27.34841
55.17050	175.3090	27.36657
55.22217	174.2802	27.39080
55.27383	173.2523	27.42276
55.32717	172.1915	27.45801
55.37717	171.1963	27.51010
55.43050	170.1368	27.57695
55.48050	169.1445	27.66416
55.53383	168.0859	27.78129
55.58383	167.0961	27.92556
55.63716	166.0445	28.15637
55.68716	165.0639	28.52934
55.74050	164.0288	29.20726
55.79050	163.0794	30.31635
55.84384	162.1002	32.29010
55.89550	161.1977	35.25716
55.94717	160.3510	39.35072
55.99883	159.5544	44.36210
56.05050	158.7867	49.76203
56.10217	158.0199	54.93340
56.15383	157.2257	59.38338
56.20550	156.3842	62.75174
56.25717	155.4837	64.85894
56.31050	154.4880	65.66901
56.36050	153.4958	65.28560
56.41382	152.3810	63.81388
56.46382	151.2941	61.68898
56.51716	150.1022	58.87684
56.56716	148.9675	55.96745
56.62050	147.7486	52.79242
56.67050	146.6085	49.91163
56.72382	145.4009	47.06766
56.77383	144.2804	44.67239
56.82717	143.1008	42.42200
56.87883	141.9716	40.51583
56.93050	140.8547	38.86772
56.98217	139.7492	37.42888
57.03383	138.6544	36.18192
57.08550	137.5666	35.10409
57.13716	136.4867	34.10176
57.19050	135.3766	33.23875
57.24050	134.3441	32.55600
57.29382	133.2490	31.92850
57.34384	132.2261	31.42432
57.39717	131.1383	30.94754
57.44717	130.1212	30.55273
57.50050	129.0378	30.18179
57.55050	128.0253	29.87062
57.60383	126.9460	29.57695
57.65383	125.9360	29.32340
57.70717	124.8600	29.07289
57.75883	123.8184	28.84916
57.81050	122.7788	28.64318
57.86217	121.7401	28.45474
57.91382	120.7014	28.28050
57.96550	119.6643	28.12388
58.01716	118.6263	27.97752
58.06884	117.5892	27.84082
58.12050	116.5516	27.71709
58.17383	115.4817	27.58140
58.22382	114.4786	27.46465
58.27717	113.4098	27.33737
58.32717	112.4079	27.22143
58.38050	111.3390	27.11322
58.43050	110.3357	27.00969
58.48383	109.2678	26.90416
58.53383	108.2658	26.81239
58.58716	107.1964	26.70718
58.63716	106.1958	26.61100
58.69050	105.1279	26.50891
58.74216	104.0930	26.41142
58.79382	103.0532	26.13770
58.84550	102.0160	26.06326
58.89717	100.9815	25.98010
58.94883	99.94738	25.90215
59.00050	98.91342	25.82813
59.05383	97.84574	25.74375
59.10383	96.84649	25.69711
59.15717	95.78397	25.73142
59.20717	94.78392	25.62886
59.26050	93.71722	25.56058
59.31050	92.71642	25.47649
59.36382	91.64969	25.39192
59.41382	90.64902	25.32348
59.46717	89.58264	25.23825
59.51716	88.58266	25.15780
59.57050	87.51601	25.07219
59.62217	86.48226	24.98696
59.67383	85.44944	24.90667
59.72550	84.41509	24.82706
59.77717	83.38222	24.75254
59.82883	82.34864	24.67950
59.88050	81.31451	24.60478
59.93217	80.28048	24.52628
59.98383	79.24712	24.45392
60.03716	78.17921	24.37538
60.08716	77.17840	24.30032
60.14050	76.11106	24.22688
60.19050	75.11054	24.15856
60.24382	74.04444	24.08246
60.29382	73.04361	24.01287
60.34716	71.97686	23.93502
60.39717	70.97620	23.86632
60.45050	69.90935	23.79332
60.50050	68.90806	23.72760
60.55383	67.84134	23.64616
60.60550	66.80706	23.56842
60.65717	65.77401	23.49220
60.70883	64.73888	23.41927
60.76050	63.70550	23.34350
60.81216	62.66969	23.25698
60.86382	61.63565	23.16784
60.91716	60.56644	23.05075
60.96717	59.56611	22.97392
61.02050	58.49729	22.87754
61.07050	57.49626	22.80390
61.12383	56.42926	22.71782
61.17383	55.42929	22.63883
61.22717	54.36162	22.56080
61.27717	53.36023	22.48133
61.33050	52.29284	22.40112
61.38050	51.29111	22.32452
61.43383	50.22316	22.23703
61.48550	49.18784	22.15096
61.53716	48.15281	22.07583
61.58882	47.11818	21.98726
61.64050	46.08354	21.90550
61.69216	45.04850	21.82235
61.74382	44.01394	21.73833
61.79550	42.97821	21.65660
61.84716	41.94284	21.57212
61.90050	40.87484	21.47942
61.95050	39.87300	21.39472
62.00383	38.80500	21.30189
62.05383	37.80337	21.20718
62.10717	36.73506	21.10218
62.15717	35.73228	21.00578
62.21050	34.66266	20.90850
62.26050	33.66050	20.80698
62.31382	32.59074	20.69941
62.36382	31.58785	20.59623
62.41716	30.51844	20.48560
62.46884	29.47976	20.38474
62.52050	28.44383	20.27132
62.57217	27.40650	20.14964
62.62383	26.36990	20.03427
62.67550	25.33178	19.91791
62.72717	24.29474	19.79456
62.77550	23.33129	19.67125
62.82717	22.75887	19.76812
62.88050	22.82045	17.14053
62.93050	23.08980	13.21607
62.98383	23.55894	8.537312
63.03383	24.10431	4.312890
63.08716	24.78336	0.2737185
63.13716	25.48727	-2.952571
63.19050	26.29492	-5.843620
63.24050	27.09647	-8.091748
63.29382	27.98734	-10.06316
63.34384	28.85135	-11.57650
63.39717	29.79739	-12.91006
63.44883	30.73167	-13.96936
63.50050	31.68191	-14.85065
63.55217	32.64473	-15.59384
63.60383	33.61796	-16.21843
63.65550	34.59797	-16.74862
63.70717	35.58733	-17.20011
63.75883	36.57978	-17.59425
63.81050	37.57786	-17.93873
63.86384	38.61328	-18.25323
63.91382	39.58570	-18.51378
63.96717	40.62675	-18.76521
64.01716	41.60683	-18.97488
64.07050	42.65332	-19.17913
64.12050	43.63633	-19.35472
64.17383	44.68734	-19.52890
64.22384	45.67342	-19.67876
64.27717	46.72598	-19.82792
64.32718	47.71422	-19.96434
64.38050	48.77062	-20.10784
64.43218	49.79274	-20.23380
64.48383	50.81653	-20.36020
64.53550	51.84010	-20.48499
64.58716	52.86543	-20.60417
64.63884	53.89045	-20.72117
64.69050	54.91635	-20.83127
64.74384	55.97614	-20.94378
64.79384	56.96975	-21.04954
64.84717	58.02963	-21.16398
64.89717	59.02300	-21.26795
64.95050	60.08476	-21.37402
65.00050	61.07880	-21.47641
65.05383	62.14062	-21.59316
65.10383	63.13500	-21.69704
65.15718	64.19809	-21.80246
65.20717	65.19390	-21.89602
65.26050	66.25564	-21.99541
65.31216	67.28350	-22.09772
65.36384	68.31294	-22.19166
65.41550	69.34114	-22.29146
65.46717	70.37100	-22.38962
65.51882	71.39985	-22.48795
65.57050	72.42888	-22.59106
65.62218	73.45900	-22.68640
65.67384	74.48834	-22.78470
65.72718	75.55118	-22.87812
65.77718	76.54692	-22.97070
65.83050	77.60951	-23.07213
65.88050	78.60544	-23.17136
65.93384	79.66680	-23.27277
65.98384	80.66372	-23.37478
66.03718	81.72640	-23.48791
66.08716	82.72214	-23.58642
66.14050	83.78474	-23.69332
66.19050	84.78147	-23.79431
66.24384	85.84442	-23.90362
66.29550	86.87376	-24.00480
66.34718	87.90259	-24.11154
66.39884	88.93188	-24.21518
66.45050	89.96051	-24.32614
66.50218	90.99080	-24.44014
66.55384	92.02032	-24.54924
66.60718	93.08282	-24.65811
66.65718	94.08041	-24.76200
66.71050	95.14225	-24.87018
66.76050	96.13891	-24.97262
66.81384	97.20172	-25.07771
66.86384	98.19818	-25.17360
66.91718	99.26019	-25.28594
66.96718	100.2569	-25.38648
67.02050	101.3193	-25.49644
67.07050	102.3161	-25.59712
67.12384	103.3779	-25.70748
67.17550	104.4076	-25.81334
67.22718	105.4378	-25.92312
67.27884	106.4666	-26.03216
67.33050	107.4958	-26.14213
67.38218	108.5248	-26.25388
67.43384	109.5546	-26.35695
67.48550	110.5832	-26.47780
67.53718	111.6126	-26.58646
67.59050	112.6745	-26.70346
67.64050	113.6711	-26.81308
67.69384	114.7337	-26.92718
67.74384	115.7298	-27.03482
67.79718	116.7927	-27.15258
67.84718	117.7892	-27.24603
67.90050	118.8518	-27.36535
67.95050	119.8483	-27.47070
68.00384	120.9100	-27.59059
68.05384	121.9056	-27.70825
68.10718	122.9680	-27.83038
68.15884	123.9971	-27.95519
68.21050	125.0274	-28.07696
68.26218	126.0556	-28.20373
68.31384	127.0850	-28.31675
68.36550	128.1142	-28.43408
68.41718	129.1414	-28.54953
68.47050	130.2036	-28.67465
68.52050	131.1995	-28.79790
68.57384	132.2610	-28.93501
68.62384	133.2572	-29.05474
68.67718	134.3186	-29.19585
68.72718	135.3143	-29.32315
68.78050	136.3760	-29.46690
68.83050	137.3717	-29.59966
68.88384	138.4338	-29.74092
68.93384	139.4292	-29.87882
68.98718	140.4903	-30.02064
69.03882	141.5183	-30.16798
69.09050	142.5472	-30.31080
69.14216	143.5744	-30.45405
69.19384	144.6016	-30.60004
69.24550	145.6300	-30.75152
69.29718	146.6570	-30.89967
69.34882	147.6842	-31.05405
69.40050	148.7118	-31.20573
69.45384	149.7727	-31.37167
69.50384	150.7675	-31.51667
69.55718	151.8277	-31.68179
69.60718	152.8209	-31.83558
69.66050	153.8817	-32.01266
69.71050	154.8745	-32.17722
69.76384	155.9349	-32.35957
69.81384	156.9282	-32.53377
69.86718	157.9884	-32.72044
69.91718	158.9819	-32.90426
69.97050	160.0410	-33.09248
70.02218	161.0679	-33.27084
70.07384	162.0946	-33.45091
70.12550	163.1217	-33.62163
70.17718	164.1492	-33.78010
70.22884	165.1778	-33.92672
70.28050	166.2062	-34.04840
70.33384	167.2694	-34.15935
70.38384	168.2667	-34.24939
70.43718	169.3308	-34.32726
70.48718	170.3287	-34.39219
70.54050	171.3926	-34.47186
70.59050	172.3911	-34.54688
70.64384	173.4553	-34.63616
70.69384	174.4523	-34.72350
70.74718	175.5156	-34.82988
70.79718	176.5121	-34.94100
70.85050	177.5735	-35.07688
70.90218	178.6016	-35.22200
70.95384	179.6290	-35.39835
71.00550	180.6547	-35.58436
71.05718	181.6798	-35.79596
71.10884	182.7037	-36.03983
71.16050	183.7258	-36.30292
71.21218	184.7479	-36.59964
71.26384	185.7674	-36.92412
71.31718	186.8201	-37.29082
71.36718	187.8041	-37.67427
71.42050	188.8522	-38.13694
71.47050	189.8319	-38.60160
71.52384	190.8750	-39.18219
71.57384	191.8484	-39.77886
71.62718	192.8861	-40.48211
71.67718	193.8553	-41.19474
71.73050	194.8867	-41.99762
71.78050	195.8532	-42.78583
71.83384	196.8806	-43.65228
71.88550	197.8756	-44.52216
71.93718	198.8689	-45.41385
71.98882	199.8610	-46.35070
72.04050	200.8509	-47.35883
72.09216	201.8373	-48.43122
72.14384	202.8204	-49.59722
72.19718	203.8316	-50.88344
72.24718	204.7749	-52.15934
72.30050	205.7789	-53.57410
72.35050	206.7203	-54.89838
72.40384	207.7252	-56.23500
72.45384	208.6754	-57.30712
72.50718	209.7029	-58.06770
72.55718	210.6892	-58.20434
72.61050	211.7770	-57.52582
72.66050	212.8354	-56.05055
72.71384	214.0001	-53.77650
72.76550	215.1516	-51.17022
72.81718	216.3130	-48.43710
72.86884	217.4686	-45.90456
72.92050	218.6097	-43.74292
72.97218	219.7332	-41.94409
73.02384	220.8422	-40.47892
73.07550	221.9356	-39.30286
73.12718	223.0186	-38.35134
73.18050	224.1270	-37.56985
73.23050	225.1588	-36.97332
73.28384	226.2515	-36.46256
73.33384	227.2723	-36.09111
73.38718	228.3566	-35.77120
73.43718	229.3687	-35.54306
73.49050	230.4477	-35.36374
73.54050	231.4559	-35.24330
73.59384	232.5295	-35.14815
73.64384	233.5342	-35.08756
73.69718	234.6065	-35.04964
73.74884	235.6423	-35.03015
73.80050	236.6780	-35.02262
73.85218	237.7141	-35.01464
73.90384	238.7484	-35.01318
73.95550	239.7828	-35.01477
74.00718	240.8171	-35.03845
74.06050	241.8835	-35.08306
74.11050	242.8832	-35.13616
74.16382	243.9498	-35.19128
74.21384	244.9491	-35.24226
74.26716	246.0154	-35.29450
74.31718	247.0139	-35.35246
74.37050	248.0801	-35.40460
74.42050	249.0790	-35.46055
74.47384	250.1439	-35.52000
74.52384	251.1432	-35.58295
74.57718	252.2080	-35.64967
74.62884	253.2394	-35.71872
74.68050	254.2712	-35.78690
74.73218	255.3022	-35.85951
74.78384	256.3342	-35.94293
74.83550	257.3658	-36.03128
74.88718	258.3970	-36.10944
74.93884	259.4290	-36.20346
74.99050	260.4594	-36.29602
75.04384	261.5224	-36.38902
75.09384	262.5205	-36.48950
75.14718	263.5828	-36.60731
75.19718	264.5800	-36.71941
75.25050	265.6436	-36.84742
75.30050	266.6399	-36.97983
75.35384	267.7027	-37.11302
75.40384	268.6976	-37.25154
75.45718	269.7593	-37.41612
75.50718	270.7537	-37.58032
75.56050	271.8130	-37.76846
-2.000000	5.000000	0.0000000