File: 2-C1(0.8mol%)+C20(0.6mol%)/matlab/150-1.txt
CLOSED
Version	1.0
Language	English
Mode	Standard
Run	4
RunSerial	11881
Instrument	DSC Q2000 V24.11 Build 124
Module	DSC Standard Cell RC
Operator	Jing
File	\\Ae520-1454\ta\Data\DSC\UQ Composites\Nan\C1(7.5)+C20P(3)+CL(Hotplate MixtureAB)\150-1
ProcName	Ramp
InstSerial	2000-0883
AutoSerial	1293
Sample	Iso150-1
Size	34.8000	mg
PanMass	Not available
PanResist	Automatic Automatic  K/W
PanFactor	Default Default
Method	Ramp
Comment
Xcomment	Pan: Tzero Aluminum Hermetic
Xcomment	Gas1: Nitrogen 50.0 ml/min
Xcomment	Gas2: Nitrogen 50.0 ml/min
Text
Exotherm	UP
Kcell	1.05230
Cpconst	Standard: 0.938
Calib	-38.6961
TempCal	1	pts	157.46	156.60
TzeroDt	-87.6168 -0.0009 -1.4231
TzeroDtz	-87.6168 0.0057 6.9570
InstCalFile	Tzero: \\Ae520-1454\ta\Data\DSC\Calibration\2017\CALIBRATION\1562_RCS (90)_05_18_2017 10_50_44.TZR
InstCalFile	Baseline: \\Ae520-1454\ta\Data\DSC\Calibration\2017\2017-05-17_Calibration.001
InstCalFile	Sapphire: \\Ae520-1454\ta\Data\DSC\Calibration\2017\2017-05-17_Saphire.001
InstCalDate	Tzero 2017-05-18 Time 10:50:44
TempRange	-87.39 to 398.39 °C at 10.00 °C/min Heat Only
AutoZero	Delta T Offset 0.000 uV
AutoZero	Delta T0 Offset 0.000 uV
MultiptCal	0
MultiPtDesc	0) Not set
AutoCellConst	Calibration Date 2017-05-18 16:59:28
Controls	Gas 1  Event Off  Sampling 0.2
Cell#	RC-01562
CoolingUnit	RCS (90)
SelHeatFlow	Heat Flow T4 (mW)
AutoLidII	Installed
AutoAnalysis	Off
MacroFile
Nsig	3
Sig1	Time (min)
Sig2	Temperature (°C)
Sig3	Heat Flow (mW)
Date	2017-06-22
Time	18:49:36
OrgMethod	1: Equilibrate at 20.00 °C
OrgMethod	2: Ramp 40.00 °C/min to 150.00 °C
OrgMethod	3: Mark end of cycle 1
OrgMethod	4: Isothermal for 40.00 min
OrgMethod	5: Mark end of cycle 2
OrgMethod	6: Ramp 20.00 °C/min to 280.00 °C
OrgMethod	7: Mark end of cycle 3
OrgMethod	8: Ramp 20.00 °C/min to 20.00 °C
OrgMethod	9: Mark end of cycle 4
OrgMethod	10: Ramp 20.00 °C/min to 280.00 °C
OrgMethod	11: Mark end of cycle 5
OrgFile	C:\Users\jarra\Desktop\DSC\2-C1(0.8mol%)+C20(0.6mol%)\150-1
StartOfData
4.99994E-4	20.04057	0.1535572
0.05383332	20.17388	0.4872924
0.1055000	21.07383	0.4217735
0.1571666	22.34674	-2.270799
0.2088333	23.79983	-5.762900
0.2605000	25.38957	-9.405888
0.3121666	27.07286	-12.73513
0.3638334	28.83193	-15.61105
0.4171667	30.70560	-18.06534
0.4671667	32.50559	-19.95686
0.5205000	34.46372	-21.59158
0.5705000	36.32550	-22.83532
0.6238334	38.33575	-23.92020
0.6738334	40.23504	-24.78220
0.7271668	42.27100	-25.63260
0.7771668	44.18299	-26.55210
0.8305000	46.22284	-27.51030
0.8804999	48.15200	-28.10694
0.9338332	50.22748	-28.57887
0.9854999	52.24328	-29.12297
1.037167	54.24418	-30.13514
1.088833	56.21404	-31.72358
1.140500	58.17951	-33.16930
1.192167	60.16738	-34.16760
1.243833	62.17520	-35.02226
1.295500	64.17646	-36.20305
1.347166	66.14672	-38.13676
1.400500	68.11472	-41.71183
1.450500	69.84192	-47.66019
1.503833	71.50898	-57.40890
1.553833	72.90785	-69.32358
1.607167	74.29224	-83.36016
1.657167	75.59814	-95.62454
1.710500	77.08300	-107.2763
1.760500	78.47344	-118.4143
1.813834	79.95932	-130.5724
1.863834	81.45725	-139.1101
1.917167	83.14141	-146.7148
1.968833	85.04601	-145.4343
2.020500	87.53582	-137.6041
2.072166	89.91993	-132.7254
2.123834	92.40419	-123.3463
2.175500	95.20834	-108.9664
2.227167	97.98644	-96.93944
2.280500	100.7249	-86.85465
2.330500	103.1852	-79.21780
2.383833	105.7146	-72.68311
2.433833	108.0154	-67.78070
2.487166	110.4052	-63.60669
2.537166	112.5989	-60.49204
2.590500	114.8969	-57.86608
2.640500	117.0204	-55.92834
2.693833	119.2599	-54.31938
2.743833	121.3388	-53.17859
2.797167	123.5406	-52.25288
2.848834	125.6605	-51.55490
2.900500	127.7720	-50.98306
2.952166	129.8785	-50.52090
3.003833	131.9784	-50.16635
3.055500	134.0745	-49.87854
3.107167	136.1661	-49.67154
3.158834	138.2545	-49.53882
3.210500	140.3392	-49.47104
3.260500	142.3541	-49.45409
3.310500	144.1796	-49.88410
3.363834	145.3220	-48.62560
3.413833	146.0957	-44.15538
3.467166	146.7382	-38.36981
3.518833	147.2417	-32.67955
3.570500	147.6541	-27.51526
3.622166	147.9962	-23.02406
3.673834	148.2800	-19.23246
3.725500	148.5175	-16.07549
3.777167	148.7153	-13.46746
3.828833	148.8816	-11.32204
3.880500	149.0206	-9.554551
3.933833	149.1411	-8.059265
3.983833	149.2367	-6.904038
4.037167	149.3229	-5.890102
4.087167	149.3905	-5.102476
4.140500	149.4529	-4.401967
4.190500	149.5018	-3.861311
4.243834	149.5463	-3.378132
4.293833	149.5820	-2.995953
4.347166	149.6151	-2.657612
4.397167	149.6414	-2.390408
4.450500	149.6647	-2.148508
4.502167	149.6847	-1.948449
4.553834	149.7028	-1.779195
4.605500	149.7172	-1.634773
4.657166	149.7298	-1.508263
4.708834	149.7412	-1.401432
4.760500	149.7514	-1.310926
4.813834	149.7599	-1.224855
4.863834	149.7679	-1.159506
4.917167	149.7752	-1.093293
4.967167	149.7806	-1.037760
5.020500	149.7858	-0.9867821
5.070500	149.7904	-0.9421089
5.123833	149.7955	-0.9008003
5.173834	149.7995	-0.8637180
5.227167	149.8026	-0.8268490
5.277168	149.8064	-0.7940680
5.330500	149.8091	-0.7639222
5.382168	149.8122	-0.7354986
5.433832	149.8149	-0.7071944
5.485500	149.8175	-0.6788921
5.537168	149.8202	-0.6540890
5.588832	149.8214	-0.6281982
5.640500	149.8244	-0.6026022
5.692166	149.8261	-0.5758778
5.743834	149.8279	-0.5499540
5.797168	149.8297	-0.5266242
5.847168	149.8316	-0.5021461
5.900500	149.8336	-0.4769304
5.950500	149.8356	-0.4540334
6.003834	149.8366	-0.4282926
6.053834	149.8385	-0.4032824
6.107168	149.8401	-0.3754460
6.157166	149.8421	-0.3510302
6.210500	149.8436	-0.3268456
6.260500	149.8444	-0.3012173
6.313832	149.8471	-0.2756710
6.365500	149.8481	-0.2492720
6.417168	149.8505	-0.2219055
6.468832	149.8518	-0.1954387
6.520500	149.8531	-0.1681856
6.572168	149.8548	-0.1377990
6.623834	149.8569	-0.1115899
6.677168	149.8579	-.08081308
6.727168	149.8600	-.05366902
6.780500	149.8622	-.02402468
6.830500	149.8640	.004821196
6.883832	149.8654	0.03677383
6.933832	149.8670	0.06826690
6.987168	149.8695	0.1004963
7.037168	149.8708	0.1300288
7.090500	149.8725	0.1637612
7.140500	149.8747	0.1948480
7.193832	149.8770	0.2305944
7.245500	149.8786	0.2635477
7.297168	149.8795	0.2982465
7.348832	149.8819	0.3353778
7.400500	149.8837	0.3696120
7.452168	149.8861	0.4073156
7.503832	149.8882	0.4440578
7.555500	149.8903	0.4825196
7.607168	149.8923	0.5233746
7.660500	149.8944	0.5614805
7.710500	149.8964	0.6008730
7.763834	149.8986	0.6404458
7.813834	149.9006	0.6829480
7.867166	149.9027	0.7246093
7.917168	149.9053	0.7669203
7.970500	149.9076	0.8127266
8.020500	149.9095	0.8573215
8.073834	149.9126	0.9020470
8.123834	149.9151	0.9481739
8.177168	149.9172	0.9948826
8.228834	149.9200	1.042645
8.280500	149.9227	1.089228
8.332168	149.9248	1.140252
8.383832	149.9275	1.190647
8.435499	149.9304	1.241025
8.487168	149.9325	1.293882
8.540500	149.9350	1.347028
8.590500	149.9378	1.399761
8.643832	149.9419	1.457627
8.693832	149.9438	1.511480
8.747168	149.9460	1.570681
8.797168	149.9492	1.625930
8.850500	149.9522	1.684691
8.900500	149.9560	1.741778
8.953834	149.9585	1.805430
9.003834	149.9620	1.861766
9.057168	149.9658	1.927422
9.108832	149.9680	1.988805
9.160499	149.9712	2.052603
9.212168	149.9745	2.118440
9.263832	149.9776	2.184171
9.315500	149.9816	2.250387
9.367166	149.9845	2.319385
9.418832	149.9883	2.387335
9.470500	149.9921	2.454508
9.523834	149.9956	2.526134
9.573834	149.9986	2.594402
9.627168	150.0030	2.668222
9.677168	150.0056	2.738442
9.730500	150.0105	2.815558
9.780500	150.0144	2.888616
9.833832	150.0181	2.967841
9.883832	150.0217	3.041445
9.937166	150.0258	3.121712
9.987168	150.0298	3.195981
10.04050	150.0332	3.278168
10.09217	150.0378	3.355933
10.14383	150.0416	3.439067
10.19550	150.0458	3.521791
10.24717	150.0501	3.604368
10.29883	150.0546	3.695306
10.35050	150.0584	3.790440
10.40383	150.0643	3.894448
10.45383	150.0694	4.004360
10.50717	150.0760	4.144361
10.55717	150.0835	4.295156
10.61050	150.0929	4.489028
10.66050	150.1034	4.716539
10.71383	150.1167	5.002075
10.76383	150.1310	5.319133
10.81716	150.1501	5.702087
10.86716	150.1697	6.097653
10.92050	150.1909	6.550998
10.97217	150.2140	7.015141
11.02383	150.2382	7.484341
11.07550	150.2608	7.945108
11.12717	150.2836	8.398414
11.17883	150.3057	8.826069
11.23050	150.3265	9.230468
11.28217	150.3452	9.604176
11.33383	150.3634	9.953594
11.38717	150.3796	10.27932
11.43716	150.3942	10.55921
11.49050	150.4089	10.83495
11.54050	150.4212	11.07345
11.59383	150.4329	11.31399
11.64383	150.4441	11.51912
11.69717	150.4557	11.72941
11.74717	150.4653	11.91911
11.80050	150.4747	12.11477
11.85050	150.4834	12.29214
11.90383	150.4930	12.47548
11.95550	150.5016	12.64646
12.00717	150.5091	12.81772
12.05884	150.5186	12.98021
12.11050	150.5265	13.13878
12.16217	150.5339	13.29379
12.21383	150.5417	13.44516
12.26717	150.5493	13.59232
12.31716	150.5555	13.72037
12.37050	150.5622	13.84834
12.42050	150.5688	13.95860
12.47383	150.5744	14.06903
12.52383	150.5788	14.15726
12.57717	150.5833	14.23792
12.62717	150.5860	14.30107
12.68050	150.5890	14.35161
12.73050	150.5910	14.38044
12.78383	150.5928	14.40083
12.83550	150.5932	14.41052
12.88717	150.5937	14.41925
12.93883	150.5948	14.42488
12.99050	150.5934	14.42451
13.04216	150.5926	14.40709
13.09383	150.5909	14.36806
13.14550	150.5888	14.32601
13.19717	150.5876	14.28281
13.25050	150.5855	14.23675
13.30050	150.5837	14.20487
13.35383	150.5822	14.16701
13.40383	150.5801	14.13712
13.45717	150.5785	14.10783
13.50717	150.5770	14.07874
13.56050	150.5759	14.05299
13.61050	150.5746	14.03440
13.66383	150.5732	14.02220
13.71383	150.5727	14.01457
13.76717	150.5720	14.00803
13.81884	150.5726	14.00376
13.87050	150.5740	14.00226
13.92217	150.5738	14.00608
13.97383	150.5748	14.02412
14.02550	150.5766	14.05649
14.07717	150.5785	14.10053
14.13050	150.5811	14.15484
14.18050	150.5833	14.21386
14.23383	150.5868	14.28167
14.28383	150.5901	14.35304
14.33717	150.5941	14.44013
14.38717	150.5986	14.52622
14.44050	150.6037	14.63266
14.49050	150.6087	14.73789
14.54384	150.6156	14.86528
14.59383	150.6215	14.99233
14.64717	150.6281	15.14137
14.69884	150.6357	15.30152
14.75050	150.6440	15.46983
14.80217	150.6533	15.65454
14.85383	150.6632	15.85036
14.90550	150.6731	16.06376
14.95717	150.6844	16.28261
15.00883	150.6956	16.50835
15.06050	150.7061	16.73760
15.11383	150.7180	16.96752
15.16383	150.7285	17.16766
15.21716	150.7392	17.36743
15.26717	150.7474	17.52432
15.32050	150.7546	17.65724
15.37050	150.7594	17.73353
15.42383	150.7622	17.77399
15.47383	150.7620	17.77346
15.52717	150.7597	17.71473
15.57717	150.7548	17.58060
15.63050	150.7470	17.39602
15.68217	150.7369	17.17636
15.73383	150.7253	16.91686
15.78550	150.7106	16.62841
15.83717	150.6957	16.31244
15.88883	150.6791	15.97925
15.94050	150.6626	15.63337
15.99383	150.6439	15.27202
16.04383	150.6276	14.92528
16.09717	150.6098	14.55888
16.14716	150.5924	14.21835
16.20050	150.5744	13.86369
16.25050	150.5586	13.53446
16.30383	150.5412	13.19956
16.35383	150.5255	12.89401
16.40716	150.5100	12.57280
16.45716	150.4951	12.28307
16.51050	150.4796	11.98986
16.56216	150.4654	11.70960
16.61383	150.4520	11.44381
16.66550	150.4386	11.18254
16.71716	150.4256	10.93316
16.76883	150.4127	10.68568
16.82050	150.4013	10.44768
16.87216	150.3894	10.21641
16.92383	150.3778	9.987649
16.97716	150.3655	9.757934
17.02716	150.3557	9.548538
17.08050	150.3444	9.327149
17.13050	150.3342	9.117781
17.18383	150.3233	8.894657
17.23383	150.3131	8.688379
17.28717	150.3024	8.470093
17.33716	150.2921	8.265688
17.39050	150.2818	8.047599
17.44050	150.2712	7.842724
17.49383	150.2608	7.618568
17.54550	150.2502	7.407105
17.59716	150.2392	7.192838
17.64883	150.2291	6.972901
17.70050	150.2181	6.757974
17.75216	150.2080	6.540375
17.80383	150.1956	6.323645
17.85716	150.1846	6.094882
17.90716	150.1744	5.876778
17.96050	150.1626	5.650518
18.01050	150.1513	5.430408
18.06383	150.1388	5.201392
18.11383	150.1275	4.980238
18.16716	150.1163	4.747518
18.21716	150.1050	4.534512
18.27050	150.0937	4.301014
18.32050	150.0832	4.084093
18.37383	150.0720	3.855394
18.42550	150.0608	3.636060
18.47716	150.0502	3.422455
18.52883	150.0404	3.207786
18.58050	150.0296	3.002502
18.63216	150.0192	2.795230
18.68383	150.0102	2.598068
18.73550	150.0003	2.406443
18.78717	149.9908	2.218528
18.84050	149.9816	2.031242
18.89050	149.9727	1.860186
18.94383	149.9642	1.691135
18.99383	149.9566	1.534744
19.04716	149.9476	1.375446
19.09716	149.9400	1.234684
19.15050	149.9329	1.094022
19.20050	149.9261	0.9635666
19.25383	149.9187	0.8325608
19.30383	149.9128	0.7197000
19.35716	149.9063	0.6038332
19.40883	149.9014	0.4984498
19.46050	149.8961	0.3982114
19.51216	149.8910	0.3042910
19.56383	149.8869	0.2153298
19.61550	149.8818	0.1319263
19.66716	149.8776	0.05196587
19.72050	149.8739	-.02307890
19.77050	149.8707	-.09184850
19.82383	149.8664	-0.1554923
19.87383	149.8639	-0.2171215
19.92716	149.8607	-0.2721214
19.97716	149.8582	-0.3249371
20.03050	149.8553	-0.3750215
20.08050	149.8533	-0.4218010
20.13383	149.8516	-0.4678870
20.18383	149.8492	-0.5081998
20.23716	149.8484	-0.5501820
20.28883	149.8464	-0.5861700
20.34050	149.8448	-0.6205120
20.39216	149.8434	-0.6515937
20.44383	149.8433	-0.6817702
20.49550	149.8406	-0.7071262
20.54716	149.8401	-0.7302651
20.59883	149.8384	-0.7546190
20.65050	149.8377	-0.7764326
20.70383	149.8363	-0.7981739
20.75383	149.8346	-0.8156468
20.80716	149.8344	-0.8347300
20.85716	149.8336	-0.8508238
20.91050	149.8320	-0.8654931
20.96050	149.8320	-0.8789592
21.01383	149.8306	-0.8938201
21.06383	149.8301	-0.9071182
21.11716	149.8294	-0.9208649
21.16716	149.8279	-0.9341534
21.22050	149.8276	-0.9479142
21.27216	149.8271	-0.9604538
21.32383	149.8261	-0.9703732
21.37550	149.8260	-0.9809124
21.42717	149.8252	-0.9909339
21.47883	149.8239	-1.001123
21.53050	149.8232	-1.011292
21.58383	149.8223	-1.021160
21.63383	149.8216	-1.030154
21.68716	149.8214	-1.039492
21.73716	149.8203	-1.048001
21.79050	149.8204	-1.057046
21.84050	149.8202	-1.065558
21.89383	149.8200	-1.074477
21.94383	149.8187	-1.082989
21.99716	149.8189	-1.091675
22.04716	149.8185	-1.099606
22.10050	149.8178	-1.107826
22.15216	149.8178	-1.115412
22.20383	149.8183	-1.122582
22.25550	149.8178	-1.129618
22.30716	149.8171	-1.136110
22.35883	149.8170	-1.142443
22.41050	149.8161	-1.148879
22.46216	149.8166	-1.154935
22.51383	149.8162	-1.161015
22.56716	149.8156	-1.166724
22.61716	149.8167	-1.171943
22.67050	149.8148	-1.177262
22.72050	149.8148	-1.181858
22.77383	149.8148	-1.186544
22.82383	149.8150	-1.190931
22.87716	149.8154	-1.195605
22.92717	149.8140	-1.199951
22.98050	149.8152	-1.204482
23.03050	149.8155	-1.208840
23.08383	149.8150	-1.213258
23.13550	149.8149	-1.217500
23.18716	149.8152	-1.221710
23.23883	149.8145	-1.225861
23.29050	149.8144	-1.229552
23.34216	149.8142	-1.233334
23.39383	149.8142	-1.236673
23.44716	149.8134	-1.239846
23.49716	149.8142	-1.242686
23.55050	149.8131	-1.245613
23.60050	149.8133	-1.248398
23.65383	149.8139	-1.251422
23.70383	149.8141	-1.254322
23.75716	149.8132	-1.257325
23.80716	149.8132	-1.259796
23.86050	149.8132	-1.262610
23.91050	149.8127	-1.265094
23.96383	149.8133	-1.267747
24.01550	149.8133	-1.270435
24.06716	149.8127	-1.272734
24.11883	149.8129	-1.275058
24.17050	149.8117	-1.277204
24.22216	149.8122	-1.279194
24.27383	149.8110	-1.281053
24.32550	149.8113	-1.282860
24.37716	149.8112	-1.284706
24.43050	149.8112	-1.286484
24.48050	149.8108	-1.288004
24.53383	149.8106	-1.289776
24.58383	149.8112	-1.291775
24.63716	149.8111	-1.293864
24.68716	149.8105	-1.295769
24.74050	149.8106	-1.297742
24.79050	149.8102	-1.299465
24.84383	149.8106	-1.301325
24.89383	149.8104	-1.302891
24.94716	149.8101	-1.304426
24.99883	149.8090	-1.305644
25.05050	149.8092	-1.307066
25.10216	149.8090	-1.308581
25.15383	149.8092	-1.310072
25.20550	149.8090	-1.311400
25.25716	149.8088	-1.312718
25.31050	149.8088	-1.314133
25.36050	149.8091	-1.315382
25.41383	149.8094	-1.317034
25.46383	149.8097	-1.318494
25.51716	149.8094	-1.320484
25.56716	149.8098	-1.322731
25.62050	149.8103	-1.325048
25.67050	149.8101	-1.327209
25.72383	149.8116	-1.329423
25.77383	149.8099	-1.331167
25.82717	149.8106	-1.332794
25.87883	149.8107	-1.334154
25.93050	149.8098	-1.335209
25.98216	149.8098	-1.335789
26.03383	149.8102	-1.336518
26.08550	149.8097	-1.336932
26.13716	149.8091	-1.337209
26.18883	149.8091	-1.337280
26.24050	149.8087	-1.337418
26.29383	149.8092	-1.337701
26.34383	149.8093	-1.338245
26.39716	149.8089	-1.339155
26.44717	149.8092	-1.340038
26.50050	149.8088	-1.341319
26.55050	149.8089	-1.342383
26.60383	149.8086	-1.343836
26.65383	149.8096	-1.345028
26.70716	149.8091	-1.346407
26.75716	149.8102	-1.347510
26.81050	149.8094	-1.348689
26.86216	149.8094	-1.349738
26.91383	149.8098	-1.350852
26.96550	149.8099	-1.352119
27.01716	149.8095	-1.353127
27.06883	149.8094	-1.354114
27.12050	149.8088	-1.355052
27.17383	149.8088	-1.355824
27.22383	149.8082	-1.356389
27.27717	149.8093	-1.356967
27.32717	149.8089	-1.357563
27.38050	149.8089	-1.358141
27.43050	149.8084	-1.358318
27.48383	149.8080	-1.358366
27.53383	149.8084	-1.358226
27.58716	149.8077	-1.358118
27.63716	149.8080	-1.358217
27.69050	149.8074	-1.358439
27.74216	149.8074	-1.358937
27.79383	149.8079	-1.359518
27.84550	149.8082	-1.360521
27.89716	149.8086	-1.361846
27.94883	149.8084	-1.363148
28.00050	149.8088	-1.364539
28.05217	149.8091	-1.365978
28.10383	149.8078	-1.367102
28.15716	149.8095	-1.368118
28.20716	149.8088	-1.369256
28.26050	149.8082	-1.369954
28.31050	149.8084	-1.370234
28.36383	149.8075	-1.370225
28.41383	149.8075	-1.370132
28.46716	149.8070	-1.370267
28.51716	149.8073	-1.370127
28.57050	149.8065	-1.369906
28.62050	149.8072	-1.369971
28.67383	149.8068	-1.370121
28.72550	149.8064	-1.370417
28.77717	149.8061	-1.370789
28.82883	149.8065	-1.371403
28.88050	149.8065	-1.372142
28.93216	149.8069	-1.373117
28.98383	149.8068	-1.374228
29.03717	149.8079	-1.375615
29.08716	149.8075	-1.377174
29.14050	149.8077	-1.378692
29.19050	149.8079	-1.380186
29.24383	149.8084	-1.381646
29.29383	149.8081	-1.382593
29.34716	149.8091	-1.383502
29.39716	149.8079	-1.384049
29.45050	149.8080	-1.384425
29.50050	149.8080	-1.384608
29.55383	149.8077	-1.384860
29.60550	149.8076	-1.384774
29.65716	149.8066	-1.384560
29.70883	149.8070	-1.384138
29.76050	149.8064	-1.383831
29.81217	149.8068	-1.383578
29.86383	149.8061	-1.383199
29.91550	149.8065	-1.383043
29.96716	149.8070	-1.383208
30.02050	149.8058	-1.383441
30.07050	149.8048	-1.383589
30.12383	149.8061	-1.383900
30.17383	149.8066	-1.384415
30.22717	149.8060	-1.385231
30.27717	149.8065	-1.385989
30.33050	149.8062	-1.387198
30.38050	149.8066	-1.388210
30.43383	149.8065	-1.389155
30.48383	149.8075	-1.390055
30.53717	149.8063	-1.390962
30.58883	149.8071	-1.391711
30.64050	149.8079	-1.392556
30.69216	149.8077	-1.393414
30.74383	149.8077	-1.394292
30.79550	149.8080	-1.395010
30.84716	149.8075	-1.395528
30.90050	149.8078	-1.395846
30.95050	149.8075	-1.396119
31.00383	149.8059	-1.395887
31.05383	149.8075	-1.395606
31.10716	149.8067	-1.395218
31.15716	149.8073	-1.394560
31.21050	149.8064	-1.394030
31.26050	149.8060	-1.393777
31.31383	149.8068	-1.393861
31.36383	149.8067	-1.394052
31.41716	149.8069	-1.394556
31.46883	149.8068	-1.395022
31.52050	149.8064	-1.395623
31.57217	149.8070	-1.396341
31.62383	149.8071	-1.397212
31.67550	149.8072	-1.398112
31.72717	149.8080	-1.398848
31.77883	149.8079	-1.399572
31.83050	149.8084	-1.400349
31.88383	149.8080	-1.400815
31.93384	149.8079	-1.401325
31.98717	149.8079	-1.401362
32.03717	149.8071	-1.401303
32.09050	149.8077	-1.401042
32.14050	149.8065	-1.400787
32.19383	149.8068	-1.400194
32.24383	149.8066	-1.399565
32.29716	149.8070	-1.399072
32.34716	149.8066	-1.398841
32.40050	149.8064	-1.398754
32.45216	149.8066	-1.399086
32.50383	149.8066	-1.399543
32.55550	149.8066	-1.400028
32.60716	149.8062	-1.400662
32.65883	149.8064	-1.401080
32.71050	149.8064	-1.401587
32.76383	149.8072	-1.402267
32.81383	149.8069	-1.402834
32.86716	149.8071	-1.403446
32.91716	149.8069	-1.404320
32.97050	149.8072	-1.405146
33.02050	149.8070	-1.405712
33.07383	149.8069	-1.406316
33.12383	149.8073	-1.406648
33.17717	149.8068	-1.407097
33.22717	149.8076	-1.407397
33.28050	149.8078	-1.407984
33.33216	149.8072	-1.408280
33.38383	149.8079	-1.408486
33.43550	149.8070	-1.408644
33.48717	149.8071	-1.408769
33.53883	149.8069	-1.408794
33.59050	149.8063	-1.408669
33.64216	149.8068	-1.408277
33.69383	149.8054	-1.407869
33.74716	149.8066	-1.407372
33.79716	149.8070	-1.407130
33.85050	149.8054	-1.406325
33.90050	149.8060	-1.406144
33.95383	149.8051	-1.406016
34.00383	149.8062	-1.405965
34.05716	149.8061	-1.406476
34.10716	149.8058	-1.406984
34.16050	149.8057	-1.407647
34.21050	149.8062	-1.408089
34.26383	149.8048	-1.408362
34.31550	149.8053	-1.408294
34.36716	149.8058	-1.408475
34.41883	149.8051	-1.408349
34.47050	149.8053	-1.408427
34.52217	149.8051	-1.408642
34.57383	149.8052	-1.409079
34.62717	149.8058	-1.409888
34.67717	149.8063	-1.410399
34.73050	149.8056	-1.411170
34.78050	149.8060	-1.412197
34.83383	149.8060	-1.412833
34.88383	149.8059	-1.413135
34.93716	149.8061	-1.413276
34.98717	149.8063	-1.413355
35.04050	149.8062	-1.413572
35.09050	149.8069	-1.413914
35.14383	149.8066	-1.414251
35.19550	149.8066	-1.414542
35.24716	149.8070	-1.414954
35.29883	149.8061	-1.415274
35.35050	149.8074	-1.415399
35.40216	149.8072	-1.415598
35.45383	149.8069	-1.415621
35.50550	149.8069	-1.415557
35.55716	149.8063	-1.415637
35.61050	149.8074	-1.415649
35.66050	149.8066	-1.415585
35.71383	149.8069	-1.415504
35.76383	149.8063	-1.415447
35.81716	149.8061	-1.415164
35.86716	149.8066	-1.414965
35.92050	149.8061	-1.414800
35.97050	149.8054	-1.414798
36.02383	149.8060	-1.414507
36.07383	149.8054	-1.414131
36.12717	149.8055	-1.413618
36.17883	149.8053	-1.413355
36.23050	149.8058	-1.413242
36.28216	149.8058	-1.413402
36.33383	149.8052	-1.413835
36.38550	149.8062	-1.414588
36.43716	149.8058	-1.415302
36.49050	149.8056	-1.415915
36.54050	149.8066	-1.416628
36.59384	149.8060	-1.417347
36.64383	149.8056	-1.417904
36.69717	149.8065	-1.418504
36.74716	149.8065	-1.418904
36.80050	149.8072	-1.419429
36.85050	149.8071	-1.420049
36.90383	149.8073	-1.420469
36.95383	149.8068	-1.420808
37.00716	149.8075	-1.420982
37.05883	149.8064	-1.420884
37.11050	149.8072	-1.420783
37.16217	149.8058	-1.420337
37.21383	149.8057	-1.419810
37.26550	149.8060	-1.419314
37.31716	149.8065	-1.418663
37.36883	149.8056	-1.418027
37.42050	149.8054	-1.417604
37.47383	149.8061	-1.417313
37.52383	149.8051	-1.417306
37.57717	149.8055	-1.417612
37.62717	149.8058	-1.418147
37.68050	149.8056	-1.418666
37.73050	149.8056	-1.419251
37.78383	149.8067	-1.419964
37.83383	149.8064	-1.420768
37.88716	149.8065	-1.421176
37.93716	149.8069	-1.421497
37.99050	149.8066	-1.421660
38.04217	149.8069	-1.422026
38.09384	149.8062	-1.422412
38.14550	149.8072	-1.422773
38.19717	149.8064	-1.423126
38.24883	149.8068	-1.423203
38.30050	149.8069	-1.423472
38.35383	149.8064	-1.423358
38.40383	149.8056	-1.422898
38.45716	149.8055	-1.422134
38.50716	149.8048	-1.421184
38.56050	149.8054	-1.420128
38.61050	149.8046	-1.419503
38.66383	149.8056	-1.419123
38.71383	149.8062	-1.419229
38.76716	149.8051	-1.419413
38.81716	149.8052	-1.419700
38.87050	149.8055	-1.420422
38.92216	149.8060	-1.421189
38.97383	149.8058	-1.421767
39.02550	149.8062	-1.422074
39.07717	149.8062	-1.422782
39.12883	149.8061	-1.423167
39.18050	149.8059	-1.423592
39.23216	149.8060	-1.424305
39.28383	149.8065	-1.424926
39.33716	149.8060	-1.425240
39.38716	149.8068	-1.425451
39.44050	149.8054	-1.425117
39.49050	149.8060	-1.424921
39.54383	149.8049	-1.424466
39.59384	149.8050	-1.423807
39.64717	149.8052	-1.423376
39.69717	149.8050	-1.423179
39.75050	149.8054	-1.423272
39.80050	149.8054	-1.423578
39.85383	149.8053	-1.423926
39.90550	149.8057	-1.424321
39.95716	149.8061	-1.424509
40.00883	149.8066	-1.425122
40.06050	149.8056	-1.425834
40.11217	149.8059	-1.426327
40.16383	149.8058	-1.426707
40.21716	149.8064	-1.426936
40.26716	149.8060	-1.427056
40.32050	149.8055	-1.427152
40.37050	149.8058	-1.427064
40.42383	149.8058	-1.427007
40.47383	149.8061	-1.426991
40.52716	149.8059	-1.426836
40.57717	149.8063	-1.426725
40.63050	149.8062	-1.426822
40.68050	149.8061	-1.427142
40.73383	149.8064	-1.427397
40.78550	149.8064	-1.427668
40.83716	149.8061	-1.428086
40.88883	149.8067	-1.428370
40.94050	149.8060	-1.428530
40.99216	149.8060	-1.428390
41.04383	149.8051	-1.428007
41.09550	149.8056	-1.427520
41.14717	149.8048	-1.427114
41.20050	149.8057	-1.426916
41.25050	149.8047	-1.426878
41.30383	149.8058	-1.426831
41.35383	149.8052	-1.427055
41.40717	149.8059	-1.427411
41.45717	149.8060	-1.427696
41.51050	149.8062	-1.428250
41.56050	149.8059	-1.428850
41.61383	149.8062	-1.429425
41.66383	149.8064	-1.430066
41.71717	149.8064	-1.430578
41.76883	149.8063	-1.430960
41.82050	149.8065	-1.431096
41.87216	149.8058	-1.430737
41.92383	149.8061	-1.430312
41.97550	149.8058	-1.429832
42.02716	149.8062	-1.429262
42.08050	149.8056	-1.428661
42.13050	149.8055	-1.428318
42.18383	149.8055	-1.428053
42.23383	149.8056	-1.428048
42.28717	149.8052	-1.427841
42.33716	149.8056	-1.427650
42.39050	149.8060	-1.427988
42.44050	149.8053	-1.428299
42.49383	149.8051	-1.428684
42.54383	149.8050	-1.429092
42.59716	149.8067	-1.429465
42.64883	149.8054	-1.429784
42.70050	149.8054	-1.430038
42.75217	149.8052	-1.430085
42.80383	149.8058	-1.430247
42.85550	149.8058	-1.430308
42.90717	149.8046	-1.430294
42.95883	149.8056	-1.430355
43.01050	149.8056	-1.430516
43.06383	149.8065	-1.430989
43.11383	149.8064	-1.431594
43.16716	149.8065	-1.431807
43.21717	149.8064	-1.431964
43.26717	149.8070	-1.432483
43.32050	149.9762	-1.285649
43.37050	150.4766	-2.500576
43.42383	151.1434	-5.210094
43.47383	151.8503	-8.103355
43.52716	152.6663	-11.09418
43.57717	153.4738	-13.58495
43.63050	154.3726	-15.85866
43.68050	155.2439	-17.63454
43.73383	156.1968	-19.20992
43.78550	157.1394	-20.45825
43.83716	158.0962	-21.49955
43.88883	159.0654	-22.35528
43.94050	160.0451	-23.07083
43.99216	161.0316	-23.67927
44.04383	162.0266	-24.20548
44.09716	163.0577	-24.67415
44.14717	164.0291	-25.06208
44.20050	165.0691	-25.44284
44.25050	166.0477	-25.75779
44.30383	167.0920	-26.07222
44.35383	168.0748	-26.34941
44.40717	169.1253	-26.62383
44.45717	170.1102	-26.86848
44.51050	171.1612	-27.12329
44.56050	172.1489	-27.35330
44.61383	173.2012	-27.59956
44.66550	174.2224	-27.83725
44.71717	175.2440	-28.07010
44.76883	176.2650	-28.30300
44.82050	177.2867	-28.53628
44.87216	178.3082	-28.77566
44.92383	179.3292	-29.02544
44.97550	180.3501	-29.27667
45.02716	181.3715	-29.54748
45.08050	182.4249	-29.83601
45.13050	183.4128	-30.10908
45.18383	184.4665	-30.42201
45.23383	185.4540	-30.71898
45.28717	186.5059	-31.04237
45.33716	187.4924	-31.36069
45.39050	188.5440	-31.71642
45.44050	189.5297	-32.05843
45.49383	190.5798	-32.44917
45.54383	191.5642	-32.82510
45.59716	192.6134	-33.24574
45.64883	193.6287	-33.66790
45.70050	194.6434	-34.10786
45.75217	195.6566	-34.56225
45.80383	196.6696	-35.04254
45.85550	197.6813	-35.55506
45.90717	198.6923	-36.08645
45.96050	199.7349	-36.66894
46.01050	200.7107	-37.24332
46.06383	201.7498	-37.88739
46.11383	202.7223	-38.53212
46.16716	203.7581	-39.25019
46.21717	204.7288	-39.97600
46.27050	205.7614	-40.80642
46.32050	206.7252	-41.65400
46.37383	207.7461	-42.74133
46.42383	208.7011	-43.79153
46.47717	209.7146	-44.99971
46.52883	210.6927	-46.32362
46.58050	211.6600	-47.86678
46.63217	212.6148	-49.73786
46.68383	213.5518	-52.06066
46.73550	214.4660	-54.88850
46.78717	215.3550	-58.28278
46.83883	216.2177	-62.22472
46.89050	217.0590	-66.62438
46.94383	217.9112	-71.44187
46.99383	218.7098	-75.85684
47.04716	219.5821	-79.94972
47.09716	220.4273	-83.17545
47.15050	221.3676	-85.65189
47.20050	222.3126	-86.33366
47.25383	223.4136	-85.00191
47.30383	224.5159	-82.39084
47.35717	225.7485	-78.42974
47.40717	226.9497	-73.73516
47.46050	228.2856	-67.49238
47.51216	229.6207	-60.83255
47.56383	230.9358	-55.01104
47.61550	232.2034	-50.30028
47.66716	233.4247	-46.56416
47.71884	234.6067	-43.60873
47.77050	235.7570	-41.28484
47.82383	236.9190	-39.39734
47.87383	237.9893	-38.01404
47.92717	239.1166	-36.85176
47.97717	240.1600	-36.00375
48.03050	241.2639	-35.29456
48.08050	242.2920	-34.78486
48.13383	243.3824	-34.35418
48.18383	244.3993	-34.04060
48.23717	245.4805	-33.78134
48.28717	246.4933	-33.59809
48.34050	247.5678	-33.44336
48.39217	248.6088	-33.33162
48.44383	249.6488	-33.24860
48.49550	250.6862	-33.19158
48.54716	251.7232	-33.15936
48.59883	252.7584	-33.13928
48.65050	253.7945	-33.13347
48.70216	254.8291	-33.13019
48.75383	255.8632	-33.12982
48.80717	256.9324	-33.14520
48.85717	257.9334	-33.17340
48.91050	259.0011	-33.20608
48.96050	260.0011	-33.24625
49.01383	261.0686	-33.29338
49.06383	262.0674	-33.33460
49.11716	263.1346	-33.39583
49.16716	264.1341	-33.44000
49.22050	265.1995	-33.49854
49.27050	266.2001	-33.55273
49.32383	267.2666	-33.60678
49.37550	268.2972	-33.66479
49.42717	269.3297	-33.73041
49.47883	270.3613	-33.79516
49.53050	271.3934	-33.85474
49.58217	272.4257	-33.90900
49.63383	273.4578	-33.99893
49.68716	274.5226	-34.07705
49.73717	275.5205	-34.16245
49.78717	276.4872	-34.21044
49.84050	276.8734	-33.19109
49.89050	276.7415	-27.86442
49.94383	276.3718	-20.57266
49.99383	275.8820	-13.69258
50.04716	275.2506	-7.130194
50.09716	274.5790	-1.907581
50.15050	273.7969	2.688000
50.20050	273.0144	6.199682
50.25383	272.1387	9.249360
50.30550	271.2578	11.66151
50.35717	270.3518	13.62197
50.40883	269.4232	15.22502
50.46050	268.4792	16.54319
50.51216	267.5198	17.63293
50.56383	266.5502	18.53111
50.61550	265.5693	19.27161
50.66716	264.5813	19.89862
50.72050	263.5547	20.43991
50.77050	262.5875	20.86518
50.82383	261.5504	21.25024
50.87383	260.5754	21.56813
50.92717	259.5320	21.84703
50.97717	258.5504	22.06918
51.03050	257.5026	22.28048
51.08050	256.5177	22.44635
51.13383	255.4658	22.59908
51.18383	254.4776	22.72884
51.23717	253.4236	22.85515
51.28883	252.4016	22.95680
51.34050	251.3792	23.04850
51.39216	250.3547	23.13302
51.44384	249.3314	23.20500
51.49550	248.3072	23.28306
51.54717	247.2828	23.35140
51.60050	246.2248	23.41305
51.65050	245.2311	23.46710
51.70383	244.1721	23.51825
51.75383	243.1784	23.55390
51.80717	242.1190	23.59020
51.85717	241.1250	23.61365
51.91050	240.0646	23.64723
51.96050	239.0704	23.67546
52.01383	238.0106	23.70573
52.06383	237.0161	23.72827
52.11716	235.9556	23.76024
52.16883	234.9278	23.78032
52.22050	233.8999	23.79836
52.27217	232.8714	23.81464
52.32383	231.8426	23.82456
52.37550	230.8144	23.83265
52.42717	229.7856	23.84260
52.47883	228.7576	23.85167
52.53050	227.7298	23.86775
52.58383	226.6680	23.89381
52.63383	225.6732	23.90795
52.68716	224.6130	23.93486
52.73717	223.6173	23.95286
52.79050	222.5552	23.96949
52.84050	221.5596	23.98314
52.89384	220.4980	23.99996
52.94384	219.5026	24.01361
52.99717	218.4387	24.02998
53.04717	217.4426	24.03967
53.10050	216.3798	24.04726
53.15217	215.3511	24.05418
53.20383	214.3221	24.06045
53.25550	213.2935	24.06644
53.30717	212.2647	24.07262
53.35883	211.2354	24.07956
53.41050	210.2062	24.08642
53.46382	209.1442	24.09337
53.51382	208.1474	24.09958
53.56716	207.0862	24.10498
53.61716	206.0898	24.10966
53.67050	205.0278	24.11423
53.72050	204.0322	24.11847
53.77383	202.9689	24.12316
53.82383	201.9750	24.12695
53.87717	200.9122	24.13039
53.92717	199.9158	24.13446
53.98050	198.8534	24.13911
54.03217	197.8242	24.14374
54.08383	196.7944	24.14810
54.13550	195.7648	24.15195
54.18716	194.7366	24.15580
54.23882	193.7060	24.16063
54.29050	192.6768	24.16520
54.34217	191.6470	24.16880
54.39384	190.6169	24.17196
54.44717	189.5543	24.17388
54.49717	188.5574	24.17550
54.55050	187.4942	24.17611
54.60050	186.4987	24.17605
54.65383	185.4358	24.17641
54.70383	184.4395	24.17676
54.75717	183.3768	24.17636
54.80717	182.3803	24.17645
54.86050	181.3180	24.17679
54.91050	180.3213	24.17705
54.96382	179.2588	24.17832
55.01550	178.2292	24.18070
55.06716	177.1993	24.18504
55.11882	176.1699	24.19232
55.17050	175.1409	24.20772
55.22217	174.1112	24.24056
55.27383	173.0831	24.27714
55.32717	172.0211	24.32127
55.37717	171.0255	24.37949
55.43050	169.9650	24.45345
55.48050	168.9735	24.54883
55.53383	167.9149	24.68838
55.58383	166.9265	24.84731
55.63716	165.8739	25.07935
55.68716	164.8908	25.39260
55.74050	163.8481	25.87515
55.79050	162.8825	26.58717
55.84384	161.8706	27.78514
55.89550	160.9182	29.58318
55.94717	160.0026	32.18488
55.99883	159.1278	35.61171
56.05050	158.2903	39.68131
56.10217	157.4715	44.03750
56.15383	156.6556	48.27328
56.20550	155.8218	52.00382
56.25717	154.9546	54.95082
56.31050	154.0127	56.99094
56.36050	153.0811	57.89030
56.41382	152.0336	57.79550
56.46382	151.0062	56.78974
56.51716	149.8654	54.89211
56.56716	148.7604	52.51182
56.62050	147.5595	49.56716
56.67050	146.4208	46.65020
56.72382	145.2048	43.62524
56.77383	144.0748	40.99792
56.82717	142.8819	38.50388
56.87883	141.7416	36.41692
56.93050	140.6170	34.63556
56.98217	139.5065	33.12182
57.03383	138.4077	31.83623
57.08550	137.3193	30.74965
57.13716	136.2411	29.82582
57.19050	135.1345	28.99503
57.24050	134.1024	28.32194
57.29382	133.0056	27.69631
57.34384	131.9829	27.22620
57.39717	130.8970	26.78716
57.44717	129.8813	26.44121
57.50050	128.8014	26.12898
57.55050	127.7909	25.86922
57.60383	126.7129	25.57097
57.65383	125.7054	25.38577
57.70717	124.6318	25.19581
57.75883	123.5927	25.02596
57.81050	122.5543	24.86673
57.86217	121.5175	24.71418
57.91382	120.4809	24.57948
57.96550	119.4444	24.45110
58.01716	118.4078	24.34084
58.06884	117.3714	24.23356
58.12050	116.3360	24.12988
58.17383	115.2670	24.02182
58.22382	114.2663	23.93078
58.27717	113.1966	23.83141
58.32717	112.1959	23.74410
58.38050	111.1286	23.65392
58.43050	110.1273	23.56898
58.48383	109.0590	23.48440
58.53383	108.0576	23.40732
58.58716	106.9908	23.32369
58.63716	105.9895	23.24675
58.69050	104.9216	23.16578
58.74216	103.8872	23.09297
58.79382	102.8532	23.02240
58.84550	101.8197	22.94932
58.89717	100.7855	22.87419
58.94883	99.75141	22.80796
59.00050	98.71780	22.74460
59.05383	97.65124	22.67705
59.10383	96.65069	22.62300
59.15717	95.58418	22.55520
59.20717	94.58422	22.49134
59.26050	93.51804	22.43161
59.31050	92.51889	22.40972
59.36382	91.45216	22.34160
59.41382	90.45249	22.27390
59.46717	89.38534	22.19470
59.51716	88.38556	22.12885
59.57050	87.31741	22.05761
59.62217	86.28447	21.98463
59.67383	85.25126	21.91610
59.72550	84.21782	21.84506
59.77717	83.18449	21.78338
59.82883	82.15235	21.72455
59.88050	81.11978	21.66374
59.93217	80.08612	21.60420
59.98383	79.05350	21.54590
60.03716	77.98730	21.48809
60.08716	76.98691	21.43118
60.14050	75.92092	21.37395
60.19050	74.92049	21.32006
60.24382	73.85488	21.25969
60.29382	72.85359	21.20380
60.34716	71.78789	21.14111
60.39717	70.78702	21.08844
60.45050	69.72021	21.02963
60.50050	68.71924	20.96839
60.55383	67.65265	20.89946
60.60550	66.61914	20.83129
60.65717	65.58552	20.76788
60.70883	64.55188	20.71084
60.76050	63.51840	20.64491
60.81216	62.48589	20.57501
60.86382	61.45139	20.50628
60.91716	60.38458	20.43549
60.96717	59.38382	20.37044
61.02050	58.31521	20.29870
61.07050	57.31445	20.22728
61.12383	56.24830	20.15577
61.17383	55.24722	20.08866
61.22717	54.17936	20.01893
61.27717	53.17781	19.94874
61.33050	52.11023	19.87944
61.38050	51.10902	19.81006
61.43383	50.04154	19.73111
61.48550	49.00592	19.65978
61.53716	47.97191	19.58562
61.58882	46.93754	19.50988
61.64050	45.90254	19.43790
61.69216	44.86863	19.36886
61.74382	43.83480	19.30019
61.79550	42.80119	19.22642
61.84716	41.76593	19.15472
61.90050	40.69756	19.06576
61.95050	39.69530	18.98502
62.00383	38.62639	18.89391
62.05383	37.62470	18.80726
62.10717	36.55582	18.70909
62.15717	35.55410	18.59909
62.21050	34.48448	18.51147
62.26050	33.48112	18.42053
62.31382	32.41121	18.32442
62.36382	31.40814	18.22446
62.41716	30.33795	18.12262
62.46884	29.30112	18.02798
62.52050	28.26567	17.92326
62.57217	27.22847	17.81486
62.62383	26.19276	17.71050
62.67550	25.15583	17.59976
62.72717	24.11786	17.49532
62.77550	23.15671	17.38402
62.82717	22.57772	17.31348
62.88050	22.62701	14.68668
62.93050	22.89746	10.91555
62.98383	23.37539	6.548938
63.03383	23.93990	2.693506
63.08716	24.63890	-0.9071954
63.13716	25.36592	-3.753103
63.19050	26.19943	-6.254371
63.24050	27.02418	-8.162729
63.29382	27.93845	-9.810856
63.34384	28.82231	-11.06024
63.39717	29.78724	-12.13937
63.44883	30.73846	-12.98513
63.50050	31.70212	-13.68282
63.55217	32.67782	-14.26616
63.60383	33.66246	-14.75862
63.65550	34.65381	-15.17131
63.70717	35.65233	-15.52163
63.75883	36.65468	-15.81569
63.81050	37.66118	-16.07767
63.86384	38.70368	-16.30968
63.91382	39.68370	-16.50262
63.96717	40.73212	-16.69066
64.01716	41.71637	-16.85296
64.07050	42.76750	-17.01333
64.12050	43.75463	-17.15105
64.17383	44.80926	-17.28882
64.22384	45.79913	-17.41225
64.27717	46.85444	-17.53846
64.32718	47.84484	-17.65158
64.38050	48.90418	-17.77819
64.43218	49.92882	-17.89125
64.48383	50.95338	-17.99826
64.53550	51.98156	-18.10456
64.58716	53.00836	-18.21346
64.63884	54.03570	-18.31820
64.69050	55.06360	-18.41532
64.74384	56.12449	-18.51518
64.79384	57.11987	-18.61140
64.84717	58.18242	-18.71090
64.89717	59.17735	-18.80181
64.95050	60.24139	-18.89481
65.00050	61.23597	-18.98543
65.05383	62.29920	-19.08375
65.10383	63.29482	-19.17456
65.15718	64.35822	-19.27066
65.20717	65.35495	-19.35461
65.26050	66.41866	-19.44466
65.31216	67.44760	-19.53449
65.36384	68.47772	-19.62202
65.41550	69.50786	-19.71215
65.46717	70.53809	-19.79636
65.51882	71.56899	-19.88306
65.57050	72.59837	-19.97272
65.62218	73.62947	-20.05800
65.67384	74.66057	-20.14166
65.72718	75.72276	-20.22789
65.77718	76.72020	-20.31329
65.83050	77.78510	-20.40691
65.88050	78.78198	-20.49061
65.93384	79.84642	-20.58168
65.98384	80.84429	-20.66339
66.03718	81.90787	-20.75719
66.08716	82.90485	-20.83880
66.14050	83.96894	-20.93027
66.19050	84.96594	-21.02234
66.24384	86.02859	-21.11767
66.29550	87.05863	-21.21435
66.34718	88.08936	-21.30980
66.39884	89.11991	-21.40664
66.45050	90.15044	-21.50654
66.50218	91.18170	-21.60495
66.55384	92.21196	-21.69910
66.60718	93.27491	-21.79420
66.65718	94.27161	-21.88210
66.71050	95.33472	-21.98524
66.76050	96.33168	-22.07824
66.81384	97.39516	-22.17530
66.86384	98.39306	-22.26592
66.91718	99.45645	-22.37183
66.96718	100.4544	-22.47034
67.02050	101.5167	-22.57256
67.07050	102.5138	-22.67345
67.12384	103.5770	-22.78926
67.17550	104.6064	-22.91058
67.22718	105.6346	-23.05002
67.27884	106.6614	-23.21938
67.33050	107.6879	-23.34627
67.38218	108.7196	-23.40979
67.43384	109.7516	-23.48388
67.48550	110.7826	-23.56925
67.53718	111.8131	-23.65026
67.59050	112.8777	-23.74476
67.64050	113.8747	-23.83116
67.69384	114.9392	-23.92574
67.74384	115.9367	-24.01445
67.79718	116.9993	-24.10853
67.84718	117.9959	-24.20073
67.90050	119.0595	-24.30538
67.95050	120.0553	-24.40604
68.00384	121.1198	-24.51499
68.05384	122.1168	-24.62434
68.10718	123.1801	-24.73858
68.15884	124.2097	-24.84910
68.21050	125.2394	-24.96312
68.26218	126.2690	-25.07280
68.31384	127.2993	-25.18144
68.36550	128.3290	-25.29289
68.41718	129.3576	-25.40083
68.47050	130.4206	-25.51694
68.52050	131.4166	-25.63801
68.57384	132.4794	-25.75969
68.62384	133.4754	-25.87528
68.67718	134.5372	-26.00553
68.72718	135.5330	-26.12891
68.78050	136.5956	-26.26760
68.83050	137.5915	-26.39782
68.88384	138.6537	-26.53042
68.93384	139.6494	-26.66488
68.98718	140.7118	-26.80485
69.03882	141.7401	-26.94062
69.09050	142.7684	-27.08092
69.14216	143.7971	-27.22074
69.19384	144.8246	-27.35974
69.24550	145.8529	-27.50432
69.29718	146.8814	-27.65357
69.34882	147.9093	-27.80318
69.40050	148.9374	-27.95112
69.45384	149.9981	-28.10559
69.50384	150.9923	-28.24993
69.55718	152.0532	-28.40698
69.60718	153.0480	-28.55832
69.66050	154.1081	-28.72699
69.71050	155.1030	-28.88150
69.76384	156.1634	-29.04795
69.81384	157.1584	-29.20314
69.86718	158.2187	-29.36767
69.91718	159.2135	-29.51644
69.97050	160.2753	-29.66910
70.02218	161.3038	-29.80635
70.07384	162.3339	-29.93118
70.12550	163.3642	-30.03240
70.17718	164.3960	-30.12122
70.22884	165.4266	-30.19678
70.28050	166.4588	-30.26060
70.33384	167.5245	-30.32110
70.38384	168.5244	-30.37545
70.43718	169.5911	-30.43328
70.48718	170.5900	-30.49316
70.54050	171.6556	-30.57336
70.59050	172.6542	-30.66022
70.64384	173.7187	-30.75638
70.69384	174.7156	-30.85982
70.74718	175.7795	-30.97953
70.79718	176.7759	-31.11346
70.85050	177.8375	-31.26720
70.90218	178.8645	-31.42986
70.95384	179.8911	-31.61122
71.00550	180.9163	-31.81333
71.05718	181.9401	-32.04583
71.10884	182.9635	-32.30469
71.16050	183.9858	-32.59288
71.21218	185.0065	-32.91561
71.26384	186.0256	-33.26756
71.31718	187.0764	-33.66867
71.36718	188.0591	-34.09296
71.42050	189.1044	-34.60252
71.47050	190.0832	-35.12588
71.52384	191.1225	-35.74685
71.57384	192.0946	-36.37330
71.62718	193.1313	-37.08125
71.67718	194.0994	-37.79024
71.73050	195.1335	-38.56150
71.78050	196.1013	-39.31325
71.83384	197.1320	-40.15210
71.88550	198.1286	-41.01358
71.93718	199.1216	-41.93045
71.98882	200.1113	-42.92040
72.04050	201.0980	-44.00632
72.09216	202.0801	-45.18701
72.14384	203.0590	-46.44618
72.19718	204.0662	-47.80545
72.24718	205.0084	-49.09420
72.30050	206.0138	-50.46304
72.35050	206.9604	-51.63126
72.40384	207.9801	-52.60770
72.45384	208.9526	-53.05992
72.50718	210.0244	-52.73937
72.55718	211.0688	-51.51550
72.61050	212.2274	-49.30837
72.66050	213.3432	-46.70308
72.71384	214.5479	-43.73694
72.76550	215.7112	-41.08716
72.81718	216.8561	-38.86460
72.86884	217.9807	-37.08834
72.92050	219.0872	-35.67784
72.97218	220.1773	-34.56132
73.02384	221.2566	-33.70265
73.07550	222.3267	-33.02949
73.12718	223.3884	-32.50928
73.18050	224.4780	-32.09742
73.23050	225.4948	-31.79440
73.28384	226.5748	-31.55260
73.33384	227.5852	-31.38734
73.38718	228.6602	-31.25474
73.43718	229.6663	-31.18098
73.49050	230.7380	-31.12984
73.54050	231.7414	-31.10612
73.59384	232.8098	-31.09506
73.64384	233.8130	-31.09473
73.69718	234.8820	-31.09778
73.74884	235.9160	-31.11264
73.80050	236.9505	-31.13419
73.85218	237.9838	-31.16320
73.90384	239.0176	-31.20675
73.95550	240.0516	-31.24822
74.00718	241.0849	-31.29855
74.06050	242.1510	-31.35613
74.11050	243.1518	-31.40695
74.16382	244.2175	-31.46384
74.21384	245.2168	-31.50801
74.26716	246.2828	-31.56326
74.31718	247.2815	-31.61876
74.37050	248.3476	-31.66930
74.42050	249.3466	-31.71796
74.47384	250.4132	-31.77454
74.52384	251.4126	-31.83338
74.57718	252.4784	-31.88982
74.62884	253.5102	-31.94812
74.68050	254.5430	-32.00226
74.73218	255.5754	-32.06116
74.78384	256.6082	-32.13473
74.83550	257.6393	-32.20445
74.88718	258.6719	-32.27266
74.93884	259.7044	-32.34467
74.99050	260.7368	-32.41960
75.04384	261.8008	-32.49114
75.09384	262.8008	-32.57044
75.14718	263.8658	-32.64580
75.19718	264.8644	-32.72812
75.25050	265.9287	-32.81334
75.30050	266.9252	-32.90644
75.35384	267.9890	-33.00461
75.40384	268.9849	-33.10708
75.45718	270.0482	-33.23000
75.50718	271.0448	-33.34951
75.56050	272.1069	-33.48096
-2.000000	5.000000	0.0000000