File: 2-C1(0.8mol%)+C20(0.6mol%)/matlab/160-2.txt
CLOSED
Version	1.0
Language	English
Mode	Standard
Run	8
RunSerial	11885
Instrument	DSC Q2000 V24.11 Build 124
Module	DSC Standard Cell RC
Operator	Jing
File	\\Ae520-1454\ta\Data\DSC\UQ Composites\Nan\C1(7.5)+C20P(3)+CL(Hotplate MixtureAB)\160-2
ProcName	Ramp
InstSerial	2000-0883
AutoSerial	1293
Sample	Iso160-2
Size	25.7000	mg
PanMass	Not available
PanResist	Automatic Automatic  K/W
PanFactor	Default Default
Method	Ramp
Comment
Xcomment	Pan: Tzero Aluminum Hermetic
Xcomment	Gas1: Nitrogen 50.0 ml/min
Xcomment	Gas2: Nitrogen 50.0 ml/min
Text
Exotherm	UP
Kcell	1.05230
Cpconst	Standard: 0.938
Calib	-38.6961
TempCal	1	pts	157.46	156.60
TzeroDt	-87.6168 -0.0009 -1.4231
TzeroDtz	-87.6168 0.0057 6.9570
InstCalFile	Tzero: \\Ae520-1454\ta\Data\DSC\Calibration\2017\CALIBRATION\1562_RCS (90)_05_18_2017 10_50_44.TZR
InstCalFile	Baseline: \\Ae520-1454\ta\Data\DSC\Calibration\2017\2017-05-17_Calibration.001
InstCalFile	Sapphire: \\Ae520-1454\ta\Data\DSC\Calibration\2017\2017-05-17_Saphire.001
InstCalDate	Tzero 2017-05-18 Time 10:50:44
TempRange	-87.39 to 398.39 °C at 10.00 °C/min Heat Only
AutoZero	Delta T Offset 0.000 uV
AutoZero	Delta T0 Offset 0.000 uV
MultiptCal	0
MultiPtDesc	0) Not set
AutoCellConst	Calibration Date 2017-05-18 16:59:28
Controls	Gas 1  Event Off  Sampling 0.2
Cell#	RC-01562
CoolingUnit	RCS (90)
SelHeatFlow	Heat Flow T4 (mW)
AutoLidII	Installed
AutoAnalysis	Off
MacroFile
Nsig	3
Sig1	Time (min)
Sig2	Temperature (°C)
Sig3	Heat Flow (mW)
Date	2017-06-23
Time	00:22:37
OrgMethod	1: Equilibrate at 20.00 °C
OrgMethod	2: Ramp 80.00 °C/min to 160.00 °C
OrgMethod	3: Mark end of cycle 1
OrgMethod	4: Isothermal for 40.00 min
OrgMethod	5: Mark end of cycle 2
OrgMethod	6: Ramp 20.00 °C/min to 280.00 °C
OrgMethod	7: Mark end of cycle 3
OrgMethod	8: Ramp 20.00 °C/min to 20.00 °C
OrgMethod	9: Mark end of cycle 4
OrgMethod	10: Ramp 20.00 °C/min to 280.00 °C
OrgMethod	11: Mark end of cycle 5
OrgFile	C:\Users\jarra\Desktop\DSC\2-C1(0.8mol%)+C20(0.6mol%)\160-2
StartOfData
4.99994E-4	20.01502	0.1493329
0.05216665	20.21804	0.5295012
0.1038333	21.83418	0.2290406
0.1538333	24.29635	-4.229154
0.2038333	27.12848	-10.09166
0.2538334	30.25679	-15.90596
0.3038333	33.58619	-21.13742
0.3538333	37.06284	-25.56145
0.4038334	40.64876	-29.18980
0.4555000	44.43558	-32.28254
0.5055000	48.14056	-35.19032
0.5571668	52.01382	-37.45887
0.6071668	55.80230	-39.62318
0.6571668	59.55082	-43.12941
0.7071668	63.30706	-45.80586
0.7571668	67.10400	-48.58863
0.8071668	70.79553	-54.86376
0.8571668	74.03918	-72.84319
0.9088334	76.74720	-100.4765
0.9604999	79.47588	-125.0506
1.010500	82.10278	-149.6566
1.060500	84.85831	-171.0347
1.110500	87.98207	-182.5442
1.160500	92.13292	-171.0582
1.210500	97.23386	-147.9511
1.260500	102.3856	-128.3803
1.312167	107.4522	-113.0010
1.362166	112.1390	-101.7595
1.413834	116.8016	-93.09584
1.463833	121.1889	-86.75379
1.513833	125.4850	-82.11326
1.563833	129.7071	-78.62329
1.613833	133.8772	-76.07669
1.663834	138.0103	-74.21418
1.713833	142.1161	-72.74151
1.763833	146.2062	-71.55293
1.813834	149.9257	-71.12072
1.863834	152.1304	-68.17244
1.913834	153.6618	-59.40140
1.963833	154.8395	-49.54496
2.015500	155.7801	-39.80350
2.067166	156.5184	-31.47492
2.117167	157.0866	-24.83154
2.167167	157.5449	-19.57317
2.217167	157.9099	-15.60814
2.267166	158.2055	-12.53906
2.317166	158.4484	-10.17263
2.367167	158.6493	-8.343907
2.417167	158.8182	-6.920078
2.468834	158.9633	-5.779570
2.520500	159.0849	-4.894017
2.570500	159.1850	-4.218586
2.620500	159.2696	-3.682698
2.670500	159.3411	-3.250646
2.720500	159.4032	-2.899156
2.770500	159.4574	-2.610902
2.820500	159.5021	-2.371936
2.872167	159.5436	-2.166009
2.922167	159.5778	-1.996870
2.973833	159.6085	-1.852417
3.023833	159.6351	-1.720749
3.073833	159.6594	-1.612495
3.123834	159.6784	-1.513872
3.173834	159.6956	-1.422531
3.223834	159.7127	-1.339093
3.273834	159.7270	-1.262047
3.325500	159.7400	-1.185794
3.377167	159.7517	-1.115505
3.427167	159.7622	-1.052471
3.477167	159.7710	-0.9866589
3.527167	159.7795	-0.9268769
3.577167	159.7879	-0.8647659
3.627167	159.7944	-0.8075806
3.677167	159.8019	-0.7464670
3.728833	159.8080	-0.6878006
3.778833	159.8139	-0.6294160
3.830500	159.8198	-0.5699176
3.880500	159.8247	-0.5118226
3.930500	159.8295	-0.4522110
3.980500	159.8345	-0.3947511
4.030500	159.8388	-0.3335428
4.080500	159.8436	-0.2738322
4.130500	159.8478	-0.2107797
4.182167	159.8524	-0.1479312
4.233834	159.8564	-.08076875
4.283834	159.8617	-.01707182
4.333834	159.8651	0.05107861
4.383834	159.8691	0.1163556
4.433834	159.8736	0.1839113
4.483834	159.8774	0.2561466
4.533834	159.8827	0.3282776
4.583834	159.8864	0.4035831
4.635500	159.8911	0.4816523
4.687167	159.8955	0.5627007
4.737167	159.9002	0.6429298
4.787167	159.9046	0.7217749
4.837167	159.9091	0.8068989
4.887167	159.9136	0.8917286
4.937167	159.9181	0.9817736
4.987167	159.9242	1.062223
5.038834	159.9283	1.159044
5.088834	159.9333	1.249224
5.140500	159.9380	1.350208
5.190500	159.9433	1.446125
5.240500	159.9486	1.545315
5.290500	159.9540	1.644596
5.340500	159.9594	1.746212
5.390500	159.9646	1.852732
5.440500	159.9704	1.958552
5.492168	159.9758	2.069068
5.543832	159.9807	2.188525
5.593834	159.9882	2.300123
5.643832	159.9934	2.414012
5.693832	159.9996	2.533344
5.743834	160.0052	2.653493
5.793832	160.0127	2.775418
5.843834	160.0182	2.900061
5.895500	160.0248	3.030158
5.945500	160.0314	3.156906
5.997168	160.0385	3.293524
6.047168	160.0445	3.426489
6.097168	160.0519	3.562373
6.147168	160.0583	3.697671
6.197168	160.0648	3.836531
6.247168	160.0724	3.971979
6.297168	160.0796	4.112758
6.348832	160.0872	4.262582
6.400500	160.0940	4.411404
6.450500	160.1020	4.553879
6.500500	160.1103	4.698570
6.550500	160.1166	4.846980
6.600500	160.1238	4.988180
6.650500	160.1317	5.137070
6.700500	160.1386	5.282162
6.750500	160.1463	5.427840
6.802168	160.1535	5.573486
6.853832	160.1610	5.727043
6.903832	160.1682	5.866415
6.953832	160.1754	6.006455
7.003832	160.1818	6.151099
7.053834	160.1891	6.296171
7.103832	160.1966	6.442226
7.153832	160.2050	6.596811
7.205500	160.2132	6.770654
7.255500	160.2222	6.948770
7.307166	160.2322	7.155250
7.357168	160.2423	7.368712
7.407166	160.2533	7.601618
7.457168	160.2659	7.857730
7.507168	160.2786	8.144579
7.557166	160.2951	8.452282
7.607168	160.3110	8.784366
7.658832	160.3290	9.156259
7.710500	160.3473	9.548386
7.760500	160.3664	9.948405
7.810500	160.3877	10.36175
7.860500	160.4084	10.78314
7.910500	160.4292	11.20796
7.960500	160.4492	11.62489
8.010500	160.4707	12.03071
8.062166	160.4901	12.43292
8.112168	160.5089	12.79749
8.163834	160.5266	13.14413
8.213834	160.5432	13.45086
8.263832	160.5560	13.72096
8.313834	160.5681	13.94951
8.363834	160.5784	14.13854
8.413834	160.5871	14.29369
8.463834	160.5935	14.40262
8.515500	160.5977	14.47850
8.567166	160.6009	14.51539
8.617166	160.6011	14.52605
8.667168	160.6011	14.52677
8.717168	160.5999	14.50848
8.767168	160.5972	14.45126
8.817166	160.5957	14.38259
8.867166	160.5912	14.31432
8.917168	160.5886	14.24486
8.968834	160.5855	14.17180
9.020500	160.5820	14.10139
9.070500	160.5783	14.04159
9.120499	160.5759	13.98546
9.170500	160.5735	13.94011
9.220500	160.5712	13.89977
9.270500	160.5702	13.87018
9.320500	160.5684	13.85472
9.372168	160.5676	13.84752
9.422168	160.5684	13.84446
9.473832	160.5691	13.84716
9.523834	160.5719	13.88691
9.573834	160.5734	13.96575
9.623834	160.5787	14.06599
9.673832	160.5842	14.20100
9.723832	160.5920	14.36003
9.773834	160.6009	14.56304
9.825500	160.6126	14.81633
9.877168	160.6268	15.11176
9.927168	160.6418	15.44531
9.977168	160.6597	15.81096
10.02717	160.6778	16.19833
10.07717	160.6976	16.59860
10.12717	160.7173	16.98846
10.17717	160.7360	17.35289
10.22883	160.7528	17.66585
10.27883	160.7653	17.89404
10.33050	160.7736	18.01871
10.38050	160.7761	18.02217
10.43050	160.7717	17.90789
10.48050	160.7623	17.66876
10.53050	160.7474	17.29947
10.58050	160.7251	16.80019
10.63050	160.6970	16.18582
10.68217	160.6630	15.45923
10.73383	160.6241	14.65220
10.78383	160.5842	13.82161
10.83383	160.5422	12.95574
10.88383	160.4991	12.08243
10.93383	160.4566	11.21417
10.98383	160.4146	10.36294
11.03383	160.3726	9.531986
11.08383	160.3331	8.734028
11.13550	160.2934	7.942087
11.18716	160.2552	7.192508
11.23717	160.2206	6.501640
11.28717	160.1881	5.856894
11.33717	160.1578	5.249775
11.38717	160.1287	4.686473
11.43716	160.1025	4.162328
11.48717	160.0778	3.684831
11.53883	160.0546	3.232161
11.58883	160.0341	2.830286
11.64050	160.0146	2.453798
11.69050	159.9985	2.121885
11.74050	159.9848	1.864485
11.79050	159.9708	1.589322
11.84050	159.9588	1.337864
11.89050	159.9463	1.114644
11.94050	159.9366	0.9055708
11.99216	159.9258	0.7089712
12.04384	159.9168	0.5371479
12.09383	159.9099	0.3840919
12.14383	159.9017	0.2442886
12.19383	159.8954	0.1196012
12.24384	159.8899	.001568648
12.29384	159.8838	-0.1080504
12.34383	159.8790	-0.2121401
12.39550	159.8738	-0.3047450
12.44550	159.8693	-0.3914902
12.49717	159.8650	-0.4699598
12.54717	159.8622	-0.5375406
12.59717	159.8594	-0.6045237
12.64717	159.8557	-0.6598280
12.69717	159.8536	-0.7150756
12.74717	159.8505	-0.7670350
12.79717	159.8480	-0.8151645
12.84883	159.8461	-0.8575489
12.90050	159.8436	-0.8977418
12.95050	159.8426	-0.9345636
13.00050	159.8403	-0.9706842
13.05050	159.8381	-1.003155
13.10050	159.8365	-1.034369
13.15050	159.8355	-1.065811
13.20050	159.8346	-1.089991
13.25050	159.8329	-1.115930
13.30217	159.8319	-1.139840
13.35383	159.8294	-1.161213
13.40383	159.8296	-1.183408
13.45383	159.8280	-1.202755
13.50383	159.8276	-1.221950
13.55383	159.8266	-1.238400
13.60383	159.8258	-1.253548
13.65383	159.8248	-1.269878
13.70550	159.8240	-1.283946
13.75550	159.8237	-1.297040
13.80717	159.8225	-1.309698
13.85716	159.8218	-1.320208
13.90717	159.8209	-1.331938
13.95717	159.8207	-1.342366
14.00717	159.8194	-1.353206
14.05717	159.8184	-1.362818
14.10716	159.8189	-1.372777
14.15883	159.8183	-1.384591
14.21050	159.8176	-1.395130
14.26050	159.8171	-1.404757
14.31050	159.8163	-1.414668
14.36050	159.8159	-1.424325
14.41050	159.8158	-1.433735
14.46050	159.8155	-1.443186
14.51050	159.8146	-1.452222
14.56216	159.8145	-1.461218
14.61217	159.8144	-1.469644
14.66383	159.8136	-1.478040
14.71383	159.8136	-1.486294
14.76383	159.8128	-1.494154
14.81383	159.8126	-1.501807
14.86383	159.8128	-1.508949
14.91383	159.8128	-1.515833
14.96383	159.8126	-1.522537
15.01550	159.8118	-1.529065
15.06716	159.8120	-1.535352
15.11716	159.8114	-1.541176
15.16716	159.8115	-1.546862
15.21716	159.8111	-1.552538
15.26717	159.8110	-1.557980
15.31716	159.8111	-1.563586
15.36716	159.8105	-1.568822
15.41716	159.8104	-1.573634
15.46884	159.8105	-1.578802
15.52050	159.8102	-1.583707
15.57050	159.8099	-1.588325
15.62050	159.8096	-1.592553
15.67050	159.8099	-1.596544
15.72050	159.8092	-1.600408
15.77050	159.8099	-1.604323
15.82050	159.8092	-1.608270
15.87217	159.8085	-1.612215
15.92217	159.8084	-1.615802
15.97384	159.8094	-1.619365
16.02383	159.8081	-1.622640
16.07383	159.8083	-1.625927
16.12383	159.8083	-1.629076
16.17383	159.8082	-1.631936
16.22383	159.8082	-1.635114
16.27383	159.8080	-1.638153
16.32550	159.8082	-1.641097
16.37716	159.8073	-1.643784
16.42716	159.8075	-1.646590
16.47716	159.8069	-1.649314
16.52716	159.8069	-1.651971
16.57716	159.8069	-1.654549
16.62716	159.8069	-1.656942
16.67716	159.8069	-1.659381
16.72883	159.8067	-1.661846
16.77883	159.8066	-1.664154
16.83050	159.8062	-1.666669
16.88050	159.8066	-1.668978
16.93050	159.8062	-1.671191
16.98050	159.8066	-1.673581
17.03050	159.8066	-1.675854
17.08050	159.8070	-1.677856
17.13050	159.8061	-1.679869
17.18216	159.8062	-1.682053
17.23383	159.8066	-1.684088
17.28383	159.8063	-1.685910
17.33383	159.8062	-1.687824
17.38383	159.8064	-1.689464
17.43383	159.8049	-1.690977
17.48383	159.8064	-1.692636
17.53383	159.8054	-1.694354
17.58383	159.8059	-1.695924
17.63550	159.8049	-1.697534
17.68716	159.8052	-1.699196
17.73716	159.8049	-1.700594
17.78717	159.8052	-1.702138
17.83716	159.8051	-1.703638
17.88716	159.8051	-1.705192
17.93716	159.8048	-1.706668
17.98716	159.8054	-1.708012
18.03883	159.8048	-1.709369
18.08883	159.8050	-1.710699
18.14050	159.8048	-1.712175
18.19050	159.8049	-1.713552
18.24050	159.8046	-1.714838
18.29050	159.8050	-1.716358
18.34050	159.8042	-1.717684
18.39050	159.8046	-1.719052
18.44050	159.8040	-1.720402
18.49216	159.8044	-1.721528
18.54383	159.8042	-1.722768
18.59383	159.8044	-1.724043
18.64383	159.8046	-1.725344
18.69383	159.8051	-1.726702
18.74383	159.8046	-1.728316
18.79383	159.8044	-1.729683
18.84383	159.8049	-1.730783
18.89550	159.8044	-1.731778
18.94550	159.8037	-1.732762
18.99716	159.8041	-1.733894
19.04716	159.8046	-1.735037
19.09716	159.8038	-1.735687
19.14716	159.8038	-1.736425
19.19716	159.8042	-1.737292
19.24716	159.8040	-1.738241
19.29716	159.8047	-1.738906
19.34883	159.8037	-1.739574
19.40050	159.8042	-1.740546
19.45050	159.8041	-1.741240
19.50050	159.8042	-1.742024
19.55050	159.8040	-1.742974
19.60050	159.8042	-1.744002
19.65050	159.8033	-1.745201
19.70050	159.8045	-1.746271
19.75050	159.8044	-1.747399
19.80216	159.8039	-1.748472
19.85383	159.8050	-1.749594
19.90383	159.8040	-1.750548
19.95383	159.8051	-1.751514
20.00383	159.8051	-1.752696
20.05383	159.8052	-1.753969
20.10383	159.8055	-1.755075
20.15383	159.8051	-1.756177
20.20550	159.8054	-1.757334
20.25550	159.8051	-1.758048
20.30716	159.8048	-1.758720
20.35716	159.8045	-1.759194
20.40716	159.8048	-1.759295
20.45716	159.8048	-1.759735
20.50716	159.8045	-1.759865
20.55716	159.8038	-1.759964
20.60716	159.8035	-1.760138
20.65883	159.8034	-1.760493
20.71050	159.8034	-1.760820
20.76050	159.8024	-1.761224
20.81050	159.8027	-1.761581
20.86050	159.8031	-1.761785
20.91050	159.8034	-1.762071
20.96050	159.8019	-1.762500
21.01050	159.8020	-1.762638
21.06216	159.8016	-1.763102
21.11216	159.8016	-1.763749
21.16383	159.8015	-1.764352
21.21383	159.8016	-1.764758
21.26383	159.8010	-1.765016
21.31383	159.8013	-1.765503
21.36383	159.8015	-1.766165
21.41383	159.8012	-1.766835
21.46383	159.8018	-1.767506
21.51550	159.8016	-1.768401
21.56716	159.8019	-1.769059
21.61716	159.8016	-1.769796
21.66716	159.8015	-1.770281
21.71716	159.8022	-1.771076
21.76716	159.8020	-1.771714
21.81716	159.8024	-1.772101
21.86716	159.8019	-1.772461
21.91716	159.8016	-1.772867
21.96883	159.8024	-1.773380
22.02050	159.8020	-1.774083
22.07050	159.8025	-1.774883
22.12050	159.8022	-1.775852
22.17050	159.8037	-1.776985
22.22050	159.8030	-1.778129
22.27050	159.8032	-1.779071
22.32050	159.8036	-1.779803
22.37216	159.8035	-1.780388
22.42216	159.8034	-1.780878
22.47383	159.8033	-1.781256
22.52383	159.8039	-1.781620
22.57383	159.8032	-1.781526
22.62383	159.8024	-1.781119
22.67383	159.8028	-1.780997
22.72383	159.8025	-1.780820
22.77383	159.8023	-1.780670
22.82550	159.8024	-1.780513
22.87716	159.8024	-1.780656
22.92717	159.8023	-1.780810
22.97716	159.8022	-1.781157
23.02717	159.8017	-1.781500
23.07716	159.8017	-1.781838
23.12716	159.8015	-1.782325
23.17717	159.8012	-1.783138
23.22883	159.8021	-1.783662
23.27883	159.8013	-1.784265
23.33050	159.8015	-1.784955
23.38050	159.8020	-1.785478
23.43050	159.8015	-1.785930
23.48050	159.8017	-1.786510
23.53050	159.8018	-1.786904
23.58050	159.8010	-1.787220
23.63050	159.8016	-1.787725
23.68216	159.8016	-1.788189
23.73383	159.8020	-1.788621
23.78383	159.8015	-1.788994
23.83383	159.8015	-1.789258
23.88383	159.8022	-1.789580
23.93383	159.8019	-1.790129
23.98383	159.8014	-1.790750
24.03383	159.8023	-1.791260
24.08383	159.8022	-1.791698
24.13550	159.8026	-1.792181
24.18716	159.8029	-1.792606
24.23716	159.8028	-1.793052
24.28717	159.8034	-1.793238
24.33716	159.8030	-1.793312
24.38716	159.8036	-1.793796
24.43716	159.8040	-1.794069
24.48716	159.8027	-1.794510
24.53883	159.8033	-1.794873
24.58883	159.8037	-1.795051
24.64050	159.8038	-1.794828
24.69050	159.8027	-1.794796
24.74050	159.8032	-1.794775
24.79050	159.8027	-1.794710
24.84050	159.8032	-1.794595
24.89050	159.8037	-1.794684
24.94050	159.8027	-1.794554
24.99216	159.8027	-1.794386
25.04383	159.8023	-1.794476
25.09383	159.8027	-1.794378
25.14383	159.8028	-1.794263
25.19383	159.8027	-1.793989
25.24383	159.8023	-1.793780
25.29383	159.8014	-1.793787
25.34383	159.8027	-1.793984
25.39550	159.8017	-1.794164
25.44550	159.8018	-1.794136
25.49716	159.8014	-1.794062
25.54716	159.8018	-1.794184
25.59716	159.8012	-1.794352
25.64716	159.8010	-1.794462
25.69717	159.8012	-1.794862
25.74716	159.8012	-1.795295
25.79716	159.8005	-1.795488
25.84883	159.8016	-1.795823
25.90050	159.8010	-1.796218
25.95050	159.8018	-1.796593
26.00050	159.8013	-1.797085
26.05050	159.8014	-1.797415
26.10050	159.8009	-1.797913
26.15050	159.8025	-1.798598
26.20050	159.8017	-1.799359
26.25050	159.8022	-1.800018
26.30217	159.8019	-1.800549
26.35383	159.8026	-1.800851
26.40383	159.8019	-1.801216
26.45383	159.8025	-1.801433
26.50383	159.8021	-1.801725
26.55383	159.8036	-1.802121
26.60383	159.8026	-1.802388
26.65383	159.8031	-1.802554
26.70550	159.8027	-1.802597
26.75550	159.8025	-1.802441
26.80716	159.8025	-1.802313
26.85716	159.8030	-1.802282
26.90716	159.8032	-1.802362
26.95716	159.8030	-1.802434
27.00716	159.8023	-1.802262
27.05716	159.8022	-1.802012
27.10716	159.8024	-1.801715
27.15883	159.8021	-1.801568
27.21050	159.8019	-1.801226
27.26050	159.8016	-1.801112
27.31050	159.8016	-1.800860
27.36050	159.8008	-1.800875
27.41050	159.8014	-1.800984
27.46050	159.8012	-1.801330
27.51050	159.8009	-1.801788
27.56217	159.8021	-1.802404
27.61216	159.8013	-1.803191
27.66383	159.8016	-1.803578
27.71383	159.8022	-1.804301
27.76383	159.8024	-1.804840
27.81383	159.8016	-1.805376
27.86383	159.8020	-1.805808
27.91383	159.8029	-1.806358
27.96383	159.8026	-1.806916
28.01550	159.8032	-1.807392
28.06716	159.8026	-1.807838
28.11716	159.8016	-1.807671
28.16716	159.8028	-1.807602
28.21716	159.8026	-1.807614
28.26716	159.8024	-1.807517
28.31716	159.8019	-1.807398
28.36716	159.8018	-1.807170
28.41716	159.8010	-1.807062
28.46883	159.8020	-1.807132
28.52050	159.8014	-1.807078
28.57050	159.8012	-1.806871
28.62050	159.8013	-1.806846
28.67050	159.8010	-1.806732
28.72050	159.8016	-1.806402
28.77050	159.8005	-1.806125
28.82050	159.8008	-1.806131
28.87216	159.8001	-1.806199
28.92216	159.8004	-1.806392
28.97383	159.7999	-1.806616
29.02383	159.8012	-1.806751
29.07383	159.8007	-1.807056
29.12383	159.8007	-1.807758
29.17383	159.8012	-1.808624
29.22383	159.8017	-1.809888
29.27383	159.8020	-1.810894
29.32550	159.8019	-1.811872
29.37716	159.8026	-1.812620
29.42717	159.8029	-1.813365
29.47717	159.8025	-1.813570
29.52717	159.8024	-1.813470
29.57717	159.8019	-1.813438
29.62716	159.8012	-1.813202
29.67717	159.8021	-1.812970
29.72883	159.8020	-1.812864
29.77883	159.8016	-1.812646
29.83050	159.8020	-1.812485
29.88050	159.8008	-1.812180
29.93050	159.8016	-1.812046
29.98050	159.8016	-1.811920
30.03050	159.8012	-1.811734
30.08050	159.8004	-1.811724
30.13050	159.8008	-1.811596
30.18216	159.8014	-1.811706
30.23383	159.8011	-1.811732
30.28383	159.8016	-1.811951
30.33383	159.8013	-1.812592
30.38383	159.8020	-1.813371
30.43383	159.8026	-1.814252
30.48383	159.8034	-1.815196
30.53383	159.8030	-1.815991
30.58383	159.8033	-1.816502
30.63550	159.8023	-1.816741
30.68717	159.8026	-1.816762
30.73716	159.8021	-1.816617
30.78717	159.8016	-1.816274
30.83716	159.8021	-1.815841
30.88716	159.8020	-1.815606
30.93717	159.8023	-1.815455
30.98716	159.8022	-1.815371
31.03883	159.8021	-1.815474
31.08883	159.8024	-1.815438
31.14050	159.8024	-1.815623
31.19050	159.8018	-1.815755
31.24050	159.8018	-1.816113
31.29050	159.8015	-1.816088
31.34050	159.8015	-1.816228
31.39050	159.8005	-1.816129
31.44050	159.8016	-1.816117
31.49216	159.8011	-1.816283
31.54383	159.8013	-1.816156
31.59383	159.8007	-1.815868
31.64383	159.8010	-1.815873
31.69383	159.8002	-1.815840
31.74383	159.8005	-1.815772
31.79383	159.8011	-1.815838
31.84384	159.8001	-1.815621
31.89550	159.8001	-1.815656
31.94550	159.8001	-1.815647
31.99716	159.8000	-1.815589
32.04716	159.7997	-1.815743
32.09716	159.8003	-1.815999
32.14717	159.8004	-1.816310
32.19717	159.8006	-1.816667
32.24716	159.8003	-1.817127
32.29716	159.8006	-1.817805
32.34883	159.8008	-1.818478
32.40050	159.8005	-1.819015
32.45050	159.8014	-1.819349
32.50050	159.8007	-1.819633
32.55050	159.8017	-1.819947
32.60050	159.8016	-1.820411
32.65050	159.8022	-1.820602
32.70050	159.8014	-1.820810
32.75050	159.8018	-1.821055
32.80217	159.8020	-1.821102
32.85383	159.8018	-1.821232
32.90383	159.8015	-1.821070
32.95383	159.8025	-1.820937
33.00383	159.8027	-1.820870
33.05383	159.8026	-1.820769
33.10383	159.8025	-1.820778
33.15383	159.8026	-1.820548
33.20550	159.8022	-1.820273
33.25550	159.8018	-1.819920
33.30716	159.8018	-1.819533
33.35716	159.8019	-1.819301
33.40716	159.8021	-1.819238
33.45716	159.8017	-1.819061
33.50716	159.8018	-1.818791
33.55716	159.8013	-1.818441
33.60716	159.8016	-1.818016
33.65883	159.8008	-1.817603
33.71050	159.8012	-1.817254
33.76050	159.8011	-1.816962
33.81050	159.8012	-1.816786
33.86050	159.8008	-1.816599
33.91050	159.8014	-1.816628
33.96050	159.8017	-1.816818
34.01050	159.8014	-1.817158
34.06216	159.8018	-1.817550
34.11217	159.8022	-1.818136
34.16383	159.8020	-1.818706
34.21383	159.8025	-1.819352
34.26383	159.8016	-1.819976
34.31383	159.8018	-1.820494
34.36383	159.8026	-1.820991
34.41383	159.8017	-1.821201
34.46383	159.8026	-1.821115
34.51550	159.8022	-1.821009
34.56716	159.8026	-1.820728
34.61716	159.8021	-1.820455
34.66716	159.8016	-1.820220
34.71716	159.8024	-1.820090
34.76716	159.8022	-1.819971
34.81716	159.8019	-1.819714
34.86716	159.8014	-1.819189
34.91716	159.8012	-1.818579
34.96884	159.8006	-1.817949
35.02050	159.8013	-1.817488
35.07050	159.8004	-1.817074
35.12050	159.8007	-1.816936
35.17050	159.8008	-1.817310
35.22050	159.8013	-1.817498
35.27050	159.8014	-1.817794
35.32050	159.8013	-1.818009
35.37216	159.8015	-1.818448
35.42216	159.8010	-1.818898
35.47383	159.8017	-1.819333
35.52383	159.8012	-1.819787
35.57383	159.8016	-1.820205
35.62383	159.8019	-1.820730
35.67383	159.8027	-1.821379
35.72383	159.8019	-1.821771
35.77383	159.8022	-1.821744
35.82550	159.8022	-1.822122
35.87717	159.8022	-1.822125
35.92717	159.8019	-1.822325
35.97717	159.8018	-1.822406
36.02716	159.8021	-1.822200
36.07717	159.8019	-1.821864
36.12717	159.8016	-1.821591
36.17717	159.8016	-1.821236
36.22883	159.8011	-1.820946
36.27883	159.8011	-1.820590
36.33050	159.8011	-1.820390
36.38050	159.8007	-1.820206
36.43050	159.8010	-1.819929
36.48050	159.8009	-1.819842
36.53050	159.8011	-1.819820
36.58050	159.8010	-1.819842
36.63050	159.8002	-1.819925
36.68216	159.8013	-1.820182
36.73383	159.7999	-1.820320
36.78383	159.8005	-1.820594
36.83383	159.8007	-1.821101
36.88383	159.8006	-1.821310
36.93384	159.8001	-1.821277
36.98383	159.8006	-1.821282
37.03383	159.8012	-1.821343
37.08383	159.8005	-1.821546
37.13550	159.8008	-1.821938
37.18716	159.8012	-1.822535
37.23717	159.8016	-1.823252
37.28717	159.8018	-1.823999
37.33716	159.8015	-1.824782
37.38716	159.8020	-1.825412
37.43716	159.8016	-1.825665
37.48717	159.8023	-1.825750
37.53883	159.8018	-1.825895
37.58883	159.8024	-1.826219
37.64050	159.8021	-1.826570
37.69050	159.8016	-1.826772
37.74050	159.8027	-1.826878
37.79050	159.8021	-1.826738
37.84050	159.8019	-1.826604
37.89050	159.8022	-1.826364
37.94050	159.8019	-1.826275
37.99216	159.8021	-1.826171
38.04383	159.8022	-1.825685
38.09384	159.8014	-1.825442
38.14383	159.8018	-1.825248
38.19383	159.8009	-1.825060
38.24383	159.8024	-1.825004
38.29383	159.8012	-1.825082
38.34384	159.8010	-1.824987
38.39550	159.8007	-1.825105
38.44550	159.8006	-1.825064
38.49716	159.8010	-1.825028
38.54716	159.8013	-1.824914
38.59716	159.8013	-1.824795
38.64717	159.8016	-1.824832
38.69717	159.8006	-1.825109
38.74716	159.8014	-1.825310
38.79716	159.8006	-1.825548
38.84883	159.8003	-1.825828
38.90050	159.8006	-1.825778
38.95050	159.8005	-1.825922
39.00050	159.8004	-1.825894
39.05050	159.8004	-1.825809
39.10050	159.8004	-1.825761
39.15050	159.8013	-1.825881
39.20050	159.8007	-1.825970
39.25050	159.8011	-1.826168
39.30217	159.8012	-1.826502
39.35383	159.8007	-1.826803
39.40383	159.8016	-1.827216
39.45383	159.8022	-1.827906
39.50383	159.8012	-1.828449
39.55383	159.8022	-1.828535
39.60383	159.8018	-1.828439
39.65383	159.8019	-1.827994
39.70550	159.8015	-1.827192
39.75550	159.8016	-1.826618
39.80716	159.8014	-1.826360
39.85716	159.8026	-1.826282
39.90716	159.8013	-1.826256
39.95716	159.8028	-1.826313
40.00716	159.8022	-1.826430
40.05716	159.8012	-1.826571
40.10716	159.8018	-1.826582
40.15883	159.8019	-1.826535
40.21050	159.8026	-1.826371
40.26050	159.8010	-1.825875
40.31050	159.8016	-1.825434
40.36050	159.8010	-1.825156
40.41050	159.8009	-1.824443
40.46050	159.8006	-1.823897
40.51050	159.7998	-1.823433
40.56216	159.8010	-1.823374
40.61217	159.8004	-1.823375
40.66383	159.8002	-1.823321
40.71383	159.8008	-1.823498
40.76383	159.8005	-1.823930
40.81383	159.8011	-1.824574
40.86383	159.8014	-1.825103
40.91383	159.8015	-1.825518
40.96383	159.8016	-1.825919
41.01550	159.8020	-1.826580
41.06717	159.8015	-1.826885
41.11716	159.8012	-1.827048
41.16716	159.8019	-1.827128
41.21717	159.8013	-1.827007
41.26717	159.8012	-1.826808
41.31717	159.8019	-1.826776
41.36716	159.8015	-1.827022
41.41716	159.8013	-1.826798
41.46884	159.8012	-1.826709
41.52050	159.8015	-1.826391
41.57050	159.8009	-1.826188
41.62050	159.8008	-1.826138
41.67050	159.8010	-1.826129
41.72050	159.8009	-1.826125
41.76717	159.8017	-1.826504
41.81717	159.9342	-1.734131
41.86716	160.4086	-2.823834
41.91716	161.0262	-5.120951
41.96884	161.7643	-7.746589
42.02050	162.5702	-10.20496
42.07050	163.4008	-12.23854
42.12050	164.2664	-13.91432
42.17050	165.1597	-15.25504
42.22050	166.0731	-16.31959
42.27050	167.0035	-17.16286
42.32050	167.9469	-17.83337
42.37216	168.9316	-18.38490
42.42216	169.8928	-18.81782
42.47383	170.8911	-19.19229
42.52383	171.8640	-19.49933
42.57383	172.8391	-19.76699
42.62383	173.8176	-19.99979
42.67383	174.7992	-20.20814
42.72383	175.7826	-20.40611
42.77383	176.7662	-20.59198
42.82550	177.7863	-20.78111
42.87717	178.8051	-20.96108
42.92717	179.7926	-21.13980
42.97717	180.7792	-21.32384
43.02716	181.7680	-21.51810
43.07717	182.7564	-21.72157
43.12717	183.7446	-21.92896
43.17717	184.7344	-22.14947
43.22883	185.7554	-22.38273
43.27883	186.7435	-22.62048
43.33050	187.7631	-22.88016
43.38050	188.7511	-23.14442
43.43050	189.7382	-23.42506
43.48050	190.7244	-23.73100
43.53050	191.7088	-24.05680
43.58050	192.6936	-24.40690
43.63050	193.6778	-24.77777
43.68217	194.6927	-25.18973
43.73383	195.7072	-25.63373
43.78383	196.6862	-26.10004
43.83383	197.6644	-26.60354
43.88383	198.6424	-27.14875
43.93383	199.6158	-27.73498
43.98383	200.5884	-28.38567
44.03383	201.5571	-29.09993
44.08383	202.5227	-29.91176
44.13550	203.5154	-30.87064
44.18716	204.5005	-31.98350
44.23717	205.4456	-33.25531
44.28717	206.3820	-34.75979
44.33716	207.3050	-36.55168
44.38716	208.2138	-38.65432
44.43716	209.1074	-41.09196
44.48717	209.9884	-43.83598
44.53883	210.8837	-46.92324
44.58883	211.7428	-50.07222
44.64050	212.6257	-53.36328
44.69050	213.4844	-56.46386
44.74050	214.3494	-59.36209
44.79050	215.2301	-61.85979
44.84050	216.1420	-63.47026
44.89050	217.1266	-63.09001
44.94050	218.2265	-60.09360
44.99216	219.4584	-55.32616
45.04383	220.7396	-49.66657
45.09384	222.0062	-43.85554
45.14383	223.2466	-38.99226
45.19383	224.4381	-35.26105
45.24383	225.5830	-32.44046
45.29383	226.6925	-30.33587
45.34384	227.7734	-28.75345
45.39550	228.8704	-27.53677
45.44550	229.9162	-26.67626
45.49716	230.9843	-26.02380
45.54716	232.0088	-25.56489
45.59716	233.0275	-25.22928
45.64717	234.0412	-24.99184
45.69717	235.0530	-24.82025
45.74716	236.0597	-24.70184
45.79716	237.0647	-24.61283
45.84883	238.1031	-24.56510
45.90050	239.1385	-24.53640
45.95050	240.1413	-24.52226
46.00050	241.1419	-24.51832
46.05050	242.1444	-24.51762
46.10050	243.1446	-24.52096
46.15050	244.1461	-24.53070
46.20050	245.1469	-24.54468
46.25050	246.1465	-24.56144
46.30217	247.1814	-24.58960
46.35383	248.2141	-24.60898
46.40383	249.2140	-24.62968
46.45383	250.2154	-24.65582
46.50383	251.2146	-24.68732
46.55383	252.2146	-24.72454
46.60383	253.2148	-24.75656
46.65383	254.2144	-24.78724
46.70550	255.2470	-24.82068
46.75550	256.2463	-24.86066
46.80717	257.2806	-24.90808
46.85717	258.2789	-24.94795
46.90717	259.2789	-24.99148
46.95717	260.2780	-25.03776
47.00717	261.2770	-25.07751
47.05717	262.2758	-25.12261
47.10717	263.2768	-25.17554
47.15883	264.3094	-25.21955
47.21050	265.3419	-25.26726
47.26050	266.3419	-25.31560
47.31050	267.3419	-25.35381
47.36050	268.3400	-25.39398
47.41050	269.3391	-25.44001
47.46050	270.3391	-25.48588
47.51050	271.3380	-25.52806
47.56216	272.3696	-25.56803
47.61217	273.3697	-25.61593
47.66383	274.4015	-25.66199
47.71383	275.4013	-25.71060
47.76050	276.3334	-25.75916
47.81050	277.1414	-25.97512
47.86050	277.2260	-23.61900
47.91050	276.9875	-18.21812
47.96050	276.5496	-12.22639
48.01050	275.9822	-6.660111
48.06216	275.2937	-1.797438
48.11217	274.5540	1.983632
48.16383	273.7332	5.060550
48.21383	272.8961	7.378137
48.26383	272.0264	9.174439
48.31383	271.1315	10.57159
48.36383	270.2183	11.66180
48.41383	269.2904	12.51298
48.46383	268.3482	13.18601
48.51550	267.3654	13.73073
48.56717	266.3755	14.16513
48.61716	265.4096	14.50425
48.66716	264.4390	14.77883
48.71717	263.4659	15.00504
48.76717	262.4881	15.18926
48.81717	261.5073	15.34854
48.86716	260.5250	15.48708
48.91716	259.5402	15.59425
48.96884	258.5210	15.68924
49.02050	257.5012	15.77642
49.07050	256.5120	15.84992
49.12050	255.5232	15.90648
49.17050	254.5324	15.96647
49.22050	253.5410	16.02085
49.27050	252.5488	16.06787
49.32050	251.5570	16.10836
49.37216	250.5314	16.14692
49.42216	249.5383	16.18004
49.47383	248.5118	16.21575
49.52383	247.5173	16.24670
49.57383	246.5226	16.27506
49.62383	245.5292	16.29732
49.67383	244.5337	16.31285
49.72383	243.5390	16.33200
49.77383	242.5446	16.34376
49.82550	241.5164	16.35642
49.87717	240.4882	16.36982
49.92717	239.4927	16.38146
49.97717	238.4977	16.39582
50.02716	237.5012	16.40964
50.07717	236.5060	16.42318
50.12717	235.5096	16.43720
50.17717	234.5145	16.44547
50.22883	233.4855	16.45384
50.27883	232.4893	16.46242
50.33050	231.4612	16.47046
50.38050	230.4646	16.48033
50.43050	229.4690	16.48968
50.48050	228.4720	16.49860
50.53050	227.4766	16.50822
50.58050	226.4806	16.51990
50.63050	225.4839	16.53168
50.68217	224.4558	16.54618
50.73383	223.4258	16.55616
50.78383	222.4297	16.56556
50.83383	221.4334	16.57450
50.88383	220.4362	16.58316
50.93383	219.4400	16.59147
50.98383	218.4442	16.60055
51.03383	217.4480	16.60872
51.08383	216.4519	16.61627
51.13550	215.4215	16.62407
51.18716	214.3924	16.63134
51.23717	213.3956	16.63854
51.28716	212.4000	16.64513
51.33716	211.4028	16.65161
51.38716	210.4066	16.65816
51.43716	209.4108	16.66460
51.48717	208.4141	16.67112
51.53883	207.3850	16.67761
51.58883	206.3881	16.68419
51.64050	205.3572	16.69074
51.69050	204.3608	16.69677
51.74050	203.3639	16.70247
51.79050	202.3675	16.70773
51.84050	201.3703	16.71190
51.89050	200.3738	16.71596
51.94050	199.3782	16.72008
51.99216	198.3473	16.72459
52.04383	197.3177	16.72963
52.09384	196.3198	16.73450
52.14384	195.3234	16.73924
52.19384	194.3265	16.74411
52.24383	193.3289	16.74928
52.29383	192.3334	16.75371
52.34384	191.3362	16.75782
52.39550	190.3065	16.76236
52.44550	189.3099	16.76593
52.49717	188.2794	16.77009
52.54717	187.2827	16.77389
52.59716	186.2864	16.77735
52.64717	185.2895	16.78125
52.69717	184.2920	16.78512
52.74717	183.2951	16.78834
52.79717	182.2988	16.79128
52.84882	181.2678	16.79425
52.90050	180.2373	16.79735
52.95050	179.2405	16.80082
53.00050	178.2437	16.80466
53.05050	177.2459	16.80926
53.10050	176.2499	16.81450
53.15050	175.2519	16.82004
53.20050	174.2541	16.82600
53.25050	173.2568	16.83183
53.30217	172.2266	16.83703
53.35383	171.1957	16.84089
53.40383	170.1975	16.84373
53.45383	169.2010	16.84648
53.50383	168.2045	16.84959
53.55383	167.2078	16.85496
53.60383	166.2120	16.87246
53.65383	165.2171	16.94839
53.70550	164.1919	17.10118
53.75550	163.2048	17.37350
53.80717	162.1959	17.90567
53.85717	161.2371	18.83276
53.90717	160.3037	20.36800
53.95717	159.4058	22.67255
54.00717	158.5478	25.77928
54.05717	157.7261	29.50617
54.10717	156.9234	33.50640
54.15883	156.0950	37.47326
54.21050	155.2451	40.86104
54.26050	154.3863	43.28868
54.31050	153.4791	44.69630
54.36050	152.5196	45.00365
54.41050	151.5062	44.26317
54.46050	150.4441	42.60906
54.51050	149.3445	40.28406
54.56216	148.1805	37.46211
54.61217	147.0451	34.63304
54.66382	145.8728	31.85322
54.71382	144.7510	29.45646
54.76382	143.6448	27.40364
54.81382	142.5561	25.69342
54.86382	141.4821	24.29108
54.91382	140.4138	22.86292
54.96382	139.3626	21.94136
55.01550	138.2890	21.15614
55.06716	137.2240	20.52002
55.11716	136.2001	20.01626
55.16716	135.1810	19.59936
55.21717	134.1644	19.25474
55.26716	133.1520	18.96156
55.31716	132.1414	18.72287
55.36716	131.1332	18.52196
55.41716	130.1261	18.33693
55.46884	129.0870	18.17534
55.52050	128.0478	18.03042
55.57050	127.0449	17.90814
55.62050	126.0412	17.79362
55.67050	125.0384	17.69406
55.72050	124.0360	17.59333
55.77050	123.0334	17.50469
55.82050	122.0313	17.41566
55.87217	120.9970	17.33453
55.92217	119.9962	17.26167
55.97382	118.9623	17.19362
56.02383	117.9606	17.12784
56.07383	116.9593	17.07168
56.12383	115.9597	17.01795
56.17383	114.9580	16.96234
56.22382	113.9596	16.90506
56.27383	112.9571	16.84977
56.32550	111.9243	16.87886
56.37717	110.9052	17.03574
56.42717	109.9036	16.92359
56.47717	108.9004	16.82873
56.52717	107.8982	16.74834
56.57717	106.8976	16.67169
56.62717	105.8960	16.60702
56.67717	104.8954	16.54674
56.72883	103.8611	16.49012
56.77883	102.8613	16.44358
56.83050	101.8264	16.38012
56.88050	100.8254	16.31800
56.93050	99.82362	16.24292
56.98050	98.82228	16.17134
57.03050	97.82086	16.10478
57.08050	96.81993	16.04683
57.13050	95.81910	15.98740
57.18217	94.78588	15.93005
57.23383	93.75212	15.87436
57.28383	92.75157	15.82641
57.33383	91.75219	15.78132
57.38383	90.75184	15.73733
57.43383	89.75152	15.68752
57.48383	88.75116	15.63189
57.53383	87.75134	15.58468
57.58383	86.75129	15.53589
57.63550	85.71839	15.48138
57.68716	84.68351	15.42611
57.73717	83.68519	15.37500
57.78716	82.68424	15.32608
57.83716	81.68594	15.27497
57.88716	80.68102	15.11144
57.93716	79.68070	15.08348
57.98717	78.68090	15.04724
58.03882	77.64763	15.00319
58.08882	76.64798	14.95709
58.14050	75.61453	14.91282
58.19050	74.61543	14.86857
58.24050	73.61500	14.82476
58.29050	72.61522	14.78251
58.34050	71.61538	14.74021
58.39050	70.61549	14.69373
58.44050	69.61491	14.65008
58.49216	68.58194	14.60346
58.54382	67.54712	14.55274
58.59384	66.54636	14.50053
58.64384	65.54712	14.44711
58.69384	64.54660	14.39557
58.74382	63.54631	14.34810
58.79382	62.54621	14.29294
58.84384	61.54592	14.23738
58.89550	60.51178	14.18211
58.94550	59.51132	14.12804
58.99717	58.47656	14.07077
59.04717	57.47693	14.01574
59.09716	56.47520	13.96251
59.14717	55.47535	13.91441
59.19717	54.47425	13.85926
59.24717	53.47344	13.80293
59.29717	52.47244	13.75108
59.34882	51.43974	13.69279
59.40050	50.40494	13.63581
59.45050	49.40452	13.58055
59.50050	48.40369	13.52732
59.55050	47.40219	13.47621
59.60050	46.40180	13.42727
59.65050	45.40036	13.37861
59.70050	44.39984	13.32685
59.75050	43.39922	13.27706
59.80217	42.36467	13.22535
59.85383	41.33198	13.17000
59.90383	40.33022	13.11936
59.95383	39.32972	13.06618
60.00383	38.32915	13.00949
60.05383	37.32864	12.95341
60.10383	36.32713	12.89758
60.15383	35.32614	12.83901
60.20550	34.29098	12.78250
60.25550	33.28955	12.72012
60.30717	32.25522	12.65345
60.35717	31.25330	12.58812
60.40717	30.25144	12.52645
60.45717	29.25030	12.46545
60.50717	28.24739	12.40056
60.55717	27.24504	12.33295
60.60717	26.24322	12.26320
60.65883	25.20678	12.18990
60.71050	24.17178	12.11140
60.75550	23.26797	12.04710
60.80717	22.40249	12.36369
60.85717	22.30432	12.04469
60.90717	22.52550	9.584514
60.95717	22.95109	6.560492
61.00717	23.50936	3.453342
61.05717	24.17021	0.6562290
61.10717	24.90353	-1.731882
61.15883	25.72134	-3.761425
61.21050	26.58484	-5.388310
61.26050	27.45342	-6.637318
61.31050	28.34656	-7.630462
61.36050	29.26033	-8.418755
61.41050	30.18942	-9.041942
61.46050	31.12961	-9.539775
61.51050	32.07954	-9.944562
61.56216	33.06918	-10.28030
61.61217	34.03317	-10.54695
61.66382	35.03408	-10.77245
61.71382	36.00792	-10.95438
61.76382	36.98356	-11.11212
61.81382	37.96221	-11.24592
61.86382	38.94340	-11.36340
61.91382	39.92712	-11.46355
61.96382	40.91079	-11.55272
62.01550	41.93058	-11.63877
62.06716	42.95067	-11.71671
62.11716	43.93926	-11.79092
62.16716	44.92866	-11.85757
62.21717	45.91956	-11.92672
62.26716	46.90954	-11.99032
62.31716	47.90176	-12.05410
62.36716	48.89362	-12.11880
62.41716	49.88552	-12.18396
62.46884	50.91135	-12.25011
62.52050	51.93754	-12.32142
62.57050	52.93164	-12.38532
62.62050	53.92494	-12.45158
62.67050	54.92030	-12.51584
62.72050	55.91389	-12.57936
62.77050	56.90968	-12.64343
62.82050	57.90484	-12.70744
62.87217	58.93449	-12.77301
62.92217	59.92988	-12.83458
62.97382	60.96018	-12.90189
63.02383	61.95578	-12.96808
63.07383	62.95250	-13.03281
63.12383	63.94953	-13.10055
63.17383	64.94693	-13.15891
63.22382	65.94356	-13.21849
63.27383	66.94100	-13.28064
63.32550	67.97114	-13.35043
63.37717	69.00078	-13.41649
63.42717	69.99747	-13.48184
63.47717	70.99525	-13.54687
63.52717	71.99218	-13.61492
63.57717	72.98884	-13.68424
63.62717	73.98632	-13.75324
63.67717	74.98332	-13.81804
63.72883	76.01426	-13.88938
63.77883	77.01144	-13.96206
63.83050	78.04200	-14.03599
63.88050	79.03949	-14.10641
63.93050	80.03686	-14.17726
63.98050	81.03308	-14.25041
64.03050	82.03100	-14.32137
64.08050	83.03006	-14.39622
64.13050	84.02626	-14.46698
64.18218	85.05676	-14.54188
64.23383	86.08789	-14.62204
64.28384	87.08481	-14.70028
64.33384	88.08278	-14.77357
64.38384	89.07969	-14.85172
64.43384	90.07587	-14.93221
64.48383	91.07444	-15.01251
64.53384	92.07158	-15.08995
64.58384	93.06876	-15.16737
64.63550	94.09978	-15.24812
64.68717	95.13045	-15.32786
64.73717	96.12874	-15.40565
64.78717	97.12674	-15.48027
64.83716	98.12428	-15.54978
64.88717	99.12147	-15.62568
64.93717	100.1199	-15.69839
64.98717	101.1176	-15.77064
65.03882	102.1482	-15.85136
65.08884	103.1452	-15.92397
65.14050	104.1764	-15.99897
65.19050	105.1741	-16.07819
65.24050	106.1720	-16.15684
65.29050	107.1697	-16.23348
65.34050	108.1669	-16.31109
65.39050	109.1642	-16.38636
65.44050	110.1618	-16.46510
65.49218	111.1927	-16.55299
65.54384	112.2239	-16.63616
65.59384	113.2208	-16.71673
65.64384	114.2184	-16.79466
65.69384	115.2156	-16.87638
65.74384	116.2132	-16.95646
65.79384	117.2101	-17.03577
65.84384	118.2080	-17.11894
65.89550	119.2379	-17.20546
65.94550	120.2355	-17.29358
65.99718	121.2663	-17.38708
66.04718	122.2628	-17.48026
66.09718	123.2603	-17.57095
66.14718	124.2578	-17.66226
66.19718	125.2540	-17.75691
66.24718	126.2514	-17.84506
66.29718	127.2477	-17.93422
66.34882	128.2783	-18.02352
66.40050	129.3082	-18.11160
66.45050	130.3061	-18.20613
66.50050	131.3044	-18.30054
66.55050	132.3012	-18.39419
66.60050	133.2991	-18.48442
66.65050	134.2964	-18.58155
66.70050	135.2931	-18.67978
66.75050	136.2908	-18.77653
66.80218	137.3204	-18.88007
66.85384	138.3500	-18.98500
66.90384	139.3466	-19.08971
66.95384	140.3433	-19.19804
67.00384	141.3388	-19.31066
67.05384	142.3348	-19.43045
67.10384	143.3294	-19.55513
67.15384	144.3270	-19.66226
67.20550	145.3560	-19.77045
67.25550	146.3519	-19.87908
67.30718	147.3819	-19.99286
67.35718	148.3783	-20.10461
67.40718	149.3734	-20.22032
67.45718	150.3692	-20.33610
67.50718	151.3656	-20.44949
67.55718	152.3614	-20.56653
67.60718	153.3572	-20.68491
67.65884	154.3864	-20.80388
67.71050	155.4162	-20.92622
67.76050	156.4128	-21.04063
67.81050	157.4083	-21.14703
67.86050	158.4059	-21.24992
67.91050	159.4037	-21.33912
67.96050	160.4012	-21.41506
68.01050	161.3995	-21.47772
68.06216	162.4327	-21.53087
68.11218	163.4329	-21.56378
68.16382	164.4658	-21.59192
68.21384	165.4660	-21.61772
68.26384	166.4676	-21.64613
68.31384	167.4673	-21.68476
68.36384	168.4669	-21.73193
68.41382	169.4663	-21.78575
68.46384	170.4653	-21.84727
68.51550	171.4965	-21.93624
68.56718	172.5288	-22.02558
68.61718	173.5242	-22.12355
68.66718	174.5219	-22.23010
68.71718	175.5172	-22.34354
68.76716	176.5119	-22.47385
68.81718	177.5075	-22.61979
68.86718	178.5009	-22.77001
68.91718	179.4957	-22.93976
68.96884	180.5208	-23.13078
69.02050	181.5470	-23.34598
69.07050	182.5370	-23.56656
69.12050	183.5287	-23.81644
69.17050	184.5178	-24.09627
69.22050	185.5055	-24.40066
69.27050	186.4925	-24.74065
69.32050	187.4757	-25.11619
69.37218	188.4910	-25.55129
69.42218	189.4709	-26.01922
69.47384	190.4820	-26.54619
69.52384	191.4581	-27.08118
69.57384	192.4335	-27.64193
69.62384	193.4086	-28.21594
69.67384	194.3835	-28.79916
69.72384	195.3574	-29.39035
69.77384	196.3299	-30.01872
69.82550	197.3328	-30.72380
69.87718	198.3333	-31.49882
69.92718	199.2966	-32.32858
69.97718	200.2579	-33.23817
70.02718	201.2152	-34.22010
70.07718	202.1685	-35.27139
70.12718	203.1213	-36.34488
70.17718	204.0733	-37.41199
70.22884	205.0604	-38.42724
70.27884	206.0215	-39.22978
70.33050	207.0318	-39.65997
70.38050	208.0338	-39.39982
70.43050	209.0761	-38.16350
70.48050	210.1682	-35.93010
70.53050	211.2895	-33.21472
70.58050	212.4144	-30.62568
70.63050	213.5218	-28.51580
70.68218	214.6427	-26.85191
70.73384	215.7413	-25.61288
70.78384	216.7894	-24.71300
70.83384	217.8253	-24.04730
70.88384	218.8516	-23.55558
70.93384	219.8715	-23.18523
70.98384	220.8872	-22.92136
71.03384	221.8988	-22.73418
71.08384	222.9077	-22.60199
71.13550	223.9482	-22.51146
71.18718	224.9858	-22.45266
71.23718	225.9894	-22.41328
71.28718	226.9912	-22.39894
71.33716	227.9931	-22.39588
71.38718	228.9948	-22.39337
71.43718	229.9941	-22.39562
71.48718	230.9948	-22.41125
71.53882	232.0274	-22.44090
71.58884	233.0286	-22.48718
71.64050	234.0613	-22.52935
71.69050	235.0624	-22.57040
71.74050	236.0614	-22.61062
71.79050	237.0620	-22.64167
71.84050	238.0613	-22.68060
71.89050	239.0617	-22.72125
71.94050	240.0615	-22.75844
71.99218	241.0947	-22.80372
72.04384	242.1273	-22.85330
72.09384	243.1271	-22.89607
72.14384	244.1262	-22.94554
72.19384	245.1260	-22.98792
72.24384	246.1255	-23.03071
72.29384	247.1248	-23.07817
72.34384	248.1248	-23.11660
72.39550	249.1570	-23.15751
72.44550	250.1563	-23.19896
72.49718	251.1900	-23.24910
72.54718	252.1903	-23.29160
72.59718	253.1886	-23.33207
72.64718	254.1881	-23.37264
72.69718	255.1876	-23.41314
72.74718	256.1878	-23.46189
72.79718	257.1877	-23.51362
72.84882	258.2198	-23.56144
72.90050	259.2525	-23.60886
72.95050	260.2510	-23.66248
73.00050	261.2503	-23.71205
73.05050	262.2495	-23.76270
73.10050	263.2488	-23.82176
73.15050	264.2476	-23.87213
73.20050	265.2466	-23.92718
73.25050	266.2448	-23.98295
73.30218	267.2783	-24.04274
73.35384	268.3102	-24.10448
73.40384	269.3098	-24.16510
73.45384	270.3085	-24.22608
73.50384	271.3076	-24.27753
73.55384	272.3064	-24.33008
-2.000000	5.000000	0.0000000