File: 2-C1(0.8mol%)+C20(0.6mol%)/matlab/160-3.txt
CLOSED
Version	1.0
Language	English
Mode	Standard
Run	9
RunSerial	11886
Instrument	DSC Q2000 V24.11 Build 124
Module	DSC Standard Cell RC
Operator	Jing
File	\\Ae520-1454\ta\Data\DSC\UQ Composites\Nan\C1(7.5)+C20P(3)+CL(Hotplate MixtureAB)\160-3
ProcName	Ramp
InstSerial	2000-0883
AutoSerial	1293
Sample	Iso160-3
Size	37.9000	mg
PanMass	Not available
PanResist	Automatic Automatic  K/W
PanFactor	Default Default
Method	Ramp
Comment
Xcomment	Pan: Tzero Aluminum Hermetic
Xcomment	Gas1: Nitrogen 50.0 ml/min
Xcomment	Gas2: Nitrogen 50.0 ml/min
Text
Exotherm	UP
Kcell	1.05230
Cpconst	Standard: 0.938
Calib	-38.6961
TempCal	1	pts	157.46	156.60
TzeroDt	-87.6168 -0.0009 -1.4231
TzeroDtz	-87.6168 0.0057 6.9570
InstCalFile	Tzero: \\Ae520-1454\ta\Data\DSC\Calibration\2017\CALIBRATION\1562_RCS (90)_05_18_2017 10_50_44.TZR
InstCalFile	Baseline: \\Ae520-1454\ta\Data\DSC\Calibration\2017\2017-05-17_Calibration.001
InstCalFile	Sapphire: \\Ae520-1454\ta\Data\DSC\Calibration\2017\2017-05-17_Saphire.001
InstCalDate	Tzero 2017-05-18 Time 10:50:44
TempRange	-87.39 to 398.39 °C at 10.00 °C/min Heat Only
AutoZero	Delta T Offset 0.000 uV
AutoZero	Delta T0 Offset 0.000 uV
MultiptCal	0
MultiPtDesc	0) Not set
AutoCellConst	Calibration Date 2017-05-18 16:59:28
Controls	Gas 1  Event Off  Sampling 0.2
Cell#	RC-01562
CoolingUnit	RCS (90)
SelHeatFlow	Heat Flow T4 (mW)
AutoLidII	Installed
AutoAnalysis	Off
MacroFile
Nsig	3
Sig1	Time (min)
Sig2	Temperature (°C)
Sig3	Heat Flow (mW)
Date	2017-06-23
Time	01:44:22
OrgMethod	1: Equilibrate at 20.00 °C
OrgMethod	2: Ramp 80.00 °C/min to 160.00 °C
OrgMethod	3: Mark end of cycle 1
OrgMethod	4: Isothermal for 40.00 min
OrgMethod	5: Mark end of cycle 2
OrgMethod	6: Ramp 20.00 °C/min to 280.00 °C
OrgMethod	7: Mark end of cycle 3
OrgMethod	8: Ramp 20.00 °C/min to 20.00 °C
OrgMethod	9: Mark end of cycle 4
OrgMethod	10: Ramp 20.00 °C/min to 280.00 °C
OrgMethod	11: Mark end of cycle 5
OrgFile	C:\Users\jarra\Desktop\DSC\2-C1(0.8mol%)+C20(0.6mol%)\160-3
StartOfData
4.99994E-4	20.05499	0.1513051
0.05216665	20.25406	0.5056093
0.1038333	21.85814	-.07674861
0.1538333	24.28170	-5.574754
0.2038333	27.03153	-13.10024
0.2538334	30.05125	-20.90099
0.3038333	33.25980	-28.23777
0.3538333	36.61438	-34.72516
0.4038334	40.08431	-40.28720
0.4555000	43.76538	-45.15536
0.5055000	47.39016	-49.31459
0.5571668	51.17696	-53.29239
0.6071668	54.87935	-56.83362
0.6571668	58.56704	-61.56695
0.7071668	62.20649	-66.84071
0.7571668	65.87836	-71.58344
0.8071668	69.54206	-77.33118
0.8571668	73.02694	-88.40697
0.9088334	76.14826	-110.1055
0.9604999	78.90118	-135.7518
1.010500	81.57241	-159.6738
1.060500	84.25711	-183.4966
1.110500	87.07891	-203.8492
1.160500	90.10403	-220.9132
1.210500	93.39892	-232.0641
1.260500	97.47805	-228.9892
1.312167	102.0134	-216.7357
1.362166	106.8685	-198.7219
1.413834	112.0526	-180.7671
1.463833	116.8988	-166.7980
1.513833	121.5806	-155.7601
1.563833	126.1243	-147.1345
1.613833	130.5614	-140.2938
1.663834	134.9022	-135.2659
1.713833	139.1655	-131.5908
1.763833	143.3730	-128.8645
1.813834	147.1758	-127.3773
1.863834	149.4506	-123.0343
1.913834	151.0776	-112.2757
1.963833	152.3807	-99.72903
2.015500	153.4664	-86.99413
2.067166	154.3599	-75.64161
2.117167	155.0755	-66.27548
2.167167	155.6718	-58.43092
2.217167	156.1678	-51.93758
2.267166	156.5835	-46.58374
2.317166	156.9306	-42.14584
2.367167	157.2224	-38.47971
2.417167	157.4688	-35.43695
2.468834	157.6836	-32.80122
2.520500	157.8655	-30.58586
2.570500	158.0158	-28.76112
2.620500	158.1461	-27.17818
2.670500	158.2596	-25.78403
2.720500	158.3581	-24.56724
2.770500	158.4476	-23.45864
2.820500	158.5251	-22.44202
2.872167	158.5997	-21.45630
2.922167	158.6657	-20.54444
2.973833	158.7306	-19.60382
3.023833	158.7916	-18.68858
3.073833	158.8497	-17.76203
3.123834	158.9079	-16.83287
3.173834	158.9635	-15.91164
3.223834	159.0168	-15.00635
3.273834	159.0692	-14.12480
3.325500	159.1208	-13.25164
3.377167	159.1693	-12.36416
3.427167	159.2184	-11.47812
3.477167	159.2672	-10.56085
3.527167	159.3177	-9.623684
3.577167	159.3680	-8.675897
3.627167	159.4166	-7.757980
3.677167	159.4621	-6.914551
3.728833	159.5057	-6.137772
3.778833	159.5422	-5.482154
3.830500	159.5750	-4.894790
3.880500	159.6038	-4.399296
3.930500	159.6282	-3.965626
3.980500	159.6497	-3.587772
4.030500	159.6683	-3.254044
4.080500	159.6854	-2.963184
4.130500	159.6987	-2.705204
4.182167	159.7136	-2.476040
4.233834	159.7248	-2.266988
4.283834	159.7349	-2.091451
4.333834	159.7447	-1.929175
4.383834	159.7526	-1.785682
4.433834	159.7595	-1.661578
4.483834	159.7670	-1.547641
4.533834	159.7726	-1.448359
4.583834	159.7784	-1.354200
4.635500	159.7831	-1.268466
4.687167	159.7874	-1.186531
4.737167	159.7923	-1.113312
4.787167	159.7964	-1.046977
4.837167	159.7996	-0.9816747
4.887167	159.8038	-0.9247639
4.937167	159.8069	-0.8652228
4.987167	159.8106	-0.8127610
5.038834	159.8133	-0.7570024
5.088834	159.8166	-0.7053722
5.140500	159.8189	-0.6531748
5.190500	159.8218	-0.6044624
5.240500	159.8246	-0.5565568
5.290500	159.8280	-0.5081645
5.340500	159.8301	-0.4623664
5.390500	159.8332	-0.4175625
5.440500	159.8361	-0.3730407
5.492168	159.8386	-0.3250846
5.543832	159.8410	-0.2763630
5.593834	159.8436	-0.2295212
5.643832	159.8459	-0.1851901
5.693832	159.8487	-0.1371335
5.743834	159.8511	-.09023461
5.793832	159.8540	-.04334701
5.843834	159.8566	.003777650
5.895500	159.8594	0.05320855
5.945500	159.8622	0.1012419
5.997168	159.8652	0.1507627
6.047168	159.8676	0.1995176
6.097168	159.8689	0.2521087
6.147168	159.8730	0.2982063
6.197168	159.8754	0.3497060
6.247168	159.8789	0.4002172
6.297168	159.8812	0.4532210
6.348832	159.8839	0.5036459
6.400500	159.8874	0.5579124
6.450500	159.8893	0.6105591
6.500500	159.8923	0.6663399
6.550500	159.8954	0.7190414
6.600500	159.8976	0.7722576
6.650500	159.9009	0.8282746
6.700500	159.9039	0.8854534
6.750500	159.9065	0.9443664
6.802168	159.9100	1.001328
6.853832	159.9127	1.064555
6.903832	159.9161	1.123312
6.953832	159.9192	1.185777
7.003832	159.9222	1.245617
7.053834	159.9249	1.307482
7.103832	159.9287	1.368152
7.153832	159.9312	1.431084
7.205500	159.9348	1.497410
7.255500	159.9381	1.562941
7.307166	159.9424	1.628019
7.357168	159.9454	1.695755
7.407166	159.9488	1.761485
7.457168	159.9520	1.829260
7.507168	159.9554	1.898340
7.557166	159.9589	1.967402
7.607168	159.9624	2.036925
7.658832	159.9664	2.111688
7.710500	159.9700	2.189491
7.760500	159.9738	2.259868
7.810500	159.9768	2.335201
7.860500	159.9818	2.404806
7.910500	159.9845	2.482914
7.960500	159.9887	2.560264
8.010500	159.9927	2.636004
8.062166	159.9976	2.716016
8.112168	160.0009	2.796542
8.163834	160.0052	2.879910
8.213834	160.0088	2.959539
8.263832	160.0130	3.041852
8.313834	160.0173	3.126590
8.363834	160.0220	3.206604
8.413834	160.0256	3.291286
8.463834	160.0310	3.375183
8.515500	160.0343	3.463297
8.567166	160.0400	3.550300
8.617166	160.0430	3.639672
8.667168	160.0487	3.725854
8.717168	160.0521	3.812505
8.767168	160.0568	3.903254
8.817166	160.0609	3.993930
8.867166	160.0656	4.080746
8.917168	160.0706	4.171844
8.968834	160.0746	4.262836
9.020500	160.0796	4.355278
9.070500	160.0847	4.447150
9.120499	160.0888	4.536365
9.170500	160.0934	4.629142
9.220500	160.0977	4.723213
9.270500	160.1023	4.809642
9.320500	160.1064	4.901336
9.372168	160.1113	4.993393
9.422168	160.1154	5.081528
9.473832	160.1208	5.170112
9.523834	160.1244	5.259232
9.573834	160.1288	5.348621
9.623834	160.1327	5.439050
9.673832	160.1378	5.521672
9.723832	160.1415	5.605256
9.773834	160.1459	5.690460
9.825500	160.1500	5.777661
9.877168	160.1538	5.866929
9.927168	160.1589	5.955678
9.977168	160.1638	6.046063
10.02717	160.1686	6.139794
10.07717	160.1728	6.248514
10.12717	160.1793	6.359855
10.17717	160.1845	6.483750
10.22883	160.1918	6.627304
10.27883	160.1989	6.782190
10.33050	160.2075	6.970844
10.38050	160.2184	7.182931
10.43050	160.2291	7.424712
10.48050	160.2423	7.703839
10.53050	160.2572	8.018662
10.58050	160.2743	8.373400
10.63050	160.2931	8.761728
10.68217	160.3138	9.196781
10.73383	160.3357	9.662286
10.78383	160.3592	10.14141
10.83383	160.3830	10.63350
10.88383	160.4083	11.13600
10.93383	160.4327	11.64206
10.98383	160.4570	12.13684
11.03383	160.4814	12.62472
11.08383	160.5054	13.09460
11.13550	160.5287	13.55554
11.18716	160.5505	13.99148
11.23717	160.5698	14.37530
11.28717	160.5888	14.73307
11.33717	160.6046	15.05603
11.38717	160.6201	15.34438
11.43716	160.6327	15.59907
11.48717	160.6443	15.81762
11.53883	160.6542	16.01140
11.58883	160.6622	16.16552
11.64050	160.6692	16.29281
11.69050	160.6742	16.38654
11.74050	160.6781	16.45439
11.79050	160.6812	16.49449
11.84050	160.6831	16.51294
11.89050	160.6824	16.51668
11.94050	160.6822	16.51353
11.99216	160.6804	16.47539
12.04384	160.6774	16.40276
12.09383	160.6743	16.32012
12.14383	160.6700	16.22215
12.19383	160.6652	16.11381
12.24384	160.6593	15.99464
12.29384	160.6531	15.85976
12.34383	160.6469	15.71509
12.39550	160.6388	15.55794
12.44550	160.6316	15.39915
12.49717	160.6231	15.22472
12.54717	160.6149	15.05096
12.59717	160.6064	14.87270
12.64717	160.5977	14.68914
12.69717	160.5877	14.50729
12.74717	160.5793	14.32362
12.79717	160.5702	14.13963
12.84883	160.5616	13.95518
12.90050	160.5514	13.76215
12.95050	160.5431	13.58005
13.00050	160.5341	13.39495
13.05050	160.5254	13.21160
13.10050	160.5154	13.02930
13.15050	160.5074	12.84736
13.20050	160.4972	12.67002
13.25050	160.4894	12.49480
13.30217	160.4805	12.31502
13.35383	160.4715	12.14301
13.40383	160.4637	11.97984
13.45383	160.4557	11.82691
13.50383	160.4477	11.66957
13.55383	160.4406	11.51918
13.60383	160.4333	11.37917
13.65383	160.4263	11.24026
13.70550	160.4194	11.10447
13.75550	160.4133	10.97301
13.80717	160.4065	10.84462
13.85716	160.4013	10.72692
13.90717	160.3947	10.61066
13.95717	160.3895	10.50312
14.00717	160.3839	10.40090
14.05717	160.3798	10.29938
14.10716	160.3744	10.20645
14.15883	160.3701	10.11984
14.21050	160.3654	10.03331
14.26050	160.3616	9.958344
14.31050	160.3584	9.885809
14.36050	160.3548	9.824894
14.41050	160.3514	9.768001
14.46050	160.3491	9.716969
14.51050	160.3476	9.676164
14.56216	160.3451	9.640069
14.61217	160.3438	9.615329
14.66383	160.3428	9.597947
14.71383	160.3417	9.587089
14.76383	160.3412	9.580874
14.81383	160.3412	9.575924
14.86383	160.3424	9.571743
14.91383	160.3420	9.568738
14.96383	160.3424	9.566434
15.01550	160.3414	9.563392
15.06716	160.3411	9.556618
15.11716	160.3394	9.532984
15.16716	160.3376	9.473306
15.21716	160.3341	9.397238
15.26717	160.3306	9.303875
15.31716	160.3258	9.193645
15.36716	160.3197	9.058142
15.41716	160.3121	8.903818
15.46884	160.3047	8.728026
15.52050	160.2943	8.531456
15.57050	160.2846	8.329518
15.62050	160.2740	8.113648
15.67050	160.2638	7.892212
15.72050	160.2530	7.660486
15.77050	160.2407	7.428643
15.82050	160.2295	7.187822
15.87217	160.2173	6.940700
15.92217	160.2058	6.706630
15.97384	160.1942	6.465026
16.02383	160.1831	6.240506
16.07383	160.1716	6.012756
16.12383	160.1603	5.784625
16.17383	160.1500	5.565920
16.22383	160.1392	5.350480
16.27383	160.1286	5.136436
16.32550	160.1175	4.920956
16.37716	160.1078	4.709280
16.42716	160.0979	4.510606
16.47716	160.0882	4.316861
16.52716	160.0780	4.123994
16.57716	160.0688	3.936084
16.62716	160.0601	3.758675
16.67716	160.0513	3.583184
16.72883	160.0423	3.404491
16.77883	160.0336	3.238925
16.83050	160.0247	3.072639
16.88050	160.0176	2.914511
16.93050	160.0104	2.764550
16.98050	160.0029	2.619479
17.03050	159.9952	2.478574
17.08050	159.9882	2.340232
17.13050	159.9816	2.206882
17.18216	159.9750	2.073330
17.23383	159.9686	1.946072
17.28383	159.9618	1.822390
17.33383	159.9556	1.707499
17.38383	159.9509	1.592848
17.43383	159.9450	1.484679
17.48383	159.9393	1.379614
17.53383	159.9349	1.278312
17.58383	159.9302	1.175041
17.63550	159.9243	1.082330
17.68716	159.9205	0.9844130
17.73716	159.9159	0.8956728
17.78717	159.9116	0.8093140
17.83716	159.9075	0.7256106
17.88716	159.9033	0.6462528
17.93716	159.9004	0.5648920
17.98716	159.8973	0.4897559
18.03883	159.8925	0.4144018
18.08883	159.8898	0.3439128
18.14050	159.8864	0.2775432
18.19050	159.8838	0.2095869
18.24050	159.8801	0.1494408
18.29050	159.8770	0.08929764
18.34050	159.8738	0.03254804
18.39050	159.8715	-.02064924
18.44050	159.8679	-.07483813
18.49216	159.8654	-0.1253200
18.54383	159.8625	-0.1740086
18.59383	159.8596	-0.2226250
18.64383	159.8574	-0.2679568
18.69383	159.8554	-0.3126648
18.74383	159.8530	-0.3560339
18.79383	159.8511	-0.3964899
18.84383	159.8487	-0.4375412
18.89550	159.8471	-0.4747963
18.94550	159.8448	-0.5126987
18.99716	159.8425	-0.5456434
19.04716	159.8408	-0.5813354
19.09716	159.8394	-0.6158388
19.14716	159.8378	-0.6469282
19.19716	159.8358	-0.6768355
19.24716	159.8350	-0.7048158
19.29716	159.8325	-0.7341641
19.34883	159.8317	-0.7602771
19.40050	159.8303	-0.7889669
19.45050	159.8294	-0.8117822
19.50050	159.8278	-0.8367780
19.55050	159.8264	-0.8601516
19.60050	159.8252	-0.8842358
19.65050	159.8238	-0.9067410
19.70050	159.8235	-0.9268514
19.75050	159.8230	-0.9471149
19.80216	159.8215	-0.9664009
19.85383	159.8210	-0.9857205
19.90383	159.8198	-1.004388
19.95383	159.8184	-1.022026
20.00383	159.8182	-1.038996
20.05383	159.8171	-1.056598
20.10383	159.8168	-1.071512
20.15383	159.8155	-1.086039
20.20550	159.8141	-1.099988
20.25550	159.8134	-1.114046
20.30716	159.8132	-1.130058
20.35716	159.8124	-1.143630
20.40716	159.8118	-1.155211
20.45716	159.8111	-1.167657
20.50716	159.8099	-1.178955
20.55716	159.8096	-1.190662
20.60716	159.8091	-1.205047
20.65883	159.8090	-1.216392
20.71050	159.8077	-1.228187
20.76050	159.8076	-1.238469
20.81050	159.8071	-1.249710
20.86050	159.8071	-1.260703
20.91050	159.8062	-1.270530
20.96050	159.8054	-1.281227
21.01050	159.8056	-1.290824
21.06216	159.8049	-1.302112
21.11216	159.8040	-1.311783
21.16383	159.8032	-1.321424
21.21383	159.8034	-1.331850
21.26383	159.8031	-1.340748
21.31383	159.8028	-1.349476
21.36383	159.8021	-1.358363
21.41383	159.8030	-1.367146
21.46383	159.8016	-1.375716
21.51550	159.8015	-1.384284
21.56716	159.8002	-1.392672
21.61716	159.8008	-1.400516
21.66716	159.8003	-1.408412
21.71716	159.8003	-1.416042
21.76716	159.7997	-1.423415
21.81716	159.7991	-1.430609
21.86716	159.7991	-1.437608
21.91716	159.7998	-1.444600
21.96883	159.7989	-1.451522
22.02050	159.7986	-1.458670
22.07050	159.7994	-1.465513
22.12050	159.7998	-1.472202
22.17050	159.7989	-1.478801
22.22050	159.7987	-1.485098
22.27050	159.7982	-1.491318
22.32050	159.7982	-1.496902
22.37216	159.7977	-1.502642
22.42216	159.7973	-1.507525
22.47383	159.7970	-1.512318
22.52383	159.7965	-1.516815
22.57383	159.7967	-1.520989
22.62383	159.7960	-1.525565
22.67383	159.7950	-1.529784
22.72383	159.7950	-1.533711
22.77383	159.7944	-1.537402
22.82550	159.7946	-1.540848
22.87716	159.7946	-1.544686
22.92717	159.7944	-1.548294
22.97716	159.7938	-1.551636
23.02717	159.7935	-1.554858
23.07716	159.7918	-1.558148
23.12716	159.7934	-1.561525
23.17717	159.7928	-1.565250
23.22883	159.7925	-1.568604
23.27883	159.7924	-1.572125
23.33050	159.7923	-1.575830
23.38050	159.7926	-1.579081
23.43050	159.7926	-1.582218
23.48050	159.7921	-1.586003
23.53050	159.7918	-1.589699
23.58050	159.7918	-1.593506
23.63050	159.7922	-1.597491
23.68216	159.7914	-1.601151
23.73383	159.7922	-1.604772
23.78383	159.7922	-1.608611
23.83383	159.7909	-1.612516
23.88383	159.7918	-1.616445
23.93383	159.7923	-1.620238
23.98383	159.7912	-1.624120
24.03383	159.7905	-1.627602
24.08383	159.7909	-1.630902
24.13550	159.7899	-1.634250
24.18716	159.7896	-1.637326
24.23716	159.7901	-1.640122
24.28717	159.7894	-1.642918
24.33716	159.7890	-1.645934
24.38716	159.7881	-1.648756
24.43716	159.7876	-1.651683
24.48716	159.7879	-1.655065
24.53883	159.7876	-1.658444
24.58883	159.7874	-1.661649
24.64050	159.7869	-1.665123
24.69050	159.7870	-1.668358
24.74050	159.7866	-1.671721
24.79050	159.7875	-1.675307
24.84050	159.7878	-1.679188
24.89050	159.7876	-1.683475
24.94050	159.7877	-1.687705
24.99216	159.7884	-1.692173
25.04383	159.7881	-1.696132
25.09383	159.7878	-1.699998
25.14383	159.7878	-1.703672
25.19383	159.7879	-1.707082
25.24383	159.7875	-1.710204
25.29383	159.7874	-1.713039
25.34383	159.7878	-1.715397
25.39550	159.7868	-1.717954
25.44550	159.7871	-1.720140
25.49716	159.7868	-1.722544
25.54716	159.7867	-1.724744
25.59716	159.7867	-1.726799
25.64716	159.7865	-1.729033
25.69717	159.7859	-1.730980
25.74716	159.7856	-1.732668
25.79716	159.7859	-1.734734
25.84883	159.7848	-1.736825
25.90050	159.7846	-1.738783
25.95050	159.7841	-1.741048
26.00050	159.7836	-1.743052
26.05050	159.7845	-1.745076
26.10050	159.7836	-1.747197
26.15050	159.7838	-1.749078
26.20050	159.7826	-1.750877
26.25050	159.7838	-1.753039
26.30217	159.7837	-1.755438
26.35383	159.7843	-1.757937
26.40383	159.7832	-1.760723
26.45383	159.7843	-1.763367
26.50383	159.7844	-1.766205
26.55383	159.7843	-1.769178
26.60383	159.7842	-1.772175
26.65383	159.7850	-1.774976
26.70550	159.7846	-1.777610
26.75550	159.7846	-1.779984
26.80716	159.7838	-1.781875
26.85716	159.7838	-1.783570
26.90716	159.7836	-1.785284
26.95716	159.7836	-1.786685
27.00716	159.7837	-1.788080
27.05716	159.7833	-1.789362
27.10716	159.7825	-1.790201
27.15883	159.7836	-1.791621
27.21050	159.7826	-1.793426
27.26050	159.7835	-1.794693
27.31050	159.7837	-1.796426
27.36050	159.7826	-1.798397
27.41050	159.7825	-1.800298
27.46050	159.7830	-1.802192
27.51050	159.7829	-1.804504
27.56217	159.7828	-1.806567
27.61216	159.7825	-1.808294
27.66383	159.7832	-1.810088
27.71383	159.7820	-1.811913
27.76383	159.7821	-1.813028
27.81383	159.7826	-1.813929
27.86383	159.7816	-1.815094
27.91383	159.7816	-1.816342
27.96383	159.7819	-1.817681
28.01550	159.7821	-1.819191
28.06716	159.7815	-1.820607
28.11716	159.7814	-1.821887
28.16716	159.7814	-1.822696
28.21716	159.7807	-1.823827
28.26716	159.7812	-1.825121
28.31716	159.7805	-1.826293
28.36716	159.7814	-1.827860
28.41716	159.7809	-1.829275
28.46883	159.7813	-1.830641
28.52050	159.7811	-1.832160
28.57050	159.7803	-1.833632
28.62050	159.7813	-1.835109
28.67050	159.7810	-1.836324
28.72050	159.7810	-1.837254
28.77050	159.7809	-1.838572
28.82050	159.7806	-1.839480
28.87216	159.7805	-1.839913
28.92216	159.7802	-1.840385
28.97383	159.7795	-1.840839
29.02383	159.7800	-1.841518
29.07383	159.7791	-1.842453
29.12383	159.7800	-1.843480
29.17383	159.7801	-1.844299
29.22383	159.7794	-1.845074
29.27383	159.7797	-1.845909
29.32550	159.7797	-1.847074
29.37716	159.7801	-1.848276
29.42717	159.7798	-1.849486
29.47717	159.7802	-1.850746
29.52717	159.7800	-1.851687
29.57717	159.7802	-1.852444
29.62716	159.7803	-1.853628
29.67717	159.7812	-1.854943
29.72883	159.7805	-1.856065
29.77883	159.7806	-1.857292
29.83050	159.7813	-1.858613
29.88050	159.7809	-1.859867
29.93050	159.7806	-1.860782
29.98050	159.7810	-1.861580
30.03050	159.7810	-1.862547
30.08050	159.7800	-1.863216
30.13050	159.7803	-1.863894
30.18216	159.7804	-1.864436
30.23383	159.7803	-1.865040
30.28383	159.7804	-1.865281
30.33383	159.7803	-1.865352
30.38383	159.7800	-1.865528
30.43383	159.7797	-1.865934
30.48383	159.7802	-1.866216
30.53383	159.7794	-1.866626
30.58383	159.7791	-1.867355
30.63550	159.7792	-1.867702
30.68717	159.7794	-1.867981
30.73716	159.7792	-1.868574
30.78717	159.7790	-1.869091
30.83716	159.7789	-1.869719
30.88716	159.7788	-1.870322
30.93717	159.7784	-1.870810
30.98716	159.7791	-1.871140
31.03883	159.7787	-1.871645
31.08883	159.7780	-1.872280
31.14050	159.7785	-1.872711
31.19050	159.7783	-1.873280
31.24050	159.7778	-1.874094
31.29050	159.7783	-1.874612
31.34050	159.7775	-1.875162
31.39050	159.7785	-1.876088
31.44050	159.7784	-1.876943
31.49216	159.7779	-1.877954
31.54383	159.7791	-1.879514
31.59383	159.7788	-1.881133
31.64383	159.7784	-1.881822
31.69383	159.7789	-1.882826
31.74383	159.7791	-1.883803
31.79383	159.7792	-1.884511
31.84384	159.7804	-1.885353
31.89550	159.7793	-1.886431
31.94550	159.7794	-1.887007
31.99716	159.7795	-1.887649
32.04716	159.7797	-1.888351
32.09716	159.7803	-1.888820
32.14717	159.7799	-1.889044
32.19717	159.7798	-1.889534
32.24716	159.7796	-1.889850
32.29716	159.7796	-1.889735
32.34883	159.7794	-1.889763
32.40050	159.7803	-1.889620
32.45050	159.7786	-1.889690
32.50050	159.7782	-1.889925
32.55050	159.7789	-1.890024
32.60050	159.7782	-1.890157
32.65050	159.7777	-1.890089
32.70050	159.7788	-1.890146
32.75050	159.7782	-1.890291
32.80217	159.7780	-1.890042
32.85383	159.7785	-1.890035
32.90383	159.7775	-1.890123
32.95383	159.7780	-1.890494
33.00383	159.7786	-1.891298
33.05383	159.7784	-1.892026
33.10383	159.7784	-1.893102
33.15383	159.7787	-1.894386
33.20550	159.7790	-1.896017
33.25550	159.7792	-1.897338
33.30716	159.7785	-1.898071
33.35716	159.7789	-1.898524
33.40716	159.7781	-1.898686
33.45716	159.7789	-1.898962
33.50716	159.7789	-1.899476
33.55716	159.7783	-1.899744
33.60716	159.7787	-1.899806
33.65883	159.7781	-1.899801
33.71050	159.7779	-1.899861
33.76050	159.7778	-1.899856
33.81050	159.7784	-1.900045
33.86050	159.7786	-1.900078
33.91050	159.7777	-1.900147
33.96050	159.7783	-1.900418
34.01050	159.7781	-1.900974
34.06216	159.7773	-1.901259
34.11217	159.7781	-1.901750
34.16383	159.7779	-1.902219
34.21383	159.7770	-1.902481
34.26383	159.7778	-1.902767
34.31383	159.7770	-1.902791
34.36383	159.7771	-1.902855
34.41383	159.7775	-1.902833
34.46383	159.7760	-1.902880
34.51550	159.7772	-1.903010
34.56716	159.7766	-1.903259
34.61716	159.7770	-1.903720
34.66716	159.7781	-1.904238
34.71716	159.7770	-1.904912
34.76716	159.7778	-1.905888
34.81716	159.7775	-1.906897
34.86716	159.7773	-1.907855
34.91716	159.7775	-1.908778
34.96884	159.7782	-1.909472
35.02050	159.7780	-1.910046
35.07050	159.7781	-1.910582
35.12050	159.7782	-1.911055
35.17050	159.7782	-1.911272
35.22050	159.7779	-1.911402
35.27050	159.7775	-1.911636
35.32050	159.7782	-1.911481
35.37216	159.7777	-1.911306
35.42216	159.7779	-1.911026
35.47383	159.7777	-1.910477
35.52383	159.7778	-1.910083
35.57383	159.7776	-1.909725
35.62383	159.7770	-1.909382
35.67383	159.7777	-1.909382
35.72383	159.7779	-1.910061
35.77383	159.7778	-1.910790
35.82550	159.7777	-1.911421
35.87717	159.7781	-1.911844
35.92717	159.7784	-1.912304
35.97717	159.7784	-1.912805
36.02716	159.7780	-1.913264
36.07717	159.7785	-1.914054
36.12717	159.7781	-1.914670
36.17717	159.7784	-1.915275
36.22883	159.7786	-1.915990
36.27883	159.7784	-1.916538
36.33050	159.7786	-1.916822
36.38050	159.7787	-1.916855
36.43050	159.7782	-1.916836
36.48050	159.7782	-1.916728
36.53050	159.7781	-1.916434
36.58050	159.7783	-1.916249
36.63050	159.7784	-1.916332
36.68216	159.7780	-1.916386
36.73383	159.7771	-1.916341
36.78383	159.7773	-1.915969
36.83383	159.7771	-1.915604
36.88383	159.7768	-1.915204
36.93384	159.7766	-1.915040
36.98383	159.7767	-1.915016
37.03383	159.7758	-1.914876
37.08383	159.7767	-1.914849
37.13550	159.7768	-1.915234
37.18716	159.7765	-1.915796
37.23717	159.7768	-1.916456
37.28717	159.7765	-1.917036
37.33716	159.7765	-1.917455
37.38716	159.7770	-1.918154
37.43716	159.7778	-1.919005
37.48717	159.7770	-1.919846
37.53883	159.7770	-1.920564
37.58883	159.7778	-1.921431
37.64050	159.7776	-1.921928
37.69050	159.7768	-1.922137
37.74050	159.7774	-1.922202
37.79050	159.7776	-1.922444
37.84050	159.7776	-1.922530
37.89050	159.7774	-1.922744
37.94050	159.7778	-1.922949
37.99216	159.7774	-1.923240
38.04383	159.7777	-1.923584
38.09384	159.7767	-1.923696
38.14383	159.7771	-1.924006
38.19383	159.7772	-1.924534
38.24383	159.7775	-1.924999
38.29383	159.7772	-1.925361
38.34384	159.7779	-1.925477
38.39550	159.7774	-1.925430
38.44550	159.7781	-1.925572
38.49716	159.7776	-1.925499
38.54716	159.7776	-1.925602
38.59716	159.7775	-1.925793
38.64717	159.7771	-1.925884
38.69717	159.7772	-1.925852
38.74716	159.7777	-1.925816
38.79716	159.7776	-1.925668
38.84883	159.7777	-1.925754
38.90050	159.7773	-1.925920
38.95050	159.7775	-1.925809
39.00050	159.7769	-1.925574
39.05050	159.7774	-1.925246
39.10050	159.7771	-1.924952
39.15050	159.7765	-1.924467
39.20050	159.7764	-1.924203
39.25050	159.7767	-1.924052
39.30217	159.7764	-1.924104
39.35383	159.7762	-1.924071
39.40383	159.7764	-1.923745
39.45383	159.7765	-1.923595
39.50383	159.7766	-1.923534
39.55383	159.7762	-1.923613
39.60383	159.7764	-1.923964
39.65383	159.7762	-1.924516
39.70550	159.7766	-1.925070
39.75550	159.7763	-1.925649
39.80716	159.7762	-1.926099
39.85716	159.7772	-1.926890
39.90716	159.7766	-1.927584
39.95716	159.7765	-1.928191
40.00716	159.7774	-1.929138
40.05716	159.7769	-1.929598
40.10716	159.7777	-1.929976
40.15883	159.7774	-1.930140
40.21050	159.7772	-1.930076
40.26050	159.7774	-1.929849
40.31050	159.7772	-1.929334
40.36050	159.7767	-1.928988
40.41050	159.7775	-1.928828
40.46050	159.7764	-1.928398
40.51050	159.7764	-1.927927
40.56216	159.7767	-1.927521
40.61217	159.7761	-1.927261
40.66383	159.7767	-1.927224
40.71383	159.7762	-1.927200
40.76383	159.7765	-1.927227
40.81383	159.7755	-1.927413
40.86383	159.7764	-1.927785
40.91383	159.7766	-1.928257
40.96383	159.7765	-1.928702
41.01550	159.7765	-1.928936
41.06717	159.7769	-1.929163
41.11716	159.7770	-1.929687
41.16716	159.7778	-1.930250
41.21717	159.7775	-1.930948
41.26717	159.7775	-1.931433
41.31717	159.7774	-1.931737
41.36716	159.7770	-1.931941
41.41716	159.7774	-1.931995
41.46884	159.7769	-1.931915
41.52050	159.7765	-1.931883
41.57050	159.7765	-1.931812
41.62050	159.7767	-1.931641
41.67050	159.7764	-1.931824
41.72050	159.7764	-1.931866
41.76717	159.7763	-1.932138
41.81717	159.9091	-1.847500
41.86716	160.3799	-3.151674
41.91716	160.9828	-5.881434
41.96884	161.6952	-9.088531
42.02050	162.4719	-12.19746
42.07050	163.2699	-14.86624
42.12050	164.1058	-17.15131
42.17050	164.9698	-19.06497
42.22050	165.8572	-20.65302
42.27050	166.7631	-21.97177
42.32050	167.6856	-23.06621
42.37216	168.6508	-23.99938
42.42216	169.5962	-24.76183
42.47383	170.5812	-25.42800
42.52383	171.5406	-25.98555
42.57383	172.5060	-26.47400
42.62383	173.4765	-26.90353
42.67383	174.4486	-27.28360
42.72383	175.4253	-27.63205
42.77383	176.4034	-27.94998
42.82550	177.4172	-28.25830
42.87717	178.4311	-28.54844
42.92717	179.4145	-28.82935
42.97717	180.3987	-29.09836
43.02716	181.3837	-29.37837
43.07717	182.3691	-29.65808
43.12717	183.3541	-29.93952
43.17717	184.3399	-30.23738
43.22883	185.3580	-30.54725
43.27883	186.3440	-30.85298
43.33050	187.3620	-31.18018
43.38050	188.3478	-31.50854
43.43050	189.3319	-31.85665
43.48050	190.3166	-32.22743
43.53050	191.2988	-32.60804
43.58050	192.2830	-33.00975
43.63050	193.2649	-33.43538
43.68217	194.2789	-33.89176
43.73383	195.2909	-34.37266
43.78383	196.2698	-34.85697
43.83383	197.2470	-35.37794
43.88383	198.2239	-35.92736
43.93383	199.1986	-36.49960
43.98383	200.1712	-37.10989
44.03383	201.1431	-37.75750
44.08383	202.1139	-38.46116
44.13550	203.1142	-39.23389
44.18716	204.1116	-40.05357
44.23717	205.0751	-40.91409
44.28717	206.0346	-41.85788
44.33716	206.9899	-42.90338
44.38716	207.9389	-44.09509
44.43716	208.8793	-45.47904
44.48717	209.8104	-47.11328
44.53883	210.7589	-49.11466
44.58883	211.6568	-51.54294
44.64050	212.5620	-54.54590
44.69050	213.4162	-57.89938
44.74050	214.2527	-61.62502
44.79050	215.0758	-65.63196
44.84050	215.8889	-69.81720
44.89050	216.6973	-74.04284
44.94050	217.5110	-78.07114
44.99216	218.3762	-81.56000
45.04383	219.2905	-83.72103
45.09384	220.2582	-83.71844
45.14383	221.3293	-81.52750
45.19383	222.4822	-77.70369
45.24383	223.6927	-72.81114
45.29383	224.9485	-66.93440
45.34384	226.2371	-60.59353
45.39550	227.5474	-54.90006
45.44550	228.7714	-50.40442
45.49716	229.9906	-46.72208
45.54716	231.1344	-43.90369
45.59716	232.2476	-41.66937
45.64717	233.3369	-39.90806
45.69717	234.4066	-38.54842
45.74716	235.4627	-37.45947
45.79716	236.5079	-36.59838
45.84883	237.5775	-35.89850
45.90050	238.6398	-35.35562
45.95050	239.6621	-34.94496
46.00050	240.6788	-34.63582
46.05050	241.6931	-34.39035
46.10050	242.7047	-34.21310
46.15050	243.7122	-34.07481
46.20050	244.7210	-33.97541
46.25050	245.7270	-33.89756
46.30217	246.7647	-33.83885
46.35383	247.8022	-33.79534
46.40383	248.8051	-33.77030
46.45383	249.8082	-33.74900
46.50383	250.8110	-33.74340
46.55383	251.8120	-33.73955
46.60383	252.8138	-33.73735
46.65383	253.8157	-33.73733
46.70550	254.8488	-33.73853
46.75550	255.8502	-33.74296
46.80717	256.8845	-33.77582
46.85717	257.8848	-33.82774
46.90717	258.8842	-33.86604
46.95717	259.8843	-33.91094
47.00717	260.8842	-33.95856
47.05717	261.8828	-34.00470
47.10717	262.8824	-34.05467
47.15883	263.9148	-34.10459
47.21050	264.9487	-34.16328
47.26050	265.9475	-34.20937
47.31050	266.9482	-34.26059
47.36050	267.9467	-34.32404
47.41050	268.9450	-34.37910
47.46050	269.9444	-34.44006
47.51050	270.9439	-34.49020
47.56216	271.9758	-34.53766
47.61217	272.9754	-34.59966
47.66383	274.0088	-34.65130
47.71383	275.0072	-34.70878
47.76050	275.9392	-34.76338
47.81050	276.7446	-35.05508
47.86050	276.8274	-32.54026
47.91050	276.6102	-26.36060
47.96050	276.2140	-19.22467
48.01050	275.6969	-12.31843
48.06216	275.0690	-6.006481
48.11217	274.3876	-0.8295758
48.16383	273.6238	3.606235
48.21383	272.8374	7.132018
48.26383	272.0166	10.02498
48.31383	271.1623	12.39268
48.36383	270.2850	14.33884
48.41383	269.3883	15.93549
48.46383	268.4748	17.25630
48.51550	267.5170	18.37553
48.56717	266.5478	19.30926
48.61716	265.5990	20.05612
48.66716	264.6442	20.68740
48.71717	263.6820	21.21458
48.76717	262.7155	21.66108
48.81717	261.7445	22.03692
48.86716	260.7696	22.35437
48.91716	259.7920	22.62838
48.96884	258.7791	22.86229
49.02050	257.7630	23.07235
49.07050	256.7789	23.24182
49.12050	255.7921	23.38387
49.17050	254.8043	23.51739
49.22050	253.8164	23.63036
49.27050	252.8262	23.72960
49.32050	251.8363	23.81836
49.37216	250.8124	23.89206
49.42216	249.8214	23.95642
49.47383	248.7960	24.02056
49.52383	247.8043	24.07866
49.57383	246.8123	24.13361
49.62383	245.8195	24.17400
49.67383	244.8272	24.21417
49.72383	243.8334	24.25395
49.77383	242.8400	24.28116
49.82550	241.8130	24.30850
49.87717	240.7867	24.32947
49.92717	239.7916	24.35273
49.97717	238.7976	24.37825
50.02716	237.8026	24.39662
50.07717	236.8082	24.41152
50.12717	235.8138	24.43245
50.17717	234.8196	24.44248
50.22883	233.7916	24.45116
50.27883	232.7966	24.46136
50.33050	231.7694	24.47027
50.38050	230.7740	24.48112
50.43050	229.7784	24.49438
50.48050	228.7831	24.50534
50.53050	227.7889	24.52156
50.58050	226.7918	24.53994
50.63050	225.7960	24.54994
50.68217	224.7684	24.56309
50.73383	223.7394	24.57506
50.78383	222.7433	24.58465
50.83383	221.7478	24.59318
50.88383	220.7518	24.60164
50.93383	219.7560	24.61035
50.98383	218.7604	24.61988
51.03383	217.7650	24.62806
51.08383	216.7692	24.63507
51.13550	215.7389	24.64230
51.18716	214.7112	24.64860
51.23717	213.7150	24.65424
51.28716	212.7187	24.65980
51.33716	211.7228	24.66476
51.38716	210.7270	24.66939
51.43716	209.7311	24.67370
51.48717	208.7346	24.67784
51.53883	207.7054	24.68148
51.58883	206.7093	24.68483
51.64050	205.6798	24.68775
51.69050	204.6834	24.68942
51.74050	203.6866	24.69098
51.79050	202.6908	24.69207
51.84050	201.6946	24.69186
51.89050	200.6986	24.69102
51.94050	199.7025	24.68990
51.99216	198.6726	24.68891
52.04383	197.6426	24.68838
52.09384	196.6468	24.68783
52.14384	195.6496	24.68711
52.19384	194.6538	24.68683
52.24383	193.6571	24.68727
52.29383	192.6613	24.68742
52.34384	191.6646	24.68710
52.39550	190.6344	24.68680
52.44550	189.6383	24.68564
52.49717	188.6082	24.68515
52.54717	187.6119	24.68425
52.59716	186.6158	24.68286
52.64717	185.6190	24.68183
52.69717	184.6225	24.68052
52.74717	183.6251	24.67809
52.79717	182.6288	24.67490
52.84882	181.5984	24.67146
52.90050	180.5687	24.66790
52.95050	179.5718	24.66478
53.00050	178.5755	24.66292
53.05050	177.5793	24.66243
53.10050	176.5828	24.66368
53.15050	175.5862	24.66696
53.20050	174.5900	24.67571
53.25050	173.5942	24.68770
53.30217	172.5646	24.69776
53.35383	171.5346	24.70611
53.40383	170.5382	24.71910
53.45383	169.5436	24.73961
53.50383	168.5468	24.78240
53.55383	167.5536	24.86186
53.60383	166.5609	24.97125
53.65383	165.5724	25.16550
53.70550	164.5577	25.53053
53.75550	163.5878	26.17952
53.80717	162.6069	27.35744
53.85717	161.6901	29.25325
53.90717	160.8166	32.11203
53.95717	159.9938	35.99876
54.00717	159.2167	40.70966
54.05717	158.4675	45.83022
54.10717	157.7219	50.82034
54.15883	156.9297	55.32412
54.21050	156.0919	58.77502
54.26050	155.2251	60.87031
54.31050	154.2927	61.62801
54.36050	153.2972	61.12466
54.41050	152.2430	59.49387
54.46050	151.1386	56.97780
54.51050	149.9986	53.88130
54.56216	148.8031	50.41906
54.61217	147.6416	47.12776
54.66382	146.4503	43.98541
54.71382	145.3141	41.29687
54.76382	144.1944	38.96656
54.81382	143.0913	36.97254
54.86382	142.0053	35.26750
54.91382	140.9300	33.78780
54.96382	139.8690	32.56342
55.01550	138.7812	31.48856
55.06716	137.7036	30.57756
55.11716	136.6660	29.81518
55.16716	135.6355	29.16104
55.21717	134.6098	28.60012
55.26716	133.5877	28.11527
55.31716	132.5676	27.69672
55.36716	131.5522	27.32979
55.41716	130.5375	26.99894
55.46884	129.4918	26.69915
55.52050	128.4475	26.43436
55.57050	127.4383	26.20664
55.62050	126.4299	26.00016
55.67050	125.4226	25.80434
55.72050	124.4162	25.62499
55.77050	123.4109	25.46117
55.82050	122.4056	25.30482
55.87217	121.3684	25.15645
55.92217	120.3642	25.02479
55.97382	119.3281	24.89574
56.02383	118.3245	24.78440
56.07383	117.3224	24.67686
56.12383	116.3200	24.57829
56.17383	115.3186	24.47544
56.22382	114.3158	24.38410
56.27383	113.3142	24.29019
56.32550	112.2793	24.19993
56.37717	111.2438	24.10913
56.42717	110.2426	24.02358
56.47717	109.2408	23.93517
56.52717	108.2393	23.85764
56.57717	107.2381	23.77256
56.62717	106.2376	23.69058
56.67717	105.2367	23.60950
56.72883	104.2024	23.53002
56.77883	103.2012	23.45472
56.83050	102.1667	23.38350
56.88050	101.1664	23.30838
56.93050	100.1666	23.23689
56.98050	99.16464	23.16252
57.03050	98.16516	23.08587
57.08050	97.16518	23.02178
57.13050	96.16476	22.95254
57.18217	95.13042	22.87727
57.23383	94.09731	22.80137
57.28383	93.09603	22.72357
57.33383	92.09531	22.65218
57.38383	91.09541	22.57609
57.43383	90.09387	22.49665
57.48383	89.09249	22.40277
57.53383	88.09018	22.31025
57.58383	87.08884	22.24289
57.63550	86.05500	22.16470
57.68716	85.02028	22.08594
57.73717	84.01938	22.01555
57.78716	83.01874	21.94577
57.83716	82.01684	21.87578
57.88716	81.01660	21.80273
57.93716	80.01592	21.72727
57.98717	79.01553	21.65898
58.03882	77.98106	21.59266
58.08882	76.98138	21.52415
58.14050	75.94740	21.45794
58.19050	74.94749	21.39735
58.24050	73.94659	21.33380
58.29050	72.94634	21.26946
58.34050	71.94630	21.20386
58.39050	70.95995	21.45420
58.44050	69.95952	21.33763
58.49216	68.92460	21.23123
58.54382	67.88882	21.14465
58.59384	66.88794	21.06032
58.64384	65.88826	20.98502
58.69384	64.88640	20.90948
58.74382	63.88535	20.84121
58.79382	62.88476	20.75921
58.84384	61.88331	20.67855
58.89550	60.84786	20.58839
58.94550	59.84551	20.50275
58.99717	58.81050	20.41984
59.04717	57.80982	20.33771
59.09716	56.80740	20.25556
59.14717	55.80645	20.18024
59.19717	54.80480	20.10337
59.24717	53.80350	20.02911
59.29717	52.80242	19.94799
59.34882	51.76760	19.86699
59.40050	50.73322	19.78435
59.45050	49.73264	19.71529
59.50050	48.73152	19.64389
59.55050	47.72973	19.57166
59.60050	46.72855	19.49748
59.65050	45.72703	19.43096
59.70050	44.72530	19.35480
59.75050	43.72500	19.28944
59.80217	42.69022	19.21511
59.85383	41.65533	19.13976
59.90383	40.65353	19.06792
59.95383	39.65188	18.99208
60.00383	38.65027	18.91298
60.05383	37.64905	18.82480
60.10383	36.64630	18.73322
60.15383	35.64298	18.64765
60.20550	34.60715	18.55619
60.25550	33.60454	18.46232
60.30717	32.56830	18.36364
60.35717	31.56597	18.26736
60.40717	30.56224	18.17134
60.45717	29.55988	18.08588
60.50717	28.55594	17.98646
60.55717	27.55524	17.88744
60.60717	26.55180	17.78731
60.65883	25.51482	17.68447
60.71050	24.47722	17.57774
60.75550	23.57399	17.48160
60.80717	22.70282	17.66324
60.85717	22.58089	16.81201
60.90717	22.76290	13.57001
60.95717	23.13848	9.623719
61.00717	23.64584	5.556670
61.05717	24.25208	1.834356
61.10717	24.93587	-1.411101
61.15883	25.70690	-4.235360
61.21050	26.52800	-6.567275
61.26050	27.36115	-8.418785
61.31050	28.22454	-9.932121
61.36050	29.11210	-11.17653
61.41050	30.01811	-12.19798
61.46050	30.93864	-13.03819
61.51050	31.87345	-13.74064
61.56216	32.84829	-14.34911
61.61217	33.80102	-14.85133
61.66382	34.79180	-15.29403
61.71382	35.75778	-15.65476
61.76382	36.72865	-15.97206
61.81382	37.70250	-16.25462
61.86382	38.67931	-16.50037
61.91382	39.65830	-16.71978
61.96382	40.64111	-16.91589
62.01550	41.65842	-17.09922
62.06716	42.67656	-17.27176
62.11716	43.66370	-17.42107
62.16716	44.65289	-17.56415
62.21717	45.64240	-17.70005
62.26716	46.63224	-17.82449
62.31716	47.62313	-17.94577
62.36716	48.61574	-18.06826
62.41716	49.60792	-18.17949
62.46884	50.63447	-18.29355
62.52050	51.66172	-18.40774
62.57050	52.65410	-18.51035
62.62050	53.65026	-18.60782
62.67050	54.64518	-18.69772
62.72050	55.64234	-18.78840
62.77050	56.63800	-18.87933
62.82050	57.63348	-18.96934
62.87217	58.66310	-19.06666
62.92217	59.65921	-19.15413
62.97382	60.68837	-19.24517
63.02383	61.68444	-19.33495
63.07383	62.68188	-19.43066
63.12383	63.67950	-19.51987
63.17383	64.67541	-19.60881
63.22382	65.67228	-19.68713
63.27383	66.67007	-19.77163
63.32550	67.69972	-19.86312
63.37717	68.73072	-19.95253
63.42717	69.72714	-20.03502
63.47717	70.72546	-20.11811
63.52717	71.72165	-20.19954
63.57717	72.71861	-20.28661
63.62717	73.71522	-20.37303
63.67717	74.71184	-20.45728
63.72883	75.74232	-20.54698
63.77883	76.73980	-20.63479
63.83050	77.76987	-20.72369
63.88050	78.76746	-20.80849
63.93050	79.76352	-20.89838
63.98050	80.76000	-20.98872
64.03050	81.75731	-21.08124
64.08050	82.75379	-21.17369
64.13050	83.75060	-21.26611
64.18218	84.77989	-21.36230
64.23383	85.80995	-21.46019
64.28384	86.80714	-21.55453
64.33384	87.80402	-21.65184
64.38384	88.80139	-21.74479
64.43384	89.79794	-21.83574
64.48383	90.79402	-21.93262
64.53384	91.79292	-22.02628
64.58384	92.78924	-22.12092
64.63550	93.81945	-22.21723
64.68717	94.85012	-22.31496
64.73717	95.84686	-22.40745
64.78717	96.84364	-22.50400
64.83716	97.84046	-22.58801
64.88717	98.83824	-22.68060
64.93717	99.83534	-22.76546
64.98717	100.8329	-22.85576
65.03882	101.8625	-22.95320
65.08884	102.8593	-23.04680
65.14050	103.8889	-23.14480
65.19050	104.8858	-23.24027
65.24050	105.8819	-23.34292
65.29050	106.8788	-23.44032
65.34050	107.8753	-23.54161
65.39050	108.8717	-23.64311
65.44050	109.8688	-23.73818
65.49218	110.8992	-23.84686
65.54384	111.9291	-23.94967
65.59384	112.9259	-24.05164
65.64384	113.9230	-24.15268
65.69384	114.9191	-24.24620
65.74384	115.9158	-24.35167
65.79384	116.9130	-24.45162
65.84384	117.9084	-24.54632
65.89550	118.9386	-24.65482
65.94550	119.9360	-24.76163
65.99718	120.9659	-24.87178
66.04718	121.9620	-24.98660
66.09718	122.9579	-25.09920
66.14718	123.9539	-25.21277
66.19718	124.9498	-25.33122
66.24718	125.9463	-25.44936
66.29718	126.9422	-25.56070
66.34882	127.9728	-25.67444
66.40050	129.0020	-25.79109
66.45050	129.9985	-25.90426
66.50050	130.9948	-26.02224
66.55050	131.9917	-26.14379
66.60050	132.9874	-26.26550
66.65050	133.9828	-26.37879
66.70050	134.9773	-26.50484
66.75050	135.9728	-26.63684
66.80218	137.0020	-26.77166
66.85384	138.0294	-26.91129
66.90384	139.0255	-27.04449
66.95384	140.0211	-27.18250
67.00384	141.0161	-27.32210
67.05384	142.0114	-27.45864
67.10384	143.0067	-27.60130
67.15384	144.0015	-27.74221
67.20550	145.0296	-27.88850
67.25550	146.0244	-28.02576
67.30718	147.0516	-28.17254
67.35718	148.0466	-28.31261
67.40718	149.0421	-28.45642
67.45718	150.0364	-28.59492
67.50718	151.0308	-28.74104
67.55718	152.0248	-28.88529
67.60718	153.0199	-29.03760
67.65884	154.0475	-29.19730
67.71050	155.0749	-29.35675
67.76050	156.0686	-29.51550
67.81050	157.0639	-29.67802
67.86050	158.0577	-29.84129
67.91050	159.0524	-30.00460
67.96050	160.0454	-30.16333
68.01050	161.0405	-30.31841
68.06216	162.0688	-30.47528
68.11218	163.0642	-30.60318
68.16382	164.0933	-30.71738
68.21384	165.0911	-30.81453
68.26384	166.0894	-30.88470
68.31384	167.0878	-30.94844
68.36384	168.0875	-31.00472
68.41382	169.0866	-31.04228
68.46384	170.0862	-31.08718
68.51550	171.1183	-31.14679
68.56718	172.1509	-31.21543
68.61718	173.1489	-31.29875
68.66718	174.1471	-31.38677
68.71718	175.1446	-31.47917
68.76716	176.1409	-31.58948
68.81718	177.1368	-31.71553
68.86718	178.1318	-31.85618
68.91718	179.1257	-32.01554
68.96884	180.1523	-32.19806
69.02050	181.1784	-32.41128
69.07050	182.1685	-32.63820
69.12050	183.1598	-32.88453
69.17050	184.1500	-33.15936
69.22050	185.1380	-33.46270
69.27050	186.1246	-33.79698
69.32050	187.1095	-34.15590
69.37218	188.1252	-34.58105
69.42218	189.1056	-35.04952
69.47384	190.1158	-35.58318
69.52384	191.0911	-36.16955
69.57384	192.0641	-36.81052
69.62384	193.0334	-37.50726
69.67384	194.0034	-38.23347
69.72384	194.9698	-38.97350
69.77384	195.9369	-39.73470
69.82550	196.9340	-40.53425
69.87718	197.9321	-41.36122
69.92718	198.8959	-42.19160
69.97718	199.8580	-43.08444
70.02718	200.8160	-44.06186
70.07718	201.7701	-45.12776
70.12718	202.7198	-46.29011
70.17718	203.6659	-47.53684
70.22884	204.6399	-48.89770
70.27884	205.5807	-50.23821
70.33050	206.5527	-51.60257
70.38050	207.4973	-52.81686
70.43050	208.4511	-53.76437
70.48050	209.4247	-54.22590
70.53050	210.4293	-53.84968
70.58050	211.4844	-52.34152
70.63050	212.5889	-49.78621
70.68218	213.7644	-46.67315
70.73384	214.9438	-43.63706
70.78384	216.0705	-41.09446
70.83384	217.1757	-39.01683
70.88384	218.2623	-37.35438
70.93384	219.3291	-36.02151
70.98384	220.3844	-34.96810
71.03384	221.4278	-34.13900
71.08384	222.4620	-33.48468
71.13550	223.5247	-32.95770
71.18718	224.5804	-32.55360
71.23718	225.5980	-32.23832
71.28718	226.6113	-32.00139
71.33716	227.6234	-31.82146
71.38718	228.6318	-31.68296
71.43718	229.6384	-31.59281
71.48718	230.6438	-31.52759
71.53882	231.6811	-31.48672
71.58884	232.6848	-31.47108
71.64050	233.7210	-31.46856
71.69050	234.7238	-31.46743
71.74050	235.7253	-31.46875
71.79050	236.7267	-31.47422
71.84050	237.7278	-31.48783
71.89050	238.7282	-31.51390
71.94050	239.7288	-31.55182
71.99218	240.7617	-31.60219
72.04384	241.7953	-31.64994
72.09384	242.7945	-31.70381
72.14384	243.7957	-31.75029
72.19384	244.7955	-31.79791
72.24384	245.7949	-31.84022
72.29384	246.7954	-31.88796
72.34384	247.7947	-31.92992
72.39550	248.8272	-31.97474
72.44550	249.8268	-32.01588
72.49718	250.8590	-32.06648
72.54718	251.8583	-32.11735
72.59718	252.8577	-32.17053
72.64718	253.8567	-32.21816
72.69718	254.8565	-32.26354
72.74718	255.8555	-32.31318
72.79718	256.8558	-32.37652
72.84882	257.8880	-32.43662
72.90050	258.9202	-32.49314
72.95050	259.9186	-32.54808
73.00050	260.9184	-32.60564
73.05050	261.9166	-32.66728
73.10050	262.9159	-32.73212
73.15050	263.9154	-32.79132
73.20050	264.9137	-32.85660
73.25050	265.9122	-32.92100
73.30218	266.9460	-32.98755
73.35384	267.9776	-33.05264
73.40384	268.9752	-33.11405
73.45384	269.9738	-33.18826
73.50384	270.9725	-33.25669
73.55384	271.9702	-33.32154
-2.000000	5.000000	0.0000000