File: 2-C1(0.8mol%)+C20(0.6mol%)/matlab/160-1.txt
CLOSED
Version	1.0
Language	English
Mode	Standard
Run	7
RunSerial	11884
Instrument	DSC Q2000 V24.11 Build 124
Module	DSC Standard Cell RC
Operator	Jing
File	\\Ae520-1454\ta\Data\DSC\UQ Composites\Nan\C1(7.5)+C20P(3)+CL(Hotplate MixtureAB)\160-1
ProcName	Ramp
InstSerial	2000-0883
AutoSerial	1293
Sample	Iso160-1
Size	42.0000	mg
PanMass	Not available
PanResist	Automatic Automatic  K/W
PanFactor	Default Default
Method	Ramp
Comment
Xcomment	Pan: Tzero Aluminum Hermetic
Xcomment	Gas1: Nitrogen 50.0 ml/min
Xcomment	Gas2: Nitrogen 50.0 ml/min
Text
Exotherm	UP
Kcell	1.05230
Cpconst	Standard: 0.938
Calib	-38.6961
TempCal	1	pts	157.46	156.60
TzeroDt	-87.6168 -0.0009 -1.4231
TzeroDtz	-87.6168 0.0057 6.9570
InstCalFile	Tzero: \\Ae520-1454\ta\Data\DSC\Calibration\2017\CALIBRATION\1562_RCS (90)_05_18_2017 10_50_44.TZR
InstCalFile	Baseline: \\Ae520-1454\ta\Data\DSC\Calibration\2017\2017-05-17_Calibration.001
InstCalFile	Sapphire: \\Ae520-1454\ta\Data\DSC\Calibration\2017\2017-05-17_Saphire.001
InstCalDate	Tzero 2017-05-18 Time 10:50:44
TempRange	-87.39 to 398.39 °C at 10.00 °C/min Heat Only
AutoZero	Delta T Offset 0.000 uV
AutoZero	Delta T0 Offset 0.000 uV
MultiptCal	0
MultiPtDesc	0) Not set
AutoCellConst	Calibration Date 2017-05-18 16:59:28
Controls	Gas 1  Event Off  Sampling 0.2
Cell#	RC-01562
CoolingUnit	RCS (90)
SelHeatFlow	Heat Flow T4 (mW)
AutoLidII	Installed
AutoAnalysis	Off
MacroFile
Nsig	3
Sig1	Time (min)
Sig2	Temperature (°C)
Sig3	Heat Flow (mW)
Date	2017-06-22
Time	23:00:54
OrgMethod	1: Equilibrate at 20.00 °C
OrgMethod	2: Ramp 80.00 °C/min to 160.00 °C
OrgMethod	3: Mark end of cycle 1
OrgMethod	4: Isothermal for 40.00 min
OrgMethod	5: Mark end of cycle 2
OrgMethod	6: Ramp 20.00 °C/min to 280.00 °C
OrgMethod	7: Mark end of cycle 3
OrgMethod	8: Ramp 20.00 °C/min to 20.00 °C
OrgMethod	9: Mark end of cycle 4
OrgMethod	10: Ramp 20.00 °C/min to 280.00 °C
OrgMethod	11: Mark end of cycle 5
OrgFile	C:\Users\jarra\Desktop\DSC\2-C1(0.8mol%)+C20(0.6mol%)\160-1
StartOfData
4.99994E-4	20.04211	0.4847766
0.05216665	20.24412	0.8704848
0.1038333	21.86262	0.4036754
0.1538333	24.28591	-5.205320
0.2038333	27.02489	-13.05527
0.2538334	30.02364	-21.32826
0.3038333	33.20547	-29.26314
0.3538333	36.53020	-36.41810
0.4038334	39.96956	-42.67569
0.4555000	43.62014	-48.26137
0.5055000	47.22024	-53.06653
0.5571668	50.98437	-57.72739
0.6071668	54.66894	-61.86704
0.6571668	58.33909	-67.07758
0.7071668	61.99578	-72.13870
0.7571668	65.67262	-77.25310
0.8071668	69.33430	-83.17347
0.8571668	72.86388	-93.04996
0.9088334	76.10742	-112.4885
0.9604999	78.92720	-137.9811
1.010500	81.58662	-162.1104
1.060500	84.27961	-186.5176
1.110500	86.94215	-210.8478
1.160500	89.89694	-228.5422
1.210500	93.38306	-241.9678
1.260500	97.46753	-246.1070
1.312167	101.6867	-241.6045
1.362166	105.7674	-230.9932
1.413834	110.5521	-212.2193
1.463833	115.5272	-195.8415
1.513833	120.3407	-182.5924
1.563833	124.9824	-172.4077
1.613833	129.5224	-163.9034
1.663834	133.9533	-157.3843
1.713833	138.2934	-152.4792
1.763833	142.5659	-148.7106
1.813834	146.4228	-146.3019
1.863834	148.7511	-141.0242
1.913834	150.4537	-128.7128
1.963833	151.8322	-114.7290
2.015500	152.9938	-100.4559
2.067166	153.9522	-87.63839
2.117167	154.7227	-76.90450
2.167167	155.3646	-67.83076
2.217167	155.9020	-60.23568
2.267166	156.3507	-53.91753
2.317166	156.7272	-48.66917
2.367167	157.0425	-44.30578
2.417167	157.3077	-40.67326
2.468834	157.5382	-37.55056
2.520500	157.7307	-34.95633
2.570500	157.8882	-32.86103
2.620500	158.0204	-31.10340
2.670500	158.1345	-29.61484
2.720500	158.2301	-28.35211
2.770500	158.3129	-27.27652
2.820500	158.3843	-26.35444
2.872167	158.4464	-25.53092
2.922167	158.4994	-24.83603
2.973833	158.5477	-24.20974
3.023833	158.5873	-23.67002
3.073833	158.6231	-23.18764
3.123834	158.6554	-22.74288
3.173834	158.6849	-22.33852
3.223834	158.7112	-21.95553
3.273834	158.7354	-21.59675
3.325500	158.7604	-21.23519
3.377167	158.7821	-20.88664
3.427167	158.8032	-20.55524
3.477167	158.8234	-20.21935
3.527167	158.8434	-19.88761
3.577167	158.8634	-19.54608
3.627167	158.8822	-19.20047
3.677167	158.9024	-18.84966
3.728833	158.9227	-18.46399
3.778833	158.9438	-18.07578
3.830500	158.9656	-17.66158
3.880500	158.9874	-17.23158
3.930500	159.0103	-16.78530
3.980500	159.0342	-16.32858
4.030500	159.0587	-15.85767
4.080500	159.0828	-15.37261
4.130500	159.1079	-14.88007
4.182167	159.1339	-14.35591
4.233834	159.1609	-13.80851
4.283834	159.1889	-13.25641
4.333834	159.2172	-12.67719
4.383834	159.2474	-12.07106
4.433834	159.2777	-11.44987
4.483834	159.3091	-10.82547
4.533834	159.3410	-10.20116
4.583834	159.3713	-9.573047
4.635500	159.4044	-8.917374
4.687167	159.4375	-8.255188
4.737167	159.4708	-7.575995
4.787167	159.5070	-6.829546
4.837167	159.5451	-6.050370
4.887167	159.5823	-5.315754
4.937167	159.6159	-4.658868
4.987167	159.6466	-4.078906
5.038834	159.6741	-3.553687
5.088834	159.6976	-3.114508
5.140500	159.7181	-2.723204
5.190500	159.7361	-2.400627
5.240500	159.7512	-2.117534
5.290500	159.7648	-1.873303
5.340500	159.7754	-1.657378
5.390500	159.7856	-1.468851
5.440500	159.7947	-1.305165
5.492168	159.8025	-1.154086
5.543832	159.8099	-1.017710
5.593834	159.8173	-0.8983546
5.643832	159.8228	-0.7881794
5.693832	159.8286	-0.6855603
5.743834	159.8334	-0.5904347
5.793832	159.8389	-0.4963553
5.843834	159.8428	-0.4062514
5.895500	159.8486	-0.3179367
5.945500	159.8527	-0.2317394
5.997168	159.8584	-0.1470832
6.047168	159.8619	-.07133674
6.097168	159.8661	.009782242
6.147168	159.8692	0.07981853
6.197168	159.8730	0.1492142
6.247168	159.8776	0.2189680
6.297168	159.8802	0.2879880
6.348832	159.8842	0.3538222
6.400500	159.8882	0.4155356
6.450500	159.8908	0.4816305
6.500500	159.8946	0.5470623
6.550500	159.8978	0.6111458
6.600500	159.9005	0.6745025
6.650500	159.9042	0.7384826
6.700500	159.9075	0.8024500
6.750500	159.9108	0.8675399
6.802168	159.9148	0.9344952
6.853832	159.9187	1.003214
6.903832	159.9225	1.073061
6.953832	159.9252	1.142579
7.003832	159.9291	1.213255
7.053834	159.9326	1.283956
7.103832	159.9361	1.351700
7.153832	159.9398	1.425450
7.205500	159.9438	1.502955
7.255500	159.9476	1.577576
7.307166	159.9520	1.656195
7.357168	159.9558	1.736141
7.407166	159.9598	1.813873
7.457168	159.9634	1.895979
7.507168	159.9668	1.976513
7.557166	159.9722	2.059729
7.607168	159.9753	2.140752
7.658832	159.9809	2.227714
7.710500	159.9845	2.318925
7.760500	159.9900	2.404196
7.810500	159.9938	2.494138
7.860500	159.9978	2.582586
7.910500	160.0026	2.672928
7.960500	160.0076	2.764209
8.010500	160.0117	2.854269
8.062166	160.0162	2.948682
8.112168	160.0215	3.044661
8.163834	160.0259	3.139840
8.213834	160.0316	3.237631
8.263832	160.0362	3.330207
8.313834	160.0412	3.430510
8.363834	160.0457	3.525765
8.413834	160.0502	3.620608
8.463834	160.0559	3.723256
8.515500	160.0610	3.822375
8.567166	160.0659	3.926379
8.617166	160.0715	4.026796
8.667168	160.0759	4.126480
8.717168	160.0812	4.227950
8.767168	160.0855	4.327600
8.817166	160.0909	4.425657
8.867166	160.0960	4.523806
8.917168	160.1002	4.625435
8.968834	160.1063	4.727076
9.020500	160.1111	4.830838
9.070500	160.1157	4.926696
9.120499	160.1208	5.028378
9.170500	160.1264	5.128614
9.220500	160.1306	5.229828
9.270500	160.1372	5.338038
9.320500	160.1419	5.452860
9.372168	160.1479	5.578332
9.422168	160.1540	5.711137
9.473832	160.1612	5.855914
9.523834	160.1689	6.007955
9.573834	160.1766	6.175981
9.623834	160.1851	6.355722
9.673832	160.1943	6.549062
9.723832	160.2052	6.756330
9.773834	160.2161	6.977549
9.825500	160.2273	7.219924
9.877168	160.2395	7.467990
9.927168	160.2521	7.716850
9.977168	160.2636	7.973745
10.02717	160.2775	8.240215
10.07717	160.2911	8.508276
10.12717	160.3044	8.788754
10.17717	160.3183	9.068457
10.22883	160.3323	9.365516
10.27883	160.3470	9.659282
10.33050	160.3622	9.973199
10.38050	160.3774	10.29074
10.43050	160.3939	10.61139
10.48050	160.4096	10.94222
10.53050	160.4266	11.28023
10.58050	160.4424	11.61529
10.63050	160.4599	11.95600
10.68217	160.4769	12.30189
10.73383	160.4941	12.63998
10.78383	160.5093	12.95634
10.83383	160.5250	13.26376
10.88383	160.5397	13.55294
10.93383	160.5541	13.82568
10.98383	160.5663	14.08220
11.03383	160.5788	14.31979
11.08383	160.5901	14.53919
11.13550	160.6010	14.74916
11.18716	160.6110	14.94179
11.23717	160.6196	15.11328
11.28717	160.6274	15.26783
11.33717	160.6354	15.41226
11.38717	160.6413	15.53874
11.43716	160.6474	15.65560
11.48717	160.6533	15.76337
11.53883	160.6579	15.86035
11.58883	160.6626	15.94702
11.64050	160.6661	16.02319
11.69050	160.6704	16.08397
11.74050	160.6737	16.12984
11.79050	160.6752	16.16599
11.84050	160.6765	16.18740
11.89050	160.6778	16.19658
11.94050	160.6778	16.19994
11.99216	160.6776	16.19794
12.04384	160.6756	16.16966
12.09383	160.6726	16.10347
12.14383	160.6699	16.02914
12.19383	160.6657	15.93516
12.24384	160.6601	15.83267
12.29384	160.6552	15.71176
12.34383	160.6487	15.57847
12.39550	160.6413	15.42560
12.44550	160.6338	15.26633
12.49717	160.6248	15.09213
12.54717	160.6156	14.90924
12.59717	160.6071	14.71734
12.64717	160.5973	14.51600
12.69717	160.5869	14.30660
12.74717	160.5759	14.09409
12.79717	160.5645	13.86990
12.84883	160.5538	13.63713
12.90050	160.5424	13.40124
12.95050	160.5306	13.17298
13.00050	160.5192	12.93604
13.05050	160.5075	12.70151
13.10050	160.4958	12.47186
13.15050	160.4845	12.24171
13.20050	160.4735	12.00808
13.25050	160.4615	11.78247
13.30217	160.4505	11.54830
13.35383	160.4389	11.31851
13.40383	160.4292	11.09854
13.45383	160.4183	10.88806
13.50383	160.4088	10.68244
13.55383	160.3981	10.48018
13.60383	160.3892	10.28401
13.65383	160.3801	10.09909
13.70550	160.3708	9.909108
13.75550	160.3628	9.737053
13.80717	160.3543	9.566351
13.85716	160.3460	9.407871
13.90717	160.3386	9.258541
13.95717	160.3324	9.116947
14.00717	160.3251	8.985714
14.05717	160.3194	8.860678
14.10716	160.3131	8.747855
14.15883	160.3076	8.631598
14.21050	160.3025	8.523644
14.26050	160.2969	8.427889
14.31050	160.2918	8.329492
14.36050	160.2864	8.231964
14.41050	160.2816	8.133851
14.46050	160.2770	8.029186
14.51050	160.2708	7.921637
14.56216	160.2651	7.800906
14.61217	160.2593	7.677018
14.66383	160.2519	7.544579
14.71383	160.2452	7.406247
14.76383	160.2376	7.263958
14.81383	160.2316	7.116269
14.86383	160.2241	6.959155
14.91383	160.2168	6.800176
14.96383	160.2084	6.640380
15.01550	160.2012	6.472060
15.06716	160.1929	6.298440
15.11716	160.1848	6.132652
15.16716	160.1775	5.963516
15.21716	160.1682	5.796864
15.26717	160.1602	5.627930
15.31716	160.1520	5.458567
15.36716	160.1434	5.292246
15.41716	160.1350	5.130184
15.46884	160.1260	4.957174
15.52050	160.1178	4.791515
15.57050	160.1100	4.627716
15.62050	160.1013	4.469109
15.67050	160.0932	4.310440
15.72050	160.0855	4.156064
15.77050	160.0780	4.005808
15.82050	160.0702	3.857540
15.87217	160.0631	3.708322
15.92217	160.0554	3.562096
15.97384	160.0480	3.420095
16.02383	160.0416	3.284726
16.07383	160.0356	3.146992
16.12383	160.0278	3.016994
16.17383	160.0225	2.885390
16.22383	160.0155	2.754695
16.27383	160.0086	2.628813
16.32550	160.0030	2.502463
16.37716	159.9961	2.378262
16.42716	159.9906	2.257291
16.47716	159.9854	2.140137
16.52716	159.9794	2.022812
16.57716	159.9738	1.906619
16.62716	159.9679	1.794769
16.67716	159.9634	1.683073
16.72883	159.9576	1.568547
16.77883	159.9524	1.464269
16.83050	159.9462	1.357220
16.88050	159.9423	1.256893
16.93050	159.9378	1.155680
16.98050	159.9322	1.060596
17.03050	159.9284	0.9634937
17.08050	159.9234	0.8745701
17.13050	159.9200	0.7863991
17.18216	159.9153	0.6962463
17.23383	159.9114	0.6123810
17.28383	159.9072	0.5328388
17.33383	159.9028	0.4593008
17.38383	159.8998	0.3840468
17.43383	159.8951	0.3150266
17.48383	159.8924	0.2459947
17.53383	159.8884	0.1794305
17.58383	159.8857	0.1116251
17.63550	159.8824	0.05177463
17.68716	159.8793	-.01291162
17.73716	159.8770	-.07209634
17.78717	159.8734	-0.1281044
17.83716	159.8704	-0.1807806
17.88716	159.8673	-0.2305312
17.93716	159.8659	-0.2813346
17.98716	159.8620	-0.3276700
18.03883	159.8600	-0.3748656
18.08883	159.8571	-0.4202738
18.14050	159.8548	-0.4652142
18.19050	159.8529	-0.5058957
18.24050	159.8503	-0.5443387
18.29050	159.8493	-0.5834570
18.34050	159.8462	-0.6208634
18.39050	159.8451	-0.6546656
18.44050	159.8433	-0.6912149
18.49216	159.8407	-0.7238865
18.54383	159.8384	-0.7572900
18.59383	159.8379	-0.7921112
18.64383	159.8358	-0.8236470
18.69383	159.8351	-0.8536034
18.74383	159.8340	-0.8820141
18.79383	159.8336	-0.9103870
18.84383	159.8322	-0.9394100
18.89550	159.8309	-0.9665174
18.94550	159.8297	-0.9899670
18.99716	159.8286	-1.014016
19.04716	159.8268	-1.036278
19.09716	159.8264	-1.056339
19.14716	159.8255	-1.075802
19.19716	159.8242	-1.093900
19.24716	159.8235	-1.112745
19.29716	159.8217	-1.129318
19.34883	159.8209	-1.147150
19.40050	159.8202	-1.166698
19.45050	159.8188	-1.182130
19.50050	159.8172	-1.198035
19.55050	159.8175	-1.213670
19.60050	159.8156	-1.230678
19.65050	159.8150	-1.244942
19.70050	159.8143	-1.260418
19.75050	159.8128	-1.276452
19.80216	159.8124	-1.290273
19.85383	159.8113	-1.306644
19.90383	159.8110	-1.322144
19.95383	159.8102	-1.335052
20.00383	159.8102	-1.346245
20.05383	159.8098	-1.357828
20.10383	159.8092	-1.369867
20.15383	159.8079	-1.381986
20.20550	159.8074	-1.393375
20.25550	159.8073	-1.407431
20.30716	159.8072	-1.419685
20.35716	159.8066	-1.431176
20.40716	159.8057	-1.441867
20.45716	159.8046	-1.452317
20.50716	159.8056	-1.463076
20.55716	159.8046	-1.473190
20.60716	159.8040	-1.482632
20.65883	159.8038	-1.492221
20.71050	159.8031	-1.501512
20.76050	159.8020	-1.510332
20.81050	159.8016	-1.518946
20.86050	159.8012	-1.527361
20.91050	159.8000	-1.535587
20.96050	159.7999	-1.543782
21.01050	159.7997	-1.551915
21.06216	159.7994	-1.560127
21.11216	159.7991	-1.567847
21.16383	159.7994	-1.575686
21.21383	159.7990	-1.583667
21.26383	159.7981	-1.591204
21.31383	159.7980	-1.598970
21.36383	159.7982	-1.606616
21.41383	159.7981	-1.613991
21.46383	159.7981	-1.621556
21.51550	159.7979	-1.629364
21.56716	159.7975	-1.636518
21.61716	159.7968	-1.643144
21.66716	159.7971	-1.649674
21.71716	159.7974	-1.655723
21.76716	159.7966	-1.661715
21.81716	159.7971	-1.667281
21.86716	159.7947	-1.672488
21.91716	159.7954	-1.677379
21.96883	159.7944	-1.682638
22.02050	159.7942	-1.687752
22.07050	159.7937	-1.692430
22.12050	159.7934	-1.697182
22.17050	159.7937	-1.701918
22.22050	159.7923	-1.706870
22.27050	159.7933	-1.711997
22.32050	159.7924	-1.717441
22.37216	159.7924	-1.723087
22.42216	159.7922	-1.728611
22.47383	159.7929	-1.734775
22.52383	159.7922	-1.740839
22.57383	159.7916	-1.746892
22.62383	159.7926	-1.753016
22.67383	159.7916	-1.758923
22.72383	159.7922	-1.764246
22.77383	159.7918	-1.769319
22.82550	159.7913	-1.773899
22.87716	159.7911	-1.778238
22.92717	159.7895	-1.782233
22.97716	159.7906	-1.785966
23.02717	159.7901	-1.789826
23.07716	159.7902	-1.793761
23.12716	159.7904	-1.798134
23.17717	159.7890	-1.802711
23.22883	159.7894	-1.807747
23.27883	159.7889	-1.812730
23.33050	159.7892	-1.817539
23.38050	159.7883	-1.822159
23.43050	159.7876	-1.826952
23.48050	159.7879	-1.831971
23.53050	159.7866	-1.836820
23.58050	159.7869	-1.841836
23.63050	159.7868	-1.846844
23.68216	159.7861	-1.851710
23.73383	159.7863	-1.856594
23.78383	159.7860	-1.861190
23.83383	159.7849	-1.865744
23.88383	159.7853	-1.870687
23.93383	159.7848	-1.875522
23.98383	159.7842	-1.880698
24.03383	159.7837	-1.885965
24.08383	159.7846	-1.891355
24.13550	159.7840	-1.896838
24.18716	159.7842	-1.902426
24.23716	159.7840	-1.907740
24.28717	159.7839	-1.913161
24.33716	159.7835	-1.918716
24.38716	159.7831	-1.923934
24.43716	159.7834	-1.928990
24.48716	159.7836	-1.934156
24.53883	159.7826	-1.939142
24.58883	159.7831	-1.943738
24.64050	159.7828	-1.948321
24.69050	159.7821	-1.952372
24.74050	159.7816	-1.956377
24.79050	159.7809	-1.959932
24.84050	159.7808	-1.963609
24.89050	159.7798	-1.967291
24.94050	159.7807	-1.970755
24.99216	159.7796	-1.974361
25.04383	159.7793	-1.978194
25.09383	159.7796	-1.982010
25.14383	159.7801	-1.985783
25.19383	159.7790	-1.989670
25.24383	159.7799	-1.993574
25.29383	159.7791	-1.997777
25.34383	159.7807	-2.002118
25.39550	159.7801	-2.006751
25.44550	159.7798	-2.011073
25.49716	159.7788	-2.015313
25.54716	159.7796	-2.019186
25.59716	159.7800	-2.022806
25.64716	159.7799	-2.026418
25.69717	159.7800	-2.029624
25.74716	159.7801	-2.032665
25.79716	159.7783	-2.035092
25.84883	159.7786	-2.037462
25.90050	159.7782	-2.039776
25.95050	159.7781	-2.041685
26.00050	159.7776	-2.043723
26.05050	159.7777	-2.045709
26.10050	159.7770	-2.047662
26.15050	159.7777	-2.049936
26.20050	159.7762	-2.052333
26.25050	159.7770	-2.055054
26.30217	159.7770	-2.058067
26.35383	159.7766	-2.061075
26.40383	159.7765	-2.063680
26.45383	159.7767	-2.066403
26.50383	159.7756	-2.069070
26.55383	159.7766	-2.071650
26.60383	159.7764	-2.074394
26.65383	159.7768	-2.077086
26.70550	159.7762	-2.079711
26.75550	159.7761	-2.082285
26.80716	159.7759	-2.084625
26.85716	159.7760	-2.087059
26.90716	159.7759	-2.089106
26.95716	159.7756	-2.091064
27.00716	159.7758	-2.093218
27.05716	159.7756	-2.094947
27.10716	159.7754	-2.096894
27.15883	159.7743	-2.098643
27.21050	159.7744	-2.100421
27.26050	159.7743	-2.101953
27.31050	159.7744	-2.103584
27.36050	159.7735	-2.104968
27.41050	159.7741	-2.106773
27.46050	159.7737	-2.108860
27.51050	159.7738	-2.111008
27.56217	159.7738	-2.113473
27.61216	159.7744	-2.116139
27.66383	159.7741	-2.118801
27.71383	159.7744	-2.120990
27.76383	159.7742	-2.123142
27.81383	159.7741	-2.125572
27.86383	159.7741	-2.127647
27.91383	159.7733	-2.129660
27.96383	159.7748	-2.131934
28.01550	159.7742	-2.134192
28.06716	159.7749	-2.136129
28.11716	159.7737	-2.137742
28.16716	159.7740	-2.139272
28.21716	159.7741	-2.141009
28.26716	159.7746	-2.142375
28.31716	159.7738	-2.143616
28.36716	159.7737	-2.144638
28.41716	159.7741	-2.145832
28.46883	159.7737	-2.146925
28.52050	159.7734	-2.147816
28.57050	159.7724	-2.148723
28.62050	159.7730	-2.149560
28.67050	159.7722	-2.150323
28.72050	159.7723	-2.151312
28.77050	159.7720	-2.152320
28.82050	159.7720	-2.153526
28.87216	159.7717	-2.154910
28.92216	159.7720	-2.156268
28.97383	159.7721	-2.157345
29.02383	159.7720	-2.158570
29.07383	159.7720	-2.159982
29.12383	159.7723	-2.161568
29.17383	159.7722	-2.163367
29.22383	159.7718	-2.164908
29.27383	159.7730	-2.166673
29.32550	159.7728	-2.168767
29.37716	159.7727	-2.170702
29.42717	159.7735	-2.172489
29.47717	159.7735	-2.173912
29.52717	159.7729	-2.175445
29.57717	159.7728	-2.176646
29.62716	159.7724	-2.177484
29.67717	159.7715	-2.178090
29.72883	159.7720	-2.178600
29.77883	159.7719	-2.178839
29.83050	159.7712	-2.178902
29.88050	159.7710	-2.179287
29.93050	159.7716	-2.179601
29.98050	159.7709	-2.180081
30.03050	159.7714	-2.180974
30.08050	159.7717	-2.181682
30.13050	159.7714	-2.182840
30.18216	159.7723	-2.184167
30.23383	159.7721	-2.185704
30.28383	159.7722	-2.187160
30.33383	159.7713	-2.188548
30.38383	159.7718	-2.189674
30.43383	159.7721	-2.190692
30.48383	159.7710	-2.191298
30.53383	159.7717	-2.191659
30.58383	159.7714	-2.192227
30.63550	159.7710	-2.192673
30.68717	159.7716	-2.193236
30.73716	159.7708	-2.193876
30.78717	159.7703	-2.194598
30.83716	159.7709	-2.195297
30.88716	159.7709	-2.196152
30.93717	159.7708	-2.196806
30.98716	159.7706	-2.197415
31.03883	159.7704	-2.197889
31.08883	159.7701	-2.198152
31.14050	159.7697	-2.198438
31.19050	159.7694	-2.198938
31.24050	159.7701	-2.199587
31.29050	159.7698	-2.200422
31.34050	159.7700	-2.201346
31.39050	159.7704	-2.202309
31.44050	159.7698	-2.203116
31.49216	159.7702	-2.203937
31.54383	159.7698	-2.204894
31.59383	159.7698	-2.206053
31.64383	159.7701	-2.207126
31.69383	159.7695	-2.207919
31.74383	159.7696	-2.208710
31.79383	159.7708	-2.209438
31.84384	159.7695	-2.210092
31.89550	159.7698	-2.210808
31.94550	159.7699	-2.211502
31.99716	159.7702	-2.212415
32.04716	159.7706	-2.213325
32.09716	159.7700	-2.214028
32.14717	159.7696	-2.214416
32.19717	159.7705	-2.215062
32.24716	159.7702	-2.215546
32.29716	159.7711	-2.216122
32.34883	159.7706	-2.216756
32.40050	159.7710	-2.217522
32.45050	159.7709	-2.218291
32.50050	159.7708	-2.218874
32.55050	159.7714	-2.219444
32.60050	159.7706	-2.219975
32.65050	159.7711	-2.220133
32.70050	159.7714	-2.220232
32.75050	159.7711	-2.220544
32.80217	159.7708	-2.220985
32.85383	159.7712	-2.221296
32.90383	159.7699	-2.221233
32.95383	159.7701	-2.221174
33.00383	159.7706	-2.221175
33.05383	159.7704	-2.221086
33.10383	159.7707	-2.221012
33.15383	159.7705	-2.221067
33.20550	159.7699	-2.221172
33.25550	159.7699	-2.221268
33.30716	159.7700	-2.221456
33.35716	159.7690	-2.221568
33.40716	159.7693	-2.221628
33.45716	159.7693	-2.221800
33.50716	159.7692	-2.221767
33.55716	159.7687	-2.221770
33.60716	159.7686	-2.221883
33.65883	159.7694	-2.222112
33.71050	159.7694	-2.222486
33.76050	159.7692	-2.223010
33.81050	159.7692	-2.223640
33.86050	159.7692	-2.224382
33.91050	159.7691	-2.225272
33.96050	159.7684	-2.226430
34.01050	159.7698	-2.227358
34.06216	159.7695	-2.228086
34.11217	159.7694	-2.228406
34.16383	159.7694	-2.228462
34.21383	159.7687	-2.228390
34.26383	159.7687	-2.228316
34.31383	159.7694	-2.228092
34.36383	159.7689	-2.227930
34.41383	159.7685	-2.227755
34.46383	159.7689	-2.227625
34.51550	159.7688	-2.227406
34.56716	159.7685	-2.227339
34.61716	159.7682	-2.227396
34.66716	159.7683	-2.227742
34.71716	159.7689	-2.228406
34.76716	159.7689	-2.229192
34.81716	159.7691	-2.229868
34.86716	159.7694	-2.231007
34.91716	159.7698	-2.232117
34.96884	159.7698	-2.233054
35.02050	159.7694	-2.234060
35.07050	159.7701	-2.234758
35.12050	159.7697	-2.235210
35.17050	159.7704	-2.235368
35.22050	159.7703	-2.235536
35.27050	159.7704	-2.235880
35.32050	159.7708	-2.236061
35.37216	159.7705	-2.236102
35.42216	159.7707	-2.235944
35.47383	159.7711	-2.235702
35.52383	159.7707	-2.235140
35.57383	159.7703	-2.234708
35.62383	159.7698	-2.234089
35.67383	159.7698	-2.233353
35.72383	159.7695	-2.232537
35.77383	159.7700	-2.231782
35.82550	159.7695	-2.231184
35.87717	159.7700	-2.230950
35.92717	159.7699	-2.231036
35.97717	159.7702	-2.230873
36.02716	159.7703	-2.231006
36.07717	159.7703	-2.231260
36.12717	159.7711	-2.231556
36.17717	159.7708	-2.231700
36.22883	159.7706	-2.231716
36.27883	159.7704	-2.231702
36.33050	159.7700	-2.231476
36.38050	159.7694	-2.231082
36.43050	159.7701	-2.230533
36.48050	159.7702	-2.229993
36.53050	159.7691	-2.229442
36.58050	159.7696	-2.228780
36.63050	159.7689	-2.228275
36.68216	159.7693	-2.227737
36.73383	159.7681	-2.227037
36.78383	159.7690	-2.226642
36.83383	159.7691	-2.226544
36.88383	159.7689	-2.226455
36.93384	159.7690	-2.226727
36.98383	159.7689	-2.227124
37.03383	159.7696	-2.227074
37.08383	159.7688	-2.227170
37.13550	159.7693	-2.227340
37.18716	159.7694	-2.227419
37.23717	159.7692	-2.227691
37.28717	159.7695	-2.227902
37.33716	159.7702	-2.228004
37.38716	159.7702	-2.227807
37.43716	159.7701	-2.227650
37.48717	159.7706	-2.227640
37.53883	159.7702	-2.228102
37.58883	159.7705	-2.228415
37.64050	159.7705	-2.228976
37.69050	159.7706	-2.229418
37.74050	159.7700	-2.229735
37.79050	159.7712	-2.229729
37.84050	159.7703	-2.229498
37.89050	159.7706	-2.229094
37.94050	159.7700	-2.228468
37.99216	159.7705	-2.227684
38.04383	159.7701	-2.227100
38.09384	159.7702	-2.226675
38.14383	159.7700	-2.226198
38.19383	159.7698	-2.225463
38.24383	159.7705	-2.225113
38.29383	159.7696	-2.224654
38.34384	159.7690	-2.224219
38.39550	159.7689	-2.223902
38.44550	159.7695	-2.223947
38.49716	159.7691	-2.224281
38.54716	159.7689	-2.224606
38.59716	159.7692	-2.225378
38.64717	159.7690	-2.226398
38.69717	159.7690	-2.227314
38.74716	159.7683	-2.228042
38.79716	159.7693	-2.228961
38.84883	159.7697	-2.230314
38.90050	159.7694	-2.231471
38.95050	159.7693	-2.232690
39.00050	159.7708	-2.233881
39.05050	159.7691	-2.235194
39.10050	159.7700	-2.236133
39.15050	159.7697	-2.237039
39.20050	159.7699	-2.237664
39.25050	159.7700	-2.238390
39.30217	159.7698	-2.239148
39.35383	159.7699	-2.239808
39.40383	159.7699	-2.240353
39.45383	159.7695	-2.240656
39.50383	159.7703	-2.241248
39.55383	159.7704	-2.241848
39.60383	159.7702	-2.242493
39.65383	159.7690	-2.242975
39.70550	159.7692	-2.243351
39.75550	159.7693	-2.243877
39.80716	159.7689	-2.244285
39.85716	159.7680	-2.244703
39.90716	159.7683	-2.244985
39.95716	159.7681	-2.245246
40.00716	159.7678	-2.245428
40.05716	159.7675	-2.246006
40.10716	159.7683	-2.246803
40.15883	159.7674	-2.247615
40.21050	159.7679	-2.248604
40.26050	159.7680	-2.249759
40.31050	159.7681	-2.251116
40.36050	159.7688	-2.252395
40.41050	159.7682	-2.253862
40.46050	159.7682	-2.255231
40.51050	159.7686	-2.256580
40.56216	159.7688	-2.257557
40.61217	159.7692	-2.258528
40.66383	159.7689	-2.259339
40.71383	159.7690	-2.260077
40.76383	159.7684	-2.260989
40.81383	159.7691	-2.261678
40.86383	159.7688	-2.262044
40.91383	159.7689	-2.262389
40.96383	159.7682	-2.262982
41.01550	159.7687	-2.263505
41.06717	159.7689	-2.264156
41.11716	159.7690	-2.264766
41.16716	159.7695	-2.264900
41.21717	159.7692	-2.264960
41.26717	159.7689	-2.265115
41.31717	159.7681	-2.265440
41.36716	159.7677	-2.265730
41.41716	159.7682	-2.265952
41.46884	159.7681	-2.266188
41.52050	159.7682	-2.266291
41.57050	159.7682	-2.266367
41.62050	159.7672	-2.266511
41.67050	159.7675	-2.266476
41.72050	159.7668	-2.266628
41.76717	159.7676	-2.267270
41.81717	159.8980	-2.202112
41.86716	160.3650	-3.589301
41.91716	160.9609	-6.422783
41.96884	161.6677	-9.738946
42.02050	162.4396	-12.94552
42.07050	163.2346	-15.70263
42.12050	164.0666	-18.06778
42.17050	164.9283	-20.05205
42.22050	165.8137	-21.70026
42.27050	166.7199	-23.07662
42.32050	167.6404	-24.21924
42.37216	168.6059	-25.20700
42.42216	169.5504	-26.00558
42.47383	170.5343	-26.70345
42.52383	171.4945	-27.30228
42.57383	172.4595	-27.81590
42.62383	173.4296	-28.26919
42.67383	174.4029	-28.67575
42.72383	175.3786	-29.04404
42.77383	176.3572	-29.38560
42.82550	177.3711	-29.71740
42.87717	178.3845	-30.03030
42.92717	179.3675	-30.33184
42.97717	180.3511	-30.62666
43.02716	181.3359	-30.92658
43.07717	182.3196	-31.23141
43.12717	183.3050	-31.53586
43.17717	184.2889	-31.85392
43.22883	185.3063	-32.19200
43.27883	186.2906	-32.52680
43.33050	187.3076	-32.88106
43.38050	188.2915	-33.24420
43.43050	189.2750	-33.62615
43.48050	190.2578	-34.02463
43.53050	191.2393	-34.43903
43.58050	192.2202	-34.87627
43.63050	193.2011	-35.33624
43.68217	194.2123	-35.83258
43.73383	195.2236	-36.34990
43.78383	196.1994	-36.88396
43.83383	197.1754	-37.45540
43.88383	198.1502	-38.05734
43.93383	199.1226	-38.68436
43.98383	200.0940	-39.34466
44.03383	201.0639	-40.04520
44.08383	202.0308	-40.78840
44.13550	203.0302	-41.58690
44.18716	204.0304	-42.33900
44.23717	204.9979	-43.07331
44.28717	205.9643	-43.88802
44.33716	206.9252	-44.82034
44.38716	207.8798	-45.91514
44.43716	208.8247	-47.21191
44.48717	209.7589	-48.76870
44.53883	210.7104	-50.75253
44.58883	211.6077	-53.16421
44.64050	212.5140	-56.13764
44.69050	213.3701	-59.45582
44.74050	214.2093	-63.10660
44.79050	215.0358	-67.00792
44.84050	215.8555	-71.02145
44.89050	216.6770	-74.93472
44.94050	217.5052	-78.63757
44.99216	218.3792	-82.00863
45.04383	219.2848	-84.55269
45.09384	220.2113	-85.75544
45.14383	221.2087	-85.17051
45.19383	222.3244	-81.72566
45.24383	223.5544	-76.08189
45.29383	224.8626	-68.98447
45.34384	226.1826	-62.25941
45.39550	227.4979	-56.60996
45.44550	228.7172	-52.23050
45.49716	229.9312	-48.65236
45.54716	231.0714	-45.89841
45.59716	232.1826	-43.71239
45.64717	233.2720	-41.98447
45.69717	234.3428	-40.60405
45.74716	235.3998	-39.51386
45.79716	236.4438	-38.64704
45.84883	237.5144	-37.93814
45.90050	238.5771	-37.39193
45.95050	239.5996	-36.97180
46.00050	240.6175	-36.65544
46.05050	241.6314	-36.40948
46.10050	242.6430	-36.22943
46.15050	243.6516	-36.09089
46.20050	244.6594	-35.98532
46.25050	245.6652	-35.91459
46.30217	246.7035	-35.86196
46.35383	247.7398	-35.82188
46.40383	248.7416	-35.80069
46.45383	249.7455	-35.79004
46.50383	250.7472	-35.78524
46.55383	251.7478	-35.78406
46.60383	252.7505	-35.78627
46.65383	253.7500	-35.79569
46.70550	254.7835	-35.80940
46.75550	255.7840	-35.83950
46.80717	256.8177	-35.89950
46.85717	257.8170	-35.94910
46.90717	258.8176	-35.99382
46.95717	259.8164	-36.04534
47.00717	260.8172	-36.09848
47.05717	261.8155	-36.14520
47.10717	262.8152	-36.19754
47.15883	263.8474	-36.25776
47.21050	264.8800	-36.31765
47.26050	265.8784	-36.37692
47.31050	266.8778	-36.43418
47.36050	267.8761	-36.48761
47.41050	268.8751	-36.54544
47.46050	269.8738	-36.60610
47.51050	270.8730	-36.65726
47.56216	271.9049	-36.70340
47.61217	272.9040	-36.75838
47.66383	273.9375	-36.80988
47.71383	274.9365	-36.85891
47.76050	275.8700	-36.90888
47.81050	276.6724	-37.31953
47.86050	276.7426	-35.18072
47.91050	276.5140	-29.25550
47.96050	276.1095	-22.25352
48.01050	275.5900	-15.36744
48.06216	274.9605	-9.014908
48.11217	274.2812	-3.734469
48.16383	273.5211	0.8413374
48.21383	272.7404	4.524584
48.26383	271.9230	7.583220
48.31383	271.0763	10.11916
48.36383	270.2046	12.22299
48.41383	269.3132	13.98012
48.46383	268.4055	15.44696
48.51550	267.4522	16.71144
48.56717	266.4882	17.77331
48.61716	265.5438	18.63930
48.66716	264.5926	19.37269
48.71717	263.6346	19.99191
48.76717	262.6709	20.52312
48.81717	261.7036	20.97180
48.86716	260.7312	21.36810
48.91716	259.7565	21.69972
48.96884	258.7457	22.00594
49.02050	257.7332	22.26391
49.07050	256.7503	22.47881
49.12050	255.7670	22.66674
49.17050	254.7814	22.82750
49.22050	253.7940	22.98670
49.27050	252.8066	23.11711
49.32050	251.8180	23.23223
49.37216	250.7951	23.34217
49.42216	249.8053	23.43308
49.47383	248.7811	23.52602
49.52383	247.7910	23.60757
49.57383	246.7998	23.68146
49.62383	245.8076	23.74036
49.67383	244.8151	23.80159
49.72383	243.8216	23.85847
49.77383	242.8294	23.90455
49.82550	241.8030	23.94738
49.87717	240.7766	23.98918
49.92717	239.7826	24.02818
49.97717	238.7891	24.06958
50.02716	237.7956	24.10406
50.07717	236.8010	24.13729
50.12717	235.8066	24.17688
50.17717	234.8124	24.20206
50.22883	233.7848	24.22391
50.27883	232.7899	24.24264
50.33050	231.7624	24.26168
50.38050	230.7670	24.28234
50.43050	229.7721	24.30140
50.48050	228.7771	24.31578
50.53050	227.7814	24.33761
50.58050	226.7869	24.36789
50.63050	225.7912	24.38304
50.68217	224.7640	24.40902
50.73383	223.7344	24.43109
50.78383	222.7396	24.44505
50.83383	221.7444	24.45758
50.88383	220.7489	24.47210
50.93383	219.7523	24.49184
50.98383	218.7570	24.51713
51.03383	217.7617	24.53026
51.08383	216.7665	24.53945
51.13550	215.7373	24.54994
51.18716	214.7086	24.55895
51.23717	213.7133	24.56730
51.28716	212.7180	24.57733
51.33716	211.7212	24.58784
51.38716	210.7268	24.59742
51.43716	209.7309	24.60652
51.48717	208.7363	24.61687
51.53883	207.7064	24.62798
51.58883	206.7104	24.63884
51.64050	205.6824	24.64906
51.69050	204.6862	24.65825
51.74050	203.6901	24.66913
51.79050	202.6948	24.67876
51.84050	201.6993	24.68730
51.89050	200.7027	24.69537
51.94050	199.7069	24.70358
51.99216	198.6775	24.71180
52.04383	197.6492	24.71988
52.09384	196.6522	24.72746
52.14384	195.6569	24.73496
52.19384	194.6610	24.74360
52.24383	193.6648	24.75482
52.29383	192.6682	24.76375
52.34384	191.6731	24.77216
52.39550	190.6434	24.78045
52.44550	189.6477	24.78740
52.49717	188.6180	24.79462
52.54717	187.6222	24.80106
52.59716	186.6270	24.80718
52.64717	185.6295	24.81422
52.69717	184.6342	24.82099
52.74717	183.6373	24.82668
52.79717	182.6412	24.83190
52.84882	181.6109	24.83705
52.90050	180.5820	24.84213
52.95050	179.5849	24.84691
53.00050	178.5891	24.85242
53.05050	177.5929	24.85840
53.10050	176.5961	24.86519
53.15050	175.5998	24.87284
53.20050	174.6038	24.88364
53.25050	173.6073	24.89702
53.30217	172.5796	24.91994
53.35383	171.5507	24.94647
53.40383	170.5542	24.99023
53.45383	169.5618	25.04985
53.50383	168.5679	25.11522
53.55383	167.5751	25.20268
53.60383	166.5836	25.31211
53.65383	165.5941	25.47451
53.70550	164.5761	25.75472
53.75550	163.5997	26.24320
53.80717	162.6060	27.14125
53.85717	161.6709	28.62436
53.90717	160.7735	30.94278
53.95717	159.9220	34.22706
54.00717	159.1162	38.39697
54.05717	158.3451	43.15230
54.10717	157.5910	48.03753
54.15883	156.8015	52.73266
54.21050	155.9833	56.66030
54.26050	155.1463	59.45647
54.31050	154.2559	61.11956
54.36050	153.3081	61.61040
54.41050	152.3033	60.99375
54.46050	151.2480	59.42780
54.51050	150.1509	57.09918
54.56216	148.9855	54.16269
54.61217	147.8401	51.07098
54.66382	146.6370	47.52452
54.71382	145.4884	44.59262
54.76382	144.3544	41.97773
54.81382	143.2395	39.69736
54.86382	142.1384	37.72130
54.91382	141.0524	36.02381
54.96382	139.9779	34.56438
55.01550	138.8801	33.28272
55.06716	137.7918	32.19271
55.11716	136.7459	31.27968
55.16716	135.7095	30.49658
55.21717	134.6761	29.82588
55.26716	133.6488	29.24377
55.31716	132.6259	28.74810
55.36716	131.6051	28.31270
55.41716	130.5885	27.91980
55.46884	129.5403	27.58706
55.52050	128.4941	27.28060
55.57050	127.4844	27.01940
55.62050	126.4742	26.79388
55.67050	125.4671	26.58491
55.72050	124.4598	26.39244
55.77050	123.4534	26.21105
55.82050	122.4481	26.04136
55.87217	121.4096	25.87798
55.92217	120.4056	25.73564
55.97382	119.3684	25.59325
56.02383	118.3652	25.47994
56.07383	117.3623	25.38104
56.12383	116.3601	25.29908
56.17383	115.3830	25.70144
56.22382	114.3818	25.56910
56.27383	113.3777	25.42763
56.32550	112.3403	25.28152
56.37717	111.3031	25.15450
56.42717	110.2998	25.03236
56.47717	109.2970	24.91588
56.52717	108.2930	24.81106
56.57717	107.2904	24.71165
56.62717	106.2896	24.61485
56.67717	105.2880	24.52300
56.72883	104.2526	24.43020
56.77883	103.2513	24.35032
56.83050	102.2168	24.26990
56.88050	101.2143	24.19194
56.93050	100.2139	24.11926
56.98050	99.21344	24.04207
57.03050	98.21231	23.96531
57.08050	97.21112	23.90101
57.13050	96.21129	23.83183
57.18217	95.17652	23.75874
57.23383	94.14356	23.68420
57.28383	93.14399	23.61972
57.33383	92.14348	23.55120
57.38383	91.14338	23.48328
57.43383	90.14261	23.41524
57.48383	89.14301	23.34439
57.53383	88.14264	23.27980
57.58383	87.14259	23.21850
57.63550	86.10903	23.14690
57.68716	85.07625	23.07917
57.73717	84.07561	23.01527
57.78716	83.07549	22.95605
57.83716	82.07590	22.89390
57.88716	81.07634	22.83229
57.93716	80.07482	22.76884
57.98717	79.07418	22.70671
58.03882	78.04084	22.64251
58.08882	77.04078	22.57961
58.14050	76.00710	22.51767
58.19050	75.00693	22.45766
58.24050	74.00628	22.39859
58.29050	73.00603	22.33725
58.34050	72.00666	22.27592
58.39050	71.00564	22.21280
58.44050	70.00500	22.15913
58.49216	68.97230	22.09630
58.54382	67.92816	21.84818
58.59384	66.92978	21.81607
58.64384	65.93068	21.77026
58.69384	64.92934	21.72192
58.74382	63.92928	21.66913
58.79382	62.92825	21.60362
58.84384	61.92664	21.54120
58.89550	60.89342	21.46320
58.94550	59.89358	21.39138
58.99717	58.85850	21.32670
59.04717	57.85790	21.25591
59.09716	56.85800	21.18527
59.14717	55.85645	21.11850
59.19717	54.85602	21.05039
59.24717	53.85534	20.99850
59.29717	52.85461	20.91980
59.34882	51.82008	20.84704
59.40050	50.78606	20.77496
59.45050	49.78500	20.71065
59.50050	48.78422	20.64102
59.55050	47.78440	20.57076
59.60050	46.78227	20.50062
59.65050	45.78088	20.44076
59.70050	44.77912	20.37683
59.75050	43.77890	20.30884
59.80217	42.74450	20.23705
59.85383	41.70975	20.16660
59.90383	40.70894	20.08848
59.95383	39.70641	20.01480
60.00383	38.70539	19.94752
60.05383	37.70470	19.86697
60.10383	36.70296	19.77782
60.15383	35.70082	19.69734
60.20550	34.66557	19.60816
60.25550	33.66371	19.51852
60.30717	32.62766	19.43273
60.35717	31.67508	20.13780
60.40717	30.66427	19.89174
60.45717	29.65460	19.69320
60.50717	28.64580	19.51978
60.55717	27.63932	19.35361
60.60717	26.63208	19.19723
60.65883	25.59201	19.04619
60.71050	24.55186	18.91026
60.75550	23.64754	18.78237
60.80717	22.77299	18.80482
60.85717	22.63644	17.57130
60.90717	22.80056	14.07149
60.95717	23.16249	9.907803
61.00717	23.65660	5.668426
61.05717	24.25190	1.804721
61.10717	24.92554	-1.568519
61.15883	25.68872	-4.508254
61.21050	26.50287	-6.936725
61.26050	27.33118	-8.872348
61.31050	28.19024	-10.45994
61.36050	29.07296	-11.76515
61.41050	29.97752	-12.83716
61.46050	30.89561	-13.72752
61.51050	31.82762	-14.46313
61.56216	32.80100	-15.10504
61.61217	33.75182	-15.63001
61.66382	34.74160	-16.09296
61.71382	35.70502	-16.47650
61.76382	36.67328	-16.81375
61.81382	37.64538	-17.11936
61.86382	38.62222	-17.38276
61.91382	39.60022	-17.61776
61.96382	40.58171	-17.82864
62.01550	41.59742	-18.03049
62.06716	42.61567	-18.21079
62.11716	43.60142	-18.37386
62.16716	44.59016	-18.52443
62.21717	45.57843	-18.66221
62.26716	46.57006	-18.79924
62.31716	47.56000	-18.92836
62.36716	48.55285	-19.05154
62.41716	49.54469	-19.16886
62.46884	50.57032	-19.28457
62.52050	51.59708	-19.40642
62.57050	52.59057	-19.51596
62.62050	53.58504	-19.61920
62.67050	54.57971	-19.72412
62.72050	55.57370	-19.82274
62.77050	56.56889	-19.92288
62.82050	57.56348	-20.02537
62.87217	58.59291	-20.12886
62.92217	59.58826	-20.22738
62.97382	60.61806	-20.32858
63.02383	61.61308	-20.42715
63.07383	62.60928	-20.52693
63.12383	63.60668	-20.62238
63.17383	64.60352	-20.71630
63.22382	65.59913	-20.80704
63.27383	66.59674	-20.89605
63.32550	67.62628	-20.98114
63.37717	68.65686	-21.07048
63.42717	69.65457	-21.15655
63.47717	70.65164	-21.24013
63.52717	71.64800	-21.32444
63.57717	72.64549	-21.41340
63.62717	73.64221	-21.50287
63.67717	74.63882	-21.58919
63.72883	75.66855	-21.67953
63.77883	76.66562	-21.76860
63.83050	77.69600	-21.85897
63.88050	78.69288	-21.95424
63.93050	79.68920	-22.05192
63.98050	80.68643	-22.14334
64.03050	81.68316	-22.23908
64.08050	82.68039	-22.33476
64.13050	83.67680	-22.42811
64.18218	84.70694	-22.52747
64.23383	85.73694	-22.62980
64.28384	86.73401	-22.72910
64.33384	87.73053	-22.82785
64.38384	88.72838	-22.92160
64.43384	89.72486	-23.01981
64.48383	90.72095	-23.12282
64.53384	91.71850	-23.22110
64.58384	92.71595	-23.31550
64.63550	93.74553	-23.41632
64.68717	94.77601	-23.51060
64.73717	95.77320	-23.61194
64.78717	96.76994	-23.70942
64.83716	97.76602	-23.79924
64.88717	98.76350	-23.89710
64.93717	99.76039	-23.98506
64.98717	100.7565	-24.08634
65.03882	101.7870	-24.18355
65.08884	102.7841	-24.28127
65.14050	103.8136	-24.38037
65.19050	104.8102	-24.47739
65.24050	105.8069	-24.58216
65.29050	106.8036	-24.68313
65.34050	107.8009	-24.78548
65.39050	108.7975	-24.88849
65.44050	109.7940	-24.98690
65.49218	110.8244	-25.09392
65.54384	111.8526	-25.19634
65.59384	112.8500	-25.29956
65.64384	113.8466	-25.40070
65.69384	114.8438	-25.50379
65.74384	115.8409	-25.60689
65.79384	116.8365	-25.71174
65.84384	117.8345	-25.80834
65.89550	118.8641	-25.91657
65.94550	119.8610	-26.02312
65.99718	120.8907	-26.13581
66.04718	121.8867	-26.24772
66.09718	122.8841	-26.35943
66.14718	123.8800	-26.47118
66.19718	124.8773	-26.58373
66.24718	125.8739	-26.69916
66.29718	126.8697	-26.81112
66.34882	127.8994	-26.92174
66.40050	128.9291	-27.03278
66.45050	129.9249	-27.14810
66.50050	130.9214	-27.26438
66.55050	131.9186	-27.38473
66.60050	132.9137	-27.50474
66.65050	133.9102	-27.61788
66.70050	134.9053	-27.74392
66.75050	135.9001	-27.87572
66.80218	136.9303	-28.01060
66.85384	137.9585	-28.14842
66.90384	138.9541	-28.27749
66.95384	139.9484	-28.41096
67.00384	140.9444	-28.55346
67.05384	141.9397	-28.68706
67.10384	142.9349	-28.82856
67.15384	143.9313	-28.97299
67.20550	144.9584	-29.11483
67.25550	145.9536	-29.25490
67.30718	146.9819	-29.40498
67.35718	147.9774	-29.55154
67.40718	148.9714	-29.69541
67.45718	149.9646	-29.84028
67.50718	150.9606	-29.99276
67.55718	151.9553	-30.14587
67.60718	152.9500	-30.29789
67.65884	153.9772	-30.46580
67.71050	155.0052	-30.63445
67.76050	155.9990	-30.79886
67.81050	156.9933	-30.96629
67.86050	157.9877	-31.13574
67.91050	158.9818	-31.30170
67.96050	159.9753	-31.46998
68.01050	160.9700	-31.62793
68.06216	161.9978	-31.78800
68.11218	162.9932	-31.92900
68.16382	164.0216	-32.06300
68.21384	165.0174	-32.17802
68.26384	166.0160	-32.26810
68.31384	167.0135	-32.34841
68.36384	168.0122	-32.41904
68.41382	169.0114	-32.47699
68.46384	170.0094	-32.53516
68.51550	171.0423	-32.59700
68.56718	172.0752	-32.67008
68.61718	173.0731	-32.75716
68.66718	174.0716	-32.84256
68.71718	175.0683	-32.93792
68.76716	176.0653	-33.04996
68.81718	177.0623	-33.17356
68.86718	178.0566	-33.31576
68.91718	179.0505	-33.47546
68.96884	180.0766	-33.66053
69.02050	181.1016	-33.87064
69.07050	182.0937	-34.10330
69.12050	183.0849	-34.35254
69.17050	184.0744	-34.62634
69.22050	185.0631	-34.93448
69.27050	186.0499	-35.26556
69.32050	187.0344	-35.62217
69.37218	188.0510	-36.04480
69.42218	189.0321	-36.50384
69.47384	190.0438	-37.02750
69.52384	191.0190	-37.59745
69.57384	191.9930	-38.22477
69.62384	192.9643	-38.90097
69.67384	193.9326	-39.61716
69.72384	194.8998	-40.35315
69.77384	195.8663	-41.12310
69.82550	196.8641	-41.93428
69.87718	197.8617	-42.77222
69.92718	198.8254	-43.60900
69.97718	199.7861	-44.49635
70.02718	200.7453	-45.46262
70.07718	201.7003	-46.50491
70.12718	202.6509	-47.63976
70.17718	203.5987	-48.85516
70.22884	204.5739	-50.17809
70.27884	205.5155	-51.49086
70.33050	206.4890	-52.85313
70.38050	207.4323	-54.08915
70.43050	208.3826	-55.13704
70.48050	209.3466	-55.83390
70.53050	210.3348	-55.93299
70.58050	211.3594	-55.18199
70.63050	212.4258	-53.47406
70.68218	213.5691	-50.91256
70.73384	214.7380	-47.93478
70.78384	215.8730	-45.13588
70.83384	216.9930	-42.72378
70.88384	218.0930	-40.76321
70.93384	219.1752	-39.18624
70.98384	220.2412	-37.90703
71.03384	221.2940	-36.89672
71.08384	222.3360	-36.08824
71.13550	223.4058	-35.43240
71.18718	224.4666	-34.91756
71.23718	225.4883	-34.51798
71.28718	226.5050	-34.20890
71.33716	227.5188	-33.97938
71.38718	228.5297	-33.79767
71.43718	229.5388	-33.66896
71.48718	230.5453	-33.58322
71.53882	231.5840	-33.52275
71.58884	232.5882	-33.49418
71.64050	233.6244	-33.48422
71.69050	234.6280	-33.48013
71.74050	235.6289	-33.47998
71.79050	236.6314	-33.48740
71.84050	237.6324	-33.49924
71.89050	238.6320	-33.52810
71.94050	239.6325	-33.56416
71.99218	240.6662	-33.62153
72.04384	241.6990	-33.67139
72.09384	242.6984	-33.73662
72.14384	243.6984	-33.79150
72.19384	244.6979	-33.85431
72.24384	245.6972	-33.91180
72.29384	246.6970	-33.96852
72.34384	247.6965	-34.02261
72.39550	248.7297	-34.07702
72.44550	249.7294	-34.12696
72.49718	250.7625	-34.18504
72.54718	251.7603	-34.24564
72.59718	252.7603	-34.30274
72.64718	253.7588	-34.36667
72.69718	254.7577	-34.43526
72.74718	255.7558	-34.49539
72.79718	256.7544	-34.57197
72.84882	257.7862	-34.64644
72.90050	258.8176	-34.71831
72.95050	259.8164	-34.79739
73.00050	260.8148	-34.87868
73.05050	261.8120	-34.96304
73.10050	262.8097	-35.05722
73.15050	263.8081	-35.14519
73.20050	264.8055	-35.23144
73.25050	265.8034	-35.32094
73.30218	266.8354	-35.41361
73.35384	267.8658	-35.50332
73.40384	268.8628	-35.59728
73.45384	269.8608	-35.70020
73.50384	270.8578	-35.80955
73.55384	271.8553	-35.91662
-2.000000	5.000000	0.0000000