File: 2-C1(0.8mol%)+C20(0.6mol%)/matlab/170-2.txt
CLOSED
Version	1.0
Language	English
Mode	Standard
Run	11
RunSerial	11888
Instrument	DSC Q2000 V24.11 Build 124
Module	DSC Standard Cell RC
Operator	Jing
File	\\Ae520-1454\ta\Data\DSC\UQ Composites\Nan\C1(7.5)+C20P(3)+CL(Hotplate MixtureAB)\170-2
ProcName	Ramp
InstSerial	2000-0883
AutoSerial	1293
Sample	Iso170-2
Size	30.7000	mg
PanMass	Not available
PanResist	Automatic Automatic  K/W
PanFactor	Default Default
Method	Ramp
Comment
Xcomment	Pan: Tzero Aluminum Hermetic
Xcomment	Gas1: Nitrogen 50.0 ml/min
Xcomment	Gas2: Nitrogen 50.0 ml/min
Text
Exotherm	UP
Kcell	1.05230
Cpconst	Standard: 0.938
Calib	-38.6961
TempCal	1	pts	157.46	156.60
TzeroDt	-87.6168 -0.0009 -1.4231
TzeroDtz	-87.6168 0.0057 6.9570
InstCalFile	Tzero: \\Ae520-1454\ta\Data\DSC\Calibration\2017\CALIBRATION\1562_RCS (90)_05_18_2017 10_50_44.TZR
InstCalFile	Baseline: \\Ae520-1454\ta\Data\DSC\Calibration\2017\2017-05-17_Calibration.001
InstCalFile	Sapphire: \\Ae520-1454\ta\Data\DSC\Calibration\2017\2017-05-17_Saphire.001
InstCalDate	Tzero 2017-05-18 Time 10:50:44
TempRange	-87.39 to 398.39 °C at 10.00 °C/min Heat Only
AutoZero	Delta T Offset 0.000 uV
AutoZero	Delta T0 Offset 0.000 uV
MultiptCal	0
MultiPtDesc	0) Not set
AutoCellConst	Calibration Date 2017-05-18 16:59:28
Controls	Gas 1  Event Off  Sampling 0.2
Cell#	RC-01562
CoolingUnit	RCS (90)
SelHeatFlow	Heat Flow T4 (mW)
AutoLidII	Installed
AutoAnalysis	Off
MacroFile
Nsig	3
Sig1	Time (min)
Sig2	Temperature (°C)
Sig3	Heat Flow (mW)
Date	2017-06-23
Time	04:27:26
OrgMethod	1: Equilibrate at 20.00 °C
OrgMethod	2: Ramp 80.00 °C/min to 170.00 °C
OrgMethod	3: Mark end of cycle 1
OrgMethod	4: Isothermal for 40.00 min
OrgMethod	5: Mark end of cycle 2
OrgMethod	6: Ramp 20.00 °C/min to 280.00 °C
OrgMethod	7: Mark end of cycle 3
OrgMethod	8: Ramp 20.00 °C/min to 20.00 °C
OrgMethod	9: Mark end of cycle 4
OrgMethod	10: Ramp 20.00 °C/min to 280.00 °C
OrgMethod	11: Mark end of cycle 5
OrgFile	C:\Users\jarra\Desktop\DSC\2-C1(0.8mol%)+C20(0.6mol%)\170-2
StartOfData
4.99994E-4	20.03744	-.01755411
0.05216665	20.26624	0.4430799
0.1021667	21.86428	0.1558909
0.1521666	24.31527	-4.714036
0.2021666	27.11240	-11.30573
0.2538334	30.29942	-18.21961
0.3038333	33.58089	-24.37640
0.3538333	37.00606	-29.66491
0.4038334	40.54510	-34.08502
0.4538334	44.16732	-37.77088
0.5038334	47.84000	-41.20000
0.5538334	51.55616	-43.98026
0.6038332	55.31800	-46.53454
0.6538332	59.03718	-50.75647
0.7038332	62.71256	-55.13208
0.7538332	66.44689	-58.34087
0.8038334	70.16822	-63.19766
0.8538332	73.62418	-75.56460
0.9038334	76.46731	-100.3493
0.9538334	79.01644	-125.9223
1.003833	81.68016	-149.6018
1.053834	84.47407	-171.2662
1.103833	87.25819	-191.8246
1.153834	90.40206	-203.6122
1.203834	94.70297	-190.7399
1.253833	99.35962	-178.0248
1.305500	104.4944	-157.7320
1.355500	109.4531	-141.4430
1.405500	114.2241	-128.5381
1.455500	118.8312	-118.3987
1.507167	123.4460	-110.5376
1.557167	127.8114	-104.4787
1.607167	132.0991	-99.82801
1.657167	136.3254	-96.27550
1.707167	140.5058	-93.51986
1.757167	144.6553	-91.29181
1.807167	148.7804	-89.53068
1.857167	152.8781	-88.26316
1.907167	156.9317	-87.43049
1.957167	160.0777	-87.46191
2.007167	161.8806	-81.24631
2.057167	163.2922	-70.73048
2.107167	164.3992	-59.67166
2.157167	165.3003	-49.39178
2.207167	166.0374	-40.48179
2.257167	166.6428	-33.05049
2.307167	167.1428	-26.97063
2.357167	167.5555	-22.04205
2.407167	167.8997	-18.06661
2.457167	168.1872	-14.87481
2.507167	168.4299	-12.30258
2.557167	168.6348	-10.22465
2.607167	168.8081	-8.539397
2.657167	168.9550	-7.162120
2.707167	169.0799	-6.030999
2.757167	169.1870	-5.090394
2.807167	169.2789	-4.302276
2.857167	169.3570	-3.636255
2.908834	169.4280	-3.046850
2.958833	169.4864	-2.556406
3.008833	169.5375	-2.131531
3.058833	169.5816	-1.753991
3.110500	169.6220	-1.408827
3.160500	169.6559	-1.107556
3.210500	169.6867	-0.8321014
3.260500	169.7143	-0.5802659
3.310500	169.7378	-0.3446615
3.360500	169.7592	-0.1191814
3.410500	169.7790	0.09756512
3.460500	169.7985	0.3055405
3.510500	169.8146	0.5096156
3.560500	169.8312	0.7075741
3.610500	169.8464	0.9046644
3.660500	169.8613	1.099728
3.710500	169.8754	1.297257
3.760500	169.8884	1.495963
3.810500	169.9016	1.693114
3.860500	169.9138	1.895361
3.910500	169.9270	2.098096
3.960500	169.9384	2.304074
4.010500	169.9514	2.511540
4.060500	169.9636	2.722419
4.110500	169.9752	2.937622
4.162167	169.9890	3.165962
4.212167	170.0009	3.387716
4.262167	170.0133	3.621276
4.312167	170.0260	3.855240
4.363834	170.0391	4.099750
4.413834	170.0512	4.348276
4.463834	170.0652	4.600297
4.513834	170.0778	4.862094
4.563834	170.0921	5.127781
4.613834	170.1057	5.400039
4.663834	170.1204	5.680115
4.713834	170.1354	5.965860
4.763834	170.1514	6.264782
4.813834	170.1655	6.569376
4.863834	170.1815	6.879980
4.913834	170.1970	7.201095
4.963834	170.2144	7.530259
5.013834	170.2308	7.860986
5.063834	170.2483	8.210402
5.113834	170.2652	8.558496
5.163833	170.2829	8.919994
5.213833	170.3014	9.284887
5.263834	170.3197	9.658274
5.313832	170.3392	10.03560
5.363834	170.3583	10.42500
5.413832	170.3771	10.81436
5.465500	170.3970	11.21642
5.515500	170.4166	11.61002
5.565500	170.4366	12.00224
5.615500	170.4555	12.40092
5.667168	170.4761	12.80624
5.717168	170.4953	13.19274
5.767168	170.5146	13.57624
5.817168	170.5329	13.95214
5.867168	170.5515	14.31728
5.917168	170.5688	14.67183
5.967168	170.5859	15.00862
6.017168	170.6012	15.33694
6.067168	170.6182	15.63809
6.117168	170.6311	15.92104
6.167168	170.6452	16.18516
6.217168	170.6576	16.41990
6.267168	170.6685	16.63033
6.317168	170.6780	16.81198
6.367168	170.6857	16.96463
6.417168	170.6922	17.08194
6.467168	170.6978	17.17241
6.517168	170.7010	17.22864
6.567168	170.7046	17.25917
6.617166	170.7048	17.26619
6.667168	170.7044	17.26216
6.718832	170.7026	17.21230
6.768832	170.6991	17.12644
6.818832	170.6947	17.02432
6.868834	170.6902	16.90060
6.920500	170.6841	16.75082
6.970500	170.6766	16.59070
7.020500	170.6676	16.41292
7.070500	170.6587	16.22076
7.120500	170.6490	16.01259
7.170500	170.6395	15.79178
7.220500	170.6285	15.55777
7.270500	170.6173	15.31731
7.320500	170.6052	15.07422
7.370500	170.5932	14.82383
7.420500	170.5814	14.57704
7.470500	170.5694	14.33322
7.520500	170.5571	14.09261
7.570500	170.5468	13.85867
7.620500	170.5356	13.63936
7.670500	170.5253	13.42668
7.720500	170.5151	13.22908
7.770500	170.5067	13.04413
7.820500	170.4972	12.87274
7.870500	170.4902	12.72107
7.920500	170.4823	12.58292
7.970500	170.4770	12.46670
8.022168	170.4718	12.36030
8.072168	170.4676	12.28340
8.122168	170.4646	12.22316
8.172168	170.4621	12.18326
8.223832	170.4606	12.16164
8.273834	170.4606	12.15488
8.323834	170.4598	12.15378
8.373834	170.4618	12.16418
8.423832	170.4638	12.20447
8.473832	170.4665	12.26835
8.523834	170.4690	12.33951
8.573834	170.4733	12.41277
8.623834	170.4764	12.49548
8.673832	170.4818	12.57957
8.723832	170.4848	12.66154
8.773834	170.4890	12.74255
8.823834	170.4933	12.82215
8.873834	170.4968	12.88893
8.923832	170.5000	12.94735
8.973832	170.5026	12.99373
9.023834	170.5045	13.02341
9.073834	170.5050	13.03528
9.123834	170.5059	13.03813
9.173832	170.5046	13.03380
9.223832	170.5028	12.98378
9.275499	170.4996	12.88940
9.325500	170.4951	12.78287
9.375500	170.4886	12.64336
9.425500	170.4816	12.47788
9.477168	170.4720	12.27630
9.527168	170.4625	12.05239
9.577168	170.4505	11.80033
9.627168	170.4372	11.52041
9.677168	170.4226	11.20926
9.727168	170.4063	10.87752
9.777168	170.3893	10.51697
9.827168	170.3720	10.13963
9.877168	170.3534	9.742061
9.927168	170.3337	9.330530
9.977168	170.3126	8.905845
10.02717	170.2919	8.470664
10.07717	170.2702	8.025989
10.12717	170.2490	7.579453
10.17717	170.2266	7.132918
10.22717	170.2054	6.682637
10.27717	170.1837	6.242344
10.32717	170.1620	5.801470
10.37717	170.1413	5.371672
10.42717	170.1202	4.950268
10.47717	170.1008	4.543232
10.52717	170.0812	4.148033
10.57883	170.0624	3.759009
10.62884	170.0446	3.393657
10.67883	170.0278	3.050671
10.72884	170.0113	2.720207
10.78050	169.9956	2.402324
10.83050	169.9817	2.110842
10.88050	169.9682	1.842318
10.93050	169.9548	1.592402
10.98050	169.9434	1.357100
11.03050	169.9328	1.141983
11.08050	169.9225	0.9432355
11.13050	169.9130	0.7604394
11.18050	169.9045	0.5927711
11.23050	169.8968	0.4411826
11.28050	169.8892	0.3033608
11.33050	169.8831	0.1769356
11.38050	169.8777	0.06128898
11.43050	169.8725	-.04242096
11.48050	169.8677	-0.1327578
11.53050	169.8636	-0.2188444
11.58050	169.8594	-0.2978782
11.63050	169.8549	-0.3670910
11.68050	169.8525	-0.4316769
11.73050	169.8492	-0.4893225
11.78050	169.8464	-0.5422709
11.83217	169.8437	-0.5915952
11.88216	169.8418	-0.6356664
11.93217	169.8395	-0.6777460
11.98217	169.8381	-0.7160755
12.03383	169.8356	-0.7521153
12.08383	169.8343	-0.7833880
12.13383	169.8320	-0.8125078
12.18383	169.8314	-0.8423511
12.23383	169.8296	-0.8686609
12.28383	169.8291	-0.8944408
12.33383	169.8269	-0.9143739
12.38383	169.8269	-0.9366004
12.43383	169.8253	-0.9592762
12.48383	169.8247	-0.9783191
12.53383	169.8231	-0.9968518
12.58383	169.8230	-1.015342
12.63383	169.8214	-1.031893
12.68383	169.8205	-1.046873
12.73383	169.8195	-1.059782
12.78383	169.8193	-1.073951
12.83383	169.8185	-1.089277
12.88383	169.8173	-1.102263
12.93383	169.8175	-1.114834
12.98383	169.8171	-1.127885
13.03383	169.8161	-1.138228
13.08383	169.8158	-1.149032
13.13550	169.8146	-1.161850
13.18550	169.8144	-1.173231
13.23550	169.8140	-1.186192
13.28550	169.8132	-1.196770
13.33717	169.8128	-1.207446
13.38717	169.8117	-1.217325
13.43716	169.8119	-1.226983
13.48716	169.8111	-1.236960
13.53717	169.8115	-1.246556
13.58717	169.8107	-1.256381
13.63717	169.8105	-1.265433
13.68716	169.8099	-1.274401
13.73716	169.8091	-1.283341
13.78717	169.8095	-1.291996
13.83717	169.8092	-1.300721
13.88717	169.8091	-1.308899
13.93716	169.8085	-1.316986
13.98716	169.8080	-1.324549
14.03717	169.8085	-1.332172
14.08717	169.8070	-1.339732
14.13717	169.8072	-1.346734
14.18716	169.8071	-1.353562
14.23716	169.8066	-1.360217
14.28717	169.8057	-1.366475
14.33717	169.8060	-1.372730
14.38883	169.8058	-1.379206
14.43883	169.8054	-1.385237
14.48883	169.8054	-1.390847
14.53883	169.8054	-1.396587
14.59050	169.8054	-1.402355
14.64050	169.8048	-1.407683
14.69050	169.8047	-1.413118
14.74050	169.8047	-1.418557
14.79050	169.8048	-1.423641
14.84050	169.8042	-1.428669
14.89050	169.8044	-1.433696
14.94050	169.8041	-1.438477
14.99050	169.8037	-1.442948
15.04050	169.8034	-1.447364
15.09050	169.8026	-1.451531
15.14050	169.8032	-1.455460
15.19050	169.8032	-1.459552
15.24050	169.8027	-1.463402
15.29050	169.8025	-1.467139
15.34050	169.8019	-1.470595
15.39050	169.8020	-1.474103
15.44050	169.8024	-1.477717
15.49050	169.8017	-1.481343
15.54050	169.8015	-1.484873
15.59050	169.8013	-1.488496
15.64050	169.8016	-1.492118
15.69217	169.8014	-1.495892
15.74216	169.8018	-1.499362
15.79216	169.8015	-1.502790
15.84216	169.8014	-1.505862
15.89384	169.8017	-1.509172
15.94384	169.8007	-1.512294
15.99383	169.8008	-1.515384
16.04383	169.8011	-1.518534
16.09383	169.8008	-1.521425
16.14383	169.8012	-1.524146
16.19383	169.8006	-1.526928
16.24383	169.8015	-1.529621
16.29383	169.8021	-1.532506
16.34383	169.8015	-1.535383
16.39383	169.8016	-1.538201
16.44383	169.8020	-1.541044
16.49383	169.8016	-1.543581
16.54383	169.8010	-1.545759
16.59383	169.8012	-1.547814
16.64383	169.8008	-1.549797
16.69383	169.8006	-1.551661
16.74383	169.8001	-1.553416
16.79383	169.8006	-1.554961
16.84383	169.7994	-1.556365
16.89383	169.7992	-1.557940
16.94550	169.7999	-1.559385
16.99550	169.7993	-1.560781
17.04550	169.7990	-1.562214
17.09550	169.7986	-1.563784
17.14716	169.7982	-1.565342
17.19716	169.7984	-1.567102
17.24716	169.7978	-1.568934
17.29716	169.7976	-1.570594
17.34716	169.7981	-1.572501
17.39716	169.7969	-1.574666
17.44716	169.7977	-1.576670
17.49716	169.7980	-1.578546
17.54716	169.7974	-1.580538
17.59716	169.7968	-1.582422
17.64716	169.7964	-1.584250
17.69716	169.7974	-1.586332
17.74716	169.7972	-1.588217
17.79716	169.7970	-1.589842
17.84716	169.7977	-1.591608
17.89716	169.7974	-1.593120
17.94716	169.7966	-1.594729
17.99716	169.7969	-1.596362
18.04716	169.7977	-1.598016
18.09716	169.7975	-1.599660
18.14716	169.7972	-1.601078
18.19716	169.7981	-1.602554
18.24883	169.7978	-1.603945
18.29883	169.7972	-1.605267
18.34883	169.7978	-1.606574
18.39883	169.7975	-1.607980
18.45050	169.7981	-1.609255
18.50050	169.7974	-1.610496
18.55050	169.7975	-1.611601
18.60050	169.7972	-1.612474
18.65050	169.7965	-1.613266
18.70050	169.7966	-1.614146
18.75050	169.7974	-1.614850
18.80050	169.7963	-1.615319
18.85050	169.7963	-1.615877
18.90050	169.7962	-1.616430
18.95050	169.7961	-1.616996
19.00050	169.7955	-1.617630
19.05050	169.7957	-1.618493
19.10050	169.7944	-1.619337
19.15050	169.7947	-1.620248
19.20050	169.7947	-1.621164
19.25050	169.7954	-1.622340
19.30050	169.7961	-1.623394
19.35050	169.7957	-1.624689
19.40050	169.7959	-1.626095
19.45050	169.7966	-1.627866
19.50216	169.7969	-1.629883
19.55216	169.7970	-1.631824
19.60216	169.7966	-1.633449
19.65216	169.7964	-1.634968
19.70383	169.7966	-1.636369
19.75383	169.7974	-1.637638
19.80383	169.7974	-1.638618
19.85383	169.7970	-1.639315
19.90383	169.7968	-1.639669
19.95383	169.7974	-1.640029
20.00383	169.7966	-1.640272
20.05383	169.7969	-1.640516
20.10383	169.7970	-1.641040
20.15383	169.7975	-1.641672
20.20383	169.7960	-1.642313
20.25383	169.7968	-1.642908
20.30383	169.7963	-1.643506
20.35383	169.7962	-1.643976
20.40383	169.7961	-1.644393
20.45383	169.7969	-1.644967
20.50383	169.7964	-1.645364
20.55383	169.7958	-1.645804
20.60383	169.7959	-1.646096
20.65383	169.7960	-1.646579
20.70383	169.7956	-1.646815
20.75383	169.7954	-1.647241
20.80550	169.7958	-1.647656
20.85550	169.7951	-1.648116
20.90550	169.7953	-1.648589
20.95550	169.7950	-1.649082
21.00716	169.7953	-1.649691
21.05716	169.7948	-1.650096
21.10716	169.7952	-1.650572
21.15716	169.7950	-1.651039
21.20717	169.7941	-1.651485
21.25716	169.7935	-1.651936
21.30716	169.7948	-1.652251
21.35716	169.7940	-1.652826
21.40716	169.7935	-1.653488
21.45717	169.7938	-1.654088
21.50716	169.7937	-1.654656
21.55716	169.7937	-1.655429
21.60716	169.7938	-1.656448
21.65716	169.7947	-1.657454
21.70717	169.7954	-1.658594
21.75716	169.7951	-1.659889
21.80716	169.7954	-1.661192
21.85716	169.7954	-1.662649
21.90716	169.7956	-1.664026
21.95717	169.7958	-1.665146
22.00716	169.7956	-1.666177
22.05883	169.7958	-1.666794
22.10883	169.7961	-1.667426
22.15883	169.7960	-1.667900
22.20883	169.7962	-1.668306
22.26050	169.7961	-1.668750
22.31050	169.7957	-1.669118
22.36050	169.7969	-1.669349
22.41050	169.7964	-1.669830
22.46050	169.7964	-1.670269
22.51050	169.7971	-1.670882
22.56050	169.7963	-1.671244
22.61050	169.7961	-1.671318
22.66050	169.7952	-1.671256
22.71050	169.7960	-1.671337
22.76050	169.7961	-1.671333
22.81050	169.7954	-1.671309
22.86050	169.7963	-1.671379
22.91050	169.7958	-1.671320
22.96050	169.7953	-1.671201
23.01050	169.7953	-1.671033
23.06050	169.7948	-1.670944
23.11050	169.7956	-1.671013
23.16050	169.7955	-1.671149
23.21050	169.7956	-1.671329
23.26050	169.7944	-1.671257
23.31050	169.7949	-1.671245
23.36216	169.7946	-1.671338
23.41217	169.7941	-1.671344
23.46216	169.7946	-1.671434
23.51216	169.7941	-1.671811
23.56383	169.7942	-1.672333
23.61383	169.7950	-1.672788
23.66383	169.7932	-1.673081
23.71383	169.7936	-1.673151
23.76383	169.7942	-1.673331
23.81383	169.7937	-1.673417
23.86383	169.7936	-1.673593
23.91383	169.7938	-1.674066
23.96383	169.7938	-1.674751
24.01383	169.7944	-1.675474
24.06383	169.7938	-1.676108
24.11383	169.7946	-1.676886
24.16383	169.7947	-1.677873
24.21383	169.7950	-1.678679
24.26383	169.7951	-1.679503
24.31383	169.7950	-1.680124
24.36383	169.7950	-1.680780
24.41383	169.7948	-1.681407
24.46383	169.7956	-1.681691
24.51383	169.7949	-1.681991
24.56383	169.7956	-1.682231
24.61550	169.7949	-1.682238
24.66550	169.7951	-1.682186
24.71550	169.7952	-1.682156
24.76550	169.7951	-1.682162
24.81716	169.7952	-1.682074
24.86716	169.7942	-1.681926
24.91716	169.7950	-1.681843
24.96716	169.7946	-1.681897
25.01716	169.7943	-1.682036
25.06716	169.7950	-1.682478
25.11716	169.7951	-1.682722
25.16716	169.7950	-1.683008
25.21716	169.7944	-1.683253
25.26716	169.7946	-1.683494
25.31716	169.7946	-1.683502
25.36716	169.7947	-1.683634
25.41716	169.7944	-1.683759
25.46716	169.7944	-1.684076
25.51716	169.7943	-1.684437
25.56716	169.7942	-1.684731
25.61716	169.7936	-1.684820
25.66716	169.7940	-1.684842
25.71716	169.7937	-1.684964
25.76716	169.7949	-1.685233
25.81716	169.7939	-1.685482
25.86716	169.7944	-1.685684
25.91883	169.7937	-1.685936
25.96883	169.7937	-1.686307
26.01883	169.7942	-1.686714
26.06883	169.7940	-1.687088
26.12050	169.7938	-1.687574
26.17050	169.7950	-1.688209
26.22050	169.7952	-1.689058
26.27050	169.7950	-1.689880
26.32050	169.7950	-1.690582
26.37050	169.7955	-1.691630
26.42050	169.7952	-1.692492
26.47050	169.7954	-1.692828
26.52050	169.7956	-1.693296
26.57050	169.7960	-1.693508
26.62050	169.7956	-1.693528
26.67050	169.7959	-1.693555
26.72050	169.7958	-1.693609
26.77050	169.7952	-1.693618
26.82050	169.7957	-1.693922
26.87050	169.7952	-1.694384
26.92050	169.7956	-1.694521
26.97050	169.7958	-1.694699
27.02050	169.7955	-1.694653
27.07050	169.7953	-1.694727
27.12050	169.7956	-1.694751
27.17216	169.7954	-1.694736
27.22216	169.7954	-1.694684
27.27216	169.7959	-1.694633
27.32217	169.7956	-1.694528
27.37383	169.7951	-1.694406
27.42383	169.7948	-1.694275
27.47383	169.7952	-1.694281
27.52383	169.7948	-1.694311
27.57383	169.7944	-1.694351
27.62383	169.7948	-1.694456
27.67383	169.7945	-1.694406
27.72383	169.7944	-1.694618
27.77383	169.7946	-1.694754
27.82383	169.7947	-1.695145
27.87383	169.7944	-1.695659
27.92383	169.7954	-1.696200
27.97383	169.7934	-1.696620
28.02383	169.7946	-1.696800
28.07383	169.7934	-1.697001
28.12383	169.7933	-1.697050
28.17383	169.7941	-1.697280
28.22383	169.7948	-1.697452
28.27383	169.7936	-1.697626
28.32383	169.7946	-1.697822
28.37383	169.7940	-1.698218
28.42383	169.7938	-1.698562
28.47550	169.7942	-1.698908
28.52550	169.7933	-1.699270
28.57550	169.7942	-1.699547
28.62550	169.7941	-1.699826
28.67717	169.7931	-1.700030
28.72717	169.7938	-1.699979
28.77717	169.7944	-1.700087
28.82717	169.7949	-1.700294
28.87716	169.7940	-1.700387
28.92717	169.7942	-1.700485
28.97717	169.7948	-1.700632
29.02717	169.7937	-1.700798
29.07717	169.7940	-1.700968
29.12716	169.7944	-1.701045
29.17717	169.7948	-1.701458
29.22717	169.7954	-1.702060
29.27717	169.7949	-1.702480
29.32717	169.7954	-1.702848
29.37716	169.7951	-1.702835
29.42717	169.7949	-1.702734
29.47717	169.7951	-1.702897
29.52717	169.7953	-1.702783
29.57717	169.7954	-1.702504
29.62716	169.7947	-1.702179
29.67717	169.7944	-1.702058
29.72883	169.7947	-1.701880
29.77883	169.7950	-1.701981
29.82883	169.7940	-1.701843
29.87883	169.7945	-1.701780
29.93050	169.7944	-1.701686
29.98050	169.7938	-1.701484
30.03050	169.7940	-1.701228
30.08050	169.7938	-1.700855
30.13050	169.7931	-1.700259
30.18050	169.7932	-1.699769
30.23050	169.7930	-1.699415
30.28050	169.7936	-1.699276
30.33050	169.7937	-1.699541
30.38050	169.7933	-1.699782
30.43050	169.7930	-1.700056
30.48050	169.7944	-1.700764
30.53050	169.7939	-1.701569
30.58050	169.7939	-1.702067
30.63050	169.7938	-1.702534
30.68050	169.7948	-1.702815
30.73050	169.7948	-1.703208
30.78050	169.7947	-1.703476
30.83050	169.7945	-1.703720
30.88050	169.7944	-1.703789
30.93050	169.7950	-1.704188
30.98050	169.7949	-1.704694
31.03216	169.7942	-1.704784
31.08216	169.7948	-1.704820
31.13216	169.7940	-1.704797
31.18216	169.7951	-1.704769
31.23383	169.7942	-1.704702
31.28383	169.7944	-1.704318
31.33383	169.7946	-1.704124
31.38383	169.7939	-1.703983
31.43383	169.7939	-1.703853
31.48383	169.7944	-1.703875
31.53383	169.7946	-1.704009
31.58383	169.7944	-1.704156
31.63383	169.7941	-1.704129
31.68383	169.7940	-1.704183
31.73383	169.7942	-1.704355
31.78383	169.7934	-1.704412
31.83383	169.7948	-1.704655
31.88383	169.7944	-1.704917
31.93384	169.7948	-1.705382
31.98383	169.7942	-1.705948
32.03383	169.7949	-1.706580
32.08383	169.7945	-1.707003
32.13383	169.7952	-1.707461
32.18384	169.7954	-1.707789
32.23383	169.7956	-1.708042
32.28550	169.7955	-1.708624
32.33550	169.7958	-1.709016
32.38550	169.7954	-1.709148
32.43550	169.7953	-1.709358
32.48717	169.7955	-1.709368
32.53717	169.7947	-1.709494
32.58716	169.7954	-1.709300
32.63716	169.7950	-1.709104
32.68716	169.7946	-1.708576
32.73717	169.7948	-1.708172
32.78717	169.7944	-1.707966
32.83716	169.7949	-1.707689
32.88716	169.7942	-1.707377
32.93716	169.7938	-1.707124
32.98717	169.7946	-1.707175
33.03717	169.7942	-1.707313
33.08716	169.7945	-1.707594
33.13716	169.7941	-1.707867
33.18716	169.7939	-1.708032
33.23717	169.7939	-1.708073
33.28717	169.7932	-1.707994
33.33716	169.7934	-1.708034
33.38716	169.7929	-1.707858
33.43716	169.7938	-1.707716
33.48717	169.7939	-1.708154
33.53717	169.7948	-1.708839
33.58883	169.7934	-1.709209
33.63883	169.7940	-1.709602
33.68883	169.7939	-1.710208
33.73883	169.7944	-1.710620
33.79050	169.7938	-1.710915
33.84050	169.7952	-1.710915
33.89050	169.7944	-1.711160
33.94050	169.7945	-1.711392
33.99050	169.7950	-1.711504
34.04050	169.7947	-1.711584
34.09050	169.7945	-1.711536
34.14050	169.7944	-1.711442
34.19050	169.7946	-1.711483
34.24050	169.7954	-1.711565
34.29050	169.7950	-1.711366
34.34050	169.7946	-1.711220
34.39050	169.7959	-1.710988
34.44050	169.7944	-1.710869
34.49050	169.7947	-1.710638
34.54050	169.7948	-1.710554
34.59050	169.7950	-1.710485
34.64050	169.7945	-1.710461
34.69050	169.7944	-1.710159
34.74050	169.7945	-1.709974
34.79050	169.7947	-1.709988
34.84216	169.7949	-1.709882
34.89216	169.7950	-1.709915
34.94216	169.7945	-1.709728
34.99216	169.7948	-1.709647
35.04383	169.7942	-1.709693
35.09384	169.7937	-1.709541
35.14383	169.7950	-1.709610
35.19383	169.7943	-1.709802
35.24383	169.7945	-1.709933
35.29383	169.7942	-1.710116
35.34384	169.7944	-1.709974
35.39383	169.7944	-1.709920
35.44383	169.7941	-1.709897
35.49383	169.7936	-1.709696
35.54383	169.7941	-1.709439
35.59384	169.7943	-1.709434
35.64383	169.7936	-1.709350
35.69383	169.7942	-1.709261
35.74383	169.7939	-1.709301
35.79383	169.7934	-1.709450
35.84384	169.7939	-1.709912
35.89383	169.7934	-1.710236
35.94383	169.7941	-1.710662
35.99383	169.7941	-1.710844
36.04383	169.7948	-1.710982
36.09384	169.7941	-1.711079
36.14550	169.7942	-1.711341
36.19550	169.7948	-1.711750
36.24550	169.7948	-1.712142
36.29550	169.7948	-1.712420
36.34716	169.7946	-1.712776
36.39717	169.7958	-1.713117
36.44717	169.7949	-1.713197
36.49716	169.7955	-1.713118
36.54716	169.7950	-1.712631
36.59716	169.7946	-1.712229
36.64717	169.7951	-1.711769
36.69717	169.7950	-1.711484
36.74716	169.7946	-1.711078
36.79716	169.7949	-1.710995
36.84716	169.7943	-1.710922
36.89717	169.7949	-1.710820
36.94717	169.7943	-1.710633
36.99716	169.7944	-1.710322
37.04716	169.7937	-1.709826
37.09716	169.7941	-1.709412
37.14717	169.7939	-1.709065
37.19717	169.7940	-1.708822
37.24716	169.7941	-1.708960
37.29716	169.7938	-1.709134
37.34716	169.7946	-1.709253
37.39883	169.7937	-1.709411
37.44883	169.7944	-1.709723
37.49883	169.7944	-1.709975
37.54883	169.7942	-1.710347
37.60050	169.7942	-1.710753
37.65050	169.7953	-1.711412
37.70050	169.7943	-1.711849
37.75050	169.7942	-1.712025
37.80050	169.7944	-1.712230
37.85050	169.7941	-1.712178
37.90050	169.7944	-1.712048
37.95050	169.7942	-1.711853
38.00050	169.7941	-1.711488
38.05050	169.7932	-1.711211
38.10050	169.7940	-1.711002
38.15050	169.7930	-1.710931
38.20050	169.7936	-1.710766
38.25050	169.7932	-1.710856
38.30050	169.7939	-1.710958
38.35050	169.7934	-1.711200
38.40050	169.7938	-1.711591
38.45050	169.7934	-1.711881
38.50050	169.7941	-1.712137
38.55050	169.7935	-1.712554
38.60050	169.7943	-1.712996
38.65050	169.7939	-1.713634
38.70216	169.7947	-1.714144
38.75217	169.7945	-1.714615
38.80217	169.7951	-1.715010
38.85217	169.7951	-1.715602
38.90383	169.7953	-1.716070
38.95383	169.7956	-1.716320
39.00383	169.7955	-1.716276
39.05383	169.7951	-1.716324
39.10383	169.7950	-1.716309
39.15383	169.7950	-1.716026
39.20383	169.7948	-1.715674
39.25383	169.7950	-1.715283
39.30383	169.7947	-1.714879
39.35383	169.7948	-1.714398
39.40383	169.7950	-1.713992
39.45383	169.7945	-1.713475
39.50383	169.7944	-1.713079
39.55383	169.7940	-1.712364
39.60383	169.7942	-1.711699
39.65383	169.7942	-1.711304
39.70383	169.7936	-1.710974
39.75383	169.7950	-1.711155
39.80383	169.7939	-1.711480
39.85383	169.7939	-1.711751
39.90383	169.7946	-1.711953
39.95550	169.7944	-1.712176
40.00550	169.7949	-1.712632
40.05550	169.7944	-1.713154
40.10550	169.7946	-1.713582
40.15716	169.7953	-1.714206
40.20716	169.7953	-1.714827
40.25716	169.7954	-1.715047
40.30716	169.7957	-1.715151
40.35716	169.7951	-1.714863
40.40716	169.7951	-1.714612
40.45716	169.7947	-1.714268
40.50716	169.7951	-1.713763
40.55716	169.7950	-1.713501
40.60716	169.7948	-1.713198
40.65716	169.7946	-1.713010
40.70716	169.7944	-1.713116
40.75716	169.7951	-1.713104
40.80716	169.7949	-1.713173
40.85716	169.7956	-1.713321
40.90716	169.7949	-1.713460
40.95716	169.7949	-1.713584
41.00717	169.7946	-1.713699
41.05717	169.7945	-1.713601
41.10717	169.7944	-1.713628
41.15717	169.7950	-1.713735
41.20717	169.7951	-1.713853
41.25883	169.7946	-1.713746
41.30883	169.7950	-1.713719
41.35883	169.7950	-1.713755
41.40883	169.7948	-1.713858
41.46050	169.7942	-1.713928
41.51050	169.7954	-1.713842
41.56050	169.7952	-1.713692
41.61050	169.7955	-1.713699
41.66050	169.7956	-1.713812
41.71050	169.7951	-1.713900
41.76050	169.7948	-1.713724
41.81050	169.7952	-1.713575
41.86050	169.7945	-1.713202
41.90717	169.8034	-1.714242
41.95717	170.0574	-1.839725
42.00717	170.5889	-3.738893
42.05717	171.2284	-6.549400
42.10717	171.9503	-9.502003
42.15717	172.7282	-12.22752
42.20717	173.5501	-14.57902
42.25717	174.4073	-16.54070
42.30717	175.2921	-18.14608
42.35717	176.1958	-19.44342
42.40717	177.1180	-20.50464
42.45717	178.0520	-21.36330
42.50717	178.9975	-22.07288
42.55717	179.9515	-22.67045
42.60717	180.9125	-23.18044
42.65717	181.8773	-23.62117
42.70717	182.8480	-24.01532
42.75717	183.8221	-24.36929
42.80717	184.7984	-24.70161
42.85717	185.7769	-25.00733
42.90883	186.7899	-25.31161
42.95883	187.7703	-25.60572
43.00883	188.7527	-25.90239
43.05883	189.7359	-26.19540
43.11050	190.7503	-26.52432
43.16050	191.7314	-26.85382
43.21050	192.7139	-27.20962
43.26050	193.6939	-27.59656
43.31050	194.6736	-28.01528
43.36050	195.6516	-28.48350
43.41050	196.6266	-29.01170
43.46050	197.5989	-29.61349
43.51050	198.5691	-30.30410
43.56050	199.5328	-31.10575
43.61050	200.4904	-32.05681
43.66050	201.4419	-33.18500
43.71050	202.3840	-34.53858
43.76050	203.3140	-36.12508
43.81050	204.2348	-37.94635
43.86050	205.1439	-39.99306
43.91050	206.0445	-42.25030
43.96050	206.9377	-44.62902
44.01050	207.8256	-47.11612
44.06050	208.7056	-49.85480
44.11050	209.5704	-52.92329
44.16217	210.4475	-56.46044
44.21216	211.2838	-60.11765
44.26216	212.1206	-63.66753
44.31216	212.9730	-66.72193
44.36383	213.8888	-68.98425
44.41383	214.8296	-69.84106
44.46383	215.8510	-68.72030
44.51383	216.9674	-65.56843
44.56383	218.1535	-61.17133
44.61383	219.3830	-55.97505
44.66383	220.6367	-50.43233
44.71383	221.8754	-45.55646
44.76383	223.0713	-41.64350
44.81383	224.2266	-38.58844
44.86383	225.3485	-36.20990
44.91383	226.4428	-34.37027
44.96383	227.5151	-32.95436
45.01383	228.5718	-31.85874
45.06383	229.6154	-31.02969
45.11383	230.6492	-30.40437
45.16383	231.6753	-29.92894
45.21383	232.6940	-29.57855
45.26383	233.7100	-29.32097
45.31383	234.7213	-29.13332
45.36383	235.7302	-29.00032
45.41383	236.7370	-28.90613
45.46550	237.7754	-28.84394
45.51550	238.7787	-28.80963
45.56550	239.7815	-28.79125
45.61550	240.7836	-28.78692
45.66716	241.8189	-28.78651
45.71717	242.8199	-28.79256
45.76717	243.8209	-28.80541
45.81717	244.8225	-28.82720
45.86716	245.8225	-28.85161
45.91716	246.8222	-28.88241
45.96717	247.8224	-28.90630
46.01717	248.8230	-28.93333
46.06717	249.8235	-28.95491
46.11716	250.8246	-28.98275
46.16716	251.8246	-29.01383
46.21717	252.8249	-29.03729
46.26717	253.8251	-29.06492
46.31717	254.8244	-29.09061
46.36716	255.8248	-29.12326
46.41716	256.8246	-29.17179
46.46717	257.8238	-29.21480
46.51717	258.8227	-29.25140
46.56717	259.8230	-29.29878
46.61716	260.8210	-29.34350
46.66716	261.8200	-29.38589
46.71884	262.8536	-29.43330
46.76883	263.8528	-29.47956
46.81883	264.8518	-29.52512
46.86883	265.8510	-29.57138
46.92050	266.8838	-29.62265
46.97050	267.8823	-29.66294
47.02050	268.8814	-29.70786
47.07050	269.8808	-29.76129
47.12050	270.8801	-29.79935
47.17050	271.8802	-29.83471
47.22050	272.8789	-29.87734
47.27050	273.8795	-29.91633
47.32050	274.8790	-29.95270
47.37050	275.8777	-30.00004
47.41716	276.7571	-30.10370
47.46717	277.0616	-29.21154
47.51717	276.9109	-24.05482
47.56717	276.5532	-17.51210
47.61716	276.0532	-10.95240
47.66716	275.4515	-5.108220
47.71717	274.7715	-0.1768663
47.76717	274.0300	3.881280
47.81883	273.2116	7.252843
47.86883	272.3824	9.861066
47.91883	271.5205	11.95176
47.96884	270.6358	13.62917
48.02050	269.7002	15.01637
48.07050	268.7781	16.08778
48.12050	267.8444	16.95764
48.17050	266.8993	17.66517
48.22050	265.9465	18.24538
48.27050	264.9863	18.72058
48.32050	264.0197	19.10786
48.37050	263.0490	19.43305
48.42050	262.0739	19.68537
48.47050	261.0959	19.90936
48.52050	260.1158	20.09676
48.57050	259.1338	20.25661
48.62050	258.1486	20.39051
48.67050	257.1633	20.50858
48.72050	256.1756	20.60896
48.77050	255.1866	20.69603
48.82050	254.1980	20.77074
48.87050	253.2084	20.84294
48.92050	252.2180	20.90428
48.97050	251.2249	20.95905
49.02050	250.2336	21.00194
49.07217	249.2079	21.04256
49.12216	248.2140	21.08192
49.17216	247.2215	21.11308
49.22217	246.2281	21.14028
49.27383	245.1998	21.16642
49.32383	244.2052	21.18790
49.37383	243.2104	21.20180
49.42383	242.2152	21.21152
49.47383	241.2209	21.21796
49.52383	240.2262	21.22424
49.57383	239.2308	21.23154
49.62383	238.2352	21.24080
49.67383	237.2396	21.24878
49.72383	236.2440	21.25870
49.77383	235.2476	21.26646
49.82383	234.2520	21.27308
49.87383	233.2566	21.27856
49.92383	232.2609	21.28283
49.97383	231.2650	21.28587
50.02383	230.2685	21.28872
50.07383	229.2723	21.29167
50.12383	228.2766	21.29400
50.17383	227.2802	21.29734
50.22383	226.2837	21.30117
50.27383	225.2875	21.30473
50.32383	224.2924	21.30941
50.37550	223.2626	21.31392
50.42550	222.2666	21.31776
50.47550	221.2700	21.32126
50.52550	220.2732	21.32442
50.57717	219.2436	21.32775
50.62717	218.2480	21.33160
50.67717	217.2516	21.33489
50.72717	216.2549	21.33792
50.77716	215.2583	21.34038
50.82717	214.2630	21.34212
50.87717	213.2656	21.34306
50.92717	212.2690	21.34322
50.97717	211.2736	21.34334
51.02716	210.2770	21.34336
51.07717	209.2801	21.34336
51.12717	208.2837	21.34263
51.17717	207.2866	21.34077
51.22717	206.2907	21.33846
51.27717	205.2939	21.33570
51.32717	204.2972	21.33291
51.37717	203.3006	21.33030
51.42717	202.3047	21.32772
51.47717	201.3088	21.32431
51.52717	200.3114	21.32127
51.57717	199.3155	21.31850
51.62883	198.2856	21.31620
51.67883	197.2889	21.31458
51.72883	196.2921	21.31274
51.77883	195.2950	21.31141
51.83050	194.2654	21.31072
51.88050	193.2686	21.31018
51.93050	192.2724	21.30958
51.98050	191.2744	21.30838
52.03050	190.2782	21.30689
52.08050	189.2813	21.30426
52.13050	188.2837	21.30216
52.18050	187.2871	21.29912
52.23050	186.2893	21.29559
52.28050	185.2924	21.29203
52.33050	184.2961	21.28788
52.38050	183.2996	21.28300
52.43050	182.3028	21.27845
52.48050	181.3058	21.27393
52.53050	180.3087	21.26945
52.58050	179.3120	21.26554
52.63050	178.3151	21.26233
52.68050	177.3176	21.26039
52.73050	176.3208	21.25925
52.78050	175.3236	21.25843
52.83050	174.3272	21.25803
52.88050	173.3303	21.25789
52.93217	172.3000	21.25766
52.98217	171.3032	21.25692
53.03217	170.3060	21.25578
53.08217	169.3088	21.25475
53.13383	168.2795	21.25379
53.18383	167.2815	21.25366
53.23383	166.2848	21.25409
53.28383	165.2894	21.26105
53.33383	164.2941	21.31953
53.38383	163.3022	21.45916
53.43383	162.3159	21.72106
53.48383	161.3380	22.19777
53.53383	160.3763	23.04933
53.58383	159.4391	24.46900
53.63383	158.5350	26.64666
53.68383	157.6744	29.68543
53.73383	156.8550	33.53004
53.78383	156.0646	37.87252
53.83383	155.2882	42.27685
53.88383	154.4999	46.30217
53.93383	153.6827	49.60387
53.98383	152.8212	51.91758
54.03383	151.9056	53.12844
54.08383	150.9352	53.17610
54.13383	149.9074	52.14484
54.18550	148.7954	50.10617
54.23550	147.6791	47.45492
54.28550	146.5409	44.47093
54.33550	145.3942	41.44261
54.38716	144.2137	38.49474
54.43716	143.0844	35.94660
54.48717	141.9729	33.75430
54.53716	140.8756	31.89371
54.58716	139.7948	30.32542
54.63716	138.7278	29.00890
54.68716	137.6721	27.91766
54.73717	136.6255	26.98889
54.78716	135.5882	26.21696
54.83716	134.5551	25.56070
54.88716	133.5274	25.00554
54.93716	132.5056	24.53601
54.98717	131.4871	24.13348
55.03716	130.4714	23.78309
55.08716	129.4591	23.48712
55.13716	128.4464	23.22325
55.18716	127.4368	22.99843
55.23717	126.4284	22.79204
55.28716	125.4212	22.60132
55.33716	124.4114	22.34739
55.38716	123.4060	22.19230
55.43716	122.4014	22.05132
55.48882	121.3638	21.91472
55.53882	120.3601	21.79256
55.58882	119.3576	21.67577
55.63882	118.3551	21.57722
55.69050	117.3192	21.47695
55.74050	116.3174	21.38652
55.79050	115.3153	21.29875
55.84050	114.3147	21.21565
55.89050	113.3120	21.13295
55.94050	112.3115	21.05662
55.99050	111.3103	20.98198
56.04050	110.3098	20.90871
56.09050	109.3086	20.83213
56.14050	108.3066	20.75982
56.19050	107.3060	20.68688
56.24050	106.3039	20.61220
56.29050	105.3031	20.53991
56.34050	104.3030	20.46475
56.39050	103.3018	20.39580
56.44050	102.3009	20.32416
56.49050	101.3001	20.24687
56.54050	100.2986	20.17828
56.59050	99.29852	20.10447
56.64050	98.29791	20.03226
56.69050	97.29662	19.96899
56.74216	96.26245	19.89856
56.79217	95.26189	19.83298
56.84217	94.26069	19.76267
56.89216	93.25938	19.69195
56.94384	92.22519	19.61609
56.99382	91.22428	19.54333
57.04382	90.22251	19.47122
57.09384	89.22174	19.39596
57.14384	88.22098	19.32041
57.19384	87.21887	19.24547
57.24382	86.21759	19.16878
57.29382	85.21649	19.09097
57.34384	84.21628	19.02135
57.39384	83.21559	18.95307
57.44384	82.21461	18.88273
57.49382	81.21343	18.80281
57.54382	80.21220	18.72467
57.59384	79.21052	18.65537
57.64384	78.20749	18.58360
57.69384	77.20751	18.51929
57.74382	76.20730	18.46147
57.79382	75.20716	18.40868
57.84384	74.20724	18.36220
57.89384	73.20796	18.31766
57.94384	72.20686	18.26784
57.99382	71.20766	18.21095
58.04550	70.17304	18.16156
58.09550	69.17378	18.11296
58.14550	68.17334	18.05387
58.19550	67.17243	17.99450
58.24717	66.13940	17.92838
58.29717	65.13855	17.86988
58.34716	64.13856	17.82928
58.39717	63.13871	17.75090
58.44717	62.13744	17.68529
58.49717	61.13638	17.61160
58.54717	60.13623	17.54181
58.59716	59.13600	17.47552
58.64717	58.13492	17.40611
58.69717	57.13461	17.33731
58.74717	56.13373	17.27666
58.79717	55.13231	17.21211
58.84716	54.12490	16.99182
58.89717	53.12338	16.96544
58.94717	52.12368	16.92040
58.99717	51.12343	16.86847
59.04717	50.12248	16.80796
59.09716	49.12210	16.75200
59.14717	48.12140	16.69358
59.19717	47.12046	16.62993
59.24717	46.11957	16.57172
59.29883	45.08568	16.50884
59.34882	44.08458	16.44548
59.39883	43.08420	16.37464
59.44883	42.08164	16.30486
59.50050	41.04636	16.22431
59.55050	40.04478	16.15451
59.60050	39.04213	16.07826
59.65050	38.04088	15.99897
59.70050	37.03867	15.91512
59.75050	36.03594	15.83735
59.80050	35.03352	15.75824
59.85050	34.03069	15.67486
59.90050	33.02838	15.58740
59.95050	32.02654	15.50863
60.00050	31.02582	15.42459
60.05050	30.02270	15.34639
60.10050	29.02072	15.26894
60.15050	28.01772	15.18060
60.20050	27.01545	15.09678
60.25050	26.01250	15.00776
60.30050	25.00929	14.91919
60.35050	24.00465	14.83278
60.39717	23.07430	14.72974
60.44717	22.46094	15.19559
60.49883	22.51361	13.63639
60.54883	22.78942	10.48074
60.59882	23.24600	6.888234
60.64883	23.81529	3.365813
60.70050	24.49709	0.1296636
60.75050	25.22743	-2.542863
60.80050	26.01138	-4.760782
60.85050	26.83560	-6.580268
60.90050	27.69276	-8.054350
60.95050	28.57636	-9.254762
61.00050	29.47994	-10.22342
61.05050	30.39990	-11.01188
61.10050	31.33171	-11.65713
61.15050	32.27592	-12.18928
61.20050	33.22609	-12.63262
61.25050	34.18494	-13.00607
61.30050	35.14945	-13.32526
61.35050	36.11911	-13.59926
61.40050	37.09142	-13.83984
61.45050	38.06717	-14.05946
61.50050	39.04538	-14.24841
61.55050	40.02630	-14.40898
61.60050	41.00914	-14.56367
61.65050	41.99426	-14.69505
61.70050	42.98072	-14.80451
61.75050	43.96846	-14.91831
61.80217	44.99128	-15.02098
61.85217	45.98119	-15.11512
61.90217	46.97291	-15.20386
61.95216	47.96399	-15.29703
62.00383	48.99122	-15.38717
62.05383	49.98358	-15.47515
62.10383	50.97754	-15.56064
62.15383	51.97200	-15.64486
62.20383	52.96672	-15.72920
62.25383	53.96094	-15.80803
62.30383	54.95610	-15.88616
62.35383	55.95232	-15.96691
62.40383	56.94780	-16.04664
62.45383	57.94302	-16.12128
62.50383	58.94052	-16.19681
62.55383	59.93754	-16.26604
62.60383	60.93372	-16.33927
62.65383	61.93080	-16.41798
62.70383	62.92824	-16.49139
62.75383	63.92543	-16.56812
62.80383	64.92235	-16.64036
62.85383	65.91962	-16.71320
62.90383	66.91804	-16.78951
62.95383	67.91544	-16.86200
63.00383	68.91288	-16.93997
63.05550	69.94481	-17.01878
63.10550	70.94166	-17.09008
63.15550	71.94024	-17.16123
63.20550	72.93812	-17.23844
63.25717	73.96850	-17.31336
63.30717	74.96616	-17.38699
63.35717	75.96418	-17.46202
63.40717	76.96103	-17.53876
63.45717	77.95958	-17.62003
63.50717	78.95644	-17.69707
63.55717	79.95369	-17.77464
63.60717	80.95124	-17.86180
63.65717	81.94866	-17.94474
63.70717	82.94616	-18.02354
63.75717	83.94366	-18.10502
63.80717	84.94164	-18.19144
63.85717	85.93976	-18.27678
63.90718	86.93671	-18.35971
63.95717	87.93424	-18.44335
64.00718	88.93139	-18.52913
64.05717	89.92929	-18.61372
64.10718	90.92675	-18.70237
64.15718	91.92450	-18.78536
64.20717	92.92324	-18.86970
64.25718	93.92053	-18.94982
64.30717	94.91797	-19.03408
64.35884	95.94830	-19.12207
64.40884	96.94528	-19.20826
64.45883	97.94328	-19.28711
64.50884	98.94040	-19.37546
64.56050	99.97038	-19.45870
64.61050	100.9683	-19.54531
64.66050	101.9656	-19.63178
64.71050	102.9637	-19.71802
64.76050	103.9606	-19.80086
64.81050	104.9584	-19.88744
64.86050	105.9565	-19.97958
64.91050	106.9532	-20.06879
64.96050	107.9494	-20.15171
65.01050	108.9478	-20.24234
65.06050	109.9441	-20.32944
65.11050	110.9430	-20.42187
65.16050	111.9386	-20.50770
65.21050	112.9359	-20.59418
65.26050	113.9329	-20.68616
65.31050	114.9300	-20.76824
65.36050	115.9269	-20.85745
65.41050	116.9242	-20.94734
65.46050	117.9229	-21.03464
65.51050	118.9201	-21.12620
65.56050	119.9170	-21.21982
65.61218	120.9473	-21.31440
65.66218	121.9442	-21.41394
65.71218	122.9416	-21.51352
65.76218	123.9381	-21.61320
65.81384	124.9684	-21.72389
65.86384	125.9649	-21.82462
65.91382	126.9629	-21.92676
65.96384	127.9592	-22.02256
66.01384	128.9559	-22.11960
66.06384	129.9538	-22.21967
66.11384	130.9506	-22.32407
66.16382	131.9474	-22.43422
66.21384	132.9434	-22.53782
66.26384	133.9406	-22.64129
66.31384	134.9369	-22.75320
66.36384	135.9331	-22.87039
66.41382	136.9296	-22.98313
66.46384	137.9257	-23.10345
66.51384	138.9225	-23.22228
66.56384	139.9182	-23.34378
66.61384	140.9135	-23.47053
66.66382	141.9107	-23.59498
66.71384	142.9047	-23.72563
66.76384	143.9015	-23.85053
66.81384	144.8967	-23.98076
66.86384	145.8917	-24.10236
66.91550	146.9199	-24.23652
66.96550	147.9152	-24.36999
67.01550	148.9104	-24.50550
67.06550	149.9056	-24.63840
67.11718	150.9334	-24.77374
67.16718	151.9290	-24.91066
67.21718	152.9238	-25.04466
67.26716	153.9186	-25.18750
67.31718	154.9145	-25.32550
67.36718	155.9108	-25.46230
67.41718	156.9062	-25.59703
67.46718	157.9017	-25.71552
67.51716	158.8981	-25.83755
67.56718	159.8942	-25.93859
67.61718	160.8923	-26.02178
67.66718	161.8916	-26.09940
67.71718	162.8900	-26.15213
67.76716	163.8898	-26.19308
67.81718	164.8900	-26.23220
67.86718	165.8901	-26.26729
67.91718	166.8901	-26.31586
67.96718	167.8899	-26.37216
68.01716	168.8885	-26.43116
68.06718	169.8863	-26.49911
68.11718	170.8835	-26.58384
68.16884	171.9158	-26.68772
68.21884	172.9124	-26.80324
68.26882	173.9091	-26.92034
68.31884	174.9050	-27.04968
68.37050	175.9330	-27.19556
68.42050	176.9268	-27.35378
68.47050	177.9192	-27.52652
68.52050	178.9122	-27.71617
68.57050	179.9041	-27.92844
68.62050	180.8954	-28.16082
68.67050	181.8847	-28.41570
68.72050	182.8732	-28.69841
68.77050	183.8612	-29.01026
68.82050	184.8460	-29.35500
68.87050	185.8312	-29.73651
68.92050	186.8130	-30.15966
68.97050	187.7940	-30.62951
69.02050	188.7719	-31.15130
69.07050	189.7472	-31.71184
69.12050	190.7218	-32.32637
69.17050	191.6949	-32.95847
69.22050	192.6666	-33.62079
69.27050	193.6375	-34.29282
69.32050	194.6065	-34.97961
69.37050	195.5754	-35.69639
69.42050	196.5414	-36.44983
69.47218	197.5391	-37.28780
69.52218	198.5004	-38.17051
69.57218	199.4589	-39.13124
69.62218	200.4130	-40.16888
69.67384	201.3964	-41.31220
69.72384	202.3456	-42.47504
69.77384	203.2944	-43.64497
69.82384	204.2440	-44.76440
69.87384	205.1985	-45.73211
69.92384	206.1638	-46.42719
69.97384	207.1496	-46.59450
70.02384	208.1676	-45.95837
70.07384	209.2277	-44.37950
70.12384	210.3284	-42.02940
70.17384	211.4505	-39.35359
70.22384	212.5754	-36.77075
70.27384	213.6870	-34.56940
70.32384	214.7772	-32.80804
70.37384	215.8500	-31.42440
70.42384	216.9061	-30.34130
70.47384	217.9510	-29.51020
70.52384	218.9855	-28.86039
70.57384	220.0125	-28.35842
70.62384	221.0334	-27.97704
70.67384	222.0501	-27.68838
70.72551	223.0960	-27.46586
70.77550	224.1060	-27.30743
70.82550	225.1140	-27.19518
70.87550	226.1196	-27.11075
70.92718	227.1572	-27.06000
70.97718	228.1614	-27.02109
71.02718	229.1640	-27.00354
71.07718	230.1662	-26.99946
71.12718	231.1673	-26.99974
71.17718	232.1696	-27.00493
71.22718	233.1699	-27.02806
71.27718	234.1711	-27.05576
71.32718	235.1716	-27.09010
71.37718	236.1715	-27.12864
71.42718	237.1708	-27.15572
71.47718	238.1709	-27.19453
71.52718	239.1712	-27.23225
71.57718	240.1710	-27.27265
71.62718	241.1706	-27.32144
71.67718	242.1709	-27.37350
71.72718	243.1709	-27.41890
71.77718	244.1705	-27.46693
71.82718	245.1696	-27.50710
71.87718	246.1694	-27.54932
71.92718	247.1683	-27.59774
71.97718	248.1683	-27.63965
72.02884	249.2005	-27.68292
72.07884	250.2006	-27.72780
72.12884	251.1999	-27.77887
72.17884	252.2001	-27.82712
72.23050	253.2325	-27.87433
72.28050	254.2322	-27.92191
72.33050	255.2311	-27.96404
72.38050	256.2308	-28.01572
72.43050	257.2293	-28.07875
72.48050	258.2286	-28.13198
72.53050	259.2270	-28.18866
72.58050	260.2263	-28.25019
72.63050	261.2246	-28.30693
72.68050	262.2244	-28.36774
72.73050	263.2234	-28.43352
72.78050	264.2222	-28.49169
72.83050	265.2207	-28.55302
72.88050	266.2188	-28.62008
72.93050	267.2175	-28.69982
72.98050	268.2154	-28.78552
73.03050	269.2129	-28.87212
73.08050	270.2097	-28.98602
73.13050	271.2056	-29.12344
73.18050	272.1988	-29.29808
-2.000000	5.000000	0.0000000