File: 2-C1(0.8mol%)+C20(0.6mol%)/matlab/170-1.txt
CLOSED
Version	1.0
Language	English
Mode	Standard
Run	10
RunSerial	11887
Instrument	DSC Q2000 V24.11 Build 124
Module	DSC Standard Cell RC
Operator	Jing
File	\\Ae520-1454\ta\Data\DSC\UQ Composites\Nan\C1(7.5)+C20P(3)+CL(Hotplate MixtureAB)\170-1
ProcName	Ramp
InstSerial	2000-0883
AutoSerial	1293
Sample	Iso170-1
Size	47.0000	mg
PanMass	Not available
PanResist	Automatic Automatic  K/W
PanFactor	Default Default
Method	Ramp
Comment
Xcomment	Pan: Tzero Aluminum Hermetic
Xcomment	Gas1: Nitrogen 50.0 ml/min
Xcomment	Gas2: Nitrogen 50.0 ml/min
Text
Exotherm	UP
Kcell	1.05230
Cpconst	Standard: 0.938
Calib	-38.6961
TempCal	1	pts	157.46	156.60
TzeroDt	-87.6168 -0.0009 -1.4231
TzeroDtz	-87.6168 0.0057 6.9570
InstCalFile	Tzero: \\Ae520-1454\ta\Data\DSC\Calibration\2017\CALIBRATION\1562_RCS (90)_05_18_2017 10_50_44.TZR
InstCalFile	Baseline: \\Ae520-1454\ta\Data\DSC\Calibration\2017\2017-05-17_Calibration.001
InstCalFile	Sapphire: \\Ae520-1454\ta\Data\DSC\Calibration\2017\2017-05-17_Saphire.001
InstCalDate	Tzero 2017-05-18 Time 10:50:44
TempRange	-87.39 to 398.39 °C at 10.00 °C/min Heat Only
AutoZero	Delta T Offset 0.000 uV
AutoZero	Delta T0 Offset 0.000 uV
MultiptCal	0
MultiPtDesc	0) Not set
AutoCellConst	Calibration Date 2017-05-18 16:59:28
Controls	Gas 1  Event Off  Sampling 0.2
Cell#	RC-01562
CoolingUnit	RCS (90)
SelHeatFlow	Heat Flow T4 (mW)
AutoLidII	Installed
AutoAnalysis	Off
MacroFile
Nsig	3
Sig1	Time (min)
Sig2	Temperature (°C)
Sig3	Heat Flow (mW)
Date	2017-06-23
Time	03:06:05
OrgMethod	1: Equilibrate at 20.00 °C
OrgMethod	2: Ramp 80.00 °C/min to 170.00 °C
OrgMethod	3: Mark end of cycle 1
OrgMethod	4: Isothermal for 40.00 min
OrgMethod	5: Mark end of cycle 2
OrgMethod	6: Ramp 20.00 °C/min to 280.00 °C
OrgMethod	7: Mark end of cycle 3
OrgMethod	8: Ramp 20.00 °C/min to 20.00 °C
OrgMethod	9: Mark end of cycle 4
OrgMethod	10: Ramp 20.00 °C/min to 280.00 °C
OrgMethod	11: Mark end of cycle 5
OrgFile	C:\Users\jarra\Desktop\DSC\2-C1(0.8mol%)+C20(0.6mol%)\170-1
StartOfData
4.99994E-4	20.07278	0.5391452
0.05216665	20.26782	0.8468406
0.1021667	21.79235	0.1820283
0.1521666	24.17668	-5.738804
0.2038333	26.96531	-14.43087
0.2538334	29.92046	-23.38953
0.3038333	33.05722	-32.01920
0.3538333	36.33446	-39.84494
0.4038334	39.72791	-46.74793
0.4538334	43.21666	-52.74878
0.5038334	46.77457	-58.07541
0.5538334	50.37512	-63.13096
0.6038332	54.02812	-67.35751
0.6538332	57.71814	-71.53411
0.7038332	61.37318	-76.95684
0.7538332	65.00182	-82.59293
0.8038334	68.64426	-88.05224
0.8538332	72.25144	-95.18458
0.9038334	75.56508	-110.7337
0.9538334	78.31600	-136.3243
1.003833	80.87648	-161.6932
1.053834	83.54897	-185.4106
1.103833	86.34319	-206.3839
1.153834	89.32621	-223.5078
1.203834	92.83956	-235.4690
1.255500	97.05859	-241.6578
1.305500	101.1373	-249.9278
1.355500	105.2161	-256.0640
1.405500	109.2931	-258.5070
1.457167	113.5045	-248.3694
1.507167	117.5818	-228.2042
1.557167	121.8097	-213.4341
1.607167	126.5430	-201.5049
1.657167	131.1606	-191.4131
1.707167	135.6701	-183.2986
1.757167	140.0936	-176.7224
1.807167	144.4504	-171.2568
1.857167	148.7570	-166.5041
1.905500	152.8715	-162.4970
1.955500	156.2898	-159.8892
2.007167	158.3748	-150.5482
2.057167	160.0086	-135.8688
2.107167	161.3570	-119.9196
2.157167	162.5109	-104.4148
2.207167	163.4984	-90.38231
2.257167	164.3455	-78.01279
2.307167	165.0777	-67.28970
2.357167	165.7108	-58.06397
2.407167	166.2554	-50.16122
2.457167	166.7284	-43.38144
2.507167	167.1380	-37.54732
2.557167	167.4916	-32.51909
2.607167	167.7972	-28.18429
2.657167	168.0627	-24.43723
2.707167	168.2942	-21.20216
2.757167	168.4939	-18.39925
2.807167	168.6683	-15.96592
2.857167	168.8197	-13.84235
2.907167	168.9531	-11.98599
2.957167	169.0692	-10.35726
3.008833	169.1750	-8.878374
3.058833	169.2654	-7.615094
3.108833	169.3450	-6.492407
3.158834	169.4156	-5.495668
3.210500	169.4810	-4.573878
3.260500	169.5371	-3.770900
3.310500	169.5869	-3.043620
3.360500	169.6324	-2.380772
3.410500	169.6739	-1.771900
3.460500	169.7117	-1.208066
3.510500	169.7457	-0.6807947
3.560500	169.7773	-0.1798173
3.610500	169.8077	0.2883063
3.660500	169.8356	0.7432431
3.710500	169.8622	1.181236
3.760500	169.8876	1.606078
3.810500	169.9125	2.022328
3.860500	169.9358	2.431051
3.910500	169.9594	2.838228
3.960500	169.9818	3.238192
4.010500	170.0039	3.643485
4.060500	170.0258	4.044494
4.110500	170.0476	4.450172
4.160500	170.0694	4.860354
4.210500	170.0921	5.272469
4.262167	170.1142	5.706422
4.312167	170.1362	6.132262
4.362167	170.1591	6.567862
4.413834	170.1824	7.026145
4.463834	170.2054	7.482788
4.513834	170.2295	7.947481
4.563834	170.2533	8.428368
4.613834	170.2767	8.918199
4.663834	170.3026	9.426501
4.713834	170.3285	9.947899
4.763834	170.3550	10.48278
4.813834	170.3827	11.03683
4.863834	170.4108	11.60587
4.913834	170.4394	12.19418
4.963834	170.4684	12.80219
5.013834	170.4995	13.42283
5.063834	170.5301	14.06495
5.113834	170.5638	14.72818
5.163833	170.5968	15.40568
5.213833	170.6309	16.10667
5.263834	170.6658	16.82085
5.313832	170.7018	17.55368
5.363834	170.7379	18.30426
5.413832	170.7758	19.06631
5.465500	170.8148	19.87161
5.515500	170.8526	20.65883
5.565500	170.8924	21.45597
5.615500	170.9311	22.25368
5.667168	170.9717	23.08290
5.717168	171.0109	23.88184
5.767168	171.0493	24.67002
5.817168	171.0873	25.45312
5.867168	171.1254	26.21236
5.917168	171.1622	26.95303
5.967168	171.1973	27.66007
6.017168	171.2310	28.33736
6.067168	171.2638	28.97136
6.117168	171.2929	29.56213
6.167168	171.3200	30.09863
6.217168	171.3448	30.57428
6.267168	171.3654	30.98700
6.317168	171.3842	31.33325
6.367168	171.3988	31.60130
6.417168	171.4108	31.79281
6.467168	171.4170	31.90244
6.517168	171.4197	31.93180
6.567168	171.4198	31.88540
6.617166	171.4134	31.72478
6.668832	171.4039	31.48786
6.718832	171.3904	31.16864
6.768832	171.3730	30.77242
6.818832	171.3509	30.29612
6.870500	171.3247	29.73040
6.920500	171.2959	29.11301
6.970500	171.2646	28.44048
7.020500	171.2308	27.71850
7.070500	171.1950	26.95127
7.120500	171.1568	26.15729
7.170500	171.1172	25.34528
7.220500	171.0782	24.52956
7.270500	171.0383	23.71475
7.320500	170.9997	22.92217
7.370500	170.9621	22.16067
7.420500	170.9276	21.44686
7.470500	170.8944	20.78691
7.520500	170.8637	20.17738
7.570500	170.8362	19.63746
7.620500	170.8122	19.16666
7.670500	170.7920	18.77756
7.720500	170.7753	18.46978
7.770500	170.7636	18.26284
7.820500	170.7566	18.15531
7.872168	170.7548	18.15722
7.922168	170.7586	18.26686
7.972168	170.7676	18.49947
8.022168	170.7824	18.83357
8.073834	170.8021	19.28421
8.123834	170.8259	19.81539
8.173832	170.8553	20.42179
8.223832	170.8860	21.09153
8.273834	170.9206	21.80771
8.323834	170.9556	22.54621
8.373834	170.9926	23.29532
8.423832	171.0282	24.03336
8.473832	171.0630	24.73964
8.523834	171.0961	25.39912
8.573834	171.1264	25.99354
8.623834	171.1536	26.51460
8.673832	171.1762	26.94428
8.723832	171.1930	27.27538
8.773834	171.2064	27.49558
8.823834	171.2145	27.60848
8.873834	171.2164	27.60492
8.923832	171.2122	27.48878
8.973832	171.2026	27.24579
9.023834	171.1889	26.90590
9.075500	171.1681	26.43328
9.125500	171.1426	25.87605
9.175500	171.1124	25.22549
9.225500	171.0783	24.48477
9.277168	171.0381	23.63404
9.327168	170.9971	22.73314
9.377168	170.9512	21.77592
9.427168	170.9025	20.76372
9.477168	170.8525	19.71170
9.527168	170.8006	18.62374
9.577168	170.7476	17.51576
9.627168	170.6933	16.40528
9.677168	170.6400	15.29236
9.727168	170.5857	14.20007
9.777168	170.5334	13.12596
9.827168	170.4819	12.08412
9.877168	170.4334	11.07623
9.927168	170.3841	10.11756
9.977168	170.3401	9.201776
10.02717	170.2973	8.341920
10.07717	170.2565	7.531762
10.12717	170.2186	6.775394
10.17717	170.1840	6.082579
10.22717	170.1522	5.439006
10.27717	170.1223	4.852010
10.32883	170.0942	4.295635
10.37883	170.0694	3.808787
10.42883	170.0468	3.367044
10.48050	170.0259	2.950638
10.53050	170.0080	2.589808
10.58050	169.9912	2.260093
10.63050	169.9762	1.961759
10.68050	169.9637	1.696174
10.73050	169.9499	1.453366
10.78050	169.9401	1.235463
10.83050	169.9294	1.034998
10.88050	169.9206	0.8534572
10.93050	169.9116	0.6923946
10.98050	169.9044	0.5445072
11.03050	169.8975	0.4045242
11.08050	169.8911	0.2804335
11.13050	169.8854	0.1654047
11.18050	169.8801	0.06497997
11.23050	169.8762	-.03300530
11.28050	169.8706	-0.1209361
11.33050	169.8671	-0.2077891
11.38050	169.8625	-0.2818701
11.43050	169.8592	-0.3523330
11.48050	169.8562	-0.4182271
11.53217	169.8530	-0.4832734
11.58217	169.8501	-0.5406818
11.63216	169.8469	-0.5993989
11.68217	169.8448	-0.6496066
11.73383	169.8420	-0.6959272
11.78383	169.8396	-0.7414062
11.83383	169.8380	-0.7857222
11.88383	169.8360	-0.8235510
11.93383	169.8337	-0.8624836
11.98383	169.8319	-0.8993430
12.03383	169.8298	-0.9327469
12.08383	169.8285	-0.9666082
12.13383	169.8267	-0.9974809
12.18383	169.8257	-1.025259
12.23383	169.8250	-1.054520
12.28383	169.8231	-1.083446
12.33383	169.8206	-1.105374
12.38383	169.8204	-1.131702
12.43383	169.8197	-1.155633
12.48383	169.8188	-1.177591
12.53383	169.8174	-1.200176
12.58383	169.8162	-1.220895
12.63383	169.8143	-1.240236
12.68383	169.8135	-1.260057
12.73550	169.8134	-1.279692
12.78550	169.8120	-1.298078
12.83550	169.8111	-1.315238
12.88550	169.8103	-1.330948
12.93716	169.8091	-1.347694
12.98716	169.8093	-1.363476
13.03717	169.8084	-1.379942
13.08717	169.8072	-1.392316
13.13717	169.8071	-1.408290
13.18716	169.8061	-1.421446
13.23716	169.8058	-1.434885
13.28717	169.8041	-1.445847
13.33717	169.8042	-1.459056
13.38717	169.8026	-1.470786
13.43716	169.8031	-1.481479
13.48716	169.8026	-1.492752
13.53717	169.8023	-1.504560
13.58717	169.8014	-1.515338
13.63717	169.7998	-1.526495
13.68716	169.8005	-1.537484
13.73716	169.7996	-1.548738
13.78717	169.7988	-1.559274
13.83717	169.7988	-1.569649
13.88717	169.7976	-1.579795
13.93883	169.7978	-1.589927
13.98883	169.7979	-1.600430
14.03883	169.7970	-1.610152
14.08883	169.7964	-1.619107
14.14050	169.7961	-1.628441
14.19050	169.7956	-1.637472
14.24050	169.7950	-1.646032
14.29050	169.7956	-1.654311
14.34050	169.7946	-1.663021
14.39050	169.7944	-1.670987
14.44050	169.7939	-1.679109
14.49050	169.7938	-1.686926
14.54050	169.7933	-1.694697
14.59050	169.7930	-1.702216
14.64050	169.7928	-1.709581
14.69050	169.7918	-1.717020
14.74050	169.7924	-1.723853
14.79050	169.7924	-1.730707
14.84050	169.7915	-1.737602
14.89050	169.7916	-1.744542
14.94050	169.7918	-1.751284
14.99050	169.7906	-1.757914
15.04050	169.7909	-1.764135
15.09050	169.7910	-1.770279
15.14216	169.7904	-1.776532
15.19217	169.7902	-1.782618
15.24216	169.7905	-1.788479
15.29216	169.7892	-1.793925
15.34383	169.7899	-1.799319
15.39383	169.7901	-1.804520
15.44384	169.7890	-1.809364
15.49384	169.7883	-1.813856
15.54384	169.7884	-1.818163
15.59383	169.7884	-1.822618
15.64383	169.7875	-1.827208
15.69384	169.7885	-1.831782
15.74384	169.7875	-1.836420
15.79384	169.7875	-1.840675
15.84383	169.7873	-1.844921
15.89384	169.7874	-1.849506
15.94384	169.7869	-1.853696
15.99383	169.7861	-1.857722
16.04383	169.7860	-1.861594
16.09383	169.7858	-1.865664
16.14383	169.7862	-1.869615
16.19383	169.7861	-1.873484
16.24383	169.7846	-1.877272
16.29383	169.7853	-1.880900
16.34383	169.7858	-1.884847
16.39550	169.7852	-1.888820
16.44550	169.7852	-1.892678
16.49550	169.7850	-1.896365
16.54716	169.7849	-1.900141
16.59716	169.7853	-1.903789
16.64716	169.7851	-1.907258
16.69716	169.7845	-1.910710
16.74716	169.7848	-1.914144
16.79716	169.7849	-1.917339
16.84716	169.7847	-1.920386
16.89716	169.7852	-1.923796
16.94716	169.7852	-1.927132
16.99716	169.7851	-1.930434
17.04716	169.7850	-1.933966
17.09716	169.7847	-1.937229
17.14716	169.7847	-1.940322
17.19716	169.7846	-1.943216
17.24716	169.7848	-1.946013
17.29716	169.7840	-1.948497
17.34716	169.7846	-1.950478
17.39716	169.7843	-1.952259
17.44716	169.7832	-1.953934
17.49716	169.7842	-1.955474
17.54716	169.7830	-1.956645
17.59883	169.7826	-1.958141
17.64883	169.7824	-1.959785
17.69884	169.7822	-1.961200
17.74883	169.7818	-1.962550
17.80050	169.7817	-1.964301
17.85050	169.7812	-1.966292
17.90050	169.7812	-1.968292
17.95050	169.7818	-1.970169
18.00050	169.7808	-1.972254
18.05050	169.7806	-1.974067
18.10050	169.7805	-1.976123
18.15050	169.7806	-1.978132
18.20050	169.7798	-1.980128
18.25050	169.7808	-1.982362
18.30050	169.7801	-1.984546
18.35050	169.7808	-1.986934
18.40050	169.7808	-1.989558
18.45050	169.7799	-1.991874
18.50050	169.7808	-1.994047
18.55050	169.7801	-1.996206
18.60050	169.7803	-1.998186
18.65050	169.7802	-2.000281
18.70050	169.7805	-2.002370
18.75050	169.7801	-2.004283
18.80216	169.7800	-2.006048
18.85216	169.7803	-2.007631
18.90216	169.7800	-2.009447
18.95216	169.7796	-2.011163
19.00383	169.7797	-2.012948
19.05383	169.7805	-2.014728
19.10383	169.7801	-2.016648
19.15383	169.7798	-2.018275
19.20383	169.7802	-2.019728
19.25383	169.7795	-2.021281
19.30383	169.7804	-2.022988
19.35383	169.7800	-2.024702
19.40383	169.7797	-2.026334
19.45383	169.7799	-2.027472
19.50383	169.7801	-2.028469
19.55383	169.7800	-2.029752
19.60383	169.7801	-2.030846
19.65383	169.7801	-2.032052
19.70383	169.7804	-2.033500
19.75383	169.7803	-2.035297
19.80383	169.7804	-2.037123
19.85383	169.7804	-2.038949
19.90383	169.7810	-2.041018
19.95383	169.7801	-2.042671
20.00550	169.7809	-2.044463
20.05550	169.7802	-2.045722
20.10550	169.7809	-2.047043
20.15550	169.7810	-2.048166
20.20716	169.7799	-2.049032
20.25716	169.7811	-2.049732
20.30716	169.7799	-2.050494
20.35716	169.7800	-2.051014
20.40716	169.7802	-2.051285
20.45716	169.7799	-2.051599
20.50716	169.7792	-2.052208
20.55716	169.7798	-2.052668
20.60716	169.7784	-2.053656
20.65716	169.7794	-2.054809
20.70717	169.7786	-2.055662
20.75716	169.7788	-2.056799
20.80716	169.7790	-2.057894
20.85716	169.7795	-2.058974
20.90716	169.7791	-2.060178
20.95717	169.7789	-2.061520
21.00716	169.7787	-2.062498
21.05716	169.7787	-2.063580
21.10716	169.7796	-2.065208
21.15716	169.7789	-2.066893
21.20883	169.7795	-2.068174
21.25883	169.7791	-2.069035
21.30883	169.7792	-2.070141
21.35883	169.7793	-2.071570
21.41050	169.7791	-2.072968
21.46050	169.7790	-2.074013
21.51050	169.7789	-2.074743
21.56050	169.7793	-2.075417
21.61050	169.7780	-2.075968
21.66050	169.7785	-2.076196
21.71050	169.7787	-2.076332
21.76050	169.7784	-2.076571
21.81050	169.7776	-2.076638
21.86050	169.7774	-2.076869
21.91050	169.7775	-2.077123
21.96050	169.7773	-2.077690
22.01050	169.7772	-2.078253
22.06050	169.7774	-2.079029
22.11050	169.7780	-2.079894
22.16050	169.7772	-2.080570
22.21050	169.7770	-2.081226
22.26050	169.7777	-2.082144
22.31050	169.7777	-2.083202
22.36050	169.7776	-2.084156
22.41050	169.7779	-2.085159
22.46216	169.7779	-2.086416
22.51216	169.7775	-2.087554
22.56216	169.7781	-2.088692
22.61383	169.7777	-2.090230
22.66383	169.7783	-2.091546
22.71383	169.7779	-2.092586
22.76383	169.7777	-2.093684
22.81383	169.7781	-2.094412
22.86383	169.7776	-2.095012
22.91383	169.7777	-2.095313
22.96383	169.7774	-2.095459
23.01383	169.7781	-2.095488
23.06383	169.7780	-2.095720
23.11383	169.7774	-2.096178
23.16383	169.7780	-2.096495
23.21383	169.7772	-2.096770
23.26383	169.7778	-2.097118
23.31383	169.7780	-2.097792
23.36383	169.7775	-2.098459
23.41383	169.7774	-2.099045
23.46383	169.7772	-2.099873
23.51383	169.7780	-2.100424
23.56383	169.7782	-2.101174
23.61383	169.7772	-2.101960
23.66550	169.7772	-2.102421
23.71550	169.7770	-2.102914
23.76550	169.7773	-2.103618
23.81550	169.7770	-2.104379
23.86716	169.7769	-2.104618
23.91716	169.7772	-2.104988
23.96716	169.7766	-2.105465
24.01716	169.7766	-2.105854
24.06716	169.7772	-2.106140
24.11716	169.7760	-2.106253
24.16716	169.7757	-2.106402
24.21716	169.7756	-2.106451
24.26716	169.7757	-2.106724
24.31716	169.7760	-2.106919
24.36716	169.7759	-2.107230
24.41716	169.7758	-2.107616
24.46716	169.7756	-2.108186
24.51716	169.7750	-2.108902
24.56716	169.7756	-2.109715
24.61716	169.7758	-2.110544
24.66716	169.7753	-2.111227
24.71716	169.7754	-2.111824
24.76716	169.7756	-2.112775
24.81716	169.7761	-2.113743
24.86883	169.7756	-2.114436
24.91883	169.7764	-2.114996
24.96883	169.7757	-2.115552
25.01883	169.7766	-2.116053
25.07050	169.7762	-2.116880
25.12050	169.7762	-2.117591
25.17050	169.7769	-2.118572
25.22050	169.7767	-2.119636
25.27050	169.7770	-2.120806
25.32050	169.7772	-2.121796
25.37050	169.7774	-2.122784
25.42050	169.7775	-2.123871
25.47050	169.7775	-2.124688
25.52050	169.7776	-2.125438
25.57050	169.7773	-2.125864
25.62050	169.7774	-2.126070
25.67050	169.7779	-2.126116
25.72050	169.7776	-2.126040
25.77050	169.7776	-2.126096
25.82050	169.7768	-2.125930
25.87050	169.7774	-2.126001
25.92050	169.7763	-2.126000
25.97050	169.7770	-2.125719
26.02050	169.7771	-2.125594
26.07217	169.7767	-2.125406
26.12216	169.7771	-2.125266
26.17216	169.7770	-2.125254
26.22216	169.7769	-2.125078
26.27383	169.7766	-2.125092
26.32383	169.7766	-2.125388
26.37383	169.7761	-2.125530
26.42383	169.7764	-2.125353
26.47383	169.7766	-2.125490
26.52383	169.7773	-2.125679
26.57383	169.7761	-2.125473
26.62383	169.7759	-2.125584
26.67383	169.7756	-2.125752
26.72383	169.7758	-2.125726
26.77383	169.7753	-2.125800
26.82383	169.7753	-2.125980
26.87383	169.7754	-2.126142
26.92383	169.7749	-2.126553
26.97383	169.7759	-2.126755
27.02383	169.7754	-2.127175
27.07383	169.7758	-2.127471
27.12383	169.7756	-2.127799
27.17383	169.7755	-2.128372
27.22383	169.7758	-2.129303
27.27550	169.7756	-2.130674
27.32550	169.7760	-2.132070
27.37550	169.7761	-2.133251
27.42550	169.7763	-2.134303
27.47717	169.7768	-2.135312
27.52717	169.7767	-2.136220
27.57717	169.7766	-2.137102
27.62716	169.7773	-2.137709
27.67717	169.7769	-2.138152
27.72717	169.7774	-2.138540
27.77717	169.7767	-2.138925
27.82717	169.7782	-2.139345
27.87716	169.7768	-2.139666
27.92717	169.7764	-2.139646
27.97717	169.7763	-2.139478
28.02717	169.7768	-2.139346
28.07717	169.7766	-2.139272
28.12716	169.7761	-2.138843
28.17717	169.7767	-2.138240
28.22717	169.7762	-2.137883
28.27717	169.7753	-2.137286
28.32717	169.7754	-2.136805
28.37716	169.7759	-2.136429
28.42717	169.7754	-2.136155
28.47717	169.7753	-2.136191
28.52883	169.7751	-2.136444
28.57883	169.7748	-2.136362
28.62883	169.7753	-2.136225
28.68050	169.7748	-2.136502
28.73050	169.7748	-2.136995
28.78050	169.7758	-2.137842
28.83050	169.7758	-2.138767
28.88050	169.7762	-2.139826
28.93050	169.7753	-2.141127
28.98050	169.7760	-2.142615
29.03050	169.7765	-2.143892
29.08050	169.7768	-2.144838
29.13050	169.7769	-2.145760
29.18050	169.7767	-2.146392
29.23050	169.7772	-2.146888
29.28050	169.7766	-2.147314
29.33050	169.7764	-2.147732
29.38050	169.7768	-2.147906
29.43050	169.7766	-2.148162
29.48050	169.7759	-2.148016
29.53050	169.7772	-2.147686
29.58050	169.7764	-2.147205
29.63050	169.7761	-2.146747
29.68050	169.7760	-2.146316
29.73216	169.7764	-2.145896
29.78216	169.7754	-2.145355
29.83216	169.7755	-2.144500
29.88216	169.7756	-2.143724
29.93383	169.7752	-2.143190
29.98383	169.7761	-2.143338
30.03383	169.7746	-2.143374
30.08383	169.7752	-2.143768
30.13383	169.7752	-2.144268
30.18383	169.7756	-2.144774
30.23383	169.7756	-2.145459
30.28383	169.7752	-2.145986
30.33383	169.7745	-2.146252
30.38383	169.7760	-2.146783
30.43383	169.7751	-2.147146
30.48383	169.7754	-2.147259
30.53383	169.7744	-2.147576
30.58383	169.7759	-2.147979
30.63383	169.7756	-2.148510
30.68383	169.7756	-2.149131
30.73383	169.7749	-2.149802
30.78383	169.7761	-2.150058
30.83383	169.7750	-2.150207
30.88383	169.7764	-2.150703
30.93550	169.7759	-2.151564
30.98550	169.7762	-2.152110
31.03550	169.7759	-2.152566
31.08550	169.7758	-2.152874
31.13716	169.7766	-2.153226
31.18717	169.7761	-2.153383
31.23716	169.7765	-2.153400
31.28717	169.7758	-2.153417
31.33716	169.7762	-2.153499
31.38716	169.7765	-2.154056
31.43717	169.7766	-2.154418
31.48716	169.7767	-2.154729
31.53717	169.7763	-2.154964
31.58716	169.7773	-2.155037
31.63716	169.7764	-2.155216
31.68717	169.7764	-2.155496
31.73716	169.7767	-2.155362
31.78717	169.7754	-2.154972
31.83716	169.7769	-2.154612
31.88716	169.7755	-2.154197
31.93716	169.7761	-2.153694
31.98717	169.7749	-2.153292
32.03717	169.7755	-2.152816
32.08716	169.7753	-2.152360
32.13883	169.7750	-2.152144
32.18883	169.7752	-2.151861
32.23883	169.7751	-2.151692
32.28883	169.7749	-2.151346
32.34050	169.7756	-2.151272
32.39050	169.7751	-2.151328
32.44050	169.7754	-2.152075
32.49050	169.7751	-2.152750
32.54050	169.7752	-2.153326
32.59050	169.7753	-2.153970
32.64050	169.7756	-2.154844
32.69050	169.7762	-2.155859
32.74050	169.7763	-2.156860
32.79050	169.7761	-2.157672
32.84050	169.7766	-2.158106
32.89050	169.7763	-2.158571
32.94050	169.7764	-2.158886
32.99050	169.7756	-2.159054
33.04050	169.7761	-2.158848
33.09050	169.7760	-2.158602
33.14050	169.7758	-2.158373
33.19050	169.7766	-2.158212
33.24050	169.7759	-2.158280
33.29050	169.7759	-2.158177
33.34216	169.7756	-2.157856
33.39216	169.7761	-2.157665
33.44216	169.7753	-2.157253
33.49216	169.7756	-2.156729
33.54383	169.7753	-2.156503
33.59384	169.7758	-2.156313
33.64383	169.7756	-2.156377
33.69383	169.7764	-2.156711
33.74383	169.7760	-2.157264
33.79383	169.7749	-2.157836
33.84384	169.7762	-2.158278
33.89383	169.7756	-2.158785
33.94383	169.7752	-2.159136
33.99383	169.7750	-2.159220
34.04383	169.7756	-2.159043
34.09384	169.7750	-2.159018
34.14383	169.7758	-2.158740
34.19383	169.7750	-2.158352
34.24383	169.7749	-2.157917
34.29383	169.7740	-2.157567
34.34384	169.7743	-2.156996
34.39383	169.7739	-2.156662
34.44383	169.7736	-2.156548
34.49383	169.7747	-2.156992
34.54383	169.7740	-2.157285
34.59550	169.7746	-2.157660
34.64550	169.7753	-2.158238
34.69550	169.7749	-2.159078
34.74716	169.7756	-2.160013
34.79716	169.7746	-2.161008
34.84716	169.7754	-2.162083
34.89717	169.7750	-2.162952
34.94717	169.7755	-2.163616
34.99716	169.7751	-2.164184
35.04716	169.7754	-2.164448
35.09716	169.7761	-2.164916
35.14717	169.7756	-2.165226
35.19717	169.7757	-2.165609
35.24716	169.7752	-2.165609
35.29716	169.7748	-2.165474
35.34716	169.7765	-2.165562
35.39717	169.7756	-2.165655
35.44717	169.7764	-2.165982
35.49716	169.7754	-2.166220
35.54716	169.7757	-2.166020
35.59716	169.7758	-2.166169
35.64717	169.7764	-2.166203
35.69717	169.7763	-2.166330
35.74716	169.7764	-2.166243
35.79883	169.7760	-2.166195
35.84883	169.7748	-2.165770
35.89883	169.7764	-2.165574
35.94883	169.7754	-2.165408
36.00050	169.7759	-2.164863
36.05050	169.7748	-2.164242
36.10050	169.7756	-2.163647
36.15050	169.7750	-2.163305
36.20050	169.7750	-2.162814
36.25050	169.7744	-2.162560
36.30050	169.7745	-2.162135
36.35050	169.7753	-2.162058
36.40050	169.7744	-2.162270
36.45050	169.7749	-2.162516
36.50050	169.7741	-2.162992
36.55050	169.7754	-2.163713
36.60050	169.7748	-2.164494
36.65050	169.7758	-2.165228
36.70050	169.7756	-2.166306
36.75050	169.7747	-2.167114
36.80050	169.7757	-2.167775
36.85050	169.7754	-2.168574
36.90050	169.7752	-2.169246
36.95050	169.7766	-2.169694
37.00217	169.7759	-2.170036
37.05217	169.7756	-2.170144
37.10217	169.7759	-2.170263
37.15216	169.7757	-2.170404
37.20383	169.7760	-2.170388
37.25383	169.7752	-2.170118
37.30383	169.7758	-2.169880
37.35383	169.7760	-2.169778
37.40383	169.7759	-2.169315
37.45383	169.7755	-2.168735
37.50383	169.7752	-2.168166
37.55383	169.7754	-2.167353
37.60383	169.7759	-2.166520
37.65383	169.7742	-2.165718
37.70383	169.7739	-2.164785
37.75383	169.7740	-2.163930
37.80383	169.7745	-2.163515
37.85383	169.7742	-2.163533
37.90383	169.7753	-2.163800
37.95383	169.7756	-2.164631
38.00383	169.7746	-2.165640
38.05383	169.7756	-2.166514
38.10383	169.7755	-2.167432
38.15383	169.7755	-2.167814
38.20550	169.7756	-2.167971
38.25550	169.7756	-2.168205
38.30550	169.7756	-2.168395
38.35550	169.7761	-2.168522
38.40716	169.7759	-2.168434
38.45716	169.7758	-2.168080
38.50716	169.7755	-2.167588
38.55716	169.7756	-2.167188
38.60716	169.7760	-2.167078
38.65716	169.7758	-2.167186
38.70716	169.7756	-2.166898
38.75716	169.7758	-2.166765
38.80716	169.7759	-2.166508
38.85716	169.7758	-2.166317
38.90716	169.7754	-2.166108
38.95716	169.7754	-2.166041
39.00716	169.7756	-2.165754
39.05716	169.7753	-2.165652
39.10716	169.7757	-2.165556
39.15716	169.7753	-2.165222
39.20716	169.7748	-2.165025
39.25716	169.7750	-2.164956
39.30716	169.7749	-2.164932
39.35716	169.7749	-2.164980
39.40883	169.7753	-2.165260
39.45883	169.7753	-2.165303
39.50883	169.7750	-2.165431
39.55883	169.7750	-2.165482
39.61050	169.7754	-2.165624
39.66050	169.7745	-2.165697
39.71050	169.7747	-2.165968
39.76050	169.7750	-2.166204
39.81050	169.7757	-2.166702
39.86050	169.7760	-2.167393
39.91050	169.7752	-2.167985
39.96050	169.7754	-2.168538
40.01050	169.7750	-2.169051
40.06050	169.7760	-2.169637
40.11050	169.7764	-2.170416
40.16050	169.7756	-2.170898
40.21050	169.7756	-2.171140
40.26050	169.7756	-2.171085
40.31050	169.7752	-2.170708
40.36050	169.7750	-2.170558
40.41050	169.7750	-2.170343
40.46050	169.7758	-2.170386
40.51050	169.7756	-2.170273
40.56050	169.7749	-2.170087
40.61050	169.7749	-2.169773
40.66217	169.7748	-2.169459
40.71216	169.7751	-2.169144
40.76216	169.7750	-2.168701
40.81383	169.7752	-2.168388
40.86383	169.7745	-2.167934
40.91383	169.7744	-2.167526
40.96383	169.7745	-2.167417
41.01383	169.7739	-2.167216
41.06383	169.7746	-2.167148
41.11383	169.7744	-2.167380
41.16383	169.7740	-2.168089
41.21383	169.7746	-2.168578
41.26383	169.7746	-2.169426
41.31383	169.7750	-2.170281
41.36383	169.7748	-2.171096
41.41383	169.7754	-2.171947
41.46383	169.7752	-2.172708
41.51383	169.7756	-2.173064
41.56383	169.7759	-2.173136
41.61383	169.7754	-2.173157
41.66383	169.7749	-2.173486
41.71383	169.7756	-2.173887
41.76383	169.7758	-2.174302
41.81383	169.7760	-2.174548
41.86550	169.7760	-2.174780
41.91383	169.7919	-2.176320
41.96383	170.0795	-2.548758
42.01383	170.6113	-5.040621
42.06383	171.2316	-8.591041
42.11383	171.9203	-12.39762
42.16383	172.6572	-16.04716
42.21383	173.4347	-19.34426
42.26383	174.2455	-22.22865
42.31383	175.0838	-24.72625
42.36383	175.9456	-26.86912
42.41383	176.8278	-28.70966
42.46383	177.7241	-30.29223
42.51383	178.6360	-31.65220
42.56383	179.5586	-32.83952
42.61383	180.4917	-33.87784
42.66550	181.4638	-34.83666
42.71550	182.4127	-35.66238
42.76550	183.3671	-36.39818
42.81550	184.3256	-37.08014
42.86716	185.3213	-37.72704
42.91716	186.2885	-38.31246
42.96717	187.2565	-38.86276
43.01717	188.2271	-39.39535
43.06717	189.1999	-39.91712
43.11716	190.1731	-40.43051
43.16716	191.1473	-40.95031
43.21717	192.1218	-41.47842
43.26717	193.0961	-42.02861
43.31717	194.0688	-42.60214
43.36716	195.0415	-43.19633
43.41716	196.0113	-43.84299
43.46717	196.9794	-44.55201
43.51717	197.9460	-45.33516
43.56717	198.9069	-46.20087
43.61716	199.8643	-47.17724
43.66716	200.8148	-48.29993
43.71717	201.7591	-49.59082
43.76717	202.6937	-51.10538
43.81717	203.6177	-52.85491
43.86883	204.5604	-54.93780
43.91883	205.4609	-57.21007
43.96884	206.3508	-59.71630
44.01883	207.2308	-62.40834
44.07050	208.1331	-65.35620
44.12050	208.9961	-68.43503
44.17050	209.8478	-71.78335
44.22050	210.6866	-75.44589
44.27050	211.5124	-79.34803
44.32050	212.3320	-83.32206
44.37050	213.1548	-87.20234
44.42050	213.9884	-90.78139
44.47050	214.8436	-93.79353
44.52050	215.7344	-95.91141
44.57050	216.6762	-96.78472
44.62050	217.6837	-96.25178
44.67050	218.7535	-94.38231
44.72050	219.8739	-91.55484
44.77050	221.0285	-88.04926
44.82050	222.2126	-83.90012
44.87050	223.4260	-79.13384
44.92050	224.6572	-74.09048
44.97050	225.8828	-69.39629
45.02050	227.0812	-65.33906
45.07217	228.2897	-61.77967
45.12216	229.4324	-58.92934
45.17216	230.5525	-56.56430
45.22217	231.6516	-54.59872
45.27383	232.7711	-52.93757
45.32383	233.8386	-51.61301
45.37383	234.8947	-50.51254
45.42383	235.9423	-49.62008
45.47383	236.9810	-48.86873
45.52383	238.0140	-48.26122
45.57383	239.0403	-47.76887
45.62383	240.0636	-47.36617
45.67383	241.0818	-47.03872
45.72383	242.0977	-46.78369
45.77383	243.1101	-46.57764
45.82383	244.1219	-46.42544
45.87383	245.1294	-46.29027
45.92383	246.1373	-46.18810
45.97383	247.1432	-46.11822
46.02383	248.1502	-46.05303
46.07383	249.1544	-46.00457
46.12383	250.1585	-45.96781
46.17383	251.1620	-45.94963
46.22383	252.1644	-45.94094
46.27550	253.2012	-45.93428
46.32550	254.2032	-45.93018
46.37550	255.2054	-45.92720
46.42550	256.2073	-45.92656
46.47717	257.2408	-45.93969
46.52716	258.2430	-45.96283
46.57717	259.2441	-46.00541
46.62717	260.2452	-46.04653
46.67717	261.2454	-46.08128
46.72717	262.2463	-46.12076
46.77716	263.2472	-46.17629
46.82717	264.2485	-46.21072
46.87717	265.2480	-46.26078
46.92717	266.2484	-46.31045
46.97717	267.2490	-46.35575
47.02716	268.2485	-46.40226
47.07717	269.2492	-46.45395
47.12717	270.2487	-46.50648
47.17717	271.2490	-46.54997
47.22717	272.2493	-46.58672
47.27716	273.2488	-46.64680
47.32717	274.2485	-46.68706
-2.000000	3.000000	0.0000000
47.42383	276.0978	-46.89348
47.47383	276.3385	-45.19080
47.52383	276.1969	-38.79889
47.57550	275.8648	-30.44338
47.62550	275.4250	-22.11420
47.67550	274.8982	-14.34615
47.72550	274.2998	-7.416770
47.77716	273.6192	-1.193452
47.82717	272.9124	3.974219
47.87717	272.1613	8.391936
47.92717	271.3757	12.17240
47.97717	270.5610	15.38967
48.02716	269.7194	18.13616
48.07717	268.8554	20.48238
48.12717	267.9741	22.48758
48.17717	267.0770	24.20556
48.22717	266.1665	25.68635
48.27716	265.2435	26.96194
48.32717	264.3112	28.05444
48.37717	263.3713	29.00591
48.42717	262.4236	29.82666
48.47717	261.4696	30.54419
48.52716	260.5106	31.16538
48.57717	259.5469	31.70941
48.62717	258.5797	32.17912
48.67717	257.6081	32.59854
48.72717	256.6340	32.96140
48.77716	255.6571	33.27152
48.82883	254.6461	33.56178
48.87883	253.6647	33.81118
48.92883	252.6822	34.02432
48.98050	251.6642	34.22473
49.03050	250.6790	34.39093
49.08050	249.6915	34.53430
49.13050	248.7039	34.66696
49.18050	247.7142	34.77778
49.23050	246.7248	34.87753
49.28050	245.7354	34.95565
49.33050	244.7436	35.03228
49.38050	243.7528	35.08930
49.43050	242.7604	35.13554
49.48050	241.7677	35.17922
49.53050	240.7752	35.21096
49.58050	239.7821	35.24076
49.63050	238.7889	35.27315
49.68050	237.7958	35.29727
49.73050	236.8018	35.31644
49.78050	235.8075	35.34414
49.83050	234.8127	35.35335
49.88050	233.8192	35.36062
49.93050	232.8248	35.36663
49.98050	231.8302	35.37188
50.03217	230.8020	35.37688
50.08217	229.8064	35.38163
50.13217	228.8112	35.38555
50.18217	227.8158	35.38983
50.23383	226.7866	35.39620
50.28383	225.7920	35.40044
50.33383	224.7971	35.40537
50.38383	223.8008	35.40994
50.43383	222.8056	35.41340
50.48383	221.8107	35.41616
50.53383	220.8142	35.41809
50.58383	219.8178	35.41926
50.63383	218.8222	35.42057
50.68383	217.8254	35.42105
50.73383	216.8300	35.41876
50.78383	215.8341	35.41482
50.83383	214.8383	35.41018
50.88383	213.8420	35.40451
50.93383	212.8454	35.39779
50.98383	211.8491	35.38965
51.03383	210.8523	35.38049
51.08383	209.8567	35.36920
51.13383	208.8601	35.35878
51.18383	207.8639	35.34396
51.23550	206.8342	35.32734
51.28550	205.8375	35.31182
51.33550	204.8416	35.29562
51.38550	203.8446	35.28530
51.43716	202.8159	35.27385
51.48717	201.8190	35.25769
51.53716	200.8223	35.24148
51.58716	199.8258	35.23050
51.63716	198.8296	35.21863
51.68716	197.8325	35.20533
51.73717	196.8367	35.18660
51.78716	195.8386	35.16965
51.83716	194.8417	35.15901
51.88716	193.8452	35.14963
51.93716	192.8490	35.13690
51.98717	191.8510	35.11945
52.03716	190.8547	35.10214
52.08716	189.8575	35.07902
52.13716	188.8605	35.06128
52.18716	187.8642	35.04341
52.23717	186.8678	35.02449
52.28716	185.8705	35.01224
52.33716	184.8734	34.99874
52.38716	183.8767	34.97541
52.43882	182.8464	34.94882
52.48882	181.8494	34.93260
52.53882	180.8528	34.91650
52.58882	179.8562	34.90451
52.64050	178.8264	34.89620
52.69050	177.8288	34.88900
52.74050	176.8324	34.88190
52.79050	175.8354	34.87466
52.84050	174.8380	34.86747
52.89050	173.8412	34.86030
52.94050	172.8436	34.85219
52.99050	171.8475	34.83415
53.04050	170.8495	34.81530
53.09050	169.8527	34.79256
53.14050	168.8566	34.77738
53.19050	167.8596	34.76606
53.24050	166.8636	34.74912
53.29050	165.8669	34.73257
53.34050	164.8709	34.72622
53.39050	163.8762	34.72650
53.44050	162.8838	34.79791
53.49050	161.8939	34.96218
53.54050	160.9077	35.23150
53.59050	159.9330	35.74567
53.64216	158.9419	36.69731
53.69216	158.0117	38.25866
53.74216	157.1205	40.70901
53.79217	156.2774	44.18028
53.84384	155.4598	48.78598
53.89384	154.7086	53.93791
53.94384	153.9792	59.35152
53.99382	153.2488	64.57018
54.04382	152.4965	69.20942
54.09384	151.7064	72.98648
54.14384	150.8676	75.69242
54.19384	149.9725	77.25874
54.24382	149.0214	77.69229
54.29382	148.0153	77.05496
54.34384	146.9604	75.45586
54.39384	145.8616	73.05624
54.44384	144.7287	70.03448
54.49382	143.5748	66.79656
54.54382	142.4174	63.54332
54.59384	141.2644	60.41208
54.64384	140.1198	57.49180
54.69384	138.9869	54.85452
54.74382	137.8675	52.49224
54.79382	136.7622	50.37730
54.84384	135.6677	48.51389
54.89550	134.5503	46.81766
54.94550	133.4784	45.37594
54.99550	132.4150	44.11762
55.04717	131.3250	42.96415
55.09716	130.2768	41.97418
55.14717	129.2338	41.10160
55.19717	128.1960	40.33410
55.24717	127.1627	39.64802
55.29717	126.1335	39.03537
55.34716	125.1084	38.47865
55.39717	124.0864	37.97318
55.44717	123.0656	37.50852
55.49717	122.0474	37.07526
55.54717	121.0299	36.67076
55.59716	120.0151	36.31686
55.64717	119.0018	35.99256
55.69717	117.9888	35.68997
55.74717	116.9780	35.42221
55.79717	115.9678	35.16628
55.84716	114.9587	34.92608
55.89717	113.9504	34.70338
55.94717	112.9428	34.49792
55.99717	111.9351	34.29676
56.04717	110.9279	34.10748
56.09882	109.8885	33.90930
56.14883	108.8829	33.74885
56.19883	107.8780	33.58310
56.24883	106.8734	33.42581
56.30050	105.8358	33.27164
56.35050	104.8313	33.12778
56.40050	103.8281	32.98935
56.45050	102.8248	32.85632
56.50050	101.8216	32.72512
56.55050	100.8184	32.59848
56.60050	99.81555	32.47297
56.65050	98.81442	32.35630
56.70050	97.81109	32.23458
56.75050	96.80826	32.12897
56.80050	95.80555	32.00435
56.85050	94.80309	31.87794
56.90050	93.80008	31.76611
56.95050	92.79718	31.63845
57.00050	91.79444	31.50672
57.05050	90.78960	31.37880
57.10050	89.78738	31.23882
57.15050	88.78236	31.10562
57.20050	87.78019	30.97513
57.25050	86.77582	30.84696
57.30217	85.73915	30.71328
57.35217	84.73553	30.58645
57.40217	83.73322	30.46118
57.45216	82.73032	30.33873
57.50383	81.69410	30.22549
57.55383	80.69053	30.10685
57.60383	79.68849	29.99275
57.65383	78.68587	29.88031
57.70383	77.68499	29.77060
57.75383	76.68206	29.66737
57.80383	75.68212	29.58490
57.85383	74.67956	29.49456
57.90383	73.67780	29.39920
57.95383	72.67624	29.30434
58.00383	71.67463	29.20559
58.05383	70.67408	29.10979
58.10383	69.67105	29.02304
58.15383	68.66926	28.92467
58.20383	67.66739	28.82394
58.25383	66.66511	28.72429
58.30383	65.66357	28.62324
58.35383	64.66076	28.52869
58.40383	63.65888	28.42476
58.45383	62.65793	28.31648
58.50550	61.62217	28.20625
58.55550	60.62049	28.09843
58.60550	59.61695	27.99170
58.65550	58.61445	27.89056
58.70717	57.58030	27.78312
58.75717	56.57696	27.66976
58.80717	55.57544	27.56669
58.85717	54.57472	27.46404
58.90717	53.57328	27.36608
58.95717	52.57081	27.26710
59.00717	51.56904	27.16302
59.05717	50.56653	27.05623
59.10717	49.56491	26.96048
59.15717	48.56329	26.86170
59.20717	47.56122	26.76057
59.25717	46.55935	26.66680
59.30717	45.55659	26.56928
59.35717	44.55433	26.47738
59.40717	43.55196	26.37865
59.45717	42.55066	26.28016
59.50717	41.54770	26.18213
59.55717	40.54482	26.08192
59.60717	39.54246	25.97239
59.65717	38.53982	25.86336
59.70883	37.50361	25.74636
59.75883	36.49980	25.62846
59.80883	35.49732	25.51225
59.85883	34.49338	25.39727
59.91050	33.45690	25.26984
59.96050	32.45281	25.15070
60.01050	31.44929	25.02383
60.06050	30.44517	24.90406
60.11050	29.44204	24.78930
60.16050	28.43848	24.66621
60.21050	27.43445	24.53604
60.26050	26.42865	24.40959
60.31050	25.42441	24.27694
60.36050	24.41876	24.13803
60.41050	23.43832	24.04250
60.46050	23.01625	24.40556
60.51050	23.11723	21.93230
60.56050	23.39462	17.79105
60.61050	23.81814	13.01708
60.66050	24.33378	8.267618
60.71050	24.92895	3.875257
60.76050	25.58926	-.03413305
60.81050	26.30213	-3.439288
60.86050	27.05970	-6.358516
60.91050	27.85365	-8.854598
60.96050	28.67888	-10.98253
61.01050	29.52827	-12.79758
61.06050	30.40008	-14.34052
61.11050	31.28970	-15.66696
61.16050	32.19476	-16.81163
61.21050	33.11244	-17.80047
61.26050	34.04089	-18.66096
61.31050	34.97811	-19.41584
61.36217	35.95506	-20.09160
61.41216	36.90680	-20.67217
61.46216	37.86537	-21.19163
61.51382	38.86042	-21.66332
61.56382	39.82614	-22.06830
61.61382	40.79531	-22.43268
61.66382	41.76828	-22.76261
61.71382	42.74483	-23.06340
61.76382	43.72281	-23.33525
61.81382	44.70200	-23.58752
61.86382	45.68530	-23.82448
61.91382	46.66856	-24.04477
61.96382	47.65389	-24.25366
62.01382	48.64030	-24.44983
62.06382	49.62728	-24.63776
62.11382	50.61532	-24.81328
62.16382	51.60486	-24.98840
62.21382	52.59351	-25.15278
62.26382	53.58384	-25.31216
62.31382	54.57489	-25.46785
62.36382	55.56560	-25.61684
62.41382	56.55870	-25.75875
62.46382	57.55041	-25.91046
62.51382	58.54330	-26.05558
62.56550	59.56962	-26.20227
62.61550	60.56265	-26.34641
62.66550	61.55661	-26.48407
62.71550	62.55024	-26.63052
62.76716	63.57701	-26.77040
62.81716	64.57162	-26.89968
62.86716	65.56505	-27.04027
62.91716	66.55869	-27.16835
62.96717	67.55422	-27.30592
63.01716	68.54861	-27.44382
63.06716	69.54462	-27.57283
63.11716	70.53888	-27.70314
63.16716	71.53419	-27.82704
63.21717	72.52950	-27.96012
63.26716	73.52484	-28.08567
63.31716	74.52019	-28.21646
63.36716	75.51499	-28.34359
63.41716	76.51062	-28.47208
63.46717	77.50418	-28.60506
63.51716	78.50002	-28.74344
63.56716	79.49614	-28.87814
63.61716	80.49030	-29.01615
63.66716	81.48620	-29.16552
63.71717	82.48145	-29.31509
63.76884	83.50888	-29.46765
63.81884	84.50371	-29.61045
63.86884	85.49790	-29.75634
63.91882	86.49338	-29.90669
63.97050	87.52066	-30.06252
64.02050	88.51514	-30.21180
64.07050	89.50958	-30.36223
64.12050	90.50395	-30.51806
64.17050	91.50072	-30.64486
64.22050	92.49530	-30.77615
64.27050	93.49195	-30.90620
64.32050	94.48755	-31.03358
64.37050	95.48336	-31.17041
64.42050	96.47949	-31.31244
64.47050	97.47465	-31.44186
64.52050	98.47074	-31.57092
64.57050	99.46671	-31.70967
64.62050	100.4628	-31.84004
64.67050	101.4584	-31.95638
64.72050	102.4553	-32.08326
64.77050	103.4516	-32.19890
64.82050	104.4484	-32.31900
64.87050	105.4450	-32.44468
64.92050	106.4414	-32.57488
64.97217	107.4709	-32.72079
65.02217	108.4656	-32.86408
65.07218	109.4618	-32.99977
65.12217	110.4569	-33.14156
65.17383	111.4857	-33.27875
65.22384	112.4815	-33.40048
65.27383	113.4775	-33.53078
65.32384	114.4738	-33.65431
65.37383	115.4696	-33.78506
65.42383	116.4651	-33.91481
65.47384	117.4608	-34.03090
65.52383	118.4573	-34.16354
65.57384	119.4525	-34.30138
65.62384	120.4483	-34.44540
65.67384	121.4446	-34.59326
65.72384	122.4396	-34.74100
65.77384	123.4354	-34.89552
65.82384	124.4313	-35.04446
65.87384	125.4263	-35.19245
65.92384	126.4215	-35.34108
65.97384	127.4157	-35.48443
66.02384	128.4110	-35.63237
66.07384	129.4065	-35.78070
66.12384	130.4011	-35.93164
66.17550	131.4296	-36.09940
66.22551	132.4246	-36.25990
66.27550	133.4194	-36.41667
66.32550	134.4145	-36.58340
66.37718	135.4411	-36.75356
66.42718	136.4371	-36.92444
66.47718	137.4309	-37.09970
66.52718	138.4252	-37.26922
66.57718	139.4201	-37.44886
66.62718	140.4148	-37.62390
66.67718	141.4083	-37.80892
66.72718	142.4027	-37.98620
66.77718	143.3977	-38.17106
66.82718	144.3913	-38.34842
66.87718	145.3840	-38.52828
66.92718	146.3788	-38.70877
66.97718	147.3710	-38.89958
67.02718	148.3659	-39.08933
67.07718	149.3573	-39.27708
67.12718	150.3508	-39.46270
67.17718	151.3441	-39.65244
67.22718	152.3372	-39.84254
67.27718	153.3310	-40.04270
67.32718	154.3237	-40.24498
67.37718	155.3156	-40.44730
67.42884	156.3425	-40.65208
67.47884	157.3354	-40.85576
67.52884	158.3298	-41.05576
67.58050	159.3554	-41.24850
67.63050	160.3501	-41.42663
67.68050	161.3461	-41.59363
67.73050	162.3425	-41.73661
67.78050	163.3394	-41.85449
67.83050	164.3370	-41.95243
67.88050	165.3364	-42.04438
67.93050	166.3356	-42.11074
67.98050	167.3354	-42.17609
68.03050	168.3345	-42.23287
68.08050	169.3354	-42.28560
68.13050	170.3348	-42.34878
68.18050	171.3330	-42.44031
68.23050	172.3321	-42.53442
68.28050	173.3289	-42.65262
68.33050	174.3250	-42.78430
68.38050	175.3216	-42.93530
68.43050	176.3164	-43.10232
68.48050	177.3094	-43.28892
68.53050	178.3009	-43.51018
68.58050	179.2916	-43.75370
68.63218	180.3146	-44.03059
68.68218	181.3028	-44.34122
68.73218	182.2902	-44.68851
68.78218	183.2752	-45.06326
68.83384	184.2928	-45.50022
68.88384	185.2737	-45.96625
68.93384	186.2529	-46.46907
68.98384	187.2316	-47.02554
69.03384	188.2058	-47.64462
69.08384	189.1766	-48.32541
69.13384	190.1454	-49.06264
69.18384	191.1127	-49.85579
69.23384	192.0762	-50.69055
69.28384	193.0387	-51.55846
69.33384	194.0007	-52.45794
69.38384	194.9607	-53.36303
69.43384	195.9195	-54.31694
69.48384	196.8768	-55.32102
69.53384	197.8304	-56.37610
69.58384	198.7830	-57.49075
69.63384	199.7318	-58.69371
69.68384	200.6753	-59.97722
69.73384	201.6174	-61.33566
69.78384	202.5551	-62.77824
69.83550	203.5204	-64.30774
69.88550	204.4551	-65.81099
69.93550	205.3904	-67.25621
69.98550	206.3307	-68.56532
70.03718	207.3148	-69.60492
70.08716	208.2866	-70.08364
70.13718	209.2908	-69.82066
70.18718	210.3321	-68.70240
70.23718	211.4090	-66.89720
70.28718	212.5094	-64.68334
70.33716	213.6233	-62.23620
70.38718	214.7446	-59.65408
70.43718	215.8669	-57.12798
70.48718	216.9810	-54.83313
70.53718	218.0809	-52.84245
70.58716	219.1661	-51.14316
70.63718	220.2398	-49.70247
70.68718	221.3016	-48.50898
70.73718	222.3544	-47.50869
70.78718	223.3977	-46.67604
70.83716	224.4348	-45.98408
70.88718	225.4653	-45.39631
70.93718	226.4911	-44.91484
70.98718	227.5128	-44.52826
71.03882	228.5650	-44.19434
71.08884	229.5802	-43.94014
71.13884	230.5929	-43.74282
71.18884	231.6034	-43.58250
71.24050	232.6460	-43.46740
71.29050	233.6531	-43.38139
71.34050	234.6595	-43.31517
71.39050	235.6644	-43.27459
71.44050	236.6691	-43.24769
71.49050	237.6718	-43.22120
71.54050	238.6749	-43.21618
71.59050	239.6771	-43.21385
71.64050	240.6798	-43.21697
71.69050	241.6815	-43.23026
71.74050	242.6830	-43.27704
71.79050	243.6836	-43.31787
71.84050	244.6848	-43.35864
71.89050	245.6855	-43.40016
71.94050	246.6849	-43.44669
71.99050	247.6862	-43.49212
72.04050	248.6865	-43.53750
72.09050	249.6875	-43.57744
72.14050	250.6872	-43.62626
72.19050	251.6877	-43.68226
72.24218	252.7202	-43.73200
72.29218	253.7202	-43.78504
72.34216	254.7203	-43.83279
72.39216	255.7197	-43.88617
72.44384	256.7526	-43.95900
72.49384	257.7519	-44.02294
72.54384	258.7527	-44.08305
72.59384	259.7516	-44.14829
72.64384	260.7520	-44.21467
72.69384	261.7507	-44.27666
72.74384	262.7510	-44.34124
72.79384	263.7498	-44.40552
72.84384	264.7486	-44.47312
72.89384	265.7486	-44.54406
72.94384	266.7494	-44.61916
72.99384	267.7482	-44.68337
73.04384	268.7466	-44.75970
73.09384	269.7455	-44.83800
73.14384	270.7440	-44.90833
73.19384	271.7426	-44.97400
-2.000000	5.000000	0.0000000