File: 4-C1(1.2mol%)+C20(0.6mol%)/matlab/140-3
CLOSED
Version	1.0
Language	English
Mode	Standard
Run	3
RunSerial	11868
Instrument	DSC Q2000 V24.11 Build 124
Module	DSC Standard Cell RC
Operator	Jing
File	\\Ae520-1454\ta\Data\DSC\UQ Composites\Nan\C1(6.5)+C20P(3)+CL(Hotplate MixtureAB) New\140-3
ProcName	Ramp
InstSerial	2000-0883
AutoSerial	1293
Sample	Iso140-3
Size	35.3000	mg
PanMass	Not available
PanResist	Automatic Automatic  K/W
PanFactor	Default Default
Method	Ramp
Comment
Xcomment	Pan: Tzero Aluminum Hermetic
Xcomment	Gas1: Nitrogen 50.0 ml/min
Xcomment	Gas2: Nitrogen 50.0 ml/min
Text
Exotherm	UP
Kcell	1.05230
Cpconst	Standard: 0.938
Calib	-38.6961
TempCal	1	pts	157.46	156.60
TzeroDt	-87.6168 -0.0009 -1.4231
TzeroDtz	-87.6168 0.0057 6.9570
InstCalFile	Tzero: \\Ae520-1454\ta\Data\DSC\Calibration\2017\CALIBRATION\1562_RCS (90)_05_18_2017 10_50_44.TZR
InstCalFile	Baseline: \\Ae520-1454\ta\Data\DSC\Calibration\2017\2017-05-17_Calibration.001
InstCalFile	Sapphire: \\Ae520-1454\ta\Data\DSC\Calibration\2017\2017-05-17_Saphire.001
InstCalDate	Tzero 2017-05-18 Time 10:50:44
TempRange	-87.39 to 398.39 °C at 10.00 °C/min Heat Only
AutoZero	Delta T Offset 0.000 uV
AutoZero	Delta T0 Offset 0.000 uV
MultiptCal	0
MultiPtDesc	0) Not set
AutoCellConst	Calibration Date 2017-05-18 16:59:28
Controls	Gas 1  Event Off  Sampling 0.2
Cell#	RC-01562
CoolingUnit	RCS (90)
SelHeatFlow	Heat Flow T4 (mW)
AutoLidII	Installed
AutoAnalysis	Off
MacroFile
Nsig	3
Sig1	Time (min)
Sig2	Temperature (°C)
Sig3	Heat Flow (mW)
Date	2017-06-21
Time	16:29:49
OrgMethod	1: Equilibrate at 20.00 °C
OrgMethod	2: Ramp 40.00 °C/min to 140.00 °C
OrgMethod	3: Mark end of cycle 1
OrgMethod	4: Isothermal for 40.00 min
OrgMethod	5: Mark end of cycle 2
OrgMethod	6: Ramp 20.00 °C/min to 280.00 °C
OrgMethod	7: Mark end of cycle 3
OrgMethod	8: Ramp 20.00 °C/min to 20.00 °C
OrgMethod	9: Mark end of cycle 4
OrgMethod	10: Ramp 20.00 °C/min to 280.00 °C
OrgMethod	11: Mark end of cycle 5
OrgFile	C:\Users\jarra\Desktop\DSC\4-C1(1.2mol%)+C20(0.6mol%)\140-3
StartOfData
4.99994E-4	20.06798	0.2727340
0.05383332	20.19326	0.9100294
0.1055000	21.18939	3.315012
0.1571666	22.60613	2.737722
0.2105000	24.20839	0.5652389
0.2605000	25.81098	-2.118918
0.3138333	27.58616	-5.086572
0.3655000	29.36076	-7.784726
0.4171667	31.17777	-10.20310
0.4705000	33.09178	-12.37202
0.5205000	34.91461	-14.11486
0.5738334	36.88727	-15.69574
0.6238334	38.75710	-16.98535
0.6771668	40.76789	-18.17970
0.7288332	42.72996	-19.20563
0.7805000	44.70111	-20.17485
0.8338332	46.73918	-21.23638
0.8838332	48.65090	-22.19843
0.9371668	50.70324	-23.03624
0.9888332	52.70305	-23.68903
1.040500	54.70938	-24.39196
1.092167	56.70556	-25.45878
1.143833	58.67895	-26.93543
1.197166	60.70933	-28.49188
1.247166	62.62046	-29.82122
1.300500	64.66507	-31.18498
1.352166	66.63208	-33.09825
1.403833	68.59710	-32.57494
1.457167	69.46619	-64.18662
1.507167	70.34150	-85.29468
1.560500	71.26842	-107.5267
1.610500	72.07475	-130.4634
1.663834	71.95450	-167.9987
1.715500	73.08031	-184.2498
1.767167	74.47340	-193.8034
1.820500	76.02766	-204.6481
1.870500	77.60490	-210.3799
1.923834	80.04221	-195.5514
1.975500	83.42642	-173.4056
2.027166	86.62674	-152.5784
2.078833	90.03887	-128.2910
2.130500	93.23420	-109.9938
2.183833	96.24889	-95.78886
2.233833	98.86788	-85.78508
2.287166	101.4961	-77.83140
2.338833	103.9188	-72.17261
2.390500	106.2458	-68.11789
2.443833	108.5820	-64.98776
2.493833	110.7203	-62.91455
2.547166	112.9610	-61.39973
2.597167	115.0308	-60.47222
2.650500	117.2154	-59.95139
2.702166	119.3036	-59.92798
2.753833	121.3789	-60.12934
2.807167	123.5135	-60.47882
2.857167	125.5096	-60.88500
2.910500	127.6351	-61.36070
2.962167	129.6913	-61.86408
3.010500	131.6134	-62.38840
3.060500	133.4720	-61.24775
3.113833	134.8533	-54.66959
3.165500	135.8175	-47.53730
3.217166	136.5414	-40.48164
3.270500	137.1091	-34.19964
3.320500	137.5201	-29.37210
3.373834	137.8613	-25.27337
3.425500	138.1217	-22.19621
3.477167	138.3265	-19.81435
3.528833	138.4896	-17.98608
3.580500	138.6221	-16.57638
3.633833	138.7304	-15.46048
3.683833	138.8153	-14.64305
3.737167	138.8879	-13.96593
3.788833	138.9465	-13.45642
3.840500	138.9958	-13.04972
3.893833	139.0380	-12.72099
3.943833	139.0719	-12.46424
3.997166	139.1021	-12.24852
4.047167	139.1258	-12.08301
4.100500	139.1481	-11.93596
4.152166	139.1678	-11.81867
4.203833	139.1840	-11.71692
4.257167	139.1984	-11.62592
4.307167	139.2108	-11.55613
4.360500	139.2228	-11.47920
4.412167	139.2326	-11.41356
4.463834	139.2429	-11.35711
4.515500	139.2503	-11.29586
4.567167	139.2584	-11.23749
4.620500	139.2666	-11.16520
4.670500	139.2741	-11.09470
4.723834	139.2824	-11.00635
4.775500	139.2895	-10.92057
4.827167	139.2970	-10.82759
4.880500	139.3056	-10.73077
4.930500	139.3120	-10.63251
4.983834	139.3200	-10.52076
5.033834	139.3279	-10.40756
5.087167	139.3352	-10.28027
5.138833	139.3437	-10.15151
5.190500	139.3522	-10.01633
5.243834	139.3611	-9.863621
5.293832	139.3690	-9.722128
5.347168	139.3779	-9.557211
5.398834	139.3868	-9.397180
5.450500	139.3954	-9.233131
5.503834	139.4042	-9.064651
5.553834	139.4127	-8.908249
5.607168	139.4224	-8.740650
5.657166	139.4311	-8.592050
5.710500	139.4390	-8.432421
5.762168	139.4469	-8.276514
5.813832	139.4557	-8.109894
5.867168	139.4650	-7.925269
5.917168	139.4740	-7.761557
5.970500	139.4820	-7.591655
6.020500	139.4914	-7.425593
6.073834	139.5006	-7.231350
6.125500	139.5111	-7.028813
6.177166	139.5221	-6.815703
6.230500	139.5334	-6.583581
6.280500	139.5444	-6.362070
6.333832	139.5574	-6.121969
6.385500	139.5697	-5.880616
6.437168	139.5816	-5.642302
6.490500	139.5940	-5.395740
6.540500	139.6063	-5.165492
6.593832	139.6187	-4.931433
6.643832	139.6289	-4.718670
6.697168	139.6403	-4.507476
6.748834	139.6510	-4.307271
6.800500	139.6609	-4.126094
6.853832	139.6697	-3.949750
6.903832	139.6789	-3.794300
6.957168	139.6868	-3.640955
7.008832	139.6942	-3.506175
7.060500	139.7004	-3.377969
7.112168	139.7068	-3.261525
7.163832	139.7131	-3.152643
7.217168	139.7191	-3.048512
7.267168	139.7235	-2.958232
7.320500	139.7289	-2.873404
7.372168	139.7334	-2.789701
7.423834	139.7379	-2.713790
7.477168	139.7417	-2.637080
7.527168	139.7448	-2.575686
7.580500	139.7484	-2.512402
7.630500	139.7520	-2.456474
7.683832	139.7545	-2.399804
7.735500	139.7576	-2.346347
7.787168	139.7598	-2.293696
7.840500	139.7628	-2.247878
7.890500	139.7658	-2.208496
7.943832	139.7681	-2.162183
7.995500	139.7697	-2.121008
8.047168	139.7720	-2.083382
8.098832	139.7735	-2.045624
8.150500	139.7764	-2.012522
8.203834	139.7781	-1.973953
8.253834	139.7798	-1.944567
8.307168	139.7808	-1.908985
8.358832	139.7825	-1.880696
8.410499	139.7852	-1.856631
8.463834	139.7869	-1.827235
8.513832	139.7881	-1.801144
8.567166	139.7890	-1.773306
8.617166	139.7914	-1.747015
8.670500	139.7924	-1.718309
8.722168	139.7944	-1.693263
8.773834	139.7950	-1.665472
8.827168	139.7964	-1.642130
8.877168	139.7980	-1.622568
8.930500	139.7997	-1.599376
8.982166	139.8004	-1.577682
9.033832	139.8016	-1.557464
9.085501	139.8030	-1.535192
9.137168	139.8040	-1.514810
9.190500	139.8058	-1.494668
9.240500	139.8056	-1.476406
9.293834	139.8077	-1.457226
9.345500	139.8087	-1.437979
9.397168	139.8094	-1.419148
9.450500	139.8105	-1.396201
9.500500	139.8114	-1.376620
9.553832	139.8124	-1.358369
9.603832	139.8127	-1.339879
9.657166	139.8147	-1.323377
9.708832	139.8159	-1.306069
9.760499	139.8168	-1.285632
9.813834	139.8182	-1.265167
9.863834	139.8188	-1.243337
9.917168	139.8204	-1.223534
9.968834	139.8209	-1.204395
10.02050	139.8219	-1.181892
10.07217	139.8230	-1.163261
10.12383	139.8245	-1.144016
10.17717	139.8253	-1.123795
10.22717	139.8266	-1.106262
10.28050	139.8277	-1.085596
10.33217	139.8288	-1.064710
10.38383	139.8294	-1.045593
10.43717	139.8311	-1.025307
10.48717	139.8316	-1.002917
10.54050	139.8336	-0.9841868
10.59050	139.8341	-0.9623446
10.64383	139.8350	-0.9422204
10.69550	139.8359	-0.9211574
10.74717	139.8376	-0.9024894
10.80050	139.8373	-0.8817266
10.85050	139.8386	-0.8639599
10.90383	139.8397	-0.8468639
10.95550	139.8412	-0.8277394
11.00717	139.8421	-0.8076456
11.05884	139.8435	-0.7883022
11.11050	139.8436	-0.7678431
11.16383	139.8448	-0.7486230
11.21383	139.8465	-0.7286672
11.26717	139.8469	-0.7080984
11.31883	139.8486	-0.6897168
11.37050	139.8503	-0.6708431
11.42383	139.8508	-0.6507522
11.47383	139.8518	-0.6300204
11.52717	139.8525	-0.6068129
11.57717	139.8538	-0.5844556
11.63050	139.8549	-0.5638340
11.68217	139.8559	-0.5420280
11.73383	139.8572	-0.5237798
11.78717	139.8578	-0.5023598
11.83717	139.8594	-0.4828262
11.89050	139.8604	-0.4630008
11.94217	139.8619	-0.4408961
11.99384	139.8625	-0.4193500
12.04717	139.8639	-0.3991314
12.09717	139.8646	-0.3804744
12.15050	139.8662	-0.3566556
12.20050	139.8671	-0.3337613
12.25384	139.8681	-0.3131578
12.30550	139.8688	-0.2932012
12.35717	139.8702	-0.2702375
12.41050	139.8710	-0.2449717
12.46050	139.8727	-0.2249595
12.51383	139.8726	-0.2026748
12.56383	139.8745	-0.1803589
12.61716	139.8757	-0.1604788
12.66883	139.8769	-0.1357431
12.72050	139.8785	-0.1136478
12.77383	139.8794	-.09187519
12.82384	139.8817	-.06791968
12.87717	139.8816	-.04270396
12.92883	139.8835	-.02030552
12.98050	139.8842	.009267625
13.03383	139.8860	0.03567700
13.08383	139.8869	0.06265430
13.13717	139.8885	0.09391272
13.18716	139.8905	0.1232610
13.24050	139.8921	0.1600584
13.29216	139.8932	0.1937162
13.34383	139.8946	0.2307145
13.39717	139.8967	0.2729178
13.44717	139.8987	0.3133740
13.50050	139.9002	0.3593220
13.55217	139.9026	0.4079508
13.60383	139.9058	0.4613894
13.65550	139.9079	0.5150929
13.70717	139.9106	0.5790313
13.76050	139.9151	0.6449365
13.81050	139.9176	0.7150650
13.86383	139.9214	0.7947190
13.91550	139.9263	0.8716522
13.96716	139.9304	0.9599559
14.02050	139.9356	1.047532
14.07050	139.9401	1.140858
14.12384	139.9454	1.240943
14.17383	139.9506	1.338815
14.22717	139.9553	1.443589
14.27883	139.9603	1.544247
14.33050	139.9649	1.645410
14.38383	139.9702	1.747301
14.43383	139.9745	1.841743
14.48716	139.9801	1.937918
14.53883	139.9846	2.035242
14.59050	139.9893	2.123289
14.64216	139.9933	2.210770
14.69384	139.9982	2.293871
14.74717	140.0022	2.377432
14.79717	140.0063	2.453277
14.85050	140.0108	2.532630
14.90217	140.0148	2.609871
14.95383	140.0187	2.684048
15.00717	140.0221	2.759050
15.05717	140.0255	2.827458
15.11050	140.0298	2.898841
15.16050	140.0324	2.965217
15.21383	140.0351	3.034696
15.26550	140.0386	3.099133
15.31716	140.0420	3.160140
15.37050	140.0461	3.223150
15.42050	140.0484	3.279329
15.47383	140.0508	3.338337
15.52550	140.0544	3.396084
15.57717	140.0573	3.451389
15.62883	140.0604	3.505578
15.68050	140.0626	3.560182
15.73383	140.0665	3.618322
15.78383	140.0689	3.668640
15.83717	140.0714	3.724190
15.88883	140.0740	3.777586
15.94050	140.0770	3.826472
15.99383	140.0796	3.879242
16.04383	140.0825	3.930841
16.09717	140.0846	3.984428
16.14716	140.0876	4.034200
16.20050	140.0909	4.085991
16.25217	140.0937	4.139539
16.30383	140.0962	4.192844
16.35716	140.0999	4.248938
16.40716	140.1023	4.301766
16.46050	140.1060	4.358023
16.51216	140.1073	4.417169
16.56383	140.1101	4.471484
16.61550	140.1134	4.529800
16.66716	140.1159	4.586874
16.72050	140.1188	4.646309
16.77050	140.1219	4.704283
16.82383	140.1248	4.767716
16.87550	140.1269	4.826512
16.92716	140.1305	4.883270
16.98050	140.1333	4.950276
17.03050	140.1361	5.010293
17.08383	140.1395	5.074726
17.13383	140.1434	5.136512
17.18716	140.1451	5.205148
17.23883	140.1496	5.266700
17.29050	140.1527	5.331528
17.34383	140.1559	5.400114
17.39383	140.1598	5.466842
17.44716	140.1626	5.535572
17.49883	140.1668	5.603489
17.55050	140.1700	5.671658
17.60216	140.1736	5.741682
17.65383	140.1774	5.810392
17.70716	140.1819	5.882980
17.75716	140.1852	5.955214
17.81050	140.1876	6.031101
17.86216	140.1919	6.103764
17.91383	140.1956	6.180674
17.96716	140.1996	6.255989
18.01716	140.2028	6.328505
18.07050	140.2074	6.404770
18.12050	140.2108	6.478637
18.17383	140.2156	6.555034
18.22550	140.2193	6.631556
18.27716	140.2236	6.706885
18.33050	140.2277	6.787346
18.38050	140.2312	6.861960
18.43383	140.2360	6.948991
18.48550	140.2396	7.026903
18.53717	140.2430	7.110974
18.59050	140.2470	7.191074
18.64050	140.2507	7.265982
18.69383	140.2540	7.346415
18.74383	140.2579	7.415278
18.79716	140.2621	7.491150
18.84883	140.2656	7.561866
18.90050	140.2687	7.629106
18.95383	140.2723	7.697684
19.00383	140.2752	7.756998
19.05716	140.2786	7.817250
19.10716	140.2816	7.874096
19.16050	140.2853	7.932610
19.21216	140.2873	7.983190
19.26383	140.2900	8.028051
19.31716	140.2929	8.071858
19.36716	140.2951	8.110243
19.42050	140.2979	8.144331
19.47216	140.2990	8.173937
19.52383	140.2999	8.202196
19.57716	140.3025	8.227384
19.62716	140.3025	8.245953
19.68050	140.3039	8.266259
19.73050	140.3044	8.278812
19.78383	140.3058	8.290122
19.83550	140.3055	8.299725
19.88716	140.3066	8.307539
19.94050	140.3069	8.315161
19.99050	140.3068	8.321747
20.04383	140.3071	8.328360
20.09550	140.3072	8.333920
20.14716	140.3064	8.338828
20.19884	140.3083	8.350608
20.25050	140.3082	8.354511
20.30383	140.3086	8.356394
20.35383	140.3076	8.356778
20.40716	140.3084	8.355731
20.45883	140.3086	8.357336
20.51050	140.3080	8.358056
20.56383	140.3068	8.353192
20.61383	140.3072	8.344986
20.66716	140.3055	8.335970
20.71716	140.3041	8.327616
20.77050	140.3034	8.316258
20.82216	140.3029	8.303954
20.87383	140.3019	8.289509
20.92717	140.3012	8.270236
20.97716	140.3000	8.251808
21.03050	140.2991	8.226240
21.08216	140.2983	8.199742
21.13383	140.2967	8.172856
21.18550	140.2962	8.139765
21.23716	140.2944	8.111749
21.29050	140.2940	8.077572
21.34050	140.2927	8.049605
21.39383	140.2905	8.018457
21.44550	140.2891	7.983142
21.49716	140.2872	7.946801
21.55050	140.2847	7.908197
21.60050	140.2836	7.870901
21.65383	140.2816	7.829368
21.70383	140.2793	7.792264
21.75716	140.2773	7.750822
21.80883	140.2748	7.712134
21.86050	140.2718	7.668432
21.91383	140.2698	7.620572
21.96383	140.2671	7.580008
22.01716	140.2650	7.533589
22.06883	140.2622	7.490311
22.12050	140.2599	7.443576
22.17216	140.2582	7.392753
22.22383	140.2558	7.348626
22.27717	140.2535	7.297344
22.32716	140.2514	7.251062
22.38050	140.2475	7.198890
22.43216	140.2466	7.150544
22.48383	140.2440	7.104386
22.53717	140.2418	7.050947
22.58716	140.2394	7.003234
22.64050	140.2374	6.952148
22.69050	140.2349	6.905510
22.74383	140.2334	6.852774
22.79550	140.2301	6.803968
22.84716	140.2278	6.754554
22.90050	140.2254	6.705960
22.95050	140.2225	6.660764
23.00383	140.2206	6.611928
23.05550	140.2176	6.562903
23.10716	140.2155	6.516499
23.15883	140.2121	6.470993
23.21050	140.2101	6.422473
23.26383	140.2074	6.372497
23.31383	140.2047	6.328309
23.36716	140.2019	6.277070
23.41883	140.1990	6.229898
23.47050	140.1976	6.181516
23.52383	140.1948	6.129690
23.57383	140.1920	6.082792
23.62716	140.1898	6.036370
23.67717	140.1876	5.988500
23.73050	140.1846	5.944598
23.78216	140.1831	5.896230
23.83383	140.1803	5.850860
23.88716	140.1781	5.804213
23.93716	140.1761	5.758550
23.99050	140.1742	5.711828
24.04216	140.1718	5.664596
24.09383	140.1698	5.621291
24.14550	140.1674	5.576865
24.19716	140.1654	5.532022
24.25050	140.1629	5.487828
24.30050	140.1610	5.444668
24.35383	140.1589	5.398742
24.40550	140.1573	5.354477
24.45717	140.1557	5.314376
24.51050	140.1526	5.271664
24.56050	140.1500	5.232637
24.61383	140.1482	5.191189
24.66383	140.1461	5.150236
24.71716	140.1446	5.108674
24.76883	140.1421	5.068680
24.82050	140.1395	5.027063
24.87383	140.1375	4.984910
24.92383	140.1352	4.946963
24.97716	140.1333	4.907262
25.02883	140.1309	4.867273
25.08050	140.1286	4.826824
25.13383	140.1265	4.785223
25.18383	140.1246	4.745906
25.23716	140.1228	4.705814
25.28717	140.1213	4.667224
25.34050	140.1195	4.626042
25.39216	140.1178	4.588489
25.44383	140.1160	4.550415
25.49716	140.1141	4.513815
25.54716	140.1128	4.478875
25.60050	140.1102	4.438544
25.65050	140.1084	4.404265
25.70383	140.1072	4.365063
25.75550	140.1048	4.328090
25.80716	140.1029	4.290600
25.86050	140.1012	4.253940
25.91050	140.0989	4.218611
25.96383	140.0972	4.182336
26.01550	140.0957	4.144940
26.06716	140.0925	4.109581
26.12050	140.0911	4.071787
26.17050	140.0898	4.037678
26.22383	140.0879	3.997137
26.27383	140.0860	3.962147
26.32717	140.0842	3.924922
26.37883	140.0820	3.889667
26.43050	140.0808	3.853689
26.48383	140.0788	3.815022
26.53383	140.0773	3.781000
26.58716	140.0757	3.741327
26.63883	140.0734	3.705710
26.69050	140.0715	3.671766
26.74216	140.0700	3.633875
26.79383	140.0680	3.600524
26.84716	140.0662	3.560971
26.89716	140.0642	3.528174
26.95050	140.0626	3.491650
27.00217	140.0600	3.454675
27.05383	140.0577	3.420843
27.10716	140.0556	3.385843
27.15716	140.0539	3.347466
27.21050	140.0515	3.312018
27.26050	140.0499	3.278638
27.31383	140.0483	3.238681
27.36550	140.0463	3.200764
27.41716	140.0449	3.161253
27.47050	140.0427	3.121930
27.52050	140.0415	3.082228
27.57383	140.0384	3.043060
27.62550	140.0378	3.005312
27.67717	140.0350	2.969746
27.72883	140.0338	2.933225
27.78050	140.0316	2.897236
27.83383	140.0296	2.857670
27.88383	140.0276	2.822419
27.93717	140.0256	2.782676
27.98883	140.0229	2.745340
28.04050	140.0206	2.706750
28.09383	140.0190	2.665436
28.14383	140.0166	2.627085
28.19717	140.0150	2.584128
28.24716	140.0124	2.543046
28.30050	140.0111	2.500679
28.35217	140.0095	2.458267
28.40383	140.0066	2.415657
28.45716	140.0054	2.373450
28.50716	140.0030	2.332187
28.56050	140.0009	2.288803
28.61216	139.9995	2.247486
28.66383	139.9971	2.208763
28.71550	139.9944	2.184112
28.76716	139.9940	2.131456
28.82050	139.9919	2.082304
28.87050	139.9896	2.036224
28.92383	139.9865	1.989671
28.97550	139.9844	1.942454
29.02717	139.9826	1.897527
29.08050	139.9787	1.849708
29.13050	139.9775	1.805577
29.18383	139.9738	1.759946
29.23383	139.9711	1.712444
29.28717	139.9692	1.663651
29.33883	139.9672	1.613172
29.39050	139.9633	1.564078
29.44383	139.9622	1.512040
29.49383	139.9597	1.466661
29.54716	139.9564	1.417002
29.59883	139.9542	1.367183
29.65050	139.9519	1.316723
29.70217	139.9498	1.268005
29.75383	139.9481	1.217731
29.80716	139.9448	1.167454
29.85716	139.9434	1.120340
29.91050	139.9403	1.066000
29.96216	139.9376	1.015522
30.01383	139.9353	0.9667597
30.06716	139.9326	0.9157968
30.11716	139.9303	0.8706784
30.17050	139.9278	0.8228180
30.22050	139.9244	0.7736492
30.27383	139.9228	0.7248957
30.32550	139.9200	0.6769353
30.37716	139.9175	0.6272664
30.43050	139.9156	0.5767815
30.48050	139.9132	0.5310645
30.53383	139.9101	0.4849270
30.58550	139.9077	0.4444996
30.63716	139.9054	0.3950746
30.68883	139.9037	0.3524752
30.74050	139.9003	0.3118319
30.79383	139.8981	0.2682294
30.84383	139.8959	0.2247436
30.89716	139.8942	0.1806932
30.94883	139.8918	0.1393250
31.00050	139.8907	0.09905478
31.05383	139.8877	0.05591419
31.10383	139.8861	0.01866830
31.15716	139.8836	-.02024199
31.20716	139.8823	-.05522293
31.26050	139.8807	-.09315644
31.31217	139.8783	-0.1298234
31.36383	139.8764	-0.1623594
31.41716	139.8752	-0.1975210
31.46716	139.8736	-0.2290433
31.52050	139.8718	-0.2615277
31.57217	139.8700	-0.2940077
31.62383	139.8682	-0.3241436
31.67717	139.8665	-0.3539446
31.72717	139.8654	-0.3821986
31.78050	139.8646	-0.4128400
31.83050	139.8624	-0.4390100
31.88383	139.8610	-0.4694690
31.93550	139.8604	-0.4947566
31.98717	139.8591	-0.5169068
32.04050	139.8576	-0.5422476
32.09050	139.8567	-0.5645829
32.14383	139.8545	-0.5855860
32.19383	139.8534	-0.6048160
32.24716	139.8521	-0.6280304
32.29883	139.8509	-0.6485105
32.35050	139.8494	-0.6689326
32.40383	139.8488	-0.6890353
32.45383	139.8478	-0.7067319
32.50716	139.8477	-0.7283721
32.55883	139.8461	-0.7471909
32.61050	139.8451	-0.7630430
32.66383	139.8446	-0.7794762
32.71383	139.8434	-0.7966571
32.76716	139.8433	-0.8125457
32.81716	139.8418	-0.8278074
32.87050	139.8414	-0.8417851
32.92216	139.8402	-0.8549532
32.97383	139.8396	-0.8691361
33.02716	139.8383	-0.8809391
33.07717	139.8388	-0.8932038
33.13050	139.8369	-0.9048974
33.18216	139.8365	-0.9168430
33.23383	139.8364	-0.9307603
33.28550	139.8356	-0.9419351
33.33716	139.8345	-0.9530670
33.39050	139.8344	-0.9658351
33.44050	139.8336	-0.9761574
33.49383	139.8341	-0.9874201
33.54550	139.8330	-0.9978321
33.59716	139.8333	-1.008692
33.65050	139.8327	-1.019070
33.70050	139.8308	-1.028641
33.75383	139.8314	-1.039252
33.80383	139.8312	-1.048848
33.85716	139.8308	-1.058498
33.90883	139.8300	-1.067431
33.96050	139.8300	-1.076809
34.01383	139.8294	-1.086301
34.06383	139.8294	-1.095027
34.11716	139.8294	-1.104041
34.16883	139.8288	-1.112294
34.22050	139.8278	-1.120306
34.27217	139.8277	-1.127842
34.32383	139.8274	-1.134879
34.37717	139.8280	-1.142130
34.42717	139.8262	-1.148580
34.48050	139.8267	-1.155486
34.53216	139.8262	-1.161992
34.58383	139.8259	-1.168460
34.63716	139.8257	-1.174974
34.68716	139.8258	-1.181102
34.74050	139.8252	-1.187474
34.79050	139.8249	-1.193115
34.84384	139.8246	-1.198916
34.89550	139.8246	-1.204469
34.94717	139.8245	-1.209600
35.00050	139.8229	-1.214254
35.05050	139.8230	-1.218227
35.10383	139.8222	-1.222552
35.15550	139.8220	-1.226565
35.20716	139.8218	-1.230706
35.25883	139.8216	-1.234988
35.31050	139.8216	-1.239407
35.36383	139.8206	-1.243849
35.41383	139.8210	-1.248110
35.46716	139.8213	-1.252656
35.51883	139.8208	-1.256668
35.57050	139.8203	-1.260676
35.62383	139.8199	-1.264748
35.67383	139.8201	-1.268632
35.72717	139.8202	-1.272474
35.77716	139.8204	-1.275861
35.83050	139.8199	-1.279566
35.88216	139.8196	-1.282746
35.93384	139.8194	-1.285822
35.98717	139.8189	-1.288818
36.03717	139.8193	-1.291678
36.09050	139.8186	-1.294660
36.14216	139.8187	-1.297483
36.19383	139.8184	-1.300414
36.24550	139.8189	-1.303218
36.29716	139.8188	-1.305862
36.35050	139.8186	-1.308478
36.40050	139.8180	-1.310864
36.45383	139.8184	-1.313713
36.50550	139.8180	-1.316410
36.55716	139.8179	-1.319051
36.61050	139.8181	-1.321577
36.66050	139.8183	-1.323985
36.71383	139.8174	-1.326500
36.76383	139.8179	-1.328726
36.81716	139.8184	-1.330836
36.86883	139.8175	-1.332604
36.92050	139.8175	-1.334510
36.97383	139.8172	-1.336636
37.02383	139.8170	-1.338485
37.07717	139.8171	-1.340308
37.12883	139.8172	-1.342094
37.18050	139.8176	-1.343953
37.23216	139.8174	-1.346015
37.28383	139.8172	-1.348042
37.33716	139.8173	-1.350254
37.38716	139.8176	-1.352246
37.44050	139.8172	-1.354225
37.49216	139.8170	-1.355788
37.54383	139.8168	-1.357274
37.59716	139.8158	-1.358269
37.64717	139.8165	-1.359284
37.70050	139.8156	-1.360237
37.75050	139.8160	-1.361200
37.80383	139.8168	-1.362468
37.85550	139.8156	-1.363548
37.90716	139.8164	-1.364975
37.96050	139.8153	-1.366558
38.01050	139.8150	-1.367818
38.06383	139.8156	-1.369171
38.11550	139.8154	-1.370619
38.16716	139.8154	-1.372018
38.22050	139.8153	-1.373577
38.27050	139.8156	-1.375022
38.32383	139.8157	-1.376456
38.37383	139.8153	-1.377645
38.42717	139.8155	-1.378580
38.47883	139.8146	-1.379443
38.53050	139.8153	-1.380362
38.58383	139.8152	-1.381526
38.63383	139.8151	-1.382422
38.68716	139.8149	-1.383424
38.73717	139.8148	-1.384504
38.79050	139.8149	-1.385450
38.84216	139.8153	-1.386354
38.89383	139.8152	-1.387446
38.94717	139.8152	-1.388495
38.99716	139.8156	-1.389287
39.05050	139.8152	-1.390053
39.10217	139.8145	-1.390949
39.15383	139.8152	-1.392100
39.20716	139.8149	-1.393356
39.25716	139.8146	-1.394126
39.31050	139.8148	-1.395117
39.36050	139.8139	-1.396198
39.41383	139.8139	-1.397214
39.46550	139.8144	-1.398075
39.51716	139.8148	-1.398921
39.57050	139.8143	-1.399701
39.62050	139.8145	-1.400500
39.67383	139.8144	-1.401353
39.72550	139.8144	-1.402296
39.77716	139.8152	-1.403126
39.82883	139.8146	-1.404153
39.88050	139.8149	-1.405091
39.93384	139.8148	-1.406014
39.98383	139.8147	-1.406597
40.03717	139.8135	-1.407087
40.08883	139.8145	-1.407646
40.14050	139.8140	-1.408081
40.19383	139.8142	-1.408399
40.24383	139.8142	-1.408704
40.29716	139.8138	-1.409118
40.34716	139.8137	-1.409453
40.40050	139.8142	-1.410052
40.45216	139.8134	-1.410554
40.50383	139.8132	-1.411170
40.55716	139.8139	-1.412050
40.60716	139.8136	-1.412660
40.66050	139.8141	-1.413536
40.71216	139.8136	-1.414349
40.76383	139.8140	-1.415115
40.81550	139.8136	-1.415810
40.86716	139.8135	-1.416435
40.92050	139.8137	-1.417007
40.97050	139.8141	-1.417556
41.02383	139.8144	-1.418246
41.07550	139.8139	-1.418835
41.12717	139.8139	-1.419244
41.18050	139.8140	-1.419580
41.23050	139.8135	-1.420148
41.28383	139.8141	-1.420369
41.33383	139.8133	-1.420436
41.38716	139.8137	-1.420776
41.43883	139.8134	-1.421124
41.49050	139.8142	-1.421370
41.54383	139.8139	-1.421566
41.59384	139.8131	-1.421799
41.64717	139.8137	-1.422274
41.69883	139.8130	-1.422663
41.75050	139.8134	-1.423257
41.80217	139.8134	-1.423884
41.85383	139.8132	-1.424372
41.90717	139.8140	-1.424815
41.95717	139.8138	-1.425099
42.01050	139.8134	-1.425587
42.06216	139.8133	-1.425908
42.11383	139.8128	-1.425827
42.16716	139.8130	-1.425947
42.21717	139.8135	-1.426035
42.27050	139.8132	-1.426345
42.32050	139.8135	-1.426762
42.37383	139.8143	-1.427745
42.42550	139.8138	-1.428664
42.47717	139.8134	-1.429609
42.53050	139.8138	-1.430369
42.58050	139.8136	-1.431014
42.63383	139.8136	-1.431240
42.68550	139.8138	-1.431493
42.73717	139.8128	-1.431249
42.78883	139.8131	-1.431014
42.84050	139.8128	-1.430873
42.89383	139.8130	-1.430736
42.94383	139.8134	-1.430671
42.99716	139.8129	-1.430632
43.04550	139.8430	-1.474388
43.09716	140.1859	-2.579224
43.15050	140.7781	-5.216960
43.20050	141.4404	-8.112388
43.25383	142.2293	-11.10366
43.30550	143.0519	-13.65009
43.35717	143.9176	-15.77980
43.41050	144.8463	-17.56381
43.46050	145.7431	-18.91021
43.51383	146.7197	-20.05805
43.56383	147.6506	-20.92444
43.61716	148.6576	-21.66522
43.66883	149.6420	-22.24999
43.72050	150.6349	-22.72756
43.77383	151.6659	-23.14156
43.82383	152.6372	-23.46717
43.87717	153.6781	-23.77879
43.92883	154.6886	-24.03792
43.98050	155.7035	-24.28010
44.03217	156.7186	-24.49306
44.08383	157.7359	-24.69188
44.13716	158.7874	-24.88843
44.18716	159.7749	-25.06092
44.24050	160.8292	-25.23613
44.29217	161.8502	-25.41148
44.34384	162.8728	-25.57773
44.39717	163.9286	-25.74384
44.44717	164.9210	-25.90580
44.50050	165.9790	-26.07001
44.55050	166.9701	-26.22448
44.60383	168.0279	-26.39653
44.65550	169.0532	-26.55024
44.70717	170.0778	-26.70627
44.76050	171.1365	-26.87258
44.81050	172.1290	-27.02916
44.86383	173.1868	-27.20622
44.91550	174.2120	-27.37138
44.96717	175.2373	-27.54086
45.01883	176.2631	-27.71538
45.07050	177.2878	-27.89198
45.12383	178.3467	-28.07725
45.17383	179.3390	-28.25974
45.22717	180.3961	-28.45869
45.27883	181.4206	-28.66532
45.33050	182.4444	-28.88354
45.38383	183.5013	-29.11368
45.43383	184.4909	-29.34968
45.48717	185.5461	-29.60892
45.53717	186.5359	-29.86095
45.59050	187.5894	-30.14242
45.64217	188.6114	-30.43040
45.69383	189.6334	-30.72194
45.74716	190.6866	-31.05029
45.79716	191.6737	-31.36025
45.85050	192.7248	-31.71656
45.90216	193.7440	-32.07486
45.95383	194.7614	-32.44916
46.00717	195.8099	-32.85939
46.05717	196.7922	-33.27182
46.11050	197.8375	-33.75294
46.16050	198.8180	-34.22272
46.21383	199.8614	-34.75910
46.26550	200.8703	-35.32018
46.31717	201.8792	-35.91448
46.37050	202.9171	-36.58032
46.42050	203.8884	-37.24568
46.47383	204.9212	-38.02795
46.52383	205.8873	-38.83858
46.57717	206.9124	-39.79144
46.62883	207.9019	-40.81211
46.68050	208.8861	-41.95848
46.73383	209.8946	-43.28744
46.78383	210.8336	-44.69343
46.83716	211.8261	-46.43694
46.88883	212.7735	-48.44590
46.94050	213.7085	-50.76211
46.99383	214.6542	-53.58536
47.04383	215.5213	-56.70171
47.09716	216.4206	-60.55850
47.14717	217.2436	-64.67126
47.20050	218.0977	-69.51255
47.25217	218.9106	-74.48571
47.30383	219.7184	-79.42681
47.35717	220.5756	-83.73306
47.40717	221.4531	-85.68551
47.46050	222.5185	-84.84608
47.51216	223.6490	-82.25671
47.56383	224.8398	-78.48280
47.61550	226.0798	-73.66451
47.66716	227.3649	-67.88032
47.72050	228.7389	-60.83501
47.77050	230.0434	-54.34536
47.82383	231.3905	-48.70042
47.87550	232.8492	-38.40498
47.92717	234.1296	-34.47862
47.98050	235.2658	-34.54832
48.03050	236.2412	-34.99658
48.08383	237.3101	-34.67148
48.13383	238.3310	-34.18924
48.18716	239.4234	-33.64567
48.23883	240.4812	-33.16715
48.29050	241.5355	-32.75060
48.34384	242.6210	-32.40598
48.39383	243.6358	-32.13076
48.44717	244.7147	-31.89702
48.49883	245.7576	-31.71835
48.55050	246.7996	-31.58496
48.60217	247.8384	-31.49914
48.65383	248.8768	-31.45961
48.70717	249.9474	-31.39388
48.75717	250.9523	-31.33776
48.81050	252.0234	-31.28732
48.86217	253.0595	-31.24779
48.91383	254.0960	-31.21907
48.96717	255.1655	-31.19228
49.01717	256.1662	-31.17863
49.07050	257.2350	-31.17870
49.12050	258.2354	-31.18227
49.17383	259.3032	-31.18568
49.22550	260.3369	-31.19196
49.27716	261.3713	-31.20166
49.33050	262.4382	-31.22034
49.38050	263.4387	-31.25957
49.43383	264.5045	-31.29944
49.48550	265.5362	-31.37984
49.53717	266.5690	-31.40818
49.58883	267.6020	-31.45225
49.64050	268.6328	-31.50318
49.69383	269.6986	-31.61564
49.74383	270.6963	-31.65990
49.79716	271.7620	-31.69787
49.84883	272.7949	-31.73261
49.90050	273.8280	-31.76558
49.95383	274.8941	-31.79978
50.00050	275.8268	-31.83400
50.05383	276.7721	-31.55114
50.10550	276.9714	-27.93779
50.15717	276.7932	-21.08694
50.21050	276.3824	-13.37424
50.26050	275.8579	-6.695610
50.31383	275.1896	-0.6421644
50.36550	274.4607	4.117598
50.41716	273.6704	7.912397
50.47050	272.8034	10.98787
50.52050	271.9553	13.25418
50.57383	271.0193	15.16052
50.62383	270.1202	16.56224
50.67717	269.1422	17.73589
50.72883	268.1800	18.63791
50.78050	267.2072	19.36282
50.83383	266.1941	19.96403
50.88383	265.2346	20.42289
50.93716	264.2060	20.81517
50.98883	263.2040	21.13192
51.04050	262.1990	21.38498
51.09217	261.1891	21.60798
51.14383	260.1784	21.79406
51.19717	259.1319	21.95288
51.24717	258.1486	22.07434
51.30050	257.0976	22.19819
51.35217	256.0796	22.29513
51.40383	255.0598	22.38548
51.45717	254.0048	22.46963
51.50717	253.0158	22.53719
51.56050	251.9588	22.59858
51.61050	250.9680	22.64808
51.66383	249.9110	22.69371
51.71550	248.8864	22.73420
51.76716	247.8605	22.77270
51.82050	246.8028	22.80977
51.87050	245.8104	22.83784
51.92383	244.7503	22.86794
51.97550	243.7233	22.89207
52.02717	242.6970	22.90453
52.07883	241.6696	22.91406
52.13050	240.6427	22.92262
52.18383	239.5832	22.93160
52.23383	238.5884	22.94554
52.28716	237.5274	22.96217
52.33883	236.5001	22.97505
52.39050	235.4716	22.99065
52.44384	234.4111	22.99983
52.49382	233.4160	23.00872
52.54717	232.3549	23.01725
52.59716	231.3604	23.02403
52.65050	230.2996	23.03138
52.70216	229.2709	23.03873
52.75383	228.2425	23.04627
52.80717	227.1810	23.05730
52.85717	226.1848	23.06555
52.91050	225.1227	23.07389
52.96216	224.0935	23.08252
53.01382	223.0644	23.08976
53.06550	222.0354	23.09585
53.11716	221.0062	23.10131
53.17050	219.9439	23.10605
53.22050	218.9488	23.11066
53.27383	217.8863	23.11568
53.32550	216.8582	23.11952
53.37717	215.8297	23.12291
53.43050	214.7670	23.12666
53.48050	213.7718	23.13024
53.53383	212.7097	23.13420
53.58383	211.7132	23.13776
53.63716	210.6512	23.14098
53.68882	209.6214	23.14348
53.74050	208.5923	23.14543
53.79382	207.5290	23.14648
53.84384	206.5327	23.14696
53.89717	205.4705	23.14683
53.94883	204.4404	23.14602
54.00050	203.4104	23.14467
54.05217	202.3818	23.14284
54.10383	201.3524	23.13996
54.15717	200.2900	23.13706
54.20717	199.2938	23.13460
54.26050	198.2312	23.13235
54.31216	197.2026	23.13108
54.36382	196.1734	23.13008
54.41716	195.1104	23.12979
54.46717	194.1151	23.13032
54.52050	193.0511	23.13197
54.57050	192.0548	23.13285
54.62383	190.9921	23.13297
54.67550	189.9618	23.13222
54.72717	188.9326	23.13021
54.78050	187.8697	23.12794
54.83050	186.8733	23.12590
54.88383	185.8100	23.12403
54.93550	184.7803	23.12215
54.98717	183.7494	23.11972
55.03882	182.7198	23.11620
55.09050	181.6896	23.11222
55.14384	180.6273	23.10747
55.19384	179.6305	23.10375
55.24717	178.5678	23.10134
55.29883	177.5386	23.10130
55.35050	176.5090	23.10398
55.40383	175.4460	23.11103
55.45383	174.4498	23.12535
55.50717	173.3878	23.15387
55.55717	172.3934	23.19110
55.61050	171.3328	23.24068
55.66216	170.3048	23.29105
55.71382	169.2778	23.36033
55.76716	168.2197	23.45208
55.81716	167.2279	23.57813
55.87050	166.1757	23.82086
55.92217	165.1652	24.28697
55.97382	164.1722	25.19530
56.02717	163.1798	26.94336
56.07717	162.2970	29.63654
56.13050	161.4164	33.81624
56.18050	160.6475	38.77391
56.23383	159.8625	44.57556
56.28550	159.1036	49.90938
56.33716	158.3100	54.30104
56.39050	157.4267	57.40343
56.44050	156.5300	58.81871
56.49382	155.4937	58.75162
56.54382	154.4539	57.34730
56.59716	153.2822	54.72374
56.64883	152.1036	51.45078
56.70050	150.9017	47.87514
56.75383	149.6570	44.25239
56.80383	148.5025	41.16197
56.85717	147.2890	38.30808
56.90883	146.1362	35.97246
56.96050	145.0012	34.03310
57.01382	143.8502	32.37314
57.06382	142.7834	31.08044
57.11716	141.6593	29.93432
57.16716	140.6148	29.03994
57.22050	139.5106	28.24244
57.27217	138.4462	27.58846
57.32383	137.3864	27.04556
57.37717	136.2989	26.56456
57.42717	135.2826	26.17887
57.48050	134.2007	25.83066
57.53217	133.1552	25.53694
57.58383	132.1118	25.28092
57.63550	131.0697	25.03755
57.68716	130.0293	24.84152
57.74050	128.9559	24.64158
57.79050	127.9489	24.46137
57.84384	126.8767	24.29480
57.89550	125.8392	24.15470
57.94717	124.8021	24.02192
58.00050	123.7319	23.89292
58.05050	122.7293	23.77391
58.10383	121.6592	23.65828
58.15383	120.6572	23.55660
58.20717	119.5886	23.43601
58.25883	118.5523	23.33222
58.31050	117.5177	23.23414
58.36382	116.4489	23.13022
58.41382	115.4468	23.04208
58.46717	114.3785	22.92644
58.51884	113.3435	22.82885
58.57050	112.3034	22.61499
58.62217	111.2606	22.37547
58.67383	110.2200	22.19238
58.72717	109.1502	22.08655
58.77717	108.1492	22.03506
58.83050	107.0837	21.98993
58.88217	106.0510	21.94550
58.93383	105.0185	21.88980
58.98717	103.9527	21.83436
59.03716	102.9537	21.78420
59.09050	101.8870	21.72822
59.14050	100.8867	21.66959
59.19384	99.82103	21.61333
59.24550	98.78653	21.54163
59.29717	97.75228	21.43997
59.35050	96.67931	21.19100
59.40050	95.67244	21.08665
59.45383	94.60587	21.03650
59.50550	93.57356	21.00263
59.55717	92.54151	20.95338
59.60883	91.50908	20.90644
59.66050	90.47684	20.85741
59.71382	89.41019	20.78786
59.76382	88.41022	20.73203
59.81716	87.34392	20.66914
59.86882	86.31047	20.60356
59.92050	85.27704	20.53562
59.97382	84.20965	20.46184
60.02383	83.20985	20.39389
60.07717	82.14282	20.32041
60.12717	81.14285	20.26054
60.18050	80.07608	20.19253
60.23217	79.04260	20.12934
60.28383	78.00868	20.06262
60.33716	76.94160	19.99580
60.38716	75.94118	19.93120
60.44050	74.87390	19.86494
60.49216	73.83993	19.79308
60.54382	72.80644	19.72838
60.59550	71.77286	19.66381
60.64717	70.73920	19.60157
60.70050	69.67092	19.53840
60.75050	68.67075	19.47199
60.80383	67.60247	19.38638
60.85550	66.56806	19.31340
60.90717	65.53407	19.24674
60.96050	64.46748	19.17867
61.01050	63.46866	19.12221
61.06382	62.40098	19.04237
61.11382	61.40099	18.97282
61.16716	60.33289	18.90399
61.21884	59.29792	18.83076
61.27050	58.26380	18.75091
61.32383	57.19590	18.66631
61.37383	56.19391	18.59461
61.42717	55.12788	18.51863
61.47883	54.09413	18.44959
61.53050	53.05986	18.37849
61.58217	52.02607	18.31049
61.63383	50.99124	18.23676
61.68716	49.92348	18.16296
61.73717	48.92201	18.09356
61.79050	47.85322	18.01764
61.84217	46.81867	17.94212
61.89384	45.78375	17.87338
61.94717	44.71575	17.79698
61.99717	43.71425	17.72706
62.05050	42.64636	17.64828
62.10050	41.64479	17.57633
62.15383	40.57708	17.50372
62.20550	39.54306	17.43202
62.25717	38.50794	17.35695
62.31050	37.44078	17.27558
62.36050	36.43908	17.19692
62.41382	35.37042	17.11268
62.46550	34.33465	17.03369
62.51716	33.30144	16.94603
62.57050	32.23292	16.85948
62.62050	31.23199	16.77503
62.67383	30.16339	16.69002
62.72382	29.16065	16.61449
62.77717	28.09073	16.52358
62.82883	27.05471	16.43042
62.88050	26.01716	16.33497
62.93383	24.94745	16.23106
62.98383	23.94370	16.13582
63.03383	22.96064	16.01712
63.08550	22.49361	15.36802
63.13716	22.58031	12.40720
63.19050	22.90923	8.369015
63.24050	23.38770	4.446672
63.29382	24.02004	0.6178322
63.34550	24.72717	-2.568721
63.39717	25.50431	-5.214606
63.45050	26.36163	-7.421554
63.50050	27.20523	-9.076444
63.55383	28.13481	-10.48564
63.60383	29.03018	-11.53322
63.65717	30.00732	-12.42258
63.70883	30.96690	-13.11195
63.76050	31.94010	-13.66629
63.81382	32.95259	-14.13375
63.86384	33.91140	-14.49324
63.91716	34.93872	-14.81561
63.96884	35.93966	-15.06886
64.02050	36.94479	-15.28652
64.07218	37.95297	-15.48243
64.12383	38.96360	-15.64645
64.17718	40.00982	-15.79577
64.22718	40.99250	-15.91504
64.28050	42.04212	-16.03600
64.33217	43.06020	-16.14412
64.38384	44.08105	-16.24471
64.43717	45.13446	-16.34125
64.48717	46.12382	-16.42918
64.54050	47.17918	-16.51976
64.59050	48.16916	-16.60400
64.64384	49.22861	-16.69014
64.69550	50.25300	-16.77277
64.74717	51.27900	-16.85562
64.80050	52.33822	-16.93416
64.85050	53.33209	-17.00840
64.90384	54.39196	-17.08554
64.95550	55.41895	-17.15740
65.00718	56.44639	-17.23373
65.05884	57.47390	-17.31484
65.11050	58.50234	-17.39154
65.16382	59.56325	-17.47595
65.21384	60.55959	-17.55275
65.26716	61.62126	-17.63710
65.31884	62.65134	-17.71785
65.37050	63.67918	-17.79465
65.42383	64.74224	-17.87730
65.47384	65.73672	-17.94793
65.52717	66.79990	-18.02552
65.57718	67.79547	-18.10734
65.63050	68.85861	-18.19203
65.68218	69.88878	-18.27308
65.73384	70.91934	-18.35006
65.78718	71.98266	-18.42837
65.83716	72.97878	-18.50286
65.89050	74.04186	-18.58670
65.94218	75.07139	-18.66759
65.99384	76.10080	-18.74638
66.04550	77.13024	-18.83121
66.09718	78.15990	-18.91649
66.15050	79.22300	-19.00450
66.20050	80.22045	-19.09066
66.25384	81.28301	-19.17921
66.30550	82.31401	-19.26454
66.35718	83.34329	-19.35347
66.41050	84.40718	-19.44206
66.46050	85.40434	-19.52688
66.51384	86.46742	-19.62320
66.56384	87.46412	-19.70723
66.61718	88.52687	-19.80268
66.66884	89.55676	-19.89400
66.72050	90.58705	-19.99615
66.77384	91.65020	-20.08435
66.82384	92.64687	-20.17733
66.87718	93.71069	-20.27299
66.92884	94.74086	-20.35904
66.98050	95.77059	-20.45274
67.03218	96.80095	-20.54472
67.08384	97.83144	-20.62920
67.13718	98.89512	-20.73077
67.18718	99.89141	-20.81301
67.24050	100.9555	-20.90895
67.29218	101.9855	-21.00355
67.34384	103.0153	-21.09330
67.39718	104.0782	-21.18436
67.44718	105.0751	-21.27816
67.50050	106.1379	-21.37914
67.55050	107.1351	-21.47090
67.60384	108.1980	-21.57040
67.65550	109.2284	-21.67042
67.70718	110.2576	-21.76641
67.76050	111.3216	-21.86562
67.81050	112.3184	-21.95795
67.86384	113.3818	-22.05470
67.91550	114.4123	-22.14749
67.96718	115.4421	-22.23857
68.02050	116.5050	-22.34026
68.07050	117.5015	-22.43011
68.12384	118.5652	-22.52914
68.17384	119.5616	-22.62125
68.22718	120.6257	-22.72078
68.27884	121.6552	-22.81551
68.33050	122.6850	-22.90874
68.38384	123.7498	-23.01264
68.43384	124.7464	-23.10875
68.48718	125.8088	-23.21160
68.53718	126.8051	-23.30497
68.59050	127.8687	-23.41215
68.64216	128.8978	-23.51118
68.69384	129.9285	-23.61556
68.74718	130.9906	-23.72778
68.79718	131.9874	-23.83419
68.85050	133.0501	-23.94678
68.90218	134.0792	-24.06366
68.95384	135.1090	-24.17673
69.00718	136.1711	-24.30008
69.05718	137.1669	-24.41838
69.11050	138.2282	-24.54385
69.16050	139.2244	-24.66756
69.21384	140.2871	-24.79677
69.26550	141.3166	-24.92836
69.31718	142.3451	-25.05126
69.37050	143.4075	-25.18714
69.42050	144.4038	-25.30872
69.47384	145.4646	-25.43639
69.52550	146.4944	-25.56649
69.57718	147.5231	-25.69921
69.62884	148.5521	-25.83109
69.68050	149.5800	-25.96504
69.73384	150.6415	-26.09971
69.78384	151.6358	-26.23390
69.83716	152.6975	-26.37752
69.88884	153.7259	-26.52908
69.94050	154.7544	-26.67606
69.99384	155.8148	-26.83684
70.04384	156.8107	-26.98294
70.09718	157.8724	-27.13153
70.14718	158.8681	-27.28263
70.20050	159.9282	-27.42614
70.25218	160.9564	-27.56650
70.30384	161.9848	-27.70950
70.35718	163.0472	-27.84047
70.40718	164.0431	-27.95490
70.46050	165.1078	-28.06022
70.51218	166.1391	-28.13419
70.56384	167.1714	-28.19761
70.61550	168.2042	-28.25180
70.66718	169.2373	-28.29014
70.72050	170.3026	-28.33601
70.77050	171.3005	-28.39301
70.82384	172.3654	-28.46609
70.87550	173.3959	-28.55510
70.92718	174.4256	-28.65832
70.98050	175.4886	-28.77684
71.03050	176.4841	-28.90438
71.08384	177.5463	-29.06150
71.13384	178.5396	-29.21952
71.18718	179.5999	-29.41139
71.23882	180.6252	-29.61254
71.29050	181.6484	-29.84343
71.34384	182.7051	-30.11228
71.39384	183.6941	-30.38195
71.44718	184.7471	-30.70427
71.49884	185.7666	-31.05135
71.55050	186.7834	-31.43160
71.60218	187.7986	-31.86270
71.65384	188.8129	-32.34850
71.70718	189.8566	-32.90006
71.75718	190.8313	-33.49384
71.81050	191.8702	-34.17432
71.86218	192.8724	-34.89001
71.91382	193.8731	-35.64255
71.96718	194.9051	-36.43511
72.01716	195.8717	-37.19621
72.07050	196.9016	-38.02126
72.12050	197.8670	-38.82088
72.17384	198.8946	-39.69746
72.22551	199.8875	-40.62282
72.27718	200.8774	-41.63144
72.33050	201.8958	-42.76630
72.38050	202.8466	-43.91676
72.43384	203.8569	-45.20097
72.48550	204.8335	-46.47391
72.53718	205.8116	-47.69958
72.58884	206.7949	-48.76358
72.64050	207.7923	-49.47074
72.69384	208.8488	-49.49600
72.74384	209.8817	-48.50203
72.79718	211.0370	-46.22836
72.84882	212.2020	-43.24300
72.90050	213.3809	-40.12724
72.95384	214.5861	-37.34587
73.00384	215.6929	-35.27081
73.05718	216.8495	-33.53750
73.10718	217.9152	-32.29518
73.16050	219.0364	-31.27697
73.21218	220.1096	-30.51655
73.26384	221.1740	-29.94580
73.31718	222.2652	-29.50361
73.36718	223.2828	-29.19072
73.42050	224.3642	-28.94807
73.47218	225.4079	-28.77240
73.52384	226.4494	-28.64840
73.57550	227.4880	-28.57044
73.62718	228.5258	-28.51342
73.68050	229.5959	-28.48906
73.73050	230.5984	-28.48429
73.78384	231.6670	-28.48318
73.83550	232.7016	-28.49068
73.88718	233.7363	-28.52024
73.94050	234.8040	-28.56050
73.99050	235.8031	-28.60402
74.04384	236.8698	-28.64252
74.09384	237.8695	-28.68592
74.14718	238.9359	-28.73957
74.19884	239.9684	-28.78906
74.25050	241.0000	-28.85320
74.30384	242.0676	-28.92027
74.35384	243.0652	-28.98379
74.40718	244.1324	-29.04852
74.45884	245.1651	-29.10356
74.51050	246.1980	-29.16207
74.56384	247.2630	-29.22352
74.61384	248.2617	-29.27740
74.66718	249.3277	-29.33574
74.71718	250.3265	-29.39746
74.77050	251.3931	-29.46284
74.82218	252.4252	-29.52410
74.87384	253.4580	-29.58228
74.92718	254.5234	-29.63986
74.97718	255.5221	-29.69148
75.03050	256.5894	-29.75956
75.08050	257.5876	-29.81978
75.13384	258.6536	-29.88047
75.18550	259.6860	-29.93798
75.23718	260.7184	-30.00430
75.29050	261.7829	-30.06736
75.34050	262.7825	-30.13392
75.39384	263.8488	-30.19992
75.44550	264.8811	-30.26735
75.49718	265.9126	-30.33228
75.55050	266.9776	-30.40840
75.60050	267.9764	-30.47783
75.65384	269.0414	-30.54293
75.70384	270.0408	-30.62097
75.75718	271.1060	-30.69668
75.80884	272.1383	-30.77722
-2.000000	5.000000	0.0000000