File: 4-C1(1.2mol%)+C20(0.6mol%)/matlab/140-1
CLOSED
Version	1.0
Language	English
Mode	Standard
Run	1
RunSerial	11866
Instrument	DSC Q2000 V24.11 Build 124
Module	DSC Standard Cell RC
Operator	Jing
File	\\Ae520-1454\ta\Data\DSC\UQ Composites\Nan\C1(6.5)+C20P(3)+CL(Hotplate MixtureAB) New\140-1
ProcName	Ramp
InstSerial	2000-0883
AutoSerial	1293
Sample	Iso140-1
Size	34.6000	mg
PanMass	Not available
PanResist	Automatic Automatic  K/W
PanFactor	Default Default
Method	Ramp
Comment
Xcomment	Pan: Tzero Aluminum Hermetic
Xcomment	Gas1: Nitrogen 50.0 ml/min
Xcomment	Gas2: Nitrogen 50.0 ml/min
Text
Exotherm	UP
Kcell	1.05230
Cpconst	Standard: 0.938
Calib	-38.6961
TempCal	1	pts	157.46	156.60
TzeroDt	-87.6168 -0.0009 -1.4231
TzeroDtz	-87.6168 0.0057 6.9570
InstCalFile	Tzero: \\Ae520-1454\ta\Data\DSC\Calibration\2017\CALIBRATION\1562_RCS (90)_05_18_2017 10_50_44.TZR
InstCalFile	Baseline: \\Ae520-1454\ta\Data\DSC\Calibration\2017\2017-05-17_Calibration.001
InstCalFile	Sapphire: \\Ae520-1454\ta\Data\DSC\Calibration\2017\2017-05-17_Saphire.001
InstCalDate	Tzero 2017-05-18 Time 10:50:44
TempRange	-87.39 to 398.39 °C at 10.00 °C/min Heat Only
AutoZero	Delta T Offset 0.000 uV
AutoZero	Delta T0 Offset 0.000 uV
MultiptCal	0
MultiPtDesc	0) Not set
AutoCellConst	Calibration Date 2017-05-18 16:59:28
Controls	Gas 1  Event Off  Sampling 0.2
Cell#	RC-01562
CoolingUnit	RCS (90)
SelHeatFlow	Heat Flow T4 (mW)
AutoLidII	Installed
AutoAnalysis	Off
MacroFile
Nsig	3
Sig1	Time (min)
Sig2	Temperature (°C)
Sig3	Heat Flow (mW)
Date	2017-06-21
Time	13:41:50
OrgMethod	1: Equilibrate at 20.00 °C
OrgMethod	2: Ramp 40.00 °C/min to 140.00 °C
OrgMethod	3: Mark end of cycle 1
OrgMethod	4: Isothermal for 40.00 min
OrgMethod	5: Mark end of cycle 2
OrgMethod	6: Ramp 20.00 °C/min to 280.00 °C
OrgMethod	7: Mark end of cycle 3
OrgMethod	8: Ramp 20.00 °C/min to 20.00 °C
OrgMethod	9: Mark end of cycle 4
OrgMethod	10: Ramp 20.00 °C/min to 280.00 °C
OrgMethod	11: Mark end of cycle 5
OrgFile	C:\Users\jarra\Desktop\DSC\4-C1(1.2mol%)+C20(0.6mol%)\140-1
StartOfData
4.99994E-4	19.96251	0.1398864
0.05383332	20.09690	0.2562231
0.1055000	20.99854	-0.4056352
0.1571666	22.27517	-3.191036
0.2105000	23.78292	-6.814475
0.2605000	25.32644	-10.30300
0.3138333	27.06748	-13.70610
0.3655000	28.82928	-16.56287
0.4171667	30.64482	-18.95148
0.4705000	32.56579	-20.99125
0.5205000	34.39990	-22.56581
0.5738334	36.38419	-23.95088
0.6238334	38.26445	-25.04424
0.6771668	40.28712	-26.04708
0.7288332	42.25770	-26.93782
0.7805000	44.23328	-27.84877
0.8338332	46.27926	-28.64082
0.8838332	48.21469	-29.15956
0.9371668	50.28912	-29.63456
0.9888332	52.30376	-30.13036
1.040500	54.31546	-30.74208
1.092167	56.32182	-31.50298
1.143833	58.32216	-32.38364
1.197166	60.38720	-33.35544
1.247166	62.32092	-34.35196
1.300500	64.37657	-35.66054
1.352166	66.34361	-37.55295
1.403833	68.25130	-40.86262
1.457167	70.08612	-47.45754
1.507167	71.61064	-57.34802
1.560500	73.05822	-70.68842
1.610500	74.34128	-83.75507
1.663834	75.72702	-97.15747
1.715500	77.10174	-109.7799
1.767167	78.49155	-121.6682
1.820500	80.00603	-132.5258
1.870500	81.56110	-139.8231
1.923834	83.47430	-140.8508
1.975500	85.74912	-136.2548
2.027166	88.02519	-133.2334
2.078833	90.28770	-129.7874
2.130500	92.64691	-123.5229
2.183833	95.37841	-110.4642
2.233833	98.06478	-98.49152
2.287166	100.8144	-88.14309
2.338833	103.3655	-80.08576
2.390500	105.8214	-73.63220
2.443833	108.2781	-68.31814
2.493833	110.5208	-64.35484
2.547166	112.8633	-60.99609
2.597167	115.0174	-58.50654
2.650500	117.2832	-56.44010
2.702166	119.4508	-54.89482
2.753833	121.5981	-53.73145
2.807167	123.7976	-52.82236
2.857167	125.8461	-52.16066
2.910500	128.0229	-51.59744
2.962167	130.1267	-51.16778
3.010500	132.0890	-50.87063
3.060500	133.9232	-50.77372
3.113833	135.0746	-48.64297
3.165500	135.8898	-43.82500
3.217166	136.5236	-38.20252
3.270500	137.0546	-32.44866
3.320500	137.4650	-27.58448
3.373834	137.8297	-23.11276
3.425500	138.1233	-19.49216
3.477167	138.3704	-16.49338
3.528833	138.5779	-14.03603
3.580500	138.7530	-12.01772
3.633833	138.9062	-10.31426
3.683833	139.0276	-8.998181
3.737167	139.1375	-7.837319
3.788833	139.2293	-6.906306
3.840500	139.3077	-6.129068
3.893833	139.3767	-5.467718
3.943833	139.4316	-4.945247
3.997166	139.4826	-4.479118
4.047167	139.5242	-4.109906
4.100500	139.5616	-3.777938
4.152166	139.5939	-3.501904
4.203833	139.6215	-3.268004
4.257167	139.6465	-3.057221
4.307167	139.6658	-2.883918
4.360500	139.6852	-2.732024
4.412167	139.7008	-2.601572
4.463834	139.7142	-2.490819
4.515500	139.7272	-2.390000
4.567167	139.7394	-2.305916
4.620500	139.7480	-2.227270
4.670500	139.7569	-2.164056
4.723834	139.7642	-2.100919
4.775500	139.7704	-2.045986
4.827167	139.7764	-1.998352
4.880500	139.7822	-1.952474
4.930500	139.7874	-1.914066
4.983834	139.7905	-1.878785
5.033834	139.7952	-1.846666
5.087167	139.7976	-1.816286
5.138833	139.8010	-1.790936
5.190500	139.8044	-1.769017
5.243834	139.8068	-1.746639
5.293832	139.8088	-1.727467
5.347168	139.8116	-1.705434
5.398834	139.8134	-1.686220
5.450500	139.8152	-1.668747
5.503834	139.8174	-1.654199
5.553834	139.8184	-1.639456
5.607168	139.8198	-1.624537
5.657166	139.8219	-1.610275
5.710500	139.8230	-1.597281
5.762168	139.8250	-1.585216
5.813832	139.8256	-1.571978
5.867168	139.8272	-1.560171
5.917168	139.8279	-1.549546
5.970500	139.8306	-1.536999
6.020500	139.8310	-1.526921
6.073834	139.8317	-1.515469
6.125500	139.8332	-1.504671
6.177166	139.8330	-1.491459
6.230500	139.8344	-1.477996
6.280500	139.8348	-1.467482
6.333832	139.8357	-1.455267
6.385500	139.8366	-1.442725
6.437168	139.8373	-1.431739
6.490500	139.8381	-1.419683
6.540500	139.8387	-1.409351
6.593832	139.8394	-1.398435
6.643832	139.8410	-1.387384
6.697168	139.8404	-1.375854
6.748834	139.8426	-1.365244
6.800500	139.8425	-1.354898
6.853832	139.8442	-1.342220
6.903832	139.8447	-1.332010
6.957168	139.8460	-1.320365
7.008832	139.8472	-1.309828
7.060500	139.8475	-1.299133
7.112168	139.8482	-1.288093
7.163832	139.8482	-1.277089
7.217168	139.8497	-1.265180
7.267168	139.8504	-1.254102
7.320500	139.8509	-1.242527
7.372168	139.8520	-1.231366
7.423834	139.8526	-1.220231
7.477168	139.8539	-1.208047
7.527168	139.8549	-1.197659
7.580500	139.8551	-1.185881
7.630500	139.8554	-1.174362
7.683832	139.8561	-1.162112
7.735500	139.8570	-1.150103
7.787168	139.8581	-1.138377
7.840500	139.8579	-1.125232
7.890500	139.8584	-1.114074
7.943832	139.8596	-1.100304
7.995500	139.8597	-1.085926
8.047168	139.8605	-1.074069
8.098832	139.8616	-1.062727
8.150500	139.8617	-1.049830
8.203834	139.8621	-1.037257
8.253834	139.8640	-1.025181
8.307168	139.8639	-1.012867
8.358832	139.8652	-1.000231
8.410499	139.8665	-0.9883290
8.463834	139.8668	-0.9750099
8.513832	139.8681	-0.9631806
8.567166	139.8686	-0.9500442
8.617166	139.8698	-0.9374770
8.670500	139.8706	-0.9229340
8.722168	139.8714	-0.9090091
8.773834	139.8724	-0.8964731
8.827168	139.8729	-0.8821899
8.877168	139.8739	-0.8682319
8.930500	139.8756	-0.8537548
8.982166	139.8755	-0.8391839
9.033832	139.8762	-0.8228850
9.085501	139.8779	-0.8097272
9.137168	139.8780	-0.7943649
9.190500	139.8797	-0.7753126
9.240500	139.8809	-0.7613455
9.293834	139.8811	-0.7433740
9.345500	139.8816	-0.7277881
9.397168	139.8830	-0.7132745
9.450500	139.8840	-0.6975559
9.500500	139.8847	-0.6812921
9.553832	139.8857	-0.6635997
9.603832	139.8860	-0.6478204
9.657166	139.8875	-0.6302564
9.708832	139.8878	-0.6143924
9.760499	139.8902	-0.5975912
9.813834	139.8900	-0.5786538
9.863834	139.8904	-0.5624190
9.917168	139.8925	-0.5443813
9.968834	139.8930	-0.5270393
10.02050	139.8932	-0.5085830
10.07217	139.8952	-0.4909866
10.12383	139.8967	-0.4738691
10.17717	139.8969	-0.4560532
10.22717	139.8988	-0.4388120
10.28050	139.8987	-0.4198494
10.33217	139.9002	-0.4006746
10.38383	139.9014	-0.3812800
10.43717	139.9022	-0.3616245
10.48717	139.9035	-0.3416092
10.54050	139.9042	-0.3219202
10.59050	139.9049	-0.3032065
10.64383	139.9065	-0.2809974
10.69550	139.9074	-0.2627773
10.74717	139.9078	-0.2405651
10.80050	139.9096	-0.2197304
10.85050	139.9105	-0.2019207
10.90383	139.9115	-0.1772023
10.95550	139.9122	-0.1565760
11.00717	139.9137	-0.1350505
11.05884	139.9150	-0.1169876
11.11050	139.9160	-.09490543
11.16383	139.9178	-.07348925
11.21383	139.9188	-.05127037
11.26717	139.9198	-.02803793
11.31883	139.9208	-4.2477E-3
11.37050	139.9222	0.01860997
11.42383	139.9235	0.04241740
11.47383	139.9236	0.06694931
11.52717	139.9256	0.09013592
11.57717	139.9264	0.1120687
11.63050	139.9283	0.1370098
11.68217	139.9294	0.1611870
11.73383	139.9302	0.1847850
11.78717	139.9311	0.2100374
11.83717	139.9332	0.2340590
11.89050	139.9347	0.2609668
11.94217	139.9358	0.2870333
11.99384	139.9370	0.3150328
12.04717	139.9389	0.3420856
12.09717	139.9401	0.3716278
12.15050	139.9414	0.4025276
12.20050	139.9428	0.4335203
12.25384	139.9446	0.4674604
12.30550	139.9468	0.5009738
12.35717	139.9481	0.5388602
12.41050	139.9502	0.5792950
12.46050	139.9520	0.6218850
12.51383	139.9542	0.6700572
12.56383	139.9570	0.7179784
12.61716	139.9593	0.7759370
12.66883	139.9620	0.8380762
12.72050	139.9662	0.9045958
12.77383	139.9679	0.9853000
12.82384	139.9725	1.065866
12.87717	139.9782	1.153224
12.92883	139.9823	1.251834
12.98050	139.9875	1.353549
13.03383	139.9930	1.468914
13.08383	139.9980	1.578080
13.13717	140.0052	1.704824
13.18716	140.0111	1.823368
13.24050	140.0177	1.953267
13.29216	140.0246	2.081289
13.34383	140.0312	2.210710
13.39717	140.0378	2.337572
13.44717	140.0438	2.458134
13.50050	140.0506	2.585247
13.55217	140.0572	2.704309
13.60383	140.0623	2.817997
13.65550	140.0684	2.930572
13.70717	140.0738	3.034646
13.76050	140.0801	3.138533
13.81050	140.0838	3.235942
13.86383	140.0896	3.330817
13.91550	140.0939	3.416744
13.96716	140.0979	3.504075
14.02050	140.1022	3.587214
14.07050	140.1065	3.660796
14.12384	140.1105	3.739778
14.17383	140.1136	3.808930
14.22717	140.1177	3.880335
14.27883	140.1214	3.947360
14.33050	140.1244	4.014854
14.38383	140.1281	4.080115
14.43383	140.1306	4.140290
14.48716	140.1349	4.204004
14.53883	140.1371	4.264564
14.59050	140.1406	4.324854
14.64216	140.1434	4.386322
14.69384	140.1464	4.444734
14.74717	140.1502	4.508970
14.79717	140.1532	4.566313
14.85050	140.1560	4.628516
14.90217	140.1597	4.691842
14.95383	140.1627	4.754512
15.00717	140.1658	4.822150
15.05717	140.1686	4.883724
15.11050	140.1727	4.952040
15.16050	140.1762	5.015207
15.21383	140.1796	5.087020
15.26550	140.1822	5.157480
15.31716	140.1864	5.226383
15.37050	140.1898	5.301453
15.42050	140.1942	5.370593
15.47383	140.1966	5.450379
15.52550	140.2016	5.525860
15.57717	140.2049	5.606930
15.62883	140.2093	5.682966
15.68050	140.2137	5.762475
15.73383	140.2176	5.850011
15.78383	140.2217	5.930628
15.83717	140.2256	6.021098
15.88883	140.2310	6.110903
15.94050	140.2355	6.199897
15.99383	140.2401	6.295253
16.04383	140.2452	6.387631
16.09717	140.2502	6.485902
16.14716	140.2547	6.579388
16.20050	140.2598	6.686424
16.25217	140.2660	6.788282
16.30383	140.2716	6.894786
16.35716	140.2760	7.005234
16.40716	140.2822	7.112808
16.46050	140.2880	7.229364
16.51216	140.2938	7.343320
16.56383	140.2995	7.458252
16.61550	140.3057	7.575746
16.66716	140.3111	7.699187
16.72050	140.3181	7.824856
16.77050	140.3233	7.946361
16.82383	140.3304	8.074242
16.87550	140.3367	8.203507
16.92716	140.3430	8.330152
16.98050	140.3498	8.464403
17.03050	140.3570	8.585428
17.08383	140.3625	8.723007
17.13383	140.3698	8.843957
17.18716	140.3763	8.983951
17.23883	140.3826	9.106613
17.29050	140.3896	9.239640
17.34383	140.3968	9.365931
17.39383	140.4026	9.486318
17.44716	140.4095	9.612069
17.49883	140.4164	9.736132
17.55050	140.4222	9.851620
17.60216	140.4282	9.971314
17.65383	140.4336	10.08251
17.70716	140.4396	10.19465
17.75716	140.4444	10.29336
17.81050	140.4496	10.39688
17.86216	140.4544	10.48867
17.91383	140.4584	10.57698
17.96716	140.4634	10.65905
18.01716	140.4661	10.72801
18.07050	140.4708	10.81315
18.12050	140.4736	10.86762
18.17383	140.4766	10.91803
18.22550	140.4786	10.95883
18.27716	140.4806	10.99087
18.33050	140.4827	11.03178
18.38050	140.4832	11.03120
18.43383	140.4835	11.03156
18.48550	140.4843	11.03200
18.53717	140.4838	11.03246
18.59050	140.4832	11.03159
18.64050	140.4825	11.02790
18.69383	140.4822	11.01570
18.74383	140.4814	10.99561
18.79716	140.4788	10.96388
18.84883	140.4775	10.92058
18.90050	140.4756	10.87826
18.95383	140.4730	10.83366
19.00383	140.4711	10.78651
19.05716	140.4678	10.73358
19.10716	140.4651	10.68196
19.16050	140.4629	10.62198
19.21216	140.4589	10.56159
19.26383	140.4574	10.49793
19.31716	140.4528	10.42884
19.36716	140.4496	10.36453
19.42050	140.4466	10.29056
19.47216	140.4432	10.22116
19.52383	140.4393	10.14700
19.57716	140.4353	10.06962
19.62716	140.4324	9.996499
19.68050	140.4284	9.918671
19.73050	140.4241	9.847042
19.78383	140.4210	9.765921
19.83550	140.4171	9.686641
19.88716	140.4131	9.608410
19.94050	140.4087	9.528515
19.99050	140.4049	9.451095
20.04383	140.4006	9.368978
20.09550	140.3969	9.290606
20.14716	140.3931	9.212824
20.19884	140.3884	9.135606
20.25050	140.3851	9.058678
20.30383	140.3800	8.982901
20.35383	140.3766	8.907648
20.40716	140.3731	8.829584
20.45883	140.3692	8.756485
20.51050	140.3654	8.681482
20.56383	140.3622	8.608026
20.61383	140.3580	8.538262
20.66716	140.3551	8.465259
20.71716	140.3513	8.399954
20.77050	140.3478	8.329188
20.82216	140.3446	8.263297
20.87383	140.3411	8.199955
20.92717	140.3382	8.129974
20.97716	140.3353	8.070116
21.03050	140.3316	8.005207
21.08216	140.3283	7.945320
21.13383	140.3258	7.885686
21.18550	140.3224	7.826084
21.23716	140.3196	7.768614
21.29050	140.3166	7.712631
21.34050	140.3137	7.658634
21.39383	140.3106	7.602593
21.44550	140.3081	7.550512
21.49716	140.3054	7.497182
21.55050	140.3032	7.447150
21.60050	140.3004	7.394342
21.65383	140.2978	7.342665
21.70383	140.2953	7.295330
21.75716	140.2929	7.244116
21.80883	140.2905	7.197391
21.86050	140.2878	7.148522
21.91383	140.2858	7.097989
21.96383	140.2839	7.053424
22.01716	140.2816	7.008428
22.06883	140.2791	6.963574
22.12050	140.2761	6.919042
22.17216	140.2744	6.874656
22.22383	140.2720	6.830556
22.27717	140.2698	6.786663
22.32716	140.2675	6.743530
22.38050	140.2653	6.702130
22.43216	140.2634	6.660554
22.48383	140.2605	6.619576
22.53717	140.2590	6.575062
22.58716	140.2573	6.534174
22.64050	140.2543	6.491592
22.69050	140.2527	6.451105
22.74383	140.2505	6.407299
22.79550	140.2481	6.365522
22.84716	140.2458	6.324014
22.90050	140.2433	6.279638
22.95050	140.2421	6.239332
23.00383	140.2398	6.194714
23.05550	140.2369	6.153106
23.10716	140.2345	6.109282
23.15883	140.2331	6.066784
23.21050	140.2296	6.026118
23.26383	140.2281	5.980282
23.31383	140.2260	5.938463
23.36716	140.2236	5.895232
23.41883	140.2217	5.848818
23.47050	140.2197	5.805744
23.52383	140.2181	5.758965
23.57383	140.2147	5.717644
23.62716	140.2133	5.670390
23.67717	140.2110	5.628004
23.73050	140.2087	5.579462
23.78216	140.2062	5.532638
23.83383	140.2041	5.487884
23.88716	140.2021	5.437882
23.93716	140.1988	5.391826
23.99050	140.1968	5.341709
24.04216	140.1948	5.293571
24.09383	140.1924	5.245040
24.14550	140.1897	5.195732
24.19716	140.1875	5.144737
24.25050	140.1844	5.093019
24.30050	140.1823	5.043338
24.35383	140.1797	4.989562
24.40550	140.1768	4.939160
24.45717	140.1738	4.884699
24.51050	140.1716	4.829728
24.56050	140.1689	4.774148
24.61383	140.1652	4.718860
24.66383	140.1632	4.664480
24.71716	140.1603	4.607480
24.76883	140.1572	4.548847
24.82050	140.1543	4.490204
24.87383	140.1508	4.430413
24.92383	140.1480	4.374594
24.97716	140.1454	4.312171
25.02883	140.1423	4.250914
25.08050	140.1395	4.187527
25.13383	140.1362	4.121315
25.18383	140.1324	4.064030
25.23716	140.1294	3.994676
25.28717	140.1256	3.932258
25.34050	140.1228	3.861386
25.39216	140.1191	3.793297
25.44383	140.1153	3.724114
25.49716	140.1114	3.652540
25.54716	140.1082	3.582338
25.60050	140.1046	3.508750
25.65050	140.1013	3.436704
25.70383	140.0965	3.360726
25.75550	140.0934	3.288309
25.80716	140.0895	3.210834
25.86050	140.0860	3.132350
25.91050	140.0820	3.057186
25.96383	140.0776	2.976906
26.01550	140.0738	2.898487
26.06716	140.0694	2.816047
26.12050	140.0659	2.734101
26.17050	140.0617	2.653402
26.22383	140.0576	2.568190
26.27383	140.0530	2.486679
26.32717	140.0491	2.401677
26.37883	140.0453	2.316532
26.43050	140.0408	2.234738
26.48383	140.0363	2.143197
26.53383	140.0322	2.062035
26.58716	140.0272	1.976494
26.63883	140.0227	1.890970
26.69050	140.0179	1.804874
26.74216	140.0138	1.719383
26.79383	140.0102	1.634710
26.84716	140.0042	1.547242
26.89716	140.0008	1.465107
26.95050	139.9967	1.375331
27.00217	139.9930	1.293029
27.05383	139.9879	1.209059
27.10716	139.9842	1.125434
27.15716	139.9807	1.046475
27.21050	139.9767	0.9665106
27.26050	139.9727	0.8900753
27.31383	139.9684	0.8094714
27.36550	139.9652	0.7360428
27.41716	139.9622	0.6599526
27.47050	139.9577	0.5831145
27.52050	139.9548	0.5148320
27.57383	139.9510	0.4444107
27.62550	139.9477	0.3827141
27.67717	139.9440	0.3161280
27.72883	139.9409	0.2525915
27.78050	139.9366	0.1930026
27.83383	139.9342	0.1293996
27.88383	139.9308	0.07419092
27.93717	139.9280	0.01680602
27.98883	139.9250	-.03744250
28.04050	139.9226	-.09206820
28.09383	139.9190	-0.1440290
28.14383	139.9174	-0.1937504
28.19717	139.9142	-0.2413546
28.24716	139.9116	-0.2877996
28.30050	139.9092	-0.3343060
28.35217	139.9071	-0.3783385
28.40383	139.9045	-0.4204802
28.45716	139.9027	-0.4604078
28.50716	139.9001	-0.4977024
28.56050	139.8988	-0.5355888
28.61216	139.8968	-0.5718186
28.66383	139.8954	-0.6050872
28.71550	139.8939	-0.6382404
28.76716	139.8914	-0.6701622
28.82050	139.8904	-0.7005863
28.87050	139.8892	-0.7309032
28.92383	139.8882	-0.7612626
28.97550	139.8864	-0.7871382
29.02717	139.8861	-0.8146606
29.08050	139.8844	-0.8381638
29.13050	139.8833	-0.8602348
29.18383	139.8826	-0.8828039
29.23383	139.8808	-0.9032028
29.28717	139.8797	-0.9212225
29.33883	139.8780	-0.9401898
29.39050	139.8764	-0.9587012
29.44383	139.8762	-0.9765394
29.49383	139.8746	-0.9934234
29.54716	139.8741	-1.009500
29.59883	139.8727	-1.024075
29.65050	139.8723	-1.037464
29.70217	139.8713	-1.052647
29.75383	139.8707	-1.067291
29.80716	139.8702	-1.080185
29.85716	139.8694	-1.093079
29.91050	139.8683	-1.106366
29.96216	139.8686	-1.118598
30.01383	139.8679	-1.129149
30.06716	139.8674	-1.141746
30.11716	139.8671	-1.152178
30.17050	139.8662	-1.163016
30.22050	139.8650	-1.172896
30.27383	139.8650	-1.183502
30.32550	139.8646	-1.193463
30.37716	139.8634	-1.203047
30.43050	139.8636	-1.213379
30.48050	139.8626	-1.222230
30.53383	139.8631	-1.231297
30.58550	139.8625	-1.239806
30.63716	139.8622	-1.247915
30.68883	139.8616	-1.255932
30.74050	139.8609	-1.263724
30.79383	139.8603	-1.271632
30.84383	139.8591	-1.278619
30.89716	139.8600	-1.285924
30.94883	139.8598	-1.292908
31.00050	139.8599	-1.299669
31.05383	139.8590	-1.306392
31.10383	139.8590	-1.312636
31.15716	139.8586	-1.318842
31.20716	139.8579	-1.324360
31.26050	139.8582	-1.330264
31.31217	139.8577	-1.335715
31.36383	139.8578	-1.340901
31.41716	139.8577	-1.346458
31.46716	139.8576	-1.351259
31.52050	139.8568	-1.356122
31.57217	139.8572	-1.360650
31.62383	139.8563	-1.365154
31.67717	139.8559	-1.369366
31.72717	139.8566	-1.373596
31.78050	139.8563	-1.377679
31.83050	139.8557	-1.381487
31.88383	139.8552	-1.385223
31.93550	139.8556	-1.388886
31.98717	139.8555	-1.392504
32.04050	139.8551	-1.396117
32.09050	139.8555	-1.399622
32.14383	139.8555	-1.403123
32.19383	139.8552	-1.406554
32.24716	139.8561	-1.410131
32.29883	139.8551	-1.413291
32.35050	139.8549	-1.416402
32.40383	139.8556	-1.419444
32.45383	139.8548	-1.422084
32.50716	139.8548	-1.424386
32.55883	139.8548	-1.426248
32.61050	139.8544	-1.428261
32.66383	139.8534	-1.430228
32.71383	139.8542	-1.432009
32.76716	139.8532	-1.434178
32.81716	139.8537	-1.436006
32.87050	139.8534	-1.437959
32.92216	139.8531	-1.440045
32.97383	139.8535	-1.442174
33.02716	139.8524	-1.444208
33.07717	139.8528	-1.446190
33.13050	139.8530	-1.448045
33.18216	139.8527	-1.449945
33.23383	139.8518	-1.452032
33.28550	139.8528	-1.454049
33.33716	139.8527	-1.455773
33.39050	139.8531	-1.457452
33.44050	139.8519	-1.458911
33.49383	139.8524	-1.460418
33.54550	139.8525	-1.462248
33.59716	139.8522	-1.464220
33.65050	139.8529	-1.466170
33.70050	139.8518	-1.467884
33.75383	139.8518	-1.469479
33.80383	139.8522	-1.470968
33.85716	139.8525	-1.472586
33.90883	139.8520	-1.473951
33.96050	139.8520	-1.475249
34.01383	139.8519	-1.476528
34.06383	139.8520	-1.477714
34.11716	139.8511	-1.479034
34.16883	139.8516	-1.480173
34.22050	139.8518	-1.481303
34.27217	139.8516	-1.482371
34.32383	139.8515	-1.483442
34.37717	139.8516	-1.484710
34.42717	139.8520	-1.485912
34.48050	139.8510	-1.487058
34.53216	139.8519	-1.488219
34.58383	139.8506	-1.489372
34.63716	139.8514	-1.490355
34.68716	139.8512	-1.491386
34.74050	139.8512	-1.492356
34.79050	139.8513	-1.493104
34.84384	139.8519	-1.494154
34.89550	139.8508	-1.494918
34.94717	139.8503	-1.495661
35.00050	139.8503	-1.496502
35.05050	139.8516	-1.497216
35.10383	139.8504	-1.498222
35.15550	139.8516	-1.499167
35.20716	139.8513	-1.500224
35.25883	139.8509	-1.501094
35.31050	139.8510	-1.501716
35.36383	139.8506	-1.502495
35.41383	139.8512	-1.503132
35.46716	139.8500	-1.503896
35.51883	139.8510	-1.504520
35.57050	139.8505	-1.505427
35.62383	139.8512	-1.506255
35.67383	139.8508	-1.507164
35.72717	139.8511	-1.507922
35.77716	139.8502	-1.508669
35.83050	139.8508	-1.509399
35.88216	139.8499	-1.510080
35.93384	139.8511	-1.510556
35.98717	139.8505	-1.511393
36.03717	139.8504	-1.512093
36.09050	139.8507	-1.512958
36.14216	139.8510	-1.513899
36.19383	139.8498	-1.514513
36.24550	139.8507	-1.515090
36.29716	139.8509	-1.515694
36.35050	139.8508	-1.516205
36.40050	139.8500	-1.516468
36.45383	139.8512	-1.516725
36.50550	139.8504	-1.517106
36.55716	139.8502	-1.517624
36.61050	139.8505	-1.517998
36.66050	139.8500	-1.518418
36.71383	139.8506	-1.519005
36.76383	139.8510	-1.519448
36.81716	139.8504	-1.519756
36.86883	139.8506	-1.520048
36.92050	139.8506	-1.520306
36.97383	139.8502	-1.520548
37.02383	139.8503	-1.520813
37.07717	139.8500	-1.521299
37.12883	139.8504	-1.521942
37.18050	139.8503	-1.522601
37.23216	139.8497	-1.523212
37.28383	139.8500	-1.523815
37.33716	139.8498	-1.524351
37.38716	139.8503	-1.524881
37.44050	139.8497	-1.525363
37.49216	139.8496	-1.525728
37.54383	139.8504	-1.526212
37.59716	139.8498	-1.526507
37.64717	139.8500	-1.526839
37.70050	139.8504	-1.527462
37.75050	139.8498	-1.527892
37.80383	139.8502	-1.528242
37.85550	139.8503	-1.528554
37.90716	139.8501	-1.528837
37.96050	139.8494	-1.529373
38.01050	139.8494	-1.529688
38.06383	139.8492	-1.530152
38.11550	139.8498	-1.530477
38.16716	139.8492	-1.530878
38.22050	139.8500	-1.531468
38.27050	139.8495	-1.531920
38.32383	139.8497	-1.532354
38.37383	139.8499	-1.532912
38.42717	139.8502	-1.533390
38.47883	139.8497	-1.533700
38.53050	139.8499	-1.534258
38.58383	139.8497	-1.534617
38.63383	139.8502	-1.534708
38.68716	139.8498	-1.534843
38.73717	139.8494	-1.534637
38.79050	139.8492	-1.534476
38.84216	139.8497	-1.534404
38.89383	139.8493	-1.534391
38.94717	139.8499	-1.534786
38.99716	139.8504	-1.535377
39.05050	139.8492	-1.536011
39.10217	139.8498	-1.536530
39.15383	139.8500	-1.537034
39.20716	139.8497	-1.537374
39.25716	139.8498	-1.537554
39.31050	139.8508	-1.538041
39.36050	139.8506	-1.538327
39.41383	139.8494	-1.538382
39.46550	139.8495	-1.538390
39.51716	139.8499	-1.538285
39.57050	139.8490	-1.538337
39.62050	139.8501	-1.538417
39.67383	139.8486	-1.538487
39.72550	139.8498	-1.538673
39.77716	139.8496	-1.538737
39.82883	139.8497	-1.539099
39.88050	139.8499	-1.539393
39.93384	139.8498	-1.539831
39.98383	139.8503	-1.540280
40.03717	139.8495	-1.540683
40.08883	139.8497	-1.541141
40.14050	139.8505	-1.541908
40.19383	139.8497	-1.542650
40.24383	139.8507	-1.543278
40.29716	139.8495	-1.543923
40.34716	139.8503	-1.544219
40.40050	139.8498	-1.544370
40.45216	139.8502	-1.544396
40.50383	139.8496	-1.544215
40.55716	139.8501	-1.543972
40.60716	139.8494	-1.543531
40.66050	139.8497	-1.543289
40.71216	139.8483	-1.543166
40.76383	139.8490	-1.542978
40.81550	139.8489	-1.542962
40.86716	139.8486	-1.542982
40.92050	139.8484	-1.543086
40.97050	139.8489	-1.543381
41.02383	139.8484	-1.543926
41.07550	139.8485	-1.544423
41.12717	139.8487	-1.544874
41.18050	139.8480	-1.545440
41.23050	139.8486	-1.545883
41.28383	139.8483	-1.546338
41.33383	139.8488	-1.546628
41.38716	139.8479	-1.547031
41.43883	139.8490	-1.547290
41.49050	139.8490	-1.547634
41.54383	139.8490	-1.547891
41.59384	139.8492	-1.548163
41.64717	139.8488	-1.548548
41.69883	139.8488	-1.548711
41.75050	139.8488	-1.548986
41.80217	139.8491	-1.549417
41.85383	139.8477	-1.549610
41.90717	139.8493	-1.549768
41.95717	139.8494	-1.549991
42.01050	139.8488	-1.549950
42.06216	139.8492	-1.549834
42.11383	139.8499	-1.549990
42.16716	139.8495	-1.550177
42.21717	139.8492	-1.550591
42.27050	139.8499	-1.551118
42.32050	139.8499	-1.551525
42.37383	139.8496	-1.551832
42.42550	139.8496	-1.551968
42.47717	139.8504	-1.552173
42.53050	139.8500	-1.552136
42.58050	139.8490	-1.552044
42.63383	139.8489	-1.552019
42.68550	139.8491	-1.551909
42.73717	139.8493	-1.551677
42.78883	139.8491	-1.551566
42.84050	139.8484	-1.551544
42.89383	139.8494	-1.551358
42.94383	139.8492	-1.551358
42.99716	139.8493	-1.551386
43.04550	139.8855	-1.541635
43.09716	140.2685	-1.939332
43.15050	140.8961	-4.053200
43.20050	141.5766	-6.672278
43.25383	142.3722	-9.582559
43.30550	143.1927	-12.18859
43.35717	144.0516	-14.47136
43.41050	144.9694	-16.45880
43.46050	145.8537	-18.01749
43.51383	146.8181	-19.39754
43.56383	147.7382	-20.47053
43.61716	148.7329	-21.41554
43.66883	149.7075	-22.17662
43.72050	150.6909	-22.81098
43.77383	151.7127	-23.37412
43.82383	152.6772	-23.82108
43.87717	153.7120	-24.24425
43.92883	154.7182	-24.60056
43.98050	155.7263	-24.92272
44.03217	156.7384	-25.21434
44.08383	157.7527	-25.47938
44.13716	158.8004	-25.74369
44.18716	159.7856	-25.96950
44.24050	160.8360	-26.20211
44.29217	161.8570	-26.42189
44.34384	162.8785	-26.62920
44.39717	163.9329	-26.83528
44.44717	164.9231	-27.02959
44.50050	165.9784	-27.22690
44.55050	166.9691	-27.41485
44.60383	168.0251	-27.61311
44.65550	169.0498	-27.79716
44.70717	170.0739	-27.98544
44.76050	171.1320	-28.17967
44.81050	172.1238	-28.36459
44.86383	173.1816	-28.56856
44.91550	174.2057	-28.76121
44.96717	175.2304	-28.95466
45.01883	176.2559	-29.15005
45.07050	177.2814	-29.34763
45.12383	178.3391	-29.55803
45.17383	179.3301	-29.76303
45.22717	180.3878	-29.98467
45.27883	181.4118	-30.21422
45.33050	182.4354	-30.46009
45.38383	183.4920	-30.71734
45.43383	184.4832	-30.97209
45.48717	185.5395	-31.24780
45.53717	186.5275	-31.51190
45.59050	187.5826	-31.80848
45.64217	188.6045	-32.10955
45.69383	189.6260	-32.41865
45.74716	190.6786	-32.76856
45.79716	191.6654	-33.09892
45.85050	192.7160	-33.47020
45.90216	193.7345	-33.85230
45.95383	194.7525	-34.24560
46.00717	195.8015	-34.67688
46.05717	196.7843	-35.10726
46.11050	197.8316	-35.59524
46.16050	198.8119	-36.07814
46.21383	199.8552	-36.62989
46.26550	200.8651	-37.20396
46.31717	201.8732	-37.81884
46.37050	202.9117	-38.50897
46.42050	203.8834	-39.19822
46.47383	204.9160	-39.97766
46.52383	205.8845	-40.75519
46.57717	206.9137	-41.64594
46.62883	207.9067	-42.58963
46.68050	208.8956	-43.65578
46.73383	209.9109	-44.88954
46.78383	210.8553	-46.19600
46.83716	211.8547	-47.80191
46.88883	212.8120	-49.61047
46.94050	213.7564	-51.73282
46.99383	214.7132	-54.31230
47.04383	215.5935	-57.14446
47.09716	216.5095	-60.64800
47.14717	217.3484	-64.36738
47.20050	218.2247	-68.70740
47.25217	219.0616	-73.18286
47.30383	219.8870	-77.82351
47.35717	220.7422	-82.44089
47.40717	221.5726	-85.90087
47.46050	222.5309	-87.57056
47.51216	223.5764	-86.60866
47.56383	224.6984	-84.35222
47.61550	225.8662	-81.18285
47.66716	227.0704	-77.29174
47.72050	228.3478	-72.51882
47.77050	229.5748	-67.41062
47.82383	230.9125	-61.35512
47.87550	232.2103	-55.78852
47.92717	233.4734	-51.14941
47.98050	234.7326	-47.30333
48.03050	235.8758	-44.44318
48.08383	237.0652	-42.02106
48.13383	238.1567	-40.24232
48.18716	239.3003	-38.74388
48.23883	240.3933	-37.61176
48.29050	241.4736	-36.71970
48.34384	242.5783	-36.00962
48.39383	243.6075	-35.48928
48.44717	244.6992	-35.05093
48.49883	245.7508	-34.72654
48.55050	246.7992	-34.46967
48.60217	247.8456	-34.27484
48.65383	248.8885	-34.12298
48.70717	249.9632	-34.00848
48.75717	250.9705	-33.93293
48.81050	252.0436	-33.87560
48.86217	253.0811	-33.83711
48.91383	254.1190	-33.81662
48.96717	255.1887	-33.80484
49.01717	256.1914	-33.80098
49.07050	257.2608	-33.80105
49.12050	258.2620	-33.80816
49.17383	259.3295	-33.84388
49.22550	260.3637	-33.90916
49.27716	261.3976	-33.97029
49.33050	262.4635	-34.03317
49.38050	263.4636	-34.11050
49.43383	264.5302	-34.17987
49.48550	265.5628	-34.24728
49.53717	266.5956	-34.31730
49.58883	267.6296	-34.37394
49.64050	268.6626	-34.43560
49.69383	269.7299	-34.49695
49.74383	270.7299	-34.54195
49.79716	271.7967	-34.58401
49.84883	272.8295	-34.63290
49.90050	273.8636	-34.68118
49.95383	274.9297	-34.73156
50.00050	275.8628	-34.78490
50.05383	276.7894	-34.79154
50.10550	276.9376	-31.92082
50.15717	276.7356	-25.43990
50.21050	276.3184	-17.76915
50.26050	275.8041	-10.89042
50.31383	275.1540	-4.443773
50.36550	274.4462	0.8052391
50.41716	273.6786	5.132203
50.47050	272.8360	8.775650
50.52050	272.0091	11.54646
50.57383	271.0930	13.95407
50.62383	270.2113	15.78738
50.67717	269.2482	17.38002
50.72883	268.2988	18.63550
50.78050	267.3358	19.66467
50.83383	266.3308	20.53546
50.88383	265.3788	21.21953
50.93716	264.3552	21.81968
50.98883	263.3579	22.30228
51.04050	262.3549	22.70354
51.09217	261.3484	23.03946
51.14383	260.3385	23.33031
51.19717	259.2930	23.57532
51.24717	258.3107	23.77062
51.30050	257.2600	23.95652
51.35217	256.2402	24.10666
51.40383	255.2195	24.23228
51.45717	254.1647	24.34793
51.50717	253.1742	24.44494
51.56050	252.1182	24.53144
51.61050	251.1258	24.60120
51.66383	250.0670	24.66304
51.71550	249.0413	24.72415
51.76716	248.0142	24.77146
51.82050	246.9539	24.81672
51.87050	245.9596	24.84522
51.92383	244.8992	24.87264
51.97550	243.8720	24.89742
52.02717	242.8440	24.91431
52.07883	241.8156	24.93008
52.13050	240.7868	24.93906
52.18383	239.7242	24.95094
52.23383	238.7298	24.96256
52.28716	237.6672	24.97626
52.33883	236.6398	24.98923
52.39050	235.6100	25.00367
52.44384	234.5480	25.01397
52.49382	233.5524	25.02282
52.54717	232.4901	25.03110
52.59716	231.4940	25.03782
52.65050	230.4316	25.04462
52.70216	229.4026	25.05108
52.75383	228.3746	25.05684
52.80717	227.3108	25.06611
52.85717	226.3143	25.07408
52.91050	225.2519	25.08180
52.96216	224.2225	25.09060
53.01382	223.1921	25.09759
53.06550	222.1627	25.10387
53.11716	221.1327	25.10940
53.17050	220.0698	25.11432
53.22050	219.0731	25.11892
53.27383	218.0092	25.12368
53.32550	216.9792	25.12703
53.37717	215.9493	25.12925
53.43050	214.8860	25.13086
53.48050	213.8897	25.13123
53.53383	212.8261	25.13061
53.58383	211.8292	25.12953
53.63716	210.7661	25.12819
53.68882	209.7359	25.12650
53.74050	208.7059	25.12464
53.79382	207.6419	25.12186
53.84384	206.6450	25.11924
53.89717	205.5813	25.11578
53.94883	204.5510	25.11115
54.00050	203.5200	25.10610
54.05217	202.4906	25.10000
54.10383	201.4601	25.09280
54.15717	200.3970	25.08546
54.20717	199.3998	25.07872
54.26050	198.3366	25.07263
54.31216	197.3066	25.06758
54.36382	196.2756	25.06242
54.41716	195.2133	25.05774
54.46717	194.2158	25.05426
54.52050	193.1537	25.05178
54.57050	192.1545	25.04920
54.62383	191.0925	25.04598
54.67550	190.0612	25.04332
54.72717	189.0308	25.03950
54.78050	187.9659	25.03518
54.83050	186.9699	25.03016
54.88383	185.9056	25.02494
54.93550	184.8753	25.01976
54.98717	183.8449	25.01306
55.03882	182.8142	25.00572
55.09050	181.7826	24.99878
55.14384	180.7199	24.99090
55.19384	179.7215	24.98378
55.24717	178.6590	24.97745
55.29883	177.6280	24.97274
55.35050	176.5980	24.96980
55.40383	175.5344	24.96797
55.45383	174.5372	24.96779
55.50717	173.4730	24.96869
55.55717	172.4753	24.96943
55.61050	171.4112	24.96836
55.66216	170.3803	24.96653
55.71382	169.3501	24.96474
55.76716	168.2863	24.96446
55.81716	167.2906	24.97507
55.87050	166.2301	25.07907
55.92217	165.2085	25.31208
55.97382	164.1979	25.83512
56.02717	163.1794	27.00576
56.07717	162.2681	29.08368
56.13050	161.3581	32.72629
56.18050	160.5734	37.52295
56.23383	159.7978	43.65706
56.28550	159.0684	49.74300
56.33716	158.3180	55.09606
56.39050	157.4854	59.18796
56.44050	156.6295	61.44082
56.49382	155.6332	62.13215
56.54382	154.6248	61.30176
56.59716	153.4789	59.15665
56.64883	152.3180	56.18882
56.70050	151.1280	52.78700
56.75383	149.8867	49.20463
56.80383	148.7290	45.99322
56.85717	147.4870	41.37555
56.90883	146.2701	38.87598
56.96050	145.1264	36.77812
57.01382	143.9661	34.94516
57.06382	142.8916	33.47051
57.11716	141.7566	32.13364
57.16716	140.7026	31.06762
57.22050	139.5867	30.09093
57.27217	138.5133	29.28247
57.32383	137.4460	28.58922
57.37717	136.3507	27.97275
57.42717	135.3265	27.46954
57.48050	134.2378	26.99569
57.53217	133.1867	26.59111
57.58383	132.1368	26.23392
57.63550	131.0898	25.91714
57.68716	130.0445	25.63134
57.74050	128.9670	25.37139
57.79050	127.9584	25.14780
57.84384	126.8824	24.92510
57.89550	125.8408	24.72578
57.94717	124.8018	24.53837
58.00050	123.7277	24.35505
58.05050	122.7231	24.19432
58.10383	121.6506	24.03740
58.15383	120.6465	23.88435
58.20717	119.5742	23.72394
58.25883	118.5370	23.59956
58.31050	117.4996	23.48016
58.36382	116.4293	23.36774
58.41382	115.4264	23.25455
58.46717	114.3565	23.13393
58.51884	113.3188	23.02537
58.57050	112.2835	22.92322
58.62217	111.2468	22.82583
58.67383	110.2107	22.72520
58.72717	109.1419	22.62383
58.77717	108.1389	22.53616
58.83050	107.0696	22.43196
58.88217	106.0341	22.34054
58.93383	104.9984	22.24699
58.98717	103.9294	22.15055
59.03716	102.9279	22.06662
59.09050	101.8588	21.98516
59.14050	100.8584	21.90361
59.19384	99.78769	21.81090
59.24550	98.75324	21.73242
59.29717	97.71831	21.65924
59.35050	96.64942	21.58016
59.40050	95.64790	21.47358
59.45383	94.57997	21.38400
59.50550	93.54530	21.31152
59.55717	92.50992	21.23436
59.60883	91.47501	21.14060
59.66050	90.43922	21.07351
59.71382	89.37308	20.99662
59.76382	88.37212	20.92085
59.81716	87.30348	20.82876
59.86882	86.26875	20.76049
59.92050	85.23575	20.68954
59.97382	84.16728	20.60736
60.02383	83.16582	20.53407
60.07717	82.09797	20.45229
60.12717	81.09619	20.37915
60.18050	80.02782	20.30938
60.23217	78.99282	20.23614
60.28383	77.95810	20.15635
60.33716	76.89038	20.07962
60.38716	75.88934	20.00868
60.44050	74.82055	19.93873
60.49216	73.78612	19.86976
60.54382	72.75156	19.80280
60.59550	71.71699	19.72811
60.64717	70.68198	19.65474
60.70050	69.61440	19.58602
60.75050	68.61288	19.51898
60.80383	67.54382	19.44241
60.85550	66.50988	19.36439
60.90717	65.47490	19.29202
60.96050	64.40622	19.21754
61.01050	63.40459	19.14951
61.06382	62.33648	19.06417
61.11382	61.33516	18.98374
61.16716	60.26720	18.90543
61.21884	59.23194	18.83106
61.27050	58.19639	18.75067
61.32383	57.12918	18.67242
61.37383	56.12792	18.59847
61.42717	55.06100	18.52130
61.47883	54.02424	18.45252
61.53050	52.98987	18.37213
61.58217	51.95369	18.29854
61.63383	50.91998	18.22122
61.68716	49.85167	18.14221
61.73717	48.84989	18.06968
61.79050	47.78130	17.99298
61.84217	46.74734	17.92504
61.89384	45.71209	17.85658
61.94717	44.64478	17.78656
61.99717	43.64154	17.72492
62.05050	42.57320	17.65558
62.10050	41.57123	17.58812
62.15383	40.50215	17.50015
62.20550	39.46667	17.43055
62.25717	38.43319	17.34920
62.31050	37.36383	17.26386
62.36050	36.36261	17.18469
62.41382	35.29334	17.09778
62.46550	34.25724	17.01418
62.51716	33.22141	16.92972
62.57050	32.15236	16.84539
62.62050	31.15089	16.75756
62.67383	30.08094	16.67003
62.72382	29.07916	16.59306
62.77717	28.00903	16.50242
62.82883	26.97307	16.41212
62.88050	25.93582	16.32004
62.93383	24.86618	16.22366
62.98383	23.86360	16.12620
63.03383	22.88524	16.08140
63.08550	22.50884	17.37678
63.13716	22.71753	16.20796
63.19050	23.12975	13.26360
63.24050	23.65116	9.845053
63.29382	24.30170	6.162574
63.34550	25.00738	2.869504
63.39717	25.77056	-.03295768
63.45050	26.60852	-2.589585
63.50050	27.42866	-4.616188
63.55383	28.33618	-6.419970
63.60383	29.21120	-7.833901
63.65717	30.16754	-9.092541
63.70883	31.10904	-10.10772
63.76050	32.06357	-10.96547
63.81382	33.06241	-11.70938
63.86384	34.00760	-12.30486
63.91716	35.02356	-12.84451
63.96884	36.01438	-13.28880
64.02050	37.01045	-13.67843
64.07218	38.01130	-14.02345
64.12383	39.01578	-14.32594
64.17718	40.05794	-14.59379
64.22718	41.03639	-14.82274
64.28050	42.08329	-15.04190
64.33217	43.09900	-15.22980
64.38384	44.11670	-15.40509
64.43717	45.16907	-15.56614
64.48717	46.15779	-15.70666
64.54050	47.21281	-15.84850
64.59050	48.20344	-15.97145
64.64384	49.26174	-16.10120
64.69550	50.28526	-16.21597
64.74717	51.31137	-16.33113
64.80050	52.37164	-16.44508
64.85050	53.36338	-16.54264
64.90384	54.42448	-16.65114
64.95550	55.45088	-16.74913
65.00718	56.47998	-16.84639
65.05884	57.50816	-16.94809
65.11050	58.53591	-17.04305
65.16382	59.59912	-17.14108
65.21384	60.59432	-17.23706
65.26716	61.65676	-17.33354
65.31884	62.68662	-17.42931
65.37050	63.71565	-17.52560
65.42383	64.77848	-17.61738
65.47384	65.77595	-17.70161
65.52717	66.83908	-17.79703
65.57718	67.83594	-17.88896
65.63050	68.89982	-17.98152
65.68218	69.92894	-18.06774
65.73384	70.95962	-18.15883
65.78718	72.02197	-18.25099
65.83716	73.01913	-18.33872
65.89050	74.08316	-18.43484
65.94218	75.11382	-18.52534
65.99384	76.14405	-18.61556
66.04550	77.17468	-18.70679
66.09718	78.20534	-18.79873
66.15050	79.26796	-18.89359
66.20050	80.26576	-18.98687
66.25384	81.32925	-19.08324
66.30550	82.35989	-19.18026
66.35718	83.39038	-19.27541
66.41050	84.45359	-19.37604
66.46050	85.45080	-19.46895
66.51384	86.51364	-19.57364
66.56384	87.51078	-19.67275
66.61718	88.57405	-19.77710
66.66884	89.60482	-19.87653
66.72050	90.63494	-19.98433
66.77384	91.69902	-20.08835
66.82384	92.69634	-20.18810
66.87718	93.75988	-20.28955
66.92884	94.79088	-20.39232
66.98050	95.82182	-20.49102
67.03218	96.85172	-20.59532
67.08384	97.88170	-20.69335
67.13718	98.94586	-20.79669
67.18718	99.94264	-20.89147
67.24050	101.0062	-20.99345
67.29218	102.0350	-21.10006
67.34384	103.0662	-21.20837
67.39718	104.1290	-21.31949
67.44718	105.1263	-21.42363
67.50050	106.1892	-21.53676
67.55050	107.1859	-21.64428
67.60384	108.2492	-21.76305
67.65550	109.2774	-21.86951
67.70718	110.3069	-21.98832
67.76050	111.3699	-22.11212
67.81050	112.3655	-22.22277
67.86384	113.4290	-22.34556
67.91550	114.4593	-22.46485
67.96718	115.4880	-22.58330
68.02050	116.5507	-22.72406
68.07050	117.5469	-22.83047
68.12384	118.6108	-22.94713
68.17384	119.6060	-23.05182
68.22718	120.6691	-23.19112
68.27884	121.6976	-23.32003
68.33050	122.7265	-23.44902
68.38384	123.7895	-23.58440
68.43384	124.7854	-23.71620
68.48718	125.8479	-23.85776
68.53718	126.8431	-23.98831
68.59050	127.9061	-24.11494
68.64216	128.9344	-24.25266
68.69384	129.9641	-24.38883
68.74718	131.0258	-24.52223
68.79718	132.0216	-24.65558
68.85050	133.0834	-24.79821
68.90218	134.1127	-24.93513
68.95384	135.1418	-25.08326
69.00718	136.2036	-25.23722
69.05718	137.1990	-25.37739
69.11050	138.2601	-25.53070
69.16050	139.2558	-25.68447
69.21384	140.3162	-25.83572
69.26550	141.3456	-25.98955
69.31718	142.3737	-26.14545
69.37050	143.4356	-26.30963
69.42050	144.4286	-26.46463
69.47384	145.4903	-26.63575
69.52550	146.5179	-26.78662
69.57718	147.5458	-26.96072
69.62884	148.5734	-27.12409
69.68050	149.6006	-27.28592
69.73384	150.6610	-27.46172
69.78384	151.6561	-27.61688
69.83716	152.7157	-27.79604
69.88884	153.7434	-27.96020
69.94050	154.7705	-28.13570
69.99384	155.8316	-28.31170
70.04384	156.8256	-28.49459
70.09718	157.8866	-28.66312
70.14718	158.8820	-28.84577
70.20050	159.9410	-29.03060
70.25218	160.9695	-29.19030
70.30384	161.9974	-29.37158
70.35718	163.0598	-29.51294
70.40718	164.0609	-29.51798
70.46050	165.1224	-29.69255
70.51218	166.1534	-29.82034
70.56384	167.1839	-29.90803
70.61550	168.2173	-29.97942
70.66718	169.2481	-30.06882
70.72050	170.3150	-30.13968
70.77050	171.3144	-30.16810
70.82384	172.3801	-30.28426
70.87550	173.4130	-30.31400
70.92718	174.4431	-30.44344
70.98050	175.5086	-30.50383
71.03050	176.5055	-30.65548
71.08384	177.5687	-30.75635
71.13384	178.5634	-30.93295
71.18718	179.6244	-31.07234
71.23882	180.6511	-31.29345
71.29050	181.6795	-31.46975
71.34384	182.7353	-31.73244
71.39384	183.7278	-31.98828
71.44718	184.7832	-32.25936
71.49884	185.8037	-32.61784
71.55050	186.8252	-32.92472
71.60218	187.8419	-33.33609
71.65384	188.8594	-33.76082
71.70718	189.9039	-34.24817
71.75718	190.8824	-34.83218
71.81050	191.9242	-35.42601
71.86218	192.9274	-36.13882
71.91382	193.9320	-36.82961
71.96718	194.9640	-37.61504
72.01716	195.9322	-38.40786
72.07050	196.9634	-39.18512
72.12050	197.9288	-40.04084
72.17384	198.9582	-40.85832
72.22551	199.9528	-41.79352
72.27718	200.9478	-42.72100
72.33050	201.9668	-43.80248
72.38050	202.9228	-44.88088
72.43384	203.9353	-46.06988
72.48550	204.9163	-47.34054
72.53718	205.8963	-48.49114
72.58884	206.8802	-49.65713
72.64050	207.8730	-50.46374
72.69384	208.9142	-50.91691
72.74384	209.9228	-50.57465
72.79718	211.0412	-49.15774
72.84882	212.1657	-47.05680
72.90050	213.3164	-44.43744
72.95384	214.5106	-41.72964
73.00384	215.6250	-39.46924
73.05718	216.7944	-37.43286
73.10718	217.8730	-35.95991
73.16050	219.0098	-34.60590
73.21218	220.0946	-33.58960
73.26384	221.1702	-32.84409
73.31718	222.2730	-32.15992
73.36718	223.2982	-31.69804
73.42050	224.3878	-31.32969
73.47218	225.4387	-31.01472
73.52384	226.4841	-30.82392
73.57550	227.5291	-30.68154
73.62718	228.5711	-30.52110
73.68050	229.6425	-30.50570
73.73050	230.6483	-30.42992
73.78384	231.7186	-30.43238
73.83550	232.7539	-30.45552
73.88718	233.7890	-30.49213
73.94050	234.8558	-30.56895
73.99050	235.8549	-30.69060
74.04384	236.9218	-30.69768
74.09384	237.9184	-30.82604
74.14718	238.9848	-30.90857
74.19884	240.0160	-30.99391
74.25050	241.0467	-31.12172
74.30384	242.1126	-31.16648
74.35384	243.1148	-31.16010
74.40718	244.1855	-31.15869
74.45884	245.2211	-31.15892
74.51050	246.2570	-31.16121
74.56384	247.3252	-31.17248
74.61384	248.3262	-31.18916
74.66718	249.3944	-31.21410
74.71718	250.3956	-31.25233
74.77050	251.4625	-31.29762
74.82218	252.4964	-31.34160
74.87384	253.5296	-31.38522
74.92718	254.5970	-31.42787
74.97718	255.5963	-31.47014
75.03050	256.6650	-31.53200
75.08050	257.6646	-31.58545
75.13384	258.7314	-31.63404
75.18550	259.7648	-31.68827
75.23718	260.7982	-31.74875
75.29050	261.8637	-31.80450
75.34050	262.8636	-31.86490
75.39384	263.9307	-31.92578
75.44550	264.9631	-31.98510
75.49718	265.9971	-32.04756
75.55050	267.0639	-32.10912
75.60050	268.0632	-32.16540
75.65384	269.1290	-32.22722
75.70384	270.1280	-32.29096
75.75718	271.1940	-32.35290
75.80884	272.2268	-32.41626
-2.000000	5.000000	0.0000000