File: 4-C1(1.2mol%)+C20(0.6mol%)/matlab/140-2
CLOSED
Version	1.0
Language	English
Mode	Standard
Run	2
RunSerial	11867
Instrument	DSC Q2000 V24.11 Build 124
Module	DSC Standard Cell RC
Operator	Jing
File	\\Ae520-1454\ta\Data\DSC\UQ Composites\Nan\C1(6.5)+C20P(3)+CL(Hotplate MixtureAB) New\140-2
ProcName	Ramp
InstSerial	2000-0883
AutoSerial	1293
Sample	Iso140-2
Size	38.8000	mg
PanMass	Not available
PanResist	Automatic Automatic  K/W
PanFactor	Default Default
Method	Ramp
Comment
Xcomment	Pan: Tzero Aluminum Hermetic
Xcomment	Gas1: Nitrogen 50.0 ml/min
Xcomment	Gas2: Nitrogen 50.0 ml/min
Text
Exotherm	UP
Kcell	1.05230
Cpconst	Standard: 0.938
Calib	-38.6961
TempCal	1	pts	157.46	156.60
TzeroDt	-87.6168 -0.0009 -1.4231
TzeroDtz	-87.6168 0.0057 6.9570
InstCalFile	Tzero: \\Ae520-1454\ta\Data\DSC\Calibration\2017\CALIBRATION\1562_RCS (90)_05_18_2017 10_50_44.TZR
InstCalFile	Baseline: \\Ae520-1454\ta\Data\DSC\Calibration\2017\2017-05-17_Calibration.001
InstCalFile	Sapphire: \\Ae520-1454\ta\Data\DSC\Calibration\2017\2017-05-17_Saphire.001
InstCalDate	Tzero 2017-05-18 Time 10:50:44
TempRange	-87.39 to 398.39 °C at 10.00 °C/min Heat Only
AutoZero	Delta T Offset 0.000 uV
AutoZero	Delta T0 Offset 0.000 uV
MultiptCal	0
MultiPtDesc	0) Not set
AutoCellConst	Calibration Date 2017-05-18 16:59:28
Controls	Gas 1  Event Off  Sampling 0.2
Cell#	RC-01562
CoolingUnit	RCS (90)
SelHeatFlow	Heat Flow T4 (mW)
AutoLidII	Installed
AutoAnalysis	Off
MacroFile
Nsig	3
Sig1	Time (min)
Sig2	Temperature (°C)
Sig3	Heat Flow (mW)
Date	2017-06-21
Time	15:05:45
OrgMethod	1: Equilibrate at 20.00 °C
OrgMethod	2: Ramp 40.00 °C/min to 140.00 °C
OrgMethod	3: Mark end of cycle 1
OrgMethod	4: Isothermal for 40.00 min
OrgMethod	5: Mark end of cycle 2
OrgMethod	6: Ramp 20.00 °C/min to 280.00 °C
OrgMethod	7: Mark end of cycle 3
OrgMethod	8: Ramp 20.00 °C/min to 20.00 °C
OrgMethod	9: Mark end of cycle 4
OrgMethod	10: Ramp 20.00 °C/min to 280.00 °C
OrgMethod	11: Mark end of cycle 5
OrgFile	C:\Users\jarra\Desktop\DSC\4-C1(1.2mol%)+C20(0.6mol%)\140-2
StartOfData
4.99994E-4	20.03052	0.3687924
0.05383332	20.14936	0.5403492
0.1055000	21.03249	0.2424759
0.1571666	22.30022	-2.546430
0.2105000	23.78976	-6.351172
0.2605000	25.31388	-10.11147
0.3138333	27.03295	-13.84575
0.3655000	28.77398	-17.02470
0.4171667	30.56979	-19.71553
0.4705000	32.47295	-22.03320
0.5205000	34.29278	-23.83308
0.5738334	36.26309	-25.43342
0.6238334	38.13318	-26.70371
0.6771668	40.14620	-27.86736
0.7288332	42.10952	-28.88631
0.7805000	44.07778	-29.96244
0.8338332	46.10914	-31.16036
0.8838332	48.02460	-31.99596
0.9371668	50.08668	-32.66806
0.9888332	52.09389	-33.32504
1.040500	54.09696	-34.16925
1.092167	56.08748	-35.29120
1.143833	58.07120	-36.53758
1.197166	60.12151	-37.73744
1.247166	62.05012	-38.81731
1.300500	64.10098	-40.22866
1.352166	66.06452	-42.23990
1.403833	67.97047	-45.59216
1.457167	69.82640	-51.55830
1.507167	71.41094	-60.16011
1.560500	72.94382	-71.92256
1.610500	74.29656	-84.01151
1.663834	75.72571	-96.66188
1.715500	77.16222	-107.8859
1.767167	78.59882	-119.8177
1.820500	80.10660	-130.8792
1.870500	81.59360	-139.9479
1.923834	83.27536	-148.4378
1.975500	84.94599	-154.3810
2.027166	86.95034	-153.1504
2.078833	89.33188	-146.2520
2.130500	91.74775	-140.6197
2.183833	94.25022	-133.6382
2.233833	96.74619	-123.3536
2.287166	99.57601	-110.5505
2.338833	102.2519	-100.2337
2.390500	104.8271	-91.70700
2.443833	107.3896	-84.58880
2.493833	109.7162	-79.18559
2.547166	112.1323	-74.57426
2.597167	114.3460	-71.12432
2.650500	116.6607	-68.23241
2.702166	118.8666	-66.06485
2.753833	121.0439	-64.44429
2.807167	123.2661	-63.23837
2.857167	125.3310	-62.42239
2.910500	127.5190	-61.80280
2.962167	129.6273	-61.36104
3.010500	131.5936	-61.11765
3.060500	133.4482	-61.24524
3.113833	134.6127	-59.72651
3.165500	135.4280	-55.07818
3.217166	136.0688	-49.50804
3.270500	136.6082	-43.71376
3.320500	137.0258	-38.75806
3.373834	137.3975	-34.16914
3.425500	137.6980	-30.40546
3.477167	137.9506	-27.25203
3.528833	138.1629	-24.62394
3.580500	138.3425	-22.44546
3.633833	138.4976	-20.57354
3.683833	138.6214	-19.11137
3.737167	138.7344	-17.80526
3.788833	138.8269	-16.74684
3.840500	138.9055	-15.84884
3.893833	138.9747	-15.07418
3.943833	139.0295	-14.45751
3.997166	139.0789	-13.89597
4.047167	139.1188	-13.44736
4.100500	139.1560	-13.04196
4.152166	139.1865	-12.70652
4.203833	139.2132	-12.41074
4.257167	139.2366	-12.15189
4.307167	139.2551	-11.94356
4.360500	139.2732	-11.74412
4.412167	139.2876	-11.57656
4.463834	139.3004	-11.42829
4.515500	139.3122	-11.29902
4.567167	139.3228	-11.17752
4.620500	139.3319	-11.06939
4.670500	139.3394	-10.97724
4.723834	139.3462	-10.89132
4.775500	139.3532	-10.80995
4.827167	139.3597	-10.73533
4.880500	139.3646	-10.65884
4.930500	139.3704	-10.59453
4.983834	139.3753	-10.52598
5.033834	139.3788	-10.46411
5.087167	139.3832	-10.39523
5.138833	139.3880	-10.33183
5.190500	139.3925	-10.27014
5.243834	139.3961	-10.20529
5.293832	139.3989	-10.14872
5.347168	139.4026	-10.08957
5.398834	139.4056	-10.03304
5.450500	139.4096	-9.979614
5.503834	139.4124	-9.921795
5.553834	139.4163	-9.867918
5.607168	139.4196	-9.809201
5.657166	139.4220	-9.750969
5.710500	139.4258	-9.690207
5.762168	139.4292	-9.624728
5.813832	139.4323	-9.560336
5.867168	139.4370	-9.490175
5.917168	139.4400	-9.417301
5.970500	139.4442	-9.343051
6.020500	139.4488	-9.268036
6.073834	139.4526	-9.186116
6.125500	139.4573	-9.103016
6.177166	139.4612	-9.017706
6.230500	139.4669	-8.928915
6.280500	139.4710	-8.839603
6.333832	139.4760	-8.742664
6.385500	139.4809	-8.643516
6.437168	139.4863	-8.541063
6.490500	139.4914	-8.432618
6.540500	139.4970	-8.329861
6.593832	139.5037	-8.217984
6.643832	139.5083	-8.108334
6.697168	139.5143	-7.991620
6.748834	139.5204	-7.877225
6.800500	139.5262	-7.763276
6.853832	139.5325	-7.642676
6.903832	139.5381	-7.529181
6.957168	139.5448	-7.411179
7.008832	139.5502	-7.298432
7.060500	139.5565	-7.187478
7.112168	139.5622	-7.071809
7.163832	139.5678	-6.955436
7.217168	139.5743	-6.830722
7.267168	139.5798	-6.713886
7.320500	139.5870	-6.586846
7.372168	139.5928	-6.466171
7.423834	139.5993	-6.341967
7.477168	139.6061	-6.209936
7.527168	139.6113	-6.087202
7.580500	139.6188	-5.958948
7.630500	139.6251	-5.838842
7.683832	139.6314	-5.711280
7.735500	139.6382	-5.582184
7.787168	139.6452	-5.456110
7.840500	139.6514	-5.331957
7.890500	139.6571	-5.212305
7.943832	139.6634	-5.088757
7.995500	139.6701	-4.963600
8.047168	139.6758	-4.846085
8.098832	139.6817	-4.723293
8.150500	139.6885	-4.606814
8.203834	139.6949	-4.486403
8.253834	139.7006	-4.369816
8.307168	139.7071	-4.247140
8.358832	139.7129	-4.125725
8.410499	139.7195	-3.995190
8.463834	139.7265	-3.856694
8.513832	139.7330	-3.722938
8.567166	139.7414	-3.571028
8.617166	139.7491	-3.421722
8.670500	139.7559	-3.254820
8.722168	139.7650	-3.091241
8.773834	139.7732	-2.922502
8.827168	139.7822	-2.744965
8.877168	139.7910	-2.589651
8.930500	139.7986	-2.427280
8.982166	139.8071	-2.277100
9.033832	139.8134	-2.141199
9.085501	139.8199	-2.018372
9.137168	139.8259	-1.909448
9.190500	139.8313	-1.803934
9.240500	139.8356	-1.714672
9.293834	139.8404	-1.634550
9.345500	139.8446	-1.564750
9.397168	139.8474	-1.499811
9.450500	139.8506	-1.441265
9.500500	139.8534	-1.398889
9.553832	139.8566	-1.351566
9.603832	139.8577	-1.312525
9.657166	139.8604	-1.277394
9.708832	139.8627	-1.246944
9.760499	139.8643	-1.215675
9.813834	139.8659	-1.189748
9.863834	139.8679	-1.165018
9.917168	139.8693	-1.141376
9.968834	139.8694	-1.117241
10.02050	139.8708	-1.098175
10.07217	139.8715	-1.078686
10.12383	139.8733	-1.062050
10.17717	139.8740	-1.044722
10.22717	139.8750	-1.030168
10.28050	139.8756	-1.013263
10.33217	139.8768	-1.000045
10.38383	139.8778	-0.9863408
10.43717	139.8788	-0.9714201
10.48717	139.8792	-0.9590455
10.54050	139.8796	-0.9454682
10.59050	139.8804	-0.9332230
10.64383	139.8810	-0.9180164
10.69550	139.8815	-0.9069691
10.74717	139.8825	-0.8947128
10.80050	139.8833	-0.8831595
10.85050	139.8842	-0.8720269
10.90383	139.8846	-0.8607547
10.95550	139.8846	-0.8491719
11.00717	139.8860	-0.8379701
11.05884	139.8864	-0.8267284
11.11050	139.8866	-0.8150352
11.16383	139.8873	-0.8022666
11.21383	139.8884	-0.7922118
11.26717	139.8881	-0.7808075
11.31883	139.8895	-0.7701075
11.37050	139.8892	-0.7584835
11.42383	139.8904	-0.7466255
11.47383	139.8903	-0.7345094
11.52717	139.8912	-0.7230000
11.57717	139.8916	-0.7125928
11.63050	139.8929	-0.7013552
11.68217	139.8931	-0.6904376
11.73383	139.8934	-0.6784592
11.78717	139.8940	-0.6664564
11.83717	139.8948	-0.6555043
11.89050	139.8954	-0.6432498
11.94217	139.8963	-0.6318305
11.99384	139.8971	-0.6201054
12.04717	139.8972	-0.6071930
12.09717	139.8978	-0.5959696
12.15050	139.8991	-0.5837930
12.20050	139.8992	-0.5725503
12.25384	139.9000	-0.5609302
12.30550	139.9006	-0.5493928
12.35717	139.9016	-0.5369529
12.41050	139.9020	-0.5252324
12.46050	139.9018	-0.5133410
12.51383	139.9029	-0.5010399
12.56383	139.9034	-0.4892843
12.61716	139.9048	-0.4760263
12.66883	139.9048	-0.4624988
12.72050	139.9061	-0.4481548
12.77383	139.9072	-0.4359791
12.82384	139.9075	-0.4234608
12.87717	139.9070	-0.4079907
12.92883	139.9083	-0.3956735
12.98050	139.9096	-0.3831434
13.03383	139.9101	-0.3676068
13.08383	139.9107	-0.3538896
13.13717	139.9116	-0.3385953
13.18716	139.9122	-0.3229565
13.24050	139.9131	-0.3047121
13.29216	139.9139	-0.2841110
13.34383	139.9154	-0.2670431
13.39717	139.9160	-0.2466930
13.44717	139.9172	-0.2247810
13.50050	139.9186	-0.2023112
13.55217	139.9196	-0.1775846
13.60383	139.9199	-0.1516281
13.65550	139.9215	-0.1253002
13.70717	139.9230	-.09407309
13.76050	139.9251	-.06387541
13.81050	139.9261	-.03067041
13.86383	139.9283	.003740196
13.91550	139.9296	0.04165011
13.96716	139.9310	0.08167553
14.02050	139.9331	0.1230861
14.07050	139.9358	0.1619267
14.12384	139.9381	0.2062211
14.17383	139.9399	0.2527704
14.22717	139.9427	0.3010192
14.27883	139.9444	0.3514242
14.33050	139.9472	0.3986007
14.38383	139.9498	0.4509350
14.43383	139.9518	0.5020088
14.48716	139.9554	0.5556606
14.53883	139.9574	0.6070437
14.59050	139.9608	0.6607993
14.64216	139.9630	0.7161812
14.69384	139.9657	0.7656839
14.74717	139.9683	0.8235556
14.79717	139.9717	0.8741528
14.85050	139.9731	0.9297278
14.90217	139.9762	0.9789254
14.95383	139.9797	1.030444
15.00717	139.9820	1.083144
15.05717	139.9837	1.131110
15.11050	139.9866	1.184743
15.16050	139.9892	1.229456
15.21383	139.9924	1.282027
15.26550	139.9946	1.327768
15.31716	139.9972	1.375071
15.37050	139.9991	1.423732
15.42050	140.0020	1.465582
15.47383	140.0037	1.511164
15.52550	140.0064	1.553927
15.57717	140.0086	1.598496
15.62883	140.0104	1.642642
15.68050	140.0124	1.681070
15.73383	140.0148	1.724667
15.78383	140.0166	1.762917
15.83717	140.0185	1.805656
15.88883	140.0211	1.843638
15.94050	140.0222	1.885669
15.99383	140.0244	1.922698
16.04383	140.0266	1.959051
16.09717	140.0291	1.996678
16.14716	140.0303	2.031023
16.20050	140.0327	2.071581
16.25217	140.0344	2.106263
16.30383	140.0362	2.141957
16.35716	140.0381	2.176680
16.40716	140.0393	2.210969
16.46050	140.0413	2.245811
16.51216	140.0438	2.280962
16.56383	140.0450	2.317187
16.61550	140.0472	2.351387
16.66716	140.0487	2.384212
16.72050	140.0499	2.421774
16.77050	140.0522	2.452640
16.82383	140.0528	2.487469
16.87550	140.0557	2.521844
16.92716	140.0574	2.554180
16.98050	140.0586	2.589692
17.03050	140.0606	2.622571
17.08383	140.0620	2.660140
17.13383	140.0636	2.690234
17.18716	140.0652	2.724164
17.23883	140.0674	2.756552
17.29050	140.0692	2.791953
17.34383	140.0714	2.826294
17.39383	140.0728	2.858795
17.44716	140.0748	2.894148
17.49883	140.0766	2.928817
17.55050	140.0777	2.965060
17.60216	140.0798	3.000838
17.65383	140.0812	3.033447
17.70716	140.0833	3.069907
17.75716	140.0850	3.104724
17.81050	140.0873	3.141006
17.86216	140.0886	3.177736
17.91383	140.0909	3.212499
17.96716	140.0925	3.248145
18.01716	140.0940	3.286424
18.07050	140.0964	3.322235
18.12050	140.0985	3.355080
18.17383	140.0994	3.392894
18.22550	140.1014	3.429869
18.27716	140.1039	3.466790
18.33050	140.1051	3.505629
18.38050	140.1075	3.542050
18.43383	140.1092	3.581944
18.48550	140.1111	3.617014
18.53717	140.1132	3.653781
18.59050	140.1144	3.693889
18.64050	140.1169	3.727515
18.69383	140.1184	3.768315
18.74383	140.1201	3.804178
18.79716	140.1223	3.846600
18.84883	140.1243	3.882788
18.90050	140.1265	3.922118
18.95383	140.1284	3.964168
19.00383	140.1302	4.002399
19.05716	140.1323	4.043472
19.10716	140.1342	4.081377
19.16050	140.1361	4.121087
19.21216	140.1390	4.161356
19.26383	140.1410	4.202774
19.31716	140.1436	4.246314
19.36716	140.1452	4.284984
19.42050	140.1480	4.328360
19.47216	140.1496	4.368671
19.52383	140.1522	4.411525
19.57716	140.1543	4.454540
19.62716	140.1568	4.497085
19.68050	140.1586	4.545166
19.73050	140.1601	4.589802
19.78383	140.1628	4.634212
19.83550	140.1654	4.679167
19.88716	140.1675	4.724228
19.94050	140.1699	4.771418
19.99050	140.1722	4.817360
20.04383	140.1741	4.866136
20.09550	140.1771	4.908842
20.14716	140.1789	4.952056
20.19884	140.1814	5.000174
20.25050	140.1839	5.046304
20.30383	140.1856	5.095035
20.35383	140.1880	5.140343
20.40716	140.1904	5.189934
20.45883	140.1930	5.237375
20.51050	140.1956	5.283114
20.56383	140.1986	5.333444
20.61383	140.1996	5.376282
20.66716	140.2034	5.425082
20.71716	140.2042	5.469184
20.77050	140.2074	5.519250
20.82216	140.2092	5.563052
20.87383	140.2118	5.607182
20.92717	140.2144	5.655070
20.97716	140.2166	5.696355
21.03050	140.2187	5.746363
21.08216	140.2210	5.788970
21.13383	140.2232	5.828922
21.18550	140.2256	5.869895
21.23716	140.2286	5.909434
21.29050	140.2306	5.952291
21.34050	140.2330	5.989088
21.39383	140.2342	6.028396
21.44550	140.2362	6.066308
21.49716	140.2380	6.104802
21.55050	140.2404	6.137778
21.60050	140.2415	6.175448
21.65383	140.2438	6.207885
21.70383	140.2449	6.232760
21.75716	140.2458	6.260999
21.80883	140.2472	6.286809
21.86050	140.2486	6.312797
21.91383	140.2498	6.337949
21.96383	140.2507	6.357604
22.01716	140.2515	6.381212
22.06883	140.2524	6.398419
22.12050	140.2531	6.414377
22.17216	140.2546	6.427237
22.22383	140.2546	6.439086
22.27717	140.2553	6.450986
22.32716	140.2563	6.458937
22.38050	140.2556	6.466586
22.43216	140.2558	6.472943
22.48383	140.2564	6.478990
22.53717	140.2574	6.484590
22.58716	140.2577	6.489135
22.64050	140.2566	6.493090
22.69050	140.2564	6.495627
22.74383	140.2575	6.496682
22.79550	140.2572	6.496244
22.84716	140.2564	6.493995
22.90050	140.2559	6.490174
22.95050	140.2552	6.484220
23.00383	140.2542	6.475350
23.05550	140.2535	6.462920
23.10716	140.2528	6.446432
23.15883	140.2519	6.425766
23.21050	140.2514	6.401443
23.26383	140.2504	6.375132
23.31383	140.2499	6.348756
23.36716	140.2472	6.318861
23.41883	140.2469	6.292312
23.47050	140.2459	6.261807
23.52383	140.2438	6.232300
23.57383	140.2424	6.202676
23.62716	140.2406	6.172342
23.67717	140.2399	6.140664
23.73050	140.2376	6.108557
23.78216	140.2355	6.075872
23.83383	140.2337	6.045088
23.88716	140.2318	6.012894
23.93716	140.2298	5.979466
23.99050	140.2287	5.942388
24.04216	140.2270	5.903695
24.09383	140.2251	5.871418
24.14550	140.2231	5.837312
24.19716	140.2219	5.800809
24.25050	140.2198	5.764058
24.30050	140.2188	5.727968
24.35383	140.2162	5.694810
24.40550	140.2152	5.661064
24.45717	140.2124	5.627124
24.51050	140.2112	5.591529
24.56050	140.2101	5.558844
24.61383	140.2070	5.522798
24.66383	140.2064	5.490010
24.71716	140.2054	5.456274
24.76883	140.2046	5.421558
24.82050	140.2032	5.388880
24.87383	140.2013	5.356658
24.92383	140.2000	5.327295
24.97716	140.1977	5.295746
25.02883	140.1961	5.266528
25.08050	140.1939	5.236975
25.13383	140.1931	5.207984
25.18383	140.1913	5.183052
25.23716	140.1887	5.156369
25.28717	140.1870	5.129818
25.34050	140.1856	5.102936
25.39216	140.1840	5.076710
25.44383	140.1826	5.049824
25.49716	140.1812	5.019572
25.54716	140.1798	4.993536
25.60050	140.1784	4.965909
25.65050	140.1774	4.940324
25.70383	140.1760	4.912868
25.75550	140.1746	4.888933
25.80716	140.1731	4.863560
25.86050	140.1719	4.836894
25.91050	140.1709	4.812822
25.96383	140.1696	4.787235
26.01550	140.1688	4.764843
26.06716	140.1674	4.742615
26.12050	140.1666	4.720235
26.17050	140.1656	4.698882
26.22383	140.1629	4.675520
26.27383	140.1634	4.656277
26.32717	140.1623	4.633355
26.37883	140.1608	4.610746
26.43050	140.1598	4.590485
26.48383	140.1590	4.568381
26.53383	140.1582	4.549574
26.58716	140.1579	4.527108
26.63883	140.1561	4.505084
26.69050	140.1545	4.487746
26.74216	140.1550	4.466000
26.79383	140.1538	4.442115
26.84716	140.1525	4.421719
26.89716	140.1511	4.402988
26.95050	140.1507	4.384170
27.00217	140.1490	4.367866
27.05383	140.1479	4.352789
27.10716	140.1469	4.335846
27.15716	140.1457	4.318902
27.21050	140.1449	4.299041
27.26050	140.1437	4.282604
27.31383	140.1432	4.261624
27.36550	140.1419	4.241387
27.41716	140.1410	4.219385
27.47050	140.1400	4.201766
27.52050	140.1399	4.182843
27.57383	140.1382	4.162864
27.62550	140.1380	4.143978
27.67717	140.1378	4.123856
27.72883	140.1354	4.104511
27.78050	140.1352	4.086331
27.83383	140.1336	4.069415
27.88383	140.1322	4.055165
27.93717	140.1321	4.038953
27.98883	140.1302	4.022266
28.04050	140.1297	4.006215
28.09383	140.1283	3.988416
28.14383	140.1273	3.971300
28.19717	140.1262	3.952052
28.24716	140.1258	3.935328
28.30050	140.1252	3.914212
28.35217	140.1236	3.899333
28.40383	140.1226	3.883690
28.45716	140.1217	3.863942
28.50716	140.1203	3.848418
28.56050	140.1202	3.829904
28.61216	140.1192	3.810685
28.66383	140.1188	3.794491
28.71550	140.1179	3.775208
28.76716	140.1168	3.758560
28.82050	140.1156	3.741177
28.87050	140.1161	3.722517
28.92383	140.1153	3.704120
28.97550	140.1147	3.684730
29.02717	140.1135	3.668953
29.08050	140.1133	3.651072
29.13050	140.1133	3.635310
29.18383	140.1111	3.620066
29.23383	140.1108	3.605355
29.28717	140.1100	3.588411
29.33883	140.1093	3.573195
29.39050	140.1081	3.557103
29.44383	140.1066	3.541006
29.49383	140.1064	3.522858
29.54716	140.1047	3.508518
29.59883	140.1037	3.493659
29.65050	140.1027	3.478219
29.70217	140.1016	3.463113
29.75383	140.1011	3.448116
29.80716	140.0999	3.430338
29.85716	140.0990	3.413617
29.91050	140.0986	3.393138
29.96216	140.0982	3.374500
30.01383	140.0983	3.355400
30.06716	140.0972	3.337534
30.11716	140.0964	3.320032
30.17050	140.0953	3.301066
30.22050	140.0950	3.284507
30.27383	140.0938	3.267210
30.32550	140.0926	3.254140
30.37716	140.0909	3.240176
30.43050	140.0901	3.222305
30.48050	140.0892	3.208670
30.53383	140.0880	3.192846
30.58550	140.0877	3.177941
30.63716	140.0864	3.160150
30.68883	140.0849	3.143117
30.74050	140.0844	3.124798
30.79383	140.0840	3.108566
30.84383	140.0828	3.090123
30.89716	140.0822	3.071910
30.94883	140.0808	3.053925
31.00050	140.0801	3.037642
31.05383	140.0792	3.018414
31.10383	140.0788	3.003072
31.15716	140.0772	2.983559
31.20716	140.0760	2.966378
31.26050	140.0762	2.943376
31.31217	140.0753	2.926445
31.36383	140.0751	2.906496
31.41716	140.0736	2.887674
31.46716	140.0734	2.870437
31.52050	140.0721	2.851459
31.57217	140.0720	2.833850
31.62383	140.0706	2.816690
31.67717	140.0699	2.801076
31.72717	140.0689	2.786380
31.78050	140.0664	2.770354
31.83050	140.0659	2.753726
31.88383	140.0647	2.736858
31.93550	140.0634	2.719504
31.98717	140.0634	2.699088
32.04050	140.0619	2.678162
32.09050	140.0608	2.659148
32.14383	140.0595	2.638790
32.19383	140.0589	2.617114
32.24716	140.0584	2.594994
32.29883	140.0570	2.576289
32.35050	140.0562	2.556064
32.40383	140.0552	2.535436
32.45383	140.0546	2.515974
32.50716	140.0532	2.494990
32.55883	140.0525	2.474970
32.61050	140.0511	2.456251
32.66383	140.0504	2.431989
32.71383	140.0492	2.413755
32.76716	140.0485	2.391876
32.81716	140.0481	2.369076
32.87050	140.0470	2.348670
32.92216	140.0458	2.328067
32.97383	140.0447	2.304913
33.02716	140.0444	2.281379
33.07717	140.0431	2.258362
33.13050	140.0419	2.236311
33.18216	140.0408	2.213387
33.23383	140.0389	2.194194
33.28550	140.0377	2.173148
33.33716	140.0358	2.152342
33.39050	140.0342	2.129485
33.44050	140.0336	2.105648
33.49383	140.0325	2.081982
33.54550	140.0309	2.056451
33.59716	140.0301	2.028290
33.65050	140.0288	2.004586
33.70050	140.0277	1.978088
33.75383	140.0267	1.951830
33.80383	140.0258	1.927315
33.85716	140.0243	1.899644
33.90883	140.0236	1.872870
33.96050	140.0221	1.847746
34.01383	140.0208	1.818418
34.06383	140.0190	1.795421
34.11716	140.0179	1.765406
34.16883	140.0167	1.738433
34.22050	140.0158	1.712777
34.27217	140.0131	1.685504
34.32383	140.0120	1.659157
34.37717	140.0099	1.633749
34.42717	140.0098	1.614420
34.48050	140.0084	1.592802
34.53216	140.0061	1.561129
34.58383	140.0049	1.523726
34.63716	140.0032	1.488969
34.68716	140.0018	1.458243
34.74050	140.0004	1.422822
34.79050	139.9988	1.390966
34.84384	139.9967	1.358594
34.89550	139.9954	1.327304
34.94717	139.9936	1.293599
35.00050	139.9921	1.258348
35.05050	139.9907	1.227402
35.10383	139.9900	1.190839
35.15550	139.9875	1.157216
35.20716	139.9860	1.124365
35.25883	139.9843	1.093065
35.31050	139.9816	1.061205
35.36383	139.9803	1.027219
35.41383	139.9790	0.9968392
35.46716	139.9776	0.9651551
35.51883	139.9756	0.9310119
35.57050	139.9735	0.8982836
35.62383	139.9726	0.8614793
35.67383	139.9700	0.8272719
35.72717	139.9682	0.7940079
35.77716	139.9667	0.7584311
35.83050	139.9652	0.7218745
35.88216	139.9637	0.6820588
35.93384	139.9614	0.6440614
35.98717	139.9602	0.6045630
36.03717	139.9577	0.5692184
36.09050	139.9564	0.5330863
36.14216	139.9543	0.4946637
36.19383	139.9524	0.4617402
36.24550	139.9512	0.4237716
36.29716	139.9487	0.3885149
36.35050	139.9470	0.3557011
36.40050	139.9449	0.3215262
36.45383	139.9439	0.2847277
36.50550	139.9417	0.2515552
36.55716	139.9396	0.2197117
36.61050	139.9375	0.1861247
36.66050	139.9351	0.1527744
36.71383	139.9340	0.1191161
36.76383	139.9314	0.08806101
36.81716	139.9307	0.05312546
36.86883	139.9284	0.02163432
36.92050	139.9267	-.01186705
36.97383	139.9252	-.04471180
37.02383	139.9232	-.07398035
37.07717	139.9215	-0.1061684
37.12883	139.9214	-0.1332466
37.18050	139.9192	-0.1628571
37.23216	139.9184	-0.1949871
37.28383	139.9170	-0.2269850
37.33716	139.9151	-0.2554014
37.38716	139.9145	-0.2859301
37.44050	139.9126	-0.3143006
37.49216	139.9113	-0.3414378
37.54383	139.9100	-0.3667785
37.59716	139.9087	-0.3928255
37.64717	139.9071	-0.4160206
37.70050	139.9061	-0.4412004
37.75050	139.9047	-0.4637676
37.80383	139.9034	-0.4853516
37.85550	139.9021	-0.5044547
37.90716	139.9014	-0.5272105
37.96050	139.9006	-0.5532832
38.01050	139.8994	-0.5772602
38.06383	139.8981	-0.6014268
38.11550	139.8973	-0.6251082
38.16716	139.8961	-0.6464442
38.22050	139.8956	-0.6649415
38.27050	139.8943	-0.6819321
38.32383	139.8930	-0.6993486
38.37383	139.8922	-0.7153032
38.42717	139.8907	-0.7288800
38.47883	139.8902	-0.7436715
38.53050	139.8889	-0.7575544
38.58383	139.8871	-0.7719251
38.63383	139.8870	-0.7854337
38.68716	139.8861	-0.7986468
38.73717	139.8850	-0.8112579
38.79050	139.8845	-0.8243368
38.84216	139.8834	-0.8368722
38.89383	139.8824	-0.8510147
38.94717	139.8825	-0.8651849
38.99716	139.8822	-0.8784942
39.05050	139.8815	-0.8914781
39.10217	139.8810	-0.9034238
39.15383	139.8808	-0.9183756
39.20716	139.8797	-0.9302074
39.25716	139.8801	-0.9418144
39.31050	139.8796	-0.9525105
39.36050	139.8790	-0.9623553
39.41383	139.8779	-0.9735691
39.46550	139.8784	-0.9838592
39.51716	139.8772	-0.9941955
39.57050	139.8756	-1.004504
39.62050	139.8756	-1.013962
39.67383	139.8761	-1.023446
39.72550	139.8746	-1.032349
39.77716	139.8734	-1.041005
39.82883	139.8728	-1.049256
39.88050	139.8725	-1.057487
39.93384	139.8719	-1.065864
39.98383	139.8722	-1.073717
40.03717	139.8716	-1.082116
40.08883	139.8715	-1.090092
40.14050	139.8716	-1.098374
40.19383	139.8700	-1.106546
40.24383	139.8706	-1.114246
40.29716	139.8697	-1.122471
40.34716	139.8698	-1.130158
40.40050	139.8696	-1.138116
40.45216	139.8688	-1.145644
40.50383	139.8695	-1.152922
40.55716	139.8686	-1.160222
40.60716	139.8679	-1.166888
40.66050	139.8680	-1.173585
40.71216	139.8676	-1.180126
40.76383	139.8677	-1.186397
40.81550	139.8672	-1.192376
40.86716	139.8670	-1.198285
40.92050	139.8669	-1.204406
40.97050	139.8673	-1.210266
41.02383	139.8672	-1.216310
41.07550	139.8662	-1.221615
41.12717	139.8665	-1.226868
41.18050	139.8658	-1.232058
41.23050	139.8656	-1.236581
41.28383	139.8657	-1.241444
41.33383	139.8660	-1.245625
41.38716	139.8648	-1.250147
41.43883	139.8650	-1.254330
41.49050	139.8642	-1.258652
41.54383	139.8643	-1.263175
41.59384	139.8640	-1.267418
41.64717	139.8644	-1.271900
41.69883	139.8639	-1.276224
41.75050	139.8640	-1.280566
41.80217	139.8638	-1.284853
41.85383	139.8636	-1.289032
41.90717	139.8634	-1.293236
41.95717	139.8624	-1.296800
42.01050	139.8624	-1.300318
42.06216	139.8624	-1.303716
42.11383	139.8615	-1.306704
42.16716	139.8606	-1.309501
42.21717	139.8604	-1.312192
42.27050	139.8611	-1.315231
42.32050	139.8614	-1.318084
42.37383	139.8609	-1.321340
42.42550	139.8611	-1.324549
42.47717	139.8605	-1.327850
42.53050	139.8598	-1.331293
42.58050	139.8599	-1.334676
42.63383	139.8603	-1.338204
42.68550	139.8592	-1.341436
42.73717	139.8602	-1.344598
42.78883	139.8598	-1.347595
42.84050	139.8594	-1.350393
42.89383	139.8596	-1.353074
42.94383	139.8592	-1.355578
42.99716	139.8596	-1.358352
43.04550	139.8916	-1.346283
43.09716	140.2654	-1.575179
43.15050	140.8918	-3.596489
43.20050	141.5717	-6.184331
43.25383	142.3678	-9.073166
43.30550	143.1894	-11.66057
43.35717	144.0510	-13.92401
43.41050	144.9702	-15.89260
43.46050	145.8584	-17.43152
43.51383	146.8241	-18.78967
43.56383	147.7460	-19.84789
43.61716	148.7441	-20.77634
43.66883	149.7204	-21.52717
43.72050	150.7053	-22.15496
43.77383	151.7314	-22.70630
43.82383	152.6970	-23.14892
43.87717	153.7337	-23.56545
43.92883	154.7402	-23.91800
43.98050	155.7513	-24.23635
44.03217	156.7647	-24.52266
44.08383	157.7806	-24.78572
44.13716	158.8309	-25.04272
44.18716	159.8164	-25.26576
44.24050	160.8696	-25.48723
44.29217	161.8918	-25.69922
44.34384	162.9146	-25.89687
44.39717	163.9705	-26.09819
44.44717	164.9625	-26.28165
44.50050	166.0202	-26.47101
44.55050	167.0111	-26.64500
44.60383	168.0692	-26.83598
44.65550	169.0944	-27.00930
44.70717	170.1197	-27.18330
44.76050	171.1772	-27.36842
44.81050	172.1705	-27.54746
44.86383	173.2282	-27.74344
44.91550	174.2536	-27.92254
44.96717	175.2804	-28.10432
45.01883	176.3062	-28.29014
45.07050	177.3313	-28.47743
45.12383	178.3896	-28.67688
45.17383	179.3826	-28.87909
45.22717	180.4397	-29.09621
45.27883	181.4642	-29.32095
45.33050	182.4883	-29.55552
45.38383	183.5454	-29.80750
45.43383	184.5367	-30.05295
45.48717	185.5927	-30.31546
45.53717	186.5827	-30.57240
45.59050	187.6364	-30.85018
45.64217	188.6595	-31.13880
45.69383	189.6810	-31.42929
45.74716	190.7354	-31.75720
45.79716	191.7231	-32.07039
45.85050	192.7760	-32.42715
45.90216	193.7950	-32.78356
45.95383	194.8134	-33.15534
46.00717	195.8627	-33.56638
46.05717	196.8471	-33.97937
46.11050	197.8942	-34.45245
46.16050	198.8748	-34.91611
46.21383	199.9196	-35.44700
46.26550	200.9298	-36.00267
46.31717	201.9386	-36.59782
46.37050	202.9777	-37.26656
46.42050	203.9504	-37.93271
46.47383	204.9856	-38.70231
46.52383	205.9518	-39.49228
46.57717	206.9810	-40.40856
46.62883	207.9730	-41.38137
46.68050	208.9607	-42.46023
46.73383	209.9756	-43.70226
46.78383	210.9199	-45.00119
46.83716	211.9204	-46.57072
46.88883	212.8812	-48.30889
46.94050	213.8294	-50.31466
46.99383	214.7937	-52.71966
47.04383	215.6826	-55.32898
47.09716	216.6124	-58.51406
47.14717	217.4662	-61.90175
47.20050	218.3592	-65.91861
47.25217	219.2087	-70.11374
47.30383	220.0474	-74.46861
47.35717	220.9147	-78.85979
47.40717	221.7494	-82.25500
47.46050	222.7054	-84.09734
47.51216	223.7206	-83.93085
47.56383	224.8110	-82.29342
47.61550	225.9556	-79.56957
47.66716	227.1392	-76.12690
47.72050	228.3934	-71.88074
47.77050	229.5966	-67.28784
47.82383	230.9105	-61.76515
47.87550	232.1964	-56.29948
47.92717	233.4612	-51.53247
47.98050	234.7273	-47.50840
48.03050	235.8797	-44.49060
48.08383	237.0756	-41.91684
48.13383	238.1719	-40.01361
48.18716	239.3208	-38.39792
48.23883	240.4167	-37.17947
48.29050	241.5004	-36.21167
48.34384	242.6090	-35.43924
48.39383	243.6390	-34.86520
48.44717	244.7322	-34.37686
48.49883	245.7860	-34.01535
48.55050	246.8348	-33.73524
48.60217	247.8816	-33.51264
48.65383	248.9245	-33.34013
48.70717	249.9996	-33.21278
48.75717	251.0066	-33.12810
48.81050	252.0794	-33.07336
48.86217	253.1162	-33.03559
48.91383	254.1538	-33.00333
48.96717	255.2242	-32.98784
49.01717	256.2262	-32.98242
49.07050	257.2946	-32.98253
49.12050	258.2964	-32.98720
49.17383	259.3629	-33.01465
49.22550	260.3972	-33.05803
49.27716	261.4308	-33.09864
49.33050	262.4978	-33.14509
49.38050	263.4980	-33.20219
49.43383	264.5648	-33.25130
49.48550	265.5980	-33.30726
49.53717	266.6313	-33.36202
49.58883	267.6650	-33.41520
49.64050	268.6984	-33.47602
49.69383	269.7641	-33.53700
49.74383	270.7644	-33.58809
49.79716	271.8300	-33.63445
49.84883	272.8633	-33.69050
49.90050	273.8967	-33.74252
49.95383	274.9631	-33.78677
50.00050	275.8963	-33.83066
50.05383	276.8354	-33.99895
50.10550	276.9756	-32.21248
50.15717	276.7428	-26.64126
50.21050	276.2961	-19.73756
50.26050	275.7565	-13.41642
50.31383	275.0845	-7.447168
50.36550	274.3584	-2.571587
50.41716	273.5748	1.453848
50.47050	272.7183	4.827124
50.52050	271.8794	7.389890
50.57383	270.9544	9.617501
50.62383	270.0642	11.32436
50.67717	269.0955	12.83096
50.72883	268.1416	14.03465
50.78050	267.1758	15.04191
50.83383	266.1676	15.92471
50.88383	265.2154	16.62954
50.93716	264.1924	17.27816
50.98883	263.1961	17.82211
51.04050	262.1954	18.29502
51.09217	261.1908	18.71164
51.14383	260.1831	19.08374
51.19717	259.1413	19.41911
51.24717	258.1615	19.69780
51.30050	257.1144	19.97306
51.35217	256.0984	20.20768
51.40383	255.0814	20.42117
51.45717	254.0294	20.62066
51.50717	253.0432	20.79064
51.56050	251.9897	20.96023
51.61050	251.0011	21.10190
51.66383	249.9458	21.24616
51.71550	248.9221	21.37782
51.76716	247.8992	21.49576
51.82050	246.8426	21.61216
51.87050	245.8508	21.70961
51.92383	244.7938	21.80824
51.97550	243.7687	21.90338
52.02717	242.7430	21.98812
52.07883	241.7182	22.06225
52.13050	240.6930	22.14097
52.18383	239.6336	22.21569
52.23383	238.6401	22.28844
52.28716	237.5798	22.35760
52.33883	236.5530	22.42881
52.39050	235.5268	22.49156
52.44384	234.4680	22.54550
52.49382	233.4732	22.59530
52.54717	232.4121	22.65282
52.59716	231.4172	22.69728
52.65050	230.3571	22.74704
52.70216	229.3290	22.79184
52.75383	228.3015	22.83911
52.80717	227.2408	22.89468
52.85717	226.2470	22.93324
52.91050	225.1864	22.98989
52.96216	224.1592	23.03670
53.01382	223.1305	23.06350
53.06550	222.1017	23.10056
53.11716	221.0727	23.13452
53.17050	220.0106	23.16534
53.22050	219.0159	23.19326
53.27383	217.9535	23.22132
53.32550	216.9245	23.24171
53.37717	215.8948	23.27081
53.43050	214.8330	23.29013
53.48050	213.8375	23.30530
53.53383	212.7752	23.32278
53.58383	211.7795	23.33911
53.63716	210.7167	23.35549
53.68882	209.6877	23.37364
53.74050	208.6586	23.38906
53.79382	207.5959	23.40224
53.84384	206.5992	23.41654
53.89717	205.5366	23.43078
53.94883	204.5068	23.44033
54.00050	203.4769	23.45001
54.05217	202.4482	23.45977
54.10383	201.4184	23.46803
54.15717	200.3548	23.47727
54.20717	199.3591	23.48742
54.26050	198.2940	23.49691
54.31216	197.2648	23.50560
54.36382	196.2340	23.51199
54.41716	195.1711	23.51853
54.46717	194.1747	23.52480
54.52050	193.1108	23.53208
54.57050	192.1146	23.54019
54.62383	191.0519	23.54954
54.67550	190.0219	23.56094
54.72717	188.9919	23.57215
54.78050	187.9292	23.58140
54.83050	186.9326	23.58989
54.88383	185.8682	23.59863
54.93550	184.8388	23.60604
54.98717	183.8085	23.61208
55.03882	182.7791	23.61699
55.09050	181.7481	23.62155
55.14384	180.6853	23.62644
55.19384	179.6872	23.63153
55.24717	178.6244	23.63934
55.29883	177.5948	23.65682
55.35050	176.5659	23.69181
55.40383	175.5039	23.75430
55.45383	174.5100	23.82740
55.50717	173.4485	23.92284
55.55717	172.4561	24.02885
55.61050	171.4001	24.16713
55.66216	170.3768	24.34277
55.71382	169.3578	24.60294
55.76716	168.3126	25.04740
55.81716	167.3455	25.79843
55.87050	166.3425	27.32624
55.92217	165.4230	30.02713
55.97382	164.5729	34.25644
56.02717	163.7666	39.92385
56.07717	163.0433	45.55332
56.13050	162.2551	50.89291
56.18050	161.4687	54.69905
56.23383	160.5582	57.25302
56.28550	159.6060	58.27996
56.33716	158.5879	58.02871
56.39050	157.4772	56.63966
56.44050	156.3942	54.56812
56.49382	155.2085	51.85812
56.54382	154.0801	49.12324
56.59716	152.8753	46.23740
56.64883	151.7126	43.63784
56.70050	150.5618	41.28720
56.75383	149.3870	39.15486
56.80383	148.2980	37.39964
56.85717	147.1495	35.76696
56.90883	146.0440	34.26672
56.96050	144.9492	33.08458
57.01382	143.8291	32.02438
57.06382	142.7878	31.15998
57.11716	141.6805	30.36035
57.16716	140.6504	29.71432
57.22050	139.5554	29.10785
57.27217	138.4987	28.58736
57.32383	137.4441	28.13535
57.37717	136.3592	27.72459
57.42717	135.3435	27.38264
57.48050	134.2629	27.06033
57.53217	133.2180	26.78219
57.58383	132.1744	26.53375
57.63550	131.1326	26.30185
57.68716	130.0908	26.09323
57.74050	129.0167	25.89674
57.79050	128.0101	25.73466
57.84384	126.9373	25.56394
57.89550	125.8984	25.40648
57.94717	124.8610	25.25383
58.00050	123.7832	24.95698
58.05050	122.7784	24.86067
58.10383	121.7107	24.75302
58.15383	120.7068	24.66350
58.20717	119.6389	24.56029
58.25883	118.6041	24.47471
58.31050	117.5689	24.38725
58.36382	116.5018	24.30844
58.41382	115.4999	24.23126
58.46717	114.4328	24.14995
58.51884	113.3979	24.07416
58.57050	112.3637	23.99794
58.62217	111.3283	23.92017
58.67383	110.2936	23.84253
58.72717	109.2240	23.75368
58.77717	108.2216	23.67624
58.83050	107.1532	23.58965
58.88217	106.1182	23.50177
58.93383	105.0832	23.42049
58.98717	104.0147	23.33836
59.03716	103.0136	23.26470
59.09050	101.9449	23.18642
59.14050	100.9436	23.10981
59.19384	99.87574	23.03428
59.24550	98.84015	22.96478
59.29717	97.80532	22.88889
59.35050	96.73725	22.82210
59.40050	95.73678	22.74843
59.45383	94.66986	22.67326
59.50550	93.63582	22.60701
59.55717	92.60274	22.53912
59.60883	91.56719	22.47178
59.66050	90.53241	22.40949
59.71382	89.46610	22.32639
59.76382	88.46549	22.26054
59.81716	87.39755	22.19004
59.86882	86.36382	22.11887
59.92050	85.32989	22.04968
59.97382	84.26265	21.98021
60.02383	83.26080	21.92122
60.07717	82.19402	21.85230
60.12717	81.19206	21.78828
60.18050	80.12593	21.71450
60.23217	79.09111	21.64770
60.28383	78.05743	21.57978
60.33716	76.99070	21.50881
60.38716	75.98991	21.44928
60.44050	74.92366	21.38702
60.49216	73.88850	21.32770
60.54382	72.85453	21.26300
60.59550	71.82031	21.19953
60.64717	70.78637	21.13064
60.70050	69.71776	21.06702
60.75050	68.71718	20.99797
60.80383	67.64961	20.91982
60.85550	66.61470	20.84391
60.90717	65.57989	20.77138
60.96050	64.51208	20.69895
61.01050	63.51070	20.62997
61.06382	62.44426	20.55726
61.11382	61.44262	20.48140
61.16716	60.37601	20.40711
61.21884	59.34070	20.33142
61.27050	58.30569	20.25756
61.32383	57.23780	20.18518
61.37383	56.23541	20.10959
61.42717	55.16791	20.03358
61.47883	54.13325	19.96412
61.53050	53.09825	19.88437
61.58217	52.06404	19.81259
61.63383	51.02842	19.73730
61.68716	49.95972	19.65983
61.73717	48.95764	19.58650
61.79050	47.88986	19.50900
61.84217	46.85509	19.43367
61.89384	45.82026	19.35867
61.94717	44.75146	19.28876
61.99717	43.74940	19.22206
62.05050	42.68067	19.14778
62.10050	41.67783	19.07698
62.15383	40.60934	18.99428
62.20550	39.57385	18.91080
62.25717	38.53908	18.82884
62.31050	37.46946	18.73600
62.36050	36.46758	18.64828
62.41382	35.39752	18.55742
62.46550	34.36183	18.47014
62.51716	33.32530	18.38107
62.57050	32.25685	18.29064
62.62050	31.25430	18.20131
62.67383	30.18445	18.11372
62.72382	29.18320	18.03218
62.77717	28.11299	17.93366
62.82883	27.07618	17.83666
62.88050	26.03905	17.74565
62.93383	24.96833	17.63943
62.98383	23.96348	17.54363
63.03383	22.98164	17.42066
63.08550	22.51468	16.85898
63.13716	22.60172	14.02031
63.19050	22.92812	9.963559
63.24050	23.40158	5.943706
63.29382	24.02395	1.954788
63.34550	24.72116	-1.406852
63.39717	25.48721	-4.233498
63.45050	26.33360	-6.618616
63.50050	27.16906	-8.431830
63.55383	28.09134	-9.988461
63.60383	28.98225	-11.16158
63.65717	29.95357	-12.16958
63.70883	30.90887	-12.96052
63.76050	31.87899	-13.60399
63.81382	32.88829	-14.15414
63.86384	33.84531	-14.58346
63.91716	34.87103	-14.96800
63.96884	35.87078	-15.28038
64.02050	36.87535	-15.54809
64.07218	37.88360	-15.79143
64.12383	38.89431	-16.00124
64.17718	39.94124	-16.18739
64.22718	40.92359	-16.34454
64.28050	41.97426	-16.50141
64.33217	42.99335	-16.63542
64.38384	44.01352	-16.76185
64.43717	45.06828	-16.88208
64.48717	46.05868	-16.99058
64.54050	47.11564	-17.10283
64.59050	48.10718	-17.20652
64.64384	49.16593	-17.31000
64.69550	50.19254	-17.40775
64.74717	51.21929	-17.50408
64.80050	52.28022	-17.60136
64.85050	53.27480	-17.68746
64.90384	54.33672	-17.77893
64.95550	55.36559	-17.86023
65.00718	56.39277	-17.94263
65.05884	57.42266	-18.02904
65.11050	58.45157	-18.11695
65.16382	59.51490	-18.20998
65.21384	60.51100	-18.29603
65.26716	61.57302	-18.38312
65.31884	62.60250	-18.47207
65.37050	63.63206	-18.56330
65.42383	64.69500	-18.65138
65.47384	65.69260	-18.73555
65.52717	66.75715	-18.82620
65.57718	67.75354	-18.91297
65.63050	68.81824	-19.00104
65.68218	69.84818	-19.08812
65.73384	70.87928	-19.17186
65.78718	71.94238	-19.26076
65.83716	72.94070	-19.34649
65.89050	74.00421	-19.43676
65.94218	75.03612	-19.52141
65.99384	76.06550	-19.60900
66.04550	77.09560	-19.69996
66.09718	78.12582	-19.79409
66.15050	79.18842	-19.89360
66.20050	80.18500	-19.99122
66.25384	81.24869	-20.09502
66.30550	82.27916	-20.19676
66.35718	83.30958	-20.29522
66.41050	84.37348	-20.39188
66.46050	85.37109	-20.48588
66.51384	86.43524	-20.58354
66.56384	87.43276	-20.67339
66.61718	88.49644	-20.76800
66.66884	89.52750	-20.85676
66.72050	90.55870	-20.95279
66.77384	91.62332	-21.04253
66.82384	92.62040	-21.12934
66.87718	93.68462	-21.21733
66.92884	94.71618	-21.30244
66.98050	95.74781	-21.39399
67.03218	96.77816	-21.48309
67.08384	97.80939	-21.56145
67.13718	98.87371	-21.65276
67.18718	99.87216	-21.73378
67.24050	100.9366	-21.82077
67.29218	101.9679	-21.90968
67.34384	102.9986	-21.99590
67.39718	104.0634	-22.07907
67.44718	105.0609	-22.16740
67.50050	106.1240	-22.26358
67.55050	107.1220	-22.35408
67.60384	108.1866	-22.45202
67.65550	109.2168	-22.54126
67.70718	110.2477	-22.63496
67.76050	111.3125	-22.73088
67.81050	112.3103	-22.82119
67.86384	113.3742	-22.91551
67.91550	114.4047	-23.00730
67.96718	115.4360	-23.09700
68.02050	116.5005	-23.19337
68.07050	117.4983	-23.27464
68.12384	118.5623	-23.37484
68.17384	119.5599	-23.46696
68.22718	120.6243	-23.56882
68.27884	121.6554	-23.66783
68.33050	122.6864	-23.76879
68.38384	123.7495	-23.87104
68.43384	124.7476	-23.96598
68.48718	125.8120	-24.07148
68.53718	126.8094	-24.16816
68.59050	127.8747	-24.27028
68.64216	128.9048	-24.35887
68.69384	129.9352	-24.45645
68.74718	130.9994	-24.56350
68.79718	131.9963	-24.66710
68.85050	133.0608	-24.77542
68.90218	134.0923	-24.88252
68.95384	135.1225	-24.98799
69.00718	136.1857	-25.10286
69.05718	137.1830	-25.21825
69.11050	138.2462	-25.34006
69.16050	139.2426	-25.45630
69.21384	140.3064	-25.58110
69.26550	141.3357	-25.70242
69.31718	142.3662	-25.82798
69.37050	143.4299	-25.95808
69.42050	144.4264	-26.07686
69.47384	145.4875	-26.20561
69.52550	146.5178	-26.33170
69.57718	147.5470	-26.46554
69.62884	148.5763	-26.59595
69.68050	149.6048	-26.72875
69.73384	150.6675	-26.86407
69.78384	151.6637	-27.00067
69.83716	152.7253	-27.14112
69.88884	153.7532	-27.28796
69.94050	154.7824	-27.43935
69.99384	155.8441	-27.60123
70.04384	156.8390	-27.75161
70.09718	157.9007	-27.91260
70.14718	158.8966	-28.07096
70.20050	159.9580	-28.23202
70.25218	160.9861	-28.39166
70.30384	162.0140	-28.55633
70.35718	163.0756	-28.72084
70.40718	164.0694	-28.87528
70.46050	165.1309	-29.04709
70.51218	166.1599	-29.20124
70.56384	167.1876	-29.35302
70.61550	168.2169	-29.49531
70.66718	169.2466	-29.62998
70.72050	170.3097	-29.75291
70.77050	171.3063	-29.86606
70.82384	172.3706	-29.97027
70.87550	173.4014	-30.07116
70.92718	174.4323	-30.16182
70.98050	175.4969	-30.25795
71.03050	176.4961	-30.35708
71.08384	177.5583	-30.47375
71.13384	178.5551	-30.58684
71.18718	179.6174	-30.74010
71.23882	180.6456	-30.89805
71.29050	181.6734	-31.08858
71.34384	182.7325	-31.30133
71.39384	183.7247	-31.52451
71.44718	184.7815	-31.79507
71.49884	185.8041	-32.07884
71.55050	186.8258	-32.39273
71.60218	187.8447	-32.74405
71.65384	188.8632	-33.13725
71.70718	189.9115	-33.58440
71.75718	190.8925	-34.06809
71.81050	191.9357	-34.63050
71.86218	192.9440	-35.25192
71.91382	193.9487	-35.94154
71.96718	194.9832	-36.72283
72.01716	195.9494	-37.51719
72.07050	196.9779	-38.42206
72.12050	197.9391	-39.29614
72.17384	198.9651	-40.24304
72.22551	199.9583	-41.17226
72.27718	200.9498	-42.11564
72.33050	201.9728	-43.12742
72.38050	202.9306	-44.11853
72.43384	203.9501	-45.21434
72.48550	204.9358	-46.30777
72.53718	205.9208	-47.41863
72.58884	206.9074	-48.46742
72.64050	207.8996	-49.35314
72.69384	208.9365	-49.92489
72.74384	209.9314	-49.92064
72.79718	211.0252	-49.12328
72.84882	212.1238	-47.51143
72.90050	213.2554	-45.26743
72.95384	214.4436	-42.63023
73.00384	215.5590	-40.18271
73.05718	216.7407	-37.87051
73.10718	217.8325	-36.07387
73.16050	218.9784	-34.52383
73.21218	220.0742	-33.33590
73.26384	221.1568	-32.39988
73.31718	222.2638	-31.64785
73.36718	223.2942	-31.08811
73.42050	224.3860	-30.62629
73.47218	225.4404	-30.27141
73.52384	226.4900	-29.99556
73.57550	227.5357	-29.78868
73.62718	228.5788	-29.62842
73.68050	229.6533	-29.52108
73.73050	230.6594	-29.45664
73.78384	231.7316	-29.41324
73.83550	232.7692	-29.39969
73.88718	233.8034	-29.42779
73.94050	234.8698	-29.45589
73.99050	235.8701	-29.50158
74.04384	236.9382	-29.53820
74.09384	237.9392	-29.54951
74.14718	239.0069	-29.56418
74.19884	240.0417	-29.58410
74.25050	241.0755	-29.62086
74.30384	242.1436	-29.66820
74.35384	243.1442	-29.71056
74.40718	244.2112	-29.75701
74.45884	245.2453	-29.79840
74.51050	246.2782	-29.84175
74.56384	247.3458	-29.89016
74.61384	248.3456	-29.92942
74.66718	249.4118	-29.97060
74.71718	250.4116	-30.01774
74.77050	251.4797	-30.07265
74.82218	252.5128	-30.12689
74.87384	253.5455	-30.17137
74.92718	254.6120	-30.22117
74.97718	255.6120	-30.27197
75.03050	256.6799	-30.33757
75.08050	257.6793	-30.39504
75.13384	258.7458	-30.42926
75.18550	259.7802	-30.46005
75.23718	260.8131	-30.49925
75.29050	261.8784	-30.58200
75.34050	262.8780	-30.66843
75.39384	263.9432	-30.76264
75.44550	264.9742	-30.88053
75.49718	266.0041	-31.00863
75.55050	267.0671	-31.15321
75.60050	268.0614	-31.35455
75.65384	269.1214	-31.58832
75.70384	270.1134	-31.80956
75.75718	271.1726	-32.04302
75.80884	272.1968	-32.26797
-2.000000	5.000000	0.0000000