File: 3-C1(1.0mol%)+C20(0.6mol%)/matlab/140-1
CLOSED
Version	1.0
Language	English
Mode	Standard
Run	1
RunSerial	11781
Instrument	DSC Q2000 V24.11 Build 124
Module	DSC Standard Cell RC
Operator	Nan
File	\\Ae520-1454\ta\Data\DSC\UQ Composites\Nan\C1(4.5)+C20P(3)+CL(HotplateMixtureAB)\Iso140_60Min_1
ProcName	H/C/H/C/H complete wood PHA
InstSerial	2000-0883
AutoSerial	1293
Sample	Iso140_60Min
Size	49.1000	mg
PanMass	Not available
PanResist	Automatic Automatic  K/W
PanFactor	Default Default
Method	H/C/H/C/H complete wood PHA
Comment
Xcomment	Pan: Tzero Aluminum Hermetic
Xcomment	Gas1: Nitrogen 50.0 ml/min
Xcomment	Gas2: Nitrogen 50.0 ml/min
Text
Exotherm	UP
Kcell	1.05230
Cpconst	Standard: 0.938
Calib	-38.6961
TempCal	1	pts	157.46	156.60
TzeroDt	-87.6168 -0.0009 -1.4231
TzeroDtz	-87.6168 0.0057 6.9570
InstCalFile	Tzero: \\Ae520-1454\ta\Data\DSC\Calibration\2017\CALIBRATION\1562_RCS (90)_05_18_2017 10_50_44.TZR
InstCalFile	Baseline: \\Ae520-1454\ta\Data\DSC\Calibration\2017\2017-05-17_Calibration.001
InstCalFile	Sapphire: \\Ae520-1454\ta\Data\DSC\Calibration\2017\2017-05-17_Saphire.001
InstCalDate	Tzero 2017-05-18 Time 10:50:44
TempRange	-87.39 to 398.39 °C at 10.00 °C/min Heat Only
AutoZero	Delta T Offset 0.000 uV
AutoZero	Delta T0 Offset 0.000 uV
MultiptCal	0
MultiPtDesc	0) Not set
AutoCellConst	Calibration Date 2017-05-18 16:59:28
Controls	Gas 1  Event Off  Sampling 0.2
Cell#	RC-01562
CoolingUnit	RCS (90)
SelHeatFlow	Heat Flow T4 (mW)
AutoLidII	Installed
AutoAnalysis	Off
MacroFile
Nsig	3
Sig1	Time (min)
Sig2	Temperature (°C)
Sig3	Heat Flow (mW)
Date	2017-06-07
Time	11:07:37
OrgMethod	1: Equilibrate at 20.00 °C
OrgMethod	2: Ramp 40.00 °C/min to 140.00 °C
OrgMethod	3: Mark end of cycle 1
OrgMethod	4: Isothermal for 60.00 min
OrgMethod	5: Mark end of cycle 2
OrgMethod	6: Ramp 20.00 °C/min to 280.00 °C
OrgMethod	7: Mark end of cycle 3
OrgMethod	8: Ramp 20.00 °C/min to 20.00 °C
OrgMethod	9: Mark end of cycle 4
OrgMethod	10: Ramp 20.00 °C/min to 280.00 °C
OrgMethod	11: Mark end of cycle 5
OrgFile	C:\Users\jarra\Desktop\DSC\3-C1(1.0mol%)+C20(0.6mol%)\140-1
StartOfData
4.99994E-4	19.98894	0.6082782
0.06716666	20.24820	0.5408789
0.1321667	21.55537	-1.967201
0.1988333	23.26833	-7.222580
0.2638334	25.16448	-13.02993
0.3288334	27.20572	-18.54768
0.3955000	29.41375	-23.50823
0.4605000	31.65164	-27.56456
0.5255000	33.95769	-30.96578
0.5921668	36.37526	-33.86806
0.6571668	38.77340	-36.27580
0.7238332	41.26094	-38.44396
0.7888332	43.69910	-40.59494
0.8538332	46.13478	-42.86988
0.9205000	48.65098	-44.86008
0.9854999	51.13084	-46.43361
1.050500	53.63112	-47.82926
1.117166	56.19643	-49.40224
1.182166	58.69102	-51.07454
1.248833	61.24449	-52.98798
1.313833	63.71526	-55.35752
1.378833	66.13962	-58.79575
1.445500	68.52378	-64.58127
1.510500	70.68157	-73.68750
1.575500	72.62916	-86.66668
1.642166	74.43074	-103.4107
1.707167	76.10363	-120.5230
1.772167	77.68121	-139.1945
1.838833	79.47813	-154.5168
1.903833	81.33105	-167.7273
1.970500	83.38934	-178.4434
2.035500	85.63726	-183.6368
2.100500	88.22809	-182.5281
2.167167	91.12899	-178.3035
2.232167	94.02441	-173.2852
2.297166	96.93688	-168.8299
2.363834	99.59200	-168.1192
2.428833	103.0350	-150.4066
2.495500	106.5662	-135.6272
2.560500	109.8550	-123.9920
2.625500	113.0092	-114.6998
2.692167	116.1283	-107.1425
2.757167	119.0798	-101.3810
2.822166	121.9568	-96.92081
2.888834	124.8506	-93.34766
2.953833	127.6286	-90.56414
3.017166	130.2997	-88.43732
3.082167	132.5354	-86.70722
3.147167	133.8188	-80.46636
3.213833	134.8206	-71.10709
3.278833	135.6008	-61.50470
3.343834	136.2382	-52.69439
3.410500	136.7762	-44.86916
3.475500	137.2080	-38.47586
3.542167	137.5750	-33.05476
3.607167	137.8720	-28.70430
3.672167	138.1210	-25.12215
3.738834	138.3344	-22.10757
3.803833	138.5088	-19.68473
3.868833	138.6561	-17.67699
3.935500	138.7834	-15.96887
4.000500	138.8889	-14.57789
4.065500	138.9787	-13.41453
4.132167	139.0569	-12.41367
4.197166	139.1239	-11.59078
4.263834	139.1803	-10.86890
4.328834	139.2300	-10.26606
4.393833	139.2729	-9.739301
4.460500	139.3121	-9.260431
4.525500	139.3456	-8.841040
4.590500	139.3760	-8.457069
4.657166	139.4040	-8.104389
4.722168	139.4292	-7.777497
4.788834	139.4526	-7.472831
4.853833	139.4735	-7.187955
4.918833	139.4928	-6.919572
4.985500	139.5121	-6.654288
5.050500	139.5286	-6.407533
5.115500	139.5455	-6.168720
5.182167	139.5609	-5.934722
5.247168	139.5756	-5.708019
5.313832	139.5900	-5.479318
5.378834	139.6032	-5.263594
5.443832	139.6155	-5.054406
5.510500	139.6282	-4.849350
5.575500	139.6399	-4.653324
5.640500	139.6514	-4.462772
5.707168	139.6623	-4.276986
5.772168	139.6725	-4.105441
5.838832	139.6826	-3.932117
5.903834	139.6922	-3.772948
5.968834	139.7007	-3.620484
6.035500	139.7095	-3.474231
6.100500	139.7174	-3.338406
6.165500	139.7248	-3.205154
6.232168	139.7321	-3.078241
6.297168	139.7389	-2.962650
6.362168	139.7453	-2.847760
6.428832	139.7517	-2.743111
6.493834	139.7583	-2.638137
6.560500	139.7634	-2.535297
6.625500	139.7691	-2.439982
6.690500	139.7742	-2.349444
6.757168	139.7792	-2.262694
6.822168	139.7835	-2.180829
6.887168	139.7880	-2.097705
6.953832	139.7928	-2.018340
7.018832	139.7962	-1.948521
7.085500	139.8010	-1.879665
7.150500	139.8044	-1.814043
7.215500	139.8082	-1.753468
7.282166	139.8112	-1.692153
7.347168	139.8152	-1.639647
7.412168	139.8180	-1.588073
7.478832	139.8208	-1.537683
7.543832	139.8234	-1.487667
7.610500	139.8267	-1.439850
7.675500	139.8292	-1.396906
7.740500	139.8310	-1.354245
7.807166	139.8341	-1.308303
7.872168	139.8358	-1.268422
7.937166	139.8384	-1.229792
8.003834	139.8399	-1.187323
8.068832	139.8425	-1.146048
8.135500	139.8446	-1.108368
8.200500	139.8467	-1.071396
8.265500	139.8488	-1.031302
8.332168	139.8512	-0.9918274
8.397168	139.8526	-0.9561191
8.462168	139.8549	-0.9208828
8.528832	139.8574	-0.8845491
8.593832	139.8593	-0.8487876
8.658832	139.8609	-0.8114342
8.725500	139.8633	-0.7762612
8.790500	139.8650	-0.7444288
8.857166	139.8672	-0.7124615
8.922168	139.8687	-0.6823568
8.987168	139.8707	-0.6510240
9.053832	139.8722	-0.6190159
9.118834	139.8737	-0.5888870
9.183832	139.8766	-0.5598852
9.250500	139.8778	-0.5252239
9.315500	139.8789	-0.4958706
9.382166	139.8804	-0.4625630
9.447168	139.8826	-0.4316946
9.512168	139.8838	-0.4001730
9.578832	139.8859	-0.3655867
9.643832	139.8874	-0.3357084
9.708832	139.8892	-0.3048882
9.775499	139.8917	-0.2752278
9.840500	139.8929	-0.2450032
9.907166	139.8950	-0.2160113
9.972168	139.8967	-0.1829223
10.03717	139.8975	-0.1477605
10.10383	139.9004	-0.1183111
10.16883	139.9015	-.08632808
10.23383	139.9032	-.05465062
10.30050	139.9050	-.02290804
10.36550	139.9068	.007986545
10.43217	139.9081	0.04089878
10.49717	139.9099	0.07067351
10.56216	139.9120	0.1036406
10.62884	139.9131	0.1356309
10.69383	139.9156	0.1657606
10.75883	139.9166	0.1970708
10.82550	139.9187	0.2287416
10.89050	139.9203	0.2615795
10.95550	139.9213	0.2936194
11.02217	139.9236	0.3254270
11.08717	139.9243	0.3584087
11.15383	139.9265	0.3888038
11.21884	139.9284	0.4183642
11.28383	139.9303	0.4511124
11.35050	139.9312	0.4843970
11.41550	139.9330	0.5166035
11.48050	139.9350	0.5486511
11.54717	139.9362	0.5795632
11.61217	139.9391	0.6100593
11.67883	139.9406	0.6426963
11.74384	139.9426	0.6755600
11.80884	139.9432	0.7077716
11.87550	139.9458	0.7404914
11.94050	139.9478	0.7743676
12.00550	139.9487	0.8107514
12.07217	139.9513	0.8425239
12.13717	139.9526	0.8764337
12.20384	139.9543	0.9107641
12.26883	139.9566	0.9415892
12.33383	139.9577	0.9757639
12.40050	139.9595	1.012980
12.46550	139.9612	1.044249
12.53050	139.9631	1.078884
12.59717	139.9650	1.114164
12.66217	139.9668	1.147649
12.72884	139.9689	1.184739
12.79384	139.9703	1.218183
12.85883	139.9721	1.254409
12.92550	139.9738	1.292621
12.99050	139.9764	1.327391
13.05550	139.9776	1.364389
13.12217	139.9797	1.399797
13.18716	139.9819	1.435412
13.25217	139.9833	1.471765
13.31884	139.9848	1.511654
13.38383	139.9869	1.546142
13.45050	139.9898	1.584678
13.51550	139.9917	1.623282
13.58050	139.9928	1.663075
13.64717	139.9958	1.701498
13.71217	139.9974	1.739675
13.77717	139.9994	1.781059
13.84383	140.0020	1.819846
13.90883	140.0040	1.862166
13.97550	140.0064	1.903559
14.04050	140.0084	1.944737
14.10550	140.0106	1.989860
14.17217	140.0125	2.034999
14.23716	140.0149	2.081011
14.30217	140.0176	2.127978
14.36884	140.0201	2.175760
14.43383	140.0228	2.225086
14.50050	140.0248	2.278628
14.56550	140.0275	2.329825
14.63050	140.0310	2.386089
14.69717	140.0331	2.445564
14.76217	140.0363	2.509498
14.82717	140.0396	2.574239
14.89383	140.0432	2.648087
14.95883	140.0472	2.726096
15.02550	140.0513	2.810934
15.09050	140.0550	2.902670
15.15550	140.0606	3.006644
15.22217	140.0672	3.124197
15.28717	140.0734	3.254884
15.35217	140.0808	3.400087
15.41883	140.0886	3.574894
15.48383	140.0988	3.766498
15.54884	140.1090	3.983650
15.61550	140.1221	4.239196
15.68050	140.1357	4.524600
15.74717	140.1520	4.852228
15.81216	140.1692	5.212094
15.87716	140.1892	5.611696
15.94384	140.2122	6.068203
16.00883	140.2359	6.551086
16.07383	140.2616	7.069981
16.14050	140.2892	7.626601
16.20550	140.3180	8.201750
16.27216	140.3485	8.796719
16.33716	140.3779	9.385672
16.40216	140.4086	9.971362
16.46883	140.4384	10.55935
16.53383	140.4664	11.11218
16.59883	140.4936	11.63737
16.66550	140.5195	12.13614
16.73050	140.5426	12.58326
16.79716	140.5643	12.99480
16.86216	140.5836	13.35240
16.92716	140.6010	13.66324
16.99383	140.6142	13.93676
17.05883	140.6262	14.15735
17.12383	140.6352	14.33761
17.19050	140.6435	14.48267
17.25550	140.6489	14.58378
17.32216	140.6523	14.65086
17.38716	140.6545	14.68715
17.45216	140.6554	14.69842
17.51883	140.6554	14.70116
17.58383	140.6541	14.69159
17.64883	140.6524	14.64196
17.71550	140.6492	14.57519
17.78050	140.6455	14.50273
17.84550	140.6424	14.42438
17.91217	140.6384	14.34099
17.97716	140.6344	14.25872
18.04383	140.6296	14.17440
18.10883	140.6259	14.08979
18.17383	140.6220	14.00762
18.24050	140.6178	13.92564
18.30550	140.6138	13.84944
18.37050	140.6102	13.77408
18.43716	140.6069	13.70375
18.50216	140.6035	13.64034
18.56883	140.6002	13.58203
18.63383	140.5978	13.52871
18.69884	140.5950	13.48033
18.76550	140.5920	13.43839
18.83050	140.5909	13.40025
18.89550	140.5889	13.36680
18.96216	140.5874	13.33933
19.02716	140.5865	13.31805
19.09383	140.5862	13.30437
19.15883	140.5853	13.29378
19.22383	140.5850	13.28482
19.29050	140.5850	13.27662
19.35550	140.5845	13.27034
19.42050	140.5852	13.26634
19.48716	140.5856	13.26505
19.55216	140.5860	13.26693
19.61883	140.5867	13.27288
19.68383	140.5876	13.28596
19.74883	140.5888	13.30520
19.81550	140.5896	13.33420
19.88050	140.5914	13.36981
19.94550	140.5919	13.40725
20.01216	140.5939	13.44529
20.07716	140.5955	13.48749
20.14216	140.5983	13.52518
20.20883	140.5999	13.57026
20.27383	140.6019	13.61562
20.34050	140.6046	13.66560
20.40550	140.6065	13.71407
20.47050	140.6091	13.76450
20.53717	140.6127	13.82052
20.60216	140.6152	13.87744
20.66716	140.6182	13.93302
20.73383	140.6216	13.99423
20.79883	140.6246	14.05429
20.86550	140.6279	14.11794
20.93050	140.6309	14.18032
20.99550	140.6351	14.24386
21.06216	140.6382	14.31430
21.12716	140.6411	14.38124
21.19216	140.6455	14.44878
21.25883	140.6488	14.52440
21.32383	140.6530	14.59458
21.39050	140.6569	14.66731
21.45550	140.6605	14.74434
21.52050	140.6640	14.81798
21.58716	140.6676	14.89748
21.65216	140.6719	14.97286
21.71716	140.6759	15.05428
21.78383	140.6798	15.13487
21.84883	140.6838	15.21732
21.91550	140.6872	15.30146
21.98050	140.6915	15.38342
22.04550	140.6953	15.46573
22.11216	140.6989	15.55062
22.17717	140.7040	15.63216
22.24216	140.7079	15.71445
22.30883	140.7129	15.79683
22.37383	140.7167	15.87968
22.43883	140.7209	15.96142
22.50550	140.7256	16.04410
22.57050	140.7297	16.12275
22.63716	140.7333	16.20534
22.70216	140.7377	16.28338
22.76716	140.7416	16.36439
22.83383	140.7456	16.43974
22.89883	140.7494	16.51095
22.96383	140.7529	16.58051
23.03050	140.7560	16.64709
23.09550	140.7608	16.71339
23.16217	140.7633	16.77574
23.22716	140.7672	16.83002
23.29216	140.7691	16.87869
23.35883	140.7721	16.92328
23.42383	140.7736	16.96534
23.48883	140.7816	17.25718
23.55550	140.7878	17.26573
23.62050	140.7876	17.26631
23.68716	140.7876	17.26445
23.75217	140.7875	17.26124
23.81716	140.7874	17.25498
23.88383	140.7861	17.24133
23.94883	140.7846	17.20111
24.01383	140.7813	17.14914
24.08050	140.7800	17.08080
24.14550	140.7766	17.01151
24.21216	140.7722	16.91882
24.27717	140.7676	16.80897
24.34216	140.7614	16.68129
24.40883	140.7549	16.54692
24.47383	140.7470	16.37510
24.53883	140.7373	16.18100
24.60550	140.7262	15.95608
24.67050	140.7130	15.71823
24.73550	140.7003	15.45440
24.80217	140.6855	15.15566
24.86716	140.6699	14.84299
24.93383	140.6524	14.50088
24.99883	140.6350	14.14039
25.06383	140.6162	13.76190
25.13050	140.5962	13.35476
25.19550	140.5764	12.94609
25.26050	140.5552	12.52216
25.32716	140.5333	12.07896
25.39216	140.5110	11.63840
25.45883	140.4877	11.18064
25.52383	140.4655	10.73436
25.58883	140.4430	10.28277
25.65550	140.4197	9.818305
25.72050	140.3967	9.372155
25.78550	140.3737	8.929236
25.85217	140.3510	8.481182
25.91716	140.3297	8.061006
25.98383	140.3075	7.624497
26.04883	140.2864	7.215410
26.11383	140.2656	6.808406
26.18050	140.2451	6.409820
26.24550	140.2256	6.030552
26.31050	140.2079	5.668089
26.37716	140.1896	5.305737
26.44216	140.1716	4.966907
26.50883	140.1543	4.636940
26.57383	140.1388	4.327178
26.63883	140.1239	4.030328
26.70550	140.1082	3.742953
26.77050	140.0954	3.473684
26.83550	140.0811	3.226030
26.90216	140.0690	2.981426
26.96716	140.0569	2.755968
27.03216	140.0456	2.540255
27.09883	140.0356	2.327310
27.16383	140.0259	2.135604
27.23050	140.0162	1.950618
27.29550	140.0080	1.779265
27.36050	139.9996	1.622261
27.42717	139.9911	1.465438
27.49216	139.9841	1.324567
27.55716	139.9777	1.189758
27.62383	139.9707	1.062360
27.68883	139.9644	0.9453594
27.75550	139.9589	0.8315009
27.82050	139.9533	0.7279601
27.88550	139.9484	0.6309199
27.95217	139.9428	0.5388134
28.01716	139.9389	0.4541836
28.08216	139.9347	0.3710118
28.14883	139.9307	0.2931984
28.21383	139.9270	0.2204747
28.28050	139.9235	0.1543267
28.34550	139.9195	0.09257801
28.41050	139.9172	0.03418052
28.47717	139.9134	-.02226484
28.54216	139.9114	-.07643524
28.60716	139.9084	-0.1255951
28.67383	139.9056	-0.1765011
28.73883	139.9036	-0.2175144
28.80550	139.9012	-0.2586341
28.87050	139.8994	-0.2991033
28.93550	139.8976	-0.3366134
29.00217	139.8962	-0.3733076
29.06716	139.8940	-0.4057182
29.13216	139.8925	-0.4356039
29.19883	139.8902	-0.4633596
29.26383	139.8883	-0.4915552
29.32883	139.8877	-0.5164691
29.39550	139.8862	-0.5408771
29.46050	139.8854	-0.5624863
29.52717	139.8833	-0.5892700
29.59216	139.8832	-0.6114216
29.65716	139.8813	-0.6321509
29.72383	139.8801	-0.6527375
29.78883	139.8798	-0.6717735
29.85383	139.8790	-0.6880522
29.92050	139.8776	-0.7050581
29.98550	139.8774	-0.7247758
30.05217	139.8766	-0.7401984
30.11716	139.8757	-0.7551900
30.18216	139.8743	-0.7676818
30.24883	139.8732	-0.7806658
30.31383	139.8732	-0.7928191
30.37883	139.8718	-0.8052112
30.44550	139.8706	-0.8173491
30.51050	139.8707	-0.8302130
30.57717	139.8698	-0.8427718
30.64216	139.8694	-0.8554988
30.70716	139.8687	-0.8674470
30.77383	139.8690	-0.8805668
30.83883	139.8682	-0.8922375
30.90383	139.8681	-0.9034592
30.97050	139.8676	-0.9149012
31.03550	139.8671	-0.9253387
31.10217	139.8669	-0.9357845
31.16716	139.8662	-0.9458390
31.23216	139.8654	-0.9553241
31.29883	139.8651	-0.9643212
31.36383	139.8648	-0.9724532
31.42883	139.8642	-0.9799045
31.49550	139.8635	-0.9873005
31.56050	139.8632	-0.9942856
31.62550	139.8632	-1.001344
31.69216	139.8620	-1.008469
31.75716	139.8627	-1.015226
31.82383	139.8618	-1.022294
31.88883	139.8617	-1.028843
31.95383	139.8608	-1.035319
32.02050	139.8610	-1.041602
32.08550	139.8611	-1.047793
32.15050	139.8606	-1.053906
32.21716	139.8599	-1.059684
32.28216	139.8598	-1.065130
32.34883	139.8602	-1.070498
32.41383	139.8599	-1.075725
32.47883	139.8595	-1.080704
32.54550	139.8594	-1.085792
32.61050	139.8600	-1.090678
32.67550	139.8592	-1.095556
32.74216	139.8593	-1.100231
32.80716	139.8593	-1.104764
32.87383	139.8584	-1.109165
32.93883	139.8584	-1.113321
33.00383	139.8594	-1.117178
33.07050	139.8588	-1.121118
33.13550	139.8572	-1.124370
33.20050	139.8590	-1.127313
33.26716	139.8577	-1.130586
33.33216	139.8572	-1.133580
33.39883	139.8571	-1.137030
33.46383	139.8578	-1.140547
33.52883	139.8572	-1.143999
33.59550	139.8572	-1.147472
33.66050	139.8570	-1.150442
33.72550	139.8566	-1.153254
33.79217	139.8574	-1.156043
33.85716	139.8564	-1.158837
33.92216	139.8568	-1.161805
33.98883	139.8569	-1.165121
34.05383	139.8569	-1.168324
34.12050	139.8563	-1.171366
34.18550	139.8559	-1.173955
34.25050	139.8558	-1.176490
34.31716	139.8555	-1.178740
34.38216	139.8550	-1.180105
34.44717	139.8559	-1.181651
34.51383	139.8553	-1.183398
34.57883	139.8555	-1.185645
34.64550	139.8553	-1.188080
34.71050	139.8546	-1.190444
34.77550	139.8552	-1.192704
34.84216	139.8549	-1.194726
34.90716	139.8543	-1.196615
34.97217	139.8546	-1.198578
35.03883	139.8543	-1.200686
35.10383	139.8540	-1.202960
35.17050	139.8542	-1.205204
35.23550	139.8541	-1.207472
35.30050	139.8551	-1.209782
35.36716	139.8548	-1.211861
35.43216	139.8546	-1.213852
35.49716	139.8543	-1.215682
35.56383	139.8539	-1.217384
35.62883	139.8544	-1.219321
35.69550	139.8540	-1.221036
35.76050	139.8542	-1.222635
35.82550	139.8541	-1.223802
35.89216	139.8540	-1.224720
35.95716	139.8540	-1.225968
36.02217	139.8534	-1.226848
36.08883	139.8534	-1.227854
36.15383	139.8530	-1.229036
36.21884	139.8535	-1.230241
36.28550	139.8542	-1.231619
36.35050	139.8536	-1.233108
36.41716	139.8529	-1.234490
36.48216	139.8536	-1.236026
36.54716	139.8547	-1.237202
36.61383	139.8524	-1.238288
36.67883	139.8532	-1.239384
36.74383	139.8535	-1.240629
36.81050	139.8526	-1.241920
36.87550	139.8532	-1.243242
36.94216	139.8522	-1.244085
37.00716	139.8527	-1.244940
37.07217	139.8526	-1.245974
37.13883	139.8526	-1.247585
37.20383	139.8530	-1.248965
37.26883	139.8528	-1.250466
37.33550	139.8527	-1.252303
37.40050	139.8526	-1.253478
37.46716	139.8528	-1.254074
37.53216	139.8523	-1.254448
37.59716	139.8523	-1.255004
37.66383	139.8524	-1.255562
37.72883	139.8524	-1.256012
37.79383	139.8516	-1.256680
37.86050	139.8525	-1.257632
37.92550	139.8523	-1.258786
37.99216	139.8525	-1.259821
38.05716	139.8525	-1.261073
38.12216	139.8522	-1.262487
38.18883	139.8522	-1.264207
38.25383	139.8531	-1.265752
38.31883	139.8527	-1.266637
38.38550	139.8521	-1.266683
38.45050	139.8519	-1.266784
38.51550	139.8517	-1.266667
38.58216	139.8524	-1.266825
38.64717	139.8510	-1.267421
38.71383	139.8523	-1.268075
38.77883	139.8519	-1.269048
38.84384	139.8514	-1.269864
38.91050	139.8514	-1.270372
38.97550	139.8519	-1.270854
39.04050	139.8511	-1.271300
39.10716	139.8522	-1.272019
39.17216	139.8517	-1.272888
39.23883	139.8518	-1.273798
39.30383	139.8517	-1.274706
39.36883	139.8514	-1.275382
39.43550	139.8517	-1.275745
39.50050	139.8511	-1.275854
39.56550	139.8509	-1.275838
39.63216	139.8510	-1.275942
39.69717	139.8509	-1.276352
39.76383	139.8510	-1.277006
39.82883	139.8507	-1.277452
39.89383	139.8508	-1.278345
39.96050	139.8514	-1.279502
40.02550	139.8520	-1.281234
40.09050	139.8520	-1.282260
40.15716	139.8518	-1.283338
40.22217	139.8519	-1.283936
40.28883	139.8512	-1.284531
40.35383	139.8518	-1.284867
40.41883	139.8517	-1.285356
40.48550	139.8517	-1.286068
40.55050	139.8519	-1.286155
40.61550	139.8514	-1.285994
40.68216	139.8512	-1.285875
40.74716	139.8511	-1.285663
40.81216	139.8514	-1.285830
40.87883	139.8506	-1.286117
40.94383	139.8520	-1.286720
41.01050	139.8510	-1.287496
41.07550	139.8512	-1.288260
41.14050	139.8515	-1.288930
41.20717	139.8512	-1.289559
41.27217	139.8512	-1.290082
41.33716	139.8519	-1.290319
41.40383	139.8506	-1.290504
41.46884	139.8506	-1.290825
41.53550	139.8509	-1.291172
41.60050	139.8504	-1.291294
41.66550	139.8505	-1.291430
41.73217	139.8510	-1.291687
41.79716	139.8511	-1.291798
41.86217	139.8513	-1.292158
41.92883	139.8507	-1.292651
41.99383	139.8512	-1.293283
42.06050	139.8508	-1.293731
42.12550	139.8512	-1.294196
42.19050	139.8509	-1.294710
42.25717	139.8505	-1.295102
42.32217	139.8512	-1.295772
42.38716	139.8508	-1.296370
42.45383	139.8515	-1.296968
42.51883	139.8517	-1.297329
42.58550	139.8516	-1.297912
42.65050	139.8515	-1.298700
42.71550	139.8517	-1.299280
42.78217	139.8504	-1.299362
42.84716	139.8504	-1.299428
42.91217	139.8508	-1.299383
42.97883	139.8507	-1.299304
43.04383	139.8507	-1.298812
43.10883	139.8501	-1.298432
43.17550	139.8505	-1.298720
43.24050	139.8509	-1.299026
43.30717	139.8500	-1.299282
43.37216	139.8505	-1.299685
43.43716	139.8503	-1.300269
43.50383	139.8511	-1.301019
43.56883	139.8506	-1.301820
43.63383	139.8506	-1.302830
43.70050	139.8505	-1.303765
43.76550	139.8510	-1.304455
43.83217	139.8512	-1.305036
43.89717	139.8515	-1.305458
43.96216	139.8511	-1.305817
44.02883	139.8511	-1.306335
44.09384	139.8500	-1.306042
44.15883	139.8514	-1.305685
44.22550	139.8504	-1.305249
44.29050	139.8503	-1.304900
44.35717	139.8508	-1.304944
44.42216	139.8509	-1.305158
44.48717	139.8504	-1.305237
44.55383	139.8501	-1.305366
44.61883	139.8511	-1.305776
44.68383	139.8505	-1.306474
44.75050	139.8512	-1.307113
44.81550	139.8508	-1.308027
44.88217	139.8505	-1.309009
44.94717	139.8507	-1.309497
45.01216	139.8503	-1.309096
45.07883	139.8500	-1.308550
45.14383	139.8507	-1.308166
45.20883	139.8506	-1.307775
45.27550	139.8500	-1.307539
45.34050	139.8505	-1.307838
45.40550	139.8506	-1.308322
45.47217	139.8504	-1.308901
45.53717	139.8494	-1.309415
45.60383	139.8507	-1.309600
45.66883	139.8499	-1.309410
45.73383	139.8501	-1.309513
45.80050	139.8496	-1.309741
45.86550	139.8499	-1.309898
45.93050	139.8490	-1.310144
45.99716	139.8503	-1.310690
46.06216	139.8498	-1.310949
46.12883	139.8498	-1.311513
46.19383	139.8502	-1.312192
46.25883	139.8506	-1.312742
46.32550	139.8500	-1.313070
46.39050	139.8501	-1.313273
46.45550	139.8501	-1.313592
46.52217	139.8503	-1.313831
46.58716	139.8509	-1.314172
46.65383	139.8498	-1.314654
46.71884	139.8507	-1.315043
46.78383	139.8511	-1.315496
46.85050	139.8514	-1.315953
46.91550	139.8510	-1.316513
46.98050	139.8504	-1.316792
47.04716	139.8506	-1.316859
47.11217	139.8499	-1.316746
47.17883	139.8504	-1.316126
47.24383	139.8505	-1.315460
47.30883	139.8504	-1.314979
47.37550	139.8508	-1.314755
47.44050	139.8506	-1.314709
47.50550	139.8500	-1.314926
47.57217	139.8506	-1.314799
47.63716	139.8501	-1.314430
47.70216	139.8504	-1.314596
47.76883	139.8502	-1.314781
47.83383	139.8503	-1.315055
47.90050	139.8500	-1.315417
47.96550	139.8504	-1.315826
48.03050	139.8510	-1.316272
48.09716	139.8505	-1.316468
48.16217	139.8504	-1.316612
48.22717	139.8501	-1.317080
48.29383	139.8507	-1.317772
48.35883	139.8512	-1.318343
48.42550	139.8502	-1.318394
48.49050	139.8502	-1.318601
48.55550	139.8506	-1.318925
48.62216	139.8506	-1.319280
48.68716	139.8509	-1.319525
48.75217	139.8506	-1.319929
48.81883	139.8503	-1.320248
48.88383	139.8503	-1.320449
48.95050	139.8498	-1.320420
49.01550	139.8500	-1.319982
49.08050	139.8498	-1.319641
49.14717	139.8497	-1.319266
49.21216	139.8502	-1.318988
49.27716	139.8504	-1.318796
49.34384	139.8505	-1.318469
49.40883	139.8489	-1.318408
49.47550	139.8499	-1.318704
49.54050	139.8498	-1.319086
49.60550	139.8504	-1.319703
49.67216	139.8491	-1.320306
49.73717	139.8494	-1.320962
49.80217	139.8499	-1.321624
49.86883	139.8498	-1.321948
49.93383	139.8497	-1.322384
49.99883	139.8501	-1.322636
50.06550	139.8499	-1.322700
50.13050	139.8504	-1.322765
50.19717	139.8500	-1.322860
50.26216	139.8500	-1.322886
50.32717	139.8498	-1.323180
50.39383	139.8505	-1.323522
50.45883	139.8495	-1.323636
50.52383	139.8497	-1.323846
50.59050	139.8498	-1.323960
50.65550	139.8504	-1.323847
50.72217	139.8501	-1.323975
50.78717	139.8493	-1.323927
50.85217	139.8504	-1.324110
50.91883	139.8501	-1.324450
50.98383	139.8506	-1.324689
51.04883	139.8502	-1.324910
51.11550	139.8500	-1.324908
51.18050	139.8506	-1.324827
51.24717	139.8503	-1.324643
51.31216	139.8505	-1.324389
51.37717	139.8504	-1.324080
51.44384	139.8502	-1.323759
51.50883	139.8501	-1.323615
51.57383	139.8494	-1.323436
51.64050	139.8501	-1.323562
51.70550	139.8502	-1.323967
51.77217	139.8503	-1.324144
51.83716	139.8504	-1.324319
51.90217	139.8502	-1.324692
51.96884	139.8502	-1.325044
52.03383	139.8502	-1.324870
52.09883	139.8507	-1.324990
52.16550	139.8501	-1.324908
52.23050	139.8500	-1.324902
52.29550	139.8501	-1.325174
52.36217	139.8507	-1.325480
52.42717	139.8514	-1.325859
52.49382	139.8494	-1.326006
52.55883	139.8502	-1.326036
52.62383	139.8504	-1.325933
52.69050	139.8502	-1.325823
52.75550	139.8507	-1.325891
52.82050	139.8502	-1.325749
52.88716	139.8503	-1.325798
52.95216	139.8495	-1.325541
53.01884	139.8503	-1.325488
53.08383	139.8501	-1.325439
53.14883	139.8501	-1.325224
53.21550	139.8503	-1.325078
53.28050	139.8498	-1.324941
53.34550	139.8502	-1.324880
53.41216	139.8504	-1.324819
53.47717	139.8495	-1.324815
53.54382	139.8498	-1.325130
53.60883	139.8504	-1.325471
53.67383	139.8496	-1.325755
53.74050	139.8496	-1.325777
53.80550	139.8500	-1.325827
53.87050	139.8504	-1.326054
53.93716	139.8502	-1.326342
54.00217	139.8500	-1.326614
54.06884	139.8500	-1.326500
54.13383	139.8502	-1.326725
54.19883	139.8502	-1.327230
54.26550	139.8496	-1.327437
54.33050	139.8511	-1.327924
54.39550	139.8497	-1.328228
54.46216	139.8494	-1.328321
54.52717	139.8499	-1.328263
54.59217	139.8505	-1.327990
54.65883	139.8501	-1.327653
54.72382	139.8501	-1.327502
54.79050	139.8500	-1.327604
54.85550	139.8499	-1.327829
54.92050	139.8496	-1.328038
54.98717	139.8500	-1.328488
55.05217	139.8496	-1.328536
55.11716	139.8503	-1.328887
55.18383	139.8497	-1.329009
55.24883	139.8499	-1.329205
55.31550	139.8501	-1.329387
55.38050	139.8506	-1.329654
55.44550	139.8500	-1.329675
55.51216	139.8506	-1.329615
55.57717	139.8505	-1.329525
55.64216	139.8500	-1.329334
55.70883	139.8502	-1.329484
55.77383	139.8500	-1.329434
55.84050	139.8506	-1.329458
55.90550	139.8500	-1.329835
55.97050	139.8498	-1.329955
56.03716	139.8497	-1.329746
56.10217	139.8488	-1.329226
56.16716	139.8494	-1.328586
56.23383	139.8494	-1.328156
56.29883	139.8499	-1.327950
56.36550	139.8493	-1.327932
56.43050	139.8499	-1.328309
56.49550	139.8492	-1.328940
56.56216	139.8500	-1.329322
56.62717	139.8493	-1.329902
56.69216	139.8492	-1.330273
56.75883	139.8499	-1.330684
56.82383	139.8499	-1.330959
56.88882	139.8502	-1.331155
56.95550	139.8499	-1.331379
57.02050	139.8509	-1.331399
57.08716	139.8494	-1.331588
57.15217	139.8504	-1.332108
57.21717	139.8503	-1.332547
57.28383	139.8504	-1.332952
57.34882	139.8498	-1.332989
57.41382	139.8500	-1.332820
57.48050	139.8501	-1.332612
57.54550	139.8504	-1.332254
57.61217	139.8494	-1.331689
57.67717	139.8500	-1.331262
57.74216	139.8497	-1.330897
57.80883	139.8497	-1.330838
57.87383	139.8505	-1.330901
57.93882	139.8503	-1.331385
58.00550	139.8504	-1.331537
58.07050	139.8504	-1.331850
58.13716	139.8502	-1.332193
58.20216	139.8503	-1.332486
58.26716	139.8503	-1.332462
58.33383	139.8512	-1.332894
58.39883	139.8507	-1.332934
58.46382	139.8504	-1.333092
58.53050	139.8505	-1.333269
58.59550	139.8506	-1.333322
58.66216	139.8501	-1.333553
58.72717	139.8499	-1.333156
58.79217	139.8505	-1.332709
58.85883	139.8502	-1.332076
58.92383	139.8502	-1.331876
58.98882	139.8499	-1.331515
59.05550	139.8505	-1.331495
59.12050	139.8502	-1.331734
59.18550	139.8508	-1.332030
59.25217	139.8499	-1.332277
59.31716	139.8501	-1.332596
59.38383	139.8497	-1.332559
59.44883	139.8499	-1.332381
59.51382	139.8496	-1.332017
59.58050	139.8504	-1.331811
59.64550	139.8496	-1.331452
59.71050	139.8504	-1.331438
59.77717	139.8495	-1.331402
59.84217	139.8495	-1.331432
59.90883	139.8496	-1.331399
59.97382	139.8496	-1.331512
60.03882	139.8500	-1.331516
60.10550	139.8496	-1.331612
60.17050	139.8499	-1.331837
60.23550	139.8492	-1.331797
60.30217	139.8498	-1.332138
60.36716	139.8504	-1.332901
60.43383	139.8500	-1.333446
60.49883	139.8505	-1.333661
60.56382	139.8505	-1.333937
60.63050	139.8506	-1.334158
60.69550	139.8500	-1.334267
60.76050	139.8503	-1.334363
60.82717	139.8502	-1.334686
60.89216	139.8505	-1.334748
60.95883	139.8505	-1.334704
61.02383	139.8500	-1.334534
61.08882	139.8505	-1.334328
61.15550	139.8503	-1.334094
61.22050	139.8506	-1.333782
61.28550	139.8497	-1.333493
61.35217	139.8500	-1.333140
61.41716	139.8496	-1.332886
61.48217	139.8501	-1.332640
61.54883	139.8498	-1.332665
61.61382	139.8500	-1.332421
61.68050	139.8496	-1.332469
61.74550	139.8494	-1.332533
61.81050	139.8500	-1.332518
61.87717	139.8502	-1.332616
61.94216	139.8500	-1.332813
62.00717	139.8503	-1.333151
62.07383	139.8491	-1.333473
62.13882	139.8501	-1.333815
62.20550	139.8503	-1.334357
62.27050	139.8495	-1.334759
62.33550	139.8499	-1.335230
62.40217	139.8506	-1.335664
62.46717	139.8506	-1.335544
62.53217	139.8504	-1.335253
62.59882	139.8503	-1.335048
62.66382	139.8506	-1.334864
62.73050	139.8502	-1.334611
62.79550	139.8497	-1.334596
62.86050	139.8498	-1.335028
62.92717	139.8501	-1.335140
62.99216	139.8496	-1.335271
63.05217	139.9042	-1.313116
63.11716	140.4493	-2.543524
63.18217	141.2286	-6.231934
63.24883	142.1501	-10.75878
63.31382	143.1250	-15.00970
63.38050	144.1897	-18.85390
63.44550	145.2751	-22.01476
63.51050	146.3998	-24.65044
63.57717	147.5851	-26.88820
63.64216	148.7662	-28.69028
63.70717	149.9671	-30.19004
63.77383	151.2155	-31.47944
63.83882	152.4458	-32.54216
63.90550	153.7192	-33.48570
63.97050	154.9692	-34.28384
64.03550	156.2262	-34.98858
64.10218	157.5215	-35.63361
64.16717	158.7880	-36.20345
64.23217	160.0573	-36.72129
64.29884	161.3640	-37.21855
64.36384	162.6396	-37.67346
64.43050	163.9501	-38.11526
64.49550	165.2300	-38.53786
64.56050	166.5105	-38.93582
64.62717	167.8247	-39.33619
64.69217	169.1064	-39.70682
64.75718	170.3887	-40.07200
64.82384	171.7059	-40.46136
64.88884	172.9901	-40.83997
64.95550	174.3065	-41.21263
65.02050	175.5906	-41.57881
65.08550	176.8749	-41.94545
65.15218	178.1914	-42.32780
65.21717	179.4758	-42.71654
65.28217	180.7588	-43.11440
65.34882	182.0736	-43.54533
65.41382	183.3562	-43.98450
65.47883	184.6388	-44.44782
65.54550	185.9534	-44.93691
65.61050	187.2337	-45.42727
65.67718	188.5475	-45.95670
65.74218	189.8273	-46.47432
65.80718	191.1046	-47.03829
65.87384	192.4148	-47.63030
65.93884	193.6906	-48.22665
66.00384	194.9649	-48.85165
66.07050	196.2694	-49.55316
66.13550	197.5413	-50.28504
66.20216	198.8420	-51.08364
66.26716	200.1082	-51.92079
66.33218	201.3713	-52.82968
66.39884	202.6634	-53.84742
66.46384	203.9192	-54.92370
66.52884	205.1715	-56.09676
66.59550	206.4503	-57.42258
66.66050	207.6917	-58.81666
66.72718	208.9611	-60.35891
66.79218	210.1903	-62.00972
66.85718	211.4123	-63.84520
66.92384	212.6541	-66.00964
66.98882	213.8499	-68.50388
67.05384	215.0266	-71.42115
67.12050	216.2122	-74.94372
67.18550	217.3376	-79.06020
67.25218	218.4557	-84.15003
67.31718	219.5047	-89.97788
67.38218	220.5173	-96.61866
67.44884	221.5255	-104.0015
67.51384	222.4997	-111.2325
67.57884	223.5140	-117.1410
67.64550	224.6944	-119.6025
67.71050	225.9976	-118.9592
67.77550	227.3978	-116.4470
67.84216	228.9133	-112.1178
67.90718	230.4620	-106.4347
67.97384	232.1289	-98.78472
68.03882	233.8264	-89.95018
68.10384	235.5243	-81.56589
68.17050	237.2035	-74.44116
68.23550	238.7761	-68.92908
68.30050	240.2922	-64.55893
68.36718	241.7998	-61.04449
68.43218	243.2348	-58.35270
68.49884	244.6784	-56.17646
68.56384	246.0631	-54.50172
68.62884	247.4304	-53.19828
68.69550	248.8194	-52.12734
68.76050	250.1625	-51.31209
68.82550	251.4975	-50.68558
68.89216	252.8592	-50.17434
68.95718	254.1810	-49.80362
69.02384	255.5322	-49.50894
69.08884	256.8472	-49.31322
69.15384	258.1589	-49.16641
69.22050	259.5010	-49.07850
69.28550	260.8091	-49.03412
69.35050	262.1138	-49.01018
69.41718	263.4526	-49.00379
69.48218	264.7572	-49.00234
69.54884	266.0932	-49.01431
69.61384	267.3955	-49.05812
69.67884	268.6976	-49.12248
69.74550	270.0324	-49.19912
69.81050	271.3339	-49.26178
69.87550	272.6347	-49.32844
69.94218	273.9696	-49.40348
70.00050	275.1367	-49.47726
70.06718	276.1975	-49.32051
70.13218	276.2430	-42.89868
70.19884	275.9111	-31.70466
70.26384	275.3705	-20.22131
70.32884	274.6806	-9.878622
70.39550	273.8520	-0.9014278
70.46050	272.9514	6.300169
70.52550	271.9782	12.17947
70.59216	270.9160	17.08236
70.65718	269.8334	20.95038
70.72384	268.6825	24.17710
70.78882	267.5291	26.72990
70.85384	266.3514	28.82089
70.92050	265.1206	30.57607
70.98550	263.9036	31.97260
71.05050	262.6738	33.12512
71.11718	261.4004	34.09434
71.18218	260.1490	34.87930
71.24884	258.8590	35.53337
71.31384	257.5950	36.06482
71.37884	256.3259	36.50105
71.44550	255.0198	36.88166
71.51050	253.7433	37.19960
71.57550	252.4636	37.46313
71.64216	251.1484	37.68755
71.70718	249.8640	37.86452
71.77218	248.5780	38.01936
71.83884	247.2591	38.15318
71.90384	245.9718	38.25558
71.97050	244.6486	38.35297
72.03550	243.3594	38.41714
72.10050	242.0686	38.47008
72.16718	240.7440	38.50464
72.23218	239.4519	38.53549
72.29718	238.1602	38.56905
72.36384	236.8348	38.59185
72.42884	235.5418	38.61899
72.49550	234.2160	38.62850
72.56050	232.9229	38.63560
72.62550	231.6292	38.64090
72.69218	230.3022	38.64541
72.75718	229.0065	38.64772
72.82218	227.7130	38.64883
72.88884	226.3848	38.65086
72.95384	225.0900	38.65120
73.02050	223.7630	38.65272
73.08550	222.4680	38.65238
73.15050	221.1732	38.65070
73.21718	219.8448	38.64758
73.28218	218.5504	38.64486
73.34718	217.2551	38.64017
73.41382	215.9273	38.63233
73.47884	214.6322	38.62410
73.54550	213.3030	38.61375
73.61050	212.0083	38.59806
73.67550	210.7125	38.58440
73.74218	209.3841	38.56709
73.80718	208.0884	38.54639
73.87218	206.7932	38.52706
73.93884	205.4654	38.50379
74.00384	204.1700	38.48645
74.06884	202.8754	38.46548
74.13550	201.5466	38.43794
74.20050	200.2525	38.41660
74.26716	198.9231	38.40090
74.33218	197.6276	38.38578
74.39718	196.3319	38.36320
74.46384	195.0034	38.34355
74.52884	193.7076	38.33164
74.59384	192.4120	38.31800
74.66050	191.0817	38.29964
74.72551	189.7866	38.27246
74.79218	188.4577	38.25060
74.85718	187.1617	38.22658
74.92218	185.8648	38.20622
74.98882	184.5359	38.18060
75.05384	183.2398	38.14382
75.11884	181.9437	38.12275
75.18550	180.6141	38.09866
75.25050	179.3176	38.08256
75.31718	177.9882	38.06395
75.38218	176.6913	38.05053
75.44718	175.3956	38.03720
75.51384	174.0648	38.02474
75.57884	172.7688	38.00535
75.64384	171.4718	37.96424
75.71050	170.1427	37.92762
75.77550	168.8466	37.91438
75.84216	167.5189	37.90960
75.90718	166.2294	37.99414
75.97218	164.9476	38.39355
76.03882	163.6631	39.52626
76.10384	162.4752	42.20081
76.16884	161.3987	47.38540
76.23550	160.4381	55.62270
76.30050	159.6084	65.41223
76.36550	158.7915	74.85849
76.43218	157.8699	82.34694
76.49718	156.8351	86.68801
76.56384	155.6186	87.98363
76.62884	154.2904	86.45439
76.69384	152.8520	82.95236
76.76050	151.3066	78.21494
76.82550	149.7685	73.22481
76.89050	148.2330	68.42212
76.95718	146.6778	63.97706
77.02218	145.1871	60.18426
77.08884	143.6850	56.82432
77.15384	142.2435	53.99277
77.21884	140.8226	51.58050
77.28550	139.3842	49.45657
77.35050	137.9547	46.78504
77.41550	136.5820	45.39059
77.48218	135.1889	44.14085
77.54718	133.8385	43.10200
77.61384	132.4608	42.16628
77.67884	131.1221	41.36098
77.74384	129.7907	40.65402
77.81050	128.4270	39.99473
77.87550	127.1013	39.43596
77.94050	125.7789	38.90882
78.00718	124.4240	38.42126
78.07218	123.1075	38.01240
78.13884	121.7574	37.58090
78.20384	120.4419	37.14184
78.26882	119.1226	36.65538
78.33550	117.7675	36.14761
78.40050	116.4458	35.68074
78.46550	115.1280	35.25260
78.53218	113.7836	35.04740
78.59718	112.4840	34.98372
78.66218	111.1844	34.89725
78.72884	109.8506	34.78225
78.79384	108.5492	34.66312
78.86050	107.2142	34.51692
78.92550	105.9096	34.35339
78.99050	104.6062	34.16692
79.05718	103.2678	33.98611
79.12218	101.9631	33.81076
79.18718	100.6593	33.64116
79.25384	99.31984	33.47280
79.31884	98.01624	33.30088
79.38550	96.67919	33.14920
79.45050	95.37516	32.98134
79.51550	94.07160	32.82042
79.58218	92.73414	32.65528
79.64718	91.42954	32.49060
79.71218	90.12559	32.32186
79.77884	88.78874	32.14870
79.84384	87.48534	31.98608
79.91050	86.14862	31.82127
79.97551	84.84455	31.66754
80.04050	83.54200	31.50855
80.10718	82.20295	31.35430
80.17218	80.89998	31.19476
80.23718	79.59613	31.03584
80.30384	78.25884	30.88193
80.36884	76.95464	30.72882
80.43550	75.61824	30.57896
80.50050	74.31506	30.43219
80.56550	73.01030	30.29004
80.63218	71.67374	30.13298
80.69718	70.37044	29.98924
80.76218	69.06650	29.84033
80.82884	67.73013	29.68734
80.89384	66.42813	29.53240
80.95884	65.12295	29.38982
81.02550	63.78571	29.23246
81.09050	62.48179	29.07486
81.15718	61.13470	28.63651
81.22218	59.82800	28.50330
81.28718	58.51760	28.21660
81.35384	57.17856	28.06316
81.41884	55.87390	27.90901
81.48384	54.56693	27.63352
81.55050	53.22659	27.49885
81.61550	51.92402	27.38530
81.68218	50.58961	27.26941
81.74718	49.28724	27.13881
81.81216	47.98494	27.02552
81.87884	46.64852	26.90851
81.94384	45.34598	26.79260
82.00884	44.04324	26.67631
82.07550	42.70667	26.54525
82.14050	41.40400	26.41202
82.20718	40.06611	26.27656
82.27218	38.76246	26.13789
82.33718	37.45888	25.98469
82.40384	36.12030	25.81765
82.46884	34.81505	25.66470
82.53384	33.51126	25.49300
82.60050	32.16855	25.27473
82.66550	30.86459	25.12858
82.73218	29.52600	24.98406
82.79718	28.22128	24.82155
82.86218	26.91526	24.65408
82.92882	25.57561	24.47846
82.99384	24.26851	24.30090
83.05718	23.16840	24.72302
83.12218	23.11371	24.09352
83.18884	23.47140	19.26480
83.25384	24.04720	13.24811
83.31884	24.76456	7.147716
83.38550	25.61140	1.551562
83.45050	26.52947	-3.054878
83.51550	27.52219	-6.872694
83.58218	28.59916	-10.08280
83.64718	29.69695	-12.64226
83.71218	30.82980	-14.73702
83.77884	32.02167	-16.51153
83.84384	33.20808	-17.94716
83.91050	34.44256	-19.17678
83.97551	35.66328	-20.18978
84.04051	36.89510	-21.05466
84.10718	38.17019	-21.82219
84.17218	39.42145	-22.45988
84.23718	40.67899	-23.01655
84.30382	41.97547	-23.51504
84.36884	43.24473	-23.93406
84.43550	44.55026	-24.32094
84.50050	45.82670	-24.65750
84.56551	47.10634	-24.96309
84.63218	48.42272	-25.25580
84.69718	49.70632	-25.51340
84.76218	50.99247	-25.75592
84.82884	52.31287	-25.99188
84.89384	53.60156	-26.20566
84.96051	54.92382	-26.40934
85.02550	56.21362	-26.60260
85.09051	57.50508	-26.79293
85.15718	58.83000	-26.98645
85.22218	60.12190	-27.16817
85.28718	61.41384	-27.35320
85.35382	62.74114	-27.54340
85.41884	64.03474	-27.72039
85.48551	65.36262	-27.89074
85.55051	66.65600	-28.05352
85.61551	67.95078	-28.22713
85.68218	69.27884	-28.38791
85.74718	70.57300	-28.55905
85.81218	71.86669	-28.71990
85.87882	73.19485	-28.89790
85.94384	74.48934	-29.06068
86.00884	75.78224	-29.22639
86.07550	77.11040	-29.40039
86.14051	78.40388	-29.57632
86.20718	79.73194	-29.75224
86.27218	81.02660	-29.92880
86.33718	82.32100	-30.10558
86.40384	83.64812	-30.28596
86.46884	84.94251	-30.46678
86.53384	86.23590	-30.65506
86.60050	87.56389	-30.85202
86.66550	88.85759	-31.03724
86.73218	90.18418	-31.23969
86.79718	91.47813	-31.42672
86.86218	92.77247	-31.61228
86.92882	94.09913	-31.79826
86.99384	95.39280	-31.99447
87.05884	96.68719	-32.19420
87.12550	98.01359	-32.38247
87.19051	99.30645	-32.57770
87.25718	100.6327	-32.77731
87.32218	101.9255	-32.98770
87.38718	103.2180	-33.19888
87.45382	104.5444	-33.39752
87.51882	105.8402	-33.55190
87.58384	107.1386	-33.63960
87.65051	108.4701	-33.72300
87.71551	109.7701	-33.78806
87.78218	111.1025	-33.89152
87.84718	112.4022	-33.99507
87.91218	113.7004	-34.11078
87.97882	115.0312	-34.23169
88.04384	116.3288	-34.36400
88.10884	117.6252	-34.49527
88.17551	118.9557	-34.64090
88.24051	120.2514	-34.79534
88.30549	121.5475	-34.95413
88.37218	122.8764	-35.12996
88.43718	124.1717	-35.30767
88.50384	125.5004	-35.48712
88.56884	126.7954	-35.66527
88.63384	128.0899	-35.84334
88.70050	129.4177	-36.02238
88.76551	130.7119	-36.20484
88.83051	132.0056	-36.40228
88.89718	133.3323	-36.59509
88.96218	134.6260	-36.80066
89.02884	135.9521	-37.02230
89.09384	137.2450	-37.23874
89.15884	138.5384	-37.45122
89.22551	139.8655	-37.67708
89.29051	141.1570	-37.89954
89.35550	142.4494	-38.13088
89.42218	143.7746	-38.37302
89.48718	145.0665	-38.60861
89.55382	146.3919	-38.85362
89.61884	147.6838	-39.10835
89.68384	148.9750	-39.35812
89.75050	150.2979	-39.62156
89.81551	151.5879	-39.89641
89.88050	152.8770	-40.18680
89.94718	154.1984	-40.50717
90.01218	155.4870	-40.84233
90.07884	156.8072	-41.20517
90.14384	158.0934	-41.59832
90.20882	159.3752	-42.06104
90.27550	160.6845	-42.72594
90.34051	161.9436	-43.76953
90.40551	163.1822	-45.25632
90.47218	164.4372	-46.99898
90.53718	165.6782	-47.85993
90.60218	166.9911	-47.59090
90.66884	168.3428	-47.31600
90.73382	169.6595	-47.07012
90.80051	171.0076	-46.87738
90.86551	172.3194	-46.74483
90.93051	173.6288	-46.68440
90.99718	174.9666	-46.66728
91.06218	176.2692	-46.67809
91.12718	177.5697	-46.79029
91.19384	178.8999	-46.95254
91.25884	180.1930	-47.17514
91.32550	181.5158	-47.47706
91.39051	182.8037	-47.84176
91.45551	184.0874	-48.27080
91.52218	185.4012	-48.79330
91.58718	186.6790	-49.37470
91.65218	187.9525	-50.04586
91.71884	189.2535	-50.84309
91.78384	190.5172	-51.73863
91.85050	191.8062	-52.79363
91.91550	193.0585	-53.96998
91.98050	194.3033	-55.27694
92.04718	195.5744	-56.70934
92.11218	196.8112	-58.17286
92.17718	198.0464	-59.67176
92.24384	199.3102	-61.23888
92.30884	200.5413	-62.84144
92.37550	201.7992	-64.59078
92.44051	203.0199	-66.46202
92.50551	204.2330	-68.44831
92.57218	205.4734	-70.56343
92.63718	206.6832	-72.59529
92.70216	207.9025	-74.34492
92.76882	209.1822	-75.39688
92.83384	210.4875	-74.98894
92.89884	211.8727	-72.81716
92.96551	213.3646	-69.19715
93.03051	214.8574	-65.01312
93.09718	216.3924	-60.86809
93.16218	217.8611	-57.51421
93.22718	219.2982	-54.82160
93.29384	220.7437	-52.64018
93.35884	222.1297	-50.98120
93.42384	223.4980	-49.69336
93.49051	224.8866	-48.66587
93.55549	226.2282	-47.88033
93.62218	227.5949	-47.28248
93.68718	228.9198	-46.84413
93.75218	230.2377	-46.56360
93.81884	231.5852	-46.38554
93.88384	232.8942	-46.33646
93.94884	234.2038	-46.20429
94.01551	235.5466	-46.10164
94.08051	236.8548	-46.02734
94.14718	238.1951	-45.97470
94.21218	239.5005	-45.93584
94.27718	240.8052	-45.92300
94.34384	242.1433	-45.92200
94.40884	243.4462	-45.93549
94.47384	244.7488	-45.97248
94.54051	246.0854	-46.01468
94.60550	247.3876	-46.06882
94.67218	248.7229	-46.11040
94.73718	250.0238	-46.15580
94.80218	251.3251	-46.21664
94.86884	252.6592	-46.28000
94.93384	253.9598	-46.34734
94.99884	255.2602	-46.41720
95.06551	256.5942	-46.50296
95.13050	257.8943	-46.58580
95.19550	259.1938	-46.66776
95.26218	260.5270	-46.76998
95.32718	261.8257	-46.85698
95.39384	263.1595	-46.96458
95.45882	264.4591	-47.04770
95.52384	265.7584	-47.14844
95.59051	267.0925	-47.24772
95.65551	268.3923	-47.35162
95.72051	269.6922	-47.46242
95.78718	271.0240	-47.55481
-2.000000	5.000000	0.0000000