File: 3-C1(1.0mol%)+C20(0.6mol%)/matlab/140-2
CLOSED
Version	1.0
Language	English
Mode	Standard
Run	2
RunSerial	11783
Instrument	DSC Q2000 V24.11 Build 124
Module	DSC Standard Cell RC
Operator	Nan
File	\\Ae520-1454\ta\Data\DSC\UQ Composites\Nan\C1(4.5)+C20P(3)+CL(HotplateMixtureAB)\Iso140_60Min_2
ProcName	H/C/H/C/H complete wood PHA
InstSerial	2000-0883
AutoSerial	1293
Sample	Iso140_60Min
Size	48.2000	mg
PanMass	Not available
PanResist	Automatic Automatic  K/W
PanFactor	Default Default
Method	H/C/H/C/H complete wood PHA
Comment
Xcomment	Pan: Tzero Aluminum Hermetic
Xcomment	Gas1: Nitrogen 50.0 ml/min
Xcomment	Gas2: Nitrogen 50.0 ml/min
Text
Exotherm	UP
Kcell	1.05230
Cpconst	Standard: 0.938
Calib	-38.6961
TempCal	1	pts	157.46	156.60
TzeroDt	-87.6168 -0.0009 -1.4231
TzeroDtz	-87.6168 0.0057 6.9570
InstCalFile	Tzero: \\Ae520-1454\ta\Data\DSC\Calibration\2017\CALIBRATION\1562_RCS (90)_05_18_2017 10_50_44.TZR
InstCalFile	Baseline: \\Ae520-1454\ta\Data\DSC\Calibration\2017\2017-05-17_Calibration.001
InstCalFile	Sapphire: \\Ae520-1454\ta\Data\DSC\Calibration\2017\2017-05-17_Saphire.001
InstCalDate	Tzero 2017-05-18 Time 10:50:44
TempRange	-87.39 to 398.39 °C at 10.00 °C/min Heat Only
AutoZero	Delta T Offset 0.000 uV
AutoZero	Delta T0 Offset 0.000 uV
MultiptCal	0
MultiPtDesc	0) Not set
AutoCellConst	Calibration Date 2017-05-18 16:59:28
Controls	Gas 1  Event Off  Sampling 0.2
Cell#	RC-01562
CoolingUnit	RCS (90)
SelHeatFlow	Heat Flow T4 (mW)
AutoLidII	Installed
AutoAnalysis	Off
MacroFile
Nsig	3
Sig1	Time (min)
Sig2	Temperature (°C)
Sig3	Heat Flow (mW)
Date	2017-06-07
Time	12:52:27
OrgMethod	1: Equilibrate at 20.00 °C
OrgMethod	2: Ramp 40.00 °C/min to 140.00 °C
OrgMethod	3: Mark end of cycle 1
OrgMethod	4: Isothermal for 60.00 min
OrgMethod	5: Mark end of cycle 2
OrgMethod	6: Ramp 20.00 °C/min to 280.00 °C
OrgMethod	7: Mark end of cycle 3
OrgMethod	8: Ramp 20.00 °C/min to 20.00 °C
OrgMethod	9: Mark end of cycle 4
OrgMethod	10: Ramp 20.00 °C/min to 280.00 °C
OrgMethod	11: Mark end of cycle 5
OrgFile	C:\Users\jarra\Desktop\DSC\3-C1(1.0mol%)+C20(0.6mol%)\140-2
StartOfData
4.99994E-4	20.05159	0.8068853
0.06716666	20.31142	1.273760
0.1321667	21.63954	-0.2846262
0.1988333	23.36978	-5.206974
0.2638334	25.28184	-10.87360
0.3288334	27.33113	-16.31580
0.3955000	29.54529	-21.24278
0.4605000	31.78690	-25.28744
0.5255000	34.09446	-28.67730
0.5921668	36.51391	-31.57194
0.6571668	38.91197	-33.98899
0.7238332	41.40098	-36.17894
0.7888332	43.83872	-38.37824
0.8538332	46.27083	-40.70560
0.9205000	48.79258	-42.57744
0.9854999	51.26928	-44.29218
1.050500	53.74578	-46.21374
1.117166	56.28584	-48.09889
1.182166	58.77822	-49.80160
1.248833	61.33120	-51.77282
1.313833	63.80038	-54.26052
1.378833	66.21818	-57.90172
1.445500	68.59444	-63.93074
1.510500	70.73479	-73.45281
1.575500	72.64372	-87.39459
1.642166	74.43952	-103.6699
1.707167	76.09397	-121.9324
1.772167	77.67706	-139.9854
1.838833	79.51194	-154.2195
1.903833	81.51404	-164.1883
1.970500	83.55512	-175.5114
2.035500	86.02381	-176.5831
2.100500	88.55910	-178.8554
2.167167	91.13388	-181.0823
2.232167	93.73738	-180.8604
2.297166	96.53762	-176.1270
2.363834	99.99282	-158.3546
2.428833	103.5794	-141.4172
2.495500	107.0641	-127.7011
2.560500	110.3041	-117.0095
2.625500	113.4154	-108.5047
2.692167	116.4984	-101.6169
2.757167	119.4222	-96.30505
2.822166	122.2776	-92.25909
2.888834	125.1482	-89.15219
2.953833	127.9007	-86.88806
3.017166	130.5503	-85.23578
3.082167	132.7725	-84.20761
3.147167	134.0455	-78.35322
3.213833	135.0399	-69.22472
3.278833	135.8054	-59.88076
3.343834	136.4422	-50.76310
3.410500	136.9879	-42.98534
3.475500	137.4003	-37.02219
3.542167	137.7390	-32.12034
3.607167	138.0070	-28.30459
3.672167	138.2275	-25.20513
3.738834	138.4143	-22.62115
3.803833	138.5659	-20.57424
3.868833	138.6911	-18.89837
3.935500	138.7985	-17.48618
4.000500	138.8859	-16.35246
4.065500	138.9600	-15.40715
4.132167	139.0239	-14.59926
4.197166	139.0761	-13.93386
4.263834	139.1233	-13.35831
4.328834	139.1612	-12.88482
4.393833	139.1942	-12.47640
4.460500	139.2234	-12.11736
4.525500	139.2472	-11.81680
4.590500	139.2688	-11.55707
4.657166	139.2872	-11.32782
4.722168	139.3036	-11.12681
4.788834	139.3177	-10.94826
4.853833	139.3299	-10.79182
4.918833	139.3411	-10.66004
4.985500	139.3509	-10.52945
5.050500	139.3597	-10.41767
5.115500	139.3675	-10.31525
5.182167	139.3744	-10.21536
5.247168	139.3823	-10.12316
5.313832	139.3878	-10.03250
5.378834	139.3940	-9.946608
5.443832	139.3993	-9.866788
5.510500	139.4052	-9.785591
5.575500	139.4101	-9.707431
5.640500	139.4144	-9.626446
5.707168	139.4205	-9.542725
5.772168	139.4250	-9.460965
5.838832	139.4301	-9.373653
5.903834	139.4342	-9.286528
5.968834	139.4395	-9.195659
6.035500	139.4453	-9.100356
6.100500	139.4500	-9.004996
6.165500	139.4563	-8.907745
6.232168	139.4616	-8.807750
6.297168	139.4667	-8.713741
6.362168	139.4716	-8.614093
6.428832	139.4776	-8.511069
6.493834	139.4820	-8.413620
6.560500	139.4880	-8.311329
6.625500	139.4934	-8.213897
6.690500	139.4979	-8.111806
6.757168	139.5039	-8.013113
6.822168	139.5094	-7.913976
6.887168	139.5142	-7.811678
6.953832	139.5202	-7.707406
7.018832	139.5255	-7.605719
7.085500	139.5312	-7.493544
7.150500	139.5364	-7.389462
7.215500	139.5416	-7.276030
7.282166	139.5488	-7.142832
7.347168	139.5560	-7.001656
7.412168	139.5631	-6.848160
7.478832	139.5716	-6.673059
7.543832	139.5817	-6.492328
7.610500	139.5911	-6.280584
7.675500	139.6022	-6.066730
7.740500	139.6139	-5.834887
7.807166	139.6273	-5.570907
7.872168	139.6411	-5.302084
7.937166	139.6548	-5.012910
8.003834	139.6705	-4.708330
8.068832	139.6861	-4.404118
8.135500	139.7016	-4.098100
8.200500	139.7169	-3.796521
8.265500	139.7322	-3.503084
8.332168	139.7470	-3.214255
8.397168	139.7598	-2.945375
8.462168	139.7744	-2.699913
8.528832	139.7864	-2.468089
8.593832	139.7974	-2.259584
8.658832	139.8073	-2.064589
8.725500	139.8168	-1.879894
8.790500	139.8258	-1.721056
8.857166	139.8330	-1.577234
8.922168	139.8394	-1.458047
8.987168	139.8452	-1.360156
9.053832	139.8500	-1.271626
9.118834	139.8541	-1.197877
9.183832	139.8582	-1.135192
9.250500	139.8607	-1.077672
9.315500	139.8638	-1.031273
9.382166	139.8658	-0.9909301
9.447168	139.8678	-0.9541222
9.512168	139.8692	-0.9221298
9.578832	139.8714	-0.8928100
9.643832	139.8727	-0.8700941
9.708832	139.8746	-0.8471828
9.775499	139.8754	-0.8264548
9.840500	139.8769	-0.8091104
9.907166	139.8771	-0.7905902
9.972168	139.8788	-0.7744936
10.03717	139.8803	-0.7590456
10.10383	139.8803	-0.7439170
10.16883	139.8814	-0.7288337
10.23383	139.8826	-0.7152337
10.30050	139.8828	-0.7017289
10.36550	139.8835	-0.6884936
10.43217	139.8847	-0.6749824
10.49717	139.8842	-0.6614956
10.56216	139.8858	-0.6488324
10.62884	139.8869	-0.6362726
10.69383	139.8874	-0.6243918
10.75883	139.8880	-0.6124588
10.82550	139.8883	-0.5992320
10.89050	139.8892	-0.5876695
10.95550	139.8895	-0.5763264
11.02217	139.8894	-0.5646226
11.08717	139.8902	-0.5531850
11.15383	139.8906	-0.5417533
11.21884	139.8922	-0.5309578
11.28383	139.8919	-0.5203035
11.35050	139.8924	-0.5091088
11.41550	139.8934	-0.4983332
11.48050	139.8942	-0.4879958
11.54717	139.8948	-0.4769626
11.61217	139.8956	-0.4662512
11.67883	139.8964	-0.4553691
11.74384	139.8969	-0.4446740
11.80884	139.8972	-0.4341400
11.87550	139.8976	-0.4231416
11.94050	139.8986	-0.4124680
12.00550	139.8989	-0.4018899
12.07217	139.8990	-0.3911194
12.13717	139.9006	-0.3805313
12.20384	139.9002	-0.3698218
12.26883	139.9011	-0.3592005
12.33383	139.9024	-0.3488365
12.40050	139.9027	-0.3381896
12.46550	139.9033	-0.3276568
12.53050	139.9041	-0.3166868
12.59717	139.9041	-0.3051501
12.66217	139.9052	-0.2939869
12.72884	139.9051	-0.2826209
12.79384	139.9057	-0.2713711
12.85883	139.9067	-0.2604390
12.92550	139.9074	-0.2488310
12.99050	139.9075	-0.2374810
13.05550	139.9088	-0.2263654
13.12217	139.9092	-0.2149420
13.18716	139.9099	-0.2034276
13.25217	139.9101	-0.1922147
13.31884	139.9107	-0.1805741
13.38383	139.9120	-0.1692096
13.45050	139.9128	-0.1577000
13.51550	139.9131	-0.1464128
13.58050	139.9136	-0.1347612
13.64717	139.9138	-0.1225988
13.71217	139.9149	-0.1100597
13.77717	139.9148	-.09750137
13.84383	139.9156	-.08548819
13.90883	139.9164	-.07343031
13.97550	139.9176	-.06139879
14.04050	139.9178	-.04898779
14.10550	139.9187	-.03725053
14.17217	139.9201	-.02514045
14.23716	139.9208	-.01339891
14.30217	139.9218	-9.8254E-4
14.36884	139.9221	0.01294096
14.43383	139.9231	0.02748164
14.50050	139.9236	0.04274530
14.56550	139.9247	0.05645888
14.63050	139.9240	0.07149481
14.69717	139.9258	0.08606945
14.76217	139.9261	0.1017623
14.82717	139.9268	0.1176320
14.89383	139.9283	0.1324301
14.95883	139.9285	0.1481885
15.02550	139.9297	0.1651624
15.09050	139.9311	0.1844218
15.15550	139.9318	0.2061598
15.22217	139.9336	0.2266852
15.28717	139.9346	0.2481568
15.35217	139.9360	0.2692936
15.41883	139.9374	0.2984766
15.48383	139.9380	0.3331977
15.54884	139.9396	0.3683162
15.61550	139.9405	0.4076063
15.68050	139.9427	0.4455064
15.74717	139.9448	0.4850930
15.81216	139.9459	0.5303222
15.87716	139.9479	0.5752212
15.94384	139.9512	0.6226277
16.00883	139.9527	0.6717658
16.07383	139.9549	0.7246036
16.14050	139.9580	0.7793528
16.20550	139.9610	0.8351678
16.27216	139.9641	0.8906641
16.33716	139.9675	0.9488586
16.40216	139.9701	1.008491
16.46883	139.9730	1.069392
16.53383	139.9763	1.129946
16.59883	139.9792	1.186507
16.66550	139.9819	1.248003
16.73050	139.9849	1.303534
16.79716	139.9878	1.360051
16.86216	139.9906	1.416838
16.92716	139.9929	1.470900
16.99383	139.9967	1.522781
17.05883	139.9986	1.576333
17.12383	140.0014	1.627182
17.19050	140.0038	1.679559
17.25550	140.0064	1.725987
17.32216	140.0091	1.774830
17.38716	140.0120	1.821350
17.45216	140.0139	1.866128
17.51883	140.0164	1.914253
17.58383	140.0184	1.959356
17.64883	140.0209	2.003053
17.71550	140.0236	2.044908
17.78050	140.0258	2.089686
17.84550	140.0279	2.131146
17.91217	140.0305	2.176410
17.97716	140.0324	2.219568
18.04383	140.0346	2.262399
18.10883	140.0370	2.304628
18.17383	140.0386	2.350635
18.24050	140.0410	2.393750
18.30550	140.0435	2.436033
18.37050	140.0458	2.476951
18.43716	140.0477	2.522400
18.50216	140.0505	2.561998
18.56883	140.0530	2.604942
18.63383	140.0552	2.649970
18.69884	140.0576	2.692313
18.76550	140.0599	2.736862
18.83050	140.0620	2.781867
18.89550	140.0645	2.826740
18.96216	140.0668	2.871796
19.02716	140.0694	2.917560
19.09383	140.0714	2.965040
19.15883	140.0737	3.011637
19.22383	140.0759	3.056758
19.29050	140.0781	3.107377
19.35550	140.0802	3.159640
19.42050	140.0821	3.207488
19.48716	140.0847	3.256680
19.55216	140.0869	3.309430
19.61883	140.0896	3.359106
19.68383	140.0920	3.411575
19.74883	140.0943	3.460803
19.81550	140.0973	3.512979
19.88050	140.1000	3.563078
19.94550	140.1026	3.613428
20.01216	140.1054	3.668200
20.07716	140.1086	3.720811
20.14216	140.1105	3.774796
20.20883	140.1138	3.827032
20.27383	140.1164	3.881837
20.34050	140.1196	3.939520
20.40550	140.1221	3.990776
20.47050	140.1258	4.044570
20.53717	140.1286	4.098534
20.60216	140.1315	4.151801
20.66716	140.1346	4.203591
20.73383	140.1374	4.258076
20.79883	140.1395	4.313937
20.86550	140.1426	4.369320
20.93050	140.1452	4.425717
20.99550	140.1472	4.479012
21.06216	140.1500	4.534076
21.12716	140.1527	4.585146
21.19216	140.1551	4.637050
21.25883	140.1575	4.687132
21.32383	140.1602	4.736250
21.39050	140.1631	4.782688
21.45550	140.1658	4.829736
21.52050	140.1684	4.877590
21.58716	140.1704	4.924604
21.65216	140.1727	4.973578
21.71716	140.1742	5.020139
21.78383	140.1766	5.069931
21.84883	140.1791	5.114320
21.91550	140.1810	5.159870
21.98050	140.1837	5.203100
22.04550	140.1859	5.247309
22.11216	140.1886	5.291606
22.17717	140.1901	5.332278
22.24216	140.1928	5.371700
22.30883	140.1950	5.417329
22.37383	140.1968	5.460457
22.43883	140.1992	5.502250
22.50550	140.2013	5.544660
22.57050	140.2046	5.581899
22.63716	140.2058	5.623944
22.70216	140.2084	5.665488
22.76716	140.2099	5.706921
22.83383	140.2124	5.751184
22.89883	140.2144	5.794705
22.96383	140.2171	5.834597
23.03050	140.2182	5.878636
23.09550	140.2204	5.918375
23.16217	140.2221	5.963548
23.22716	140.2241	6.006124
23.29216	140.2266	6.046594
23.35883	140.2290	6.091358
23.42383	140.2308	6.133094
23.48883	140.2331	6.173992
23.55550	140.2349	6.217244
23.62050	140.2377	6.257688
23.68716	140.2387	6.303385
23.75217	140.2419	6.343340
23.81716	140.2436	6.385028
23.88383	140.2468	6.427363
23.94883	140.2481	6.469488
24.01383	140.2506	6.511156
24.08050	140.2528	6.553088
24.14550	140.2548	6.595454
24.21216	140.2573	6.637411
24.27717	140.2592	6.680656
24.34216	140.2616	6.720344
24.40883	140.2640	6.764297
24.47383	140.2663	6.805411
24.53883	140.2686	6.844012
24.60550	140.2704	6.885186
24.67050	140.2727	6.923110
24.73550	140.2747	6.962418
24.80217	140.2768	7.001969
24.86716	140.2788	7.041926
24.93383	140.2808	7.078892
24.99883	140.2818	7.114401
25.06383	140.2850	7.144849
25.13050	140.2861	7.180907
25.19550	140.2874	7.213653
25.26050	140.2896	7.245312
25.32716	140.2907	7.279668
25.39216	140.2920	7.309131
25.45883	140.2931	7.341730
25.52383	140.2937	7.367702
25.58883	140.2956	7.389874
25.65550	140.2972	7.410538
25.72050	140.2986	7.430696
25.78550	140.2992	7.448264
25.85217	140.3013	7.466431
25.91716	140.3008	7.481912
25.98383	140.3032	7.495376
26.04883	140.3036	7.508790
26.11383	140.3044	7.522711
26.18050	140.3052	7.535250
26.24550	140.3055	7.547218
26.31050	140.3055	7.558972
26.37716	140.3060	7.570476
26.44216	140.3062	7.580562
26.50883	140.3064	7.591794
26.57383	140.3068	7.599929
26.63883	140.3075	7.607220
26.70550	140.3074	7.613455
26.77050	140.3070	7.615950
26.83550	140.3074	7.614960
26.90216	140.3072	7.611350
26.96716	140.3064	7.605597
27.03216	140.3062	7.597384
27.09883	140.3050	7.586820
27.16383	140.3044	7.575003
27.23050	140.3032	7.562053
27.29550	140.3020	7.548591
27.36050	140.3011	7.534913
27.42717	140.2994	7.520142
27.49216	140.2986	7.504170
27.55716	140.2985	7.484122
27.62383	140.2976	7.462590
27.68883	140.2953	7.441570
27.75550	140.2943	7.414759
27.82050	140.2939	7.390630
27.88550	140.2924	7.365026
27.95217	140.2916	7.339257
28.01716	140.2900	7.312585
28.08216	140.2892	7.285263
28.14883	140.2876	7.254043
28.21383	140.2865	7.226511
28.28050	140.2852	7.199541
28.34550	140.2841	7.172571
28.41050	140.2818	7.145810
28.47717	140.2816	7.117842
28.54216	140.2792	7.087648
28.60716	140.2780	7.061087
28.67383	140.2754	7.032312
28.73883	140.2742	7.004372
28.80550	140.2724	6.976026
28.87050	140.2711	6.949750
28.93550	140.2694	6.924265
29.00217	140.2688	6.891397
29.06716	140.2666	6.861436
29.13216	140.2658	6.830138
29.19883	140.2644	6.799462
29.26383	140.2629	6.768856
29.32883	140.2617	6.741830
29.39550	140.2608	6.710680
29.46050	140.2592	6.681994
29.52717	140.2577	6.653716
29.59216	140.2564	6.626720
29.65716	140.2551	6.600178
29.72383	140.2537	6.573618
29.78883	140.2522	6.546692
29.85383	140.2511	6.518618
29.92050	140.2495	6.493824
29.98550	140.2474	6.467153
30.05217	140.2467	6.440024
30.11716	140.2449	6.414008
30.18216	140.2434	6.384596
30.24883	140.2424	6.356690
30.31383	140.2409	6.332411
30.37883	140.2391	6.303521
30.44550	140.2383	6.275850
30.51050	140.2364	6.246392
30.57717	140.2350	6.221003
30.64216	140.2329	6.195538
30.70716	140.2319	6.172778
30.77383	140.2308	6.145979
30.83883	140.2292	6.118878
30.90383	140.2270	6.089638
30.97050	140.2263	6.058979
31.03550	140.2256	6.031346
31.10217	140.2237	6.001261
31.16716	140.2231	5.972153
31.23216	140.2214	5.944939
31.29883	140.2198	5.918057
31.36383	140.2192	5.890125
31.42883	140.2172	5.867298
31.49550	140.2164	5.838306
31.56050	140.2142	5.813429
31.62550	140.2138	5.781384
31.69216	140.2121	5.753560
31.75716	140.2102	5.725128
31.82383	140.2092	5.696912
31.88883	140.2077	5.671120
31.95383	140.2062	5.644291
32.02050	140.2041	5.617024
32.08550	140.2036	5.585747
32.15050	140.2022	5.553426
32.21716	140.1998	5.525750
32.28216	140.1990	5.496485
32.34883	140.1975	5.467942
32.41383	140.1965	5.436542
32.47883	140.1944	5.409156
32.54550	140.1929	5.376832
32.61050	140.1920	5.347810
32.67550	140.1907	5.315461
32.74216	140.1887	5.286555
32.80716	140.1878	5.256020
32.87383	140.1854	5.227606
32.93883	140.1841	5.199294
33.00383	140.1822	5.173368
33.07050	140.1802	5.142438
33.13550	140.1787	5.112034
33.20050	140.1766	5.081640
33.26716	140.1751	5.048384
33.33216	140.1739	5.013367
33.39883	140.1719	4.982620
33.46383	140.1710	4.951492
33.52883	140.1692	4.920948
33.59550	140.1686	4.887980
33.66050	140.1668	4.855276
33.72550	140.1658	4.819508
33.79217	140.1639	4.786218
33.85716	140.1627	4.758981
33.92216	140.1614	4.727960
33.98883	140.1596	4.700717
34.05383	140.1574	4.670517
34.12050	140.1554	4.639700
34.18550	140.1534	4.611633
34.25050	140.1520	4.584412
34.31716	140.1503	4.551938
34.38216	140.1483	4.520298
34.44717	140.1475	4.488111
34.51383	140.1458	4.452834
34.57883	140.1440	4.421230
34.64550	140.1425	4.390766
34.71050	140.1407	4.360260
34.77550	140.1395	4.330267
34.84216	140.1379	4.297163
34.90716	140.1360	4.270067
34.97217	140.1350	4.239808
35.03883	140.1338	4.208092
35.10383	140.1324	4.177335
35.17050	140.1304	4.147652
35.23550	140.1291	4.116634
35.30050	140.1275	4.088787
35.36716	140.1264	4.059738
35.43216	140.1246	4.029541
35.49716	140.1229	3.999436
35.56383	140.1220	3.971481
35.62883	140.1204	3.942264
35.69550	140.1188	3.913662
35.76050	140.1179	3.886194
35.82550	140.1161	3.859854
35.89216	140.1149	3.829859
35.95716	140.1128	3.803712
36.02217	140.1114	3.776298
36.08883	140.1102	3.747563
36.15383	140.1086	3.721074
36.21884	140.1074	3.690844
36.28550	140.1063	3.662132
36.35050	140.1038	3.636972
36.41716	140.1035	3.607781
36.48216	140.1020	3.582359
36.54716	140.1006	3.556074
36.61383	140.0991	3.528316
36.67883	140.0978	3.500095
36.74383	140.0966	3.473352
36.81050	140.0952	3.446115
36.87550	140.0938	3.421218
36.94216	140.0931	3.393356
37.00716	140.0910	3.367554
37.07217	140.0902	3.342596
37.13883	140.0891	3.315292
37.20383	140.0876	3.290298
37.26883	140.0862	3.266126
37.33550	140.0848	3.241096
37.40050	140.0832	3.221945
37.46716	140.0814	3.195644
37.53216	140.0800	3.172238
37.59716	140.0795	3.144589
37.66383	140.0772	3.118800
37.72883	140.0762	3.092476
37.79383	140.0754	3.067109
37.86050	140.0740	3.043192
37.92550	140.0732	3.017694
37.99216	140.0718	2.993081
38.05716	140.0701	2.968432
38.12216	140.0690	2.947842
38.18883	140.0676	2.920606
38.25383	140.0668	2.897541
38.31883	140.0654	2.873950
38.38550	140.0648	2.850053
38.45050	140.0631	2.825676
38.51550	140.0622	2.800372
38.58216	140.0605	2.776722
38.64717	140.0604	2.749331
38.71383	140.0596	2.723581
38.77883	140.0578	2.701330
38.84384	140.0565	2.682494
38.91050	140.0548	2.661427
38.97550	140.0535	2.643411
39.04050	140.0516	2.621998
39.10716	140.0508	2.599017
39.17216	140.0494	2.574378
39.23883	140.0486	2.550286
39.30383	140.0478	2.523390
39.36883	140.0464	2.502460
39.43550	140.0452	2.479016
39.50050	140.0439	2.456275
39.56550	140.0433	2.432461
39.63216	140.0417	2.408461
39.69717	140.0418	2.384514
39.76383	140.0399	2.360050
39.82883	140.0387	2.340566
39.89383	140.0375	2.319654
39.96050	140.0364	2.296850
40.02550	140.0351	2.274322
40.09050	140.0342	2.249580
40.15716	140.0328	2.226260
40.22217	140.0324	2.206242
40.28883	140.0309	2.182982
40.35383	140.0298	2.160424
40.41883	140.0284	2.137610
40.48550	140.0271	2.114152
40.55050	140.0254	2.095262
40.61550	140.0248	2.076971
40.68216	140.0235	2.051645
40.74716	140.0220	2.028468
40.81216	140.0212	2.004730
40.87883	140.0197	1.981539
40.94383	140.0190	1.958435
41.01050	140.0175	1.933357
41.07550	140.0168	1.909436
41.14050	140.0151	1.890150
41.20717	140.0141	1.865928
41.27217	140.0139	1.840905
41.33716	140.0120	1.818019
41.40383	140.0105	1.795938
41.46884	140.0093	1.775514
41.53550	140.0089	1.752648
41.60050	140.0068	1.731168
41.66550	140.0061	1.705970
41.73217	140.0052	1.684214
41.79716	140.0039	1.660541
41.86217	140.0024	1.637371
41.92883	140.0016	1.611091
41.99383	140.0012	1.586207
42.06050	140.0000	1.562340
42.12550	139.9983	1.540159
42.19050	139.9971	1.515339
42.25717	139.9956	1.491673
42.32217	139.9940	1.469084
42.38716	139.9936	1.446067
42.45383	139.9912	1.422005
42.51883	139.9911	1.396304
42.58550	139.9892	1.371254
42.65050	139.9874	1.351208
42.71550	139.9868	1.328172
42.78217	139.9856	1.302059
42.84716	139.9845	1.275598
42.91217	139.9834	1.248491
42.97883	139.9816	1.225413
43.04383	139.9799	1.199602
43.10883	139.9794	1.175376
43.17550	139.9775	1.149674
43.24050	139.9764	1.124703
43.30717	139.9758	1.100702
43.37216	139.9740	1.085998
43.43716	139.9722	1.060431
43.50383	139.9732	1.031938
43.56883	139.9708	1.003057
43.63383	139.9706	0.9725406
43.70050	139.9686	0.9438370
43.76550	139.9667	0.9189328
43.83217	139.9661	0.8926981
43.89717	139.9643	0.8646875
43.96216	139.9634	0.8386297
44.02883	139.9619	0.8113601
44.09384	139.9611	0.7847979
44.15883	139.9591	0.7601870
44.22550	139.9576	0.7307864
44.29050	139.9570	0.7053958
44.35717	139.9548	0.6769715
44.42216	139.9542	0.6487535
44.48717	139.9524	0.6226074
44.55383	139.9506	0.5946036
44.61883	139.9489	0.5700216
44.68383	139.9475	0.5427403
44.75050	139.9458	0.5144760
44.81550	139.9442	0.4856199
44.88217	139.9440	0.4565410
44.94717	139.9428	0.4301584
45.01216	139.9414	0.4038090
45.07883	139.9400	0.3766918
45.14383	139.9386	0.3497813
45.20883	139.9376	0.3247110
45.27550	139.9356	0.2993460
45.34050	139.9351	0.2740328
45.40550	139.9336	0.2448930
45.47217	139.9320	0.2227844
45.53717	139.9313	0.1967213
45.60383	139.9291	0.1726352
45.66883	139.9278	0.1479219
45.73383	139.9270	0.1245848
45.80050	139.9245	0.09976509
45.86550	139.9239	0.07545509
45.93050	139.9224	0.05246426
45.99716	139.9218	0.02610513
46.06216	139.9204	9.37454E-4
46.12883	139.9191	-.02568289
46.19383	139.9178	-.04718336
46.25883	139.9170	-.06956745
46.32550	139.9156	-.09178261
46.39050	139.9147	-0.1152790
46.45550	139.9135	-0.1359216
46.52217	139.9122	-0.1558266
46.58716	139.9111	-0.1752299
46.65383	139.9096	-0.1947860
46.71884	139.9086	-0.2130308
46.78383	139.9078	-0.2316722
46.85050	139.9071	-0.2532504
46.91550	139.9058	-0.2743894
46.98050	139.9046	-0.2936345
47.04716	139.9039	-0.3146591
47.11217	139.9028	-0.3314482
47.17883	139.9010	-0.3477107
47.24383	139.9010	-0.3662402
47.30883	139.8998	-0.3824722
47.37550	139.8987	-0.4000404
47.44050	139.8978	-0.4171888
47.50550	139.8972	-0.4356361
47.57217	139.8968	-0.4525575
47.63716	139.8958	-0.4675976
47.70216	139.8952	-0.4832132
47.76883	139.8942	-0.4998761
47.83383	139.8937	-0.5135102
47.90050	139.8930	-0.5285699
47.96550	139.8921	-0.5426278
48.03050	139.8908	-0.5564586
48.09716	139.8903	-0.5704932
48.16217	139.8898	-0.5851988
48.22717	139.8896	-0.5989262
48.29383	139.8881	-0.6119710
48.35883	139.8872	-0.6246363
48.42550	139.8864	-0.6373390
48.49050	139.8862	-0.6499497
48.55550	139.8854	-0.6622391
48.62216	139.8851	-0.6748565
48.68716	139.8848	-0.6868630
48.75217	139.8840	-0.6995444
48.81883	139.8831	-0.7117543
48.88383	139.8831	-0.7238110
48.95050	139.8824	-0.7355170
49.01550	139.8823	-0.7463030
49.08050	139.8815	-0.7570418
49.14717	139.8811	-0.7677574
49.21216	139.8805	-0.7784610
49.27716	139.8797	-0.7886936
49.34384	139.8798	-0.7985366
49.40883	139.8790	-0.8078744
49.47550	139.8784	-0.8170830
49.54050	139.8781	-0.8261451
49.60550	139.8782	-0.8352641
49.67216	139.8778	-0.8444482
49.73717	139.8778	-0.8531613
49.80217	139.8766	-0.8616852
49.86883	139.8766	-0.8700688
49.93383	139.8759	-0.8780170
49.99883	139.8750	-0.8854184
50.06550	139.8748	-0.8927176
50.13050	139.8745	-0.8997326
50.19717	139.8742	-0.9069064
50.26216	139.8730	-0.9138076
50.32717	139.8734	-0.9205390
50.39383	139.8726	-0.9273038
50.45883	139.8719	-0.9335540
50.52383	139.8712	-0.9394901
50.59050	139.8700	-0.9454754
50.65550	139.8710	-0.9512866
50.72217	139.8707	-0.9571856
50.78717	139.8705	-0.9632305
50.85217	139.8704	-0.9693012
50.91883	139.8707	-0.9759387
50.98383	139.8701	-0.9824700
51.04883	139.8705	-0.9889588
51.11550	139.8701	-0.9955566
51.18050	139.8710	-1.001843
51.24717	139.8702	-1.008213
51.31216	139.8703	-1.013815
51.37717	139.8708	-1.019041
51.44384	139.8706	-1.024255
51.50883	139.8695	-1.028596
51.57383	139.8697	-1.032593
51.64050	139.8694	-1.036168
51.70550	139.8694	-1.039333
51.77217	139.8684	-1.042448
51.83716	139.8688	-1.045980
51.90217	139.8680	-1.049308
51.96884	139.8686	-1.052780
52.03383	139.8677	-1.056433
52.09883	139.8673	-1.059966
52.16550	139.8674	-1.063822
52.23050	139.8672	-1.067564
52.29550	139.8664	-1.070846
52.36217	139.8664	-1.074200
52.42717	139.8660	-1.077520
52.49382	139.8660	-1.080825
52.55883	139.8661	-1.084154
52.62383	139.8652	-1.087690
52.69050	139.8659	-1.091252
52.75550	139.8659	-1.094896
52.82050	139.8656	-1.098044
52.88716	139.8656	-1.101353
52.95216	139.8646	-1.104094
53.01884	139.8644	-1.106986
53.08383	139.8640	-1.109456
53.14883	139.8651	-1.111767
53.21550	139.8642	-1.114401
53.28050	139.8638	-1.116869
53.34550	139.8646	-1.119630
53.41216	139.8650	-1.122282
53.47717	139.8644	-1.124619
53.54382	139.8634	-1.127030
53.60883	139.8634	-1.129513
53.67383	139.8644	-1.132181
53.74050	139.8639	-1.134852
53.80550	139.8641	-1.137292
53.87050	139.8641	-1.139736
53.93716	139.8640	-1.142437
54.00217	139.8631	-1.144615
54.06884	139.8642	-1.146779
54.13383	139.8636	-1.148368
54.19883	139.8638	-1.149894
54.26550	139.8632	-1.151203
54.33050	139.8636	-1.152777
54.39550	139.8630	-1.154437
54.46216	139.8630	-1.156095
54.52717	139.8616	-1.157401
54.59217	139.8621	-1.158598
54.65883	139.8629	-1.159841
54.72382	139.8619	-1.161452
54.79050	139.8615	-1.163122
54.85550	139.8626	-1.165103
54.92050	139.8622	-1.166987
54.98717	139.8626	-1.169148
55.05217	139.8617	-1.171115
55.11716	139.8621	-1.173042
55.18383	139.8624	-1.174894
55.24883	139.8622	-1.176547
55.31550	139.8618	-1.177874
55.38050	139.8618	-1.178842
55.44550	139.8612	-1.179399
55.51216	139.8606	-1.179808
55.57717	139.8610	-1.180787
55.64216	139.8610	-1.181846
55.70883	139.8616	-1.183191
55.77383	139.8611	-1.184784
55.84050	139.8604	-1.186642
55.90550	139.8605	-1.188375
55.97050	139.8611	-1.189912
56.03716	139.8607	-1.191127
56.10217	139.8610	-1.192389
56.16716	139.8612	-1.193593
56.23383	139.8609	-1.194973
56.29883	139.8614	-1.196189
56.36550	139.8604	-1.197430
56.43050	139.8604	-1.198795
56.49550	139.8606	-1.200135
56.56216	139.8603	-1.201642
56.62717	139.8609	-1.203182
56.69216	139.8607	-1.204437
56.75883	139.8607	-1.205320
56.82383	139.8604	-1.205982
56.88882	139.8604	-1.206618
56.95550	139.8609	-1.207340
57.02050	139.8605	-1.207795
57.08716	139.8605	-1.208474
57.15217	139.8602	-1.209259
57.21717	139.8602	-1.210196
57.28383	139.8599	-1.211049
57.34882	139.8604	-1.211918
57.41382	139.8600	-1.212728
57.48050	139.8602	-1.213449
57.54550	139.8601	-1.214438
57.61217	139.8606	-1.215436
57.67717	139.8604	-1.216401
57.74216	139.8603	-1.217478
57.80883	139.8596	-1.218389
57.87383	139.8600	-1.219177
57.93882	139.8592	-1.220174
58.00550	139.8593	-1.220874
58.07050	139.8596	-1.221420
58.13716	139.8607	-1.222127
58.20216	139.8593	-1.223021
58.26716	139.8593	-1.224000
58.33383	139.8595	-1.225173
58.39883	139.8593	-1.226341
58.46382	139.8589	-1.227361
58.53050	139.8587	-1.228257
58.59550	139.8587	-1.228996
58.66216	139.8591	-1.229919
58.72717	139.8585	-1.231014
58.79217	139.8589	-1.231777
58.85883	139.8586	-1.232368
58.92383	139.8587	-1.232797
58.98882	139.8584	-1.233270
59.05550	139.8587	-1.233848
59.12050	139.8588	-1.234326
59.18550	139.8584	-1.235323
59.25217	139.8594	-1.236187
59.31716	139.8588	-1.237222
59.38383	139.8584	-1.238180
59.44883	139.8588	-1.238927
59.51382	139.8596	-1.239212
59.58050	139.8585	-1.239576
59.64550	139.8588	-1.239900
59.71050	139.8584	-1.240448
59.77717	139.8592	-1.241140
59.84217	139.8591	-1.241809
59.90883	139.8585	-1.242442
59.97382	139.8594	-1.243060
60.03882	139.8591	-1.243677
60.10550	139.8595	-1.244260
60.17050	139.8593	-1.244448
60.23550	139.8592	-1.244792
60.30217	139.8588	-1.244848
60.36716	139.8591	-1.245111
60.43383	139.8588	-1.245784
60.49883	139.8588	-1.246209
60.56382	139.8581	-1.246172
60.63050	139.8588	-1.245560
60.69550	139.8579	-1.244955
60.76050	139.8582	-1.244636
60.82717	139.8576	-1.244651
60.89216	139.8584	-1.245054
60.95883	139.8581	-1.245646
61.02383	139.8578	-1.246257
61.08882	139.8583	-1.247004
61.15550	139.8583	-1.247830
61.22050	139.8580	-1.248888
61.28550	139.8584	-1.249405
61.35217	139.8583	-1.249725
61.41716	139.8578	-1.250057
61.48217	139.8582	-1.250231
61.54883	139.8588	-1.250760
61.61382	139.8583	-1.251540
61.68050	139.8582	-1.251844
61.74550	139.8582	-1.252246
61.81050	139.8569	-1.252352
61.87717	139.8578	-1.252625
61.94216	139.8581	-1.253308
62.00717	139.8586	-1.253480
62.07383	139.8581	-1.253651
62.13882	139.8585	-1.253941
62.20550	139.8581	-1.254774
62.27050	139.8590	-1.255857
62.33550	139.8585	-1.256665
62.40217	139.8580	-1.256833
62.46717	139.8575	-1.256533
62.53217	139.8582	-1.256274
62.59882	139.8581	-1.255865
62.66382	139.8577	-1.255702
62.73050	139.8583	-1.255876
62.79550	139.8580	-1.256022
62.86050	139.8579	-1.256499
62.92717	139.8574	-1.257027
62.99216	139.8579	-1.257386
63.05217	139.9117	-1.169447
63.11716	140.4596	-2.171926
63.18217	141.2476	-5.664615
63.24883	142.1808	-9.975952
63.31382	143.1697	-14.01577
63.38050	144.2468	-17.62746
63.44550	145.3444	-20.56892
63.51050	146.4783	-22.98544
63.57717	147.6720	-25.02277
63.64216	148.8615	-26.65289
63.70717	150.0695	-27.99766
63.77383	151.3234	-29.14865
63.83882	152.5594	-30.09214
63.90550	153.8356	-30.92059
63.97050	155.0897	-31.62188
64.03550	156.3473	-32.24646
64.10218	157.6438	-32.82526
64.16717	158.9112	-33.35535
64.23217	160.1814	-33.85990
64.29884	161.4831	-34.44907
64.36384	162.7510	-35.04520
64.43050	164.0581	-35.47520
64.49550	165.3417	-35.81133
64.56050	166.6248	-36.12310
64.62717	167.9419	-36.44123
64.69217	169.2284	-36.73405
64.75718	170.5143	-37.02570
64.82384	171.8332	-37.33420
64.88884	173.1206	-37.64422
64.95550	174.4416	-37.95038
65.02050	175.7279	-38.24973
65.08550	177.0146	-38.55137
65.15218	178.3348	-38.86931
65.21717	179.6208	-39.19685
65.28217	180.9076	-39.53200
65.34882	182.2260	-39.90574
65.41382	183.5115	-40.27702
65.47883	184.7965	-40.67643
65.54550	186.1136	-41.09574
65.61050	187.3972	-41.51455
65.67718	188.7124	-41.96050
65.74218	189.9949	-42.39439
65.80718	191.2778	-42.85567
65.87384	192.5903	-43.35562
65.93884	193.8700	-43.87324
66.00384	195.1482	-44.41120
66.07050	196.4572	-45.01440
66.13550	197.7320	-45.65854
66.20216	199.0362	-46.36686
66.26716	200.3047	-47.13084
66.33218	201.5707	-47.96545
66.39884	202.8647	-48.91804
66.46384	204.1225	-49.93212
66.52884	205.3753	-51.03967
66.59550	206.6558	-52.30266
66.66050	207.8980	-53.66579
66.72718	209.1648	-55.24722
66.79218	210.3930	-56.97878
66.85718	211.6086	-58.96526
66.92384	212.8422	-61.33409
66.98882	214.0270	-64.04094
67.05384	215.1906	-67.25464
67.12050	216.3585	-71.15337
67.18550	217.4647	-75.68362
67.25218	218.5662	-81.05893
67.31718	219.6088	-86.94209
67.38218	220.6277	-93.29652
67.44884	221.6633	-99.91281
67.51384	222.7019	-105.3462
67.57884	223.8602	-107.6562
67.64550	225.1888	-107.2911
67.71050	226.5745	-105.1010
67.77550	228.0308	-101.4409
67.84216	229.5781	-96.66474
67.90718	231.1254	-91.20590
67.97384	232.7462	-84.84862
68.03882	234.3598	-77.94964
68.10384	235.9783	-71.16910
68.17050	237.5990	-65.21943
68.23550	239.1295	-60.54635
68.30050	240.6133	-56.86071
68.36718	242.0948	-53.90097
68.43218	243.5081	-51.65178
68.49884	244.9344	-49.84150
68.56384	246.3047	-48.45634
68.62884	247.6612	-47.39110
68.69550	249.0386	-46.53572
68.76050	250.3733	-45.89175
68.82550	251.7010	-45.40034
68.89216	253.0578	-45.00932
68.95718	254.3755	-44.71660
69.02384	255.7238	-44.48819
69.08884	257.0360	-44.34738
69.15384	258.3440	-44.24570
69.22050	259.6848	-44.18603
69.28550	260.9911	-44.15984
69.35050	262.2952	-44.14597
69.41718	263.6328	-44.14303
69.48218	264.9370	-44.14356
69.54884	266.2737	-44.15332
69.61384	267.5756	-44.17314
69.67884	268.8778	-44.21049
69.74550	270.2128	-44.26562
69.81050	271.5142	-44.29877
69.87550	272.8158	-44.33672
69.94218	274.1516	-44.36680
70.00050	275.3206	-44.39746
70.06718	276.3832	-44.36978
70.13218	276.4040	-38.72617
70.19884	276.0227	-28.73373
70.26384	275.4294	-18.48494
70.32884	274.6906	-9.257541
70.39550	273.8217	-1.220778
70.46050	272.8909	5.262514
70.52550	271.8937	10.58974
70.59216	270.8144	15.02528
70.65718	269.7176	18.52425
70.72384	268.5560	21.42370
70.78882	267.3930	23.72652
70.85384	266.2075	25.60415
70.92050	264.9698	27.17884
70.98550	263.7482	28.43125
71.05050	262.5144	29.45981
71.11718	261.2389	30.33430
71.18218	259.9860	31.04261
71.24884	258.6946	31.64620
71.31384	257.4291	32.13480
71.37884	256.1582	32.54215
71.44550	254.8517	32.89067
71.51050	253.5743	33.18782
71.57550	252.2931	33.43361
71.64216	250.9784	33.63948
71.70718	249.6932	33.81333
71.77218	248.4072	33.96164
71.83884	247.0866	34.08989
71.90384	245.7985	34.18778
71.97050	244.4764	34.27354
72.03550	243.1865	34.33925
72.10050	241.8962	34.39520
72.16718	240.5706	34.44125
72.23218	239.2795	34.47813
72.29718	237.9872	34.51600
72.36384	236.6606	34.54407
72.42884	235.3676	34.57015
72.49550	234.0408	34.57868
72.56050	232.7484	34.58540
72.62550	231.4548	34.59132
72.69218	230.1284	34.59826
72.75718	228.8349	34.60542
72.82218	227.5411	34.61682
72.88884	226.2134	34.63256
72.95384	224.9194	34.64498
73.02050	223.5904	34.65774
73.08550	222.2963	34.66583
73.15050	221.0016	34.67217
73.21718	219.6737	34.67688
73.28218	218.3787	34.68176
73.34718	217.0836	34.68458
73.41382	215.7561	34.68504
73.47884	214.4610	34.68360
73.54550	213.1330	34.68090
73.61050	211.8381	34.67730
73.67550	210.5436	34.67357
73.74218	209.2148	34.67020
73.80718	207.9204	34.66630
73.87218	206.6254	34.66158
73.93884	205.2966	34.65576
74.00384	204.0013	34.64896
74.06884	202.7058	34.64080
74.13550	201.3770	34.62500
74.20050	200.0821	34.61197
74.26716	198.7532	34.60088
74.33218	197.4582	34.59020
74.39718	196.1633	34.57760
74.46384	194.8351	34.56669
74.52884	193.5389	34.55870
74.59384	192.2443	34.54970
74.66050	190.9144	34.53986
74.72551	189.6198	34.52380
74.79218	188.2915	34.51286
74.85718	186.9951	34.49916
74.92218	185.6989	34.48694
74.98882	184.3695	34.47106
75.05384	183.0728	34.44545
75.11884	181.7764	34.42699
75.18550	180.4466	34.40680
75.25050	179.1508	34.39153
75.31718	177.8216	34.38167
75.38218	176.5258	34.37393
75.44718	175.2299	34.36775
75.51384	173.9000	34.36367
75.57884	172.6050	34.36140
75.64384	171.3100	34.36063
75.71050	169.9834	34.38675
75.77550	168.6925	34.53036
75.84216	167.3770	34.84350
75.90718	166.1122	35.61704
75.97218	164.8908	37.47742
76.03882	163.7207	41.24160
76.10384	162.6776	46.88268
76.16884	161.7039	53.67420
76.23550	160.7223	60.61313
76.30050	159.7321	66.47696
76.36550	158.6794	70.92954
76.43218	157.5198	73.80066
76.49718	156.3068	74.94566
76.56384	154.9838	74.53448
76.62884	153.6262	72.85908
76.69384	152.2180	70.23510
76.76050	150.7357	66.94864
76.82550	149.2728	63.47382
76.89050	147.8044	59.98200
76.95718	146.3046	56.58230
77.02218	144.8556	53.58400
77.08884	143.3868	50.84174
77.15384	141.9709	48.54580
77.21884	140.5730	46.55438
77.28550	139.1526	44.79728
77.35050	137.7808	43.33212
77.41550	136.4180	42.04676
77.48218	135.0318	40.92696
77.54718	133.6871	39.99584
77.61384	132.3142	39.15692
77.67884	130.9814	38.43405
77.74384	129.6532	37.80670
77.81050	128.2952	37.25868
77.87550	126.9744	36.77530
77.94050	125.6576	36.35760
78.00718	124.3094	35.97078
78.07218	122.9952	35.62312
78.13884	121.6494	35.29224
78.20384	120.3386	34.99104
78.26882	119.0287	34.71018
78.33550	117.6865	34.44687
78.40050	116.3789	34.21477
78.46550	115.0726	33.98500
78.53218	113.7337	33.77914
78.59718	112.4264	33.57784
78.66218	111.1206	33.38160
78.72884	109.7825	33.18152
78.79384	108.4771	33.00272
78.86050	107.1400	32.81565
78.92550	105.8354	32.64528
78.99050	104.5310	32.47783
79.05718	103.1932	32.30858
79.12218	101.8897	32.15182
79.18718	100.5868	31.99905
79.25384	99.24968	31.84342
79.31884	97.94776	31.69437
79.38550	96.61099	31.55742
79.45050	95.30853	31.40892
79.51550	94.00672	31.26735
79.58218	92.67022	31.12252
79.64718	91.36782	30.98210
79.71218	90.06399	30.83614
79.77884	88.72710	30.68603
79.84384	87.42499	30.54050
79.91050	86.08941	30.39140
79.97551	84.78691	30.25912
80.04050	83.48484	30.12696
80.10718	82.14706	29.99432
80.17218	80.84472	29.85696
80.23718	79.54329	29.72601
80.30384	78.20650	29.59695
80.36884	76.90328	29.46632
80.43550	75.56728	29.33596
80.50050	74.26472	29.21268
80.56550	72.96034	29.04792
80.63218	71.62201	28.84880
80.69718	70.31560	28.65600
80.76218	69.00265	28.28502
80.82884	67.66262	28.13342
80.89384	66.36070	28.01216
80.95884	65.05671	27.88706
81.02550	63.72024	27.76035
81.09050	62.41724	27.62031
81.15718	61.08218	27.49232
81.22218	59.78000	27.37120
81.28718	58.47844	27.26576
81.35384	57.14438	27.17810
81.41884	55.84316	27.07836
81.48384	54.54136	26.97032
81.55050	53.20660	26.85325
81.61550	51.90471	26.74192
81.68218	50.56903	26.61675
81.74718	49.26610	26.49365
81.81216	47.96464	26.37460
81.87884	46.62735	26.25144
81.94384	45.32478	26.13171
82.00884	44.02034	26.01124
82.07550	42.68296	25.88362
82.14050	41.37916	25.74510
82.20718	40.04206	25.60863
82.27218	38.73889	25.46650
82.33718	37.43350	25.31344
82.40384	36.09616	25.15030
82.46884	34.79250	24.99830
82.53384	33.48872	24.83990
82.60050	32.14994	24.67756
82.66550	30.84436	24.51068
82.73218	29.50492	24.35059
82.79718	28.20004	24.17918
82.86218	26.89334	24.00573
82.92882	25.55242	23.82713
82.99384	24.24418	23.63556
83.05718	23.13572	23.73213
83.12218	23.01907	21.93684
83.18884	23.33322	16.58810
83.25384	23.89293	10.41318
83.31884	24.61414	4.546042
83.38550	25.48218	-0.6889072
83.45050	26.42108	-4.923756
83.51550	27.43553	-8.366524
83.58218	28.53386	-11.21580
83.64718	29.64965	-13.44470
83.71218	30.80106	-15.24032
83.77884	32.00900	-16.74003
83.84384	33.20882	-17.93424
83.91050	34.45700	-18.94719
83.97551	35.68760	-19.76811
84.04051	36.93047	-20.46266
84.10718	38.21265	-21.07320
84.17218	39.47152	-21.57575
84.23718	40.73620	-22.00867
84.30382	42.03836	-22.40164
84.36884	43.31170	-22.73364
84.43550	44.62078	-23.03520
84.50050	45.90112	-23.30168
84.56551	47.18360	-23.54573
84.63218	48.50171	-23.78141
84.69718	49.78738	-23.99074
84.76218	51.07639	-24.19141
84.82884	52.39830	-24.38280
84.89384	53.68870	-24.55927
84.96051	55.01181	-24.72848
85.02550	56.30340	-24.88942
85.09051	57.59547	-25.05573
85.15718	58.92270	-25.22533
85.22218	60.21464	-25.40866
85.28718	61.50514	-25.61092
85.35382	62.82989	-25.82563
85.41884	64.12084	-26.03623
85.48551	65.44475	-26.26520
85.55051	66.73461	-26.50724
85.61551	68.02686	-26.64241
85.68218	69.35845	-26.72914
85.74718	70.65650	-26.82649
85.81218	71.95403	-26.93166
85.87882	73.28563	-27.04966
85.94384	74.58149	-27.16442
86.00884	75.87900	-27.28176
86.07550	77.20826	-27.41108
86.14051	78.50462	-27.54621
86.20718	79.83393	-27.68375
86.27218	81.13066	-27.82642
86.33718	82.42749	-27.95992
86.40384	83.75738	-28.09821
86.46884	85.05376	-28.23401
86.53384	86.34955	-28.37188
86.60050	87.67938	-28.52070
86.66550	88.97532	-28.66450
86.73218	90.30456	-28.82205
86.79718	91.60099	-28.96730
86.86218	92.89649	-29.11628
86.92882	94.22586	-29.26026
86.99384	95.52094	-29.41511
87.05884	96.81630	-29.56410
87.12550	98.14610	-29.70200
87.19051	99.44119	-29.85483
87.25718	100.7711	-30.00268
87.32218	102.0675	-30.15447
87.38718	103.3634	-30.29386
87.45382	104.6931	-30.45081
87.51882	105.9879	-30.60185
87.58384	107.2837	-30.75268
87.65051	108.6123	-30.91130
87.71551	109.9078	-31.05959
87.78218	111.2363	-31.22517
87.84718	112.5308	-31.38247
87.91218	113.8255	-31.53763
87.97882	115.1537	-31.69458
88.04384	116.4483	-31.86124
88.10884	117.7439	-32.00778
88.17551	119.0726	-32.17444
88.24051	120.3674	-32.34058
88.30549	121.6633	-32.51165
88.37218	122.9915	-32.68496
88.43718	124.2866	-32.85816
88.50384	125.6148	-33.03003
88.56884	126.9098	-33.19824
88.63384	128.2045	-33.35887
88.70050	129.5318	-33.53190
88.76551	130.8268	-33.70512
88.83051	132.1223	-33.88665
88.89718	133.4490	-34.06415
88.96218	134.7435	-34.25306
89.02884	136.0716	-34.45126
89.09384	137.3651	-34.65024
89.15884	138.6593	-34.84266
89.22551	139.9859	-35.04544
89.29051	141.2794	-35.25094
89.35550	142.5724	-35.45929
89.42218	143.8993	-35.67720
89.48718	145.1921	-35.88360
89.55382	146.5190	-36.10359
89.61884	147.8115	-36.31937
89.68384	149.1043	-36.53620
89.75050	150.4302	-36.76043
89.81551	151.7212	-36.98890
89.88050	153.0136	-37.22794
89.94718	154.3374	-37.48762
90.01218	155.6271	-37.75840
90.07884	156.9498	-38.05116
90.14384	158.2390	-38.36533
90.20882	159.5252	-38.71106
90.27550	160.8447	-39.09940
90.34051	162.1296	-39.48765
90.40551	163.4201	-39.74480
90.47218	164.7446	-39.99683
90.53718	166.0375	-40.22202
90.60218	167.3311	-40.43666
90.66884	168.6594	-40.62462
90.73382	169.9553	-40.77378
90.80051	171.2857	-40.90406
90.86551	172.5830	-41.02149
90.93051	173.8806	-41.13447
90.99718	175.2111	-41.25894
91.06218	176.5089	-41.40244
91.12718	177.8044	-41.56480
91.19384	179.1312	-41.76339
91.25884	180.4243	-42.00054
91.32550	181.7479	-42.29102
91.39051	183.0369	-42.61816
91.45551	184.3232	-42.99916
91.52218	185.6406	-43.44269
91.58718	186.9226	-43.92328
91.65218	188.2005	-44.47788
91.71884	189.5083	-45.12924
91.78384	190.7782	-45.86770
91.85050	192.0751	-46.73868
91.91550	193.3338	-47.71871
91.98050	194.5864	-48.82415
92.04718	195.8660	-50.07055
92.11218	197.1089	-51.37674
92.17718	198.3503	-52.73686
92.24384	199.6210	-54.15854
92.30884	200.8584	-55.59932
92.37550	202.1235	-57.16864
92.44051	203.3528	-58.81690
92.50551	204.5772	-60.57957
92.57218	205.8282	-62.45294
92.63718	207.0488	-64.24718
92.70216	208.2794	-65.76656
92.76882	209.5671	-66.65628
92.83384	210.8690	-66.36589
92.89884	212.2342	-64.70929
92.96551	213.6906	-61.90386
93.03051	215.1428	-58.61539
93.09718	216.6416	-55.15760
93.16218	218.0924	-52.09204
93.22718	219.5221	-49.49956
93.29384	220.9646	-47.34056
93.35884	222.3506	-45.67286
93.42384	223.7182	-44.36442
93.49051	225.1072	-43.30847
93.55549	226.4494	-42.49440
93.62218	227.8177	-41.85372
93.68718	229.1434	-41.37108
93.75218	230.4663	-41.02137
93.81884	231.8166	-40.75054
93.88384	233.1299	-40.56951
93.94884	234.4400	-40.44114
94.01551	235.7817	-40.34914
94.08051	237.0887	-40.28140
94.14718	238.4266	-40.25062
94.21218	239.7311	-40.23904
94.27718	241.0326	-40.23774
94.34384	242.3689	-40.26318
94.40884	243.6705	-40.30652
94.47384	244.9725	-40.35338
94.54051	246.3078	-40.40177
94.60550	247.6092	-40.45360
94.67218	248.9438	-40.49774
94.73718	250.2446	-40.54180
94.80218	251.5444	-40.60722
94.86884	252.8776	-40.67095
94.93384	254.1779	-40.73650
94.99884	255.4775	-40.79714
95.06551	256.8112	-40.88198
95.13050	258.1106	-40.95494
95.19550	259.4109	-41.03536
95.26218	260.7446	-41.12110
95.32718	262.0446	-41.18960
95.39384	263.3784	-41.26953
95.45882	264.6780	-41.33648
95.52384	265.9787	-41.41210
95.59051	267.3124	-41.48242
95.65551	268.6122	-41.55911
95.72051	269.9111	-41.63661
95.78718	271.2444	-41.71436
-2.000000	5.000000	0.0000000