File: 3-C1(1.0mol%)+C20(0.6mol%)/matlab/140-3
CLOSED
Version	1.0
Language	English
Mode	Standard
Run	3
RunSerial	11784
Instrument	DSC Q2000 V24.11 Build 124
Module	DSC Standard Cell RC
Operator	Nan
File	\\Ae520-1454\ta\Data\DSC\UQ Composites\Nan\C1(4.5)+C20P(3)+CL(HotplateMixtureAB)\Iso140_60Min_3
ProcName	H/C/H/C/H complete wood PHA
InstSerial	2000-0883
AutoSerial	1293
Sample	Iso140_60Min
Size	31.2000	mg
PanMass	Not available
PanResist	Automatic Automatic  K/W
PanFactor	Default Default
Method	H/C/H/C/H complete wood PHA
Comment
Xcomment	Pan: Tzero Aluminum Hermetic
Xcomment	Gas1: Nitrogen 50.0 ml/min
Xcomment	Gas2: Nitrogen 50.0 ml/min
Text
Exotherm	UP
Kcell	1.05230
Cpconst	Standard: 0.938
Calib	-38.6961
TempCal	1	pts	157.46	156.60
TzeroDt	-87.6168 -0.0009 -1.4231
TzeroDtz	-87.6168 0.0057 6.9570
InstCalFile	Tzero: \\Ae520-1454\ta\Data\DSC\Calibration\2017\CALIBRATION\1562_RCS (90)_05_18_2017 10_50_44.TZR
InstCalFile	Baseline: \\Ae520-1454\ta\Data\DSC\Calibration\2017\2017-05-17_Calibration.001
InstCalFile	Sapphire: \\Ae520-1454\ta\Data\DSC\Calibration\2017\2017-05-17_Saphire.001
InstCalDate	Tzero 2017-05-18 Time 10:50:44
TempRange	-87.39 to 398.39 °C at 10.00 °C/min Heat Only
AutoZero	Delta T Offset 0.000 uV
AutoZero	Delta T0 Offset 0.000 uV
MultiptCal	0
MultiPtDesc	0) Not set
AutoCellConst	Calibration Date 2017-05-18 16:59:28
Controls	Gas 1  Event Off  Sampling 0.2
Cell#	RC-01562
CoolingUnit	RCS (90)
SelHeatFlow	Heat Flow T4 (mW)
AutoLidII	Installed
AutoAnalysis	Off
MacroFile
Nsig	3
Sig1	Time (min)
Sig2	Temperature (°C)
Sig3	Heat Flow (mW)
Date	2017-06-07
Time	14:36:27
OrgMethod	1: Equilibrate at 20.00 °C
OrgMethod	2: Ramp 40.00 °C/min to 140.00 °C
OrgMethod	3: Mark end of cycle 1
OrgMethod	4: Isothermal for 60.00 min
OrgMethod	5: Mark end of cycle 2
OrgMethod	6: Ramp 20.00 °C/min to 280.00 °C
OrgMethod	7: Mark end of cycle 3
OrgMethod	8: Ramp 20.00 °C/min to 20.00 °C
OrgMethod	9: Mark end of cycle 4
OrgMethod	10: Ramp 20.00 °C/min to 280.00 °C
OrgMethod	11: Mark end of cycle 5
OrgFile	C:\Users\jarra\Desktop\DSC\3-C1(1.0mol%)+C20(0.6mol%)\140-3
StartOfData
4.99994E-4	20.03330	0.2359962
0.06716666	20.32115	0.9157343
0.1321667	21.69199	-0.1867892
0.1988333	23.48370	-4.131974
0.2638334	25.47182	-8.501108
0.3288334	27.61031	-12.46646
0.3955000	29.91828	-15.84520
0.4605000	32.24347	-18.48472
0.5255000	34.63000	-20.54484
0.5921668	37.12270	-22.19068
0.6571668	39.58447	-23.55298
0.7238332	42.12316	-24.85744
0.7888332	44.59828	-26.34514
0.8538332	47.07614	-27.67206
0.9205000	49.64883	-28.63370
0.9854999	52.17630	-29.41047
1.050500	54.70630	-30.21710
1.117166	57.32107	-30.81288
1.182166	59.84180	-32.24074
1.248833	62.40254	-33.87145
1.313833	64.89136	-35.93360
1.378833	67.31119	-39.73237
1.445500	69.60239	-47.97150
1.510500	71.54538	-61.27714
1.575500	73.28946	-77.58180
1.642166	75.01465	-94.49482
1.707167	76.75890	-109.9386
1.772167	78.55322	-124.3187
1.838833	80.56939	-135.1764
1.903833	82.70985	-143.0768
1.970500	85.58584	-134.6039
2.035500	88.60947	-128.6289
2.100500	91.56705	-121.5954
2.167167	95.05004	-104.5961
2.232167	98.49109	-90.33402
2.297166	101.7503	-79.37794
2.363834	104.9306	-70.85438
2.428833	107.9124	-64.61230
2.495500	110.8762	-59.78735
2.560500	113.6956	-56.29676
2.625500	116.4614	-53.71465
2.692167	119.2555	-51.78856
2.757167	121.9481	-50.47861
2.822166	124.6147	-49.61542
2.888834	127.3320	-49.04412
2.953833	129.9669	-48.74328
3.017166	132.5230	-48.68630
3.082167	134.6188	-49.60734
3.147167	135.7417	-46.36262
3.213833	136.5750	-40.10926
3.278833	137.1862	-33.56113
3.343834	137.6599	-27.72275
3.410500	138.0385	-22.79840
3.475500	138.3278	-19.00066
3.542167	138.5636	-15.97356
3.607167	138.7456	-13.70656
3.672167	138.8913	-11.95334
3.738834	139.0125	-10.58136
3.803833	139.1080	-9.556134
3.868833	139.1862	-8.762858
3.935500	139.2519	-8.129978
4.000500	139.3054	-7.641018
4.065500	139.3503	-7.258620
4.132167	139.3891	-6.938690
4.197166	139.4216	-6.681850
4.263834	139.4505	-6.457875
4.328834	139.4747	-6.270112
4.393833	139.4965	-6.105209
4.460500	139.5167	-5.944951
4.525500	139.5336	-5.800346
4.590500	139.5499	-5.665113
4.657166	139.5644	-5.531855
4.722168	139.5782	-5.405218
4.788834	139.5907	-5.277752
4.853833	139.6022	-5.155571
4.918833	139.6129	-5.033678
4.985500	139.6237	-4.912537
5.050500	139.6334	-4.791034
5.115500	139.6425	-4.674100
5.182167	139.6515	-4.555377
5.247168	139.6597	-4.442597
5.313832	139.6689	-4.327833
5.378834	139.6762	-4.216777
5.443832	139.6835	-4.111389
5.510500	139.6905	-4.003557
5.575500	139.6977	-3.898603
5.640500	139.7040	-3.795832
5.707168	139.7102	-3.695204
5.772168	139.7163	-3.595622
5.838832	139.7233	-3.494088
5.903834	139.7291	-3.398245
5.968834	139.7344	-3.299246
6.035500	139.7398	-3.204153
6.100500	139.7450	-3.109104
6.165500	139.7506	-3.015784
6.232168	139.7558	-2.923252
6.297168	139.7610	-2.833734
6.362168	139.7660	-2.746691
6.428832	139.7708	-2.657615
6.493834	139.7755	-2.571841
6.560500	139.7804	-2.487598
6.625500	139.7850	-2.406830
6.690500	139.7888	-2.326319
6.757168	139.7942	-2.249038
6.822168	139.7971	-2.173253
6.887168	139.8010	-2.106670
6.953832	139.8049	-2.038462
7.018832	139.8093	-1.975463
7.085500	139.8114	-1.910645
7.150500	139.8162	-1.853316
7.215500	139.8189	-1.795461
7.282166	139.8225	-1.741600
7.347168	139.8256	-1.686149
7.412168	139.8277	-1.628147
7.478832	139.8309	-1.575268
7.543832	139.8338	-1.524486
7.610500	139.8369	-1.475723
7.675500	139.8396	-1.427975
7.740500	139.8418	-1.385085
7.807166	139.8442	-1.340199
7.872168	139.8469	-1.298431
7.937166	139.8484	-1.256730
8.003834	139.8509	-1.216736
8.068832	139.8527	-1.180793
8.135500	139.8547	-1.141834
8.200500	139.8568	-1.110411
8.265500	139.8588	-1.074480
8.332168	139.8604	-1.041746
8.397168	139.8622	-1.009306
8.462168	139.8642	-0.9794678
8.528832	139.8658	-0.9502444
8.593832	139.8668	-0.9240272
8.658832	139.8688	-0.8984418
8.725500	139.8711	-0.8744207
8.790500	139.8722	-0.8493432
8.857166	139.8735	-0.8252145
8.922168	139.8744	-0.8051660
8.987168	139.8764	-0.7838098
9.053832	139.8779	-0.7601825
9.118834	139.8788	-0.7351710
9.183832	139.8801	-0.7122216
9.250500	139.8813	-0.6872199
9.315500	139.8826	-0.6651600
9.382166	139.8833	-0.6409916
9.447168	139.8845	-0.6212210
9.512168	139.8853	-0.5978118
9.578832	139.8876	-0.5775051
9.643832	139.8878	-0.5548764
9.708832	139.8895	-0.5300190
9.775499	139.8905	-0.5055952
9.840500	139.8920	-0.4831002
9.907166	139.8929	-0.4597178
9.972168	139.8946	-0.4389350
10.03717	139.8956	-0.4172180
10.10383	139.8971	-0.3950735
10.16883	139.8980	-0.3710266
10.23383	139.8997	-0.3481977
10.30050	139.9006	-0.3224875
10.36550	139.9017	-0.3097231
10.43217	139.9020	-0.2979808
10.49717	139.9035	-0.2842984
10.56216	139.9044	-0.2652760
10.62884	139.9054	-0.2432808
10.69383	139.9066	-0.2174002
10.75883	139.9077	-0.1956069
10.82550	139.9089	-0.1695926
10.89050	139.9106	-0.1476102
10.95550	139.9110	-0.1256724
11.02217	139.9119	-0.1025940
11.08717	139.9131	-.08367613
11.15383	139.9148	-.06190472
11.21884	139.9153	-.04284500
11.28383	139.9166	-.02089744
11.35050	139.9184	.002590067
11.41550	139.9192	0.02187444
11.48050	139.9201	0.04333344
11.54717	139.9208	0.06622339
11.61217	139.9222	0.08513000
11.67883	139.9236	0.1050736
11.74384	139.9250	0.1246697
11.80884	139.9253	0.1447342
11.87550	139.9270	0.1641732
11.94050	139.9268	0.1865477
12.00550	139.9280	0.2060856
12.07217	139.9298	0.2247192
12.13717	139.9309	0.2444623
12.20384	139.9320	0.2657626
12.26883	139.9325	0.2840570
12.33383	139.9334	0.3021831
12.40050	139.9344	0.3208206
12.46550	139.9358	0.3419506
12.53050	139.9378	0.3598572
12.59717	139.9375	0.3808478
12.66217	139.9388	0.4012798
12.72884	139.9397	0.4190250
12.79384	139.9415	0.4390926
12.85883	139.9425	0.4586316
12.92550	139.9432	0.4782321
12.99050	139.9444	0.4993560
13.05550	139.9453	0.5184876
13.12217	139.9466	0.5389638
13.18716	139.9468	0.5603394
13.25217	139.9486	0.5804868
13.31884	139.9492	0.6007995
13.38383	139.9506	0.6230420
13.45050	139.9523	0.6413822
13.51550	139.9527	0.6647126
13.58050	139.9543	0.6840244
13.64717	139.9548	0.7068702
13.71217	139.9556	0.7277997
13.77717	139.9576	0.7491192
13.84383	139.9577	0.7722651
13.90883	139.9601	0.7934549
13.97550	139.9609	0.8147576
14.04050	139.9619	0.8382343
14.10550	139.9631	0.8600494
14.17217	139.9640	0.8849320
14.23716	139.9650	0.9092774
14.30217	139.9667	0.9354371
14.36884	139.9681	0.9578080
14.43383	139.9694	0.9821306
14.50050	139.9709	1.006487
14.56550	139.9725	1.031565
14.63050	139.9739	1.058932
14.69717	139.9746	1.087809
14.76217	139.9759	1.117014
14.82717	139.9772	1.145425
14.89383	139.9786	1.180798
14.95883	139.9802	1.213626
15.02550	139.9826	1.250103
15.09050	139.9842	1.286460
15.15550	139.9860	1.328368
15.22217	139.9886	1.375028
15.28717	139.9909	1.419240
15.35217	139.9934	1.469362
15.41883	139.9956	1.528785
15.48383	139.9984	1.589598
15.54884	140.0016	1.661736
15.61550	140.0060	1.740054
15.68050	140.0098	1.828026
15.74717	140.0150	1.929642
15.81216	140.0206	2.045677
15.87716	140.0264	2.171584
15.94384	140.0346	2.323047
16.00883	140.0421	2.490703
16.07383	140.0514	2.680466
16.14050	140.0622	2.898638
16.20550	140.0741	3.137253
16.27216	140.0878	3.403389
16.33716	140.1020	3.688541
16.40216	140.1172	4.001780
16.46883	140.1342	4.344494
16.53383	140.1514	4.692358
16.59883	140.1696	5.051966
16.66550	140.1889	5.428588
16.73050	140.2072	5.795455
16.79716	140.2268	6.169718
16.86216	140.2437	6.516216
16.92716	140.2604	6.846485
16.99383	140.2771	7.162866
17.05883	140.2919	7.441000
17.12383	140.3052	7.684044
17.19050	140.3159	7.904816
17.25550	140.3258	8.084305
17.32216	140.3337	8.228595
17.38716	140.3402	8.337584
17.45216	140.3448	8.414511
17.51883	140.3484	8.462095
17.58383	140.3499	8.481249
17.64883	140.3505	8.487282
17.71550	140.3500	8.487066
17.78050	140.3485	8.466915
17.84550	140.3459	8.415422
17.91217	140.3429	8.352255
17.97716	140.3397	8.285831
18.04383	140.3361	8.212062
18.10883	140.3322	8.138301
18.17383	140.3284	8.060500
18.24050	140.3236	7.981063
18.30550	140.3201	7.901970
18.37050	140.3162	7.825714
18.43716	140.3129	7.747638
18.50216	140.3089	7.678344
18.56883	140.3059	7.610493
18.63383	140.3015	7.549144
18.69884	140.2991	7.493651
18.76550	140.2962	7.439331
18.83050	140.2931	7.390834
18.89550	140.2909	7.346803
18.96216	140.2894	7.305579
19.02716	140.2870	7.271558
19.09383	140.2853	7.236901
19.15883	140.2834	7.211990
19.22383	140.2823	7.187720
19.29050	140.2811	7.166882
19.35550	140.2795	7.147582
19.42050	140.2794	7.130501
19.48716	140.2793	7.118175
19.55216	140.2790	7.106806
19.61883	140.2784	7.096347
19.68383	140.2788	7.086740
19.74883	140.2781	7.078228
19.81550	140.2781	7.070790
19.88050	140.2778	7.065546
19.94550	140.2775	7.062760
20.01216	140.2778	7.062534
20.07716	140.2779	7.064161
20.14216	140.2781	7.067566
20.20883	140.2784	7.072574
20.27383	140.2786	7.079022
20.34050	140.2798	7.086756
20.40550	140.2800	7.095999
20.47050	140.2804	7.106430
20.53717	140.2810	7.118680
20.60216	140.2822	7.134720
20.66716	140.2829	7.148926
20.73383	140.2840	7.168072
20.79883	140.2850	7.189843
20.86550	140.2867	7.212218
20.93050	140.2866	7.236990
20.99550	140.2885	7.258255
21.06216	140.2896	7.279784
21.12716	140.2907	7.305951
21.19216	140.2919	7.328714
21.25883	140.2925	7.358032
21.32383	140.2946	7.383007
21.39050	140.2968	7.410005
21.45550	140.2979	7.435358
21.52050	140.3000	7.460474
21.58716	140.3012	7.485657
21.65216	140.3022	7.515870
21.71716	140.3038	7.546926
21.78383	140.3056	7.578259
21.84883	140.3070	7.606510
21.91550	140.3082	7.636736
21.98050	140.3104	7.667915
22.04550	140.3115	7.699289
22.11216	140.3134	7.730911
22.17717	140.3143	7.763384
22.24216	140.3157	7.797437
22.30883	140.3171	7.831359
22.37383	140.3192	7.863491
22.43883	140.3210	7.894966
22.50550	140.3227	7.927682
22.57050	140.3241	7.962041
22.63716	140.3261	7.995688
22.70216	140.3286	8.024757
22.76716	140.3297	8.062680
22.83383	140.3309	8.097736
22.89883	140.3329	8.135735
22.96383	140.3346	8.167290
23.03050	140.3376	8.200016
23.09550	140.3387	8.233976
23.16217	140.3403	8.269974
23.22716	140.3419	8.305932
23.29216	140.3435	8.342881
23.35883	140.3454	8.378165
23.42383	140.3472	8.413100
23.48883	140.3495	8.444481
23.55550	140.3506	8.482020
23.62050	140.3528	8.514394
23.68716	140.3545	8.548144
23.75217	140.3561	8.581191
23.81716	140.3589	8.613089
23.88383	140.3604	8.644832
23.94883	140.3614	8.677228
24.01383	140.3626	8.708420
24.08050	140.3642	8.739653
24.14550	140.3649	8.768424
24.21216	140.3668	8.795528
24.27717	140.3670	8.822558
24.34216	140.3686	8.843609
24.40883	140.3696	8.848564
24.47383	140.3694	8.857235
24.53883	140.3708	8.867141
24.60550	140.3717	8.877811
24.67050	140.3725	8.888436
24.73550	140.3802	9.082398
24.80217	140.3803	9.071639
24.86716	140.3802	9.070082
24.93383	140.3805	9.066649
24.99883	140.3792	9.060899
25.06383	140.3782	9.052688
25.13050	140.3780	9.040669
25.19550	140.3763	9.026642
25.26050	140.3756	9.008508
25.32716	140.3734	8.979275
25.39216	140.3715	8.941881
25.45883	140.3706	8.892741
25.52383	140.3673	8.841394
25.58883	140.3639	8.785141
25.65550	140.3614	8.714906
25.72050	140.3593	8.642884
25.78550	140.3535	8.564424
25.85217	140.3489	8.470141
25.91716	140.3451	8.373451
25.98383	140.3388	8.261789
26.04883	140.3340	8.142440
26.11383	140.3276	8.010919
26.18050	140.3206	7.871264
26.24550	140.3138	7.722888
26.31050	140.3063	7.569910
26.37716	140.2984	7.400054
26.44216	140.2896	7.230230
26.50883	140.2808	7.041108
26.57383	140.2719	6.853576
26.63883	140.2610	6.659749
26.70550	140.2506	6.458051
26.77050	140.2404	6.256460
26.83550	140.2291	6.045183
26.90216	140.2186	5.828972
26.96716	140.2064	5.611265
27.03216	140.1966	5.394309
27.09883	140.1849	5.168328
27.16383	140.1746	4.950798
27.23050	140.1640	4.726402
27.29550	140.1524	4.509938
27.36050	140.1421	4.297939
27.42717	140.1309	4.083111
27.49216	140.1203	3.885535
27.55716	140.1094	3.690612
27.62383	140.0993	3.483283
27.68883	140.0894	3.289640
27.75550	140.0790	3.098783
27.82050	140.0704	2.914271
27.88550	140.0607	2.737226
27.95217	140.0521	2.560084
28.01716	140.0432	2.394838
28.08216	140.0359	2.236087
28.14883	140.0282	2.081076
28.21383	140.0203	1.938743
28.28050	140.0133	1.794873
28.34550	140.0067	1.661691
28.41050	140.0011	1.537114
28.47717	139.9942	1.414482
28.54216	139.9887	1.302128
28.60716	139.9826	1.193693
28.67383	139.9789	1.089425
28.73883	139.9725	0.9922804
28.80550	139.9680	0.8967032
28.87050	139.9632	0.8132900
28.93550	139.9588	0.7305766
29.00217	139.9536	0.6543204
29.06716	139.9499	0.5804346
29.13216	139.9460	0.5134619
29.19883	139.9425	0.4466782
29.26383	139.9389	0.3841448
29.32883	139.9359	0.3232515
29.39550	139.9336	0.2625010
29.46050	139.9298	0.2113186
29.52717	139.9282	0.1598405
29.59216	139.9259	0.1096581
29.65716	139.9239	0.06578610
29.72383	139.9221	0.02408588
29.78883	139.9197	-.01532244
29.85383	139.9183	-.05072722
29.92050	139.9156	-.09114932
29.98550	139.9148	-0.1252710
30.05217	139.9133	-0.1579362
30.11716	139.9108	-0.1857961
30.18216	139.9090	-0.2107619
30.24883	139.9071	-0.2345490
30.31383	139.9056	-0.2595538
30.37883	139.9042	-0.2822654
30.44550	139.9031	-0.3080944
30.51050	139.9015	-0.3318761
30.57717	139.9001	-0.3523655
30.64216	139.8990	-0.3740637
30.70716	139.8976	-0.3915508
30.77383	139.8973	-0.4086416
30.83883	139.8966	-0.4271635
30.90383	139.8954	-0.4443153
30.97050	139.8945	-0.4620016
31.03550	139.8935	-0.4767960
31.10217	139.8934	-0.4915684
31.16716	139.8926	-0.5058426
31.23216	139.8923	-0.5218196
31.29883	139.8916	-0.5372363
31.36383	139.8914	-0.5501452
31.42883	139.8904	-0.5629068
31.49550	139.8899	-0.5765020
31.56050	139.8890	-0.5891950
31.62550	139.8889	-0.6012195
31.69216	139.8883	-0.6127940
31.75716	139.8874	-0.6234956
31.82383	139.8875	-0.6342121
31.88883	139.8870	-0.6445395
31.95383	139.8860	-0.6548443
32.02050	139.8856	-0.6650561
32.08550	139.8858	-0.6749086
32.15050	139.8844	-0.6841450
32.21716	139.8842	-0.6927514
32.28216	139.8831	-0.7006304
32.34883	139.8836	-0.7087872
32.41383	139.8831	-0.7168728
32.47883	139.8828	-0.7245393
32.54550	139.8824	-0.7321890
32.61050	139.8825	-0.7394522
32.67550	139.8820	-0.7464475
32.74216	139.8822	-0.7537569
32.80716	139.8820	-0.7608191
32.87383	139.8814	-0.7675881
32.93883	139.8799	-0.7737884
33.00383	139.8799	-0.7792234
33.07050	139.8792	-0.7844256
33.13550	139.8796	-0.7891438
33.20050	139.8790	-0.7941356
33.26716	139.8789	-0.7993860
33.33216	139.8791	-0.8045422
33.39883	139.8791	-0.8100032
33.46383	139.8779	-0.8151276
33.52883	139.8779	-0.8198470
33.59550	139.8778	-0.8247980
33.66050	139.8782	-0.8294384
33.72550	139.8780	-0.8339606
33.79217	139.8773	-0.8383048
33.85716	139.8774	-0.8419891
33.92216	139.8768	-0.8453612
33.98883	139.8765	-0.8484536
34.05383	139.8754	-0.8513801
34.12050	139.8756	-0.8544168
34.18550	139.8758	-0.8576270
34.25050	139.8751	-0.8604745
34.31716	139.8743	-0.8635939
34.38216	139.8756	-0.8665711
34.44717	139.8752	-0.8701026
34.51383	139.8749	-0.8736251
34.57883	139.8751	-0.8769972
34.64550	139.8749	-0.8802976
34.71050	139.8754	-0.8835919
34.77550	139.8749	-0.8863288
34.84216	139.8743	-0.8891406
34.90716	139.8744	-0.8915958
34.97217	139.8747	-0.8941063
35.03883	139.8744	-0.8967025
35.10383	139.8742	-0.8990532
35.17050	139.8744	-0.9015845
35.23550	139.8743	-0.9043516
35.30050	139.8742	-0.9075934
35.36716	139.8748	-0.9105931
35.43216	139.8744	-0.9127381
35.49716	139.8746	-0.9142394
35.56383	139.8742	-0.9154603
35.62883	139.8739	-0.9163959
35.69550	139.8743	-0.9177954
35.76050	139.8744	-0.9193008
35.82550	139.8740	-0.9207438
35.89216	139.8733	-0.9226593
35.95716	139.8737	-0.9247108
36.02217	139.8743	-0.9266384
36.08883	139.8733	-0.9283582
36.15383	139.8735	-0.9298191
36.21884	139.8736	-0.9312511
36.28550	139.8730	-0.9326199
36.35050	139.8734	-0.9340997
36.41716	139.8734	-0.9357515
36.48216	139.8734	-0.9375718
36.54716	139.8728	-0.9393910
36.61383	139.8734	-0.9409936
36.67883	139.8728	-0.9422754
36.74383	139.8722	-0.9431866
36.81050	139.8716	-0.9440553
36.87550	139.8722	-0.9448388
36.94216	139.8724	-0.9459421
37.00716	139.8721	-0.9472186
37.07217	139.8722	-0.9487968
37.13883	139.8727	-0.9505106
37.20383	139.8726	-0.9521249
37.26883	139.8726	-0.9536426
37.33550	139.8728	-0.9552743
37.40050	139.8721	-0.9564570
37.46716	139.8728	-0.9576911
37.53216	139.8719	-0.9585907
37.59716	139.8720	-0.9594880
37.66383	139.8730	-0.9603281
37.72883	139.8720	-0.9608495
37.79383	139.8724	-0.9613518
37.86050	139.8724	-0.9620716
37.92550	139.8718	-0.9630359
37.99216	139.8717	-0.9639386
38.05716	139.8712	-0.9649141
38.12216	139.8717	-0.9658965
38.18883	139.8712	-0.9666409
38.25383	139.8709	-0.9676080
38.31883	139.8713	-0.9687053
38.38550	139.8710	-0.9697387
38.45050	139.8706	-0.9704059
38.51550	139.8707	-0.9710030
38.58216	139.8710	-0.9716234
38.64717	139.8708	-0.9726305
38.71383	139.8707	-0.9739499
38.77883	139.8716	-0.9752625
38.84384	139.8709	-0.9764718
38.91050	139.8716	-0.9774276
38.97550	139.8713	-0.9786176
39.04050	139.8707	-0.9796075
39.10716	139.8716	-0.9805775
39.17216	139.8716	-0.9812024
39.23883	139.8712	-0.9817168
39.30383	139.8712	-0.9822130
39.36883	139.8708	-0.9824024
39.43550	139.8704	-0.9822684
39.50050	139.8711	-0.9823111
39.56550	139.8708	-0.9825759
39.63216	139.8699	-0.9829772
39.69717	139.8710	-0.9837169
39.76383	139.8715	-0.9845138
39.82883	139.8708	-0.9854449
39.89383	139.8704	-0.9862875
39.96050	139.8711	-0.9870926
40.02550	139.8709	-0.9880705
40.09050	139.8708	-0.9887899
40.15716	139.8707	-0.9894056
40.22217	139.8706	-0.9899472
40.28883	139.8706	-0.9906788
40.35383	139.8712	-0.9915238
40.41883	139.8708	-0.9920929
40.48550	139.8705	-0.9925912
40.55050	139.8711	-0.9930087
40.61550	139.8703	-0.9936707
40.68216	139.8713	-0.9942895
40.74716	139.8710	-0.9949022
40.81216	139.8712	-0.9952658
40.87883	139.8714	-0.9954863
40.94383	139.8709	-0.9955219
41.01050	139.8708	-0.9959070
41.07550	139.8712	-0.9962712
41.14050	139.8699	-0.9966015
41.20717	139.8700	-0.9969069
41.27217	139.8711	-0.9970528
41.33716	139.8692	-0.9970688
41.40383	139.8698	-0.9970775
41.46884	139.8694	-0.9970374
41.53550	139.8698	-0.9972795
41.60050	139.8697	-0.9976180
41.66550	139.8695	-0.9983782
41.73217	139.8701	-0.9992645
41.79716	139.8694	-1.000239
41.86217	139.8700	-1.001506
41.92883	139.8703	-1.002497
41.99383	139.8705	-1.002947
42.06050	139.8706	-1.003187
42.12550	139.8705	-1.003544
42.19050	139.8709	-1.004108
42.25717	139.8698	-1.004450
42.32217	139.8699	-1.004886
42.38716	139.8704	-1.005125
42.45383	139.8698	-1.004653
42.51883	139.8695	-1.004227
42.58550	139.8697	-1.004016
42.65050	139.8698	-1.003883
42.71550	139.8692	-1.004180
42.78217	139.8690	-1.004514
42.84716	139.8697	-1.004984
42.91217	139.8703	-1.005714
42.97883	139.8696	-1.006361
43.04383	139.8694	-1.006970
43.10883	139.8695	-1.007544
43.17550	139.8696	-1.008214
43.24050	139.8698	-1.008598
43.30717	139.8695	-1.008777
43.37216	139.8696	-1.009378
43.43716	139.8700	-1.009697
43.50383	139.8698	-1.009966
43.56883	139.8694	-1.010412
43.63383	139.8694	-1.010566
43.70050	139.8696	-1.010582
43.76550	139.8696	-1.010720
43.83217	139.8692	-1.011027
43.89717	139.8692	-1.011231
43.96216	139.8696	-1.011682
44.02883	139.8696	-1.012130
44.09384	139.8702	-1.012860
44.15883	139.8703	-1.013748
44.22550	139.8703	-1.014419
44.29050	139.8694	-1.015252
44.35717	139.8697	-1.015470
44.42216	139.8693	-1.015549
44.48717	139.8694	-1.015021
44.55383	139.8692	-1.014952
44.61883	139.8693	-1.015065
44.68383	139.8692	-1.015233
44.75050	139.8694	-1.015502
44.81550	139.8690	-1.015585
44.88217	139.8696	-1.015842
44.94717	139.8688	-1.016492
45.01216	139.8693	-1.016774
45.07883	139.8691	-1.017217
45.14383	139.8691	-1.017817
45.20883	139.8691	-1.018046
45.27550	139.8692	-1.018170
45.34050	139.8696	-1.018284
45.40550	139.8692	-1.018170
45.47217	139.8691	-1.018386
45.53717	139.8692	-1.018702
45.60383	139.8693	-1.019077
45.66883	139.8688	-1.019241
45.73383	139.8694	-1.019679
45.80050	139.8692	-1.020313
45.86550	139.8698	-1.020570
45.93050	139.8698	-1.020999
45.99716	139.8700	-1.020929
46.06216	139.8696	-1.021393
46.12883	139.8691	-1.021694
46.19383	139.8702	-1.022080
46.25883	139.8700	-1.022644
46.32550	139.8698	-1.022831
46.39050	139.8697	-1.022863
46.45550	139.8695	-1.022690
46.52217	139.8692	-1.022900
46.58716	139.8694	-1.022884
46.65383	139.8692	-1.022598
46.71884	139.8692	-1.022286
46.78383	139.8691	-1.022413
46.85050	139.8690	-1.022537
46.91550	139.8690	-1.022908
46.98050	139.8690	-1.023373
47.04716	139.8690	-1.023927
47.11217	139.8688	-1.024354
47.17883	139.8688	-1.024629
47.24383	139.8689	-1.024981
47.30883	139.8690	-1.024842
47.37550	139.8684	-1.024716
47.44050	139.8686	-1.024860
47.50550	139.8692	-1.025141
47.57217	139.8690	-1.025766
47.63716	139.8689	-1.026143
47.70216	139.8692	-1.026787
47.76883	139.8691	-1.027213
47.83383	139.8679	-1.027268
47.90050	139.8699	-1.027378
47.96550	139.8689	-1.027835
48.03050	139.8693	-1.028010
48.09716	139.8698	-1.028296
48.16217	139.8695	-1.028824
48.22717	139.8692	-1.028893
48.29383	139.8687	-1.029019
48.35883	139.8692	-1.028911
48.42550	139.8690	-1.028768
48.49050	139.8696	-1.028799
48.55550	139.8691	-1.028964
48.62216	139.8691	-1.028836
48.68716	139.8695	-1.029032
48.75217	139.8700	-1.029431
48.81883	139.8695	-1.029604
48.88383	139.8691	-1.029820
48.95050	139.8697	-1.030532
49.01550	139.8697	-1.031167
49.08050	139.8696	-1.031433
49.14717	139.8682	-1.031188
49.21216	139.8690	-1.030453
49.27716	139.8688	-1.029821
49.34384	139.8684	-1.029065
49.40883	139.8680	-1.028750
49.47550	139.8692	-1.029118
49.54050	139.8682	-1.029812
49.60550	139.8686	-1.030632
49.67216	139.8684	-1.031181
49.73717	139.8696	-1.032007
49.80217	139.8689	-1.032617
49.86883	139.8688	-1.033093
49.93383	139.8693	-1.033358
49.99883	139.8688	-1.033539
50.06550	139.8685	-1.033419
50.13050	139.8686	-1.033030
50.19717	139.8688	-1.032822
50.26216	139.8692	-1.032955
50.32717	139.8684	-1.033148
50.39383	139.8685	-1.033192
50.45883	139.8684	-1.033534
50.52383	139.8689	-1.033693
50.59050	139.8692	-1.033856
50.65550	139.8686	-1.034083
50.72217	139.8692	-1.034450
50.78717	139.8690	-1.034903
50.85217	139.8689	-1.035077
50.91883	139.8686	-1.035535
50.98383	139.8688	-1.035965
51.04883	139.8689	-1.036462
51.11550	139.8686	-1.036837
51.18050	139.8684	-1.036615
51.24717	139.8684	-1.036346
51.31216	139.8684	-1.036376
51.37717	139.8678	-1.036195
51.44384	139.8680	-1.036034
51.50883	139.8684	-1.036181
51.57383	139.8678	-1.036054
51.64050	139.8686	-1.036088
51.70550	139.8681	-1.036145
51.77217	139.8683	-1.036105
51.83716	139.8686	-1.036296
51.90217	139.8687	-1.036806
51.96884	139.8684	-1.036981
52.03383	139.8680	-1.037374
52.09883	139.8686	-1.037796
52.16550	139.8686	-1.038061
52.23050	139.8684	-1.038113
52.29550	139.8688	-1.038309
52.36217	139.8696	-1.038928
52.42717	139.8692	-1.039408
52.49382	139.8691	-1.039638
52.55883	139.8692	-1.039813
52.62383	139.8690	-1.040048
52.69050	139.8685	-1.039954
52.75550	139.8694	-1.039912
52.82050	139.8694	-1.039882
52.88716	139.8694	-1.039715
52.95216	139.8690	-1.039533
53.01884	139.8684	-1.039221
53.08383	139.8678	-1.038612
53.14883	139.8686	-1.038524
53.21550	139.8677	-1.038283
53.28050	139.8684	-1.038387
53.34550	139.8681	-1.038703
53.41216	139.8679	-1.039199
53.47717	139.8680	-1.039522
53.54382	139.8679	-1.039671
53.60883	139.8679	-1.039559
53.67383	139.8682	-1.039379
53.74050	139.8680	-1.039247
53.80550	139.8681	-1.039147
53.87050	139.8683	-1.039407
53.93716	139.8681	-1.039815
54.00217	139.8683	-1.040224
54.06884	139.8688	-1.041051
54.13383	139.8690	-1.041520
54.19883	139.8687	-1.041917
54.26550	139.8690	-1.042289
54.33050	139.8690	-1.042656
54.39550	139.8683	-1.042670
54.46216	139.8681	-1.042747
54.52717	139.8685	-1.042863
54.59217	139.8684	-1.042795
54.65883	139.8682	-1.042634
54.72382	139.8684	-1.043001
54.79050	139.8688	-1.043288
54.85550	139.8680	-1.043343
54.92050	139.8676	-1.043454
54.98717	139.8683	-1.043742
55.05217	139.8680	-1.043983
55.11716	139.8685	-1.044233
55.18383	139.8691	-1.044411
55.24883	139.8686	-1.044660
55.31550	139.8692	-1.044948
55.38050	139.8694	-1.045416
55.44550	139.8694	-1.045552
55.51216	139.8686	-1.045844
55.57717	139.8685	-1.045541
55.64216	139.8682	-1.045268
55.70883	139.8682	-1.044865
55.77383	139.8680	-1.044551
55.84050	139.8681	-1.044145
55.90550	139.8686	-1.043894
55.97050	139.8679	-1.043961
56.03716	139.8688	-1.044057
56.10217	139.8686	-1.044536
56.16716	139.8682	-1.044416
56.23383	139.8679	-1.044528
56.29883	139.8689	-1.044618
56.36550	139.8686	-1.044549
56.43050	139.8675	-1.044392
56.49550	139.8680	-1.043932
56.56216	139.8680	-1.043761
56.62717	139.8678	-1.043811
56.69216	139.8685	-1.044011
56.75883	139.8680	-1.043995
56.82383	139.8680	-1.044027
56.88882	139.8680	-1.044017
56.95550	139.8680	-1.044179
57.02050	139.8690	-1.044563
57.08716	139.8682	-1.044934
57.15217	139.8692	-1.045394
57.21717	139.8684	-1.046003
57.28383	139.8684	-1.046379
57.34882	139.8690	-1.046495
57.41382	139.8687	-1.046630
57.48050	139.8689	-1.046798
57.54550	139.8689	-1.046524
57.61217	139.8686	-1.046120
57.67717	139.8686	-1.045673
57.74216	139.8684	-1.045551
57.80883	139.8689	-1.045323
57.87383	139.8688	-1.045170
57.93882	139.8684	-1.045194
58.00550	139.8688	-1.045381
58.07050	139.8685	-1.045655
58.13716	139.8690	-1.046526
58.20216	139.8684	-1.046991
58.26716	139.8684	-1.047399
58.33383	139.8678	-1.047474
58.39883	139.8682	-1.047250
58.46382	139.8678	-1.046949
58.53050	139.8677	-1.046696
58.59550	139.8681	-1.046671
58.66216	139.8688	-1.046713
58.72717	139.8676	-1.046803
58.79217	139.8685	-1.047023
58.85883	139.8689	-1.047496
58.92383	139.8678	-1.047754
58.98882	139.8687	-1.047771
59.05550	139.8683	-1.048118
59.12050	139.8684	-1.048524
59.18550	139.8688	-1.048763
59.25217	139.8688	-1.049205
59.31716	139.8691	-1.049524
59.38383	139.8690	-1.049684
59.44883	139.8692	-1.049872
59.51382	139.8681	-1.050086
59.58050	139.8683	-1.049720
59.64550	139.8682	-1.049174
59.71050	139.8676	-1.048652
59.77717	139.8682	-1.047741
59.84217	139.8679	-1.047378
59.90883	139.8677	-1.047166
59.97382	139.8685	-1.047486
60.03882	139.8681	-1.047697
60.10550	139.8684	-1.048165
60.17050	139.8675	-1.048449
60.23550	139.8685	-1.048471
60.30217	139.8679	-1.048393
60.36716	139.8679	-1.048121
60.43383	139.8677	-1.048061
60.49883	139.8676	-1.047894
60.56382	139.8680	-1.047829
60.63050	139.8676	-1.047839
60.69550	139.8674	-1.047888
60.76050	139.8679	-1.047922
60.82717	139.8682	-1.048657
60.89216	139.8675	-1.049083
60.95883	139.8679	-1.049179
61.02383	139.8679	-1.049376
61.08882	139.8677	-1.049585
61.15550	139.8676	-1.049754
61.22050	139.8680	-1.050300
61.28550	139.8677	-1.050536
61.35217	139.8680	-1.050641
61.41716	139.8688	-1.050854
61.48217	139.8676	-1.050971
61.54883	139.8681	-1.051139
61.61382	139.8684	-1.051199
61.68050	139.8679	-1.051401
61.74550	139.8684	-1.051522
61.81050	139.8681	-1.051684
61.87717	139.8689	-1.051980
61.94216	139.8686	-1.052054
62.00717	139.8679	-1.052228
62.07383	139.8685	-1.052413
62.13882	139.8684	-1.052285
62.20550	139.8686	-1.052058
62.27050	139.8684	-1.052127
62.33550	139.8686	-1.052130
62.40217	139.8688	-1.052112
62.46717	139.8686	-1.051982
62.53217	139.8685	-1.051931
62.59882	139.8683	-1.051820
62.66382	139.8688	-1.051915
62.73050	139.8686	-1.051924
62.79550	139.8689	-1.051670
62.86050	139.8677	-1.051376
62.92717	139.8690	-1.051162
62.99216	139.8681	-1.050940
63.05217	139.9308	-0.8698625
63.11716	140.5114	-1.396631
63.18217	141.3391	-4.163938
63.24883	142.3205	-7.530585
63.31382	143.3607	-10.56642
63.38050	144.4898	-13.16214
63.44550	145.6346	-15.16810
63.51050	146.8142	-16.73872
63.57717	148.0498	-17.98306
63.64216	149.2738	-18.92777
63.70717	150.5122	-19.67140
63.77383	151.7934	-20.29403
63.83882	153.0505	-20.80102
63.90550	154.3474	-21.26152
63.97050	155.6148	-21.68451
64.03550	156.8851	-22.08636
64.10218	158.1904	-22.46108
64.16717	159.4660	-22.80598
64.23217	160.7432	-23.10821
64.29884	162.0568	-23.39577
64.36384	163.3390	-23.66166
64.43050	164.6569	-23.91901
64.49550	165.9434	-24.15920
64.56050	167.2313	-24.37732
64.62717	168.5526	-24.59184
64.69217	169.8410	-24.80536
64.75718	171.1295	-25.02687
64.82384	172.4518	-25.25935
64.88884	173.7411	-25.49354
64.95550	175.0631	-25.73709
65.02050	176.3523	-25.98281
65.08550	177.6410	-26.23730
65.15218	178.9619	-26.50033
65.21717	180.2509	-26.76851
65.28217	181.5385	-27.05018
65.34882	182.8582	-27.35386
65.41382	184.1451	-27.66121
65.47883	185.4323	-27.98912
65.54550	186.7526	-28.32080
65.61050	188.0393	-28.64481
65.67718	189.3589	-28.98220
65.74218	190.6457	-29.33338
65.80718	191.9298	-29.71078
65.87384	193.2452	-30.16664
65.93884	194.5238	-30.64437
66.00384	195.8019	-31.16543
66.07050	197.1112	-31.75570
66.13550	198.3858	-32.38470
66.20216	199.6902	-33.06819
66.26716	200.9602	-33.78428
66.33218	202.2283	-34.56203
66.39884	203.5258	-35.41058
66.46384	204.7884	-36.30218
66.52884	206.0478	-37.26026
66.59550	207.3354	-38.32387
66.66050	208.5855	-39.51578
66.72718	209.8591	-40.92628
66.79218	211.0920	-42.51443
66.85718	212.3129	-44.37195
66.92384	213.5496	-46.67976
66.98882	214.7323	-49.45420
67.05384	215.8865	-52.89494
67.12050	217.0336	-57.28020
67.18550	218.1104	-62.44861
67.25218	219.1788	-68.54366
67.31718	220.1930	-74.99000
67.38218	221.2039	-81.28000
67.44884	222.3120	-85.51132
67.51384	223.5758	-85.24812
67.57884	224.9964	-82.00497
67.64550	226.5557	-76.63024
67.71050	228.1575	-69.59044
67.77550	229.8476	-60.66400
67.84216	231.5898	-52.13970
67.90718	233.2027	-45.90938
67.97384	234.7696	-41.26563
68.03882	236.2356	-38.01684
68.10384	237.6558	-35.66532
68.17050	239.0775	-33.93966
68.23550	240.4404	-32.73781
68.30050	241.7859	-31.88686
68.36718	243.1530	-31.26239
68.43218	244.4774	-30.83470
68.49884	245.8295	-30.51824
68.56384	247.1436	-30.30164
68.62884	248.4525	-30.14930
68.69550	249.7935	-30.04664
68.76050	251.0999	-29.98864
68.82550	252.4037	-29.95619
68.89216	253.7410	-29.94365
68.95718	255.0429	-29.94164
69.02384	256.3784	-29.94357
69.08884	257.6808	-29.96106
69.15384	258.9832	-29.98880
69.22050	260.3186	-30.03523
69.28550	261.6188	-30.07787
69.35050	262.9187	-30.14041
69.41718	264.2534	-30.20451
69.48218	265.5535	-30.28377
69.54884	266.8876	-30.34795
69.61384	268.1876	-30.41383
69.67884	269.4878	-30.47591
69.74550	270.8206	-30.53208
69.81050	272.1198	-30.58274
69.87550	273.4204	-30.65142
69.94218	274.7544	-30.68479
70.00050	275.9224	-30.75302
70.06718	276.9580	-30.71326
70.13218	276.9494	-25.27709
70.19884	276.5174	-16.39423
70.26384	275.8506	-7.889806
70.32884	275.0243	-0.7731570
70.39550	274.0577	4.922812
70.46050	273.0309	9.132056
70.52550	271.9435	12.29661
70.59216	270.7785	14.72359
70.65718	269.6082	16.50374
70.72384	268.3802	17.88023
70.78882	267.1644	18.89839
70.85384	265.9328	19.68929
70.92050	264.6576	20.32198
70.98550	263.4022	20.80984
71.05050	262.1412	21.19000
71.11718	260.8406	21.50595
71.18218	259.5680	21.75758
71.24884	258.2592	21.96359
71.31384	256.9800	22.13658
71.37884	255.6984	22.27115
71.44550	254.3824	22.40306
71.51050	253.0971	22.50642
71.57550	251.8104	22.59596
71.64216	250.4895	22.67355
71.70718	249.2010	22.74315
71.77218	247.9102	22.80479
71.83884	246.5870	22.86094
71.90384	245.2957	22.89956
71.97050	243.9701	22.93344
72.03550	242.6770	22.95455
72.10050	241.3837	22.96954
72.16718	240.0567	22.98272
72.23218	238.7628	22.99373
72.29718	237.4680	23.00539
72.36384	236.1402	23.01680
72.42884	234.8458	23.02602
72.49550	233.5184	23.03400
72.56050	232.2242	23.03953
72.62550	230.9294	23.04320
72.69218	229.6002	23.04711
72.75718	228.3057	23.05047
72.82218	227.0114	23.05492
72.88884	225.6828	23.05912
72.95384	224.3884	23.06505
73.02050	223.0606	23.07122
73.08550	221.7655	23.07719
73.15050	220.4698	23.08297
73.21718	219.1423	23.08926
73.28218	217.8466	23.09619
73.34718	216.5508	23.10108
73.41382	215.2227	23.10444
73.47884	213.9277	23.10662
73.54550	212.5979	23.10800
73.61050	211.3020	23.10782
73.67550	210.0068	23.10649
73.74218	208.6774	23.10405
73.80718	207.3816	23.10018
73.87218	206.0858	23.09644
73.93884	204.7566	23.09201
74.00384	203.4595	23.08738
74.06884	202.1631	23.08130
74.13550	200.8344	23.07120
74.20050	199.5389	23.06296
74.26716	198.2101	23.05524
74.33218	196.9132	23.04815
74.39718	195.6172	23.04047
74.46384	194.2884	23.03322
74.52884	192.9924	23.02742
74.59384	191.6959	23.02116
74.66050	190.3666	23.01475
74.72551	189.0700	23.00766
74.79218	187.7414	23.00052
74.85718	186.4446	22.99301
74.92218	185.1490	22.98598
74.98882	183.8190	22.97822
75.05384	182.5218	22.96997
75.11884	181.2265	22.96182
75.18550	179.8972	22.95307
75.25050	178.6011	22.94715
75.31718	177.2708	22.94405
75.38218	175.9747	22.94324
75.44718	174.6794	22.94458
75.51384	173.3504	22.95005
75.57884	172.0558	22.96098
75.64384	170.7606	22.98604
75.71050	169.4352	23.04018
75.77550	168.1427	23.14756
75.84216	166.8215	23.34925
75.90718	165.5441	23.81508
75.97218	164.2941	24.99517
76.03882	163.0754	27.71326
76.10384	161.9872	32.58787
76.16884	161.0102	39.60188
76.23550	160.0714	47.61325
76.30050	159.1266	54.28665
76.36550	158.0771	58.47928
76.43218	156.8587	59.80346
76.49718	155.5352	58.46040
76.56384	154.0670	55.07605
76.62884	152.5678	50.66518
76.69384	151.0467	46.09984
76.76050	149.4998	41.89010
76.82550	148.0245	38.42589
76.89050	146.5782	35.59133
76.95718	145.1250	33.25736
77.02218	143.7312	31.42299
77.08884	142.3217	29.91608
77.15384	140.9625	28.73393
77.21884	139.6154	27.77276
77.28550	138.2432	26.95585
77.35050	136.9127	26.30524
77.41550	135.5891	25.77646
77.48218	134.2367	25.32475
77.54718	132.9202	24.94821
77.61384	131.5738	24.61064
77.67884	130.2619	24.32434
77.74384	128.9515	24.07327
77.81050	127.5826	23.27490
77.87550	126.3043	23.68571
77.94050	124.9967	23.45090
78.00718	123.6550	23.22068
78.07218	122.3486	23.01586
78.13884	121.0094	22.82598
78.20384	119.7056	22.65873
78.26882	118.4011	22.51206
78.33550	117.0642	22.37178
78.40050	115.7612	22.24089
78.46550	114.4586	22.11417
78.53218	113.1229	21.98952
78.59718	111.8215	21.87306
78.66218	110.5186	21.76189
78.72884	109.1828	21.64072
78.79384	107.8800	21.53200
78.86050	106.5444	21.40820
78.92550	105.2413	21.29673
78.99050	103.9403	21.18668
79.05718	102.6043	21.08290
79.12218	101.3022	20.97660
79.18718	100.0012	20.87516
79.25384	98.66545	20.77604
79.31884	97.36531	20.67854
79.38550	96.03007	20.58476
79.45050	94.72836	20.48660
79.51550	93.42762	20.38644
79.58218	92.09301	20.28846
79.64718	90.79188	20.19651
79.71218	89.49102	20.09253
79.77884	88.15744	19.99592
79.84384	86.85634	19.90864
79.91050	85.52113	19.81504
79.97551	84.22116	19.72324
80.04050	82.92040	19.63715
80.10718	81.58528	19.54795
80.17218	80.28461	19.46041
80.23718	78.98335	19.37568
80.30384	77.64861	19.28409
80.36884	76.34718	19.19875
80.43550	75.01250	19.11197
80.50050	73.71055	19.02527
80.56550	72.40910	18.94111
80.63218	71.07440	18.84392
80.69718	69.77268	18.75937
80.76218	68.47150	18.66814
80.82884	67.13699	18.57781
80.89384	65.83655	18.48457
80.95884	64.53430	18.39849
81.02550	63.19990	18.29976
81.09050	61.89856	18.20261
81.15718	60.56182	18.04171
81.22218	59.25955	17.97475
81.28718	57.94670	17.66938
81.35384	56.61318	17.64889
81.41884	55.31426	17.60648
81.48384	54.01435	17.54707
81.55050	52.68024	17.47323
81.61550	51.37981	17.39364
81.68218	50.04549	17.30148
81.74718	48.74376	17.21492
81.81216	47.44278	17.12889
81.87884	46.10718	17.04260
81.94384	44.80557	16.95802
82.00884	43.50406	16.87428
82.07550	42.16829	16.78324
82.14050	40.86582	16.69034
82.20718	39.53040	16.59177
82.27218	38.22718	16.48798
82.33718	36.92462	16.37470
82.40384	35.58862	16.26558
82.46884	34.28510	16.15414
82.53384	32.98216	16.04005
82.60050	31.64436	15.92739
82.66550	30.34061	15.82256
82.73218	29.00354	15.71026
82.79718	27.70030	15.58932
82.86218	26.39537	15.47089
82.92882	25.05720	15.34078
82.99384	23.75343	15.21382
83.05718	22.66214	15.32954
83.12218	22.56612	13.53618
83.18884	22.92792	9.039757
83.25384	23.56244	4.243290
83.31884	24.37504	-.02025144
83.38550	25.34028	-3.575538
83.45050	26.37090	-6.273755
83.51550	27.46770	-8.337852
83.58218	28.64082	-9.929670
83.64718	29.81994	-11.10643
83.71218	31.02355	-12.00378
83.77884	32.27934	-12.71749
83.84384	33.51787	-13.26107
83.91050	34.79776	-13.71857
83.97551	36.05641	-14.07998
84.04051	37.32082	-14.38066
84.10718	38.62225	-14.64538
84.17218	39.89536	-14.86472
84.23718	41.17146	-15.05975
84.30382	42.48292	-15.25773
84.36884	43.76211	-15.44811
84.43550	45.07757	-15.57784
84.50050	46.36516	-15.68918
84.56551	47.65287	-15.79828
84.63218	48.97452	-15.90965
84.69718	50.26431	-16.01896
84.76218	51.55618	-16.12829
84.82884	52.88105	-16.23362
84.89384	54.17397	-16.33296
84.96051	55.50115	-16.42441
85.02550	56.79389	-16.51981
85.09051	58.08741	-16.61628
85.15718	59.41476	-16.71436
85.22218	60.70968	-16.81370
85.28718	62.00495	-16.91466
85.35382	63.33350	-17.01437
85.41884	64.62847	-17.11258
85.48551	65.95660	-17.20284
85.55051	67.25184	-17.30435
85.61551	68.54780	-17.40620
85.68218	69.87696	-17.50565
85.74718	71.17298	-17.60425
85.81218	72.46957	-17.70188
85.87882	73.79848	-17.79664
85.94384	75.09369	-17.88902
86.00884	76.39005	-17.98309
86.07550	77.72080	-18.06575
86.14051	79.02320	-18.05121
86.20718	80.36010	-18.04771
86.27218	81.66163	-18.05075
86.33718	82.96216	-18.08335
86.40384	84.29491	-18.15348
86.46884	85.59285	-18.27305
86.53384	86.88818	-18.40771
86.60050	88.21764	-18.53031
86.66550	89.51207	-18.64984
86.73218	90.84124	-18.77234
86.79718	92.13791	-18.88541
86.86218	93.43445	-18.99401
86.92882	94.76430	-19.10410
86.99384	96.06264	-19.21178
87.05884	97.35961	-19.31184
87.12550	98.69070	-19.41674
87.19051	99.98798	-19.51959
87.25718	101.3180	-19.62306
87.32218	102.6164	-19.72734
87.38718	103.9138	-19.82492
87.45382	105.2447	-19.92824
87.51882	106.5423	-20.03096
87.58384	107.8397	-20.13380
87.65051	109.1697	-20.23443
87.71551	110.4681	-20.34388
87.78218	111.7983	-20.45167
87.84718	113.0957	-20.55803
87.91218	114.3921	-20.66936
87.97882	115.7220	-20.78362
88.04384	117.0190	-20.89830
88.10884	118.3172	-21.01512
88.17551	119.6469	-21.12598
88.24051	120.9445	-21.25310
88.30549	122.2411	-21.37564
88.37218	123.5713	-21.49922
88.43718	124.8675	-21.62252
88.50384	126.1975	-21.75161
88.56884	127.4929	-21.86788
88.63384	128.7900	-21.99054
88.70050	130.1197	-22.12045
88.76551	131.4163	-22.25422
88.83051	132.7124	-22.40620
88.89718	134.0424	-22.51399
88.96218	135.3383	-22.65742
89.02884	136.6666	-22.82071
89.09384	137.9629	-22.97235
89.15884	139.2590	-23.13410
89.22551	140.5876	-23.29367
89.29051	141.8830	-23.48310
89.35550	143.1777	-23.68537
89.42218	144.5046	-23.89246
89.48718	145.7991	-24.09520
89.55382	147.1250	-24.31010
89.61884	148.4179	-24.52967
89.68384	149.7100	-24.75662
89.75050	151.0346	-25.00847
89.81551	152.3251	-25.26988
89.88050	153.6142	-25.56741
89.94718	154.9351	-25.90879
90.01218	156.2205	-26.30817
90.07884	157.5335	-26.84416
90.14384	158.8005	-27.51141
90.20882	160.0903	-27.81458
90.27550	161.4134	-28.05359
90.34051	162.7180	-28.00148
90.40551	164.0240	-27.98922
90.47218	165.3616	-27.98717
90.53718	166.6648	-27.98554
90.60218	167.9689	-27.98469
90.66884	169.3047	-27.98427
90.73382	170.6068	-27.98621
90.80051	171.9419	-28.01748
90.86551	173.2432	-28.09741
90.93051	174.5418	-28.18545
90.99718	175.8726	-28.30412
91.06218	177.1686	-28.44956
91.12718	178.4624	-28.62814
91.19384	179.7886	-28.84722
91.25884	181.0793	-29.09283
91.32550	182.4012	-29.39398
91.39051	183.6897	-29.72321
91.45551	184.9750	-30.10557
91.52218	186.2909	-30.54654
91.58718	187.5718	-31.03291
91.65218	188.8490	-31.59900
91.71884	190.1553	-32.26526
91.78384	191.4248	-33.02187
91.85050	192.7201	-33.90960
91.91550	193.9787	-34.86834
91.98050	195.2352	-35.86460
92.04718	196.5228	-36.91112
92.11218	197.7776	-37.94825
92.17718	199.0316	-39.01565
92.24384	200.3140	-40.19906
92.30884	201.5597	-41.46762
92.37550	202.8309	-42.92440
92.44051	204.0649	-44.44546
92.50551	205.2963	-45.98467
92.57218	206.5648	-47.40646
92.63718	207.8194	-48.28305
92.70216	209.1171	-48.07178
92.76882	210.5221	-46.13408
92.83384	211.9621	-42.87895
92.89884	213.4332	-39.22330
92.96551	214.9304	-35.92178
93.03051	216.3569	-33.46519
93.09718	217.7865	-31.63166
93.16218	219.1539	-30.34456
93.22718	220.5025	-29.41531
93.29384	221.8738	-28.74380
93.35884	223.1993	-28.28209
93.42384	224.5181	-27.96274
93.49051	225.8667	-27.72965
93.55549	227.1758	-27.58828
93.62218	228.5178	-27.49219
93.68718	229.8234	-27.45155
93.75218	231.1278	-27.43658
93.81884	232.4634	-27.43265
93.88384	233.7658	-27.43427
93.94884	235.0672	-27.45160
94.01551	236.4013	-27.49428
94.08051	237.7025	-27.52913
94.14718	239.0364	-27.58050
94.21218	240.3382	-27.62668
94.27718	241.6399	-27.67661
94.34384	242.9725	-27.73460
94.40884	244.2733	-27.79176
94.47384	245.5733	-27.84469
94.54051	246.9060	-27.90328
94.60550	248.2066	-27.95169
94.67218	249.5406	-28.00263
94.73718	250.8412	-28.05342
94.80218	252.1406	-28.10422
94.86884	253.4749	-28.16218
94.93384	254.7744	-28.21538
94.99884	256.0737	-28.28370
95.06551	257.4076	-28.36039
95.13050	258.7069	-28.41984
95.19550	260.0059	-28.48722
95.26218	261.3326	-28.70930
95.32718	262.6365	-28.68452
95.39384	263.9731	-28.68169
95.45882	265.2739	-28.68642
95.52384	266.5742	-28.72170
95.59051	267.9081	-28.77918
95.65551	269.2084	-28.83684
95.72051	270.5075	-28.91765
95.78718	271.8399	-28.99457
-2.000000	5.000000	0.0000000