File: 3-C1(1.0mol%)+C20(0.6mol%)/matlab/150-1
CLOSED
Version	1.0
Language	English
Mode	Standard
Run	4
RunSerial	11785
Instrument	DSC Q2000 V24.11 Build 124
Module	DSC Standard Cell RC
Operator	Nan
File	\\Ae520-1454\ta\Data\DSC\UQ Composites\Nan\C1(4.5)+C20P(3)+CL(HotplateMixtureAB)\Iso150_60Min_1
ProcName	H/C/H/C/H complete wood PHA
InstSerial	2000-0883
AutoSerial	1293
Sample	Iso150_60Min
Size	35.5000	mg
PanMass	Not available
PanResist	Automatic Automatic  K/W
PanFactor	Default Default
Method	H/C/H/C/H complete wood PHA
Comment
Xcomment	Pan: Tzero Aluminum Hermetic
Xcomment	Gas1: Nitrogen 50.0 ml/min
Xcomment	Gas2: Nitrogen 50.0 ml/min
Text
Exotherm	UP
Kcell	1.05230
Cpconst	Standard: 0.938
Calib	-38.6961
TempCal	1	pts	157.46	156.60
TzeroDt	-87.6168 -0.0009 -1.4231
TzeroDtz	-87.6168 0.0057 6.9570
InstCalFile	Tzero: \\Ae520-1454\ta\Data\DSC\Calibration\2017\CALIBRATION\1562_RCS (90)_05_18_2017 10_50_44.TZR
InstCalFile	Baseline: \\Ae520-1454\ta\Data\DSC\Calibration\2017\2017-05-17_Calibration.001
InstCalFile	Sapphire: \\Ae520-1454\ta\Data\DSC\Calibration\2017\2017-05-17_Saphire.001
InstCalDate	Tzero 2017-05-18 Time 10:50:44
TempRange	-87.39 to 398.39 °C at 10.00 °C/min Heat Only
AutoZero	Delta T Offset 0.000 uV
AutoZero	Delta T0 Offset 0.000 uV
MultiptCal	0
MultiPtDesc	0) Not set
AutoCellConst	Calibration Date 2017-05-18 16:59:28
Controls	Gas 1  Event Off  Sampling 0.2
Cell#	RC-01562
CoolingUnit	RCS (90)
SelHeatFlow	Heat Flow T4 (mW)
AutoLidII	Installed
AutoAnalysis	Off
MacroFile
Nsig	3
Sig1	Time (min)
Sig2	Temperature (°C)
Sig3	Heat Flow (mW)
Date	2017-06-07
Time	16:20:27
OrgMethod	1: Equilibrate at 20.00 °C
OrgMethod	2: Ramp 40.00 °C/min to 150.00 °C
OrgMethod	3: Mark end of cycle 1
OrgMethod	4: Isothermal for 60.00 min
OrgMethod	5: Mark end of cycle 2
OrgMethod	6: Ramp 20.00 °C/min to 280.00 °C
OrgMethod	7: Mark end of cycle 3
OrgMethod	8: Ramp 20.00 °C/min to 20.00 °C
OrgMethod	9: Mark end of cycle 4
OrgMethod	10: Ramp 20.00 °C/min to 280.00 °C
OrgMethod	11: Mark end of cycle 5
OrgFile	C:\Users\jarra\Desktop\DSC\3-C1(1.0mol%)+C20(0.6mol%)\150-1
StartOfData
4.99994E-4	20.04659	0.2975201
0.06716666	20.30456	0.6011720
0.1321667	21.60203	-1.474126
0.1971667	23.28294	-6.137820
0.2638334	25.27096	-11.32236
0.3288334	27.37105	-15.84521
0.3938334	29.58928	-19.57441
0.4588333	31.89487	-22.49836
0.5255000	34.32681	-24.83090
0.5905000	36.74242	-26.63660
0.6555000	39.18666	-28.18657
0.7205000	41.64922	-29.61428
0.7871668	44.17520	-31.26784
0.8521668	46.62808	-33.09129
0.9171668	49.11008	-34.25525
0.9821668	51.62656	-35.11750
1.048834	54.20340	-36.25679
1.113833	56.70963	-37.54008
1.178834	59.21246	-38.89530
1.245500	61.78103	-40.43716
1.310500	64.24950	-42.87244
1.375500	66.63536	-47.15113
1.440500	68.86435	-54.77561
1.507167	70.91912	-67.10624
1.572166	72.69192	-83.07306
1.637166	74.33744	-100.5693
1.702167	75.99761	-117.9232
1.768833	77.72740	-134.2155
1.833833	79.59162	-146.6369
1.898834	81.67993	-155.1424
1.963833	83.90019	-161.7481
2.030500	86.54968	-159.0569
2.095500	89.57084	-150.7838
2.160500	93.02809	-132.1161
2.225500	96.70288	-113.5719
2.292167	100.2481	-98.83437
2.357167	103.5038	-87.89051
2.422167	106.6038	-79.57764
2.488834	109.6609	-73.12556
2.553833	112.5480	-68.42363
2.618834	115.3665	-64.88158
2.683833	118.1321	-62.25698
2.750500	120.9280	-60.34230
2.815500	123.6221	-59.05112
2.880500	126.2916	-58.17710
2.945500	128.9436	-57.59882
3.012167	131.6469	-57.30871
3.077166	134.2700	-57.25485
3.142166	136.8842	-57.41472
3.207167	139.4916	-57.74424
3.272167	142.0891	-58.19218
3.337167	144.1240	-58.84332
3.402167	145.2640	-54.39211
3.467166	146.1036	-47.40906
3.533833	146.7556	-40.04704
3.598834	147.2504	-33.79454
3.663833	147.6400	-28.66972
3.728833	147.9507	-24.58748
3.795500	148.2062	-21.31504
3.860500	148.4076	-18.83581
3.925500	148.5702	-16.89755
3.990500	148.7064	-15.36690
4.057167	148.8210	-14.11642
4.122166	148.9155	-13.13186
4.187167	148.9957	-12.31704
4.253834	149.0673	-11.60876
4.318833	149.1280	-11.01188
4.383834	149.1811	-10.48586
4.448834	149.2287	-10.00708
4.515500	149.2727	-9.547982
4.580500	149.3115	-9.124618
4.645500	149.3478	-8.718228
4.710500	149.3812	-8.316351
4.777167	149.4138	-7.915557
4.842167	149.4434	-7.530989
4.907166	149.4714	-7.158794
4.972168	149.4979	-6.802388
5.038834	149.5223	-6.452420
5.103833	149.5446	-6.128271
5.168833	149.5658	-5.824397
5.235500	149.5854	-5.526356
5.300500	149.6035	-5.255022
5.365500	149.6207	-4.994746
5.430500	149.6361	-4.750168
5.497168	149.6513	-4.504798
5.562168	149.6650	-4.285652
5.627168	149.6788	-4.078058
5.692166	149.6901	-3.878848
5.758832	149.7018	-3.685208
5.823834	149.7124	-3.497522
5.888832	149.7235	-3.321348
5.953832	149.7327	-3.154864
6.020500	149.7435	-2.985235
6.085500	149.7520	-2.833316
6.150500	149.7603	-2.680584
6.215500	149.7680	-2.537094
6.282166	149.7763	-2.399560
6.347168	149.7834	-2.265664
6.412168	149.7910	-2.135578
6.478832	149.7974	-2.001685
6.543832	149.8052	-1.874278
6.608832	149.8114	-1.745420
6.673834	149.8192	-1.618563
6.740500	149.8250	-1.488982
6.805500	149.8325	-1.368414
6.870500	149.8388	-1.247058
6.935500	149.8444	-1.134789
7.002168	149.8500	-1.032640
7.067168	149.8564	-0.9442590
7.132168	149.8596	-0.8645155
7.197168	149.8637	-0.7909824
7.263834	149.8676	-0.7336521
7.328834	149.8706	-0.6775494
7.393832	149.8730	-0.6223687
7.460500	149.8767	-0.5713378
7.525500	149.8793	-0.5134468
7.590500	149.8827	-0.4552340
7.655500	149.8849	-0.3974416
7.722168	149.8892	-0.3351050
7.787168	149.8926	-0.2710530
7.852168	149.8954	-0.2070958
7.917168	149.8986	-0.1437531
7.983832	149.9029	-.07625504
8.048834	149.9065	-.01277948
8.113834	149.9092	0.05485034
8.178832	149.9128	0.1186882
8.245500	149.9157	0.1856619
8.310500	149.9192	0.2503386
8.375500	149.9235	0.3212292
8.442168	149.9266	0.3916006
8.507168	149.9304	0.4665799
8.572168	149.9340	0.5414680
8.637168	149.9384	0.6152033
8.703834	149.9426	0.6853591
8.768832	149.9456	0.7510574
8.833832	149.9497	0.8125495
8.898834	149.9518	0.8755975
8.965500	149.9558	0.9361726
9.030500	149.9587	0.9972788
9.095500	149.9619	1.062094
9.160499	149.9646	1.122272
9.227168	149.9681	1.177493
9.292168	149.9708	1.228169
9.357166	149.9747	1.280066
9.422168	149.9766	1.331393
9.488834	149.9791	1.383362
9.553832	149.9819	1.429117
9.618834	149.9840	1.477295
9.685499	149.9867	1.529997
9.750500	149.9890	1.578155
9.815500	149.9919	1.627624
9.880500	149.9941	1.675147
9.947168	149.9970	1.722304
10.01217	149.9997	1.771858
10.07717	150.0022	1.822564
10.14217	150.0047	1.868367
10.20883	150.0076	1.916922
10.27383	150.0094	1.966789
10.33883	150.0122	2.014764
10.40383	150.0146	2.065457
10.47050	150.0166	2.117848
10.53550	150.0197	2.167840
10.60050	150.0227	2.220706
10.66717	150.0248	2.275404
10.73217	150.0282	2.326202
10.79717	150.0304	2.379900
10.86217	150.0331	2.433959
10.92883	150.0364	2.489248
10.99384	150.0384	2.549211
11.05884	150.0419	2.603796
11.12383	150.0446	2.661117
11.19050	150.0477	2.719813
11.25550	150.0506	2.779900
11.32050	150.0530	2.841110
11.38550	150.0562	2.901594
11.45217	150.0594	2.962622
11.51717	150.0625	3.025286
11.58217	150.0661	3.088240
11.64883	150.0692	3.155506
11.71383	150.0718	3.217908
11.77883	150.0760	3.283039
11.84383	150.0794	3.348638
11.91050	150.0816	3.415456
11.97550	150.0859	3.482995
12.04050	150.0895	3.553110
12.10550	150.0930	3.620594
12.17217	150.0968	3.692008
12.23717	150.0999	3.762717
12.30216	150.1036	3.834172
12.36716	150.1070	3.904728
12.43383	150.1112	3.983887
12.49883	150.1150	4.055295
12.56383	150.1192	4.128883
12.62884	150.1221	4.201435
12.69550	150.1260	4.279856
12.76050	150.1299	4.355198
12.82550	150.1336	4.430186
12.89216	150.1374	4.510676
12.95717	150.1424	4.588524
13.02217	150.1454	4.666803
13.08717	150.1488	4.748033
13.15383	150.1536	4.831160
13.21884	150.1584	4.914627
13.28383	150.1621	5.006206
13.34883	150.1667	5.100218
13.41550	150.1721	5.199019
13.48050	150.1774	5.309248
13.54550	150.1832	5.431196
13.61050	150.1904	5.576885
13.67717	150.1989	5.762039
13.74216	150.2094	5.983672
13.80717	150.2227	6.265166
13.87384	150.2398	6.639058
13.93883	150.2616	7.101901
14.00383	150.2887	7.672644
14.06884	150.3218	8.370031
14.13550	150.3621	9.202762
14.20050	150.4060	10.12680
14.26550	150.4564	11.14942
14.33050	150.5099	12.24348
14.39717	150.5676	13.42540
14.46217	150.6273	14.60469
14.52717	150.6862	15.79440
14.59216	150.7446	16.97388
14.65883	150.8042	18.14419
14.72383	150.8594	19.23412
14.78883	150.9114	20.25765
14.85550	150.9612	21.22342
14.92050	151.0043	22.06675
14.98550	151.0436	22.81494
15.05050	151.0778	23.45718
15.11716	151.1058	24.00632
15.18217	151.1288	24.43608
15.24717	151.1474	24.76950
15.31216	151.1604	25.01735
15.37883	151.1708	25.19414
15.44384	151.1782	25.32894
15.50883	151.1840	25.43416
15.57384	151.1877	25.48226
15.64050	151.1886	25.49213
15.70550	151.1876	25.47974
15.77050	151.1831	25.39306
15.83550	151.1791	25.28355
15.90217	151.1724	25.15164
15.96716	151.1659	24.99892
16.03216	151.1577	24.83495
16.09883	151.1487	24.65522
16.16383	151.1394	24.45961
16.22883	151.1298	24.26044
16.29383	151.1194	24.05110
16.36050	151.1097	23.84020
16.42550	151.0979	23.61608
16.49050	151.0862	23.38535
16.55550	151.0745	23.14834
16.62216	151.0628	22.90184
16.68716	151.0519	22.66480
16.75216	151.0386	22.41582
16.81716	151.0255	22.16354
16.88383	151.0132	21.88961
16.94884	150.9989	21.60800
17.01383	150.9843	21.30994
17.08050	150.9692	20.97408
17.14550	150.9524	20.62819
17.21050	150.9337	20.25219
17.27550	150.9148	19.84594
17.34216	150.8928	19.40150
17.40716	150.8690	18.93244
17.47216	150.8452	18.43248
17.53717	150.8200	17.92656
17.60383	150.7915	17.35838
17.66883	150.7627	16.77854
17.73383	150.7332	16.18034
17.79883	150.7018	15.56710
17.86550	150.6690	14.92168
17.93050	150.6376	14.28810
17.99550	150.6052	13.64126
18.06216	150.5719	12.98154
18.12716	150.5404	12.34070
18.19216	150.5092	11.70627
18.25716	150.4774	11.08206
18.32383	150.4464	10.45418
18.38883	150.4160	9.856964
18.45383	150.3866	9.276363
18.51883	150.3587	8.716731
18.58550	150.3298	8.164063
18.65050	150.3038	7.640799
18.71550	150.2791	7.147558
18.78050	150.2549	6.669649
18.84716	150.2320	6.207743
18.91217	150.2098	5.775720
18.97716	150.1893	5.365361
19.04216	150.1685	4.975856
19.10883	150.1500	4.594479
19.17383	150.1318	4.244641
19.23883	150.1154	3.916194
19.30550	150.0986	3.595453
19.37050	150.0837	3.304733
19.43550	150.0702	3.027966
19.50050	150.0572	2.770221
19.56716	150.0444	2.520364
19.63216	150.0327	2.291438
19.69716	150.0218	2.077774
19.76216	150.0114	1.875120
19.82883	150.0013	1.680693
19.89383	149.9926	1.500358
19.95883	149.9844	1.339571
20.02383	149.9771	1.180108
20.09050	149.9702	1.031909
20.15550	149.9624	0.8964726
20.22050	149.9558	0.7731990
20.28717	149.9493	0.6568281
20.35216	149.9440	0.5476910
20.41716	149.9390	0.4474512
20.48216	149.9344	0.3512326
20.54883	149.9295	0.2601330
20.61383	149.9259	0.1783571
20.67883	149.9210	0.1031897
20.74383	149.9182	0.02921088
20.81050	149.9148	-.03884052
20.87550	149.9117	-0.1027610
20.94050	149.9088	-0.1592434
21.00550	149.9060	-0.2128331
21.07216	149.9028	-0.2630905
21.13716	149.9000	-0.3062928
21.20216	149.8970	-0.3448382
21.26883	149.8954	-0.3884246
21.33383	149.8924	-0.4237461
21.39883	149.8914	-0.4590509
21.46383	149.8897	-0.4915378
21.53050	149.8874	-0.5225795
21.59550	149.8862	-0.5534926
21.66050	149.8851	-0.5814020
21.72550	149.8837	-0.6075812
21.79216	149.8825	-0.6352654
21.85716	149.8814	-0.6578588
21.92216	149.8801	-0.6778958
21.98716	149.8796	-0.6975624
22.05383	149.8778	-0.7147269
22.11883	149.8776	-0.7296074
22.18383	149.8757	-0.7468310
22.24883	149.8753	-0.7615748
22.31550	149.8745	-0.7760739
22.38050	149.8739	-0.7906316
22.44550	149.8729	-0.8039275
22.51216	149.8724	-0.8186024
22.57716	149.8717	-0.8336478
22.64216	149.8708	-0.8475663
22.70717	149.8710	-0.8605930
22.77383	149.8700	-0.8737999
22.83883	149.8702	-0.8861469
22.90383	149.8693	-0.8982860
22.96883	149.8698	-0.9099582
23.03550	149.8687	-0.9212375
23.10050	149.8687	-0.9314876
23.16550	149.8674	-0.9410555
23.23050	149.8678	-0.9500828
23.29716	149.8661	-0.9586602
23.36216	149.8659	-0.9660796
23.42717	149.8651	-0.9734008
23.49383	149.8647	-0.9808098
23.55883	149.8641	-0.9879956
23.62383	149.8634	-0.9952137
23.68883	149.8632	-1.002553
23.75550	149.8631	-1.010097
23.82050	149.8628	-1.017390
23.88550	149.8628	-1.024658
23.95050	149.8630	-1.031726
24.01716	149.8621	-1.038415
24.08216	149.8624	-1.044692
24.14716	149.8621	-1.050994
24.21216	149.8626	-1.057227
24.27883	149.8620	-1.063183
24.34383	149.8621	-1.068466
24.40883	149.8616	-1.073298
24.47550	149.8616	-1.078121
24.54050	149.8621	-1.083282
24.60550	149.8614	-1.088043
24.67050	149.8606	-1.092453
24.73716	149.8618	-1.096354
24.80217	149.8604	-1.099874
24.86716	149.8604	-1.102911
24.93216	149.8591	-1.105414
24.99883	149.8593	-1.108052
25.06383	149.8587	-1.110715
25.12883	149.8590	-1.113926
25.19383	149.8589	-1.117544
25.26050	149.8596	-1.121615
25.32550	149.8586	-1.125652
25.39050	149.8592	-1.129867
25.45550	149.8589	-1.133742
25.52216	149.8592	-1.137433
25.58716	149.8584	-1.141047
25.65216	149.8595	-1.144482
25.71883	149.8584	-1.147494
25.78383	149.8583	-1.149659
25.84883	149.8578	-1.151332
25.91383	149.8577	-1.152740
25.98050	149.8577	-1.154145
26.04550	149.8572	-1.155540
26.11050	149.8572	-1.157306
26.17550	149.8571	-1.159398
26.24216	149.8567	-1.161976
26.30716	149.8571	-1.164968
26.37216	149.8577	-1.168104
26.43717	149.8584	-1.171128
26.50383	149.8579	-1.173822
26.56883	149.8570	-1.175889
26.63383	149.8568	-1.177680
26.70050	149.8574	-1.179247
26.76550	149.8569	-1.180526
26.83050	149.8558	-1.181916
26.89550	149.8564	-1.183293
26.96216	149.8560	-1.184554
27.02717	149.8560	-1.185730
27.09216	149.8563	-1.187289
27.15716	149.8559	-1.188550
27.22383	149.8555	-1.190020
27.28883	149.8552	-1.191337
27.35383	149.8556	-1.192901
27.41883	149.8546	-1.194370
27.48550	149.8552	-1.195996
27.55050	149.8545	-1.197487
27.61550	149.8550	-1.199140
27.68216	149.8552	-1.200815
27.74716	149.8556	-1.202766
27.81217	149.8549	-1.204874
27.87716	149.8566	-1.207241
27.94383	149.8560	-1.209395
28.00883	149.8564	-1.211359
28.07383	149.8561	-1.212892
28.13883	149.8560	-1.214340
28.20550	149.8560	-1.215400
28.27050	149.8553	-1.216167
28.33550	149.8556	-1.216881
28.40050	149.8551	-1.217475
28.46716	149.8556	-1.218036
28.53216	149.8552	-1.218428
28.59716	149.8544	-1.218942
28.66217	149.8549	-1.219750
28.72883	149.8548	-1.220596
28.79383	149.8542	-1.221439
28.85883	149.8546	-1.222510
28.92550	149.8545	-1.223989
28.99050	149.8547	-1.225523
29.05550	149.8548	-1.226866
29.12050	149.8551	-1.228225
29.18717	149.8553	-1.229821
29.25217	149.8551	-1.231199
29.31716	149.8553	-1.232335
29.38216	149.8554	-1.233574
29.44883	149.8552	-1.234721
29.51383	149.8551	-1.235864
29.57883	149.8547	-1.236610
29.64383	149.8548	-1.236896
29.71050	149.8545	-1.237026
29.77550	149.8543	-1.237290
29.84050	149.8537	-1.237739
29.90716	149.8542	-1.238168
29.97216	149.8542	-1.238966
30.03717	149.8548	-1.239921
30.10217	149.8548	-1.240865
30.16883	149.8545	-1.241994
30.23383	149.8552	-1.243197
30.29883	149.8546	-1.244276
30.36383	149.8541	-1.245098
30.43050	149.8550	-1.245806
30.49550	149.8543	-1.246381
30.56050	149.8536	-1.246832
30.62550	149.8538	-1.246878
30.69216	149.8538	-1.246626
30.75716	149.8540	-1.246612
30.82217	149.8537	-1.246738
30.88883	149.8532	-1.247297
30.95383	149.8540	-1.247895
31.01883	149.8539	-1.248899
31.08383	149.8530	-1.249914
31.15050	149.8538	-1.250724
31.21550	149.8542	-1.251664
31.28050	149.8544	-1.252743
31.34550	149.8541	-1.253660
31.41217	149.8538	-1.254547
31.47717	149.8543	-1.255621
31.54216	149.8537	-1.256397
31.60716	149.8541	-1.257068
31.67383	149.8539	-1.257284
31.73883	149.8536	-1.257444
31.80383	149.8538	-1.257893
31.86883	149.8537	-1.258160
31.93550	149.8533	-1.258436
32.00050	149.8535	-1.258640
32.06550	149.8538	-1.259268
32.13216	149.8537	-1.260294
32.19717	149.8538	-1.260502
32.26216	149.8528	-1.260376
32.32717	149.8534	-1.260145
32.39383	149.8533	-1.260352
32.45883	149.8532	-1.260811
32.52383	149.8531	-1.261066
32.58883	149.8525	-1.261309
32.65550	149.8529	-1.261754
32.72050	149.8523	-1.262186
32.78550	149.8527	-1.262518
32.85050	149.8527	-1.263360
32.91716	149.8531	-1.264218
32.98216	149.8528	-1.264671
33.04716	149.8529	-1.265347
33.11383	149.8535	-1.266058
33.17883	149.8536	-1.266795
33.24383	149.8532	-1.267256
33.30883	149.8534	-1.267613
33.37550	149.8534	-1.268154
33.44050	149.8537	-1.269011
33.50550	149.8536	-1.269719
33.57050	149.8528	-1.270014
33.63716	149.8534	-1.270005
33.70216	149.8520	-1.269745
33.76716	149.8526	-1.269718
33.83216	149.8528	-1.269688
33.89883	149.8528	-1.269557
33.96383	149.8534	-1.269637
34.02883	149.8530	-1.270018
34.09550	149.8533	-1.270566
34.16050	149.8533	-1.271313
34.22550	149.8529	-1.272132
34.29050	149.8524	-1.272806
34.35716	149.8532	-1.273682
34.42216	149.8534	-1.274090
34.48717	149.8535	-1.274298
34.55217	149.8539	-1.274425
34.61883	149.8528	-1.274537
34.68384	149.8530	-1.275031
34.74883	149.8526	-1.275244
34.81383	149.8536	-1.275403
34.88050	149.8527	-1.275285
34.94550	149.8525	-1.275056
35.01050	149.8524	-1.274336
35.07550	149.8523	-1.274040
35.14216	149.8523	-1.274145
35.20716	149.8520	-1.274674
35.27217	149.8529	-1.275630
35.33883	149.8525	-1.276509
35.40383	149.8528	-1.277414
35.46884	149.8529	-1.278340
35.53383	149.8523	-1.279357
35.60050	149.8535	-1.280667
35.66550	149.8536	-1.281929
35.73050	149.8529	-1.282240
35.79550	149.8531	-1.282462
35.86217	149.8530	-1.282671
35.92717	149.8538	-1.282981
35.99216	149.8530	-1.283151
36.05716	149.8532	-1.283019
36.12383	149.8521	-1.282893
36.18883	149.8533	-1.282797
36.25383	149.8522	-1.282242
36.32050	149.8523	-1.282152
36.38550	149.8526	-1.282263
36.45050	149.8524	-1.282206
36.51550	149.8520	-1.281785
36.58216	149.8519	-1.281357
36.64717	149.8524	-1.280950
36.71216	149.8522	-1.280546
36.77716	149.8518	-1.280705
36.84384	149.8519	-1.280944
36.90883	149.8517	-1.281174
36.97383	149.8521	-1.281671
37.03883	149.8523	-1.282458
37.10550	149.8522	-1.282844
37.17050	149.8523	-1.283217
37.23550	149.8525	-1.283587
37.30217	149.8528	-1.284225
37.36716	149.8525	-1.284708
37.43216	149.8534	-1.285178
37.49716	149.8531	-1.285578
37.56383	149.8529	-1.285751
37.62883	149.8532	-1.285867
37.69383	149.8530	-1.285809
37.75883	149.8527	-1.285530
37.82550	149.8522	-1.285361
37.89050	149.8523	-1.285070
37.95550	149.8526	-1.284862
38.02050	149.8519	-1.284688
38.08716	149.8526	-1.285054
38.15216	149.8529	-1.285310
38.21716	149.8520	-1.285630
38.28216	149.8526	-1.286120
38.34883	149.8533	-1.286848
38.41383	149.8530	-1.287686
38.47883	149.8530	-1.288284
38.54550	149.8533	-1.288921
38.61050	149.8533	-1.289400
38.67550	149.8528	-1.289578
38.74050	149.8522	-1.289252
38.80716	149.8522	-1.288664
38.87216	149.8516	-1.288470
38.93716	149.8516	-1.288155
39.00217	149.8519	-1.288336
39.06883	149.8518	-1.288366
39.13383	149.8523	-1.288266
39.19883	149.8512	-1.288396
39.26383	149.8521	-1.288650
39.33050	149.8521	-1.289476
39.39550	149.8522	-1.290368
39.46050	149.8529	-1.291165
39.52716	149.8523	-1.291755
39.59216	149.8530	-1.292530
39.65716	149.8534	-1.293346
39.72217	149.8533	-1.294072
39.78883	149.8527	-1.294686
39.85383	149.8535	-1.294885
39.91883	149.8535	-1.295070
39.98383	149.8529	-1.295014
40.05050	149.8528	-1.294315
40.11550	149.8528	-1.293497
40.18050	149.8530	-1.293122
40.24550	149.8528	-1.293063
40.31216	149.8528	-1.293188
40.37717	149.8526	-1.293524
40.44216	149.8524	-1.293808
40.50883	149.8518	-1.293595
40.57383	149.8521	-1.293708
40.63883	149.8520	-1.293867
40.70383	149.8518	-1.293888
40.77050	149.8522	-1.294321
40.83550	149.8520	-1.294904
40.90050	149.8520	-1.295432
40.96550	149.8519	-1.295721
41.03217	149.8521	-1.296099
41.09716	149.8514	-1.296212
41.16217	149.8514	-1.295905
41.22717	149.8517	-1.295857
41.29383	149.8518	-1.296146
41.35883	149.8511	-1.296599
41.42383	149.8516	-1.297245
41.48883	149.8515	-1.297657
41.55550	149.8518	-1.298076
41.62050	149.8524	-1.298704
41.68550	149.8518	-1.299408
41.75217	149.8515	-1.300105
41.81717	149.8520	-1.300847
41.88217	149.8520	-1.301607
41.94717	149.8525	-1.302322
42.01383	149.8515	-1.302797
42.07883	149.8528	-1.303350
42.14383	149.8520	-1.303449
42.20883	149.8523	-1.303688
42.27550	149.8527	-1.304214
42.34050	149.8526	-1.304734
42.40550	149.8522	-1.305182
42.47050	149.8506	-1.304948
42.53717	149.8526	-1.304792
42.60217	149.8519	-1.304595
42.66716	149.8510	-1.304160
42.73383	149.8522	-1.304007
42.79883	149.8513	-1.303909
42.86383	149.8516	-1.303759
42.92883	149.8512	-1.303634
42.99550	149.8517	-1.303850
43.06050	149.8513	-1.304096
43.12550	149.8515	-1.304149
43.19050	149.8505	-1.304047
43.25717	149.8509	-1.304207
43.32217	149.8518	-1.304564
43.38716	149.8518	-1.304900
43.45216	149.8516	-1.305173
43.51883	149.8513	-1.305623
43.58383	149.8515	-1.306129
43.64883	149.8513	-1.306571
43.71550	149.8513	-1.307134
43.78050	149.8515	-1.307040
43.84550	149.8511	-1.307376
43.91050	149.8518	-1.307649
43.97717	149.8514	-1.307949
44.04217	149.8523	-1.308462
44.10717	149.8521	-1.308752
44.17216	149.8513	-1.308848
44.23883	149.8518	-1.308922
44.30383	149.8519	-1.309105
44.36883	149.8517	-1.309470
44.43383	149.8514	-1.309656
44.50050	149.8514	-1.309672
44.56550	149.8516	-1.309728
44.63050	149.8513	-1.309460
44.69550	149.8517	-1.309022
44.76216	149.8511	-1.308790
44.82717	149.8514	-1.308720
44.89217	149.8518	-1.308819
44.95883	149.8514	-1.309299
45.02383	149.8510	-1.309478
45.08883	149.8516	-1.309590
45.15383	149.8519	-1.309937
45.22050	149.8512	-1.310291
45.28550	149.8514	-1.310582
45.35050	149.8519	-1.310870
45.41550	149.8517	-1.311251
45.48217	149.8518	-1.311509
45.54716	149.8520	-1.311794
45.61217	149.8516	-1.312166
45.67717	149.8520	-1.312680
45.74383	149.8511	-1.313367
45.80883	149.8514	-1.313699
45.87383	149.8514	-1.313464
45.94050	149.8507	-1.312919
46.00550	149.8509	-1.312254
46.07050	149.8506	-1.311797
46.13550	149.8504	-1.311578
46.20216	149.8502	-1.311332
46.26717	149.8505	-1.311342
46.33217	149.8499	-1.311716
46.39717	149.8503	-1.311961
46.46383	149.8496	-1.311951
46.52883	149.8497	-1.312108
46.59384	149.8507	-1.312618
46.65883	149.8504	-1.313204
46.72550	149.8504	-1.313937
46.79050	149.8510	-1.314947
46.85550	149.8511	-1.315971
46.92216	149.8506	-1.316956
46.98717	149.8513	-1.317856
47.05217	149.8509	-1.318249
47.11716	149.8515	-1.318231
47.18383	149.8506	-1.317642
47.24883	149.8514	-1.316985
47.31383	149.8500	-1.316524
47.37883	149.8511	-1.316176
47.44550	149.8509	-1.315932
47.51050	149.8508	-1.315754
47.57550	149.8502	-1.315587
47.64050	149.8509	-1.315514
47.70717	149.8515	-1.315836
47.77217	149.8510	-1.316114
47.83716	149.8515	-1.316337
47.90216	149.8509	-1.316692
47.96884	149.8516	-1.317242
48.03383	149.8514	-1.317746
48.09883	149.8515	-1.318068
48.16550	149.8513	-1.318001
48.23050	149.8513	-1.318144
48.29550	149.8514	-1.318116
48.36050	149.8514	-1.318131
48.42717	149.8518	-1.318082
48.49216	149.8507	-1.318026
48.55717	149.8509	-1.317897
48.62216	149.8514	-1.318157
48.68883	149.8516	-1.318098
48.75383	149.8506	-1.318224
48.81883	149.8507	-1.318574
48.88383	149.8514	-1.318942
48.95050	149.8516	-1.319081
49.01550	149.8512	-1.319059
49.08050	149.8513	-1.318848
49.14717	149.8513	-1.318849
49.21216	149.8512	-1.318854
49.27716	149.8515	-1.318891
49.34217	149.8514	-1.318990
49.40883	149.8504	-1.318977
49.47383	149.8509	-1.319234
49.53883	149.8508	-1.319285
49.60383	149.8511	-1.319313
49.67050	149.8512	-1.319241
49.73550	149.8502	-1.319113
49.80050	149.8506	-1.318977
49.86550	149.8506	-1.318745
49.93217	149.8506	-1.318889
49.99716	149.8499	-1.319306
50.06216	149.8503	-1.319682
50.12883	149.8501	-1.319963
50.19383	149.8495	-1.320258
50.25883	149.8507	-1.320504
50.32383	149.8506	-1.320740
50.39050	149.8505	-1.321274
50.45550	149.8505	-1.321669
50.52050	149.8506	-1.322119
50.58550	149.8508	-1.322536
50.65216	149.8513	-1.322966
50.71717	149.8510	-1.323142
50.78217	149.8511	-1.323369
50.84716	149.8512	-1.323824
50.91383	149.8509	-1.323897
50.97883	149.8515	-1.324160
51.04383	149.8507	-1.324084
51.10883	149.8508	-1.323859
51.17550	149.8514	-1.323701
51.24050	149.8510	-1.323548
51.30550	149.8509	-1.323500
51.37217	149.8508	-1.323309
51.43716	149.8511	-1.323187
51.50217	149.8505	-1.323126
51.56716	149.8506	-1.323539
51.63383	149.8504	-1.323581
51.69883	149.8508	-1.323317
51.76383	149.8507	-1.322857
51.82883	149.8501	-1.322330
51.89550	149.8502	-1.321993
51.96050	149.8501	-1.321894
52.02550	149.8504	-1.321907
52.09050	149.8501	-1.321907
52.15717	149.8501	-1.322063
52.22217	149.8506	-1.322435
52.28716	149.8509	-1.322614
52.35383	149.8500	-1.322590
52.41883	149.8508	-1.322924
52.48383	149.8505	-1.323070
52.54883	149.8506	-1.323190
52.61550	149.8504	-1.323454
52.68050	149.8506	-1.323841
52.74550	149.8507	-1.324060
52.81050	149.8510	-1.324199
52.87717	149.8498	-1.324379
52.94216	149.8510	-1.324847
53.00717	149.8508	-1.325210
53.07217	149.8511	-1.325439
53.13882	149.8505	-1.325245
53.20383	149.8502	-1.325083
53.26884	149.8509	-1.325110
53.33550	149.8506	-1.324877
53.40050	149.8514	-1.324844
53.46550	149.8500	-1.324691
53.53050	149.8512	-1.324591
53.59716	149.8499	-1.324560
53.66216	149.8499	-1.324253
53.72717	149.8508	-1.323684
53.79217	149.8504	-1.323109
53.85883	149.8496	-1.322576
53.92383	149.8497	-1.322671
53.98882	149.8505	-1.323222
54.05383	149.8500	-1.323566
54.12050	149.8506	-1.324169
54.18550	149.8499	-1.324803
54.25050	149.8497	-1.325157
54.31550	149.8506	-1.325345
54.38217	149.8508	-1.325594
54.44717	149.8499	-1.325779
54.51216	149.8509	-1.326215
54.57883	149.8505	-1.326562
54.64384	149.8505	-1.326792
54.70883	149.8512	-1.326780
54.77383	149.8496	-1.326816
54.84050	149.8509	-1.326799
54.90550	149.8504	-1.326635
54.97050	149.8505	-1.326608
55.03550	149.8501	-1.326481
55.10217	149.8505	-1.326678
55.16716	149.8512	-1.326663
55.23217	149.8496	-1.326792
55.29717	149.8505	-1.327266
55.36382	149.8516	-1.327449
55.42883	149.8510	-1.327280
55.49382	149.8509	-1.326903
55.56050	149.8509	-1.326825
55.62550	149.8504	-1.326640
55.69050	149.8511	-1.326703
55.75550	149.8507	-1.327011
55.82217	149.8514	-1.327286
55.88716	149.8513	-1.327529
55.95216	149.8516	-1.327515
56.01716	149.8514	-1.327589
56.08383	149.8509	-1.327270
56.14883	149.8510	-1.326966
56.21382	149.8507	-1.326716
56.27883	149.8513	-1.326638
56.34550	149.8512	-1.326503
56.41050	149.8510	-1.326201
56.47550	149.8506	-1.326280
56.54217	149.8501	-1.326330
56.60717	149.8507	-1.326602
56.67217	149.8506	-1.326858
56.73717	149.8505	-1.327026
56.80383	149.8512	-1.327296
56.86882	149.8509	-1.327478
56.93383	149.8506	-1.327533
56.99883	149.8498	-1.327263
57.06550	149.8505	-1.327040
57.13050	149.8496	-1.326776
57.19550	149.8496	-1.326256
57.26050	149.8499	-1.325922
57.32717	149.8491	-1.325506
57.39216	149.8494	-1.325119
57.45717	149.8489	-1.324871
57.52217	149.8494	-1.324906
57.58882	149.8494	-1.325285
57.65383	149.8492	-1.326137
57.71884	149.8498	-1.327234
57.78550	149.8492	-1.328342
57.85050	149.8502	-1.329192
57.91550	149.8504	-1.329688
57.98050	149.8514	-1.330174
58.04717	149.8505	-1.330580
58.11217	149.8504	-1.330897
58.17717	149.8510	-1.331279
58.24216	149.8510	-1.331534
58.30883	149.8511	-1.331536
58.37383	149.8513	-1.331534
58.43882	149.8509	-1.331299
58.50383	149.8502	-1.331182
58.57050	149.8508	-1.330906
58.63550	149.8505	-1.330666
58.70050	149.8508	-1.330421
58.76716	149.8514	-1.330610
58.83217	149.8510	-1.330598
58.89717	149.8507	-1.330791
58.96216	149.8506	-1.330919
59.02883	149.8507	-1.330692
59.09384	149.8508	-1.330473
59.15883	149.8504	-1.330300
59.22382	149.8513	-1.330505
59.29050	149.8508	-1.330782
59.35550	149.8510	-1.330779
59.42050	149.8511	-1.330709
59.48550	149.8515	-1.330790
59.55217	149.8509	-1.330861
59.61716	149.8508	-1.330735
59.68217	149.8504	-1.330770
59.74883	149.8515	-1.331112
59.81382	149.8509	-1.331244
59.87883	149.8511	-1.331136
59.94384	149.8508	-1.331040
60.01050	149.8514	-1.330495
60.07550	149.8508	-1.330200
60.14050	149.8506	-1.330098
60.20550	149.8508	-1.330451
60.27217	149.8509	-1.330628
60.33716	149.8501	-1.330490
60.40217	149.8501	-1.330023
60.46717	149.8504	-1.329538
60.53383	149.8498	-1.328850
60.59882	149.8494	-1.328390
60.66382	149.8492	-1.327901
60.72883	149.8487	-1.327486
60.79550	149.8484	-1.327275
60.86050	149.8486	-1.326803
60.92550	149.8491	-1.326765
60.99216	149.8487	-1.327065
61.05717	149.8489	-1.327433
61.12217	149.8490	-1.328166
61.18716	149.8491	-1.328743
61.25383	149.8486	-1.329257
61.31884	149.8486	-1.329720
61.38383	149.8491	-1.330263
61.44883	149.8491	-1.330495
61.51550	149.8486	-1.331024
61.58050	149.8491	-1.331205
61.64550	149.8490	-1.331648
61.71050	149.8495	-1.332081
61.77717	149.8494	-1.332542
61.84217	149.8501	-1.333015
61.90717	149.8506	-1.333438
61.97382	149.8502	-1.333969
62.03882	149.8512	-1.334824
62.10383	149.8505	-1.335390
62.16882	149.8508	-1.335805
62.23550	149.8511	-1.336264
62.30050	149.8514	-1.336477
62.36550	149.8512	-1.336704
62.43050	149.8509	-1.336492
62.49717	149.8520	-1.336236
62.56216	149.8518	-1.335604
62.62717	149.8507	-1.334500
62.69216	149.8511	-1.333474
62.75883	149.8512	-1.332972
62.82383	149.8516	-1.332518
62.88882	149.8512	-1.332152
62.95550	149.8510	-1.332108
63.02050	149.8512	-1.332281
63.08550	149.8514	-1.332498
63.15050	149.8523	-1.332536
63.21717	149.8512	-1.332670
63.27717	149.8545	-1.333411
63.34217	150.1885	-1.570516
63.40717	150.9177	-4.393754
63.47217	151.7991	-8.232719
63.53882	152.8083	-12.07665
63.60383	153.8651	-15.27863
63.66882	154.9756	-17.88113
63.73383	156.1262	-19.94019
63.80050	157.3388	-21.59528
63.86550	158.5455	-22.87313
63.93050	159.7689	-23.90737
63.99550	161.0040	-24.80209
64.06216	162.2807	-25.59890
64.12717	163.5364	-26.19213
64.19217	164.8000	-26.68503
64.25884	166.1025	-27.12274
64.32384	167.3745	-27.50864
64.38884	168.6513	-27.86194
64.45383	169.9296	-28.19565
64.52050	171.2424	-28.52934
64.58550	172.5247	-28.84465
64.65050	173.8071	-29.15620
64.71550	175.0899	-29.46273
64.78217	176.4067	-29.78482
64.84717	177.6903	-30.10753
64.91217	178.9747	-30.43700
64.97718	180.2592	-30.77824
65.04384	181.5778	-31.14900
65.10884	182.8618	-31.52323
65.17383	184.1460	-31.90858
65.24050	185.4616	-32.32372
65.30550	186.7446	-32.73377
65.37050	188.0268	-33.16562
65.43550	189.3089	-33.61597
65.50217	190.6224	-34.09670
65.56718	191.9028	-34.58112
65.63218	193.1822	-35.09488
65.69718	194.4602	-35.62921
65.76384	195.7695	-36.20612
65.82884	197.0448	-36.80590
65.89384	198.3176	-37.45676
65.95884	199.5883	-38.14563
66.02550	200.8897	-38.91417
66.09050	202.1555	-39.72976
66.15550	203.4201	-40.61419
66.22218	204.7127	-41.58312
66.28718	205.9692	-42.61238
66.35218	207.2224	-43.73324
66.41718	208.4696	-44.95754
66.48384	209.7433	-46.36642
66.54884	210.9782	-47.91641
66.61384	212.2030	-49.69804
66.67884	213.4150	-51.81428
66.74550	214.6348	-54.55440
66.81050	215.7894	-58.05680
66.87550	216.8999	-62.58022
66.94050	217.9612	-68.14039
67.00718	219.0046	-74.87056
67.07218	219.9844	-82.11258
67.13718	220.9558	-89.36837
67.20216	221.9713	-95.18984
67.26882	223.1754	-96.85538
67.33384	224.5516	-94.30516
67.39884	226.0828	-88.46718
67.46550	227.7944	-79.60968
67.53050	229.5459	-69.50254
67.59550	231.2881	-60.34531
67.66050	232.9358	-53.43118
67.72718	234.5330	-48.22557
67.79218	236.0204	-44.53625
67.85718	237.4587	-41.82898
67.92218	238.8595	-39.86704
67.98882	240.2686	-38.41178
68.05384	241.6225	-37.39503
68.11884	242.9628	-36.66656
68.18384	244.2932	-36.14248
68.25050	245.6498	-35.75902
68.31550	246.9670	-35.48780
68.38050	248.2795	-35.29656
68.44718	249.6230	-35.16800
68.51218	250.9307	-35.09322
68.57718	252.2364	-35.05636
68.64216	253.5410	-35.04186
68.70884	254.8789	-35.03750
68.77384	256.1800	-35.08030
68.83884	257.4817	-35.13278
68.90384	258.7836	-35.17590
68.97050	260.1181	-35.23316
69.03550	261.4194	-35.28630
69.10050	262.7197	-35.35337
69.16550	264.0208	-35.42653
69.23218	265.3548	-35.50549
69.29718	266.6543	-35.59631
69.36218	267.9555	-35.67211
69.42884	269.2892	-35.75935
69.49384	270.5886	-35.83596
69.55884	271.8888	-35.90750
69.62384	273.1890	-35.99460
69.69050	274.5226	-36.07388
69.75050	275.7226	-36.15728
69.81718	276.7876	-35.91374
69.88218	276.8286	-29.77473
69.94718	276.4626	-20.05245
70.01384	275.8310	-10.19961
70.07884	275.0444	-2.101941
70.14384	274.1366	4.313160
70.20884	273.1368	9.265144
70.27550	272.0432	13.12700
70.34050	270.9240	15.99202
70.40550	269.7668	18.17731
70.47050	268.5810	19.85514
70.53718	267.3410	21.18060
70.60218	266.1146	22.18970
70.66718	264.8745	22.98480
70.73218	263.6235	23.61522
70.79884	262.3329	24.12869
70.86384	261.0676	24.54232
70.92884	259.7971	24.87798
70.99550	258.4894	25.15403
71.06050	257.2108	25.38237
71.12550	255.9305	25.56875
71.19050	254.6470	25.73489
71.25718	253.3287	25.87639
71.32218	252.0420	25.98766
71.38718	250.7539	26.07727
71.45216	249.4642	26.15487
71.51882	248.1408	26.22941
71.58384	246.8510	26.28754
71.64884	245.5593	26.33595
71.71384	244.2676	26.37593
71.78050	242.9434	26.40795
71.84550	241.6506	26.43875
71.91050	240.3585	26.46648
71.97551	239.0650	26.49186
72.04218	237.7385	26.51443
72.10718	236.4448	26.53323
72.17218	235.1500	26.54715
72.23882	233.8232	26.55562
72.30384	232.5289	26.56302
72.36884	231.2340	26.56910
72.43384	229.9390	26.57482
72.50050	228.6120	26.57996
72.56550	227.3164	26.58662
72.63050	226.0216	26.59386
72.69550	224.7267	26.60103
72.76218	223.3982	26.60878
72.82718	222.1032	26.61526
72.89216	220.8078	26.62116
72.95718	219.5129	26.62674
73.02384	218.1834	26.63357
73.08884	216.8878	26.63800
73.15384	215.5920	26.64092
73.22050	214.2633	26.64209
73.28550	212.9671	26.64162
73.35050	211.6715	26.63913
73.41550	210.3755	26.63564
73.48218	209.0478	26.63145
73.54718	207.7522	26.62700
73.61218	206.4572	26.62312
73.67718	205.1613	26.61904
73.74384	203.8314	26.61416
73.80884	202.5363	26.60797
73.87384	201.2411	26.59988
73.93884	199.9440	26.59208
74.00550	198.6158	26.58432
74.07050	197.3205	26.57663
74.13550	196.0232	26.56815
74.20216	194.6939	26.55936
74.26716	193.3978	26.55228
74.33218	192.1028	26.54504
74.39718	190.8063	26.53804
74.46384	189.4763	26.53020
74.52884	188.1801	26.52293
74.59384	186.8836	26.51356
74.65884	185.5870	26.50495
74.72551	184.2577	26.49432
74.79050	182.9617	26.47860
74.85550	181.6656	26.46646
74.92050	180.3696	26.45436
74.98718	179.0409	26.44400
75.05218	177.7447	26.43596
75.11718	176.4483	26.43063
75.18218	175.1511	26.42667
75.24884	173.8219	26.42378
75.31384	172.5258	26.42090
75.37884	171.2291	26.41720
75.44550	169.9003	26.41401
75.51050	168.6055	26.41900
75.57550	167.3130	26.50432
75.64050	166.0256	26.73635
75.70718	164.7205	27.37322
75.77218	163.4874	28.97242
75.83716	162.3345	32.47560
75.90218	161.3044	38.64985
75.96884	160.3749	47.29692
76.03384	159.5160	56.07872
76.09882	158.5970	63.05337
76.16382	157.5432	66.98874
76.23050	156.2976	67.66648
76.29550	154.9358	65.49347
76.36050	153.4662	61.39508
76.42718	151.8953	56.27688
76.49218	150.3516	51.31116
76.55718	148.8312	46.95300
76.62218	147.3441	43.31996
76.68884	145.8548	40.27467
76.75384	144.4312	37.88172
76.81884	143.0321	35.93894
76.88384	141.6530	34.36175
76.95050	140.2538	33.03544
77.01550	138.9003	31.95830
77.08050	137.5564	31.05548
77.14550	136.2210	30.29523
77.21218	134.8586	29.67800
77.27718	133.5364	29.17029
77.34216	132.2172	28.71356
77.40884	130.8425	27.59135
77.47384	129.5134	27.16226
77.53882	128.1951	26.74576
77.60384	126.8807	26.41468
77.67050	125.5363	26.14336
77.73550	124.2940	27.37408
77.80050	122.9831	26.86453
77.86550	121.6708	26.55430
77.93218	120.3275	26.27680
77.99718	119.0185	26.04364
78.06216	117.7109	25.82879
78.12718	116.4040	25.65195
78.19384	115.0654	25.48755
78.25884	113.7604	25.32858
78.32384	112.4556	25.17506
78.38884	111.1514	25.02263
78.45550	109.8141	24.87213
78.52050	108.5104	24.73981
78.58550	107.2076	24.60528
78.65218	105.8710	24.47610
78.71718	104.5673	24.34888
78.78218	103.2651	24.22039
78.84718	101.9634	24.10302
78.91382	100.6277	23.98242
78.97884	99.32830	23.92285
79.04384	98.02652	23.79220
79.10884	96.72418	23.68644
79.17550	95.38936	23.57168
79.24050	94.08694	23.45923
79.30550	92.78447	23.34885
79.37050	91.48309	23.23858
79.43718	90.14716	23.12016
79.50218	88.84542	23.00412
79.56718	87.54337	22.89827
79.63384	86.20868	22.78543
79.69884	84.90724	22.69159
79.76384	83.60532	22.58938
79.82884	82.30382	22.49789
79.89550	80.96942	22.39367
79.96050	79.66700	22.29260
80.02550	78.36494	22.19065
80.09050	77.06432	22.09511
80.15718	75.72889	21.99744
80.22218	74.42744	21.90547
80.28718	73.12588	21.81567
80.35218	71.82437	21.71602
80.41884	70.48897	21.62276
80.48384	69.18843	21.52467
80.54884	67.88689	21.43206
80.61550	66.55106	21.33266
80.68050	65.24988	21.23859
80.74550	63.94780	21.14084
80.81050	62.64496	21.03438
80.87718	61.30938	20.91472
80.94218	60.00820	20.80863
81.00718	58.70576	20.70318
81.07218	57.40441	20.60157
81.13884	56.06897	20.49537
81.20384	54.76609	20.39582
81.26882	53.46343	20.29366
81.33384	52.16040	20.18478
81.40050	50.82390	20.07120
81.46550	49.52037	19.96228
81.53050	48.21802	19.85583
81.59550	46.91576	19.74546
81.66218	45.57972	19.64578
81.72718	44.27703	19.54552
81.79218	42.97412	19.44208
81.85884	41.63720	19.33990
81.92384	40.33475	19.23318
81.98882	39.03209	19.12504
82.05382	37.73050	19.00399
82.12050	36.39500	18.88702
82.18550	35.09084	18.77566
82.25050	33.78794	18.66260
82.31550	32.48336	18.53724
82.38218	31.14576	18.40502
82.44718	29.84136	18.27626
82.51218	28.53586	18.14128
82.57718	27.23050	17.99827
82.64384	25.89316	17.85331
82.70882	24.58819	17.71310
82.77218	23.31879	17.55262
82.83718	22.62248	17.41688
82.90218	22.74560	13.59026
82.96718	23.20980	8.336418
83.03384	23.91794	3.004294
83.09882	24.76665	-1.431349
83.16382	25.72842	-4.990210
83.22882	26.77120	-7.766700
83.29550	27.90122	-9.944920
83.36050	29.04846	-11.56563
83.42550	30.22866	-12.80625
83.49050	31.43230	-13.76908
83.55718	32.68605	-14.54230
83.62218	33.92236	-15.14216
83.68718	35.17115	-15.62892
83.75384	36.45911	-16.03699
83.81884	37.72266	-16.36924
83.88384	38.99100	-16.65446
83.94884	40.26336	-16.89516
84.01551	41.57330	-17.11160
84.08051	42.85235	-17.29884
84.14551	44.13421	-17.46675
84.21051	45.41748	-17.62258
84.27718	46.73544	-17.77341
84.34218	48.02198	-17.91668
84.40718	49.31098	-18.05349
84.47218	50.59997	-18.18247
84.53882	51.92422	-18.31229
84.60382	53.21509	-18.42592
84.66884	54.50722	-18.54631
84.73551	55.83250	-18.65764
84.80051	57.12544	-18.77352
84.86551	58.41838	-18.89008
84.93051	59.71123	-19.00503
84.99718	61.03832	-19.12671
85.06218	62.33300	-19.25162
85.12718	63.62842	-19.37148
85.19218	64.92368	-19.47889
85.25884	66.25352	-19.59371
85.32384	67.54829	-19.70627
85.38884	68.84458	-19.81740
85.45382	70.13994	-19.92908
85.52050	71.46943	-20.03888
85.58551	72.76516	-20.14933
85.65051	74.06238	-20.26440
85.71551	75.35816	-20.38072
85.78218	76.68780	-20.49287
85.84718	77.98316	-20.60246
85.91218	79.28012	-20.71719
85.97882	80.61003	-20.83018
86.04384	81.90640	-20.93679
86.10884	83.20538	-21.01426
86.17384	84.50272	-21.10038
86.24051	85.83344	-21.20449
86.30549	87.13142	-21.31115
86.37051	88.42939	-21.41976
86.43550	89.72681	-21.53648
86.50218	91.05694	-21.65954
86.56718	92.35301	-21.78058
86.63218	93.65074	-21.89991
86.69718	94.94659	-22.01709
86.76384	96.27538	-22.14425
86.82884	97.57147	-22.26720
86.89384	98.86757	-22.39085
86.96051	100.1975	-22.52402
87.02550	101.4944	-22.64761
87.09051	102.7924	-22.77053
87.15551	104.0890	-22.88814
87.22218	105.4199	-23.01247
87.28718	106.7170	-23.13166
87.35218	108.0136	-23.25285
87.41718	109.3103	-23.37053
87.48382	110.6396	-23.50285
87.54884	111.9373	-23.62969
87.61384	113.2330	-23.75620
87.67882	114.5295	-23.87815
87.74550	115.8592	-24.00860
87.81050	117.1567	-24.13625
87.87550	118.4535	-24.26277
87.94218	119.7831	-24.39504
88.00718	121.0798	-24.52904
88.07218	122.3757	-24.67094
88.13718	123.6726	-24.80928
88.20382	125.0021	-24.95696
88.26882	126.2979	-25.09637
88.33384	127.5940	-25.23112
88.39884	128.8892	-25.36839
88.46551	130.2180	-25.51839
88.53051	131.5134	-25.67819
88.59551	132.8087	-25.83420
88.66050	134.1041	-25.98756
88.72718	135.4327	-26.15295
88.79218	136.7280	-26.32298
88.85718	138.0227	-26.49275
88.92218	139.3170	-26.66480
88.98882	140.6456	-26.85017
89.05382	141.9402	-27.03135
89.11884	143.2346	-27.21719
89.18550	144.5607	-27.40756
89.25050	145.8544	-27.60140
89.31551	147.1466	-27.80954
89.38050	148.4380	-28.02468
89.44718	149.7624	-28.27117
89.51218	151.0538	-28.52798
89.57718	152.3437	-28.82468
89.64218	153.6296	-29.18617
89.70882	154.9465	-29.60894
89.77384	156.2289	-30.04934
89.83884	157.5091	-30.50388
89.90384	158.7965	-30.76010
89.97051	160.1272	-30.85153
90.03551	161.4255	-30.97345
90.10050	162.7228	-31.10149
90.16718	164.0536	-31.22599
90.23218	165.3526	-31.33564
90.29718	166.6524	-31.41117
90.36218	167.9518	-31.47680
90.42882	169.2861	-31.52108
90.49384	170.5861	-31.57020
90.55884	171.8851	-31.65510
90.62384	173.1838	-31.76806
90.69051	174.5152	-31.88844
90.75551	175.8114	-32.03568
90.82050	177.1074	-32.20432
90.88550	178.3997	-32.40948
90.95216	179.7248	-32.66062
91.01718	181.0138	-32.93784
91.08218	182.3016	-33.26942
91.14884	183.6210	-33.65135
91.21384	184.9046	-34.08132
91.27884	186.1860	-34.55540
91.34384	187.4642	-35.10307
91.41050	188.7718	-35.74268
91.47551	190.0414	-36.46033
91.54051	191.3056	-37.29814
91.60550	192.5656	-38.25236
91.67218	193.8517	-39.33313
91.73718	195.1026	-40.43741
91.80218	196.3519	-41.57447
91.86718	197.6025	-42.72472
91.93384	198.8820	-43.93802
91.99884	200.1281	-45.19989
92.06384	201.3685	-46.59746
92.12882	202.6017	-48.15133
92.19550	203.8605	-49.86484
92.26051	205.0852	-51.57302
92.32550	206.3132	-53.16266
92.39218	207.5903	-54.29941
92.45718	208.8789	-54.29110
92.52218	210.2464	-52.35972
92.58718	211.7066	-48.54860
92.65384	213.2450	-44.18665
92.71884	214.7228	-40.66228
92.78384	216.1596	-38.01352
92.84882	217.5616	-36.06400
92.91550	218.9720	-34.60191
92.98050	220.3284	-33.55418
93.04550	221.6691	-32.80685
93.11051	223.0001	-32.25964
93.17718	224.3562	-31.86705
93.24218	225.6730	-31.58926
93.30718	226.9856	-31.40462
93.37384	228.3271	-31.28145
93.43884	229.6336	-31.21611
93.50384	230.9385	-31.19101
93.56884	232.2426	-31.18248
93.63550	233.5791	-31.18461
93.70050	234.8820	-31.19905
93.76551	236.1831	-31.23562
93.83051	237.4834	-31.26604
93.89718	238.8174	-31.32372
93.96218	240.1176	-31.38034
94.02718	241.4188	-31.44375
94.09218	242.7198	-31.51837
94.15884	244.0538	-31.58352
94.22384	245.3542	-31.64150
94.28882	246.6545	-31.70445
94.35550	247.9873	-31.76013
94.42050	249.2879	-31.81826
94.48551	250.5885	-31.88410
94.55051	251.8880	-31.95815
94.61718	253.2204	-32.01900
94.68218	254.5200	-32.08244
94.74718	255.8202	-32.14917
94.81218	257.1196	-32.23538
94.87882	258.4529	-32.31311
94.94384	259.7524	-32.39396
95.00884	261.0523	-32.47182
95.07384	262.3516	-32.54824
95.14051	263.6836	-32.63806
95.20551	264.9834	-32.72974
95.27050	266.2826	-32.82496
95.33551	267.5818	-32.91435
95.40218	268.9136	-33.01200
95.46718	270.2115	-33.13585
95.53218	271.5088	-33.24822
-2.000000	5.000000	0.0000000