File: 3-C1(1.0mol%)+C20(0.6mol%)/matlab/150-2
CLOSED
Version	1.0
Language	English
Mode	Standard
Run	5
RunSerial	11786
Instrument	DSC Q2000 V24.11 Build 124
Module	DSC Standard Cell RC
Operator	Nan
File	\\Ae520-1454\ta\Data\DSC\UQ Composites\Nan\C1(4.5)+C20P(3)+CL(HotplateMixtureAB)\Iso150_60Min_2
ProcName	H/C/H/C/H complete wood PHA
InstSerial	2000-0883
AutoSerial	1293
Sample	Iso150_60Min
Size	47.6000	mg
PanMass	Not available
PanResist	Automatic Automatic  K/W
PanFactor	Default Default
Method	H/C/H/C/H complete wood PHA
Comment
Xcomment	Pan: Tzero Aluminum Hermetic
Xcomment	Gas1: Nitrogen 50.0 ml/min
Xcomment	Gas2: Nitrogen 50.0 ml/min
Text
Exotherm	UP
Kcell	1.05230
Cpconst	Standard: 0.938
Calib	-38.6961
TempCal	1	pts	157.46	156.60
TzeroDt	-87.6168 -0.0009 -1.4231
TzeroDtz	-87.6168 0.0057 6.9570
InstCalFile	Tzero: \\Ae520-1454\ta\Data\DSC\Calibration\2017\CALIBRATION\1562_RCS (90)_05_18_2017 10_50_44.TZR
InstCalFile	Baseline: \\Ae520-1454\ta\Data\DSC\Calibration\2017\2017-05-17_Calibration.001
InstCalFile	Sapphire: \\Ae520-1454\ta\Data\DSC\Calibration\2017\2017-05-17_Saphire.001
InstCalDate	Tzero 2017-05-18 Time 10:50:44
TempRange	-87.39 to 398.39 °C at 10.00 °C/min Heat Only
AutoZero	Delta T Offset 0.000 uV
AutoZero	Delta T0 Offset 0.000 uV
MultiptCal	0
MultiPtDesc	0) Not set
AutoCellConst	Calibration Date 2017-05-18 16:59:28
Controls	Gas 1  Event Off  Sampling 0.2
Cell#	RC-01562
CoolingUnit	RCS (90)
SelHeatFlow	Heat Flow T4 (mW)
AutoLidII	Installed
AutoAnalysis	Off
MacroFile
Nsig	3
Sig1	Time (min)
Sig2	Temperature (°C)
Sig3	Heat Flow (mW)
Date	2017-06-07
Time	18:04:12
OrgMethod	1: Equilibrate at 20.00 °C
OrgMethod	2: Ramp 40.00 °C/min to 150.00 °C
OrgMethod	3: Mark end of cycle 1
OrgMethod	4: Isothermal for 60.00 min
OrgMethod	5: Mark end of cycle 2
OrgMethod	6: Ramp 20.00 °C/min to 280.00 °C
OrgMethod	7: Mark end of cycle 3
OrgMethod	8: Ramp 20.00 °C/min to 20.00 °C
OrgMethod	9: Mark end of cycle 4
OrgMethod	10: Ramp 20.00 °C/min to 280.00 °C
OrgMethod	11: Mark end of cycle 5
OrgFile	C:\Users\jarra\Desktop\DSC\3-C1(1.0mol%)+C20(0.6mol%)\150-2
StartOfData
4.99994E-4	20.08866	0.7246270
0.06716666	20.34949	1.368827
0.1321667	21.69569	0.1421607
0.1971667	23.39092	-4.509708
0.2638334	25.35524	-10.24133
0.3288334	27.40786	-15.64640
0.3938334	29.56622	-20.42602
0.4588333	31.80579	-24.45445
0.5255000	34.17184	-27.88513
0.5905000	36.53040	-30.64514
0.6555000	38.92947	-32.97194
0.7205000	41.35838	-34.94800
0.7871668	43.86645	-36.87596
0.8521668	46.30646	-39.02555
0.9171668	48.75317	-40.98774
0.9821668	51.22563	-42.57144
1.048834	53.77712	-44.20172
1.113833	56.24337	-46.38808
1.178834	58.69630	-48.68402
1.245500	61.22824	-50.79814
1.310500	63.70479	-52.87700
1.375500	66.15485	-55.67951
1.440500	68.51849	-60.56523
1.507167	70.76830	-69.14890
1.572166	72.74726	-81.62120
1.637166	74.50955	-97.82219
1.702167	76.18968	-114.5963
1.768833	77.91974	-131.7208
1.833833	79.63648	-147.7029
1.898834	81.48828	-160.8350
1.963833	83.48303	-171.4318
2.030500	85.71375	-178.7800
2.095500	88.12449	-181.5383
2.160500	90.75824	-180.7477
2.225500	93.44124	-179.9230
2.292167	96.30338	-175.2891
2.357167	99.69571	-157.3899
2.422167	103.2955	-140.3250
2.488834	106.7856	-126.5583
2.553833	110.0221	-115.9059
2.618834	113.1334	-107.4111
2.683833	116.1403	-100.6727
2.750500	119.1346	-95.29972
2.815500	121.9854	-91.31441
2.880500	124.7842	-88.22976
2.945500	127.5423	-85.84295
3.012167	130.3355	-84.00214
3.077166	133.0326	-82.77416
3.142166	135.7050	-81.96116
3.207167	138.3589	-81.54262
3.272167	140.9919	-81.46834
3.337167	143.0403	-82.03165
3.402167	144.2002	-76.99718
3.467166	145.0886	-68.89772
3.533833	145.8105	-60.08844
3.598834	146.3799	-52.30153
3.663833	146.8460	-45.65260
3.728833	147.2276	-40.12842
3.795500	147.5507	-35.50594
3.860500	147.8098	-31.84008
3.925500	148.0256	-28.84822
3.990500	148.2051	-26.41310
4.057167	148.3586	-24.37402
4.122166	148.4833	-22.73925
4.187167	148.5883	-21.39777
4.253834	148.6792	-20.25982
4.318833	148.7540	-19.33485
4.383834	148.8184	-18.56837
4.448834	148.8720	-17.92106
4.515500	148.9191	-17.36104
4.580500	148.9589	-16.89620
4.645500	148.9924	-16.50168
4.710500	149.0222	-16.15717
4.777167	149.0479	-15.84864
4.842167	149.0703	-15.58385
4.907166	149.0900	-15.34159
4.972168	149.1080	-15.12400
5.038834	149.1243	-14.91742
5.103833	149.1391	-14.72830
5.168833	149.1520	-14.54664
5.235500	149.1651	-14.36731
5.300500	149.1775	-14.19632
5.365500	149.1889	-14.00724
5.430500	149.2012	-13.80416
5.497168	149.2153	-13.57834
5.562168	149.2279	-13.35018
5.627168	149.2424	-13.11652
5.692166	149.2549	-12.87474
5.758832	149.2696	-12.63446
5.823834	149.2816	-12.39434
5.888832	149.2949	-12.16280
5.953832	149.3087	-11.93040
6.020500	149.3204	-11.69817
6.085500	149.3330	-11.47174
6.150500	149.3452	-11.25111
6.215500	149.3564	-11.02797
6.282166	149.3691	-10.79887
6.347168	149.3814	-10.57012
6.412168	149.3935	-10.34623
6.478832	149.4053	-10.10830
6.543832	149.4176	-9.877363
6.608832	149.4295	-9.648751
6.673834	149.4417	-9.414852
6.740500	149.4535	-9.173445
6.805500	149.4660	-8.937843
6.870500	149.4785	-8.695389
6.935500	149.4898	-8.454611
7.002168	149.5033	-8.202594
7.067168	149.5155	-7.949170
7.132168	149.5295	-7.692439
7.197168	149.5423	-7.425030
7.263834	149.5563	-7.145584
7.328834	149.5707	-6.864161
7.393832	149.5854	-6.572702
7.460500	149.6007	-6.263130
7.525500	149.6161	-5.939660
7.590500	149.6338	-5.606924
7.655500	149.6511	-5.242880
7.722168	149.6710	-4.840322
7.787168	149.6920	-4.424824
7.852168	149.7129	-3.990284
7.917168	149.7345	-3.551281
7.983832	149.7571	-3.114150
8.048834	149.7775	-2.702863
8.113834	149.7983	-2.316935
8.178832	149.8164	-1.954930
8.245500	149.8344	-1.607181
8.310500	149.8506	-1.298485
8.375500	149.8641	-1.022041
8.442168	149.8778	-0.7779369
8.507168	149.8886	-0.5713568
8.572168	149.8982	-0.3893661
8.637168	149.9070	-0.2335143
8.703834	149.9146	-.09563922
8.768832	149.9200	0.02441180
8.833832	149.9258	0.1312238
8.898834	149.9311	0.2215420
8.965500	149.9354	0.3126017
9.030500	149.9396	0.3886137
9.095500	149.9438	0.4607270
9.160499	149.9474	0.5295308
9.227168	149.9507	0.5920341
9.292168	149.9544	0.6525902
9.357166	149.9574	0.7093575
9.422168	149.9601	0.7658937
9.488834	149.9631	0.8218574
9.553832	149.9657	0.8754722
9.618834	149.9683	0.9268754
9.685499	149.9717	0.9784936
9.750500	149.9741	1.033688
9.815500	149.9764	1.084392
9.880500	149.9788	1.135262
9.947168	149.9824	1.182829
10.01217	149.9852	1.235254
10.07717	149.9870	1.286116
10.14217	149.9900	1.339711
10.20883	149.9929	1.393304
10.27383	149.9950	1.444608
10.33883	149.9983	1.497978
10.40383	150.0008	1.548534
10.47050	150.0035	1.604896
10.53550	150.0061	1.659169
10.60050	150.0079	1.713752
10.66717	150.0119	1.770762
10.73217	150.0139	1.827431
10.79717	150.0172	1.883670
10.86217	150.0200	1.939380
10.92883	150.0227	1.999520
10.99384	150.0256	2.056602
11.05884	150.0295	2.117206
11.12383	150.0317	2.175406
11.19050	150.0346	2.239276
11.25550	150.0384	2.297358
11.32050	150.0410	2.361966
11.38550	150.0444	2.422119
11.45217	150.0474	2.486452
11.51717	150.0505	2.551383
11.58217	150.0544	2.613712
11.64883	150.0573	2.682176
11.71383	150.0605	2.746607
11.77883	150.0644	2.812152
11.84383	150.0670	2.882588
11.91050	150.0710	2.949812
11.97550	150.0743	3.021104
12.04050	150.0777	3.089148
12.10550	150.0820	3.164231
12.17217	150.0855	3.235564
12.23717	150.0886	3.311164
12.30216	150.0923	3.382172
12.36716	150.0964	3.455616
12.43383	150.0998	3.534850
12.49883	150.1041	3.610088
12.56383	150.1084	3.692908
12.62884	150.1120	3.775741
12.69550	150.1167	3.867883
12.76050	150.1217	3.964200
12.82550	150.1265	4.069539
12.89216	150.1323	4.190460
12.95717	150.1390	4.326100
13.02217	150.1460	4.480604
13.08717	150.1549	4.651867
13.15383	150.1652	4.853476
13.21884	150.1756	5.069688
13.28383	150.1870	5.304462
13.34883	150.1990	5.550334
13.41550	150.2126	5.824322
13.48050	150.2264	6.103635
13.54550	150.2400	6.387680
13.61050	150.2547	6.677628
13.67717	150.2704	6.981388
13.74216	150.2849	7.281718
13.80717	150.2996	7.577124
13.87384	150.3154	7.879420
13.93883	150.3294	8.172412
14.00383	150.3440	8.463420
14.06884	150.3585	8.754003
14.13550	150.3732	9.050024
14.20050	150.3871	9.331031
14.26550	150.4020	9.617758
14.33050	150.4167	9.898420
14.39717	150.4299	10.18585
14.46217	150.4450	10.46666
14.52717	150.4588	10.74776
14.59216	150.4728	11.02747
14.65883	150.4873	11.31967
14.72383	150.5021	11.60261
14.78883	150.5160	11.89141
14.85550	150.5311	12.18002
14.92050	150.5450	12.46870
14.98550	150.5599	12.75537
15.05050	150.5736	13.04376
15.11716	150.5891	13.33892
15.18217	150.6036	13.62387
15.24717	150.6178	13.91307
15.31216	150.6319	14.20200
15.37883	150.6467	14.49544
15.44384	150.6610	14.78300
15.50883	150.6759	15.07202
15.57384	150.6906	15.35830
15.64050	150.7057	15.65378
15.70550	150.7197	15.92646
15.77050	150.7334	16.20433
15.83550	150.7474	16.48061
15.90217	150.7622	16.76327
15.96716	150.7756	17.03724
16.03216	150.7894	17.31504
16.09883	150.8032	17.59865
16.16383	150.8183	17.87274
16.22883	150.8306	18.15406
16.29383	150.8451	18.43150
16.36050	150.8577	18.71968
16.42550	150.8721	19.00146
16.49050	150.8860	19.28429
16.55550	150.9009	19.56946
16.62216	150.9154	19.86368
16.68716	150.9298	20.15864
16.75216	150.9447	20.46099
16.81716	150.9598	20.76501
16.88383	150.9756	21.08264
16.94884	150.9914	21.40147
17.01383	151.0071	21.71804
17.08050	151.0244	22.04709
17.14550	151.0394	22.36267
17.21050	151.0551	22.66350
17.27550	151.0702	22.95824
17.34216	151.0833	23.22661
17.40716	151.0948	23.45531
17.47216	151.1059	23.64517
17.53717	151.1138	23.77887
17.60383	151.1199	23.88093
17.66883	151.1224	23.92961
17.73383	151.1234	23.93546
17.79883	151.1217	23.89814
17.86550	151.1156	23.77580
17.93050	151.1096	23.61270
17.99550	151.0995	23.40198
18.06216	151.0875	23.14842
18.12716	151.0732	22.85625
18.19216	151.0577	22.52704
18.25716	151.0406	22.16584
18.32383	151.0203	21.77003
18.38883	151.0011	21.36181
18.45383	150.9801	20.94134
18.51883	150.9583	20.50688
18.58550	150.9360	20.05256
18.65050	150.9152	19.61482
18.71550	150.8922	19.17631
18.78050	150.8712	18.74069
18.84716	150.8482	18.30453
18.91217	150.8274	17.88608
18.97716	150.8061	17.47963
19.04216	150.7870	17.07725
19.10883	150.7664	16.67988
19.17383	150.7471	16.29710
19.23883	150.7282	15.93032
19.30550	150.7106	15.55548
19.37050	150.6923	15.20320
19.43550	150.6748	14.85446
19.50050	150.6582	14.51587
19.56716	150.6411	14.17960
19.63216	150.6252	13.85898
19.69716	150.6094	13.53524
19.76216	150.5930	13.21485
19.82883	150.5762	12.89001
19.89383	150.5608	12.57127
19.95883	150.5452	12.26209
20.02383	150.5306	11.94707
20.09050	150.5142	11.62885
20.15550	150.4988	11.32156
20.22050	150.4839	11.01655
20.28717	150.4671	10.69004
20.35216	150.4516	10.37123
20.41716	150.4355	10.05366
20.48216	150.4193	9.732764
20.54883	150.4030	9.405464
20.61383	150.3854	9.085309
20.67883	150.3701	8.760011
20.74383	150.3535	8.438892
20.81050	150.3370	8.104522
20.87550	150.3201	7.777685
20.94050	150.3037	7.455821
21.00550	150.2878	7.127157
21.07216	150.2708	6.795092
21.13716	150.2549	6.476352
21.20216	150.2385	6.158200
21.26883	150.2230	5.833235
21.33383	150.2070	5.524877
21.39883	150.1919	5.222335
21.46383	150.1775	4.924972
21.53050	150.1616	4.623129
21.59550	150.1484	4.343269
21.66050	150.1344	4.068116
21.72550	150.1208	3.798495
21.79216	150.1076	3.536728
21.85716	150.0949	3.282797
21.92216	150.0834	3.043827
21.98716	150.0725	2.814235
22.05383	150.0607	2.589323
22.11883	150.0496	2.381056
22.18383	150.0398	2.184317
22.24883	150.0296	1.990473
22.31550	150.0199	1.809823
22.38050	150.0114	1.642837
22.44550	150.0025	1.476308
22.51216	149.9947	1.320121
22.57716	149.9879	1.175306
22.64216	149.9806	1.039490
22.70717	149.9741	0.9077241
22.77383	149.9682	0.7830390
22.83883	149.9625	0.6699059
22.90383	149.9568	0.5639135
22.96883	149.9516	0.4640326
23.03550	149.9472	0.3659914
23.10050	149.9425	0.2825713
23.16550	149.9383	0.2000414
23.23050	149.9345	0.1230692
23.29716	149.9302	0.05098778
23.36216	149.9264	-.01488486
23.42717	149.9234	-.07742316
23.49383	149.9197	-0.1335028
23.55883	149.9171	-0.1886502
23.62383	149.9140	-0.2372609
23.68883	149.9114	-0.2871995
23.75550	149.9086	-0.3326966
23.82050	149.9064	-0.3768506
23.88550	149.9043	-0.4161084
23.95050	149.9024	-0.4532646
24.01716	149.9019	-0.4907172
24.08216	149.8992	-0.5232670
24.14716	149.8985	-0.5560260
24.21216	149.8970	-0.5870566
24.27883	149.8954	-0.6128044
24.34383	149.8943	-0.6393847
24.40883	149.8932	-0.6646395
24.47550	149.8930	-0.6905293
24.54050	149.8914	-0.7089239
24.60550	149.8899	-0.7259942
24.67050	149.8891	-0.7418395
24.73716	149.8874	-0.7567460
24.80217	149.8862	-0.7714540
24.86716	149.8845	-0.7862756
24.93216	149.8839	-0.8007105
24.99883	149.8828	-0.8176269
25.06383	149.8816	-0.8322608
25.12883	149.8812	-0.8460403
25.19383	149.8805	-0.8606591
25.26050	149.8803	-0.8740547
25.32550	149.8795	-0.8872474
25.39050	149.8789	-0.8994595
25.45550	149.8787	-0.9123001
25.52216	149.8779	-0.9253978
25.58716	149.8779	-0.9369725
25.65216	149.8769	-0.9487516
25.71883	149.8766	-0.9604321
25.78383	149.8769	-0.9713949
25.84883	149.8769	-0.9821613
25.91383	149.8762	-0.9927424
25.98050	149.8761	-1.002901
26.04550	149.8758	-1.011859
26.11050	149.8758	-1.020201
26.17550	149.8744	-1.027902
26.24216	149.8744	-1.035103
26.30716	149.8736	-1.041961
26.37216	149.8734	-1.048591
26.43717	149.8734	-1.055749
26.50383	149.8730	-1.062713
26.56883	149.8729	-1.069418
26.63383	149.8733	-1.075860
26.70050	149.8733	-1.082746
26.76550	149.8724	-1.088984
26.83050	149.8724	-1.094984
26.89550	149.8717	-1.100689
26.96216	149.8716	-1.105660
27.02717	149.8706	-1.109745
27.09216	149.8710	-1.113809
27.15716	149.8706	-1.117980
27.22383	149.8703	-1.122506
27.28883	149.8700	-1.127138
27.35383	149.8710	-1.131679
27.41883	149.8698	-1.136373
27.48550	149.8698	-1.141194
27.55050	149.8697	-1.145786
27.61550	149.8693	-1.149856
27.68216	149.8686	-1.153694
27.74716	149.8675	-1.156712
27.81217	149.8679	-1.159293
27.87716	149.8676	-1.161837
27.94383	149.8678	-1.164690
28.00883	149.8672	-1.167922
28.07383	149.8677	-1.171572
28.13883	149.8676	-1.175300
28.20550	149.8676	-1.178810
28.27050	149.8674	-1.182478
28.33550	149.8676	-1.186659
28.40050	149.8677	-1.190379
28.46716	149.8669	-1.193945
28.53216	149.8667	-1.196708
28.59716	149.8669	-1.198737
28.66217	149.8662	-1.200531
28.72883	149.8658	-1.202245
28.79383	149.8660	-1.203810
28.85883	149.8667	-1.206372
28.92550	149.8660	-1.208686
28.99050	149.8659	-1.210770
29.05550	149.8658	-1.212810
29.12050	149.8647	-1.214747
29.18717	149.8654	-1.216569
29.25217	149.8649	-1.218056
29.31716	149.8649	-1.219629
29.38216	149.8649	-1.221376
29.44883	149.8650	-1.223872
29.51383	149.8651	-1.226279
29.57883	149.8649	-1.228606
29.64383	149.8647	-1.230904
29.71050	149.8652	-1.233278
29.77550	149.8652	-1.235780
29.84050	149.8653	-1.237980
29.90716	149.8655	-1.240261
29.97216	149.8654	-1.242622
30.03717	149.8644	-1.244567
30.10217	149.8651	-1.246344
30.16883	149.8656	-1.247806
30.23383	149.8652	-1.249185
30.29883	149.8655	-1.250225
30.36383	149.8658	-1.251663
30.43050	149.8645	-1.253262
30.49550	149.8648	-1.254790
30.56050	149.8651	-1.256283
30.62550	149.8640	-1.257304
30.69216	149.8635	-1.257826
30.75716	149.8631	-1.257891
30.82217	149.8638	-1.258009
30.88883	149.8630	-1.258293
30.95383	149.8638	-1.258858
31.01883	149.8633	-1.260111
31.08383	149.8636	-1.261694
31.15050	149.8633	-1.263674
31.21550	149.8633	-1.265244
31.28050	149.8638	-1.267181
31.34550	149.8638	-1.269009
31.41217	149.8637	-1.270646
31.47717	149.8636	-1.272140
31.54216	149.8637	-1.273677
31.60716	149.8644	-1.275524
31.67383	149.8636	-1.276776
31.73883	149.8642	-1.278008
31.80383	149.8634	-1.278949
31.86883	149.8640	-1.279544
31.93550	149.8634	-1.280090
32.00050	149.8634	-1.280690
32.06550	149.8625	-1.280732
32.13216	149.8628	-1.280638
32.19717	149.8624	-1.280392
32.26216	149.8626	-1.280369
32.32717	149.8630	-1.281065
32.39383	149.8626	-1.282343
32.45883	149.8632	-1.283810
32.52383	149.8626	-1.285572
32.58883	149.8630	-1.287111
32.65550	149.8627	-1.288541
32.72050	149.8628	-1.289489
32.78550	149.8629	-1.289989
32.85050	149.8633	-1.290826
32.91716	149.8631	-1.292046
32.98216	149.8629	-1.292972
33.04716	149.8632	-1.293958
33.11383	149.8630	-1.294583
33.17883	149.8626	-1.295101
33.24383	149.8626	-1.295634
33.30883	149.8620	-1.295902
33.37550	149.8625	-1.296806
33.44050	149.8628	-1.297546
33.50550	149.8622	-1.298073
33.57050	149.8621	-1.298074
33.63716	149.8617	-1.297841
33.70216	149.8616	-1.297806
33.76716	149.8617	-1.298122
33.83216	149.8617	-1.298759
33.89883	149.8616	-1.299776
33.96383	149.8618	-1.300649
34.02883	149.8618	-1.301526
34.09550	149.8610	-1.302313
34.16050	149.8615	-1.303091
34.22550	149.8616	-1.304192
34.29050	149.8621	-1.305852
34.35716	149.8621	-1.307082
34.42216	149.8619	-1.308013
34.48717	149.8620	-1.308987
34.55217	149.8622	-1.309948
34.61883	149.8621	-1.310711
34.68384	149.8618	-1.311499
34.74883	149.8624	-1.312270
34.81383	149.8625	-1.312781
34.88050	149.8626	-1.313897
34.94550	149.8625	-1.314513
35.01050	149.8625	-1.314898
35.07550	149.8621	-1.315139
35.14216	149.8622	-1.315438
35.20716	149.8621	-1.315860
35.27217	149.8618	-1.316070
35.33883	149.8621	-1.316512
35.40383	149.8624	-1.316742
35.46884	149.8619	-1.316972
35.53383	149.8615	-1.317203
35.60050	149.8607	-1.317254
35.66550	149.8612	-1.317022
35.73050	149.8603	-1.316686
35.79550	149.8611	-1.316416
35.86217	149.8614	-1.316379
35.92717	149.8610	-1.316998
35.99216	149.8616	-1.317851
36.05716	149.8617	-1.319106
36.12383	149.8608	-1.320091
36.18883	149.8616	-1.320796
36.25383	149.8611	-1.321396
36.32050	149.8616	-1.321841
36.38550	149.8617	-1.322514
36.45050	149.8621	-1.322872
36.51550	149.8616	-1.323415
36.58216	149.8614	-1.323692
36.64717	149.8611	-1.324258
36.71216	149.8611	-1.324749
36.77716	149.8608	-1.324961
36.84384	149.8612	-1.324933
36.90883	149.8611	-1.324745
36.97383	149.8605	-1.324798
37.03883	149.8608	-1.325196
37.10550	149.8609	-1.325817
37.17050	149.8604	-1.326438
37.23550	149.8602	-1.326814
37.30217	149.8602	-1.326851
37.36716	149.8606	-1.326900
37.43216	149.8602	-1.327178
37.49716	149.8605	-1.327873
37.56383	149.8606	-1.328673
37.62883	149.8608	-1.329322
37.69383	149.8601	-1.329808
37.75883	149.8610	-1.330488
37.82550	149.8612	-1.331389
37.89050	149.8608	-1.332247
37.95550	149.8619	-1.333142
38.02050	149.8610	-1.333988
38.08716	149.8622	-1.334337
38.15216	149.8617	-1.334821
38.21716	149.8617	-1.335540
38.28216	149.8619	-1.335860
38.34883	149.8613	-1.335999
38.41383	149.8614	-1.336217
38.47883	149.8614	-1.336366
38.54550	149.8617	-1.336435
38.61050	149.8610	-1.336014
38.67550	149.8611	-1.335660
38.74050	149.8608	-1.335157
38.80716	149.8616	-1.334849
38.87216	149.8610	-1.334751
38.93716	149.8610	-1.334884
39.00217	149.8602	-1.335050
39.06883	149.8601	-1.335285
39.13383	149.8601	-1.335106
39.19883	149.8603	-1.335068
39.26383	149.8607	-1.335111
39.33050	149.8596	-1.335458
39.39550	149.8605	-1.336203
39.46050	149.8604	-1.336798
39.52716	149.8602	-1.337325
39.59216	149.8603	-1.337676
39.65716	149.8602	-1.338163
39.72217	149.8606	-1.338549
39.78883	149.8606	-1.339281
39.85383	149.8603	-1.339899
39.91883	149.8612	-1.340703
39.98383	149.8605	-1.341173
40.05050	149.8608	-1.341925
40.11550	149.8611	-1.342312
40.18050	149.8608	-1.342689
40.24550	149.8605	-1.342984
40.31216	149.8606	-1.342903
40.37717	149.8603	-1.342723
40.44216	149.8600	-1.342270
40.50883	149.8598	-1.341584
40.57383	149.8600	-1.341226
40.63883	149.8594	-1.340713
40.70383	149.8598	-1.340408
40.77050	149.8589	-1.340258
40.83550	149.8600	-1.340268
40.90050	149.8596	-1.340632
40.96550	149.8601	-1.341238
41.03217	149.8600	-1.342190
41.09716	149.8600	-1.343296
41.16217	149.8598	-1.344353
41.22717	149.8605	-1.345002
41.29383	149.8601	-1.345666
41.35883	149.8601	-1.346138
41.42383	149.8602	-1.346766
41.48883	149.8607	-1.347501
41.55550	149.8614	-1.348075
41.62050	149.8611	-1.348604
41.68550	149.8603	-1.348849
41.75217	149.8597	-1.348492
41.81717	149.8596	-1.348061
41.88217	149.8601	-1.347566
41.94717	149.8604	-1.347191
42.01383	149.8595	-1.346738
42.07883	149.8599	-1.346763
42.14383	149.8600	-1.346921
42.20883	149.8604	-1.347388
42.27550	149.8601	-1.347636
42.34050	149.8606	-1.348044
42.40550	149.8603	-1.348534
42.47050	149.8606	-1.348978
42.53717	149.8604	-1.349375
42.60217	149.8600	-1.349751
42.66716	149.8611	-1.350170
42.73383	149.8611	-1.350417
42.79883	149.8605	-1.350480
42.86383	149.8608	-1.350381
42.92883	149.8608	-1.350476
42.99550	149.8609	-1.350508
43.06050	149.8605	-1.350377
43.12550	149.8600	-1.350006
43.19050	149.8597	-1.349683
43.25717	149.8592	-1.349238
43.32217	149.8600	-1.348831
43.38716	149.8608	-1.348895
43.45216	149.8592	-1.349116
43.51883	149.8596	-1.349486
43.58383	149.8602	-1.350044
43.64883	149.8598	-1.350326
43.71550	149.8598	-1.350759
43.78050	149.8600	-1.351062
43.84550	149.8605	-1.351892
43.91050	149.8595	-1.352871
43.97717	149.8605	-1.353308
44.04217	149.8608	-1.354005
44.10717	149.8608	-1.354334
44.17216	149.8604	-1.354431
44.23883	149.8606	-1.354597
44.30383	149.8596	-1.354515
44.36883	149.8598	-1.354001
44.43383	149.8598	-1.353422
44.50050	149.8600	-1.352984
44.56550	149.8601	-1.353075
44.63050	149.8598	-1.353430
44.69550	149.8602	-1.353991
44.76216	149.8601	-1.354357
44.82717	149.8598	-1.354784
44.89217	149.8597	-1.354726
44.95883	149.8594	-1.354390
45.02383	149.8598	-1.353966
45.08883	149.8598	-1.354082
45.15383	149.8591	-1.353923
45.22050	149.8594	-1.353792
45.28550	149.8598	-1.353961
45.35050	149.8599	-1.354166
45.41550	149.8592	-1.354459
45.48217	149.8596	-1.355066
45.54716	149.8598	-1.355699
45.61217	149.8595	-1.356114
45.67717	149.8598	-1.356363
45.74383	149.8603	-1.356674
45.80883	149.8599	-1.356884
45.87383	149.8593	-1.357109
45.94050	149.8596	-1.357463
46.00550	149.8595	-1.357336
46.07050	149.8601	-1.357000
46.13550	149.8599	-1.357150
46.20216	149.8599	-1.357225
46.26717	149.8604	-1.357426
46.33217	149.8599	-1.357604
46.39717	149.8611	-1.357926
46.46383	149.8605	-1.358064
46.52883	149.8604	-1.358432
46.59384	149.8601	-1.358751
46.65883	149.8605	-1.359091
46.72550	149.8605	-1.358952
46.79050	149.8600	-1.358832
46.85550	149.8604	-1.358694
46.92216	149.8600	-1.358536
46.98717	149.8606	-1.358544
47.05217	149.8604	-1.358394
47.11716	149.8603	-1.358431
47.18383	149.8608	-1.358562
47.24883	149.8603	-1.358901
47.31383	149.8605	-1.359042
47.37883	149.8601	-1.359241
47.44550	149.8599	-1.359021
47.51050	149.8594	-1.358968
47.57550	149.8598	-1.358508
47.64050	149.8597	-1.358124
47.70717	149.8596	-1.357900
47.77217	149.8599	-1.357816
47.83716	149.8590	-1.357993
47.90216	149.8596	-1.358402
47.96884	149.8590	-1.358778
48.03383	149.8593	-1.359226
48.09883	149.8598	-1.359873
48.16550	149.8596	-1.360672
48.23050	149.8600	-1.361252
48.29550	149.8599	-1.361789
48.36050	149.8604	-1.362146
48.42717	149.8609	-1.362658
48.49216	149.8603	-1.362961
48.55717	149.8602	-1.363145
48.62216	149.8602	-1.363177
48.68883	149.8608	-1.363209
48.75383	149.8601	-1.363077
48.81883	149.8599	-1.362423
48.88383	149.8596	-1.361567
48.95050	149.8604	-1.360859
49.01550	149.8597	-1.359876
49.08050	149.8599	-1.359666
49.14717	149.8600	-1.359578
49.21216	149.8599	-1.359804
49.27716	149.8596	-1.360550
49.34217	149.8597	-1.361134
49.40883	149.8602	-1.362016
49.47383	149.8609	-1.362797
49.53883	149.8604	-1.363379
49.60383	149.8600	-1.363635
49.67050	149.8601	-1.363996
49.73550	149.8600	-1.364278
49.80050	149.8599	-1.364454
49.86550	149.8606	-1.364547
49.93217	149.8596	-1.364287
49.99716	149.8596	-1.363584
50.06216	149.8598	-1.363196
50.12883	149.8600	-1.362784
50.19383	149.8594	-1.362444
50.25883	149.8594	-1.362445
50.32383	149.8596	-1.362412
50.39050	149.8602	-1.362642
50.45550	149.8598	-1.363082
50.52050	149.8601	-1.363448
50.58550	149.8598	-1.363634
50.65216	149.8591	-1.363477
50.71717	149.8589	-1.363181
50.78217	149.8594	-1.363004
50.84716	149.8592	-1.362736
50.91383	149.8597	-1.362938
50.97883	149.8595	-1.363680
51.04383	149.8594	-1.364263
51.10883	149.8598	-1.365258
51.17550	149.8597	-1.365962
51.24050	149.8600	-1.366616
51.30550	149.8598	-1.367176
51.37217	149.8602	-1.367434
51.43716	149.8599	-1.367411
51.50217	149.8599	-1.367239
51.56716	149.8601	-1.366910
51.63383	149.8594	-1.366456
51.69883	149.8597	-1.366134
51.76383	149.8588	-1.365533
51.82883	149.8590	-1.365204
51.89550	149.8594	-1.365110
51.96050	149.8596	-1.364956
52.02550	149.8596	-1.364867
52.09050	149.8595	-1.364863
52.15717	149.8600	-1.365048
52.22217	149.8602	-1.365338
52.28716	149.8602	-1.365668
52.35383	149.8596	-1.366028
52.41883	149.8596	-1.366168
52.48383	149.8609	-1.366445
52.54883	149.8598	-1.366824
52.61550	149.8598	-1.367384
52.68050	149.8602	-1.367912
52.74550	149.8598	-1.368100
52.81050	149.8600	-1.368017
52.87717	149.8601	-1.367908
52.94216	149.8601	-1.367887
53.00717	149.8604	-1.367831
53.07217	149.8599	-1.367929
53.13882	149.8598	-1.367677
53.20383	149.8608	-1.367564
53.26884	149.8599	-1.367190
53.33550	149.8591	-1.366948
53.40050	149.8594	-1.366925
53.46550	149.8592	-1.366819
53.53050	149.8601	-1.366919
53.59716	149.8600	-1.367085
53.66216	149.8594	-1.366959
53.72717	149.8594	-1.366998
53.79217	149.8596	-1.367133
53.85883	149.8597	-1.367423
53.92383	149.8592	-1.367349
53.98882	149.8592	-1.367493
54.05383	149.8597	-1.367636
54.12050	149.8585	-1.367466
54.18550	149.8587	-1.367228
54.25050	149.8589	-1.367408
54.31550	149.8592	-1.367744
54.38217	149.8591	-1.367891
54.44717	149.8591	-1.367676
54.51216	149.8592	-1.367273
54.57883	149.8589	-1.367245
54.64384	149.8588	-1.367479
54.70883	149.8595	-1.367905
54.77383	149.8596	-1.368590
54.84050	149.8595	-1.369319
54.90550	149.8595	-1.369586
54.97050	149.8601	-1.370051
55.03550	149.8600	-1.370476
55.10217	149.8599	-1.370830
55.16716	149.8597	-1.371032
55.23217	149.8606	-1.371170
55.29717	149.8603	-1.371482
55.36382	149.8599	-1.371612
55.42883	149.8600	-1.371766
55.49382	149.8604	-1.371650
55.56050	149.8600	-1.371810
55.62550	149.8598	-1.371897
55.69050	149.8602	-1.371832
55.75550	149.8600	-1.371735
55.82217	149.8595	-1.371217
55.88716	149.8596	-1.370840
55.95216	149.8604	-1.370865
56.01716	149.8599	-1.371206
56.08383	149.8602	-1.371647
56.14883	149.8600	-1.371844
56.21382	149.8603	-1.371992
56.27883	149.8596	-1.371634
56.34550	149.8592	-1.370956
56.41050	149.8592	-1.370425
56.47550	149.8595	-1.369866
56.54217	149.8592	-1.369518
56.60717	149.8595	-1.368872
56.67217	149.8592	-1.368574
56.73717	149.8594	-1.368529
56.80383	149.8594	-1.368748
56.86882	149.8598	-1.369032
56.93383	149.8590	-1.369401
56.99883	149.8597	-1.370099
57.06550	149.8598	-1.370888
57.13050	149.8605	-1.371804
57.19550	149.8600	-1.372630
57.26050	149.8598	-1.373067
57.32717	149.8596	-1.373010
57.39216	149.8599	-1.373161
57.45717	149.8602	-1.372996
57.52217	149.8600	-1.372654
57.58882	149.8593	-1.372056
57.65383	149.8595	-1.371583
57.71884	149.8590	-1.371264
57.78550	149.8595	-1.371050
57.85050	149.8585	-1.370859
57.91550	149.8590	-1.370642
57.98050	149.8589	-1.370349
58.04717	149.8586	-1.369935
58.11217	149.8584	-1.369376
58.17717	149.8585	-1.369104
58.24216	149.8590	-1.369708
58.30883	149.8591	-1.370096
58.37383	149.8585	-1.370663
58.43882	149.8587	-1.370703
58.50383	149.8587	-1.370958
58.57050	149.8586	-1.370717
58.63550	149.8583	-1.370239
58.70050	149.8576	-1.370069
58.76716	149.8582	-1.370165
58.83217	149.8583	-1.370605
58.89717	149.8583	-1.370554
58.96216	149.8586	-1.370718
59.02883	149.8581	-1.370573
59.09384	149.8584	-1.370820
59.15883	149.8582	-1.370838
59.22382	149.8589	-1.371007
59.29050	149.8582	-1.371285
59.35550	149.8588	-1.371635
59.42050	149.8588	-1.372121
59.48550	149.8584	-1.372232
59.55217	149.8593	-1.372880
59.61716	149.8588	-1.373716
59.68217	149.8589	-1.374305
59.74883	149.8594	-1.374665
59.81382	149.8601	-1.375396
59.87883	149.8599	-1.376123
59.94384	149.8600	-1.376553
60.01050	149.8606	-1.377261
60.07550	149.8602	-1.377675
60.14050	149.8613	-1.378001
60.20550	149.8608	-1.378183
60.27217	149.8603	-1.378170
60.33716	149.8609	-1.377999
60.40217	149.8609	-1.378139
60.46717	149.8616	-1.377970
60.53383	149.8612	-1.377556
60.59882	149.8604	-1.376902
60.66382	149.8605	-1.376005
60.72883	149.8606	-1.375423
60.79550	149.8610	-1.374858
60.86050	149.8601	-1.374361
60.92550	149.8612	-1.373827
60.99216	149.8607	-1.373644
61.05717	149.8604	-1.373498
61.12217	149.8604	-1.373399
61.18716	149.8605	-1.373208
61.25383	149.8595	-1.372898
61.31884	149.8598	-1.372248
61.38383	149.8588	-1.371710
61.44883	149.8594	-1.371126
61.51550	149.8592	-1.370944
61.58050	149.8595	-1.371345
61.64550	149.8592	-1.371937
61.71050	149.8604	-1.372533
61.77717	149.8600	-1.373126
61.84217	149.8597	-1.373679
61.90717	149.8598	-1.374242
61.97382	149.8602	-1.374816
62.03882	149.8604	-1.375270
62.10383	149.8599	-1.375790
62.16882	149.8604	-1.376237
62.23550	149.8600	-1.376358
62.30050	149.8608	-1.376342
62.36550	149.8602	-1.376283
62.43050	149.8598	-1.375798
62.49717	149.8595	-1.375181
62.56216	149.8598	-1.374548
62.62717	149.8592	-1.373793
62.69216	149.8591	-1.373201
62.75883	149.8594	-1.372955
62.82383	149.8597	-1.372882
62.88882	149.8594	-1.373487
62.95550	149.8598	-1.374060
63.02050	149.8589	-1.374390
63.08550	149.8599	-1.374560
63.15050	149.8592	-1.374651
63.21717	149.8594	-1.374214
63.27717	149.8625	-1.374766
63.34217	150.2075	-1.281405
63.40717	150.9478	-4.014600
63.47217	151.8259	-8.033115
63.53882	152.8179	-12.26696
63.60383	153.8516	-15.96517
63.66882	154.9363	-19.09264
63.73383	156.0606	-21.67122
63.80050	157.2475	-23.82602
63.86550	158.4301	-25.54295
63.93050	159.6324	-26.95620
63.99550	160.8490	-28.16696
64.06216	162.1077	-29.35325
64.12717	163.3345	-30.44968
64.19217	164.5814	-31.18558
64.25884	165.8705	-31.82576
64.32384	167.1332	-32.37505
64.38884	168.4013	-32.87690
64.45383	169.6732	-33.34408
64.52050	170.9793	-33.79502
64.58550	172.2549	-34.21585
64.65050	173.5316	-34.63025
64.71550	174.8092	-35.02817
64.78217	176.1211	-35.43916
64.84717	177.3990	-35.84551
64.91217	178.6795	-36.25685
64.97718	179.9582	-36.67850
65.04384	181.2718	-37.12300
65.10884	182.5513	-37.57561
65.17383	183.8308	-38.02875
65.24050	185.1434	-38.51802
65.30550	186.4219	-39.00286
65.37050	187.7005	-39.50300
65.43550	188.9776	-40.02856
65.50217	190.2882	-40.58410
65.56718	191.5641	-41.15272
65.63218	192.8396	-41.74126
65.69718	194.1138	-42.36680
65.76384	195.4186	-43.02732
65.82884	196.6904	-43.71281
65.89384	197.9609	-44.44496
65.95884	199.2282	-45.21258
66.02550	200.5259	-46.05908
66.09050	201.7898	-46.93160
66.15550	203.0504	-47.88781
66.22218	204.3402	-48.93414
66.28718	205.5947	-50.02670
66.35218	206.8458	-51.18694
66.41718	208.0939	-52.42822
66.48384	209.3659	-53.91368
66.54884	210.6010	-55.42375
66.61384	211.8289	-57.12631
66.67884	213.0466	-59.07082
66.74550	214.2792	-61.48130
66.81050	215.4547	-64.50082
66.87550	216.5904	-68.46230
66.94050	217.6756	-73.57272
67.00718	218.7364	-79.95593
67.07218	219.7278	-86.99484
67.13718	220.6958	-94.46126
67.20216	221.6655	-101.6741
67.26882	222.7156	-107.4778
67.33384	223.8806	-109.3992
67.39884	225.2466	-107.0963
67.46550	226.7840	-102.0858
67.53050	228.3816	-95.28411
67.59550	230.0285	-87.63778
67.66050	231.7023	-79.44419
67.72718	233.4230	-71.22159
67.79218	235.0496	-64.55408
67.85718	236.6102	-59.31054
67.92218	238.1127	-55.24719
67.98882	239.6058	-52.05881
68.05384	241.0272	-49.69816
68.11884	242.4203	-47.88820
68.18384	243.7930	-46.50826
68.25050	245.1828	-45.41494
68.31550	246.5266	-44.61066
68.38050	247.8597	-43.99754
68.44718	249.2220	-43.50633
68.51218	250.5440	-43.14992
68.57718	251.8613	-42.88789
68.64216	253.1752	-42.68393
68.70884	254.5200	-42.53174
68.77384	255.8286	-42.43203
68.83884	257.1352	-42.38510
68.90384	258.4416	-42.35929
68.97050	259.7797	-42.35294
69.03550	261.0840	-42.35303
69.10050	262.3857	-42.36132
69.16550	263.6890	-42.40620
69.23218	265.0234	-42.46890
69.29718	266.3250	-42.53733
69.36218	267.6266	-42.59974
69.42884	268.9618	-42.67227
69.49384	270.2636	-42.74534
69.55884	271.5640	-42.80209
69.62384	272.8650	-42.87072
69.69050	274.1992	-42.93391
69.75050	275.4005	-43.00045
69.81718	276.4630	-43.02660
69.88218	276.4923	-36.97832
69.94718	276.1423	-26.73632
70.01384	275.5518	-15.86660
70.07884	274.8196	-6.549032
70.14384	273.9716	1.172025
70.20884	273.0328	7.402515
70.27550	271.9976	12.48261
70.34050	270.9313	16.42241
70.40550	269.8214	19.56279
70.47050	268.6762	22.07092
70.53718	267.4718	24.12473
70.60218	266.2746	25.73276
70.66718	265.0590	27.03762
70.73218	263.8297	28.08754
70.79884	262.5569	28.96987
70.86384	261.3062	29.67120
70.92884	260.0486	30.25333
70.99550	258.7522	30.74422
71.06050	257.4822	31.14608
71.12550	256.2085	31.47352
71.19050	254.9300	31.74706
71.25718	253.6175	31.98622
71.32218	252.3350	32.18164
71.38718	251.0499	32.34054
71.45216	249.7639	32.47338
71.51882	248.4432	32.59174
71.58384	247.1547	32.68518
71.64884	245.8653	32.76018
71.71384	244.5760	32.83040
71.78050	243.2514	32.88580
71.84550	241.9594	32.92804
71.91050	240.6678	32.95652
71.97551	239.3748	32.98750
72.04218	238.0489	33.02004
72.10718	236.7547	33.04382
72.17218	235.4608	33.06659
72.23882	234.1340	33.07356
72.30384	232.8405	33.08015
72.36884	231.5468	33.08480
72.43384	230.2526	33.08904
72.50050	228.9246	33.09284
72.56550	227.6306	33.09683
72.63050	226.3370	33.10492
72.69550	225.0430	33.11191
72.76218	223.7145	33.12202
72.82718	222.4194	33.12878
72.89216	221.1250	33.13452
72.95718	219.8296	33.13906
73.02384	218.5020	33.14406
73.08884	217.2065	33.14737
73.15384	215.9114	33.14859
73.22050	214.5829	33.14871
73.28550	213.2870	33.14731
73.35050	211.9907	33.14428
73.41550	210.6954	33.14038
73.48218	209.3658	33.13522
73.54718	208.0704	33.12818
73.61218	206.7739	33.11914
73.67718	205.4784	33.10620
73.74384	204.1494	33.09306
73.80884	202.8546	33.08078
73.87384	201.5594	33.06332
73.93884	200.2639	33.05248
74.00550	198.9344	33.04110
74.07050	197.6383	33.03018
74.13550	196.3422	33.01636
74.20216	195.0132	33.00146
74.26716	193.7176	32.99045
74.33218	192.4213	32.97733
74.39718	191.1259	32.96335
74.46384	189.7962	32.94824
74.52884	188.4992	32.93161
74.59384	187.2035	32.91403
74.65884	185.9072	32.89796
74.72551	184.5779	32.88330
74.79050	183.2821	32.85920
74.85550	181.9861	32.84380
74.92050	180.6900	32.83113
74.98718	179.3602	32.81984
75.05218	178.0634	32.80950
75.11718	176.7680	32.80072
75.18218	175.4710	32.79250
75.24884	174.1406	32.78496
75.31384	172.8436	32.77693
75.37884	171.5465	32.76118
75.44550	170.2168	32.74085
75.51050	168.9214	32.73125
75.57550	167.6274	32.72730
75.64050	166.3355	32.81453
75.70718	165.0203	33.16800
75.77218	163.7616	34.12640
75.83716	162.5576	36.41184
75.90218	161.4483	40.83047
75.96884	160.4324	47.82120
76.03384	159.5302	56.07011
76.09882	158.6346	63.94542
76.16382	157.6661	69.93702
76.23050	156.5540	73.50172
76.29550	155.3448	74.47516
76.36050	154.0272	73.39892
76.42718	152.5899	70.76140
76.49218	151.1374	67.33882
76.55718	149.6606	63.60464
76.62218	148.1812	59.87620
76.68884	146.6709	56.29203
76.75384	145.2128	53.11058
76.81884	143.7709	50.25156
76.88384	142.3447	47.70627
76.95050	140.8980	45.41272
77.01550	139.5020	43.47524
77.08050	138.1192	41.81376
77.14550	136.7486	40.37891
77.21218	135.3527	39.08715
77.27718	133.9970	37.98094
77.34216	132.6580	37.16325
77.40884	131.2908	36.44391
77.47384	129.9631	35.83315
77.53882	128.6393	35.31183
77.60384	127.3195	34.84842
77.67050	125.9669	34.36740
77.73550	124.6513	34.00082
77.80050	123.3392	33.67387
77.86550	122.0281	33.36676
77.93218	120.6844	33.07686
77.99718	119.3757	32.81124
78.06216	118.0513	31.88530
78.12718	116.7306	31.80314
78.19384	115.4089	31.96293
78.25884	114.1022	31.75854
78.32384	112.7974	31.56847
78.38884	111.4920	31.39010
78.45550	110.1535	31.20566
78.52050	108.8482	31.03723
78.58550	107.5436	30.86944
78.65218	106.2064	30.70068
78.71718	104.9016	30.54220
78.78218	103.5989	30.38896
78.84718	102.2939	30.24268
78.91382	100.9576	30.08706
78.97884	99.65432	29.94114
79.04384	98.35095	29.79999
79.10884	97.04869	29.66968
79.17550	95.71246	29.53108
79.24050	94.40959	29.39067
79.30550	93.10634	29.25889
79.37050	91.80175	29.12559
79.43718	90.46626	28.98782
79.50218	89.16278	28.83827
79.56718	87.86042	28.70012
79.63384	86.52414	28.55808
79.69884	85.22113	28.42480
79.76384	83.91868	28.29085
79.82884	82.61730	28.16220
79.89550	81.28086	28.03350
79.96050	79.97809	27.90744
80.02550	78.67445	27.77898
80.09050	77.37222	27.65559
80.15718	76.03612	27.52908
80.22218	74.73325	27.41234
80.28718	73.43111	27.29134
80.35218	72.12859	27.17144
80.41884	70.79328	27.04553
80.48384	69.48944	26.92883
80.54884	68.18768	26.80444
80.61550	66.84982	26.67712
80.68050	65.54731	26.55128
80.74550	64.24458	26.42121
80.81050	62.94162	26.29382
80.87718	61.60518	26.14912
80.94218	60.30175	26.01607
81.00718	58.99854	25.88622
81.07218	57.69544	25.74922
81.13884	56.35855	25.60662
81.20384	55.05567	25.48377
81.26882	53.75186	25.34987
81.33384	52.44910	25.22117
81.40050	51.11282	25.08241
81.46550	49.80982	24.95668
81.53050	48.50662	24.83675
81.59550	47.20350	24.70103
81.66218	45.86644	24.58232
81.72718	44.56429	24.45980
81.79218	43.25957	24.33880
81.85884	41.92210	24.21245
81.92384	40.61848	24.07930
81.98882	39.31534	23.95012
82.05382	38.00921	23.80820
82.12050	36.67302	23.65358
82.18550	35.36820	23.50958
82.25050	34.06094	23.28422
82.31550	32.74940	22.99611
82.38218	31.40380	22.73682
82.44718	30.09400	22.51734
82.51218	28.78444	22.31511
82.57718	27.47562	22.11535
82.64384	26.13451	21.91902
82.70882	24.82756	21.75722
82.77218	23.55838	21.61922
82.83718	22.89082	22.25001
82.90218	23.05387	18.81302
82.96718	23.51706	13.29939
83.03384	24.19022	7.265450
83.09882	24.98834	1.951486
83.16382	25.89387	-2.555325
83.22882	26.87916	-6.278307
83.29550	27.95344	-9.400982
83.36050	29.04818	-11.87829
83.42550	30.18254	-13.90868
83.49050	31.34260	-15.58581
83.55718	32.55766	-17.01427
83.62218	33.77083	-17.96776
83.68718	35.00153	-18.76643
83.75384	36.27420	-19.45824
83.81884	37.52545	-20.02664
83.88384	38.78368	-20.52057
83.94884	40.04790	-20.94108
84.01551	41.34955	-21.32051
84.08051	42.62369	-21.64766
84.14551	43.90053	-21.94437
84.21051	45.18134	-22.20613
84.27718	46.49716	-22.45485
84.34218	47.78214	-22.67781
84.40718	49.06910	-22.88898
84.47218	50.35679	-23.08842
84.53882	51.67880	-23.28550
84.60382	52.96906	-23.46302
84.66884	54.26066	-23.63718
84.73551	55.58593	-23.79737
84.80051	56.87840	-23.95126
84.86551	58.17250	-24.09972
84.93051	59.46686	-24.24953
84.99718	60.79331	-24.39984
85.06218	62.08764	-24.55052
85.12718	63.38209	-24.70080
85.19218	64.67730	-24.84672
85.25884	66.00628	-24.98360
85.32384	67.30145	-25.12551
85.38884	68.59726	-25.26432
85.45382	69.89294	-25.39356
85.52050	71.22058	-25.52732
85.58551	72.51689	-25.67351
85.65051	73.81250	-25.80991
85.71551	75.10847	-25.94672
85.78218	76.43775	-26.08455
85.84718	77.73375	-26.22329
85.91218	79.02878	-26.36678
85.97882	80.35826	-26.51142
86.04384	81.65447	-26.65881
86.10884	82.94961	-26.80271
86.17384	84.24506	-26.94717
86.24051	85.57480	-27.10186
86.30549	86.87130	-27.24694
86.37051	88.16719	-27.38668
86.43550	89.46232	-27.53263
86.50218	90.79257	-27.66480
86.56718	92.08931	-27.77434
86.63218	93.38778	-27.89536
86.69718	94.68512	-28.01760
86.76384	96.01610	-28.15084
86.82884	97.31298	-28.28370
86.89384	98.60891	-28.41775
86.96051	99.93804	-28.56370
87.02550	101.2333	-28.71014
87.09051	102.5294	-28.85800
87.15551	103.8255	-29.00613
87.22218	105.1542	-29.16720
87.28718	106.4514	-29.32276
87.35218	107.7460	-29.48465
87.41718	109.0413	-29.64091
87.48382	110.3697	-29.80394
87.54884	111.6641	-29.96402
87.61384	112.9598	-30.12870
87.67882	114.2547	-30.28638
87.74550	115.5827	-30.45654
87.81050	116.8789	-30.61805
87.87550	118.1727	-30.77006
87.94218	119.5020	-30.94003
88.00718	120.7968	-31.11420
88.07218	122.0913	-31.28307
88.13718	123.3860	-31.46360
88.20382	124.7134	-31.65044
88.26882	126.0083	-31.83726
88.33384	127.3027	-32.00914
88.39884	128.5978	-32.18759
88.46551	129.9247	-32.36594
88.53051	131.2198	-32.55219
88.59551	132.5135	-32.73988
88.66050	133.8083	-32.92478
88.72718	135.1349	-33.12214
88.79218	136.4275	-33.32876
88.85718	137.7205	-33.53922
88.92218	139.0148	-33.74402
88.98882	140.3406	-33.96841
89.05382	141.6338	-34.18742
89.11884	142.9262	-34.41050
89.18550	144.2521	-34.64624
89.25050	145.5438	-34.87000
89.31551	146.8366	-35.10678
89.38050	148.1275	-35.35660
89.44718	149.4523	-35.61809
89.51218	150.7436	-35.87509
89.57718	152.0340	-36.15473
89.64218	153.3240	-36.45750
89.70882	154.6433	-36.83134
89.77384	155.9271	-37.23890
89.83884	157.2106	-37.63794
89.90384	158.5014	-37.86569
89.97051	159.8278	-38.07204
90.03551	161.1223	-38.28526
90.10050	162.4161	-38.49739
90.16718	163.7439	-38.70148
90.23218	165.0393	-38.89075
90.29718	166.3348	-39.04220
90.36218	167.6325	-39.17418
90.42882	168.9645	-39.27407
90.49384	170.2648	-39.35648
90.55884	171.5641	-39.45338
90.62384	172.8634	-39.56196
90.69051	174.1941	-39.68555
90.75551	175.4898	-39.83097
90.82050	176.7857	-40.01156
90.88550	178.0798	-40.21299
90.95216	179.4039	-40.46600
91.01718	180.6948	-40.74644
91.08218	181.9818	-41.08965
91.14884	183.3003	-41.49282
91.21384	184.5826	-41.94382
91.27884	185.8645	-42.44453
91.34384	187.1418	-43.01466
91.41050	188.4496	-43.68650
91.47551	189.7202	-44.42712
91.54051	190.9853	-45.28832
91.60550	192.2449	-46.25738
91.67218	193.5312	-47.37618
91.73718	194.7809	-48.55266
91.80218	196.0265	-49.78422
91.86718	197.2721	-51.06447
91.93384	198.5472	-52.40270
91.99884	199.7875	-53.77363
92.06384	201.0234	-55.25789
92.12882	202.2531	-56.90412
92.19550	203.5071	-58.73684
92.26051	204.7263	-60.61319
92.32550	205.9424	-62.48684
92.39218	207.1992	-64.16739
92.45718	208.4476	-65.13862
92.52218	209.7509	-64.80201
92.58718	211.1328	-62.68995
92.65384	212.6211	-59.14282
92.71884	214.1021	-55.28494
92.78384	215.5803	-51.65816
92.84882	217.0322	-48.63904
92.91550	218.4904	-46.20067
92.98050	219.8852	-44.35432
93.04550	221.2595	-42.93926
93.11051	222.6171	-41.85422
93.17718	223.9964	-41.01641
93.24218	225.3315	-40.38598
93.30718	226.6600	-39.91296
93.37384	228.0148	-39.54905
93.43884	229.3302	-39.28844
93.50384	230.6427	-39.12039
93.56884	231.9512	-39.00385
93.63550	233.2924	-38.94670
93.70050	234.5987	-38.92230
93.76551	235.9039	-38.91263
93.83051	237.2088	-38.90826
93.89718	238.5446	-38.90709
93.96218	239.8480	-38.91361
94.02718	241.1491	-38.95818
94.09218	242.4515	-39.02040
94.15884	243.7868	-39.08174
94.22384	245.0886	-39.14185
94.28882	246.3897	-39.19965
94.35550	247.7241	-39.25917
94.42050	249.0262	-39.30613
94.48551	250.3264	-39.36002
94.55051	251.6268	-39.43118
94.61718	252.9594	-39.50136
94.68218	254.2605	-39.57060
94.74718	255.5608	-39.63506
94.81218	256.8618	-39.71940
94.87882	258.1942	-39.79780
94.94384	259.4942	-39.89106
95.00884	260.7938	-39.97504
95.07384	262.0930	-40.05924
95.14051	263.4252	-40.15854
95.20551	264.7252	-40.25574
95.27050	266.0254	-40.36004
95.33551	267.3252	-40.45240
95.40218	268.6575	-40.56602
95.46718	269.9551	-40.67856
95.53218	271.2535	-40.78235
-2.000000	5.000000	0.0000000