File: 3-C1(1.0mol%)+C20(0.6mol%)/matlab/150-3
CLOSED
Version	1.0
Language	English
Mode	Standard
Run	6
RunSerial	11787
Instrument	DSC Q2000 V24.11 Build 124
Module	DSC Standard Cell RC
Operator	Nan
File	\\Ae520-1454\ta\Data\DSC\UQ Composites\Nan\C1(4.5)+C20P(3)+CL(HotplateMixtureAB)\Iso150_60Min_3
ProcName	H/C/H/C/H complete wood PHA
InstSerial	2000-0883
AutoSerial	1293
Sample	Iso150_60Min
Size	29.8000	mg
PanMass	Not available
PanResist	Automatic Automatic  K/W
PanFactor	Default Default
Method	H/C/H/C/H complete wood PHA
Comment
Xcomment	Pan: Tzero Aluminum Hermetic
Xcomment	Gas1: Nitrogen 50.0 ml/min
Xcomment	Gas2: Nitrogen 50.0 ml/min
Text
Exotherm	UP
Kcell	1.05230
Cpconst	Standard: 0.938
Calib	-38.6961
TempCal	1	pts	157.46	156.60
TzeroDt	-87.6168 -0.0009 -1.4231
TzeroDtz	-87.6168 0.0057 6.9570
InstCalFile	Tzero: \\Ae520-1454\ta\Data\DSC\Calibration\2017\CALIBRATION\1562_RCS (90)_05_18_2017 10_50_44.TZR
InstCalFile	Baseline: \\Ae520-1454\ta\Data\DSC\Calibration\2017\2017-05-17_Calibration.001
InstCalFile	Sapphire: \\Ae520-1454\ta\Data\DSC\Calibration\2017\2017-05-17_Saphire.001
InstCalDate	Tzero 2017-05-18 Time 10:50:44
TempRange	-87.39 to 398.39 °C at 10.00 °C/min Heat Only
AutoZero	Delta T Offset 0.000 uV
AutoZero	Delta T0 Offset 0.000 uV
MultiptCal	0
MultiPtDesc	0) Not set
AutoCellConst	Calibration Date 2017-05-18 16:59:28
Controls	Gas 1  Event Off  Sampling 0.2
Cell#	RC-01562
CoolingUnit	RCS (90)
SelHeatFlow	Heat Flow T4 (mW)
AutoLidII	Installed
AutoAnalysis	Off
MacroFile
Nsig	3
Sig1	Time (min)
Sig2	Temperature (°C)
Sig3	Heat Flow (mW)
Date	2017-06-07
Time	19:47:57
OrgMethod	1: Equilibrate at 20.00 °C
OrgMethod	2: Ramp 40.00 °C/min to 150.00 °C
OrgMethod	3: Mark end of cycle 1
OrgMethod	4: Isothermal for 60.00 min
OrgMethod	5: Mark end of cycle 2
OrgMethod	6: Ramp 20.00 °C/min to 280.00 °C
OrgMethod	7: Mark end of cycle 3
OrgMethod	8: Ramp 20.00 °C/min to 20.00 °C
OrgMethod	9: Mark end of cycle 4
OrgMethod	10: Ramp 20.00 °C/min to 280.00 °C
OrgMethod	11: Mark end of cycle 5
OrgFile	C:\Users\jarra\Desktop\DSC\3-C1(1.0mol%)+C20(0.6mol%)\150-3
StartOfData
4.99994E-4	20.05066	0.09574911
0.06716666	20.33424	0.6215640
0.1321667	21.67675	-0.9678182
0.1971667	23.40436	-4.993172
0.2638334	25.44101	-9.430541
0.3288334	27.58630	-13.24099
0.3938334	29.84436	-16.33600
0.4588333	32.18116	-18.74448
0.5255000	34.63840	-20.64463
0.5905000	37.07422	-22.10535
0.6555000	39.53647	-23.33155
0.7205000	42.01254	-24.52420
0.7871668	44.54290	-26.20430
0.8521668	46.99776	-27.89230
0.9171668	49.49820	-28.76190
0.9821668	52.01038	-29.86076
1.048834	54.56543	-31.47054
1.113833	57.05774	-32.90604
1.178834	59.57886	-33.86484
1.245500	62.15805	-35.41007
1.310500	64.61560	-38.19174
1.375500	66.96994	-43.21158
1.440500	69.14770	-51.93650
1.507167	71.13830	-65.48006
1.572166	72.86368	-82.32356
1.637166	74.51255	-99.42120
1.702167	76.22696	-115.5130
1.768833	78.06335	-129.8726
1.833833	80.03994	-140.5759
1.898834	82.19312	-147.4874
1.963833	84.89220	-142.0894
2.030500	88.30351	-125.8090
2.095500	92.01108	-105.6351
2.160500	95.57788	-89.51918
2.225500	98.90603	-77.50314
2.292167	102.1238	-68.46328
2.357167	105.1211	-61.95727
2.422167	108.0142	-57.25615
2.488834	110.8965	-53.85516
2.553833	113.6479	-51.52696
2.618834	116.3538	-49.97870
2.683833	119.0269	-49.02881
2.750500	121.7410	-48.57950
2.815500	124.3680	-48.48547
2.880500	126.9859	-48.54866
2.945500	129.5918	-48.78842
3.012167	132.2560	-49.21759
3.077166	134.8470	-49.76953
3.142166	137.4301	-50.47310
3.207167	140.0106	-51.27519
3.272167	142.5800	-52.21199
3.337167	144.5608	-53.22907
3.402167	145.6638	-49.25461
3.467166	146.4493	-43.14524
3.533833	147.0432	-36.82278
3.598834	147.4802	-31.58205
3.663833	147.8163	-27.41280
3.728833	148.0758	-24.21543
3.795500	148.2852	-21.75301
3.860500	148.4451	-19.95370
3.925500	148.5736	-18.60941
3.990500	148.6763	-17.59354
4.057167	148.7631	-16.80576
4.122166	148.8316	-16.21492
4.187167	148.8882	-15.75850
4.253834	148.9375	-15.39453
4.318833	148.9769	-15.11077
4.383834	149.0109	-14.88402
4.448834	149.0402	-14.69775
4.515500	149.0658	-14.53176
4.580500	149.0876	-14.39213
4.645500	149.1063	-14.26846
4.710500	149.1239	-14.15272
4.777167	149.1391	-14.04299
4.842167	149.1532	-13.93917
4.907166	149.1662	-13.83584
4.972168	149.1770	-13.73609
5.038834	149.1879	-13.63663
5.103833	149.1984	-13.53454
5.168833	149.2070	-13.43110
5.235500	149.2168	-13.31864
5.300500	149.2266	-13.20700
5.365500	149.2354	-13.08404
5.430500	149.2436	-12.95653
5.497168	149.2533	-12.82005
5.562168	149.2621	-12.68133
5.627168	149.2713	-12.53595
5.692166	149.2799	-12.38602
5.758832	149.2898	-12.22478
5.823834	149.2990	-12.05667
5.888832	149.3089	-11.88418
5.953832	149.3198	-11.70055
6.020500	149.3292	-11.50446
6.085500	149.3413	-11.30060
6.150500	149.3521	-11.08711
6.215500	149.3641	-10.85742
6.282166	149.3766	-10.61097
6.347168	149.3898	-10.35889
6.412168	149.4038	-10.09461
6.478832	149.4182	-9.806597
6.543832	149.4331	-9.511405
6.608832	149.4490	-9.201298
6.673834	149.4664	-8.870472
6.740500	149.4838	-8.506394
6.805500	149.5026	-8.126588
6.870500	149.5234	-7.712894
6.935500	149.5446	-7.263769
7.002168	149.5697	-6.764280
7.067168	149.5960	-6.228960
7.132168	149.6250	-5.642634
7.197168	149.6561	-5.019789
7.263834	149.6892	-4.363070
7.328834	149.7206	-3.736719
7.393832	149.7502	-3.180210
7.460500	149.7749	-2.707685
7.525500	149.7949	-2.338757
7.590500	149.8102	-2.042176
7.655500	149.8234	-1.808225
7.722168	149.8339	-1.614895
7.787168	149.8419	-1.465681
7.852168	149.8489	-1.345565
7.917168	149.8547	-1.243819
7.983832	149.8599	-1.157642
8.048834	149.8632	-1.087390
8.113834	149.8666	-1.024153
8.178832	149.8693	-0.9686408
8.245500	149.8727	-0.9234509
8.310500	149.8755	-0.8786484
8.375500	149.8772	-0.8382122
8.442168	149.8791	-0.7982172
8.507168	149.8820	-0.7639194
8.572168	149.8833	-0.7307745
8.637168	149.8855	-0.6980884
8.703834	149.8874	-0.6659556
8.768832	149.8881	-0.6342388
8.833832	149.8900	-0.6077142
8.898834	149.8920	-0.5794082
8.965500	149.8938	-0.5519049
9.030500	149.8953	-0.5230906
9.095500	149.8965	-0.4956872
9.160499	149.8979	-0.4700250
9.227168	149.8994	-0.4427188
9.292168	149.9008	-0.4168144
9.357166	149.9030	-0.3923924
9.422168	149.9036	-0.3665932
9.488834	149.9049	-0.3415694
9.553832	149.9067	-0.3177792
9.618834	149.9076	-0.2930070
9.685499	149.9091	-0.2646580
9.750500	149.9107	-0.2413813
9.815500	149.9117	-0.2147022
9.880500	149.9140	-0.1891839
9.947168	149.9142	-0.1650769
10.01217	149.9153	-0.1423190
10.07717	149.9173	-0.1153175
10.14217	149.9177	-.09037494
10.20883	149.9196	-.06549752
10.27383	149.9201	-.04043277
10.33883	149.9224	-.01584106
10.40383	149.9235	0.01105760
10.47050	149.9252	0.03577566
10.53550	149.9266	0.06047370
10.60050	149.9272	0.08655582
10.66717	149.9289	0.1146014
10.73217	149.9299	0.1391573
10.79717	149.9316	0.1637302
10.86217	149.9324	0.1925556
10.92883	149.9339	0.2186098
10.99384	149.9362	0.2454486
11.05884	149.9373	0.2715430
11.12383	149.9380	0.2980778
11.19050	149.9400	0.3267778
11.25550	149.9411	0.3525500
11.32050	149.9429	0.3813694
11.38550	149.9441	0.4088144
11.45217	149.9449	0.4380106
11.51717	149.9466	0.4662476
11.58217	149.9487	0.4933926
11.64883	149.9502	0.5232067
11.71383	149.9514	0.5540532
11.77883	149.9529	0.5826342
11.84383	149.9540	0.6124739
11.91050	149.9559	0.6407868
11.97550	149.9578	0.6704250
12.04050	149.9592	0.7022482
12.10550	149.9603	0.7312038
12.17217	149.9622	0.7625874
12.23717	149.9629	0.7926739
12.30216	149.9651	0.8238266
12.36716	149.9665	0.8546332
12.43383	149.9681	0.8864361
12.49883	149.9705	0.9167174
12.56383	149.9712	0.9503019
12.62884	149.9731	0.9821145
12.69550	149.9752	1.014042
12.76050	149.9769	1.047693
12.82550	149.9786	1.081189
12.89216	149.9799	1.115658
12.95717	149.9816	1.148828
13.02217	149.9837	1.184562
13.08717	149.9856	1.217942
13.15383	149.9874	1.252043
13.21884	149.9889	1.287502
13.28383	149.9904	1.324938
13.34883	149.9922	1.360838
13.41550	149.9942	1.399856
13.48050	149.9963	1.437149
13.54550	149.9981	1.473441
13.61050	150.0001	1.511306
13.67717	150.0019	1.549604
13.74216	150.0038	1.589646
13.80717	150.0057	1.634318
13.87384	150.0088	1.679352
13.93883	150.0105	1.733236
14.00383	150.0136	1.788702
14.06884	150.0164	1.856756
14.13550	150.0199	1.940310
14.20050	150.0257	2.036571
14.26550	150.0299	2.153553
14.33050	150.0358	2.292312
14.39717	150.0447	2.461469
14.46217	150.0540	2.647660
14.52717	150.0641	2.855963
14.59216	150.0749	3.081717
14.65883	150.0871	3.334518
14.72383	150.0999	3.592540
14.78883	150.1141	3.864697
14.85550	150.1278	4.156418
14.92050	150.1430	4.444740
14.98550	150.1575	4.744302
15.05050	150.1714	5.040478
15.11716	150.1865	5.332494
15.18217	150.2013	5.613672
15.24717	150.2154	5.876106
15.31216	150.2271	6.124936
15.37883	150.2397	6.362778
15.44384	150.2505	6.578150
15.50883	150.2605	6.774262
15.57384	150.2700	6.957415
15.64050	150.2796	7.130946
15.70550	150.2868	7.292200
15.77050	150.2939	7.440484
15.83550	150.3014	7.576505
15.90217	150.3082	7.711124
15.96716	150.3146	7.833531
16.03216	150.3210	7.952256
16.09883	150.3266	8.070764
16.16383	150.3318	8.180187
16.22883	150.3375	8.283199
16.29383	150.3426	8.383168
16.36050	150.3479	8.483155
16.42550	150.3523	8.576691
16.49050	150.3579	8.676640
16.55550	150.3623	8.765753
16.62216	150.3666	8.854035
16.68716	150.3711	8.936226
16.75216	150.3754	9.021314
16.81716	150.3788	9.103345
16.88383	150.3838	9.182587
16.94884	150.3874	9.260420
17.01383	150.3912	9.338457
17.08050	150.3952	9.414691
17.14550	150.3998	9.489168
17.21050	150.4028	9.572059
17.27550	150.4070	9.641109
17.34216	150.4103	9.714238
17.40716	150.4130	9.783637
17.47216	150.4166	9.849132
17.53717	150.4203	9.897876
17.60383	150.4224	9.939236
17.66883	150.4250	9.997163
17.73383	150.4274	10.05377
17.79883	150.4305	10.09841
17.86550	150.4322	10.13770
17.93050	150.4344	10.16766
17.99550	150.4356	10.19030
18.06216	150.4364	10.20431
18.12716	150.4372	10.21203
18.19216	150.4374	10.21841
18.25716	150.4375	10.22107
18.32383	150.4360	10.21785
18.38883	150.4349	10.19987
18.45383	150.4330	10.15958
18.51883	150.4304	10.10333
18.58550	150.4278	10.04033
18.65050	150.4250	9.977161
18.71550	150.4217	9.902795
18.78050	150.4176	9.826148
18.84716	150.4137	9.738072
18.91217	150.4091	9.645679
18.97716	150.4042	9.548157
19.04216	150.3990	9.443696
19.10883	150.3938	9.333418
19.17383	150.3878	9.216984
19.23883	150.3816	9.099562
19.30550	150.3758	8.969678
19.37050	150.3695	8.839142
19.43550	150.3626	8.703126
19.50050	150.3560	8.558886
19.56716	150.3480	8.411681
19.63216	150.3404	8.266953
19.69716	150.3338	8.117356
19.76216	150.3259	7.965718
19.82883	150.3184	7.810976
19.89383	150.3109	7.662954
19.95883	150.3032	7.517859
20.02383	150.2970	7.375632
20.09050	150.2893	7.230113
20.15550	150.2825	7.093869
20.22050	150.2757	6.961056
20.28717	150.2688	6.823938
20.35216	150.2626	6.697954
20.41716	150.2565	6.577544
20.48216	150.2499	6.459161
20.54883	150.2443	6.339868
20.61383	150.2393	6.231118
20.67883	150.2332	6.122647
20.74383	150.2282	6.017628
20.81050	150.2230	5.912080
20.87550	150.2180	5.816094
20.94050	150.2125	5.719538
21.00550	150.2086	5.624766
21.07216	150.2036	5.531974
21.13716	150.1990	5.443924
21.20216	150.1945	5.352675
21.26883	150.1900	5.257668
21.33383	150.1864	5.171936
21.39883	150.1814	5.082760
21.46383	150.1778	4.992028
21.53050	150.1729	4.898734
21.59550	150.1687	4.807146
21.66050	150.1636	4.717142
21.72550	150.1598	4.625191
21.79216	150.1546	4.531438
21.85716	150.1503	4.432836
21.92216	150.1451	4.338274
21.98716	150.1401	4.242817
22.05383	150.1352	4.144936
22.11883	150.1299	4.050360
22.18383	150.1245	3.951875
22.24883	150.1200	3.860105
22.31550	150.1146	3.761298
22.38050	150.1101	3.667200
22.44550	150.1053	3.576518
22.51216	150.1005	3.481245
22.57716	150.0966	3.389798
22.64216	150.0913	3.300344
22.70717	150.0868	3.210476
22.77383	150.0826	3.123332
22.83883	150.0780	3.036723
22.90383	150.0741	2.951560
22.96883	150.0698	2.866992
23.03550	150.0654	2.782449
23.10050	150.0620	2.699596
23.16550	150.0575	2.621066
23.23050	150.0529	2.539770
23.29716	150.0499	2.455935
23.36216	150.0456	2.380466
23.42717	150.0416	2.303014
23.49383	150.0377	2.223053
23.55883	150.0343	2.147563
23.62383	150.0302	2.071287
23.68883	150.0271	1.997352
23.75550	150.0239	1.921589
23.82050	150.0212	1.849411
23.88550	150.0172	1.777019
23.95050	150.0134	1.707079
24.01716	150.0108	1.633681
24.08216	150.0068	1.565671
24.14716	150.0042	1.498547
24.21216	150.0001	1.434378
24.27883	149.9964	1.366878
24.34383	149.9932	1.301653
24.40883	149.9891	1.240771
24.47550	149.9862	1.175547
24.54050	149.9817	1.114601
24.60550	149.9790	1.049471
24.67050	149.9755	0.9863526
24.73716	149.9730	0.9265288
24.80217	149.9706	0.8667220
24.86716	149.9673	0.8075595
24.93216	149.9648	0.7487874
24.99883	149.9625	0.6907978
25.06383	149.9601	0.6377007
25.12883	149.9567	0.5837203
25.19383	149.9531	0.5362783
25.26050	149.9514	0.4847692
25.32550	149.9478	0.4365426
25.39050	149.9456	0.3842975
25.45550	149.9428	0.3368110
25.52216	149.9420	0.2864125
25.58716	149.9389	0.2392992
25.65216	149.9368	0.1931401
25.71883	149.9335	0.1512582
25.78383	149.9324	0.1102007
25.84883	149.9296	0.06907556
25.91383	149.9278	0.02740455
25.98050	149.9255	-.01391295
26.04550	149.9240	-.05279322
26.11050	149.9215	-.08794244
26.17550	149.9198	-0.1254227
26.24216	149.9182	-0.1610114
26.30716	149.9168	-0.1961943
26.37216	149.9152	-0.2305087
26.43717	149.9129	-0.2608411
26.50383	149.9114	-0.2914578
26.56883	149.9104	-0.3197512
26.63383	149.9075	-0.3477920
26.70050	149.9070	-0.3790745
26.76550	149.9059	-0.4075561
26.83050	149.9044	-0.4361687
26.89550	149.9024	-0.4586006
26.96216	149.9019	-0.4855646
27.02717	149.9007	-0.5102384
27.09216	149.8995	-0.5331641
27.15716	149.8978	-0.5557144
27.22383	149.8963	-0.5753702
27.28883	149.8958	-0.5989180
27.35383	149.8941	-0.6210026
27.41883	149.8940	-0.6416434
27.48550	149.8922	-0.6606769
27.55050	149.8915	-0.6782595
27.61550	149.8906	-0.6953551
27.68216	149.8887	-0.7129070
27.74716	149.8869	-0.7275395
27.81217	149.8860	-0.7434688
27.87716	149.8854	-0.7595138
27.94383	149.8850	-0.7756647
28.00883	149.8845	-0.7913944
28.07383	149.8829	-0.8051324
28.13883	149.8822	-0.8203266
28.20550	149.8823	-0.8353339
28.27050	149.8810	-0.8496406
28.33550	149.8805	-0.8639794
28.40050	149.8808	-0.8785897
28.46716	149.8801	-0.8918964
28.53216	149.8801	-0.9054220
28.59716	149.8794	-0.9177908
28.66217	149.8790	-0.9301181
28.72883	149.8788	-0.9421891
28.79383	149.8777	-0.9534734
28.85883	149.8781	-0.9642870
28.92550	149.8778	-0.9745972
28.99050	149.8778	-0.9845826
29.05550	149.8768	-0.9946728
29.12050	149.8770	-1.004578
29.18717	149.8756	-1.014473
29.25217	149.8757	-1.023507
29.31716	149.8750	-1.031632
29.38216	149.8749	-1.039565
29.44883	149.8740	-1.047275
29.51383	149.8737	-1.055058
29.57883	149.8739	-1.062708
29.64383	149.8731	-1.070457
29.71050	149.8727	-1.077976
29.77550	149.8717	-1.084705
29.84050	149.8714	-1.090910
29.90716	149.8708	-1.097263
29.97216	149.8703	-1.102640
30.03717	149.8698	-1.108594
30.10217	149.8696	-1.114248
30.16883	149.8694	-1.120011
30.23383	149.8702	-1.126275
30.29883	149.8694	-1.132151
30.36383	149.8694	-1.137969
30.43050	149.8699	-1.143904
30.49550	149.8694	-1.149441
30.56050	149.8697	-1.154463
30.62550	149.8694	-1.159276
30.69216	149.8694	-1.163995
30.75716	149.8691	-1.168490
30.82217	149.8688	-1.172727
30.88883	149.8683	-1.176756
30.95383	149.8680	-1.180148
31.01883	149.8674	-1.183043
31.08383	149.8668	-1.185991
31.15050	149.8672	-1.189263
31.21550	149.8671	-1.192962
31.28050	149.8671	-1.196821
31.34550	149.8678	-1.200795
31.41217	149.8671	-1.204937
31.47717	149.8664	-1.208417
31.54216	149.8664	-1.211614
31.60716	149.8669	-1.214474
31.67383	149.8664	-1.217330
31.73883	149.8664	-1.220050
31.80383	149.8658	-1.222434
31.86883	149.8660	-1.224802
31.93550	149.8656	-1.227201
32.00050	149.8654	-1.229222
32.06550	149.8650	-1.231161
32.13216	149.8648	-1.233019
32.19717	149.8641	-1.234927
32.26216	149.8651	-1.236967
32.32717	149.8636	-1.238996
32.39383	149.8648	-1.241365
32.45883	149.8645	-1.243526
32.52383	149.8641	-1.245849
32.58883	149.8650	-1.248139
32.65550	149.8646	-1.250724
32.72050	149.8653	-1.253184
32.78550	149.8646	-1.255545
32.85050	149.8648	-1.257278
32.91716	149.8642	-1.258682
32.98216	149.8634	-1.259676
33.04716	149.8632	-1.260557
33.11383	149.8633	-1.261415
33.17883	149.8623	-1.262424
33.24383	149.8632	-1.263730
33.30883	149.8628	-1.265213
33.37550	149.8627	-1.266574
33.44050	149.8632	-1.268063
33.50550	149.8628	-1.269701
33.57050	149.8634	-1.271454
33.63716	149.8636	-1.273508
33.70216	149.8645	-1.275497
33.76716	149.8643	-1.277516
33.83216	149.8642	-1.279002
33.89883	149.8639	-1.280088
33.96383	149.8635	-1.281266
34.02883	149.8641	-1.282383
34.09550	149.8638	-1.283101
34.16050	149.8644	-1.283882
34.22550	149.8640	-1.284508
34.29050	149.8637	-1.284988
34.35716	149.8628	-1.285282
34.42216	149.8626	-1.285496
34.48717	149.8636	-1.286090
34.55217	149.8629	-1.286916
34.61883	149.8639	-1.288082
34.68384	149.8629	-1.289409
34.74883	149.8634	-1.290894
34.81383	149.8637	-1.292020
34.88050	149.8636	-1.293192
34.94550	149.8632	-1.294199
35.01050	149.8638	-1.294684
35.07550	149.8638	-1.295204
35.14216	149.8635	-1.295667
35.20716	149.8629	-1.296307
35.27217	149.8637	-1.296908
35.33883	149.8632	-1.297588
35.40383	149.8628	-1.298166
35.46884	149.8627	-1.298519
35.53383	149.8619	-1.298686
35.60050	149.8624	-1.298434
35.66550	149.8620	-1.298217
35.73050	149.8617	-1.298420
35.79550	149.8623	-1.299279
35.86217	149.8628	-1.300026
35.92717	149.8617	-1.301174
35.99216	149.8626	-1.302335
36.05716	149.8626	-1.303300
36.12383	149.8629	-1.304466
36.18883	149.8624	-1.305310
36.25383	149.8624	-1.306369
36.32050	149.8631	-1.307281
36.38550	149.8621	-1.307694
36.45050	149.8621	-1.307574
36.51550	149.8611	-1.307183
36.58216	149.8614	-1.306951
36.64717	149.8614	-1.307021
36.71216	149.8611	-1.307328
36.77716	149.8613	-1.307814
36.84384	149.8611	-1.308091
36.90883	149.8615	-1.308566
36.97383	149.8613	-1.309227
37.03883	149.8624	-1.310229
37.10550	149.8615	-1.311140
37.17050	149.8628	-1.312137
37.23550	149.8621	-1.313168
37.30217	149.8623	-1.314106
37.36716	149.8624	-1.315111
37.43216	149.8629	-1.315844
37.49716	149.8621	-1.316208
37.56383	149.8630	-1.316876
37.62883	149.8634	-1.317659
37.69383	149.8627	-1.318006
37.75883	149.8631	-1.318343
37.82550	149.8620	-1.318882
37.89050	149.8622	-1.318518
37.95550	149.8620	-1.318078
38.02050	149.8626	-1.317584
38.08716	149.8616	-1.317163
38.15216	149.8617	-1.316863
38.21716	149.8610	-1.316911
38.28216	149.8621	-1.317183
38.34883	149.8617	-1.317765
38.41383	149.8621	-1.318407
38.47883	149.8611	-1.318922
38.54550	149.8616	-1.319676
38.61050	149.8623	-1.320513
38.67550	149.8622	-1.321294
38.74050	149.8619	-1.322151
38.80716	149.8622	-1.322614
38.87216	149.8623	-1.322766
38.93716	149.8618	-1.322317
39.00217	149.8611	-1.321708
39.06883	149.8609	-1.321176
39.13383	149.8604	-1.320924
39.19883	149.8610	-1.320854
39.26383	149.8612	-1.321376
39.33050	149.8616	-1.322238
39.39550	149.8613	-1.322884
39.46050	149.8610	-1.323610
39.52716	149.8612	-1.324328
39.59216	149.8615	-1.324569
39.65716	149.8611	-1.324849
39.72217	149.8616	-1.325172
39.78883	149.8617	-1.325657
39.85383	149.8617	-1.325999
39.91883	149.8619	-1.326340
39.98383	149.8624	-1.326584
40.05050	149.8621	-1.327187
40.11550	149.8618	-1.327651
40.18050	149.8623	-1.328372
40.24550	149.8621	-1.328631
40.31216	149.8616	-1.328496
40.37717	149.8618	-1.328184
40.44216	149.8624	-1.328181
40.50883	149.8626	-1.328161
40.57383	149.8615	-1.327988
40.63883	149.8614	-1.328084
40.70383	149.8618	-1.328321
40.77050	149.8618	-1.328741
40.83550	149.8616	-1.328970
40.90050	149.8609	-1.328921
40.96550	149.8606	-1.328585
41.03217	149.8613	-1.328518
41.09716	149.8612	-1.328619
41.16217	149.8616	-1.329119
41.22717	149.8615	-1.329564
41.29383	149.8608	-1.330065
41.35883	149.8618	-1.330675
41.42383	149.8617	-1.331286
41.48883	149.8619	-1.331584
41.55550	149.8613	-1.332074
41.62050	149.8618	-1.332528
41.68550	149.8617	-1.332679
41.75217	149.8614	-1.332619
41.81717	149.8611	-1.332582
41.88217	149.8614	-1.332821
41.94717	149.8615	-1.333026
42.01383	149.8619	-1.333248
42.07883	149.8618	-1.333691
42.14383	149.8625	-1.334218
42.20883	149.8623	-1.334651
42.27550	149.8619	-1.334777
42.34050	149.8624	-1.334854
42.40550	149.8618	-1.334863
42.47050	149.8625	-1.335005
42.53717	149.8615	-1.335098
42.60217	149.8617	-1.335275
42.66716	149.8615	-1.335190
42.73383	149.8617	-1.334831
42.79883	149.8615	-1.334705
42.86383	149.8623	-1.334909
42.92883	149.8618	-1.335498
42.99550	149.8620	-1.336388
43.06050	149.8614	-1.336729
43.12550	149.8617	-1.336879
43.19050	149.8610	-1.336744
43.25717	149.8613	-1.336310
43.32217	149.8607	-1.335696
43.38716	149.8608	-1.335374
43.45216	149.8614	-1.335309
43.51883	149.8609	-1.335647
43.58383	149.8614	-1.335991
43.64883	149.8618	-1.336580
43.71550	149.8614	-1.337197
43.78050	149.8618	-1.337727
43.84550	149.8616	-1.338161
43.91050	149.8617	-1.338172
43.97717	149.8606	-1.338128
44.04217	149.8622	-1.338120
44.10717	149.8612	-1.338142
44.17216	149.8614	-1.338081
44.23883	149.8611	-1.338151
44.30383	149.8619	-1.338035
44.36883	149.8615	-1.338080
44.43383	149.8607	-1.338089
44.50050	149.8612	-1.338299
44.56550	149.8610	-1.338594
44.63050	149.8611	-1.338872
44.69550	149.8610	-1.339026
44.76216	149.8610	-1.338978
44.82717	149.8604	-1.338905
44.89217	149.8612	-1.338906
44.95883	149.8609	-1.339024
45.02383	149.8614	-1.339172
45.08883	149.8614	-1.339551
45.15383	149.8609	-1.340074
45.22050	149.8610	-1.340272
45.28550	149.8612	-1.340294
45.35050	149.8605	-1.340116
45.41550	149.8614	-1.339840
45.48217	149.8610	-1.339626
45.54716	149.8608	-1.339938
45.61217	149.8613	-1.340227
45.67717	149.8618	-1.340344
45.74383	149.8611	-1.340606
45.80883	149.8617	-1.340836
45.87383	149.8618	-1.341216
45.94050	149.8628	-1.341761
46.00550	149.8620	-1.342365
46.07050	149.8620	-1.342804
46.13550	149.8626	-1.343176
46.20216	149.8616	-1.343166
46.26717	149.8618	-1.342856
46.33217	149.8619	-1.342452
46.39717	149.8610	-1.341854
46.46383	149.8612	-1.340978
46.52883	149.8613	-1.340668
46.59384	149.8614	-1.340511
46.65883	149.8612	-1.340698
46.72550	149.8613	-1.340769
46.79050	149.8615	-1.340918
46.85550	149.8609	-1.341201
46.92216	149.8609	-1.341375
46.98717	149.8614	-1.341487
47.05217	149.8616	-1.341604
47.11716	149.8613	-1.341944
47.18383	149.8619	-1.342404
47.24883	149.8615	-1.342816
47.31383	149.8617	-1.342957
47.37883	149.8613	-1.343214
47.44550	149.8611	-1.343308
47.51050	149.8618	-1.343726
47.57550	149.8615	-1.343952
47.64050	149.8618	-1.344026
47.70717	149.8611	-1.343620
47.77217	149.8610	-1.343296
47.83716	149.8616	-1.343070
47.90216	149.8608	-1.343053
47.96884	149.8610	-1.343182
48.03383	149.8614	-1.343463
48.09883	149.8615	-1.343571
48.16550	149.8615	-1.343683
48.23050	149.8617	-1.343716
48.29550	149.8617	-1.344051
48.36050	149.8622	-1.344708
48.42717	149.8617	-1.344778
48.49216	149.8624	-1.344957
48.55717	149.8621	-1.345076
48.62216	149.8620	-1.345020
48.68883	149.8620	-1.344832
48.75383	149.8612	-1.344856
48.81883	149.8613	-1.344769
48.88383	149.8602	-1.344658
48.95050	149.8600	-1.344134
49.01550	149.8612	-1.343850
49.08050	149.8611	-1.343732
49.14717	149.8616	-1.343594
49.21216	149.8616	-1.343844
49.27716	149.8614	-1.344197
49.34217	149.8616	-1.344839
49.40883	149.8613	-1.345477
49.47383	149.8615	-1.345870
49.53883	149.8617	-1.346077
49.60383	149.8615	-1.345958
49.67050	149.8618	-1.346026
49.73550	149.8621	-1.346226
49.80050	149.8624	-1.346408
49.86550	149.8615	-1.346492
49.93217	149.8612	-1.346202
49.99716	149.8613	-1.345847
50.06216	149.8618	-1.345654
50.12883	149.8618	-1.345458
50.19383	149.8615	-1.345549
50.25883	149.8617	-1.345483
50.32383	149.8612	-1.345551
50.39050	149.8610	-1.345298
50.45550	149.8611	-1.345097
50.52050	149.8617	-1.345005
50.58550	149.8612	-1.345099
50.65216	149.8613	-1.345351
50.71717	149.8608	-1.345604
50.78217	149.8615	-1.345929
50.84716	149.8607	-1.346228
50.91383	149.8615	-1.346473
50.97883	149.8622	-1.346764
51.04383	149.8623	-1.346985
51.10883	149.8624	-1.347300
51.17550	149.8616	-1.347540
51.24050	149.8614	-1.347501
51.30550	149.8618	-1.347692
51.37217	149.8628	-1.348006
51.43716	149.8627	-1.348015
51.50217	149.8620	-1.348132
51.56716	149.8616	-1.348040
51.63383	149.8618	-1.347374
51.69883	149.8622	-1.346854
51.76383	149.8609	-1.346539
51.82883	149.8620	-1.346285
51.89550	149.8610	-1.346122
51.96050	149.8606	-1.345815
52.02550	149.8606	-1.345512
52.09050	149.8599	-1.345005
52.15717	149.8600	-1.344796
52.22217	149.8605	-1.344496
52.28716	149.8602	-1.344451
52.35383	149.8614	-1.344766
52.41883	149.8603	-1.345303
52.48383	149.8604	-1.346032
52.54883	149.8613	-1.346993
52.61550	149.8616	-1.347808
52.68050	149.8615	-1.348617
52.74550	149.8616	-1.349302
52.81050	149.8619	-1.349710
52.87717	149.8622	-1.350383
52.94216	149.8620	-1.350664
53.00717	149.8621	-1.350609
53.07217	149.8622	-1.350444
53.13882	149.8620	-1.350126
53.20383	149.8621	-1.349880
53.26884	149.8615	-1.349754
53.33550	149.8619	-1.349577
53.40050	149.8624	-1.349260
53.46550	149.8615	-1.349140
53.53050	149.8614	-1.348845
53.59716	149.8615	-1.348540
53.66216	149.8616	-1.348078
53.72717	149.8614	-1.348181
53.79217	149.8617	-1.348388
53.85883	149.8619	-1.348529
53.92383	149.8614	-1.348941
53.98882	149.8619	-1.349296
54.05383	149.8623	-1.349520
54.12050	149.8608	-1.349808
54.18550	149.8614	-1.349778
54.25050	149.8617	-1.349559
54.31550	149.8614	-1.349347
54.38217	149.8615	-1.349257
54.44717	149.8607	-1.349092
54.51216	149.8609	-1.349273
54.57883	149.8613	-1.349303
54.64384	149.8618	-1.349147
54.70883	149.8611	-1.349326
54.77383	149.8616	-1.349412
54.84050	149.8608	-1.349341
54.90550	149.8606	-1.349106
54.97050	149.8606	-1.348956
55.03550	149.8611	-1.348873
55.10217	149.8613	-1.348885
55.16716	149.8620	-1.348860
55.23217	149.8621	-1.349152
55.29717	149.8623	-1.349774
55.36382	149.8620	-1.349986
55.42883	149.8622	-1.350189
55.49382	149.8624	-1.350548
55.56050	149.8620	-1.350762
55.62550	149.8622	-1.350766
55.69050	149.8616	-1.350601
55.75550	149.8626	-1.350624
55.82217	149.8620	-1.350433
55.88716	149.8622	-1.350453
55.95216	149.8616	-1.350254
56.01716	149.8612	-1.349864
56.08383	149.8614	-1.349420
56.14883	149.8609	-1.349090
56.21382	149.8610	-1.348779
56.27883	149.8608	-1.348822
56.34550	149.8611	-1.349033
56.41050	149.8611	-1.349171
56.47550	149.8601	-1.349014
56.54217	149.8606	-1.348773
56.60717	149.8607	-1.348626
56.67217	149.8604	-1.348607
56.73717	149.8613	-1.349020
56.80383	149.8606	-1.349392
56.86882	149.8616	-1.350105
56.93383	149.8617	-1.350772
56.99883	149.8614	-1.351505
57.06550	149.8624	-1.352271
57.13050	149.8614	-1.352719
57.19550	149.8619	-1.352931
57.26050	149.8620	-1.353035
57.32717	149.8622	-1.353014
57.39216	149.8613	-1.352915
57.45717	149.8622	-1.352717
57.52217	149.8621	-1.352471
57.58882	149.8623	-1.352208
57.65383	149.8628	-1.352256
57.71884	149.8623	-1.352440
57.78550	149.8621	-1.352616
57.85050	149.8617	-1.352515
57.91550	149.8616	-1.352268
57.98050	149.8611	-1.351896
58.04717	149.8622	-1.351617
58.11217	149.8615	-1.351054
58.17717	149.8614	-1.350837
58.24216	149.8610	-1.350469
58.30883	149.8603	-1.350138
58.37383	149.8608	-1.350135
58.43882	149.8613	-1.350466
58.50383	149.8614	-1.350822
58.57050	149.8608	-1.350886
58.63550	149.8606	-1.351169
58.70050	149.8616	-1.351420
58.76716	149.8614	-1.351728
58.83217	149.8608	-1.352019
58.89717	149.8620	-1.352464
58.96216	149.8617	-1.353005
59.02883	149.8617	-1.353408
59.09384	149.8618	-1.353626
59.15883	149.8615	-1.353730
59.22382	149.8621	-1.353681
59.29050	149.8625	-1.353521
59.35550	149.8620	-1.353414
59.42050	149.8619	-1.353439
59.48550	149.8623	-1.353491
59.55217	149.8619	-1.353399
59.61716	149.8625	-1.353588
59.68217	149.8620	-1.353735
59.74883	149.8623	-1.354010
59.81382	149.8628	-1.353990
59.87883	149.8616	-1.353609
59.94384	149.8616	-1.352966
60.01050	149.8615	-1.352666
60.07550	149.8615	-1.352184
60.14050	149.8617	-1.351861
60.20550	149.8613	-1.351736
60.27217	149.8614	-1.351736
60.33716	149.8611	-1.351831
60.40217	149.8614	-1.352070
60.46717	149.8620	-1.352159
60.53383	149.8618	-1.352121
60.59882	149.8616	-1.352308
60.66382	149.8609	-1.352555
60.72883	149.8618	-1.352805
60.79550	149.8613	-1.352971
60.86050	149.8624	-1.352858
60.92550	149.8611	-1.352744
60.99216	149.8613	-1.352763
61.05717	149.8618	-1.352767
61.12217	149.8618	-1.352972
61.18716	149.8622	-1.353159
61.25383	149.8617	-1.353299
61.31884	149.8622	-1.353712
61.38383	149.8617	-1.353757
61.44883	149.8620	-1.353705
61.51550	149.8616	-1.353778
61.58050	149.8616	-1.353765
61.64550	149.8618	-1.353716
61.71050	149.8619	-1.353558
61.77717	149.8614	-1.353628
61.84217	149.8614	-1.353804
61.90717	149.8617	-1.353908
61.97382	149.8618	-1.353773
62.03882	149.8619	-1.353898
62.10383	149.8616	-1.354036
62.16882	149.8624	-1.354082
62.23550	149.8620	-1.354086
62.30050	149.8620	-1.354234
62.36550	149.8619	-1.354612
62.43050	149.8616	-1.355109
62.49717	149.8619	-1.355328
62.56216	149.8613	-1.355113
62.62717	149.8620	-1.354949
62.69216	149.8616	-1.354779
62.75883	149.8611	-1.354266
62.82383	149.8616	-1.353593
62.88882	149.8618	-1.353478
62.95550	149.8613	-1.353380
63.02050	149.8611	-1.352961
63.08550	149.8612	-1.353005
63.15050	149.8617	-1.353284
63.21717	149.8614	-1.353369
63.27717	149.8645	-1.354434
63.34217	150.2166	-1.559801
63.40717	150.9698	-3.954074
63.47217	151.8891	-7.081118
63.53882	152.9411	-10.09538
63.60383	154.0394	-12.50546
63.66882	155.1882	-14.38140
63.73383	156.3731	-15.79755
63.80050	157.6138	-16.89139
63.86550	158.8442	-17.70764
63.93050	160.0883	-18.34156
63.99550	161.3415	-18.86305
64.06216	162.6360	-19.31317
64.12717	163.9034	-19.68383
64.19217	165.1763	-20.00560
64.25884	166.4860	-20.29561
64.32384	167.7644	-20.55834
64.38884	169.0455	-20.80635
64.45383	170.3285	-21.04202
64.52050	171.6451	-21.28766
64.58550	172.9303	-21.53159
64.65050	174.2156	-21.76704
64.71550	175.5024	-22.00127
64.78217	176.8224	-22.24588
64.84717	178.1088	-22.49290
64.91217	179.3958	-22.74496
64.97718	180.6844	-23.01170
65.04384	182.0050	-23.29781
65.10884	183.2927	-23.58760
65.17383	184.5800	-23.88840
65.24050	185.8999	-24.20719
65.30550	187.1866	-24.52196
65.37050	188.4741	-24.85354
65.43550	189.7602	-25.18724
65.50217	191.0799	-25.55449
65.56718	192.3660	-25.92534
65.63218	193.6504	-26.30998
65.69718	194.9346	-26.71116
65.76384	196.2503	-27.15250
65.82884	197.5326	-27.61611
65.89384	198.8128	-28.11268
65.95884	200.0922	-28.63885
66.02550	201.4015	-29.23180
66.09050	202.6755	-29.85836
66.15550	203.9476	-30.54365
66.22218	205.2496	-31.30598
66.28718	206.5150	-32.13763
66.35218	207.7770	-33.05112
66.41718	209.0342	-34.07262
66.48384	210.3183	-35.25490
66.54884	211.5633	-36.57434
66.61384	212.7979	-38.14351
66.67884	214.0177	-40.10416
66.74550	215.2413	-42.77396
66.81050	216.3941	-46.32896
66.87550	217.4984	-51.00700
66.94050	218.5524	-56.71476
67.00718	219.5966	-63.29549
67.07218	220.6054	-69.72439
67.13718	221.6558	-74.78842
67.20216	222.8650	-75.47919
67.26882	224.3308	-71.72741
67.33384	225.8760	-65.93839
67.39884	227.4930	-58.71188
67.46550	229.2097	-50.10782
67.53050	230.8712	-42.70620
67.59550	232.4424	-37.39356
67.66050	233.9320	-33.71929
67.72718	235.3994	-31.14363
67.79218	236.7902	-29.43194
67.85718	238.1525	-28.26260
67.92218	239.4958	-27.47438
67.98882	240.8594	-26.95719
68.05384	242.1808	-26.62678
68.11884	243.4955	-26.40660
68.18384	244.8063	-26.26555
68.25050	246.1485	-26.16957
68.31550	247.4553	-26.11958
68.38050	248.7603	-26.09091
68.44718	250.0979	-26.08380
68.51218	251.4010	-26.07994
68.57718	252.7040	-26.08031
68.64216	254.0063	-26.08627
68.70884	255.3420	-26.10460
68.77384	256.6438	-26.14144
68.83884	257.9451	-26.20358
68.90384	259.2454	-26.25242
68.97050	260.5802	-26.31808
69.03550	261.8808	-26.36226
69.10050	263.1820	-26.42763
69.16550	264.4826	-26.47447
69.23218	265.8161	-26.54097
69.29718	267.1164	-26.60046
69.36218	268.4172	-26.65264
69.42884	269.7506	-26.71609
69.49384	271.0508	-26.77670
69.55884	272.3510	-26.82546
69.62384	273.6507	-26.88174
69.69050	274.9838	-27.00754
69.75050	276.1776	-27.25310
69.81718	277.2178	-27.06722
69.88218	277.2046	-21.91670
69.94718	276.7540	-14.04808
70.01384	276.0248	-6.406176
70.07884	275.1448	-0.3860588
70.14384	274.1538	4.188222
70.20884	273.0816	7.569751
70.27550	271.9256	10.10858
70.34050	270.7576	11.93902
70.40550	269.5598	13.26214
70.47050	268.3402	14.28754
70.53718	267.0730	15.04840
70.60218	265.8249	15.64216
70.66718	264.5666	16.11066
70.73218	263.3025	16.48534
70.79884	261.9995	16.79229
70.86384	260.7244	17.00513
70.92884	259.4444	17.20634
70.99550	258.1306	17.37625
71.06050	256.8462	17.51846
71.12550	255.5606	17.63387
71.19050	254.2732	17.73998
71.25718	252.9512	17.83548
71.32218	251.6625	17.91168
71.38718	250.3720	17.98175
71.45216	249.0812	18.04722
71.51882	247.7567	18.10722
71.58384	246.4648	18.15875
71.64884	245.1715	18.19810
71.71384	243.8780	18.23344
71.78050	242.5516	18.26112
71.84550	241.2578	18.28113
71.91050	239.9642	18.30604
71.97551	238.6707	18.32941
72.04218	237.3426	18.35376
72.10718	236.0480	18.37732
72.17218	234.7533	18.39478
72.23882	233.4251	18.40768
72.30384	232.1299	18.41935
72.36884	230.8348	18.43045
72.43384	229.5397	18.44354
72.50050	228.2106	18.45410
72.56550	226.9150	18.46853
72.63050	225.6207	18.47917
72.69550	224.3257	18.49795
72.76218	222.9968	18.51113
72.82718	221.7016	18.52464
72.89216	220.4060	18.53672
72.95718	219.1106	18.55008
73.02384	217.7816	18.56459
73.08884	216.4846	18.57584
73.15384	215.1888	18.58600
73.22050	213.8584	18.59499
73.28550	212.5633	18.60238
73.35050	211.2675	18.60889
73.41550	209.9717	18.61541
73.48218	208.6412	18.62201
73.54718	207.3452	18.62741
73.61218	206.0489	18.63177
73.67718	204.7523	18.63425
73.74384	203.4232	18.63605
73.80884	202.1281	18.63730
73.87384	200.8324	18.63823
73.93884	199.5362	18.64078
74.00550	198.2069	18.64464
74.07050	196.9103	18.64905
74.13550	195.6142	18.65353
74.20216	194.2846	18.65922
74.26716	192.9879	18.66520
74.33218	191.6916	18.67003
74.39718	190.3948	18.67454
74.46384	189.0655	18.67787
74.52884	187.7685	18.68054
74.59384	186.4717	18.68221
74.65884	185.1754	18.68313
74.72551	183.8464	18.68257
74.79050	182.5502	18.68143
74.85550	181.2533	18.68014
74.92050	179.9575	18.67863
74.98718	178.6289	18.67819
75.05218	177.3334	18.67988
75.11718	176.0377	18.68437
75.18218	174.7411	18.69142
75.24884	173.4115	18.70174
75.31384	172.1154	18.71028
75.37884	170.8181	18.71848
75.44550	169.4898	18.74092
75.51050	168.1955	18.86051
75.57550	166.9092	19.11046
75.64050	165.6356	19.73226
75.70718	164.3664	21.19970
75.77218	163.1872	24.02059
75.83716	162.0927	28.63474
75.90218	161.0772	34.74438
75.96884	160.0707	41.27474
76.03384	159.0486	46.37776
76.09882	157.9306	49.27606
76.16382	156.6943	49.77380
76.23050	155.3138	48.07509
76.29550	153.8818	44.91246
76.36050	152.4018	41.02530
76.42718	150.8728	37.03932
76.49218	149.3985	33.59631
76.55718	147.9513	30.74580
76.62218	146.5342	28.46468
76.68884	145.1060	26.63686
76.75384	143.7342	25.24122
76.81884	142.3791	24.14121
76.88384	141.0349	23.27666
76.95050	139.6666	22.56550
77.01550	138.3408	22.01075
77.08050	137.0209	21.56220
77.14550	135.7046	21.19283
77.21218	134.3577	20.87579
77.27718	133.0476	20.61420
77.34216	131.7368	20.34042
77.40884	130.3925	20.08472
77.47384	129.0864	19.91190
77.53882	127.7812	19.75575
77.60384	126.4769	19.61075
77.67050	125.1398	19.47484
77.73550	123.8370	19.34234
77.80050	122.5333	19.20782
77.86550	121.2304	19.08416
77.93218	119.8948	18.97039
77.99718	118.5917	18.86752
78.06216	117.2903	18.77037
78.12718	115.9864	18.64106
78.19384	114.6517	18.54590
78.25884	113.3501	18.45426
78.32384	112.0476	18.36213
78.38884	110.7466	18.27951
78.45550	109.4127	18.18976
78.52050	108.1114	18.11041
78.58550	106.8098	18.03062
78.65218	105.4755	17.94776
78.71718	104.1734	17.86442
78.78218	102.8720	17.78721
78.84718	101.5707	17.70678
78.91382	100.2367	17.62966
78.97884	98.93592	17.55575
79.04384	97.63553	17.48022
79.10884	96.33452	17.41121
79.17550	95.00121	17.33690
79.24050	93.70016	17.26684
79.30550	92.39985	17.19509
79.37050	91.09894	17.12394
79.43718	89.76375	17.04649
79.50218	88.46339	16.96988
79.56718	87.16272	16.89970
79.63384	85.82745	16.82198
79.69884	84.52601	16.74678
79.76384	83.22442	16.67595
79.82884	81.92447	16.60302
79.89550	80.59071	16.52434
79.96050	79.29040	16.45469
80.02550	77.98865	16.37562
80.09050	76.68757	16.31165
80.15718	75.35474	16.24637
80.22218	74.05393	16.18402
80.28718	72.75337	16.11918
80.35218	71.45239	16.05260
80.41884	70.11834	15.98467
80.48384	68.81712	15.91756
80.54884	67.51614	15.84390
80.61550	66.18084	15.77068
80.68050	64.87963	15.70164
80.74550	63.57880	15.62960
80.81050	62.27724	15.55162
80.87718	60.94292	15.46431
80.94218	59.64170	15.38903
81.00718	58.34090	15.31497
81.07218	57.03936	15.24239
81.13884	55.70571	15.16791
81.20384	54.40508	15.09580
81.26882	53.10408	15.01935
81.33384	51.80306	14.94912
81.40050	50.46831	14.87668
81.46550	49.16734	14.80534
81.53050	47.86594	14.73355
81.59550	46.56418	14.66133
81.66218	45.22950	14.59065
81.72718	43.92884	14.52321
81.79218	42.62716	14.45223
81.85884	41.29320	14.36789
81.92384	39.98981	14.27217
81.98882	38.68776	14.21360
82.05382	37.38589	14.13946
82.12050	36.05232	14.05673
82.18550	34.75015	13.97409
82.25050	33.44650	13.87925
82.31550	32.14399	13.77308
82.38218	30.80718	13.66429
82.44718	29.50414	13.56442
82.51218	28.20050	13.44876
82.57718	26.89629	13.33929
82.64384	25.55929	13.22826
82.70882	24.25516	13.11544
82.77218	22.98694	12.98727
82.83718	22.32942	13.12566
82.90218	22.50320	10.06897
82.96718	23.03668	5.891093
83.03384	23.81426	1.703576
83.09882	24.72832	-1.722857
83.16382	25.74836	-4.417188
83.22882	26.84044	-6.459522
83.29550	28.01542	-8.014792
83.36050	29.19785	-9.131531
83.42550	30.40471	-9.960009
83.49050	31.63104	-10.58232
83.55718	32.90278	-11.06880
83.62218	34.15433	-11.43796
83.68718	35.41402	-11.73963
83.75384	36.71120	-11.99098
83.81884	37.98100	-12.20857
83.88384	39.25362	-12.39236
83.94884	40.53022	-12.55013
84.01551	41.84183	-12.72948
84.08051	43.12346	-12.82368
84.14551	44.40962	-12.90532
84.21051	45.69643	-12.98548
84.27718	47.01671	-13.06904
84.34218	48.30746	-13.15386
84.40718	49.59830	-13.23455
84.47218	50.88956	-13.31656
84.53882	52.21493	-13.40117
84.60382	53.50784	-13.48177
84.66884	54.80070	-13.56166
84.73551	56.12762	-13.64838
84.80051	57.42099	-13.73364
84.86551	58.71534	-13.81691
84.93051	60.01118	-13.90245
84.99718	61.33915	-13.99258
85.06218	62.63461	-14.08439
85.12718	63.93092	-14.17331
85.19218	65.22696	-14.25587
85.25884	66.55694	-14.34280
85.32384	67.85253	-14.43032
85.38884	69.14934	-14.51887
85.45382	70.44668	-14.60738
85.52050	71.77664	-14.69678
85.58551	73.07452	-14.78862
85.65051	74.37149	-14.87589
85.71551	75.66876	-14.96113
85.78218	76.99993	-15.05249
85.84718	78.29765	-15.14130
85.91218	79.59468	-15.23160
85.97882	80.92474	-15.32692
86.04384	82.22215	-15.42285
86.10884	83.51922	-15.51595
86.17384	84.81832	-15.61052
86.24051	86.14991	-15.70822
86.30549	87.44819	-15.80091
86.37051	88.74684	-15.89158
86.43550	90.04382	-15.98765
86.50218	91.37511	-16.08576
86.56718	92.67188	-16.18016
86.63218	93.97032	-16.27656
86.69718	95.26889	-16.37201
86.76384	96.60054	-16.46401
86.82884	97.89844	-16.54084
86.89384	99.19829	-16.63031
86.96051	100.5300	-16.71342
87.02550	101.8284	-16.78970
87.09051	103.1266	-16.87259
87.15551	104.4251	-16.96136
87.22218	105.7561	-17.05924
87.28718	107.0535	-17.15446
87.35218	108.3517	-17.25527
87.41718	109.6491	-17.34891
87.48382	110.9807	-17.45908
87.54884	112.2779	-17.55773
87.61384	113.5757	-17.65913
87.67882	114.8724	-17.75969
87.74550	116.2039	-17.86924
87.81050	117.5015	-17.97095
87.87550	118.7996	-18.07670
87.94218	120.1308	-18.18614
88.00718	121.4280	-18.28968
88.07218	122.7256	-18.39986
88.13718	124.0230	-18.50903
88.20382	125.3540	-18.62301
88.26882	126.6517	-18.73576
88.33384	127.9493	-18.83926
88.39884	129.2464	-18.94749
88.46551	130.5768	-19.05948
88.53051	131.8757	-19.18032
88.59551	133.1733	-19.29344
88.66050	134.4702	-19.40910
88.72718	135.7999	-19.53562
88.79218	137.0970	-19.66222
88.85718	138.3927	-19.79118
88.92218	139.6896	-19.92645
88.98882	141.0193	-20.06728
89.05382	142.3156	-20.20401
89.11884	143.6123	-20.34424
89.18550	144.9407	-20.48947
89.25050	146.2368	-20.63277
89.31551	147.5310	-20.78830
89.38050	148.8273	-20.94658
89.44718	150.1542	-21.11488
89.51218	151.4496	-21.29024
89.57718	152.7435	-21.48744
89.64218	154.0352	-21.71084
89.70882	155.3608	-21.92328
89.77384	156.6566	-22.06413
89.83884	157.9536	-22.20612
89.90384	159.2494	-22.35674
89.97051	160.5792	-22.50489
90.03551	161.8753	-22.65556
90.10050	163.1709	-22.79045
90.16718	164.5016	-22.91454
90.23218	165.8008	-23.00608
90.29718	167.0994	-23.08088
90.36218	168.3984	-23.14340
90.42882	169.7322	-23.20063
90.49384	171.0315	-23.26166
90.55884	172.3314	-23.34174
90.62384	173.6302	-23.43440
90.69051	174.9616	-23.53862
90.75551	176.2590	-23.66008
90.82050	177.5549	-23.80702
90.88550	178.8502	-23.97669
90.95216	180.1763	-24.17855
91.01718	181.4682	-24.41166
91.08218	182.7580	-24.68306
91.14884	184.0797	-24.99936
91.21384	185.3669	-25.35659
91.27884	186.6516	-25.74842
91.34384	187.9338	-26.20458
91.41050	189.2466	-26.74985
91.47551	190.5219	-27.35965
91.54051	191.7935	-28.05789
91.60550	193.0608	-28.84684
91.67218	194.3576	-29.71586
91.73718	195.6206	-30.58422
91.80218	196.8813	-31.46524
91.86718	198.1428	-32.36724
91.93384	199.4350	-33.34193
91.99884	200.6898	-34.39294
92.06384	201.9412	-35.56711
92.12882	203.1856	-36.85492
92.19550	204.4602	-38.23520
92.26051	205.7031	-39.50461
92.32550	206.9581	-40.46662
92.39218	208.2736	-40.69153
92.45718	209.6088	-39.66470
92.52218	211.0075	-37.26420
92.58718	212.4538	-34.01348
92.65384	213.9436	-30.81070
92.71884	215.3674	-28.43481
92.78384	216.7570	-26.74324
92.84882	218.1218	-25.56814
92.91550	219.5017	-24.73153
92.98050	220.8333	-24.17331
93.04550	222.1546	-23.79820
93.11051	223.4698	-23.55416
93.17718	224.8160	-23.40264
93.24218	226.1235	-23.31155
93.30718	227.4296	-23.27006
93.37384	228.7674	-23.24782
93.43884	230.0700	-23.24360
93.50384	231.3730	-23.25048
93.56884	232.6753	-23.28681
93.63550	234.0107	-23.34199
93.70050	235.3119	-23.39146
93.76551	236.6122	-23.44590
93.83051	237.9127	-23.49778
93.89718	239.2468	-23.55737
93.96218	240.5487	-23.61802
94.02718	241.8486	-23.68246
94.09218	243.1502	-23.74982
94.15884	244.4839	-23.81990
94.22384	245.7844	-23.88361
94.28882	247.0854	-23.93802
94.35550	248.4196	-23.98951
94.42050	249.7205	-24.03827
94.48551	251.0209	-24.09618
94.55051	252.3204	-24.15600
94.61718	253.6548	-24.21840
94.68218	254.9541	-24.27414
94.74718	256.2536	-24.34115
94.81218	257.5552	-24.41460
94.87882	258.8890	-24.48352
94.94384	260.1894	-24.55123
95.00884	261.4895	-24.61438
95.07384	262.7890	-24.68430
95.14051	264.1228	-24.75740
95.20551	265.4229	-24.82806
95.27050	266.7220	-24.93875
95.33551	268.0222	-24.99816
95.40218	269.3555	-25.04761
95.46718	270.6556	-25.12944
95.53218	271.9558	-25.17794
-2.000000	5.000000	0.0000000