File: 3-C1(1.0mol%)+C20(0.6mol%)/matlab/160-2
CLOSED
Version	1.0
Language	English
Mode	Standard
Run	8
RunSerial	11789
Instrument	DSC Q2000 V24.11 Build 124
Module	DSC Standard Cell RC
Operator	Nan
File	\\Ae520-1454\ta\Data\DSC\UQ Composites\Nan\C1(4.5)+C20P(3)+CL(HotplateMixtureAB)\Iso160_60Min_2
ProcName	H/C/H/C/H complete wood PHA
InstSerial	2000-0883
AutoSerial	1293
Sample	Iso160_60Min
Size	45.0000	mg
PanMass	Not available
PanResist	Automatic Automatic  K/W
PanFactor	Default Default
Method	H/C/H/C/H complete wood PHA
Comment
Xcomment	Pan: Tzero Aluminum Hermetic
Xcomment	Gas1: Nitrogen 50.0 ml/min
Xcomment	Gas2: Nitrogen 50.0 ml/min
Text
Exotherm	UP
Kcell	1.05230
Cpconst	Standard: 0.938
Calib	-38.6961
TempCal	1	pts	157.46	156.60
TzeroDt	-87.6168 -0.0009 -1.4231
TzeroDtz	-87.6168 0.0057 6.9570
InstCalFile	Tzero: \\Ae520-1454\ta\Data\DSC\Calibration\2017\CALIBRATION\1562_RCS (90)_05_18_2017 10_50_44.TZR
InstCalFile	Baseline: \\Ae520-1454\ta\Data\DSC\Calibration\2017\2017-05-17_Calibration.001
InstCalFile	Sapphire: \\Ae520-1454\ta\Data\DSC\Calibration\2017\2017-05-17_Saphire.001
InstCalDate	Tzero 2017-05-18 Time 10:50:44
TempRange	-87.39 to 398.39 °C at 10.00 °C/min Heat Only
AutoZero	Delta T Offset 0.000 uV
AutoZero	Delta T0 Offset 0.000 uV
MultiptCal	0
MultiPtDesc	0) Not set
AutoCellConst	Calibration Date 2017-05-18 16:59:28
Controls	Gas 1  Event Off  Sampling 0.2
Cell#	RC-01562
CoolingUnit	RCS (90)
SelHeatFlow	Heat Flow T4 (mW)
AutoLidII	Installed
AutoAnalysis	Off
MacroFile
Nsig	3
Sig1	Time (min)
Sig2	Temperature (°C)
Sig3	Heat Flow (mW)
Date	2017-06-07
Time	23:14:04
OrgMethod	1: Equilibrate at 20.00 °C
OrgMethod	2: Ramp 60.00 °C/min to 160.00 °C
OrgMethod	3: Mark end of cycle 1
OrgMethod	4: Isothermal for 60.00 min
OrgMethod	5: Mark end of cycle 2
OrgMethod	6: Ramp 20.00 °C/min to 280.00 °C
OrgMethod	7: Mark end of cycle 3
OrgMethod	8: Ramp 20.00 °C/min to 20.00 °C
OrgMethod	9: Mark end of cycle 4
OrgMethod	10: Ramp 20.00 °C/min to 280.00 °C
OrgMethod	11: Mark end of cycle 5
OrgFile	C:\Users\jarra\Desktop\DSC\3-C1(1.0mol%)+C20(0.6mol%)\160-2
StartOfData
4.99994E-4	20.08332	0.5580918
0.06550000	20.42459	0.9711887
0.1305000	22.32032	-2.015570
0.1955000	24.81355	-9.665032
0.2588334	27.58525	-18.09541
0.3238334	30.65514	-26.29125
0.3888333	33.90016	-33.43716
0.4521667	37.18712	-39.28667
0.5171667	40.65614	-44.30215
0.5821668	44.19382	-48.63306
0.6455000	47.66821	-52.90047
0.7105000	51.24806	-57.13186
0.7755000	54.85637	-61.21987
0.8388332	58.38046	-65.14264
0.9038334	62.02855	-68.86128
0.9688332	65.65588	-73.51436
1.032167	69.09475	-80.53650
1.097166	72.33326	-94.67407
1.162166	75.04145	-118.9189
1.225500	77.44126	-144.2944
1.290500	79.96610	-169.1049
1.355500	82.75926	-186.8562
1.420500	85.46514	-210.2490
1.483833	88.55128	-221.6846
1.548833	92.15290	-224.1940
1.613833	96.31782	-218.5910
1.677167	100.5193	-212.0258
1.742167	104.8912	-203.0759
1.807167	109.6198	-186.3996
1.870500	114.3301	-170.7593
1.935500	119.0157	-157.5262
2.000500	123.5500	-147.1320
2.063833	127.8371	-139.2883
2.128833	132.1166	-133.4130
2.193833	136.2949	-129.3676
2.257167	140.3041	-126.4036
2.322166	144.3727	-124.2742
2.383833	148.0742	-123.2179
2.448834	150.5084	-119.0534
2.513833	152.1396	-106.8787
2.577166	153.3523	-93.25888
2.642166	154.3447	-80.09201
2.707167	155.1420	-68.78906
2.770500	155.7716	-59.70629
2.835500	156.2986	-52.13404
2.900500	156.7292	-46.02739
2.963833	157.0763	-41.21708
3.028833	157.3716	-37.23264
3.093834	157.6160	-34.01663
3.157167	157.8144	-31.49010
3.222166	157.9836	-29.40939
3.287167	158.1268	-27.70246
3.350500	158.2441	-26.31924
3.415500	158.3467	-25.13269
3.480500	158.4350	-24.12266
3.545500	158.5117	-23.24694
3.608833	158.5779	-22.47913
3.673834	158.6398	-21.75603
3.738834	158.6943	-21.09127
3.802166	158.7435	-20.49481
3.867166	158.7894	-19.91515
3.932167	158.8318	-19.35888
3.995500	158.8708	-18.83044
4.060500	158.9092	-18.28494
4.125500	158.9470	-17.71078
4.188834	158.9849	-17.08870
4.253834	159.0272	-16.35616
4.318833	159.0736	-15.52744
4.382167	159.1226	-14.64754
4.447166	159.1736	-13.67318
4.512167	159.2277	-12.66863
4.575500	159.2770	-11.76285
4.640500	159.3231	-10.91566
4.705500	159.3652	-10.12848
4.770500	159.4055	-9.378639
4.833834	159.4430	-8.650819
4.898834	159.4832	-7.890903
4.963834	159.5237	-7.079631
5.027167	159.5681	-6.205899
5.092167	159.6155	-5.247436
5.157166	159.6650	-4.285513
5.220500	159.7096	-3.428816
5.285500	159.7498	-2.677089
5.350500	159.7837	-2.057949
5.413832	159.8104	-1.559577
5.478832	159.8332	-1.130708
5.543832	159.8535	-0.7681981
5.607168	159.8693	-0.4656008
5.672168	159.8848	-0.2002618
5.737168	159.8969	0.02855496
5.800500	159.9072	0.2233030
5.865500	159.9175	0.4001794
5.930500	159.9259	0.5616835
5.993834	159.9337	0.6985785
6.058832	159.9415	0.8330568
6.123832	159.9479	0.9563097
6.188832	159.9544	1.067988
6.252168	159.9601	1.174365
6.317168	159.9657	1.279060
6.382168	159.9714	1.379463
6.445500	159.9765	1.475078
6.510500	159.9814	1.571041
6.575500	159.9866	1.663369
6.638832	159.9915	1.756500
6.703832	159.9960	1.848439
6.768832	160.0006	1.943750
6.832168	160.0062	2.030612
6.897168	160.0105	2.125534
6.962168	160.0154	2.219706
7.025500	160.0208	2.318066
7.090500	160.0254	2.412403
7.155500	160.0310	2.511852
7.218832	160.0362	2.609314
7.283832	160.0414	2.712544
7.348832	160.0459	2.811560
7.413832	160.0512	2.915333
7.477168	160.0570	3.024051
7.542168	160.0626	3.131405
7.607168	160.0676	3.244919
7.670500	160.0750	3.351188
7.735500	160.0788	3.467758
7.800500	160.0856	3.582219
7.863834	160.0913	3.701160
7.928834	160.0969	3.820710
7.993834	160.1034	3.942213
8.057168	160.1097	4.065857
8.122168	160.1164	4.193824
8.187166	160.1227	4.321352
8.250500	160.1299	4.453986
8.315500	160.1356	4.582154
8.380500	160.1431	4.718260
8.443832	160.1488	4.853676
8.508832	160.1568	4.994300
8.573834	160.1636	5.140674
8.637168	160.1697	5.280915
8.702168	160.1776	5.426880
8.767168	160.1848	5.575166
8.832168	160.1927	5.727818
8.895500	160.2006	5.877192
8.960499	160.2079	6.031138
9.025499	160.2158	6.186660
9.088832	160.2233	6.341326
9.153832	160.2312	6.500843
9.218834	160.2399	6.662359
9.282168	160.2470	6.818044
9.347168	160.2552	6.981093
9.412168	160.2643	7.148374
9.475500	160.2717	7.310626
9.540500	160.2793	7.473724
9.605499	160.2878	7.637970
9.668832	160.2960	7.800256
9.733832	160.3042	7.965480
9.798834	160.3130	8.128196
9.862168	160.3212	8.289076
9.927168	160.3299	8.448359
9.992166	160.3384	8.610303
10.05717	160.3464	8.775379
10.12050	160.3544	8.930734
10.18550	160.3624	9.100496
10.25050	160.3710	9.276468
10.31383	160.3784	9.462518
10.37883	160.3883	9.670514
10.44383	160.4001	9.897434
10.50717	160.4112	10.14990
10.57217	160.4250	10.43922
10.63717	160.4401	10.76415
10.70050	160.4570	11.12697
10.76550	160.4778	11.54668
10.83050	160.5003	12.02771
10.89383	160.5255	12.55950
10.95883	160.5554	13.17458
11.02383	160.5884	13.86269
11.08717	160.6238	14.59754
11.15217	160.6634	15.41107
11.21717	160.7049	16.26427
11.28050	160.7471	17.11881
11.34550	160.7908	18.00714
11.41050	160.8338	18.88212
11.47550	160.8769	19.73670
11.53883	160.9171	20.52720
11.60383	160.9553	21.28356
11.66883	160.9906	21.97456
11.73217	161.0211	22.58513
11.79717	161.0494	23.12763
11.86217	161.0734	23.59592
11.92550	161.0939	23.97660
11.99050	161.1103	24.29553
12.05550	161.1228	24.54846
12.11884	161.1327	24.72976
12.18383	161.1400	24.86048
12.24883	161.1441	24.93052
12.31216	161.1461	24.95659
12.37717	161.1457	24.95640
12.44217	161.1434	24.90610
12.50550	161.1392	24.80111
12.57050	161.1331	24.67198
12.63550	161.1270	24.52040
12.70050	161.1180	24.34089
12.76383	161.1101	24.14547
12.82883	161.1010	23.96635
12.89383	161.0911	23.74950
12.95717	161.0800	23.52946
13.02217	161.0694	23.30208
13.08717	161.0574	23.07782
13.15050	161.0460	22.85902
13.21550	161.0350	22.63035
13.28050	161.0239	22.40214
13.34383	161.0134	22.17224
13.40883	161.0018	21.94396
13.47383	160.9909	21.71353
13.53717	160.9801	21.49924
13.60217	160.9688	21.27663
13.66716	160.9566	21.05058
13.73050	160.9466	20.83803
13.79550	160.9352	20.62046
13.86050	160.9255	20.40612
13.92383	160.9151	20.21088
13.98883	160.9064	20.01454
14.05383	160.8972	19.83372
14.11884	160.8886	19.65834
14.18217	160.8802	19.49362
14.24717	160.8713	19.31671
14.31216	160.8630	19.12693
14.37550	160.8534	18.92136
14.44050	160.8414	18.66875
14.50550	160.8278	18.37070
14.56884	160.8116	18.01913
14.63383	160.7914	17.60238
14.69884	160.7689	17.12537
14.76217	160.7429	16.59267
14.82717	160.7128	15.98240
14.89216	160.6820	15.33029
14.95550	160.6501	14.66094
15.02050	160.6148	13.95722
15.08550	160.5796	13.24390
15.14883	160.5457	12.55319
15.21383	160.5117	11.85310
15.27883	160.4777	11.16964
15.34383	160.4451	10.50328
15.40717	160.4149	9.885791
15.47217	160.3836	9.269119
15.53717	160.3542	8.673866
15.60050	160.3273	8.120193
15.66550	160.3003	7.576020
15.73050	160.2744	7.053174
15.79384	160.2499	6.574974
15.85883	160.2265	6.113718
15.92383	160.2042	5.679033
15.98716	160.1838	5.277118
16.05217	160.1646	4.892053
16.11716	160.1452	4.529915
16.18050	160.1286	4.190170
16.24550	160.1124	3.864980
16.31050	160.0969	3.556422
16.37383	160.0823	3.278445
16.43883	160.0690	3.002477
16.50383	160.0564	2.748756
16.56716	160.0455	2.506514
16.63216	160.0333	2.273994
16.69716	160.0235	2.054420
16.76216	160.0124	1.850648
16.82550	160.0028	1.662735
16.89050	159.9935	1.486688
16.95550	159.9845	1.319434
17.01883	159.9766	1.167856
17.08383	159.9691	1.016823
17.14883	159.9622	0.8742437
17.21216	159.9554	0.7469251
17.27716	159.9492	0.6265979
17.34216	159.9438	0.5080554
17.40550	159.9388	0.4087378
17.47050	159.9332	0.3084900
17.53550	159.9286	0.2159198
17.59883	159.9244	0.1346986
17.66383	159.9202	0.05324479
17.72883	159.9164	-.02125276
17.79216	159.9130	-.09314004
17.85716	159.9096	-0.1601947
17.92216	159.9070	-0.2263870
17.98716	159.9045	-0.2843322
18.05050	159.9020	-0.3391998
18.11550	159.8990	-0.3882020
18.18050	159.8967	-0.4351170
18.24383	159.8942	-0.4775543
18.30883	159.8927	-0.5189547
18.37383	159.8904	-0.5572474
18.43716	159.8884	-0.5940694
18.50216	159.8873	-0.6303521
18.56716	159.8846	-0.6590926
18.63050	159.8839	-0.6883566
18.69550	159.8820	-0.7153020
18.76050	159.8796	-0.7428249
18.82383	159.8786	-0.7655871
18.88883	159.8771	-0.7905343
18.95383	159.8767	-0.8140447
19.01716	159.8743	-0.8367298
19.08216	159.8738	-0.8558570
19.14716	159.8723	-0.8756114
19.21050	159.8714	-0.8960747
19.27550	159.8704	-0.9112944
19.34050	159.8704	-0.9266391
19.40550	159.8688	-0.9412064
19.46883	159.8686	-0.9572481
19.53383	159.8680	-0.9738911
19.59883	159.8671	-0.9871681
19.66217	159.8661	-1.000674
19.72716	159.8659	-1.013891
19.79216	159.8652	-1.026480
19.85550	159.8642	-1.039686
19.92050	159.8649	-1.052646
19.98550	159.8638	-1.065273
20.04883	159.8631	-1.077232
20.11383	159.8628	-1.089672
20.17883	159.8623	-1.101755
20.24216	159.8623	-1.112765
20.30716	159.8618	-1.123689
20.37216	159.8616	-1.134528
20.43550	159.8611	-1.144442
20.50050	159.8602	-1.154182
20.56550	159.8596	-1.163286
20.63050	159.8590	-1.172067
20.69383	159.8584	-1.180155
20.75883	159.8579	-1.188230
20.82383	159.8572	-1.195997
20.88716	159.8567	-1.202962
20.95216	159.8561	-1.209728
21.01716	159.8560	-1.216438
21.08050	159.8560	-1.223064
21.14550	159.8550	-1.229838
21.21050	159.8549	-1.236276
21.27383	159.8547	-1.242788
21.33883	159.8544	-1.249492
21.40383	159.8537	-1.255957
21.46716	159.8544	-1.262320
21.53216	159.8536	-1.268883
21.59716	159.8535	-1.275390
21.66050	159.8542	-1.281673
21.72550	159.8536	-1.287656
21.79050	159.8542	-1.293272
21.85383	159.8535	-1.298321
21.91883	159.8538	-1.303555
21.98383	159.8539	-1.308153
22.04883	159.8533	-1.312397
22.11216	159.8538	-1.316342
22.17717	159.8532	-1.320206
22.24216	159.8534	-1.323976
22.30550	159.8529	-1.327110
22.37050	159.8535	-1.328622
22.43550	159.8524	-1.331244
22.49883	159.8532	-1.334581
22.56383	159.8524	-1.337902
22.62883	159.8521	-1.340764
22.69216	159.8515	-1.343382
22.75716	159.8511	-1.346203
22.82216	159.8512	-1.348844
22.88550	159.8502	-1.351410
22.95050	159.8512	-1.354975
23.01550	159.8507	-1.358612
23.07883	159.8513	-1.362563
23.14383	159.8499	-1.366555
23.20883	159.8511	-1.370478
23.27383	159.8510	-1.374126
23.33716	159.8508	-1.377591
23.40216	159.8514	-1.380802
23.46716	159.8511	-1.384260
23.53050	159.8508	-1.387080
23.59550	159.8504	-1.389200
23.66050	159.8500	-1.390410
23.72383	159.8489	-1.391249
23.78883	159.8491	-1.391884
23.85383	159.8486	-1.392681
23.91716	159.8487	-1.393777
23.98216	159.8484	-1.395322
24.04716	159.8489	-1.397723
24.11050	159.8492	-1.400295
24.17550	159.8488	-1.403350
24.24050	159.8494	-1.406612
24.30383	159.8495	-1.409495
24.36883	159.8493	-1.412217
24.43383	159.8488	-1.414640
24.49716	159.8488	-1.416729
24.56216	159.8491	-1.418902
24.62716	159.8484	-1.421056
24.69216	159.8488	-1.423196
24.75550	159.8494	-1.425128
24.82050	159.8490	-1.426520
24.88550	159.8489	-1.427748
24.94883	159.8476	-1.428545
25.01383	159.8478	-1.429415
25.07883	159.8480	-1.430055
25.14216	159.8474	-1.430290
25.20717	159.8476	-1.430909
25.27216	159.8473	-1.431928
25.33550	159.8482	-1.433315
25.40050	159.8478	-1.435170
25.46550	159.8478	-1.436846
25.52883	159.8474	-1.438722
25.59383	159.8477	-1.440688
25.65883	159.8473	-1.442296
25.72216	159.8472	-1.443767
25.78717	159.8475	-1.444863
25.85217	159.8475	-1.445922
25.91716	159.8470	-1.447461
25.98050	159.8470	-1.449110
26.04550	159.8479	-1.450752
26.11050	159.8473	-1.452345
26.17383	159.8471	-1.453670
26.23883	159.8471	-1.454745
26.30383	159.8483	-1.456141
26.36716	159.8483	-1.457304
26.43216	159.8478	-1.458321
26.49716	159.8478	-1.459419
26.56050	159.8475	-1.460404
26.62550	159.8478	-1.461584
26.69050	159.8475	-1.462669
26.75383	159.8472	-1.463637
26.81883	159.8478	-1.464724
26.88383	159.8476	-1.465614
26.94717	159.8467	-1.465903
27.01216	159.8474	-1.466354
27.07717	159.8464	-1.467112
27.14050	159.8467	-1.467307
27.20550	159.8469	-1.467558
27.27050	159.8456	-1.467640
27.33550	159.8458	-1.467696
27.39883	159.8465	-1.468144
27.46383	159.8456	-1.468622
27.52883	159.8454	-1.469359
27.59216	159.8458	-1.470418
27.65716	159.8458	-1.471559
27.72216	159.8461	-1.472955
27.78550	159.8466	-1.474173
27.85050	159.8466	-1.475444
27.91550	159.8458	-1.476877
27.97883	159.8466	-1.478244
28.04383	159.8465	-1.479484
28.10883	159.8461	-1.480687
28.17216	159.8462	-1.481510
28.23716	159.8456	-1.482262
28.30217	159.8458	-1.482432
28.36550	159.8453	-1.482364
28.43050	159.8460	-1.482514
28.49550	159.8450	-1.482708
28.56050	159.8453	-1.483049
28.62383	159.8447	-1.483478
28.68883	159.8453	-1.483833
28.75383	159.8455	-1.484354
28.81716	159.8449	-1.484716
28.88216	159.8451	-1.485548
28.94717	159.8447	-1.486189
29.01050	159.8457	-1.487058
29.07550	159.8446	-1.487954
29.14050	159.8451	-1.488765
29.20383	159.8451	-1.489181
29.26883	159.8446	-1.489271
29.33383	159.8448	-1.489119
29.39716	159.8445	-1.489384
29.46216	159.8453	-1.490208
29.52717	159.8448	-1.491329
29.59050	159.8453	-1.492673
29.65550	159.8452	-1.494139
29.72050	159.8454	-1.495567
29.78383	159.8461	-1.496949
29.84883	159.8454	-1.498436
29.91383	159.8454	-1.499834
29.97883	159.8465	-1.500996
30.04216	159.8464	-1.502239
30.10716	159.8470	-1.503177
30.17216	159.8465	-1.503427
30.23550	159.8464	-1.503248
30.30050	159.8457	-1.502562
30.36550	159.8456	-1.501470
30.42883	159.8456	-1.500542
30.49383	159.8450	-1.500140
30.55883	159.8456	-1.500104
30.62216	159.8450	-1.500120
30.68717	159.8456	-1.500356
30.75217	159.8458	-1.500839
30.81550	159.8448	-1.501210
30.88050	159.8452	-1.501552
30.94550	159.8448	-1.502048
31.00883	159.8449	-1.502494
31.07383	159.8452	-1.502831
31.13883	159.8449	-1.502982
31.20383	159.8440	-1.503098
31.26716	159.8448	-1.503532
31.33216	159.8444	-1.503992
31.39716	159.8455	-1.504356
31.46050	159.8447	-1.504880
31.52550	159.8449	-1.505721
31.59050	159.8455	-1.506702
31.65383	159.8454	-1.507922
31.71883	159.8448	-1.508934
31.78383	159.8453	-1.509997
31.84716	159.8455	-1.510645
31.91217	159.8457	-1.511044
31.97717	159.8456	-1.511393
32.04050	159.8453	-1.511828
32.10550	159.8452	-1.512176
32.17050	159.8445	-1.512214
32.23383	159.8447	-1.511893
32.29883	159.8448	-1.511394
32.36383	159.8451	-1.510979
32.42717	159.8447	-1.511066
32.49216	159.8452	-1.511100
32.55716	159.8451	-1.511255
32.62216	159.8449	-1.511517
32.68550	159.8449	-1.512228
32.75050	159.8451	-1.513043
32.81550	159.8446	-1.513812
32.87883	159.8450	-1.514366
32.94383	159.8455	-1.515227
33.00883	159.8451	-1.516367
33.07217	159.8452	-1.517246
33.13716	159.8457	-1.518209
33.20216	159.8457	-1.518718
33.26550	159.8453	-1.519069
33.33050	159.8450	-1.518930
33.39550	159.8457	-1.518902
33.45883	159.8453	-1.518831
33.52383	159.8456	-1.518429
33.58883	159.8452	-1.518314
33.65216	159.8439	-1.518011
33.71716	159.8444	-1.517790
33.78216	159.8444	-1.517384
33.84716	159.8442	-1.517279
33.91050	159.8439	-1.517163
33.97550	159.8439	-1.517301
34.04050	159.8448	-1.517749
34.10383	159.8442	-1.518072
34.16883	159.8446	-1.518560
34.23383	159.8440	-1.518974
34.29716	159.8446	-1.519717
34.36217	159.8451	-1.520969
34.42717	159.8455	-1.522223
34.49050	159.8449	-1.523284
34.55550	159.8454	-1.524321
34.62050	159.8449	-1.524671
34.68384	159.8457	-1.524356
34.74883	159.8452	-1.524142
34.81383	159.8453	-1.524028
34.87717	159.8454	-1.523803
34.94216	159.8450	-1.523747
35.00716	159.8448	-1.523827
35.07050	159.8447	-1.523784
35.13550	159.8444	-1.523476
35.20050	159.8446	-1.523072
35.26550	159.8436	-1.522327
35.32883	159.8443	-1.521821
35.39383	159.8444	-1.521706
35.45883	159.8440	-1.521829
35.52217	159.8438	-1.522156
35.58716	159.8439	-1.522696
35.65216	159.8442	-1.523594
35.71550	159.8444	-1.524854
35.78050	159.8447	-1.526032
35.84550	159.8449	-1.527157
35.90883	159.8445	-1.528154
35.97383	159.8444	-1.528863
36.03883	159.8448	-1.529364
36.10217	159.8454	-1.529795
36.16716	159.8454	-1.530244
36.23216	159.8449	-1.530336
36.29550	159.8449	-1.530021
36.36050	159.8455	-1.529968
36.42550	159.8451	-1.529918
36.49050	159.8450	-1.529468
36.55383	159.8445	-1.529029
36.61883	159.8446	-1.528478
36.68384	159.8444	-1.527931
36.74716	159.8442	-1.527361
36.81216	159.8439	-1.527467
36.87717	159.8444	-1.527668
36.94050	159.8444	-1.527660
37.00550	159.8438	-1.527795
37.07050	159.8430	-1.527907
37.13383	159.8439	-1.528062
37.19883	159.8438	-1.528347
37.26383	159.8435	-1.528526
37.32717	159.8434	-1.528821
37.39216	159.8441	-1.529093
37.45716	159.8438	-1.529428
37.52050	159.8444	-1.529826
37.58550	159.8441	-1.530320
37.65050	159.8441	-1.530796
37.71383	159.8444	-1.531124
37.77883	159.8443	-1.531623
37.84384	159.8437	-1.531889
37.90883	159.8441	-1.532247
37.97217	159.8443	-1.532220
38.03717	159.8439	-1.532148
38.10217	159.8445	-1.532449
38.16550	159.8436	-1.532484
38.23050	159.8444	-1.532525
38.29550	159.8442	-1.532750
38.35883	159.8443	-1.532934
38.42383	159.8446	-1.533548
38.48883	159.8440	-1.533964
38.55217	159.8446	-1.534268
38.61716	159.8446	-1.534689
38.68216	159.8448	-1.535172
38.74550	159.8451	-1.535542
38.81050	159.8456	-1.535863
38.87550	159.8452	-1.536302
38.93883	159.8451	-1.536762
39.00383	159.8452	-1.537236
39.06883	159.8446	-1.537611
39.13383	159.8452	-1.537720
39.19717	159.8454	-1.537448
39.26216	159.8448	-1.537016
39.32717	159.8449	-1.536814
39.39050	159.8452	-1.536894
39.45550	159.8452	-1.537037
39.52050	159.8445	-1.536783
39.58383	159.8450	-1.536545
39.64883	159.8447	-1.536678
39.71383	159.8439	-1.536590
39.77716	159.8441	-1.536559
39.84216	159.8440	-1.536087
39.90716	159.8439	-1.535401
39.97050	159.8444	-1.535297
40.03550	159.8441	-1.535590
40.10050	159.8440	-1.535675
40.16383	159.8440	-1.536254
40.22883	159.8442	-1.536472
40.29383	159.8441	-1.536853
40.35716	159.8434	-1.537308
40.42216	159.8439	-1.538000
40.48717	159.8440	-1.538914
40.55217	159.8446	-1.540056
40.61550	159.8443	-1.540756
40.68050	159.8443	-1.541230
40.74550	159.8445	-1.541227
40.80883	159.8446	-1.541091
40.87383	159.8440	-1.540767
40.93883	159.8446	-1.540384
41.00217	159.8440	-1.539979
41.06717	159.8441	-1.539408
41.13217	159.8437	-1.539034
41.19550	159.8435	-1.538612
41.26050	159.8438	-1.538243
41.32550	159.8436	-1.538316
41.38883	159.8433	-1.538883
41.45383	159.8437	-1.539735
41.51883	159.8447	-1.540721
41.58217	159.8445	-1.541189
41.64717	159.8445	-1.541688
41.71216	159.8442	-1.542365
41.77716	159.8440	-1.542792
41.84050	159.8438	-1.542792
41.90550	159.8439	-1.542298
41.97050	159.8441	-1.541705
42.03383	159.8446	-1.540827
42.09883	159.8434	-1.540229
42.16383	159.8431	-1.540130
42.22717	159.8434	-1.540252
42.29217	159.8430	-1.540189
42.35717	159.8435	-1.540024
42.42050	159.8431	-1.539783
42.48550	159.8433	-1.540372
42.55050	159.8432	-1.540774
42.61383	159.8435	-1.541449
42.67883	159.8448	-1.542409
42.74383	159.8438	-1.543364
42.80717	159.8447	-1.544071
42.87216	159.8436	-1.544438
42.93716	159.8441	-1.544742
43.00050	159.8441	-1.544934
43.06550	159.8438	-1.545022
43.13050	159.8442	-1.545180
43.19550	159.8443	-1.544973
43.25883	159.8442	-1.544876
43.32383	159.8442	-1.544841
43.38883	159.8445	-1.544756
43.45216	159.8444	-1.544278
43.51717	159.8441	-1.543862
43.58217	159.8441	-1.543451
43.64550	159.8441	-1.543355
43.71050	159.8439	-1.543401
43.77550	159.8441	-1.543399
43.83883	159.8445	-1.543621
43.90383	159.8442	-1.543798
43.96884	159.8439	-1.543824
44.03217	159.8443	-1.543703
44.09716	159.8436	-1.544082
44.16217	159.8443	-1.544421
44.22550	159.8438	-1.544540
44.29050	159.8441	-1.544500
44.35550	159.8444	-1.544373
44.42050	159.8445	-1.544356
44.48383	159.8442	-1.544344
44.54883	159.8442	-1.544334
44.61383	159.8445	-1.544398
44.67717	159.8444	-1.544398
44.74216	159.8446	-1.544468
44.80717	159.8450	-1.544876
44.87050	159.8439	-1.545237
44.93550	159.8444	-1.545553
45.00050	159.8438	-1.545749
45.06383	159.8444	-1.546050
45.12883	159.8440	-1.546499
45.19383	159.8444	-1.546676
45.25717	159.8445	-1.546685
45.32217	159.8449	-1.546809
45.38716	159.8446	-1.546814
45.45050	159.8440	-1.546659
45.51550	159.8445	-1.546500
45.58050	159.8440	-1.546405
45.64383	159.8446	-1.546149
45.70883	159.8446	-1.545909
45.77383	159.8438	-1.545769
45.83883	159.8436	-1.545466
45.90216	159.8436	-1.545331
45.96717	159.8431	-1.545394
46.03217	159.8436	-1.545478
46.09550	159.8441	-1.545766
46.16050	159.8439	-1.545773
46.22550	159.8438	-1.545791
46.28883	159.8436	-1.546094
46.35383	159.8442	-1.546434
46.41883	159.8447	-1.547114
46.48217	159.8446	-1.547926
46.54716	159.8439	-1.548586
46.61217	159.8446	-1.549459
46.67550	159.8447	-1.550153
46.74050	159.8446	-1.550604
46.80550	159.8443	-1.550779
46.86883	159.8448	-1.550960
46.93383	159.8444	-1.550592
46.99883	159.8449	-1.549888
47.06383	159.8441	-1.549233
47.12717	159.8445	-1.548883
47.19217	159.8445	-1.548926
47.25717	159.8444	-1.548711
47.32050	159.8444	-1.548373
47.38550	159.8437	-1.547899
47.45050	159.8432	-1.547360
47.51383	159.8437	-1.547152
47.57883	159.8435	-1.546858
47.64383	159.8446	-1.546914
47.70717	159.8435	-1.546785
47.77217	159.8429	-1.546572
47.83716	159.8428	-1.546506
47.90050	159.8426	-1.546387
47.96550	159.8430	-1.546095
48.03050	159.8428	-1.545647
48.09384	159.8426	-1.545306
48.15883	159.8426	-1.545149
48.22383	159.8422	-1.545227
48.28717	159.8419	-1.545303
48.35217	159.8424	-1.545446
48.41716	159.8421	-1.545878
48.48217	159.8425	-1.546238
48.54550	159.8428	-1.546889
48.61050	159.8423	-1.547551
48.67550	159.8425	-1.548378
48.73883	159.8429	-1.549078
48.80383	159.8424	-1.549836
48.86883	159.8426	-1.550101
48.93217	159.8427	-1.550441
48.99716	159.8434	-1.550771
49.06216	159.8430	-1.550977
49.12550	159.8429	-1.551161
49.19050	159.8425	-1.551497
49.25550	159.8427	-1.551680
49.31883	159.8431	-1.551781
49.38383	159.8431	-1.551648
49.44883	159.8434	-1.551760
49.51216	159.8434	-1.551727
49.57717	159.8433	-1.551955
49.64217	159.8436	-1.552380
49.70717	159.8438	-1.553150
49.77050	159.8441	-1.554049
49.83550	159.8455	-1.555040
49.90050	159.8453	-1.555350
49.96383	159.8442	-1.555470
50.02883	159.8450	-1.555317
50.09384	159.8442	-1.555021
50.15717	159.8450	-1.554707
50.22217	159.8449	-1.554408
50.28717	159.8447	-1.553996
50.35050	159.8455	-1.554170
50.41550	159.8449	-1.554201
50.48050	159.8451	-1.554474
50.54383	159.8451	-1.554752
50.60883	159.8458	-1.555065
50.67383	159.8446	-1.554946
50.73717	159.8450	-1.554899
50.80217	159.8457	-1.554610
50.86716	159.8453	-1.554565
50.93050	159.8452	-1.554391
50.99550	159.8449	-1.553896
51.06050	159.8448	-1.553508
51.12550	159.8447	-1.553039
51.18883	159.8450	-1.552550
51.25383	159.8450	-1.551970
51.31884	159.8440	-1.551404
51.38217	159.8444	-1.551062
51.44717	159.8438	-1.550535
51.51216	159.8439	-1.550131
51.57550	159.8436	-1.549492
51.64050	159.8434	-1.548756
51.70550	159.8433	-1.548791
51.76884	159.8436	-1.548958
51.83383	159.8434	-1.549424
51.89883	159.8440	-1.550259
51.96216	159.8436	-1.551079
52.02717	159.8436	-1.551575
52.09217	159.8439	-1.552095
52.15550	159.8439	-1.552664
52.22050	159.8436	-1.553039
52.28550	159.8442	-1.553558
52.35050	159.8439	-1.554018
52.41383	159.8438	-1.554222
52.47883	159.8444	-1.554635
52.54382	159.8442	-1.555054
52.60717	159.8443	-1.555183
52.67217	159.8443	-1.555112
52.73717	159.8444	-1.555455
52.80050	159.8441	-1.555314
52.86550	159.8441	-1.555443
52.93050	159.8436	-1.555271
52.99382	159.8435	-1.554874
53.05883	159.8444	-1.554512
53.12383	159.8443	-1.554131
53.18716	159.8436	-1.553602
53.25217	159.8436	-1.553398
53.31716	159.8440	-1.553091
53.38050	159.8431	-1.552732
53.44550	159.8432	-1.552910
53.51050	159.8436	-1.553720
53.57383	159.8430	-1.554191
53.63882	159.8436	-1.554770
53.70383	159.8426	-1.555140
53.76884	159.8431	-1.555160
53.83217	159.8431	-1.555084
53.89717	159.8432	-1.554874
53.96216	159.8430	-1.554657
54.02550	159.8437	-1.554633
54.09050	159.8442	-1.554808
54.15550	159.8433	-1.555095
54.21884	159.8441	-1.555275
54.28383	159.8440	-1.555859
54.34882	159.8446	-1.556770
54.41216	159.8440	-1.557615
54.47717	159.8445	-1.558237
54.54217	159.8440	-1.558420
54.60550	159.8446	-1.558162
54.67050	159.8444	-1.558144
54.73550	159.8447	-1.558016
54.79883	159.8440	-1.557711
54.86382	159.8438	-1.556816
54.92883	159.8439	-1.556074
54.99382	159.8437	-1.555608
55.05717	159.8438	-1.555048
55.12217	159.8432	-1.554539
55.18716	159.8436	-1.554149
55.25050	159.8435	-1.554024
55.31550	159.8435	-1.553924
55.38050	159.8434	-1.553779
55.44384	159.8435	-1.553868
55.50883	159.8434	-1.554069
55.57383	159.8441	-1.554666
55.63716	159.8439	-1.555212
55.70216	159.8440	-1.555669
55.76716	159.8439	-1.556216
55.83050	159.8438	-1.556584
55.89550	159.8439	-1.557036
55.96050	159.8439	-1.557152
56.02383	159.8437	-1.557211
56.08882	159.8441	-1.557588
56.15383	159.8444	-1.558071
56.21717	159.8443	-1.557928
56.28217	159.8444	-1.557912
56.34716	159.8437	-1.558123
56.41216	159.8448	-1.558286
56.47550	159.8440	-1.558222
56.54050	159.8446	-1.558057
56.60550	159.8439	-1.557896
56.66882	159.8438	-1.557524
56.73383	159.8438	-1.557366
56.79883	159.8438	-1.557112
56.86217	159.8440	-1.556951
56.92717	159.8432	-1.556753
56.99216	159.8441	-1.556601
57.05550	159.8439	-1.556686
57.12050	159.8440	-1.557076
57.18550	159.8443	-1.557404
57.24883	159.8441	-1.557731
57.31382	159.8447	-1.558052
57.37883	159.8440	-1.558161
57.44216	159.8436	-1.558070
57.50717	159.8435	-1.557605
57.57217	159.8435	-1.557039
57.63716	159.8438	-1.556766
57.70050	159.8441	-1.556449
57.76550	159.8434	-1.556205
57.83050	159.8439	-1.555794
57.89384	159.8433	-1.555787
57.95883	159.8432	-1.555937
58.02383	159.8434	-1.556212
58.08716	159.8439	-1.556218
58.15217	159.8439	-1.556188
58.21717	159.8437	-1.556280
58.28050	159.8439	-1.556597
58.34550	159.8439	-1.556827
58.41050	159.8438	-1.557422
58.47382	159.8445	-1.558273
58.53882	159.8443	-1.559287
58.60383	159.8449	-1.560232
58.66716	159.8446	-1.560591
58.73217	159.8443	-1.560790
58.79717	159.8445	-1.560801
58.86050	159.8444	-1.560594
58.92550	159.8443	-1.559956
58.99050	159.8441	-1.559202
59.05550	159.8436	-1.557975
59.11882	159.8440	-1.557052
59.18383	159.8436	-1.556405
59.24883	159.8433	-1.555780
59.31216	159.8432	-1.555490
59.37717	159.8430	-1.555290
59.44216	159.8428	-1.555164
59.50550	159.8434	-1.555123
59.57050	159.8431	-1.555444
59.63550	159.8439	-1.555922
59.69883	159.8431	-1.556470
59.76382	159.8438	-1.556958
59.82883	159.8436	-1.557322
59.89216	159.8438	-1.557872
59.95717	159.8446	-1.558303
60.02217	159.8433	-1.558856
60.08550	159.8431	-1.559205
60.15050	159.8445	-1.560303
60.21550	159.8442	-1.561294
60.28050	159.8450	-1.561938
60.34384	159.8445	-1.562099
60.40883	159.8449	-1.562140
60.47382	159.8439	-1.561960
60.53716	159.8449	-1.561553
60.60217	159.8447	-1.561049
60.66716	159.8444	-1.560424
60.73050	159.8440	-1.559758
60.79550	159.8439	-1.558938
60.86050	159.8423	-1.558194
60.92383	159.8438	-1.557717
60.98882	159.8440	-1.557341
61.05383	159.8438	-1.557169
61.11716	159.8436	-1.557276
61.18217	159.8440	-1.557400
61.24717	159.8435	-1.557924
61.31050	159.8436	-1.558293
61.37550	159.8440	-1.558751
61.44050	159.8436	-1.559200
61.50383	159.8442	-1.559483
61.56884	159.8436	-1.559499
61.63383	159.8438	-1.559537
61.69883	159.8436	-1.559074
61.76216	159.8439	-1.558624
61.82717	159.8431	-1.558423
61.89216	159.8433	-1.558078
61.95550	159.8441	-1.558097
62.02050	159.8435	-1.558310
62.08550	159.8440	-1.558708
62.14883	159.8441	-1.559051
62.21382	159.8436	-1.559343
62.27883	159.8437	-1.559818
62.33882	159.8439	-1.560059
62.40383	159.9942	-1.565854
62.46884	160.6272	-4.075906
62.53383	161.4401	-8.364868
62.59716	162.3412	-12.78180
62.66216	163.3447	-16.87064
62.72717	164.4082	-20.31268
62.79050	165.4892	-23.05785
62.85550	166.6356	-25.34572
62.92050	167.8099	-27.19412
62.98383	168.9766	-28.65588
63.04883	170.1916	-29.89469
63.11382	171.4200	-30.93169
63.17717	172.6284	-31.78904
63.24216	173.8781	-32.54654
63.30717	175.1332	-33.20308
63.37050	176.3630	-33.77094
63.43550	177.6274	-34.31042
63.50050	178.8959	-34.80223
63.56382	180.1354	-35.27597
63.62883	181.4084	-35.75189
63.69384	182.6825	-36.22543
63.75717	183.9258	-36.68542
63.82217	185.2017	-37.17136
63.88716	186.4780	-37.66113
63.95216	187.7532	-38.17597
64.01550	188.9955	-38.71050
64.08050	190.2691	-39.28412
64.14550	191.5429	-39.89003
64.20883	192.7818	-40.50824
64.27383	194.0525	-41.16714
64.33884	195.3225	-41.84794
64.40218	196.5586	-42.55190
64.46717	197.8267	-43.32268
64.53217	199.0912	-44.11978
64.59550	200.3228	-44.94721
64.66050	201.5856	-45.84218
64.72551	202.8456	-46.78028
64.78882	204.0728	-47.69378
64.85383	205.3308	-48.72709
64.91884	206.5796	-49.96777
64.98217	207.7866	-51.38304
65.04718	209.0174	-53.05614
65.11217	210.2278	-55.22566
65.17718	211.4088	-58.06965
65.24050	212.5264	-61.61101
65.30550	213.6344	-66.10528
65.37050	214.7102	-71.24168
65.43384	215.7298	-76.86939
65.49884	216.7537	-83.08352
65.56384	217.7681	-89.43616
65.62718	218.7724	-95.02938
65.69218	219.8905	-98.25782
65.75718	221.1952	-97.14011
65.82050	222.6022	-93.67808
65.88550	224.1250	-88.63218
65.95050	225.6870	-82.70030
66.01384	227.2601	-75.89456
66.07884	228.9016	-68.47668
66.14384	230.5148	-62.06328
66.20718	232.0302	-57.08276
66.27218	233.5294	-53.14206
66.33716	234.9835	-50.12519
66.40050	236.3647	-47.88256
66.46550	237.7549	-46.12585
66.53050	239.1238	-44.79662
66.59550	240.4769	-43.79038
66.65884	241.7844	-43.05908
66.72384	243.1158	-42.50086
66.78882	244.4414	-42.08870
66.85218	245.7276	-41.78276
66.91718	247.0442	-41.54817
66.98218	248.3564	-41.36389
67.04550	249.6332	-41.23962
67.11050	250.9412	-41.15298
67.17550	252.2485	-41.09948
67.23882	253.5207	-41.06510
67.30384	254.8252	-41.04319
67.36884	256.1302	-41.03515
67.43218	257.3999	-41.03504
67.49718	258.7021	-41.04273
67.56216	260.0050	-41.08462
67.62550	261.2734	-41.13711
67.69050	262.5758	-41.21384
67.75550	263.8764	-41.26670
67.82050	265.1778	-41.32613
67.88384	266.4461	-41.38709
67.94884	267.7476	-41.43985
68.01384	269.0487	-41.49902
68.07718	270.3168	-41.55544
68.14216	271.6172	-41.59631
68.20718	272.9178	-41.65727
68.27050	274.1863	-41.69480
-2.000000	3.000000	0.0000000
68.39384	276.4670	-41.76053
68.45884	276.5617	-36.73274
68.52384	276.2214	-27.19760
68.58716	275.6560	-17.35058
68.65218	274.9196	-8.331681
68.71718	274.0649	-0.8436851
68.78050	273.1450	5.050613
68.84550	272.1310	9.881558
68.91050	271.0618	13.72398
68.97384	269.9790	16.71360
69.03882	268.8341	19.16974
69.10384	267.6611	21.15802
69.16718	266.4988	22.73472
69.23218	265.2850	24.01789
69.29718	264.0591	25.13108
69.36050	262.8563	26.07520
69.42550	261.6118	26.88542
69.49050	260.3605	27.56810
69.55384	259.1337	28.12758
69.61884	257.8692	28.61132
69.68384	256.6004	29.02486
69.74884	255.3276	29.37830
69.81216	254.0841	29.67232
69.87718	252.8057	29.93798
69.94218	251.5250	30.16496
70.00550	250.2750	30.35972
70.07050	248.9911	30.53703
70.13550	247.7054	30.69145
70.19884	246.4521	30.82223
70.26384	245.1652	30.93132
70.32884	243.8768	31.03265
70.39216	242.6206	31.11568
70.45718	241.3306	31.18229
70.52218	240.0394	31.25213
70.58550	238.7816	31.31370
70.65050	237.4908	31.36662
70.71550	236.1983	31.42157
70.77884	234.9390	31.45388
70.84384	233.6469	31.48196
70.90884	232.3539	31.50332
70.97384	231.0602	31.51856
71.03718	229.8004	31.53760
71.10218	228.5065	31.55195
71.16718	227.2136	31.58399
71.23050	225.9518	31.60626
71.29550	224.6586	31.63394
71.36050	223.3653	31.65317
71.42384	222.1032	31.66556
71.48882	220.8089	31.67826
71.55384	219.5141	31.68839
71.61718	218.2534	31.70039
71.68218	216.9586	31.70984
71.74718	215.6639	31.71812
71.81050	214.4034	31.72497
71.87550	213.1086	31.73141
71.94050	211.8130	31.73762
72.00384	210.5518	31.74320
72.06884	209.2559	31.74826
72.13384	207.9604	31.75178
72.19718	206.6982	31.75434
72.26218	205.4025	31.75555
72.32718	204.1064	31.75521
72.39216	202.8114	31.75371
72.45550	201.5489	31.75035
72.52050	200.2535	31.74536
72.58550	198.9582	31.73979
72.64884	197.6951	31.73416
72.71384	196.3995	31.72745
72.77884	195.1041	31.72008
72.84216	193.8424	31.71411
72.90718	192.5466	31.70820
72.97218	191.2502	31.70170
73.03550	189.9885	31.69468
73.10050	188.6924	31.68528
73.16550	187.3972	31.67682
73.22884	186.1345	31.66897
73.29384	184.8384	31.66160
73.35884	183.5430	31.65169
73.42218	182.2792	31.64206
73.48718	180.9838	31.63128
73.55218	179.6879	31.62154
73.61718	178.3920	31.61399
73.68050	177.1286	31.60855
73.74550	175.8328	31.60504
73.81050	174.5365	31.60383
73.87384	173.2728	31.60478
73.93884	171.9783	31.60830
74.00384	170.6844	31.64034
74.06718	169.4256	31.76531
74.13218	168.1402	31.99240
74.19718	166.8610	32.39447
74.26050	165.6284	33.08600
74.32550	164.3851	34.31505
74.39050	163.1797	36.41525
74.45384	162.0618	39.73790
74.51882	160.9894	44.69398
74.58384	159.9827	50.85951
74.64718	159.0304	57.11624
74.71218	158.0290	62.75012
74.77718	156.9615	66.88934
74.84050	155.8435	69.22446
74.90550	154.6093	69.89740
74.97050	153.2966	69.06599
75.03550	151.9194	67.02682
75.09882	150.5294	64.20195
75.16382	149.0733	60.80493
75.22884	147.6019	57.24580
75.29218	146.1714	53.88540
75.35718	144.7156	50.74037
75.42218	143.2734	47.91614
75.48550	141.8890	45.55974
75.55050	140.4854	43.50266
75.61550	139.0988	41.76812
75.67884	137.7604	40.33454
75.74384	136.3987	39.06990
75.80884	135.0471	37.99431
75.87218	133.7378	37.10998
75.93718	132.4012	36.33650
76.00218	131.0706	35.66646
76.06550	129.7785	35.10129
76.13050	128.4554	34.59830
76.19550	127.1371	34.15842
76.26050	125.8195	33.76582
76.32384	124.5398	33.41700
76.38884	123.2277	33.09434
76.45384	121.9171	32.79934
76.51716	120.6353	32.42704
76.58218	119.3268	32.17146
76.64718	118.0181	31.92938
76.71050	116.7420	31.63521
76.77550	115.4360	31.46174
76.84050	114.1303	31.28390
76.90384	112.8595	31.12715
76.96884	111.5544	30.96690
77.03384	110.2500	30.80344
77.09718	108.9790	30.65283
77.16218	107.6756	30.48465
77.22718	106.3705	30.30575
77.29050	105.0994	30.13366
77.35550	103.7945	29.96315
77.42050	102.4905	29.82160
77.48384	101.2204	29.68094
77.54884	99.91992	29.59572
77.61384	98.61621	29.44367
77.67884	97.31415	29.31744
77.74218	96.04484	29.19374
77.80718	94.74318	29.06174
77.87218	93.43981	28.94075
77.93550	92.17148	28.81658
78.00050	90.86908	28.69572
78.06550	89.56632	28.56040
78.12884	88.29719	28.43492
78.19384	86.99454	28.31540
78.25884	85.69200	28.18420
78.32218	84.42364	28.06463
78.38718	83.12191	27.94488
78.45216	81.81955	27.82518
78.51550	80.54998	27.70535
78.58050	79.24816	27.57905
78.64550	77.94586	27.44662
78.70884	76.67547	27.32041
78.77384	75.37137	27.16742
78.83884	74.06725	27.01871
78.90384	72.76448	26.86651
78.96718	71.49236	26.72404
79.03218	70.19081	26.64192
79.09718	68.89051	26.54396
79.16050	67.62278	26.45268
79.22551	66.32201	26.34806
79.29050	65.01989	26.25586
79.35384	63.76276	26.32510
79.41884	62.45718	26.14900
79.48384	61.15356	25.99237
79.54718	59.88374	25.85064
79.61218	58.57849	25.70914
79.67718	57.27509	25.56577
79.74050	56.00504	25.43390
79.80550	54.70160	25.29707
79.87050	53.39712	25.16505
79.93384	52.12680	25.02934
79.99884	50.82316	24.89049
80.06384	49.52109	24.75709
80.12718	48.25083	24.63103
80.19218	46.94842	24.49621
80.25718	45.64363	24.37434
80.32218	44.34012	24.24585
80.38550	43.06910	24.11741
80.45050	41.76553	23.98422
80.51550	40.46067	23.84536
80.57884	39.18874	23.70556
80.64384	37.88526	23.55011
80.70884	36.57984	23.39230
80.77218	35.30836	23.23826
80.83716	34.00278	23.08073
80.90218	32.69745	22.91688
80.96550	31.42338	22.75762
81.03050	30.11932	22.59622
81.09550	28.81287	22.43868
81.15884	27.54105	22.26804
81.22384	26.23374	22.10466
81.28882	24.92688	21.92392
81.34882	23.72113	21.74860
81.41382	22.91156	21.95575
81.47884	23.00029	18.49697
81.54218	23.40863	13.12509
81.60718	24.03851	7.205785
81.67218	24.81956	1.837722
81.73718	25.71295	-2.708048
81.80050	26.66721	-6.333965
81.86550	27.71120	-9.331968
81.93050	28.80690	-11.72515
81.99384	29.91272	-13.59406
82.05884	31.07713	-15.13526
82.12384	32.26636	-16.39071
82.18718	33.44476	-17.39256
82.25218	34.66881	-18.24110
82.31718	35.90448	-18.95036
82.38050	37.11770	-19.53596
82.44550	38.37233	-20.05876
82.51050	39.63203	-20.50219
82.57384	40.86552	-20.87656
82.63884	42.13643	-21.22110
82.70382	43.41148	-21.52432
82.76718	44.65615	-21.78594
82.83218	45.93704	-22.03202
82.89718	47.22036	-22.25616
82.96050	48.47220	-22.46970
83.02550	49.75868	-22.66520
83.09050	51.04588	-22.85434
83.15550	52.33502	-23.03514
83.21884	53.59215	-23.20407
83.28384	54.88370	-23.36183
83.34882	56.17580	-23.51780
83.41218	57.43470	-23.66832
83.47718	58.72784	-23.81422
83.54218	60.02180	-23.95700
83.60550	61.28182	-24.10294
83.67050	62.57696	-24.25830
83.73550	63.87105	-24.39969
83.79884	65.13336	-24.52694
83.86384	66.42732	-24.65584
83.92882	67.72256	-24.79822
83.99218	68.98510	-24.93102
84.05718	70.28066	-25.06255
84.12218	71.57668	-25.19739
84.18550	72.83946	-25.32849
84.25050	74.13429	-25.46126
84.31551	75.43007	-25.59705
84.38050	76.72711	-25.72726
84.44384	77.98990	-25.85746
84.50884	79.28511	-25.99027
84.57384	80.58087	-26.13114
84.63718	81.84314	-26.26958
84.70216	83.13892	-26.41106
84.76718	84.43503	-26.54560
84.83051	85.69907	-26.68396
84.89551	86.99524	-26.82263
84.96051	88.29118	-26.96280
85.02384	89.55405	-27.09917
85.08884	90.85038	-27.24597
85.15384	92.14784	-27.38397
85.21718	93.41150	-27.52056
85.28218	94.70790	-27.65717
85.34718	96.00501	-27.79221
85.41050	97.26838	-27.92172
85.47551	98.56500	-28.05014
85.54051	99.86030	-28.18872
85.60382	101.1236	-28.31602
85.66884	102.4196	-28.46029
85.73382	103.7159	-28.60068
85.79884	105.0122	-28.74296
85.86218	106.2740	-28.88257
85.92718	107.5705	-29.03408
85.99218	108.8664	-29.18417
86.05549	110.1298	-29.32560
86.12051	111.4258	-29.47256
86.18550	112.7213	-29.61661
86.24884	113.9838	-29.75854
86.31384	115.2803	-29.90172
86.37882	116.5759	-30.05222
86.44218	117.8391	-30.18682
86.50718	119.1353	-30.33704
86.57218	120.4313	-30.48846
86.63550	121.6941	-30.64067
86.70050	122.9901	-30.79636
86.76551	124.2862	-30.95482
86.82884	125.5480	-31.10537
86.89384	126.8439	-31.26675
86.95882	128.1396	-31.41938
87.02384	129.4351	-31.57677
87.08718	130.6965	-31.72892
87.15218	131.9929	-31.90604
87.21718	133.2880	-32.06869
87.28051	134.5498	-32.23690
87.34551	135.8444	-32.41952
87.41050	137.1394	-32.60201
87.47384	138.4015	-32.78310
87.53882	139.6965	-32.97217
87.60382	140.9908	-33.16364
87.66718	142.2518	-33.34844
87.73218	143.5462	-33.54416
87.79718	144.8397	-33.74116
87.86051	146.0991	-33.92940
87.92551	147.3929	-34.13444
87.99051	148.6868	-34.34218
88.05382	149.9466	-34.54224
88.11884	151.2395	-34.75648
88.18384	152.5308	-34.97628
88.24718	153.7914	-35.20406
88.31218	155.0830	-35.43706
88.37718	156.3756	-35.68082
88.44218	157.6680	-35.91885
88.50551	158.9269	-36.16834
88.57050	160.2175	-36.40844
88.63550	161.5100	-36.66414
88.69884	162.7685	-36.90532
88.76384	164.0608	-37.14300
88.82884	165.3541	-37.37094
88.89218	166.6145	-37.56184
88.95718	167.9092	-37.74350
89.02218	169.2054	-37.88464
89.08551	170.4681	-38.00492
89.15051	171.7659	-38.13032
89.21551	173.0639	-38.26416
89.27884	174.3282	-38.38370
89.34384	175.6245	-38.52380
89.40884	176.9207	-38.69142
89.47218	178.1812	-38.87424
89.53718	179.4746	-39.09992
89.60218	180.7662	-39.35608
89.66718	182.0558	-39.67091
89.73050	183.3107	-40.00629
89.79550	184.5953	-40.41615
89.86051	185.8790	-40.86352
89.92384	187.1255	-41.36091
89.98882	188.4035	-41.94270
90.05382	189.6774	-42.59953
90.11718	190.9138	-43.34660
90.18218	192.1780	-44.21094
90.24718	193.4370	-45.19951
90.31050	194.6594	-46.23880
90.37550	195.9106	-47.39548
90.44051	197.1585	-48.61176
90.50384	198.3733	-49.83663
90.56884	199.6183	-51.13784
90.63384	200.8597	-52.49798
90.69718	202.0656	-53.93342
90.76218	203.2980	-55.50429
90.82718	204.5266	-57.16824
90.89051	205.7218	-58.79600
90.95551	206.9530	-60.34590
91.02050	208.1976	-61.51594
91.08551	209.4731	-61.95140
91.14884	210.7580	-61.36338
91.21384	212.1285	-59.65735
91.27884	213.5456	-57.00350
91.34218	214.9594	-53.78836
91.40718	216.4214	-50.44390
91.47218	217.8641	-47.58290
91.53551	219.2464	-45.32300
91.60050	220.6412	-43.48300
91.66550	222.0168	-42.04960
91.72882	223.3412	-40.96416
91.79384	224.6886	-40.10519
91.85884	226.0250	-39.43310
91.92218	227.3196	-38.94772
91.98718	228.6429	-38.54958
92.05218	229.9608	-38.27282
92.11551	231.2416	-38.07262
92.18051	232.5518	-37.93480
92.24550	233.8615	-37.85002
92.31050	235.1679	-37.79370
92.37384	236.4407	-37.77428
92.43884	237.7464	-37.75930
92.50384	239.0499	-37.75559
92.56718	240.3198	-37.75602
92.63218	241.6228	-37.77622
92.69718	242.9246	-37.84185
92.76051	244.1926	-37.89905
92.82550	245.4937	-37.96032
92.89051	246.7951	-38.02700
92.95382	248.0620	-38.08074
93.01882	249.3631	-38.14202
93.08384	250.6640	-38.20522
93.14718	251.9316	-38.27764
93.21218	253.2313	-38.33884
93.27718	254.5325	-38.40274
93.34051	255.7994	-38.46172
93.40551	257.0996	-38.54204
93.47051	258.4003	-38.60972
93.53384	259.6662	-38.68222
93.59882	260.9679	-38.75183
93.66382	262.2672	-38.80842
93.72882	263.5690	-38.87650
93.79218	264.8368	-38.94939
93.85718	266.1350	-39.11404
93.92218	267.4334	-39.19645
93.98551	268.7028	-39.18572
94.05051	270.0210	-38.81363
94.11551	271.3260	-38.81921
-2.000000	5.000000	0.0000000