File: 3-C1(1.0mol%)+C20(0.6mol%)/matlab/160-1
CLOSED
Version	1.0
Language	English
Mode	Standard
Run	7
RunSerial	11788
Instrument	DSC Q2000 V24.11 Build 124
Module	DSC Standard Cell RC
Operator	Nan
File	\\Ae520-1454\ta\Data\DSC\UQ Composites\Nan\C1(4.5)+C20P(3)+CL(HotplateMixtureAB)\Iso160_60Min_1
ProcName	H/C/H/C/H complete wood PHA
InstSerial	2000-0883
AutoSerial	1293
Sample	Iso160_60Min
Size	47.2000	mg
PanMass	Not available
PanResist	Automatic Automatic  K/W
PanFactor	Default Default
Method	H/C/H/C/H complete wood PHA
Comment
Xcomment	Pan: Tzero Aluminum Hermetic
Xcomment	Gas1: Nitrogen 50.0 ml/min
Xcomment	Gas2: Nitrogen 50.0 ml/min
Text
Exotherm	UP
Kcell	1.05230
Cpconst	Standard: 0.938
Calib	-38.6961
TempCal	1	pts	157.46	156.60
TzeroDt	-87.6168 -0.0009 -1.4231
TzeroDtz	-87.6168 0.0057 6.9570
InstCalFile	Tzero: \\Ae520-1454\ta\Data\DSC\Calibration\2017\CALIBRATION\1562_RCS (90)_05_18_2017 10_50_44.TZR
InstCalFile	Baseline: \\Ae520-1454\ta\Data\DSC\Calibration\2017\2017-05-17_Calibration.001
InstCalFile	Sapphire: \\Ae520-1454\ta\Data\DSC\Calibration\2017\2017-05-17_Saphire.001
InstCalDate	Tzero 2017-05-18 Time 10:50:44
TempRange	-87.39 to 398.39 °C at 10.00 °C/min Heat Only
AutoZero	Delta T Offset 0.000 uV
AutoZero	Delta T0 Offset 0.000 uV
MultiptCal	0
MultiPtDesc	0) Not set
AutoCellConst	Calibration Date 2017-05-18 16:59:28
Controls	Gas 1  Event Off  Sampling 0.2
Cell#	RC-01562
CoolingUnit	RCS (90)
SelHeatFlow	Heat Flow T4 (mW)
AutoLidII	Installed
AutoAnalysis	Off
MacroFile
Nsig	3
Sig1	Time (min)
Sig2	Temperature (°C)
Sig3	Heat Flow (mW)
Date	2017-06-07
Time	21:31:42
OrgMethod	1: Equilibrate at 20.00 °C
OrgMethod	2: Ramp 60.00 °C/min to 160.00 °C
OrgMethod	3: Mark end of cycle 1
OrgMethod	4: Isothermal for 60.00 min
OrgMethod	5: Mark end of cycle 2
OrgMethod	6: Ramp 20.00 °C/min to 280.00 °C
OrgMethod	7: Mark end of cycle 3
OrgMethod	8: Ramp 20.00 °C/min to 20.00 °C
OrgMethod	9: Mark end of cycle 4
OrgMethod	10: Ramp 20.00 °C/min to 280.00 °C
OrgMethod	11: Mark end of cycle 5
OrgFile	C:\Users\jarra\Desktop\DSC\3-C1(1.0mol%)+C20(0.6mol%)\160-1
StartOfData
4.99994E-4	20.06786	0.7739743
0.06550000	20.44528	1.327316
0.1305000	22.39068	-1.559817
0.1955000	24.90007	-9.310149
0.2588334	27.67549	-17.96671
0.3238334	30.73976	-26.46932
0.3888333	33.97452	-33.96842
0.4521667	37.24893	-40.15588
0.5171667	40.70584	-45.53925
0.5821668	44.23443	-50.23676
0.6455000	47.69453	-54.89856
0.7105000	51.26789	-59.36613
0.7755000	54.89129	-63.06504
0.8388332	58.45951	-66.50915
0.9038334	62.12578	-70.17182
0.9688332	65.78501	-74.23745
1.032167	69.27735	-80.29266
1.097166	72.56085	-93.90374
1.162166	75.28653	-117.7922
1.225500	77.66968	-143.9850
1.290500	80.06235	-171.4022
1.355500	82.65258	-194.5488
1.420500	85.42822	-213.7685
1.483833	88.58368	-223.5001
1.548833	92.35218	-225.5811
1.613833	96.10754	-229.4250
1.677167	99.85126	-230.6707
1.742167	103.9937	-223.8260
1.807167	109.0509	-199.8164
1.870500	113.9542	-181.6262
1.935500	118.7351	-167.0278
2.000500	123.3270	-155.8305
2.063833	127.6590	-147.2088
2.128833	131.9935	-140.3004
2.193833	136.2361	-135.0394
2.257167	140.2990	-131.2638
2.322166	144.4026	-128.6075
2.383833	148.1155	-127.2488
2.448834	150.4888	-123.5331
2.513833	152.0927	-111.4332
2.577166	153.3098	-97.31038
2.642166	154.3364	-83.19868
2.707167	155.1810	-70.58412
2.770500	155.8568	-60.32854
2.835500	156.4269	-51.65735
2.900500	156.8966	-44.57678
2.963833	157.2746	-38.94598
3.028833	157.5980	-34.21410
3.093834	157.8666	-30.34294
3.157167	158.0856	-27.23252
3.222166	158.2766	-24.58314
3.287167	158.4372	-22.36569
3.350500	158.5722	-20.53071
3.415500	158.6909	-18.92085
3.480500	158.7938	-17.53752
3.545500	158.8833	-16.34072
3.608833	158.9593	-15.31530
3.673834	159.0278	-14.38493
3.738834	159.0890	-13.54995
3.802166	159.1425	-12.81521
3.867166	159.1920	-12.11583
3.932167	159.2373	-11.47305
3.995500	159.2779	-10.88473
4.060500	159.3166	-10.31103
4.125500	159.3522	-9.765026
4.188834	159.3849	-9.255281
4.253834	159.4170	-8.747882
4.318833	159.4478	-8.253930
4.382167	159.4756	-7.790024
4.447166	159.5026	-7.335078
4.512167	159.5289	-6.900032
4.575500	159.5526	-6.486791
4.640500	159.5763	-6.077598
4.705500	159.5991	-5.678650
4.770500	159.6217	-5.285668
4.833834	159.6421	-4.906083
4.898834	159.6637	-4.522756
4.963834	159.6835	-4.140115
5.027167	159.7030	-3.775596
5.092167	159.7234	-3.395925
5.157166	159.7438	-3.016376
5.220500	159.7638	-2.636084
5.285500	159.7849	-2.226401
5.350500	159.8058	-1.804755
5.413832	159.8262	-1.378630
5.478832	159.8495	-0.9375141
5.543832	159.8722	-0.4936490
5.607168	159.8939	-.06533838
5.672168	159.9158	0.3593052
5.737168	159.9368	0.7709750
5.800500	159.9576	1.157164
5.865500	159.9766	1.543202
5.930500	159.9961	1.933612
5.993834	160.0158	2.307752
6.058832	160.0332	2.655410
6.123832	160.0492	2.972772
6.188832	160.0648	3.266365
6.252168	160.0788	3.532688
6.317168	160.0919	3.785317
6.382168	160.1046	4.025826
6.445500	160.1154	4.246109
6.510500	160.1272	4.467338
6.575500	160.1378	4.680275
6.638832	160.1483	4.885324
6.703832	160.1594	5.087162
6.768832	160.1686	5.291821
6.832168	160.1788	5.487572
6.897168	160.1887	5.689408
6.962168	160.1990	5.893490
7.025500	160.2088	6.091084
7.090500	160.2197	6.295145
7.155500	160.2300	6.505261
7.218832	160.2403	6.707176
7.283832	160.2506	6.922874
7.348832	160.2623	7.137322
7.413832	160.2721	7.359547
7.477168	160.2842	7.574832
7.542168	160.2949	7.803894
7.607168	160.3070	8.038746
7.670500	160.3184	8.274631
7.735500	160.3309	8.523282
7.800500	160.3435	8.775462
7.863834	160.3564	9.024621
7.928834	160.3693	9.291566
7.993834	160.3828	9.562488
8.057168	160.3959	9.830156
8.122168	160.4102	10.11395
8.187166	160.4248	10.39981
8.250500	160.4383	10.68896
8.315500	160.4536	10.98841
8.380500	160.4690	11.29432
8.443832	160.4833	11.59882
8.508832	160.4991	11.91309
8.573834	160.5147	12.23175
8.637168	160.5304	12.54705
8.702168	160.5466	12.87322
8.767168	160.5630	13.20494
8.832168	160.5794	13.53698
8.895500	160.5954	13.85816
8.960499	160.6128	14.19143
9.025499	160.6286	14.52541
9.088832	160.6445	14.84454
9.153832	160.6609	15.17599
9.218834	160.6768	15.49881
9.282168	160.6920	15.81261
9.347168	160.7084	16.12135
9.412168	160.7236	16.42699
9.475500	160.7373	16.71104
9.540500	160.7511	16.98876
9.605499	160.7653	17.25646
9.668832	160.7768	17.49904
9.733832	160.7894	17.72965
9.798834	160.7996	17.94186
9.862168	160.8095	18.12394
9.927168	160.8186	18.29114
9.992166	160.8258	18.44375
10.05717	160.8327	18.59019
10.12050	160.8411	18.76661
10.18550	160.8528	19.03086
10.25050	160.8724	19.48026
10.31383	160.9036	20.22431
10.37883	160.9571	21.44260
10.44383	161.0376	23.23446
10.50717	161.1425	25.56697
10.57217	161.2812	28.50485
10.63717	161.4411	31.88376
10.70050	161.6130	35.42396
10.76550	161.7954	39.15300
10.83050	161.9768	42.81909
10.89383	162.1452	46.20252
10.95883	162.3057	49.37761
11.02383	162.4481	52.17322
11.08717	162.5676	54.47139
11.15217	162.6662	56.35393
11.21717	162.7394	57.68494
11.28050	162.7838	58.42562
11.34550	162.7996	58.57558
11.41050	162.7872	58.12496
11.47550	162.7435	57.07856
11.53883	162.6743	55.51331
11.60383	162.5814	53.44606
11.66883	162.4586	50.82779
11.73217	162.3246	48.01976
11.79717	162.1744	44.88940
11.86217	162.0146	41.59590
11.92550	161.8546	38.31944
11.99050	161.6903	34.97190
12.05550	161.5287	31.70396
12.11884	161.3762	28.66314
12.18383	161.2286	25.70343
12.24883	161.0908	22.96884
12.31216	160.9672	20.51214
12.37717	160.8504	18.21045
12.44217	160.7452	16.13814
12.50550	160.6542	14.35152
12.57050	160.5702	12.71207
12.63550	160.4957	11.24859
12.70050	160.4296	9.955959
12.76383	160.3722	8.838681
12.82883	160.3200	7.824191
12.89383	160.2748	6.923916
12.95717	160.2350	6.150200
13.02217	160.1989	5.444824
13.08717	160.1674	4.817761
13.15050	160.1396	4.276119
13.21550	160.1139	3.782750
13.28050	160.0924	3.343080
13.34383	160.0718	2.957436
13.40883	160.0542	2.605803
13.47383	160.0386	2.292878
13.53717	160.0244	2.015694
13.60217	160.0117	1.760028
13.66716	160.0005	1.535358
13.73050	159.9902	1.334461
13.79550	159.9804	1.148110
13.86050	159.9722	0.9823272
13.92383	159.9642	0.8332578
13.98883	159.9574	0.6959351
14.05383	159.9510	0.5668180
14.11884	159.9446	0.4552918
14.18217	159.9392	0.3557918
14.24717	159.9348	0.2569545
14.31216	159.9296	0.1697530
14.37550	159.9265	0.08748819
14.44050	159.9215	0.01496463
14.50550	159.9188	-.05635795
14.56884	159.9154	-0.1205018
14.63383	159.9116	-0.1782259
14.69884	159.9094	-0.2340979
14.76217	159.9069	-0.2880176
14.82717	159.9050	-0.3351657
14.89216	159.9017	-0.3824262
14.95550	159.9004	-0.4246456
15.02050	159.8981	-0.4645366
15.08550	159.8961	-0.5001452
15.14883	159.8948	-0.5347551
15.21383	159.8931	-0.5648853
15.27883	159.8908	-0.5976153
15.34383	159.8897	-0.6258898
15.40717	159.8881	-0.6521578
15.47217	159.8864	-0.6785518
15.53717	159.8856	-0.7028640
15.60050	159.8837	-0.7253560
15.66550	159.8832	-0.7465561
15.73050	159.8814	-0.7691265
15.79384	159.8801	-0.7890056
15.85883	159.8797	-0.8093159
15.92383	159.8791	-0.8276700
15.98716	159.8783	-0.8414774
16.05217	159.8771	-0.8586658
16.11716	159.8761	-0.8748524
16.18050	159.8756	-0.8917824
16.24550	159.8753	-0.9074020
16.31050	159.8738	-0.9215363
16.37383	159.8736	-0.9342091
16.43883	159.8739	-0.9484826
16.50383	159.8728	-0.9614705
16.56716	159.8716	-0.9743924
16.63216	159.8711	-0.9872989
16.69716	159.8708	-0.9997745
16.76216	159.8702	-1.012040
16.82550	159.8695	-1.023335
16.89050	159.8685	-1.034760
16.95550	159.8684	-1.045565
17.01883	159.8676	-1.055691
17.08383	159.8667	-1.065729
17.14883	159.8675	-1.075901
17.21216	159.8659	-1.085764
17.27716	159.8658	-1.095482
17.34216	159.8649	-1.104884
17.40550	159.8652	-1.113717
17.47050	159.8644	-1.122814
17.53550	159.8650	-1.131518
17.59883	159.8642	-1.140016
17.66383	159.8638	-1.148109
17.72883	159.8635	-1.155834
17.79216	159.8636	-1.162796
17.85716	159.8633	-1.170256
17.92216	159.8628	-1.177560
17.98716	159.8620	-1.184320
18.05050	159.8621	-1.190734
18.11550	159.8620	-1.197343
18.18050	159.8616	-1.203890
18.24383	159.8613	-1.210282
18.30883	159.8612	-1.216568
18.37383	159.8610	-1.222326
18.43716	159.8605	-1.227794
18.50216	159.8616	-1.233590
18.56716	159.8610	-1.239348
18.63050	159.8606	-1.244781
18.69550	159.8611	-1.250488
18.76050	159.8606	-1.256096
18.82383	159.8605	-1.260891
18.88883	159.8602	-1.264850
18.95383	159.8597	-1.268638
19.01716	159.8594	-1.272092
19.08216	159.8589	-1.275346
19.14716	159.8586	-1.278940
19.21050	159.8589	-1.282282
19.27550	159.8583	-1.285684
19.34050	159.8582	-1.289170
19.40550	159.8577	-1.292889
19.46883	159.8579	-1.296519
19.53383	159.8574	-1.300077
19.59883	159.8573	-1.303614
19.66217	159.8569	-1.306923
19.72716	159.8563	-1.310290
19.79216	159.8566	-1.313411
19.85550	159.8556	-1.316579
19.92050	159.8566	-1.319655
19.98550	159.8561	-1.322923
20.04883	159.8558	-1.326244
20.11383	159.8555	-1.329438
20.17883	159.8558	-1.332514
20.24216	159.8561	-1.335783
20.30716	159.8561	-1.339343
20.37216	159.8564	-1.342984
20.43550	159.8565	-1.347028
20.50050	159.8566	-1.351060
20.56550	159.8569	-1.354750
20.63050	159.8566	-1.357881
20.69383	159.8570	-1.360095
20.75883	159.8558	-1.361522
20.82383	159.8554	-1.362852
20.88716	159.8555	-1.364021
20.95216	159.8552	-1.365604
21.01716	159.8551	-1.367370
21.08050	159.8550	-1.368780
21.14550	159.8550	-1.370455
21.21050	159.8546	-1.371924
21.27383	159.8550	-1.373437
21.33883	159.8547	-1.375436
21.40383	159.8555	-1.377950
21.46716	159.8542	-1.380154
21.53216	159.8546	-1.382089
21.59716	159.8546	-1.384698
21.66050	159.8548	-1.387307
21.72550	159.8548	-1.389938
21.79050	159.8543	-1.391668
21.85383	159.8545	-1.393306
21.91883	159.8544	-1.394815
21.98383	159.8550	-1.396220
22.04883	159.8540	-1.397761
22.11216	159.8548	-1.399262
22.17717	159.8542	-1.400939
22.24216	159.8541	-1.402558
22.30550	159.8543	-1.404155
22.37050	159.8541	-1.405669
22.43550	159.8540	-1.407359
22.49883	159.8534	-1.408786
22.56383	159.8530	-1.410039
22.62883	159.8542	-1.411350
22.69216	159.8539	-1.412795
22.75716	159.8532	-1.414155
22.82216	159.8529	-1.415376
22.88550	159.8528	-1.416698
22.95050	159.8532	-1.417760
23.01550	159.8527	-1.418246
23.07883	159.8524	-1.419072
23.14383	159.8520	-1.419624
23.20883	159.8519	-1.420439
23.27383	159.8527	-1.421472
23.33716	159.8525	-1.423328
23.40216	159.8526	-1.425446
23.46716	159.8533	-1.427551
23.53050	159.8526	-1.429135
23.59550	159.8525	-1.431091
23.66050	159.8524	-1.433028
23.72383	159.8533	-1.434531
23.78883	159.8533	-1.435988
23.85383	159.8527	-1.437300
23.91716	159.8526	-1.438438
23.98216	159.8529	-1.439416
24.04716	159.8526	-1.440105
24.11050	159.8528	-1.440589
24.17550	159.8529	-1.441138
24.24050	159.8527	-1.441723
24.30383	159.8526	-1.442138
24.36883	159.8527	-1.442365
24.43383	159.8520	-1.442666
24.49716	159.8515	-1.442783
24.56216	159.8527	-1.443905
24.62716	159.8516	-1.444988
24.69216	159.8516	-1.445898
24.75550	159.8516	-1.446710
24.82050	159.8518	-1.447539
24.88550	159.8518	-1.447876
24.94883	159.8507	-1.448087
25.01383	159.8506	-1.448420
25.07883	159.8511	-1.449136
25.14216	159.8510	-1.450134
25.20717	159.8514	-1.451466
25.27216	159.8508	-1.452626
25.33550	159.8512	-1.453589
25.40050	159.8520	-1.454838
25.46550	159.8515	-1.456407
25.52883	159.8514	-1.457809
25.59383	159.8522	-1.459613
25.65883	159.8514	-1.461542
25.72216	159.8523	-1.463174
25.78717	159.8516	-1.464017
25.85217	159.8518	-1.464652
25.91716	159.8519	-1.465268
25.98050	159.8511	-1.465402
26.04550	159.8512	-1.465242
26.11050	159.8516	-1.465095
26.17383	159.8511	-1.464829
26.23883	159.8504	-1.464476
26.30383	159.8510	-1.464957
26.36716	159.8512	-1.465586
26.43216	159.8511	-1.466368
26.49716	159.8507	-1.467074
26.56050	159.8510	-1.468191
26.62550	159.8518	-1.469385
26.69050	159.8520	-1.470854
26.75383	159.8518	-1.472154
26.81883	159.8518	-1.473729
26.88383	159.8520	-1.474745
26.94717	159.8512	-1.474913
27.01216	159.8512	-1.474394
27.07717	159.8510	-1.473662
27.14050	159.8509	-1.472909
27.20550	159.8508	-1.472219
27.27050	159.8510	-1.472046
27.33550	159.8510	-1.473146
27.39883	159.8515	-1.474648
27.46383	159.8514	-1.476378
27.52883	159.8518	-1.478200
27.59216	159.8517	-1.479462
27.65716	159.8519	-1.480554
27.72216	159.8518	-1.481362
27.78550	159.8516	-1.481773
27.85050	159.8516	-1.482097
27.91550	159.8524	-1.482623
27.97883	159.8513	-1.483356
28.04383	159.8508	-1.483385
28.10883	159.8509	-1.483017
28.17216	159.8507	-1.482352
28.23716	159.8502	-1.481628
28.30217	159.8503	-1.480981
28.36550	159.8502	-1.480391
28.43050	159.8502	-1.480519
28.49550	159.8497	-1.480549
28.56050	159.8499	-1.481051
28.62383	159.8502	-1.481749
28.68883	159.8501	-1.482832
28.75383	159.8504	-1.483947
28.81716	159.8504	-1.485498
28.88216	159.8504	-1.487465
28.94717	159.8505	-1.489158
29.01050	159.8507	-1.490573
29.07550	159.8515	-1.491792
29.14050	159.8511	-1.492815
29.20383	159.8511	-1.493248
29.26883	159.8511	-1.493436
29.33383	159.8511	-1.493188
29.39716	159.8508	-1.492936
29.46216	159.8514	-1.492803
29.52717	159.8514	-1.493094
29.59050	159.8508	-1.493561
29.65550	159.8514	-1.493964
29.72050	159.8517	-1.494144
29.78383	159.8512	-1.494860
29.84883	159.8512	-1.495507
29.91383	159.8512	-1.495954
29.97883	159.8512	-1.496169
30.04216	159.8510	-1.495864
30.10716	159.8512	-1.495671
30.17216	159.8509	-1.495779
30.23550	159.8508	-1.496332
30.30050	159.8508	-1.496476
30.36550	159.8506	-1.496140
30.42883	159.8493	-1.495542
30.49383	159.8502	-1.494890
30.55883	159.8497	-1.494734
30.62216	159.8501	-1.494685
30.68717	159.8498	-1.495209
30.75217	159.8497	-1.495842
30.81550	159.8498	-1.496591
30.88050	159.8501	-1.497085
30.94550	159.8499	-1.497425
31.00883	159.8498	-1.497840
31.07383	159.8499	-1.498551
31.13883	159.8499	-1.499647
31.20383	159.8508	-1.500741
31.26716	159.8501	-1.501672
31.33216	159.8503	-1.503006
31.39716	159.8508	-1.504080
31.46050	159.8506	-1.505222
31.52550	159.8511	-1.506044
31.59050	159.8505	-1.506893
31.65383	159.8504	-1.507072
31.71883	159.8515	-1.507253
31.78383	159.8514	-1.507201
31.84716	159.8508	-1.507230
31.91217	159.8512	-1.506981
31.97717	159.8503	-1.506654
32.04050	159.8509	-1.506100
32.10550	159.8502	-1.505773
32.17050	159.8500	-1.505411
32.23383	159.8498	-1.504948
32.29883	159.8496	-1.504322
32.36383	159.8500	-1.503856
32.42717	159.8506	-1.503746
32.49216	159.8504	-1.503930
32.55716	159.8500	-1.504475
32.62216	159.8495	-1.504848
32.68550	159.8501	-1.505133
32.75050	159.8500	-1.505420
32.81550	159.8502	-1.505844
32.87883	159.8500	-1.506377
32.94383	159.8516	-1.507310
33.00883	159.8503	-1.507907
33.07217	159.8502	-1.508499
33.13716	159.8503	-1.509412
33.20216	159.8501	-1.510058
33.26550	159.8494	-1.510415
33.33050	159.8501	-1.510427
33.39550	159.8498	-1.510187
33.45883	159.8498	-1.509413
33.52383	159.8486	-1.508913
33.58883	159.8498	-1.508474
33.65216	159.8496	-1.508936
33.71716	159.8495	-1.509448
33.78216	159.8500	-1.509868
33.84716	159.8501	-1.510805
33.91050	159.8498	-1.511734
33.97550	159.8500	-1.512688
34.04050	159.8502	-1.513367
34.10383	159.8498	-1.514025
34.16883	159.8496	-1.514438
34.23383	159.8505	-1.514907
34.29716	159.8511	-1.515287
34.36217	159.8509	-1.515691
34.42717	159.8505	-1.515931
34.49050	159.8511	-1.516149
34.55550	159.8505	-1.516186
34.62050	159.8509	-1.516192
34.68384	159.8510	-1.516182
34.74883	159.8509	-1.516024
34.81383	159.8505	-1.515801
34.87717	159.8504	-1.515054
34.94216	159.8496	-1.514229
35.00716	159.8495	-1.513181
35.07050	159.8489	-1.512377
35.13550	159.8494	-1.511708
35.20050	159.8491	-1.511596
35.26550	159.8498	-1.511563
35.32883	159.8496	-1.511943
35.39383	159.8498	-1.512655
35.45883	159.8496	-1.513664
35.52217	159.8504	-1.514759
35.58716	159.8504	-1.515869
35.65216	159.8505	-1.517032
35.71550	159.8506	-1.518354
35.78050	159.8508	-1.519028
35.84550	159.8501	-1.519546
35.90883	159.8503	-1.520073
35.97383	159.8506	-1.520140
36.03883	159.8505	-1.520273
36.10217	159.8503	-1.520170
36.16716	159.8513	-1.520087
36.23216	159.8505	-1.519983
36.29550	159.8506	-1.519842
36.36050	159.8502	-1.519488
36.42550	159.8503	-1.519187
36.49050	159.8499	-1.518987
36.55383	159.8494	-1.518678
36.61883	159.8494	-1.518115
36.68384	159.8495	-1.517447
36.74716	159.8489	-1.516994
36.81216	159.8495	-1.516764
36.87717	159.8489	-1.517074
36.94050	159.8499	-1.517681
37.00550	159.8494	-1.518156
37.07050	159.8494	-1.518577
37.13383	159.8492	-1.519156
37.19883	159.8500	-1.520086
37.26383	159.8500	-1.521283
37.32717	159.8504	-1.522092
37.39216	159.8497	-1.522345
37.45716	159.8491	-1.522402
37.52050	159.8488	-1.521924
37.58550	159.8493	-1.521345
37.65050	159.8490	-1.520586
37.71383	159.8490	-1.520203
37.77883	159.8493	-1.520260
37.84384	159.8495	-1.520938
37.90883	159.8503	-1.522011
37.97217	159.8501	-1.522950
38.03717	159.8501	-1.523870
38.10217	159.8501	-1.524336
38.16550	159.8500	-1.524489
38.23050	159.8504	-1.524511
38.29550	159.8498	-1.524374
38.35883	159.8496	-1.524474
38.42383	159.8502	-1.524225
38.48883	159.8495	-1.523848
38.55217	159.8496	-1.523103
38.61716	159.8500	-1.522612
38.68216	159.8494	-1.522282
38.74550	159.8505	-1.522357
38.81050	159.8492	-1.522476
38.87550	159.8500	-1.523299
38.93883	159.8500	-1.524271
39.00383	159.8502	-1.525018
39.06883	159.8505	-1.525982
39.13383	159.8500	-1.526601
39.19717	159.8513	-1.526879
39.26216	159.8505	-1.527163
39.32717	159.8509	-1.527556
39.39050	159.8503	-1.527866
39.45550	159.8509	-1.528003
39.52050	159.8509	-1.527836
39.58383	159.8506	-1.527494
39.64883	159.8505	-1.527110
39.71383	159.8504	-1.526514
39.77716	159.8500	-1.525886
39.84216	159.8503	-1.525574
39.90716	159.8499	-1.525269
39.97050	159.8511	-1.525462
40.03550	159.8498	-1.525478
40.10050	159.8498	-1.525226
40.16383	159.8494	-1.525574
40.22883	159.8497	-1.525891
40.29383	159.8492	-1.526001
40.35716	159.8502	-1.526047
40.42216	159.8501	-1.526084
40.48717	159.8497	-1.525700
40.55217	159.8494	-1.525389
40.61550	159.8493	-1.525226
40.68050	159.8499	-1.525321
40.74550	159.8502	-1.525738
40.80883	159.8493	-1.526043
40.87383	159.8498	-1.526458
40.93883	159.8498	-1.526761
41.00217	159.8491	-1.526954
41.06717	159.8494	-1.527279
41.13217	159.8499	-1.527805
41.19550	159.8500	-1.528028
41.26050	159.8498	-1.528425
41.32550	159.8496	-1.529066
41.38883	159.8505	-1.529664
41.45383	159.8506	-1.530189
41.51883	159.8504	-1.530631
41.58217	159.8501	-1.531192
41.64717	159.8504	-1.531610
41.71216	159.8502	-1.531902
41.77716	159.8502	-1.532158
41.84050	159.8495	-1.532160
41.90550	159.8498	-1.531661
41.97050	159.8496	-1.530908
42.03383	159.8498	-1.529783
42.09883	159.8496	-1.528876
42.16383	159.8498	-1.528190
42.22717	159.8490	-1.527957
42.29217	159.8493	-1.527610
42.35717	159.8503	-1.527910
42.42050	159.8492	-1.528492
42.48550	159.8496	-1.529046
42.55050	159.8491	-1.529575
42.61383	159.8495	-1.530348
42.67883	159.8496	-1.530794
42.74383	159.8493	-1.531124
42.80717	159.8501	-1.531446
42.87216	159.8500	-1.531921
42.93716	159.8500	-1.532113
43.00050	159.8490	-1.532399
43.06550	159.8502	-1.532737
43.13050	159.8500	-1.532903
43.19550	159.8508	-1.533292
43.25883	159.8503	-1.533806
43.32383	159.8504	-1.534220
43.38883	159.8504	-1.534378
43.45216	159.8506	-1.534284
43.51717	159.8497	-1.534394
43.58217	159.8507	-1.534206
43.64550	159.8499	-1.533804
43.71050	159.8504	-1.533421
43.77550	159.8496	-1.532968
43.83883	159.8498	-1.532047
43.90383	159.8484	-1.531228
43.96884	159.8497	-1.530504
44.03217	159.8492	-1.530409
44.09716	159.8498	-1.530104
44.16217	159.8496	-1.530125
44.22550	159.8493	-1.530294
44.29050	159.8502	-1.530858
44.35550	159.8500	-1.531416
44.42050	159.8500	-1.532138
44.48383	159.8506	-1.533207
44.54883	159.8496	-1.534264
44.61383	159.8500	-1.535104
44.67717	159.8498	-1.535693
44.74216	159.8500	-1.535783
44.80717	159.8503	-1.535768
44.87050	159.8495	-1.535728
44.93550	159.8500	-1.535409
45.00050	159.8502	-1.535224
45.06383	159.8502	-1.534496
45.12883	159.8491	-1.533914
45.19383	159.8492	-1.533283
45.25717	159.8496	-1.533114
45.32217	159.8488	-1.533276
45.38716	159.8502	-1.533833
45.45050	159.8491	-1.534246
45.51550	159.8498	-1.534774
45.58050	159.8505	-1.535434
45.64383	159.8498	-1.535805
45.70883	159.8500	-1.536423
45.77383	159.8501	-1.537081
45.83883	159.8508	-1.537687
45.90216	159.8505	-1.538185
45.96717	159.8495	-1.538257
46.03217	159.8503	-1.538044
46.09550	159.8505	-1.537818
46.16050	159.8505	-1.537349
46.22550	159.8492	-1.536720
46.28883	159.8496	-1.536084
46.35383	159.8497	-1.535706
46.41883	159.8491	-1.535762
46.48217	159.8497	-1.535585
46.54716	159.8495	-1.535271
46.61217	159.8491	-1.534800
46.67550	159.8489	-1.534579
46.74050	159.8500	-1.534331
46.80550	159.8484	-1.534403
46.86883	159.8496	-1.534378
46.93383	159.8488	-1.534703
46.99883	159.8496	-1.535334
47.06383	159.8496	-1.535802
47.12717	159.8493	-1.536291
47.19217	159.8496	-1.536854
47.25717	159.8500	-1.537555
47.32050	159.8500	-1.538213
47.38550	159.8496	-1.538486
47.45050	159.8500	-1.538524
47.51383	159.8498	-1.538512
47.57883	159.8500	-1.538709
47.64383	159.8507	-1.538658
47.70717	159.8504	-1.538750
47.77217	159.8502	-1.539018
47.83716	159.8506	-1.539324
47.90050	159.8500	-1.539601
47.96550	159.8505	-1.539312
48.03050	159.8492	-1.538563
48.09384	159.8491	-1.537381
48.15883	159.8485	-1.536285
48.22383	159.8478	-1.535110
48.28717	159.8482	-1.534169
48.35217	159.8483	-1.533573
48.41716	159.8484	-1.533220
48.48217	159.8484	-1.533142
48.54550	159.8485	-1.533621
48.61050	159.8486	-1.534217
48.67550	159.8481	-1.535079
48.73883	159.8480	-1.536016
48.80383	159.8488	-1.537065
48.86883	159.8491	-1.537858
48.93217	159.8487	-1.538536
48.99716	159.8486	-1.538936
49.06216	159.8491	-1.539204
49.12550	159.8488	-1.539398
49.19050	159.8490	-1.539936
49.25550	159.8489	-1.539936
49.31883	159.8495	-1.540018
49.38383	159.8484	-1.539947
49.44883	159.8491	-1.540115
49.51216	159.8489	-1.540160
49.57717	159.8491	-1.540566
49.64217	159.8500	-1.541571
49.70717	159.8501	-1.542607
49.77050	159.8501	-1.543642
49.83550	159.8511	-1.544839
49.90050	159.8509	-1.545641
49.96383	159.8502	-1.545802
50.02883	159.8506	-1.545856
50.09384	159.8502	-1.545605
50.15717	159.8499	-1.545347
50.22217	159.8510	-1.544702
50.28717	159.8503	-1.543578
50.35050	159.8507	-1.542728
50.41550	159.8510	-1.542159
50.48050	159.8500	-1.541231
50.54383	159.8511	-1.540681
50.60883	159.8501	-1.540126
50.67383	159.8502	-1.539561
50.73717	159.8503	-1.539582
50.80217	159.8504	-1.539631
50.86716	159.8505	-1.539821
50.93050	159.8500	-1.540250
50.99550	159.8504	-1.540339
51.06050	159.8508	-1.540779
51.12550	159.8502	-1.540898
51.18883	159.8503	-1.540914
51.25383	159.8505	-1.540742
51.31884	159.8504	-1.540599
51.38217	159.8503	-1.540703
51.44717	159.8514	-1.540979
51.51216	159.8503	-1.541478
51.57550	159.8506	-1.541928
51.64050	159.8507	-1.542562
51.70550	159.8504	-1.542456
51.76884	159.8506	-1.542006
51.83383	159.8500	-1.541035
51.89883	159.8491	-1.540109
51.96216	159.8496	-1.539359
52.02717	159.8496	-1.539053
52.09217	159.8495	-1.538628
52.15550	159.8495	-1.538168
52.22050	159.8495	-1.538114
52.28550	159.8489	-1.538108
52.35050	159.8496	-1.538476
52.41383	159.8496	-1.538948
52.47883	159.8499	-1.539696
52.54382	159.8500	-1.540544
52.60717	159.8502	-1.541116
52.67217	159.8496	-1.541486
52.73717	159.8493	-1.541625
52.80050	159.8501	-1.541616
52.86550	159.8497	-1.541619
52.93050	159.8502	-1.541680
52.99382	159.8499	-1.542031
53.05883	159.8496	-1.542367
53.12383	159.8499	-1.542523
53.18716	159.8497	-1.542715
53.25217	159.8499	-1.542710
53.31716	159.8489	-1.542581
53.38050	159.8497	-1.542214
53.44550	159.8497	-1.541774
53.51050	159.8501	-1.541409
53.57383	159.8497	-1.541110
53.63882	159.8500	-1.541184
53.70383	159.8498	-1.541506
53.76884	159.8500	-1.542132
53.83217	159.8502	-1.542621
53.89717	159.8505	-1.543166
53.96216	159.8501	-1.543629
54.02550	159.8498	-1.544060
54.09050	159.8498	-1.544453
54.15550	159.8505	-1.544704
54.21884	159.8501	-1.544591
54.28383	159.8505	-1.544357
54.34882	159.8498	-1.544183
54.41216	159.8506	-1.544382
54.47717	159.8511	-1.544210
54.54217	159.8504	-1.543972
54.60550	159.8506	-1.543602
54.67050	159.8508	-1.543662
54.73550	159.8503	-1.543230
54.79883	159.8502	-1.543119
54.86382	159.8502	-1.543258
54.92883	159.8500	-1.543159
54.99382	159.8501	-1.543166
55.05717	159.8505	-1.543435
55.12217	159.8499	-1.543421
55.18716	159.8497	-1.543526
55.25050	159.8502	-1.543707
55.31550	159.8498	-1.543477
55.38050	159.8497	-1.543411
55.44384	159.8497	-1.543059
55.50883	159.8493	-1.542811
55.57383	159.8503	-1.542805
55.63716	159.8488	-1.542639
55.70216	159.8492	-1.542228
55.76716	159.8486	-1.542248
55.83050	159.8499	-1.542135
55.89550	159.8501	-1.542241
55.96050	159.8498	-1.542488
56.02383	159.8496	-1.542807
56.08882	159.8487	-1.543032
56.15383	159.8492	-1.543273
56.21717	159.8494	-1.543608
56.28217	159.8501	-1.543863
56.34716	159.8497	-1.544122
56.41216	159.8498	-1.544475
56.47550	159.8500	-1.544852
56.54050	159.8492	-1.545188
56.60550	159.8503	-1.545474
56.66882	159.8506	-1.545725
56.73383	159.8506	-1.546056
56.79883	159.8502	-1.546330
56.86217	159.8504	-1.545997
56.92717	159.8497	-1.545334
56.99216	159.8498	-1.544649
57.05550	159.8502	-1.544405
57.12050	159.8501	-1.544341
57.18550	159.8499	-1.544340
57.24883	159.8500	-1.544172
57.31382	159.8498	-1.544300
57.37883	159.8504	-1.544677
57.44216	159.8496	-1.544680
57.50717	159.8499	-1.544525
57.57217	159.8504	-1.544537
57.63716	159.8496	-1.544309
57.70050	159.8498	-1.544142
57.76550	159.8500	-1.543853
57.83050	159.8499	-1.543771
57.89384	159.8498	-1.543827
57.95883	159.8499	-1.544150
58.02383	159.8498	-1.544521
58.08716	159.8497	-1.544426
58.15217	159.8495	-1.544260
58.21717	159.8495	-1.544240
58.28050	159.8494	-1.544087
58.34550	159.8491	-1.544309
58.41050	159.8498	-1.544421
58.47382	159.8499	-1.544323
58.53882	159.8500	-1.544528
58.60383	159.8500	-1.544766
58.66716	159.8499	-1.545322
58.73217	159.8502	-1.546139
58.79717	159.8509	-1.546940
58.86050	159.8504	-1.547660
58.92550	159.8506	-1.548146
58.99050	159.8501	-1.548180
59.05550	159.8503	-1.548215
59.11882	159.8510	-1.548136
59.18383	159.8509	-1.547889
59.24883	159.8500	-1.547321
59.31216	159.8500	-1.546634
59.37717	159.8494	-1.545765
59.44216	159.8496	-1.544718
59.50550	159.8496	-1.543773
59.57050	159.8499	-1.543399
59.63550	159.8498	-1.543350
59.69883	159.8497	-1.542964
59.76382	159.8497	-1.542813
59.82883	159.8499	-1.542930
59.89216	159.8494	-1.543161
59.95717	159.8495	-1.543472
60.02217	159.8506	-1.544294
60.08550	159.8502	-1.544986
60.15050	159.8505	-1.545766
60.21550	159.8500	-1.546399
60.28050	159.8504	-1.547132
60.34384	159.8505	-1.547411
60.40883	159.8497	-1.547255
60.47382	159.8504	-1.547097
60.53716	159.8511	-1.547018
60.60217	159.8502	-1.547030
60.66716	159.8498	-1.546885
60.73050	159.8502	-1.546483
60.79550	159.8500	-1.546044
60.86050	159.8499	-1.545611
60.92383	159.8498	-1.545043
60.98882	159.8496	-1.544600
61.05383	159.8499	-1.544378
61.11716	159.8491	-1.544312
61.18217	159.8496	-1.544369
61.24717	159.8498	-1.544999
61.31050	159.8509	-1.545942
61.37550	159.8502	-1.546818
61.44050	159.8502	-1.547421
61.50383	159.8502	-1.547430
61.56884	159.8502	-1.547703
61.63383	159.8500	-1.547806
61.69883	159.8506	-1.547913
61.76216	159.8502	-1.547984
61.82717	159.8504	-1.548189
61.89216	159.8512	-1.548382
61.95550	159.8509	-1.548420
62.02050	159.8506	-1.548276
62.08550	159.8504	-1.547926
62.14883	159.8509	-1.547926
62.21382	159.8504	-1.547989
62.27883	159.8499	-1.548152
62.33882	159.8510	-1.548391
62.40383	160.0143	-1.508766
62.46884	160.6578	-4.051773
62.53383	161.4704	-8.452811
62.59716	162.3670	-13.07012
62.66216	163.3594	-17.42133
62.72717	164.4102	-21.16107
62.79050	165.4784	-24.20864
62.85550	166.6102	-26.79526
62.92050	167.7726	-28.92749
62.98383	168.9280	-30.64402
63.04883	170.1335	-32.11078
63.11382	171.3541	-33.35107
63.17717	172.5547	-34.38219
63.24216	173.7960	-35.29097
63.30717	175.0468	-36.08360
63.37050	176.2715	-36.76904
63.43550	177.5325	-37.40390
63.50050	178.7975	-37.98429
63.56382	180.0324	-38.53111
63.62883	181.3038	-39.08206
63.69384	182.5761	-39.62704
63.75717	183.8176	-40.15117
63.82217	185.0920	-40.70205
63.88716	186.3663	-41.25735
63.95216	187.6410	-41.83126
64.01550	188.8816	-42.41773
64.08050	190.1546	-43.05554
64.14550	191.4256	-43.73460
64.20883	192.6626	-44.44430
64.27383	193.9305	-45.22328
64.33884	195.1946	-46.04006
64.40218	196.4247	-46.89772
64.46717	197.6846	-47.84594
64.53217	198.9416	-48.84283
64.59550	200.1632	-49.88199
64.66050	201.4137	-51.02704
64.72551	202.6622	-52.27213
64.78882	203.8735	-53.58854
64.85383	205.1104	-55.08682
64.91884	206.3377	-56.80176
64.98217	207.5220	-58.76092
65.04718	208.7196	-61.18218
65.11217	209.8951	-64.12654
65.17718	211.0438	-67.65625
65.24050	212.1378	-71.64835
65.30550	213.2353	-76.28335
65.37050	214.3078	-81.49325
65.43384	215.3298	-87.04351
65.49884	216.3617	-93.07681
65.56384	217.3910	-99.04982
65.62718	218.4280	-103.7565
65.69218	219.6164	-105.3547
65.75718	220.9848	-103.0455
65.82050	222.4372	-98.66882
65.88550	223.9910	-92.98551
65.95050	225.5874	-86.41984
66.01384	227.1739	-79.40743
66.07884	228.8115	-72.22922
66.14384	230.4068	-66.18369
66.20718	231.9089	-61.47100
66.27218	233.3992	-57.70903
66.33716	234.8459	-54.79838
66.40050	236.2248	-52.61094
66.46550	237.6138	-50.87312
66.53050	238.9822	-49.54809
66.59550	240.3369	-48.53797
66.65884	241.6437	-47.80004
66.72384	242.9772	-47.23578
66.78882	244.3025	-46.81567
66.85218	245.5884	-46.49866
66.91718	246.9042	-46.26056
66.98218	248.2162	-46.07989
67.04550	249.4935	-45.95616
67.11050	250.8014	-45.87387
67.17550	252.1085	-45.82616
67.23882	253.3804	-45.79484
67.30384	254.6855	-45.77914
67.36884	255.9896	-45.77318
67.43218	257.2599	-45.77520
67.49718	258.5629	-45.79010
67.56216	259.8657	-45.83964
67.62550	261.1332	-45.89384
67.69050	262.4351	-45.95246
67.75550	263.7369	-46.02763
67.82050	265.0389	-46.10058
67.88384	266.3067	-46.17377
67.94884	267.6079	-46.23667
68.01384	268.9082	-46.31348
68.07718	270.1760	-46.39124
68.14216	271.4770	-46.45886
68.20718	272.7771	-46.53544
68.27050	274.0452	-46.60697
-2.000000	3.000000	0.0000000
68.39384	276.3076	-46.50543
68.45884	276.4158	-40.34248
68.52384	276.1160	-29.56048
68.58716	275.5948	-18.55474
68.65218	274.9014	-8.455196
68.71718	274.0856	.009908047
68.78050	273.1997	6.741152
68.84550	272.2170	12.31886
68.91050	271.1746	16.79706
68.97384	270.1118	20.30101
69.03882	268.9838	23.20208
69.10384	267.8252	25.54289
69.16718	266.6722	27.38895
69.23218	265.4688	28.92658
69.29718	264.2485	30.18117
69.36050	263.0467	31.17946
69.42550	261.8024	32.01490
69.49050	260.5503	32.70525
69.55384	259.3232	33.26038
69.61884	258.0580	33.73429
69.68384	256.7870	34.13190
69.74884	255.5132	34.45228
69.81216	254.2686	34.73156
69.87718	252.9883	34.97043
69.94218	251.7070	35.17263
70.00550	250.4555	35.33710
70.07050	249.1708	35.48514
70.13550	247.8847	35.61555
70.19884	246.6296	35.72959
70.26384	245.3397	35.81760
70.32884	244.0509	35.88578
70.39216	242.7928	35.93619
70.45718	241.5022	35.97480
70.52218	240.2102	36.00930
70.58550	238.9504	36.04162
70.65050	237.6582	36.07094
70.71550	236.3653	36.09740
70.77884	235.1050	36.11582
70.84384	233.8122	36.12461
70.90884	232.5184	36.13185
70.97384	231.2242	36.13712
71.03718	229.9634	36.14172
71.10218	228.6690	36.14518
71.16718	227.3743	36.14993
71.23050	226.1140	36.15532
71.29550	224.8204	36.16122
71.36050	223.5258	36.16860
71.42384	222.2642	36.17460
71.48882	220.9688	36.17984
71.55384	219.6747	36.18424
71.61718	218.4123	36.18878
71.68218	217.1180	36.19088
71.74718	215.8227	36.19024
71.81050	214.5610	36.18691
71.87550	213.2661	36.17990
71.94050	211.9710	36.17122
72.00384	210.7090	36.16253
72.06884	209.4139	36.15330
72.13384	208.1198	36.14356
72.19718	206.8566	36.13278
72.26218	205.5622	36.12064
72.32718	204.2668	36.10645
72.39216	202.9708	36.09402
72.45550	201.7084	36.07278
72.52050	200.4124	36.05446
72.58550	199.1172	36.03679
72.64884	197.8544	36.02231
72.71384	196.5584	36.00534
72.77884	195.2626	35.98975
72.84216	194.0002	35.97610
72.90718	192.7037	35.96040
72.97218	191.4071	35.93444
73.03550	190.1452	35.91144
73.10050	188.8478	35.88320
73.16550	187.5532	35.85964
73.22884	186.2904	35.84160
73.29384	184.9952	35.82846
73.35884	183.6992	35.80859
73.42218	182.4357	35.78822
73.48718	181.1398	35.76834
73.55218	179.8436	35.74850
73.61718	178.5468	35.73576
73.68050	177.2839	35.72508
73.74550	175.9873	35.71289
73.81050	174.6910	35.70168
73.87384	173.4280	35.69049
73.93884	172.1316	35.67332
74.00384	170.8356	35.65404
74.06718	169.5722	35.63206
74.13218	168.2761	35.62195
74.19718	166.9814	35.61604
74.26050	165.7227	35.68425
74.32550	164.4388	36.03568
74.39050	163.1804	36.96708
74.45384	162.0042	39.11096
74.51882	160.8870	43.32950
74.58384	159.8833	49.88750
74.64718	158.9984	57.88192
74.71218	158.1201	66.26348
74.77718	157.1984	73.30581
74.84050	156.2016	77.96718
74.90550	155.0609	80.26262
74.97050	153.7995	80.21343
75.03550	152.4356	78.22369
75.09882	151.0329	74.98576
75.16382	149.5475	70.90494
75.22884	148.0401	66.54446
75.29218	146.5724	62.41021
75.35718	145.0784	58.54201
75.42218	143.6065	55.11818
75.48550	142.1941	52.22662
75.55050	140.7669	49.69458
75.61550	139.3594	47.55515
75.67884	138.0034	45.74759
75.74384	136.6242	43.92078
75.80884	135.2430	42.50133
75.87218	133.9228	41.42081
75.93718	132.5770	40.46368
76.00218	131.2388	39.64794
76.06550	129.9403	38.95371
76.13050	128.6128	38.34355
76.19550	127.2884	37.80579
76.26050	125.9676	37.33218
76.32384	124.6835	36.90335
76.38884	123.3676	36.51128
76.45384	122.0534	36.15276
76.51716	120.7759	35.83319
76.58218	119.4651	35.53359
76.64718	118.1547	35.26502
76.71050	116.8803	35.02212
76.77550	115.5719	34.78838
76.84050	114.2646	34.56456
76.90384	112.9915	34.36133
76.96884	111.6848	34.15453
77.03384	110.3792	33.95706
77.09718	109.1066	33.76392
77.16218	107.8007	33.57916
77.22718	106.4959	33.39050
77.29050	105.2243	33.21610
77.35550	103.9203	33.04366
77.42050	102.6158	32.88144
77.48384	101.3444	32.71762
77.54884	100.0404	32.56122
77.61384	98.73621	32.40765
77.67884	97.43268	32.25770
77.74218	96.16230	32.10908
77.80718	94.85772	31.95143
77.87218	93.55492	31.79973
77.93550	92.28439	31.65262
78.00050	90.98121	31.50435
78.06550	89.67738	31.34906
78.12884	88.40656	31.19985
78.19384	87.10275	31.05617
78.25884	85.79991	30.90442
78.32218	84.53068	30.75728
78.38718	83.22762	30.62018
78.45216	81.92312	30.48394
78.51550	80.65530	30.34724
78.58050	79.35150	30.21836
78.64550	78.04880	30.08398
78.70884	76.77945	29.95694
78.77384	75.47682	29.82426
78.83884	74.17322	29.70040
78.90384	72.87080	29.57086
78.96718	71.60132	29.44287
79.03218	70.29820	29.31753
79.09718	68.99524	29.18279
79.16050	67.72558	29.05810
79.22551	66.42376	28.92006
79.29050	65.12019	28.79558
79.35384	63.85051	28.66654
79.41884	62.54676	28.52256
79.48384	61.24390	28.36754
79.54718	59.97400	28.22980
79.61218	58.67250	28.09478
79.67718	57.36800	27.95582
79.74050	56.09887	27.82146
79.80550	54.79550	27.68706
79.87050	53.49124	27.54641
79.93384	52.22092	27.41214
79.99884	50.91717	27.26676
80.06384	49.61300	27.12956
80.12718	48.34180	26.99730
80.19218	47.03797	26.85250
80.25718	45.73484	26.72046
80.32218	44.43114	26.59129
80.38550	43.16060	26.46128
80.45050	41.85770	26.32858
80.51550	40.55383	26.19377
80.57884	39.28422	26.05834
80.64384	37.98000	25.91295
80.70884	36.67663	25.75758
80.77218	35.40552	25.61167
80.83716	34.10254	25.45579
80.90218	32.79750	25.29795
80.96550	31.52568	25.13978
81.03050	30.22210	24.98292
81.09550	28.91496	24.81917
81.15884	27.64127	24.64475
81.22384	26.33504	24.46364
81.28882	25.02701	24.27587
81.34882	23.82051	24.08549
81.41382	23.02097	23.68615
81.47884	23.06870	19.27092
81.54218	23.43336	13.08623
81.60718	24.02790	6.559490
81.67218	24.78296	0.7604690
81.73718	25.65879	-4.087600
81.80050	26.60045	-7.919040
81.86550	27.63470	-11.06510
81.93050	28.72349	-13.55802
81.99384	29.82508	-15.49447
82.05884	30.98770	-17.08798
82.12384	32.17606	-18.37227
82.18718	33.35191	-19.39120
82.25218	34.57450	-20.25311
82.31718	35.80997	-20.96694
82.38050	37.02395	-21.55356
82.44550	38.27774	-22.07096
82.51050	39.53743	-22.50830
82.57384	40.76987	-22.87608
82.63884	42.03902	-23.21730
82.70382	43.31354	-23.51745
82.76718	44.55688	-23.77898
82.83218	45.83515	-24.02808
82.89718	47.11734	-24.25450
82.96050	48.36807	-24.46997
83.02550	49.65384	-24.67188
83.09050	50.93984	-24.86581
83.15550	52.22760	-25.06070
83.21884	53.48304	-25.24105
83.28384	54.77226	-25.42045
83.34882	56.06122	-25.59088
83.41218	57.32005	-25.75554
83.47718	58.61260	-25.91748
83.54218	59.90521	-26.07056
83.60550	61.16449	-26.22190
83.67050	62.45894	-26.38642
83.73550	63.75289	-26.53845
83.79884	65.01431	-26.67816
83.86384	66.30924	-26.82306
83.92882	67.60366	-26.97654
83.99218	68.86499	-27.11772
84.05718	70.16001	-27.26535
84.12218	71.45532	-27.40516
84.18550	72.71708	-27.54914
84.25050	74.01170	-27.69328
84.31551	75.30671	-27.83992
84.38050	76.60108	-27.98770
84.44384	77.86320	-28.14148
84.50884	79.15840	-28.29554
84.57384	80.45439	-28.45313
84.63718	81.71710	-28.59982
84.70216	83.01264	-28.75022
84.76718	84.30785	-28.89992
84.83051	85.56985	-29.05925
84.89551	86.86505	-29.22150
84.96051	88.16072	-29.37924
85.02384	89.42305	-29.53786
85.08884	90.71899	-29.70989
85.15384	92.01509	-29.86860
85.21718	93.27716	-30.02008
85.28218	94.57313	-30.17488
85.34718	95.86884	-30.33450
85.41050	97.13038	-30.48587
85.47551	98.42749	-30.61579
85.54051	99.72344	-30.74875
85.60382	100.9876	-30.88160
85.66884	102.2849	-31.02574
85.73382	103.5804	-31.16907
85.79884	104.8774	-31.32125
85.86218	106.1392	-31.47527
85.92718	107.4349	-31.64100
85.99218	108.7302	-31.80818
86.05549	109.9928	-31.96719
86.12051	111.2872	-32.14209
86.18550	112.5830	-32.31368
86.24884	113.8444	-32.47961
86.31384	115.1391	-32.65088
86.37882	116.4337	-32.83056
86.44218	117.6958	-32.99980
86.50718	118.9899	-33.18838
86.57218	120.2849	-33.38292
86.63550	121.5475	-33.57135
86.70050	122.8430	-33.77046
86.76551	124.1383	-33.97437
86.82884	125.4002	-34.16306
86.89384	126.6952	-34.36122
86.95882	127.9893	-34.55480
87.02384	129.2841	-34.75043
87.08718	130.5455	-34.94262
87.15218	131.8404	-35.15165
87.21718	133.1342	-35.35163
87.28051	134.3946	-35.56188
87.34551	135.6873	-35.78466
87.41050	136.9799	-36.00991
87.47384	138.2409	-36.23756
87.53882	139.5343	-36.47441
87.60382	140.8269	-36.71164
87.66718	142.0872	-36.93948
87.73218	143.3796	-37.18324
87.79718	144.6712	-37.42731
87.86051	145.9295	-37.67685
87.92551	147.2204	-37.94779
87.99051	148.5104	-38.23553
88.05382	149.7642	-38.55178
88.11884	151.0510	-38.90615
88.18384	152.3365	-39.27988
88.24718	153.5879	-39.66278
88.31218	154.8765	-39.94822
88.37718	156.1680	-40.19354
88.44218	157.4600	-40.45250
88.50551	158.7191	-40.71168
88.57050	160.0109	-40.96106
88.63550	161.3037	-41.20926
88.69884	162.5630	-41.44258
88.76384	163.8567	-41.67022
88.82884	165.1515	-41.87790
88.89218	166.4132	-42.03954
88.95718	167.7101	-42.19261
89.02218	169.0072	-42.31580
89.08551	170.2708	-42.42813
89.15051	171.5689	-42.57094
89.21551	172.8662	-42.72628
89.27884	174.1284	-42.88320
89.34384	175.4231	-43.07196
89.40884	176.7156	-43.29287
89.47218	177.9745	-43.53853
89.53718	179.2640	-43.83637
89.60218	180.5521	-44.17452
89.66718	181.8381	-44.57090
89.73050	183.0883	-45.00982
89.79550	184.3694	-45.51851
89.86051	185.6470	-46.08778
89.92384	186.8889	-46.70663
89.98882	188.1602	-47.44250
90.05382	189.4254	-48.28072
90.11718	190.6541	-49.22435
90.18218	191.9084	-50.30847
90.24718	193.1573	-51.51360
90.31050	194.3696	-52.77378
90.37550	195.6108	-54.10432
90.44051	196.8506	-55.48764
90.50384	198.0582	-56.87494
90.56884	199.2931	-58.36300
90.63384	200.5245	-59.96889
90.69718	201.7188	-61.66352
90.76218	202.9375	-63.54152
90.82718	204.1540	-65.47828
90.89051	205.3393	-67.29364
90.95551	206.5668	-68.86453
91.02050	207.8236	-69.65925
91.08551	209.1392	-69.03399
91.14884	210.4962	-66.74331
91.21384	211.9497	-63.34720
91.27884	213.4230	-59.68629
91.34218	214.8566	-56.24039
91.40718	216.3117	-53.11630
91.47218	217.7402	-50.57058
91.53551	219.1083	-48.60019
91.60050	220.4914	-47.00449
91.66550	221.8566	-45.76933
91.72882	223.1724	-44.83344
91.79384	224.5133	-44.10270
91.85884	225.8451	-43.52891
91.92218	227.1367	-43.11941
91.98718	228.4559	-42.78588
92.05218	229.7720	-42.55670
92.11551	231.0510	-42.39453
92.18051	232.3619	-42.29297
92.24550	233.6700	-42.23084
92.31050	234.9764	-42.19868
92.37384	236.2477	-42.19030
92.43884	237.5521	-42.18520
92.50384	238.8545	-42.18589
92.56718	240.1240	-42.20544
92.63218	241.4266	-42.25834
92.69718	242.7282	-42.33404
92.76051	243.9970	-42.39188
92.82550	245.2983	-42.45110
92.89051	246.5990	-42.51752
92.95382	247.8677	-42.57808
93.01882	249.1686	-42.63889
93.08384	250.4707	-42.70196
93.14718	251.7388	-42.76996
93.21218	253.0406	-42.82947
93.27718	254.3418	-42.88982
93.34051	255.6095	-42.94734
93.40551	256.9099	-43.03286
93.47051	258.2106	-43.10922
93.53384	259.4768	-43.19330
93.59882	260.7771	-43.28873
93.66382	262.0766	-43.37274
93.72882	263.3763	-43.47280
93.79218	264.6430	-43.56980
93.85718	265.9433	-43.67528
93.92218	267.2436	-43.77623
93.98551	268.5107	-43.87589
94.05051	269.8098	-43.97860
94.11551	271.1100	-44.07234
-2.000000	5.000000	0.0000000