File: 3-C1(1.0mol%)+C20(0.6mol%)/matlab/160-3
CLOSED
Version	1.0
Language	English
Mode	Standard
Run	9
RunSerial	11790
Instrument	DSC Q2000 V24.11 Build 124
Module	DSC Standard Cell RC
Operator	Nan
File	\\Ae520-1454\ta\Data\DSC\UQ Composites\Nan\C1(4.5)+C20P(3)+CL(HotplateMixtureAB)\Iso160_60Min_3
ProcName	H/C/H/C/H complete wood PHA
InstSerial	2000-0883
AutoSerial	1293
Sample	Iso160_60Min
Size	43.2000	mg
PanMass	Not available
PanResist	Automatic Automatic  K/W
PanFactor	Default Default
Method	H/C/H/C/H complete wood PHA
Comment
Xcomment	Pan: Tzero Aluminum Hermetic
Xcomment	Gas1: Nitrogen 50.0 ml/min
Xcomment	Gas2: Nitrogen 50.0 ml/min
Text
Exotherm	UP
Kcell	1.05230
Cpconst	Standard: 0.938
Calib	-38.6961
TempCal	1	pts	157.46	156.60
TzeroDt	-87.6168 -0.0009 -1.4231
TzeroDtz	-87.6168 0.0057 6.9570
InstCalFile	Tzero: \\Ae520-1454\ta\Data\DSC\Calibration\2017\CALIBRATION\1562_RCS (90)_05_18_2017 10_50_44.TZR
InstCalFile	Baseline: \\Ae520-1454\ta\Data\DSC\Calibration\2017\2017-05-17_Calibration.001
InstCalFile	Sapphire: \\Ae520-1454\ta\Data\DSC\Calibration\2017\2017-05-17_Saphire.001
InstCalDate	Tzero 2017-05-18 Time 10:50:44
TempRange	-87.39 to 398.39 °C at 10.00 °C/min Heat Only
AutoZero	Delta T Offset 0.000 uV
AutoZero	Delta T0 Offset 0.000 uV
MultiptCal	0
MultiPtDesc	0) Not set
AutoCellConst	Calibration Date 2017-05-18 16:59:28
Controls	Gas 1  Event Off  Sampling 0.2
Cell#	RC-01562
CoolingUnit	RCS (90)
SelHeatFlow	Heat Flow T4 (mW)
AutoLidII	Installed
AutoAnalysis	Off
MacroFile
Nsig	3
Sig1	Time (min)
Sig2	Temperature (°C)
Sig3	Heat Flow (mW)
Date	2017-06-08
Time	00:56:26
OrgMethod	1: Equilibrate at 20.00 °C
OrgMethod	2: Ramp 60.00 °C/min to 160.00 °C
OrgMethod	3: Mark end of cycle 1
OrgMethod	4: Isothermal for 60.00 min
OrgMethod	5: Mark end of cycle 2
OrgMethod	6: Ramp 20.00 °C/min to 280.00 °C
OrgMethod	7: Mark end of cycle 3
OrgMethod	8: Ramp 20.00 °C/min to 20.00 °C
OrgMethod	9: Mark end of cycle 4
OrgMethod	10: Ramp 20.00 °C/min to 280.00 °C
OrgMethod	11: Mark end of cycle 5
OrgFile	C:\Users\jarra\Desktop\DSC\3-C1(1.0mol%)+C20(0.6mol%)\160-3
StartOfData
4.99994E-4	20.05336	0.5824157
0.06550000	20.39560	0.9391858
0.1305000	22.28390	-2.247890
0.1955000	24.77489	-9.989679
0.2588334	27.55185	-18.41324
0.3238334	30.63260	-26.51086
0.3888333	33.89105	-33.52430
0.4521667	37.19223	-39.23410
0.5171667	40.67540	-44.14842
0.5821668	44.22240	-48.59072
0.6455000	47.67722	-53.37676
0.7105000	51.27369	-57.08896
0.7755000	54.92663	-60.48952
0.8388332	58.49712	-63.69239
0.9038334	62.18369	-66.96360
0.9688332	65.84047	-71.21425
1.032167	69.28012	-78.53055
1.097166	72.45624	-94.10913
1.162166	75.12812	-118.5531
1.225500	77.61005	-141.3478
1.290500	80.41650	-160.2030
1.355500	83.54058	-172.6254
1.420500	86.98468	-180.0309
1.483833	90.53421	-184.5115
1.548833	94.33465	-186.3433
1.613833	98.24575	-186.3445
1.677167	102.1305	-187.4772
1.742167	104.6679	-216.4827
1.807167	109.1122	-196.0573
1.870500	114.0457	-176.7125
1.935500	118.8554	-161.6076
2.000500	123.4631	-150.0041
2.063833	127.8113	-140.9329
2.128833	132.1755	-133.3134
2.193833	136.4512	-127.3590
2.257167	140.5472	-122.7956
2.322166	144.6941	-119.1273
2.383833	148.4669	-116.6627
2.448834	150.9502	-111.7344
2.513833	152.6069	-98.94915
2.577166	153.8601	-84.38826
2.642166	154.9032	-70.10090
2.707167	155.7508	-57.66016
2.770500	156.4274	-47.49897
2.835500	156.9991	-38.92864
2.900500	157.4695	-31.96476
2.963833	157.8487	-26.45520
3.028833	158.1714	-21.86841
3.093834	158.4398	-18.15437
3.157167	158.6570	-15.21294
3.222166	158.8437	-12.74862
3.287167	158.9989	-10.73384
3.350500	159.1275	-9.107619
3.415500	159.2376	-7.717918
3.480500	159.3316	-6.557538
3.545500	159.4120	-5.578964
3.608833	159.4791	-4.776146
3.673834	159.5376	-4.074300
3.738834	159.5886	-3.482210
3.802166	159.6309	-2.981290
3.867166	159.6694	-2.544820
3.932167	159.7012	-2.166995
3.995500	159.7288	-1.843584
4.060500	159.7536	-1.559521
4.125500	159.7750	-1.305676
4.188834	159.7944	-1.086913
4.253834	159.8108	-0.8872188
4.318833	159.8254	-0.7069258
4.382167	159.8382	-0.5511047
4.447166	159.8512	-0.4009978
4.512167	159.8617	-0.2650474
4.575500	159.8712	-0.1392874
4.640500	159.8811	-.01821344
4.705500	159.8890	0.09667964
4.770500	159.8972	0.2057815
4.833834	159.9049	0.3112188
4.898834	159.9119	0.4126680
4.963834	159.9192	0.5102324
5.027167	159.9258	0.6066601
5.092167	159.9313	0.7044854
5.157166	159.9377	0.8070816
5.220500	159.9434	0.8997420
5.285500	159.9487	0.9969789
5.350500	159.9545	1.092555
5.413832	159.9599	1.185028
5.478832	159.9650	1.283113
5.543832	159.9711	1.379980
5.607168	159.9755	1.475299
5.672168	159.9814	1.571987
5.737168	159.9872	1.672297
5.800500	159.9931	1.766062
5.865500	159.9978	1.869778
5.930500	160.0029	1.974253
5.993834	160.0085	2.075098
6.058832	160.0148	2.181965
6.123832	160.0200	2.290528
6.188832	160.0258	2.398858
6.252168	160.0316	2.509304
6.317168	160.0369	2.622704
6.382168	160.0440	2.736463
6.445500	160.0494	2.853545
6.510500	160.0556	2.970872
6.575500	160.0620	3.093814
6.638832	160.0680	3.218909
6.703832	160.0746	3.342340
6.768832	160.0810	3.471674
6.832168	160.0883	3.600016
6.897168	160.0946	3.737219
6.962168	160.1025	3.870508
7.025500	160.1088	4.008244
7.090500	160.1164	4.153430
7.155500	160.1237	4.301656
7.218832	160.1306	4.446268
7.283832	160.1381	4.601110
7.348832	160.1461	4.752731
7.413832	160.1537	4.911836
7.477168	160.1616	5.069185
7.542168	160.1698	5.231930
7.607168	160.1782	5.399633
7.670500	160.1868	5.567902
7.735500	160.1956	5.744038
7.800500	160.2043	5.922304
7.863834	160.2133	6.098272
7.928834	160.2220	6.285270
7.993834	160.2313	6.472035
8.057168	160.2408	6.659014
8.122168	160.2507	6.855784
8.187166	160.2607	7.058511
8.250500	160.2705	7.258939
8.315500	160.2811	7.464634
8.380500	160.2915	7.675940
8.443832	160.3022	7.887961
8.508832	160.3132	8.104990
8.573834	160.3234	8.330670
8.637168	160.3360	8.555019
8.702168	160.3464	8.786187
8.767168	160.3581	9.021461
8.832168	160.3706	9.260880
8.895500	160.3818	9.497031
8.960499	160.3944	9.743418
9.025499	160.4070	9.992860
9.088832	160.4193	10.24067
9.153832	160.4315	10.49656
9.218834	160.4446	10.75256
9.282168	160.4572	11.00787
9.347168	160.4700	11.27095
9.412168	160.4833	11.53625
9.475500	160.4959	11.79989
9.540500	160.5091	12.06465
9.605499	160.5226	12.33178
9.668832	160.5350	12.59210
9.733832	160.5491	12.85738
9.798834	160.5623	13.11841
9.862168	160.5741	13.37431
9.927168	160.5871	13.63055
9.992166	160.5999	13.88329
10.05717	160.6124	14.13307
10.12050	160.6238	14.37002
10.18550	160.6356	14.60836
10.25050	160.6468	14.84149
10.31383	160.6578	15.05709
10.37883	160.6691	15.26631
10.44383	160.6785	15.47043
10.50717	160.6884	15.65286
10.57217	160.6971	15.82630
10.63717	160.7052	16.00494
10.70050	160.7150	16.18362
10.76550	160.7243	16.39799
10.83050	160.7376	16.68217
10.89383	160.7548	17.08224
10.95883	160.7804	17.66268
11.02383	160.8168	18.46892
11.08717	160.8640	19.49508
11.15217	160.9250	20.80459
11.21717	160.9990	22.36333
11.28050	161.0809	24.09388
11.34550	161.1742	26.04638
11.41050	161.2750	28.11877
11.47550	161.3792	30.26070
11.53883	161.4822	32.35327
11.60383	161.5863	34.45480
11.66883	161.6862	36.46586
11.73217	161.7783	38.29950
11.79717	161.8654	40.02706
11.86217	161.9436	41.57293
11.92550	162.0126	42.89676
11.99050	162.0702	44.05444
12.05550	162.1215	45.00996
12.11884	162.1599	45.73474
12.18383	162.1897	46.26728
12.24883	162.2082	46.58731
12.31216	162.2164	46.69213
12.37717	162.2142	46.58970
12.44217	162.2008	46.24824
12.50550	162.1778	45.70398
12.57050	162.1429	44.93366
12.63550	162.0960	43.90752
12.70050	162.0378	42.66258
12.76383	161.9695	41.19466
12.82883	161.8891	39.48735
12.89383	161.7982	37.59910
12.95717	161.7011	35.54290
13.02217	161.5931	33.31624
13.08717	161.4808	31.00348
13.15050	161.3683	28.69820
13.21550	161.2516	26.32637
13.28050	161.1358	23.99582
13.34383	161.0278	21.80220
13.40883	160.9208	19.67314
13.47383	160.8216	17.67827
13.53717	160.7305	15.89005
13.60217	160.6457	14.20905
13.66716	160.5686	12.69121
13.73050	160.5015	11.35774
13.79550	160.4384	10.13533
13.86050	160.3829	9.041159
13.92383	160.3341	8.088642
13.98883	160.2897	7.220474
14.05383	160.2501	6.439492
14.11884	160.2146	5.746074
14.18217	160.1841	5.144324
14.24717	160.1558	4.588504
14.31216	160.1308	4.098808
14.37550	160.1089	3.664922
14.44050	160.0887	3.268314
14.50550	160.0718	2.912986
14.56884	160.0553	2.604595
14.63383	160.0410	2.314270
14.69884	160.0287	2.055034
14.76217	160.0166	1.828748
14.82717	160.0058	1.619816
14.89216	159.9965	1.432373
14.95550	159.9874	1.264044
15.02050	159.9797	1.107717
15.08550	159.9722	0.9643426
15.14883	159.9654	0.8391434
15.21383	159.9597	0.7178855
15.27883	159.9533	0.6102538
15.34383	159.9482	0.5092066
15.40717	159.9441	0.4219340
15.47217	159.9385	0.3374164
15.53717	159.9354	0.2555148
15.60050	159.9310	0.1864832
15.66550	159.9284	0.1163342
15.73050	159.9237	0.05511684
15.79384	159.9216	-4.2223E-3
15.85883	159.9186	-.05559798
15.92383	159.9166	-0.1077412
15.98716	159.9140	-0.1541489
16.05217	159.9113	-0.1999180
16.11716	159.9092	-0.2432056
16.18050	159.9070	-0.2797202
16.24550	159.9051	-0.3155396
16.31050	159.9039	-0.3510642
16.37383	159.9028	-0.3840569
16.43883	159.9009	-0.4145320
16.50383	159.9003	-0.4444113
16.56716	159.8991	-0.4737275
16.63216	159.8974	-0.5009546
16.69716	159.8959	-0.5241890
16.76216	159.8941	-0.5434562
16.82550	159.8932	-0.5651948
16.89050	159.8918	-0.5818672
16.95550	159.8909	-0.6026145
17.01883	159.8894	-0.6201391
17.08383	159.8896	-0.6395118
17.14883	159.8886	-0.6556928
17.21216	159.8876	-0.6717415
17.27716	159.8859	-0.6898866
17.34216	159.8857	-0.7044488
17.40550	159.8848	-0.7184926
17.47050	159.8844	-0.7317786
17.53550	159.8834	-0.7449970
17.59883	159.8822	-0.7572509
17.66383	159.8816	-0.7708429
17.72883	159.8814	-0.7832488
17.79216	159.8798	-0.7960262
17.85716	159.8794	-0.8085509
17.92216	159.8790	-0.8213512
17.98716	159.8780	-0.8347015
18.05050	159.8779	-0.8469220
18.11550	159.8776	-0.8594586
18.18050	159.8770	-0.8709100
18.24383	159.8768	-0.8810194
18.30883	159.8765	-0.8914705
18.37383	159.8756	-0.9011450
18.43716	159.8760	-0.9102162
18.50216	159.8756	-0.9197699
18.56716	159.8756	-0.9293598
18.63050	159.8752	-0.9384830
18.69550	159.8752	-0.9475937
18.76050	159.8746	-0.9563294
18.82383	159.8749	-0.9646286
18.88883	159.8747	-0.9728134
18.95383	159.8735	-0.9803761
19.01716	159.8739	-0.9876379
19.08216	159.8734	-0.9946899
19.14716	159.8736	-1.001255
19.21050	159.8726	-1.007142
19.27550	159.8725	-1.013119
19.34050	159.8717	-1.018722
19.40550	159.8715	-1.023892
19.46883	159.8712	-1.028626
19.53383	159.8696	-1.033142
19.59883	159.8702	-1.037857
19.66217	159.8698	-1.042606
19.72716	159.8698	-1.047462
19.79216	159.8694	-1.052725
19.85550	159.8695	-1.058074
19.92050	159.8687	-1.063675
19.98550	159.8696	-1.069623
20.04883	159.8696	-1.075311
20.11383	159.8701	-1.080930
20.17883	159.8695	-1.086328
20.24216	159.8692	-1.091000
20.30716	159.8698	-1.095051
20.37216	159.8690	-1.098984
20.43550	159.8683	-1.102629
20.50050	159.8686	-1.106338
20.56550	159.8683	-1.109875
20.63050	159.8680	-1.113212
20.69383	159.8683	-1.116611
20.75883	159.8677	-1.119993
20.82383	159.8675	-1.123081
20.88716	159.8669	-1.125768
20.95216	159.8674	-1.128973
21.01716	159.8669	-1.132064
21.08050	159.8667	-1.135266
21.14550	159.8670	-1.138384
21.21050	159.8665	-1.141703
21.27383	159.8661	-1.144576
21.33883	159.8659	-1.146875
21.40383	159.8651	-1.148627
21.46716	159.8651	-1.150383
21.53216	159.8650	-1.152310
21.59716	159.8647	-1.155051
21.66050	159.8648	-1.157793
21.72550	159.8648	-1.160615
21.79050	159.8649	-1.163285
21.85383	159.8645	-1.165815
21.91883	159.8646	-1.168084
21.98383	159.8643	-1.170675
22.04883	159.8655	-1.173612
22.11216	159.8648	-1.176641
22.17717	159.8650	-1.179812
22.24216	159.8648	-1.182967
22.30550	159.8651	-1.185618
22.37050	159.8651	-1.188160
22.43550	159.8649	-1.190751
22.49883	159.8648	-1.193180
22.56383	159.8649	-1.195452
22.62883	159.8652	-1.197436
22.69216	159.8649	-1.199252
22.75716	159.8653	-1.200791
22.82216	159.8646	-1.202493
22.88550	159.8646	-1.203919
22.95050	159.8644	-1.204992
23.01550	159.8636	-1.205535
23.07883	159.8636	-1.205918
23.14383	159.8631	-1.206417
23.20883	159.8633	-1.206719
23.27383	159.8623	-1.207327
23.33716	159.8638	-1.208591
23.40216	159.8632	-1.210545
23.46716	159.8627	-1.212698
23.53050	159.8636	-1.214901
23.59550	159.8633	-1.217060
23.66050	159.8636	-1.219204
23.72383	159.8640	-1.221203
23.78883	159.8639	-1.223302
23.85383	159.8631	-1.225280
23.91716	159.8635	-1.227006
23.98216	159.8633	-1.228521
24.04716	159.8639	-1.229846
24.11050	159.8630	-1.230932
24.17550	159.8636	-1.232108
24.24050	159.8626	-1.233166
24.30383	159.8627	-1.233892
24.36883	159.8624	-1.234321
24.43383	159.8619	-1.234648
24.49716	159.8620	-1.234784
24.56216	159.8624	-1.235456
24.62716	159.8622	-1.236417
24.69216	159.8627	-1.237830
24.75550	159.8626	-1.239803
24.82050	159.8630	-1.241822
24.88550	159.8630	-1.243819
24.94883	159.8633	-1.245729
25.01383	159.8632	-1.247579
25.07883	159.8628	-1.248456
25.14216	159.8622	-1.249050
25.20717	159.8628	-1.249952
25.27216	159.8624	-1.251388
25.33550	159.8624	-1.252288
25.40050	159.8626	-1.253148
25.46550	159.8622	-1.253498
25.52883	159.8621	-1.253563
25.59383	159.8618	-1.253534
25.65883	159.8613	-1.253741
25.72216	159.8616	-1.253972
25.78717	159.8617	-1.254699
25.85217	159.8611	-1.255606
25.91716	159.8624	-1.256721
25.98050	159.8614	-1.258276
26.04550	159.8619	-1.259300
26.11050	159.8616	-1.260163
26.17383	159.8616	-1.261023
26.23883	159.8620	-1.262354
26.30383	159.8618	-1.263755
26.36716	159.8614	-1.265084
26.43216	159.8614	-1.266181
26.49716	159.8609	-1.267055
26.56050	159.8608	-1.266893
26.62550	159.8605	-1.266630
26.69050	159.8604	-1.266570
26.75383	159.8616	-1.266781
26.81883	159.8606	-1.267464
26.88383	159.8611	-1.268064
26.94717	159.8604	-1.269074
27.01216	159.8610	-1.270251
27.07717	159.8607	-1.271093
27.14050	159.8611	-1.272284
27.20550	159.8606	-1.273535
27.27050	159.8606	-1.274797
27.33550	159.8608	-1.276100
27.39883	159.8615	-1.277128
27.46383	159.8614	-1.278397
27.52883	159.8612	-1.279692
27.59216	159.8612	-1.280475
27.65716	159.8606	-1.280806
27.72216	159.8613	-1.281243
27.78550	159.8609	-1.280983
27.85050	159.8602	-1.280722
27.91550	159.8607	-1.280518
27.97883	159.8606	-1.280512
28.04383	159.8608	-1.280852
28.10883	159.8601	-1.281758
28.17216	159.8616	-1.282936
28.23716	159.8612	-1.284142
28.30217	159.8610	-1.285188
28.36550	159.8608	-1.286554
28.43050	159.8610	-1.287490
28.49550	159.8617	-1.288214
28.56050	159.8604	-1.288803
28.62383	159.8612	-1.289055
28.68883	159.8609	-1.289100
28.75383	159.8611	-1.288936
28.81716	159.8612	-1.288871
28.88216	159.8611	-1.288764
28.94717	159.8600	-1.288608
29.01050	159.8600	-1.288249
29.07550	159.8602	-1.288186
29.14050	159.8601	-1.288144
29.20383	159.8604	-1.288880
29.26883	159.8598	-1.289408
29.33383	159.8601	-1.290069
29.39716	159.8604	-1.290728
29.46216	159.8605	-1.291464
29.52717	159.8602	-1.292385
29.59050	159.8609	-1.293552
29.65550	159.8603	-1.294966
29.72050	159.8606	-1.296198
29.78383	159.8608	-1.297334
29.84883	159.8602	-1.298184
29.91383	159.8607	-1.298933
29.97883	159.8609	-1.299241
30.04216	159.8604	-1.299179
30.10716	159.8599	-1.298546
30.17216	159.8599	-1.298057
30.23550	159.8599	-1.297582
30.30050	159.8605	-1.297643
30.36550	159.8603	-1.297854
30.42883	159.8600	-1.298035
30.49383	159.8599	-1.298477
30.55883	159.8604	-1.298905
30.62216	159.8600	-1.299028
30.68717	159.8600	-1.299399
30.75217	159.8600	-1.299947
30.81550	159.8601	-1.300552
30.88050	159.8604	-1.301239
30.94550	159.8605	-1.302152
31.00883	159.8614	-1.303148
31.07383	159.8617	-1.303966
31.13883	159.8609	-1.305132
31.20383	159.8614	-1.306108
31.26716	159.8612	-1.306764
31.33216	159.8608	-1.307068
31.39716	159.8601	-1.306919
31.46050	159.8604	-1.306769
31.52550	159.8605	-1.306743
31.59050	159.8603	-1.306772
31.65383	159.8602	-1.306830
31.71883	159.8611	-1.306788
31.78383	159.8607	-1.306959
31.84716	159.8602	-1.306787
31.91217	159.8604	-1.306588
31.97717	159.8611	-1.306922
32.04050	159.8599	-1.307331
32.10550	159.8602	-1.307364
32.17050	159.8591	-1.306838
32.23383	159.8597	-1.306525
32.29883	159.8595	-1.306279
32.36383	159.8595	-1.306321
32.42717	159.8599	-1.306564
32.49216	159.8592	-1.306777
32.55716	159.8597	-1.307110
32.62216	159.8592	-1.307160
32.68550	159.8592	-1.307455
32.75050	159.8593	-1.308048
32.81550	159.8602	-1.309162
32.87883	159.8598	-1.310432
32.94383	159.8599	-1.311666
33.00883	159.8604	-1.313031
33.07217	159.8600	-1.314456
33.13716	159.8606	-1.315538
33.20216	159.8604	-1.316364
33.26550	159.8601	-1.316825
33.33050	159.8610	-1.317293
33.39550	159.8601	-1.317383
33.45883	159.8602	-1.316999
33.52383	159.8599	-1.316394
33.58883	159.8597	-1.315404
33.65216	159.8595	-1.314596
33.71716	159.8598	-1.314340
33.78216	159.8604	-1.314804
33.84716	159.8603	-1.315520
33.91050	159.8597	-1.315994
33.97550	159.8600	-1.316848
34.04050	159.8596	-1.317158
34.10383	159.8607	-1.317724
34.16883	159.8602	-1.318170
34.23383	159.8599	-1.318232
34.29716	159.8600	-1.318424
34.36217	159.8603	-1.318423
34.42717	159.8600	-1.318681
34.49050	159.8593	-1.318442
34.55550	159.8592	-1.317951
34.62050	159.8596	-1.317470
34.68384	159.8587	-1.316864
34.74883	159.8590	-1.316576
34.81383	159.8596	-1.316386
34.87717	159.8594	-1.316212
34.94216	159.8587	-1.316394
35.00716	159.8590	-1.316838
35.07050	159.8588	-1.317746
35.13550	159.8596	-1.319052
35.20050	159.8599	-1.320216
35.26550	159.8594	-1.321144
35.32883	159.8592	-1.321637
35.39383	159.8593	-1.321997
35.45883	159.8594	-1.322028
35.52217	159.8583	-1.322051
35.58716	159.8587	-1.321964
35.65216	159.8591	-1.321839
35.71550	159.8589	-1.321828
35.78050	159.8594	-1.322018
35.84550	159.8589	-1.322296
35.90883	159.8592	-1.322716
35.97383	159.8594	-1.323026
36.03883	159.8596	-1.323733
36.10217	159.8596	-1.324441
36.16716	159.8596	-1.325280
36.23216	159.8597	-1.325814
36.29550	159.8600	-1.326126
36.36050	159.8590	-1.326116
36.42550	159.8589	-1.325809
36.49050	159.8590	-1.325682
36.55383	159.8598	-1.325737
36.61883	159.8598	-1.325742
36.68384	159.8595	-1.325526
36.74716	159.8598	-1.325477
36.81216	159.8596	-1.325628
36.87717	159.8597	-1.326202
36.94050	159.8601	-1.326678
37.00550	159.8595	-1.327240
37.07050	159.8601	-1.327664
37.13383	159.8596	-1.327767
37.19883	159.8596	-1.327842
37.26383	159.8600	-1.327868
37.32717	159.8589	-1.327812
37.39216	159.8600	-1.327820
37.45716	159.8604	-1.327703
37.52050	159.8593	-1.327434
37.58550	159.8599	-1.327175
37.65050	159.8598	-1.327029
37.71383	159.8599	-1.327339
37.77883	159.8596	-1.327500
37.84384	159.8595	-1.327535
37.90883	159.8597	-1.327327
37.97217	159.8596	-1.327360
38.03717	159.8591	-1.327700
38.10217	159.8600	-1.328203
38.16550	159.8600	-1.328906
38.23050	159.8594	-1.329276
38.29550	159.8596	-1.329874
38.35883	159.8601	-1.330311
38.42383	159.8593	-1.330609
38.48883	159.8594	-1.330574
38.55217	159.8591	-1.330200
38.61716	159.8594	-1.330060
38.68216	159.8597	-1.330400
38.74550	159.8594	-1.330617
38.81050	159.8601	-1.330902
38.87550	159.8598	-1.331153
38.93883	159.8591	-1.331357
39.00383	159.8592	-1.331494
39.06883	159.8589	-1.331179
39.13383	159.8591	-1.331187
39.19717	159.8599	-1.331554
39.26216	159.8596	-1.331849
39.32717	159.8595	-1.331922
39.39050	159.8598	-1.332084
39.45550	159.8597	-1.332224
39.52050	159.8595	-1.332366
39.58383	159.8602	-1.332473
39.64883	159.8599	-1.333022
39.71383	159.8605	-1.333639
39.77716	159.8589	-1.334109
39.84216	159.8596	-1.333868
39.90716	159.8594	-1.333337
39.97050	159.8588	-1.332626
40.03550	159.8591	-1.332363
40.10050	159.8590	-1.332207
40.16383	159.8596	-1.332298
40.22883	159.8594	-1.332612
40.29383	159.8590	-1.333285
40.35716	159.8588	-1.333956
40.42216	159.8594	-1.334684
40.48717	159.8595	-1.335293
40.55217	159.8600	-1.336418
40.61550	159.8598	-1.337082
40.68050	159.8593	-1.337294
40.74550	159.8600	-1.336988
40.80883	159.8596	-1.336410
40.87383	159.8589	-1.335939
40.93883	159.8594	-1.335443
41.00217	159.8587	-1.334781
41.06717	159.8593	-1.334320
41.13217	159.8592	-1.333980
41.19550	159.8592	-1.333655
41.26050	159.8584	-1.333978
41.32550	159.8590	-1.334158
41.38883	159.8587	-1.334631
41.45383	159.8578	-1.334749
41.51883	159.8592	-1.334819
41.58217	159.8587	-1.335090
41.64717	159.8582	-1.335165
41.71216	159.8587	-1.335312
41.77716	159.8593	-1.335484
41.84050	159.8592	-1.335692
41.90550	159.8592	-1.336198
41.97050	159.8590	-1.336769
42.03383	159.8592	-1.337241
42.09883	159.8593	-1.337349
42.16383	159.8596	-1.337198
42.22717	159.8594	-1.337478
42.29217	159.8602	-1.337956
42.35717	159.8593	-1.338619
42.42050	159.8596	-1.339587
42.48550	159.8588	-1.340142
42.55050	159.8591	-1.339949
42.61383	159.8595	-1.339675
42.67883	159.8593	-1.339182
42.74383	159.8602	-1.338916
42.80717	159.8591	-1.338953
42.87216	159.8599	-1.338761
42.93716	159.8598	-1.338618
43.00050	159.8588	-1.338695
43.06550	159.8594	-1.339103
43.13050	159.8599	-1.339681
43.19550	159.8594	-1.339942
43.25883	159.8590	-1.339801
43.32383	159.8588	-1.339097
43.38883	159.8584	-1.338341
43.45216	159.8587	-1.337819
43.51717	159.8593	-1.337443
43.58217	159.8589	-1.337524
43.64550	159.8584	-1.337674
43.71050	159.8576	-1.337091
43.77550	159.8579	-1.336651
43.83883	159.8578	-1.336301
43.90383	159.8578	-1.336464
43.96884	159.8580	-1.336846
44.03217	159.8582	-1.337101
44.09716	159.8584	-1.337545
44.16217	159.8580	-1.338011
44.22550	159.8587	-1.338535
44.29050	159.8585	-1.339075
44.35550	159.8590	-1.339746
44.42050	159.8589	-1.340254
44.48383	159.8596	-1.340924
44.54883	159.8592	-1.341690
44.61383	159.8592	-1.342565
44.67717	159.8601	-1.343421
44.74216	159.8600	-1.344228
44.80717	159.8603	-1.344898
44.87050	159.8607	-1.345152
44.93550	159.8600	-1.345290
45.00050	159.8603	-1.345344
45.06383	159.8604	-1.345267
45.12883	159.8600	-1.345098
45.19383	159.8596	-1.344504
45.25717	159.8595	-1.344196
45.32217	159.8599	-1.344124
45.38716	159.8603	-1.344029
45.45050	159.8597	-1.344076
45.51550	159.8595	-1.344348
45.58050	159.8601	-1.344578
45.64383	159.8604	-1.344583
45.70883	159.8601	-1.344263
45.77383	159.8598	-1.343714
45.83883	159.8595	-1.343052
45.90216	159.8589	-1.342315
45.96717	159.8597	-1.341344
46.03217	159.8593	-1.340635
46.09550	159.8596	-1.340134
46.16050	159.8591	-1.339970
46.22550	159.8589	-1.340035
46.28883	159.8589	-1.340123
46.35383	159.8593	-1.340377
46.41883	159.8588	-1.340674
46.48217	159.8590	-1.340787
46.54716	159.8589	-1.340985
46.61217	159.8586	-1.341108
46.67550	159.8588	-1.341340
46.74050	159.8596	-1.341741
46.80550	159.8581	-1.341956
46.86883	159.8588	-1.342190
46.93383	159.8594	-1.342616
46.99883	159.8592	-1.342770
47.06383	159.8587	-1.343007
47.12717	159.8598	-1.343340
47.19217	159.8595	-1.343864
47.25717	159.8593	-1.344091
47.32050	159.8598	-1.344602
47.38550	159.8591	-1.345169
47.45050	159.8598	-1.345569
47.51383	159.8604	-1.345786
47.57883	159.8588	-1.345517
47.64383	159.8590	-1.344921
47.70717	159.8591	-1.344020
47.77217	159.8590	-1.343441
47.83716	159.8589	-1.342562
47.90050	159.8590	-1.342007
47.96550	159.8590	-1.342024
48.03050	159.8586	-1.342107
48.09384	159.8588	-1.342557
48.15883	159.8586	-1.343086
48.22383	159.8589	-1.343589
48.28717	159.8593	-1.344244
48.35217	159.8584	-1.344796
48.41716	159.8590	-1.345241
48.48217	159.8587	-1.345707
48.54550	159.8586	-1.346054
48.61050	159.8588	-1.346161
48.67550	159.8590	-1.346281
48.73883	159.8596	-1.346290
48.80383	159.8588	-1.346202
48.86883	159.8594	-1.346510
48.93217	159.8591	-1.346966
48.99716	159.8593	-1.347454
49.06216	159.8599	-1.348056
49.12550	159.8599	-1.348572
49.19050	159.8600	-1.348798
49.25550	159.8600	-1.349066
49.31883	159.8591	-1.349263
49.38383	159.8598	-1.349099
49.44883	159.8597	-1.348847
49.51216	159.8595	-1.348614
49.57717	159.8592	-1.348335
49.64217	159.8594	-1.347983
49.70717	159.8600	-1.347913
49.77050	159.8594	-1.348052
49.83550	159.8598	-1.348083
49.90050	159.8597	-1.347940
49.96383	159.8596	-1.347775
50.02883	159.8594	-1.347377
50.09384	159.8580	-1.346942
50.15717	159.8586	-1.346570
50.22217	159.8591	-1.346288
50.28717	159.8579	-1.345922
50.35050	159.8587	-1.345452
50.41550	159.8579	-1.345204
50.48050	159.8588	-1.344815
50.54383	159.8580	-1.344565
50.60883	159.8588	-1.344483
50.67383	159.8595	-1.345034
50.73717	159.8596	-1.345919
50.80217	159.8592	-1.346897
50.86716	159.8582	-1.348016
50.93050	159.8598	-1.349072
50.99550	159.8595	-1.350159
51.06050	159.8594	-1.350824
51.12550	159.8592	-1.351089
51.18883	159.8595	-1.351377
51.25383	159.8589	-1.350920
51.31884	159.8585	-1.349969
51.38217	159.8586	-1.349053
51.44717	159.8588	-1.348466
51.51216	159.8572	-1.347782
51.57550	159.8579	-1.347310
51.64050	159.8579	-1.346562
51.70550	159.8575	-1.345935
51.76884	159.8578	-1.345431
51.83383	159.8576	-1.345326
51.89883	159.8572	-1.345447
51.96216	159.8577	-1.345730
52.02717	159.8569	-1.346309
52.09217	159.8577	-1.346836
52.15550	159.8576	-1.347426
52.22050	159.8563	-1.348000
52.28550	159.8569	-1.348561
52.35050	159.8571	-1.348956
52.41383	159.8580	-1.349417
52.47883	159.8575	-1.349849
52.54382	159.8579	-1.350206
52.60717	159.8585	-1.350653
52.67217	159.8583	-1.351167
52.73717	159.8584	-1.351778
52.80050	159.8588	-1.352236
52.86550	159.8585	-1.352599
52.93050	159.8591	-1.352974
52.99382	159.8595	-1.353610
53.05883	159.8597	-1.354343
53.12383	159.8602	-1.354923
53.18716	159.8594	-1.355720
53.25217	159.8597	-1.356248
53.31716	159.8611	-1.356789
53.38050	159.8603	-1.356935
53.44550	159.8605	-1.357129
53.51050	159.8604	-1.356887
53.57383	159.8604	-1.356670
53.63882	159.8602	-1.356234
53.70383	159.8606	-1.355418
53.76884	159.8605	-1.354540
53.83217	159.8604	-1.353970
53.89717	159.8605	-1.353256
53.96216	159.8600	-1.352586
54.02550	159.8606	-1.352299
54.09050	159.8605	-1.352350
54.15550	159.8599	-1.352456
54.21884	159.8601	-1.352374
54.28383	159.8604	-1.352174
54.34882	159.8604	-1.352210
54.41216	159.8602	-1.352068
54.47717	159.8605	-1.351975
54.54217	159.8606	-1.351829
54.60550	159.8601	-1.352013
54.67050	159.8599	-1.351719
54.73550	159.8594	-1.351450
54.79883	159.8591	-1.350827
54.86382	159.8590	-1.350000
54.92883	159.8590	-1.349225
54.99382	159.8590	-1.348388
55.05717	159.8590	-1.348291
55.12217	159.8585	-1.348041
55.18716	159.8579	-1.348138
55.25050	159.8588	-1.348701
55.31550	159.8587	-1.349526
55.38050	159.8589	-1.350234
55.44384	159.8589	-1.350931
55.50883	159.8585	-1.351558
55.57383	159.8590	-1.351826
55.63716	159.8588	-1.351892
55.70216	159.8581	-1.351874
55.76716	159.8579	-1.351818
55.83050	159.8581	-1.351887
55.89550	159.8583	-1.352146
55.96050	159.8588	-1.352468
56.02383	159.8589	-1.352849
56.08882	159.8587	-1.352937
56.15383	159.8587	-1.352942
56.21717	159.8591	-1.352953
56.28217	159.8586	-1.353097
56.34716	159.8587	-1.353293
56.41216	159.8586	-1.353569
56.47550	159.8589	-1.353785
56.54050	159.8591	-1.354086
56.60550	159.8586	-1.354369
56.66882	159.8592	-1.354512
56.73383	159.8594	-1.355088
56.79883	159.8594	-1.355354
56.86217	159.8600	-1.355596
56.92717	159.8602	-1.355790
56.99216	159.8599	-1.355937
57.05550	159.8592	-1.356180
57.12050	159.8587	-1.356392
57.18550	159.8587	-1.355919
57.24883	159.8591	-1.355302
57.31382	159.8588	-1.354559
57.37883	159.8587	-1.353675
57.44216	159.8587	-1.352854
57.50717	159.8588	-1.352384
57.57217	159.8586	-1.352139
57.63716	159.8584	-1.352159
57.70050	159.8581	-1.352200
57.76550	159.8584	-1.352358
57.83050	159.8578	-1.352531
57.89384	159.8579	-1.352486
57.95883	159.8576	-1.352197
58.02383	159.8580	-1.351812
58.08716	159.8572	-1.351182
58.15217	159.8571	-1.350859
58.21717	159.8578	-1.350937
58.28050	159.8574	-1.351105
58.34550	159.8576	-1.351556
58.41050	159.8584	-1.352063
58.47382	159.8579	-1.352837
58.53882	159.8572	-1.353579
58.60383	159.8578	-1.354166
58.66716	159.8580	-1.354431
58.73217	159.8581	-1.354708
58.79717	159.8589	-1.355014
58.86050	159.8588	-1.355690
58.92550	159.8593	-1.356718
58.99050	159.8589	-1.357451
59.05550	159.8597	-1.358335
59.11882	159.8597	-1.358766
59.18383	159.8595	-1.359082
59.24883	159.8598	-1.359072
59.31216	159.8600	-1.359128
59.37717	159.8599	-1.358854
59.44216	159.8595	-1.358211
59.50550	159.8599	-1.358165
59.57050	159.8598	-1.358101
59.63550	159.8600	-1.357582
59.69883	159.8601	-1.357431
59.76382	159.8600	-1.357292
59.82883	159.8602	-1.357287
59.89216	159.8597	-1.357112
59.95717	159.8599	-1.356684
60.02217	159.8596	-1.356180
60.08550	159.8592	-1.355597
60.15050	159.8599	-1.355104
60.21550	159.8595	-1.354510
60.28050	159.8594	-1.354311
60.34384	159.8596	-1.354541
60.40883	159.8594	-1.355040
60.47382	159.8595	-1.355714
60.53716	159.8594	-1.356516
60.60217	159.8595	-1.357176
60.66716	159.8596	-1.357248
60.73050	159.8590	-1.357250
60.79550	159.8596	-1.357012
60.86050	159.8594	-1.356668
60.92383	159.8596	-1.356710
60.98882	159.8593	-1.356944
61.05383	159.8604	-1.357178
61.11716	159.8599	-1.357444
61.18217	159.8593	-1.357428
61.24717	159.8586	-1.357030
61.31050	159.8587	-1.356515
61.37550	159.8589	-1.356221
61.44050	159.8588	-1.355789
61.50383	159.8586	-1.355216
61.56884	159.8584	-1.354644
61.63383	159.8588	-1.354268
61.69883	159.8583	-1.354027
61.76216	159.8581	-1.353984
61.82717	159.8584	-1.354659
61.89216	159.8582	-1.355127
61.95550	159.8591	-1.355913
62.02050	159.8588	-1.356512
62.08550	159.8591	-1.357011
62.14883	159.8595	-1.357627
62.21382	159.8589	-1.358312
62.27883	159.8594	-1.358953
62.33882	159.8597	-1.359562
62.40383	160.0109	-1.337894
62.46884	160.6504	-3.643462
62.53383	161.4712	-7.794700
62.59716	162.3755	-12.23144
62.66216	163.3742	-16.47798
62.72717	164.4279	-20.17039
62.79050	165.4982	-23.20805
62.85550	166.6325	-25.81058
62.92050	167.7956	-27.97386
62.98383	168.9504	-29.72539
63.04883	170.1561	-31.23286
63.11382	171.3760	-32.51166
63.17717	172.5781	-33.57828
63.24216	173.8214	-34.51742
63.30717	175.0714	-35.32962
63.37050	176.2973	-36.03754
63.43550	177.5596	-36.69100
63.50050	178.8265	-37.28547
63.56382	180.0631	-37.83622
63.62883	181.3353	-38.38753
63.69384	182.6091	-38.92654
63.75717	183.8500	-39.44590
63.82217	185.1268	-39.99071
63.88716	186.4025	-40.53091
63.95216	187.6775	-41.08620
64.01550	188.9199	-41.65140
64.08050	190.1936	-42.25302
64.14550	191.4667	-42.89127
64.20883	192.7056	-43.55688
64.27383	193.9746	-44.28412
64.33884	195.2429	-45.05191
64.40218	196.4755	-45.85328
64.46717	197.7404	-46.73556
64.53217	199.0009	-47.65948
64.59550	200.2266	-48.62500
64.66050	201.4821	-49.67567
64.72551	202.7344	-50.81209
64.78882	203.9520	-51.98289
64.85383	205.1959	-53.31149
64.91884	206.4307	-54.85515
64.98217	207.6230	-56.63360
65.04718	208.8299	-58.87984
65.11217	210.0128	-61.67334
65.17718	211.1682	-65.08207
65.24050	212.2666	-68.97175
65.30550	213.3694	-73.49322
65.37050	214.4495	-78.49570
65.43384	215.4840	-83.75100
65.49884	216.5354	-89.30270
65.56384	217.5992	-94.36662
65.62718	218.7104	-97.29454
65.69218	219.9656	-97.71572
65.75718	221.3209	-96.14078
65.82050	222.7066	-93.41219
65.88550	224.1711	-89.76372
65.95050	225.6694	-85.37101
66.01384	227.1583	-80.48676
66.07884	228.7129	-74.87756
66.14384	230.2776	-69.21484
66.20718	231.7844	-64.23389
66.27218	233.2944	-59.97540
66.33716	234.7662	-56.53144
66.40050	236.1662	-53.86682
66.46550	237.5762	-51.68556
66.53050	238.9627	-49.98192
66.59550	240.3316	-48.64914
66.65884	241.6520	-47.64210
66.72384	242.9962	-46.83492
66.78882	244.3308	-46.21224
66.85218	245.6252	-45.72836
66.91718	246.9487	-45.34567
66.98218	248.2668	-45.04141
67.04550	249.5475	-44.80908
67.11050	250.8598	-44.63696
67.17550	252.1706	-44.51730
67.23882	253.4451	-44.42922
67.30384	254.7520	-44.35626
67.36884	256.0592	-44.32008
67.43218	257.3301	-44.31272
67.49718	258.6350	-44.30804
67.56216	259.9386	-44.30852
67.62550	261.2082	-44.31926
67.69050	262.5116	-44.34422
67.75550	263.8142	-44.39780
67.82050	265.1160	-44.44900
67.88384	266.3848	-44.50856
67.94884	267.6867	-44.57187
68.01384	268.9879	-44.64178
68.07718	270.2549	-44.73104
68.14216	271.5542	-44.82558
68.20718	272.8520	-44.97493
68.27050	274.1149	-45.17524
-2.000000	3.000000	0.0000000
68.39384	276.3707	-45.79278
68.45884	276.4575	-40.95471
68.52384	276.1200	-31.16896
68.58716	275.5764	-20.55713
68.65218	274.8770	-10.50144
68.71718	274.0588	-1.949245
68.78050	273.1760	4.946313
68.84550	272.1961	10.73611
68.91050	271.1582	15.44010
68.97384	270.1010	19.16892
69.03882	268.9788	22.28543
69.10384	267.8250	24.82592
69.16718	266.6773	26.84809
69.23218	265.4776	28.54697
69.29718	264.2614	29.93282
69.36050	263.0629	31.04817
69.42550	261.8216	31.98518
69.49050	260.5726	32.75347
69.55384	259.3456	33.36534
69.61884	258.0819	33.88004
69.68384	256.8127	34.31033
69.74884	255.5383	34.65984
69.81216	254.2932	34.95112
69.87718	253.0125	35.19519
69.94218	251.7304	35.39712
70.00550	250.4782	35.55288
70.07050	249.1914	35.68702
70.13550	247.9038	35.80343
70.19884	246.6473	35.89414
70.26384	245.3576	35.96250
70.32884	244.0660	36.01782
70.39216	242.8082	36.04576
70.45718	241.5154	36.06829
70.52218	240.2235	36.08635
70.58550	238.9642	36.10431
70.65050	237.6704	36.12106
70.71550	236.3779	36.13612
70.77884	235.1173	36.14625
70.84384	233.8224	36.15267
70.90884	232.5289	36.15502
70.97384	231.2350	36.15152
71.03718	229.9733	36.14736
71.10218	228.6792	36.14108
71.16718	227.3843	36.13666
71.23050	226.1229	36.13378
71.29550	224.8280	36.13156
71.36050	223.5330	36.13067
71.42384	222.2700	36.12686
71.48882	220.9748	36.11961
71.55384	219.6789	36.10980
71.61718	218.4165	36.10150
71.68218	217.1217	36.08572
71.74718	215.8259	36.07026
71.81050	214.5632	36.05454
71.87550	213.2678	36.03215
71.94050	211.9724	36.01166
72.00384	210.7099	35.99751
72.06884	209.4145	35.98311
72.13384	208.1186	35.96283
72.19718	206.8558	35.94105
72.26218	205.5603	35.91974
72.32718	204.2642	35.89528
72.39216	202.9685	35.87472
72.45550	201.7058	35.84331
72.52050	200.4094	35.81652
72.58550	199.1131	35.79213
72.64884	197.8507	35.76996
72.71384	196.5544	35.74350
72.77884	195.2583	35.72097
72.84216	193.9956	35.70515
72.90718	192.7002	35.68584
72.97218	191.4038	35.66296
73.03550	190.1408	35.63890
73.10050	188.8449	35.60450
73.16550	187.5489	35.57608
73.22884	186.2864	35.54672
73.29384	184.9900	35.52410
73.35884	183.6943	35.49202
73.42218	182.4300	35.46878
73.48718	181.1337	35.43640
73.55218	179.8375	35.41057
73.61718	178.5395	35.39984
73.68050	177.2764	35.38988
73.74550	175.9799	35.37769
73.81050	174.6835	35.36650
73.87384	173.4199	35.35387
73.93884	172.1241	35.33070
74.00384	170.8262	35.31228
74.06718	169.5634	35.29286
74.13218	168.2688	35.28713
74.19718	166.9757	35.32884
74.26050	165.7208	35.51469
74.32550	164.4420	35.93485
74.39050	163.1868	36.93948
74.45384	162.0106	39.07900
74.51882	160.8902	43.20850
74.58384	159.8802	49.61124
74.64718	158.9814	57.30525
74.71218	158.0813	65.19945
74.77718	157.1315	71.69121
74.84050	156.1135	75.94736
74.90550	154.9552	78.01819
74.97050	153.6909	78.00198
75.03550	152.3373	76.29004
75.09882	150.9530	73.49176
75.16382	149.4909	69.89030
75.22884	148.0054	65.97563
75.29218	146.5553	62.17317
75.35718	145.0742	58.51280
75.42218	143.6102	55.21850
75.48550	142.2026	52.40388
75.55050	140.7786	49.91089
75.61550	139.3723	47.77309
75.67884	138.0171	45.99586
75.74384	136.6403	44.42512
75.80884	135.2738	43.08496
75.87218	133.9540	41.96250
75.93718	132.6064	40.98144
76.00218	131.2672	40.12964
76.06550	129.9675	39.40936
76.13050	128.6386	38.77147
76.19550	127.3136	38.21087
76.26050	125.9912	37.70141
76.32384	124.6956	37.06425
76.38884	123.3803	36.67791
76.45384	122.0667	36.31754
76.51716	120.7885	35.99719
76.58218	119.4762	35.67268
76.64718	118.1655	35.40813
76.71050	116.8906	35.16806
76.77550	115.5828	34.93324
76.84050	114.2766	34.70770
76.90384	112.9986	34.38798
76.96884	111.6809	33.98027
77.03384	110.3735	33.76644
77.09718	109.0998	33.52044
77.16218	107.7924	33.29510
77.22718	106.4854	33.06385
77.29050	105.2105	32.82380
77.35550	103.9029	32.59722
77.42050	102.5965	32.40615
77.48384	101.3245	32.21841
77.54884	100.0182	31.99466
77.61384	98.71082	31.80090
77.67884	97.40534	31.63710
77.74218	96.13418	31.47335
77.80718	94.82906	31.31568
77.87218	93.52606	31.16967
77.93550	92.25574	31.03206
78.00050	90.95382	30.90464
78.06550	89.65234	30.77074
78.12884	88.44932	31.90370
78.19384	87.13728	31.49205
78.25884	85.82600	31.20947
78.32218	84.54969	30.96470
78.38718	83.24139	30.73537
78.45216	81.93554	30.54223
78.51550	80.66218	30.36060
78.58050	79.35669	30.19600
78.64550	78.05015	30.02137
78.70884	76.77906	29.86082
78.77384	75.47398	29.71368
78.83884	74.17049	29.57024
78.90384	72.86705	29.41713
78.96718	71.59697	29.28256
79.03218	70.29322	29.14547
79.09718	68.98889	29.00339
79.16050	67.71839	28.86950
79.22551	66.41550	28.71901
79.29050	65.11156	28.58413
79.35384	63.84121	28.44645
79.41884	62.53780	28.29502
79.48384	61.23387	28.13965
79.54718	59.96438	27.99451
79.61218	58.66118	27.85464
79.67718	57.35800	27.70929
79.74050	56.08707	27.57344
79.80550	54.78373	27.43190
79.87050	53.47953	27.29329
79.93384	52.20998	27.14558
79.99884	50.90634	27.00438
80.06384	49.60440	26.86116
80.12718	48.33292	26.72713
80.19218	47.02870	26.55982
80.25718	45.72146	26.36737
80.32218	44.41608	26.22208
80.38550	43.14504	26.07279
80.45050	41.84045	25.92348
80.51550	40.53578	25.76466
80.57884	39.26164	25.58130
80.64384	37.95762	25.45213
80.70884	36.65375	25.27871
80.77218	35.38347	25.14157
80.83716	34.07922	25.00884
80.90218	32.77604	24.87661
80.96550	31.50596	24.73932
81.03050	30.20244	24.60363
81.09550	28.89696	24.45594
81.15884	27.62568	24.29390
81.22384	26.31841	24.12631
81.28882	25.01260	23.94563
81.34882	23.80670	23.76736
81.41382	22.98553	23.68576
81.47884	23.04948	19.82297
81.54218	23.42933	13.96435
81.60718	24.03424	7.586592
81.67218	24.79388	1.833726
81.73718	25.67146	-3.032615
81.80050	26.61182	-6.913930
81.86550	27.64552	-10.12230
81.93050	28.73300	-12.68953
81.99384	29.83235	-14.69386
82.05884	30.99338	-16.35442
82.12384	32.17922	-17.69692
82.18718	33.35472	-18.76868
82.25218	34.57758	-19.68184
82.31718	35.81242	-20.43994
82.38050	37.02569	-21.07448
82.44550	38.27924	-21.63667
82.51050	39.53956	-22.11506
82.57384	40.77190	-22.52416
82.63884	42.04167	-22.90123
82.70382	43.31552	-23.23987
82.76718	44.55792	-23.54287
82.83218	45.83672	-23.82949
82.89718	47.11759	-24.09606
82.96050	48.36941	-24.33741
83.02550	49.65642	-24.52362
83.09050	50.94600	-24.69640
83.15550	52.23630	-24.86523
83.21884	53.49489	-25.01834
83.28384	54.78604	-25.17326
83.34882	56.07888	-25.32006
83.41218	57.33870	-25.46756
83.47718	58.63278	-25.61790
83.54218	59.92654	-25.75972
83.60550	61.18762	-25.90408
83.67050	62.48229	-26.05825
83.73550	63.77877	-26.20630
83.79884	65.04082	-26.33115
83.86384	66.33611	-26.46125
83.92882	67.63153	-26.60407
83.99218	68.89370	-26.73224
84.05718	70.18965	-26.86986
84.12218	71.48594	-27.00045
84.18550	72.74806	-27.13820
84.25050	74.04370	-27.27392
84.31551	75.33910	-27.40932
84.38050	76.63412	-27.54389
84.44384	77.89656	-27.68398
84.50884	79.19141	-27.82796
84.57384	80.48706	-27.97234
84.63718	81.75000	-28.11882
84.70216	83.04584	-28.26516
84.76718	84.34113	-28.40959
84.83051	85.60489	-28.55837
84.89551	86.89968	-28.70906
84.96051	88.19520	-28.85649
85.02384	89.45770	-29.00350
85.08884	90.75445	-29.16728
85.15384	92.05063	-29.31428
85.21718	93.31366	-29.45696
85.28218	94.60949	-29.60066
85.34718	95.90497	-29.74966
85.41050	97.16843	-29.89211
85.47551	98.46489	-30.03024
85.54051	99.76118	-30.17375
85.60382	101.0236	-30.31912
85.66884	102.3193	-30.47096
85.73382	103.6160	-30.61283
85.79884	104.9124	-30.76176
85.86218	106.1752	-30.91305
85.92718	107.4711	-31.06384
85.99218	108.7671	-31.21269
86.05549	110.0300	-31.36110
86.12051	111.3264	-31.51823
86.18550	112.6224	-31.66894
86.24884	113.8845	-31.81528
86.31384	115.1805	-31.95792
86.37882	116.4770	-32.12242
86.44218	117.7390	-32.26443
86.50718	119.0341	-32.42633
86.57218	120.3295	-32.59160
86.63550	121.5906	-32.76338
86.70050	122.8870	-32.94037
86.76551	124.1815	-33.10472
86.82884	125.4434	-33.26974
86.89384	126.7389	-33.43228
86.95882	128.0339	-33.59626
87.02384	129.3291	-33.76047
87.08718	130.5920	-33.92465
87.15218	131.8876	-34.10503
87.21718	133.1822	-34.27920
87.28051	134.4434	-34.45506
87.34551	135.7371	-34.64392
87.41050	137.0314	-34.83765
87.47384	138.2924	-35.03490
87.53882	139.5860	-35.24278
87.60382	140.8780	-35.45504
87.66718	142.1389	-35.66403
87.73218	143.4330	-35.88846
87.79718	144.7245	-36.11418
87.86051	145.9837	-36.32748
87.92551	147.2766	-36.55454
87.99051	148.5688	-36.78320
88.05382	149.8280	-37.00336
88.11884	151.1191	-37.22985
88.18384	152.4116	-37.46387
88.24718	153.6701	-37.70364
88.31218	154.9624	-37.95360
88.37718	156.2535	-38.21243
88.44218	157.5450	-38.47413
88.50551	158.8035	-38.73698
88.57050	160.0944	-39.00110
88.63550	161.3856	-39.26926
88.69884	162.6444	-39.52384
88.76384	163.9370	-39.76606
88.82884	165.2312	-39.98586
88.89218	166.4924	-40.15800
88.95718	167.7884	-40.31408
89.02218	169.0858	-40.43452
89.08551	170.3507	-40.53442
89.15051	171.6490	-40.65465
89.21551	172.9478	-40.78019
89.27884	174.2125	-40.90860
89.34384	175.5088	-41.05620
89.40884	176.8044	-41.23394
89.47218	178.0647	-41.42925
89.53718	179.3570	-41.67825
89.60218	180.6464	-41.96547
89.66718	181.9352	-42.30145
89.73050	183.1888	-42.67913
89.79550	184.4720	-43.12133
89.86051	185.7529	-43.62556
89.92384	186.9976	-44.16924
89.98882	188.2723	-44.81870
90.05382	189.5434	-45.55765
90.11718	190.7766	-46.39665
90.18218	192.0372	-47.36220
90.24718	193.2915	-48.44861
90.31050	194.5105	-49.59878
90.37550	195.7558	-50.83068
90.44051	197.0005	-52.11926
90.50384	198.2109	-53.41804
90.56884	199.4506	-54.81606
90.63384	200.6862	-56.32422
90.69718	201.8851	-57.91730
90.76218	203.1080	-59.70793
90.82718	204.3262	-61.59068
90.89051	205.5111	-63.44254
90.95551	206.7325	-65.21818
91.02050	207.9698	-66.52944
91.08551	209.2454	-66.88794
91.14884	210.5499	-65.76206
91.21384	211.9585	-63.16768
91.27884	213.4125	-59.81949
91.34218	214.8417	-56.38008
91.40718	216.3044	-53.05060
91.47218	217.7469	-50.20900
91.53551	219.1278	-47.94482
91.60050	220.5234	-46.07794
91.66550	221.8994	-44.61594
91.72882	223.2252	-43.49311
91.79384	224.5733	-42.59996
91.85884	225.9117	-41.89255
91.92218	227.2075	-41.37516
91.98718	228.5316	-40.94608
92.05218	229.8511	-40.64507
92.11551	231.1323	-40.42664
92.18051	232.4450	-40.27300
92.24550	233.7544	-40.16867
92.31050	235.0622	-40.10579
92.37384	236.3347	-40.07656
92.43884	237.6392	-40.05518
92.50384	238.9442	-40.05115
92.56718	240.2140	-40.05063
92.63218	241.5173	-40.06439
92.69718	242.8196	-40.11872
92.76051	244.0876	-40.17558
92.82550	245.3896	-40.22903
92.89051	246.6904	-40.29411
92.95382	247.9586	-40.34366
93.01882	249.2598	-40.39932
93.08384	250.5606	-40.46062
93.14718	251.8291	-40.52983
93.21218	253.1298	-40.59277
93.27718	254.4320	-40.65932
93.34051	255.6990	-40.71599
93.40551	257.0002	-40.80020
93.47051	258.2998	-40.86856
93.53384	259.5664	-40.94864
93.59882	260.8664	-41.03052
93.66382	262.1650	-41.12752
93.72882	263.4662	-41.21902
93.79218	264.7331	-41.29989
93.85718	266.0327	-41.38581
93.92218	267.3340	-41.46616
93.98551	268.6006	-41.54713
94.05051	269.9002	-41.62755
94.11551	271.2010	-41.68788
-2.000000	5.000000	0.0000000