File: 3-C1(1.0mol%)+C20(0.6mol%)/matlab/170-1
CLOSED
Version	1.0
Language	English
Mode	Standard
Run	10
RunSerial	11791
Instrument	DSC Q2000 V24.11 Build 124
Module	DSC Standard Cell RC
Operator	Nan
File	\\Ae520-1454\ta\Data\DSC\UQ Composites\Nan\C1(4.5)+C20P(3)+CL(HotplateMixtureAB)\.5)+C20P(3)+CL(HotplateMixtureAB)\Iso160_60Min_3
ProcName	H/C/H/C/H complete wood PHA
InstSerial	2000-0883
AutoSerial	1293
Sample	Iso170_60Min
Size	48.5000	mg
PanMass	Not available
PanResist	Automatic Automatic  K/W
PanFactor	Default Default
Method	H/C/H/C/H complete wood PHA
Comment
Xcomment	Pan: Tzero Aluminum Hermetic
Xcomment	Gas1: Nitrogen 50.0 ml/min
Xcomment	Gas2: Nitrogen 50.0 ml/min
Text
Exotherm	UP
Kcell	1.05230
Cpconst	Standard: 0.938
Calib	-38.6961
TempCal	1	pts	157.46	156.60
TzeroDt	-87.6168 -0.0009 -1.4231
TzeroDtz	-87.6168 0.0057 6.9570
InstCalFile	Tzero: \\Ae520-1454\ta\Data\DSC\Calibration\2017\CALIBRATION\1562_RCS (90)_05_18_2017 10_50_44.TZR
InstCalFile	Baseline: \\Ae520-1454\ta\Data\DSC\Calibration\2017\2017-05-17_Calibration.001
InstCalFile	Sapphire: \\Ae520-1454\ta\Data\DSC\Calibration\2017\2017-05-17_Saphire.001
InstCalDate	Tzero 2017-05-18 Time 10:50:44
TempRange	-87.39 to 398.39 °C at 10.00 °C/min Heat Only
AutoZero	Delta T Offset 0.000 uV
AutoZero	Delta T0 Offset 0.000 uV
MultiptCal	0
MultiPtDesc	0) Not set
AutoCellConst	Calibration Date 2017-05-18 16:59:28
Controls	Gas 1  Event Off  Sampling 0.2
Cell#	RC-01562
CoolingUnit	RCS (90)
SelHeatFlow	Heat Flow T4 (mW)
AutoLidII	Installed
AutoAnalysis	Off
MacroFile
Nsig	3
Sig1	Time (min)
Sig2	Temperature (°C)
Sig3	Heat Flow (mW)
Date	2017-06-08
Time	02:38:47
OrgMethod	1: Equilibrate at 20.00 °C
OrgMethod	2: Ramp 60.00 °C/min to 170.00 °C
OrgMethod	3: Mark end of cycle 1
OrgMethod	4: Isothermal for 60.00 min
OrgMethod	5: Mark end of cycle 2
OrgMethod	6: Ramp 20.00 °C/min to 280.00 °C
OrgMethod	7: Mark end of cycle 3
OrgMethod	8: Ramp 20.00 °C/min to 20.00 °C
OrgMethod	9: Mark end of cycle 4
OrgMethod	10: Ramp 20.00 °C/min to 280.00 °C
OrgMethod	11: Mark end of cycle 5
OrgFile	C:\Users\jarra\Desktop\DSC\3-C1(1.0mol%)+C20(0.6mol%)\170-1
StartOfData
4.99994E-4	20.09840	1.188310
0.06550000	20.47625	3.143723
0.1305000	22.63072	5.099730
0.1938333	25.25474	0.4172028
0.2588334	28.21744	-6.600190
0.3221667	31.26435	-13.93809
0.3871667	34.52231	-21.01592
0.4505000	37.79784	-27.17309
0.5155000	41.24371	-32.66213
0.5788334	44.66819	-37.31968
0.6438332	48.23169	-41.67182
0.7088332	51.80740	-46.33066
0.7721668	55.31338	-50.38283
0.8371668	58.92930	-54.84453
0.9005001	62.43354	-59.64672
0.9654999	65.97547	-67.49482
1.028833	68.81666	-85.70319
1.093833	71.46600	-110.8973
1.157166	74.07036	-132.1095
1.222166	76.58688	-158.5612
1.287167	79.06554	-184.2735
1.350500	81.49663	-211.3520
1.415500	84.08482	-232.5920
1.478833	87.16285	-243.9047
1.543833	90.59660	-251.6402
1.607167	94.48837	-249.5354
1.672166	98.54064	-247.2216
1.735500	102.7811	-237.7220
1.800500	107.7691	-214.9252
1.863834	112.7622	-194.7905
1.928833	117.6632	-177.8345
1.993833	122.3583	-164.7792
2.057167	126.7527	-155.4595
2.122166	131.0919	-148.4475
2.185500	135.2298	-143.2825
2.250500	139.4143	-139.0710
2.313833	143.4373	-136.0134
2.378833	147.5014	-134.0510
2.442167	151.4258	-132.5762
2.500500	155.0289	-131.3827
2.565500	158.7166	-130.8998
2.630500	160.8257	-124.6760
2.693833	162.3027	-112.2721
2.758833	163.4716	-98.14594
2.822166	164.3780	-85.64403
2.887167	165.1192	-74.76855
2.950500	165.7063	-65.90682
3.015500	166.1974	-58.51184
3.078833	166.5918	-52.65450
3.143833	166.9262	-47.76004
3.208833	167.2035	-43.79502
3.272167	167.4289	-40.62559
3.337167	167.6232	-37.95164
3.400500	167.7825	-35.80180
3.465500	167.9202	-33.97678
3.528833	168.0342	-32.47737
3.593834	168.1358	-31.16822
3.657167	168.2190	-30.07522
3.722166	168.2941	-29.09716
3.787167	168.3610	-28.21699
3.850500	168.4185	-27.44849
3.915500	168.4725	-26.71383
3.978833	168.5203	-26.05134
4.043833	168.5651	-25.39912
4.107167	168.6071	-24.79518
4.172167	168.6463	-24.18532
4.235500	168.6822	-23.60265
4.300500	168.7199	-23.01006
4.363834	168.7551	-22.42780
4.428833	168.7892	-21.82659
4.493834	168.8236	-21.21505
4.557167	168.8584	-20.59636
4.622166	168.8942	-19.92910
4.685500	168.9298	-19.25836
4.750500	168.9684	-18.52859
4.813834	169.0063	-17.77676
4.878834	169.0484	-16.95720
4.942166	169.0907	-16.11099
5.007167	169.1362	-15.21779
5.072166	169.1818	-14.32200
5.135500	169.2254	-13.45591
5.200500	169.2697	-12.56711
5.263834	169.3137	-11.68781
5.328834	169.3599	-10.75506
5.392168	169.4069	-9.812593
5.457168	169.4552	-8.848530
5.520500	169.5001	-7.933142
5.585500	169.5457	-7.040875
5.650500	169.5877	-6.196705
5.713832	169.6264	-5.427932
5.778834	169.6641	-4.704920
5.842168	169.6962	-4.084914
5.907166	169.7245	-3.539911
5.970500	169.7476	-3.094509
6.035500	169.7684	-2.707086
6.098832	169.7841	-2.383837
6.163832	169.7998	-2.102858
6.227168	169.8122	-1.862801
6.292168	169.8242	-1.639894
6.357168	169.8333	-1.451008
6.420500	169.8423	-1.288233
6.485500	169.8504	-1.136521
6.548834	169.8576	-1.011323
6.613834	169.8644	-0.8873359
6.677168	169.8697	-0.7842136
6.742166	169.8750	-0.6866132
6.805500	169.8794	-0.5997537
6.870500	169.8843	-0.5210728
6.935500	169.8878	-0.4455772
6.998834	169.8912	-0.3776077
7.063834	169.8946	-0.3114124
7.127168	169.8982	-0.2553956
7.192166	169.9015	-0.1953699
7.255500	169.9044	-0.1409016
7.320500	169.9074	-.08967828
7.383832	169.9097	-.03750625
7.448834	169.9130	0.01137523
7.513834	169.9161	0.06391528
7.577168	169.9178	0.1104544
7.642168	169.9207	0.1614662
7.705500	169.9230	0.2119275
7.770500	169.9258	0.2614214
7.833832	169.9283	0.3104860
7.898834	169.9308	0.3622506
7.962168	169.9340	0.4138762
8.027168	169.9366	0.4688282
8.090500	169.9388	0.5180088
8.155500	169.9422	0.5725878
8.220500	169.9444	0.6275187
8.283832	169.9466	0.6823374
8.348832	169.9500	0.7398516
8.412168	169.9531	0.7936116
8.477168	169.9564	0.8529232
8.540500	169.9586	0.9094012
8.605499	169.9616	0.9670278
8.668832	169.9644	1.028579
8.733832	169.9676	1.086299
8.798834	169.9714	1.147125
8.862168	169.9741	1.207272
8.927168	169.9766	1.269588
8.990500	169.9806	1.333652
9.055500	169.9835	1.396330
9.118834	169.9865	1.460499
9.183832	169.9897	1.527232
9.247168	169.9933	1.591486
9.312166	169.9964	1.660518
9.377168	169.9996	1.729174
9.440500	170.0033	1.797951
9.505500	170.0074	1.863361
9.568832	170.0104	1.934815
9.633832	170.0142	2.005347
9.697168	170.0180	2.077663
9.762168	170.0209	2.154214
9.825500	170.0250	2.222280
9.890500	170.0287	2.298661
9.953834	170.0327	2.369390
10.01883	170.0355	2.446342
10.08383	170.0400	2.522221
10.14717	170.0436	2.597786
10.21217	170.0476	2.674925
10.27550	170.0508	2.754607
10.34050	170.0548	2.828320
10.40383	170.0586	2.908410
10.46883	170.0632	2.986262
10.53217	170.0668	3.064535
10.59717	170.0694	3.146506
10.66217	170.0748	3.224604
10.72550	170.0792	3.302407
10.79050	170.0826	3.382548
10.85383	170.0868	3.459785
10.91883	170.0905	3.539354
10.98217	170.0944	3.619305
11.04717	170.0984	3.695618
11.11050	170.1018	3.776814
11.17550	170.1064	3.851703
11.24050	170.1104	3.932100
11.30383	170.1130	4.008308
11.36884	170.1180	4.085428
11.43217	170.1213	4.161885
11.49717	170.1251	4.236170
11.56050	170.1290	4.308682
11.62550	170.1326	4.383434
11.68883	170.1355	4.457997
11.75384	170.1394	4.525644
11.81716	170.1435	4.594504
11.88216	170.1461	4.663518
11.94717	170.1494	4.728860
12.01050	170.1530	4.791154
12.07550	170.1560	4.856832
12.13883	170.1592	4.916094
12.20384	170.1613	4.976636
12.26717	170.1657	5.029570
12.33217	170.1678	5.087289
12.39550	170.1705	5.138113
12.46050	170.1731	5.186219
12.52550	170.1751	5.232593
12.58883	170.1774	5.276650
12.65383	170.1795	5.318930
12.71717	170.1823	5.357338
12.78217	170.1835	5.389574
12.84550	170.1848	5.421937
12.91050	170.1859	5.447220
12.97383	170.1870	5.472220
13.03883	170.1891	5.491180
13.10383	170.1896	5.507606
13.16716	170.1904	5.519582
13.23216	170.1915	5.530206
13.29550	170.1920	5.540260
13.36050	170.1929	5.549980
13.42383	170.1928	5.558385
13.48883	170.1929	5.565082
13.55217	170.1929	5.569746
13.61716	170.1921	5.572131
13.68050	170.1934	5.572051
13.74550	170.1916	5.569685
13.81050	170.1910	5.565097
13.87384	170.1904	5.558346
13.93883	170.1900	5.546785
14.00217	170.1886	5.535845
14.06716	170.1886	5.520414
14.13050	170.1878	5.504199
14.19550	170.1866	5.488874
14.25883	170.1855	5.473570
14.32384	170.1848	5.459429
14.38883	170.1842	5.446020
14.45217	170.1837	5.434280
14.51717	170.1822	5.423145
14.58050	170.1840	5.413694
14.64550	170.1834	5.406215
14.70883	170.1832	5.401911
14.77383	170.1839	5.401668
14.83717	170.1847	5.408184
14.90217	170.1864	5.428420
14.96716	170.1881	5.471202
15.03050	170.1906	5.522618
15.09550	170.1934	5.588082
15.15883	170.1965	5.658960
15.22383	170.2000	5.738190
15.28717	170.2042	5.831465
15.35217	170.2095	5.933852
15.41550	170.2147	6.044168
15.48050	170.2205	6.169705
15.54384	170.2274	6.304712
15.60883	170.2341	6.451617
15.67383	170.2412	6.609148
15.73716	170.2488	6.765250
15.80217	170.2576	6.940061
15.86550	170.2661	7.114684
15.93050	170.2756	7.294204
15.99383	170.2839	7.478755
16.05883	170.2934	7.665356
16.12216	170.3020	7.846314
16.18716	170.3117	8.030918
16.25217	170.3200	8.212360
16.31550	170.3283	8.386163
16.38050	170.3375	8.554191
16.44383	170.3448	8.711339
16.50883	170.3521	8.861126
16.57216	170.3588	8.995891
16.63716	170.3654	9.122869
16.70050	170.3708	9.236255
16.76550	170.3760	9.333472
16.83050	170.3807	9.415610
16.89383	170.3848	9.484632
16.95883	170.3871	9.537003
17.02216	170.3896	9.570981
17.08716	170.3907	9.589995
17.15050	170.3912	9.597563
17.21550	170.3909	9.601778
17.27883	170.3902	9.600447
17.34383	170.3890	9.579751
17.40716	170.3862	9.525959
17.47216	170.3846	9.455311
17.53717	170.3804	9.381112
17.60050	170.3770	9.294986
17.66550	170.3724	9.201488
17.72883	170.3673	9.100512
17.79383	170.3620	8.991168
17.85716	170.3565	8.873776
17.92216	170.3512	8.755362
17.98550	170.3450	8.634234
18.05050	170.3390	8.503999
18.11550	170.3325	8.374820
18.17883	170.3266	8.245000
18.24383	170.3202	8.114765
18.30716	170.3144	7.987261
18.37216	170.3079	7.860631
18.43550	170.3014	7.736481
18.50050	170.2950	7.613962
18.56383	170.2894	7.494620
18.62883	170.2838	7.378916
18.69383	170.2780	7.265598
18.75716	170.2727	7.157850
18.82216	170.2667	7.051757
18.88550	170.2624	6.950687
18.95050	170.2575	6.852184
19.01383	170.2533	6.759288
19.07883	170.2487	6.671128
19.14216	170.2439	6.585190
19.20716	170.2404	6.504851
19.27050	170.2367	6.428094
19.33550	170.2326	6.353989
19.40050	170.2293	6.278144
19.46383	170.2256	6.211704
19.52883	170.2224	6.141184
19.59216	170.2198	6.079532
19.65716	170.2166	6.014190
19.72050	170.2142	5.953052
19.78550	170.2106	5.893229
19.84883	170.2080	5.835269
19.91383	170.2047	5.776300
19.97883	170.2024	5.716949
20.04216	170.1996	5.662934
20.10716	170.1970	5.602858
20.17050	170.1939	5.545610
20.23550	170.1907	5.484332
20.29883	170.1880	5.424040
20.36383	170.1855	5.360070
20.42716	170.1815	5.300820
20.49216	170.1784	5.235372
20.55716	170.1748	5.168408
20.62050	170.1726	5.095615
20.68550	170.1688	5.027930
20.74883	170.1655	4.955790
20.81383	170.1620	4.883052
20.87716	170.1587	4.802858
20.94216	170.1553	4.722701
21.00550	170.1514	4.644840
21.07050	170.1480	4.562416
21.13383	170.1441	4.481228
21.19883	170.1404	4.403516
21.26383	170.1363	4.321074
21.32716	170.1320	4.240992
21.39216	170.1281	4.159756
21.45550	170.1242	4.082789
21.52050	170.1197	4.001877
21.58383	170.1152	3.926035
21.64883	170.1111	3.845592
21.71216	170.1071	3.770018
21.77717	170.1041	3.691644
21.84216	170.1000	3.613461
21.90550	170.0964	3.535852
21.97050	170.0932	3.460720
22.03383	170.0892	3.391990
22.09883	170.0854	3.323515
22.16217	170.0822	3.257120
22.22716	170.0788	3.189015
22.29050	170.0754	3.129355
22.35550	170.0720	3.063865
22.42050	170.0695	3.001492
22.48383	170.0671	2.941578
22.54883	170.0639	2.875221
22.61216	170.0612	2.814160
22.67717	170.0584	2.759662
22.74050	170.0554	2.704422
22.80550	170.0529	2.650845
22.86883	170.0507	2.596344
22.93383	170.0476	2.547262
22.99716	170.0448	2.499770
23.06216	170.0422	2.451323
23.12716	170.0399	2.401129
23.19050	170.0369	2.357551
23.25550	170.0345	2.306872
23.31883	170.0329	2.260806
23.38383	170.0308	2.211891
23.44716	170.0277	2.164215
23.51216	170.0259	2.119148
23.57550	170.0235	2.070942
23.64050	170.0224	2.019724
23.70550	170.0194	1.974366
23.76883	170.0173	1.928110
23.83383	170.0152	1.882135
23.89716	170.0129	1.836220
23.96216	170.0102	1.792509
24.02550	170.0079	1.743405
24.09050	170.0051	1.692061
24.15383	170.0015	1.641424
24.21883	169.9993	1.587148
24.28383	169.9974	1.533555
24.34716	169.9939	1.479711
24.41217	169.9919	1.420126
24.47550	169.9891	1.361480
24.54050	169.9856	1.301571
24.60383	169.9831	1.240190
24.66883	169.9800	1.174666
24.73216	169.9767	1.112428
24.79716	169.9749	1.042492
24.86050	169.9714	0.9814014
24.92550	169.9681	0.9105429
24.99050	169.9652	0.8405059
25.05383	169.9623	0.7764966
25.11883	169.9586	0.7075268
25.18216	169.9552	0.6435497
25.24716	169.9520	0.5727125
25.31050	169.9479	0.5090515
25.37550	169.9451	0.4391626
25.43883	169.9415	0.3694681
25.50383	169.9382	0.2985380
25.56883	169.9355	0.2268535
25.63216	169.9319	0.1629582
25.69717	169.9289	0.09078406
25.76050	169.9254	0.02713838
25.82550	169.9219	-.04031372
25.88883	169.9188	-0.1037984
25.95383	169.9152	-0.1704131
26.01716	169.9122	-0.2303365
26.08216	169.9087	-0.2897723
26.14716	169.9055	-0.3509882
26.21050	169.9030	-0.4068920
26.27550	169.8994	-0.4642454
26.33883	169.8969	-0.5185377
26.40383	169.8937	-0.5762624
26.46716	169.8914	-0.6313118
26.53216	169.8889	-0.6855278
26.59550	169.8862	-0.7329260
26.66050	169.8841	-0.7865390
26.72383	169.8818	-0.8350335
26.78883	169.8798	-0.8849499
26.85383	169.8771	-0.9307749
26.91716	169.8759	-0.9729272
26.98216	169.8738	-1.015108
27.04550	169.8718	-1.055436
27.11050	169.8700	-1.096233
27.17383	169.8687	-1.129926
27.23883	169.8666	-1.164613
27.30217	169.8646	-1.192636
27.36716	169.8626	-1.228442
27.43216	169.8605	-1.258138
27.49550	169.8595	-1.288861
27.56050	169.8577	-1.318292
27.62383	169.8568	-1.344786
27.68883	169.8552	-1.372444
27.75217	169.8541	-1.400279
27.81716	169.8528	-1.422445
27.88050	169.8522	-1.447040
27.94550	169.8512	-1.470209
28.01050	169.8494	-1.488756
28.07383	169.8492	-1.504850
28.13883	169.8475	-1.521984
28.20217	169.8474	-1.540248
28.26716	169.8462	-1.557682
28.33050	169.8458	-1.575006
28.39550	169.8450	-1.589536
28.45883	169.8427	-1.604089
28.52383	169.8428	-1.617519
28.58716	169.8408	-1.631013
28.65216	169.8405	-1.646377
28.71716	169.8398	-1.659943
28.78050	169.8392	-1.674560
28.84550	169.8390	-1.688412
28.90883	169.8376	-1.701312
28.97383	169.8378	-1.714196
29.03717	169.8370	-1.726805
29.10217	169.8359	-1.738733
29.16550	169.8352	-1.749890
29.23050	169.8348	-1.761208
29.29550	169.8349	-1.772791
29.35883	169.8346	-1.784320
29.42383	169.8340	-1.795722
29.48716	169.8339	-1.806559
29.55217	169.8332	-1.817606
29.61550	169.8335	-1.827496
29.68050	169.8325	-1.837124
29.74383	169.8318	-1.845991
29.80883	169.8313	-1.854605
29.87383	169.8309	-1.863350
29.93717	169.8307	-1.871213
30.00217	169.8303	-1.879053
30.06550	169.8288	-1.885894
30.13050	169.8285	-1.892534
30.19383	169.8290	-1.898980
30.25883	169.8285	-1.905974
30.32217	169.8281	-1.912698
30.38716	169.8281	-1.919848
30.45050	169.8280	-1.927307
30.51550	169.8278	-1.935112
30.58050	169.8280	-1.942796
30.64383	169.8277	-1.949866
30.70883	169.8280	-1.956496
30.77216	169.8272	-1.963083
30.83716	169.8270	-1.969289
30.90050	169.8274	-1.975611
30.96550	169.8262	-1.981549
31.02883	169.8271	-1.986695
31.09383	169.8263	-1.992213
31.15883	169.8259	-1.997204
31.22216	169.8254	-2.001552
31.28717	169.8250	-2.006002
31.35050	169.8247	-2.010113
31.41550	169.8248	-2.013638
31.47883	169.8243	-2.017775
31.54383	169.8246	-2.022232
31.60716	169.8238	-2.026658
31.67216	169.8238	-2.031290
31.73716	169.8235	-2.035433
31.80050	169.8236	-2.039368
31.86550	169.8242	-2.043812
31.92883	169.8234	-2.048002
31.99383	169.8234	-2.052239
32.05716	169.8233	-2.056150
32.12216	169.8227	-2.059889
32.18550	169.8228	-2.062881
32.25050	169.8222	-2.065765
32.31383	169.8222	-2.068492
32.37883	169.8215	-2.071440
32.44383	169.8208	-2.074223
32.50716	169.8207	-2.076918
32.57217	169.8203	-2.080117
32.63550	169.8200	-2.082847
32.70050	169.8200	-2.086475
32.76383	169.8207	-2.089648
32.82883	169.8202	-2.093056
32.89216	169.8199	-2.096791
32.95716	169.8208	-2.100377
33.02217	169.8203	-2.104189
33.08550	169.8207	-2.107728
33.15050	169.8208	-2.111189
33.21383	169.8196	-2.114182
33.27883	169.8204	-2.116992
33.34216	169.8203	-2.120005
33.40716	169.8201	-2.122184
33.47050	169.8203	-2.124836
33.53550	169.8200	-2.127592
33.60050	169.8197	-2.129924
33.66383	169.8198	-2.132170
33.72883	169.8198	-2.134782
33.79217	169.8191	-2.136475
33.85716	169.8184	-2.138323
33.92050	169.8190	-2.139980
33.98550	169.8182	-2.140795
34.04883	169.8176	-2.141975
34.11383	169.8172	-2.143370
34.17717	169.8173	-2.144732
34.24216	169.8180	-2.146348
34.30716	169.8173	-2.148640
34.37050	169.8178	-2.150792
34.43550	169.8175	-2.153666
34.49883	169.8179	-2.156612
34.56383	169.8182	-2.159331
34.62717	169.8172	-2.162128
34.69216	169.8183	-2.164766
34.75550	169.8180	-2.166930
34.82050	169.8182	-2.169808
34.88550	169.8186	-2.172064
34.94883	169.8178	-2.174142
35.01383	169.8184	-2.175910
35.07717	169.8177	-2.177612
35.14216	169.8172	-2.178217
35.20550	169.8174	-2.178627
35.27050	169.8174	-2.179375
35.33383	169.8171	-2.180190
35.39883	169.8173	-2.181642
35.46383	169.8158	-2.182984
35.52716	169.8168	-2.184714
35.59216	169.8168	-2.185871
35.65550	169.8166	-2.187134
35.72050	169.8170	-2.188063
35.78383	169.8159	-2.189064
35.84883	169.8160	-2.190470
35.91217	169.8165	-2.192093
35.97717	169.8164	-2.194517
36.04050	169.8172	-2.196606
36.10550	169.8175	-2.198400
36.17050	169.8164	-2.200706
36.23383	169.8175	-2.202620
36.29883	169.8168	-2.204720
36.36217	169.8168	-2.205939
36.42717	169.8159	-2.206836
36.49050	169.8161	-2.207096
36.55550	169.8164	-2.207371
36.61883	169.8162	-2.207389
36.68384	169.8161	-2.207875
36.74883	169.8156	-2.208942
36.81216	169.8158	-2.210086
36.87717	169.8165	-2.211255
36.94050	169.8158	-2.212234
37.00550	169.8154	-2.213733
37.06883	169.8155	-2.215117
37.13383	169.8159	-2.217006
37.19717	169.8159	-2.218576
37.26216	169.8154	-2.219823
37.32717	169.8157	-2.220192
37.39050	169.8146	-2.220358
37.45550	169.8152	-2.220370
37.51883	169.8155	-2.221018
37.58383	169.8142	-2.221716
37.64717	169.8149	-2.222788
37.71216	169.8147	-2.224222
37.77550	169.8150	-2.225098
37.84050	169.8147	-2.226504
37.90383	169.8150	-2.228035
37.96884	169.8144	-2.229558
38.03383	169.8150	-2.231147
38.09716	169.8153	-2.233014
38.16217	169.8145	-2.234282
38.22550	169.8148	-2.234982
38.29050	169.8148	-2.235000
38.35383	169.8137	-2.234993
38.41883	169.8141	-2.234827
38.48216	169.8150	-2.235026
38.54716	169.8148	-2.236026
38.61217	169.8147	-2.237290
38.67550	169.8144	-2.238364
38.74050	169.8150	-2.239958
38.80383	169.8154	-2.241036
38.86883	169.8153	-2.242192
38.93216	169.8152	-2.243298
38.99716	169.8154	-2.244222
39.06050	169.8149	-2.245110
39.12550	169.8144	-2.245458
39.19050	169.8148	-2.245738
39.25383	169.8133	-2.245962
39.31883	169.8144	-2.246393
39.38216	169.8144	-2.246611
39.44717	169.8132	-2.247100
39.51050	169.8136	-2.247525
39.57550	169.8134	-2.248031
39.63883	169.8141	-2.248781
39.70383	169.8130	-2.248772
39.76716	169.8125	-2.249104
39.83216	169.8134	-2.249318
39.89717	169.8131	-2.250233
39.96050	169.8131	-2.250616
40.02550	169.8135	-2.251812
40.08883	169.8131	-2.252828
40.15383	169.8136	-2.254414
40.21716	169.8126	-2.255782
40.28216	169.8136	-2.256851
40.34550	169.8132	-2.257772
40.41050	169.8137	-2.258630
40.47550	169.8139	-2.259871
40.53883	169.8131	-2.260521
40.60383	169.8140	-2.261391
40.66716	169.8144	-2.262164
40.73216	169.8137	-2.263167
40.79550	169.8134	-2.264178
40.86050	169.8139	-2.265406
40.92383	169.8139	-2.265965
40.98883	169.8143	-2.266994
41.05383	169.8148	-2.267901
41.11716	169.8144	-2.268648
41.18217	169.8140	-2.269392
41.24550	169.8137	-2.269429
41.31050	169.8141	-2.269468
41.37383	169.8144	-2.269281
41.43883	169.8141	-2.269089
41.50217	169.8141	-2.269543
41.56717	169.8139	-2.269976
41.63050	169.8140	-2.270027
41.69550	169.8136	-2.269778
41.76050	169.8130	-2.269464
41.82383	169.8130	-2.269136
41.88883	169.8123	-2.269325
41.95216	169.8128	-2.269322
42.01717	169.8128	-2.269958
42.08050	169.8135	-2.270203
42.14550	169.8130	-2.270748
42.20883	169.8124	-2.271358
42.27383	169.8136	-2.271990
42.33883	169.8130	-2.272954
42.40216	169.8132	-2.273843
42.46717	169.8132	-2.274917
42.53050	169.8139	-2.276320
42.59550	169.8130	-2.277875
42.65883	169.8134	-2.278868
42.72383	169.8134	-2.279875
42.78717	169.8131	-2.280394
42.85217	169.8133	-2.280526
42.91716	169.8132	-2.281079
42.98050	169.8132	-2.281247
43.04550	169.8139	-2.281228
43.10883	169.8134	-2.281511
43.17383	169.8138	-2.281554
43.23717	169.8131	-2.281772
43.30217	169.8136	-2.281830
43.36550	169.8122	-2.281966
43.43050	169.8128	-2.282073
43.49383	169.8118	-2.281804
43.55883	169.8121	-2.281080
43.62383	169.8116	-2.280578
43.68716	169.8121	-2.280308
43.75217	169.8117	-2.280782
43.81550	169.8114	-2.281612
43.88050	169.8124	-2.282731
43.94383	169.8130	-2.284588
44.00883	169.8128	-2.286528
44.07217	169.8127	-2.287644
44.13716	169.8130	-2.288698
44.20216	169.8130	-2.289742
44.26550	169.8129	-2.290328
44.33050	169.8129	-2.291106
44.39383	169.8129	-2.291460
44.45883	169.8128	-2.291468
44.52217	169.8127	-2.291012
44.58716	169.8120	-2.290358
44.65050	169.8120	-2.289541
44.71550	169.8123	-2.289206
44.78050	169.8114	-2.289012
44.84384	169.8131	-2.289146
44.90883	169.8124	-2.290054
44.97217	169.8130	-2.290900
45.03717	169.8132	-2.291961
45.10050	169.8126	-2.293418
45.16550	169.8130	-2.294113
45.22883	169.8130	-2.294860
45.29383	169.8131	-2.295412
45.35717	169.8128	-2.295308
45.42216	169.8124	-2.295746
45.48717	169.8123	-2.296013
45.55050	169.8132	-2.296623
45.61550	169.8122	-2.296236
45.67883	169.8122	-2.296068
45.74383	169.8116	-2.295104
45.80717	169.8117	-2.294613
45.87216	169.8112	-2.294053
45.93550	169.8119	-2.293888
46.00050	169.8116	-2.293680
46.06550	169.8118	-2.293886
46.12883	169.8107	-2.294389
46.19383	169.8121	-2.295051
46.25717	169.8116	-2.296253
46.32217	169.8123	-2.297209
46.38550	169.8122	-2.298140
46.45050	169.8131	-2.299088
46.51383	169.8131	-2.300290
46.57883	169.8125	-2.301142
46.64383	169.8120	-2.302131
46.70717	169.8116	-2.302370
46.77217	169.8130	-2.302628
46.83550	169.8123	-2.302498
46.90050	169.8114	-2.302283
46.96383	169.8130	-2.302239
47.02883	169.8127	-2.302447
47.09217	169.8118	-2.302515
47.15717	169.8127	-2.302715
47.22050	169.8123	-2.302807
47.28550	169.8118	-2.302774
47.35050	169.8119	-2.302942
47.41383	169.8119	-2.303408
47.47883	169.8124	-2.303679
47.54217	169.8129	-2.304413
47.60717	169.8122	-2.304949
47.67050	169.8121	-2.305752
47.73550	169.8124	-2.305786
47.79883	169.8128	-2.305638
47.86383	169.8116	-2.305479
47.92883	169.8118	-2.305710
47.99216	169.8126	-2.306323
48.05717	169.8125	-2.306646
48.12050	169.8122	-2.306736
48.18550	169.8124	-2.306431
48.24883	169.8112	-2.306038
48.31383	169.8114	-2.305650
48.37717	169.8115	-2.305735
48.44217	169.8113	-2.305806
48.50717	169.8121	-2.306270
48.57050	169.8116	-2.306835
48.63550	169.8116	-2.307376
48.69883	169.8119	-2.308021
48.76383	169.8116	-2.308415
48.82717	169.8117	-2.308776
48.89217	169.8122	-2.308714
48.95550	169.8120	-2.308848
49.02050	169.8119	-2.308855
49.08383	169.8122	-2.309093
49.14883	169.8121	-2.309867
49.21383	169.8116	-2.310480
49.27716	169.8120	-2.311113
49.34217	169.8123	-2.311801
49.40550	169.8123	-2.311996
49.47050	169.8119	-2.312448
49.53383	169.8118	-2.312811
49.59883	169.8116	-2.312793
49.66217	169.8114	-2.312295
49.72717	169.8112	-2.311933
49.79217	169.8114	-2.311458
49.85550	169.8114	-2.311363
49.92050	169.8114	-2.311466
49.98383	169.8119	-2.312100
50.04883	169.8118	-2.312466
50.11217	169.8127	-2.313664
50.17717	169.8116	-2.314694
50.24050	169.8128	-2.315149
50.30550	169.8122	-2.315677
50.37050	169.8127	-2.316122
50.43383	169.8122	-2.316330
50.49883	169.8129	-2.316250
50.56216	169.8122	-2.316290
50.62717	169.8117	-2.316074
50.69050	169.8125	-2.315877
50.75550	169.8117	-2.315366
50.81883	169.8114	-2.314651
50.88383	169.8113	-2.313831
50.94717	169.8111	-2.313490
51.01216	169.8114	-2.313397
51.07717	169.8111	-2.313019
51.14050	169.8113	-2.313370
51.20550	169.8115	-2.314123
51.26884	169.8118	-2.314780
51.33383	169.8120	-2.315779
51.39717	169.8118	-2.316230
51.46216	169.8121	-2.316754
51.52550	169.8116	-2.317084
51.59050	169.8122	-2.317043
51.65550	169.8114	-2.317406
51.71884	169.8115	-2.317816
51.78383	169.8119	-2.318278
51.84716	169.8112	-2.318040
51.91216	169.8109	-2.317611
51.97550	169.8113	-2.317692
52.04050	169.8111	-2.317644
52.10383	169.8122	-2.317698
52.16883	169.8111	-2.317738
52.23383	169.8116	-2.317944
52.29717	169.8114	-2.318186
52.36217	169.8112	-2.318222
52.42550	169.8110	-2.318373
52.49050	169.8102	-2.318270
52.55383	169.8106	-2.318132
52.61882	169.8100	-2.317781
52.68217	169.8104	-2.317677
52.74717	169.8098	-2.317528
52.81050	169.8096	-2.317193
52.87550	169.8099	-2.316906
52.94050	169.8105	-2.316855
53.00383	169.8097	-2.317198
53.06884	169.8094	-2.317798
53.13217	169.8098	-2.318392
53.19717	169.8098	-2.319131
53.26050	169.8096	-2.319900
53.32550	169.8101	-2.320135
53.38882	169.8102	-2.320596
53.45383	169.8102	-2.321056
53.51884	169.8102	-2.321455
53.58217	169.8107	-2.322346
53.64717	169.8109	-2.323342
53.71050	169.8110	-2.324457
53.77550	169.8116	-2.325572
53.83882	169.8117	-2.326366
53.90383	169.8110	-2.327121
53.96717	169.8124	-2.327618
54.03217	169.8120	-2.328116
54.09716	169.8128	-2.328735
54.16050	169.8123	-2.328718
54.22550	169.8126	-2.328868
54.28882	169.8126	-2.328628
54.35383	169.8117	-2.328211
54.41716	169.8120	-2.327831
54.48217	169.8125	-2.327585
54.54550	169.8124	-2.327400
54.61050	169.8121	-2.326731
54.67383	169.8118	-2.326808
54.73882	169.8121	-2.326665
54.80383	169.8120	-2.326598
54.86716	169.8114	-2.326526
54.93217	169.8123	-2.326416
54.99550	169.8119	-2.326484
55.06050	169.8117	-2.325885
55.12383	169.8115	-2.325708
55.18882	169.8122	-2.325871
55.25217	169.8120	-2.325823
55.31716	169.8118	-2.326090
55.38217	169.8120	-2.326086
55.44550	169.8119	-2.326317
55.51050	169.8119	-2.326172
55.57383	169.8118	-2.325727
55.63882	169.8112	-2.325594
55.70216	169.8117	-2.325877
55.76716	169.8122	-2.326748
55.83050	169.8114	-2.327336
55.89550	169.8115	-2.327744
55.96050	169.8112	-2.327741
56.02383	169.8105	-2.327715
56.08882	169.8110	-2.327072
56.15217	169.8107	-2.327069
56.21717	169.8108	-2.326556
56.28050	169.8105	-2.326563
56.34550	169.8101	-2.326677
56.40883	169.8108	-2.327062
56.47382	169.8114	-2.327994
56.53716	169.8112	-2.328631
56.60217	169.8113	-2.329055
56.66716	169.8119	-2.329875
56.73050	169.8116	-2.330283
56.79550	169.8116	-2.330797
56.85883	169.8119	-2.331562
56.92383	169.8121	-2.331814
56.98717	169.8120	-2.331918
57.05217	169.8121	-2.332276
57.11550	169.8115	-2.332158
57.18050	169.8120	-2.332180
57.24550	169.8119	-2.331824
57.30883	169.8112	-2.331652
57.37383	169.8114	-2.331066
57.43716	169.8115	-2.330299
57.50217	169.8112	-2.329870
57.56550	169.8114	-2.329462
57.63050	169.8112	-2.329360
57.69384	169.8107	-2.329523
57.75883	169.8111	-2.329906
57.82383	169.8111	-2.330184
57.88716	169.8106	-2.330513
57.95216	169.8108	-2.330238
58.01550	169.8106	-2.330068
58.08050	169.8114	-2.330000
58.14384	169.8109	-2.329990
58.20883	169.8104	-2.330119
58.27217	169.8106	-2.330192
58.33716	169.8102	-2.330242
58.40050	169.8111	-2.330400
58.46550	169.8109	-2.330720
58.53050	169.8099	-2.330705
58.59384	169.8106	-2.331240
58.65883	169.8108	-2.332118
58.72217	169.8108	-2.332765
58.78716	169.8102	-2.333526
58.85050	169.8114	-2.334064
58.91550	169.8112	-2.335373
58.97883	169.8116	-2.335875
59.04382	169.8108	-2.336505
59.10883	169.8113	-2.336252
59.17217	169.8116	-2.336139
59.23717	169.8116	-2.336004
59.30050	169.8110	-2.335143
59.36550	169.8112	-2.334692
59.42883	169.8104	-2.334408
59.49382	169.8117	-2.334473
59.55717	169.8109	-2.334456
59.62217	169.8110	-2.334038
59.68716	169.8109	-2.333670
59.75050	169.8106	-2.333218
59.81550	169.8108	-2.333039
59.87883	169.8114	-2.333750
59.94384	169.8112	-2.334352
60.00717	169.8114	-2.334940
60.07217	169.8116	-2.336025
60.13550	169.8114	-2.336102
60.20050	169.8115	-2.336764
60.26382	169.8121	-2.336792
60.32883	169.8119	-2.336805
60.39384	169.8114	-2.336320
60.45717	169.8112	-2.336037
60.52217	169.8108	-2.335260
60.58550	169.8104	-2.334976
60.65050	169.8098	-2.334397
60.71382	169.8096	-2.333526
60.77883	169.8098	-2.332935
60.84217	169.8091	-2.332235
60.90717	169.8096	-2.331833
60.97217	169.8090	-2.331966
61.03550	169.8095	-2.331533
61.10050	169.8091	-2.331594
61.16382	169.8100	-2.331789
61.22883	169.8094	-2.332574
61.29217	169.8095	-2.332830
61.35717	169.8096	-2.333732
61.42050	169.8094	-2.334773
61.48550	169.8091	-2.335689
61.55050	169.8091	-2.336384
61.61382	169.8099	-2.337362
61.67883	169.8098	-2.338161
61.74216	169.8099	-2.338268
61.80717	169.8094	-2.338963
61.87050	169.8111	-2.339049
61.93550	169.8100	-2.339281
61.99883	169.8105	-2.339400
62.06382	169.8101	-2.339387
62.12717	169.8105	-2.339716
62.19216	169.8105	-2.339412
62.25717	169.8108	-2.339569
62.32050	169.8102	-2.339248
62.38550	169.8104	-2.339525
62.44883	169.8104	-2.339538
62.51050	169.8100	-2.339853
62.57550	170.0028	-2.240152
62.64050	170.6692	-4.783748
62.70383	171.4762	-8.997863
62.76884	172.4095	-13.56704
62.83217	173.3920	-17.59460
62.89717	174.4577	-21.09886
62.96050	175.5405	-23.90748
63.02550	176.6865	-26.27028
63.08882	177.8302	-28.14487
63.15383	179.0272	-29.73448
63.21717	180.2100	-31.01836
63.28217	181.4393	-32.14575
63.34716	182.6777	-33.10410
63.41050	183.8941	-33.92748
63.47550	185.1479	-34.67523
63.53882	186.3756	-35.34231
63.60383	187.6373	-35.98078
63.66716	188.8716	-36.57363
63.73217	190.1408	-37.17528
63.79550	191.3780	-37.75309
63.86050	192.6481	-38.36794
63.92550	193.9180	-38.97606
63.98882	195.1554	-39.62218
64.05383	196.4216	-40.35630
64.11718	197.6525	-41.15460
64.18218	198.9136	-42.04957
64.24550	200.1367	-43.03066
64.31050	201.3872	-44.18460
64.37383	202.5975	-45.48440
64.43884	203.8291	-47.06108
64.50384	205.0466	-48.94675
64.56717	206.2190	-51.15116
64.63218	207.4048	-53.77063
64.69550	208.5451	-56.64786
64.76050	209.7018	-59.88098
64.82384	210.8148	-63.36552
64.88884	211.9391	-67.35700
64.95216	213.0156	-71.68702
65.01716	214.1002	-76.53732
65.08050	215.1480	-81.40103
65.14550	216.2336	-86.02075
65.21050	217.3592	-89.52626
65.27383	218.5507	-90.54016
65.33884	219.9130	-88.49543
65.40218	221.3445	-84.54541
65.46717	222.8844	-79.12720
65.53050	224.4264	-73.06306
65.59550	226.0280	-66.59480
65.65884	227.5698	-60.92507
65.72384	229.1052	-56.20385
65.78882	230.5912	-52.54236
65.85218	231.9997	-49.76131
65.91718	233.4116	-47.57132
65.98050	234.7646	-45.93674
66.04550	236.1321	-44.66158
66.10884	237.4507	-43.69560
66.17384	238.7909	-42.95170
66.23718	240.0876	-42.41786
66.30218	241.4122	-42.01428
66.36718	242.7301	-41.73724
66.43050	244.0117	-41.54470
66.49550	245.3226	-41.41603
66.55884	246.5982	-41.32905
66.62384	247.9048	-41.27497
66.68718	249.1763	-41.25488
66.75218	250.4809	-41.24356
66.81550	251.7502	-41.24504
66.88050	253.0527	-41.27038
66.94384	254.3205	-41.33522
67.00884	255.6217	-41.39820
67.07384	256.9224	-41.50131
67.13718	258.1877	-41.60278
67.20216	259.4860	-41.75035
67.26550	260.7494	-41.92847
67.33050	262.0434	-42.17856
67.39384	263.2967	-42.67165
67.45884	264.5615	-43.72876
67.52218	265.7688	-45.16400
67.58716	267.0686	-45.00141
67.65218	268.3659	-45.28793
67.71550	269.6181	-45.69191
67.78050	270.9209	-45.65288
67.84384	272.1955	-45.55300
67.90884	273.5058	-45.36616
67.97218	274.7838	-45.21284
68.03050	275.9497	-44.99917
68.09550	276.5053	-43.49824
68.15884	276.3396	-35.36612
68.22384	275.8672	-25.03547
68.28718	275.2207	-15.52198
68.35218	274.4220	-7.159028
68.41718	273.5206	-0.2990644
68.48050	272.5676	5.131118
68.54550	271.5296	9.649731
68.60884	270.4720	13.24028
68.67384	269.3490	16.24680
68.73718	268.2265	18.63333
68.80218	267.0489	20.66289
68.86550	265.8830	22.29890
68.93050	264.6680	23.69717
68.99550	263.4407	24.85480
69.05884	262.2332	25.79573
69.12384	260.9845	26.61043
69.18718	259.7606	27.27342
69.25218	258.4994	27.83774
69.31550	257.2639	28.30778
69.38050	255.9930	28.71918
69.44384	254.7508	29.06148
69.50884	253.4724	29.37387
69.57384	252.1904	29.63580
69.63718	250.9411	29.85400
69.70216	249.6566	30.04700
69.76550	248.4038	30.22189
69.83050	247.1160	30.37070
69.89384	245.8600	30.49008
69.95884	244.5719	30.59917
70.02218	243.3152	30.68789
70.08716	242.0256	30.77033
70.15050	240.7675	30.84262
70.21550	239.4764	30.91016
70.28050	238.1848	30.97910
70.34384	236.9261	31.03350
70.40884	235.6334	31.09408
70.47218	234.3745	31.12987
70.53718	233.0816	31.16528
70.60050	231.8227	31.19080
70.66550	230.5290	31.22779
70.72884	229.2692	31.25932
70.79384	227.9756	31.29288
70.85884	226.6829	31.34102
70.92218	225.4236	31.36686
70.98718	224.1285	31.40919
71.05050	222.8686	31.43386
71.11550	221.5740	31.46080
71.17884	220.3124	31.48425
71.24384	219.0178	31.50888
71.30718	217.7564	31.52688
71.37218	216.4621	31.53875
71.43718	215.1680	31.54967
71.50050	213.9054	31.55896
71.56550	212.6106	31.56875
71.62884	211.3501	31.57805
71.69384	210.0556	31.58863
71.75718	208.7930	31.59993
71.82218	207.4982	31.61094
71.88550	206.2366	31.62100
71.95050	204.9412	31.62942
72.01384	203.6797	31.63704
72.07884	202.3851	31.64424
72.14384	201.0894	31.64990
72.20718	199.8279	31.65587
72.27218	198.5330	31.66261
72.33550	197.2708	31.66966
72.40050	195.9759	31.67577
72.46384	194.7143	31.68214
72.52884	193.4186	31.69096
72.59216	192.1566	31.69838
72.65718	190.8609	31.70498
72.72218	189.5658	31.71022
72.78550	188.3039	31.71419
72.85050	187.0096	31.71648
72.91382	185.7479	31.71912
72.97884	184.4519	31.72185
73.04218	183.1898	31.72285
73.10718	181.8930	31.72380
73.17050	180.6309	31.72351
73.23550	179.3350	31.72344
73.30050	178.0395	31.72465
73.36384	176.7775	31.72776
73.42884	175.4813	31.73274
73.49218	174.2184	31.73927
73.55718	172.9231	31.74778
73.62050	171.6617	31.75676
73.68550	170.3661	31.78646
73.74884	169.1069	31.89860
73.81384	167.8175	32.09939
73.87718	166.5706	32.47224
73.94218	165.3086	33.28260
74.00718	164.0808	34.97070
74.07050	162.9499	38.09395
74.13550	161.8856	43.37236
74.19884	160.9433	50.30772
74.26384	160.0258	58.03389
74.32718	159.1092	64.64922
74.39216	158.0848	69.46820
74.45550	156.9799	71.93139
74.52050	155.7376	72.31542
74.58550	154.4009	70.94012
74.64884	153.0321	68.39949
74.71384	151.5837	65.07000
74.77718	150.1484	61.50664
74.84216	148.6712	57.85301
74.90550	147.2394	54.51280
74.97050	145.7850	51.42684
75.03384	144.3866	48.79696
75.09882	142.9684	46.46850
75.16382	141.5689	44.46596
75.22718	140.2198	42.79695
75.29218	138.8472	41.33787
75.35550	137.5211	40.12722
75.42050	136.1686	39.05331
75.48384	134.8580	38.15038
75.54884	133.5207	37.35901
75.61218	132.2239	36.69575
75.67718	130.8959	36.08880
75.74050	129.6058	35.58215
75.80550	128.2852	35.12200
75.87050	126.9680	34.70624
75.93384	125.6856	34.33758
75.99884	124.3700	33.91958
76.06216	123.0904	33.61876
76.12718	121.7809	33.33672
76.19050	120.5059	33.08715
76.25550	119.1979	32.85259
76.31884	117.9243	32.64225
76.38384	116.6179	32.45410
76.44884	115.3115	32.26232
76.51218	114.0387	32.07354
76.57718	112.7301	31.81970
76.64050	111.4566	31.63300
76.70550	110.1519	31.46127
76.76882	108.8797	31.29279
76.83384	107.5748	31.10745
76.89718	106.3021	30.91616
76.96218	104.9981	30.75177
77.02718	103.6942	30.60305
77.09050	102.4237	30.45977
77.15550	101.1200	30.31208
77.21884	99.84992	30.16772
77.28384	98.54668	30.03284
77.34718	97.27668	29.88905
77.41218	95.97194	29.73721
77.47551	94.70165	29.57576
77.54050	93.39816	29.43766
77.60384	92.12869	29.30234
77.66884	90.82494	29.16711
77.73384	89.52194	29.02251
77.79718	88.25231	28.88774
77.86218	86.94821	28.75290
77.92550	85.67950	28.61615
77.99050	84.37738	28.47918
78.05384	83.10682	28.35293
78.11884	81.80451	28.22274
78.18218	80.53492	28.09656
78.24718	79.23144	27.96327
78.31216	77.92836	27.81362
78.37550	76.65806	27.68789
78.44050	75.35616	27.55599
78.50384	74.08600	27.43498
78.56884	72.78332	27.30900
78.63218	71.51312	27.18915
78.69718	70.21206	27.06359
78.76050	68.94070	26.95178
78.82550	67.63862	26.82390
78.89050	66.33692	26.68887
78.95384	65.06648	26.57233
79.01882	63.76281	26.44326
79.08218	62.49261	26.30132
79.14718	61.18906	26.14922
79.21050	59.91912	26.01365
79.27550	58.61768	25.87843
79.33884	57.34790	25.75137
79.40384	56.04385	25.61157
79.46718	54.77484	25.48199
79.53218	53.46950	25.31622
79.59718	52.16546	25.18439
79.66050	50.89428	25.02818
79.72551	49.59010	24.87627
79.78882	48.31389	24.60400
79.85384	47.00883	24.47284
79.91718	45.73867	24.36814
79.98218	44.43592	24.25286
80.04550	43.16642	24.14197
80.11050	41.86356	24.01894
80.17550	40.55986	23.89292
80.23882	39.28935	23.76359
80.30384	37.98477	23.61882
80.36718	36.71470	23.45486
80.43218	35.41022	23.31455
80.49550	34.13813	23.17043
80.56050	32.83403	23.01771
80.62384	31.56287	22.87000
80.68884	30.25776	22.72032
80.75384	28.95178	22.57153
80.81718	27.67918	22.41720
80.88218	26.37371	22.25563
80.94550	25.10101	22.09188
81.00550	23.89499	21.93709
81.07050	22.93465	22.62912
81.13550	22.99756	20.66998
81.19884	23.39080	15.90346
81.26384	24.00861	10.14766
81.32718	24.75334	4.820856
81.39216	25.62807	0.03997792
81.45550	26.56400	-3.865374
81.52050	27.59100	-7.163390
81.58384	28.64145	-9.777726
81.64884	29.76301	-11.96662
81.71384	30.91672	-13.74827
81.77718	32.06501	-15.18558
81.84216	33.26558	-16.40580
81.90550	34.45059	-17.40450
81.97050	35.68042	-18.26694
82.03384	36.88914	-18.98583
82.09882	38.13819	-19.62253
82.16218	39.36341	-20.16138
82.22718	40.62762	-20.63990
82.29050	41.86165	-21.04745
82.35550	43.13545	-21.41492
82.42050	44.41100	-21.74381
82.48382	45.65747	-22.03305
82.54884	46.93856	-22.29687
82.61218	48.18991	-22.54734
82.67718	49.47478	-22.78078
82.74050	50.72992	-22.99984
82.80549	52.01804	-23.21144
82.86884	53.27481	-23.40428
82.93384	54.56554	-23.59371
82.99884	55.85653	-23.76892
83.06218	57.11539	-23.92965
83.12718	58.40700	-24.09513
83.19050	59.66662	-24.25952
83.25550	60.96040	-24.42086
83.31884	62.22186	-24.58763
83.38384	63.51612	-24.74278
83.44718	64.77918	-24.88763
83.51218	66.07338	-25.02379
83.57718	67.36936	-25.17276
83.64050	68.63171	-25.31098
83.70550	69.92541	-25.45161
83.76882	71.18768	-25.58464
83.83384	72.48250	-25.73279
83.89718	73.74439	-25.86781
83.96218	75.03965	-26.00524
84.02550	76.30230	-26.14004
84.09051	77.59888	-26.28190
84.15384	78.86113	-26.42194
84.21884	80.15708	-26.56400
84.28384	81.45316	-26.70619
84.34718	82.71522	-26.84025
84.41218	84.01072	-26.97947
84.47551	85.27422	-27.12057
84.54051	86.56941	-27.26972
84.60382	87.83337	-27.41477
84.66884	89.12759	-27.55593
84.73218	90.39147	-27.71426
84.79718	91.68731	-27.85747
84.86218	92.98251	-28.00495
84.92551	94.24507	-28.14764
84.99051	95.54106	-28.30324
85.05382	96.80322	-28.44930
85.11884	98.09866	-28.58820
85.18218	99.36118	-28.73818
85.24718	100.6561	-28.88194
85.31050	101.9192	-29.03357
85.37550	103.2148	-29.17866
85.44051	104.5102	-29.32718
85.50384	105.7710	-29.48008
85.56884	107.0675	-29.63785
85.63218	108.3300	-29.79350
85.69718	109.6245	-29.94414
85.76051	110.8880	-30.10350
85.82550	112.1832	-30.25599
85.88884	113.4457	-30.41059
85.95382	114.7409	-30.56004
86.01718	116.0039	-30.70740
86.08218	117.2990	-30.86052
86.14718	118.5936	-31.01408
86.21051	119.8549	-31.17477
86.27550	121.1502	-31.34526
86.33884	122.4116	-31.51532
86.40384	123.7075	-31.69432
86.46718	124.9687	-31.86123
86.53218	126.2641	-32.03788
86.59551	127.5249	-32.19964
86.66050	128.8188	-32.37383
86.72551	130.1142	-32.54545
86.78882	131.3756	-32.72796
86.85382	132.6706	-32.91072
86.91718	133.9307	-33.08962
86.98218	135.2261	-33.27808
87.04550	136.4864	-33.47116
87.11051	137.7797	-33.67369
87.17384	139.0411	-33.86662
87.23882	140.3342	-34.07672
87.30382	141.6286	-34.28128
87.36718	142.8879	-34.48968
87.43218	144.1821	-34.69700
87.49550	145.4425	-34.89834
87.56050	146.7358	-35.11060
87.62384	147.9962	-35.31578
87.68884	149.2896	-35.52958
87.75218	150.5496	-35.73680
87.81718	151.8427	-35.95459
87.88050	153.1017	-36.18294
87.94550	154.3950	-36.42395
88.01051	155.6865	-36.66985
88.07384	156.9459	-36.91531
88.13884	158.2370	-37.17194
88.20216	159.4941	-37.43713
88.26718	160.7866	-37.70408
88.33051	162.0437	-37.98311
88.39551	163.3350	-38.25574
88.45882	164.5927	-38.52118
88.52384	165.8846	-38.77460
88.58884	167.1769	-39.00973
88.65218	168.4372	-39.20996
88.71718	169.7324	-39.39033
88.78051	170.9946	-39.54619
88.84551	172.2914	-39.68176
88.90884	173.5563	-39.83282
88.97384	174.8523	-39.97065
89.03718	176.1169	-40.12666
89.10218	177.4102	-40.31120
89.16718	178.7042	-40.49900
89.23050	179.9631	-40.72168
89.29550	181.2542	-40.98896
89.35884	182.5111	-41.30098
89.42384	183.8000	-41.64994
89.48718	185.0524	-42.03968
89.55218	186.3359	-42.48266
89.61551	187.5838	-42.97217
89.68051	188.8611	-43.55228
89.74384	190.1035	-44.18464
89.80884	191.3726	-44.91900
89.87384	192.6378	-45.78334
89.93718	193.8654	-46.71754
90.00218	195.1207	-47.77322
90.06551	196.3394	-48.89469
90.13050	197.5869	-50.10464
90.19384	198.8008	-51.31313
90.25884	200.0456	-52.62251
90.32218	201.2546	-53.94182
90.38718	202.4920	-55.43314
90.45216	203.7222	-57.07363
90.51551	204.9146	-58.77049
90.58051	206.1360	-60.61918
90.64384	207.3249	-62.38845
90.70882	208.5529	-63.93538
90.77218	209.7745	-64.85291
90.83718	211.0708	-64.70347
90.90051	212.3987	-63.08079
90.96551	213.8188	-60.39810
91.03051	215.2634	-57.29530
91.09384	216.6776	-54.24287
91.15884	218.1209	-51.34031
91.22218	219.5104	-48.89189
91.28718	220.9155	-46.84182
91.35050	222.2642	-45.26425
91.41550	223.6320	-43.99340
91.47882	224.9499	-43.01630
91.54384	226.2922	-42.24768
91.60718	227.5914	-41.67743
91.67218	228.9170	-41.21728
91.73718	230.2376	-40.90306
91.80051	231.5198	-40.67558
91.86551	232.8325	-40.51554
91.92882	234.1086	-40.41494
91.99384	235.4169	-40.35528
92.05718	236.6897	-40.32007
92.12218	237.9942	-40.29797
92.18550	239.2643	-40.29556
92.25050	240.5673	-40.30925
92.31551	241.8695	-40.35691
92.37882	243.1385	-40.41164
92.44384	244.4398	-40.49426
92.50718	245.7074	-40.56515
92.57218	247.0064	-40.65170
92.63550	248.2736	-40.72456
92.70050	249.5726	-40.79400
92.76384	250.8392	-40.88881
92.82884	252.1385	-40.98760
92.89384	253.4375	-41.08007
92.95718	254.7039	-41.16880
93.02218	256.0023	-41.26490
93.08551	257.2684	-41.35863
93.15051	258.5672	-41.45767
93.21384	259.8329	-41.57085
93.27884	261.1316	-41.67684
93.34218	262.3968	-41.78043
93.40718	263.6960	-41.90187
93.47051	264.9616	-42.01447
93.53551	266.2598	-42.13259
93.60050	267.5598	-42.24752
93.66382	268.8240	-42.36050
93.72882	270.1226	-42.48797
93.79218	271.3868	-42.59788
-2.000000	5.000000	0.0000000