File: 6-C1(1.2mol%)+C20(0.4mol%)/matlab/130-1.txt
CLOSED
Version	1.0
Language	English
Mode	Standard
Run	3
RunSerial	12305
Instrument	DSC Q2000 V24.11 Build 124
Module	DSC Standard Cell RC
Operator
File	\\AE520-1454\Users\dsc\Desktop\Data\31-08-17\130-1.001
ProcName
InstSerial	2000-0883
AutoSerial	1293
Sample	130-1
Size	23.9000	mg
PanMass	Not available
PanResist	Automatic Automatic  K/W
PanFactor	Default Default
Method
Comment
Xcomment	Pan: Tzero Aluminum Hermetic
Xcomment	Gas1: Nitrogen 50.0 ml/min
Xcomment	Gas2: Nitrogen 50.0 ml/min
Text
Exotherm	UP
Kcell	1.05230
Cpconst	Standard: 0.938
Calib	-38.6961
TempCal	1	pts	157.46	156.60
TzeroDt	-87.6168 -0.0009 -1.4231
TzeroDtz	-87.6168 0.0057 6.9570
InstCalFile	Tzero: \\Ae520-1454\ta\Data\DSC\Calibration\2017\CALIBRATION\1562_RCS (90)_05_18_2017 10_50_44.TZR
InstCalFile	Baseline: \\Ae520-1454\ta\Data\DSC\Calibration\2017\2017-05-17_Calibration.001
InstCalFile	Sapphire: \\Ae520-1454\ta\Data\DSC\Calibration\2017\2017-05-17_Saphire.001
InstCalDate	Tzero 2017-05-18 Time 10:50:44
TempRange	-87.39 to 398.39 °C at 10.00 °C/min Heat Only
AutoZero	Delta T Offset 0.000 uV
AutoZero	Delta T0 Offset 0.000 uV
MultiptCal	0
MultiPtDesc	0) Not set
AutoCellConst	Calibration Date 2017-05-18 16:59:28
Controls	Gas 1  Event Off  Sampling 0.2
Cell#	RC-01562
CoolingUnit	RCS (90)
SelHeatFlow	Heat Flow T4P (mW)
AutoLidII	Installed
AutoAnalysis	Off
MacroFile
Nsig	3
Sig1	Time (min)
Sig2	Temperature (°C)
Sig3	Heat Flow (mW)
Date	2017-08-31
Time	12:24:45
OrgMethod	1: Equilibrate at 80.00 °C
OrgMethod	2: Isothermal for 3.00 min
OrgMethod	3: Jump to 130.00 °C
OrgMethod	4: Mark end of cycle 1
OrgMethod	5: Isothermal for 40.00 min
OrgMethod	6: Mark end of cycle 2
OrgMethod	7: Ramp 20.00 °C/min to 280.00 °C
OrgMethod	8: Mark end of cycle 3
OrgMethod	9: Ramp 20.00 °C/min to 20.00 °C
OrgMethod	10: Mark end of cycle 4
OrgMethod	11: Ramp 20.00 °C/min to 280.00 °C
OrgMethod	12: Mark end of cycle 5
OrgFile	C:\Users\jarra\Desktop\DSC\6-C1(1.2mol%)+C20(0.4mol%)\130-1.001
StartOfData
4.99994E-4	79.76218	-2.641130
0.05383332	79.78974	-2.264952
0.1071666	79.80874	-1.988178
0.1588333	79.82119	-1.794896
0.2105000	79.83070	-1.654471
0.2638334	79.83672	-1.553096
0.3155000	79.84070	-1.485230
0.3671667	79.84410	-1.437305
0.4205000	79.84460	-1.405360
0.4721666	79.84510	-1.386286
0.5238333	79.84575	-1.375628
0.5771668	79.84535	-1.369467
0.6305000	79.84498	-1.365972
0.6805000	79.84482	-1.363548
0.7338332	79.84311	-1.361102
0.7871668	79.84264	-1.358750
0.8371668	79.84286	-1.356757
0.8904999	79.84094	-1.354949
0.9438332	79.83978	-1.353360
0.9955000	79.83919	-1.352192
1.047167	79.83821	-1.351266
1.100500	79.83750	-1.350627
1.152167	79.83692	-1.350234
1.203834	79.83649	-1.350094
1.257166	79.83554	-1.350102
1.308833	79.83474	-1.350405
1.360500	79.83400	-1.350765
1.413834	79.83334	-1.351463
1.465500	79.83197	-1.352170
1.517167	79.83138	-1.353066
1.570500	79.83112	-1.354209
1.623833	79.82970	-1.355450
1.673834	79.82869	-1.356802
1.727167	79.82816	-1.358407
1.780500	79.82813	-1.360059
1.830500	79.82710	-1.361680
1.883833	79.82626	-1.363462
1.937166	79.82547	-1.365412
1.988833	79.82502	-1.367334
2.040500	79.82437	-1.369325
2.093834	79.82355	-1.371421
2.145500	79.82313	-1.373542
2.197166	79.82202	-1.375643
2.250500	79.82280	-1.377992
2.302166	79.82094	-1.380160
2.353833	79.82034	-1.382438
2.407167	79.81974	-1.384814
2.458833	79.81929	-1.387104
2.510500	79.81831	-1.389476
2.563833	79.81835	-1.391916
2.617167	79.81700	-1.394425
2.667167	79.81806	-1.396778
2.720500	79.81656	-1.399339
2.773833	79.81708	-1.401892
2.823833	79.81600	-1.404196
2.877167	79.81519	-1.406625
2.930500	79.81455	-1.409084
2.982167	79.81426	-1.411422
3.030500	79.86338	-2.866478
3.082167	80.96462	-19.90927
3.133833	83.23986	-33.60366
3.187167	86.24466	-45.89659
3.238834	89.63624	-56.06531
3.290500	93.36992	-64.53030
3.343834	97.48481	-71.67868
3.397167	101.7879	-77.50229
3.447167	105.9400	-81.99438
3.500500	110.4540	-85.99048
3.553833	114.9106	-86.71039
3.603833	118.1720	-75.45906
3.657167	120.6126	-63.64126
3.710500	122.4310	-52.82376
3.762167	123.7498	-43.86277
3.813833	124.7647	-36.41135
3.867166	125.5724	-30.24482
3.918833	126.1821	-25.55706
3.970500	126.6641	-21.91166
4.023834	127.0617	-19.01974
4.075500	127.3713	-16.87140
4.127167	127.6252	-15.22130
4.180500	127.8416	-13.91490
4.232167	128.0166	-12.94369
4.283834	128.1641	-12.19165
4.337167	128.2941	-11.58689
4.390500	128.4038	-11.10632
4.440500	128.4953	-10.75081
4.493834	128.5789	-10.43762
4.547167	128.6512	-10.18473
4.597166	128.7118	-9.988838
4.650500	128.7686	-9.806805
4.703833	128.8186	-9.656645
4.755500	128.8621	-9.534603
4.807167	128.9005	-9.424084
4.860500	128.9361	-9.325232
4.912167	128.9662	-9.241629
4.963834	128.9935	-9.163238
5.017166	129.0195	-9.093593
5.068833	129.0409	-9.032968
5.120500	129.0620	-8.977798
5.173834	129.0812	-8.927042
5.225500	129.0969	-8.880179
5.277168	129.1111	-8.838258
5.330500	129.1255	-8.798456
5.383832	129.1382	-8.762959
5.433832	129.1476	-8.728851
5.487168	129.1593	-8.699848
5.540500	129.1680	-8.669531
5.590500	129.1764	-8.643457
5.643832	129.1848	-8.615788
5.697168	129.1940	-8.591272
5.748834	129.2004	-8.565952
5.800500	129.2061	-8.540861
5.853832	129.2126	-8.516700
5.905500	129.2176	-8.493114
5.957168	129.2232	-8.471625
6.010500	129.2290	-8.447111
6.062168	129.2325	-8.424142
6.113834	129.2370	-8.404220
6.167168	129.2406	-8.381306
6.220500	129.2441	-8.361578
6.270500	129.2488	-8.342022
6.323834	129.2515	-8.321472
6.377168	129.2557	-8.301684
6.427168	129.2592	-8.281875
6.480500	129.2620	-8.259472
6.533832	129.2659	-8.235782
6.585500	129.2690	-8.213118
6.637168	129.2717	-8.188579
6.690500	129.2748	-8.162988
6.742166	129.2772	-8.136293
6.793832	129.2804	-8.111205
6.847168	129.2827	-8.085460
6.898834	129.2847	-8.063580
6.950500	129.2882	-8.042581
7.003832	129.2891	-8.013956
7.055500	129.2920	-7.993837
7.107168	129.2940	-7.970958
7.160500	129.2964	-7.948480
7.213834	129.2980	-7.925296
7.263834	129.2998	-7.905081
7.317168	129.3025	-7.884108
7.370500	129.3041	-7.862497
7.420500	129.3054	-7.842181
7.473834	129.3079	-7.819614
7.527168	129.3098	-7.798455
7.578834	129.3112	-7.775495
7.630500	129.3126	-7.753540
7.683832	129.3152	-7.731901
7.735500	129.3171	-7.708032
7.787168	129.3188	-7.683444
7.840500	129.3213	-7.657812
7.892168	129.3231	-7.630254
7.943832	129.3255	-7.603447
7.997168	129.3271	-7.575626
8.048834	129.3292	-7.548462
8.100500	129.3318	-7.522010
8.153832	129.3338	-7.496156
8.207168	129.3352	-7.467578
8.257168	129.3369	-7.442222
8.310500	129.3394	-7.415681
8.363834	129.3413	-7.389428
8.413834	129.3417	-7.364276
8.467168	129.3444	-7.336913
8.520500	129.3472	-7.308164
8.572168	129.3492	-7.281035
8.623834	129.3510	-7.252812
8.677168	129.3529	-7.225268
8.728834	129.3551	-7.197044
8.780500	129.3573	-7.172047
8.833832	129.3593	-7.146265
8.885499	129.3609	-7.121631
8.937166	129.3635	-7.096378
8.990500	129.3647	-7.070628
9.042168	129.3662	-7.046250
9.093832	129.3684	-7.023257
9.147168	129.3699	-6.999441
9.200500	129.3708	-6.974590
9.250500	129.3725	-6.950147
9.303832	129.3745	-6.923970
9.357166	129.3773	-6.901179
9.407166	129.3781	-6.878844
9.460499	129.3801	-6.854278
9.513832	129.3823	-6.828155
9.565500	129.3836	-6.803059
9.617166	129.3852	-6.778424
9.670500	129.3869	-6.751040
9.722168	129.3888	-6.725702
9.773834	129.3907	-6.700488
9.827168	129.3934	-6.671454
9.878834	129.3947	-6.641702
9.930500	129.3972	-6.613344
9.983832	129.3999	-6.582390
10.03550	129.4006	-6.552050
10.08717	129.4026	-6.524293
10.14050	129.4045	-6.491858
10.19383	129.4073	-6.464346
10.24383	129.4098	-6.437280
10.29717	129.4105	-6.407680
10.35050	129.4120	-6.378936
10.40050	129.4144	-6.353805
10.45383	129.4170	-6.324443
10.50717	129.4200	-6.293360
10.55884	129.4212	-6.262537
10.61050	129.4237	-6.230510
10.66383	129.4252	-6.198310
10.71550	129.4275	-6.169001
10.76717	129.4290	-6.138508
10.82050	129.4310	-6.108531
10.87217	129.4333	-6.076532
10.92383	129.4352	-6.042738
10.97717	129.4383	-6.005956
11.03050	129.4406	-5.964123
11.08050	129.4428	-5.924934
11.13383	129.4454	-5.884079
11.18716	129.4482	-5.843132
11.23717	129.4498	-5.806176
11.29050	129.4524	-5.767002
11.34383	129.4564	-5.726612
11.39550	129.4582	-5.685377
11.44717	129.4608	-5.643834
11.50050	129.4642	-5.598089
11.55216	129.4671	-5.551997
11.60383	129.4707	-5.503443
11.65717	129.4737	-5.451508
11.70883	129.4773	-5.396972
11.76050	129.4808	-5.337168
11.81383	129.4854	-5.268740
11.86550	129.4890	-5.199311
11.91717	129.4945	-5.119686
11.97050	129.5004	-5.018860
12.02383	129.5067	-4.895300
12.07383	129.5155	-4.766890
12.12717	129.5248	-4.624744
12.18050	129.5337	-4.493353
12.23050	129.5427	-4.380661
12.28383	129.5494	-4.268284
12.33717	129.5563	-4.170537
12.38883	129.5626	-4.085488
12.44050	129.5685	-4.001270
12.49384	129.5741	-3.927242
12.54550	129.5784	-3.858536
12.59717	129.5840	-3.796864
12.65050	129.5886	-3.737067
12.70217	129.5917	-3.687103
12.75384	129.5953	-3.642383
12.80717	129.5981	-3.601848
12.85883	129.6006	-3.569944
12.91050	129.6034	-3.542916
12.96383	129.6047	-3.517109
13.01717	129.6075	-3.495732
13.06716	129.6084	-3.478938
13.12050	129.6093	-3.464794
13.17383	129.6108	-3.452020
13.22383	129.6108	-3.442180
13.27717	129.6127	-3.432854
13.33050	129.6151	-3.423882
13.38216	129.6153	-3.415453
13.43383	129.6156	-3.408576
13.48716	129.6170	-3.401716
13.53883	129.6178	-3.394760
13.59050	129.6184	-3.387834
13.64383	129.6190	-3.380154
13.69550	129.6196	-3.372851
13.74717	129.6212	-3.365513
13.80050	129.6222	-3.357642
13.85217	129.6230	-3.349964
13.90383	129.6230	-3.342208
13.95717	129.6236	-3.334163
14.01050	129.6244	-3.326191
14.06050	129.6254	-3.318637
14.11383	129.6252	-3.310550
14.16716	129.6262	-3.302554
14.21716	129.6263	-3.295136
14.27050	129.6265	-3.287292
14.32384	129.6265	-3.279474
14.37550	129.6275	-3.272033
14.42717	129.6279	-3.264643
14.48050	129.6289	-3.257110
14.53217	129.6280	-3.249936
14.58383	129.6288	-3.242965
14.63717	129.6286	-3.235901
14.68883	129.6294	-3.229262
14.74050	129.6294	-3.222837
14.79384	129.6293	-3.216323
14.84550	129.6301	-3.210268
14.89717	129.6304	-3.204441
14.95050	129.6304	-3.198599
15.00383	129.6309	-3.192950
15.05383	129.6307	-3.187602
15.10716	129.6305	-3.182079
15.16050	129.6315	-3.176650
15.21050	129.6322	-3.171700
15.26383	129.6317	-3.166575
15.31716	129.6314	-3.161552
15.36884	129.6327	-3.156778
15.42050	129.6326	-3.152094
15.47383	129.6317	-3.147460
15.52550	129.6330	-3.143046
15.57717	129.6330	-3.138675
15.63050	129.6340	-3.134255
15.68217	129.6336	-3.130076
15.73383	129.6336	-3.125944
15.78717	129.6336	-3.121855
15.84050	129.6338	-3.117875
15.89050	129.6343	-3.114281
15.94384	129.6338	-3.110510
15.99717	129.6354	-3.106876
16.04716	129.6354	-3.103511
16.10050	129.6341	-3.100027
16.15383	129.6347	-3.096696
16.20550	129.6353	-3.093591
16.25716	129.6353	-3.090517
16.31050	129.6344	-3.087390
16.36216	129.6357	-3.084385
16.41383	129.6362	-3.081423
16.46716	129.6366	-3.078428
16.51883	129.6362	-3.075530
16.57050	129.6356	-3.072647
16.62383	129.6365	-3.069866
16.67550	129.6359	-3.067208
16.72716	129.6354	-3.064667
16.78050	129.6364	-3.062065
16.83383	129.6363	-3.059486
16.88383	129.6359	-3.057116
16.93716	129.6370	-3.054619
16.99050	129.6366	-3.052199
17.04050	129.6369	-3.049919
17.09383	129.6375	-3.047488
17.14716	129.6382	-3.045090
17.19884	129.6378	-3.042785
17.25050	129.6383	-3.040587
17.30383	129.6378	-3.038320
17.35550	129.6381	-3.036212
17.40716	129.6382	-3.034099
17.46050	129.6388	-3.031878
17.51216	129.6388	-3.029732
17.56383	129.6388	-3.027610
17.61716	129.6388	-3.025460
17.66883	129.6393	-3.023414
17.72050	129.6393	-3.021384
17.77383	129.6387	-3.019250
17.82716	129.6389	-3.017153
17.87716	129.6392	-3.015288
17.93050	129.6391	-3.013216
17.98383	129.6398	-3.011159
18.03383	129.6399	-3.009243
18.08716	129.6401	-3.007260
18.14050	129.6397	-3.005233
18.19216	129.6393	-3.003266
18.24383	129.6402	-3.001461
18.29716	129.6405	-2.999608
18.34883	129.6402	-2.997963
18.40050	129.6407	-2.996318
18.45383	129.6401	-2.994596
18.50550	129.6411	-2.992930
18.55716	129.6406	-2.991259
18.61050	129.6402	-2.989532
18.66217	129.6409	-2.987938
18.71383	129.6406	-2.986270
18.76716	129.6405	-2.984547
18.82050	129.6406	-2.982874
18.87050	129.6408	-2.981292
18.92383	129.6414	-2.979644
18.97716	129.6405	-2.977982
19.02716	129.6405	-2.976542
19.08050	129.6414	-2.975078
19.13383	129.6408	-2.973475
19.18550	129.6420	-2.972067
19.23716	129.6415	-2.970553
19.29050	129.6422	-2.968994
19.34216	129.6421	-2.967515
19.39383	129.6422	-2.966050
19.44716	129.6416	-2.964524
19.49883	129.6427	-2.963225
19.55050	129.6426	-2.961856
19.60383	129.6432	-2.960440
19.65550	129.6433	-2.959025
19.70716	129.6429	-2.957600
19.76050	129.6425	-2.956138
19.81383	129.6426	-2.954613
19.86383	129.6434	-2.953248
19.91716	129.6429	-2.951726
19.97050	129.6432	-2.950306
20.02050	129.6434	-2.948912
20.07383	129.6428	-2.947394
20.12716	129.6434	-2.946016
20.17883	129.6432	-2.944566
20.23050	129.6432	-2.943230
20.28383	129.6440	-2.941886
20.33550	129.6438	-2.940554
20.38716	129.6444	-2.939334
20.44050	129.6447	-2.938002
20.49216	129.6439	-2.936674
20.54383	129.6444	-2.935310
20.59716	129.6439	-2.933916
20.65050	129.6446	-2.932535
20.70050	129.6447	-2.931200
20.75383	129.6437	-2.929702
20.80716	129.6448	-2.928299
20.85716	129.6445	-2.926909
20.91050	129.6446	-2.925534
20.96383	129.6456	-2.924202
21.01550	129.6449	-2.922721
21.06716	129.6453	-2.921303
21.12050	129.6445	-2.919828
21.17216	129.6450	-2.918378
21.22383	129.6455	-2.916916
21.27717	129.6454	-2.915455
21.32883	129.6454	-2.914025
21.38050	129.6444	-2.912617
21.43383	129.6449	-2.911206
21.48550	129.6452	-2.909831
21.53717	129.6452	-2.908473
21.59050	129.6457	-2.907140
21.64383	129.6465	-2.905800
21.69383	129.6458	-2.904610
21.74716	129.6471	-2.903336
21.80050	129.6473	-2.902114
21.85050	129.6468	-2.900919
21.90383	129.6468	-2.899646
21.95717	129.6478	-2.898429
22.00883	129.6482	-2.897064
22.06050	129.6474	-2.895658
22.11383	129.6478	-2.894217
22.16550	129.6476	-2.892677
22.21716	129.6473	-2.891138
22.27050	129.6479	-2.889500
22.32216	129.6472	-2.887887
22.37383	129.6466	-2.886238
22.42717	129.6476	-2.884578
22.47883	129.6476	-2.882865
22.53050	129.6470	-2.881080
22.58383	129.6469	-2.879252
22.63716	129.6467	-2.877454
22.68716	129.6472	-2.875778
22.74050	129.6473	-2.874166
22.79383	129.6475	-2.872487
22.84383	129.6472	-2.870974
22.89716	129.6481	-2.869265
22.95050	129.6491	-2.867639
23.00217	129.6488	-2.865994
23.05383	129.6497	-2.864339
23.10716	129.6492	-2.862639
23.15883	129.6497	-2.860980
23.21050	129.6502	-2.859247
23.26383	129.6504	-2.857366
23.31550	129.6505	-2.855497
23.36716	129.6507	-2.853613
23.42050	129.6509	-2.851672
23.47216	129.6511	-2.849861
23.52383	129.6515	-2.847954
23.57716	129.6511	-2.845942
23.63050	129.6503	-2.843926
23.68050	129.6510	-2.842106
23.73383	129.6513	-2.840020
23.78717	129.6520	-2.837902
23.83716	129.6520	-2.835880
23.89050	129.6524	-2.833645
23.94383	129.6518	-2.831409
23.99550	129.6527	-2.829303
24.04716	129.6522	-2.827007
24.10050	129.6515	-2.824601
24.15216	129.6521	-2.822268
24.20383	129.6524	-2.819914
24.25716	129.6528	-2.817398
24.30883	129.6524	-2.815020
24.36050	129.6530	-2.812675
24.41383	129.6532	-2.810160
24.46550	129.6532	-2.807746
24.51716	129.6535	-2.805226
24.57050	129.6541	-2.802601
24.62383	129.6532	-2.799837
24.67383	129.6534	-2.797262
24.72716	129.6542	-2.794469
24.78050	129.6550	-2.791513
24.83050	129.6541	-2.788722
24.88383	129.6544	-2.785817
24.93716	129.6548	-2.783000
24.98883	129.6549	-2.780230
25.04050	129.6548	-2.777560
25.09383	129.6555	-2.774944
25.14550	129.6560	-2.772438
25.19716	129.6564	-2.769998
25.25050	129.6564	-2.767580
25.30217	129.6574	-2.765366
25.35383	129.6571	-2.763097
25.40716	129.6577	-2.760786
25.46050	129.6578	-2.758378
25.51050	129.6575	-2.756174
25.56383	129.6572	-2.753837
25.61716	129.6580	-2.751368
25.66716	129.6589	-2.749090
25.72050	129.6586	-2.746478
25.77383	129.6588	-2.743980
25.82550	129.6592	-2.741405
25.87716	129.6594	-2.738789
25.93050	129.6593	-2.735932
25.98216	129.6587	-2.733026
26.03383	129.6604	-2.730152
26.08716	129.6599	-2.727151
26.13883	129.6607	-2.724112
26.19050	129.6609	-2.721024
26.24383	129.6607	-2.717848
26.29550	129.6611	-2.714722
26.34716	129.6615	-2.711550
26.40050	129.6617	-2.708244
26.45383	129.6620	-2.704898
26.50383	129.6636	-2.701694
26.55716	129.6640	-2.698245
26.61050	129.6639	-2.694662
26.66050	129.6648	-2.691286
26.71383	129.6638	-2.687528
26.76716	129.6644	-2.683719
26.81883	129.6640	-2.679963
26.87050	129.6654	-2.676207
26.92383	129.6646	-2.672421
26.97550	129.6649	-2.668789
27.02717	129.6654	-2.665154
27.08050	129.6647	-2.661378
27.13216	129.6659	-2.657902
27.18383	129.6658	-2.654322
27.23716	129.6657	-2.650708
27.28883	129.6654	-2.647189
27.34050	129.6662	-2.643742
27.39383	129.6663	-2.640191
27.44717	129.6672	-2.636583
27.49716	129.6668	-2.633168
27.55050	129.6667	-2.629541
27.60383	129.6668	-2.625941
27.65383	129.6665	-2.622504
27.70716	129.6680	-2.618818
27.76050	129.6665	-2.615170
27.81217	129.6670	-2.611738
27.86383	129.6674	-2.608326
27.91716	129.6672	-2.604930
27.96883	129.6682	-2.601697
28.02050	129.6679	-2.598501
28.07383	129.6688	-2.595288
28.12550	129.6690	-2.592222
28.17717	129.6691	-2.589100
28.23050	129.6692	-2.585964
28.28216	129.6695	-2.582924
28.33383	129.6682	-2.579842
28.38716	129.6700	-2.576738
28.44050	129.6702	-2.573624
28.49050	129.6699	-2.570668
28.54383	129.6705	-2.567585
28.59716	129.6712	-2.564484
28.64716	129.6714	-2.561577
28.70050	129.6712	-2.558599
28.75383	129.6716	-2.555617
28.80550	129.6714	-2.552772
28.85716	129.6720	-2.550065
28.91050	129.6716	-2.547256
28.96216	129.6721	-2.544574
29.01383	129.6728	-2.541907
29.06716	129.6731	-2.539118
29.11883	129.6732	-2.536449
29.17050	129.6725	-2.533872
29.22383	129.6733	-2.531168
29.27550	129.6738	-2.528469
29.32717	129.6732	-2.525774
29.38050	129.6737	-2.523030
29.43383	129.6738	-2.520183
29.48383	129.6731	-2.517535
29.53717	129.6736	-2.514830
29.59050	129.6746	-2.512148
29.64050	129.6737	-2.509657
29.69383	129.6745	-2.507120
29.74716	129.6744	-2.504578
29.79883	129.6746	-2.502175
29.85050	129.6749	-2.499792
29.90383	129.6751	-2.497354
29.95550	129.6755	-2.495033
30.00716	129.6758	-2.492643
30.06050	129.6760	-2.490220
30.11216	129.6761	-2.487894
30.16383	129.6764	-2.485554
30.21716	129.6762	-2.483200
30.27050	129.6762	-2.480753
30.32050	129.6759	-2.478522
30.37383	129.6774	-2.476140
30.42717	129.6772	-2.473765
30.47717	129.6777	-2.471570
30.53050	129.6772	-2.469170
30.58383	129.6781	-2.466885
30.63550	129.6779	-2.464625
30.68717	129.6778	-2.462317
30.74050	129.6781	-2.459963
30.79216	129.6781	-2.457670
30.84383	129.6785	-2.455412
30.89716	129.6785	-2.453164
30.94883	129.6784	-2.450939
31.00050	129.6780	-2.448638
31.05383	129.6780	-2.446318
31.10550	129.6784	-2.444091
31.15716	129.6772	-2.441726
31.21050	129.6779	-2.439352
31.26383	129.6786	-2.437073
31.31383	129.6771	-2.434963
31.36716	129.6780	-2.432796
31.42050	129.6773	-2.430701
31.47050	129.6776	-2.428842
31.52383	129.6780	-2.426861
31.57717	129.6785	-2.424852
31.62883	129.6781	-2.422789
31.68050	129.6791	-2.420800
31.73383	129.6788	-2.418817
31.78550	129.6791	-2.416915
31.83716	129.6791	-2.415005
31.89050	129.6794	-2.413116
31.94216	129.6803	-2.411350
31.99383	129.6806	-2.409568
32.04716	129.6802	-2.407734
32.09883	129.6802	-2.405987
32.15050	129.6814	-2.404330
32.20383	129.6816	-2.402537
32.25716	129.6811	-2.400725
32.30716	129.6821	-2.398925
32.36050	129.6817	-2.397077
32.41383	129.6817	-2.395086
32.46383	129.6816	-2.393334
32.51716	129.6829	-2.391451
32.57050	129.6821	-2.389574
32.62216	129.6826	-2.387774
32.67383	129.6824	-2.385867
32.72717	129.6824	-2.384074
32.77883	129.6830	-2.382314
32.83050	129.6837	-2.380503
32.88383	129.6824	-2.378661
32.93550	129.6825	-2.376791
32.98717	129.6824	-2.374910
33.04050	129.6825	-2.372936
33.09216	129.6827	-2.370970
33.14383	129.6822	-2.369039
33.19717	129.6830	-2.367014
33.25050	129.6830	-2.365037
33.30050	129.6820	-2.363276
33.35383	129.6835	-2.361446
33.40716	129.6816	-2.359648
33.45716	129.6833	-2.358136
33.51050	129.6832	-2.356473
33.56383	129.6830	-2.354679
33.61550	129.6840	-2.353068
33.66716	129.6850	-2.351434
33.72050	129.6843	-2.349606
33.77217	129.6840	-2.347890
33.82383	129.6841	-2.346244
33.87717	129.6848	-2.344530
33.92883	129.6841	-2.342684
33.98050	129.6844	-2.340953
34.03383	129.6838	-2.339042
34.08550	129.6846	-2.337234
34.13716	129.6844	-2.335296
34.19050	129.6839	-2.333378
34.24383	129.6843	-2.331508
34.29383	129.6852	-2.329807
34.34716	129.6846	-2.328154
34.40050	129.6845	-2.326463
34.45050	129.6848	-2.324963
34.50383	129.6854	-2.323284
34.55716	129.6852	-2.321720
34.60883	129.6868	-2.320234
34.66050	129.6874	-2.318740
34.71383	129.6871	-2.317186
34.76550	129.6868	-2.315664
34.81716	129.6872	-2.314110
34.87050	129.6874	-2.312551
34.92216	129.6879	-2.311028
34.97383	129.6879	-2.309412
35.02716	129.6886	-2.307759
35.08050	129.6876	-2.306040
35.13050	129.6883	-2.304489
35.18384	129.6885	-2.302776
35.23717	129.6890	-2.301150
35.28717	129.6888	-2.299567
35.34050	129.6893	-2.297836
35.39383	129.6899	-2.296164
35.44550	129.6892	-2.294428
35.49716	129.6895	-2.292676
35.55050	129.6893	-2.290876
35.60217	129.6892	-2.289125
35.65383	129.6900	-2.287410
35.70716	129.6895	-2.285648
35.75883	129.6893	-2.283931
35.81050	129.6895	-2.282237
35.86383	129.6901	-2.280509
35.91550	129.6896	-2.278748
35.96716	129.6893	-2.277046
36.02050	129.6900	-2.275398
36.07383	129.6901	-2.273714
36.12383	129.6897	-2.272084
36.17717	129.6898	-2.270354
36.23050	129.6901	-2.268659
36.28050	129.6898	-2.266934
36.33383	129.6891	-2.265059
36.38716	129.6898	-2.263211
36.43883	129.6894	-2.261351
36.49050	129.6899	-2.259518
36.54383	129.6893	-2.257556
36.59550	129.6890	-2.255676
36.64717	129.6894	-2.253923
36.70050	129.6896	-2.252152
36.75217	129.6892	-2.250480
36.80383	129.6904	-2.248944
36.85716	129.6893	-2.247224
36.90883	129.6904	-2.245673
36.96050	129.6902	-2.243964
37.01383	129.6904	-2.242264
37.06716	129.6906	-2.240454
37.11716	129.6909	-2.238777
37.17050	129.6906	-2.236946
37.22383	129.6919	-2.235246
37.27383	129.6912	-2.233668
37.32717	129.6919	-2.232066
37.38050	129.6916	-2.230423
37.43216	129.6914	-2.228758
37.48383	129.6918	-2.227162
37.53717	129.6917	-2.225470
37.58883	129.6922	-2.223892
37.64050	129.6923	-2.222380
37.69383	129.6923	-2.220773
37.74550	129.6922	-2.219115
37.79716	129.6936	-2.217611
37.85050	129.6939	-2.216032
37.90216	129.6941	-2.214455
37.95383	129.6934	-2.212900
38.00716	129.6941	-2.211348
38.06050	129.6949	-2.209699
38.11050	129.6957	-2.208208
38.16383	129.6958	-2.206489
38.21716	129.6952	-2.204741
38.26716	129.6953	-2.203135
38.32050	129.6964	-2.201427
38.37383	129.6958	-2.199625
38.42550	129.6951	-2.197865
38.47717	129.6950	-2.196095
38.53050	129.6953	-2.194173
38.58216	129.6948	-2.192306
38.63383	129.6947	-2.190584
38.68716	129.6957	-2.188870
38.73883	129.6951	-2.187150
38.79050	129.6964	-2.185474
38.84384	129.6960	-2.183786
38.89550	129.6964	-2.182182
38.94717	129.6957	-2.180549
39.00050	129.6961	-2.178946
39.05383	129.6966	-2.177202
39.10383	129.6967	-2.175645
39.15716	129.6965	-2.173931
39.21050	129.6956	-2.172302
39.26050	129.6963	-2.170678
39.31383	129.6959	-2.168972
39.36716	129.6957	-2.167328
39.41883	129.6960	-2.165787
39.47050	129.6964	-2.164322
39.52383	129.6975	-2.162766
39.57550	129.6968	-2.161266
39.62717	129.6974	-2.159826
39.68050	129.6967	-2.158358
39.73216	129.6972	-2.156970
39.78383	129.6970	-2.155542
39.83716	129.6974	-2.154070
39.89050	129.6986	-2.152581
39.94050	129.6969	-2.151125
39.99383	129.6974	-2.149623
40.04716	129.6986	-2.148217
40.09716	129.6982	-2.146858
40.15050	129.6984	-2.145448
40.20383	129.6976	-2.144037
40.25550	129.6985	-2.142770
40.30716	129.6988	-2.141441
40.36050	129.6986	-2.140040
40.41217	129.6992	-2.138713
40.46383	129.6992	-2.137309
40.51716	129.6984	-2.135910
40.56883	129.6988	-2.134651
40.62050	129.6982	-2.133303
40.67383	129.6992	-2.131926
40.72550	129.6989	-2.130582
40.77716	129.6993	-2.129319
40.83050	129.6982	-2.127956
40.88383	129.6983	-2.126534
40.93384	129.6991	-2.125256
40.98717	129.6981	-2.123808
41.04050	129.6979	-2.122345
41.09050	129.6978	-2.121075
41.14383	129.6977	-2.119735
41.19717	129.6979	-2.118475
41.24883	129.6981	-2.117272
41.30050	129.6988	-2.116212
41.35383	129.6991	-2.115134
41.40550	129.6988	-2.114188
41.45717	129.6989	-2.113209
41.51050	129.6993	-2.112174
41.56216	129.6997	-2.111181
41.61383	129.6997	-2.110156
41.66716	129.6995	-2.109154
41.71884	129.6998	-2.108227
41.77050	129.7005	-2.107205
41.82383	129.7006	-2.106178
41.87717	129.6996	-2.105118
41.92717	129.7007	-2.104166
41.98050	129.7003	-2.103180
42.03383	129.7004	-2.102180
42.08383	129.7012	-2.101316
42.13716	129.7009	-2.100361
42.19050	129.7012	-2.099335
42.24216	129.7016	-2.098395
42.29383	129.7012	-2.097463
42.34716	129.7008	-2.096528
42.39883	129.7017	-2.095554
42.45050	129.7005	-2.094627
42.50383	129.7015	-2.093612
42.55550	129.7011	-2.092652
42.60717	129.7013	-2.091730
42.66050	129.7013	-2.090791
42.71216	129.7019	-2.089836
42.76383	129.7008	-2.088823
42.81717	129.7007	-2.087715
42.87050	129.7010	-2.086607
42.92050	129.7000	-2.085605
42.97383	129.7011	-2.084522
43.02217	129.7010	-2.083924
43.07383	129.7784	-4.143534
43.12717	130.1359	-8.106182
43.17883	130.6703	-11.08649
43.23050	131.3363	-13.48065
43.28383	132.1216	-15.31714
43.33550	132.9500	-16.66358
43.38716	133.8241	-17.71623
43.44050	134.7605	-18.56910
43.49216	135.6925	-19.23609
43.54383	136.6432	-19.76762
43.59716	137.6384	-20.21656
43.65050	138.6469	-20.60172
43.70050	139.5982	-20.91255
43.75383	140.6206	-21.22746
43.80717	141.6461	-21.54208
43.85717	142.6104	-21.83824
43.91050	143.6406	-22.14635
43.96383	144.6722	-22.49733
44.01550	145.6705	-22.86336
44.06717	146.6680	-23.30945
44.12050	147.6947	-23.82494
44.17216	148.6857	-24.40054
44.22383	149.6739	-24.98066
44.27716	150.6973	-25.43493
44.32883	151.6968	-25.67473
44.38050	152.7058	-25.79430
44.43383	153.7494	-26.14574
44.48550	154.7601	-26.33716
44.53717	155.7766	-26.42044
44.59050	156.8308	-26.50860
44.64383	157.8882	-26.60981
44.69383	158.8741	-26.88291
44.74716	159.9309	-26.89682
44.80050	160.9935	-26.90530
44.85050	161.9923	-26.90151
44.90383	163.0576	-26.89730
44.95717	164.1236	-26.89314
45.00883	165.1476	-27.21458
45.06050	166.1696	-27.31612
45.11383	167.2312	-27.29830
45.16550	168.2652	-27.28758
45.21717	169.3008	-27.19480
45.27050	170.3627	-27.27802
45.32217	171.3929	-27.30754
45.37383	172.4262	-27.28550
45.42717	173.5002	-27.02727
45.48050	174.5769	-26.76594
45.53050	175.5912	-26.50882
45.58383	176.6742	-26.23732
45.63716	177.7575	-25.94285
45.68716	178.7768	-25.53314
45.74050	179.8683	-25.08875
45.79383	180.9630	-24.61884
45.84550	182.0238	-24.17532
45.89717	183.0870	-23.68789
45.95050	184.1860	-23.14192
46.00217	185.2502	-22.73560
46.05383	186.3094	-22.41612
46.10717	187.3990	-22.12846
46.15883	188.4506	-21.88867
46.21050	189.5018	-21.65167
46.26383	190.5850	-21.45412
46.31550	191.6316	-21.29316
46.36716	192.6758	-21.21960
46.42050	193.7510	-21.10991
46.47383	194.8253	-21.02186
46.52383	195.8328	-20.91703
46.57717	196.9066	-20.81232
46.63050	197.9822	-20.66184
46.68050	198.9864	-21.03442
46.73383	200.0347	-21.27795
46.78717	201.0992	-21.17456
46.83883	202.1374	-20.92148
46.89050	203.1784	-20.68237
46.94383	204.2556	-20.46294
46.99550	205.3000	-20.28892
47.04716	206.3430	-20.14372
47.10050	207.4190	-20.05310
47.15216	208.4585	-20.04973
47.20383	209.4907	-20.14672
47.25717	210.5474	-20.64168
47.30883	211.5609	-21.13777
47.36050	212.5690	-21.64006
47.41383	213.6081	-22.12351
47.46717	214.6468	-22.55700
47.51717	215.6240	-22.81088
47.57050	216.6830	-22.29128
47.62383	217.7910	-20.42769
47.67383	218.8530	-19.43235
47.72717	219.9706	-19.04138
47.78050	221.0688	-18.87713
47.83217	222.1192	-18.86575
47.88383	223.1596	-18.92984
47.93716	224.2248	-19.03239
47.98883	225.2533	-19.33701
48.04050	226.2756	-19.64973
48.09384	227.3272	-19.96272
48.14550	228.3438	-20.30264
48.19717	229.3568	-20.66101
48.25050	230.4028	-21.04439
48.30217	231.4142	-21.43231
48.35383	232.4256	-21.80990
48.40717	233.4706	-22.17002
48.46050	234.5168	-22.54060
48.51050	235.4973	-22.86284
48.56383	236.5436	-23.18604
48.61716	237.5923	-23.49458
48.66716	238.5757	-23.76697
48.72050	239.6260	-24.04678
48.77383	240.6762	-24.29218
48.82550	241.6956	-24.54931
48.87717	242.7153	-24.77106
48.93050	243.7668	-25.00291
48.98217	244.7894	-25.19840
49.03383	245.8118	-25.37402
49.08716	246.8679	-25.54845
49.13883	247.8922	-25.70160
49.19050	248.9166	-25.85029
49.24383	249.9745	-26.01050
49.29550	250.9996	-26.15277
49.34716	252.0252	-26.28022
49.40050	253.0833	-26.41872
49.45383	254.1419	-26.54463
49.50383	255.1348	-26.67339
49.55717	256.1947	-26.80981
49.61050	257.2537	-26.93105
49.66050	258.2466	-27.05115
49.71383	259.3072	-27.17865
49.76717	260.3662	-27.29321
49.81883	261.3938	-27.42376
49.87050	262.4209	-27.53860
49.92383	263.4818	-27.64576
49.97550	264.5093	-27.77728
50.02716	265.5366	-27.88469
50.08050	266.5990	-28.00639
50.13217	267.6260	-28.12000
50.18383	268.6528	-28.24074
50.23717	269.7142	-28.35682
50.29050	270.7740	-28.46057
50.34050	271.7683	-28.56932
50.39383	272.8298	-28.68872
50.44717	273.8899	-28.78846
50.49716	274.8668	-28.14450
50.54716	275.8110	-30.67252
50.59716	276.3618	-27.11562
50.65050	276.4358	-17.64978
50.70383	276.1646	-10.13239
50.75550	275.6756	-4.882171
50.80717	275.0371	-1.169558
50.86050	274.2698	1.503402
50.91217	273.4556	3.313601
50.96383	272.5917	4.609380
51.01717	271.6632	5.564604
51.06883	270.7384	6.243910
51.12050	269.7950	6.750250
51.17383	268.8082	7.156356
51.22550	267.8399	7.460863
51.27717	266.8651	7.717578
51.33050	265.8498	7.937530
51.38383	264.8294	8.110284
51.43383	263.8686	8.257900
51.48717	262.8401	8.395722
51.54050	261.8068	8.525156
51.59050	260.8364	8.632162
51.64384	259.7996	8.734730
51.69717	258.7588	8.837841
51.74883	257.7503	8.923319
51.80050	256.7396	9.016509
51.85383	255.6963	9.107675
51.90550	254.6834	9.192931
51.95717	253.6694	9.270020
52.01050	252.6214	9.350806
52.06216	251.6058	9.420411
52.11383	250.5890	9.492344
52.16716	249.5399	9.565613
52.21884	248.5211	9.640431
52.27050	247.5031	9.705284
52.32383	246.4512	9.773047
52.37717	245.3980	9.840832
52.42717	244.4111	9.900611
52.48050	243.3568	9.959399
52.53383	242.3021	10.01092
52.58383	241.3133	10.06182
52.63716	240.2580	10.10950
52.69050	239.2035	10.16514
52.74216	238.1809	10.21600
52.79382	237.1585	10.26398
52.84716	236.1018	10.32101
52.89883	235.0783	10.36868
52.95050	234.0554	10.41091
53.00383	232.9994	10.46512
53.05550	231.9764	10.50912
53.10717	230.9528	10.55586
53.16050	229.8952	10.60582
53.21216	228.8714	10.64776
53.26382	227.8469	10.69729
53.31716	226.7903	10.74384
53.37050	225.7330	10.79172
53.42050	224.7424	10.83864
53.47382	223.6847	10.88987
53.52717	222.6268	10.93121
53.57717	221.6358	10.97166
53.63050	220.5769	11.01448
53.68383	219.5202	11.06020
53.73550	218.4944	11.10787
53.78716	217.4700	11.14602
53.84050	216.4116	11.18936
53.89216	215.3875	11.22745
53.94384	214.3617	11.26480
53.99717	213.3028	11.30486
54.04883	212.2775	11.34280
54.10050	211.2523	11.38169
54.15383	210.1944	11.42077
54.20550	209.1685	11.46057
54.25717	208.1431	11.49507
54.31050	207.0848	11.53007
54.36382	206.0264	11.56855
54.41382	205.0340	11.60493
54.46717	203.9760	11.64094
54.52050	202.9170	11.68244
54.57050	201.9245	11.71263
54.62383	200.8656	11.75905
54.67717	199.8073	11.79633
54.72883	198.7816	11.83627
54.78050	197.7555	11.87400
54.83383	196.6967	11.91086
54.88550	195.6711	11.94335
54.93716	194.6450	11.98047
54.99050	193.5850	12.01487
55.04217	192.5599	12.04332
55.09384	191.5344	12.08100
55.14717	190.4754	12.11850
55.20050	189.4170	12.15292
55.25050	188.4242	12.18620
55.30383	187.3656	12.22131
55.35717	186.3054	12.25986
55.40717	185.3129	12.28918
55.46050	184.2528	12.31901
55.51382	183.1930	12.34442
55.56550	182.1665	12.37256
55.61716	181.1403	12.40410
55.67050	180.0809	12.44284
55.72217	179.0552	12.48013
55.77383	178.0285	12.51822
55.82717	176.9688	12.56084
55.87883	175.9445	12.61021
55.93050	174.9198	12.68496
55.98383	173.8626	12.78903
56.03550	172.8395	12.93944
56.08716	171.8207	13.14624
56.14050	170.7712	13.46501
56.19384	169.7302	13.88549
56.24382	168.7601	14.45330
56.29717	167.7350	15.24202
56.35050	166.7254	16.35150
56.40050	165.7976	17.76959
56.45383	164.8308	19.66523
56.50717	163.8898	21.88994
56.55883	162.9948	24.19338
56.61050	162.1104	26.49793
56.66382	161.1962	28.57455
56.71550	160.2958	30.19309
56.76716	159.3730	31.33523
56.82050	158.3914	31.96408
56.87217	157.4094	32.11408
56.92383	156.3976	31.85534
56.97717	155.3237	31.14202
57.02883	154.2596	30.17572
57.08050	153.1750	28.95625
57.13383	152.0381	27.52273
57.18716	150.8897	25.99952
57.23717	149.8049	24.55312
57.29050	148.6457	23.07832
57.34384	147.4899	21.72556
57.39384	146.4109	20.58045
57.44717	145.2684	19.52748
57.50050	144.1356	18.65729
57.55217	143.0493	17.96116
57.60383	141.9718	17.38292
57.65717	140.8689	16.90462
57.70883	139.8064	16.50802
57.76050	138.7490	16.18089
57.81382	137.6623	15.91745
57.86550	136.6158	15.70708
57.91716	135.5716	15.53998
57.97050	134.4966	15.40373
58.02217	133.4579	15.27599
58.07383	132.4208	15.17230
58.12717	131.3505	15.06493
58.18050	130.2819	14.96544
58.23050	129.2803	14.89855
58.28383	128.2124	14.83184
58.33716	127.1455	14.78204
58.38716	126.1466	14.74824
58.44050	125.0796	14.68260
58.49382	124.0148	14.63934
58.54550	122.9826	14.59824
58.59716	121.9513	14.54806
58.65050	120.8860	14.50384
58.70216	119.8558	14.47180
58.75383	118.8243	14.45314
58.80717	117.7600	14.42333
58.85883	116.7278	14.40014
58.91050	115.6962	14.37228
58.96382	114.6312	14.33892
59.01550	113.5994	14.31184
59.06716	112.5686	14.28023
59.12050	111.5046	14.26048
59.17383	110.4407	14.24434
59.22382	109.4436	14.21346
59.27717	108.3816	14.19946
59.33050	107.3172	14.18216
59.38050	106.3208	14.17379
59.43383	105.2587	14.16357
59.48717	104.1956	14.14842
59.53882	103.1656	14.13147
59.59050	102.1360	14.12491
59.64384	101.0744	14.11699
59.69550	100.0445	14.10986
59.74717	99.01439	14.09852
59.80050	97.95038	14.07952
59.85217	96.92111	14.06789
59.90383	95.89256	14.05836
59.95717	94.82939	14.05121
60.01050	93.76712	14.04306
60.06050	92.76942	14.03255
60.11382	91.70662	14.02362
60.16716	90.64228	14.00985
60.21717	89.64532	13.99577
60.27050	88.58180	13.98180
60.32383	87.51851	13.96512
60.37550	86.48798	13.93317
60.42717	85.45624	13.90240
60.48050	84.39259	13.86696
60.53217	83.36285	13.84909
60.58383	82.33250	13.83277
60.63716	81.26916	13.81753
60.68882	80.23905	13.80270
60.74050	79.20972	13.78848
60.79382	78.14485	13.76999
60.84550	77.11519	13.75848
60.89717	76.08501	13.73974
60.95050	75.02232	13.72484
61.00383	73.95862	13.71288
61.05383	72.96088	13.69031
61.10717	71.89692	13.67188
61.16050	70.83336	13.64799
61.21050	69.83542	13.62552
61.26382	68.77148	13.58465
61.31716	67.70660	13.54989
61.36882	66.67514	13.51518
61.42050	65.64466	13.48906
61.47382	64.57982	13.46150
61.52550	63.54943	13.43854
61.57717	62.51910	13.41027
61.63050	61.45490	13.38372
61.68217	60.42436	13.35391
61.73383	59.39281	13.33107
61.78716	58.32816	13.29053
61.83882	57.29626	13.24415
61.89050	56.26502	13.21406
61.94384	55.20006	13.18542
61.99717	54.13489	13.15192
62.04717	53.13804	13.12166
62.10050	52.07348	13.08694
62.15383	51.00800	13.06048
62.20383	50.01098	13.03424
62.25717	48.94486	13.00489
62.31050	47.88227	12.97789
62.36217	46.85078	12.94604
62.41382	45.81949	12.92271
62.46717	44.75402	12.89181
62.51884	43.72314	12.87200
62.57050	42.69187	12.84911
62.62383	41.62703	12.80768
62.67550	40.59441	12.77894
62.72717	39.56338	12.73842
62.78050	38.49708	12.68405
62.83217	37.46260	12.59801
62.88383	36.42903	12.54880
62.93716	35.36230	12.48820
62.99050	34.29474	12.42838
63.04050	33.29529	12.36407
63.09384	32.22801	12.32171
63.14717	31.16156	12.26294
63.19717	30.16041	12.21719
63.25050	29.09440	12.16908
63.30383	28.02610	12.10710
63.35550	26.99240	12.05291
63.40717	25.95917	11.99433
63.46050	24.89155	11.97033
63.51050	23.89043	11.96818
63.56216	22.93891	12.55375
63.61382	22.49088	6.747588
63.66716	22.47837	1.260130
63.71884	22.77772	-2.516518
63.77050	23.28990	-4.959519
63.82383	23.97130	-6.667097
63.87550	24.73492	-7.787951
63.92717	25.56690	-8.593808
63.98050	26.47646	-9.181625
64.03384	27.42291	-9.625171
64.08384	28.33201	-9.933751
64.13717	29.31976	-10.20828
64.19050	30.32219	-10.41227
64.24050	31.26944	-10.57098
64.29384	32.28789	-10.70834
64.34717	33.30975	-10.83566
64.39883	34.30538	-10.95364
64.45050	35.30283	-11.06178
64.50384	36.33750	-11.15883
64.55550	37.34133	-11.26063
64.60718	38.34706	-11.35240
64.66050	39.38844	-11.43699
64.71217	40.39920	-11.51410
64.76384	41.41072	-11.59897
64.81717	42.45777	-11.67990
64.87050	43.50389	-11.76114
64.92050	44.48626	-11.83899
64.97384	45.53612	-11.91226
65.02717	46.58606	-11.99614
65.07718	47.57048	-12.08213
65.13050	48.62318	-12.16829
65.18384	49.67466	-12.25758
65.23550	50.69470	-12.34222
65.28717	51.71576	-12.42761
65.34050	52.77046	-12.51546
65.39216	53.79231	-12.59776
65.44384	54.81504	-12.67852
65.49717	55.87034	-12.76624
65.54884	56.89387	-12.84705
65.60050	57.91810	-12.93906
65.65384	58.97320	-13.02862
65.70550	59.99808	-13.11691
65.75718	61.02102	-13.20586
65.81050	62.07932	-13.30722
65.86384	63.13748	-13.40085
65.91382	64.12951	-13.47997
65.96718	65.18840	-13.56436
66.02050	66.24674	-13.65726
66.07050	67.23892	-13.74314
66.12384	68.29894	-13.82934
66.17718	69.35884	-13.91815
66.22884	70.38550	-14.00144
66.28050	71.41250	-14.08388
66.33384	72.47372	-14.17120
66.38550	73.50103	-14.25700
66.43718	74.52820	-14.34406
66.49050	75.58874	-14.42797
66.54218	76.61624	-14.50649
66.59384	77.64322	-14.59794
66.64718	78.70375	-14.70019
66.69884	79.73032	-14.77445
66.75050	80.75712	-14.87620
66.80384	81.81870	-14.96415
66.85718	82.87824	-15.06416
66.90718	83.87348	-15.14558
66.96050	84.93422	-15.23199
67.01384	85.99530	-15.32230
67.06384	86.98866	-15.42760
67.11718	88.04913	-15.52296
67.17050	89.10988	-15.61216
67.22218	90.13797	-15.70955
67.27384	91.16675	-15.79974
67.32718	92.22789	-15.89237
67.37884	93.25581	-15.98640
67.43050	94.28238	-16.08239
67.48384	95.34306	-16.18098
67.53550	96.37103	-16.26891
67.58716	97.39816	-16.38375
67.64050	98.45778	-16.47618
67.69218	99.48534	-16.55924
67.74384	100.5133	-16.64673
67.79718	101.5740	-16.74529
67.85050	102.6353	-16.84527
67.90050	103.6299	-16.93226
67.95384	104.6909	-17.04047
68.00718	105.7514	-17.13084
68.05718	106.7467	-17.23534
68.11050	107.8081	-17.32481
68.16382	108.8691	-17.41156
68.21550	109.8972	-17.51066
68.26716	110.9266	-17.59941
68.32050	111.9874	-17.70424
68.37218	113.0155	-17.79450
68.42384	114.0433	-17.88831
68.47718	115.1050	-17.98420
68.52884	116.1331	-18.07636
68.58050	117.1623	-18.16070
68.63384	118.2223	-18.28032
68.68550	119.2501	-18.36935
68.73718	120.2778	-18.47285
68.79050	121.3393	-18.56992
68.84384	122.4020	-18.66921
68.89384	123.3976	-18.76752
68.94718	124.4605	-18.87140
69.00050	125.5205	-18.97490
69.05050	126.5157	-19.07582
69.10384	127.5760	-19.17900
69.15718	128.6375	-19.28370
69.20884	129.6651	-19.39012
69.26050	130.6931	-19.50058
69.31384	131.7541	-19.61332
69.36550	132.7824	-19.71201
69.41718	133.8089	-19.82859
69.47050	134.8690	-19.94941
69.52218	135.8954	-20.07474
69.57384	136.9223	-20.20564
69.62718	137.9814	-20.33986
69.68050	139.0416	-20.46791
69.73050	140.0338	-20.60092
69.78384	141.0938	-20.73068
69.83716	142.1529	-20.86925
69.88718	143.1468	-21.00146
69.94050	144.2058	-21.12668
69.99384	145.2651	-21.23526
70.04550	146.2927	-21.34137
70.09718	147.3197	-21.44757
70.15050	148.3796	-21.57454
70.20216	149.4072	-21.68690
70.25384	150.4338	-21.81069
70.30718	151.4942	-21.93654
70.35884	152.5212	-22.06616
70.41050	153.5484	-22.17189
70.46384	154.6092	-22.27812
70.51550	155.6360	-22.38655
70.56718	156.6643	-22.48590
70.62050	157.7249	-22.59089
70.67384	158.7869	-22.67770
70.72384	159.7814	-22.75991
70.77718	160.8439	-22.83816
70.83050	161.9072	-22.89553
70.88050	162.9049	-22.94060
70.93384	163.9691	-22.98714
70.98718	165.0339	-23.04228
71.03882	166.0649	-23.09827
71.09050	167.0964	-23.17572
71.14384	168.1594	-23.24528
71.19550	169.1908	-23.33600
71.24718	170.2202	-23.41763
71.30050	171.2832	-23.53127
71.35218	172.3127	-23.64233
71.40384	173.3412	-23.75709
71.45718	174.4030	-23.87976
71.50884	175.4291	-24.01542
71.56050	176.4556	-24.16976
71.61384	177.5132	-24.33754
71.66718	178.5701	-24.54605
71.71718	179.5594	-24.74370
71.77050	180.6144	-24.99284
71.82384	181.6672	-25.25902
71.87384	182.6528	-25.54071
71.92718	183.7035	-25.84624
71.98050	184.7521	-26.21884
72.03218	185.7653	-26.58932
72.08384	186.7750	-27.03159
72.13718	187.8161	-27.52092
72.18884	188.8231	-28.01014
72.24050	189.8272	-28.53792
72.29384	190.8622	-29.10867
72.34550	191.8634	-29.65642
72.39718	192.8638	-30.25280
72.45050	193.8951	-30.89166
72.50218	194.8912	-31.55340
72.55384	195.8850	-32.27534
72.60718	196.9070	-33.09009
72.66050	197.9262	-33.96492
72.71050	198.8776	-34.87329
72.76384	199.8873	-35.87556
72.81718	200.8954	-36.91988
72.86718	201.8395	-37.90334
72.92050	202.8453	-38.90604
72.97384	203.8528	-39.78924
73.02550	204.8377	-40.44030
73.07718	205.8344	-40.68313
73.13050	206.8885	-40.40539
73.18218	207.9501	-38.73168
73.23384	209.0694	-36.00130
73.28718	210.2870	-32.37301
73.33884	211.4962	-29.41129
73.39050	212.6858	-27.68720
73.44384	213.8710	-26.69348
73.49550	214.9816	-26.09823
73.54718	216.0675	-25.73066
73.60050	217.1690	-25.48985
73.65384	218.2583	-25.36808
73.70384	219.2708	-25.29465
73.75718	220.3466	-25.28174
73.81050	221.4182	-25.27522
73.86050	222.4214	-25.27862
73.91382	223.4886	-25.28162
73.96718	224.5547	-25.30774
74.01882	225.5871	-25.35381
74.07050	226.6183	-25.43365
74.12384	227.6834	-25.49810
74.17550	228.7146	-25.55740
74.22718	229.7451	-25.63235
74.28050	230.8095	-25.69946
74.33218	231.8388	-25.77799
74.38384	232.8692	-25.86603
74.43718	233.9326	-25.93658
74.49050	234.9958	-26.00980
74.54050	235.9934	-26.06836
74.59384	237.0562	-26.13167
74.64718	238.1193	-26.21839
74.69718	239.1162	-26.27824
74.75050	240.1786	-26.35424
74.80384	241.2411	-26.45126
74.85550	242.2716	-26.51985
74.90718	243.3014	-26.59636
74.96050	244.3645	-26.66312
75.01218	245.3957	-26.73781
75.06384	246.4245	-26.80602
75.11718	247.4880	-26.87978
75.16884	248.5186	-26.95019
75.22050	249.5487	-27.02173
75.27384	250.6133	-27.08472
75.32550	251.6432	-27.16045
75.37718	252.6737	-27.23129
75.43050	253.7369	-27.29328
75.48384	254.8013	-27.36866
75.53384	255.7974	-27.44649
75.58716	256.8608	-27.52765
75.64050	257.9240	-27.60360
75.69050	258.9211	-27.67644
75.74384	259.9836	-27.76798
75.79718	261.0461	-27.84238
75.84882	262.0755	-27.94138
75.90050	263.1046	-28.01311
75.95384	264.1674	-28.09160
76.00550	265.1968	-28.17838
76.05718	266.2266	-28.25756
76.11050	267.2887	-28.33344
76.16218	268.3171	-28.42893
76.21384	269.3461	-28.50749
76.26716	270.4083	-28.59480
76.31884	271.4373	-28.66778
-2.000000	5.000000	0.0000000