File: 7-C1(1.2mol%)+C20(0.6mol%)(1)/matlab/130-2.txt
CLOSED
Version	1.0
Language	English
Mode	Standard
Run	26
RunSerial	12294
Instrument	DSC Q2000 V24.11 Build 124
Module	DSC Standard Cell RC
Operator
File	\\AE520-1454\Users\dsc\Desktop\Data\29-08-17-3\130-2.001
ProcName
InstSerial	2000-0883
AutoSerial	1293
Sample	130-2
Size	29.6000	mg
PanMass	Not available
PanResist	Automatic Automatic  K/W
PanFactor	Default Default
Method
Comment
Xcomment	Pan: Tzero Aluminum Hermetic
Xcomment	Gas1: Nitrogen 50.0 ml/min
Xcomment	Gas2: Nitrogen 50.0 ml/min
Text
Exotherm	UP
Kcell	1.05230
Cpconst	Standard: 0.938
Calib	-38.6961
TempCal	1	pts	157.46	156.60
TzeroDt	-87.6168 -0.0009 -1.4231
TzeroDtz	-87.6168 0.0057 6.9570
InstCalFile	Tzero: \\Ae520-1454\ta\Data\DSC\Calibration\2017\CALIBRATION\1562_RCS (90)_05_18_2017 10_50_44.TZR
InstCalFile	Baseline: \\Ae520-1454\ta\Data\DSC\Calibration\2017\2017-05-17_Calibration.001
InstCalFile	Sapphire: \\Ae520-1454\ta\Data\DSC\Calibration\2017\2017-05-17_Saphire.001
InstCalDate	Tzero 2017-05-18 Time 10:50:44
TempRange	-87.39 to 398.39 °C at 10.00 °C/min Heat Only
AutoZero	Delta T Offset 0.000 uV
AutoZero	Delta T0 Offset 0.000 uV
MultiptCal	0
MultiPtDesc	0) Not set
AutoCellConst	Calibration Date 2017-05-18 16:59:28
Controls	Gas 1  Event Off  Sampling 0.2
Cell#	RC-01562
CoolingUnit	RCS (90)
SelHeatFlow	Heat Flow T4P (mW)
AutoLidII	Installed
AutoAnalysis	Off
MacroFile
Nsig	3
Sig1	Time (min)
Sig2	Temperature (°C)
Sig3	Heat Flow (mW)
Date	2017-08-30
Time	21:25:21
OrgMethod	1: Equilibrate at 80.00 °C
OrgMethod	2: Isothermal for 3.00 min
OrgMethod	3: Jump to 130.00 °C
OrgMethod	4: Mark end of cycle 1
OrgMethod	5: Isothermal for 40.00 min
OrgMethod	6: Mark end of cycle 2
OrgMethod	7: Ramp 20.00 °C/min to 280.00 °C
OrgMethod	8: Mark end of cycle 3
OrgMethod	9: Ramp 20.00 °C/min to 20.00 °C
OrgMethod	10: Mark end of cycle 4
OrgMethod	11: Ramp 20.00 °C/min to 280.00 °C
OrgMethod	12: Mark end of cycle 5
OrgFile	C:\Users\jarra\Desktop\DSC\7-C1(1.2mol%)+C20(0.6mol%)(1)\130-2.001
StartOfData
4.99994E-4	78.64448	-17.01508
0.05383332	78.90254	-13.71968
0.1071666	79.10663	-11.08338
0.1588333	79.26562	-9.038359
0.2105000	79.39160	-7.396363
0.2638334	79.49790	-6.039030
0.3155000	79.57822	-4.985187
0.3671667	79.64249	-4.137412
0.4205000	79.69599	-3.439350
0.4721666	79.73788	-2.900240
0.5238333	79.77029	-2.462006
0.5771668	79.79681	-2.105848
0.6305000	79.81882	-1.818372
0.6805000	79.83496	-1.605594
0.7338332	79.84795	-1.425731
0.7871668	79.85774	-1.281950
0.8371668	79.86590	-1.174126
0.8904999	79.87212	-1.085966
0.9438332	79.87726	-1.016482
0.9955000	79.88120	-0.9631405
1.047167	79.88311	-0.9218554
1.100500	79.88522	-0.8919246
1.152167	79.88770	-0.8696059
1.203834	79.88924	-0.8530068
1.257166	79.88866	-0.8414776
1.308833	79.88960	-0.8333025
1.360500	79.88974	-0.8285292
1.413834	79.89053	-0.8245492
1.465500	79.89014	-0.8205600
1.517167	79.89022	-0.8165120
1.570500	79.88936	-0.8123590
1.623833	79.88900	-0.8082275
1.673834	79.88868	-0.8044918
1.727167	79.88837	-0.8006729
1.780500	79.88830	-0.7970439
1.830500	79.88797	-0.7937799
1.883833	79.88620	-0.7904949
1.937166	79.88598	-0.7875190
1.988833	79.88612	-0.7848402
2.040500	79.88563	-0.7823722
2.093834	79.88509	-0.7799834
2.145500	79.88450	-0.7778288
2.197166	79.88400	-0.7759644
2.250500	79.88350	-0.7742034
2.302166	79.88309	-0.7725999
2.353833	79.88184	-0.7711818
2.407167	79.88159	-0.7699884
2.458833	79.88093	-0.7689887
2.510500	79.88082	-0.7681410
2.563833	79.87970	-0.7674185
2.617167	79.87965	-0.7669349
2.667167	79.87886	-0.7666168
2.720500	79.87836	-0.7662938
2.773833	79.87837	-0.7661716
2.823833	79.87761	-0.7661279
2.877167	79.87730	-0.7661258
2.930500	79.87734	-0.7662616
2.982167	79.87612	-0.7664669
3.030500	79.94008	-1.732050
3.082167	81.28692	-14.79318
3.133833	83.68290	-27.79316
3.187167	86.66449	-40.99978
3.238834	89.95148	-52.99246
3.290500	93.53718	-63.78220
3.343834	97.48199	-73.47518
3.397167	101.6140	-81.78689
3.447167	105.6175	-88.43856
3.500500	109.9924	-94.43374
3.553833	114.2872	-97.61009
3.603833	117.2333	-90.92812
3.657167	119.4634	-81.39688
3.710500	121.2242	-70.91426
3.762167	122.5904	-60.96216
3.813833	123.7113	-51.79426
3.867166	124.6653	-43.47328
3.918833	125.4277	-36.57122
3.970500	126.0644	-30.74640
4.023834	126.6136	-25.74549
4.075500	127.0176	-22.33042
4.127167	127.4024	-18.80259
4.180500	127.7395	-15.83755
4.232167	128.0141	-13.48360
4.283834	128.2474	-11.54991
4.337167	128.4510	-9.919394
4.390500	128.6236	-8.583891
4.440500	128.7618	-7.551424
4.493834	128.8881	-6.637231
4.547167	128.9949	-5.885316
4.597166	129.0827	-5.299652
4.650500	129.1624	-4.773137
4.703833	129.2304	-4.337666
4.755500	129.2881	-3.984728
4.807167	129.3387	-3.686875
4.860500	129.3826	-3.427054
4.912167	129.4203	-3.215986
4.963834	129.4539	-3.041342
5.017166	129.4824	-2.885278
5.068833	129.5086	-2.759972
5.120500	129.5302	-2.650522
5.173834	129.5509	-2.556115
5.225500	129.5684	-2.476728
5.277168	129.5838	-2.410817
5.330500	129.5970	-2.354342
5.383832	129.6105	-2.306906
5.433832	129.6200	-2.268064
5.487168	129.6300	-2.234657
5.540500	129.6386	-2.205734
5.590500	129.6465	-2.184148
5.643832	129.6540	-2.164716
5.697168	129.6602	-2.148300
5.748834	129.6659	-2.134204
5.800500	129.6708	-2.122378
5.853832	129.6758	-2.111138
5.905500	129.6795	-2.101930
5.957168	129.6832	-2.094117
6.010500	129.6866	-2.087347
6.062168	129.6898	-2.080969
6.113834	129.6924	-2.074768
6.167168	129.6949	-2.068200
6.220500	129.6981	-2.061533
6.270500	129.6998	-2.055132
6.323834	129.7019	-2.048246
6.377168	129.7046	-2.041354
6.427168	129.7060	-2.034845
6.480500	129.7074	-2.027916
6.533832	129.7095	-2.021047
6.585500	129.7107	-2.014455
6.637168	129.7123	-2.007949
6.690500	129.7131	-2.001275
6.742166	129.7147	-1.994886
6.793832	129.7161	-1.988609
6.847168	129.7174	-1.982084
6.898834	129.7180	-1.975839
6.950500	129.7188	-1.969726
7.003832	129.7195	-1.963434
7.055500	129.7212	-1.957427
7.107168	129.7214	-1.951440
7.160500	129.7233	-1.945495
7.213834	129.7244	-1.939545
7.263834	129.7241	-1.934048
7.317168	129.7248	-1.928234
7.370500	129.7265	-1.922591
7.420500	129.7263	-1.917336
7.473834	129.7278	-1.911838
7.527168	129.7280	-1.906411
7.578834	129.7290	-1.901218
7.630500	129.7289	-1.896110
7.683832	129.7296	-1.890941
7.735500	129.7307	-1.886035
7.787168	129.7311	-1.881157
7.840500	129.7322	-1.876194
7.892168	129.7316	-1.871472
7.943832	129.7322	-1.866820
7.997168	129.7332	-1.862059
8.048834	129.7333	-1.857524
8.100500	129.7338	-1.852970
8.153832	129.7337	-1.848337
8.207168	129.7346	-1.843817
8.257168	129.7355	-1.839642
8.310500	129.7345	-1.835205
8.363834	129.7357	-1.830861
8.413834	129.7368	-1.826831
8.467168	129.7364	-1.822507
8.520500	129.7364	-1.818306
8.572168	129.7372	-1.814275
8.623834	129.7372	-1.810310
8.677168	129.7370	-1.806230
8.728834	129.7386	-1.802432
8.780500	129.7389	-1.798618
8.833832	129.7402	-1.794745
8.885499	129.7389	-1.791062
8.937166	129.7387	-1.787431
8.990500	129.7396	-1.783729
9.042168	129.7405	-1.780192
9.093832	129.7404	-1.776657
9.147168	129.7412	-1.773074
9.200500	129.7418	-1.769512
9.250500	129.7418	-1.766159
9.303832	129.7421	-1.762639
9.357166	129.7429	-1.759141
9.407166	129.7427	-1.755822
9.460499	129.7434	-1.752371
9.513832	129.7439	-1.748938
9.565500	129.7438	-1.745670
9.617166	129.7433	-1.742318
9.670500	129.7434	-1.738895
9.722168	129.7443	-1.735555
9.773834	129.7443	-1.732204
9.827168	129.7446	-1.728706
9.878834	129.7445	-1.725362
9.930500	129.7445	-1.722109
9.983832	129.7453	-1.718794
10.03550	129.7455	-1.715680
10.08717	129.7462	-1.712596
10.14050	129.7464	-1.709403
10.19383	129.7464	-1.706253
10.24383	129.7468	-1.703341
10.29717	129.7480	-1.700330
10.35050	129.7474	-1.697302
10.40050	129.7470	-1.694406
10.45383	129.7470	-1.691338
10.50717	129.7490	-1.688249
10.55884	129.7488	-1.685205
10.61050	129.7485	-1.682092
10.66383	129.7480	-1.678941
10.71550	129.7494	-1.675956
10.76717	129.7492	-1.672896
10.82050	129.7493	-1.669785
10.87217	129.7500	-1.666806
10.92383	129.7498	-1.663928
10.97717	129.7506	-1.660893
11.03050	129.7508	-1.657896
11.08050	129.7503	-1.655077
11.13383	129.7512	-1.652071
11.18716	129.7508	-1.648972
11.23717	129.7511	-1.646096
11.29050	129.7513	-1.643034
11.34383	129.7519	-1.639980
11.39550	129.7522	-1.637041
11.44717	129.7523	-1.634091
11.50050	129.7528	-1.631074
11.55216	129.7526	-1.628130
11.60383	129.7535	-1.625226
11.65717	129.7530	-1.622178
11.70883	129.7535	-1.619186
11.76050	129.7537	-1.616134
11.81383	129.7539	-1.613027
11.86550	129.7543	-1.610042
11.91717	129.7545	-1.607070
11.97050	129.7539	-1.603960
12.02383	129.7549	-1.600848
12.07383	129.7554	-1.597927
12.12717	129.7555	-1.594786
12.18050	129.7556	-1.591690
12.23050	129.7559	-1.588771
12.28383	129.7551	-1.585629
12.33717	129.7564	-1.582440
12.38883	129.7568	-1.579396
12.44050	129.7573	-1.576283
12.49384	129.7574	-1.572977
12.54550	129.7568	-1.569852
12.59717	129.7575	-1.566674
12.65050	129.7590	-1.563356
12.70217	129.7585	-1.560110
12.75384	129.7586	-1.556928
12.80717	129.7595	-1.553576
12.85883	129.7593	-1.550342
12.91050	129.7588	-1.547069
12.96383	129.7601	-1.543687
13.01717	129.7597	-1.540317
13.06716	129.7611	-1.537136
13.12050	129.7618	-1.533722
13.17383	129.7619	-1.530258
13.22383	129.7616	-1.526906
13.27717	129.7626	-1.523385
13.33050	129.7624	-1.519734
13.38216	129.7622	-1.516141
13.43383	129.7624	-1.512482
13.48716	129.7628	-1.508701
13.53883	129.7640	-1.504978
13.59050	129.7636	-1.501211
13.64383	129.7640	-1.497208
13.69550	129.7645	-1.493309
13.74717	129.7638	-1.489305
13.80050	129.7648	-1.485086
13.85217	129.7655	-1.480915
13.90383	129.7656	-1.476692
13.95717	129.7670	-1.472284
14.01050	129.7660	-1.467764
14.06050	129.7666	-1.463558
14.11383	129.7677	-1.458924
14.16716	129.7682	-1.454279
14.21716	129.7684	-1.449792
14.27050	129.7684	-1.444863
14.32384	129.7694	-1.439883
14.37550	129.7701	-1.434743
14.42717	129.7700	-1.429488
14.48050	129.7708	-1.423923
14.53217	129.7716	-1.418423
14.58383	129.7724	-1.412698
14.63717	129.7719	-1.406637
14.68883	129.7731	-1.400622
14.74050	129.7744	-1.394414
14.79384	129.7744	-1.387767
14.84550	129.7750	-1.381136
14.89717	129.7749	-1.374308
14.95050	129.7764	-1.366842
15.00383	129.7776	-1.359184
15.05383	129.7784	-1.350521
15.10716	129.7792	-1.341532
15.16050	129.7790	-1.331807
15.21050	129.7802	-1.322268
15.26383	129.7820	-1.311852
15.31716	129.7829	-1.298958
15.36884	129.7843	-1.285581
15.42050	129.7852	-1.270939
15.47383	129.7856	-1.254416
15.52550	129.7876	-1.239643
15.57717	129.7891	-1.221614
15.63050	129.7900	-1.202602
15.68217	129.7914	-1.182506
15.73383	129.7922	-1.163831
15.78717	129.7938	-1.142779
15.84050	129.7953	-1.119946
15.89050	129.7971	-1.098016
15.94384	129.7979	-1.074186
15.99717	129.8002	-1.050057
16.04716	129.8000	-1.027392
16.10050	129.8024	-1.006412
16.15383	129.8032	-0.9820892
16.20550	129.8055	-0.9609718
16.25716	129.8064	-0.9408326
16.31050	129.8078	-0.9189299
16.36216	129.8098	-0.8977611
16.41383	129.8114	-0.8773290
16.46716	129.8128	-0.8561566
16.51883	129.8142	-0.8363676
16.57050	129.8151	-0.8152984
16.62383	129.8166	-0.7964616
16.67550	129.8180	-0.7758261
16.72716	129.8191	-0.7584921
16.78050	129.8203	-0.7406362
16.83383	129.8215	-0.7233960
16.88383	129.8226	-0.7080714
16.93716	129.8236	-0.6925657
16.99050	129.8250	-0.6783114
17.04050	129.8262	-0.6649818
17.09383	129.8279	-0.6512832
17.14716	129.8280	-0.6360104
17.19884	129.8290	-0.6238094
17.25050	129.8305	-0.6113093
17.30383	129.8308	-0.5988690
17.35550	129.8325	-0.5881002
17.40716	129.8337	-0.5749493
17.46050	129.8337	-0.5632722
17.51216	129.8342	-0.5518032
17.56383	129.8358	-0.5414998
17.61716	129.8354	-0.5301013
17.66883	129.8370	-0.5198978
17.72050	129.8378	-0.5095896
17.77383	129.8390	-0.4993918
17.82716	129.8394	-0.4891832
17.87716	129.8408	-0.4794872
17.93050	129.8411	-0.4691101
17.98383	129.8421	-0.4583610
18.03383	129.8428	-0.4485498
18.08716	129.8431	-0.4377947
18.14050	129.8446	-0.4271426
18.19216	129.8447	-0.4169678
18.24383	129.8460	-0.4067869
18.29716	129.8465	-0.3962929
18.34883	129.8468	-0.3861794
18.40050	129.8475	-0.3761585
18.45383	129.8481	-0.3659162
18.50550	129.8495	-0.3559468
18.55716	129.8498	-0.3460586
18.61050	129.8492	-0.3358887
18.66217	129.8508	-0.3260995
18.71383	129.8519	-0.3163433
18.76716	129.8524	-0.3062693
18.82050	129.8528	-0.2962317
18.87050	129.8531	-0.2868342
18.92383	129.8542	-0.2769122
18.97716	129.8543	-0.2670271
19.02716	129.8547	-0.2577378
19.08050	129.8564	-0.2478538
19.13383	129.8569	-0.2379564
19.18550	129.8573	-0.2284102
19.23716	129.8572	-0.2188885
19.29050	129.8586	-0.2090580
19.34216	129.8592	-0.1995548
19.39383	129.8585	-0.1901073
19.44716	129.8607	-0.1804096
19.49883	129.8610	-0.1709927
19.55050	129.8612	-0.1616480
19.60383	129.8626	-0.1519757
19.65550	129.8633	-0.1426360
19.70716	129.8635	-0.1331737
19.76050	129.8640	-0.1234282
19.81383	129.8648	-0.1135965
19.86383	129.8660	-0.1043160
19.91716	129.8662	-.09438813
19.97050	129.8669	-.08439911
20.02050	129.8680	-.07499450
20.07383	129.8687	-.06483321
20.12716	129.8688	-.05474813
20.17883	129.8701	-.04500196
20.23050	129.8707	-.03505742
20.28383	129.8711	-.02482316
20.33550	129.8717	-.01484822
20.38716	129.8725	-4.9086E-3
20.44050	129.8737	.005776191
20.49216	129.8752	0.01582311
20.54383	129.8756	0.02627076
20.59716	129.8756	0.03761419
20.65050	129.8776	0.04813234
20.70050	129.8774	0.05811824
20.75383	129.8788	0.06877792
20.80716	129.8802	0.07947402
20.85716	129.8804	0.08998680
20.91050	129.8802	0.1011430
20.96383	129.8824	0.1122188
21.01550	129.8823	0.1232724
21.06716	129.8835	0.1344964
21.12050	129.8844	0.1462735
21.17216	129.8853	0.1580119
21.22383	129.8864	0.1698209
21.27717	129.8875	0.1827689
21.32883	129.8878	0.1943423
21.38050	129.8881	0.2065474
21.43383	129.8897	0.2185924
21.48550	129.8902	0.2302736
21.53717	129.8912	0.2439147
21.59050	129.8923	0.2572832
21.64383	129.8932	0.2709556
21.69383	129.8938	0.2848894
21.74716	129.8956	0.2998276
21.80050	129.8945	0.3135738
21.85050	129.8967	0.3259175
21.90383	129.8979	0.3404632
21.95717	129.8982	0.3548234
22.00883	129.8996	0.3678209
22.06050	129.9001	0.3817061
22.11383	129.9009	0.3953687
22.16550	129.9027	0.4101360
22.21716	129.9037	0.4249160
22.27050	129.9045	0.4404650
22.32216	129.9063	0.4564139
22.37383	129.9068	0.4705197
22.42717	129.9073	0.4868600
22.47883	129.9092	0.5033286
22.53050	129.9094	0.5212537
22.58383	129.9103	0.5377432
22.63716	129.9120	0.5534325
22.68716	129.9141	0.5681318
22.74050	129.9139	0.5861428
22.79383	129.9150	0.6024389
22.84383	129.9168	0.6187232
22.89716	129.9173	0.6380868
22.95050	129.9187	0.6553308
23.00217	129.9202	0.6723103
23.05383	129.9204	0.6901269
23.10716	129.9220	0.7084694
23.15883	129.9236	0.7250216
23.21050	129.9252	0.7417518
23.26383	129.9259	0.7619034
23.31550	129.9276	0.7784454
23.36716	129.9284	0.7970190
23.42050	129.9294	0.8183301
23.47216	129.9303	0.8366016
23.52383	129.9311	0.8538830
23.57716	129.9330	0.8721778
23.63050	129.9340	0.8919781
23.68050	129.9355	0.9120590
23.73383	129.9373	0.9303165
23.78717	129.9376	0.9515444
23.83716	129.9396	0.9695741
23.89050	129.9398	0.9904889
23.94383	129.9421	1.009742
23.99550	129.9424	1.030304
24.04716	129.9446	1.048563
24.10050	129.9453	1.068913
24.15216	129.9456	1.087966
24.20383	129.9470	1.106202
24.25716	129.9484	1.126776
24.30883	129.9504	1.143528
24.36050	129.9512	1.162023
24.41383	129.9522	1.181623
24.46550	129.9534	1.201870
24.51716	129.9547	1.220910
24.57050	129.9559	1.239833
24.62383	129.9567	1.257518
24.67383	129.9586	1.274173
24.72716	129.9596	1.292962
24.78050	129.9614	1.312098
24.83050	129.9626	1.330201
24.88383	129.9641	1.348429
24.93716	129.9654	1.368860
24.98883	129.9663	1.387653
25.04050	129.9678	1.406159
25.09383	129.9688	1.424957
25.14550	129.9701	1.443743
25.19716	129.9705	1.461620
25.25050	129.9718	1.479649
25.30217	129.9736	1.496984
25.35383	129.9756	1.512716
25.40716	129.9751	1.530779
25.46050	129.9779	1.546138
25.51050	129.9784	1.561323
25.56383	129.9799	1.577596
25.61716	129.9800	1.594463
25.66716	129.9824	1.608769
25.72050	129.9828	1.625863
25.77383	129.9841	1.642179
25.82550	129.9851	1.656004
25.87716	129.9868	1.670204
25.93050	129.9876	1.685172
25.98216	129.9888	1.698909
26.03383	129.9890	1.713281
26.08716	129.9905	1.725685
26.13883	129.9919	1.737947
26.19050	129.9922	1.751072
26.24383	129.9939	1.762988
26.29550	129.9935	1.776923
26.34716	129.9953	1.788279
26.40050	129.9962	1.800311
26.45383	129.9973	1.811792
26.50383	129.9978	1.823450
26.55716	129.9988	1.835748
26.61050	129.9998	1.847765
26.66050	130.0000	1.858199
26.71383	130.0010	1.869251
26.76716	130.0019	1.879980
26.81883	130.0030	1.890447
26.87050	130.0038	1.900993
26.92383	130.0038	1.911891
26.97550	130.0047	1.922582
27.02717	130.0055	1.933124
27.08050	130.0056	1.944182
27.13216	130.0074	1.954562
27.18383	130.0071	1.965004
27.23716	130.0080	1.975689
27.28883	130.0085	1.985966
27.34050	130.0095	1.996212
27.39383	130.0102	2.006675
27.44717	130.0104	2.016984
27.49716	130.0109	2.026566
27.55050	130.0112	2.036688
27.60383	130.0121	2.046644
27.65383	130.0116	2.055885
27.70716	130.0119	2.065642
27.76050	130.0144	2.075134
27.81217	130.0137	2.084318
27.86383	130.0134	2.093358
27.91716	130.0146	2.102446
27.96883	130.0157	2.111105
28.02050	130.0154	2.119590
28.07383	130.0167	2.128174
28.12550	130.0167	2.136360
28.17717	130.0171	2.144382
28.23050	130.0165	2.152466
28.28216	130.0178	2.160029
28.33383	130.0178	2.167528
28.38716	130.0195	2.175058
28.44050	130.0180	2.182369
28.49050	130.0197	2.188987
28.54383	130.0190	2.195920
28.59716	130.0198	2.202535
28.64716	130.0195	2.208557
28.70050	130.0202	2.214768
28.75383	130.0200	2.220825
28.80550	130.0195	2.226408
28.85716	130.0204	2.231772
28.91050	130.0200	2.237066
28.96216	130.0206	2.241899
29.01383	130.0200	2.246511
29.06716	130.0213	2.250879
29.11883	130.0198	2.254945
29.17050	130.0210	2.258682
29.22383	130.0211	2.262283
29.27550	130.0198	2.265550
29.32717	130.0194	2.268516
29.38050	130.0196	2.271280
29.43383	130.0199	2.273790
29.48383	130.0190	2.275859
29.53717	130.0189	2.277738
29.59050	130.0188	2.279304
29.64050	130.0187	2.280507
29.69383	130.0179	2.281431
29.74716	130.0181	2.281994
29.79883	130.0176	2.282224
29.85050	130.0166	2.282145
29.90383	130.0164	2.281584
29.95550	130.0160	2.280803
30.00716	130.0156	2.279697
30.06050	130.0156	2.278188
30.11216	130.0144	2.276412
30.16383	130.0145	2.274242
30.21716	130.0136	2.271708
30.27050	130.0131	2.268846
30.32050	130.0126	2.265903
30.37383	130.0125	2.262407
30.42717	130.0118	2.258531
30.47717	130.0109	2.254631
30.53050	130.0103	2.250232
30.58383	130.0100	2.245529
30.63550	130.0091	2.240674
30.68717	130.0087	2.235692
30.74050	130.0085	2.230099
30.79216	130.0071	2.224516
30.84383	130.0066	2.218716
30.89716	130.0052	2.212451
30.94883	130.0047	2.206084
31.00050	130.0038	2.199443
31.05383	130.0031	2.192421
31.10550	130.0021	2.185366
31.15716	130.0010	2.178129
31.21050	130.0006	2.170410
31.26383	130.0004	2.162460
31.31383	129.9985	2.154482
31.36716	129.9979	2.145947
31.42050	129.9969	2.137360
31.47050	129.9962	2.129102
31.52383	129.9962	2.120027
31.57717	129.9951	2.110904
31.62883	129.9935	2.101912
31.68050	129.9935	2.092024
31.73383	129.9929	2.081727
31.78550	129.9924	2.072389
31.83716	129.9915	2.062987
31.89050	129.9907	2.053167
31.94216	129.9899	2.043539
31.99383	129.9877	2.033792
32.04716	129.9879	2.023238
32.09883	129.9873	2.012854
32.15050	129.9866	2.002804
32.20383	129.9854	1.992399
32.25716	129.9851	1.982035
32.30716	129.9842	1.971838
32.36050	129.9830	1.961281
32.41383	129.9828	1.950611
32.46383	129.9819	1.940697
32.51716	129.9805	1.929728
32.57050	129.9804	1.918556
32.62216	129.9801	1.907942
32.67383	129.9794	1.897304
32.72717	129.9780	1.886383
32.77883	129.9777	1.875819
32.83050	129.9760	1.865320
32.88383	129.9766	1.854420
32.93550	129.9755	1.843924
32.98717	129.9752	1.833379
33.04050	129.9743	1.822412
33.09216	129.9736	1.811899
33.14383	129.9724	1.801443
33.19717	129.9723	1.790706
33.25050	129.9715	1.779999
33.30050	129.9701	1.769900
33.35383	129.9699	1.759269
33.40716	129.9690	1.748541
33.45716	129.9689	1.738612
33.51050	129.9678	1.727995
33.56383	129.9662	1.717453
33.61550	129.9661	1.707307
33.66716	129.9658	1.697162
33.72050	129.9651	1.686818
33.77217	129.9641	1.676862
33.82383	129.9640	1.666940
33.87717	129.9633	1.656794
33.92883	129.9626	1.646933
33.98050	129.9618	1.637179
34.03383	129.9620	1.627141
34.08550	129.9604	1.617463
34.13716	129.9599	1.607811
34.19050	129.9592	1.597920
34.24383	129.9597	1.588093
34.29383	129.9589	1.579020
34.34716	129.9577	1.569403
34.40050	129.9572	1.559968
34.45050	129.9573	1.551137
34.50383	129.9559	1.541898
34.55716	129.9559	1.532729
34.60883	129.9549	1.523887
34.66050	129.9542	1.515170
34.71383	129.9540	1.506234
34.76550	129.9533	1.497662
34.81716	129.9528	1.489201
34.87050	129.9524	1.480452
34.92216	129.9516	1.472073
34.97383	129.9515	1.463747
35.02716	129.9510	1.455226
35.08050	129.9509	1.446804
35.13050	129.9498	1.438991
35.18384	129.9490	1.430742
35.23717	129.9494	1.422482
35.28717	129.9487	1.414872
35.34050	129.9484	1.406834
35.39383	129.9488	1.398778
35.44550	129.9475	1.391191
35.49716	129.9473	1.383659
35.55050	129.9464	1.375964
35.60217	129.9465	1.368510
35.65383	129.9461	1.361114
35.70716	129.9463	1.353482
35.75883	129.9451	1.346240
35.81050	129.9445	1.339073
35.86383	129.9444	1.331788
35.91550	129.9442	1.324832
35.96716	129.9432	1.317949
36.02050	129.9434	1.310957
36.07383	129.9428	1.304033
36.12383	129.9426	1.297652
36.17717	129.9421	1.290876
36.23050	129.9418	1.284192
36.28050	129.9415	1.277889
36.33383	129.9410	1.271319
36.38716	129.9408	1.264726
36.43883	129.9405	1.258578
36.49050	129.9394	1.252489
36.54383	129.9396	1.246254
36.59550	129.9389	1.240303
36.64717	129.9388	1.234376
36.70050	129.9388	1.228272
36.75217	129.9384	1.222419
36.80383	129.9376	1.216671
36.85716	129.9374	1.210754
36.90883	129.9374	1.205067
36.96050	129.9372	1.199496
37.01383	129.9372	1.193810
37.06716	129.9359	1.188274
37.11716	129.9348	1.183174
37.17050	129.9352	1.177747
37.22383	129.9355	1.172324
37.27383	129.9341	1.167380
37.32717	129.9336	1.161991
37.38050	129.9332	1.156609
37.43216	129.9335	1.151444
37.48383	129.9332	1.146248
37.53717	129.9329	1.141023
37.58883	129.9331	1.135927
37.64050	129.9319	1.130921
37.69383	129.9320	1.125829
37.74550	129.9314	1.121000
37.79716	129.9316	1.116194
37.85050	129.9315	1.111266
37.90216	129.9307	1.106493
37.95383	129.9310	1.101780
38.00716	129.9306	1.096928
38.06050	129.9302	1.092149
38.11050	129.9302	1.087681
38.16383	129.9293	1.082954
38.21716	129.9292	1.078249
38.26716	129.9292	1.073780
38.32050	129.9294	1.069107
38.37383	129.9283	1.064523
38.42550	129.9286	1.060116
38.47717	129.9290	1.055753
38.53050	129.9280	1.051255
38.58216	129.9281	1.046993
38.63383	129.9277	1.042777
38.68716	129.9271	1.038455
38.73883	129.9265	1.034238
38.79050	129.9271	1.029968
38.84384	129.9262	1.025677
38.89550	129.9267	1.021405
38.94717	129.9260	1.017181
39.00050	129.9261	1.012917
39.05383	129.9258	1.008627
39.10383	129.9259	1.004679
39.15716	129.9245	1.000455
39.21050	129.9253	0.9963074
39.26050	129.9245	0.9924475
39.31383	129.9245	0.9883576
39.36716	129.9244	0.9842863
39.41883	129.9238	0.9803937
39.47050	129.9240	0.9765066
39.52383	129.9229	0.9724944
39.57550	129.9236	0.9686061
39.62717	129.9230	0.9648384
39.68050	129.9223	0.9608822
39.73216	129.9231	0.9570632
39.78383	129.9219	0.9532716
39.83716	129.9210	0.9493149
39.89050	129.9214	0.9452844
39.94050	129.9210	0.9415566
39.99383	129.9215	0.9376138
40.04716	129.9206	0.9337356
40.09716	129.9193	0.9300731
40.15050	129.9210	0.9262145
40.20383	129.9203	0.9223053
40.25550	129.9193	0.9185125
40.30716	129.9186	0.9147874
40.36050	129.9195	0.9108621
40.41217	129.9189	0.9071046
40.46383	129.9190	0.9034082
40.51716	129.9176	0.8995835
40.56883	129.9178	0.8958666
40.62050	129.9180	0.8921424
40.67383	129.9171	0.8882455
40.72550	129.9175	0.8844219
40.77716	129.9173	0.8806851
40.83050	129.9174	0.8768439
40.88383	129.9169	0.8730532
40.93384	129.9169	0.8694769
40.98717	129.9163	0.8656999
41.04050	129.9160	0.8619461
41.09050	129.9156	0.8584718
41.14383	129.9157	0.8547524
41.19717	129.9153	0.8510726
41.24883	129.9150	0.8475369
41.30050	129.9144	0.8440180
41.35383	129.9140	0.8403426
41.40550	129.9140	0.8367929
41.45717	129.9140	0.8332453
41.51050	129.9137	0.8294852
41.56216	129.9134	0.8258868
41.61383	129.9134	0.8222039
41.66716	129.9134	0.8183874
41.71884	129.9132	0.8147914
41.77050	129.9128	0.8111889
41.82383	129.9130	0.8074816
41.87717	129.9115	0.8038745
41.92717	129.9121	0.8004178
41.98050	129.9124	0.7968043
42.03383	129.9114	0.7931806
42.08383	129.9110	0.7897960
42.13716	129.9104	0.7862140
42.19050	129.9111	0.7825705
42.24216	129.9105	0.7790313
42.29383	129.9098	0.7754285
42.34716	129.9091	0.7717343
42.39883	129.9097	0.7680860
42.45050	129.9090	0.7644856
42.50383	129.9092	0.7608380
42.55550	129.9084	0.7573174
42.60717	129.9091	0.7537564
42.66050	129.9086	0.7502082
42.71216	129.9086	0.7467199
42.76383	129.9079	0.7432639
42.81717	129.9070	0.7396756
42.87050	129.9073	0.7360910
42.92050	129.9065	0.7327106
42.97383	129.9056	0.7290710
43.02217	129.9068	0.7248440
43.07383	130.0014	-0.9457101
43.12717	130.3759	-4.843044
43.17883	130.8906	-8.442476
43.23050	131.5169	-11.69693
43.28383	132.2482	-14.47060
43.33550	133.0233	-16.66254
43.38716	133.8475	-18.43547
43.44050	134.7396	-19.90589
43.49216	135.6357	-21.04108
43.54383	136.5562	-21.95890
43.59716	137.5286	-22.72101
43.65050	138.5181	-23.32312
43.70050	139.4577	-23.77850
43.75383	140.4723	-24.17167
43.80717	141.4946	-24.48012
43.85717	142.4608	-24.73833
43.91050	143.4954	-24.94678
43.96383	144.5353	-25.12150
44.01550	145.5458	-25.28029
44.06717	146.5587	-25.43628
44.12050	147.6063	-25.58442
44.17216	148.6205	-25.78040
44.22383	149.6349	-25.99592
44.27716	150.6814	-26.19748
44.32883	151.6954	-26.42002
44.38050	152.7094	-26.66419
44.43383	153.7560	-26.91471
44.48550	154.7673	-27.20992
44.53717	155.7805	-27.47111
44.59050	156.8268	-27.69490
44.64383	157.8747	-27.92141
44.69383	158.8591	-28.14935
44.74716	159.9096	-28.31635
44.80050	160.9620	-28.49981
44.85050	161.9498	-28.64612
44.90383	163.0057	-28.75010
44.95717	164.0669	-28.74175
45.00883	165.1030	-28.60670
45.06050	166.1460	-28.24368
45.11383	167.2290	-27.87196
45.16550	168.2814	-27.51125
45.21717	169.3399	-27.01532
45.27050	170.4376	-26.38370
45.32217	171.5077	-25.69922
45.37383	172.5836	-24.94842
45.42717	173.6981	-24.10684
45.48050	174.8162	-23.25110
45.53050	175.8654	-22.50636
45.58383	176.9824	-21.73620
45.63716	178.0969	-21.03330
45.68716	179.1388	-20.44875
45.74050	180.2461	-19.89804
45.79383	181.3479	-19.43716
45.84550	182.4104	-19.06678
45.89717	183.4694	-18.78848
45.95050	184.5548	-18.60568
46.00217	185.6012	-18.52496
46.05383	186.6405	-18.50541
46.10717	187.7086	-18.53167
46.15883	188.7375	-18.78816
46.21050	189.7592	-19.14765
46.26383	190.8060	-19.58746
46.31550	191.8148	-20.14762
46.36716	192.8149	-20.85785
46.42050	193.8384	-21.70774
46.47383	194.8548	-22.68834
46.52383	195.7996	-23.73630
46.57717	196.7980	-25.04404
46.63050	197.7908	-26.35446
46.68050	198.7146	-27.71796
46.73383	199.6954	-29.20631
46.78717	200.6713	-30.78248
46.83883	201.6131	-32.31014
46.89050	202.5544	-33.94148
46.94383	203.5209	-35.59881
46.99550	204.4565	-37.31227
47.04716	205.3857	-39.07816
47.10050	206.3412	-41.05176
47.15216	207.2594	-43.13212
47.20383	208.1697	-45.39765
47.25717	209.0956	-47.98453
47.30883	209.9816	-50.75732
47.36050	210.8530	-53.76804
47.41383	211.7368	-57.19599
47.46717	212.6041	-60.81172
47.51717	213.4064	-64.32405
47.57050	214.2554	-68.06106
47.62383	215.1086	-71.29805
47.67383	215.9390	-73.18980
47.72717	216.8847	-73.67792
47.78050	217.9033	-73.11807
47.83217	218.9404	-72.47408
47.88383	219.9711	-73.59770
47.93716	221.0099	-72.85304
47.98883	222.1560	-67.65730
48.04050	223.3873	-63.60868
48.09384	224.6832	-59.36004
48.14550	225.9582	-55.00335
48.19717	227.2420	-50.88738
48.25050	228.5508	-47.48866
48.30217	229.7862	-44.98297
48.35383	230.9852	-43.04490
48.40717	232.1884	-41.47700
48.46050	233.3643	-40.25168
48.51050	234.4457	-39.33059
48.56383	235.5816	-38.55852
48.61716	236.7032	-37.94006
48.66716	237.7443	-37.49662
48.72050	238.8449	-37.11136
48.77383	239.9396	-36.82660
48.82550	240.9927	-36.63076
48.87717	242.0424	-36.46762
48.93050	243.1218	-36.37245
48.98217	244.1664	-36.27390
49.03383	245.2068	-36.22788
49.08716	246.2798	-36.18260
49.13883	247.3181	-36.16282
49.19050	248.3551	-36.14844
49.24383	249.4248	-36.14385
49.29550	250.4590	-36.14278
49.34716	251.4937	-36.14316
49.40050	252.5604	-36.14784
49.45383	253.6267	-36.16168
49.50383	254.6264	-36.18828
49.55717	255.6928	-36.24307
49.61050	256.7578	-36.30041
49.66050	257.7560	-36.35728
49.71383	258.8210	-36.43118
49.76717	259.8861	-36.49652
49.81883	260.9174	-36.55830
49.87050	261.9484	-36.62548
49.92383	263.0148	-36.68129
49.97550	264.0454	-36.74622
50.02716	265.0769	-36.81294
50.08050	266.1414	-36.87588
50.13217	267.1726	-36.94762
50.18383	268.2041	-37.01355
50.23717	269.2684	-37.09057
50.29050	270.3324	-37.15006
50.34050	271.3297	-37.20712
50.39383	272.3932	-37.27625
50.44717	273.4576	-37.32108
50.49716	274.4546	-37.32790
50.54716	275.4060	-37.99219
50.59716	275.8667	-36.06824
50.65050	275.9192	-27.72110
50.70383	275.7156	-18.70689
50.75550	275.3476	-10.83217
50.80717	274.8526	-4.179824
50.86050	274.2384	1.443071
50.91217	273.5648	5.851654
50.96383	272.8290	9.408894
51.01717	272.0172	12.36578
51.06883	271.1878	14.66697
51.12050	270.3262	16.52488
51.17383	269.4101	18.06787
51.22550	268.4990	19.27771
51.27717	267.5705	20.26748
51.33050	266.5972	21.09919
51.38383	265.6089	21.78279
51.43383	264.6737	22.31765
51.48717	263.6686	22.78467
51.54050	262.6536	23.17646
51.59050	261.6956	23.48744
51.64384	260.6710	23.76535
51.69717	259.6402	23.99104
51.74883	258.6380	24.18200
51.80050	257.6328	24.34228
51.85383	256.5922	24.48329
51.90550	255.5826	24.59915
51.95717	254.5713	24.70603
52.01050	253.5246	24.80246
52.06216	252.5098	24.88392
52.11383	251.4934	24.95205
52.16716	250.4434	25.01278
52.21884	249.4254	25.07031
52.27050	248.4063	25.11828
52.32383	247.3532	25.16373
52.37717	246.3001	25.19993
52.42717	245.3118	25.23088
52.48050	244.2574	25.25579
52.53383	243.2015	25.27696
52.58383	242.2125	25.28840
52.63716	241.1557	25.29948
52.69050	240.0993	25.31064
52.74216	239.0761	25.32190
52.79382	238.0521	25.33581
52.84716	236.9960	25.35080
52.89883	235.9717	25.36418
52.95050	234.9469	25.37314
53.00383	233.8895	25.38197
53.05550	232.8650	25.38820
53.10717	231.8407	25.39460
53.16050	230.7819	25.40124
53.21216	229.7562	25.40747
53.26382	228.7306	25.41386
53.31716	227.6722	25.42094
53.37050	226.6135	25.42800
53.42050	225.6223	25.43613
53.47382	224.5630	25.44513
53.52717	223.5044	25.45304
53.57717	222.5117	25.46016
53.63050	221.4512	25.46821
53.68383	220.3923	25.47600
53.73550	219.3666	25.48420
53.78716	218.3403	25.49188
53.84050	217.2809	25.49963
53.89216	216.2544	25.50715
53.94384	215.2276	25.51432
53.99717	214.1676	25.52166
54.04883	213.1408	25.52834
54.10050	212.1135	25.53467
54.15383	211.0533	25.54106
54.20550	210.0272	25.54706
54.25717	208.9999	25.55263
54.31050	207.9396	25.55802
54.36382	206.8801	25.56295
54.41382	205.8857	25.56732
54.46717	204.8263	25.57176
54.52050	203.7662	25.57604
54.57050	202.7727	25.57963
54.62383	201.7124	25.58320
54.67717	200.6517	25.58670
54.72883	199.6261	25.59001
54.78050	198.5984	25.59326
54.83383	197.5400	25.59654
54.88550	196.5133	25.59961
54.93716	195.4869	25.60295
54.99050	194.4264	25.60690
55.04217	193.3986	25.61039
55.09384	192.3712	25.61369
55.14717	191.3110	25.61701
55.20050	190.2503	25.61949
55.25050	189.2565	25.62180
55.30383	188.1952	25.62363
55.35717	187.1351	25.62495
55.40717	186.1406	25.62616
55.46050	185.0800	25.62710
55.51382	184.0189	25.62769
55.56550	182.9928	25.62831
55.61716	181.9642	25.62890
55.67050	180.9045	25.62931
55.72217	179.8774	25.63034
55.77383	178.8502	25.63177
55.82717	177.7892	25.63370
55.87883	176.7624	25.63611
55.93050	175.7361	25.63956
55.98383	174.6752	25.64310
56.03550	173.6490	25.64668
56.08716	172.6209	25.65031
56.14050	171.5610	25.65396
56.19384	170.5010	25.65762
56.24382	169.5070	25.66327
56.29717	168.4487	25.68636
56.35050	167.3913	25.82019
56.40050	166.4059	26.17429
56.45383	165.3687	26.86464
56.50717	164.3580	28.27120
56.55883	163.4238	30.63180
56.61050	162.5466	34.02065
56.66382	161.7028	38.33545
56.71550	160.9326	42.94632
56.76716	160.1899	47.60544
56.82050	159.4308	52.16206
56.87217	158.6824	55.98858
56.92383	157.9021	59.03496
56.97717	157.0484	61.18586
57.02883	156.1640	62.23389
57.08050	155.2184	62.28404
57.13383	154.1755	61.47380
57.18716	153.0695	59.57385
57.23717	151.9832	57.33054
57.29050	150.7811	54.48800
57.34384	149.5498	51.38416
57.39384	148.3751	48.41022
57.44717	147.1169	45.45200
57.50050	145.8680	42.83381
57.55217	144.6732	40.60787
57.60383	143.4956	38.69361
57.65717	142.3005	36.98883
57.70883	141.1591	35.58095
57.76050	140.0328	34.33492
57.81382	138.8839	33.23621
57.86550	137.7817	32.28650
57.91716	136.6893	31.49526
57.97050	135.5712	30.79829
58.02217	134.4958	30.22078
58.07383	133.4266	29.73768
58.12717	132.3310	29.29335
58.18050	131.2392	28.92345
58.23050	130.2198	28.60966
58.28383	129.1360	28.31696
58.33716	128.0552	28.06625
58.38716	127.0442	27.84884
58.44050	125.9684	27.65486
58.49382	124.8933	27.46089
58.54550	123.8534	27.30172
58.59716	122.8146	27.15160
58.65050	121.7431	27.00527
58.70216	120.7050	26.86310
58.75383	119.6680	26.74712
58.80717	118.5975	26.61200
58.85883	117.5617	26.49990
58.91050	116.5256	26.38385
58.96382	115.4552	26.24046
59.01550	114.4186	26.11825
59.06716	113.3805	25.91436
59.12050	112.3064	25.66047
59.17383	111.2314	25.48976
59.22382	110.2257	25.33641
59.27717	109.1523	25.20813
59.33050	108.0816	25.07460
59.38050	107.0778	24.95461
59.43383	106.0079	24.84048
59.48717	104.9387	24.73980
59.53882	103.9045	24.64977
59.59050	102.8688	24.57056
59.64384	101.8026	24.48290
59.69550	100.7691	24.41046
59.74717	99.73551	24.34000
59.80050	98.66946	24.26597
59.85217	97.63715	24.20380
59.90383	96.60522	24.14453
59.95717	95.53839	24.07294
60.01050	94.47343	24.01725
60.06050	93.47338	23.96920
60.11382	92.40594	23.75743
60.16716	91.33326	23.59609
60.21717	90.32916	23.46249
60.27050	89.25754	23.34848
60.32383	88.18926	23.25252
60.37550	87.15418	23.15108
60.42717	86.11949	23.05802
60.48050	85.05130	22.97012
60.53217	84.01722	22.89155
60.58383	82.98300	22.80610
60.63716	81.91641	22.72596
60.68882	80.88188	22.63627
60.74050	79.84756	22.56543
60.79382	78.78139	22.47808
60.84550	77.74724	22.40726
60.89717	76.71386	22.33723
60.95050	75.64776	22.26016
61.00383	74.57962	22.18566
61.05383	73.57984	22.11336
61.10717	72.51364	22.03857
61.16050	71.44638	21.96666
61.21050	70.44597	21.90070
61.26382	69.37939	21.81799
61.31716	68.31220	21.73284
61.36882	67.27902	21.65652
61.42050	66.24568	21.58658
61.47382	65.17722	21.50728
61.52550	64.14392	21.42681
61.57717	63.11032	21.35035
61.63050	62.04348	21.26062
61.68217	61.00884	21.18806
61.73383	59.97514	21.11340
61.78716	58.90850	21.03108
61.83882	57.87393	20.94803
61.89050	56.84060	20.86694
61.94384	55.77266	20.78950
61.99717	54.70450	20.71505
62.04717	53.70471	20.63220
62.10050	52.63769	20.55657
62.15383	51.57130	20.47719
62.20383	50.57136	20.40764
62.25717	49.50346	20.33405
62.31050	48.43603	20.25375
62.36217	47.40098	20.17959
62.41382	46.36847	20.12768
62.46717	45.30192	20.09220
62.51884	44.26706	19.95987
62.57050	43.23220	19.87648
62.62383	42.16367	19.78836
62.67550	41.12898	19.71132
62.72717	40.09372	19.62599
62.78050	39.02444	19.52588
62.83217	37.99044	19.43166
62.88383	36.95490	19.34418
62.93716	35.88670	19.24586
62.99050	34.81648	19.14530
63.04050	33.81330	19.04676
63.09384	32.74478	18.93859
63.14717	31.67426	18.84473
63.19717	30.67136	18.74196
63.25050	29.60115	18.63634
63.30383	28.53052	18.52029
63.35550	27.49438	18.41170
63.40717	26.45776	18.30043
63.46050	25.38638	18.23424
63.51050	24.38196	18.25225
63.56216	23.46170	18.56891
63.61382	23.10111	14.39588
63.66716	23.07802	8.770775
63.71884	23.30322	3.710434
63.77050	23.70088	-0.4746010
63.82383	24.25458	-3.975210
63.87550	24.89588	-6.675206
63.92717	25.61526	-8.829668
63.98050	26.42230	-10.59859
64.03384	27.28108	-12.00761
64.08384	28.12075	-13.07411
64.13717	29.04850	-14.00693
64.19050	29.99944	-14.75008
64.24050	30.90726	-15.34284
64.29384	31.89169	-15.87069
64.34717	32.88821	-16.29944
64.39883	33.86247	-16.66336
64.45050	34.84335	-16.97860
64.50384	35.86525	-17.25528
64.55550	36.85738	-17.49940
64.60718	37.85549	-17.71961
64.66050	38.88854	-17.91180
64.71217	39.89288	-18.08862
64.76384	40.90107	-18.24184
64.81717	41.94231	-18.39636
64.87050	42.98740	-18.54254
64.92050	43.96806	-18.66889
64.97384	45.01496	-18.79147
65.02717	46.06517	-18.91556
65.07718	47.05048	-19.02901
65.13050	48.10166	-19.14795
65.18384	49.15274	-19.26516
65.23550	50.17407	-19.38114
65.28717	51.19426	-19.48386
65.34050	52.24956	-19.59396
65.39216	53.27043	-19.71067
65.44384	54.29418	-19.80772
65.49717	55.34812	-19.91559
65.54884	56.37198	-20.02379
65.60050	57.39541	-20.12811
65.65384	58.45235	-20.24874
65.70550	59.47773	-20.34933
65.75718	60.50179	-20.45073
65.81050	61.56062	-20.57164
65.86384	62.61890	-20.69019
65.91382	63.61052	-20.78697
65.96718	64.66959	-20.88566
66.02050	65.72851	-20.98892
66.07050	66.72113	-21.09029
66.12384	67.78042	-21.19984
66.17718	68.84019	-21.30808
66.22884	69.86684	-21.40914
66.28050	70.89249	-21.50474
66.33384	71.95350	-21.61738
66.38550	72.98170	-21.72400
66.43718	74.00812	-21.82186
66.49050	75.06770	-21.93447
66.54218	76.09445	-22.04490
66.59384	77.12079	-22.16296
66.64718	78.18084	-22.27297
66.69884	79.20686	-22.39406
66.75050	80.23406	-22.50937
66.80384	81.29381	-22.62993
66.85718	82.35406	-22.75720
66.90718	83.34700	-22.86565
66.96050	84.40712	-22.98856
67.01384	85.46569	-23.11804
67.06384	86.45924	-23.23880
67.11718	87.51924	-23.36714
67.17050	88.58016	-23.49345
67.22218	89.60605	-23.62772
67.27384	90.63241	-23.74468
67.32718	91.69220	-23.87793
67.37884	92.71816	-24.00839
67.43050	93.74431	-24.12963
67.48384	94.80382	-24.26138
67.53550	95.83032	-24.40092
67.58716	96.85682	-24.51168
67.64050	97.91626	-24.65281
67.69218	98.94348	-24.78136
67.74384	99.96856	-24.91432
67.79718	101.0283	-25.06036
67.85050	102.0878	-25.19334
67.90050	103.0802	-25.31569
67.95384	104.1392	-25.47186
68.00718	105.1980	-25.61744
68.05718	106.1902	-25.76649
68.11050	107.2485	-25.90802
68.16382	108.3073	-26.05867
68.21550	109.3323	-26.22572
68.26716	110.3569	-26.36995
68.32050	111.4146	-26.52395
68.37218	112.4398	-26.67586
68.42384	113.4653	-26.82217
68.47718	114.5234	-26.97335
68.52884	115.5489	-27.12438
68.58050	116.5744	-27.27385
68.63384	117.6320	-27.43560
68.68550	118.6570	-27.59295
68.73718	119.6821	-27.76166
68.79050	120.7386	-27.92768
68.84384	121.7968	-28.10796
68.89384	122.7883	-28.27661
68.94718	123.8461	-28.44510
69.00050	124.9038	-28.59015
69.05050	125.8962	-28.74600
69.10384	126.9530	-28.93631
69.15718	128.0112	-29.08905
69.20884	129.0367	-29.22216
69.26050	130.0654	-29.26916
69.31384	131.1302	-29.32150
69.36550	132.1595	-29.41168
69.41718	133.1898	-29.50390
69.47050	134.2522	-29.58900
69.52218	135.2821	-29.69297
69.57384	136.3106	-29.81254
69.62718	137.3734	-29.94791
69.68050	138.4346	-30.06670
69.73050	139.4303	-30.15646
69.78384	140.4947	-30.14737
69.83716	141.5641	-30.14492
69.88718	142.5646	-30.15292
69.94050	143.6289	-30.24578
69.99384	144.6916	-30.37609
70.04550	145.7210	-30.48538
70.09718	146.7496	-30.61380
70.15050	147.8104	-30.73350
70.20216	148.8383	-30.86113
70.25384	149.8651	-30.99205
70.30718	150.9257	-31.13260
70.35884	151.9518	-31.26390
70.41050	152.9789	-31.41482
70.46384	154.0391	-31.55341
70.51550	155.0664	-31.69552
70.56718	156.0932	-31.84456
70.62050	157.1527	-31.98424
70.67384	158.2117	-32.12906
70.72384	159.2043	-32.25930
70.77718	160.2649	-32.39280
70.83050	161.3251	-32.49242
70.88050	162.3219	-32.57329
70.93384	163.3834	-32.64578
70.98718	164.4482	-32.71460
71.03882	165.4795	-32.76291
71.09050	166.5110	-32.81885
71.14384	167.5762	-32.88198
71.19550	168.6067	-32.94710
71.24718	169.6382	-33.02034
71.30050	170.7019	-33.12865
71.35218	171.7306	-33.24853
71.40384	172.7598	-33.37344
71.45718	173.8209	-33.51390
71.50884	174.8469	-33.66850
71.56050	175.8729	-33.84937
71.61384	176.9294	-34.05460
71.66718	177.9862	-34.29140
71.71718	178.9748	-34.53639
71.77050	180.0264	-34.82656
71.82384	181.0764	-35.16303
71.87384	182.0605	-35.50960
71.92718	183.1048	-35.92067
71.98050	184.1476	-36.39066
72.03218	185.1563	-36.88433
72.08384	186.1614	-37.44282
72.13718	187.1952	-38.08692
72.18884	188.1934	-38.76273
72.24050	189.1876	-39.51692
72.29384	190.2106	-40.33605
72.34550	191.1976	-41.18634
72.39718	192.1815	-42.05639
72.45050	193.1953	-42.98689
72.50218	194.1770	-43.88696
72.55384	195.1570	-44.82254
72.60718	196.1665	-45.84214
72.66050	197.1736	-46.92132
72.71050	198.1133	-48.01400
72.76384	199.1125	-49.25137
72.81718	200.1072	-50.57340
72.86718	201.0337	-51.88614
72.92050	202.0202	-53.30188
72.97384	203.0045	-54.70284
73.02550	203.9599	-55.93687
73.07718	204.9225	-56.96566
73.13050	205.9292	-57.54186
73.18218	206.9341	-57.31582
73.23384	207.9822	-55.98687
73.28718	209.1252	-53.46468
73.33884	210.2869	-50.49000
73.39050	211.4787	-47.49304
73.44384	212.7217	-44.54621
73.49550	213.9213	-42.11013
73.54718	215.1021	-40.21836
73.60050	216.2961	-38.72348
73.65384	217.4635	-37.58591
73.70384	218.5405	-36.71547
73.75718	219.6716	-36.01072
73.81050	220.7895	-35.46196
73.86050	221.8269	-35.05536
73.91382	222.9267	-34.72740
73.96718	224.0186	-34.46289
74.01882	225.0712	-34.27644
74.07050	226.1194	-34.15410
74.12384	227.1982	-34.04788
74.17550	228.2390	-33.98404
74.22718	229.2801	-33.95105
74.28050	230.3516	-33.93167
74.33218	231.3883	-33.92548
74.38384	232.4241	-33.92493
74.43718	233.4919	-33.92578
74.49050	234.5598	-33.93038
74.54050	235.5598	-33.94524
74.59384	236.6274	-33.96208
74.64718	237.6935	-33.99174
74.69718	238.6944	-34.03020
74.75050	239.7596	-34.08885
74.80384	240.8252	-34.14840
74.85550	241.8574	-34.21481
74.90718	242.8894	-34.27634
74.96050	243.9547	-34.33405
75.01218	244.9866	-34.39022
75.06384	246.0196	-34.45097
75.11718	247.0837	-34.49743
75.16884	248.1158	-34.54880
75.22050	249.1475	-34.58960
75.27384	250.2120	-34.64456
75.32550	251.2443	-34.70248
75.37718	252.2756	-34.75534
75.43050	253.3413	-34.80581
75.48384	254.4056	-34.85841
75.53384	255.4038	-34.91940
75.58716	256.4674	-34.99631
75.64050	257.5308	-35.06424
75.69050	258.5296	-35.13224
75.74384	259.5930	-35.19904
75.79718	260.6556	-35.27167
75.84882	261.6883	-35.33748
75.90050	262.7187	-35.40920
75.95384	263.7822	-35.47905
76.00550	264.8126	-35.55815
76.05718	265.8438	-35.62790
76.11050	266.9065	-35.69222
76.16218	267.9370	-35.76709
76.21384	268.9680	-35.84046
76.26716	270.0313	-35.90504
76.31884	271.0610	-35.96866
-2.000000	5.000000	0.0000000