File: 7-C1(1.2mol%)+C20(0.6mol%)(1)/matlab/130-1.txt
CLOSED
Version	1.0
Language	English
Mode	Standard
Run	25
RunSerial	12293
Instrument	DSC Q2000 V24.11 Build 124
Module	DSC Standard Cell RC
Operator
File	\\AE520-1454\Users\dsc\Desktop\Data\29-08-17-3\130-1.001
ProcName
InstSerial	2000-0883
AutoSerial	1293
Sample	130-1
Size	27.4000	mg
PanMass	Not available
PanResist	Automatic Automatic  K/W
PanFactor	Default Default
Method
Comment
Xcomment	Pan: Tzero Aluminum Hermetic
Xcomment	Gas1: Nitrogen 50.0 ml/min
Xcomment	Gas2: Nitrogen 50.0 ml/min
Text
Exotherm	UP
Kcell	1.05230
Cpconst	Standard: 0.938
Calib	-38.6961
TempCal	1	pts	157.46	156.60
TzeroDt	-87.6168 -0.0009 -1.4231
TzeroDtz	-87.6168 0.0057 6.9570
InstCalFile	Tzero: \\Ae520-1454\ta\Data\DSC\Calibration\2017\CALIBRATION\1562_RCS (90)_05_18_2017 10_50_44.TZR
InstCalFile	Baseline: \\Ae520-1454\ta\Data\DSC\Calibration\2017\2017-05-17_Calibration.001
InstCalFile	Sapphire: \\Ae520-1454\ta\Data\DSC\Calibration\2017\2017-05-17_Saphire.001
InstCalDate	Tzero 2017-05-18 Time 10:50:44
TempRange	-87.39 to 398.39 °C at 10.00 °C/min Heat Only
AutoZero	Delta T Offset 0.000 uV
AutoZero	Delta T0 Offset 0.000 uV
MultiptCal	0
MultiPtDesc	0) Not set
AutoCellConst	Calibration Date 2017-05-18 16:59:28
Controls	Gas 1  Event Off  Sampling 0.2
Cell#	RC-01562
CoolingUnit	RCS (90)
SelHeatFlow	Heat Flow T4P (mW)
AutoLidII	Installed
AutoAnalysis	Off
MacroFile
Nsig	3
Sig1	Time (min)
Sig2	Temperature (°C)
Sig3	Heat Flow (mW)
Date	2017-08-30
Time	20:02:30
OrgMethod	1: Equilibrate at 80.00 °C
OrgMethod	2: Isothermal for 3.00 min
OrgMethod	3: Jump to 130.00 °C
OrgMethod	4: Mark end of cycle 1
OrgMethod	5: Isothermal for 40.00 min
OrgMethod	6: Mark end of cycle 2
OrgMethod	7: Ramp 20.00 °C/min to 280.00 °C
OrgMethod	8: Mark end of cycle 3
OrgMethod	9: Ramp 20.00 °C/min to 20.00 °C
OrgMethod	10: Mark end of cycle 4
OrgMethod	11: Ramp 20.00 °C/min to 280.00 °C
OrgMethod	12: Mark end of cycle 5
OrgFile	C:\Users\jarra\Desktop\DSC\7-C1(1.2mol%)+C20(0.6mol%)(1)\130-1.001
StartOfData
4.99994E-4	79.58461	-4.992182
0.05383332	79.65351	-4.083138
0.1071666	79.70518	-3.397046
0.1588333	79.74319	-2.893651
0.2105000	79.77194	-2.504963
0.2638334	79.79446	-2.202983
0.3155000	79.81062	-1.980111
0.3671667	79.82168	-1.813384
0.4205000	79.83140	-1.688051
0.4721666	79.83795	-1.601149
0.5238333	79.84211	-1.532792
0.5771668	79.84581	-1.484735
0.6305000	79.84735	-1.453451
0.6805000	79.84810	-1.431138
0.7338332	79.85010	-1.415762
0.7871668	79.85022	-1.407319
0.8371668	79.84988	-1.403026
0.8904999	79.85053	-1.399988
0.9438332	79.84994	-1.396954
0.9955000	79.84958	-1.394122
1.047167	79.84844	-1.391384
1.100500	79.84834	-1.388842
1.152167	79.84813	-1.386626
1.203834	79.84708	-1.384633
1.257166	79.84578	-1.382925
1.308833	79.84529	-1.381541
1.360500	79.84497	-1.380394
1.413834	79.84390	-1.379512
1.465500	79.84282	-1.378947
1.517167	79.84249	-1.378708
1.570500	79.84168	-1.378663
1.623833	79.84091	-1.378994
1.673834	79.84092	-1.379372
1.727167	79.84039	-1.379950
1.780500	79.83862	-1.380720
1.830500	79.83866	-1.381601
1.883833	79.83738	-1.382717
1.937166	79.83560	-1.383967
1.988833	79.83638	-1.385344
2.040500	79.83550	-1.386758
2.093834	79.83508	-1.388240
2.145500	79.83510	-1.389884
2.197166	79.83406	-1.391490
2.250500	79.83271	-1.393259
2.302166	79.83278	-1.395009
2.353833	79.83306	-1.396790
2.407167	79.83179	-1.398716
2.458833	79.83202	-1.400616
2.510500	79.83074	-1.402583
2.563833	79.83062	-1.404705
2.617167	79.83062	-1.406893
2.667167	79.82934	-1.408945
2.720500	79.82875	-1.411098
2.773833	79.82866	-1.413341
2.823833	79.82860	-1.415458
2.877167	79.82836	-1.417714
2.930500	79.82759	-1.419927
2.982167	79.82624	-1.422003
3.030500	79.88769	-2.523526
3.082167	81.17388	-16.63000
3.133833	83.52940	-30.01031
3.187167	86.52268	-42.86192
3.238834	89.86472	-54.01519
3.290500	93.53150	-63.62761
3.343834	97.57431	-71.97259
3.397167	101.8085	-78.89048
3.447167	105.9054	-84.33085
3.500500	110.3722	-89.15986
3.553833	114.7497	-90.97376
3.603833	117.7920	-82.45500
3.657167	120.1026	-71.79122
3.710500	121.8754	-61.13390
3.762167	123.2033	-51.77331
3.813833	124.2518	-43.67852
3.867166	125.1110	-36.74356
3.918833	125.7737	-31.29548
3.970500	126.3104	-26.89794
4.023834	126.7607	-23.30554
4.075500	127.1169	-20.55863
4.127167	127.4116	-18.38705
4.180500	127.6646	-16.61834
4.232167	127.8702	-15.26434
4.283834	128.0434	-14.18975
4.337167	128.1947	-13.31020
4.390500	128.3239	-12.60789
4.440500	128.4282	-12.06861
4.493834	128.5238	-11.59836
4.547167	128.6076	-11.20960
4.597166	128.6759	-10.90258
4.650500	128.7408	-10.62238
4.703833	128.7969	-10.38134
4.755500	128.8444	-10.18300
4.807167	128.8865	-10.00940
4.860500	128.9264	-9.857338
4.912167	128.9596	-9.724924
4.963834	128.9898	-9.606754
5.017166	129.0169	-9.502712
5.068833	129.0415	-9.412158
5.120500	129.0623	-9.328249
5.173834	129.0819	-9.253371
5.225500	129.0993	-9.186718
5.277168	129.1148	-9.127314
5.330500	129.1289	-9.072645
5.383832	129.1425	-9.019158
5.433832	129.1536	-8.976120
5.487168	129.1650	-8.932398
5.540500	129.1748	-8.891656
5.590500	129.1835	-8.857648
5.643832	129.1915	-8.821895
5.697168	129.2000	-8.788288
5.748834	129.2066	-8.756689
5.800500	129.2132	-8.727600
5.853832	129.2198	-8.699034
5.905500	129.2244	-8.671416
5.957168	129.2299	-8.645438
6.010500	129.2349	-8.618268
6.062168	129.2399	-8.593288
6.113834	129.2438	-8.566942
6.167168	129.2485	-8.540478
6.220500	129.2529	-8.514259
6.270500	129.2559	-8.489511
6.323834	129.2596	-8.463426
6.377168	129.2638	-8.439581
6.427168	129.2664	-8.415701
6.480500	129.2706	-8.389247
6.533832	129.2737	-8.364648
6.585500	129.2766	-8.340247
6.637168	129.2801	-8.316486
6.690500	129.2819	-8.290309
6.742166	129.2855	-8.267072
6.793832	129.2880	-8.242349
6.847168	129.2904	-8.215394
6.898834	129.2936	-8.189441
6.950500	129.2966	-8.162080
7.003832	129.2984	-8.134476
7.055500	129.3009	-8.107481
7.107168	129.3032	-8.078538
7.160500	129.3057	-8.050330
7.213834	129.3088	-8.018147
7.263834	129.3106	-7.988584
7.317168	129.3142	-7.956189
7.370500	129.3162	-7.922309
7.420500	129.3200	-7.888535
7.473834	129.3214	-7.851931
7.527168	129.3241	-7.815686
7.578834	129.3271	-7.777982
7.630500	129.3295	-7.741926
7.683832	129.3329	-7.704003
7.735500	129.3352	-7.665276
7.787168	129.3383	-7.624978
7.840500	129.3409	-7.580172
7.892168	129.3439	-7.536704
7.943832	129.3475	-7.489072
7.997168	129.3512	-7.434722
8.048834	129.3547	-7.382406
8.100500	129.3580	-7.331305
8.153832	129.3622	-7.275210
8.207168	129.3652	-7.217405
8.257168	129.3689	-7.163176
8.310500	129.3730	-7.104760
8.363834	129.3765	-7.044951
8.413834	129.3804	-6.988894
8.467168	129.3860	-6.921825
8.520500	129.3906	-6.848569
8.572168	129.3958	-6.769189
8.623834	129.4014	-6.676456
8.677168	129.4087	-6.562428
8.728834	129.4174	-6.436892
8.780500	129.4256	-6.303693
8.833832	129.4349	-6.166952
8.885499	129.4439	-6.034322
8.937166	129.4532	-5.904747
8.990500	129.4626	-5.769494
9.042168	129.4700	-5.647632
9.093832	129.4784	-5.541313
9.147168	129.4855	-5.440195
9.200500	129.4922	-5.352127
9.250500	129.4978	-5.277543
9.303832	129.5024	-5.209275
9.357166	129.5066	-5.151072
9.407166	129.5104	-5.102649
9.460499	129.5138	-5.060172
9.513832	129.5173	-5.024373
9.565500	129.5195	-4.993943
9.617166	129.5227	-4.968800
9.670500	129.5245	-4.946224
9.722168	129.5257	-4.926480
9.773834	129.5280	-4.909253
9.827168	129.5292	-4.892603
9.878834	129.5312	-4.878213
9.930500	129.5326	-4.863880
9.983832	129.5340	-4.850543
10.03550	129.5353	-4.839491
10.08717	129.5362	-4.828572
10.14050	129.5376	-4.816296
10.19383	129.5390	-4.803776
10.24383	129.5398	-4.793300
10.29717	129.5408	-4.782026
10.35050	129.5413	-4.769624
10.40050	129.5428	-4.759128
10.45383	129.5437	-4.746838
10.50717	129.5448	-4.733594
10.55884	129.5462	-4.720526
10.61050	129.5480	-4.705800
10.66383	129.5486	-4.691544
10.71550	129.5503	-4.677802
10.76717	129.5513	-4.662320
10.82050	129.5525	-4.647739
10.87217	129.5536	-4.633132
10.92383	129.5549	-4.617878
10.97717	129.5558	-4.601461
11.03050	129.5568	-4.584702
11.08050	129.5586	-4.570406
11.13383	129.5589	-4.554239
11.18716	129.5599	-4.538400
11.23717	129.5613	-4.524315
11.29050	129.5629	-4.509353
11.34383	129.5639	-4.494828
11.39550	129.5647	-4.480496
11.44717	129.5654	-4.467848
11.50050	129.5661	-4.455489
11.55216	129.5676	-4.443288
11.60383	129.5690	-4.431533
11.65717	129.5703	-4.417816
11.70883	129.5708	-4.405630
11.76050	129.5720	-4.393556
11.81383	129.5725	-4.378516
11.86550	129.5741	-4.364822
11.91717	129.5752	-4.350574
11.97050	129.5759	-4.335838
12.02383	129.5772	-4.320502
12.07383	129.5781	-4.305972
12.12717	129.5788	-4.289834
12.18050	129.5802	-4.273756
12.23050	129.5821	-4.258732
12.28383	129.5825	-4.243212
12.33717	129.5833	-4.227130
12.38883	129.5850	-4.211285
12.44050	129.5854	-4.194504
12.49384	129.5868	-4.177614
12.54550	129.5888	-4.161078
12.59717	129.5892	-4.142922
12.65050	129.5906	-4.123411
12.70217	129.5918	-4.106592
12.75384	129.5930	-4.089246
12.80717	129.5944	-4.068851
12.85883	129.5961	-4.049154
12.91050	129.5975	-4.027956
12.96383	129.5990	-4.005364
13.01717	129.5998	-3.981968
13.06716	129.6020	-3.959418
13.12050	129.6019	-3.934447
13.17383	129.6046	-3.911411
13.22383	129.6060	-3.885182
13.27717	129.6083	-3.851888
13.33050	129.6094	-3.816325
13.38216	129.6107	-3.778925
13.43383	129.6128	-3.740824
13.48716	129.6154	-3.698663
13.53883	129.6179	-3.655859
13.59050	129.6210	-3.610606
13.64383	129.6229	-3.563916
13.69550	129.6261	-3.518405
13.74717	129.6283	-3.471139
13.80050	129.6316	-3.422162
13.85217	129.6346	-3.373602
13.90383	129.6380	-3.322817
13.95717	129.6403	-3.270826
14.01050	129.6442	-3.220710
14.06050	129.6471	-3.174801
14.11383	129.6502	-3.128891
14.16716	129.6537	-3.084925
14.21716	129.6554	-3.047950
14.27050	129.6586	-3.012678
14.32384	129.6608	-2.978224
14.37550	129.6634	-2.948420
14.42717	129.6657	-2.921007
14.48050	129.6672	-2.896467
14.53217	129.6685	-2.876091
14.58383	129.6698	-2.856705
14.63717	129.6724	-2.839625
14.68883	129.6734	-2.824000
14.74050	129.6740	-2.810498
14.79384	129.6757	-2.799171
14.84550	129.6766	-2.788222
14.89717	129.6779	-2.778712
14.95050	129.6784	-2.769930
15.00383	129.6790	-2.761881
15.05383	129.6799	-2.755096
15.10716	129.6814	-2.747750
15.16050	129.6815	-2.740212
15.21050	129.6823	-2.733096
15.26383	129.6822	-2.725358
15.31716	129.6836	-2.717610
15.36884	129.6841	-2.710020
15.42050	129.6848	-2.702513
15.47383	129.6852	-2.694710
15.52550	129.6853	-2.687191
15.57717	129.6854	-2.679744
15.63050	129.6869	-2.672087
15.68217	129.6871	-2.664760
15.73383	129.6871	-2.657505
15.78717	129.6874	-2.650098
15.84050	129.6880	-2.642832
15.89050	129.6879	-2.636172
15.94384	129.6889	-2.629136
15.99717	129.6893	-2.622209
16.04716	129.6898	-2.615784
16.10050	129.6898	-2.609029
16.15383	129.6893	-2.602389
16.20550	129.6909	-2.595940
16.25716	129.6907	-2.589556
16.31050	129.6910	-2.583137
16.36216	129.6909	-2.577010
16.41383	129.6921	-2.570966
16.46716	129.6931	-2.564787
16.51883	129.6928	-2.558812
16.57050	129.6932	-2.552938
16.62383	129.6928	-2.546838
16.67550	129.6939	-2.541015
16.72716	129.6941	-2.535219
16.78050	129.6939	-2.529224
16.83383	129.6949	-2.523498
16.88383	129.6942	-2.518073
16.93716	129.6953	-2.512410
16.99050	129.6953	-2.506722
17.04050	129.6961	-2.501468
17.09383	129.6966	-2.495834
17.14716	129.6963	-2.490252
17.19884	129.6966	-2.484814
17.25050	129.6975	-2.479311
17.30383	129.6979	-2.473613
17.35550	129.6987	-2.468025
17.40716	129.6985	-2.462353
17.46050	129.6994	-2.456448
17.51216	129.7001	-2.450722
17.56383	129.7006	-2.444876
17.61716	129.7004	-2.438742
17.66883	129.7014	-2.432736
17.72050	129.7019	-2.426644
17.77383	129.7024	-2.420332
17.82716	129.7023	-2.413856
17.87716	129.7029	-2.407761
17.93050	129.7044	-2.401187
17.98383	129.7051	-2.394436
18.03383	129.7057	-2.388041
18.08716	129.7062	-2.381067
18.14050	129.7060	-2.373980
18.19216	129.7073	-2.366963
18.24383	129.7079	-2.359795
18.29716	129.7080	-2.352275
18.34883	129.7088	-2.344929
18.40050	129.7094	-2.337510
18.45383	129.7108	-2.329830
18.50550	129.7112	-2.322214
18.55716	129.7119	-2.314435
18.61050	129.7122	-2.306375
18.66217	129.7134	-2.298501
18.71383	129.7127	-2.290506
18.76716	129.7139	-2.282246
18.82050	129.7145	-2.273817
18.87050	129.7153	-2.265852
18.92383	129.7164	-2.257213
18.97716	129.7158	-2.248474
19.02716	129.7174	-2.240340
19.08050	129.7177	-2.231594
19.13383	129.7179	-2.222843
19.18550	129.7193	-2.214317
19.23716	129.7196	-2.205734
19.29050	129.7200	-2.196948
19.34216	129.7208	-2.188403
19.39383	129.7217	-2.179852
19.44716	129.7216	-2.171025
19.49883	129.7228	-2.162515
19.55050	129.7234	-2.153986
19.60383	129.7230	-2.145200
19.65550	129.7243	-2.136758
19.70716	129.7252	-2.128300
19.76050	129.7254	-2.119661
19.81383	129.7257	-2.111020
19.86383	129.7262	-2.102998
19.91716	129.7270	-2.094528
19.97050	129.7282	-2.086074
20.02050	129.7277	-2.078242
20.07383	129.7282	-2.069951
20.12716	129.7287	-2.061742
20.17883	129.7300	-2.053882
20.23050	129.7298	-2.046051
20.28383	129.7308	-2.038016
20.33550	129.7300	-2.030275
20.38716	129.7306	-2.022688
20.44050	129.7315	-2.014972
20.49216	129.7318	-2.007610
20.54383	129.7326	-2.000288
20.59716	129.7325	-1.992828
20.65050	129.7338	-1.985466
20.70050	129.7337	-1.978639
20.75383	129.7338	-1.971431
20.80716	129.7339	-1.964356
20.85716	129.7351	-1.957732
20.91050	129.7352	-1.950758
20.96383	129.7358	-1.943853
21.01550	129.7360	-1.937266
21.06716	129.7350	-1.930730
21.12050	129.7360	-1.924152
21.17216	129.7369	-1.917810
21.22383	129.7366	-1.911586
21.27717	129.7378	-1.905219
21.32883	129.7380	-1.899162
21.38050	129.7384	-1.893196
21.43383	129.7384	-1.887108
21.48550	129.7387	-1.881269
21.53717	129.7396	-1.875458
21.59050	129.7399	-1.869565
21.64383	129.7403	-1.863693
21.69383	129.7404	-1.858212
21.74716	129.7402	-1.852408
21.80050	129.7404	-1.846714
21.85050	129.7413	-1.841422
21.90383	129.7411	-1.835956
21.95717	129.7419	-1.830446
22.00883	129.7421	-1.825219
22.06050	129.7425	-1.820035
22.11383	129.7426	-1.814769
22.16550	129.7429	-1.809710
22.21716	129.7423	-1.804680
22.27050	129.7430	-1.799612
22.32216	129.7441	-1.794746
22.37383	129.7432	-1.789839
22.42717	129.7440	-1.784906
22.47883	129.7445	-1.780192
22.53050	129.7437	-1.775506
22.58383	129.7443	-1.770753
22.63716	129.7456	-1.766087
22.68716	129.7445	-1.761682
22.74050	129.7458	-1.757116
22.79383	129.7461	-1.752566
22.84383	129.7464	-1.748226
22.89716	129.7459	-1.743713
22.95050	129.7467	-1.739185
23.00217	129.7467	-1.734911
23.05383	129.7467	-1.730646
23.10716	129.7476	-1.726319
23.15883	129.7476	-1.722150
23.21050	129.7481	-1.718044
23.26383	129.7481	-1.713865
23.31550	129.7487	-1.709909
23.36716	129.7479	-1.705850
23.42050	129.7495	-1.701776
23.47216	129.7494	-1.697784
23.52383	129.7495	-1.693781
23.57716	129.7496	-1.689672
23.63050	129.7502	-1.685626
23.68050	129.7509	-1.681831
23.73383	129.7505	-1.677757
23.78717	129.7511	-1.673730
23.83716	129.7523	-1.669934
23.89050	129.7509	-1.665823
23.94383	129.7519	-1.661822
23.99550	129.7524	-1.657883
24.04716	129.7519	-1.653941
24.10050	129.7535	-1.649895
24.15216	129.7528	-1.645894
24.20383	129.7528	-1.641934
24.25716	129.7526	-1.637782
24.30883	129.7527	-1.633772
24.36050	129.7531	-1.629804
24.41383	129.7527	-1.625706
24.46550	129.7536	-1.621780
24.51716	129.7536	-1.617912
24.57050	129.7538	-1.613944
24.62383	129.7547	-1.610044
24.67383	129.7547	-1.606406
24.72716	129.7553	-1.602519
24.78050	129.7562	-1.598726
24.83050	129.7561	-1.595085
24.88383	129.7558	-1.591130
24.93716	129.7560	-1.587203
24.98883	129.7567	-1.583365
25.04050	129.7562	-1.579481
25.09383	129.7578	-1.575464
25.14550	129.7568	-1.571530
25.19716	129.7579	-1.567629
25.25050	129.7581	-1.563625
25.30217	129.7585	-1.559716
25.35383	129.7590	-1.555817
25.40716	129.7587	-1.551745
25.46050	129.7592	-1.547666
25.51050	129.7597	-1.543885
25.56383	129.7603	-1.539799
25.61716	129.7607	-1.535718
25.66716	129.7617	-1.531810
25.72050	129.7618	-1.527618
25.77383	129.7619	-1.523328
25.82550	129.7615	-1.519098
25.87716	129.7625	-1.514922
25.93050	129.7628	-1.510568
25.98216	129.7621	-1.506363
26.03383	129.7624	-1.502191
26.08716	129.7632	-1.497830
26.13883	129.7633	-1.493601
26.19050	129.7631	-1.489379
26.24383	129.7640	-1.485030
26.29550	129.7643	-1.480817
26.34716	129.7645	-1.476561
26.40050	129.7648	-1.472209
26.45383	129.7643	-1.467912
26.50383	129.7651	-1.463862
26.55716	129.7657	-1.459492
26.61050	129.7660	-1.455010
26.66050	129.7659	-1.450822
26.71383	129.7664	-1.446362
26.76716	129.7669	-1.441856
26.81883	129.7667	-1.437540
26.87050	129.7673	-1.433143
26.92383	129.7677	-1.428633
26.97550	129.7679	-1.424272
27.02717	129.7676	-1.419884
27.08050	129.7693	-1.415390
27.13216	129.7684	-1.411029
27.18383	129.7688	-1.406724
27.23716	129.7699	-1.402211
27.28883	129.7698	-1.397799
27.34050	129.7708	-1.393403
27.39383	129.7708	-1.388775
27.44717	129.7711	-1.384157
27.49716	129.7704	-1.379871
27.55050	129.7712	-1.375275
27.60383	129.7726	-1.370724
27.65383	129.7720	-1.366399
27.70716	129.7716	-1.361746
27.76050	129.7724	-1.357149
27.81217	129.7730	-1.352756
27.86383	129.7737	-1.348328
27.91716	129.7732	-1.343604
27.96883	129.7746	-1.339088
28.02050	129.7738	-1.334575
28.07383	129.7747	-1.329940
28.12550	129.7743	-1.325365
28.17717	129.7757	-1.320915
28.23050	129.7757	-1.316146
28.28216	129.7760	-1.311600
28.33383	129.7758	-1.307074
28.38716	129.7770	-1.302484
28.44050	129.7773	-1.297825
28.49050	129.7779	-1.293445
28.54383	129.7776	-1.288664
28.59716	129.7781	-1.283947
28.64716	129.7792	-1.279496
28.70050	129.7788	-1.274678
28.75383	129.7794	-1.269877
28.80550	129.7796	-1.265227
28.85716	129.7798	-1.260533
28.91050	129.7795	-1.255735
28.96216	129.7801	-1.251146
29.01383	129.7808	-1.246582
29.06716	129.7819	-1.241780
29.11883	129.7819	-1.237182
29.17050	129.7815	-1.232513
29.22383	129.7819	-1.227726
29.27550	129.7824	-1.223118
29.32717	129.7823	-1.218493
29.38050	129.7825	-1.213743
29.43383	129.7832	-1.208949
29.48383	129.7838	-1.204469
29.53717	129.7837	-1.199701
29.59050	129.7839	-1.194933
29.64050	129.7840	-1.190479
29.69383	129.7850	-1.185801
29.74716	129.7847	-1.181151
29.79883	129.7849	-1.176641
29.85050	129.7860	-1.172110
29.90383	129.7852	-1.167451
29.95550	129.7862	-1.162981
30.00716	129.7866	-1.158472
30.06050	129.7871	-1.153857
30.11216	129.7875	-1.149400
30.16383	129.7873	-1.144973
30.21716	129.7881	-1.140333
30.27050	129.7878	-1.135752
30.32050	129.7888	-1.131516
30.37383	129.7886	-1.126898
30.42717	129.7892	-1.122252
30.47717	129.7888	-1.117844
30.53050	129.7890	-1.113213
30.58383	129.7896	-1.108598
30.63550	129.7894	-1.104139
30.68717	129.7899	-1.099670
30.74050	129.7904	-1.095147
30.79216	129.7906	-1.090734
30.84383	129.7910	-1.086352
30.89716	129.7913	-1.081905
30.94883	129.7916	-1.077601
31.00050	129.7923	-1.073408
31.05383	129.7918	-1.069120
31.10550	129.7920	-1.064950
31.15716	129.7929	-1.060801
31.21050	129.7934	-1.056530
31.26383	129.7937	-1.052268
31.31383	129.7933	-1.048291
31.36716	129.7936	-1.044035
31.42050	129.7942	-1.039792
31.47050	129.7939	-1.035917
31.52383	129.7955	-1.031753
31.57717	129.7948	-1.027614
31.62883	129.7957	-1.023694
31.68050	129.7955	-1.019708
31.73383	129.7960	-1.015674
31.78550	129.7958	-1.011816
31.83716	129.7964	-1.007889
31.89050	129.7974	-1.003877
31.94216	129.7969	-0.9999064
31.99383	129.7967	-0.9959751
32.04716	129.7973	-0.9919876
32.09883	129.7978	-0.9881420
32.15050	129.7985	-0.9844001
32.20383	129.7987	-0.9804225
32.25716	129.7986	-0.9764638
32.30716	129.7984	-0.9728356
32.36050	129.7985	-0.9690125
32.41383	129.7990	-0.9651903
32.46383	129.7987	-0.9615874
32.51716	129.8003	-0.9578076
32.57050	129.7997	-0.9539532
32.62216	129.8000	-0.9502259
32.67383	129.7996	-0.9465380
32.72717	129.7997	-0.9427391
32.77883	129.8009	-0.9390431
32.83050	129.8005	-0.9352936
32.88383	129.8003	-0.9313812
32.93550	129.8004	-0.9276389
32.98717	129.8008	-0.9240004
33.04050	129.8009	-0.9202324
33.09216	129.8012	-0.9167004
33.14383	129.8022	-0.9131550
33.19717	129.8014	-0.9095559
33.25050	129.8015	-0.9059539
33.30050	129.8024	-0.9026460
33.35383	129.8032	-0.8991903
33.40716	129.8017	-0.8956625
33.45716	129.8026	-0.8924650
33.51050	129.8036	-0.8890491
33.56383	129.8039	-0.8856739
33.61550	129.8034	-0.8823484
33.66716	129.8036	-0.8791281
33.72050	129.8049	-0.8758334
33.77217	129.8044	-0.8725320
33.82383	129.8048	-0.8693259
33.87717	129.8043	-0.8659676
33.92883	129.8050	-0.8627837
33.98050	129.8049	-0.8596608
34.03383	129.8054	-0.8564189
34.08550	129.8054	-0.8532936
34.13716	129.8062	-0.8501700
34.19050	129.8061	-0.8469431
34.24383	129.8056	-0.8437259
34.29383	129.8068	-0.8407780
34.34716	129.8068	-0.8376408
34.40050	129.8063	-0.8345812
34.45050	129.8070	-0.8317451
34.50383	129.8079	-0.8287064
34.55716	129.8075	-0.8256570
34.60883	129.8070	-0.8227243
34.66050	129.8075	-0.8197955
34.71383	129.8080	-0.8168016
34.76550	129.8074	-0.8139128
34.81716	129.8080	-0.8110531
34.87050	129.8079	-0.8081124
34.92216	129.8083	-0.8053585
34.97383	129.8082	-0.8026310
35.02716	129.8086	-0.7998532
35.08050	129.8086	-0.7971280
35.13050	129.8083	-0.7945916
35.18384	129.8090	-0.7920026
35.23717	129.8086	-0.7894105
35.28717	129.8093	-0.7870384
35.34050	129.8095	-0.7845418
35.39383	129.8098	-0.7821750
35.44550	129.8098	-0.7799294
35.49716	129.8101	-0.7777491
35.55050	129.8105	-0.7755230
35.60217	129.8093	-0.7733989
35.65383	129.8101	-0.7713512
35.70716	129.8102	-0.7693036
35.75883	129.8105	-0.7672900
35.81050	129.8108	-0.7653586
35.86383	129.8113	-0.7634062
35.91550	129.8104	-0.7615492
35.96716	129.8115	-0.7599084
36.02050	129.8112	-0.7581528
36.07383	129.8106	-0.7564424
36.12383	129.8107	-0.7548706
36.17717	129.8115	-0.7532898
36.23050	129.8114	-0.7516656
36.28050	129.8109	-0.7502075
36.33383	129.8116	-0.7487097
36.38716	129.8112	-0.7473243
36.43883	129.8120	-0.7459619
36.49050	129.8113	-0.7447066
36.54383	129.8109	-0.7434850
36.59550	129.8112	-0.7423046
36.64717	129.8115	-0.7412262
36.70050	129.8114	-0.7400239
36.75217	129.8114	-0.7389538
36.80383	129.8104	-0.7378782
36.85716	129.8109	-0.7368638
36.90883	129.8118	-0.7359707
36.96050	129.8118	-0.7350801
37.01383	129.8111	-0.7342172
37.06716	129.8109	-0.7333108
37.11716	129.8106	-0.7324912
37.17050	129.8114	-0.7317235
37.22383	129.8100	-0.7308932
37.27383	129.8110	-0.7301889
37.32717	129.8115	-0.7294929
37.38050	129.8110	-0.7287642
37.43216	129.8107	-0.7281292
37.48383	129.8106	-0.7275186
37.53717	129.8109	-0.7270320
37.58883	129.8107	-0.7266257
37.64050	129.8104	-0.7263180
37.69383	129.8118	-0.7260969
37.74550	129.8114	-0.7259358
37.79716	129.8118	-0.7257207
37.85050	129.8118	-0.7256391
37.90216	129.8108	-0.7255241
37.95383	129.8110	-0.7255548
38.00716	129.8109	-0.7256938
38.06050	129.8117	-0.7256955
38.11050	129.8114	-0.7257166
38.16383	129.8114	-0.7257807
38.21716	129.8111	-0.7259293
38.26716	129.8105	-0.7259998
38.32050	129.8124	-0.7261118
38.37383	129.8106	-0.7262388
38.42550	129.8106	-0.7264182
38.47717	129.8101	-0.7266328
38.53050	129.8106	-0.7269210
38.58216	129.8104	-0.7272571
38.63383	129.8101	-0.7276140
38.68716	129.8097	-0.7280193
38.73883	129.8098	-0.7284150
38.79050	129.8098	-0.7287929
38.84384	129.8099	-0.7291658
38.89550	129.8098	-0.7295694
38.94717	129.8098	-0.7301355
39.00050	129.8099	-0.7306692
39.05383	129.8099	-0.7312863
39.10383	129.8096	-0.7319063
39.15716	129.8086	-0.7326678
39.21050	129.8096	-0.7334648
39.26050	129.8094	-0.7342391
39.31383	129.8091	-0.7350997
39.36716	129.8086	-0.7359688
39.41883	129.8087	-0.7368707
39.47050	129.8087	-0.7377244
39.52383	129.8081	-0.7385447
39.57550	129.8080	-0.7394358
39.62717	129.8087	-0.7403462
39.68050	129.8084	-0.7412356
39.73216	129.8076	-0.7422539
39.78383	129.8084	-0.7433151
39.83716	129.8084	-0.7443115
39.89050	129.8080	-0.7451812
39.94050	129.8088	-0.7460780
39.99383	129.8084	-0.7470718
40.04716	129.8079	-0.7481236
40.09716	129.8069	-0.7491165
40.15050	129.8083	-0.7503430
40.20383	129.8071	-0.7515918
40.25550	129.8072	-0.7530465
40.30716	129.8069	-0.7545197
40.36050	129.8074	-0.7560554
40.41217	129.8070	-0.7576218
40.46383	129.8069	-0.7590740
40.51716	129.8073	-0.7606320
40.56883	129.8066	-0.7621384
40.62050	129.8069	-0.7636350
40.67383	129.8063	-0.7651578
40.72550	129.8058	-0.7666542
40.77716	129.8069	-0.7681594
40.83050	129.8062	-0.7697305
40.88383	129.8055	-0.7713770
40.93384	129.8064	-0.7729374
40.98717	129.8057	-0.7745556
41.04050	129.8054	-0.7762122
41.09050	129.8056	-0.7777239
41.14383	129.8047	-0.7793882
41.19717	129.8049	-0.7811166
41.24883	129.8045	-0.7827320
41.30050	129.8042	-0.7844780
41.35383	129.8048	-0.7863082
41.40550	129.8046	-0.7879880
41.45717	129.8050	-0.7896766
41.51050	129.8045	-0.7914547
41.56216	129.8047	-0.7932202
41.61383	129.8050	-0.7950068
41.66716	129.8041	-0.7967806
41.71884	129.8036	-0.7985272
41.77050	129.8025	-0.8002978
41.82383	129.8042	-0.8021680
41.87717	129.8035	-0.8039526
41.92717	129.8028	-0.8056934
41.98050	129.8035	-0.8075280
42.03383	129.8031	-0.8093575
42.08383	129.8026	-0.8111294
42.13716	129.8031	-0.8130584
42.19050	129.8026	-0.8149856
42.24216	129.8030	-0.8168599
42.29383	129.8031	-0.8187084
42.34716	129.8024	-0.8206426
42.39883	129.8022	-0.8225132
42.45050	129.8024	-0.8244549
42.50383	129.8012	-0.8263765
42.55550	129.8018	-0.8283384
42.60717	129.8007	-0.8303207
42.66050	129.8012	-0.8323442
42.71216	129.8013	-0.8341789
42.76383	129.8007	-0.8360436
42.81717	129.8004	-0.8379175
42.87050	129.8014	-0.8398598
42.92050	129.8010	-0.8416359
42.97383	129.8007	-0.8434711
43.02217	129.8010	-0.8457879
43.07383	129.8939	-2.525985
43.12717	130.2750	-6.190921
43.17883	130.8130	-9.304996
43.23050	131.4707	-11.93697
43.28383	132.2415	-14.05902
43.33550	133.0536	-15.64114
43.38716	133.9134	-16.87698
43.44050	134.8389	-17.88161
43.49216	135.7632	-18.61340
43.54383	136.7082	-19.18574
43.59716	137.7000	-19.66188
43.65050	138.7041	-20.05900
43.70050	139.6556	-20.34890
43.75383	140.6779	-20.62413
43.80717	141.7069	-20.85932
43.85717	142.6763	-21.05214
43.91050	143.7119	-21.26746
43.96383	144.7504	-21.48791
44.01550	145.7577	-21.71918
44.06717	146.7647	-21.97683
44.12050	147.8052	-22.26738
44.17216	148.8118	-22.60788
44.22383	149.8155	-22.98767
44.27716	150.8500	-23.47882
44.32883	151.8484	-23.95268
44.38050	152.8456	-24.44884
44.43383	153.8753	-24.92816
44.48550	154.8748	-25.28438
44.53717	155.8822	-25.48478
44.59050	156.9326	-25.50280
44.64383	157.9933	-25.44666
44.69383	158.9951	-25.17317
44.74716	160.0752	-24.75548
44.80050	161.1604	-24.31463
44.85050	162.1862	-23.78094
44.90383	163.2838	-23.19658
44.95717	164.3864	-22.62052
45.00883	165.4545	-22.06306
45.06050	166.5223	-21.51077
45.11383	167.6237	-20.97560
45.16550	168.6913	-20.47082
45.21717	169.7570	-20.01859
45.27050	170.8538	-19.55730
45.32217	171.9164	-19.13756
45.37383	172.9766	-18.75942
45.42717	174.0683	-18.42968
45.48050	175.1564	-18.12256
45.53050	176.1753	-17.89976
45.58383	177.2563	-17.78498
45.63716	178.3314	-17.75168
45.68716	179.3365	-17.72126
45.74050	180.4069	-17.71320
45.79383	181.4754	-17.71006
45.84550	182.5094	-17.70936
45.89717	183.5419	-17.71032
45.95050	184.6071	-17.71517
46.00217	185.6399	-17.73007
46.05383	186.6718	-17.77167
46.10717	187.7357	-17.82452
46.15883	188.7668	-17.88444
46.21050	189.7969	-17.97217
46.26383	190.8608	-18.05794
46.31550	191.8894	-18.14808
46.36716	192.9169	-18.25776
46.42050	193.9782	-18.36771
46.47383	195.0388	-18.49072
46.52383	196.0316	-18.62751
46.57717	197.0899	-18.78299
46.63050	198.1476	-18.98896
46.68050	199.1361	-19.20911
46.73383	200.1886	-19.53946
46.78717	201.2360	-19.94947
46.83883	202.2458	-20.45436
46.89050	203.2485	-21.09522
46.94383	204.2775	-21.91000
46.99550	205.2640	-22.89056
47.04716	206.2397	-24.08749
47.10050	207.2349	-25.58532
47.15216	208.1835	-27.32890
47.20383	209.1153	-29.37423
47.25717	210.0598	-31.80225
47.30883	210.9564	-34.45083
47.36050	211.8368	-37.30758
47.41383	212.7328	-40.38492
47.46717	213.6230	-43.36456
47.51717	214.4638	-45.63814
47.57050	215.4018	-46.35720
47.62383	216.4388	-44.36369
47.67383	217.5020	-41.94422
47.72717	218.6750	-39.80693
47.78050	219.8603	-37.70750
47.83217	221.0162	-35.45305
47.88383	222.1807	-33.22763
47.93716	223.3800	-31.27946
47.98883	224.5198	-30.16659
48.04050	225.6314	-29.46512
48.09384	226.7550	-29.01585
48.14550	227.8246	-28.71646
48.19717	228.8826	-28.56724
48.25050	229.9670	-28.47310
48.30217	231.0084	-28.44839
48.35383	232.0470	-28.45374
48.40717	233.1154	-28.46012
48.46050	234.1836	-28.48104
48.51050	235.1816	-28.53250
48.56383	236.2473	-28.61644
48.61716	237.3116	-28.70833
48.66716	238.3087	-28.79431
48.72050	239.3718	-28.88010
48.77383	240.4357	-28.96599
48.82550	241.4655	-29.04724
48.87717	242.4956	-29.13100
48.93050	243.5590	-29.20178
48.98217	244.5898	-29.27605
49.03383	245.6195	-29.45317
49.08716	246.6861	-29.41504
49.13883	247.7186	-29.41266
49.19050	248.7500	-29.43893
49.24383	249.8134	-29.48672
49.29550	250.8448	-29.55416
49.34716	251.8756	-29.62319
49.40050	252.9394	-29.68086
49.45383	254.0031	-29.75466
49.50383	254.9996	-29.80306
49.55717	256.0635	-29.88220
49.61050	257.1267	-29.96448
49.66050	258.1238	-30.02909
49.71383	259.1878	-30.09852
49.76717	260.2518	-30.17529
49.81883	261.2799	-30.23532
49.87050	262.3113	-30.30865
49.92383	263.3751	-30.36322
49.97550	264.4068	-30.43946
50.02716	265.4367	-30.49836
50.08050	266.5008	-30.55038
50.13217	267.5311	-30.61469
50.18383	268.5623	-30.67881
50.23717	269.6255	-30.72696
50.29050	270.6892	-30.79410
50.34050	271.6858	-30.85271
50.39383	272.7493	-30.90424
50.44717	273.8135	-30.95632
50.49716	274.8095	-30.95948
50.54716	275.7648	-31.76710
50.59716	276.2474	-29.34305
50.65050	276.2913	-20.92836
50.70383	276.0423	-12.89568
50.75550	275.6056	-6.503379
50.80717	275.0294	-1.518160
50.86050	274.3272	2.400442
50.91217	273.5697	5.263455
50.96383	272.7546	7.430090
51.01717	271.8691	9.124832
51.06883	270.9774	10.34592
51.12050	270.0625	11.29155
51.17383	269.0960	12.04536
51.22550	268.1446	12.60150
51.27717	267.1815	13.04699
51.33050	266.1782	13.40994
51.38383	265.1650	13.71031
51.43383	264.2114	13.93460
51.48717	263.1863	14.13392
51.54050	262.1570	14.30743
51.59050	261.1903	14.44222
51.64384	260.1551	14.57030
51.69717	259.1169	14.68802
51.74883	258.1102	14.78660
51.80050	257.1017	14.87194
51.85383	256.0584	14.95348
51.90550	255.0454	15.03386
51.95717	254.0312	15.10369
52.01050	252.9841	15.16728
52.06216	251.9680	15.22701
52.11383	250.9510	15.28094
52.16716	249.8994	15.33672
52.21884	248.8813	15.38492
52.27050	247.8629	15.43740
52.32383	246.8098	15.48202
52.37717	245.7568	15.52831
52.42717	244.7685	15.57095
52.48050	243.7144	15.61129
52.53383	242.6596	15.65217
52.58383	241.6710	15.68682
52.63716	240.6154	15.72700
52.69050	239.5592	15.75945
52.74216	238.5365	15.78967
52.79382	237.5125	15.82496
52.84716	236.4572	15.85558
52.89883	235.4339	15.89121
52.95050	234.4095	15.91870
53.00383	233.3524	15.94076
53.05550	232.3280	15.96414
53.10717	231.3025	15.98639
53.16050	230.2446	16.01159
53.21216	229.2196	16.03064
53.26382	228.1951	16.06166
53.31716	227.1370	16.09360
53.37050	226.0793	16.12658
53.42050	225.0887	16.15728
53.47382	224.0312	16.19281
53.52717	222.9740	16.23252
53.57717	221.9813	16.27792
53.63050	220.9243	16.30309
53.68383	219.8652	16.33271
53.73550	218.8408	16.36374
53.78716	217.8156	16.38415
53.84050	216.7568	16.41581
53.89216	215.7309	16.44071
53.94384	214.7060	16.45972
53.99717	213.6461	16.48733
54.04883	212.6201	16.50331
54.10050	211.5939	16.52123
54.15383	210.5341	16.53920
54.20550	209.5090	16.56163
54.25717	208.4825	16.57691
54.31050	207.4234	16.59811
54.36382	206.3654	16.61856
54.41382	205.3724	16.63867
54.46717	204.3135	16.66236
54.52050	203.2549	16.68796
54.57050	202.2624	16.70637
54.62383	201.2030	16.73216
54.67717	200.1447	16.75561
54.72883	199.1192	16.78017
54.78050	198.0933	16.80672
54.83383	197.0347	16.83306
54.88550	196.0086	16.85923
54.93716	194.9829	16.88583
54.99050	193.9214	16.90629
55.04217	192.8944	16.92417
55.09384	191.8680	16.93747
55.14717	190.8073	16.95168
55.20050	189.7478	16.96418
55.25050	188.7534	16.97625
55.30383	187.6937	16.98908
55.35717	186.6346	17.00431
55.40717	185.6412	17.02456
55.46050	184.5809	17.04227
55.51382	183.5219	17.06332
55.56550	182.4946	17.08160
55.61716	181.4671	17.09766
55.67050	180.4082	17.11236
55.72217	179.3815	17.13966
55.77383	178.3544	17.16450
55.82717	177.2954	17.19128
55.87883	176.2696	17.22090
55.93050	175.2425	17.25418
55.98383	174.1840	17.29045
56.03550	173.1573	17.32761
56.08716	172.1320	17.38118
56.14050	171.0739	17.48361
56.19384	170.0183	17.65244
56.24382	169.0314	17.85486
56.29717	167.9814	18.14533
56.35050	166.9376	18.53354
56.40050	165.9658	19.03918
56.45383	164.9393	19.84847
56.50717	163.9333	21.09258
56.55883	162.9859	22.93928
56.61050	162.0772	25.53687
56.66382	161.1892	29.09566
56.71550	160.3755	33.12920
56.76716	159.5938	37.29994
56.82050	158.7961	41.18777
56.87217	158.0032	44.19015
56.92383	157.1692	46.18910
56.97717	156.2460	47.05033
57.02883	155.2835	46.75043
57.08050	154.2499	45.33297
57.13383	153.1132	43.02298
57.18716	151.9211	40.15254
57.23717	150.7689	37.26224
57.29050	149.5216	34.25864
57.34384	148.2734	31.53981
57.39384	147.1144	29.33776
57.44717	145.8969	27.36116
57.50050	144.7010	25.74452
57.55217	143.5647	24.49410
57.60383	142.4467	23.49248
57.65717	141.3116	22.66916
57.70883	140.2269	22.05016
57.76050	139.1525	21.52556
57.81382	138.0510	21.09362
57.86550	136.9929	20.75780
57.91716	135.9402	20.48616
57.97050	134.8586	20.25379
58.02217	133.8137	20.06619
58.07383	132.7722	19.91443
58.12717	131.6989	19.76439
58.18050	130.6272	19.65718
58.23050	129.6228	19.56168
58.28383	128.5532	19.47258
58.33716	127.4865	19.39874
58.38716	126.4855	19.32377
58.44050	125.4182	19.25619
58.49382	124.3517	19.19066
58.54550	123.3193	19.13748
58.59716	122.2858	19.08223
58.65050	121.2198	19.02525
58.70216	120.1892	18.97982
58.75383	119.1560	18.94565
58.80717	118.0929	18.91153
58.85883	117.0616	18.88470
58.91050	116.0304	18.85974
58.96382	114.9670	18.82990
59.01550	113.9344	18.78936
59.06716	112.9022	18.73107
59.12050	111.8364	18.64555
59.17383	110.7693	18.56143
59.22382	109.7694	18.48759
59.27717	108.7041	18.43279
59.33050	107.6390	18.38953
59.38050	106.6392	18.35382
59.43383	105.5748	18.31563
59.48717	104.5103	18.27910
59.53882	103.4790	18.25056
59.59050	102.4478	18.21891
59.64384	101.3844	18.18693
59.69550	100.3526	18.16159
59.74717	99.32293	18.13684
59.80050	98.26038	18.12206
59.85217	97.22980	18.10846
59.90383	96.20011	18.07936
59.95717	95.13559	18.03792
60.01050	94.07069	17.97770
60.06050	93.07174	17.91718
60.11382	92.00579	17.85052
60.16716	90.94006	17.78886
60.21717	89.94016	17.72203
60.27050	88.87497	17.67509
60.32383	87.80908	17.62266
60.37550	86.77606	17.58014
60.42717	85.74384	17.53021
60.48050	84.67871	17.48501
60.53217	83.64674	17.44329
60.58383	82.61418	17.40170
60.63716	81.54953	17.35824
60.68882	80.51736	17.31482
60.74050	79.48582	17.27274
60.79382	78.42128	17.23002
60.84550	77.38922	17.18985
60.89717	76.35756	17.15068
60.95050	75.29266	17.10950
61.00383	74.22747	17.07093
61.05383	73.22964	17.02710
61.10717	72.16350	16.98796
61.16050	71.09864	16.93887
61.21050	70.09906	16.89482
61.26382	69.03495	16.84867
61.31716	67.96841	16.79312
61.36882	66.93670	16.74466
61.42050	65.90271	16.70358
61.47382	64.83856	16.65178
61.52550	63.80554	16.60099
61.57717	62.77237	16.54442
61.63050	61.70614	16.48832
61.68217	60.67321	16.43565
61.73383	59.64153	16.38149
61.78716	58.57530	16.32758
61.83882	57.54387	16.28463
61.89050	56.51079	16.24054
61.94384	55.44528	16.19112
61.99717	54.37950	16.15199
62.04717	53.37949	16.09658
62.10050	52.31390	16.04442
62.15383	51.24550	15.98265
62.20383	50.24574	15.92141
62.25717	49.17978	15.87580
62.31050	48.11355	15.81950
62.36217	47.08194	15.77384
62.41382	46.04882	15.72944
62.46717	44.98352	15.67532
62.51884	43.95098	15.62677
62.57050	42.91950	15.58123
62.62383	41.85219	15.52096
62.67550	40.81905	15.46698
62.72717	39.78631	15.41066
62.78050	38.71982	15.34174
62.83217	37.68695	15.27357
62.88383	36.65356	15.21504
62.93716	35.58658	15.14935
62.99050	34.51831	15.08545
63.04050	33.51831	15.01307
63.09384	32.45074	14.94625
63.14717	31.38091	14.86838
63.19717	30.38158	14.79943
63.25050	29.31291	14.74042
63.30383	28.24361	14.64581
63.35550	27.20901	14.57676
63.40717	26.17251	14.49208
63.46050	25.10362	14.44714
63.51050	24.10235	14.45085
63.56216	23.17140	14.92050
63.61382	22.77722	10.09106
63.66716	22.76019	4.532662
63.71884	23.02539	0.1067761
63.77050	23.48265	-3.167060
63.82383	24.10418	-5.698078
63.87550	24.81100	-7.517960
63.92717	25.59182	-8.892600
63.98050	26.45881	-9.971630
64.03384	27.36650	-10.79476
64.08384	28.24720	-11.40217
64.13717	29.20944	-11.91748
64.19050	30.19129	-12.32414
64.24050	31.12224	-12.64590
64.29384	32.12765	-12.92687
64.34717	33.14016	-13.16755
64.39883	34.12654	-13.36783
64.45050	35.11984	-13.53447
64.50384	36.15048	-13.69727
64.55550	37.15070	-13.84558
64.60718	38.15368	-13.98265
64.66050	39.19390	-14.10281
64.71217	40.20320	-14.21374
64.76384	41.21399	-14.32548
64.81717	42.25922	-14.42884
64.87050	43.30662	-14.52920
64.92050	44.28912	-14.61965
64.97384	45.33853	-14.71631
65.02717	46.38908	-14.80589
65.07718	47.37512	-14.89982
65.13050	48.42894	-14.99101
65.18384	49.48004	-15.08150
65.23550	50.50019	-15.17874
65.28717	51.52152	-15.28020
65.34050	52.57578	-15.36615
65.39216	53.59868	-15.46328
65.44384	54.62184	-15.54657
65.49717	55.67818	-15.63805
65.54884	56.70273	-15.73366
65.60050	57.72644	-15.82122
65.65384	58.78432	-15.91684
65.70550	59.80865	-16.01181
65.75718	60.83344	-16.10355
65.81050	61.89174	-16.20998
65.86384	62.94986	-16.30022
65.91382	63.94340	-16.38744
65.96718	65.00222	-16.47548
66.02050	66.06201	-16.56610
66.07050	67.05540	-16.65811
66.12384	68.11488	-16.75069
66.17718	69.17508	-16.83952
66.22884	70.20259	-16.93114
66.28050	71.22816	-17.01848
66.33384	72.28954	-17.12052
66.38550	73.31572	-17.20939
66.43718	74.34341	-17.30327
66.49050	75.40222	-17.39696
66.54218	76.43068	-17.49146
66.59384	77.45868	-17.58493
66.64718	78.51870	-17.67678
66.69884	79.54670	-17.77741
66.75050	80.57434	-17.87301
66.80384	81.63526	-17.96957
66.85718	82.69595	-18.06326
66.90718	83.69094	-18.16241
66.96050	84.75187	-18.26540
67.01384	85.81332	-18.35928
67.06384	86.80785	-18.46222
67.11718	87.86936	-18.56434
67.17050	88.93101	-18.65542
67.22218	89.95800	-18.76676
67.27384	90.98614	-18.86080
67.32718	92.04624	-18.96282
67.37884	93.07472	-19.06914
67.43050	94.10110	-19.17093
67.48384	95.16168	-19.28364
67.53550	96.18920	-19.38231
67.58716	97.21782	-19.47593
67.64050	98.27949	-19.58154
67.69218	99.30744	-19.67554
67.74384	100.3362	-19.77910
67.79718	101.3973	-19.87875
67.85050	102.4587	-19.98137
67.90050	103.4538	-20.07805
67.95384	104.5148	-20.18134
68.00718	105.5762	-20.29261
68.05718	106.5720	-20.39592
68.11050	107.6332	-20.50140
68.16382	108.6942	-20.60436
68.21550	109.7224	-20.71438
68.26716	110.7500	-20.81488
68.32050	111.8112	-20.92900
68.37218	112.8394	-21.02869
68.42384	113.8664	-21.13164
68.47718	114.9281	-21.25122
68.52884	115.9562	-21.35013
68.58050	116.9846	-21.44622
68.63384	118.0464	-21.55764
68.68550	119.0736	-21.66611
68.73718	120.1018	-21.78508
68.79050	121.1619	-21.90618
68.84384	122.2210	-22.03491
68.89384	123.2159	-22.15274
68.94718	124.2769	-22.27254
69.00050	125.3363	-22.39804
69.05050	126.3302	-22.51286
69.10384	127.3912	-22.63386
69.15718	128.4507	-22.75594
69.20884	129.4783	-22.88276
69.26050	130.5044	-23.01060
69.31384	131.5647	-23.14640
69.36550	132.5898	-23.26851
69.41718	133.6168	-23.41408
69.47050	134.6759	-23.55537
69.52218	135.7014	-23.69269
69.57384	136.7272	-23.83408
69.62718	137.7862	-23.97959
69.68050	138.8461	-24.13452
69.73050	139.8395	-24.26156
69.78384	140.8992	-24.40390
69.83716	141.9575	-24.56014
69.88718	142.9503	-24.71274
69.94050	144.0075	-24.87204
69.99384	145.0661	-25.03683
70.04550	146.0920	-25.13426
70.09718	147.1197	-25.22258
70.15050	148.1803	-25.32203
70.20216	149.2088	-25.43489
70.25384	150.2377	-25.55354
70.30718	151.2977	-25.66235
70.35884	152.3256	-25.81004
70.41050	153.3528	-25.93647
70.46384	154.4134	-26.06170
70.51550	155.4408	-26.18758
70.56718	156.4671	-26.30890
70.62050	157.5278	-26.42640
70.67384	158.5888	-26.52740
70.72384	159.5841	-26.60878
70.77718	160.6486	-26.64559
70.83050	161.7140	-26.65768
70.88050	162.7134	-26.66463
70.93384	163.7808	-26.66734
70.98718	164.8492	-26.67272
71.03882	165.8821	-26.68656
71.09050	166.9153	-26.73188
71.14384	167.9812	-26.79350
71.19550	169.0128	-26.88260
71.24718	170.0438	-26.98202
71.30050	171.1064	-27.10784
71.35218	172.1351	-27.23908
71.40384	173.1627	-27.36155
71.45718	174.2226	-27.54759
71.50884	175.2481	-27.68006
71.56050	176.2730	-27.85194
71.61384	177.3305	-28.05623
71.66718	178.3868	-28.28555
71.71718	179.3751	-28.49634
71.77050	180.4282	-28.77338
71.82384	181.4790	-29.08345
71.87384	182.4631	-29.39170
71.92718	183.5105	-29.78152
71.98050	184.5553	-30.21148
72.03218	185.5644	-30.66989
72.08384	186.5704	-31.19760
72.13718	187.6066	-31.78670
72.18884	188.6074	-32.40388
72.24050	189.6046	-33.06106
72.29384	190.6328	-33.74890
72.34550	191.6277	-34.42337
72.39718	192.6222	-35.10706
72.45050	193.6471	-35.82102
72.50218	194.6386	-36.56741
72.55384	195.6267	-37.38397
72.60718	196.6433	-38.32855
72.66050	197.6550	-39.35999
72.71050	198.5988	-40.41836
72.76384	199.5994	-41.63572
72.81718	200.5962	-42.90600
72.86718	201.5270	-44.11581
72.92050	202.5190	-45.37967
72.97384	203.5136	-46.50597
73.02550	204.4830	-47.34984
73.07718	205.4706	-47.68361
73.13050	206.5205	-47.30816
73.18218	207.5920	-45.20904
73.23384	208.7338	-41.88572
73.28718	209.9798	-37.91468
73.33884	211.2112	-34.71591
73.39050	212.4206	-32.62523
73.44384	213.6269	-31.23213
73.49550	214.7592	-30.32926
73.54718	215.8642	-29.67684
73.60050	216.9831	-29.21752
73.65384	218.0870	-28.90198
73.70384	219.1112	-28.69704
73.75718	220.1961	-28.56476
73.81050	221.2748	-28.48222
73.86050	222.2823	-28.44429
73.91382	223.3548	-28.43428
73.96718	224.4244	-28.43260
74.01882	225.4588	-28.43256
74.07050	226.4930	-28.43484
74.12384	227.5601	-28.44202
74.17550	228.5934	-28.46470
74.22718	229.6274	-28.51236
74.28050	230.6919	-28.56168
74.33218	231.7242	-28.63242
74.38384	232.7556	-28.69416
74.43718	233.8204	-28.76526
74.49050	234.8852	-28.81688
74.54050	235.8842	-28.86984
74.59384	236.9489	-28.91946
74.64718	238.0124	-28.98092
74.69718	239.0102	-29.04060
74.75050	240.0738	-29.11304
74.80384	241.1382	-29.18875
74.85550	242.1688	-29.24876
74.90718	243.2010	-29.32169
74.96050	244.2653	-29.37496
75.01218	245.2959	-29.43872
75.06384	246.3276	-29.49848
75.11718	247.3922	-29.54966
75.16884	248.4225	-29.60176
75.22050	249.4532	-29.67033
75.27384	250.5170	-29.73325
75.32550	251.5477	-29.80113
75.37718	252.5783	-29.86830
75.43050	253.6420	-29.92363
75.48384	254.7060	-29.98506
75.53384	255.7030	-30.05308
75.58716	256.7673	-30.12806
75.64050	257.8312	-30.19791
75.69050	258.8292	-30.26626
75.74384	259.8918	-30.34706
75.79718	260.9558	-30.41646
75.84882	261.9854	-30.49265
75.90050	263.0161	-30.56706
75.95384	264.0794	-30.64027
76.00550	265.1088	-30.72014
76.05718	266.1386	-30.80678
76.11050	267.1998	-30.91041
76.16218	268.2286	-31.01692
76.21384	269.2572	-31.08974
76.26716	270.3207	-31.15782
76.31884	271.3500	-31.22586
-2.000000	5.000000	0.0000000