File: 7-C1(1.2mol%)+C20(0.6mol%)(1)/matlab/140-1.txt
CLOSED
Version	1.0
Language	English
Mode	Standard
Run	27
RunSerial	12295
Instrument	DSC Q2000 V24.11 Build 124
Module	DSC Standard Cell RC
Operator
File	\\AE520-1454\Users\dsc\Desktop\Data\29-08-17-3\140-1.001
ProcName
InstSerial	2000-0883
AutoSerial	1293
Sample	140-1
Size	18.8000	mg
PanMass	Not available
PanResist	Automatic Automatic  K/W
PanFactor	Default Default
Method
Comment
Xcomment	Pan: Tzero Aluminum Hermetic
Xcomment	Gas1: Nitrogen 50.0 ml/min
Xcomment	Gas2: Nitrogen 50.0 ml/min
Text
Exotherm	UP
Kcell	1.05230
Cpconst	Standard: 0.938
Calib	-38.6961
TempCal	1	pts	157.46	156.60
TzeroDt	-87.6168 -0.0009 -1.4231
TzeroDtz	-87.6168 0.0057 6.9570
InstCalFile	Tzero: \\Ae520-1454\ta\Data\DSC\Calibration\2017\CALIBRATION\1562_RCS (90)_05_18_2017 10_50_44.TZR
InstCalFile	Baseline: \\Ae520-1454\ta\Data\DSC\Calibration\2017\2017-05-17_Calibration.001
InstCalFile	Sapphire: \\Ae520-1454\ta\Data\DSC\Calibration\2017\2017-05-17_Saphire.001
InstCalDate	Tzero 2017-05-18 Time 10:50:44
TempRange	-87.39 to 398.39 °C at 10.00 °C/min Heat Only
AutoZero	Delta T Offset 0.000 uV
AutoZero	Delta T0 Offset 0.000 uV
MultiptCal	0
MultiPtDesc	0) Not set
AutoCellConst	Calibration Date 2017-05-18 16:59:28
Controls	Gas 1  Event Off  Sampling 0.2
Cell#	RC-01562
CoolingUnit	RCS (90)
SelHeatFlow	Heat Flow T4P (mW)
AutoLidII	Installed
AutoAnalysis	Off
MacroFile
Nsig	3
Sig1	Time (min)
Sig2	Temperature (°C)
Sig3	Heat Flow (mW)
Date	2017-08-30
Time	22:48:16
OrgMethod	1: Equilibrate at 80.00 °C
OrgMethod	2: Isothermal for 3.00 min
OrgMethod	3: Jump to 140.00 °C
OrgMethod	4: Mark end of cycle 1
OrgMethod	5: Isothermal for 40.00 min
OrgMethod	6: Mark end of cycle 2
OrgMethod	7: Ramp 20.00 °C/min to 280.00 °C
OrgMethod	8: Mark end of cycle 3
OrgMethod	9: Ramp 20.00 °C/min to 20.00 °C
OrgMethod	10: Mark end of cycle 4
OrgMethod	11: Ramp 20.00 °C/min to 280.00 °C
OrgMethod	12: Mark end of cycle 5
OrgFile	C:\Users\jarra\Desktop\DSC\7-C1(1.2mol%)+C20(0.6mol%)(1)\140-1.001
StartOfData
4.99994E-4	79.80050	-2.287686
0.05383332	79.83157	-1.844415
0.1055000	79.85391	-1.523320
0.1571666	79.87107	-1.279866
0.2105000	79.88220	-1.090018
0.2605000	79.89170	-0.9595641
0.3138333	79.89778	-0.8535672
0.3655000	79.90234	-0.7809215
0.4171667	79.90551	-0.7259134
0.4705000	79.90722	-0.6859712
0.5205000	79.90772	-0.6594024
0.5738334	79.90835	-0.6414382
0.6238334	79.90921	-0.6301640
0.6771668	79.90854	-0.6225276
0.7288332	79.90821	-0.6185713
0.7805000	79.90762	-0.6154139
0.8338332	79.90679	-0.6120336
0.8838332	79.90659	-0.6088876
0.9371668	79.90556	-0.6056120
0.9888332	79.90429	-0.6025874
1.040500	79.90546	-0.5997352
1.093833	79.90337	-0.5969460
1.143833	79.90278	-0.5946081
1.197166	79.90212	-0.5922638
1.247166	79.90162	-0.5902730
1.300500	79.90070	-0.5883861
1.352166	79.89980	-0.5866250
1.403833	79.89956	-0.5851310
1.457167	79.89901	-0.5837770
1.507167	79.89863	-0.5826076
1.560500	79.89718	-0.5815292
1.612166	79.89778	-0.5806158
1.663834	79.89726	-0.5798149
1.717167	79.89650	-0.5791056
1.767167	79.89549	-0.5785000
1.820500	79.89497	-0.5780274
1.870500	79.89401	-0.5776945
1.923834	79.89374	-0.5774229
1.975500	79.89282	-0.5772663
2.027166	79.89295	-0.5771812
2.080500	79.89157	-0.5771645
2.130500	79.89062	-0.5772148
2.183833	79.89074	-0.5773868
2.235500	79.89001	-0.5775450
2.287166	79.88962	-0.5778252
2.338833	79.88945	-0.5781735
2.390500	79.88785	-0.5785050
2.443833	79.88760	-0.5789209
2.493833	79.88770	-0.5793336
2.547166	79.88731	-0.5797790
2.598834	79.88709	-0.5802948
2.650500	79.88606	-0.5808724
2.703833	79.88626	-0.5814895
2.753833	79.88601	-0.5820610
2.807167	79.88540	-0.5827400
2.858833	79.88561	-0.5834900
2.910500	79.88484	-0.5842300
2.962167	79.88503	-0.5850601
3.010500	79.89106	-0.6489696
3.060500	80.67361	-6.326781
3.113833	83.19020	-16.47399
3.165500	86.16316	-25.75547
3.217166	89.56868	-34.56238
3.270500	93.42059	-42.57664
3.320500	97.26668	-48.98042
3.373834	101.5514	-54.68886
3.425500	105.8304	-59.27620
3.477167	110.2013	-63.05330
3.530500	114.7829	-66.21710
3.580500	119.1182	-68.70788
3.633833	123.7554	-70.75674
3.683833	127.5374	-68.50530
3.737167	130.0985	-60.07032
3.788833	131.9776	-51.50532
3.840500	133.4158	-42.89623
3.893833	134.5826	-34.99742
3.943833	135.4564	-28.65670
3.997166	136.2035	-23.06919
4.048834	136.7846	-18.69850
4.100500	137.2575	-15.19579
4.153834	137.6546	-12.32610
4.203833	137.9614	-10.21024
4.257167	138.2306	-8.423700
4.307167	138.4402	-7.100050
4.360500	138.6262	-5.985995
4.412167	138.7782	-5.134074
4.463834	138.9049	-4.454364
4.517166	139.0169	-3.901870
4.567167	139.1046	-3.484838
4.620500	139.1852	-3.135262
4.672167	139.2518	-2.854180
4.723834	139.3097	-2.635886
4.775500	139.3588	-2.459746
4.827167	139.4019	-2.316358
4.880500	139.4406	-2.197471
4.930500	139.4730	-2.107532
4.983834	139.5019	-2.029133
5.035500	139.5262	-1.968918
5.087167	139.5484	-1.921439
5.140500	139.5675	-1.881382
5.190500	139.5852	-1.850401
5.243834	139.5996	-1.824471
5.295500	139.6132	-1.804496
5.347168	139.6249	-1.788626
5.398834	139.6347	-1.776563
5.450500	139.6444	-1.766994
5.503834	139.6533	-1.758790
5.553834	139.6607	-1.752583
5.607168	139.6682	-1.747352
5.658832	139.6741	-1.741930
5.710500	139.6798	-1.736582
5.763834	139.6848	-1.730942
5.813832	139.6888	-1.725577
5.867168	139.6942	-1.719793
5.917168	139.6976	-1.714258
5.970500	139.7009	-1.708364
6.022168	139.7047	-1.702681
6.073834	139.7068	-1.697000
6.127168	139.7104	-1.691166
6.177166	139.7120	-1.685747
6.230500	139.7145	-1.679999
6.282166	139.7167	-1.674497
6.333832	139.7192	-1.669044
6.387168	139.7212	-1.663430
6.437168	139.7220	-1.658258
6.490500	139.7242	-1.652856
6.540500	139.7247	-1.647801
6.593832	139.7272	-1.642521
6.645500	139.7289	-1.637480
6.697168	139.7313	-1.632485
6.750500	139.7316	-1.627425
6.800500	139.7328	-1.622692
6.853832	139.7336	-1.617663
6.905500	139.7351	-1.612866
6.957168	139.7352	-1.608075
7.010500	139.7376	-1.603222
7.060500	139.7376	-1.598694
7.113834	139.7390	-1.593893
7.163832	139.7398	-1.589413
7.217168	139.7395	-1.584717
7.268832	139.7406	-1.580167
7.320500	139.7420	-1.575626
7.373834	139.7438	-1.570935
7.423834	139.7436	-1.566495
7.477168	139.7443	-1.561780
7.528832	139.7451	-1.557250
7.580500	139.7446	-1.552703
7.633832	139.7466	-1.548065
7.683832	139.7465	-1.543685
7.737168	139.7469	-1.539007
7.787168	139.7486	-1.534682
7.840500	139.7488	-1.530012
7.892168	139.7494	-1.525486
7.943832	139.7492	-1.521024
7.997168	139.7505	-1.516400
8.047168	139.7513	-1.512149
8.100500	139.7518	-1.507537
8.152168	139.7528	-1.503094
8.203834	139.7522	-1.498639
8.255500	139.7532	-1.494202
8.307168	139.7537	-1.489737
8.360500	139.7540	-1.485085
8.410499	139.7558	-1.480798
8.463834	139.7547	-1.476116
8.515500	139.7555	-1.471639
8.567166	139.7558	-1.467099
8.620499	139.7571	-1.462388
8.670500	139.7569	-1.457977
8.723832	139.7574	-1.453251
8.775499	139.7575	-1.448609
8.827168	139.7586	-1.444023
8.878834	139.7588	-1.439393
8.930500	139.7586	-1.434739
8.983832	139.7588	-1.429927
9.033832	139.7601	-1.425398
9.087168	139.7606	-1.420555
9.138834	139.7610	-1.415779
9.190500	139.7615	-1.410995
9.243834	139.7623	-1.406051
9.293834	139.7623	-1.401356
9.347168	139.7634	-1.396345
9.398834	139.7633	-1.391436
9.450500	139.7634	-1.386486
9.502168	139.7646	-1.381567
9.553832	139.7646	-1.376544
9.607166	139.7646	-1.371373
9.657166	139.7662	-1.366498
9.710499	139.7664	-1.361264
9.762168	139.7668	-1.356156
9.813834	139.7676	-1.350987
9.867166	139.7670	-1.345580
9.917168	139.7677	-1.340546
9.970500	139.7691	-1.335160
10.02050	139.7694	-1.330014
10.07383	139.7702	-1.324525
10.12550	139.7706	-1.319210
10.17717	139.7712	-1.313814
10.23050	139.7711	-1.308163
10.28050	139.7725	-1.302814
10.33383	139.7722	-1.297106
10.38550	139.7734	-1.291430
10.43717	139.7745	-1.285753
10.49050	139.7746	-1.279802
10.54050	139.7745	-1.274144
10.59383	139.7757	-1.268072
10.64383	139.7746	-1.262284
10.69717	139.7772	-1.256061
10.74883	139.7765	-1.249941
10.80050	139.7775	-1.243754
10.85383	139.7781	-1.237322
10.90383	139.7780	-1.231170
10.95717	139.7792	-1.224598
11.00883	139.7796	-1.218118
11.06050	139.7797	-1.211631
11.11383	139.7801	-1.204879
11.16383	139.7814	-1.198503
11.21717	139.7822	-1.191566
11.26717	139.7825	-1.184945
11.32050	139.7830	-1.177838
11.37217	139.7836	-1.170880
11.42383	139.7844	-1.163838
11.47717	139.7851	-1.156470
11.52717	139.7858	-1.149505
11.58050	139.7862	-1.141991
11.63216	139.7872	-1.134670
11.68383	139.7876	-1.127276
11.73717	139.7889	-1.119626
11.78717	139.7902	-1.112362
11.84050	139.7898	-1.104470
11.89050	139.7906	-1.097035
11.94383	139.7916	-1.089001
11.99550	139.7923	-1.081074
12.04717	139.7918	-1.073058
12.10050	139.7925	-1.064732
12.15050	139.7934	-1.056827
12.20384	139.7947	-1.048221
12.25550	139.7952	-1.039779
12.30717	139.7951	-1.031217
12.35883	139.7964	-1.022615
12.41050	139.7972	-1.013874
12.46383	139.7976	-1.004695
12.51383	139.7990	-0.9960746
12.56716	139.7999	-0.9867697
12.61884	139.8006	-0.9776916
12.67050	139.7999	-0.9682788
12.72383	139.8014	-0.9587879
12.77383	139.8019	-0.9496551
12.82717	139.8036	-0.9398852
12.87883	139.8044	-0.9302837
12.93050	139.8054	-0.9205734
12.98216	139.8064	-0.9108544
13.03383	139.8059	-0.9004757
13.08717	139.8079	-0.8896140
13.13717	139.8086	-0.8791205
13.19050	139.8090	-0.8673009
13.24216	139.8104	-0.8547592
13.29384	139.8108	-0.8428522
13.34717	139.8123	-0.8308997
13.39717	139.8133	-0.8175544
13.45050	139.8137	-0.8010734
13.50050	139.8152	-0.7835582
13.55383	139.8161	-0.7641899
13.60550	139.8178	-0.7434550
13.65717	139.8198	-0.7208945
13.71050	139.8206	-0.6913575
13.76050	139.8219	-0.6586728
13.81383	139.8237	-0.6190766
13.86550	139.8258	-0.5753752
13.91716	139.8280	-0.5267920
13.97050	139.8310	-0.4729750
14.02050	139.8340	-0.4183858
14.07384	139.8362	-0.3555444
14.12384	139.8403	-0.2953248
14.17717	139.8436	-0.2306189
14.22884	139.8479	-0.1649328
14.28050	139.8514	-.09728710
14.33383	139.8561	-.02469599
14.38383	139.8598	0.04491667
14.43716	139.8666	0.1196516
14.48883	139.8705	0.1975646
14.54050	139.8753	0.2732638
14.59383	139.8801	0.3527222
14.64383	139.8858	0.4260904
14.69717	139.8903	0.5045925
14.74717	139.8960	0.5751366
14.80050	139.9013	0.6491687
14.85217	139.9056	0.7194586
14.90383	139.9102	0.7853750
14.95717	139.9140	0.8514778
15.00717	139.9186	0.9068997
15.06050	139.9225	0.9652845
15.11217	139.9265	1.016694
15.16383	139.9298	1.066325
15.21716	139.9334	1.112683
15.26717	139.9359	1.153251
15.32050	139.9396	1.191880
15.37050	139.9411	1.226530
15.42383	139.9444	1.258684
15.47550	139.9459	1.290670
15.52717	139.9492	1.318242
15.58050	139.9520	1.346389
15.63050	139.9535	1.371776
15.68383	139.9554	1.398426
15.73550	139.9573	1.422351
15.78717	139.9594	1.446608
15.83883	139.9616	1.468237
15.89050	139.9625	1.492787
15.94384	139.9644	1.516235
15.99383	139.9661	1.538546
16.04716	139.9682	1.563766
16.09883	139.9698	1.587557
16.15050	139.9711	1.612996
16.20383	139.9720	1.639801
16.25383	139.9741	1.664041
16.30716	139.9769	1.691021
16.35883	139.9777	1.717347
16.41050	139.9791	1.743713
16.46216	139.9818	1.769349
16.51383	139.9828	1.796273
16.56716	139.9853	1.826134
16.61716	139.9869	1.854569
16.67050	139.9896	1.884002
16.72216	139.9914	1.914688
16.77383	139.9931	1.946008
16.82716	139.9948	1.975284
16.87716	139.9962	2.004086
16.93050	139.9993	2.035775
16.98216	140.0009	2.066520
17.03383	140.0033	2.095906
17.08550	140.0054	2.125158
17.13716	140.0077	2.154058
17.19050	140.0100	2.184480
17.24050	140.0112	2.214468
17.29383	140.0138	2.245371
17.34550	140.0153	2.274521
17.39716	140.0176	2.304002
17.45050	140.0195	2.334623
17.50050	140.0217	2.364690
17.55383	140.0241	2.394786
17.60383	140.0257	2.423468
17.65716	140.0283	2.453545
17.70883	140.0303	2.483306
17.76050	140.0322	2.512744
17.81383	140.0344	2.543668
17.86383	140.0357	2.572248
17.91716	140.0378	2.604365
17.96883	140.0396	2.635088
18.02050	140.0414	2.665220
18.07383	140.0436	2.696667
18.12383	140.0468	2.727738
18.17716	140.0486	2.759787
18.22716	140.0504	2.788367
18.28050	140.0519	2.817300
18.33216	140.0546	2.848132
18.38383	140.0558	2.878980
18.43716	140.0584	2.908846
18.48716	140.0605	2.937309
18.54050	140.0626	2.967668
18.59216	140.0642	2.997170
18.64383	140.0660	3.024464
18.69716	140.0670	3.053216
18.74716	140.0702	3.078663
18.80050	140.0714	3.105672
18.85050	140.0731	3.131670
18.90383	140.0752	3.156461
18.95550	140.0778	3.178590
19.00716	140.0793	3.201865
19.06050	140.0794	3.222976
19.11050	140.0809	3.242275
19.16383	140.0829	3.261494
19.21550	140.0841	3.278345
19.26716	140.0849	3.294356
19.32050	140.0858	3.307758
19.37050	140.0872	3.319344
19.42383	140.0885	3.329015
19.47383	140.0885	3.337434
19.52716	140.0896	3.345050
19.57883	140.0901	3.352483
19.63050	140.0908	3.359800
19.68383	140.0907	3.367200
19.73383	140.0913	3.374008
19.78717	140.0925	3.381074
19.83883	140.0916	3.387612
19.89050	140.0924	3.393844
19.94216	140.0924	3.399798
19.99383	140.0929	3.405253
20.04716	140.0919	3.410471
20.09716	140.0922	3.414734
20.15050	140.0920	3.418721
20.20216	140.0916	3.422027
20.25383	140.0907	3.424714
20.30716	140.0902	3.426674
20.35716	140.0890	3.427681
20.41050	140.0879	3.427925
20.46216	140.0869	3.427331
20.51383	140.0872	3.425311
20.56550	140.0856	3.422986
20.61716	140.0853	3.419864
20.67050	140.0834	3.415482
20.72050	140.0821	3.410374
20.77383	140.0812	3.402172
20.82550	140.0801	3.395100
20.87716	140.0793	3.387464
20.93050	140.0771	3.375644
20.98050	140.0760	3.362906
21.03383	140.0747	3.347668
21.08383	140.0740	3.332712
21.13716	140.0721	3.316817
21.18883	140.0708	3.301215
21.24050	140.0696	3.285750
21.29383	140.0685	3.269732
21.34383	140.0672	3.254947
21.39716	140.0653	3.238037
21.44883	140.0652	3.221074
21.50050	140.0635	3.207218
21.55383	140.0624	3.191466
21.60383	140.0604	3.178086
21.65716	140.0604	3.161890
21.70717	140.0591	3.149458
21.76050	140.0584	3.136814
21.81216	140.0568	3.123795
21.86383	140.0556	3.110859
21.91716	140.0540	3.098054
21.96716	140.0536	3.085904
22.02050	140.0532	3.071546
22.07216	140.0522	3.058672
22.12383	140.0518	3.046396
22.17717	140.0511	3.035584
22.22716	140.0498	3.024776
22.28050	140.0485	3.014144
22.33050	140.0482	3.004211
22.38383	140.0464	2.993360
22.43550	140.0461	2.982857
22.48716	140.0461	2.972673
22.54050	140.0445	2.962328
22.59050	140.0439	2.952473
22.64383	140.0434	2.941897
22.69550	140.0430	2.931611
22.74716	140.0421	2.921408
22.80050	140.0411	2.910550
22.85050	140.0398	2.900592
22.90383	140.0392	2.889775
22.95383	140.0396	2.879772
23.00716	140.0385	2.868986
23.05883	140.0379	2.858562
23.11050	140.0370	2.848259
23.16383	140.0372	2.837845
23.21383	140.0360	2.828229
23.26716	140.0361	2.818049
23.31883	140.0353	2.808457
23.37050	140.0358	2.798965
23.42216	140.0341	2.789743
23.47383	140.0341	2.780636
23.52717	140.0329	2.771365
23.57716	140.0324	2.762774
23.63050	140.0325	2.753786
23.68216	140.0322	2.745146
23.73383	140.0314	2.736633
23.78717	140.0306	2.727814
23.83716	140.0300	2.719705
23.89050	140.0291	2.711128
23.94216	140.0294	2.702850
23.99383	140.0282	2.694686
24.04550	140.0285	2.686520
24.09716	140.0281	2.678432
24.15050	140.0275	2.670113
24.20050	140.0271	2.662334
24.25383	140.0271	2.654068
24.30550	140.0254	2.646059
24.35716	140.0248	2.637961
24.41050	140.0253	2.629547
24.46050	140.0248	2.621636
24.51383	140.0233	2.613043
24.56550	140.0228	2.604608
24.61716	140.0224	2.596092
24.66883	140.0211	2.587518
24.72050	140.0204	2.578752
24.77383	140.0198	2.569459
24.82383	140.0194	2.560630
24.87716	140.0177	2.551050
24.92883	140.0180	2.541533
24.98050	140.0158	2.531864
25.03383	140.0153	2.521654
25.08383	140.0146	2.510883
25.13716	140.0136	2.499120
25.18716	140.0127	2.487667
25.24050	140.0119	2.476261
25.29216	140.0112	2.464740
25.34383	140.0105	2.452592
25.39716	140.0099	2.438920
25.44716	140.0083	2.426482
25.50050	140.0075	2.412210
25.55217	140.0058	2.397382
25.60383	140.0064	2.382446
25.65716	140.0042	2.368750
25.70716	140.0042	2.354318
25.76050	140.0026	2.339819
25.81050	140.0010	2.325404
25.86383	140.0004	2.307934
25.91550	139.9997	2.292375
25.96716	139.9979	2.277737
26.02050	139.9965	2.261129
26.07050	139.9965	2.246494
26.12383	139.9940	2.232056
26.17550	139.9931	2.215982
26.22717	139.9917	2.200125
26.28050	139.9912	2.183081
26.33050	139.9898	2.166142
26.38383	139.9898	2.147066
26.43383	139.9888	2.131637
26.48716	139.9879	2.116100
26.53883	139.9869	2.098390
26.59050	139.9855	2.082561
26.64383	139.9846	2.067541
26.69383	139.9832	2.052437
26.74716	139.9826	2.036434
26.79883	139.9814	2.020321
26.85050	139.9804	2.003504
26.90383	139.9791	1.986402
26.95383	139.9777	1.970514
27.00716	139.9775	1.956815
27.05716	139.9765	1.942627
27.11050	139.9750	1.925762
27.16217	139.9739	1.909173
27.21383	139.9730	1.893312
27.26716	139.9718	1.875053
27.31716	139.9714	1.860057
27.37050	139.9691	1.844618
27.42216	139.9689	1.829080
27.47383	139.9681	1.814248
27.52550	139.9659	1.799605
27.57717	139.9654	1.783073
27.63050	139.9640	1.767418
27.68050	139.9631	1.752608
27.73383	139.9616	1.737359
27.78550	139.9610	1.722083
27.83716	139.9598	1.708293
27.89050	139.9587	1.694459
27.94050	139.9578	1.680245
27.99383	139.9570	1.665675
28.04550	139.9561	1.651776
28.09716	139.9552	1.636177
28.14883	139.9540	1.622539
28.20050	139.9530	1.608744
28.25383	139.9526	1.594578
28.30383	139.9507	1.581028
28.35716	139.9508	1.566269
28.40883	139.9492	1.551737
28.46050	139.9488	1.537413
28.51383	139.9477	1.523706
28.56383	139.9478	1.510066
28.61716	139.9462	1.497562
28.66716	139.9447	1.483988
28.72050	139.9444	1.470470
28.77216	139.9439	1.457405
28.82383	139.9433	1.444996
28.87716	139.9424	1.432655
28.92717	139.9424	1.419860
28.98050	139.9406	1.408114
29.03216	139.9392	1.396681
29.08383	139.9379	1.385499
29.13716	139.9382	1.373436
29.18717	139.9366	1.362480
29.24050	139.9356	1.350133
29.29050	139.9343	1.338963
29.34383	139.9337	1.326383
29.39550	139.9321	1.314605
29.44717	139.9311	1.302727
29.50050	139.9312	1.290889
29.55050	139.9302	1.279559
29.60383	139.9294	1.267602
29.65550	139.9278	1.256061
29.70716	139.9277	1.243039
29.76050	139.9272	1.230957
29.81050	139.9254	1.218571
29.86383	139.9257	1.205881
29.91383	139.9247	1.194490
29.96716	139.9240	1.182409
30.01883	139.9229	1.170533
30.07050	139.9226	1.158965
30.12383	139.9220	1.146790
30.17383	139.9210	1.135929
30.22717	139.9200	1.124042
30.27883	139.9204	1.112792
30.33050	139.9181	1.101596
30.38383	139.9179	1.089988
30.43383	139.9180	1.078740
30.48716	139.9174	1.067004
30.53717	139.9163	1.056118
30.59050	139.9158	1.044701
30.64216	139.9148	1.033575
30.69383	139.9136	1.022482
30.74716	139.9134	1.010566
30.79716	139.9121	0.9999359
30.85050	139.9126	0.9885688
30.90216	139.9117	0.9775793
30.95383	139.9110	0.9666144
31.00550	139.9100	0.9557008
31.05716	139.9089	0.9449141
31.11050	139.9083	0.9339078
31.16050	139.9075	0.9235232
31.21383	139.9068	0.9124454
31.26550	139.9058	0.9017975
31.31716	139.9052	0.8911774
31.37050	139.9050	0.8801801
31.42050	139.9045	0.8699637
31.47383	139.9032	0.8591026
31.52550	139.9025	0.8486413
31.57717	139.9014	0.8382074
31.62883	139.9004	0.8278778
31.68050	139.8994	0.8175676
31.73383	139.8991	0.8069360
31.78383	139.8982	0.7969944
31.83716	139.8976	0.7864224
31.88883	139.8973	0.7761754
31.94050	139.8959	0.7658081
31.99383	139.8959	0.7551440
32.04383	139.8946	0.7452944
32.09716	139.8949	0.7347670
32.14883	139.8934	0.7246610
32.20050	139.8928	0.7144730
32.25217	139.8932	0.7042960
32.30383	139.8924	0.6941440
32.35716	139.8914	0.6836980
32.40716	139.8912	0.6740094
32.46050	139.8898	0.6637081
32.51216	139.8902	0.6537676
32.56383	139.8894	0.6438150
32.61716	139.8886	0.6336582
32.66716	139.8879	0.6241684
32.72050	139.8876	0.6140656
32.77050	139.8864	0.6047151
32.82383	139.8861	0.5946760
32.87550	139.8860	0.5849842
32.92717	139.8842	0.5753258
32.98050	139.8834	0.5654259
33.03050	139.8839	0.5561335
33.08383	139.8824	0.5462734
33.13550	139.8817	0.5367868
33.18716	139.8811	0.5272533
33.24050	139.8796	0.5175184
33.29050	139.8807	0.5082821
33.34384	139.8799	0.4983672
33.39383	139.8798	0.4890822
33.44717	139.8786	0.4792510
33.49883	139.8780	0.4696850
33.55050	139.8779	0.4601940
33.60383	139.8768	0.4504318
33.65383	139.8769	0.4412961
33.70716	139.8764	0.4316531
33.75883	139.8747	0.4223320
33.81050	139.8745	0.4130280
33.86383	139.8736	0.4033721
33.91383	139.8736	0.3942810
33.96716	139.8726	0.3845954
34.01716	139.8722	0.3754638
34.07050	139.8714	0.3657953
34.12216	139.8709	0.3564609
34.17383	139.8700	0.3471740
34.22717	139.8696	0.3375648
34.27716	139.8690	0.3286191
34.33050	139.8672	0.3191309
34.38216	139.8671	0.3097975
34.43384	139.8667	0.3004494
34.48717	139.8661	0.2907387
34.53717	139.8656	0.2816023
34.59050	139.8645	0.2719086
34.64050	139.8646	0.2628051
34.69383	139.8634	0.2531143
34.74550	139.8629	0.2437560
34.79716	139.8620	0.2344280
34.85050	139.8609	0.2247715
34.90050	139.8606	0.2157202
34.95383	139.8600	0.2060034
35.00550	139.8586	0.1965408
35.05716	139.8590	0.1869948
35.10883	139.8579	0.1773971
35.16050	139.8576	0.1677689
35.21383	139.8568	0.1577389
35.26383	139.8555	0.1483229
35.31716	139.8550	0.1383286
35.36883	139.8545	0.1286039
35.42050	139.8535	0.1188798
35.47383	139.8526	0.1087807
35.52383	139.8516	0.09932285
35.57717	139.8512	0.08909820
35.62883	139.8509	0.07917632
35.68050	139.8491	0.06920466
35.73216	139.8495	0.05883978
35.78383	139.8486	0.04873644
35.83716	139.8486	0.03817932
35.88716	139.8478	0.02810204
35.94050	139.8466	0.01726353
35.99216	139.8464	.006439441
36.04383	139.8460	-4.1999E-3
36.09716	139.8451	-.01493766
36.14717	139.8444	-.02540057
36.20050	139.8438	-.03639428
36.25050	139.8420	-.04710066
36.30383	139.8415	-.05798690
36.35550	139.8403	-.06889554
36.40716	139.8397	-.07955524
36.46050	139.8387	-.09141387
36.51050	139.8385	-0.1029029
36.56383	139.8372	-0.1147006
36.61550	139.8365	-0.1264614
36.66716	139.8356	-0.1380159
36.72050	139.8342	-0.1498144
36.77050	139.8344	-0.1611758
36.82383	139.8331	-0.1724838
36.87383	139.8325	-0.1839868
36.92717	139.8318	-0.1970534
36.97883	139.8300	-0.2088917
37.03050	139.8296	-0.2211895
37.08383	139.8290	-0.2335173
37.13383	139.8275	-0.2457764
37.18716	139.8276	-0.2578050
37.23883	139.8277	-0.2701830
37.29050	139.8258	-0.2819974
37.34384	139.8246	-0.2946900
37.39383	139.8242	-0.3065215
37.44717	139.8231	-0.3187376
37.49716	139.8220	-0.3307894
37.55050	139.8212	-0.3433498
37.60217	139.8201	-0.3553902
37.65383	139.8186	-0.3669498
37.70716	139.8184	-0.3794874
37.75716	139.8180	-0.3907849
37.81050	139.8156	-0.4026283
37.86217	139.8146	-0.4145479
37.91383	139.8142	-0.4275896
37.96716	139.8141	-0.4414859
38.01716	139.8124	-0.4544790
38.07050	139.8121	-0.4676818
38.12050	139.8120	-0.4794521
38.17383	139.8108	-0.4914250
38.22550	139.8100	-0.5037396
38.27716	139.8088	-0.5154572
38.33050	139.8084	-0.5275828
38.38050	139.8075	-0.5386382
38.43384	139.8064	-0.5508804
38.48550	139.8057	-0.5622551
38.53717	139.8052	-0.5735688
38.58883	139.8038	-0.5851085
38.64050	139.8032	-0.5965244
38.69383	139.8023	-0.6082785
38.74383	139.8011	-0.6193945
38.79716	139.8016	-0.6321863
38.84883	139.8003	-0.6437018
38.90050	139.7991	-0.6550736
38.95383	139.7993	-0.6668460
39.00383	139.7989	-0.6777720
39.05716	139.7982	-0.6894219
39.10883	139.7972	-0.7005842
39.16050	139.7969	-0.7117114
39.21216	139.7967	-0.7227461
39.26383	139.7956	-0.7337295
39.31716	139.7952	-0.7449186
39.36716	139.7948	-0.7554876
39.42050	139.7940	-0.7666389
39.47217	139.7936	-0.7773418
39.52383	139.7932	-0.7879540
39.57717	139.7919	-0.7988626
39.62717	139.7911	-0.8089981
39.68050	139.7906	-0.8198325
39.73216	139.7899	-0.8301750
39.78383	139.7889	-0.8404266
39.83550	139.7885	-0.8505481
39.88716	139.7873	-0.8605836
39.94050	139.7862	-0.8709676
39.99050	139.7866	-0.8803789
40.04383	139.7862	-0.8901947
40.09550	139.7851	-0.8995126
40.14717	139.7849	-0.9089095
40.20050	139.7848	-0.9186059
40.25050	139.7832	-0.9276715
40.30383	139.7830	-0.9372601
40.35383	139.7824	-0.9462918
40.40716	139.7810	-0.9559475
40.45883	139.7812	-0.9653109
40.51050	139.7812	-0.9746270
40.56383	139.7806	-0.9841816
40.61383	139.7801	-0.9931122
40.66716	139.7793	-1.002539
40.71884	139.7787	-1.011563
40.77050	139.7784	-1.020548
40.82383	139.7780	-1.029727
40.87383	139.7762	-1.038224
40.92717	139.7770	-1.047279
40.97717	139.7761	-1.055651
41.03050	139.7758	-1.064527
41.08217	139.7755	-1.073009
41.13383	139.7754	-1.081528
41.18716	139.7740	-1.090235
41.23717	139.7743	-1.098306
41.29050	139.7734	-1.106726
41.34217	139.7725	-1.114776
41.39383	139.7722	-1.122747
41.44717	139.7715	-1.130866
41.49716	139.7705	-1.138466
41.55050	139.7709	-1.146589
41.60050	139.7697	-1.154171
41.65383	139.7706	-1.162264
41.70550	139.7698	-1.169933
41.75717	139.7686	-1.177496
41.81050	139.7682	-1.185321
41.86050	139.7677	-1.192589
41.91383	139.7677	-1.200244
41.96550	139.7671	-1.207612
42.01717	139.7672	-1.214960
42.07050	139.7678	-1.222480
42.12050	139.7661	-1.229415
42.17383	139.7660	-1.236871
42.22383	139.7658	-1.243780
42.27716	139.7653	-1.251138
42.32883	139.7642	-1.258096
42.38050	139.7648	-1.265001
42.43383	139.7636	-1.272057
42.48383	139.7637	-1.278664
42.53717	139.7629	-1.285644
42.58883	139.7625	-1.292356
42.64050	139.7621	-1.298976
42.69217	139.7611	-1.305519
42.74383	139.7610	-1.312038
42.79716	139.7610	-1.318652
42.84716	139.7599	-1.324752
42.90050	139.7596	-1.331156
42.95216	139.7589	-1.337297
43.00050	139.7587	-1.342962
43.05383	139.7936	-1.995744
43.10550	140.0953	-4.842122
43.15717	140.6067	-7.710150
43.21050	141.2717	-10.31330
43.26050	141.9884	-12.25079
43.31383	142.8250	-13.86100
43.36550	143.6875	-15.04884
43.41716	144.5858	-15.96201
43.47050	145.5444	-16.67002
43.52050	146.4646	-17.20120
43.57383	147.4607	-17.63446
43.62383	148.4092	-17.96795
43.67717	149.4297	-18.24262
43.72883	150.4252	-18.46318
43.78050	151.4269	-18.65394
43.83383	152.4654	-18.82301
43.88383	153.4416	-18.95099
43.93716	154.4874	-19.09920
43.98883	155.5016	-19.23082
44.04050	156.5167	-19.36792
44.09384	157.5678	-19.49176
44.14383	158.5527	-19.60227
44.19717	159.6038	-19.72922
44.24716	160.5916	-19.86070
44.30050	161.6458	-19.97938
44.35217	162.6676	-20.10690
44.40383	163.6906	-20.24123
44.45717	164.7466	-20.36258
44.50717	165.7366	-20.49518
44.56050	166.7933	-20.63685
44.61217	167.8162	-20.76963
44.66383	168.8394	-20.91234
44.71717	169.8950	-21.05803
44.76717	170.8843	-21.19960
44.82050	171.9409	-21.37162
44.87050	172.9310	-21.51169
44.92383	173.9880	-21.67961
44.97550	175.0111	-21.81384
45.02716	176.0354	-21.96016
45.08050	177.0906	-22.17173
45.13050	178.0790	-22.36254
45.18383	179.1335	-22.56870
45.23550	180.1551	-22.77691
45.28717	181.1756	-23.00366
45.33883	182.1944	-23.23794
45.39050	183.2138	-23.49000
45.44383	184.2646	-23.77047
45.49383	185.2496	-24.02129
45.54716	186.2989	-24.31845
45.59883	187.3144	-24.63901
45.65050	188.3289	-24.94808
45.70383	189.3771	-25.28708
45.75383	190.3578	-25.59735
45.80717	191.4053	-25.94133
45.85883	192.4184	-26.26969
45.91050	193.4316	-26.61237
45.96216	194.4466	-26.92013
46.01383	195.4607	-27.26060
46.06717	196.5014	-27.74850
46.11716	197.4810	-28.15189
46.17050	198.5231	-28.56900
46.22217	199.5314	-29.04160
46.27383	200.5369	-29.55594
46.32717	201.5727	-30.12928
46.37717	202.5416	-30.74954
46.43050	203.5682	-31.48401
46.48217	204.5603	-32.29714
46.53383	205.5455	-33.22310
46.58550	206.5250	-34.28200
46.63716	207.4943	-35.54105
46.69050	208.4837	-37.09088
46.74050	209.3981	-38.80786
46.79383	210.3563	-41.00812
46.84550	211.2656	-43.49791
46.89717	212.1523	-46.45478
46.95050	213.0419	-49.95138
47.00050	213.8532	-53.58759
47.05383	214.6969	-57.72771
47.10383	215.4764	-61.55138
47.15717	216.3127	-65.05090
47.20883	217.1584	-67.15806
47.26050	218.0510	-68.80171
47.31383	219.0102	-69.59274
47.36383	219.9834	-68.07551
47.41716	221.1310	-64.47460
47.46884	222.3452	-59.45891
47.52050	223.6574	-52.75635
47.57383	225.1150	-44.29477
47.62383	226.5144	-38.37290
47.67717	227.9296	-34.51218
47.72717	229.1768	-31.97452
47.78050	230.4374	-30.05210
47.83217	231.6087	-28.64290
47.88383	232.7433	-27.64008
47.93716	233.8860	-26.92015
47.98717	234.9380	-26.38710
48.04050	236.0457	-25.97346
48.09217	237.1085	-25.70870
48.14383	238.1639	-25.50815
48.19717	239.2466	-25.36877
48.24716	240.2578	-25.28242
48.30050	241.3320	-25.22702
48.35050	242.3386	-25.19667
48.40383	243.4094	-25.18477
48.45550	244.4454	-25.17706
48.50717	245.4802	-25.17498
48.56050	246.5492	-25.17442
48.61050	247.5490	-25.17485
48.66383	248.6141	-25.17608
48.71550	249.6486	-25.17916
48.76717	250.6812	-25.19082
48.82050	251.7470	-25.20869
48.87050	252.7463	-25.23627
48.92383	253.8108	-25.25872
48.97383	254.8095	-25.29562
49.02716	255.8755	-25.33818
49.07883	256.9074	-25.38670
49.13050	257.9387	-25.43367
49.18383	259.0029	-25.49031
49.23383	260.0015	-25.54057
49.28717	261.0654	-25.58413
49.33883	262.0967	-25.64193
49.39050	263.1284	-25.68540
49.44217	264.1596	-25.72915
49.49383	265.1919	-25.77210
49.54716	266.2559	-25.81347
49.59716	267.2553	-25.84739
49.65050	268.3201	-25.89416
49.70216	269.3509	-25.93915
49.75383	270.3820	-25.98356
49.80717	271.4470	-26.02420
49.85717	272.4457	-26.06348
49.91050	273.5116	-26.10508
49.96216	274.5424	-26.12776
50.01050	275.5066	-26.16977
50.06050	276.3760	-26.91912
50.11383	276.6869	-21.38838
50.16550	276.6072	-13.64332
50.21717	276.2768	-6.730824
50.27050	275.7528	-1.060609
50.32050	275.1416	3.011104
50.37383	274.3930	6.291967
50.42550	273.5980	8.669376
50.47717	272.7512	10.45301
50.53050	271.8377	11.82364
50.58050	270.9528	12.79356
50.63383	269.9862	13.56832
50.68383	269.0628	14.12724
50.73717	268.0651	14.57771
50.78883	267.0860	14.91311
50.84050	266.1010	15.17783
50.89383	265.0758	15.37980
50.94383	264.1096	15.53289
50.99716	263.0747	15.66939
51.04883	262.0703	15.77253
51.10050	261.0613	15.85469
51.15383	260.0178	15.92390
51.20383	259.0375	15.98137
51.25717	257.9910	16.02898
51.30717	257.0073	16.06769
51.36050	255.9568	16.10392
51.41216	254.9390	16.13585
51.46383	253.9207	16.16576
51.51716	252.8675	16.20064
51.56716	251.8806	16.22455
51.62050	250.8264	16.24765
51.67217	249.8048	16.26707
51.72383	248.7828	16.28906
51.77550	247.7587	16.30759
51.82717	246.7349	16.32220
51.88050	245.6792	16.33187
51.93050	244.6868	16.34185
51.98383	243.6294	16.34975
52.03550	242.6051	16.35648
52.08716	241.5810	16.36235
52.14050	240.5234	16.37065
52.19050	239.5314	16.37969
52.24383	238.4731	16.38942
52.29550	237.4484	16.40171
52.34716	236.4225	16.41230
52.39883	235.3970	16.42149
52.45050	234.3714	16.42902
52.50383	233.3126	16.43662
52.55383	232.3190	16.44374
52.60717	231.2598	16.45141
52.65883	230.2341	16.45893
52.71050	229.2074	16.46678
52.76382	228.1485	16.47567
52.81382	227.1550	16.48538
52.86716	226.0964	16.49389
52.91716	225.1039	16.50664
52.97050	224.0435	16.51772
53.02217	223.0171	16.52682
53.07383	221.9898	16.53623
53.12717	220.9304	16.54488
53.17717	219.9362	16.55358
53.23050	218.8771	16.56321
53.28217	217.8496	16.57237
53.33383	216.8242	16.58052
53.38716	215.7635	16.58988
53.43716	214.7710	16.59781
53.49050	213.7103	16.60659
53.54050	212.7164	16.61459
53.59384	211.6564	16.62295
53.64550	210.6278	16.63111
53.69717	209.6002	16.63892
53.75050	208.5378	16.64666
53.80050	207.5442	16.65346
53.85383	206.4817	16.66021
53.90550	205.4541	16.66611
53.95717	204.4266	16.67193
54.01050	203.3661	16.67747
54.06050	202.3717	16.68241
54.11382	201.3120	16.68764
54.16382	200.3178	16.69259
54.21717	199.2567	16.69778
54.26884	198.2295	16.70293
54.32050	197.2011	16.70784
54.37383	196.1397	16.71284
54.42383	195.1455	16.71755
54.47717	194.0857	16.72266
54.52883	193.0576	16.72777
54.58050	192.0305	16.73266
54.63383	190.9686	16.73781
54.68383	189.9739	16.74213
54.73717	188.9133	16.74690
54.78716	187.9196	16.75116
54.84050	186.8581	16.75559
54.89216	185.8288	16.75992
54.94384	184.8012	16.76396
54.99717	183.7395	16.76799
55.04717	182.7430	16.77146
55.10050	181.6817	16.77470
55.15217	180.6537	16.77802
55.20383	179.6246	16.78111
55.25550	178.5972	16.78412
55.30717	177.5695	16.78759
55.36050	176.5092	16.79166
55.41050	175.5145	16.79884
55.46382	174.4549	16.81749
55.51550	173.4284	16.87820
55.56716	172.4043	17.04682
55.62050	171.3521	17.32576
55.67050	170.3716	17.69131
55.72382	169.3346	18.25548
55.77550	168.3415	19.00692
55.82717	167.3618	20.00204
55.87883	166.3974	21.29250
55.93050	165.4522	22.91446
55.98383	164.4981	24.95316
56.03383	163.6253	27.22081
56.08716	162.7190	30.00922
56.13882	161.8616	32.94567
56.19050	161.0192	35.90341
56.24382	160.1486	38.65844
56.29382	159.3159	40.72236
56.34716	158.3972	42.21338
56.39883	157.4652	42.87460
56.45050	156.4862	42.74270
56.50217	155.4587	41.86734
56.55383	154.3846	40.34424
56.60717	153.2339	38.29742
56.65717	152.1258	36.08853
56.71050	150.9217	33.62415
56.76216	149.7432	31.23612
56.81382	148.5648	29.02654
56.86716	147.3579	27.02625
56.91716	146.2375	25.42320
56.97050	145.0619	23.98536
57.02050	143.9749	22.89332
57.07383	142.8320	21.94642
57.12550	141.7381	21.21004
57.17717	140.6572	20.59326
57.23050	139.5510	20.10036
57.28050	138.5220	19.71371
57.33383	137.4300	19.36045
57.38550	136.3779	19.08854
57.43716	135.3290	18.85066
57.49050	134.2501	18.65530
57.54050	133.2413	18.48334
57.59384	132.1675	18.33656
57.64384	131.1612	18.20693
57.69717	130.0900	18.09061
57.74883	129.0531	17.99213
57.80050	128.0161	17.89202
57.85383	126.9478	17.79084
57.90383	125.9450	17.70967
57.95717	124.8761	17.60382
58.00883	123.8420	17.52236
58.06050	122.8075	17.44500
58.11382	121.7406	17.36641
58.16382	120.7408	17.28990
58.21717	119.6702	17.04347
58.26716	118.6695	17.08028
58.32050	117.6035	17.06266
58.37217	116.5718	17.02870
58.42383	115.5399	16.97647
58.47717	114.4742	16.92725
58.52717	113.4758	16.88339
58.58050	112.4096	16.83297
58.63217	111.3768	16.77754
58.68383	110.3434	16.71825
58.73717	109.2780	16.65938
58.78716	108.2787	16.60048
58.84050	107.2120	16.54218
58.89050	106.2124	16.48125
58.94384	105.1464	16.40951
58.99550	104.1128	16.32151
59.04717	103.0775	16.23513
59.10050	102.0111	16.15548
59.15050	101.0101	16.08491
59.20383	99.94319	16.01950
59.25550	98.90945	15.95849
59.30717	97.87551	15.90512
59.35883	96.84194	15.85043
59.41050	95.80931	15.78894
59.46382	94.74316	15.72751
59.51382	93.74251	15.67333
59.56716	92.67566	15.61132
59.61882	91.64336	15.55159
59.67050	90.60974	15.49480
59.72382	89.54474	15.43227
59.77383	88.54481	15.38196
59.82717	87.47746	15.32305
59.87883	86.44462	15.26596
59.93050	85.41112	15.20588
59.98217	84.37866	15.15087
60.03383	83.34555	15.10363
60.08716	82.28032	15.04951
60.13716	81.28042	14.99978
60.19050	80.21386	14.94463
60.24216	79.18004	14.88900
60.29382	78.14637	14.83407
60.34716	77.08136	14.77825
60.39717	76.08284	14.73085
60.45050	75.01559	14.68390
60.50050	74.01614	14.63583
60.55383	72.94981	14.59379
60.60550	71.91674	14.54175
60.65717	70.88420	14.48802
60.71050	69.81830	14.43246
60.76050	68.81721	14.38124
60.81382	67.75056	14.31892
60.86550	66.71831	14.26078
60.91716	65.68518	14.21420
60.97050	64.61884	14.16142
61.02050	63.61769	14.10728
61.07383	62.55141	14.04309
61.12383	61.55166	13.98569
61.17717	60.48469	13.92628
61.22883	59.45095	13.87459
61.28050	58.41860	13.81176
61.33383	57.35093	13.75691
61.38383	56.35166	13.70461
61.43716	55.28505	13.65128
61.48882	54.25090	13.60062
61.54050	53.21740	13.53956
61.59384	52.14883	13.48025
61.64384	51.14980	13.42170
61.69717	50.08218	13.36517
61.74717	49.08070	13.30972
61.80050	48.01368	13.25242
61.85217	46.98110	13.20260
61.90383	45.94810	13.14889
61.95717	44.88220	13.09834
62.00717	43.88144	13.05010
62.06050	42.81556	12.99134
62.11217	41.78161	12.93263
62.16382	40.74818	12.87866
62.21717	39.68131	12.81871
62.26716	38.67978	12.75792
62.32050	37.61218	12.68176
62.37050	36.61146	12.61396
62.42383	35.54238	12.54469
62.47550	34.50720	12.47483
62.52717	33.47138	12.39830
62.58050	32.40253	12.32831
62.63050	31.40086	12.24769
62.68383	30.33234	12.18662
62.73550	29.29691	12.11244
62.78716	28.26161	12.02775
62.83882	27.22543	11.95355
62.89050	26.18900	11.87332
62.94384	25.12006	11.80336
62.99382	24.11626	11.80799
63.04550	23.12035	11.98326
63.09716	22.61802	9.638264
63.15050	22.58120	4.954384
63.20050	22.81438	1.165972
63.25383	23.27650	-1.969239
63.30550	23.87379	-4.271957
63.35717	24.57757	-6.002168
63.41050	25.38678	-7.346506
63.46050	26.20180	-8.289606
63.51382	27.11524	-9.072312
63.56550	28.03060	-9.653769
63.61716	28.97184	-10.10677
63.66882	29.92806	-10.44970
63.72050	30.89832	-10.73526
63.77383	31.91010	-10.97031
63.82383	32.86698	-11.15435
63.87716	33.89380	-11.30762
63.92883	34.89292	-11.44263
63.98050	35.89738	-11.55500
64.03384	36.93611	-11.66282
64.08384	37.91313	-11.75007
64.13717	38.95898	-11.83741
64.18717	39.93963	-11.90632
64.24050	40.98795	-11.98071
64.29218	42.00445	-12.05044
64.34384	43.02298	-12.11379
64.39717	44.07551	-12.18320
64.44717	45.06324	-12.24434
64.50050	46.11636	-12.30764
64.55218	47.13744	-12.37285
64.60383	48.16084	-12.44676
64.65718	49.21750	-12.50481
64.70717	50.20834	-12.57263
64.76050	51.26548	-12.63784
64.81050	52.25800	-12.69871
64.86384	53.31623	-12.76308
64.91550	54.34092	-12.82687
64.96717	55.36682	-12.89589
65.02050	56.42638	-12.95809
65.07050	57.41891	-13.02925
65.12383	58.47999	-13.09572
65.17550	59.50652	-13.16258
65.22718	60.53418	-13.22454
65.28050	61.59465	-13.30426
65.33050	62.58880	-13.36909
65.38384	63.64882	-13.44280
65.43384	64.64385	-13.50906
65.48717	65.70710	-13.57257
65.53882	66.73352	-13.64760
65.59050	67.76010	-13.71909
65.64384	68.82149	-13.79771
65.69384	69.81645	-13.86848
65.74718	70.87884	-13.93681
65.79884	71.90701	-14.01163
65.85050	72.93540	-14.08785
65.90384	73.99740	-14.16013
65.95384	74.99197	-14.22645
66.00718	76.05336	-14.30809
66.05718	77.04993	-14.38405
66.11050	78.11074	-14.45915
66.16218	79.13858	-14.54005
66.21384	80.16840	-14.61846
66.26716	81.22900	-14.69652
66.31718	82.22570	-14.77071
66.37050	83.28800	-14.84861
66.42218	84.31782	-14.92410
66.47384	85.34618	-14.99587
66.52550	86.37704	-15.08040
66.57718	87.40678	-15.15897
66.63050	88.46856	-15.24042
66.68050	89.46352	-15.32571
66.73384	90.52597	-15.40811
66.78550	91.55535	-15.49362
66.83716	92.58465	-15.57329
66.89050	93.64645	-15.65527
66.94050	94.64149	-15.73815
66.99384	95.70374	-15.82716
67.04550	96.73225	-15.91116
67.09718	97.76047	-15.98666
67.14884	98.78819	-16.08411
67.20050	99.81625	-16.17025
67.25384	100.8783	-16.25463
67.30384	101.8752	-16.34367
67.35718	102.9378	-16.42761
67.40884	103.9658	-16.50910
67.46050	104.9962	-16.60149
67.51384	106.0569	-16.68858
67.56384	107.0534	-16.78112
67.61718	108.1148	-16.87466
67.66718	109.1107	-16.96241
67.72050	110.1726	-17.04976
67.77218	111.2021	-17.14282
67.82384	112.2310	-17.27209
67.87718	113.2920	-17.35374
67.92718	114.2866	-17.44097
67.98050	115.3481	-17.54179
68.03218	116.3766	-17.62550
68.08384	117.4071	-17.65082
68.13718	118.4713	-17.67741
68.18718	119.4695	-17.71386
68.24050	120.5331	-17.76943
68.29050	121.5309	-17.83717
68.34384	122.5943	-17.90599
68.39550	123.6254	-17.96250
68.44718	124.6568	-18.02214
68.50050	125.7206	-18.07750
68.55050	126.7186	-18.09220
68.60384	127.7851	-18.10328
68.65550	128.8167	-18.13733
68.70718	129.8481	-18.18996
68.76050	130.9120	-18.27929
68.81050	131.9096	-18.35604
68.86384	132.9726	-18.43220
68.91382	133.9692	-18.52314
68.96718	135.0311	-18.61392
69.01882	136.0605	-18.69745
69.07050	137.0899	-18.78631
69.12384	138.1517	-18.88252
69.17384	139.1477	-18.97774
69.22718	140.2098	-19.07777
69.27884	141.2380	-19.17318
69.33050	142.2655	-19.27871
69.38384	143.3275	-19.39188
69.43384	144.3214	-19.49922
69.48718	145.3808	-19.62702
69.53718	146.3763	-19.74164
69.59050	147.4364	-19.85205
69.64216	148.4621	-19.98515
69.69384	149.4896	-20.10054
69.74718	150.5502	-20.21552
69.79718	151.5435	-20.33006
69.85050	152.6038	-20.45492
69.90218	153.6315	-20.57440
69.95384	154.6584	-20.68940
70.00550	155.6852	-20.81065
70.05718	156.7128	-20.92722
70.11050	157.7727	-21.04037
70.16050	158.7677	-21.14129
70.21384	159.8281	-21.24170
70.26550	160.8582	-21.33638
70.31718	161.8855	-21.40913
70.37050	162.9505	-21.47364
70.42050	163.9484	-21.52665
70.47384	165.0136	-21.56598
70.52550	166.0456	-21.58943
70.57718	167.0784	-21.61136
70.62884	168.1102	-21.63058
70.68050	169.1435	-21.65455
70.73384	170.2074	-21.69048
70.78384	171.2060	-21.75836
70.83716	172.2699	-21.85411
70.88884	173.3006	-21.94416
70.94050	174.3294	-22.03499
70.99384	175.3916	-22.14832
71.04384	176.3866	-22.25756
71.09718	177.4466	-22.40308
71.14884	178.4729	-22.55131
71.20050	179.4976	-22.71712
71.25218	180.5211	-22.90690
71.30384	181.5448	-23.11479
71.35718	182.5995	-23.35042
71.40718	183.5867	-23.60832
71.46050	184.6393	-23.90222
71.51218	185.6559	-24.22572
71.56384	186.6705	-24.58409
71.61718	187.7154	-24.99530
71.66718	188.6931	-25.42598
71.72050	189.7341	-25.92983
71.77050	190.7075	-26.43312
71.82384	191.7419	-27.02092
71.87550	192.7421	-27.61604
71.92718	193.7411	-28.23135
71.98050	194.7688	-28.88887
72.03050	195.7318	-29.53390
72.08384	196.7586	-30.25689
72.13550	197.7501	-30.99635
72.18718	198.7408	-31.78778
72.24050	199.7573	-32.70320
72.29050	200.7067	-33.64512
72.34384	201.7151	-34.72381
72.39384	202.6557	-35.80346
72.44718	203.6553	-36.97936
72.49884	204.6229	-38.11618
72.55050	205.5909	-39.15545
72.60384	206.5963	-39.98904
72.65384	207.5533	-40.36242
72.70718	208.6014	-40.03162
72.75884	209.6658	-38.25164
72.81050	210.7944	-35.29906
72.86384	212.0246	-31.55200
72.91382	213.2024	-28.68673
72.96718	214.4352	-26.71131
73.01716	215.5569	-25.43313
73.07050	216.7212	-24.44044
73.12218	217.8247	-23.74730
73.17384	218.9105	-23.23096
73.22718	220.0159	-22.84972
73.27718	221.0436	-22.58610
73.33050	222.1319	-22.39296
73.38218	223.1804	-22.25209
73.43384	224.2256	-22.18190
73.48718	225.2997	-22.10458
73.53718	226.3051	-22.08104
73.59050	227.3767	-22.06451
73.64050	228.3785	-22.05715
73.69384	229.4463	-22.05626
73.74550	230.4810	-22.05664
73.79718	231.5140	-22.05893
73.85050	232.5804	-22.06884
73.90050	233.5797	-22.09004
73.95384	234.6454	-22.11644
74.00550	235.6774	-22.15211
74.05718	236.7105	-22.18330
74.10884	237.7422	-22.22217
74.16050	238.7738	-22.25338
74.21384	239.8387	-22.30338
74.26384	240.8366	-22.34442
74.31718	241.9026	-22.40406
74.36884	242.9334	-22.44966
74.42050	243.9660	-22.49982
74.47384	245.0302	-22.53748
74.52384	246.0301	-22.57824
74.57718	247.0944	-22.61384
74.62884	248.1260	-22.64636
74.68050	249.1574	-22.68226
74.73218	250.1897	-22.71826
74.78384	251.2207	-22.76267
74.83716	252.2858	-22.80082
74.88718	253.2834	-22.84868
74.94050	254.3474	-22.88603
74.99218	255.3784	-22.93034
75.04384	256.4091	-22.98986
75.09718	257.4749	-23.03914
75.14718	258.4725	-23.08404
75.20050	259.5369	-23.13986
75.25050	260.5346	-23.18103
75.30384	261.5980	-23.23517
75.35550	262.6295	-23.29066
75.40718	263.6604	-23.34198
75.46050	264.7232	-23.39513
75.51050	265.7219	-23.44458
75.56384	266.7862	-23.49525
75.61550	267.8169	-23.54368
75.66718	268.8472	-23.59677
75.72050	269.9114	-23.65331
75.77050	270.9082	-23.69946
75.82384	271.9724	-23.74647
-2.000000	5.000000	0.0000000