File: 7-C1(1.2mol%)+C20(0.6mol%)(1)/matlab/140-2.txt
CLOSED
Version	1.0
Language	English
Mode	Standard
Run	28
RunSerial	12296
Instrument	DSC Q2000 V24.11 Build 124
Module	DSC Standard Cell RC
Operator
File	\\AE520-1454\Users\dsc\Desktop\Data\29-08-17-3\140-2.001
ProcName
InstSerial	2000-0883
AutoSerial	1293
Sample	140-2
Size	25.1000	mg
PanMass	Not available
PanResist	Automatic Automatic  K/W
PanFactor	Default Default
Method
Comment
Xcomment	Pan: Tzero Aluminum Hermetic
Xcomment	Gas1: Nitrogen 50.0 ml/min
Xcomment	Gas2: Nitrogen 50.0 ml/min
Text
Exotherm	UP
Kcell	1.05230
Cpconst	Standard: 0.938
Calib	-38.6961
TempCal	1	pts	157.46	156.60
TzeroDt	-87.6168 -0.0009 -1.4231
TzeroDtz	-87.6168 0.0057 6.9570
InstCalFile	Tzero: \\Ae520-1454\ta\Data\DSC\Calibration\2017\CALIBRATION\1562_RCS (90)_05_18_2017 10_50_44.TZR
InstCalFile	Baseline: \\Ae520-1454\ta\Data\DSC\Calibration\2017\2017-05-17_Calibration.001
InstCalFile	Sapphire: \\Ae520-1454\ta\Data\DSC\Calibration\2017\2017-05-17_Saphire.001
InstCalDate	Tzero 2017-05-18 Time 10:50:44
TempRange	-87.39 to 398.39 °C at 10.00 °C/min Heat Only
AutoZero	Delta T Offset 0.000 uV
AutoZero	Delta T0 Offset 0.000 uV
MultiptCal	0
MultiPtDesc	0) Not set
AutoCellConst	Calibration Date 2017-05-18 16:59:28
Controls	Gas 1  Event Off  Sampling 0.2
Cell#	RC-01562
CoolingUnit	RCS (90)
SelHeatFlow	Heat Flow T4P (mW)
AutoLidII	Installed
AutoAnalysis	Off
MacroFile
Nsig	3
Sig1	Time (min)
Sig2	Temperature (°C)
Sig3	Heat Flow (mW)
Date	2017-08-31
Time	00:10:40
OrgMethod	1: Equilibrate at 80.00 °C
OrgMethod	2: Isothermal for 3.00 min
OrgMethod	3: Jump to 140.00 °C
OrgMethod	4: Mark end of cycle 1
OrgMethod	5: Isothermal for 40.00 min
OrgMethod	6: Mark end of cycle 2
OrgMethod	7: Ramp 20.00 °C/min to 280.00 °C
OrgMethod	8: Mark end of cycle 3
OrgMethod	9: Ramp 20.00 °C/min to 20.00 °C
OrgMethod	10: Mark end of cycle 4
OrgMethod	11: Ramp 20.00 °C/min to 280.00 °C
OrgMethod	12: Mark end of cycle 5
OrgFile	C:\Users\jarra\Desktop\DSC\7-C1(1.2mol%)+C20(0.6mol%)(1)\140-2.001
StartOfData
4.99994E-4	79.52459	-5.640912
0.05383332	79.61212	-4.490734
0.1055000	79.67761	-3.639169
0.1571666	79.72784	-2.978302
0.2105000	79.76611	-2.450304
0.2605000	79.79454	-2.073884
0.3138333	79.81824	-1.764932
0.3655000	79.83384	-1.534296
0.4171667	79.84595	-1.361980
0.4705000	79.85710	-1.224714
0.5205000	79.86286	-1.128507
0.5738334	79.86820	-1.052217
0.6238334	79.87200	-1.000352
0.6771668	79.87359	-0.9578609
0.7288332	79.87629	-0.9303632
0.7805000	79.87688	-0.9109722
0.8338332	79.87778	-0.8985775
0.8838332	79.87769	-0.8912798
0.9371668	79.87696	-0.8866257
0.9888332	79.87793	-0.8834930
1.040500	79.87619	-0.8803049
1.093833	79.87615	-0.8769660
1.143833	79.87582	-0.8739830
1.197166	79.87549	-0.8709603
1.247166	79.87405	-0.8682795
1.300500	79.87322	-0.8657085
1.352166	79.87236	-0.8633991
1.403833	79.87249	-0.8613718
1.457167	79.87163	-0.8594765
1.507167	79.87072	-0.8579309
1.560500	79.86999	-0.8564932
1.612166	79.86915	-0.8554110
1.663834	79.86842	-0.8545116
1.717167	79.86684	-0.8538234
1.767167	79.86598	-0.8533875
1.820500	79.86638	-0.8531000
1.870500	79.86584	-0.8530358
1.923834	79.86394	-0.8531226
1.975500	79.86352	-0.8533768
2.027166	79.86332	-0.8538824
2.080500	79.86296	-0.8545920
2.130500	79.86141	-0.8553147
2.183833	79.86172	-0.8562676
2.235500	79.86066	-0.8571270
2.287166	79.86048	-0.8581339
2.338833	79.85914	-0.8591841
2.390500	79.85859	-0.8602982
2.443833	79.85845	-0.8614746
2.493833	79.85779	-0.8625966
2.547166	79.85743	-0.8638868
2.598834	79.85639	-0.8652362
2.650500	79.85649	-0.8666562
2.703833	79.85536	-0.8682870
2.753833	79.85507	-0.8698166
2.807167	79.85486	-0.8714745
2.858833	79.85388	-0.8730469
2.910500	79.85356	-0.8746378
2.962167	79.85312	-0.8762602
3.010500	79.85732	-0.9173811
3.060500	80.48286	-8.454535
3.113833	82.71292	-22.30780
3.165500	85.46032	-34.34650
3.217166	88.67219	-45.61669
3.270500	92.35574	-55.82717
3.320500	96.06825	-64.00891
3.373834	100.2370	-71.34775
3.425500	104.4263	-77.25219
3.477167	108.7233	-82.14918
3.530500	113.2377	-86.31291
3.580500	117.5167	-89.58121
3.633833	122.0999	-92.49519
3.683833	125.9114	-89.62944
3.737167	128.6395	-78.68764
3.788833	130.6565	-68.24493
3.840500	132.2122	-57.86699
3.893833	133.4744	-48.40984
3.943833	134.4162	-40.82800
3.997166	135.2206	-34.14656
4.048834	135.8477	-28.88420
4.100500	136.3575	-24.67110
4.153834	136.7875	-21.23931
4.203833	137.1204	-18.68739
4.257167	137.4159	-16.54260
4.307167	137.6476	-14.96537
4.360500	137.8550	-13.64229
4.412167	138.0249	-12.63848
4.463834	138.1684	-11.84627
4.517166	138.2963	-11.19996
4.567167	138.3995	-10.71604
4.620500	138.4949	-10.30348
4.672167	138.5744	-9.978199
4.723834	138.6450	-9.713569
4.775500	138.7060	-9.497084
4.827167	138.7604	-9.317626
4.880500	138.8098	-9.162116
4.930500	138.8511	-9.037116
4.983834	138.8901	-8.927491
5.035500	138.9239	-8.832844
5.087167	138.9540	-8.753035
5.140500	138.9839	-8.680291
5.190500	139.0068	-8.615348
5.243834	139.0300	-8.553687
5.295500	139.0502	-8.499053
5.347168	139.0687	-8.450003
5.398834	139.0860	-8.402347
5.450500	139.1019	-8.356249
5.503834	139.1168	-8.308495
5.553834	139.1294	-8.263738
5.607168	139.1428	-8.218060
5.658832	139.1542	-8.175292
5.710500	139.1644	-8.129493
5.763834	139.1764	-8.084038
5.813832	139.1853	-8.039960
5.867168	139.1948	-7.988679
5.917168	139.2039	-7.939910
5.970500	139.2124	-7.888172
6.022168	139.2208	-7.837362
6.073834	139.2289	-7.783886
6.127168	139.2366	-7.725659
6.177166	139.2434	-7.669284
6.230500	139.2514	-7.605779
6.282166	139.2594	-7.537769
6.333832	139.2670	-7.466176
6.387168	139.2740	-7.387603
6.437168	139.2817	-7.305220
6.490500	139.2904	-7.209416
6.540500	139.2990	-7.106218
6.593832	139.3084	-6.982122
6.645500	139.3201	-6.837045
6.697168	139.3314	-6.664106
6.750500	139.3463	-6.459820
6.800500	139.3618	-6.244907
6.853832	139.3796	-5.990126
6.905500	139.3982	-5.726670
6.957168	139.4180	-5.453881
7.010500	139.4387	-5.158140
7.060500	139.4575	-4.884308
7.113834	139.4774	-4.597342
7.163832	139.4957	-4.336441
7.217168	139.5150	-4.076598
7.268832	139.5316	-3.844459
7.320500	139.5480	-3.633737
7.373834	139.5615	-3.438496
7.423834	139.5731	-3.280324
7.477168	139.5844	-3.131201
7.528832	139.5939	-3.014924
7.580500	139.6016	-2.912740
7.633832	139.6088	-2.816243
7.683832	139.6154	-2.736262
7.737168	139.6218	-2.661780
7.787168	139.6264	-2.599933
7.840500	139.6316	-2.544210
7.892168	139.6356	-2.496492
7.943832	139.6389	-2.456498
7.997168	139.6430	-2.418634
8.047168	139.6454	-2.385382
8.100500	139.6484	-2.354042
8.152168	139.6512	-2.327476
8.203834	139.6535	-2.306891
8.255500	139.6543	-2.289290
8.307168	139.6564	-2.275544
8.360500	139.6583	-2.261916
8.410499	139.6604	-2.249495
8.463834	139.6616	-2.236929
8.515500	139.6628	-2.226011
8.567166	139.6647	-2.216658
8.620499	139.6656	-2.206581
8.670500	139.6667	-2.198552
8.723832	139.6682	-2.190324
8.775499	139.6693	-2.183348
8.827168	139.6706	-2.176042
8.878834	139.6713	-2.168556
8.930500	139.6720	-2.161125
8.983832	139.6734	-2.153337
9.033832	139.6736	-2.145910
9.087168	139.6757	-2.137990
9.138834	139.6758	-2.130258
9.190500	139.6762	-2.122426
9.243834	139.6773	-2.114296
9.293834	139.6777	-2.106680
9.347168	139.6775	-2.098645
9.398834	139.6784	-2.091018
9.450500	139.6789	-2.083516
9.502168	139.6796	-2.076241
9.553832	139.6793	-2.069026
9.607166	139.6802	-2.061804
9.657166	139.6811	-2.055039
9.710499	139.6822	-2.047928
9.762168	139.6820	-2.041048
9.813834	139.6836	-2.034323
9.867166	139.6840	-2.027372
9.917168	139.6841	-2.020908
9.970500	139.6842	-2.013970
10.02050	139.6846	-2.007474
10.07383	139.6859	-2.000510
10.12550	139.6861	-1.993703
10.17717	139.6869	-1.986920
10.23050	139.6870	-1.979813
10.28050	139.6885	-1.973259
10.33383	139.6880	-1.966182
10.38550	139.6882	-1.959341
10.43717	139.6898	-1.952506
10.49050	139.6905	-1.945505
10.54050	139.6909	-1.938898
10.59383	139.6907	-1.931865
10.64383	139.6920	-1.925253
10.69717	139.6918	-1.918197
10.74883	139.6922	-1.911364
10.80050	139.6925	-1.904576
10.85383	139.6935	-1.897589
10.90383	139.6944	-1.891036
10.95717	139.6945	-1.884022
11.00883	139.6947	-1.877265
11.06050	139.6948	-1.870474
11.11383	139.6960	-1.863499
11.16383	139.6965	-1.856914
11.21717	139.6972	-1.849806
11.26717	139.6982	-1.843142
11.32050	139.6984	-1.836031
11.37217	139.6988	-1.829101
11.42383	139.6992	-1.822141
11.47717	139.7002	-1.814971
11.52717	139.7007	-1.808205
11.58050	139.7011	-1.801019
11.63216	139.7015	-1.794068
11.68383	139.7026	-1.787202
11.73717	139.7028	-1.780007
11.78717	139.7031	-1.773237
11.84050	139.7033	-1.766006
11.89050	139.7052	-1.759206
11.94383	139.7045	-1.751924
11.99550	139.7061	-1.744811
12.04717	139.7069	-1.737731
12.10050	139.7066	-1.730302
12.15050	139.7073	-1.723358
12.20384	139.7087	-1.715859
12.25550	139.7088	-1.708586
12.30717	139.7100	-1.701247
12.35883	139.7100	-1.693922
12.41050	139.7111	-1.686485
12.46383	139.7118	-1.678819
12.51383	139.7116	-1.671597
12.56716	139.7126	-1.663959
12.61884	139.7132	-1.656454
12.67050	139.7141	-1.648936
12.72383	139.7140	-1.641124
12.77383	139.7148	-1.633848
12.82717	139.7144	-1.626038
12.87883	139.7156	-1.618428
12.93050	139.7160	-1.610813
12.98216	139.7175	-1.603176
13.03383	139.7180	-1.595464
13.08717	139.7188	-1.587462
13.13717	139.7190	-1.579870
13.19050	139.7202	-1.571786
13.24216	139.7202	-1.564005
13.29384	139.7211	-1.556123
13.34717	139.7223	-1.547907
13.39717	139.7224	-1.540219
13.45050	139.7229	-1.531896
13.50050	139.7238	-1.524061
13.55383	139.7240	-1.515664
13.60550	139.7248	-1.507410
13.65717	139.7251	-1.498953
13.71050	139.7264	-1.490047
13.76050	139.7269	-1.481580
13.81383	139.7275	-1.472127
13.86550	139.7283	-1.462964
13.91716	139.7289	-1.453499
13.97050	139.7298	-1.443163
14.02050	139.7297	-1.432966
14.07384	139.7313	-1.420126
14.12384	139.7330	-1.405584
14.17717	139.7333	-1.390705
14.22884	139.7348	-1.374022
14.28050	139.7358	-1.352483
14.33383	139.7377	-1.327743
14.38383	139.7388	-1.304004
14.43716	139.7404	-1.274892
14.48883	139.7424	-1.246027
14.54050	139.7439	-1.215731
14.59383	139.7458	-1.180577
14.64383	139.7477	-1.149337
14.69717	139.7495	-1.111154
14.74717	139.7516	-1.076166
14.80050	139.7534	-1.038070
14.85217	139.7555	-1.001272
14.90383	139.7586	-0.9655559
14.95717	139.7598	-0.9278692
15.00717	139.7611	-0.8961381
15.06050	139.7640	-0.8601566
15.11217	139.7659	-0.8272322
15.16383	139.7683	-0.7950676
15.21716	139.7712	-0.7652884
15.26717	139.7724	-0.7351207
15.32050	139.7757	-0.7038824
15.37050	139.7773	-0.6738166
15.42383	139.7796	-0.6432285
15.47550	139.7818	-0.6116373
15.52717	139.7837	-0.5843456
15.58050	139.7856	-0.5541418
15.63050	139.7870	-0.5268422
15.68383	139.7901	-0.4995639
15.73550	139.7914	-0.4717002
15.78717	139.7936	-0.4419156
15.83883	139.7951	-0.4133083
15.89050	139.7968	-0.3850367
15.94384	139.7980	-0.3566990
15.99383	139.8008	-0.3313564
16.04716	139.8023	-0.3032297
16.09883	139.8040	-0.2769396
16.15050	139.8066	-0.2526042
16.20383	139.8083	-0.2262708
16.25383	139.8098	-0.2027324
16.30716	139.8115	-0.1766836
16.35883	139.8133	-0.1496623
16.41050	139.8146	-0.1249969
16.46216	139.8170	-0.1012725
16.51383	139.8188	-.07563166
16.56716	139.8205	-.05069778
16.61716	139.8225	-.02680226
16.67050	139.8241	-6.3505E-4
16.72216	139.8248	0.02374892
16.77383	139.8272	0.04564997
16.82716	139.8296	0.07007181
16.87716	139.8299	0.09341124
16.93050	139.8316	0.1164524
16.98216	139.8334	0.1389015
17.03383	139.8350	0.1613572
17.08550	139.8364	0.1843207
17.13716	139.8380	0.2059372
17.19050	139.8400	0.2287890
17.24050	139.8412	0.2501140
17.29383	139.8428	0.2736333
17.34550	139.8445	0.2948289
17.39716	139.8454	0.3171553
17.45050	139.8476	0.3409497
17.50050	139.8492	0.3630080
17.55383	139.8498	0.3864266
17.60383	139.8520	0.4073430
17.65716	139.8537	0.4310787
17.70883	139.8551	0.4528238
17.76050	139.8571	0.4761520
17.81383	139.8580	0.4986431
17.86383	139.8602	0.5203379
17.91716	139.8612	0.5439892
17.96883	139.8636	0.5672084
18.02050	139.8651	0.5893922
18.07383	139.8661	0.6134738
18.12383	139.8675	0.6358311
18.17716	139.8699	0.6594188
18.22716	139.8710	0.6828961
18.28050	139.8717	0.7065644
18.33216	139.8740	0.7279520
18.38383	139.8750	0.7496299
18.43716	139.8766	0.7726538
18.48716	139.8781	0.7932582
18.54050	139.8803	0.8144751
18.59216	139.8812	0.8349762
18.64383	139.8829	0.8564574
18.69716	139.8842	0.8786824
18.74716	139.8857	0.8971131
18.80050	139.8877	0.9174407
18.85050	139.8883	0.9367294
18.90383	139.8899	0.9565899
18.95550	139.8912	0.9757812
19.00716	139.8928	0.9921528
19.06050	139.8945	1.008304
19.11050	139.8968	1.024526
19.16383	139.8978	1.039820
19.21550	139.8984	1.056480
19.26716	139.9005	1.072024
19.32050	139.9015	1.088855
19.37050	139.9027	1.104777
19.42383	139.9044	1.120805
19.47383	139.9045	1.137897
19.52716	139.9064	1.153153
19.57883	139.9073	1.167302
19.63050	139.9078	1.180800
19.68383	139.9098	1.193263
19.73383	139.9096	1.205353
19.78717	139.9113	1.216649
19.83883	139.9119	1.228084
19.89050	139.9130	1.239215
19.94216	139.9125	1.250419
19.99383	139.9147	1.259876
20.04716	139.9148	1.269883
20.09716	139.9156	1.279427
20.15050	139.9161	1.289342
20.20216	139.9171	1.298891
20.25383	139.9178	1.308577
20.30716	139.9179	1.318484
20.35716	139.9176	1.327703
20.41050	139.9186	1.337556
20.46216	139.9186	1.347050
20.51383	139.9188	1.356476
20.56550	139.9192	1.365748
20.61716	139.9200	1.374824
20.67050	139.9192	1.384030
20.72050	139.9207	1.392391
20.77383	139.9202	1.401199
20.82550	139.9199	1.409448
20.87716	139.9216	1.417490
20.93050	139.9207	1.425446
20.98050	139.9214	1.432610
21.03383	139.9225	1.439918
21.08383	139.9216	1.446463
21.13716	139.9228	1.453122
21.18883	139.9225	1.459287
21.24050	139.9219	1.465234
21.29383	139.9228	1.471053
21.34383	139.9232	1.476323
21.39716	139.9225	1.481691
21.44883	139.9228	1.486681
21.50050	139.9227	1.491396
21.55383	139.9229	1.496056
21.60383	139.9228	1.500135
21.65716	139.9232	1.504203
21.70717	139.9234	1.507719
21.76050	139.9232	1.511322
21.81216	139.9226	1.514527
21.86383	139.9223	1.517514
21.91716	139.9229	1.520238
21.96716	139.9234	1.522571
22.02050	139.9223	1.524845
22.07216	139.9216	1.526769
22.12383	139.9222	1.528387
22.17717	139.9229	1.529870
22.22716	139.9227	1.531073
22.28050	139.9216	1.532116
22.33050	139.9221	1.532900
22.38383	139.9216	1.533532
22.43550	139.9220	1.533916
22.48716	139.9218	1.534128
22.54050	139.9211	1.534168
22.59050	139.9206	1.533925
22.64383	139.9207	1.533500
22.69550	139.9213	1.532940
22.74716	139.9203	1.532286
22.80050	139.9196	1.531436
22.85050	139.9199	1.530521
22.90383	139.9197	1.529432
22.95383	139.9191	1.528230
23.00716	139.9189	1.526821
23.05883	139.9186	1.525296
23.11050	139.9176	1.523698
23.16383	139.9166	1.521936
23.21383	139.9179	1.520057
23.26716	139.9177	1.517996
23.31883	139.9169	1.515869
23.37050	139.9166	1.513608
23.42216	139.9166	1.511175
23.47383	139.9161	1.508706
23.52717	139.9159	1.505985
23.57716	139.9158	1.503385
23.63050	139.9154	1.500522
23.68216	139.9158	1.497647
23.73383	139.9150	1.494677
23.78717	139.9152	1.491530
23.83716	139.9149	1.488630
23.89050	139.9152	1.485562
23.94216	139.9148	1.482560
23.99383	139.9144	1.479512
24.04550	139.9140	1.476355
24.09716	139.9134	1.473180
24.15050	139.9136	1.469795
24.20050	139.9127	1.466660
24.25383	139.9132	1.463260
24.30550	139.9126	1.460038
24.35716	139.9125	1.456771
24.41050	139.9125	1.453472
24.46050	139.9112	1.450406
24.51383	139.9114	1.447040
24.56550	139.9102	1.443824
24.61716	139.9103	1.440479
24.66883	139.9106	1.437198
24.72050	139.9104	1.433890
24.77383	139.9101	1.430366
24.82383	139.9103	1.427086
24.87716	139.9100	1.423619
24.92883	139.9100	1.420202
24.98050	139.9090	1.416919
25.03383	139.9086	1.413537
25.08383	139.9086	1.410384
25.13716	139.9086	1.407068
25.18716	139.9084	1.404011
25.24050	139.9077	1.400771
25.29216	139.9082	1.397676
25.34383	139.9081	1.394595
25.39716	139.9070	1.391371
25.44716	139.9072	1.388306
25.50050	139.9074	1.385026
25.55217	139.9068	1.381779
25.60383	139.9075	1.378489
25.65716	139.9071	1.375089
25.70716	139.9071	1.371920
25.76050	139.9067	1.368538
25.81050	139.9070	1.365388
25.86383	139.9068	1.361961
25.91550	139.9066	1.358761
25.96716	139.9059	1.355508
26.02050	139.9056	1.352251
26.07050	139.9055	1.349178
26.12383	139.9050	1.345909
26.17550	139.9053	1.342774
26.22717	139.9049	1.339619
26.28050	139.9038	1.336349
26.33050	139.9033	1.333238
26.38383	139.9028	1.329892
26.43383	139.9039	1.326656
26.48716	139.9032	1.323298
26.53883	139.9027	1.319928
26.59050	139.9020	1.316590
26.64383	139.9019	1.312981
26.69383	139.9019	1.309684
26.74716	139.9019	1.306074
26.79883	139.9016	1.302545
26.85050	139.9019	1.298956
26.90383	139.9012	1.295202
26.95383	139.9014	1.291690
27.00716	139.9004	1.288018
27.05716	139.9006	1.284463
27.11050	139.9005	1.280775
27.16217	139.8999	1.277095
27.21383	139.8992	1.273484
27.26716	139.8986	1.269672
27.31716	139.8989	1.266067
27.37050	139.8981	1.262289
27.42216	139.8980	1.258588
27.47383	139.8981	1.254951
27.52550	139.8978	1.251246
27.57717	139.8974	1.247460
27.63050	139.8973	1.243518
27.68050	139.8972	1.239728
27.73383	139.8965	1.235641
27.78550	139.8966	1.231681
27.83716	139.8955	1.227630
27.89050	139.8964	1.223471
27.94050	139.8956	1.219598
27.99383	139.8964	1.215460
28.04550	139.8945	1.211484
28.09716	139.8948	1.207507
28.14883	139.8944	1.203560
28.20050	139.8935	1.199510
28.25383	139.8940	1.195374
28.30383	139.8932	1.191498
28.35716	139.8937	1.187385
28.40883	139.8934	1.183416
28.46050	139.8931	1.179392
28.51383	139.8917	1.175177
28.56383	139.8918	1.171264
28.61716	139.8918	1.167080
28.66716	139.8919	1.163159
28.72050	139.8909	1.159033
28.77216	139.8912	1.155050
28.82383	139.8904	1.151006
28.87716	139.8899	1.146750
28.92717	139.8899	1.142742
28.98050	139.8894	1.138358
29.03216	139.8890	1.134081
29.08383	139.8902	1.129767
29.13716	139.8888	1.125347
29.18717	139.8891	1.121164
29.24050	139.8883	1.116794
29.29050	139.8871	1.112602
29.34383	139.8877	1.108150
29.39550	139.8879	1.103812
29.44717	139.8869	1.099506
29.50050	139.8873	1.094979
29.55050	139.8871	1.090740
29.60383	139.8858	1.086233
29.65550	139.8864	1.081772
29.70716	139.8867	1.077306
29.76050	139.8852	1.072626
29.81050	139.8849	1.068210
29.86383	139.8849	1.063516
29.91383	139.8845	1.059120
29.96716	139.8842	1.054331
30.01883	139.8841	1.049651
30.07050	139.8841	1.044949
30.12383	139.8833	1.040133
30.17383	139.8824	1.035731
30.22717	139.8816	1.030918
30.27883	139.8814	1.026265
30.33050	139.8814	1.021562
30.38383	139.8805	1.016661
30.43383	139.8804	1.012009
30.48716	139.8797	1.007022
30.53717	139.8786	1.002294
30.59050	139.8786	0.9971906
30.64216	139.8788	0.9921968
30.69383	139.8783	0.9871728
30.74716	139.8777	0.9819219
30.79716	139.8772	0.9769220
30.85050	139.8774	0.9715539
30.90216	139.8764	0.9662993
30.95383	139.8766	0.9610284
31.00550	139.8758	0.9556772
31.05716	139.8761	0.9503130
31.11050	139.8748	0.9446412
31.16050	139.8750	0.9393472
31.21383	139.8738	0.9336632
31.26550	139.8738	0.9281647
31.31716	139.8741	0.9225262
31.37050	139.8730	0.9166991
31.42050	139.8733	0.9111855
31.47383	139.8732	0.9052682
31.52550	139.8730	0.8995588
31.57717	139.8717	0.8938194
31.62883	139.8714	0.8880176
31.68050	139.8718	0.8821655
31.73383	139.8710	0.8761231
31.78383	139.8703	0.8704669
31.83716	139.8694	0.8644428
31.88883	139.8692	0.8585159
31.94050	139.8696	0.8525363
31.99383	139.8684	0.8463850
32.04383	139.8680	0.8406063
32.09716	139.8677	0.8343482
32.14883	139.8680	0.8282040
32.20050	139.8674	0.8220360
32.25217	139.8662	0.8158355
32.30383	139.8665	0.8096821
32.35716	139.8655	0.8034125
32.40716	139.8641	0.7975382
32.46050	139.8639	0.7911526
32.51216	139.8639	0.7850151
32.56383	139.8625	0.7788620
32.61716	139.8616	0.7724316
32.66716	139.8628	0.7664137
32.72050	139.8616	0.7599878
32.77050	139.8613	0.7539318
32.82383	139.8604	0.7473813
32.87550	139.8598	0.7410357
32.92717	139.8591	0.7346015
32.98050	139.8584	0.7279381
33.03050	139.8585	0.7216332
33.08383	139.8578	0.7149430
33.13550	139.8578	0.7084680
33.18716	139.8578	0.7019812
33.24050	139.8564	0.6953299
33.29050	139.8566	0.6889764
33.34384	139.8561	0.6821738
33.39383	139.8556	0.6757112
33.44717	139.8550	0.6687585
33.49883	139.8547	0.6620813
33.55050	139.8545	0.6552920
33.60383	139.8537	0.6483286
33.65383	139.8536	0.6418110
33.70716	139.8522	0.6349286
33.75883	139.8526	0.6282568
33.81050	139.8526	0.6215541
33.86383	139.8514	0.6145625
33.91383	139.8516	0.6079675
33.96716	139.8505	0.6009527
34.01716	139.8503	0.5942603
34.07050	139.8500	0.5871399
34.12216	139.8503	0.5802852
34.17383	139.8496	0.5734810
34.22717	139.8484	0.5663770
34.27716	139.8488	0.5597222
34.33050	139.8481	0.5526314
34.38216	139.8471	0.5457688
34.43384	139.8472	0.5389282
34.48717	139.8461	0.5318985
34.53717	139.8460	0.5253014
34.59050	139.8458	0.5182317
34.64050	139.8458	0.5116242
34.69383	139.8446	0.5046142
34.74550	139.8438	0.4978566
34.79716	139.8429	0.4910782
34.85050	139.8430	0.4841054
34.90050	139.8419	0.4775097
34.95383	139.8414	0.4705367
35.00550	139.8410	0.4637354
35.05716	139.8416	0.4569016
35.10883	139.8402	0.4500420
35.16050	139.8398	0.4431660
35.21383	139.8384	0.4359981
35.26383	139.8385	0.4291914
35.31716	139.8378	0.4219340
35.36883	139.8380	0.4148950
35.42050	139.8376	0.4078785
35.47383	139.8373	0.4004738
35.52383	139.8361	0.3937153
35.57717	139.8362	0.3863228
35.62883	139.8357	0.3793274
35.68050	139.8344	0.3723198
35.73216	139.8345	0.3653406
35.78383	139.8337	0.3584294
35.83716	139.8332	0.3512689
35.88716	139.8333	0.3446462
35.94050	139.8321	0.3375188
35.99216	139.8320	0.3306072
36.04383	139.8315	0.3236883
36.09716	139.8304	0.3165178
36.14717	139.8310	0.3096624
36.20050	139.8306	0.3024450
36.25050	139.8298	0.2956621
36.30383	139.8294	0.2883698
36.35550	139.8291	0.2812297
36.40716	139.8285	0.2741294
36.46050	139.8286	0.2668686
36.51050	139.8275	0.2600317
36.56383	139.8275	0.2527609
36.61550	139.8270	0.2457294
36.66716	139.8262	0.2386976
36.72050	139.8257	0.2314081
36.77050	139.8251	0.2246866
36.82383	139.8251	0.2175134
36.87383	139.8242	0.2108017
36.92717	139.8237	0.2037434
36.97883	139.8237	0.1967614
37.03050	139.8226	0.1897722
37.08383	139.8228	0.1826023
37.13383	139.8219	0.1758908
37.18716	139.8222	0.1687240
37.23883	139.8209	0.1617705
37.29050	139.8206	0.1548799
37.34384	139.8191	0.1478066
37.39383	139.8199	0.1412202
37.44717	139.8179	0.1342384
37.49716	139.8178	0.1276212
37.55050	139.8172	0.1205503
37.60217	139.8174	0.1136672
37.65383	139.8163	0.1067664
37.70716	139.8162	0.09959754
37.75716	139.8158	0.09284168
37.81050	139.8154	0.08559650
37.86217	139.8150	0.07849076
37.91383	139.8146	0.07138557
37.96716	139.8143	0.06423492
38.01716	139.8144	0.05745288
38.07050	139.8130	0.05028121
38.12050	139.8136	0.04355396
38.17383	139.8127	0.03636179
38.22550	139.8117	0.02946484
38.27716	139.8114	0.02258523
38.33050	139.8105	0.01552386
38.38050	139.8110	.008944605
38.43384	139.8096	.001972003
38.48550	139.8084	-4.7045E-3
38.53717	139.8096	-.01147024
38.58883	139.8081	-.01814109
38.64050	139.8082	-.02499892
38.69383	139.8077	-.03205180
38.74383	139.8073	-.03874641
38.79716	139.8072	-.04581426
38.84883	139.8067	-.05273026
38.90050	139.8064	-.05963849
38.95383	139.8058	-.06676820
39.00383	139.8050	-.07335472
39.05716	139.8046	-.08004613
39.10883	139.8044	-.08642742
39.16050	139.8043	-.09278234
39.21216	139.8032	-.09916812
39.26383	139.8030	-0.1056046
39.31716	139.8010	-0.1122735
39.36716	139.8009	-0.1185456
39.42050	139.8012	-0.1253481
39.47217	139.8003	-0.1319709
39.52383	139.8002	-0.1386173
39.57717	139.7992	-0.1455573
39.62717	139.7989	-0.1521278
39.68050	139.7991	-0.1591748
39.73216	139.7981	-0.1660070
39.78383	139.7988	-0.1728458
39.83550	139.7980	-0.1798088
39.88716	139.7979	-0.1866412
39.94050	139.7977	-0.1937244
39.99050	139.7967	-0.2002554
40.04383	139.7967	-0.2072527
40.09550	139.7951	-0.2139210
40.14717	139.7954	-0.2206621
40.20050	139.7961	-0.2275604
40.25050	139.7945	-0.2340659
40.30383	139.7944	-0.2410283
40.35383	139.7939	-0.2475394
40.40716	139.7930	-0.2543778
40.45883	139.7934	-0.2610685
40.51050	139.7924	-0.2677426
40.56383	139.7922	-0.2746282
40.61383	139.7918	-0.2810800
40.66716	139.7916	-0.2878992
40.71884	139.7915	-0.2945352
40.77050	139.7908	-0.3010772
40.82383	139.7907	-0.3078369
40.87383	139.7902	-0.3142725
40.92717	139.7894	-0.3211022
40.97717	139.7894	-0.3275200
41.03050	139.7887	-0.3343654
41.08217	139.7881	-0.3409675
41.13383	139.7882	-0.3476067
41.18716	139.7878	-0.3544798
41.23717	139.7876	-0.3608573
41.29050	139.7869	-0.3676539
41.34217	139.7861	-0.3741680
41.39383	139.7851	-0.3805578
41.44717	139.7834	-0.3870761
41.49716	139.7843	-0.3931445
41.55050	139.7834	-0.3996886
41.60050	139.7833	-0.4058851
41.65383	139.7830	-0.4125537
41.70550	139.7822	-0.4189288
41.75717	139.7816	-0.4253576
41.81050	139.7808	-0.4320114
41.86050	139.7814	-0.4382734
41.91383	139.7807	-0.4449114
41.96550	139.7804	-0.4512724
42.01717	139.7795	-0.4576758
42.07050	139.7788	-0.4641440
42.12050	139.7790	-0.4701972
42.17383	139.7776	-0.4765894
42.22383	139.7777	-0.4825537
42.27716	139.7767	-0.4888826
42.32883	139.7762	-0.4950000
42.38050	139.7764	-0.5011213
42.43383	139.7743	-0.5074692
42.48383	139.7753	-0.5134540
42.53717	139.7742	-0.5198217
42.58883	139.7750	-0.5261318
42.64050	139.7739	-0.5323726
42.69217	139.7735	-0.5385904
42.74383	139.7736	-0.5448289
42.79716	139.7731	-0.5511587
42.84716	139.7729	-0.5570884
42.90050	139.7718	-0.5634134
42.95216	139.7719	-0.5695372
43.00050	139.7721	-0.5752288
43.05383	139.8001	-1.251020
43.10550	140.0734	-4.522843
43.15717	140.5540	-7.869312
43.21050	141.1872	-10.90109
43.26050	141.8769	-13.17331
43.31383	142.6884	-15.07859
43.36550	143.5290	-16.49896
43.41716	144.4102	-17.60986
43.47050	145.3514	-18.48629
43.52050	146.2576	-19.12432
43.57383	147.2432	-19.66068
43.62383	148.1808	-20.06329
43.67717	149.1918	-20.40870
43.72883	150.1784	-20.68154
43.78050	151.1735	-20.90669
43.83383	152.2054	-21.10087
43.88383	153.1771	-21.27662
43.93716	154.2163	-21.43651
43.98883	155.2262	-21.58730
44.04050	156.2381	-21.73978
44.09384	157.2841	-21.87625
44.14383	158.2665	-22.00604
44.19717	159.3146	-22.12224
44.24716	160.2990	-22.23795
44.30050	161.3516	-22.31433
44.35217	162.3720	-22.40007
44.40383	163.3946	-22.46854
44.45717	164.4506	-22.53319
44.50717	165.4430	-22.57841
44.56050	166.5017	-22.61825
44.61217	167.5284	-22.65393
44.66383	168.5577	-22.67286
44.71717	169.6179	-22.68836
44.76717	170.6133	-22.69978
44.82050	171.6768	-22.71729
44.87050	172.6732	-22.73157
44.92383	173.7367	-22.74358
44.97550	174.7662	-22.75798
45.02716	175.7961	-22.78219
45.08050	176.8594	-22.81881
45.13050	177.8552	-22.87921
45.18383	178.9170	-22.98041
45.23550	179.9452	-23.08590
45.28717	180.9722	-23.20165
45.33883	181.9976	-23.34275
45.39050	183.0227	-23.48963
45.44383	184.0800	-23.66471
45.49383	185.0692	-23.84563
45.54716	186.1244	-24.04926
45.59883	187.1446	-24.29117
45.65050	188.1635	-24.57710
45.70383	189.2135	-24.86917
45.75383	190.1964	-25.16833
45.80717	191.2439	-25.51250
45.85883	192.2567	-25.86631
45.91050	193.2674	-26.54954
45.96216	194.2176	-30.99856
46.01383	195.0222	-35.54185
46.06717	195.9215	-36.61705
46.11716	196.8216	-37.35726
46.17050	197.8188	-37.71803
46.22217	198.8178	-37.62254
46.27383	199.8537	-36.49572
46.32717	200.9561	-35.71355
46.37717	201.9864	-35.37921
46.43050	203.0718	-35.40071
46.48217	204.1074	-35.50613
46.53383	205.1316	-36.11397
46.58550	206.1416	-36.79023
46.63716	207.1384	-37.70145
46.69050	208.1524	-38.90302
46.74050	209.0849	-40.53856
46.79383	210.0656	-42.25228
46.84550	210.9948	-44.44947
46.89717	211.9039	-47.02596
46.95050	212.8176	-50.09116
47.00050	213.6538	-53.25586
47.05383	214.5290	-56.97000
47.10383	215.3226	-60.45070
47.15717	216.1943	-63.25260
47.20883	217.0633	-65.29974
47.26050	217.9694	-66.51362
47.31383	218.9545	-66.78550
47.36383	219.9332	-65.67690
47.41716	221.0603	-62.62110
47.46884	222.2444	-58.04112
47.52050	223.5293	-51.29189
47.57383	224.9702	-43.28954
47.62383	226.3206	-38.81817
47.67717	227.6826	-35.75747
47.72717	228.8910	-33.71553
47.78050	230.1220	-32.11248
47.83217	231.2740	-30.98913
47.88383	232.3936	-30.18021
47.93716	233.5250	-29.57406
47.98717	234.5698	-29.17748
48.04050	235.6715	-28.86220
48.09217	236.7295	-28.62499
48.14383	237.7811	-28.48988
48.19717	238.8602	-28.40522
48.24716	239.8672	-28.36953
48.30050	240.9389	-28.35065
48.35050	241.9427	-28.34713
48.40383	243.0114	-28.34672
48.45550	244.0455	-28.34715
48.50717	245.0801	-28.34908
48.56050	246.1460	-28.35476
48.61050	247.1456	-28.36817
48.66383	248.2108	-28.39320
48.71550	249.2437	-28.43222
48.76717	250.2758	-28.47693
48.82050	251.3409	-28.53291
48.87050	252.3388	-28.58117
48.92383	253.4031	-28.63278
48.97383	254.4017	-28.67885
49.02716	255.4651	-28.73552
49.07883	256.4963	-28.79664
49.13050	257.5278	-28.85048
49.18383	258.5917	-28.91148
49.23383	259.5892	-28.96680
49.28717	260.6527	-29.01208
49.33883	261.6848	-29.06414
49.39050	262.7169	-29.12506
49.44217	263.7481	-29.16609
49.49383	264.7792	-29.22719
49.54716	265.8438	-29.27312
49.59716	266.8422	-29.30844
49.65050	267.9070	-29.34644
49.70216	268.9381	-29.36826
49.75383	269.9696	-29.39145
49.80717	271.0344	-29.42169
49.85717	272.0305	-29.59938
49.91050	273.0928	-29.65616
49.96216	274.1243	-29.65788
50.01050	275.0904	-29.69326
50.06050	275.9730	-30.70244
50.11383	276.3110	-25.69275
50.16550	276.2616	-17.46636
50.21717	275.9634	-9.894422
50.27050	275.4778	-3.525942
50.32050	274.8958	1.099415
50.37383	274.1756	4.848590
50.42550	273.4072	7.622066
50.47717	272.5870	9.749381
50.53050	271.6974	11.42741
50.58050	270.8329	12.58624
50.63383	269.8851	13.52074
50.68383	268.9780	14.22101
50.73717	267.9950	14.81260
50.78883	267.0334	15.28334
50.84050	266.0620	15.66626
50.89383	265.0521	15.97425
50.94383	264.0977	16.20429
50.99716	263.0746	16.38446
51.04883	262.0769	16.48472
51.10050	261.0760	16.62213
51.15383	260.0406	16.72699
51.20383	259.0670	16.82748
51.25717	258.0270	16.92603
51.30717	257.0512	17.00248
51.36050	256.0067	17.08289
51.41216	254.9953	17.15890
51.46383	253.9819	17.23058
51.51716	252.9340	17.28861
51.56716	251.9502	17.34087
51.62050	250.9012	17.38535
51.67217	249.8828	17.42681
51.72383	248.8643	17.46782
51.77550	247.8450	17.50326
51.82717	246.8248	17.53625
51.88050	245.7718	17.56803
51.93050	244.7836	17.59425
51.98383	243.7300	17.61861
52.03550	242.7077	17.64254
52.08716	241.6845	17.65980
52.14050	240.6298	17.67480
52.19050	239.6400	17.69423
52.24383	238.5832	17.71480
52.29550	237.5598	17.73414
52.34716	236.5367	17.75532
52.39883	235.5130	17.77306
52.45050	234.4885	17.78719
52.50383	233.4308	17.80016
52.55383	232.4392	17.81149
52.60717	231.3824	17.82419
52.65883	230.3574	17.83816
52.71050	229.3325	17.85124
52.76382	228.2752	17.86743
52.81382	227.2823	17.88692
52.86716	226.2240	17.90092
52.91716	225.2316	17.91700
52.97050	224.1732	17.93238
53.02217	223.1473	17.94652
53.07383	222.1215	17.95797
53.12717	221.0629	17.97074
53.17717	220.0695	17.98238
53.23050	219.0105	17.99377
53.28217	217.9844	18.00348
53.33383	216.9584	18.01156
53.38716	215.8995	18.02108
53.43716	214.9065	18.02921
53.49050	213.8470	18.03908
53.54050	212.8546	18.04827
53.59384	211.7952	18.05741
53.64550	210.7698	18.06723
53.69717	209.7436	18.07622
53.75050	208.6820	18.08566
53.80050	207.6888	18.09431
53.85383	206.6283	18.10332
53.90550	205.6016	18.11173
53.95717	204.5756	18.12032
54.01050	203.5145	18.13024
54.06050	202.5212	18.13821
54.11382	201.4620	18.14680
54.16382	200.4673	18.15574
54.21717	199.4072	18.16454
54.26884	198.3807	18.17277
54.32050	197.3544	18.18086
54.37383	196.2948	18.18920
54.42383	195.3016	18.19725
54.47717	194.2412	18.20699
54.52883	193.2156	18.21646
54.58050	192.1885	18.22613
54.63383	191.1286	18.23640
54.68383	190.1356	18.24480
54.73717	189.0740	18.25466
54.78716	188.0802	18.26301
54.84050	187.0208	18.27240
54.89216	185.9939	18.28182
54.94384	184.9658	18.29118
54.99717	183.9055	18.29953
55.04717	182.9115	18.30737
55.10050	181.8498	18.31576
55.15217	180.8229	18.32346
55.20383	179.7953	18.33236
55.25550	178.7687	18.34061
55.30717	177.7411	18.35151
55.36050	176.6809	18.36588
55.41050	175.6874	18.37968
55.46382	174.6271	18.39785
55.51550	173.6006	18.42291
55.56716	172.5739	18.46592
55.62050	171.5161	18.56417
55.67050	170.5252	18.73094
55.72382	169.4722	18.95667
55.77550	168.4562	19.25287
55.82717	167.4467	19.70475
55.87883	166.4484	20.39525
55.93050	165.4678	21.50032
55.98383	164.4837	23.27782
56.03383	163.5974	25.68906
56.08716	162.7008	29.17220
56.13882	161.8838	33.24641
56.19050	161.1055	37.61350
56.24382	160.3192	41.85094
56.29382	159.5702	45.15674
56.34716	158.7326	47.67425
56.39883	157.8668	49.02602
56.45050	156.9366	49.26752
56.50217	155.9400	48.59714
56.55383	154.8787	46.84231
56.60717	153.7258	44.47568
56.65717	152.6038	41.89507
56.71050	151.3789	39.00578
56.76216	150.1799	36.28375
56.81382	148.9800	33.79050
56.86716	147.7535	31.49186
56.91716	146.6167	29.64789
56.97050	145.4224	27.95468
57.02050	144.3198	26.61755
57.07383	143.1599	25.44176
57.12550	142.0528	24.50865
57.17717	140.9570	23.72305
57.23050	139.8392	23.06937
57.28050	138.8006	22.55800
57.33383	137.7002	22.11675
57.38550	136.6400	21.75930
57.43716	135.5870	21.45527
57.49050	134.5036	21.20544
57.54050	133.4920	21.00802
57.59384	132.4142	20.82194
57.64384	131.4072	20.66893
57.69717	130.3342	20.52844
57.74883	129.2968	20.41397
57.80050	128.2597	20.30692
57.85383	127.1896	20.21130
57.90383	126.1878	20.11183
57.95717	125.1196	20.02045
58.00883	124.0855	19.94524
58.06050	123.0516	19.86220
58.11382	121.9850	19.78604
58.16382	120.9853	19.71962
58.21717	119.9192	19.65335
58.26716	118.9195	19.59881
58.32050	117.8529	19.53776
58.37217	116.8210	19.45976
58.42383	115.7858	19.34787
58.47717	114.7175	19.21420
58.52717	113.7140	19.12570
58.58050	112.6452	19.03429
58.63217	111.6110	18.94968
58.68383	110.5766	18.87352
58.73717	109.5096	18.80293
58.78716	108.5092	18.73740
58.84050	107.4433	18.67129
58.89050	106.4428	18.62107
58.94384	105.3770	18.54524
58.99550	104.3434	18.48980
59.04717	103.3098	18.42494
59.10050	102.2442	18.37334
59.15050	101.2448	18.31809
59.20383	100.1789	18.25691
59.25550	99.14569	18.19728
59.30717	98.11321	18.14150
59.35883	97.07949	18.08209
59.41050	96.04684	18.01887
59.46382	94.98012	17.95199
59.51382	93.97906	17.75031
59.56716	92.91082	17.75367
59.61882	91.87906	17.71784
59.67050	90.84515	17.66536
59.72382	89.77818	17.54908
59.77383	88.77819	17.51075
59.82717	87.71239	17.44950
59.87883	86.67858	17.33911
59.93050	85.64569	17.30288
59.98217	84.61181	17.25471
60.03383	83.57968	17.21213
60.08716	82.51566	17.19371
60.13716	81.51850	17.18156
60.19050	80.45505	17.17203
60.24216	79.42490	17.15495
60.29382	78.39370	17.14251
60.34716	77.33124	17.12801
60.39717	76.33362	17.11753
60.45050	75.27046	17.10089
60.50050	74.27281	17.08400
60.55383	73.20985	17.05778
60.60550	72.17910	17.03219
60.65717	71.14690	16.99134
60.71050	70.08261	16.91233
60.76050	69.08355	16.81722
60.81382	68.01690	16.73254
60.86550	66.98219	16.55664
60.91716	65.94600	16.44426
60.97050	64.87476	16.31059
61.02050	63.87080	16.21062
61.07383	62.80062	16.10994
61.12383	61.79800	16.02696
61.17717	60.72949	15.93254
61.22883	59.69379	15.86146
61.28050	58.66026	15.78570
61.33383	57.59280	15.69810
61.38383	56.59034	15.63799
61.43716	55.52398	15.55733
61.48882	54.48916	15.48849
61.54050	53.45661	15.41125
61.59384	52.39014	15.34520
61.64384	51.39106	15.28377
61.69717	50.32340	15.22633
61.74717	49.32404	15.17369
61.80050	48.25734	15.10921
61.85217	47.22293	15.04664
61.90383	46.19034	14.97854
61.95717	45.12392	14.91766
62.00717	44.12342	14.85649
62.06050	43.05750	14.79804
62.11217	42.02488	14.73354
62.16382	40.99034	14.66914
62.21717	39.92422	14.59786
62.26716	38.92336	14.52513
62.32050	37.85628	14.44975
62.37050	36.85588	14.37069
62.42383	35.78880	14.29583
62.47550	34.75388	14.22423
62.52717	33.72041	14.14664
62.58050	32.65170	14.06154
62.63050	31.64950	13.99306
62.68383	30.58310	13.91429
62.73550	29.54861	13.84522
62.78716	28.51354	13.75516
62.83882	27.47974	13.66776
62.89050	26.44310	13.59042
62.94384	25.37556	13.51285
62.99382	24.37316	13.51896
63.04550	23.37020	13.75858
63.09716	22.83470	11.60206
63.15050	22.76164	6.464816
63.20050	22.95674	2.190752
63.25383	23.37920	-1.469340
63.30550	23.93842	-4.206846
63.35717	24.60881	-6.299350
63.41050	25.38420	-7.956966
63.46050	26.17139	-9.148225
63.51382	27.05970	-10.13711
63.56550	27.95393	-10.88377
63.61716	28.87422	-11.47647
63.66882	29.81537	-11.94828
63.72050	30.77030	-12.32631
63.77383	31.77022	-12.64943
63.82383	32.71556	-12.89488
63.87716	33.73239	-13.11934
63.92883	34.72206	-13.29960
63.98050	35.71668	-13.46033
64.03384	36.74771	-13.60733
64.08384	37.71780	-13.73430
64.13717	38.75638	-13.85066
64.18717	39.73142	-13.94663
64.24050	40.77478	-14.04766
64.29218	41.78620	-14.13314
64.34384	42.79950	-14.21992
64.39717	43.84795	-14.30209
64.44717	44.83122	-14.38106
64.50050	45.88008	-14.46234
64.55218	46.89838	-14.53846
64.60383	47.91762	-14.62175
64.65718	48.97024	-14.69547
64.70717	49.95740	-14.76994
64.76050	51.01065	-14.85604
64.81050	51.99971	-14.93296
64.86384	53.05390	-15.01467
64.91550	54.07719	-15.08944
64.96717	55.09976	-15.16739
65.02050	56.15715	-15.24965
65.07050	57.14756	-15.32319
65.12383	58.20513	-15.40499
65.17550	59.22984	-15.48439
65.22718	60.25318	-15.56819
65.28050	61.31046	-15.66252
65.33050	62.30244	-15.74376
65.38384	63.36037	-15.83392
65.43384	64.35273	-15.91387
65.48717	65.41101	-16.00144
65.53882	66.43692	-16.09050
65.59050	67.46252	-16.17302
65.64384	68.52309	-16.25940
65.69384	69.51532	-16.34118
65.74718	70.57453	-16.43064
65.79884	71.60088	-16.52323
65.85050	72.62812	-16.62064
65.90384	73.68700	-16.70773
65.95384	74.68045	-16.80264
66.00718	75.73937	-16.89892
66.05718	76.73244	-16.98511
66.11050	77.79230	-17.08519
66.16218	78.81985	-17.18106
66.21384	79.84637	-17.28069
66.26716	80.90497	-17.38583
66.31718	81.89926	-17.48356
66.37050	82.95922	-17.58662
66.42218	83.98497	-17.68875
66.47384	85.01275	-17.79753
66.52550	86.03938	-17.89796
66.57718	87.06550	-18.00378
66.63050	88.12632	-18.11349
66.68050	89.11949	-18.21646
66.73384	90.17844	-18.33742
66.78550	91.20528	-18.45250
66.83716	92.23290	-18.51193
66.89050	93.29556	-18.53915
66.94050	94.29699	-18.53648
66.99384	95.36371	-18.53649
67.04550	96.39428	-18.55901
67.09718	97.42506	-18.61261
67.14884	98.45421	-18.70101
67.20050	99.48495	-18.77899
67.25384	100.5482	-18.86550
67.30384	101.5429	-18.94723
67.35718	102.6057	-19.02862
67.40884	103.6347	-19.11194
67.46050	104.6648	-19.20184
67.51384	105.7261	-19.29035
67.56384	106.7204	-19.37518
67.61718	107.7838	-19.46601
67.66718	108.7781	-19.54468
67.72050	109.8402	-19.64240
67.77218	110.8688	-19.73106
67.82384	111.8973	-19.82291
67.87718	112.9594	-19.90565
67.92718	113.9557	-19.99122
67.98050	115.0178	-20.08275
68.03218	116.0463	-20.17041
68.08384	117.0741	-20.25295
68.13718	118.1365	-20.34861
68.18718	119.1311	-20.44270
68.24050	120.1923	-20.53641
68.29050	121.1879	-20.63706
68.34384	122.2492	-20.73746
68.39550	123.2765	-20.83697
68.44718	124.3052	-20.94560
68.50050	125.3666	-21.04040
68.55050	126.3617	-21.13424
68.60384	127.4238	-21.23593
68.65550	128.4506	-21.33478
68.70718	129.4787	-21.43005
68.76050	130.5398	-21.54527
68.81050	131.5339	-21.64619
68.86384	132.5951	-21.75145
68.91382	133.5894	-21.86754
68.96718	134.6496	-21.97900
69.01882	135.6776	-22.09896
69.07050	136.7043	-22.21300
69.12384	137.7638	-22.33508
69.17384	138.7576	-22.45463
69.22718	139.8174	-22.58360
69.27884	140.8444	-22.69684
69.33050	141.8715	-22.82580
69.38384	142.9310	-22.95279
69.43384	143.9256	-23.06955
69.48718	144.9863	-23.18721
69.53718	145.9803	-23.30664
69.59050	147.0405	-23.43800
69.64216	148.0669	-23.56458
69.69384	149.0932	-23.68532
69.74718	150.1527	-23.81566
69.79718	151.1456	-23.93123
69.85050	152.2054	-24.05238
69.90218	153.2325	-24.17548
69.95384	154.2598	-24.29695
70.00550	155.2867	-24.42219
70.05718	156.3129	-24.56066
70.11050	157.3722	-24.69075
70.16050	158.3662	-24.80934
70.21384	159.4256	-24.92884
70.26550	160.4531	-25.04006
70.31718	161.4811	-25.12856
70.37050	162.5432	-25.20994
70.42050	163.5387	-25.25995
70.47384	164.6036	-25.31002
70.52550	165.6351	-25.33889
70.57718	166.6662	-25.36506
70.62884	167.7000	-25.39576
70.68050	168.7320	-25.42142
70.73384	169.7967	-25.46783
70.78384	170.7946	-25.54182
70.83716	171.8581	-25.63967
70.88884	172.8891	-25.73669
70.94050	173.9186	-25.83780
70.99384	174.9809	-25.96390
71.04384	175.9750	-26.08894
71.09718	177.0350	-26.23047
71.14884	178.0604	-26.39254
71.20050	179.0849	-26.57242
71.25218	180.1083	-26.78685
71.30384	181.1296	-27.02662
71.35718	182.1824	-27.28592
71.40718	183.1681	-27.57198
71.46050	184.2183	-27.90613
71.51218	185.2336	-28.26539
71.56384	186.2470	-28.64595
71.61718	187.2898	-29.12306
71.66718	188.2645	-29.61338
71.72050	189.3005	-30.18760
71.77050	190.2696	-30.76640
71.82384	191.2995	-31.43331
71.87550	192.2960	-32.09545
71.92718	193.2909	-32.77406
71.98050	194.3154	-33.48180
72.03050	195.2748	-34.17428
72.08384	196.2972	-34.96149
72.13550	197.2850	-35.79587
72.18718	198.2690	-36.68150
72.24050	199.2799	-37.72080
72.29050	200.2228	-38.78016
72.34384	201.2241	-39.99406
72.39384	202.1575	-41.19091
72.44718	203.1509	-42.48906
72.49884	204.1114	-43.71274
72.55050	205.0725	-44.85257
72.60384	206.0718	-45.78602
72.65384	207.0222	-46.22266
72.70718	208.0640	-45.90976
72.75884	209.1172	-44.45502
72.81050	210.2294	-41.81635
72.86384	211.4400	-38.22247
72.91382	212.6176	-34.83982
72.96718	213.8732	-32.13421
73.01716	215.0234	-30.44513
73.07050	216.2138	-29.18099
73.12218	217.3364	-28.31468
73.17384	218.4373	-27.65618
73.22718	219.5550	-27.17122
73.27718	220.5914	-26.83159
73.33050	221.6854	-26.57166
73.38218	222.7381	-26.41119
73.43384	223.7858	-26.29425
73.48718	224.8640	-26.20316
73.53718	225.8705	-26.16000
73.59050	226.9428	-26.13786
73.64050	227.9463	-26.12552
73.69384	229.0152	-26.12282
73.74550	230.0495	-26.12282
73.79718	231.0831	-26.12422
73.85050	232.1492	-26.13739
73.90050	233.1476	-26.16372
73.95384	234.2133	-26.20379
74.00550	235.2456	-26.25065
74.05718	236.2779	-26.29150
74.10884	237.3097	-26.33814
74.16050	238.3425	-26.38578
74.21384	239.4066	-26.43338
74.26384	240.4044	-26.49401
74.31718	241.4691	-26.57020
74.36884	242.5003	-26.62828
74.42050	243.5312	-26.69689
74.47384	244.5960	-26.75876
74.52384	245.5933	-26.80977
74.57718	246.6577	-26.86373
74.62884	247.6888	-26.91030
74.68050	248.7194	-26.95200
74.73218	249.7512	-27.00370
74.78384	250.7823	-27.05468
74.83716	251.8465	-27.10564
74.88718	252.8453	-27.15020
74.94050	253.9092	-27.19664
74.99218	254.9405	-27.24781
75.04384	255.9725	-27.30332
75.09718	257.0365	-27.36354
75.14718	258.0347	-27.42349
75.20050	259.0976	-27.48488
75.25050	260.0958	-27.54118
75.30384	261.1598	-27.59781
75.35550	262.1902	-27.66580
75.40718	263.2210	-27.72065
75.46050	264.2847	-27.78395
75.51050	265.2822	-27.84389
75.56384	266.3472	-27.89582
75.61550	267.3780	-27.93868
75.66718	268.4059	-28.15699
75.72050	269.4704	-28.13391
75.77050	270.4680	-28.17682
75.82384	271.5282	-28.42870
-2.000000	5.000000	0.0000000