File: 7-C1(1.2mol%)+C20(0.6mol%)(1)/matlab/150-1.txt
CLOSED
Version	1.0
Language	English
Mode	Standard
Run	29
RunSerial	12297
Instrument	DSC Q2000 V24.11 Build 124
Module	DSC Standard Cell RC
Operator
File	\\AE520-1454\Users\dsc\Desktop\Data\29-08-17-3\150-1.001
ProcName
InstSerial	2000-0883
AutoSerial	1293
Sample	150-1
Size	16.8000	mg
PanMass	Not available
PanResist	Automatic Automatic  K/W
PanFactor	Default Default
Method
Comment
Xcomment	Pan: Tzero Aluminum Hermetic
Xcomment	Gas1: Nitrogen 50.0 ml/min
Xcomment	Gas2: Nitrogen 50.0 ml/min
Text
Exotherm	UP
Kcell	1.05230
Cpconst	Standard: 0.938
Calib	-38.6961
TempCal	1	pts	157.46	156.60
TzeroDt	-87.6168 -0.0009 -1.4231
TzeroDtz	-87.6168 0.0057 6.9570
InstCalFile	Tzero: \\Ae520-1454\ta\Data\DSC\Calibration\2017\CALIBRATION\1562_RCS (90)_05_18_2017 10_50_44.TZR
InstCalFile	Baseline: \\Ae520-1454\ta\Data\DSC\Calibration\2017\2017-05-17_Calibration.001
InstCalFile	Sapphire: \\Ae520-1454\ta\Data\DSC\Calibration\2017\2017-05-17_Saphire.001
InstCalDate	Tzero 2017-05-18 Time 10:50:44
TempRange	-87.39 to 398.39 °C at 10.00 °C/min Heat Only
AutoZero	Delta T Offset 0.000 uV
AutoZero	Delta T0 Offset 0.000 uV
MultiptCal	0
MultiPtDesc	0) Not set
AutoCellConst	Calibration Date 2017-05-18 16:59:28
Controls	Gas 1  Event Off  Sampling 0.2
Cell#	RC-01562
CoolingUnit	RCS (90)
SelHeatFlow	Heat Flow T4P (mW)
AutoLidII	Installed
AutoAnalysis	Off
MacroFile
Nsig	3
Sig1	Time (min)
Sig2	Temperature (°C)
Sig3	Heat Flow (mW)
Date	2017-08-31
Time	01:33:05
OrgMethod	1: Equilibrate at 80.00 °C
OrgMethod	2: Isothermal for 3.00 min
OrgMethod	3: Jump to 150.00 °C
OrgMethod	4: Mark end of cycle 1
OrgMethod	5: Isothermal for 40.00 min
OrgMethod	6: Mark end of cycle 2
OrgMethod	7: Ramp 20.00 °C/min to 280.00 °C
OrgMethod	8: Mark end of cycle 3
OrgMethod	9: Ramp 20.00 °C/min to 20.00 °C
OrgMethod	10: Mark end of cycle 4
OrgMethod	11: Ramp 20.00 °C/min to 280.00 °C
OrgMethod	12: Mark end of cycle 5
OrgFile	C:\Users\jarra\Desktop\DSC\7-C1(1.2mol%)+C20(0.6mol%)(1)\150-1.001
StartOfData
4.99994E-4	79.86165	-1.532170
0.05383332	79.87680	-1.290952
0.1038333	79.88665	-1.128127
0.1571666	79.89320	-1.002969
0.2071666	79.89575	-0.9192163
0.2605000	79.89960	-0.8581892
0.3105000	79.90046	-0.8162032
0.3638334	79.90100	-0.7865313
0.4138333	79.90051	-0.7693220
0.4671667	79.90113	-0.7583026
0.5171667	79.89974	-0.7517495
0.5705000	79.89839	-0.7482806
0.6205000	79.89666	-0.7456664
0.6721668	79.89592	-0.7428530
0.7238332	79.89508	-0.7401500
0.7755000	79.89356	-0.7375182
0.8271668	79.89290	-0.7351134
0.8788332	79.89050	-0.7328605
0.9305000	79.88925	-0.7308280
0.9821668	79.88856	-0.7289931
1.033833	79.88840	-0.7273897
1.083833	79.88620	-0.7259888
1.137166	79.88540	-0.7246664
1.187166	79.88455	-0.7236518
1.240500	79.88357	-0.7227459
1.290500	79.88330	-0.7219996
1.343833	79.88280	-0.7213611
1.393833	79.88179	-0.7209326
1.447166	79.88061	-0.7205710
1.497166	79.87850	-0.7204407
1.550500	79.87876	-0.7204487
1.600500	79.87766	-0.7204785
1.653833	79.87734	-0.7206470
1.703833	79.87662	-0.7209062
1.755500	79.87585	-0.7212085
1.807167	79.87512	-0.7215708
1.858834	79.87500	-0.7220600
1.910500	79.87385	-0.7225613
1.962166	79.87318	-0.7231966
2.013833	79.87285	-0.7238647
2.065500	79.87207	-0.7245979
2.117167	79.87168	-0.7254343
2.167167	79.87074	-0.7262940
2.220500	79.87042	-0.7272391
2.270500	79.86918	-0.7282012
2.323833	79.86954	-0.7292893
2.373834	79.86957	-0.7302984
2.427167	79.86701	-0.7314194
2.477167	79.86759	-0.7325032
2.530500	79.86687	-0.7336749
2.580500	79.86747	-0.7348028
2.633833	79.86645	-0.7359450
2.683833	79.86547	-0.7370492
2.737167	79.86470	-0.7382682
2.787167	79.86549	-0.7395331
2.838833	79.86455	-0.7407446
2.890500	79.86350	-0.7419603
2.942167	79.86286	-0.7432305
2.993833	79.86256	-0.7444795
3.040500	80.05220	-3.612183
3.093834	81.90770	-16.77625
3.143833	84.53165	-26.24216
3.197167	87.87622	-35.56265
3.247166	91.37476	-43.46529
3.300500	95.39824	-50.50058
3.350500	99.39397	-55.59698
3.403833	103.8277	-59.74072
3.453833	108.0925	-62.74444
3.505500	112.5709	-65.16063
3.557167	117.0911	-67.07872
3.608833	121.6320	-68.70884
3.660500	126.1834	-70.02842
3.712167	130.7428	-70.98503
3.763833	135.2293	-70.54700
3.815500	138.7112	-61.09956
3.867166	141.0569	-50.45657
3.917167	142.7658	-41.07537
3.970500	144.1265	-32.37670
4.020500	145.1014	-25.68730
4.073834	145.9046	-20.00537
4.123833	146.4927	-15.84932
4.177166	146.9918	-12.44470
4.227167	147.3672	-10.02383
4.280500	147.6932	-8.066732
4.330500	147.9446	-6.691275
4.383834	148.1677	-5.588639
4.433834	148.3450	-4.808283
4.487167	148.5034	-4.182524
4.537167	148.6309	-3.740808
4.588834	148.7452	-3.390360
4.640500	148.8440	-3.124590
4.692166	148.9308	-2.918758
4.743834	149.0058	-2.764292
4.795500	149.0718	-2.643626
4.847166	149.1312	-2.551279
4.898834	149.1831	-2.475815
4.950500	149.2286	-2.416096
5.000500	149.2671	-2.372492
5.053834	149.3046	-2.337798
5.103833	149.3366	-2.309190
5.157166	149.3675	-2.286323
5.207167	149.3925	-2.268475
5.260500	149.4168	-2.253919
5.310500	149.4370	-2.242921
5.363834	149.4558	-2.233311
5.413832	149.4734	-2.225592
5.467168	149.4888	-2.218782
5.517168	149.5032	-2.212584
5.570500	149.5162	-2.206634
5.620500	149.5278	-2.201106
5.672168	149.5376	-2.194983
5.723834	149.5476	-2.188818
5.775500	149.5571	-2.182392
5.827168	149.5667	-2.175717
5.878834	149.5732	-2.168688
5.930500	149.5807	-2.161434
5.982168	149.5870	-2.154082
6.033832	149.5933	-2.146345
6.083832	149.5984	-2.138756
6.137168	149.6040	-2.130188
6.187168	149.6099	-2.121599
6.240500	149.6138	-2.111918
6.290500	149.6183	-2.102393
6.343834	149.6226	-2.090933
6.393832	149.6268	-2.080872
6.447168	149.6305	-2.068543
6.497168	149.6340	-2.055850
6.550500	149.6375	-2.041038
6.600500	149.6403	-2.027204
6.653832	149.6447	-2.012990
6.703832	149.6469	-1.994744
6.755500	149.6502	-1.976863
6.807166	149.6528	-1.957074
6.858832	149.6559	-1.936061
6.910500	149.6583	-1.913856
6.962168	149.6614	-1.891418
7.013834	149.6641	-1.867511
7.065500	149.6664	-1.843686
7.117166	149.6692	-1.818279
7.167168	149.6714	-1.794071
7.220500	149.6738	-1.768327
7.270500	149.6754	-1.741644
7.323834	149.6792	-1.715754
7.373834	149.6818	-1.690750
7.427168	149.6836	-1.661092
7.477168	149.6865	-1.631710
7.530500	149.6893	-1.601911
7.580500	149.6913	-1.572320
7.633832	149.6938	-1.541484
7.683832	149.6969	-1.511797
7.737168	149.6994	-1.479196
7.787168	149.7015	-1.447812
7.838834	149.7038	-1.417115
7.890500	149.7066	-1.383411
7.942168	149.7087	-1.349106
7.993834	149.7115	-1.313444
8.045500	149.7138	-1.279500
8.097168	149.7166	-1.244837
8.148834	149.7196	-1.209379
8.200500	149.7218	-1.172321
8.250500	149.7247	-1.136200
8.303832	149.7275	-1.098713
8.353832	149.7301	-1.061900
8.407166	149.7330	-1.022332
8.457168	149.7363	-0.9837670
8.510499	149.7384	-0.9427937
8.560500	149.7416	-0.9049309
8.613834	149.7448	-0.8650056
8.663834	149.7476	-0.8251191
8.717168	149.7509	-0.7818778
8.767168	149.7536	-0.7381461
8.820500	149.7573	-0.6940318
8.870499	149.7599	-0.6495886
8.922168	149.7638	-0.6034348
8.973832	149.7658	-0.5562236
9.025499	149.7702	-0.5092194
9.077168	149.7733	-0.4601138
9.128834	149.7768	-0.4114753
9.180500	149.7799	-0.3619916
9.232166	149.7833	-0.3130711
9.283832	149.7864	-0.2626392
9.333832	149.7899	-0.2126237
9.387168	149.7938	-0.1614038
9.437166	149.7975	-0.1118888
9.490500	149.8005	-.05594709
9.540500	149.8037	-5.7735E-3
9.593832	149.8084	0.04815447
9.643832	149.8116	0.1011346
9.697168	149.8156	0.1590409
9.747168	149.8193	0.2114456
9.800500	149.8236	0.2680428
9.850500	149.8275	0.3234444
9.903832	149.8313	0.3831362
9.953834	149.8357	0.4405738
10.00550	149.8397	0.5047564
10.05717	149.8444	0.5785904
10.10883	149.8492	0.6611950
10.16050	149.8560	0.7590851
10.21217	149.8628	0.8825743
10.26383	149.8712	1.031928
10.31550	149.8834	1.211234
10.36717	149.8956	1.420178
10.41717	149.9101	1.638535
10.47050	149.9254	1.894325
10.52050	149.9419	2.141295
10.57383	149.9598	2.409486
10.62383	149.9771	2.666750
10.67717	149.9947	2.938280
10.72717	150.0121	3.189048
10.78050	150.0295	3.451671
10.83050	150.0454	3.689303
10.88383	150.0623	3.938034
10.93383	150.0771	4.165090
10.98717	150.0929	4.395750
11.03717	150.1076	4.600398
11.08883	150.1214	4.809556
11.14050	150.1336	5.002754
11.19217	150.1468	5.185264
11.24384	150.1586	5.353894
11.29550	150.1691	5.512510
11.34717	150.1794	5.649732
11.39883	150.1875	5.776859
11.45050	150.1957	5.888419
11.50050	150.2012	5.982570
11.55383	150.2084	6.060368
11.60383	150.2129	6.119807
11.65717	150.2157	6.166697
11.70717	150.2181	6.194213
11.76050	150.2200	6.209234
11.81050	150.2204	6.214512
11.86383	150.2200	6.216204
11.91383	150.2191	6.216548
11.96717	150.2173	6.213560
12.01717	150.2152	6.198210
12.07050	150.2110	6.159500
12.12050	150.2080	6.101516
12.17217	150.2047	6.026164
12.22383	150.2004	5.948552
12.27550	150.1946	5.869030
12.32717	150.1907	5.786672
12.37884	150.1848	5.704294
12.43050	150.1794	5.618151
12.48217	150.1732	5.531296
12.53383	150.1687	5.442230
12.58383	150.1631	5.363644
12.63717	150.1571	5.273574
12.68716	150.1512	5.192403
12.74050	150.1461	5.105848
12.79050	150.1419	5.029547
12.84383	150.1352	4.950852
12.89383	150.1304	4.876088
12.94717	150.1258	4.799948
12.99717	150.1211	4.731976
13.05050	150.1159	4.660843
13.10050	150.1129	4.594867
13.15383	150.1071	4.527312
13.20383	150.1032	4.468343
13.25550	150.0998	4.403042
13.30717	150.0950	4.343828
13.35883	150.0906	4.279702
13.41050	150.0869	4.217072
13.46217	150.0826	4.155989
13.51383	150.0787	4.097336
13.56550	150.0753	4.042179
13.61716	150.0719	3.988357
13.66716	150.0679	3.936817
13.72050	150.0643	3.883222
13.77050	150.0611	3.836544
13.82384	150.0572	3.790336
13.87384	150.0542	3.747218
13.92717	150.0512	3.705524
13.97717	150.0498	3.663750
14.03050	150.0471	3.625363
14.08050	150.0431	3.589566
14.13383	150.0431	3.554194
14.18383	150.0393	3.523968
14.23716	150.0367	3.491544
14.28717	150.0344	3.462196
14.33883	150.0331	3.432092
14.39050	150.0305	3.405965
14.44217	150.0292	3.377985
14.49384	150.0270	3.353494
14.54550	150.0245	3.328688
14.59717	150.0231	3.305042
14.64883	150.0220	3.283725
14.70050	150.0201	3.262980
14.75050	150.0192	3.242501
14.80383	150.0176	3.222911
14.85383	150.0158	3.203652
14.90717	150.0143	3.183853
14.95717	150.0136	3.167887
15.01050	150.0120	3.150198
15.06050	150.0109	3.134724
15.11383	150.0094	3.119375
15.16383	150.0090	3.105432
15.21716	150.0070	3.090980
15.26717	150.0066	3.078447
15.32050	150.0050	3.067392
15.37050	150.0049	3.058020
15.42217	150.0037	3.048651
15.47383	150.0027	3.039617
15.52550	150.0024	3.030880
15.57717	150.0015	3.022692
15.62883	150.0012	3.014282
15.68050	150.0010	3.005975
15.73216	150.0004	2.997603
15.78383	150.0002	2.989227
15.83383	149.9999	2.981178
15.88716	149.9991	2.972676
15.93717	149.9984	2.964853
15.99050	149.9978	2.956711
16.04050	149.9979	2.949322
16.09383	149.9971	2.941681
16.14383	149.9972	2.934706
16.19717	149.9967	2.927566
16.24716	149.9966	2.921201
16.30050	149.9956	2.914630
16.35050	149.9960	2.908654
16.40383	149.9951	2.902658
16.45383	149.9953	2.897324
16.50550	149.9955	2.892090
16.55716	149.9958	2.887212
16.60883	149.9960	2.882709
16.66050	149.9961	2.878638
16.71216	149.9960	2.874965
16.76383	149.9964	2.871712
16.81550	149.9968	2.868996
16.86716	149.9970	2.866730
16.91716	149.9977	2.865080
16.97050	149.9988	2.863910
17.02050	149.9990	2.863436
17.07383	149.9998	2.863604
17.12383	150.0006	2.864460
17.17716	150.0016	2.866492
17.22716	150.0023	2.869525
17.28050	150.0042	2.874690
17.33050	150.0049	2.881732
17.38383	150.0070	2.890376
17.43383	150.0077	2.902026
17.48716	150.0100	2.916767
17.53717	150.0113	2.933062
17.58883	150.0122	2.955180
17.64050	150.0144	2.976072
17.69216	150.0155	3.001082
17.74383	150.0183	3.026291
17.79550	150.0195	3.051410
17.84716	150.0212	3.076653
17.89883	150.0233	3.101968
17.95050	150.0255	3.126755
18.00050	150.0267	3.151058
18.05383	150.0283	3.177944
18.10383	150.0302	3.202606
18.15716	150.0317	3.228594
18.20716	150.0334	3.250195
18.26050	150.0345	3.272134
18.31050	150.0356	3.286050
18.36383	150.0367	3.300010
18.41383	150.0384	3.308206
18.46716	150.0383	3.315063
18.51716	150.0380	3.321197
18.57050	150.0388	3.327133
18.62050	150.0378	3.331937
18.67216	150.0360	3.335925
18.72383	150.0349	3.339880
18.77550	150.0326	3.341538
18.82716	150.0305	3.333626
18.87883	150.0270	3.308958
18.93050	150.0243	3.265747
18.98216	150.0209	3.209242
19.03383	150.0174	3.145172
19.08383	150.0138	3.079004
19.13716	150.0098	3.009119
19.18716	150.0054	2.943539
19.24050	150.0001	2.872675
19.29050	149.9958	2.808047
19.34383	149.9919	2.736294
19.39383	149.9877	2.670717
19.44716	149.9827	2.599363
19.49716	149.9784	2.533289
19.55050	149.9739	2.461435
19.60050	149.9694	2.393925
19.65383	149.9643	2.326485
19.70383	149.9601	2.259741
19.75550	149.9550	2.193375
19.80716	149.9502	2.123202
19.85883	149.9457	2.056770
19.91050	149.9415	1.987119
19.96216	149.9368	1.919005
20.01383	149.9327	1.850963
20.06550	149.9276	1.784756
20.11716	149.9226	1.719933
20.16716	149.9190	1.655072
20.22050	149.9146	1.587573
20.27050	149.9106	1.524404
20.32383	149.9061	1.459305
20.37383	149.9020	1.398800
20.42716	149.9066	1.393012
20.47716	149.9028	1.389931
20.53050	149.8968	1.324500
20.58050	149.8923	1.233145
20.63383	149.8880	1.151252
20.68383	149.8840	1.099599
20.73716	149.8811	1.072252
20.78717	149.8766	1.008230
20.83883	149.8722	0.9314403
20.89050	149.8671	0.8636011
20.94216	149.8622	0.7998719
20.99383	149.8584	0.7390874
21.04550	149.8551	0.6803985
21.09716	149.8504	0.6230440
21.14883	149.8464	0.5658746
21.20050	149.8436	0.5085734
21.25050	149.8406	0.4549097
21.30383	149.8359	0.4009794
21.35383	149.8340	0.3473082
21.40716	149.8290	0.2919870
21.45717	149.8263	0.2376480
21.51050	149.8220	0.1856360
21.56050	149.8189	0.1302585
21.61383	149.8154	0.07978410
21.66383	149.8113	0.02826863
21.71716	149.8079	-.03094470
21.76716	149.8044	-.08143300
21.82050	149.8002	-0.1377429
21.87050	149.7974	-0.1888696
21.92216	149.7932	-0.2415146
21.97383	149.7890	-0.2947377
22.02550	149.7858	-0.3487078
22.07716	149.7810	-0.4017785
22.12883	149.7779	-0.4573982
22.18050	149.7748	-0.5115976
22.23216	149.7708	-0.5648080
22.28383	149.7676	-0.6196015
22.33383	149.7648	-0.6694901
22.38716	149.7604	-0.7244691
22.43716	149.7578	-0.7776803
22.49050	149.7540	-0.8295678
22.54050	149.7512	-0.8802056
22.59383	149.7486	-0.9316554
22.64383	149.7450	-0.9780566
22.69716	149.7414	-1.029646
22.74716	149.7378	-1.075931
22.80050	149.7359	-1.122975
22.85050	149.7323	-1.168215
22.90383	149.7297	-1.216348
22.95383	149.7255	-1.258124
23.00550	149.7230	-1.302854
23.05716	149.7202	-1.344235
23.10883	149.7163	-1.384798
23.16050	149.7137	-1.424476
23.21216	149.7109	-1.464370
23.26383	149.7072	-1.501980
23.31550	149.7049	-1.539883
23.36716	149.7015	-1.575528
23.41716	149.6992	-1.608961
23.47050	149.6976	-1.643320
23.52050	149.6953	-1.676673
23.57383	149.6935	-1.710706
23.62383	149.6909	-1.739858
23.67717	149.6898	-1.772228
23.72716	149.6873	-1.797665
23.78050	149.6861	-1.826538
23.83050	149.6839	-1.848794
23.88383	149.6830	-1.872833
23.93383	149.6812	-1.894633
23.98716	149.6795	-1.913516
24.03717	149.6774	-1.931208
24.08883	149.6771	-1.947888
24.14050	149.6750	-1.962097
24.19216	149.6731	-1.976810
24.24383	149.6723	-1.991123
24.29550	149.6705	-2.005312
24.34716	149.6692	-2.019344
24.39883	149.6689	-2.034411
24.45050	149.6669	-2.046388
24.50050	149.6673	-2.059100
24.55383	149.6662	-2.069582
24.60383	149.6644	-2.077835
24.65716	149.6646	-2.087102
24.70717	149.6632	-2.094793
24.76050	149.6638	-2.103328
24.81050	149.6619	-2.111187
24.86383	149.6615	-2.119762
24.91383	149.6606	-2.127826
24.96716	149.6601	-2.136454
25.01716	149.6594	-2.144545
25.07050	149.6582	-2.153163
25.12050	149.6590	-2.161307
25.17216	149.6584	-2.169656
25.22383	149.6576	-2.178008
25.27550	149.6581	-2.186270
25.32716	149.6579	-2.194462
25.37883	149.6567	-2.202392
25.43050	149.6566	-2.210167
25.48216	149.6558	-2.217776
25.53383	149.6559	-2.225208
25.58383	149.6550	-2.232204
25.63716	149.6556	-2.239533
25.68717	149.6555	-2.246226
25.74050	149.6540	-2.253279
25.79050	149.6550	-2.259841
25.84383	149.6543	-2.266582
25.89383	149.6547	-2.272842
25.94717	149.6540	-2.279266
25.99716	149.6550	-2.285175
26.05050	149.6542	-2.291350
26.10050	149.6538	-2.296876
26.15383	149.6548	-2.302710
26.20383	149.6538	-2.307958
26.25550	149.6538	-2.313254
26.30716	149.6542	-2.318438
26.35883	149.6538	-2.323399
26.41050	149.6533	-2.328212
26.46216	149.6530	-2.332860
26.51383	149.6527	-2.337329
26.56550	149.6528	-2.341684
26.61716	149.6528	-2.345896
26.66716	149.6520	-2.349816
26.72050	149.6513	-2.353866
26.77050	149.6525	-2.357654
26.82383	149.6520	-2.361566
26.87383	149.6515	-2.365104
26.92717	149.6519	-2.368846
26.97717	149.6522	-2.372156
27.03050	149.6509	-2.375632
27.08050	149.6515	-2.378755
27.13383	149.6506	-2.381879
27.18383	149.6507	-2.384737
27.23716	149.6497	-2.387642
27.28717	149.6498	-2.390293
27.33883	149.6495	-2.393005
27.39050	149.6491	-2.395675
27.44216	149.6496	-2.398352
27.49383	149.6496	-2.400985
27.54550	149.6493	-2.403543
27.59716	149.6499	-2.406130
27.64883	149.6495	-2.408624
27.70050	149.6491	-2.410985
27.75050	149.6501	-2.413234
27.80383	149.6495	-2.415548
27.85383	149.6493	-2.417624
27.90716	149.6495	-2.419816
27.95716	149.6494	-2.421765
28.01050	149.6499	-2.423820
28.06050	149.6490	-2.425619
28.11383	149.6490	-2.427522
28.16383	149.6492	-2.429199
28.21716	149.6495	-2.430899
28.26716	149.6496	-2.432432
28.32050	149.6491	-2.434094
28.37050	149.6483	-2.435630
28.42216	149.6495	-2.437156
28.47383	149.6486	-2.438624
28.52550	149.6489	-2.440186
28.57717	149.6481	-2.441639
28.62883	149.6490	-2.443096
28.68050	149.6487	-2.444467
28.73216	149.6485	-2.445781
28.78383	149.6483	-2.446950
28.83383	149.6476	-2.447975
28.88716	149.6482	-2.449054
28.93717	149.6476	-2.450063
28.99050	149.6477	-2.451080
29.04050	149.6465	-2.451992
29.09383	149.6472	-2.452916
29.14383	149.6465	-2.453846
29.19717	149.6461	-2.454795
29.24716	149.6463	-2.455668
29.30050	149.6458	-2.456634
29.35050	149.6462	-2.457506
29.40383	149.6464	-2.458449
29.45383	149.6457	-2.459343
29.50550	149.6460	-2.460348
29.55716	149.6461	-2.461425
29.60883	149.6470	-2.462505
29.66050	149.6478	-2.463575
29.71216	149.6472	-2.464655
29.76383	149.6472	-2.465674
29.81550	149.6473	-2.466656
29.86716	149.6474	-2.467629
29.91716	149.6489	-2.468523
29.97050	149.6489	-2.469380
30.02050	149.6481	-2.470160
30.07383	149.6485	-2.470951
30.12383	149.6480	-2.471637
30.17717	149.6484	-2.472389
30.22717	149.6476	-2.472986
30.28050	149.6479	-2.473694
30.33050	149.6479	-2.474285
30.38383	149.6474	-2.474960
30.43383	149.6474	-2.475443
30.48716	149.6469	-2.476005
30.53717	149.6473	-2.476466
30.58883	149.6470	-2.476972
30.64050	149.6478	-2.477437
30.69216	149.6474	-2.477902
30.74383	149.6476	-2.478466
30.79550	149.6467	-2.478968
30.84716	149.6472	-2.479597
30.89883	149.6465	-2.480174
30.95050	149.6468	-2.480667
31.00050	149.6474	-2.481119
31.05383	149.6469	-2.481502
31.10383	149.6465	-2.481910
31.15716	149.6456	-2.482247
31.20716	149.6460	-2.482588
31.26050	149.6461	-2.482933
31.31050	149.6463	-2.483344
31.36383	149.6456	-2.483630
31.41383	149.6460	-2.484058
31.46716	149.6461	-2.484499
31.51716	149.6465	-2.484945
31.57050	149.6470	-2.485501
31.62050	149.6464	-2.486040
31.67216	149.6467	-2.486550
31.72383	149.6472	-2.487056
31.77550	149.6469	-2.487554
31.82717	149.6470	-2.488035
31.87883	149.6469	-2.488504
31.93050	149.6467	-2.488924
31.98216	149.6471	-2.489364
32.03383	149.6472	-2.489739
32.08383	149.6468	-2.490073
32.13716	149.6461	-2.490390
32.18716	149.6472	-2.490785
32.24050	149.6467	-2.491216
32.29050	149.6454	-2.491456
32.34384	149.6467	-2.491823
32.39383	149.6459	-2.492068
32.44717	149.6463	-2.492277
32.49716	149.6461	-2.492485
32.55050	149.6450	-2.492580
32.60050	149.6453	-2.492719
32.65383	149.6459	-2.492941
32.70383	149.6454	-2.493117
32.75550	149.6454	-2.493343
32.80716	149.6459	-2.493652
32.85883	149.6460	-2.493971
32.91050	149.6469	-2.494388
32.96216	149.6464	-2.494808
33.01383	149.6461	-2.495251
33.06550	149.6458	-2.495581
33.11716	149.6467	-2.495915
33.16716	149.6458	-2.496282
33.22050	149.6460	-2.496498
33.27050	149.6456	-2.496713
33.32383	149.6470	-2.496958
33.37383	149.6459	-2.497072
33.42717	149.6465	-2.497386
33.47717	149.6464	-2.497670
33.53050	149.6471	-2.497950
33.58050	149.6469	-2.498205
33.63383	149.6470	-2.498438
33.68384	149.6469	-2.498622
33.73717	149.6464	-2.498825
33.78717	149.6469	-2.499063
33.83883	149.6471	-2.499218
33.89050	149.6466	-2.499358
33.94216	149.6466	-2.499495
33.99383	149.6460	-2.499608
34.04550	149.6468	-2.499772
34.09716	149.6454	-2.499920
34.14883	149.6464	-2.500086
34.20050	149.6464	-2.500246
34.25050	149.6466	-2.500336
34.30383	149.6459	-2.500374
34.35383	149.6462	-2.500520
34.40716	149.6459	-2.500621
34.45716	149.6451	-2.500872
34.51050	149.6452	-2.501064
34.56050	149.6465	-2.501323
34.61383	149.6461	-2.501582
34.66383	149.6459	-2.501930
34.71716	149.6466	-2.502280
34.76716	149.6454	-2.502552
34.82050	149.6462	-2.502858
34.87050	149.6465	-2.503054
34.92216	149.6466	-2.503294
34.97383	149.6462	-2.503489
35.02550	149.6462	-2.503716
35.07717	149.6463	-2.503875
35.12883	149.6466	-2.504086
35.18050	149.6464	-2.504283
35.23216	149.6460	-2.504380
35.28383	149.6468	-2.504564
35.33383	149.6467	-2.504682
35.38716	149.6459	-2.504900
35.43716	149.6460	-2.505051
35.49050	149.6468	-2.505258
35.54050	149.6458	-2.505380
35.59384	149.6461	-2.505558
35.64383	149.6465	-2.505737
35.69717	149.6459	-2.505850
35.74716	149.6457	-2.505926
35.80050	149.6452	-2.505940
35.85050	149.6450	-2.505970
35.90383	149.6448	-2.505932
35.95383	149.6444	-2.505894
36.00550	149.6442	-2.505832
36.05716	149.6444	-2.505850
36.10883	149.6450	-2.505835
36.16050	149.6451	-2.505943
36.21216	149.6452	-2.506042
36.26383	149.6452	-2.506226
36.31550	149.6444	-2.506398
36.36716	149.6451	-2.506638
36.41716	149.6453	-2.506906
36.47050	149.6459	-2.507231
36.52050	149.6455	-2.507480
36.57383	149.6457	-2.507770
36.62383	149.6458	-2.508002
36.67717	149.6469	-2.508273
36.72717	149.6461	-2.508443
36.78050	149.6454	-2.508581
36.83050	149.6454	-2.508640
36.88383	149.6456	-2.508752
36.93384	149.6446	-2.508715
36.98717	149.6452	-2.508723
37.03717	149.6454	-2.508617
37.08883	149.6451	-2.508637
37.14050	149.6446	-2.508702
37.19216	149.6458	-2.508944
37.24383	149.6461	-2.509141
37.29550	149.6453	-2.509358
37.34716	149.6464	-2.509611
37.39883	149.6456	-2.509870
37.45050	149.6462	-2.510164
37.50050	149.6467	-2.510326
37.55383	149.6465	-2.510425
37.60383	149.6469	-2.510508
37.65716	149.6465	-2.510563
37.70716	149.6462	-2.510660
37.76050	149.6465	-2.510726
37.81050	149.6453	-2.510752
37.86383	149.6454	-2.510768
37.91383	149.6446	-2.510704
37.96716	149.6459	-2.510632
38.01716	149.6440	-2.510595
38.07050	149.6448	-2.510584
38.12050	149.6449	-2.510602
38.17216	149.6456	-2.510723
38.22383	149.6448	-2.510824
38.27550	149.6454	-2.511039
38.32717	149.6456	-2.511290
38.37883	149.6456	-2.511491
38.43050	149.6456	-2.511710
38.48216	149.6466	-2.511873
38.53383	149.6461	-2.511953
38.58383	149.6451	-2.511966
38.63716	149.6449	-2.511938
38.68716	149.6453	-2.511961
38.74050	149.6448	-2.511868
38.79050	149.6450	-2.511804
38.84384	149.6444	-2.511635
38.89383	149.6445	-2.511604
38.94717	149.6444	-2.511516
38.99716	149.6453	-2.511456
39.05050	149.6444	-2.511431
39.10050	149.6444	-2.511402
39.15383	149.6440	-2.511488
39.20383	149.6448	-2.511681
39.25550	149.6449	-2.511945
39.30716	149.6451	-2.512200
39.35883	149.6455	-2.512397
39.41050	149.6461	-2.512666
39.46216	149.6454	-2.512845
39.51383	149.6459	-2.513023
39.56550	149.6456	-2.513220
39.61716	149.6458	-2.513313
39.66716	149.6462	-2.513404
39.72050	149.6461	-2.513430
39.77050	149.6461	-2.513520
39.82383	149.6458	-2.513598
39.87383	149.6459	-2.513668
39.92717	149.6465	-2.513778
39.97717	149.6461	-2.513786
40.03050	149.6456	-2.513790
40.08050	149.6453	-2.513790
40.13383	149.6459	-2.513768
40.18384	149.6449	-2.513715
40.23717	149.6450	-2.513584
40.28717	149.6449	-2.513521
40.33883	149.6444	-2.513466
40.39050	149.6448	-2.513427
40.44216	149.6450	-2.513472
40.49383	149.6453	-2.513563
40.54550	149.6455	-2.513740
40.59716	149.6454	-2.513845
40.64883	149.6455	-2.514039
40.70050	149.6459	-2.514222
40.75050	149.6459	-2.514427
40.80383	149.6454	-2.514646
40.85383	149.6461	-2.514883
40.90716	149.6454	-2.514978
40.95716	149.6460	-2.515038
41.01050	149.6458	-2.515095
41.06050	149.6455	-2.515126
41.11383	149.6451	-2.515032
41.16383	149.6444	-2.515013
41.21717	149.6443	-2.514924
41.26717	149.6448	-2.514821
41.32050	149.6440	-2.514714
41.37050	149.6436	-2.514646
41.42216	149.6440	-2.514602
41.47383	149.6443	-2.514630
41.52550	149.6448	-2.514739
41.57717	149.6454	-2.514841
41.62883	149.6442	-2.515028
41.68050	149.6448	-2.515236
41.73217	149.6449	-2.515504
41.78383	149.6454	-2.515716
41.83383	149.6453	-2.515868
41.88716	149.6448	-2.516107
41.93716	149.6451	-2.516218
41.99050	149.6450	-2.516309
42.04050	149.6456	-2.516301
42.09384	149.6454	-2.516314
42.14383	149.6449	-2.516344
42.19717	149.6461	-2.516519
42.24716	149.6453	-2.516632
42.30050	149.6452	-2.516701
42.35050	149.6464	-2.516801
42.40383	149.6461	-2.516880
42.45383	149.6460	-2.517014
42.50550	149.6454	-2.517025
42.55717	149.6462	-2.517155
42.60883	149.6459	-2.517186
42.66050	149.6462	-2.517204
42.71216	149.6451	-2.517246
42.76383	149.6452	-2.517335
42.81550	149.6454	-2.517360
42.86716	149.6456	-2.517417
42.91716	149.6462	-2.517432
42.97050	149.6453	-2.517431
43.01717	149.6454	-2.517547
43.07050	149.7327	-4.141894
43.12050	150.0872	-7.450474
43.17216	150.6342	-10.20727
43.22383	151.3144	-12.43366
43.27550	152.0864	-14.07912
43.32717	152.9256	-15.31126
43.37883	153.8121	-16.22001
43.43050	154.7315	-16.89459
43.48217	155.6768	-17.40616
43.53383	156.6385	-17.79815
43.58383	157.5818	-18.09860
43.63716	158.5988	-18.35419
43.68716	159.5609	-18.54146
43.74050	160.5911	-18.73223
43.79050	161.5608	-18.87905
43.84384	162.5995	-19.02510
43.89383	163.5756	-19.15972
43.94717	164.6196	-19.29275
43.99716	165.5996	-19.42020
44.05050	166.6461	-19.55412
44.10050	167.6292	-19.68057
44.15383	168.6784	-19.81383
44.20383	169.6619	-19.93789
44.25550	170.6776	-20.08838
44.30717	171.6960	-20.24306
44.35883	172.7144	-20.39102
44.41050	173.7334	-20.54186
44.46216	174.7521	-20.69385
44.51383	175.7715	-20.86125
44.56550	176.7904	-21.02530
44.61716	177.8099	-21.19310
44.66716	178.7965	-21.38570
44.72050	179.8483	-21.57603
44.77050	180.8345	-21.77994
44.82383	181.8842	-22.00583
44.87383	182.8700	-22.23593
44.92717	183.9204	-22.46715
44.97717	184.9044	-22.72480
45.03050	185.9544	-22.99377
45.08050	186.9373	-23.26729
45.13383	187.9848	-23.57712
45.18383	188.9663	-23.87298
45.23717	190.0121	-24.21506
45.28717	190.9922	-24.54136
45.33883	192.0045	-24.89783
45.39050	193.0150	-25.28247
45.44217	194.0256	-25.66304
45.49383	195.0346	-26.08762
45.54550	196.0422	-26.53922
45.59716	197.0478	-27.01581
45.64883	198.0524	-27.53958
45.70050	199.0530	-28.10082
45.75050	200.0214	-28.68481
45.80383	201.0494	-29.39782
45.85383	202.0108	-30.13050
45.90717	203.0293	-31.02647
45.95717	203.9787	-32.00196
46.01050	204.9828	-33.24105
46.06050	205.9160	-34.50303
46.11383	206.9031	-36.10217
46.16383	207.8140	-37.89074
46.21717	208.7696	-40.11445
46.26717	209.6504	-42.43180
46.32050	210.5756	-45.03517
46.37050	211.4353	-47.46652
46.42216	212.3264	-49.57693
46.47383	213.2388	-51.11010
46.52550	214.1687	-52.65752
46.57717	215.1016	-54.36669
46.62883	216.0336	-56.17161
46.68050	216.9636	-57.79472
46.73217	217.9180	-58.21394
46.78383	218.9380	-56.58450
46.83383	220.0262	-52.66479
46.88716	221.2774	-48.24926
46.93716	222.5040	-43.28946
46.99050	223.8732	-36.92497
47.04050	225.1807	-32.34895
47.09384	226.5154	-29.53972
47.14383	227.7014	-27.78774
47.19717	228.9093	-26.50346
47.24716	230.0044	-25.66720
47.30050	231.1422	-25.02168
47.35050	232.1894	-24.60350
47.40383	233.2925	-24.30275
47.45383	234.3167	-24.09951
47.50550	235.3680	-23.96338
47.55717	236.4139	-23.85920
47.60883	237.4556	-23.79998
47.66050	238.4945	-23.76421
47.71216	239.5316	-23.75186
47.76383	240.5666	-23.74793
47.81550	241.6006	-23.74784
47.86716	242.6336	-23.74856
47.91716	243.6337	-23.75222
47.97050	244.6982	-23.76220
48.02050	245.6972	-23.77860
48.07383	246.7620	-23.80367
48.12383	247.7604	-23.82980
48.17717	248.8252	-23.86345
48.22717	249.8242	-23.89576
48.28050	250.8895	-23.93304
48.33050	251.8871	-23.97226
48.38383	252.9525	-24.01170
48.43383	253.9496	-24.05102
48.48717	255.0145	-24.10387
48.53717	256.0114	-24.15641
48.58883	257.0424	-24.21129
48.64050	258.0728	-24.26813
48.69217	259.1033	-24.31960
48.74383	260.1339	-24.36727
48.79550	261.1629	-24.41662
48.84716	262.1935	-24.48062
48.89883	263.2251	-24.52568
48.95050	264.2556	-24.57650
49.00050	265.2530	-24.61952
49.05383	266.3170	-24.66570
49.10383	267.3146	-24.70491
49.15717	268.3784	-24.74864
49.20717	269.3756	-24.79491
49.26050	270.4396	-24.83484
49.31050	271.4358	-24.87072
49.36383	272.4996	-24.92024
49.41383	273.4979	-24.96139
49.46717	274.5625	-24.98190
49.51383	275.4922	-25.04558
49.56550	276.3615	-26.01297
49.61716	276.6402	-19.67588
49.66716	276.5435	-12.28421
49.72050	276.1703	-5.655190
49.77050	275.6509	-0.9062061
49.82383	274.9659	2.865597
49.87383	274.2371	5.455509
49.92717	273.3941	7.478702
49.97717	272.5573	8.856775
50.03050	271.6304	9.922266
50.08050	270.7341	10.65574
50.13383	269.7605	11.23301
50.18383	268.8314	11.63821
50.23717	267.8300	11.95934
50.28717	266.8817	12.18605
50.33883	265.8953	12.36702
50.39050	264.9025	12.50904
50.44217	263.9065	12.61439
50.49383	262.9059	12.70273
50.54550	261.9022	12.77700
50.59716	260.8961	12.83649
50.64883	259.8878	12.88717
50.70050	258.8766	12.93059
50.75050	257.8972	12.96772
50.80383	256.8526	13.00160
50.85383	255.8708	13.03246
50.90717	254.8216	13.06776
50.95717	253.8383	13.09625
51.01050	252.7867	13.12636
51.06050	251.8013	13.14596
51.11383	250.7485	13.16792
51.16383	249.7610	13.18953
51.21717	248.7080	13.21131
51.26716	247.7195	13.23251
51.32050	246.6648	13.25383
51.37050	245.6764	13.26996
51.42217	244.6536	13.28939
51.47383	243.6310	13.30276
51.52550	242.6087	13.31745
51.57717	241.5853	13.33142
51.62883	240.5619	13.35022
51.68050	239.5380	13.36673
51.73217	238.5146	13.38356
51.78383	237.4901	13.39860
51.83383	236.4992	13.42120
51.88716	235.4419	13.43830
51.93716	234.4502	13.45203
51.99050	233.3926	13.46182
52.04050	232.4002	13.47264
52.09384	231.3417	13.48261
52.14384	230.3491	13.49405
52.19717	229.2904	13.50351
52.24717	228.2983	13.51627
52.30050	227.2389	13.53419
52.35050	226.2459	13.54410
52.40383	225.1867	13.55877
52.45383	224.1951	13.57044
52.50550	223.1686	13.58484
52.55717	222.1439	13.59884
52.60883	221.1173	13.61245
52.66050	220.0908	13.62521
52.71216	219.0649	13.63873
52.76382	218.0375	13.65208
52.81550	217.0102	13.66136
52.86716	215.9846	13.67091
52.91716	214.9908	13.68224
52.97050	213.9309	13.69256
53.02050	212.9379	13.70257
53.07383	211.8783	13.71349
53.12383	210.8850	13.72420
53.17717	209.8256	13.73415
53.22717	208.8317	13.74455
53.28050	207.7728	13.75568
53.33050	206.7791	13.76631
53.38383	205.7198	13.77688
53.43383	204.7260	13.78876
53.48717	203.6660	13.80080
53.53716	202.6725	13.81074
53.58882	201.6454	13.82131
53.64050	200.6172	13.83207
53.69216	199.5901	13.84302
53.74382	198.5625	13.85328
53.79550	197.5373	13.86362
53.84716	196.5102	13.87428
53.89883	195.4838	13.88702
53.95050	194.4578	13.90346
54.00050	193.4628	13.91588
54.05383	192.4029	13.92811
54.10383	191.4094	13.93837
54.15717	190.3487	13.95084
54.20717	189.3531	13.96154
54.26050	188.2928	13.97158
54.31050	187.2984	13.98192
54.36382	186.2385	13.99486
54.41382	185.2449	14.00928
54.46717	184.1845	14.01954
54.51716	183.1891	14.02981
54.57050	182.1292	14.04001
54.62050	181.1340	14.04971
54.67217	180.1079	14.06073
54.72382	179.0802	14.07392
54.77550	178.0547	14.08394
54.82717	177.0267	14.10288
54.87883	176.0000	14.11789
54.93050	174.9712	14.13256
54.98217	173.9441	14.14446
55.03383	172.9160	14.15924
55.08383	171.9217	14.17230
55.13716	170.8610	14.18840
55.18716	169.8676	14.21710
55.24050	168.8084	14.30647
55.29050	167.8177	14.51201
55.34384	166.7661	14.84608
55.39384	165.7906	15.40059
55.44717	164.7703	16.52234
55.49717	163.8473	18.32504
55.55050	162.9116	21.26886
55.60050	162.0912	24.90209
55.65383	161.2646	29.18242
55.70383	160.5111	32.99158
55.75550	159.7221	36.20406
55.80717	158.8941	38.36098
55.85883	158.0077	39.35141
55.91050	157.0559	39.30875
55.96216	156.0399	38.42328
56.01382	154.9674	36.72004
56.06550	153.8501	34.63718
56.11716	152.7019	32.40404
56.16716	151.5760	30.17847
56.22050	150.3687	27.94133
56.27050	149.2396	26.03974
56.32383	148.0472	24.26341
56.37383	146.9416	22.81069
56.42717	145.7778	21.51160
56.47717	144.6970	20.45723
56.53050	143.5585	19.51278
56.58050	142.5022	18.79304
56.63383	141.3859	18.14344
56.68383	140.3482	17.64924
56.73717	139.2492	17.22150
56.78716	138.2252	16.89500
56.83882	137.1734	16.61263
56.89050	136.1244	16.34551
56.94216	135.0764	16.06730
56.99382	134.0295	15.84902
57.04550	132.9862	15.67782
57.09716	131.9454	15.52149
57.14883	130.9057	15.40144
57.20050	129.8678	15.28160
57.25050	128.8641	15.18827
57.30383	127.7956	15.08483
57.35383	126.7919	15.00457
57.40717	125.7243	14.91975
57.45717	124.7228	14.84114
57.51050	123.6553	14.75907
57.56050	122.6541	14.68439
57.61382	121.5864	14.61059
57.66382	120.5859	14.54693
57.71717	119.5203	14.47498
57.76716	118.5189	14.41677
57.82050	117.4520	14.35912
57.87050	116.4517	14.29290
57.92217	115.4182	14.22775
57.97382	114.3852	14.13301
58.02550	113.3516	14.10923
58.07717	112.3190	14.05679
58.12883	111.2870	14.00814
58.18050	110.2540	13.95900
58.23217	109.2215	13.91071
58.28383	108.1882	13.86422
58.33383	107.1898	13.81010
58.38716	106.1230	13.76287
58.43716	105.1246	13.71379
58.49050	104.0588	13.66749
58.54050	103.0598	13.62388
58.59384	101.9937	13.58420
58.64384	100.9952	13.54058
58.69717	99.92980	13.49814
58.74717	98.93011	13.44692
58.80050	97.86562	13.39967
58.85050	96.86658	13.35727
58.90383	95.80132	13.31383
58.95383	94.80278	13.26972
59.00550	93.77097	13.22607
59.05717	92.74024	13.18563
59.10883	91.70822	13.14879
59.16050	90.67672	13.10912
59.21216	89.64528	13.07112
59.26382	88.61264	13.03171
59.31550	87.58208	12.98971
59.36716	86.55098	12.95459
59.41716	85.55168	12.91664
59.47050	84.48812	12.87427
59.52050	83.48861	12.83902
59.57383	82.42430	12.80341
59.62383	81.42588	12.76956
59.67717	80.36137	12.73049
59.72717	79.36374	12.69766
59.78050	78.29922	12.65872
59.83050	77.30063	12.62778
59.88383	76.23608	12.58771
59.93383	75.23791	12.55435
59.98717	74.17306	12.51566
60.03716	73.17422	12.47974
60.08882	72.14234	12.43724
60.14050	71.11091	12.40124
60.19216	70.07993	12.36595
60.24382	69.04879	12.32975
60.29550	68.01686	12.29349
60.34716	66.98645	12.25151
60.39883	65.95429	12.21811
60.45050	64.92284	12.18040
60.50050	63.92402	12.13730
60.55383	62.85932	12.09737
60.60383	61.86072	12.04794
60.65717	60.79580	12.00724
60.70717	59.79794	11.96898
60.76050	58.73306	11.92759
60.81050	57.73492	11.88929
60.86382	56.66894	11.85175
60.91382	55.66991	11.81083
60.96717	54.60598	11.76487
61.01716	53.60672	11.72684
61.07050	52.54003	11.68127
61.12050	51.54221	11.64275
61.17217	50.50925	11.59908
61.22382	49.47654	11.55725
61.27550	48.44436	11.50757
61.32717	47.41098	11.46668
61.37883	46.37950	11.42952
61.43050	45.34672	11.38703
61.48217	44.31406	11.34120
61.53383	43.28140	11.29684
61.58383	42.28224	11.24690
61.63716	41.21483	11.18934
61.68716	40.21603	11.13815
61.74050	39.14868	11.08208
61.79050	38.14958	11.02348
61.84384	37.08213	10.96180
61.89384	36.08162	10.90816
61.94717	35.01422	10.84574
61.99717	34.01242	10.78764
62.05050	32.94466	10.72521
62.10050	31.94294	10.66113
62.15383	30.87629	10.60302
62.20383	29.87517	10.54990
62.25550	28.84114	10.48908
62.30717	27.80738	10.43336
62.35883	26.77229	10.37153
62.41050	25.73831	10.29144
62.46216	24.70332	10.26120
62.51050	23.73574	10.26191
62.56050	22.86199	10.53013
62.61382	22.56515	7.095704
62.66382	22.64126	3.363959
62.71717	22.99115	-.01902201
62.76716	23.49127	-2.418862
62.82050	24.16178	-4.363836
62.87050	24.88048	-5.729538
62.92217	25.68894	-6.788571
62.97382	26.54890	-7.595534
63.02550	27.44717	-8.205282
63.07717	28.37155	-8.671007
63.12883	29.31726	-9.033784
63.18050	30.27721	-9.316725
63.23217	31.24838	-9.537719
63.28383	32.22970	-9.723062
63.33383	33.18615	-9.861011
63.38716	34.21225	-9.985063
63.43716	35.17733	-10.08366
63.49050	36.21106	-10.16986
63.54050	37.18476	-10.24702
63.59384	38.22400	-10.31967
63.64384	39.20045	-10.38310
63.69717	40.24390	-10.44090
63.74717	41.22579	-10.49202
63.80050	42.27191	-10.54041
63.85050	43.25504	-10.58937
63.90383	44.30424	-10.64041
63.95383	45.28991	-10.69151
64.00550	46.30758	-10.73701
64.05717	47.32574	-10.78966
64.10884	48.34705	-10.84752
64.16050	49.36678	-10.89740
64.21217	50.38784	-10.95327
64.26384	51.40941	-11.01140
64.31550	52.43082	-11.06664
64.36718	53.45328	-11.12818
64.41717	54.44444	-11.17684
64.47050	55.50105	-11.23664
64.52050	56.49140	-11.29483
64.57384	57.54868	-11.35535
64.62383	58.54130	-11.41331
64.67718	59.59809	-11.47176
64.72718	60.59250	-11.52704
64.78050	61.65064	-11.59686
64.83050	62.64440	-11.65875
64.88384	63.70328	-11.72173
64.93384	64.69800	-11.77757
64.98717	65.75711	-11.83295
65.03717	66.75152	-11.90038
65.08884	67.77758	-11.96091
65.14050	68.80454	-12.02744
65.19217	69.83232	-12.09525
65.24384	70.85938	-12.15636
65.29550	71.88606	-12.22529
65.34717	72.91480	-12.29274
65.39883	73.94099	-12.35873
65.45050	74.96892	-12.42919
65.50050	75.96340	-12.49122
65.55384	77.02414	-12.56316
65.60384	78.01843	-12.63556
65.65718	79.07950	-12.71224
65.70718	80.07462	-12.78483
65.76050	81.13550	-12.85786
65.81050	82.13144	-12.93323
65.86384	83.19242	-13.00046
65.91382	84.18750	-13.07370
65.96718	85.24970	-13.15141
66.01716	86.24486	-13.22302
66.07050	87.30656	-13.29878
66.12050	88.30162	-13.37136
66.17218	89.32916	-13.44877
66.22384	90.35874	-13.53384
66.27550	91.38699	-13.60376
66.32718	92.41519	-13.68433
66.37884	93.44470	-13.75711
66.43050	94.47392	-13.83192
66.48218	95.50219	-13.91032
66.53384	96.53121	-13.98182
66.58384	97.52701	-14.05010
66.63718	98.58918	-14.13036
66.68718	99.58501	-14.20419
66.74050	100.6480	-14.27582
66.79050	101.6438	-14.35148
66.84384	102.7066	-14.43174
66.89384	103.7029	-14.50364
66.94718	104.7654	-14.58460
66.99718	105.7602	-14.66259
67.05050	106.8223	-14.74449
67.10050	107.8182	-14.82391
67.15384	108.8799	-14.90346
67.20384	109.8737	-14.99149
67.25550	110.9031	-15.07720
67.30718	111.9310	-15.16446
67.35884	112.9585	-15.24595
67.41050	113.9870	-15.33599
67.46218	115.0149	-15.42192
67.51384	116.0440	-15.51041
67.56550	117.0726	-15.58428
67.61718	118.1009	-15.67520
67.66718	119.0956	-15.76269
67.72050	120.1570	-15.85582
67.77050	121.1534	-15.94650
67.82384	122.2154	-16.04188
67.87384	123.2099	-16.12898
67.92718	124.2719	-16.22759
67.97718	125.2668	-16.31706
68.03050	126.3284	-16.41133
68.08050	127.3226	-16.49750
68.13384	128.3840	-16.60228
68.18384	129.3790	-16.69014
68.23718	130.4384	-16.79895
68.28718	131.4340	-16.90267
68.33884	132.4617	-16.99308
68.39050	133.4890	-17.09793
68.44218	134.5163	-17.20376
68.49384	135.5430	-17.30786
68.54550	136.5694	-17.42473
68.59718	137.5957	-17.54035
68.64884	138.6236	-17.65037
68.70050	139.6498	-17.76205
68.75050	140.6445	-17.87155
68.80384	141.7040	-17.99400
68.85384	142.6978	-18.10372
68.90718	143.7575	-18.22486
68.95718	144.7507	-18.33726
69.01050	145.8117	-18.44656
69.06050	146.8036	-18.57031
69.11384	147.8648	-18.68587
69.16382	148.8584	-18.79642
69.21718	149.9188	-18.90795
69.26716	150.9124	-19.02416
69.32050	151.9722	-19.13966
69.37050	152.9658	-19.24737
69.42218	153.9934	-19.36681
69.47384	155.0206	-19.47676
69.52550	156.0471	-19.58052
69.57718	157.0754	-19.67987
69.62884	158.1040	-19.77170
69.68050	159.1323	-19.85510
69.73218	160.1613	-19.93318
69.78384	161.1910	-19.99968
69.83384	162.1872	-20.04538
69.88718	163.2516	-20.08706
69.93718	164.2508	-20.11664
69.99050	165.3165	-20.13859
70.04050	166.3164	-20.15988
70.09384	167.3823	-20.19506
70.14384	168.3806	-20.22804
70.19718	169.4456	-20.27572
70.24718	170.4427	-20.35146
70.30050	171.5077	-20.44784
70.35050	172.5035	-20.54176
70.40384	173.5661	-20.64780
70.45384	174.5614	-20.74957
70.50550	175.5888	-20.87762
70.55718	176.6162	-21.00604
70.60884	177.6426	-21.15112
70.66050	178.6674	-21.31426
70.71218	179.6917	-21.48545
70.76384	180.7152	-21.68668
70.81550	181.7361	-21.91328
70.86718	182.7578	-22.16326
70.91718	183.7443	-22.42543
70.97050	184.7948	-22.73342
71.02050	185.7773	-23.05342
71.07384	186.8232	-23.44297
71.12384	187.8021	-23.83864
71.17718	188.8448	-24.29521
71.22718	189.8188	-24.78192
71.28050	190.8566	-25.31758
71.33050	191.8279	-25.84397
71.38384	192.8626	-26.41914
71.43384	193.8297	-26.95881
71.48718	194.8615	-27.57728
71.53718	195.8269	-28.18830
71.58884	196.8225	-28.87748
71.64050	197.8161	-29.60199
71.69218	198.8058	-30.42353
71.74384	199.7912	-31.30856
71.79550	200.7721	-32.24869
71.84718	201.7509	-33.22253
71.89884	202.7274	-34.17713
71.95050	203.7060	-35.05250
72.00050	204.6569	-35.72397
72.05384	205.6839	-36.05610
72.10384	206.6670	-35.80032
72.15718	207.7550	-34.34846
72.20718	208.8255	-32.04566
72.26050	210.0193	-29.07742
72.31050	211.1634	-26.44405
72.36384	212.3804	-24.40205
72.41382	213.4942	-23.20272
72.46718	214.6529	-22.34339
72.51716	215.7152	-21.78183
72.57050	216.8294	-21.35762
72.62050	217.8608	-21.07906
72.67218	218.9170	-20.88275
72.72384	219.9673	-20.75019
72.77550	221.0120	-20.65997
72.82718	222.0539	-20.59758
72.87884	223.0930	-20.56186
72.93050	224.1298	-20.54153
72.98218	225.1666	-20.52801
73.03384	226.2010	-20.52444
73.08384	227.1994	-20.53116
73.13718	228.2639	-20.56073
73.18718	229.2622	-20.59388
73.24050	230.3280	-20.62390
73.29050	231.3262	-20.65451
73.34384	232.3911	-20.70170
73.39384	233.3882	-20.74086
73.44718	234.4537	-20.78286
73.49718	235.4509	-20.82601
73.55050	236.5161	-20.86196
73.60050	237.5138	-20.89572
73.65384	238.5799	-20.92792
73.70384	239.5775	-20.95975
73.75550	240.6080	-20.99514
73.80718	241.6395	-21.04098
73.85884	242.6710	-21.08770
73.91050	243.7028	-21.13335
73.96218	244.7334	-21.17112
74.01384	245.7654	-21.21160
74.06550	246.7970	-21.25047
74.11718	247.8282	-21.28927
74.16718	248.8263	-21.32484
74.22050	249.8920	-21.36560
74.27050	250.8896	-21.40379
74.32384	251.9546	-21.44879
74.37384	252.9525	-21.48550
74.42718	254.0183	-21.52575
74.47718	255.0151	-21.56430
74.53050	256.0808	-21.61609
74.58050	257.0779	-21.66453
74.63384	258.1423	-21.71525
74.68384	259.1401	-21.77067
74.73718	260.2044	-21.82475
74.78718	261.2001	-21.87225
74.83884	262.2312	-21.94360
74.89050	263.2625	-22.00725
74.94218	264.2921	-22.06509
74.99384	265.3222	-22.13275
75.04550	266.3528	-22.21192
75.09718	267.3816	-22.28523
75.14884	268.4098	-22.39062
75.20050	269.4384	-22.49871
75.25050	270.4318	-22.60230
75.30384	271.4920	-22.74408
-2.000000	5.000000	0.0000000