File: 7-C1(1.2mol%)+C20(0.6mol%)(1)/matlab/150-2.txt
CLOSED
Version	1.0
Language	English
Mode	Standard
Run	30
RunSerial	12298
Instrument	DSC Q2000 V24.11 Build 124
Module	DSC Standard Cell RC
Operator
File	\\AE520-1454\Users\dsc\Desktop\Data\29-08-17-3\150-2.001
ProcName
InstSerial	2000-0883
AutoSerial	1293
Sample	150-2
Size	21.5000	mg
PanMass	Not available
PanResist	Automatic Automatic  K/W
PanFactor	Default Default
Method
Comment
Xcomment	Pan: Tzero Aluminum Hermetic
Xcomment	Gas1: Nitrogen 50.0 ml/min
Xcomment	Gas2: Nitrogen 50.0 ml/min
Text
Exotherm	UP
Kcell	1.05230
Cpconst	Standard: 0.938
Calib	-38.6961
TempCal	1	pts	157.46	156.60
TzeroDt	-87.6168 -0.0009 -1.4231
TzeroDtz	-87.6168 0.0057 6.9570
InstCalFile	Tzero: \\Ae520-1454\ta\Data\DSC\Calibration\2017\CALIBRATION\1562_RCS (90)_05_18_2017 10_50_44.TZR
InstCalFile	Baseline: \\Ae520-1454\ta\Data\DSC\Calibration\2017\2017-05-17_Calibration.001
InstCalFile	Sapphire: \\Ae520-1454\ta\Data\DSC\Calibration\2017\2017-05-17_Saphire.001
InstCalDate	Tzero 2017-05-18 Time 10:50:44
TempRange	-87.39 to 398.39 °C at 10.00 °C/min Heat Only
AutoZero	Delta T Offset 0.000 uV
AutoZero	Delta T0 Offset 0.000 uV
MultiptCal	0
MultiPtDesc	0) Not set
AutoCellConst	Calibration Date 2017-05-18 16:59:28
Controls	Gas 1  Event Off  Sampling 0.2
Cell#	RC-01562
CoolingUnit	RCS (90)
SelHeatFlow	Heat Flow T4P (mW)
AutoLidII	Installed
AutoAnalysis	Off
MacroFile
Nsig	3
Sig1	Time (min)
Sig2	Temperature (°C)
Sig3	Heat Flow (mW)
Date	2017-08-31
Time	02:54:58
OrgMethod	1: Equilibrate at 80.00 °C
OrgMethod	2: Isothermal for 3.00 min
OrgMethod	3: Jump to 150.00 °C
OrgMethod	4: Mark end of cycle 1
OrgMethod	5: Isothermal for 40.00 min
OrgMethod	6: Mark end of cycle 2
OrgMethod	7: Ramp 20.00 °C/min to 280.00 °C
OrgMethod	8: Mark end of cycle 3
OrgMethod	9: Ramp 20.00 °C/min to 20.00 °C
OrgMethod	10: Mark end of cycle 4
OrgMethod	11: Ramp 20.00 °C/min to 280.00 °C
OrgMethod	12: Mark end of cycle 5
OrgFile	C:\Users\jarra\Desktop\DSC\7-C1(1.2mol%)+C20(0.6mol%)(1)\150-2.001
StartOfData
4.99994E-4	79.70681	-3.556362
0.05383332	79.75951	-2.834922
0.1038333	79.79722	-2.317355
0.1571666	79.82710	-1.898860
0.2071666	79.84796	-1.597447
0.2605000	79.86425	-1.349773
0.3105000	79.87594	-1.177967
0.3638334	79.88426	-1.039545
0.4138333	79.89038	-0.9399825
0.4671667	79.89634	-0.8634405
0.5171667	79.89770	-0.8075509
0.5705000	79.89966	-0.7685481
0.6205000	79.90063	-0.7401374
0.6721668	79.90170	-0.7214281
0.7238332	79.90241	-0.7082161
0.7755000	79.90193	-0.6994619
0.8271668	79.90138	-0.6941619
0.8788332	79.90110	-0.6908748
0.9305000	79.90122	-0.6875040
0.9821668	79.89988	-0.6840782
1.033833	79.89905	-0.6806806
1.083833	79.89835	-0.6775170
1.137166	79.89716	-0.6742250
1.187166	79.89711	-0.6713938
1.240500	79.89503	-0.6684388
1.290500	79.89454	-0.6659401
1.343833	79.89329	-0.6633962
1.393833	79.89297	-0.6612654
1.447166	79.89201	-0.6591500
1.497166	79.89165	-0.6573301
1.550500	79.89048	-0.6555728
1.600500	79.89038	-0.6541248
1.653833	79.88861	-0.6527076
1.703833	79.88824	-0.6515342
1.755500	79.88821	-0.6504602
1.807167	79.88732	-0.6495347
1.858834	79.88649	-0.6487465
1.910500	79.88593	-0.6480704
1.962166	79.88547	-0.6475330
2.013833	79.88525	-0.6470630
2.065500	79.88461	-0.6467914
2.117167	79.88295	-0.6465598
2.167167	79.88305	-0.6464529
2.220500	79.88260	-0.6464195
2.270500	79.88212	-0.6464463
2.323833	79.88188	-0.6466076
2.373834	79.88120	-0.6467597
2.427167	79.88082	-0.6470196
2.477167	79.88000	-0.6472535
2.530500	79.88056	-0.6476415
2.580500	79.87944	-0.6479582
2.633833	79.87928	-0.6484178
2.683833	79.87888	-0.6488810
2.737167	79.87811	-0.6493967
2.787167	79.87741	-0.6499988
2.838833	79.87668	-0.6505724
2.890500	79.87551	-0.6512598
2.942167	79.87593	-0.6519500
2.993833	79.87616	-0.6527016
3.040500	80.05335	-2.782524
3.093834	81.92375	-15.16358
3.143833	84.47934	-25.68110
3.197167	87.70282	-36.49003
3.247166	91.09975	-45.57254
3.300500	95.02128	-53.88630
3.350500	98.91121	-60.39630
3.403833	103.2240	-66.14116
3.453833	107.3811	-70.54968
3.505500	111.7598	-74.23951
3.557167	116.1938	-77.21924
3.608833	120.6610	-79.75860
3.660500	125.1500	-81.81860
3.712167	129.6553	-83.45486
3.763833	134.1081	-83.97908
3.815500	137.5672	-76.97621
3.867166	139.9078	-66.52185
3.917167	141.6926	-56.36421
3.970500	143.1691	-46.13571
4.020500	144.2699	-37.77816
4.073834	145.2059	-30.28304
4.123833	145.9090	-24.55899
4.177166	146.5159	-19.66324
4.227167	146.9789	-16.00371
4.280500	147.3837	-12.92444
4.330500	147.6972	-10.65631
4.383834	147.9763	-8.755128
4.433834	148.1948	-7.355859
4.487167	148.3932	-6.189730
4.537167	148.5502	-5.326182
4.588834	148.6891	-4.616828
4.640500	148.8073	-4.049903
4.692166	148.9109	-3.600920
4.743834	148.9988	-3.241210
4.795500	149.0768	-2.951970
4.847166	149.1446	-2.717467
4.898834	149.2039	-2.525920
4.950500	149.2555	-2.367266
5.000500	149.3003	-2.245428
5.053834	149.3415	-2.134299
5.103833	149.3774	-2.050401
5.157166	149.4088	-1.972469
5.207167	149.4374	-1.914682
5.260500	149.4630	-1.857190
5.310500	149.4856	-1.815383
5.363834	149.5064	-1.774306
5.413832	149.5235	-1.743734
5.467168	149.5413	-1.712937
5.517168	149.5552	-1.687373
5.570500	149.5685	-1.662684
5.620500	149.5804	-1.641174
5.672168	149.5909	-1.619937
5.723834	149.6012	-1.601606
5.775500	149.6106	-1.582267
5.827168	149.6187	-1.564819
5.878834	149.6265	-1.547378
5.930500	149.6340	-1.530879
5.982168	149.6408	-1.513941
6.033832	149.6477	-1.497028
6.083832	149.6524	-1.479912
6.137168	149.6587	-1.462276
6.187168	149.6637	-1.444444
6.240500	149.6683	-1.423415
6.290500	149.6726	-1.403915
6.343834	149.6772	-1.382525
6.393832	149.6822	-1.361808
6.447168	149.6862	-1.337343
6.497168	149.6902	-1.314171
6.550500	149.6934	-1.289498
6.600500	149.6982	-1.265121
6.653832	149.7019	-1.236464
6.703832	149.7044	-1.207475
6.755500	149.7083	-1.177717
6.807166	149.7119	-1.146274
6.858832	149.7150	-1.113719
6.910500	149.7180	-1.079064
6.962168	149.7214	-1.046526
7.013834	149.7250	-1.013927
7.065500	149.7273	-0.9791894
7.117166	149.7313	-0.9433750
7.167168	149.7333	-0.9084318
7.220500	149.7376	-0.8702750
7.270500	149.7402	-0.8339310
7.323834	149.7438	-0.7947198
7.373834	149.7466	-0.7575230
7.427168	149.7498	-0.7164074
7.477168	149.7522	-0.6758106
7.530500	149.7569	-0.6353489
7.580500	149.7600	-0.5943813
7.633832	149.7638	-0.5493597
7.683832	149.7665	-0.5068804
7.737168	149.7706	-0.4599772
7.787168	149.7733	-0.4136676
7.838834	149.7761	-0.3664649
7.890500	149.7801	-0.3183790
7.942168	149.7843	-0.2683645
7.993834	149.7881	-0.2183502
8.045500	149.7916	-0.1664998
8.097168	149.7958	-0.1149665
8.148834	149.7985	-.06318304
8.200500	149.8026	-9.4135E-3
8.250500	149.8056	0.04292032
8.303832	149.8102	0.1008473
8.353832	149.8142	0.1561599
8.407166	149.8184	0.2128061
8.457168	149.8230	0.2711000
8.510499	149.8270	0.3350922
8.560500	149.8312	0.3932140
8.613834	149.8362	0.4581050
8.663834	149.8402	0.5189160
8.717168	149.8448	0.5867706
8.767168	149.8489	0.6530255
8.820500	149.8537	0.7208937
8.870499	149.8584	0.7862890
8.922168	149.8623	0.8554188
8.973832	149.8669	0.9247368
9.025499	149.8724	0.9944005
9.077168	149.8775	1.066683
9.128834	149.8822	1.139759
9.180500	149.8867	1.212404
9.232166	149.8920	1.286712
9.283832	149.8964	1.361078
9.333832	149.9016	1.434778
9.387168	149.9077	1.512765
9.437166	149.9124	1.586330
9.490500	149.9177	1.668715
9.540500	149.9231	1.748664
9.593832	149.9280	1.837966
9.643832	149.9354	1.927954
9.697168	149.9428	2.045348
9.747168	149.9500	2.171708
9.800500	149.9614	2.335291
9.850500	149.9723	2.521085
9.903832	149.9864	2.748570
9.953834	150.0027	2.992838
10.00550	150.0198	3.273483
10.05717	150.0394	3.572334
10.10883	150.0608	3.888584
10.16050	150.0822	4.219788
10.21217	150.1039	4.551540
10.26383	150.1269	4.894649
10.31550	150.1499	5.236530
10.36717	150.1721	5.574930
10.41717	150.1947	5.899969
10.47050	150.2164	6.235868
10.52050	150.2361	6.536684
10.57383	150.2581	6.840814
10.62383	150.2755	7.116269
10.67717	150.2949	7.389272
10.72717	150.3108	7.618476
10.78050	150.3258	7.839232
10.83050	150.3385	8.028454
10.88383	150.3509	8.201366
10.93383	150.3607	8.335688
10.98717	150.3688	8.449799
11.03717	150.3752	8.527480
11.08883	150.3798	8.583528
11.14050	150.3824	8.614594
11.19217	150.3828	8.626300
11.24384	150.3825	8.627959
11.29550	150.3815	8.627121
11.34717	150.3787	8.614918
11.39883	150.3757	8.565819
11.45050	150.3706	8.481942
11.50050	150.3654	8.385538
11.55383	150.3607	8.282350
11.60383	150.3538	8.184631
11.65717	150.3468	8.076872
11.70717	150.3402	7.972968
11.76050	150.3338	7.864394
11.81050	150.3274	7.760398
11.86383	150.3204	7.650770
11.91383	150.3136	7.549243
11.96717	150.3062	7.441986
12.01717	150.2993	7.342932
12.07050	150.2924	7.239589
12.12050	150.2858	7.142330
12.17217	150.2802	7.045369
12.22383	150.2732	6.952231
12.27550	150.2674	6.859324
12.32717	150.2617	6.772901
12.37884	150.2558	6.688982
12.43050	150.2502	6.608546
12.48217	150.2456	6.530637
12.53383	150.2408	6.452395
12.58383	150.2356	6.385387
12.63717	150.2308	6.311974
12.68716	150.2262	6.248188
12.74050	150.2216	6.182006
12.79050	150.2184	6.121239
12.84383	150.2134	6.061819
12.89383	150.2095	6.009464
12.94717	150.2064	5.954388
12.99717	150.2022	5.903082
13.05050	150.1994	5.852951
13.10050	150.1963	5.805537
13.15383	150.1923	5.758980
13.20383	150.1900	5.717342
13.25550	150.1870	5.673819
13.30717	150.1848	5.632545
13.35883	150.1816	5.594104
13.41050	150.1788	5.556324
13.46217	150.1764	5.519860
13.51383	150.1736	5.485256
13.56550	150.1719	5.450257
13.61716	150.1686	5.418876
13.66716	150.1671	5.386150
13.72050	150.1638	5.355400
13.77050	150.1626	5.326086
13.82384	150.1604	5.298082
13.87384	150.1589	5.272466
13.92717	150.1568	5.244454
13.97717	150.1546	5.218850
14.03050	150.1528	5.191562
14.08050	150.1512	5.167965
14.13383	150.1500	5.143130
14.18383	150.1483	5.121334
14.23716	150.1471	5.101398
14.28717	150.1454	5.080139
14.33883	150.1441	5.060656
14.39050	150.1427	5.040992
14.44217	150.1408	5.021785
14.49384	150.1391	5.003915
14.54550	150.1380	4.985194
14.59717	150.1376	4.967478
14.64883	150.1357	4.950510
14.70050	150.1342	4.934712
14.75050	150.1332	4.918534
14.80383	150.1324	4.901696
14.85383	150.1306	4.889219
14.90717	150.1294	4.876439
14.95717	150.1286	4.864030
15.01050	150.1272	4.851368
15.06050	150.1260	4.839188
15.11383	150.1249	4.826982
15.16383	150.1242	4.815432
15.21716	150.1228	4.804537
15.26717	150.1226	4.794194
15.32050	150.1216	4.782370
15.37050	150.1211	4.773140
15.42217	150.1202	4.763116
15.47383	150.1188	4.753630
15.52550	150.1182	4.744304
15.57717	150.1186	4.734146
15.62883	150.1170	4.724784
15.68050	150.1173	4.715098
15.73216	150.1165	4.705596
15.78383	150.1166	4.696175
15.83383	150.1167	4.687113
15.88716	150.1157	4.677567
15.93717	150.1156	4.668718
15.99050	150.1145	4.659556
16.04050	150.1146	4.651175
16.09383	150.1144	4.642534
16.14383	150.1149	4.634690
16.19717	150.1142	4.626730
16.24716	150.1157	4.619611
16.30050	150.1161	4.612374
16.35050	150.1151	4.606204
16.40383	150.1154	4.600140
16.45383	150.1161	4.595022
16.50550	150.1156	4.590382
16.55716	150.1164	4.586350
16.60883	150.1166	4.582968
16.66050	150.1175	4.580322
16.71216	150.1179	4.578400
16.76383	150.1193	4.577254
16.81550	150.1192	4.576965
16.86716	150.1195	4.577471
16.91716	150.1214	4.578936
16.97050	150.1216	4.581608
17.02050	150.1224	4.585434
17.07383	150.1243	4.591574
17.12383	150.1243	4.600072
17.17716	150.1259	4.611038
17.22716	150.1274	4.624824
17.28050	150.1284	4.644440
17.33050	150.1309	4.666938
17.38383	150.1325	4.696797
17.43383	150.1337	4.728070
17.48716	150.1361	4.763248
17.53717	150.1391	4.801308
17.58883	150.1422	4.846807
17.64050	150.1438	4.897037
17.69216	150.1471	4.946574
17.74383	150.1498	4.997340
17.79550	150.1536	5.045637
17.84716	150.1554	5.092148
17.89883	150.1585	5.134586
17.95050	150.1609	5.170420
18.00050	150.1630	5.201030
18.05383	150.1651	5.226030
18.10383	150.1671	5.243699
18.15716	150.1691	5.255932
18.20716	150.1695	5.263165
18.26050	150.1699	5.267918
18.31050	150.1694	5.271820
18.36383	150.1691	5.275413
18.41383	150.1684	5.277910
18.46716	150.1678	5.279656
18.51716	150.1655	5.278538
18.57050	150.1629	5.268023
18.62050	150.1609	5.243192
18.67216	150.1582	5.204526
18.72383	150.1538	5.157010
18.77550	150.1512	5.098598
18.82716	150.1474	5.035900
18.87883	150.1434	4.970848
18.93050	150.1391	4.908632
18.98216	150.1354	4.849734
19.03383	150.1308	4.784076
19.08383	150.1262	4.715778
19.13716	150.1216	4.640286
19.18716	150.1173	4.570729
19.24050	150.1126	4.495248
19.29050	150.1069	4.427620
19.34383	150.1029	4.353020
19.39383	150.0986	4.292061
19.44716	150.0932	4.210238
19.49716	150.0880	4.127550
19.55050	150.0824	4.043163
19.60050	150.0766	3.964485
19.65383	150.0717	3.879868
19.70383	150.0672	3.802792
19.75550	150.0621	3.721488
19.80716	150.0566	3.644696
19.85883	150.0512	3.563070
19.91050	150.0458	3.483754
19.96216	150.0408	3.405043
20.01383	150.0355	3.322098
20.06550	150.0301	3.243072
20.11716	150.0245	3.164230
20.16716	150.0203	3.087148
20.22050	150.0156	3.004654
20.27050	150.0099	2.931189
20.32383	150.0051	2.850611
20.37383	150.0000	2.775352
20.42716	149.9952	2.694916
20.47716	149.9902	2.621469
20.53050	149.9844	2.543832
20.58050	149.9791	2.468876
20.63383	149.9739	2.389010
20.68383	149.9692	2.316537
20.73716	149.9636	2.239346
20.78717	149.9590	2.164284
20.83883	149.9537	2.084296
20.89050	149.9484	2.008184
20.94216	149.9431	1.929968
20.99383	149.9377	1.850397
21.04550	149.9324	1.769988
21.09716	149.9272	1.690413
21.14883	149.9228	1.607908
21.20050	149.9171	1.530082
21.25050	149.9120	1.455078
21.30383	149.9064	1.374278
21.35383	149.9016	1.298220
21.40716	149.8960	1.214426
21.45717	149.8916	1.138925
21.51050	149.8859	1.058736
21.56050	149.8815	0.9822525
21.61383	149.8761	0.9043130
21.66383	149.8711	0.8281985
21.71716	149.8662	0.7523609
21.76716	149.8616	0.6793191
21.82050	149.8564	0.6030864
21.87050	149.8519	0.5328399
21.92216	149.8465	0.4627724
21.97383	149.8419	0.3911072
22.02550	149.8372	0.3221458
22.07716	149.8319	0.2538054
22.12883	149.8281	0.1866589
22.18050	149.8229	0.1221084
22.23216	149.8186	0.05699134
22.28383	149.8152	-8.9209E-3
22.33383	149.8117	-.06755530
22.38716	149.8064	-0.1313162
22.43716	149.8025	-0.1907341
22.49050	149.7985	-0.2518423
22.54050	149.7944	-0.3056992
22.59383	149.7903	-0.3615040
22.64383	149.7882	-0.4126225
22.69716	149.7826	-0.4648935
22.74716	149.7800	-0.5153199
22.80050	149.7771	-0.5670816
22.85050	149.7736	-0.6150184
22.90383	149.7704	-0.6644353
22.95383	149.7675	-0.7101742
23.00550	149.7640	-0.7541278
23.05716	149.7626	-0.7970406
23.10883	149.7582	-0.8372430
23.16050	149.7564	-0.8775659
23.21216	149.7532	-0.9166406
23.26383	149.7510	-0.9534624
23.31550	149.7475	-0.9891722
23.36716	149.7461	-1.024514
23.41716	149.7438	-1.057957
23.47050	149.7423	-1.090371
23.52050	149.7392	-1.119860
23.57383	149.7364	-1.151058
23.62383	149.7344	-1.179502
23.67717	149.7331	-1.208902
23.72716	149.7308	-1.234903
23.78050	149.7290	-1.261285
23.83050	149.7258	-1.284032
23.88383	149.7246	-1.305632
23.93383	149.7234	-1.324590
23.98716	149.7212	-1.344991
24.03717	149.7190	-1.362938
24.08883	149.7179	-1.381721
24.14050	149.7164	-1.399908
24.19216	149.7146	-1.417548
24.24383	149.7120	-1.433567
24.29550	149.7119	-1.449784
24.34716	149.7103	-1.465428
24.39883	149.7091	-1.480380
24.45050	149.7079	-1.495334
24.50050	149.7072	-1.510209
24.55383	149.7074	-1.523752
24.60383	149.7050	-1.536160
24.65716	149.7047	-1.546918
24.70717	149.7038	-1.555672
24.76050	149.7031	-1.565361
24.81050	149.7031	-1.573892
24.86383	149.7008	-1.583013
24.91383	149.7016	-1.591504
24.96716	149.6994	-1.600362
25.01716	149.7000	-1.608879
25.07050	149.6982	-1.617948
25.12050	149.6985	-1.626898
25.17216	149.6976	-1.635974
25.22383	149.6968	-1.645020
25.27550	149.6970	-1.654133
25.32716	149.6965	-1.663164
25.37883	149.6960	-1.672214
25.43050	149.6963	-1.681195
25.48216	149.6952	-1.690068
25.53383	149.6946	-1.698767
25.58383	149.6941	-1.707115
25.63716	149.6935	-1.715854
25.68717	149.6932	-1.723910
25.74050	149.6921	-1.732451
25.79050	149.6918	-1.740332
25.84383	149.6918	-1.748683
25.89383	149.6917	-1.756473
25.94717	149.6918	-1.764628
25.99716	149.6910	-1.772130
26.05050	149.6908	-1.780004
26.10050	149.6897	-1.787188
26.15383	149.6894	-1.794690
26.20383	149.6888	-1.801572
26.25550	149.6884	-1.808589
26.30716	149.6886	-1.815558
26.35883	149.6884	-1.822420
26.41050	149.6879	-1.829216
26.46216	149.6878	-1.835890
26.51383	149.6878	-1.842436
26.56550	149.6880	-1.848830
26.61716	149.6873	-1.855026
26.66716	149.6875	-1.860875
26.72050	149.6868	-1.866963
26.77050	149.6860	-1.872525
26.82383	149.6852	-1.878222
26.87383	149.6858	-1.883502
26.92717	149.6849	-1.888986
26.97717	149.6851	-1.894085
27.03050	149.6845	-1.899428
27.08050	149.6853	-1.904380
27.13383	149.6854	-1.909536
27.18383	149.6846	-1.914222
27.23716	149.6839	-1.919008
27.28717	149.6840	-1.923340
27.33883	149.6839	-1.927760
27.39050	149.6838	-1.931982
27.44216	149.6840	-1.936125
27.49383	149.6829	-1.940160
27.54550	149.6827	-1.944109
27.59716	149.6834	-1.948000
27.64883	149.6826	-1.951922
27.70050	149.6834	-1.955768
27.75050	149.6827	-1.959420
27.80383	149.6823	-1.963206
27.85383	149.6828	-1.966556
27.90716	149.6828	-1.970084
27.95716	149.6824	-1.973220
28.01050	149.6818	-1.976430
28.06050	149.6822	-1.979333
28.11383	149.6818	-1.982314
28.16383	149.6823	-1.985133
28.21716	149.6818	-1.987982
28.26716	149.6819	-1.990606
28.32050	149.6806	-1.993414
28.37050	149.6808	-1.995976
28.42216	149.6815	-1.998703
28.47383	149.6816	-2.001334
28.52550	149.6815	-2.003822
28.57717	149.6814	-2.006276
28.62883	149.6812	-2.008556
28.68050	149.6822	-2.010781
28.73216	149.6805	-2.012902
28.78383	149.6812	-2.015034
28.83383	149.6806	-2.016974
28.88716	149.6809	-2.018981
28.93717	149.6807	-2.020762
28.99050	149.6803	-2.022600
29.04050	149.6805	-2.024322
29.09383	149.6800	-2.026119
29.14383	149.6809	-2.027886
29.19717	149.6814	-2.029812
29.24716	149.6812	-2.031574
29.30050	149.6806	-2.033375
29.35050	149.6809	-2.035021
29.40383	149.6810	-2.036776
29.45383	149.6807	-2.038295
29.50550	149.6805	-2.039818
29.55716	149.6814	-2.041296
29.60883	149.6808	-2.042720
29.66050	149.6809	-2.044075
29.71216	149.6804	-2.045394
29.76383	149.6800	-2.046776
29.81550	149.6805	-2.048028
29.86716	149.6808	-2.049182
29.91716	149.6808	-2.050316
29.97050	149.6812	-2.051516
30.02050	149.6799	-2.052518
30.07383	149.6797	-2.053597
30.12383	149.6797	-2.054542
30.17717	149.6797	-2.055452
30.22717	149.6788	-2.056295
30.28050	149.6794	-2.057328
30.33050	149.6792	-2.058291
30.38383	149.6795	-2.059341
30.43383	149.6789	-2.060274
30.48716	149.6796	-2.061342
30.53717	149.6803	-2.062285
30.58883	149.6794	-2.063225
30.64050	149.6791	-2.064148
30.69216	149.6789	-2.065025
30.74383	149.6797	-2.065886
30.79550	149.6788	-2.066604
30.84716	149.6789	-2.067335
30.89883	149.6788	-2.068069
30.95050	149.6788	-2.068854
31.00050	149.6793	-2.069723
31.05383	149.6792	-2.070620
31.10383	149.6792	-2.071530
31.15716	149.6789	-2.072544
31.20716	149.6791	-2.073467
31.26050	149.6798	-2.074424
31.31050	149.6800	-2.075173
31.36383	149.6794	-2.075952
31.41383	149.6794	-2.076662
31.46716	149.6798	-2.077431
31.51716	149.6795	-2.078029
31.57050	149.6787	-2.078551
31.62050	149.6789	-2.079098
31.67216	149.6790	-2.079518
31.72383	149.6785	-2.079939
31.77550	149.6786	-2.080399
31.82717	149.6785	-2.080906
31.87883	149.6792	-2.081494
31.93050	149.6785	-2.081991
31.98216	149.6786	-2.082520
32.03383	149.6787	-2.083061
32.08383	149.6794	-2.083592
32.13716	149.6786	-2.084190
32.18716	149.6786	-2.084664
32.24050	149.6797	-2.085324
32.29050	149.6792	-2.085785
32.34384	149.6782	-2.086357
32.39383	149.6787	-2.086742
32.44717	149.6778	-2.087222
32.49716	149.6789	-2.087609
32.55050	149.6786	-2.088024
32.60050	149.6779	-2.088402
32.65383	149.6777	-2.088756
32.70383	149.6781	-2.089116
32.75550	149.6780	-2.089362
32.80716	149.6776	-2.089570
32.85883	149.6772	-2.089792
32.91050	149.6778	-2.090096
32.96216	149.6774	-2.090414
33.01383	149.6772	-2.090822
33.06550	149.6770	-2.091236
33.11716	149.6777	-2.091754
33.16716	149.6775	-2.092297
33.22050	149.6779	-2.092750
33.27050	149.6769	-2.093178
33.32383	149.6776	-2.093603
33.37383	149.6768	-2.093912
33.42717	149.6776	-2.094189
33.47717	149.6765	-2.094387
33.53050	149.6768	-2.094574
33.58050	149.6773	-2.094759
33.63383	149.6774	-2.094973
33.68384	149.6766	-2.095190
33.73717	149.6769	-2.095508
33.78717	149.6762	-2.095829
33.83883	149.6766	-2.096262
33.89050	149.6759	-2.096722
33.94216	149.6762	-2.097197
33.99383	149.6773	-2.097669
34.04550	149.6774	-2.098144
34.09716	149.6771	-2.098462
34.14883	149.6766	-2.098728
34.20050	149.6766	-2.098967
34.25050	149.6775	-2.099215
34.30383	149.6766	-2.099525
34.35383	149.6772	-2.099854
34.40716	149.6770	-2.100177
34.45716	149.6775	-2.100511
34.51050	149.6770	-2.100822
34.56050	149.6780	-2.101158
34.61383	149.6768	-2.101467
34.66383	149.6775	-2.101826
34.71716	149.6770	-2.102285
34.76716	149.6777	-2.102644
34.82050	149.6779	-2.103077
34.87050	149.6784	-2.103488
34.92216	149.6780	-2.103919
34.97383	149.6778	-2.104372
35.02550	149.6783	-2.104722
35.07717	149.6769	-2.105025
35.12883	149.6789	-2.105423
35.18050	149.6785	-2.105750
35.23216	149.6786	-2.106110
35.28383	149.6781	-2.106392
35.33383	149.6781	-2.106634
35.38716	149.6779	-2.106859
35.43716	149.6779	-2.106933
35.49050	149.6789	-2.106992
35.54050	149.6772	-2.107110
35.59384	149.6777	-2.107236
35.64383	149.6781	-2.107401
35.69717	149.6787	-2.107627
35.74716	149.6784	-2.107810
35.80050	149.6778	-2.107986
35.85050	149.6772	-2.108104
35.90383	149.6773	-2.108258
35.95383	149.6771	-2.108285
36.00550	149.6768	-2.108380
36.05716	149.6772	-2.108437
36.10883	149.6764	-2.108446
36.16050	149.6773	-2.108555
36.21216	149.6776	-2.108734
36.26383	149.6764	-2.108898
36.31550	149.6769	-2.109175
36.36716	149.6780	-2.109400
36.41716	149.6769	-2.109647
36.47050	149.6775	-2.109938
36.52050	149.6774	-2.110206
36.57383	149.6776	-2.110424
36.62383	149.6770	-2.110645
36.67717	149.6771	-2.110776
36.72717	149.6780	-2.110916
36.78050	149.6768	-2.111006
36.83050	149.6770	-2.111119
36.88383	149.6772	-2.111297
36.93384	149.6766	-2.111426
36.98717	149.6772	-2.111544
37.03717	149.6772	-2.111633
37.08883	149.6768	-2.111724
37.14050	149.6761	-2.111916
37.19216	149.6768	-2.112183
37.24383	149.6769	-2.112414
37.29550	149.6772	-2.112669
37.34716	149.6769	-2.112946
37.39883	149.6769	-2.113231
37.45050	149.6777	-2.113506
37.50050	149.6778	-2.113802
37.55383	149.6776	-2.114066
37.60383	149.6778	-2.114312
37.65716	149.6771	-2.114580
37.70716	149.6778	-2.114763
37.76050	149.6771	-2.114950
37.81050	149.6768	-2.115121
37.86383	149.6774	-2.115373
37.91383	149.6781	-2.115535
37.96716	149.6774	-2.115664
38.01716	149.6774	-2.115800
38.07050	149.6770	-2.115888
38.12050	149.6774	-2.116004
38.17216	149.6769	-2.116064
38.22383	149.6758	-2.116125
38.27550	149.6762	-2.116160
38.32717	149.6766	-2.116156
38.37883	149.6755	-2.116145
38.43050	149.6762	-2.116170
38.48216	149.6761	-2.116130
38.53383	149.6754	-2.116107
38.58383	149.6759	-2.116234
38.63716	149.6759	-2.116422
38.68716	149.6758	-2.116671
38.74050	149.6767	-2.116966
38.79050	149.6760	-2.117296
38.84384	149.6757	-2.117626
38.89383	149.6764	-2.117942
38.94717	149.6769	-2.118271
38.99716	149.6764	-2.118456
39.05050	149.6765	-2.118669
39.10050	149.6750	-2.118748
39.15383	149.6762	-2.118784
39.20383	149.6754	-2.118758
39.25550	149.6756	-2.118797
39.30716	149.6760	-2.118884
39.35883	149.6759	-2.118982
39.41050	149.6759	-2.119165
39.46216	149.6766	-2.119413
39.51383	149.6760	-2.119602
39.56550	149.6763	-2.119816
39.61716	149.6763	-2.119995
39.66716	149.6762	-2.120208
39.72050	149.6759	-2.120392
39.77050	149.6768	-2.120618
39.82383	149.6763	-2.120842
39.87383	149.6765	-2.120974
39.92717	149.6766	-2.121154
39.97717	149.6766	-2.121304
40.03050	149.6763	-2.121472
40.08050	149.6763	-2.121544
40.13383	149.6771	-2.121727
40.18384	149.6761	-2.121820
40.23717	149.6756	-2.121897
40.28717	149.6763	-2.122032
40.33883	149.6763	-2.122007
40.39050	149.6766	-2.122051
40.44216	149.6757	-2.122012
40.49383	149.6753	-2.122000
40.54550	149.6753	-2.122011
40.59716	149.6758	-2.122130
40.64883	149.6760	-2.122292
40.70050	149.6759	-2.122510
40.75050	149.6757	-2.122766
40.80383	149.6762	-2.123060
40.85383	149.6760	-2.123274
40.90716	149.6762	-2.123534
40.95716	149.6762	-2.123749
41.01050	149.6773	-2.123987
41.06050	149.6765	-2.124186
41.11383	149.6774	-2.124452
41.16383	149.6762	-2.124573
41.21717	149.6762	-2.124818
41.26717	149.6767	-2.124932
41.32050	149.6775	-2.125044
41.37050	149.6768	-2.125088
41.42216	149.6759	-2.125072
41.47383	149.6762	-2.125040
41.52550	149.6759	-2.124970
41.57717	149.6760	-2.124894
41.62883	149.6759	-2.124930
41.68050	149.6752	-2.124950
41.73217	149.6759	-2.125045
41.78383	149.6756	-2.125189
41.83383	149.6760	-2.125352
41.88716	149.6761	-2.125533
41.93716	149.6755	-2.125684
41.99050	149.6754	-2.125840
42.04050	149.6755	-2.125978
42.09384	149.6755	-2.126144
42.14383	149.6760	-2.126328
42.19717	149.6754	-2.126434
42.24716	149.6757	-2.126493
42.30050	149.6750	-2.126497
42.35050	149.6750	-2.126550
42.40383	149.6748	-2.126636
42.45383	149.6760	-2.126738
42.50550	149.6757	-2.126847
42.55717	149.6757	-2.127035
42.60883	149.6762	-2.127186
42.66050	149.6763	-2.127376
42.71216	149.6759	-2.127592
42.76383	149.6758	-2.127837
42.81550	149.6765	-2.128120
42.86716	149.6763	-2.128275
42.91716	149.6769	-2.128374
42.97050	149.6763	-2.128447
43.01717	149.6765	-2.128590
43.07050	149.7649	-3.407555
43.12050	150.1237	-6.631532
43.17216	150.6582	-9.727325
43.22383	151.3151	-12.41946
43.27550	152.0606	-14.53439
43.32717	152.8699	-16.19468
43.37883	153.7290	-17.47051
43.43050	154.6236	-18.46616
43.48217	155.5474	-19.23923
43.53383	156.4917	-19.85164
43.58383	157.4219	-20.31814
43.63716	158.4270	-20.73689
43.68716	159.3789	-21.05323
43.74050	160.4010	-21.33735
43.79050	161.3653	-21.57686
43.84384	162.3987	-21.79705
43.89383	163.3707	-21.99681
43.94717	164.4103	-22.18211
43.99716	165.3890	-22.36300
44.05050	166.4339	-22.52618
44.10050	167.4149	-22.69330
44.15383	168.4616	-22.86186
44.20383	169.4448	-23.00262
44.25550	170.4620	-23.16594
44.30717	171.4798	-23.32136
44.35883	172.4983	-23.53919
44.41050	173.5153	-23.78152
44.46216	174.5333	-23.91515
44.51383	175.5505	-24.10770
44.56550	176.5704	-24.29037
44.61716	177.5896	-24.50284
44.66716	178.5746	-24.70566
44.72050	179.6267	-24.92622
44.77050	180.6112	-25.16151
44.82383	181.6617	-25.41703
44.87383	182.6478	-25.65860
44.92717	183.6986	-25.94056
44.97717	184.6816	-26.20545
45.03050	185.7309	-26.50791
45.08050	186.7120	-26.80772
45.13383	187.7595	-27.13436
45.18383	188.7400	-27.44641
45.23717	189.7853	-27.82159
45.28717	190.7640	-28.17770
45.33883	191.7754	-28.54911
45.39050	192.7854	-28.93139
45.44217	193.7949	-29.34580
45.49383	194.8035	-29.77068
45.54550	195.8116	-30.23926
45.59716	196.8179	-30.70754
45.64883	197.8234	-31.18728
45.70050	198.8275	-31.73496
45.75050	199.7966	-32.31940
45.80383	200.8279	-33.02956
45.85383	201.7896	-33.71040
45.90717	202.8135	-34.55794
45.95717	203.7658	-35.48972
46.01050	204.7731	-36.65518
46.06050	205.7090	-37.91906
46.11383	206.6970	-39.49733
46.16383	207.6098	-41.20414
46.21717	208.5705	-43.24841
46.26717	209.4614	-45.24046
46.32050	210.4048	-47.39786
46.37050	211.2866	-49.35214
46.42216	212.2031	-51.15602
46.47383	213.1270	-52.87096
46.52550	214.0522	-54.78200
46.57717	214.9698	-56.98922
46.62883	215.8745	-59.45322
46.68050	216.7660	-62.06611
46.73217	217.6510	-64.63215
46.78383	218.5419	-66.73470
46.83383	219.4306	-67.61450
46.88716	220.4570	-66.00710
46.93716	221.5463	-61.38535
46.99050	222.8502	-54.68461
47.04050	224.1916	-46.62056
47.09384	225.6615	-40.76518
47.14383	226.9733	-37.27729
47.19717	228.2967	-34.55285
47.24716	229.4808	-32.63456
47.30050	230.6959	-31.06666
47.35050	231.8014	-29.97104
47.40383	232.9550	-29.07617
47.45383	234.0160	-28.45082
47.50550	235.0974	-27.95784
47.55717	236.1676	-27.57100
47.60883	237.2288	-27.30049
47.66050	238.2830	-27.09614
47.71216	239.3318	-26.95522
47.76383	240.3772	-26.85246
47.81550	241.4192	-26.79313
47.86716	242.4584	-26.75136
47.91716	243.4625	-26.73188
47.97050	244.5330	-26.72003
48.02050	245.5357	-26.71634
48.07383	246.6047	-26.71527
48.12383	247.6052	-26.71454
48.17717	248.6729	-26.71470
48.22717	249.6728	-26.71642
48.28050	250.7401	-26.72457
48.33050	251.7400	-26.73857
48.38383	252.8066	-26.75889
48.43383	253.8066	-26.77954
48.48717	254.8727	-26.80705
48.53717	255.8713	-26.85175
48.58883	256.9036	-26.90256
48.64050	257.9360	-26.95144
48.69217	258.9674	-27.00390
48.74383	260.0000	-27.05856
48.79550	261.0312	-27.10412
48.84716	262.0630	-27.15264
48.89883	263.0956	-27.20330
48.95050	264.1274	-27.24768
49.00050	265.1264	-27.29255
49.05383	266.1924	-27.34172
49.10383	267.1900	-27.38003
49.15717	268.2553	-27.42878
49.20717	269.2540	-27.47540
49.26050	270.3188	-27.53436
49.31050	271.3149	-27.70904
49.36383	272.3758	-27.87357
49.41383	273.3718	-27.93498
49.46717	274.4340	-27.95305
49.51383	275.3638	-27.99010
49.56550	276.2172	-28.51875
49.61716	276.4329	-24.43370
49.66716	276.3276	-17.61394
49.72050	275.9846	-10.44684
49.77050	275.5136	-4.733919
49.82383	274.8889	0.1801640
49.87383	274.2170	3.803280
49.92717	273.4294	6.817772
49.97717	272.6398	9.002472
50.03050	271.7558	10.81415
50.08050	270.8954	12.12868
50.13383	269.9508	13.21954
50.18383	269.0464	14.02129
50.23717	268.0660	14.68847
50.28717	267.1344	15.18670
50.33883	266.1623	15.59101
50.39050	265.1798	15.92294
50.44217	264.1914	16.18144
50.49383	263.1970	16.39122
50.54550	262.1985	16.56752
50.59716	261.1953	16.71222
50.64883	260.1894	16.81758
50.70050	259.1820	16.92064
50.75050	258.2041	17.00334
50.80383	257.1587	17.07162
50.85383	256.1774	17.12827
50.90717	255.1295	17.18506
50.95717	254.1452	17.23408
51.01050	253.0952	17.27719
51.06050	252.1088	17.31554
51.11383	251.0562	17.34948
51.16383	250.0674	17.37679
51.21717	249.0138	17.40334
51.26716	248.0251	17.42608
51.32050	246.9702	17.44611
51.37050	245.9810	17.46279
51.42217	244.9590	17.47768
51.47383	243.9366	17.49257
51.52550	242.9138	17.50661
51.57717	241.8892	17.51742
51.62883	240.8660	17.52678
51.68050	239.8406	17.53406
51.73217	238.8168	17.54236
51.78383	237.7928	17.55048
51.83383	236.8013	17.56136
51.88716	235.7437	17.57219
51.93716	234.7508	17.57983
51.99050	233.6927	17.58757
52.04050	232.6999	17.59437
52.09384	231.6399	17.60144
52.14384	230.6476	17.60818
52.19717	229.5886	17.61533
52.24717	228.5956	17.62196
52.30050	227.5362	17.63000
52.35050	226.5425	17.63672
52.40383	225.4830	17.64395
52.45383	224.4913	17.65086
52.50550	223.4641	17.65870
52.55717	222.4380	17.66582
52.60883	221.4111	17.67316
52.66050	220.3837	17.68030
52.71216	219.3563	17.68817
52.76382	218.3299	17.69519
52.81550	217.3031	17.70187
52.86716	216.2767	17.70840
52.91716	215.2822	17.71465
52.97050	214.2223	17.72084
53.02050	213.2282	17.72632
53.07383	212.1675	17.73188
53.12383	211.1734	17.73680
53.17717	210.1130	17.74193
53.22717	209.1184	17.74666
53.28050	208.0581	17.75141
53.33050	207.0647	17.75587
53.38383	206.0044	17.76059
53.43383	205.0101	17.76501
53.48717	203.9508	17.76977
53.53716	202.9549	17.77416
53.58882	201.9273	17.77844
53.64050	200.9002	17.78277
53.69216	199.8727	17.78702
53.74382	198.8457	17.79114
53.79550	197.8184	17.79520
53.84716	196.7905	17.79917
53.89883	195.7624	17.80300
53.95050	194.7352	17.80678
54.00050	193.7405	17.81047
54.05383	192.6797	17.81409
54.10383	191.6851	17.81732
54.15717	190.6245	17.82075
54.20717	189.6304	17.82380
54.26050	188.5688	17.82709
54.31050	187.5746	17.83002
54.36382	186.5130	17.83334
54.41382	185.5194	17.83629
54.46717	184.4576	17.83942
54.51716	183.4642	17.84220
54.57050	182.4027	17.84532
54.62050	181.4075	17.84808
54.67217	180.3804	17.85088
54.72382	179.3525	17.85395
54.77550	178.3268	17.85736
54.82717	177.2987	17.86162
54.87883	176.2722	17.86699
54.93050	175.2449	17.87188
54.98217	174.2178	17.87730
55.03383	173.1904	17.88299
55.08383	172.1954	17.88852
55.13716	171.1328	17.89427
55.18716	170.1392	17.90024
55.24050	169.0789	17.91509
55.29050	168.0862	17.96036
55.34384	167.0295	18.14251
55.39384	166.0434	18.44604
55.44717	165.0026	18.98510
55.49717	164.0410	19.89083
55.55050	163.0459	21.51232
55.60050	162.1508	23.83964
55.65383	161.2484	27.21204
55.70383	160.4488	30.96362
55.75550	159.6567	34.96203
55.80717	158.8732	38.62109
55.85883	158.0729	41.58505
55.91050	157.2359	43.64594
55.96216	156.3462	44.75398
56.01382	155.4011	44.94735
56.06550	154.3993	44.42192
56.11716	153.3495	43.22056
56.16716	152.2966	41.73664
56.22050	151.1465	39.97300
56.27050	150.0516	38.24422
56.32383	148.8724	36.25138
56.37383	147.7638	34.56456
56.42717	146.5850	32.82436
56.47717	145.4832	31.28944
56.53050	144.3137	29.76790
56.58050	143.2240	28.44004
56.63383	142.0596	26.89398
56.68383	140.9789	25.83973
56.73717	139.8401	24.90020
56.78716	138.7839	24.16290
56.83882	137.7016	23.53334
56.89050	136.6294	23.02460
56.94216	135.5648	22.62353
56.99382	134.5078	22.29052
57.04550	133.4557	22.03306
57.09716	132.3990	21.23341
57.14883	131.3351	20.96072
57.20050	130.2810	20.67328
57.25050	129.2641	20.42661
57.30383	128.1844	20.18262
57.35383	127.1730	20.06087
57.40717	126.0984	19.86237
57.45717	125.0922	19.73942
57.51050	124.0197	19.63104
57.56050	123.0165	19.51068
57.61382	121.9466	19.41832
57.66382	120.9456	19.34395
57.71717	119.8773	19.23542
57.76716	118.8770	19.15808
57.82050	117.8098	19.09659
57.87050	116.8102	19.04800
57.92217	115.7766	18.98465
57.97382	114.7440	18.92676
58.02550	113.7117	18.86150
58.07717	112.6789	18.80326
58.12883	111.6470	18.78035
58.18050	110.6205	18.78828
58.23217	109.5946	18.83107
58.28383	108.5689	18.85650
58.33383	107.5759	18.88912
58.38716	106.5156	18.89723
58.43716	105.5193	18.89816
58.49050	104.4562	18.89803
58.54050	103.4608	18.89694
58.59384	102.3945	18.85115
58.64384	101.3952	18.74296
58.69717	100.3282	18.65902
58.74717	99.32336	18.42845
58.80050	98.25211	18.33213
58.85050	97.24942	18.26948
58.90383	96.18051	18.14206
58.95383	95.17838	18.07023
59.00550	94.14426	18.00862
59.05717	93.11080	17.90980
59.10883	92.07665	17.83863
59.16050	91.04239	17.76554
59.21216	90.00731	17.68044
59.26382	88.97356	17.59499
59.31550	87.93839	17.51520
59.36716	86.90358	17.44436
59.41716	85.90269	17.37738
59.47050	84.83624	17.31143
59.52050	83.83634	17.25462
59.57383	82.76978	17.19076
59.62383	81.77018	17.13201
59.67717	80.70300	17.06812
59.72717	79.70436	17.00467
59.78050	78.63678	16.95011
59.83050	77.63784	16.87936
59.88383	76.57178	16.82985
59.93383	75.57288	16.77777
59.98717	74.50684	16.72355
60.03716	73.50774	16.67372
60.08882	72.47653	16.61624
60.14050	71.44262	16.56412
60.19216	70.41094	16.50223
60.24382	69.37682	16.44624
60.29550	68.34386	16.38574
60.34716	67.31172	16.32336
60.39883	66.27968	16.27030
60.45050	65.24659	16.22282
60.50050	64.24726	16.16485
60.55383	63.18070	16.09789
60.60383	62.18082	16.03068
60.65717	61.11441	15.96694
60.70717	60.11446	15.90990
60.76050	59.04840	15.85175
60.81050	58.04818	15.79163
60.86382	56.98099	15.72604
60.91382	55.98093	15.66680
60.96717	54.91458	15.60871
61.01716	53.91509	15.54511
61.07050	52.84861	15.48511
61.12050	51.84862	15.43176
61.17217	50.81540	15.36785
61.22382	49.78218	15.31132
61.27550	48.74930	15.24884
61.32717	47.71658	15.19714
61.37883	46.68384	15.14192
61.43050	45.65056	15.09239
61.48217	44.61814	15.03268
61.53383	43.58511	14.97248
61.58383	42.58445	14.91426
61.63716	41.51691	14.84189
61.68716	40.51540	14.77708
61.74050	39.44778	14.70484
61.79050	38.44790	14.62933
61.84384	37.38023	14.54426
61.89384	36.37860	14.47226
61.94717	35.31044	14.40042
61.99717	34.30906	14.31947
62.05050	33.24063	14.23287
62.10050	32.23841	14.14972
62.15383	31.17116	14.07217
62.20383	30.16791	13.99557
62.25550	29.13250	13.90410
62.30717	28.09726	13.81628
62.35883	27.05999	13.73253
62.41050	26.02392	13.63246
62.46216	24.98710	13.59778
62.51050	24.01727	13.60424
62.56050	23.11534	13.99757
62.61382	22.72617	9.585164
62.66382	22.71986	4.672778
62.71717	22.99295	0.2445301
62.76716	23.43397	-2.897940
62.82050	24.05005	-5.449636
62.87050	24.72968	-7.252424
62.92217	25.50550	-8.665816
62.97382	26.33933	-9.737792
63.02550	27.21410	-10.57226
63.07717	28.12194	-11.22532
63.12883	29.05223	-11.72827
63.18050	30.00178	-12.12977
63.23217	30.96489	-12.44991
63.28383	31.93854	-12.72300
63.33383	32.88930	-12.92966
63.38716	33.91038	-13.12496
63.43716	34.87067	-13.27876
63.49050	35.90118	-13.42038
63.54050	36.87144	-13.54651
63.59384	37.90863	-13.66274
63.64384	38.88440	-13.76958
63.69717	39.92637	-13.86806
63.74717	40.90555	-13.94421
63.80050	41.95239	-14.02997
63.85050	42.93475	-14.10634
63.90383	43.98367	-14.18168
63.95383	44.96834	-14.25135
64.00550	45.98742	-14.32138
64.05717	47.00559	-14.39898
64.10884	48.02600	-14.48163
64.16050	49.04554	-14.54980
64.21217	50.06661	-14.62774
64.26384	51.08900	-14.70367
64.31550	52.11154	-14.78344
64.36718	53.13362	-14.85314
64.41717	54.12576	-14.92634
64.47050	55.18257	-15.00320
64.52050	56.17268	-15.07092
64.57384	57.23080	-15.14970
64.62383	58.22216	-15.22770
64.67718	59.28012	-15.31065
64.72718	60.27170	-15.39117
64.78050	61.33037	-15.47785
64.83050	62.32400	-15.55401
64.88384	63.38171	-15.63838
64.93384	64.37550	-15.71689
64.98717	65.43582	-15.78846
65.03717	66.42972	-15.86847
65.08884	67.45750	-15.94729
65.14050	68.48575	-16.02773
65.19217	69.51324	-16.09896
65.24384	70.54043	-16.17043
65.29550	71.56880	-16.25487
65.34717	72.59800	-16.33640
65.39883	73.62456	-16.41206
65.45050	74.65228	-16.49620
65.50050	75.64569	-16.58060
65.55384	76.70666	-16.67506
65.60384	77.69990	-16.75926
65.65718	78.76050	-16.84844
65.70718	79.75534	-16.94762
65.76050	80.81514	-17.03341
65.81050	81.81024	-17.12835
65.86384	82.86972	-17.22219
65.91382	83.86429	-17.31209
65.96718	84.92658	-17.40653
66.01716	85.91988	-17.49620
66.07050	86.98251	-17.60672
66.12050	87.97665	-17.69512
66.17218	89.00414	-17.79260
66.22384	90.03254	-17.89344
66.27550	91.06039	-17.98232
66.32718	92.08878	-18.08494
66.37884	93.11591	-18.18010
66.43050	94.14382	-18.28112
66.48218	95.17134	-18.38383
66.53384	96.19818	-18.48574
66.58384	97.19351	-18.57840
66.63718	98.25512	-18.68548
66.68718	99.24918	-18.78402
66.74050	100.3105	-18.89284
66.79050	101.3038	-18.99019
66.84384	102.3652	-19.10649
66.89384	103.3595	-19.20175
66.94718	104.4203	-19.31659
66.99718	105.4143	-19.41893
67.05050	106.4750	-19.53911
67.10050	107.4683	-19.64825
67.15384	108.5283	-19.76969
67.20384	109.5220	-19.88499
67.25550	110.5484	-19.99424
67.30718	111.5759	-20.11143
67.35884	112.6037	-20.21738
67.41050	113.6303	-20.32854
67.46218	114.6575	-20.43958
67.51384	115.6846	-20.55449
67.56550	116.7129	-20.66252
67.61718	117.7401	-20.78547
67.66718	118.7339	-20.89068
67.72050	119.7943	-21.02492
67.77050	120.7874	-21.14792
67.82384	121.8476	-21.27026
67.87384	122.8407	-21.37306
67.92718	123.9022	-21.48969
67.97718	124.8953	-21.60622
68.03050	125.9565	-21.74620
68.08050	126.9498	-21.86201
68.13384	128.0086	-22.01617
68.18384	129.0009	-22.14936
68.23718	130.0611	-22.22768
68.28718	131.0571	-22.30998
68.33884	132.0902	-22.32707
68.39050	133.1272	-22.26902
68.44218	134.1630	-22.25545
68.49384	135.1959	-22.25302
68.54550	136.2256	-22.37314
68.59718	137.2533	-22.53148
68.64884	138.2830	-22.53383
68.70050	139.3170	-22.52678
68.75050	140.3178	-22.52947
68.80384	141.3830	-22.56169
68.85384	142.3816	-22.63815
68.90718	143.4451	-22.73006
68.95718	144.4403	-22.82684
69.01050	145.5030	-22.92760
69.06050	146.4992	-23.02352
69.11384	147.5622	-23.12368
69.16382	148.5576	-23.21974
69.21718	149.6195	-23.31275
69.26716	150.6146	-23.40364
69.32050	151.6767	-23.51094
69.37050	152.6725	-23.61551
69.42218	153.7012	-23.70871
69.47384	154.7305	-23.81228
69.52550	155.7586	-23.90476
69.57718	156.7876	-24.00450
69.62884	157.8166	-24.10246
69.68050	158.8457	-24.18910
69.73218	159.8748	-24.27192
69.78384	160.9045	-24.34428
69.83384	161.9014	-24.40178
69.88718	162.9663	-24.45714
69.93718	163.9651	-24.49216
69.99050	165.0303	-24.52433
70.04050	166.0285	-24.55694
70.09384	167.0919	-24.61152
70.14384	168.0916	-24.67234
70.19718	169.1560	-24.75125
70.24718	170.1523	-24.84559
70.30050	171.2163	-24.95169
70.35050	172.2120	-25.08246
70.40384	173.2734	-25.20988
70.45384	174.2686	-25.33986
70.50550	175.2943	-25.49290
70.55718	176.3196	-25.67168
70.60884	177.3436	-25.86125
70.66050	178.3662	-26.07878
70.71218	179.3880	-26.31065
70.76384	180.4078	-26.56791
70.81550	181.4260	-26.86969
70.86718	182.4432	-27.19845
70.91718	183.4252	-27.54458
70.97050	184.4705	-27.94834
71.02050	185.4485	-28.37120
71.07384	186.4895	-28.85700
71.12384	187.4633	-29.36977
71.17718	188.4991	-29.93741
71.22718	189.4666	-30.54651
71.28050	190.4973	-31.22112
71.33050	191.4597	-31.87850
71.38384	192.4841	-32.63251
71.43384	193.4439	-33.34675
71.48718	194.4654	-34.13275
71.53718	195.4229	-34.87994
71.58884	196.4096	-35.72550
71.64050	197.3952	-36.62644
71.69218	198.3756	-37.60898
71.74384	199.3516	-38.69145
71.79550	200.3229	-39.83571
71.84718	201.2886	-41.04350
71.89884	202.2520	-42.28384
71.95050	203.2146	-43.47247
72.00050	204.1475	-44.49760
72.05384	205.1521	-45.31676
72.10384	206.1091	-45.60570
72.15718	207.1625	-45.20207
72.20718	208.1968	-43.25208
72.26050	209.3698	-40.02366
72.31050	210.5295	-36.35483
72.36384	211.7970	-33.00196
72.41382	212.9672	-30.94172
72.46718	214.1755	-29.46396
72.51716	215.2773	-28.45121
72.57050	216.4244	-27.65494
72.62050	217.4816	-27.10082
72.67218	218.5592	-26.68218
72.72384	219.6253	-26.37706
72.77550	220.6836	-26.14526
72.82718	221.7354	-25.99074
72.87884	222.7824	-25.88918
72.93050	223.8254	-25.81566
72.98218	224.8659	-25.76302
73.03384	225.9058	-25.74100
73.08384	226.9086	-25.73200
73.13718	227.9775	-25.72817
73.18718	228.9786	-25.72758
73.24050	230.0452	-25.72908
73.29050	231.0454	-25.73684
73.34384	232.1130	-25.75965
73.39384	233.1106	-25.79476
73.44718	234.1774	-25.83924
73.49718	235.1760	-25.88402
73.55050	236.2422	-25.92600
73.60050	237.2414	-25.95810
73.65384	238.3071	-25.99457
73.70384	239.3064	-26.04062
73.75550	240.3377	-26.08694
73.80718	241.3702	-26.14961
73.85884	242.4008	-26.20318
73.91050	243.4319	-26.26085
73.96218	244.4645	-26.30860
74.01384	245.4956	-26.35296
74.06550	246.5283	-26.40123
74.11718	247.5598	-26.43850
74.16718	248.5577	-26.47531
74.22050	249.6234	-26.52128
74.27050	250.6214	-26.56776
74.32384	251.6858	-26.62250
74.37384	252.6840	-26.66976
74.42718	253.7498	-26.71696
74.47718	254.7473	-26.75778
74.53050	255.8125	-26.81111
74.58050	256.8098	-26.86016
74.63384	257.8751	-26.91703
74.68384	258.8728	-26.96722
74.73718	259.9378	-27.02388
74.78718	260.9352	-27.06954
74.83884	261.9674	-27.12806
74.89050	262.9990	-27.18089
74.94218	264.0303	-27.23065
74.99384	265.0608	-27.28529
75.04550	266.0924	-27.33977
75.09718	267.1244	-27.38739
75.14884	268.1552	-27.43812
75.20050	269.1867	-27.49466
75.25050	270.1844	-27.53872
75.30384	271.2488	-27.58602
-2.000000	5.000000	0.0000000