File: 7-C1(1.2mol%)+C20(0.6mol%)(1)/matlab/150-3.txt
CLOSED
Version	1.0
Language	English
Mode	Standard
Run	31
RunSerial	12299
Instrument	DSC Q2000 V24.11 Build 124
Module	DSC Standard Cell RC
Operator
File	\\AE520-1454\Users\dsc\Desktop\Data\29-08-17-3\150-3.001
ProcName
InstSerial	2000-0883
AutoSerial	1293
Sample	150-3
Size	35.0000	mg
PanMass	Not available
PanResist	Automatic Automatic  K/W
PanFactor	Default Default
Method
Comment
Xcomment	Pan: Tzero Aluminum Hermetic
Xcomment	Gas1: Nitrogen 50.0 ml/min
Xcomment	Gas2: Nitrogen 50.0 ml/min
Text
Exotherm	UP
Kcell	1.05230
Cpconst	Standard: 0.938
Calib	-38.6961
TempCal	1	pts	157.46	156.60
TzeroDt	-87.6168 -0.0009 -1.4231
TzeroDtz	-87.6168 0.0057 6.9570
InstCalFile	Tzero: \\Ae520-1454\ta\Data\DSC\Calibration\2017\CALIBRATION\1562_RCS (90)_05_18_2017 10_50_44.TZR
InstCalFile	Baseline: \\Ae520-1454\ta\Data\DSC\Calibration\2017\2017-05-17_Calibration.001
InstCalFile	Sapphire: \\Ae520-1454\ta\Data\DSC\Calibration\2017\2017-05-17_Saphire.001
InstCalDate	Tzero 2017-05-18 Time 10:50:44
TempRange	-87.39 to 398.39 °C at 10.00 °C/min Heat Only
AutoZero	Delta T Offset 0.000 uV
AutoZero	Delta T0 Offset 0.000 uV
MultiptCal	0
MultiPtDesc	0) Not set
AutoCellConst	Calibration Date 2017-05-18 16:59:28
Controls	Gas 1  Event Off  Sampling 0.2
Cell#	RC-01562
CoolingUnit	RCS (90)
SelHeatFlow	Heat Flow T4P (mW)
AutoLidII	Installed
AutoAnalysis	Off
MacroFile
Nsig	3
Sig1	Time (min)
Sig2	Temperature (°C)
Sig3	Heat Flow (mW)
Date	2017-08-31
Time	04:16:54
OrgMethod	1: Equilibrate at 80.00 °C
OrgMethod	2: Isothermal for 3.00 min
OrgMethod	3: Jump to 150.00 °C
OrgMethod	4: Mark end of cycle 1
OrgMethod	5: Isothermal for 40.00 min
OrgMethod	6: Mark end of cycle 2
OrgMethod	7: Ramp 20.00 °C/min to 280.00 °C
OrgMethod	8: Mark end of cycle 3
OrgMethod	9: Ramp 20.00 °C/min to 20.00 °C
OrgMethod	10: Mark end of cycle 4
OrgMethod	11: Ramp 20.00 °C/min to 280.00 °C
OrgMethod	12: Mark end of cycle 5
OrgFile	C:\Users\jarra\Desktop\DSC\7-C1(1.2mol%)+C20(0.6mol%)(1)\150-3.001
StartOfData
4.99994E-4	78.77820	-15.19358
0.05383332	79.00289	-12.31228
0.1038333	79.17026	-10.15440
0.1571666	79.31314	-8.308022
0.2071666	79.42103	-6.922588
0.2605000	79.51187	-5.740198
0.3105000	79.58018	-4.858565
0.3638334	79.63795	-4.103664
0.4138333	79.68079	-3.539524
0.4671667	79.71764	-3.060930
0.5171667	79.74426	-2.698982
0.5705000	79.76695	-2.396901
0.6205000	79.78394	-2.167093
0.6721668	79.79772	-1.984309
0.7238332	79.80811	-1.837411
0.7755000	79.81636	-1.721718
0.8271668	79.82360	-1.633078
0.8788332	79.82740	-1.564134
0.9305000	79.83222	-1.511511
0.9821668	79.83407	-1.471617
1.033833	79.83578	-1.443762
1.083833	79.83750	-1.424126
1.137166	79.83832	-1.409684
1.187166	79.83978	-1.401368
1.240500	79.83916	-1.395004
1.290500	79.83919	-1.391141
1.343833	79.83955	-1.387517
1.393833	79.83891	-1.384022
1.447166	79.83830	-1.380365
1.497166	79.83863	-1.377059
1.550500	79.83772	-1.373718
1.600500	79.83628	-1.370806
1.653833	79.83618	-1.368011
1.703833	79.83588	-1.365656
1.755500	79.83525	-1.363493
1.807167	79.83524	-1.361672
1.858834	79.83412	-1.359992
1.910500	79.83304	-1.358669
1.962166	79.83258	-1.357540
2.013833	79.83218	-1.356657
2.065500	79.83015	-1.356022
2.117167	79.82996	-1.355628
2.167167	79.82951	-1.355446
2.220500	79.82818	-1.355407
2.270500	79.82812	-1.355573
2.323833	79.82732	-1.355975
2.373834	79.82686	-1.356473
2.427167	79.82563	-1.357149
2.477167	79.82478	-1.357964
2.530500	79.82453	-1.358968
2.580500	79.82386	-1.359971
2.633833	79.82300	-1.361235
2.683833	79.82232	-1.362535
2.737167	79.82170	-1.364043
2.787167	79.82128	-1.365639
2.838833	79.82097	-1.367539
2.890500	79.82022	-1.369530
2.942167	79.81940	-1.371703
2.993833	79.81886	-1.373894
3.040500	79.99165	-4.609491
3.093834	81.66290	-20.91503
3.143833	83.97900	-34.79134
3.197167	86.93851	-49.36996
3.247166	90.08055	-62.00320
3.300500	93.73871	-73.99016
3.350500	97.39819	-83.70411
3.403833	101.4926	-92.60703
3.453833	105.4639	-99.78309
3.505500	109.6592	-106.2301
3.557167	113.9322	-111.6435
3.608833	118.2530	-116.3932
3.660500	122.6082	-120.5601
3.712167	126.9878	-124.1524
3.763833	131.3242	-126.4484
3.815500	134.8012	-118.7254
3.867166	137.2688	-106.3322
3.917167	139.1956	-94.13212
3.970500	140.8403	-81.52585
4.020500	142.0978	-70.93490
4.073834	143.1913	-61.15297
4.123833	144.0346	-53.40305
4.177166	144.7795	-46.50530
4.227167	145.3590	-41.14377
4.280500	145.8759	-36.45342
4.330500	146.2817	-32.83828
4.383834	146.6455	-29.67905
4.433834	146.9352	-27.24315
4.487167	147.1983	-25.09490
4.537167	147.4081	-23.42190
4.588834	147.5940	-21.98485
4.640500	147.7544	-20.78134
4.692166	147.8930	-19.77274
4.743834	148.0130	-18.91791
4.795500	148.1178	-18.19374
4.847166	148.2094	-17.56828
4.898834	148.2892	-17.03146
4.950500	148.3600	-16.55998
5.000500	148.4209	-16.15867
5.053834	148.4800	-15.77469
5.103833	148.5282	-15.44726
5.157166	148.5750	-15.13476
5.207167	148.6148	-14.85989
5.260500	148.6534	-14.59015
5.310500	148.6867	-14.35111
5.363834	148.7196	-14.10918
5.413832	148.7470	-13.89544
5.467168	148.7753	-13.66926
5.517168	148.8008	-13.47139
5.570500	148.8247	-13.26042
5.620500	148.8472	-13.06310
5.672168	148.8694	-12.86762
5.723834	148.8896	-12.67244
5.775500	148.9092	-12.47934
5.827168	148.9283	-12.28776
5.878834	148.9475	-12.09984
5.930500	148.9645	-11.90856
5.982168	148.9818	-11.72344
6.033832	148.9985	-11.54454
6.083832	149.0140	-11.36843
6.137168	149.0297	-11.18354
6.187168	149.0436	-11.01491
6.240500	149.0591	-10.83509
6.290500	149.0737	-10.67111
6.343834	149.0874	-10.48735
6.393832	149.1018	-10.31199
6.447168	149.1163	-10.10424
6.497168	149.1312	-9.895995
6.550500	149.1499	-9.645801
6.600500	149.1676	-9.385126
6.653832	149.1887	-9.081799
6.703832	149.2108	-8.755293
6.755500	149.2362	-8.374410
6.807166	149.2657	-7.945718
6.858832	149.2961	-7.486180
6.910500	149.3264	-7.029340
6.962168	149.3590	-6.569762
7.013834	149.3895	-6.119285
7.065500	149.4184	-5.708660
7.117166	149.4433	-5.346662
7.167168	149.4655	-5.044980
7.220500	149.4858	-4.761236
7.270500	149.5014	-4.540494
7.323834	149.5171	-4.336002
7.373834	149.5292	-4.173461
7.427168	149.5404	-4.020748
7.477168	149.5495	-3.899539
7.530500	149.5580	-3.784650
7.580500	149.5652	-3.690694
7.633832	149.5721	-3.601921
7.683832	149.5770	-3.529445
7.737168	149.5828	-3.458331
7.787168	149.5886	-3.396706
7.838834	149.5926	-3.339853
7.890500	149.5977	-3.289152
7.942168	149.6008	-3.243482
7.993834	149.6044	-3.202603
8.045500	149.6077	-3.160057
8.097168	149.6113	-3.120472
8.148834	149.6139	-3.078166
8.200500	149.6167	-3.040494
8.250500	149.6211	-3.005874
8.303832	149.6231	-2.968478
8.353832	149.6262	-2.936917
8.407166	149.6288	-2.903295
8.457168	149.6313	-2.874027
8.510499	149.6340	-2.843618
8.560500	149.6365	-2.815405
8.613834	149.6387	-2.784296
8.663834	149.6405	-2.757280
8.717168	149.6428	-2.728264
8.767168	149.6449	-2.703362
8.820500	149.6465	-2.677618
8.870499	149.6496	-2.653084
8.922168	149.6511	-2.625684
8.973832	149.6539	-2.602055
9.025499	149.6555	-2.575675
9.077168	149.6567	-2.550972
9.128834	149.6594	-2.526718
9.180500	149.6619	-2.500360
9.232166	149.6630	-2.473506
9.283832	149.6660	-2.447614
9.333832	149.6680	-2.421596
9.387168	149.6696	-2.393520
9.437166	149.6717	-2.365933
9.490500	149.6739	-2.338688
9.540500	149.6761	-2.312647
9.593832	149.6772	-2.284648
9.643832	149.6796	-2.258830
9.697168	149.6809	-2.229548
9.747168	149.6840	-2.203032
9.800500	149.6850	-2.173874
9.850500	149.6878	-2.149119
9.903832	149.6892	-2.116289
9.953834	149.6917	-2.089098
10.00550	149.6945	-2.059785
10.05717	149.6956	-2.030348
10.10883	149.6981	-1.998567
10.16050	149.6998	-1.967456
10.21217	149.7019	-1.937560
10.26383	149.7046	-1.907131
10.31550	149.7057	-1.876522
10.36717	149.7085	-1.846826
10.41717	149.7105	-1.817272
10.47050	149.7129	-1.784526
10.52050	149.7146	-1.754239
10.57383	149.7167	-1.720432
10.62383	149.7190	-1.687758
10.67717	149.7216	-1.652938
10.72717	149.7235	-1.618188
10.78050	149.7252	-1.583558
10.83050	149.7277	-1.551515
10.88383	149.7308	-1.515601
10.93383	149.7326	-1.481953
10.98717	149.7351	-1.447215
11.03717	149.7372	-1.412985
11.08883	149.7399	-1.375905
11.14050	149.7413	-1.339103
11.19217	149.7448	-1.304470
11.24384	149.7468	-1.268093
11.29550	149.7499	-1.232070
11.34717	149.7517	-1.193608
11.39883	149.7546	-1.157132
11.45050	149.7569	-1.117730
11.50050	149.7595	-1.082310
11.55383	149.7620	-1.041175
11.60383	149.7650	-1.003093
11.65717	149.7666	-0.9639161
11.70717	149.7700	-0.9280855
11.76050	149.7722	-0.8878098
11.81050	149.7749	-0.8519144
11.86383	149.7784	-0.8121724
11.91383	149.7804	-0.7721963
11.96717	149.7841	-0.7300239
12.01717	149.7868	-0.6886614
12.07050	149.7896	-0.6428299
12.12050	149.7924	-0.5986094
12.17217	149.7951	-0.5515786
12.22383	149.7987	-0.5011220
12.27550	149.8014	-0.4422050
12.32717	149.8055	-0.3794984
12.37884	149.8099	-0.3017011
12.43050	149.8154	-0.2129066
12.48217	149.8214	-0.1067241
12.53383	149.8284	0.01290034
12.58383	149.8368	0.1449214
12.63717	149.8465	0.3020274
12.68716	149.8570	0.4683150
12.74050	149.8688	0.6542302
12.79050	149.8811	0.8410156
12.84383	149.8946	1.040498
12.89383	149.9071	1.239000
12.94717	149.9216	1.449448
12.99717	149.9339	1.641340
13.05050	149.9474	1.849419
13.10050	149.9602	2.035027
13.15383	149.9733	2.225210
13.20383	149.9852	2.397958
13.25550	149.9964	2.570436
13.30717	150.0079	2.733330
13.35883	150.0186	2.887944
13.41050	150.0289	3.036802
13.46217	150.0379	3.180558
13.51383	150.0477	3.316918
13.56550	150.0557	3.446442
13.61716	150.0645	3.570922
13.66716	150.0725	3.685274
13.72050	150.0807	3.801733
13.77050	150.0872	3.907380
13.82384	150.0948	4.012691
13.87384	150.1012	4.110980
13.92717	150.1073	4.209024
13.97717	150.1145	4.294748
14.03050	150.1201	4.384468
14.08050	150.1255	4.460888
14.13383	150.1307	4.539340
14.18383	150.1354	4.608666
14.23716	150.1416	4.675117
14.28717	150.1445	4.734139
14.33883	150.1492	4.792002
14.39050	150.1532	4.842460
14.44217	150.1560	4.887018
14.49384	150.1596	4.925766
14.54550	150.1606	4.958478
14.59717	150.1624	4.984898
14.64883	150.1650	5.005086
14.70050	150.1661	5.019402
14.75050	150.1664	5.028135
14.80383	150.1673	5.034161
14.85383	150.1678	5.037794
14.90717	150.1678	5.041531
14.95717	150.1673	5.044454
15.01050	150.1651	5.046856
15.06050	150.1642	5.048180
15.11383	150.1635	5.048416
15.16383	150.1624	5.045502
15.21716	150.1606	5.037164
15.26717	150.1578	5.023233
15.32050	150.1561	4.999288
15.37050	150.1544	4.972043
15.42217	150.1526	4.937436
15.47383	150.1494	4.899526
15.52550	150.1474	4.858894
15.57717	150.1449	4.816360
15.62883	150.1417	4.773216
15.68050	150.1395	4.728102
15.73216	150.1367	4.684596
15.78383	150.1333	4.641296
15.83383	150.1316	4.599094
15.88716	150.1290	4.554624
15.93717	150.1263	4.515761
15.99050	150.1237	4.473719
16.04050	150.1206	4.434390
16.09383	150.1182	4.392254
16.14383	150.1152	4.353180
16.19717	150.1122	4.315710
16.24716	150.1110	4.278134
16.30050	150.1073	4.241620
16.35050	150.1056	4.206428
16.40383	150.1030	4.169778
16.45383	150.1007	4.136002
16.50550	150.0989	4.103117
16.55716	150.0971	4.070437
16.60883	150.0950	4.039581
16.66050	150.0920	4.008636
16.71216	150.0903	3.980170
16.76383	150.0890	3.950786
16.81550	150.0872	3.922192
16.86716	150.0854	3.897036
16.91716	150.0832	3.871830
16.97050	150.0814	3.844493
17.02050	150.0801	3.819278
17.07383	150.0777	3.794557
17.12383	150.0760	3.773772
17.17716	150.0750	3.752606
17.22716	150.0724	3.733025
17.28050	150.0709	3.713196
17.33050	150.0692	3.695588
17.38383	150.0688	3.674495
17.43383	150.0661	3.656206
17.48716	150.0652	3.636536
17.53717	150.0637	3.617870
17.58883	150.0620	3.601162
17.64050	150.0601	3.583890
17.69216	150.0589	3.566074
17.74383	150.0584	3.548651
17.79550	150.0568	3.533096
17.84716	150.0561	3.517050
17.89883	150.0548	3.501083
17.95050	150.0535	3.485613
18.00050	150.0524	3.472410
18.05383	150.0522	3.457063
18.10383	150.0513	3.444922
18.15716	150.0495	3.431972
18.20716	150.0474	3.418024
18.26050	150.0475	3.405306
18.31050	150.0460	3.393762
18.36383	150.0447	3.380606
18.41383	150.0429	3.368068
18.46716	150.0419	3.354659
18.51716	150.0419	3.341940
18.57050	150.0406	3.330686
18.62050	150.0402	3.317530
18.67216	150.0384	3.302166
18.72383	150.0373	3.285786
18.77550	150.0366	3.269401
18.82716	150.0358	3.251922
18.87883	150.0351	3.234009
18.93050	150.0345	3.219340
18.98216	150.0332	3.205317
19.03383	150.0325	3.191328
19.08383	150.0314	3.180272
19.13716	150.0305	3.167156
19.18716	150.0296	3.154412
19.24050	150.0280	3.142231
19.29050	150.0278	3.129122
19.34383	150.0257	3.115654
19.39383	150.0247	3.100906
19.44716	150.0237	3.086992
19.49716	150.0227	3.073629
19.55050	150.0210	3.058292
19.60050	150.0209	3.043812
19.65383	150.0197	3.027234
19.70383	150.0188	3.012586
19.75550	150.0183	2.995020
19.80716	150.0168	2.978076
19.85883	150.0161	2.961457
19.91050	150.0166	2.943496
19.96216	150.0144	2.928732
20.01383	150.0139	2.911847
20.06550	150.0135	2.897756
20.11716	150.0118	2.884872
20.16716	150.0112	2.870647
20.22050	150.0106	2.856869
20.27050	150.0089	2.846246
20.32383	150.0073	2.832384
20.37383	150.0074	2.819113
20.42716	150.0058	2.806650
20.47716	150.0049	2.793543
20.53050	150.0033	2.780422
20.58050	150.0024	2.764741
20.63383	150.0016	2.749915
20.68383	149.9996	2.735343
20.73716	149.9993	2.722148
20.78717	149.9982	2.708892
20.83883	149.9976	2.695712
20.89050	149.9962	2.683584
20.94216	149.9958	2.670315
20.99383	149.9948	2.657065
21.04550	149.9936	2.643938
21.09716	149.9928	2.631216
21.14883	149.9929	2.618536
21.20050	149.9921	2.606419
21.25050	149.9917	2.595414
21.30383	149.9908	2.584183
21.35383	149.9900	2.573514
21.40716	149.9900	2.562286
21.45717	149.9892	2.551884
21.51050	149.9887	2.540890
21.56050	149.9880	2.530772
21.61383	149.9869	2.520110
21.66383	149.9862	2.510282
21.71716	149.9860	2.500054
21.76716	149.9853	2.490652
21.82050	149.9852	2.480832
21.87050	149.9843	2.471734
21.92216	149.9836	2.462478
21.97383	149.9842	2.453347
22.02550	149.9830	2.444331
22.07716	149.9836	2.435349
22.12883	149.9828	2.426598
22.18050	149.9824	2.418014
22.23216	149.9820	2.409606
22.28383	149.9819	2.401422
22.33383	149.9826	2.393730
22.38716	149.9816	2.385870
22.43716	149.9805	2.378798
22.49050	149.9814	2.371547
22.54050	149.9809	2.365000
22.59383	149.9804	2.358347
22.64383	149.9809	2.352324
22.69716	149.9803	2.346148
22.74716	149.9804	2.340666
22.80050	149.9810	2.335121
22.85050	149.9820	2.330264
22.90383	149.9822	2.325594
22.95383	149.9816	2.321602
23.00550	149.9817	2.317951
23.05716	149.9822	2.314734
23.10883	149.9833	2.312102
23.16050	149.9834	2.310010
23.21216	149.9840	2.308500
23.26383	149.9844	2.307543
23.31550	149.9852	2.307260
23.36716	149.9854	2.307576
23.41716	149.9867	2.308456
23.47050	149.9871	2.310090
23.52050	149.9873	2.312236
23.57383	149.9890	2.315271
23.62383	149.9906	2.318592
23.67717	149.9905	2.323213
23.72716	149.9914	2.328284
23.78050	149.9925	2.334937
23.83050	149.9931	2.341678
23.88383	149.9932	2.351492
23.93383	149.9951	2.360267
23.98716	149.9956	2.370401
24.03717	149.9962	2.381272
24.08883	149.9969	2.392556
24.14050	149.9982	2.401858
24.19216	149.9989	2.411408
24.24383	150.0001	2.420412
24.29550	150.0004	2.429310
24.34716	150.0014	2.437435
24.39883	150.0032	2.445686
24.45050	150.0032	2.453894
24.50050	150.0031	2.461897
24.55383	150.0043	2.470227
24.60383	150.0041	2.477858
24.65716	150.0036	2.485658
24.70717	150.0038	2.492504
24.76050	150.0034	2.499348
24.81050	150.0034	2.505068
24.86383	150.0026	2.510365
24.91383	150.0030	2.514395
24.96716	150.0023	2.517805
25.01716	150.0007	2.520344
25.07050	149.9999	2.521725
25.12050	149.9988	2.521008
25.17216	149.9970	2.518385
25.22383	149.9958	2.511946
25.27550	149.9932	2.501594
25.32716	149.9923	2.485192
25.37883	149.9899	2.463466
25.43050	149.9890	2.437876
25.48216	149.9864	2.408296
25.53383	149.9850	2.379985
25.58383	149.9818	2.349620
25.63716	149.9804	2.313152
25.68717	149.9774	2.279238
25.74050	149.9755	2.240833
25.79050	149.9743	2.205335
25.84383	149.9711	2.169098
25.89383	149.9682	2.131014
25.94717	149.9652	2.089653
25.99716	149.9623	2.049541
26.05050	149.9596	2.008818
26.10050	149.9569	1.971199
26.15383	149.9607	1.954107
26.20383	149.9639	1.974819
26.25550	149.9613	1.973794
26.30716	149.9582	1.953375
26.35883	149.9534	1.896208
26.41050	149.9503	1.829124
26.46216	149.9463	1.771795
26.51383	149.9423	1.715798
26.56550	149.9390	1.664968
26.61716	149.9360	1.616286
26.66716	149.9331	1.573839
26.72050	149.9300	1.533024
26.77050	149.9274	1.494826
26.82383	149.9259	1.454470
26.87383	149.9224	1.419603
26.92717	149.9209	1.384430
26.97717	149.9171	1.352932
27.03050	149.9161	1.318768
27.08050	149.9132	1.288856
27.13383	149.9111	1.258054
27.18383	149.9088	1.229158
27.23716	149.9063	1.200208
27.28717	149.9048	1.167914
27.33883	149.9025	1.137827
27.39050	149.9009	1.107681
27.44216	149.8993	1.077887
27.49383	149.8974	1.048703
27.54550	149.8957	1.018935
27.59716	149.8938	0.9929194
27.64883	149.8923	0.9656452
27.70050	149.8904	0.9399069
27.75050	149.8885	0.9145058
27.80383	149.8884	0.8878952
27.85383	149.8856	0.8656632
27.90716	149.8831	0.8425356
27.95716	149.8814	0.8204551
28.01050	149.8803	0.7942582
28.06050	149.8781	0.7710244
28.11383	149.8757	0.7432970
28.16383	149.8746	0.7187970
28.21716	149.8725	0.6936900
28.26716	149.8710	0.6690935
28.32050	149.8685	0.6450508
28.37050	149.8676	0.6199840
28.42216	149.8652	0.5960408
28.47383	149.8636	0.5712707
28.52550	149.8612	0.5458279
28.57717	149.8597	0.5203556
28.62883	149.8583	0.4957158
28.68050	149.8558	0.4706465
28.73216	149.8540	0.4445833
28.78383	149.8524	0.4170146
28.83383	149.8496	0.3942856
28.88716	149.8485	0.3659722
28.93717	149.8470	0.3410603
28.99050	149.8454	0.3140698
29.04050	149.8434	0.2887648
29.09383	149.8416	0.2631346
29.14383	149.8398	0.2355332
29.19717	149.8382	0.2080349
29.24716	149.8372	0.1799540
29.30050	149.8349	0.1505614
29.35050	149.8331	0.1223351
29.40383	149.8317	0.09471912
29.45383	149.8299	0.06695376
29.50550	149.8282	0.03843628
29.55716	149.8268	0.01226397
29.60883	149.8249	-.01209176
29.66050	149.8239	-.03841972
29.71216	149.8206	-.06429055
29.76383	149.8197	-.09499481
29.81550	149.8176	-0.1226473
29.86716	149.8164	-0.1531338
29.91716	149.8148	-0.1800814
29.97050	149.8128	-0.2093174
30.02050	149.8108	-0.2365118
30.07383	149.8091	-0.2675769
30.12383	149.8077	-0.2935202
30.17717	149.8056	-0.3203902
30.22717	149.8040	-0.3473310
30.28050	149.8015	-0.3748336
30.33050	149.7991	-0.4016610
30.38383	149.7976	-0.4311763
30.43383	149.7947	-0.4583769
30.48716	149.7930	-0.4875667
30.53717	149.7906	-0.5168924
30.58883	149.7890	-0.5480706
30.64050	149.7865	-0.5792222
30.69216	149.7846	-0.6111075
30.74383	149.7837	-0.6423535
30.79550	149.7808	-0.6742197
30.84716	149.7790	-0.7067475
30.89883	149.7772	-0.7391702
30.95050	149.7760	-0.7697662
31.00050	149.7736	-0.8001184
31.05383	149.7719	-0.8313769
31.10383	149.7705	-0.8604851
31.15716	149.7687	-0.8899059
31.20716	149.7664	-0.9186078
31.26050	149.7640	-0.9493149
31.31050	149.7626	-0.9787188
31.36383	149.7599	-1.009831
31.41383	149.7580	-1.038179
31.46716	149.7563	-1.068611
31.51716	149.7542	-1.098179
31.57050	149.7521	-1.130329
31.62050	149.7499	-1.160530
31.67216	149.7476	-1.191381
31.72383	149.7462	-1.222555
31.77550	149.7435	-1.250680
31.82717	149.7426	-1.280330
31.87883	149.7404	-1.307861
31.93050	149.7380	-1.337455
31.98216	149.7354	-1.365906
32.03383	149.7338	-1.394828
32.08383	149.7318	-1.422436
32.13716	149.7292	-1.452416
32.18716	149.7274	-1.479525
32.24050	149.7255	-1.509285
32.29050	149.7234	-1.531582
32.34384	149.7223	-1.554505
32.39383	149.7209	-1.577075
32.44717	149.7189	-1.606774
32.49716	149.7173	-1.638069
32.55050	149.7160	-1.670014
32.60050	149.7144	-1.693142
32.65383	149.7137	-1.706080
32.70383	149.7114	-1.727095
32.75550	149.7096	-1.760023
32.80716	149.7063	-1.795488
32.85883	149.7050	-1.829560
32.91050	149.7036	-1.860170
32.96216	149.7007	-1.888126
33.01383	149.6987	-1.915078
33.06550	149.6968	-1.939341
33.11716	149.6953	-1.964020
33.16716	149.6939	-1.988437
33.22050	149.6919	-2.013622
33.27050	149.6909	-2.036895
33.32383	149.6895	-2.058588
33.37383	149.6881	-2.080141
33.42717	149.6866	-2.103289
33.47717	149.6846	-2.122867
33.53050	149.6838	-2.144636
33.58050	149.6820	-2.164174
33.63383	149.6811	-2.184367
33.68384	149.6796	-2.201324
33.73717	149.6783	-2.219532
33.78717	149.6765	-2.237258
33.83883	149.6757	-2.255150
33.89050	149.6750	-2.271676
33.94216	149.6735	-2.287254
33.99383	149.6716	-2.302558
34.04550	149.6701	-2.317184
34.09716	149.6686	-2.331560
34.14883	149.6681	-2.345438
34.20050	149.6673	-2.358129
34.25050	149.6653	-2.370057
34.30383	149.6644	-2.384946
34.35383	149.6631	-2.401308
34.40716	149.6624	-2.419724
34.45716	149.6604	-2.434170
34.51050	149.6602	-2.450492
34.56050	149.6589	-2.463566
34.61383	149.6584	-2.475606
34.66383	149.6577	-2.487719
34.71716	149.6561	-2.499264
34.76716	149.6558	-2.510422
34.82050	149.6534	-2.520970
34.87050	149.6531	-2.531526
34.92216	149.6525	-2.542122
34.97383	149.6514	-2.552510
35.02550	149.6511	-2.563600
35.07717	149.6498	-2.574506
35.12883	149.6489	-2.585918
35.18050	149.6493	-2.597720
35.23216	149.6482	-2.609190
35.28383	149.6471	-2.620032
35.33383	149.6466	-2.629864
35.38716	149.6457	-2.640345
35.43716	149.6453	-2.650145
35.49050	149.6440	-2.660504
35.54050	149.6433	-2.670134
35.59384	149.6427	-2.680363
35.64383	149.6428	-2.690021
35.69717	149.6413	-2.700330
35.74716	149.6412	-2.710009
35.80050	149.6405	-2.720444
35.85050	149.6389	-2.730259
35.90383	149.6394	-2.740816
35.95383	149.6385	-2.750432
36.00550	149.6391	-2.760275
36.05716	149.6375	-2.769968
36.10883	149.6380	-2.779556
36.16050	149.6371	-2.789052
36.21216	149.6369	-2.798525
36.26383	149.6360	-2.807839
36.31550	149.6355	-2.817080
36.36716	149.6349	-2.826236
36.41716	149.6344	-2.835001
36.47050	149.6349	-2.844297
36.52050	149.6336	-2.852898
36.57383	149.6333	-2.861992
36.62383	149.6325	-2.870366
36.67717	149.6322	-2.879030
36.72717	149.6309	-2.887078
36.78050	149.6306	-2.895492
36.83050	149.6313	-2.903284
36.88383	149.6296	-2.911384
36.93384	149.6296	-2.918873
36.98717	149.6286	-2.926791
37.03717	149.6282	-2.934248
37.08883	149.6282	-2.941822
37.14050	149.6282	-2.949329
37.19216	149.6282	-2.956745
37.24383	149.6272	-2.964016
37.29550	149.6267	-2.971138
37.34716	149.6262	-2.978159
37.39883	149.6256	-2.985070
37.45050	149.6257	-2.991840
37.50050	149.6250	-2.998304
37.55383	149.6251	-3.005056
37.60383	149.6254	-3.011306
37.65716	149.6236	-3.017898
37.70716	149.6250	-3.024168
37.76050	149.6236	-3.030644
37.81050	149.6233	-3.036697
37.86383	149.6232	-3.043066
37.91383	149.6239	-3.048906
37.96716	149.6234	-3.055008
38.01716	149.6236	-3.060603
38.07050	149.6220	-3.066392
38.12050	149.6224	-3.071709
38.17216	149.6222	-3.077076
38.22383	149.6206	-3.082364
38.27550	149.6208	-3.087610
38.32717	149.6213	-3.092745
38.37883	149.6197	-3.097736
38.43050	149.6202	-3.102725
38.48216	149.6199	-3.107559
38.53383	149.6192	-3.112282
38.58383	149.6184	-3.116770
38.63716	149.6189	-3.121590
38.68716	149.6189	-3.126025
38.74050	149.6186	-3.130852
38.79050	149.6181	-3.135382
38.84384	149.6185	-3.140164
38.89383	149.6184	-3.144554
38.94717	149.6182	-3.149200
38.99716	149.6185	-3.153526
39.05050	149.6188	-3.157968
39.10050	149.6175	-3.161949
39.15383	149.6171	-3.166016
39.20383	149.6176	-3.169692
39.25550	149.6179	-3.173437
39.30716	149.6172	-3.177159
39.35883	149.6172	-3.180881
39.41050	149.6171	-3.184552
39.46216	149.6167	-3.188255
39.51383	149.6162	-3.191841
39.56550	149.6162	-3.195528
39.61716	149.6164	-3.199078
39.66716	149.6162	-3.202444
39.72050	149.6166	-3.205994
39.77050	149.6153	-3.209171
39.82383	149.6160	-3.212690
39.87383	149.6154	-3.215752
39.92717	149.6164	-3.218991
39.97717	149.6162	-3.222010
40.03050	149.6150	-3.225075
40.08050	149.6152	-3.227928
40.13383	149.6152	-3.230932
40.18384	149.6149	-3.233670
40.23717	149.6148	-3.236526
40.28717	149.6141	-3.239090
40.33883	149.6142	-3.241773
40.39050	149.6140	-3.244328
40.44216	149.6134	-3.246836
40.49383	149.6136	-3.249366
40.54550	149.6130	-3.251958
40.59716	149.6128	-3.254517
40.64883	149.6129	-3.257178
40.70050	149.6133	-3.259844
40.75050	149.6124	-3.262354
40.80383	149.6136	-3.265082
40.85383	149.6139	-3.267492
40.90716	149.6135	-3.269996
40.95716	149.6126	-3.272263
41.01050	149.6129	-3.274631
41.06050	149.6127	-3.276797
41.11383	149.6125	-3.279019
41.16383	149.6129	-3.281122
41.21717	149.6124	-3.283355
41.26717	149.6124	-3.285424
41.32050	149.6126	-3.287536
41.37050	149.6127	-3.289416
41.42216	149.6118	-3.291224
41.47383	149.6118	-3.292994
41.52550	149.6113	-3.294742
41.57717	149.6120	-3.296454
41.62883	149.6112	-3.298168
41.68050	149.6106	-3.299955
41.73217	149.6109	-3.301724
41.78383	149.6117	-3.303498
41.83383	149.6114	-3.305133
41.88716	149.6105	-3.306883
41.93716	149.6106	-3.308505
41.99050	149.6113	-3.310188
42.04050	149.6112	-3.311730
42.09384	149.6103	-3.313373
42.14383	149.6101	-3.314937
42.19717	149.6107	-3.316562
42.24716	149.6112	-3.318106
42.30050	149.6104	-3.319666
42.35050	149.6106	-3.321094
42.40383	149.6105	-3.322607
42.45383	149.6098	-3.324008
42.50550	149.6100	-3.325464
42.55717	149.6100	-3.326910
42.60883	149.6102	-3.328300
42.66050	149.6102	-3.329622
42.71216	149.6102	-3.331038
42.76383	149.6096	-3.332343
42.81550	149.6096	-3.333668
42.86716	149.6107	-3.334994
42.91716	149.6095	-3.336221
42.97050	149.6093	-3.337434
43.01717	149.6089	-3.338583
43.07050	149.6925	-5.083618
43.12050	150.0191	-9.112636
43.17216	150.5145	-13.02924
43.22383	151.1266	-16.49829
43.27550	151.8272	-19.33117
43.32717	152.5966	-21.62868
43.37883	153.4186	-23.46482
43.43050	154.2802	-24.94025
43.48217	155.1739	-26.14262
43.53383	156.0931	-27.11227
43.58383	157.0016	-27.89768
43.63716	157.9852	-28.59254
43.68716	158.9214	-29.14302
43.74050	159.9290	-29.63943
43.79050	160.8809	-30.05081
43.84384	161.9037	-30.43772
43.89383	162.8666	-30.76770
43.94717	163.8982	-31.09320
43.99716	164.8705	-31.36464
44.05050	165.9078	-31.64028
44.10050	166.8832	-31.89780
44.15383	167.9244	-32.15053
44.20383	168.9012	-32.39368
44.25550	169.9127	-32.63753
44.30717	170.9246	-32.88872
44.35883	171.9376	-33.13337
44.41050	172.9517	-33.37650
44.46216	173.9640	-33.61471
44.51383	174.9788	-33.86860
44.56550	175.9934	-34.11920
44.61716	177.0075	-34.39983
44.66716	177.9891	-34.66533
44.72050	179.0346	-34.94810
44.77050	180.0168	-35.24658
44.82383	181.0624	-35.56640
44.87383	182.0438	-35.87406
44.92717	183.0886	-36.22688
44.97717	184.0683	-36.56545
45.03050	185.1112	-36.94320
45.08050	186.0900	-37.29270
45.13383	187.1335	-37.70170
45.18383	188.1108	-38.10000
45.23717	189.1525	-38.53222
45.28717	190.1280	-38.95876
45.33883	191.1342	-39.42109
45.39050	192.1405	-39.90812
45.44217	193.1449	-40.41080
45.49383	194.1470	-40.95310
45.54550	195.1484	-41.51322
45.59716	196.1482	-42.13234
45.64883	197.1462	-42.77372
45.70050	198.1426	-43.45480
45.75050	199.1037	-44.17011
45.80383	200.1272	-44.89865
45.85383	201.0873	-45.60592
45.90717	202.1108	-46.35738
45.95717	203.0697	-47.10770
46.01050	204.0889	-48.05804
46.06050	205.0365	-49.09736
46.11383	206.0384	-50.37802
46.16383	206.9709	-51.76366
46.21717	207.9506	-53.52765
46.26717	208.8537	-55.54114
46.32050	209.7948	-58.18080
46.37050	210.6529	-61.11909
46.42216	211.5118	-64.69570
46.47383	212.3396	-68.76172
46.52550	213.1449	-72.82030
46.57717	213.9606	-76.00538
46.62883	214.7908	-79.16074
46.68050	215.6318	-82.21518
46.73217	216.4755	-85.50806
46.78383	217.3156	-88.79742
46.83383	218.1348	-91.61474
46.88716	219.0306	-93.75882
46.93716	219.9227	-94.03622
46.99050	220.9841	-90.94192
47.04050	222.1358	-85.06049
47.09384	223.4954	-78.11736
47.14383	224.8351	-71.36290
47.19717	226.3129	-63.61282
47.24716	227.7152	-57.35584
47.30050	229.1546	-52.84413
47.35050	230.4337	-49.75016
47.40383	231.7319	-47.25976
47.45383	232.8995	-45.46280
47.50550	234.0664	-44.04817
47.55717	235.2032	-42.95812
47.60883	236.3162	-42.11908
47.66050	237.4110	-41.49670
47.71216	238.4908	-41.02098
47.76383	239.5591	-40.75807
47.81550	240.6178	-40.44289
47.86716	241.6717	-40.27048
47.91716	242.6858	-40.15746
47.97050	243.7644	-40.08742
48.02050	244.7715	-40.03803
48.07383	245.8440	-40.00911
48.12383	246.8482	-39.99681
48.17717	247.9182	-39.99208
48.22717	248.9196	-39.99224
48.28050	249.9869	-39.99307
48.33050	250.9878	-40.00232
48.38383	252.0523	-40.02908
48.43383	253.0514	-40.07817
48.48717	254.1165	-40.14398
48.53717	255.1155	-40.22090
48.58883	256.1465	-40.30557
48.64050	257.1790	-40.38580
48.69217	258.2104	-40.46211
48.74383	259.2412	-40.54334
48.79550	260.2720	-40.61238
48.84716	261.3028	-40.70832
48.89883	262.3323	-40.79606
48.95050	263.3625	-40.88654
49.00050	264.3589	-40.97262
49.05383	265.4228	-41.07182
49.10383	266.4200	-41.13720
49.15717	267.4822	-41.23785
49.20717	268.4788	-41.32176
49.26050	269.5428	-41.41328
49.31050	270.5388	-41.48234
49.36383	271.6011	-41.57822
49.41383	272.5980	-41.66820
49.46717	273.6606	-41.69070
49.51383	274.5900	-41.77620
49.56550	275.4676	-42.92828
49.61716	275.8125	-35.53555
49.66716	275.8294	-25.63264
49.72050	275.6020	-15.89078
49.77050	275.2224	-8.305606
49.82383	274.6822	-1.827234
49.87383	274.0775	2.975750
49.92717	273.3515	7.018100
49.97717	272.6092	10.00739
50.03050	271.7689	12.51825
50.08050	270.9449	14.38608
50.13383	270.0321	15.96724
50.18383	269.1538	17.15532
50.23717	268.1960	18.17889
50.28717	267.2824	18.95168
50.33883	266.3274	19.61362
50.39050	265.3597	20.15131
50.44217	264.3844	20.59940
50.49383	263.4028	20.98292
50.54550	262.4134	21.29444
50.59716	261.4205	21.56417
50.64883	260.4228	21.79182
50.70050	259.4219	21.99048
50.75050	258.4497	22.15861
50.80383	257.4102	22.30907
50.85383	256.4348	22.44376
50.90717	255.3924	22.56386
50.95717	254.4126	22.68253
51.01050	253.3660	22.77684
51.06050	252.3842	22.86772
51.11383	251.3347	22.94900
51.16383	250.3514	23.02076
51.21717	249.3006	23.10064
51.26716	248.3156	23.16550
51.32050	247.2639	23.23852
51.37050	246.2778	23.29093
51.42217	245.2586	23.34870
51.47383	244.2372	23.39848
51.52550	243.2168	23.44146
51.57717	242.1953	23.48350
51.62883	241.1726	23.52242
51.68050	240.1497	23.55477
51.73217	239.1270	23.59609
51.78383	238.1049	23.63147
51.83383	237.1142	23.66461
51.88716	236.0574	23.69672
51.93716	235.0684	23.72190
51.99050	234.0124	23.75221
52.04050	233.0220	23.77796
52.09384	231.9656	23.80988
52.14384	230.9743	23.84263
52.19717	229.9180	23.86914
52.24717	228.9271	23.89420
52.30050	227.8706	23.93838
52.35050	226.8807	23.97564
52.40383	225.8239	24.01812
52.45383	224.8340	24.06191
52.50550	223.8079	24.09674
52.55717	222.7844	24.11716
52.60883	221.7591	24.14447
52.66050	220.7355	24.16638
52.71216	219.7108	24.19559
52.76382	218.6850	24.22096
52.81550	217.6597	24.23889
52.86716	216.6348	24.25494
52.91716	215.6435	24.27237
52.97050	214.5861	24.29575
53.02050	213.5933	24.32433
53.07383	212.5347	24.34511
53.12383	211.5415	24.36592
53.17717	210.4835	24.38502
53.22717	209.4899	24.40041
53.28050	208.4309	24.41302
53.33050	207.4380	24.42638
53.38383	206.3790	24.44312
53.43383	205.3858	24.45490
53.48717	204.3278	24.46692
53.53716	203.3351	24.47796
53.58882	202.3091	24.48673
53.64050	201.2836	24.49738
53.69216	200.2582	24.50933
53.74382	199.2323	24.52522
53.79550	198.2059	24.54140
53.84716	197.1787	24.55374
53.89883	196.1524	24.56936
53.95050	195.1263	24.58061
54.00050	194.1318	24.59590
54.05383	193.0728	24.60630
54.10383	192.0791	24.62076
54.15717	191.0200	24.63385
54.20717	190.0267	24.64354
54.26050	188.9664	24.65594
54.31050	187.9733	24.66649
54.36382	186.9135	24.68128
54.41382	185.9210	24.69100
54.46717	184.8614	24.70466
54.51716	183.8681	24.71421
54.57050	182.8094	24.72976
54.62050	181.8154	24.74238
54.67217	180.7899	24.75430
54.72382	179.7638	24.77426
54.77550	178.7381	24.79785
54.82717	177.7109	24.82494
54.87883	176.6848	24.85437
54.93050	175.6584	24.88374
54.98217	174.6317	24.90735
55.03383	173.6038	24.93338
55.08383	172.6114	24.95466
55.13716	171.5514	25.01929
55.18716	170.5615	25.13392
55.24050	169.5082	25.38435
55.29050	168.5250	25.71638
55.34384	167.4879	26.30543
55.39384	166.5310	27.25476
55.44717	165.5408	29.00722
55.49717	164.6560	31.61603
55.55050	163.7755	35.60900
55.60050	163.0153	40.32170
55.65383	162.2607	45.85195
55.70383	161.5808	50.83891
55.75550	160.8700	55.27710
55.80717	160.1222	58.63530
55.85883	159.3138	60.71101
55.91050	158.4336	61.56989
55.96216	157.4786	61.31542
56.01382	156.4540	60.12670
56.06550	155.3711	58.24928
56.11716	154.2403	55.86918
56.16716	153.1124	53.28164
56.22050	151.8848	50.32716
56.27050	150.7189	47.53084
56.32383	149.4710	44.64350
56.37383	148.3040	42.11699
56.42717	147.0686	39.67649
56.47717	145.9236	37.67536
56.53050	144.7200	35.81989
56.58050	143.6077	34.33806
56.63383	142.4371	33.01058
56.68383	141.3553	31.95740
56.73717	140.2170	31.02926
56.78716	139.1601	30.28910
56.83882	138.0778	29.63306
56.89050	137.0053	29.10108
56.94216	135.9392	28.64142
56.99382	134.8797	28.25532
57.04550	133.8243	27.93712
57.09716	132.7756	27.65732
57.14883	131.7278	27.41200
57.20050	130.6830	27.20203
57.25050	129.6746	27.02709
57.30383	128.6000	26.86360
57.35383	127.5945	26.73498
57.40717	126.5222	26.58889
57.45717	125.5168	26.45400
57.51050	124.4461	26.32871
57.56050	123.4432	26.21377
57.61382	122.3745	26.10788
57.66382	121.3735	26.01462
57.71717	120.3059	25.92206
57.76716	119.3048	25.83480
57.82050	118.2379	25.75190
57.87050	117.2377	25.68721
57.92217	116.2034	25.61078
57.97382	115.1701	25.53940
58.02550	114.1368	25.46471
58.07717	113.1028	25.38628
58.12883	112.0692	25.30638
58.18050	111.0360	25.24462
58.23217	110.0034	25.16833
58.28383	108.9702	25.10788
58.33383	107.9704	25.02518
58.38716	106.9044	24.94746
58.43716	105.9042	24.86456
58.49050	104.8369	24.78502
58.54050	103.8371	24.72180
58.59384	102.7703	24.64900
58.64384	101.7703	24.57594
58.69717	100.7048	24.51302
58.74717	99.70549	24.44331
58.80050	98.63909	24.36458
58.85050	97.63894	24.28831
58.90383	96.57226	24.21214
58.95383	95.57141	24.13712
59.00550	94.53863	24.05737
59.05717	93.50391	23.97965
59.10883	92.46978	23.87330
59.16050	91.43629	23.80966
59.21216	90.40352	23.73258
59.26382	89.36974	23.67142
59.31550	88.33735	23.60229
59.36716	87.30532	23.54131
59.41716	86.30518	23.46834
59.47050	85.23975	23.39714
59.52050	84.23999	23.34038
59.57383	83.17431	23.27560
59.62383	82.17538	23.21685
59.67717	81.10991	23.15532
59.72717	80.11151	23.09597
59.78050	79.04337	23.03569
59.83050	78.04556	22.96887
59.88383	76.97975	22.91180
59.93383	75.98162	22.85534
59.98717	74.91565	22.80383
60.03716	73.91862	22.74563
60.08882	72.88528	22.68304
60.14050	71.85241	22.61871
60.19216	70.82100	22.55730
60.24382	69.78705	22.49184
60.29550	68.75474	22.42186
60.34716	67.72147	22.35124
60.39883	66.68906	22.28400
60.45050	65.65568	22.22545
60.50050	64.65748	22.15036
60.55383	63.59180	22.08147
60.60383	62.59194	22.01144
60.65717	61.52598	21.94153
60.70717	60.52694	21.87150
60.76050	59.46081	21.80416
60.81050	58.46030	21.73498
60.86382	57.39416	21.66031
60.91382	56.39389	21.59142
60.96717	55.32774	21.51893
61.01716	54.32659	21.44646
61.07050	53.26040	21.36660
61.12050	52.26152	21.30413
61.17217	51.22776	21.22614
61.22382	50.19372	21.16254
61.27550	49.15998	21.08778
61.32717	48.12680	21.01421
61.37883	47.09290	20.94815
61.43050	46.05830	20.88244
61.48217	45.02411	20.81104
61.53383	43.99024	20.74041
61.58383	42.98935	20.66876
61.63716	41.92118	20.58544
61.68716	40.92052	20.50787
61.74050	39.85272	20.42188
61.79050	38.85094	20.33247
61.84384	37.78195	20.23471
61.89384	36.78020	20.14516
61.94717	35.71048	20.05400
61.99717	34.70800	19.95832
62.05050	33.64022	19.85018
62.10050	32.63844	19.75305
62.15383	31.56797	19.64951
62.20383	30.56178	19.38051
62.25550	29.51198	19.15539
62.30717	28.47507	19.14055
62.35883	27.43971	19.08546
62.41050	26.40414	19.00466
62.46216	25.36816	18.95766
62.51050	24.39925	18.96136
62.56050	23.50662	19.33852
62.61382	23.10941	14.51020
62.66382	23.06356	8.825028
62.71717	23.27281	3.338563
62.76716	23.64666	-0.8282105
62.82050	24.19132	-4.389083
62.87050	24.80601	-7.016774
62.92217	25.52319	-9.192609
62.97382	26.30273	-10.91099
63.02550	27.13222	-12.29003
63.07717	28.00055	-13.40961
63.12883	28.89688	-14.30290
63.18050	29.81678	-15.04413
63.23217	30.75657	-15.65783
63.28383	31.70764	-16.17198
63.33383	32.64090	-16.59969
63.38716	33.64444	-16.97444
63.43716	34.59366	-17.29689
63.49050	35.61220	-17.57671
63.54050	36.57150	-17.82560
63.59384	37.59932	-18.06521
63.64384	38.56683	-18.25336
63.69717	39.60225	-18.43880
63.74717	40.57569	-18.61079
63.80050	41.61590	-18.76173
63.85050	42.59350	-18.90371
63.90383	43.63824	-19.04205
63.95383	44.61784	-19.16618
64.00550	45.63086	-19.29734
64.05717	46.64590	-19.42496
64.10884	47.66202	-19.55237
64.16050	48.67974	-19.67794
64.21217	49.69552	-19.79905
64.26384	50.71410	-19.92118
64.31550	51.73228	-20.04289
64.36718	52.75266	-20.15698
64.41717	53.74014	-20.26469
64.47050	54.79344	-20.38257
64.52050	55.78063	-20.48976
64.57384	56.83530	-20.61576
64.62383	57.82472	-20.73135
64.67718	58.88012	-20.84366
64.72718	59.87014	-20.95930
64.78050	60.92672	-21.07928
64.83050	61.91856	-21.18052
64.88384	62.97446	-21.29873
64.93384	63.96693	-21.39594
64.98717	65.02508	-21.51000
65.03717	66.01680	-21.61604
65.08884	67.04066	-21.73313
65.14050	68.06600	-21.84682
65.19217	69.09168	-21.96050
65.24384	70.11612	-22.06637
65.29550	71.14105	-22.18486
65.34717	72.16637	-22.29780
65.39883	73.19188	-22.41264
65.45050	74.21788	-22.52644
65.50050	75.20955	-22.63649
65.55384	76.26910	-22.75410
65.60384	77.26234	-22.86934
65.65718	78.32050	-22.99128
65.70718	79.31280	-23.11545
65.76050	80.37259	-23.23314
65.81050	81.36618	-23.34800
65.86384	82.42545	-23.46846
65.91382	83.41849	-23.58219
65.96718	84.47844	-23.70902
66.01716	85.46941	-23.82558
66.07050	86.52897	-23.96056
66.12050	87.52188	-24.07825
66.17218	88.54842	-24.18899
66.22384	89.57455	-24.33532
66.27550	90.60053	-24.45010
66.32718	91.62701	-24.57489
66.37884	92.65247	-24.69680
66.43050	93.68031	-24.81530
66.48218	94.70672	-24.93253
66.53384	95.73319	-25.05779
66.58384	96.72731	-25.16342
66.63718	97.78624	-25.29507
66.68718	98.77981	-25.40868
66.74050	99.84001	-25.53436
66.79050	100.8340	-25.65166
66.84384	101.8938	-25.77734
66.89384	102.8876	-25.88627
66.94718	103.9494	-26.00980
66.99718	104.9442	-26.11688
67.05050	106.0040	-26.22448
67.10050	106.9992	-26.34215
67.15384	108.0611	-26.47258
67.20384	109.0535	-26.59142
67.25550	110.0806	-26.73279
67.30718	111.1079	-26.85748
67.35884	112.1344	-26.98990
67.41050	113.1608	-27.11295
67.46218	114.1865	-27.24112
67.51384	115.2132	-27.38513
67.56550	116.2393	-27.50748
67.61718	117.2661	-27.64224
67.66718	118.2594	-27.77514
67.72050	119.3192	-27.91804
67.77050	120.3125	-28.05395
67.82384	121.3733	-28.19970
67.87384	122.3666	-28.33697
67.92718	123.4256	-28.49639
67.97718	124.4181	-28.63028
68.03050	125.4757	-28.79120
68.08050	126.4684	-28.92236
68.13384	127.5270	-29.07709
68.18384	128.5194	-29.22422
68.23718	129.5771	-29.38902
68.28718	130.5697	-29.55542
68.33884	131.5954	-29.69362
68.39050	132.6206	-29.85789
68.44218	133.6451	-30.01648
68.49384	134.6701	-30.18926
68.54550	135.6944	-30.36210
68.59718	136.7186	-30.54366
68.64884	137.7430	-30.71482
68.70050	138.7664	-30.89112
68.75050	139.7573	-31.07703
68.80384	140.8134	-31.27278
68.85384	141.8035	-31.45698
68.90718	142.8599	-31.65500
68.95718	143.8496	-31.85225
69.01050	144.9061	-32.07022
69.06050	145.8954	-32.27164
69.11384	146.9489	-32.50147
69.16382	147.9367	-32.73660
69.21718	148.9906	-33.01130
69.26716	149.9748	-33.28414
69.32050	151.0231	-33.68231
69.37050	152.0036	-33.99092
69.42218	153.0183	-34.22595
69.47384	154.0412	-34.28055
69.52550	155.0677	-34.31531
69.57718	156.0980	-34.36100
69.62884	157.1295	-34.43290
69.68050	158.1585	-34.54086
69.73218	159.1882	-34.66524
69.78384	160.2175	-34.78064
69.83384	161.2144	-34.89126
69.88718	162.2761	-34.97796
69.93718	163.2744	-35.06503
69.99050	164.3384	-35.13641
70.04050	165.3361	-35.18140
70.09384	166.4012	-35.24300
70.14384	167.3989	-35.29230
70.19718	168.4642	-35.35400
70.24718	169.4615	-35.42363
70.30050	170.5244	-35.54381
70.35050	171.5202	-35.67063
70.40384	172.5814	-35.79941
70.45384	173.5748	-35.94920
70.50550	174.6018	-36.11453
70.55718	175.6275	-36.28963
70.60884	176.6519	-36.48563
70.66050	177.6753	-36.68695
70.71218	178.6977	-36.92688
70.76384	179.7190	-37.18912
70.81550	180.7373	-37.48685
70.86718	181.7547	-37.82446
70.91718	182.7386	-38.16600
70.97050	183.7838	-38.56676
71.02050	184.7624	-39.00354
71.07384	185.8031	-39.50420
71.12384	186.7764	-40.03738
71.17718	187.8122	-40.66086
71.22718	188.7785	-41.31679
71.28050	189.8055	-42.09310
71.33050	190.7644	-42.86813
71.38384	191.7819	-43.75664
71.43384	192.7338	-44.62752
71.48718	193.7481	-45.54350
71.53718	194.6966	-46.43462
71.58884	195.6764	-47.38608
71.64050	196.6538	-48.37436
71.69218	197.6295	-49.41050
71.74384	198.5994	-50.56524
71.79550	199.5666	-51.82656
71.84718	200.5268	-53.19734
71.89884	201.4805	-54.67660
71.95050	202.4313	-56.16961
72.00050	203.3480	-57.63132
72.05384	204.3241	-59.15926
72.10384	205.2418	-60.48041
72.15718	206.2290	-61.54588
72.20718	207.1736	-61.95051
72.26050	208.2187	-61.45436
72.31050	209.2614	-58.94508
72.36384	210.4608	-54.84853
72.41382	211.6570	-50.51340
72.46718	212.9603	-46.60637
72.51716	214.1644	-44.00028
72.57050	215.4095	-42.04668
72.62050	216.5402	-40.70531
72.67218	217.6762	-39.64801
72.72384	218.7894	-38.84794
72.77550	219.8832	-38.24925
72.82718	220.9627	-37.81212
72.87884	222.0317	-37.47395
72.93050	223.0911	-37.24890
72.98218	224.1450	-37.08234
73.03384	225.1945	-36.96129
73.08384	226.2031	-36.90360
73.13718	227.2780	-36.85844
73.18718	228.2848	-36.84110
73.24050	229.3558	-36.83975
73.29050	230.3578	-36.84037
73.34384	231.4254	-36.84719
73.39384	232.4256	-36.88310
73.44718	233.4910	-36.94900
73.49718	234.4883	-37.03260
73.55050	235.5525	-37.11982
73.60050	236.5518	-37.18462
73.65384	237.6156	-37.25878
73.70384	238.6145	-37.32527
73.75550	239.6455	-37.39764
73.80718	240.6770	-37.47528
73.85884	241.7072	-37.55630
73.91050	242.7379	-37.64875
73.96218	243.7676	-37.73150
74.01384	244.7985	-37.81080
74.06550	245.8276	-37.89356
74.11718	246.8582	-37.97542
74.16718	247.8556	-38.04705
74.22050	248.9184	-38.11650
74.27050	249.9162	-38.19818
74.32384	250.9795	-38.28100
74.37384	251.9766	-38.35635
74.42718	253.0397	-38.42765
74.47718	254.0372	-38.50298
74.53050	255.1005	-38.58977
74.58050	256.0978	-38.67479
74.63384	257.1607	-38.75772
74.68384	258.1581	-38.84283
74.73718	259.2217	-38.92878
74.78718	260.2178	-38.99680
74.83884	261.2492	-39.08500
74.89050	262.2800	-39.17584
74.94218	263.3093	-39.25938
74.99384	264.3398	-39.35012
75.04550	265.3696	-39.44102
75.09718	266.3996	-39.53062
75.14884	267.4291	-39.62970
75.20050	268.4588	-39.73356
75.25050	269.4548	-39.81687
75.30384	270.5174	-39.90832
-2.000000	5.000000	0.0000000