File: 7-C1(1.2mol%)+C20(0.6mol%)(1)/matlab/160-3.txt
CLOSED
Version	1.0
Language	English
Mode	Standard
Run	34
RunSerial	12302
Instrument	DSC Q2000 V24.11 Build 124
Module	DSC Standard Cell RC
Operator
File	\\AE520-1454\Users\dsc\Desktop\Data\29-08-17-3\160-3.001
ProcName
InstSerial	2000-0883
AutoSerial	1293
Sample	160-3
Size	27.0000	mg
PanMass	Not available
PanResist	Automatic Automatic  K/W
PanFactor	Default Default
Method
Comment
Xcomment	Pan: Tzero Aluminum Hermetic
Xcomment	Gas1: Nitrogen 50.0 ml/min
Xcomment	Gas2: Nitrogen 50.0 ml/min
Text
Exotherm	UP
Kcell	1.05230
Cpconst	Standard: 0.938
Calib	-38.6961
TempCal	1	pts	157.46	156.60
TzeroDt	-87.6168 -0.0009 -1.4231
TzeroDtz	-87.6168 0.0057 6.9570
InstCalFile	Tzero: \\Ae520-1454\ta\Data\DSC\Calibration\2017\CALIBRATION\1562_RCS (90)_05_18_2017 10_50_44.TZR
InstCalFile	Baseline: \\Ae520-1454\ta\Data\DSC\Calibration\2017\2017-05-17_Calibration.001
InstCalFile	Sapphire: \\Ae520-1454\ta\Data\DSC\Calibration\2017\2017-05-17_Saphire.001
InstCalDate	Tzero 2017-05-18 Time 10:50:44
TempRange	-87.39 to 398.39 °C at 10.00 °C/min Heat Only
AutoZero	Delta T Offset 0.000 uV
AutoZero	Delta T0 Offset 0.000 uV
MultiptCal	0
MultiPtDesc	0) Not set
AutoCellConst	Calibration Date 2017-05-18 16:59:28
Controls	Gas 1  Event Off  Sampling 0.2
Cell#	RC-01562
CoolingUnit	RCS (90)
SelHeatFlow	Heat Flow T4P (mW)
AutoLidII	Installed
AutoAnalysis	Off
MacroFile
Nsig	3
Sig1	Time (min)
Sig2	Temperature (°C)
Sig3	Heat Flow (mW)
Date	2017-08-31
Time	08:21:32
OrgMethod	1: Equilibrate at 80.00 °C
OrgMethod	2: Isothermal for 3.00 min
OrgMethod	3: Jump to 160.00 °C
OrgMethod	4: Mark end of cycle 1
OrgMethod	5: Isothermal for 40.00 min
OrgMethod	6: Mark end of cycle 2
OrgMethod	7: Ramp 20.00 °C/min to 280.00 °C
OrgMethod	8: Mark end of cycle 3
OrgMethod	9: Ramp 20.00 °C/min to 20.00 °C
OrgMethod	10: Mark end of cycle 4
OrgMethod	11: Ramp 20.00 °C/min to 280.00 °C
OrgMethod	12: Mark end of cycle 5
OrgFile	C:\Users\jarra\Desktop\DSC\7-C1(1.2mol%)+C20(0.6mol%)(1)\160-3.001
StartOfData
4.99994E-4	79.66894	-3.913060
0.05383332	79.72242	-3.190283
0.1038333	79.76034	-2.671256
0.1555000	79.78980	-2.263932
0.2071666	79.81140	-1.952154
0.2571667	79.82636	-1.721066
0.3105000	79.84003	-1.543549
0.3605000	79.84824	-1.413266
0.4121666	79.85407	-1.319920
0.4638333	79.85799	-1.248006
0.5138333	79.86094	-1.200723
0.5655000	79.86306	-1.164490
0.6171668	79.86365	-1.139297
0.6671668	79.86443	-1.124801
0.7205000	79.86300	-1.116397
0.7705000	79.86332	-1.112738
0.8221666	79.86350	-1.110272
0.8738332	79.86230	-1.107688
0.9238334	79.86089	-1.105337
0.9755000	79.86093	-1.103240
1.027167	79.85894	-1.101257
1.077166	79.85872	-1.099645
1.130500	79.85725	-1.098219
1.180500	79.85542	-1.097235
1.232166	79.85428	-1.096470
1.283834	79.85375	-1.096057
1.333833	79.85289	-1.095814
1.385500	79.85178	-1.095827
1.437167	79.85126	-1.096088
1.487166	79.84972	-1.096437
1.540500	79.84849	-1.097109
1.590500	79.84876	-1.097955
1.642166	79.84793	-1.098986
1.693833	79.84556	-1.100129
1.743833	79.84576	-1.101426
1.795500	79.84472	-1.102825
1.847167	79.84350	-1.104397
1.897167	79.84304	-1.105978
1.950500	79.84174	-1.107743
2.000500	79.84161	-1.109676
2.052166	79.84063	-1.111738
2.103833	79.83941	-1.113881
2.153833	79.83969	-1.116124
2.205500	79.83872	-1.118424
2.257167	79.83840	-1.120810
2.307167	79.83799	-1.123195
2.360500	79.83699	-1.125744
2.410500	79.83590	-1.128235
2.462167	79.83518	-1.130910
2.513833	79.83424	-1.133508
2.563833	79.83418	-1.136068
2.617167	79.83312	-1.138772
2.667167	79.83280	-1.141422
2.717167	79.83222	-1.144056
2.770500	79.83115	-1.146763
2.820500	79.83019	-1.149406
2.872167	79.82892	-1.152219
2.923834	79.83020	-1.154996
2.973833	79.82910	-1.157585
3.020500	79.85516	-1.699553
3.073833	80.79298	-16.51450
3.123834	82.88653	-30.70710
3.175500	85.64564	-43.83020
3.227167	88.86969	-55.70157
3.277167	92.33259	-65.46958
3.328833	96.17840	-73.95530
3.380500	100.2260	-80.95214
3.430500	104.2818	-86.56078
3.483833	108.7215	-91.47012
3.533833	112.9551	-95.22543
3.585500	117.3789	-98.49200
3.637167	121.8290	-101.3634
3.687167	126.1566	-103.6371
3.738834	130.6410	-105.6097
3.790500	135.1280	-107.3011
3.840500	139.4672	-108.7093
3.893833	143.8793	-106.1230
3.943833	146.9488	-92.99696
3.995500	149.2760	-80.18334
4.047167	151.0569	-68.16524
4.097166	152.3889	-58.15768
4.150500	153.5037	-49.27960
4.200500	154.3168	-42.73025
4.250500	154.9704	-37.39584
4.303834	155.5375	-32.89172
4.353833	155.9682	-29.57296
4.405500	156.3414	-26.83119
4.457167	156.6528	-24.65968
4.507167	156.9089	-22.97751
4.560500	157.1426	-21.54281
4.610500	157.3304	-20.45415
4.660500	157.4943	-19.55719
4.713834	157.6462	-18.75430
4.763834	157.7718	-18.11939
4.815500	157.8862	-17.54406
4.867166	157.9899	-17.04530
4.917167	158.0784	-16.61102
4.970500	158.1639	-16.19856
5.020500	158.2359	-15.83689
5.070500	158.3020	-15.50321
5.123833	158.3660	-15.15611
5.173834	158.4222	-14.82564
5.225500	158.4786	-14.47867
5.277168	158.5312	-14.12448
5.327168	158.5790	-13.79359
5.380500	158.6261	-13.44741
5.430500	158.6681	-13.12022
5.480500	158.7086	-12.78558
5.533832	158.7502	-12.41645
5.583832	158.7898	-12.03788
5.635500	158.8310	-11.64215
5.687168	158.8690	-11.25005
5.737168	158.9043	-10.87566
5.790500	158.9433	-10.47018
5.840500	158.9782	-10.07495
5.890500	159.0133	-9.667831
5.943832	159.0494	-9.253744
5.993834	159.0804	-8.883734
6.045500	159.1116	-8.530069
6.097168	159.1398	-8.205488
6.147168	159.1646	-7.923056
6.200500	159.1888	-7.656400
6.250500	159.2087	-7.423619
6.300500	159.2275	-7.208320
6.353832	159.2478	-6.950553
6.403832	159.2677	-6.722876
6.455500	159.2870	-6.482480
6.507168	159.3062	-6.242283
6.557166	159.3248	-5.996718
6.610500	159.3459	-5.725784
6.660500	159.3657	-5.482992
6.712168	159.3836	-5.264576
6.763834	159.3982	-5.082569
6.813834	159.4110	-4.930954
6.865500	159.4230	-4.794982
6.917168	159.4334	-4.673703
6.967168	159.4428	-4.559278
7.020500	159.4526	-4.452430
7.070500	159.4606	-4.358204
7.122168	159.4681	-4.265412
7.173834	159.4762	-4.183150
7.223834	159.4811	-4.103504
7.275500	159.4886	-4.027882
7.327168	159.4942	-3.950572
7.377168	159.5005	-3.872166
7.430500	159.5079	-3.775412
7.480500	159.5150	-3.683713
7.532166	159.5207	-3.589715
7.583832	159.5280	-3.504432
7.633832	159.5340	-3.427222
7.685500	159.5400	-3.346817
7.737168	159.5460	-3.271770
7.787168	159.5513	-3.198940
7.840500	159.5572	-3.125417
7.890500	159.5638	-3.055101
7.942168	159.5688	-2.981670
7.993834	159.5756	-2.906801
8.043834	159.5818	-2.830362
8.095500	159.5868	-2.748664
8.147168	159.5920	-2.677076
8.197168	159.5984	-2.605309
8.250500	159.6038	-2.527703
8.300500	159.6090	-2.455924
8.352168	159.6142	-2.383594
8.403832	159.6184	-2.310020
8.453834	159.6245	-2.242959
8.505500	159.6288	-2.170430
8.557168	159.6343	-2.100201
8.607166	159.6384	-2.029504
8.660499	159.6441	-1.955105
8.710499	159.6488	-1.884774
8.762168	159.6538	-1.809786
8.813834	159.6585	-1.734945
8.863834	159.6629	-1.665214
8.917168	159.6684	-1.590739
8.967168	159.6725	-1.519894
9.017168	159.6785	-1.451442
9.070500	159.6835	-1.374811
9.120499	159.6892	-1.304215
9.172168	159.6936	-1.227743
9.223832	159.6988	-1.154727
9.273834	159.7036	-1.083071
9.327168	159.7095	-1.009848
9.377168	159.7133	-0.9371239
9.427168	159.7184	-0.8661181
9.480500	159.7246	-0.7867518
9.530500	159.7297	-0.7047411
9.582168	159.7348	-0.6221160
9.633832	159.7399	-0.5492199
9.683832	159.7458	-0.4782502
9.737168	159.7507	-0.4039855
9.787168	159.7551	-0.3382350
9.837168	159.7603	-0.2703711
9.890500	159.7646	-0.2027702
9.940500	159.7691	-0.1405428
9.992166	159.7734	-.07595947
10.04383	159.7779	-.01242036
10.09383	159.7820	0.04595165
10.14717	159.7870	0.1061238
10.19717	159.7913	0.1645068
10.24717	159.7961	0.2249864
10.30050	159.8007	0.2931338
10.35050	159.8048	0.3592217
10.40217	159.8100	0.4312780
10.45383	159.8150	0.5095425
10.50384	159.8210	0.5910662
10.55717	159.8272	0.6839646
10.60717	159.8325	0.7802788
10.65717	159.8396	0.8799054
10.71050	159.8461	0.9970039
10.76050	159.8529	1.111308
10.81216	159.8611	1.237679
10.86383	159.8696	1.370734
10.91383	159.8784	1.504832
10.96717	159.8875	1.654637
11.01717	159.8968	1.798739
11.06716	159.9063	1.944780
11.12050	159.9163	2.106333
11.17050	159.9267	2.258028
11.22217	159.9367	2.417460
11.27383	159.9469	2.570369
11.32383	159.9578	2.721933
11.37717	159.9676	2.876519
11.42717	159.9764	3.017235
11.47884	159.9859	3.158403
11.53050	159.9945	3.290612
11.58050	160.0033	3.410027
11.63216	160.0111	3.526894
11.68383	160.0186	3.632794
11.73383	160.0245	3.727852
11.78717	160.0317	3.818145
11.83717	160.0375	3.894166
11.88883	160.0421	3.966729
11.94050	160.0472	4.028366
11.99050	160.0506	4.087253
12.04217	160.0550	4.132309
12.09383	160.0588	4.177519
12.14383	160.0606	4.212780
12.19717	160.0634	4.242040
12.24717	160.0646	4.265420
12.29884	160.0659	4.281010
12.35050	160.0674	4.290692
12.40050	160.0675	4.296210
12.45217	160.0684	4.299736
12.50384	160.0675	4.302912
12.55383	160.0667	4.305178
12.60717	160.0661	4.306542
12.65717	160.0644	4.306582
12.70883	160.0629	4.301668
12.76050	160.0615	4.288148
12.81050	160.0590	4.265216
12.86217	160.0570	4.227290
12.91383	160.0539	4.181802
12.96383	160.0511	4.129671
13.01717	160.0481	4.069246
13.06716	160.0437	4.012438
13.11884	160.0398	3.948868
13.17050	160.0371	3.884839
13.22050	160.0331	3.825166
13.27217	160.0288	3.759791
13.32384	160.0243	3.697019
13.37384	160.0209	3.636558
13.42717	160.0159	3.564064
13.47717	160.0126	3.502200
13.52883	160.0086	3.435654
13.58050	160.0039	3.371396
13.63050	159.9999	3.306350
13.68383	159.9951	3.240072
13.73383	159.9914	3.179223
13.78383	159.9879	3.118265
13.83717	159.9832	3.055900
13.88717	159.9807	2.993848
13.93883	159.9763	2.934244
13.99050	159.9731	2.875444
14.04050	159.9690	2.821002
14.09383	159.9658	2.762381
14.14383	159.9618	2.709043
14.19384	159.9586	2.655005
14.24717	159.9556	2.597834
14.29717	159.9506	2.549452
14.34883	159.9474	2.494175
14.40050	159.9449	2.440344
14.45050	159.9414	2.393143
14.50383	159.9372	2.340182
14.55383	159.9342	2.290698
14.60383	159.9305	2.242390
14.65717	159.9275	2.192300
14.70717	159.9236	2.145273
14.75883	159.9212	2.095674
14.81050	159.9165	2.052702
14.86050	159.9143	2.005522
14.91383	159.9124	1.954821
14.96383	159.9086	1.912500
15.01383	159.9072	1.868381
15.06716	159.9030	1.824121
15.11716	159.9001	1.782185
15.16883	159.8975	1.739786
15.22050	159.8942	1.698581
15.27050	159.8921	1.654927
15.32384	159.8893	1.613317
15.37384	159.8880	1.575615
15.42383	159.8850	1.539697
15.47717	159.8817	1.500814
15.52717	159.8796	1.461466
15.57883	159.8773	1.423762
15.63050	159.8739	1.387549
15.68050	159.8726	1.355200
15.73383	159.8695	1.316429
15.78383	159.8673	1.281354
15.83383	159.8654	1.249292
15.88716	159.8643	1.214592
15.93717	159.8614	1.183880
15.98883	159.8582	1.152990
16.04050	159.8557	1.117857
16.09050	159.8544	1.085776
16.14383	159.8521	1.054795
16.19383	159.8507	1.024613
16.24550	159.8480	0.9952697
16.29716	159.8457	0.9647228
16.34717	159.8446	0.9349312
16.39883	159.8422	0.9055058
16.45050	159.8409	0.8744211
16.50050	159.8393	0.8447960
16.55383	159.8366	0.8161851
16.60383	159.8360	0.7911478
16.65550	159.8339	0.7659460
16.70716	159.8319	0.7397200
16.75716	159.8300	0.7128389
16.80883	159.8286	0.6872610
16.86050	159.8267	0.6617788
16.91050	159.8256	0.6376996
16.96383	159.8226	0.6143540
17.01383	159.8219	0.5906944
17.06550	159.8201	0.5663614
17.11716	159.8176	0.5436945
17.16716	159.8164	0.5169076
17.21883	159.8144	0.4912970
17.27050	159.8122	0.4646578
17.32050	159.8107	0.4393117
17.37383	159.8086	0.4128964
17.42383	159.8068	0.3875568
17.47550	159.8061	0.3612666
17.52716	159.8044	0.3360960
17.57716	159.8022	0.3121902
17.62883	159.8007	0.2874657
17.68050	159.8002	0.2637451
17.73050	159.7979	0.2409417
17.78383	159.7966	0.2176934
17.83383	159.7950	0.1941524
17.88550	159.7935	0.1706402
17.93716	159.7923	0.1467173
17.98716	159.7914	0.1229023
18.03883	159.7892	0.09983032
18.09050	159.7875	0.07642438
18.14050	159.7874	0.05351545
18.19383	159.7849	0.03420506
18.24383	159.7839	0.01312623
18.29550	159.7823	-8.6035E-3
18.34716	159.7804	-.03112185
18.39716	159.7793	-.05214014
18.45050	159.7774	-.07281871
18.50050	159.7769	-.09265131
18.55050	159.7753	-0.1135711
18.60383	159.7737	-0.1335293
18.65383	159.7736	-0.1530081
18.70550	159.7717	-0.1710063
18.75716	159.7701	-0.1880438
18.80716	159.7691	-0.2051025
18.86050	159.7674	-0.2213611
18.91050	159.7658	-0.2370348
18.96050	159.7649	-0.2528198
19.01383	159.7635	-0.2701972
19.06383	159.7632	-0.2878356
19.11550	159.7607	-0.3039330
19.16716	159.7598	-0.3203245
19.21716	159.7587	-0.3361918
19.27050	159.7564	-0.3516146
19.32050	159.7566	-0.3684616
19.37050	159.7558	-0.3846696
19.42383	159.7549	-0.4002962
19.47383	159.7539	-0.4162159
19.52550	159.7531	-0.4327866
19.57716	159.7524	-0.4475720
19.62716	159.7519	-0.4613322
19.68050	159.7508	-0.4739072
19.73050	159.7500	-0.4841838
19.78050	159.7494	-0.4946312
19.83383	159.7473	-0.5050834
19.88383	159.7466	-0.5145153
19.93550	159.7454	-0.5241733
19.98716	159.7438	-0.5340546
20.03717	159.7440	-0.5440050
20.09050	159.7429	-0.5550066
20.14050	159.7418	-0.5644579
20.19050	159.7406	-0.5744930
20.24383	159.7412	-0.5856455
20.29383	159.7404	-0.5955382
20.34550	159.7398	-0.6055616
20.39716	159.7397	-0.6154680
20.44716	159.7394	-0.6248829
20.50050	159.7383	-0.6347812
20.55050	159.7377	-0.6437961
20.60050	159.7372	-0.6526030
20.65383	159.7372	-0.6615869
20.70383	159.7366	-0.6697944
20.75550	159.7370	-0.6780152
20.80716	159.7368	-0.6859178
20.85716	159.7363	-0.6933410
20.91050	159.7366	-0.7007928
20.96050	159.7368	-0.7073420
21.01216	159.7364	-0.7136661
21.06383	159.7373	-0.7197030
21.11383	159.7376	-0.7251240
21.16550	159.7373	-0.7302975
21.21716	159.7370	-0.7351293
21.26716	159.7370	-0.7395616
21.32050	159.7364	-0.7441054
21.37050	159.7370	-0.7482939
21.42216	159.7366	-0.7524995
21.47383	159.7360	-0.7567349
21.52383	159.7359	-0.7610234
21.57550	159.7348	-0.7655407
21.62716	159.7338	-0.7702550
21.67717	159.7336	-0.7751528
21.73050	159.7333	-0.7806804
21.78050	159.7325	-0.7863599
21.83216	159.7316	-0.7925474
21.88383	159.7302	-0.7998434
21.93383	159.7296	-0.8080216
21.98550	159.7294	-0.8197881
22.03717	159.7280	-0.8318434
22.08716	159.7275	-0.8445069
22.14050	159.7262	-0.8590141
22.19050	159.7257	-0.8736816
22.24216	159.7244	-0.8893891
22.29383	159.7232	-0.9064250
22.34383	159.7225	-0.9211137
22.39550	159.7211	-0.9366507
22.44716	159.7200	-0.9557342
22.49716	159.7200	-0.9728478
22.55050	159.7179	-0.9894359
22.60050	159.7166	-1.007092
22.65216	159.7156	-1.023863
22.70383	159.7152	-1.039804
22.75383	159.7140	-1.055434
22.80550	159.7115	-1.071671
22.85716	159.7108	-1.088897
22.90716	159.7094	-1.103935
22.96050	159.7084	-1.121095
23.01050	159.7071	-1.136085
23.06216	159.7058	-1.150897
23.11383	159.7043	-1.167005
23.16383	159.7035	-1.182738
23.21716	159.7019	-1.201344
23.26716	159.7018	-1.218807
23.31716	159.7000	-1.234013
23.37050	159.6994	-1.251545
23.42050	159.6980	-1.265850
23.47216	159.6982	-1.283668
23.52383	159.6968	-1.297719
23.57383	159.6959	-1.311960
23.62716	159.6944	-1.326179
23.67717	159.6945	-1.339176
23.72716	159.6928	-1.350119
23.78050	159.6917	-1.361669
23.83050	159.6907	-1.372920
23.88216	159.6897	-1.385738
23.93383	159.6886	-1.397514
23.98383	159.6873	-1.410393
24.03717	159.6856	-1.425319
24.08716	159.6859	-1.441808
24.13716	159.6849	-1.457565
24.19050	159.6839	-1.475362
24.24050	159.6827	-1.488953
24.29216	159.6821	-1.501864
24.34383	159.6809	-1.516663
24.39383	159.6810	-1.529301
24.44716	159.6790	-1.542756
24.49716	159.6783	-1.555582
24.54716	159.6775	-1.567733
24.60050	159.6765	-1.583135
24.65050	159.6759	-1.596704
24.70216	159.6740	-1.610604
24.75383	159.6727	-1.626636
24.80383	159.6722	-1.643048
24.85716	159.6706	-1.662323
24.90716	159.6694	-1.682686
24.95717	159.6679	-1.701868
25.01050	159.6679	-1.722982
25.06050	159.6673	-1.742174
25.11216	159.6660	-1.762720
25.16383	159.6647	-1.781448
25.21383	159.6642	-1.800073
25.26716	159.6628	-1.819147
25.31716	159.6612	-1.838199
25.36716	159.6602	-1.857843
25.42050	159.6590	-1.879242
25.47050	159.6582	-1.896737
25.52216	159.6574	-1.917504
25.57383	159.6560	-1.935640
25.62383	159.6548	-1.951074
25.67717	159.6534	-1.968626
25.72717	159.6515	-1.984937
25.77883	159.6506	-2.002041
25.83050	159.6493	-2.020259
25.88050	159.6484	-2.039499
25.93216	159.6474	-2.057391
25.98383	159.6453	-2.073624
26.03383	159.6451	-2.090652
26.08716	159.6415	-2.107863
26.13716	159.6417	-2.127045
26.18883	159.6404	-2.144956
26.24050	159.6396	-2.165524
26.29050	159.6392	-2.183432
26.34216	159.6377	-2.199426
26.39383	159.6374	-2.217721
26.44383	159.6353	-2.233924
26.49716	159.6350	-2.253203
26.54716	159.6343	-2.268999
26.59883	159.6336	-2.284920
26.65050	159.6329	-2.298430
26.70050	159.6322	-2.311331
26.75217	159.6309	-2.324600
26.80383	159.6294	-2.337215
26.85383	159.6291	-2.351831
26.90716	159.6282	-2.365875
26.95716	159.6276	-2.379208
27.00883	159.6260	-2.391224
27.06050	159.6256	-2.403559
27.11050	159.6248	-2.414622
27.16217	159.6234	-2.426722
27.21383	159.6220	-2.437398
27.26383	159.6205	-2.449429
27.31716	159.6200	-2.462146
27.36716	159.6193	-2.473880
27.41883	159.6178	-2.485353
27.47050	159.6164	-2.496612
27.52050	159.6159	-2.509230
27.57217	159.6140	-2.520551
27.62383	159.6128	-2.532881
27.67383	159.6127	-2.545298
27.72717	159.6115	-2.557862
27.77717	159.6108	-2.572696
27.82883	159.6104	-2.586411
27.88050	159.6095	-2.600188
27.93050	159.6085	-2.611843
27.98383	159.6078	-2.625062
28.03383	159.6077	-2.636842
28.08383	159.6066	-2.647712
28.13716	159.6054	-2.659082
28.18717	159.6054	-2.669648
28.23883	159.6038	-2.680413
28.29050	159.6025	-2.691582
28.34050	159.6024	-2.702324
28.39383	159.6010	-2.713547
28.44383	159.6001	-2.724596
28.49383	159.6005	-2.735620
28.54716	159.5994	-2.747405
28.59716	159.5986	-2.759016
28.64883	159.5980	-2.770228
28.70050	159.5979	-2.781330
28.75050	159.5967	-2.792279
28.80383	159.5964	-2.803902
28.85383	159.5958	-2.814404
28.90383	159.5954	-2.824878
28.95716	159.5942	-2.835988
29.00716	159.5942	-2.846377
29.05883	159.5930	-2.857089
29.11050	159.5923	-2.867876
29.16050	159.5923	-2.878265
29.21383	159.5915	-2.889383
29.26383	159.5914	-2.899642
29.31383	159.5909	-2.909878
29.36716	159.5902	-2.920702
29.41716	159.5898	-2.930846
29.46883	159.5891	-2.941173
29.52050	159.5883	-2.951522
29.57050	159.5878	-2.961472
29.62383	159.5871	-2.971914
29.67383	159.5872	-2.981670
29.72383	159.5861	-2.991358
29.77717	159.5862	-3.001505
29.82717	159.5845	-3.010902
29.87883	159.5838	-3.020526
29.93050	159.5833	-3.030088
29.98050	159.5828	-3.039250
30.03383	159.5820	-3.048996
30.08383	159.5815	-3.058128
30.13383	159.5813	-3.067308
30.18717	159.5796	-3.076984
30.23716	159.5802	-3.086056
30.28883	159.5792	-3.095232
30.34050	159.5793	-3.104385
30.39050	159.5788	-3.113148
30.44383	159.5786	-3.122370
30.49383	159.5771	-3.131041
30.54550	159.5774	-3.139928
30.59716	159.5775	-3.148720
30.64716	159.5764	-3.157084
30.69883	159.5758	-3.165619
30.75050	159.5762	-3.174013
30.80050	159.5755	-3.182011
30.85383	159.5747	-3.190409
30.90383	159.5736	-3.198240
30.95550	159.5738	-3.206123
31.00716	159.5732	-3.213876
31.05716	159.5725	-3.221303
31.10883	159.5720	-3.228996
31.16050	159.5716	-3.236643
31.21050	159.5711	-3.244083
31.26383	159.5718	-3.251980
31.31383	159.5714	-3.259280
31.36550	159.5711	-3.266701
31.41716	159.5710	-3.274081
31.46716	159.5702	-3.281015
31.51883	159.5707	-3.288166
31.57050	159.5698	-3.295054
31.62050	159.5702	-3.301775
31.67383	159.5680	-3.308728
31.72383	159.5682	-3.315181
31.77550	159.5681	-3.321668
31.82717	159.5680	-3.328040
31.87717	159.5674	-3.334112
31.92883	159.5664	-3.340258
31.98050	159.5663	-3.346405
32.03050	159.5657	-3.352336
32.08383	159.5648	-3.358605
32.13383	159.5646	-3.364576
32.18550	159.5651	-3.370678
32.23717	159.5638	-3.376739
32.28717	159.5654	-3.382534
32.33883	159.5649	-3.388364
32.39050	159.5644	-3.394216
32.44050	159.5642	-3.399765
32.49383	159.5635	-3.405506
32.54383	159.5639	-3.410825
32.59550	159.5634	-3.416195
32.64717	159.5626	-3.421520
32.69717	159.5625	-3.426554
32.75050	159.5622	-3.431947
32.80050	159.5616	-3.436870
32.85050	159.5620	-3.441754
32.90383	159.5623	-3.446918
32.95383	159.5615	-3.451595
33.00550	159.5615	-3.456421
33.05716	159.5606	-3.461124
33.10716	159.5606	-3.465663
33.16050	159.5600	-3.470391
33.21050	159.5606	-3.474780
33.26050	159.5596	-3.479143
33.31383	159.5598	-3.483624
33.36383	159.5594	-3.487820
33.41550	159.5594	-3.492080
33.46716	159.5583	-3.496232
33.51716	159.5574	-3.500163
33.57050	159.5581	-3.504353
33.62050	159.5571	-3.508203
33.67050	159.5567	-3.512094
33.72383	159.5580	-3.516226
33.77383	159.5568	-3.520036
33.82550	159.5570	-3.524022
33.87717	159.5564	-3.527934
33.92717	159.5561	-3.531691
33.98050	159.5568	-3.535617
34.03050	159.5570	-3.539319
34.08050	159.5562	-3.542980
34.13383	159.5554	-3.546822
34.18384	159.5564	-3.550441
34.23550	159.5566	-3.554096
34.28717	159.5562	-3.557624
34.33716	159.5564	-3.561154
34.39050	159.5555	-3.564835
34.44050	159.5551	-3.568184
34.49050	159.5556	-3.571515
34.54383	159.5547	-3.574948
34.59384	159.5557	-3.578163
34.64550	159.5552	-3.581370
34.69717	159.5541	-3.584511
34.74716	159.5549	-3.587669
34.80050	159.5546	-3.590808
34.85050	159.5543	-3.593742
34.90050	159.5544	-3.596646
34.95383	159.5546	-3.599712
35.00383	159.5540	-3.602553
35.05550	159.5537	-3.605534
35.10716	159.5545	-3.608405
35.15716	159.5542	-3.611200
35.21050	159.5542	-3.614056
35.26050	159.5536	-3.616794
35.31216	159.5530	-3.619496
35.36383	159.5539	-3.622241
35.41383	159.5535	-3.624845
35.46550	159.5530	-3.627504
35.51716	159.5529	-3.630146
35.56716	159.5526	-3.632680
35.62050	159.5522	-3.635266
35.67050	159.5523	-3.637680
35.72217	159.5516	-3.640025
35.77383	159.5516	-3.642336
35.82383	159.5509	-3.644526
35.87550	159.5515	-3.646795
35.92717	159.5509	-3.649002
35.97717	159.5512	-3.651173
36.03050	159.5520	-3.653460
36.08050	159.5509	-3.655602
36.13216	159.5512	-3.657869
36.18384	159.5513	-3.659967
36.23383	159.5510	-3.662035
36.28550	159.5513	-3.664216
36.33716	159.5512	-3.666326
36.38716	159.5517	-3.668321
36.44050	159.5508	-3.670266
36.49050	159.5499	-3.672035
36.54217	159.5502	-3.673764
36.59384	159.5502	-3.675390
36.64383	159.5494	-3.676988
36.69550	159.5496	-3.678562
36.74716	159.5490	-3.680036
36.79716	159.5491	-3.681461
36.85050	159.5491	-3.683033
36.90050	159.5491	-3.684470
36.95216	159.5493	-3.685984
37.00383	159.5500	-3.687654
37.05383	159.5494	-3.689319
37.10550	159.5498	-3.691030
37.15716	159.5498	-3.692672
37.20716	159.5494	-3.694183
37.26050	159.5495	-3.695786
37.31050	159.5500	-3.697185
37.36217	159.5498	-3.698570
37.41383	159.5500	-3.699788
37.46383	159.5483	-3.700828
37.51716	159.5497	-3.701975
37.56716	159.5482	-3.702933
37.61716	159.5490	-3.703926
37.67050	159.5489	-3.705049
37.72050	159.5487	-3.706118
37.77217	159.5489	-3.707166
37.82383	159.5479	-3.708220
37.87383	159.5480	-3.709293
37.92717	159.5478	-3.710378
37.97717	159.5478	-3.711503
38.02716	159.5476	-3.712601
38.08050	159.5487	-3.713720
38.13050	159.5473	-3.714624
38.18216	159.5482	-3.715672
38.23383	159.5482	-3.716545
38.28383	159.5479	-3.717467
38.33716	159.5487	-3.718632
38.38716	159.5480	-3.719641
38.43716	159.5488	-3.720770
38.49050	159.5477	-3.721937
38.54050	159.5483	-3.723112
38.59216	159.5479	-3.724175
38.64383	159.5477	-3.725300
38.69383	159.5477	-3.726242
38.74716	159.5474	-3.727280
38.79716	159.5467	-3.728272
38.84716	159.5460	-3.729283
38.90050	159.5472	-3.730398
38.95050	159.5467	-3.731402
39.00217	159.5468	-3.732552
39.05383	159.5465	-3.733799
39.10383	159.5464	-3.735120
39.15716	159.5466	-3.736597
39.20716	159.5463	-3.737871
39.25716	159.5462	-3.739190
39.31050	159.5475	-3.740654
39.36050	159.5474	-3.741976
39.41217	159.5472	-3.743385
39.46383	159.5464	-3.744816
39.51383	159.5469	-3.746206
39.56716	159.5471	-3.747589
39.61716	159.5471	-3.748920
39.66716	159.5459	-3.750226
39.72050	159.5467	-3.751590
39.77050	159.5454	-3.752859
39.82217	159.5468	-3.754246
39.87383	159.5463	-3.755530
39.92383	159.5456	-3.756847
39.97717	159.5456	-3.758245
40.02716	159.5460	-3.759578
40.07883	159.5454	-3.760910
40.13050	159.5460	-3.762288
40.18050	159.5458	-3.763503
40.23216	159.5462	-3.764729
40.28383	159.5454	-3.765852
40.33383	159.5457	-3.766912
40.38716	159.5460	-3.767978
40.43716	159.5449	-3.768887
40.48883	159.5450	-3.769886
40.54050	159.5446	-3.770848
40.59050	159.5444	-3.771734
40.64216	159.5446	-3.772678
40.69383	159.5433	-3.773587
40.74383	159.5431	-3.774510
40.79716	159.5431	-3.775564
40.84716	159.5434	-3.776605
40.89883	159.5430	-3.777740
40.95050	159.5440	-3.778925
41.00050	159.5432	-3.780152
41.05217	159.5435	-3.781461
41.10383	159.5438	-3.782892
41.15383	159.5434	-3.784352
41.20717	159.5439	-3.785970
41.25717	159.5438	-3.787338
41.30883	159.5435	-3.788675
41.36050	159.5433	-3.789918
41.41050	159.5431	-3.791059
41.46216	159.5434	-3.792184
41.51383	159.5426	-3.793245
41.56383	159.5426	-3.794253
41.61716	159.5421	-3.795309
41.66716	159.5423	-3.796358
41.71884	159.5422	-3.797450
41.77050	159.5426	-3.798651
41.82050	159.5427	-3.799802
41.87216	159.5426	-3.801098
41.92383	159.5431	-3.802432
41.97383	159.5430	-3.803691
42.02716	159.5436	-3.804987
42.07717	159.5437	-3.806146
42.12883	159.5432	-3.807260
42.18050	159.5433	-3.808333
42.23050	159.5439	-3.809351
42.28383	159.5437	-3.810372
42.33383	159.5429	-3.811355
42.38383	159.5430	-3.812278
42.43716	159.5428	-3.813235
42.48717	159.5435	-3.814168
42.53883	159.5432	-3.815040
42.59050	159.5429	-3.815860
42.64050	159.5428	-3.816735
42.69383	159.5430	-3.817668
42.74383	159.5425	-3.818444
42.79383	159.5422	-3.819270
42.84716	159.5422	-3.820137
42.89717	159.5427	-3.820852
42.94883	159.5417	-3.821461
-2.000000	2.000000	0.0000000
43.05050	159.5621	-4.551877
43.10050	159.7810	-8.487814
43.15050	160.2051	-12.28710
43.20383	160.8083	-15.72437
43.25383	161.4824	-18.23109
43.30550	162.2552	-20.24101
43.35717	163.0874	-21.79644
43.40717	163.9346	-22.96043
43.46050	164.8720	-23.94392
43.51050	165.7731	-24.68434
43.56050	166.6906	-25.30525
43.61383	167.6852	-25.83640
43.66383	168.6298	-26.13846
43.71550	169.6163	-26.45243
43.76717	170.6082	-26.74371
43.81717	171.5720	-27.00510
43.87050	172.6056	-27.25498
43.92050	173.5775	-27.47428
43.97050	174.5508	-27.69618
44.02383	175.5922	-27.92393
44.07383	176.5707	-28.11858
44.12550	177.5812	-28.34305
44.17717	178.5924	-28.57522
44.22717	179.5726	-28.79859
44.28050	180.6178	-29.05792
44.33050	181.5972	-29.30944
44.38050	182.5777	-29.56164
44.43383	183.6232	-29.83830
44.48383	184.6050	-30.00060
44.53550	185.6234	-30.16100
44.58716	186.6412	-30.41848
44.63716	187.6248	-30.70039
44.69050	188.6706	-31.06438
44.74050	189.6496	-31.37754
44.79050	190.6284	-31.71276
44.84384	191.6724	-32.10918
44.89383	192.6478	-32.51813
44.94550	193.6556	-32.96312
44.99716	194.6609	-33.45564
45.04716	195.6318	-33.97390
45.10050	196.6642	-34.58902
45.15050	197.6301	-35.21414
45.20050	198.5918	-35.90976
45.25383	199.6152	-36.71472
45.30383	200.5713	-37.41511
45.35550	201.5594	-38.28418
45.40717	202.5425	-39.73706
45.45717	203.4629	-40.74460
45.51050	204.4571	-42.19972
45.56050	205.3763	-43.90324
45.61217	206.3065	-46.00414
45.66383	207.2179	-48.48246
45.71383	208.0804	-51.19296
45.76550	208.9533	-54.26360
45.81717	209.8106	-57.45696
45.86716	210.6334	-60.51450
45.92050	211.5085	-63.67251
45.97050	212.3346	-66.38614
46.02217	213.2018	-68.83366
46.07383	214.0875	-70.83234
46.12383	214.9731	-72.03866
46.17550	215.9335	-71.96397
46.22717	216.9777	-69.43686
46.27716	218.1208	-63.92798
46.33050	219.4422	-58.56689
46.38050	220.7170	-53.44256
46.43217	222.0620	-47.73872
46.48383	223.4128	-43.02174
46.53383	224.6733	-40.07398
46.58550	225.9142	-37.95500
46.63716	227.1023	-36.42127
46.68716	228.2145	-35.33691
46.74050	229.3676	-34.50794
46.79050	230.4274	-33.94376
46.84217	231.5070	-33.54810
46.89383	232.5724	-33.25784
46.94383	233.5961	-33.05788
46.99550	234.6459	-32.93692
47.04716	235.6911	-32.85613
47.09716	236.6996	-32.81010
47.15050	237.7709	-32.79610
47.20050	238.7746	-32.79365
47.25217	239.8100	-32.79477
47.30383	240.8437	-32.79955
47.35383	241.8433	-32.82684
47.40550	242.8771	-32.87996
47.45717	243.9087	-32.93728
47.50717	244.9066	-33.00524
47.56050	245.9719	-33.08394
47.61050	246.9681	-33.21376
47.66217	247.9965	-33.36259
47.71383	249.0269	-33.42833
47.76383	250.0237	-33.46778
47.81717	251.0864	-33.52338
47.86716	252.0836	-33.60053
47.91716	253.0826	-33.64462
47.97050	254.1467	-33.68323
48.02050	255.1445	-33.74506
48.07217	256.1752	-33.83281
48.12383	257.2060	-33.86816
48.17383	258.2020	-33.97348
48.22717	259.2648	-34.04078
48.27716	260.2628	-34.10958
48.32717	261.2594	-34.18266
48.38050	262.3222	-34.26290
48.43050	263.3196	-34.33286
48.48217	264.3493	-34.41930
48.53383	265.3795	-34.49875
48.58383	266.3770	-34.56738
48.63716	267.4407	-34.62577
48.68716	268.4370	-34.70280
48.73717	269.4347	-34.73422
48.79050	270.4997	-34.77128
48.84050	271.4980	-34.81348
48.89217	272.5302	-34.88213
48.94383	273.5614	-34.91488
48.99383	274.5591	-34.92646
49.04550	275.5512	-35.91756
49.09716	276.0838	-32.60632
49.14717	276.1665	-23.68201
49.19883	275.9708	-15.14468
49.25050	275.5728	-8.142358
49.30050	275.0476	-2.823188
49.35383	274.3726	1.541728
49.40383	273.6619	4.662424
49.45550	272.8648	7.135418
49.50717	272.0226	9.023376
49.55717	271.1724	10.43131
49.60883	270.2685	11.56663
49.66050	269.3416	12.45056
49.71050	268.4292	13.13569
49.76383	267.4416	13.71400
49.81383	266.5061	14.14421
49.86550	265.5284	14.52158
49.91716	264.5441	14.82108
49.96717	263.5870	15.06192
50.01883	262.5932	15.27900
50.07050	261.5960	15.46139
50.12050	260.6280	15.61451
50.17383	259.5904	15.76225
50.22383	258.6169	15.88327
50.27550	257.6090	15.98974
50.32717	256.5984	16.09467
50.37717	255.6198	16.18060
50.42883	254.6066	16.27442
50.48050	253.5926	16.35485
50.53050	252.6108	16.42970
50.58383	251.5619	16.50541
50.63383	250.5783	16.57146
50.68550	249.5602	16.64269
50.73717	248.5433	16.70723
50.78717	247.5565	16.77719
50.83883	246.5373	16.82944
50.89050	245.5169	16.88477
50.94050	244.5294	16.93204
50.99383	243.4753	16.98531
51.04383	242.4870	17.02820
51.09550	241.4651	17.06799
51.14717	240.4434	17.10718
51.19717	239.4540	17.15519
51.25050	238.3990	17.19727
51.30050	237.4097	17.24021
51.35050	236.4194	17.28320
51.40383	235.3614	17.31605
51.45383	234.3716	17.34584
51.50550	233.3484	17.37673
51.55717	232.3252	17.40863
51.60717	231.3344	17.43923
51.66050	230.2770	17.48218
51.71050	229.2863	17.51320
51.76050	228.2953	17.55093
51.81383	227.2385	17.59698
51.86383	226.2475	17.63503
51.91550	225.2238	17.67342
51.96717	224.1998	17.71478
52.01716	223.2078	17.74266
52.07050	222.1489	17.77180
52.12050	221.1567	17.79578
52.17050	220.1650	17.82538
52.22383	219.1069	17.85988
52.27383	218.1145	17.88501
52.32550	217.0886	17.90920
52.37717	216.0639	17.93403
52.42717	215.0719	17.95864
52.48050	214.0126	17.98250
52.53050	213.0206	18.00592
52.58050	212.0279	18.02961
52.63383	210.9694	18.05333
52.68383	209.9776	18.07499
52.73550	208.9516	18.10630
52.78716	207.9268	18.13052
52.83716	206.9349	18.16538
52.89050	205.8763	18.19095
52.94050	204.8837	18.22118
52.99050	203.8909	18.24334
53.04382	202.8336	18.26552
53.09384	201.8395	18.28562
53.14550	200.8142	18.31288
53.19717	199.7878	18.33829
53.24717	198.7951	18.36171
53.30050	197.7367	18.38690
53.35050	196.7424	18.40828
53.40050	195.7508	18.42667
53.45383	194.6920	18.45859
53.50383	193.6974	18.48456
53.55550	192.6728	18.50622
53.60717	191.6473	18.53150
53.65717	190.6533	18.55276
53.71050	189.5937	18.57472
53.76050	188.6017	18.59295
53.81216	187.5754	18.61399
53.86382	186.5480	18.63755
53.91382	185.5562	18.65744
53.96550	184.5296	18.67795
54.01716	183.5025	18.70030
54.06716	182.5094	18.71662
54.12050	181.4486	18.73230
54.17050	180.4554	18.74803
54.22217	179.4278	18.76680
54.27383	178.4010	18.79114
54.32383	177.4087	18.81710
54.37550	176.3826	18.84579
54.42717	175.3568	18.88935
54.47717	174.3645	18.94160
54.53050	173.3072	19.04647
54.58050	172.3175	19.21302
54.63217	171.2981	19.48697
54.68383	170.2875	19.93866
54.73383	169.3202	20.62028
54.78550	168.3393	21.72911
54.83716	167.3828	23.33148
54.88716	166.4863	25.38965
54.94050	165.5644	28.10538
54.99050	164.7276	31.05772
55.04217	163.8912	34.42350
55.09384	163.0723	37.87466
55.14384	162.2872	41.07992
55.19550	161.4669	43.95621
55.24717	160.6236	46.20096
55.29717	159.7724	47.63353
55.35050	158.8166	48.28348
55.40050	157.8713	48.08270
55.45216	156.8460	47.15183
55.50383	155.7685	45.46326
55.55383	154.6846	43.44460
55.60550	153.5334	40.96338
55.65717	152.3584	38.39812
55.70717	151.2110	35.93255
55.76050	149.9801	33.31897
55.81050	148.8273	31.00778
55.86217	147.6493	29.07930
55.91382	146.4923	27.50806
55.96382	145.3914	26.26875
56.01716	144.2391	25.21261
56.06716	143.1744	24.42840
56.11716	142.1220	23.76926
56.17050	141.0089	23.09609
56.22050	139.9730	22.64422
56.27217	138.9103	22.25527
56.32383	137.8534	21.92810
56.37383	136.8355	21.65994
56.42717	135.7545	21.42052
56.47717	134.7442	21.24410
56.52717	133.7371	21.08776
56.58050	132.6632	20.93428
56.63050	131.6579	20.80386
56.68217	130.6224	20.68852
56.73383	129.5857	20.59505
56.78383	128.5834	20.49220
56.83716	127.5152	20.40802
56.88716	126.5147	20.32271
56.93716	125.5133	20.24425
56.99050	124.4459	20.16650
57.04050	123.4460	20.08721
57.09217	122.4124	20.01224
57.14384	121.3785	19.94587
57.19384	120.3787	19.87733
57.24717	119.3142	19.81323
57.29717	118.3148	19.76044
57.34716	117.3171	19.71440
57.40050	116.2518	19.66333
57.45050	115.2520	19.61688
57.50217	114.2208	19.56252
57.55383	113.1888	19.51220
57.60383	112.1888	19.45578
57.65717	111.1248	19.39590
57.70717	110.1255	19.34164
57.75717	109.1269	19.29096
57.81050	108.0625	19.24004
57.86050	107.0640	19.18789
57.91216	106.0342	19.14676
57.96382	105.0014	19.09741
58.01382	104.0037	19.05110
58.06716	102.9395	19.00743
58.11716	101.9402	18.95888
58.16716	100.9425	18.91090
58.22050	99.87745	18.86379
58.27050	98.87812	18.81625
58.32217	97.84803	18.77719
58.37383	96.81580	18.73548
58.42383	95.81853	18.68875
58.47717	94.75379	18.64381
58.52717	93.75566	18.60449
58.57883	92.72501	18.56090
58.63050	91.69400	18.52522
58.68050	90.69689	18.48104
58.73217	89.66550	18.43045
58.78383	88.63414	18.38272
58.83383	87.63638	18.34068
58.88716	86.57098	18.29330
58.93716	85.57294	18.24945
58.98882	84.54272	18.20636
59.04050	83.51038	18.16631
59.09050	82.51194	18.12928
59.14216	81.48088	18.08295
59.19384	80.44868	18.03730
59.24382	79.45160	17.99273
59.29717	78.38701	17.94377
59.34716	77.38974	17.90292
59.39883	76.35790	17.86428
59.45050	75.32657	17.81877
59.50050	74.32866	17.77754
59.55217	73.29687	17.73651
59.60383	72.26674	17.68801
59.65383	71.26888	17.65301
59.70717	70.20362	17.60330
59.75717	69.20515	17.55402
59.80883	68.17408	17.50355
59.86050	67.14216	17.44662
59.91050	66.14420	17.40158
59.96216	65.11221	17.34816
60.01382	64.07868	17.29789
60.06382	63.08063	17.23708
60.11716	62.01446	17.17282
60.16716	61.01563	17.11960
60.21884	59.98342	17.05964
60.27050	58.95121	17.00910
60.32050	57.95124	16.95634
60.37217	56.91928	16.89224
60.42383	55.88705	16.84210
60.47382	54.88920	16.79456
60.52717	53.82319	16.73723
60.57717	52.82292	16.68786
60.62883	51.79178	16.62652
60.68050	50.76008	16.57164
60.73050	49.76100	16.51866
60.78383	48.69494	16.46547
60.83383	47.69580	16.41520
60.88383	46.69715	16.37099
60.93716	45.63162	16.31813
60.98717	44.63282	16.26651
61.03882	43.60046	16.21486
61.09050	42.56770	16.16400
61.14050	41.56854	16.10511
61.19384	40.50195	16.03940
61.24382	39.50254	15.97952
61.29382	38.50096	15.91140
61.34716	37.43432	15.83418
61.39717	36.43331	15.77524
61.44883	35.40045	15.69664
61.50050	34.36675	15.62839
61.55050	33.36633	15.56422
61.60383	32.29918	15.48186
61.65383	31.29925	15.41594
61.70383	30.29766	15.35280
61.75717	29.23133	15.27766
61.80717	28.23022	15.20814
61.85883	27.19529	15.13174
61.91050	26.16133	15.05071
61.96050	25.15869	15.01186
62.01050	24.15782	15.01561
62.06050	23.27018	15.42123
62.11217	22.91402	11.34630
62.16382	22.91332	6.278891
62.21382	23.15962	1.979301
62.26716	23.61246	-1.627203
62.31716	24.17234	-4.254746
62.36716	24.83054	-6.301307
62.42050	25.61038	-7.997485
62.47050	26.39860	-9.230211
62.52217	27.25696	-10.23145
62.57383	28.14888	-11.03313
62.62383	29.03644	-11.65102
62.67717	30.00284	-12.18516
62.72717	30.92437	-12.59593
62.77883	31.88875	-12.94824
62.83050	32.86202	-13.25308
62.88050	33.81072	-13.50364
62.93217	34.79801	-13.73246
62.98383	35.79000	-13.92704
63.03383	36.75389	-14.10319
63.08716	37.78516	-14.27094
63.13716	38.75610	-14.41032
63.18882	39.76112	-14.54444
63.24050	40.76896	-14.67536
63.29050	41.74475	-14.78644
63.34217	42.75528	-14.90133
63.39384	43.76731	-15.01449
63.44384	44.74931	-15.11708
63.49717	45.79686	-15.22496
63.54717	46.77977	-15.32288
63.59882	47.79592	-15.42727
63.65050	48.81420	-15.52856
63.70050	49.80020	-15.62156
63.75217	50.81760	-15.72481
63.80383	51.83838	-15.82512
63.85383	52.82588	-15.91661
63.90718	53.87937	-16.01808
63.95717	54.86744	-16.11023
64.00884	55.88870	-16.21086
64.06050	56.91158	-16.30732
64.11050	57.90046	-16.40114
64.16217	58.92394	-16.49875
64.21384	59.94716	-16.59962
64.26384	60.93726	-16.69103
64.31717	61.99394	-16.80244
64.36718	62.98557	-16.89670
64.41884	64.01040	-16.98948
64.47050	65.03499	-17.08576
64.52050	66.02722	-17.17444
64.57218	67.05166	-17.27998
64.62383	68.07624	-17.37956
64.67383	69.06934	-17.47951
64.72718	70.12657	-17.57538
64.77717	71.12063	-17.67028
64.82885	72.14626	-17.77008
64.88050	73.17326	-17.86478
64.93050	74.16513	-17.95575
64.98383	75.22511	-18.06531
65.03384	76.21853	-18.15723
65.08384	77.21060	-18.25508
65.13717	78.26978	-18.36656
65.18717	79.26376	-18.46771
65.23882	80.28943	-18.57575
65.29050	81.31644	-18.68081
65.34050	82.31098	-18.77664
65.39384	83.37039	-18.87848
65.44384	84.36447	-18.98194
65.49384	85.35844	-19.08927
65.54718	86.41711	-19.19523
65.59718	87.40881	-19.30573
65.64884	88.43670	-19.41793
65.70050	89.46311	-19.52872
65.75050	90.45747	-19.62941
65.80384	91.51788	-19.73969
65.85384	92.51249	-19.84445
65.90384	93.50769	-19.93538
65.95718	94.56844	-20.04225
66.00718	95.56291	-20.14602
66.05884	96.59174	-20.24363
66.11050	97.61853	-20.33678
66.16050	98.61402	-20.44191
66.21384	99.67337	-20.54720
66.26384	100.6684	-20.65136
66.31384	101.6628	-20.75222
66.36718	102.7231	-20.86795
66.41718	103.7168	-20.97390
66.46884	104.7442	-21.08668
66.52050	105.7734	-21.19419
66.57050	106.7652	-21.30236
66.62384	107.8266	-21.41773
66.67384	108.8205	-21.52920
66.72384	109.8137	-21.64440
66.77718	110.8759	-21.75585
66.82718	111.8698	-21.86397
66.87884	112.8974	-21.97338
66.93050	113.9243	-22.07478
66.98050	114.9203	-22.18544
67.03384	115.9820	-22.30202
67.08384	116.9772	-22.39300
67.13384	117.9719	-22.49803
67.18718	119.0322	-22.62360
67.23718	120.0274	-22.73910
67.28882	121.0542	-22.85446
67.34050	122.0810	-22.98039
67.39050	123.0746	-23.10017
67.44384	124.1346	-23.22788
67.49384	125.1280	-23.34890
67.54550	126.1551	-23.46537
67.59718	127.1827	-23.58708
67.64718	128.1770	-23.70686
67.69884	129.2040	-23.82228
67.75050	130.2308	-23.95292
67.80050	131.2253	-24.07708
67.85384	132.2852	-24.19969
67.90384	133.2803	-24.33906
67.95550	134.3054	-24.45602
68.00718	135.3331	-24.60008
68.05718	136.3249	-24.73200
68.10884	137.3519	-24.87944
68.16050	138.3773	-25.02118
68.21050	139.3710	-25.15262
68.26384	140.4304	-25.30052
68.31384	141.4218	-25.44156
68.36550	142.4480	-25.59516
68.41718	143.4739	-25.74126
68.46718	144.4674	-25.88252
68.51882	145.4932	-26.02902
68.57050	146.5191	-26.18260
68.62050	147.5113	-26.33267
68.67384	148.5692	-26.48304
68.72384	149.5618	-26.63120
68.77550	150.5867	-26.79128
68.82718	151.6108	-26.95428
68.87718	152.6029	-27.11748
68.92884	153.6269	-27.27602
68.98050	154.6518	-27.44805
69.03050	155.6430	-27.60347
69.08384	156.7012	-27.77033
69.13384	157.6929	-27.92491
69.18550	158.7184	-28.07900
69.23718	159.7432	-28.22004
69.28718	160.7371	-28.36367
69.33884	161.7638	-28.48686
69.39050	162.7900	-28.61409
69.44050	163.7847	-28.71052
69.49384	164.8472	-28.80458
69.54384	165.8426	-28.88281
69.59550	166.8730	-28.95669
69.64718	167.9030	-29.02283
69.69718	168.8991	-29.09369
69.75050	169.9623	-29.17865
69.80050	170.9594	-29.27570
69.85050	171.9556	-29.38109
69.90384	173.0178	-29.49171
69.95384	174.0123	-29.60852
70.00550	175.0402	-29.75242
70.05718	176.0666	-29.89209
70.10718	177.0595	-30.05288
70.16050	178.1166	-30.23952
70.21050	179.1082	-30.43233
70.26050	180.0984	-30.62998
70.31384	181.1534	-30.87628
70.36384	182.1416	-31.12016
70.41550	183.1606	-31.40764
70.46718	184.1783	-31.72500
70.51716	185.1620	-32.04693
70.57050	186.2099	-32.42460
70.62050	187.1889	-32.83082
70.67050	188.1667	-33.27206
70.72384	189.2071	-33.79563
70.77384	190.1786	-34.33760
70.82550	191.1804	-34.94109
70.87718	192.1781	-35.59314
70.92718	193.1427	-36.23210
70.98050	194.1697	-36.94352
71.03050	195.1319	-37.60925
71.08050	196.0916	-38.30070
71.13384	197.1146	-39.09699
71.18384	198.0713	-39.88168
71.23550	199.0565	-40.78613
71.28718	200.0368	-41.78757
71.33716	200.9806	-42.86081
71.39050	201.9813	-44.08770
71.44050	202.9146	-45.28197
71.49050	203.8459	-46.50616
71.54384	204.8378	-47.76267
71.59384	205.7711	-48.79494
71.64550	206.7439	-49.53083
71.69718	207.7369	-49.69474
71.74718	208.7301	-48.99376
71.80050	209.8448	-46.86449
71.85050	210.9494	-43.83854
71.90050	212.1058	-40.45787
71.95384	213.3605	-37.32739
72.00384	214.5240	-35.20779
72.05550	215.6960	-33.68283
72.10718	216.8357	-32.64262
72.15718	217.9114	-31.89966
72.21050	219.0391	-31.33365
72.26050	220.0813	-30.94644
72.31216	221.1457	-30.68138
72.36384	222.2024	-30.49216
72.41382	223.2176	-30.36745
72.46550	224.2640	-30.30259
72.51716	225.3049	-30.24918
72.56718	226.3092	-30.23990
72.62050	227.3794	-30.23571
72.67050	228.3808	-30.23629
72.72218	229.4151	-30.24137
72.77384	230.4481	-30.26358
72.82384	231.4471	-30.31819
72.87550	232.4785	-30.40572
72.92718	233.5094	-30.47865
72.97718	234.5062	-30.55859
73.03050	235.5728	-30.63558
73.08050	236.5706	-30.69509
73.13218	237.6023	-30.75818
73.18384	238.6330	-30.82295
73.23384	239.6305	-30.89453
73.28550	240.6611	-30.95628
73.33716	241.6911	-31.04256
73.38718	242.6875	-31.11698
73.44050	243.7508	-31.19661
73.49050	244.7480	-31.26220
73.54218	245.7784	-31.33215
73.59384	246.8088	-31.40383
73.64384	247.8057	-31.46596
73.69550	248.8370	-31.53810
73.74718	249.8662	-31.60385
73.79718	250.8642	-31.68124
73.85050	251.9280	-31.74750
73.90050	252.9260	-31.82394
73.95216	253.9562	-31.88373
74.00384	254.9861	-31.95459
74.05384	255.9852	-32.03310
74.10550	257.0154	-32.09891
74.15718	258.0464	-32.17378
74.20718	259.0436	-32.24902
74.26050	260.1074	-32.33033
74.31050	261.1043	-32.40958
74.36218	262.1346	-32.49628
74.41382	263.1641	-32.56470
74.46384	264.1609	-32.64660
74.51716	265.2239	-32.73225
74.56718	266.2206	-32.81060
74.61718	267.2168	-32.88988
74.67050	268.2796	-33.00258
74.72050	269.2750	-33.08860
74.77218	270.3033	-33.17026
74.82384	271.3334	-33.25788
-2.000000	5.000000	0.0000000