File: 7-C1(1.2mol%)+C20(0.6mol%)(1)/matlab/160-2.txt
CLOSED
Version	1.0
Language	English
Mode	Standard
Run	33
RunSerial	12301
Instrument	DSC Q2000 V24.11 Build 124
Module	DSC Standard Cell RC
Operator
File	\\AE520-1454\Users\dsc\Desktop\Data\29-08-17-3\160-2.001
ProcName
InstSerial	2000-0883
AutoSerial	1293
Sample	160-2
Size	31.6000	mg
PanMass	Not available
PanResist	Automatic Automatic  K/W
PanFactor	Default Default
Method
Comment
Xcomment	Pan: Tzero Aluminum Hermetic
Xcomment	Gas1: Nitrogen 50.0 ml/min
Xcomment	Gas2: Nitrogen 50.0 ml/min
Text
Exotherm	UP
Kcell	1.05230
Cpconst	Standard: 0.938
Calib	-38.6961
TempCal	1	pts	157.46	156.60
TzeroDt	-87.6168 -0.0009 -1.4231
TzeroDtz	-87.6168 0.0057 6.9570
InstCalFile	Tzero: \\Ae520-1454\ta\Data\DSC\Calibration\2017\CALIBRATION\1562_RCS (90)_05_18_2017 10_50_44.TZR
InstCalFile	Baseline: \\Ae520-1454\ta\Data\DSC\Calibration\2017\2017-05-17_Calibration.001
InstCalFile	Sapphire: \\Ae520-1454\ta\Data\DSC\Calibration\2017\2017-05-17_Saphire.001
InstCalDate	Tzero 2017-05-18 Time 10:50:44
TempRange	-87.39 to 398.39 °C at 10.00 °C/min Heat Only
AutoZero	Delta T Offset 0.000 uV
AutoZero	Delta T0 Offset 0.000 uV
MultiptCal	0
MultiPtDesc	0) Not set
AutoCellConst	Calibration Date 2017-05-18 16:59:28
Controls	Gas 1  Event Off  Sampling 0.2
Cell#	RC-01562
CoolingUnit	RCS (90)
SelHeatFlow	Heat Flow T4P (mW)
AutoLidII	Installed
AutoAnalysis	Off
MacroFile
Nsig	3
Sig1	Time (min)
Sig2	Temperature (°C)
Sig3	Heat Flow (mW)
Date	2017-08-31
Time	07:00:09
OrgMethod	1: Equilibrate at 80.00 °C
OrgMethod	2: Isothermal for 3.00 min
OrgMethod	3: Jump to 160.00 °C
OrgMethod	4: Mark end of cycle 1
OrgMethod	5: Isothermal for 40.00 min
OrgMethod	6: Mark end of cycle 2
OrgMethod	7: Ramp 20.00 °C/min to 280.00 °C
OrgMethod	8: Mark end of cycle 3
OrgMethod	9: Ramp 20.00 °C/min to 20.00 °C
OrgMethod	10: Mark end of cycle 4
OrgMethod	11: Ramp 20.00 °C/min to 280.00 °C
OrgMethod	12: Mark end of cycle 5
OrgFile	C:\Users\jarra\Desktop\DSC\7-C1(1.2mol%)+C20(0.6mol%)(1)\160-2.001
StartOfData
4.99994E-4	78.70791	-16.04079
0.05383332	78.94575	-12.97406
0.1038333	79.12743	-10.66484
0.1555000	79.27607	-8.725472
0.2071666	79.39734	-7.167280
0.2571667	79.49179	-5.943574
0.3105000	79.57380	-4.894920
0.3605000	79.63474	-4.102676
0.4121666	79.68507	-3.439100
0.4638333	79.72634	-2.900182
0.5138333	79.75735	-2.485967
0.5655000	79.78450	-2.134490
0.6171668	79.80581	-1.853460
0.6671668	79.82197	-1.634544
0.7205000	79.83544	-1.448936
0.7705000	79.84582	-1.309363
0.8221666	79.85489	-1.193359
0.8738332	79.86184	-1.101752
0.9238334	79.86756	-1.030614
0.9755000	79.87026	-0.9724800
1.027167	79.87413	-0.9302436
1.077166	79.87610	-0.8964157
1.130500	79.87750	-0.8696594
1.180500	79.87910	-0.8533070
1.232166	79.88048	-0.8398009
1.283834	79.88138	-0.8300455
1.333833	79.88165	-0.8235969
1.385500	79.88220	-0.8191096
1.437167	79.88188	-0.8151144
1.487166	79.88262	-0.8112006
1.540500	79.88242	-0.8069840
1.590500	79.88089	-0.8030200
1.642166	79.88156	-0.7991163
1.693833	79.88103	-0.7952106
1.743833	79.88085	-0.7915921
1.795500	79.88018	-0.7880668
1.847167	79.88003	-0.7847369
1.897167	79.87908	-0.7816639
1.950500	79.87776	-0.7787530
2.000500	79.87818	-0.7761962
2.052166	79.87740	-0.7737808
2.103833	79.87661	-0.7715682
2.153833	79.87574	-0.7695847
2.205500	79.87678	-0.7677705
2.257167	79.87543	-0.7660750
2.307167	79.87437	-0.7646640
2.360500	79.87446	-0.7632405
2.410500	79.87511	-0.7621264
2.462167	79.87465	-0.7608982
2.513833	79.87379	-0.7599036
2.563833	79.87280	-0.7590142
2.617167	79.87329	-0.7582999
2.667167	79.87156	-0.7577915
2.717167	79.87156	-0.7574682
2.770500	79.87178	-0.7572950
2.820500	79.87042	-0.7572012
2.872167	79.86994	-0.7571926
2.923834	79.86981	-0.7574542
2.973833	79.86920	-0.7576980
3.020500	79.89264	-1.112295
3.073833	80.82940	-13.88795
3.123834	82.90324	-28.23428
3.175500	85.57755	-42.18769
3.227167	88.68909	-55.33347
3.277167	92.01876	-66.77437
3.328833	95.71863	-77.14966
3.380500	99.62348	-86.09046
3.430500	103.5524	-93.53234
3.483833	107.8674	-100.2148
3.533833	111.9999	-105.4258
3.585500	116.3297	-110.0002
3.637167	120.6973	-114.0383
3.687167	124.9550	-117.2816
3.738834	129.3853	-120.0519
3.790500	133.8322	-122.3436
3.840500	138.1464	-124.0743
3.893833	142.5983	-123.0737
3.943833	145.7393	-111.0840
3.995500	148.1551	-97.41895
4.047167	150.1002	-83.53847
4.097166	151.6208	-71.14142
4.150500	152.9488	-59.44276
4.200500	153.9683	-50.04586
4.250500	154.8146	-42.09694
4.303834	155.5642	-35.03046
4.353833	156.1463	-29.55164
4.405500	156.6544	-24.85022
4.457167	157.0802	-20.97263
4.507167	157.4294	-17.87096
4.560500	157.7450	-15.16196
4.610500	157.9989	-13.05272
4.660500	158.2154	-11.29912
4.713834	158.4132	-9.741641
4.763834	158.5735	-8.527116
4.815500	158.7156	-7.470756
4.867166	158.8389	-6.579822
4.917167	158.9437	-5.846572
4.970500	159.0408	-5.184415
5.020500	159.1185	-4.649199
5.070500	159.1892	-4.192130
5.123833	159.2540	-3.766108
5.173834	159.3058	-3.417992
5.225500	159.3554	-3.107221
5.277168	159.3976	-2.826700
5.327168	159.4352	-2.591969
5.380500	159.4704	-2.368262
5.430500	159.5006	-2.176808
5.480500	159.5267	-1.998342
5.533832	159.5525	-1.831969
5.583832	159.5741	-1.680129
5.635500	159.5954	-1.536981
5.687168	159.6142	-1.400516
5.737168	159.6318	-1.274076
5.790500	159.6484	-1.143339
5.840500	159.6630	-1.023661
5.890500	159.6768	-0.9094881
5.943832	159.6912	-0.7866172
5.993834	159.7030	-0.6722726
6.045500	159.7168	-0.5553460
6.097168	159.7285	-0.4350712
6.147168	159.7399	-0.3175921
6.200500	159.7518	-0.1928202
6.250500	159.7622	-.07651092
6.300500	159.7734	0.04494110
6.353832	159.7849	0.1745991
6.403832	159.7948	0.3003739
6.455500	159.8061	0.4300783
6.507168	159.8168	0.5647388
6.557166	159.8278	0.6976628
6.610500	159.8391	0.8459852
6.660500	159.8502	0.9849680
6.712168	159.8605	1.135826
6.763834	159.8718	1.288396
6.813834	159.8831	1.440613
6.865500	159.8953	1.602213
6.917168	159.9068	1.771332
6.967168	159.9182	1.937680
7.020500	159.9318	2.118281
7.070500	159.9442	2.293455
7.122168	159.9575	2.476336
7.173834	159.9701	2.664153
7.223834	159.9831	2.853440
7.275500	159.9972	3.050980
7.327168	160.0121	3.253558
7.377168	160.0249	3.456036
7.430500	160.0403	3.674538
7.480500	160.0546	3.883008
7.532166	160.0694	4.101215
7.583832	160.0841	4.322844
7.633832	160.0988	4.541510
7.685500	160.1146	4.765996
7.737168	160.1292	4.992958
7.787168	160.1435	5.210883
7.840500	160.1596	5.446084
7.890500	160.1735	5.658699
7.942168	160.1880	5.881788
7.993834	160.2020	6.097962
8.043834	160.2154	6.299446
8.095500	160.2300	6.499637
8.147168	160.2423	6.693525
8.197168	160.2546	6.868924
8.250500	160.2660	7.049714
8.300500	160.2781	7.207110
8.352168	160.2884	7.365708
8.403832	160.2992	7.514078
8.453834	160.3086	7.660462
8.505500	160.3188	7.822800
8.557168	160.3303	8.005806
8.607166	160.3448	8.207007
8.660499	160.3592	8.466806
8.710499	160.3772	8.746398
8.762168	160.3985	9.079816
8.813834	160.4216	9.452991
8.863834	160.4473	9.840003
8.917168	160.4760	10.28367
8.967168	160.5041	10.71083
9.017168	160.5318	11.13515
9.070500	160.5611	11.57718
9.120499	160.5873	11.96912
9.172168	160.6131	12.34195
9.223832	160.6361	12.68031
9.273834	160.6548	12.95978
9.327168	160.6730	13.20776
9.377168	160.6862	13.39103
9.427168	160.6963	13.51892
9.480500	160.7031	13.60908
9.530500	160.7071	13.64481
9.582168	160.7086	13.65164
9.633832	160.7069	13.64886
9.683832	160.7032	13.63152
9.737168	160.6979	13.53756
9.787168	160.6925	13.41099
9.837168	160.6851	13.29332
9.890500	160.6778	13.17302
9.940500	160.6716	13.06588
9.992166	160.6641	12.96072
10.04383	160.6567	12.85642
10.09383	160.6511	12.76450
10.14717	160.6458	12.66751
10.19717	160.6384	12.58907
10.24717	160.6343	12.51028
10.30050	160.6285	12.43666
10.35050	160.6247	12.37217
10.40217	160.6193	12.31132
10.45383	160.6160	12.25229
10.50384	160.6122	12.20182
10.55717	160.6091	12.15243
10.60717	160.6063	12.11230
10.65717	160.6032	12.07442
10.71050	160.6004	12.03369
10.76050	160.5984	11.99763
10.81216	160.5963	11.96379
10.86383	160.5937	11.93068
10.91383	160.5911	11.90105
10.96717	160.5891	11.86962
11.01717	160.5873	11.83949
11.06716	160.5857	11.81072
11.12050	160.5838	11.78158
11.17050	160.5823	11.75321
11.22217	160.5806	11.72434
11.27383	160.5793	11.69741
11.32383	160.5777	11.67163
11.37717	160.5761	11.64681
11.42717	160.5742	11.62362
11.47884	160.5724	11.60102
11.53050	160.5710	11.57747
11.58050	160.5697	11.55628
11.63216	160.5680	11.53586
11.68383	160.5669	11.51269
11.73383	160.5657	11.49293
11.78717	160.5643	11.47276
11.83717	160.5633	11.45579
11.88883	160.5620	11.44157
11.94050	160.5609	11.42835
11.99050	160.5599	11.41924
12.04217	160.5579	11.41187
12.09383	160.5589	11.40400
12.14383	160.5571	11.39722
12.19717	160.5560	11.38995
12.24717	160.5559	11.38309
12.29884	160.5552	11.37618
12.35050	160.5547	11.36940
12.40050	160.5547	11.36306
12.45217	160.5543	11.35670
12.50384	160.5548	11.35061
12.55383	160.5556	11.34514
12.60717	160.5557	11.33980
12.65717	160.5554	11.33536
12.70883	160.5558	11.33146
12.76050	160.5564	11.32842
12.81050	160.5588	11.32641
12.86217	160.5598	11.32512
12.91383	160.5608	11.32720
12.96383	160.5633	11.33579
13.01717	160.5661	11.35825
13.06716	160.5692	11.39601
13.11884	160.5722	11.45264
13.17050	160.5770	11.52218
13.22050	160.5815	11.59896
13.27217	160.5862	11.68674
13.32384	160.5916	11.78566
13.37384	160.5978	11.88498
13.42717	160.6051	12.00249
13.47717	160.6128	12.12264
13.52883	160.6211	12.25425
13.58050	160.6299	12.39682
13.63050	160.6390	12.53736
13.68383	160.6492	12.69943
13.73383	160.6594	12.85875
13.78383	160.6699	13.02054
13.83717	160.6814	13.19387
13.88717	160.6926	13.36371
13.93883	160.7037	13.53720
13.99050	160.7147	13.70816
14.04050	160.7257	13.87596
14.09383	160.7374	14.04538
14.14383	160.7470	14.19525
14.19384	160.7561	14.33025
14.24717	160.7657	14.44914
14.29717	160.7708	14.53800
14.34883	160.7761	14.59872
14.40050	160.7781	14.62638
14.45050	160.7773	14.63236
14.50383	160.7750	14.63029
14.55383	160.7703	14.57285
14.60383	160.7623	14.41429
14.65717	160.7530	14.22066
14.70717	160.7407	14.00138
14.75883	160.7238	13.73184
14.81050	160.7051	13.41664
14.86050	160.6826	13.06929
14.91383	160.6576	12.66188
14.96383	160.6314	12.26213
15.01383	160.6050	11.83031
15.06716	160.5721	11.34327
15.11716	160.5426	10.87107
15.16883	160.5092	10.36802
15.22050	160.4756	9.855582
15.27050	160.4438	9.358258
15.32384	160.4092	8.826972
15.37384	160.3756	8.328612
15.42383	160.3435	7.831184
15.47717	160.3095	7.313284
15.52717	160.2782	6.820576
15.57883	160.2461	6.333166
15.63050	160.2151	5.868139
15.68050	160.1860	5.428299
15.73383	160.1569	4.985433
15.78383	160.1295	4.569395
15.83383	160.1039	4.174002
15.88716	160.0762	3.770822
15.93717	160.0532	3.426736
15.98883	160.0310	3.076310
16.04050	160.0082	2.745822
16.09050	159.9886	2.432156
16.14383	159.9673	2.109822
16.19383	159.9474	1.832059
16.24550	159.9294	1.548638
16.29716	159.9116	1.290780
16.34717	159.8967	1.054296
16.39883	159.8814	0.8253322
16.45050	159.8670	0.6122484
16.50050	159.8534	0.4188140
16.55383	159.8412	0.2292536
16.60383	159.8302	0.06401819
16.65550	159.8208	-.09497909
16.70716	159.8104	-0.2408840
16.75716	159.8015	-0.3756350
16.80883	159.7927	-0.4978006
16.86050	159.7851	-0.6149277
16.91050	159.7781	-0.7195950
16.96383	159.7707	-0.8218166
17.01383	159.7646	-0.9096535
17.06550	159.7588	-0.9952968
17.11716	159.7542	-1.076812
17.16716	159.7488	-1.143378
17.21883	159.7433	-1.210195
17.27050	159.7391	-1.276603
17.32050	159.7355	-1.332644
17.37383	159.7312	-1.391614
17.42383	159.7285	-1.441209
17.47550	159.7252	-1.487757
17.52716	159.7219	-1.533259
17.57716	159.7203	-1.573280
17.62883	159.7166	-1.610331
17.68050	159.7146	-1.646082
17.73050	159.7118	-1.677593
17.78383	159.7099	-1.709891
17.83383	159.7069	-1.736669
17.88550	159.7055	-1.763704
17.93716	159.7031	-1.788825
17.98716	159.7024	-1.811965
18.03883	159.7002	-1.834158
18.09050	159.6985	-1.855301
18.14050	159.6972	-1.873031
18.19383	159.6954	-1.890730
18.24383	159.6942	-1.906510
18.29550	159.6931	-1.922337
18.34716	159.6910	-1.936513
18.39716	159.6904	-1.950512
18.45050	159.6903	-1.962573
18.50050	159.6884	-1.974496
18.55050	159.6871	-1.986470
18.60383	159.6866	-1.999271
18.65383	159.6858	-2.009362
18.70550	159.6853	-2.019365
18.75716	159.6834	-2.028204
18.80716	159.6834	-2.037384
18.86050	159.6830	-2.046302
18.91050	159.6814	-2.054336
18.96050	159.6816	-2.062684
19.01383	159.6808	-2.071442
19.06383	159.6794	-2.079870
19.11550	159.6794	-2.088542
19.16716	159.6786	-2.097478
19.21716	159.6789	-2.106230
19.27050	159.6781	-2.115386
19.32050	159.6777	-2.123940
19.37050	159.6769	-2.132462
19.42383	159.6771	-2.141549
19.47383	159.6771	-2.149835
19.52550	159.6751	-2.158320
19.57716	159.6749	-2.166672
19.62716	159.6742	-2.174614
19.68050	159.6739	-2.182892
19.73050	159.6725	-2.190520
19.78050	159.6730	-2.198150
19.83383	159.6718	-2.206195
19.88383	159.6719	-2.213798
19.93550	159.6715	-2.221474
19.98716	159.6712	-2.229094
20.03717	159.6701	-2.236402
20.09050	159.6708	-2.244104
20.14050	159.6697	-2.251078
20.19050	159.6685	-2.257927
20.24383	159.6685	-2.265115
20.29383	159.6694	-2.271699
20.34550	159.6686	-2.278325
20.39716	159.6675	-2.284800
20.44716	159.6686	-2.290972
20.50050	159.6662	-2.297407
20.55050	159.6674	-2.303403
20.60050	159.6670	-2.309262
20.65383	159.6663	-2.315486
20.70383	159.6668	-2.321244
20.75550	159.6657	-2.327140
20.80716	159.6665	-2.332995
20.85716	159.6664	-2.338564
20.91050	159.6658	-2.344429
20.96050	159.6664	-2.349825
21.01216	159.6658	-2.355222
21.06383	159.6650	-2.360640
21.11383	159.6654	-2.365770
21.16550	159.6654	-2.370981
21.21716	159.6656	-2.376005
21.26716	159.6656	-2.380716
21.32050	159.6652	-2.385502
21.37050	159.6646	-2.389975
21.42216	159.6641	-2.394284
21.47383	159.6636	-2.398569
21.52383	159.6640	-2.402568
21.57550	159.6631	-2.406575
21.62716	159.6636	-2.410450
21.67717	159.6630	-2.414155
21.73050	159.6633	-2.417953
21.78050	159.6623	-2.421512
21.83216	159.6624	-2.425269
21.88383	159.6620	-2.428963
21.93383	159.6622	-2.432517
21.98550	159.6620	-2.436060
22.03717	159.6610	-2.439556
22.08716	159.6621	-2.442886
22.14050	159.6614	-2.446383
22.19050	159.6617	-2.449504
22.24216	159.6615	-2.452590
22.29383	159.6612	-2.455591
22.34383	159.6604	-2.458354
22.39550	159.6601	-2.461127
22.44716	159.6602	-2.463918
22.49716	159.6603	-2.466614
22.55050	159.6600	-2.469355
22.60050	159.6597	-2.471976
22.65216	159.6595	-2.474683
22.70383	159.6588	-2.477328
22.75383	159.6599	-2.480000
22.80550	159.6593	-2.482674
22.85716	159.6591	-2.485290
22.90716	159.6592	-2.487758
22.96050	159.6586	-2.490295
23.01050	159.6592	-2.492711
23.06216	159.6588	-2.495190
23.11383	159.6595	-2.497759
23.16383	159.6596	-2.500221
23.21716	159.6593	-2.502847
23.26716	159.6594	-2.505236
23.31716	159.6598	-2.507543
23.37050	159.6606	-2.509902
23.42050	159.6608	-2.512005
23.47216	159.6600	-2.514225
23.52383	159.6609	-2.516295
23.57383	159.6592	-2.518122
23.62716	159.6601	-2.520006
23.67717	159.6598	-2.521718
23.72716	159.6596	-2.523237
23.78050	159.6589	-2.524803
23.83050	159.6592	-2.526174
23.88216	159.6587	-2.527600
23.93383	159.6589	-2.529009
23.98383	159.6582	-2.530374
24.03717	159.6574	-2.531984
24.08716	159.6581	-2.533550
24.13716	159.6579	-2.535183
24.19050	159.6582	-2.536948
24.24050	159.6584	-2.538464
24.29216	159.6585	-2.540015
24.34383	159.6581	-2.541382
24.39383	159.6570	-2.542628
24.44716	159.6570	-2.543925
24.49716	159.6568	-2.545156
24.54716	159.6575	-2.546379
24.60050	159.6577	-2.547731
24.65050	159.6581	-2.549073
24.70216	159.6579	-2.550508
24.75383	159.6581	-2.551968
24.80383	159.6575	-2.553438
24.85716	159.6585	-2.555008
24.90716	159.6581	-2.556403
24.95717	159.6578	-2.557772
25.01050	159.6577	-2.559114
25.06050	159.6576	-2.560351
25.11216	159.6577	-2.561566
25.16383	159.6584	-2.562803
25.21383	159.6572	-2.563898
25.26716	159.6580	-2.565131
25.31716	159.6579	-2.566238
25.36716	159.6581	-2.567332
25.42050	159.6579	-2.568483
25.47050	159.6583	-2.569470
25.52216	159.6578	-2.570376
25.57383	159.6580	-2.571264
25.62383	159.6577	-2.572147
25.67717	159.6568	-2.572951
25.72717	159.6566	-2.573664
25.77883	159.6568	-2.574402
25.83050	159.6564	-2.575086
25.88050	159.6559	-2.575703
25.93216	159.6559	-2.576334
25.98383	159.6565	-2.576944
26.03383	159.6556	-2.577536
26.08716	159.6554	-2.578245
26.13716	159.6550	-2.578928
26.18883	159.6554	-2.579751
26.24050	159.6550	-2.580532
26.29050	159.6554	-2.581387
26.34216	159.6551	-2.582344
26.39383	159.6541	-2.583185
26.44383	159.6549	-2.584116
26.49716	159.6546	-2.585080
26.54716	159.6546	-2.585969
26.59883	159.6547	-2.586822
26.65050	159.6546	-2.587727
26.70050	159.6549	-2.588591
26.75217	159.6556	-2.589481
26.80383	159.6546	-2.590398
26.85383	159.6556	-2.591377
26.90716	159.6546	-2.592419
26.95716	159.6548	-2.593520
27.00883	159.6561	-2.594645
27.06050	159.6555	-2.595706
27.11050	159.6559	-2.596720
27.16217	159.6564	-2.597795
27.21383	159.6569	-2.598760
27.26383	159.6567	-2.599548
27.31716	159.6558	-2.600346
27.36716	159.6556	-2.601013
27.41883	159.6558	-2.601563
27.47050	159.6556	-2.602024
27.52050	159.6556	-2.602446
27.57217	159.6553	-2.602748
27.62383	159.6556	-2.603091
27.67383	159.6550	-2.603457
27.72717	159.6546	-2.603842
27.77717	159.6544	-2.604262
27.82883	159.6547	-2.604782
27.88050	159.6551	-2.605410
27.93050	159.6549	-2.606104
27.98383	159.6551	-2.606907
28.03383	159.6549	-2.607685
28.08383	159.6550	-2.608423
28.13716	159.6555	-2.609263
28.18717	159.6552	-2.609963
28.23883	159.6556	-2.610652
28.29050	159.6560	-2.611216
28.34050	159.6554	-2.611660
28.39383	159.6556	-2.612045
28.44383	159.6551	-2.612312
28.49383	159.6547	-2.612626
28.54716	159.6549	-2.612760
28.59716	159.6540	-2.612914
28.64883	159.6546	-2.613088
28.70050	159.6544	-2.613386
28.75050	159.6543	-2.613727
28.80383	159.6543	-2.614166
28.85383	159.6536	-2.614680
28.90383	159.6550	-2.615227
28.95716	159.6538	-2.615747
29.00716	159.6535	-2.616214
29.05883	159.6543	-2.616785
29.11050	159.6548	-2.617334
29.16050	159.6544	-2.617962
29.21383	159.6546	-2.618545
29.26383	159.6558	-2.619220
29.31383	159.6553	-2.619822
29.36716	159.6555	-2.620437
29.41716	159.6543	-2.621013
29.46883	159.6551	-2.621695
29.52050	159.6550	-2.622271
29.57050	159.6543	-2.622750
29.62383	159.6548	-2.623184
29.67383	159.6549	-2.623516
29.72383	159.6550	-2.623742
29.77717	159.6543	-2.623941
29.82717	159.6547	-2.624134
29.87883	159.6537	-2.624226
29.93050	159.6535	-2.624317
29.98050	159.6538	-2.624457
30.03383	159.6528	-2.624660
30.08383	159.6537	-2.624976
30.13383	159.6538	-2.625366
30.18717	159.6534	-2.625890
30.23716	159.6543	-2.626480
30.28883	159.6539	-2.627188
30.34050	159.6544	-2.627896
30.39050	159.6553	-2.628548
30.44383	159.6544	-2.629102
30.49383	159.6537	-2.629608
30.54550	159.6548	-2.630113
30.59716	159.6546	-2.630559
30.64716	159.6536	-2.630975
30.69883	159.6544	-2.631430
30.75050	159.6550	-2.631872
30.80050	159.6548	-2.632202
30.85383	159.6551	-2.632577
30.90383	159.6543	-2.632850
30.95550	159.6544	-2.633186
31.00716	159.6540	-2.633489
31.05716	159.6540	-2.633757
31.10883	159.6544	-2.634013
31.16050	159.6542	-2.634244
31.21050	159.6540	-2.634537
31.26383	159.6546	-2.634800
31.31383	159.6547	-2.635077
31.36550	159.6544	-2.635355
31.41716	159.6534	-2.635575
31.46716	159.6545	-2.635785
31.51883	159.6536	-2.635950
31.57050	159.6536	-2.636140
31.62050	159.6530	-2.636208
31.67383	159.6532	-2.636335
31.72383	159.6525	-2.636428
31.77550	159.6529	-2.636380
31.82717	159.6523	-2.636370
31.87717	159.6525	-2.636494
31.92883	159.6529	-2.636656
31.98050	159.6529	-2.636948
32.03050	159.6522	-2.637406
32.08383	159.6534	-2.638042
32.13383	159.6533	-2.638586
32.18550	159.6529	-2.639092
32.23717	159.6533	-2.639610
32.28717	159.6530	-2.640173
32.33883	159.6535	-2.640598
32.39050	159.6536	-2.641028
32.44050	159.6522	-2.641392
32.49383	159.6529	-2.641900
32.54383	159.6532	-2.642322
32.59550	159.6534	-2.642800
32.64717	159.6544	-2.643259
32.69717	159.6538	-2.643605
32.75050	159.6532	-2.643897
32.80050	159.6537	-2.644166
32.85050	159.6536	-2.644425
32.90383	159.6532	-2.644611
32.95383	159.6537	-2.644746
33.00550	159.6538	-2.644886
33.05716	159.6536	-2.644976
33.10716	159.6526	-2.644956
33.16050	159.6534	-2.645048
33.21050	159.6528	-2.645175
33.26050	159.6522	-2.645356
33.31383	159.6532	-2.645618
33.36383	159.6536	-2.645990
33.41550	159.6540	-2.646364
33.46716	159.6537	-2.646763
33.51716	159.6544	-2.647240
33.57050	159.6548	-2.647717
33.62050	159.6532	-2.648092
33.67050	159.6540	-2.648410
33.72383	159.6542	-2.648716
33.77383	159.6538	-2.648954
33.82550	159.6532	-2.649045
33.87717	159.6539	-2.649153
33.92717	159.6529	-2.649144
33.98050	159.6534	-2.649070
34.03050	159.6528	-2.648964
34.08050	159.6520	-2.648854
34.13383	159.6524	-2.648832
34.18384	159.6524	-2.648806
34.23550	159.6520	-2.648804
34.28717	159.6522	-2.648984
34.33716	159.6522	-2.649304
34.39050	159.6522	-2.649748
34.44050	159.6525	-2.650225
34.49050	159.6527	-2.650764
34.54383	159.6526	-2.651289
34.59384	159.6526	-2.651746
34.64550	159.6528	-2.652109
34.69717	159.6532	-2.652399
34.74716	159.6529	-2.652574
34.80050	159.6524	-2.652704
34.85050	159.6524	-2.652848
34.90050	159.6530	-2.653124
34.95383	159.6518	-2.653393
35.00383	159.6527	-2.653711
35.05550	159.6528	-2.653963
35.10716	159.6532	-2.654196
35.15716	159.6528	-2.654427
35.21050	159.6527	-2.654744
35.26050	159.6522	-2.654976
35.31216	159.6526	-2.655170
35.36383	159.6527	-2.655368
35.41383	159.6531	-2.655540
35.46550	159.6530	-2.655718
35.51716	159.6525	-2.655836
35.56716	159.6532	-2.656040
35.62050	159.6528	-2.656184
35.67050	159.6524	-2.656339
35.72217	159.6521	-2.656425
35.77383	159.6529	-2.656498
35.82383	159.6526	-2.656530
35.87550	159.6521	-2.656512
35.92717	159.6525	-2.656406
35.97717	159.6516	-2.656285
36.03050	159.6515	-2.656217
36.08050	159.6515	-2.656345
36.13216	159.6520	-2.656530
36.18384	159.6530	-2.656900
36.23383	159.6512	-2.657264
36.28550	159.6528	-2.657746
36.33716	159.6527	-2.658141
36.38716	159.6525	-2.658514
36.44050	159.6527	-2.658910
36.49050	159.6528	-2.659177
36.54217	159.6529	-2.659438
36.59384	159.6533	-2.659620
36.64383	159.6527	-2.659704
36.69550	159.6531	-2.659976
36.74716	159.6533	-2.660188
36.79716	159.6532	-2.660438
36.85050	159.6521	-2.660551
36.90050	159.6536	-2.660665
36.95216	159.6533	-2.660754
37.00383	159.6528	-2.660735
37.05383	159.6523	-2.660675
37.10550	159.6530	-2.660672
37.15716	159.6518	-2.660644
37.20716	159.6527	-2.660649
37.26050	159.6528	-2.660774
37.31050	159.6526	-2.660782
37.36217	159.6520	-2.660706
37.41383	159.6526	-2.660635
37.46383	159.6512	-2.660510
37.51716	159.6518	-2.660361
37.56716	159.6506	-2.660227
37.61716	159.6519	-2.660132
37.67050	159.6517	-2.660111
37.72050	159.6514	-2.660078
37.77217	159.6513	-2.660170
37.82383	159.6523	-2.660385
37.87383	159.6517	-2.660650
37.92717	159.6516	-2.660937
37.97717	159.6526	-2.661314
38.02716	159.6522	-2.661638
38.08050	159.6528	-2.662009
38.13050	159.6532	-2.662327
38.18216	159.6526	-2.662608
38.23383	159.6524	-2.662817
38.28383	159.6535	-2.662989
38.33716	159.6536	-2.663144
38.38716	159.6523	-2.663178
38.43716	159.6529	-2.663196
38.49050	159.6516	-2.663083
38.54050	159.6529	-2.663000
38.59216	159.6522	-2.662831
38.64383	159.6522	-2.662702
38.69383	159.6518	-2.662475
38.74716	159.6524	-2.662400
38.79716	159.6518	-2.662439
38.84716	159.6519	-2.662541
38.90050	159.6525	-2.662610
38.95050	159.6519	-2.662820
39.00217	159.6524	-2.663131
39.05383	159.6524	-2.663407
39.10383	159.6524	-2.663699
39.15716	159.6526	-2.663904
39.20716	159.6531	-2.664166
39.25716	159.6521	-2.664374
39.31050	159.6534	-2.664620
39.36050	159.6531	-2.664676
39.41217	159.6524	-2.664774
39.46383	159.6521	-2.664798
39.51383	159.6524	-2.664774
39.56716	159.6517	-2.664624
39.61716	159.6522	-2.664532
39.66716	159.6516	-2.664375
39.72050	159.6517	-2.664259
39.77050	159.6516	-2.664335
39.82217	159.6514	-2.664509
39.87383	159.6528	-2.664768
39.92383	159.6520	-2.664979
39.97717	159.6529	-2.665328
40.02716	159.6528	-2.665638
40.07883	159.6529	-2.665891
40.13050	159.6527	-2.666088
40.18050	159.6525	-2.666204
40.23216	159.6527	-2.666274
40.28383	159.6525	-2.666274
40.33383	159.6527	-2.666171
40.38716	159.6524	-2.666033
40.43716	159.6516	-2.665854
40.48883	159.6519	-2.665660
40.54050	159.6519	-2.665446
40.59050	159.6523	-2.665398
40.64216	159.6516	-2.665476
40.69383	159.6519	-2.665632
40.74383	159.6520	-2.665856
40.79716	159.6520	-2.666110
40.84716	159.6526	-2.666304
40.89883	159.6517	-2.666421
40.95050	159.6524	-2.666525
41.00050	159.6525	-2.666552
41.05217	159.6516	-2.666537
41.10383	159.6514	-2.666438
41.15383	159.6520	-2.666361
41.20717	159.6512	-2.666214
41.25717	159.6517	-2.666140
41.30883	159.6516	-2.666038
41.36050	159.6504	-2.666033
41.41050	159.6517	-2.666246
41.46216	159.6517	-2.666586
41.51383	159.6520	-2.666960
41.56383	159.6520	-2.667360
41.61716	159.6528	-2.667765
41.66716	159.6522	-2.668071
41.71884	159.6525	-2.668364
41.77050	159.6528	-2.668633
41.82050	159.6526	-2.668932
41.87216	159.6520	-2.669246
41.92383	159.6533	-2.669570
41.97383	159.6534	-2.669764
42.02716	159.6533	-2.669897
42.07717	159.6528	-2.670012
42.12883	159.6518	-2.670046
42.18050	159.6529	-2.670119
42.23050	159.6519	-2.670066
42.28383	159.6528	-2.669944
42.33383	159.6520	-2.669653
42.38383	159.6519	-2.669358
42.43716	159.6506	-2.668982
42.48717	159.6509	-2.668700
42.53883	159.6507	-2.668417
42.59050	159.6511	-2.668314
42.64050	159.6511	-2.668352
42.69383	159.6512	-2.668457
42.74383	159.6518	-2.668678
42.79383	159.6525	-2.668924
42.84716	159.6519	-2.669044
42.89717	159.6522	-2.669222
42.94883	159.6515	-2.669294
-2.000000	2.000000	0.0000000
43.05050	159.6701	-3.297458
43.10050	159.8714	-7.345946
43.15050	160.2690	-11.75532
43.20383	160.8291	-16.02553
43.25383	161.4571	-19.37094
43.30550	162.1837	-22.16362
43.35717	162.9714	-24.40445
43.40717	163.7792	-26.13637
43.46050	164.6809	-27.60926
43.51050	165.5548	-28.73425
43.56050	166.4562	-29.50620
43.61383	167.4324	-30.31197
43.66383	168.3616	-30.92484
43.71550	169.3330	-31.44893
43.76717	170.3129	-31.91895
43.81717	171.2688	-32.32022
43.87050	172.2937	-32.69894
43.92050	173.2582	-33.01954
43.97050	174.2280	-33.31034
44.02383	175.2650	-33.60567
44.07383	176.2390	-33.87266
44.12550	177.2466	-34.15276
44.17717	178.2566	-34.43612
44.22717	179.2345	-34.69810
44.28050	180.2769	-35.00903
44.33050	181.2530	-35.33212
44.38050	182.2324	-35.62096
44.43383	183.2742	-36.00478
44.48383	184.2504	-36.36244
44.53550	185.2583	-36.75141
44.58716	186.2659	-37.16956
44.63716	187.2406	-37.58904
44.69050	188.2802	-38.02700
44.74050	189.2541	-38.48899
44.79050	190.2260	-38.96738
44.84384	191.2610	-39.51792
44.89383	192.2279	-40.08645
44.94550	193.2258	-40.71525
44.99716	194.2219	-41.38316
45.04716	195.1822	-42.12570
45.10050	196.2010	-42.99158
45.15050	197.1527	-43.86992
45.20050	198.1007	-44.76041
45.25383	199.1119	-45.73728
45.30383	200.0535	-46.84404
45.35550	201.0207	-48.13663
45.40717	201.9792	-49.58152
45.45717	202.8959	-51.23166
45.51050	203.8580	-53.31328
45.56050	204.7449	-55.50174
45.61217	205.6478	-57.94762
45.66383	206.5379	-60.47926
45.71383	207.3927	-63.05615
45.76550	208.2699	-65.77039
45.81717	209.1437	-68.58588
45.86716	209.9856	-71.22688
45.92050	210.8820	-74.13782
45.97050	211.7194	-76.91490
46.02217	212.5826	-79.87222
46.07383	213.4445	-82.77105
46.12383	214.2822	-85.26504
46.17550	215.1761	-86.60959
46.22717	216.1641	-84.33032
46.27716	217.2785	-79.26972
46.33050	218.5733	-74.31660
46.38050	219.8230	-69.58438
46.43217	221.1449	-64.19458
46.48383	222.4964	-58.53100
46.53383	223.8006	-54.07708
46.58550	225.1080	-50.61089
46.63716	226.3661	-47.94354
46.68716	227.5424	-45.91478
46.74050	228.7580	-44.20790
46.79050	229.8693	-42.94578
46.84217	230.9940	-41.92824
46.89383	232.1011	-41.12400
46.94383	233.1558	-40.51041
46.99550	234.2342	-40.01286
47.04716	235.3036	-39.61196
47.09716	236.3316	-39.31545
47.15050	237.4211	-39.06709
47.20050	238.4388	-38.88224
47.25217	239.4852	-38.76393
47.30383	240.5296	-38.66966
47.35383	241.5380	-38.61316
47.40550	242.5778	-38.57202
47.45717	243.6170	-38.54959
47.50717	244.6218	-38.53388
47.56050	245.6920	-38.52524
47.61050	246.6952	-38.52311
47.66217	247.7316	-38.52130
47.71383	248.7671	-38.51956
47.76383	249.7681	-38.51865
47.81717	250.8360	-38.51903
47.86716	251.8353	-38.52332
47.91716	252.8357	-38.53609
47.97050	253.9025	-38.55378
48.02050	254.9027	-38.58769
48.07217	255.9350	-38.63208
48.12383	256.9668	-38.67792
48.17383	257.9666	-38.73220
48.22717	259.0311	-38.80115
48.27716	260.0297	-38.85861
48.32717	261.0276	-38.91638
48.38050	262.0920	-38.99530
48.43050	263.0904	-39.04100
48.48217	264.1221	-39.11048
48.53383	265.1528	-39.17571
48.58383	266.1525	-39.24198
48.63716	267.2162	-39.29092
48.68716	268.2140	-39.35975
48.73717	269.2128	-39.41851
48.79050	270.2770	-39.46864
48.84050	271.2754	-39.51508
48.89217	272.3068	-39.57395
48.94383	273.3384	-39.62067
48.99383	274.3352	-39.63212
49.04550	275.3272	-40.25420
49.09716	275.8344	-37.98287
49.14717	275.9166	-29.57600
49.19883	275.7622	-20.24732
49.25050	275.4322	-11.79712
49.30050	274.9864	-4.875138
49.35383	274.3992	1.201484
49.40383	273.7705	5.844002
49.45550	273.0542	9.742652
49.50717	272.2826	12.89764
49.55717	271.4939	15.37642
49.60883	270.6435	17.46280
49.66050	269.7643	19.15381
49.71050	268.8890	20.48735
49.76383	267.9358	21.64781
49.81383	267.0261	22.54186
49.86550	266.0727	23.30565
49.91716	265.1070	23.92480
49.96717	264.1655	24.43588
50.01883	263.1838	24.86047
50.07050	262.1976	25.22649
50.12050	261.2357	25.51914
50.17383	260.2056	25.78091
50.22383	259.2361	25.99204
50.27550	258.2320	26.16978
50.32717	257.2247	26.32426
50.37717	256.2475	26.43979
50.42883	255.2363	26.56293
50.48050	254.2227	26.67081
50.53050	253.2404	26.75428
50.58383	252.1921	26.82884
50.63383	251.2066	26.88962
50.68550	250.1883	26.94518
50.73717	249.1685	26.99791
50.78717	248.1825	27.03458
50.83883	247.1613	27.07924
50.89050	246.1406	27.10657
50.94050	245.1518	27.13635
50.99383	244.0970	27.15768
51.04383	243.1073	27.17609
51.09550	242.0842	27.18762
51.14717	241.0611	27.20215
51.19717	240.0714	27.21280
51.25050	239.0144	27.22630
51.30050	238.0232	27.24272
51.35050	237.0329	27.25438
51.40383	235.9749	27.26730
51.45383	234.9838	27.27262
51.50550	233.9580	27.27975
51.55717	232.9337	27.28535
51.60717	231.9415	27.29058
51.66050	230.8827	27.29628
51.71050	229.8898	27.30154
51.76050	228.8982	27.30702
51.81383	227.8401	27.31408
51.86383	226.8470	27.32024
51.91550	225.8221	27.32662
51.96717	224.7968	27.33416
52.01716	223.8034	27.34042
52.07050	222.7445	27.34686
52.12050	221.7520	27.35309
52.17050	220.7585	27.35910
52.22383	219.7004	27.36576
52.27383	218.7079	27.37200
52.32550	217.6825	27.37832
52.37717	216.6576	27.38474
52.42717	215.6656	27.39102
52.48050	214.6068	27.39731
52.53050	213.6144	27.40337
52.58050	212.6213	27.40942
52.63383	211.5612	27.41550
52.68383	210.5676	27.42121
52.73550	209.5403	27.42650
52.78716	208.5131	27.43130
52.83716	207.5202	27.43543
52.89050	206.4592	27.43998
52.94050	205.4665	27.44382
52.99050	204.4716	27.44756
53.04382	203.4122	27.45082
53.09384	202.4198	27.45361
53.14550	201.3932	27.45619
53.19717	200.3661	27.45872
53.24717	199.3734	27.46115
53.30050	198.3141	27.46408
53.35050	197.3209	27.46652
53.40050	196.3250	27.46884
53.45383	195.2649	27.47129
53.50383	194.2695	27.47350
53.55550	193.2426	27.47522
53.60717	192.2152	27.47672
53.65717	191.2204	27.47805
53.71050	190.1614	27.47886
53.76050	189.1672	27.47968
53.81216	188.1409	27.48006
53.86382	187.1140	27.48073
53.91382	186.1211	27.48151
53.96550	185.0938	27.48220
54.01716	184.0670	27.48280
54.06716	183.0724	27.48371
54.12050	182.0122	27.48440
54.17050	181.0182	27.48490
54.22217	179.9915	27.48565
54.27383	178.9642	27.48660
54.32383	177.9708	27.48772
54.37550	176.9448	27.48938
54.42717	175.9168	27.49150
54.47717	174.9229	27.49360
54.53050	173.8622	27.49588
54.58050	172.8674	27.49794
54.63217	171.8392	27.49997
54.68383	170.8120	27.50141
54.73383	169.8190	27.50325
54.78550	168.7926	27.50924
54.83716	167.7682	27.54685
54.88716	166.7789	27.73346
54.94050	165.7308	28.12234
54.99050	164.7574	28.73430
55.04217	163.7746	29.90554
55.09384	162.8278	31.93319
55.14384	161.9619	34.94163
55.19550	161.1317	39.18188
55.24717	160.3676	44.18266
55.29717	159.6679	49.20644
55.35050	158.9347	54.11996
55.40050	158.2294	57.92098
55.45216	157.4547	60.80642
55.50383	156.6196	62.52751
55.55383	155.7496	63.20835
55.60550	154.7867	62.99742
55.65717	153.7639	62.05061
55.70717	152.7296	60.64705
55.76050	151.5872	58.77045
55.81050	150.4908	56.78424
55.86217	149.3400	54.61742
55.91382	148.1776	52.49096
55.96382	147.0506	50.38154
56.01716	145.8456	48.18551
56.06716	144.7160	46.03722
56.11716	143.5834	44.02812
56.17050	142.3814	41.98334
56.22050	141.2623	40.26143
56.27217	140.1172	38.74495
56.32383	138.9864	37.44013
56.37383	137.9038	36.32375
56.42717	136.7617	35.29503
56.47717	135.6999	34.47400
56.52717	134.6449	33.69631
56.58050	133.5301	33.04128
56.63050	132.4994	33.21333
56.68217	131.4267	31.93486
56.73383	130.3603	31.48010
56.78383	129.3336	31.11289
56.83716	128.2447	30.78491
56.88716	127.2282	30.54412
56.93716	126.2144	30.32170
56.99050	125.1374	30.13784
57.04050	124.1304	29.94424
57.09217	123.0867	29.57709
57.14384	122.0375	29.27379
57.19384	121.0259	29.04810
57.24717	119.9475	28.83613
57.29717	118.9394	28.64646
57.34716	117.9286	28.41945
57.40050	116.8574	28.37438
57.45050	115.8505	28.16722
57.50217	114.8109	27.99762
57.55383	113.7698	27.75952
57.60383	112.7626	27.59078
57.65717	111.6880	27.41720
57.70717	110.6822	27.25958
57.75717	109.6770	27.12180
57.81050	108.6046	26.97516
57.86050	107.6000	26.84031
57.91216	106.5620	26.71522
57.96382	105.5256	26.58511
58.01382	104.5222	26.47924
58.06716	103.4536	26.35864
58.11716	102.4517	26.24280
58.16716	101.4490	26.14216
58.22050	100.3807	26.03023
58.27050	99.37879	25.92689
58.32217	98.34272	25.82886
58.37383	97.30762	25.72096
58.42383	96.30524	25.62226
58.47717	95.23570	25.50410
58.52717	94.23370	25.40748
58.57883	93.19864	25.31393
58.63050	92.16403	25.20938
58.68050	91.16275	25.10809
58.73217	90.12822	25.01069
58.78383	89.09335	24.91216
58.83383	88.09239	24.82576
58.88716	87.02508	24.72699
58.93716	86.02449	24.64257
58.98882	84.99051	24.54761
59.04050	83.95632	24.45873
59.09050	82.95416	24.37695
59.14216	81.91934	24.28587
59.19384	80.88532	24.19164
59.24382	79.88420	24.10863
59.29717	78.81581	24.01712
59.34716	77.81446	23.92981
59.39883	76.77972	23.83956
59.45050	75.74516	23.75382
59.50050	74.74368	23.66988
59.55217	73.70842	23.57496
59.60383	72.67282	23.47961
59.65383	71.67188	23.39546
59.70717	70.60489	23.30342
59.75717	69.60375	23.21885
59.80883	68.56974	23.13578
59.86050	67.53564	23.04431
59.91050	66.53637	22.97169
59.96216	65.50222	22.88634
60.01382	64.46713	22.79779
60.06382	63.46690	22.70483
60.11716	62.39768	22.60280
60.16716	61.39620	22.50938
60.21884	60.36197	22.42420
60.27050	59.32668	22.33087
60.32050	58.32535	22.24022
60.37217	57.29068	22.15122
60.42383	56.25463	22.05894
60.47382	55.25368	21.97125
60.52717	54.18604	21.87598
60.57717	53.18391	21.79136
60.62883	52.14932	21.70438
60.68050	51.11455	21.61027
60.73050	50.11269	21.52252
60.78383	49.04516	21.43075
60.83383	48.04404	21.34348
60.88383	47.04145	21.25664
60.93716	45.97364	21.15513
60.98717	44.97114	21.04839
61.03882	43.93510	20.95351
61.09050	42.89984	20.86572
61.14050	41.89855	20.76498
61.19384	40.82898	20.67356
61.24382	39.82615	20.57832
61.29382	38.82295	20.47101
61.34716	37.75308	20.35500
61.39717	36.74957	20.25196
61.44883	35.71297	20.14198
61.50050	34.67561	20.03312
61.55050	33.67172	19.93104
61.60383	32.60272	19.80877
61.65383	31.59930	19.70574
61.70383	30.59648	19.60120
61.75717	29.52569	19.48002
61.80717	28.52028	19.38381
61.85883	27.48148	19.24226
61.91050	26.44343	19.12055
61.96050	25.43957	19.07384
62.01050	24.43530	19.09092
62.06050	23.53912	19.35184
62.11217	23.16765	15.42338
62.16382	23.12875	9.896506
62.21382	23.32399	4.796254
62.26716	23.71158	0.2246754
62.31716	24.20801	-3.286755
62.36716	24.80380	-6.134876
62.42050	25.52476	-8.587871
62.47050	26.26454	-10.42847
62.52217	27.07862	-11.97975
62.57383	27.93242	-13.23898
62.62383	28.79068	-14.23453
62.67717	29.73062	-15.10159
62.72717	30.63214	-15.77397
62.77883	31.57760	-16.36784
62.83050	32.53500	-16.86405
62.88050	33.47223	-17.27164
62.93217	34.44822	-17.64262
62.98383	35.43165	-17.96111
63.03383	36.38963	-18.23776
63.08716	37.41660	-18.49094
63.13716	38.38400	-18.69802
63.18882	39.38617	-18.88868
63.24050	40.39269	-19.06984
63.29050	41.36570	-19.23508
63.34217	42.37552	-19.38625
63.39384	43.38711	-19.52816
63.44384	44.36829	-19.66287
63.49717	45.41713	-19.79262
63.54717	46.39986	-19.90588
63.59882	47.41610	-20.03543
63.65050	48.43468	-20.15134
63.70050	49.42067	-20.26392
63.75217	50.43992	-20.38611
63.80383	51.46018	-20.50020
63.85383	52.44656	-20.60772
63.90718	53.50258	-20.72625
63.95717	54.49091	-20.82841
64.00884	55.51407	-20.93774
64.06050	56.53797	-21.05214
64.11050	57.52693	-21.15936
64.16217	58.55050	-21.27437
64.21384	59.57418	-21.38322
64.26384	60.56588	-21.49116
64.31717	61.62320	-21.61390
64.36718	62.61519	-21.71738
64.41884	63.64096	-21.82570
64.47050	64.66596	-21.93086
64.52050	65.65932	-22.02995
64.57218	66.68432	-22.13508
64.62383	67.71088	-22.24425
64.67383	68.70382	-22.34657
64.72718	69.76362	-22.44770
64.77717	70.75703	-22.55042
64.82885	71.78272	-22.65844
64.88050	72.80845	-22.76724
64.93050	73.80226	-22.87165
64.98383	74.86189	-22.98941
65.03384	75.85460	-23.09520
65.08384	76.84755	-23.20684
65.13717	77.90718	-23.33114
65.18717	78.89912	-23.44752
65.23882	79.92634	-23.56939
65.29050	80.95202	-23.69438
65.34050	81.94488	-23.81350
65.39384	83.00458	-23.93883
65.44384	83.99894	-24.05870
65.49384	84.99269	-24.17318
65.54718	86.05304	-24.30320
65.59718	87.04728	-24.41798
65.64884	88.07276	-24.53907
65.70050	89.09918	-24.67429
65.75050	90.09311	-24.80184
65.80384	91.15234	-24.93392
65.85384	92.14603	-25.05461
65.90384	93.13832	-25.18518
65.95718	94.19926	-25.32196
66.00718	95.19116	-25.45062
66.05884	96.21725	-25.57937
66.11050	97.24291	-25.70858
66.16050	98.23602	-25.84705
66.21384	99.29547	-25.98100
66.26384	100.2886	-26.12000
66.31384	101.2805	-26.25290
66.36718	102.3394	-26.39607
66.41718	103.3330	-26.52935
66.46884	104.3588	-26.66870
66.52050	105.3846	-26.82412
66.57050	106.3776	-26.96124
66.62384	107.4366	-27.12108
66.67384	108.4286	-27.27185
66.72384	109.4208	-27.43365
66.77718	110.4782	-27.60308
66.82718	111.4697	-27.77128
66.87884	112.4942	-27.93356
66.93050	113.5167	-28.11676
66.98050	114.5071	-28.29558
67.03384	115.5634	-28.49125
67.08384	116.5527	-28.67452
67.13384	117.5414	-28.87774
67.18718	118.5960	-29.08578
67.23718	119.5865	-29.22297
67.28882	120.6130	-29.34462
67.34050	121.6392	-29.51130
67.39050	122.6310	-29.65965
67.44384	123.6898	-29.84460
67.49384	124.6803	-30.02482
67.54550	125.7046	-30.21765
67.59718	126.7288	-30.37543
67.64718	127.7199	-30.52808
67.69884	128.7457	-30.68041
67.75050	129.7695	-30.88097
67.80050	130.7598	-31.06631
67.85384	131.8152	-31.24969
67.90384	132.8064	-31.45387
67.95550	133.8276	-31.64591
68.00718	134.8499	-31.87219
68.05718	135.8385	-32.08330
68.10884	136.8588	-32.32964
68.16050	137.8808	-32.55906
68.21050	138.8676	-32.81162
68.26384	139.9235	-32.83792
68.31384	140.9194	-32.96422
68.36550	141.9463	-33.17290
68.41718	142.9706	-33.31603
68.46718	143.9674	-33.32574
68.51882	144.9964	-33.44098
68.57050	146.0258	-33.57567
68.62050	147.0193	-33.70906
68.67384	148.0796	-33.85694
68.72384	149.0734	-34.02832
68.77550	150.0989	-34.20020
68.82718	151.1241	-34.37993
68.87718	152.1166	-34.49615
68.92884	153.1436	-34.62912
68.98050	154.1693	-34.77044
69.03050	155.1626	-34.93076
69.08384	156.2219	-35.08862
69.13384	157.2154	-35.23866
69.18550	158.2414	-35.39347
69.23718	159.2678	-35.55509
69.28718	160.2619	-35.66694
69.33884	161.2900	-35.77643
69.39050	162.3188	-35.86087
69.44050	163.3158	-35.93000
69.49384	164.3796	-36.00029
69.54384	165.3774	-36.05371
69.59550	166.4086	-36.12720
69.64718	167.4406	-36.21018
69.69718	168.4384	-36.28862
69.75050	169.5022	-36.38856
69.80050	170.4984	-36.52422
69.85050	171.4938	-36.63670
69.90384	172.5555	-36.78059
69.95384	173.5489	-36.93166
70.00550	174.5742	-37.09733
70.05718	175.5987	-37.30931
70.10718	176.5891	-37.52698
70.16050	177.6434	-37.77840
70.21050	178.6307	-38.05023
70.26050	179.6171	-38.35880
70.31384	180.6657	-38.71220
70.36384	181.6471	-39.08400
70.41550	182.6605	-39.51080
70.46718	183.6700	-39.99468
70.51716	184.6442	-40.48426
70.57050	185.6801	-41.08933
70.62050	186.6490	-41.70464
70.67050	187.6140	-42.37369
70.72384	188.6402	-43.14616
70.77384	189.5979	-43.95156
70.82550	190.5853	-44.82283
70.87718	191.5682	-45.73242
70.92718	192.5176	-46.64539
70.98050	193.5277	-47.60724
71.03050	194.4741	-48.57050
71.08050	195.4164	-49.59034
71.13384	196.4209	-50.73712
71.18384	197.3569	-51.87810
71.23550	198.3198	-53.18786
71.28718	199.2787	-54.56619
71.33716	200.2004	-55.98254
71.39050	201.1780	-57.57892
71.44050	202.0922	-59.09274
71.49050	203.0058	-60.54526
71.54384	203.9842	-61.91358
71.59384	204.9111	-62.86109
71.64550	205.8906	-63.22874
71.69718	206.9082	-62.62710
71.74718	207.9548	-60.26319
71.80050	209.1480	-56.66140
71.85050	210.3208	-53.09037
71.90050	211.5138	-49.77093
71.95384	212.7864	-46.67041
72.00384	213.9605	-44.41175
72.05550	215.1456	-42.64848
72.10718	216.2994	-41.31002
72.15718	217.3915	-40.30816
72.21050	218.5347	-39.48100
72.26050	219.5910	-38.88616
72.31216	220.6698	-38.41527
72.36384	221.7388	-38.05670
72.41382	222.7648	-37.80110
72.46550	223.8208	-37.58950
72.51716	224.8707	-37.43633
72.56718	225.8822	-37.34773
72.62050	226.9589	-37.27866
72.67050	227.9658	-37.23810
72.72218	229.0048	-37.22978
72.77384	230.0425	-37.22602
72.82384	231.0446	-37.22548
72.87550	232.0803	-37.22789
72.92718	233.1133	-37.23729
72.97718	234.1145	-37.26406
73.03050	235.1803	-37.31155
73.08050	236.1807	-37.35066
73.13218	237.2131	-37.40852
73.18384	238.2460	-37.47240
73.23384	239.2439	-37.53281
73.28550	240.2766	-37.60686
73.33716	241.3076	-37.68905
73.38718	242.3076	-37.75789
73.44050	243.3721	-37.82992
73.49050	244.3707	-37.88850
73.54218	245.4022	-37.95307
73.59384	246.4334	-38.01956
73.64384	247.4316	-38.07914
73.69550	248.4636	-38.13491
73.74718	249.4961	-38.19100
73.79718	250.4949	-38.24698
73.85050	251.5601	-38.31147
73.90050	252.5582	-38.36969
73.95216	253.5902	-38.42837
74.00384	254.6219	-38.49222
74.05384	255.6200	-38.56384
74.10550	256.6520	-38.63825
74.15718	257.6826	-38.71526
74.20718	258.6802	-38.79199
74.26050	259.7442	-38.87143
74.31050	260.7410	-38.94670
74.36218	261.7711	-39.03886
74.41382	262.8017	-39.10778
74.46384	263.8000	-39.19310
74.51716	264.8638	-39.27426
74.56718	265.8617	-39.34953
74.61718	266.8588	-39.41924
74.67050	267.9214	-39.50384
74.72050	268.9188	-39.59695
74.77218	269.9484	-39.67167
74.82384	270.9782	-39.74860
-2.000000	5.000000	0.0000000