File: 7-C1(1.2mol%)+C20(0.6mol%)(1)/matlab/160-1.txt
CLOSED
Version	1.0
Language	English
Mode	Standard
Run	32
RunSerial	12300
Instrument	DSC Q2000 V24.11 Build 124
Module	DSC Standard Cell RC
Operator
File	\\AE520-1454\Users\dsc\Desktop\Data\29-08-17-3\160-1.001
ProcName
InstSerial	2000-0883
AutoSerial	1293
Sample	160-1
Size	18.7000	mg
PanMass	Not available
PanResist	Automatic Automatic  K/W
PanFactor	Default Default
Method
Comment
Xcomment	Pan: Tzero Aluminum Hermetic
Xcomment	Gas1: Nitrogen 50.0 ml/min
Xcomment	Gas2: Nitrogen 50.0 ml/min
Text
Exotherm	UP
Kcell	1.05230
Cpconst	Standard: 0.938
Calib	-38.6961
TempCal	1	pts	157.46	156.60
TzeroDt	-87.6168 -0.0009 -1.4231
TzeroDtz	-87.6168 0.0057 6.9570
InstCalFile	Tzero: \\Ae520-1454\ta\Data\DSC\Calibration\2017\CALIBRATION\1562_RCS (90)_05_18_2017 10_50_44.TZR
InstCalFile	Baseline: \\Ae520-1454\ta\Data\DSC\Calibration\2017\2017-05-17_Calibration.001
InstCalFile	Sapphire: \\Ae520-1454\ta\Data\DSC\Calibration\2017\2017-05-17_Saphire.001
InstCalDate	Tzero 2017-05-18 Time 10:50:44
TempRange	-87.39 to 398.39 °C at 10.00 °C/min Heat Only
AutoZero	Delta T Offset 0.000 uV
AutoZero	Delta T0 Offset 0.000 uV
MultiptCal	0
MultiPtDesc	0) Not set
AutoCellConst	Calibration Date 2017-05-18 16:59:28
Controls	Gas 1  Event Off  Sampling 0.2
Cell#	RC-01562
CoolingUnit	RCS (90)
SelHeatFlow	Heat Flow T4P (mW)
AutoLidII	Installed
AutoAnalysis	Off
MacroFile
Nsig	3
Sig1	Time (min)
Sig2	Temperature (°C)
Sig3	Heat Flow (mW)
Date	2017-08-31
Time	05:38:48
OrgMethod	1: Equilibrate at 80.00 °C
OrgMethod	2: Isothermal for 3.00 min
OrgMethod	3: Jump to 160.00 °C
OrgMethod	4: Mark end of cycle 1
OrgMethod	5: Isothermal for 40.00 min
OrgMethod	6: Mark end of cycle 2
OrgMethod	7: Ramp 20.00 °C/min to 280.00 °C
OrgMethod	8: Mark end of cycle 3
OrgMethod	9: Ramp 20.00 °C/min to 20.00 °C
OrgMethod	10: Mark end of cycle 4
OrgMethod	11: Ramp 20.00 °C/min to 280.00 °C
OrgMethod	12: Mark end of cycle 5
OrgFile	C:\Users\jarra\Desktop\DSC\7-C1(1.2mol%)+C20(0.6mol%)(1)\160-1.001
StartOfData
4.99994E-4	79.87758	-1.399114
0.05383332	79.89069	-1.175371
0.1038333	79.89960	-1.026840
0.1555000	79.90520	-0.9151630
0.2071666	79.90848	-0.8352618
0.2571667	79.91082	-0.7804124
0.3105000	79.91118	-0.7438845
0.3605000	79.91106	-0.7214745
0.4121666	79.91116	-0.7072374
0.4638333	79.91026	-0.6987803
0.5138333	79.90938	-0.6943046
0.5655000	79.90869	-0.6914020
0.6171668	79.90758	-0.6886716
0.6671668	79.90632	-0.6859813
0.7205000	79.90394	-0.6832912
0.7705000	79.90297	-0.6808770
0.8221666	79.90326	-0.6786109
0.8738332	79.90103	-0.6764349
0.9238334	79.90059	-0.6746901
0.9755000	79.89881	-0.6729843
1.027167	79.89922	-0.6714545
1.077166	79.89788	-0.6701446
1.130500	79.89641	-0.6689280
1.180500	79.89539	-0.6679572
1.232166	79.89518	-0.6671594
1.283834	79.89438	-0.6665074
1.333833	79.89350	-0.6660274
1.385500	79.89250	-0.6657197
1.437167	79.89232	-0.6655968
1.487166	79.89057	-0.6654772
1.540500	79.88962	-0.6654712
1.590500	79.88868	-0.6655228
1.642166	79.88929	-0.6656938
1.693833	79.88779	-0.6659400
1.743833	79.88744	-0.6662955
1.795500	79.88657	-0.6667742
1.847167	79.88629	-0.6672316
1.897167	79.88642	-0.6678284
1.950500	79.88531	-0.6685058
2.000500	79.88444	-0.6691772
2.052166	79.88382	-0.6699566
2.103833	79.88312	-0.6708053
2.153833	79.88235	-0.6716578
2.205500	79.88318	-0.6726249
2.257167	79.88300	-0.6735486
2.307167	79.88130	-0.6744754
2.360500	79.88141	-0.6755545
2.410500	79.88085	-0.6764764
2.462167	79.87995	-0.6775229
2.513833	79.88040	-0.6786068
2.563833	79.87905	-0.6795934
2.617167	79.87902	-0.6807058
2.667167	79.87753	-0.6817772
2.717167	79.87826	-0.6829302
2.770500	79.87686	-0.6840676
2.820500	79.87762	-0.6852102
2.872167	79.87648	-0.6863691
2.923834	79.87612	-0.6875586
2.973833	79.87524	-0.6887796
3.020500	79.89891	-1.068706
3.073833	80.87353	-13.31096
3.123834	83.08718	-25.45220
3.175500	85.98637	-36.13802
3.227167	89.37515	-45.36132
3.277167	92.99809	-52.75126
3.328833	97.00028	-58.91897
3.380500	101.1924	-63.84082
3.430500	105.3759	-67.70364
3.483833	109.9353	-70.94921
3.533833	114.2663	-73.31796
3.585500	118.7784	-75.31584
3.637167	123.3110	-76.97826
3.687167	127.7102	-78.13540
3.738834	132.2617	-79.04334
3.790500	136.8114	-79.68701
3.840500	141.2102	-80.04700
3.893833	145.7319	-77.50829
3.943833	148.8644	-65.85741
3.995500	151.1660	-54.19877
4.047167	152.9052	-43.58226
4.097166	154.1801	-34.86984
4.150500	155.2278	-27.30502
4.200500	155.9858	-21.66790
4.250500	156.5857	-17.24866
4.303834	157.0919	-13.60409
4.353833	157.4728	-10.98013
4.405500	157.7936	-8.914931
4.457167	158.0559	-7.330720
4.507167	158.2675	-6.157752
4.560500	158.4561	-5.200550
4.610500	158.6052	-4.507516
4.660500	158.7347	-3.969805
4.713834	158.8514	-3.515842
4.763834	158.9461	-3.183954
4.815500	159.0318	-2.907834
4.867166	159.1052	-2.685133
4.917167	159.1689	-2.509403
4.970500	159.2283	-2.351170
5.020500	159.2779	-2.228752
5.070500	159.3197	-2.121703
5.123833	159.3619	-2.026278
5.173834	159.3961	-1.945633
5.225500	159.4284	-1.870413
5.277168	159.4561	-1.798293
5.327168	159.4819	-1.736017
5.380500	159.5058	-1.672169
5.430500	159.5267	-1.614546
5.480500	159.5448	-1.556734
5.533832	159.5646	-1.498482
5.583832	159.5790	-1.441867
5.635500	159.5944	-1.384185
5.687168	159.6081	-1.328662
5.737168	159.6215	-1.269748
5.790500	159.6336	-1.206571
5.840500	159.6446	-1.147317
5.890500	159.6542	-1.084710
5.943832	159.6656	-1.019679
5.993834	159.6752	-0.9565144
6.045500	159.6854	-0.8886079
6.097168	159.6938	-0.8157792
6.147168	159.7025	-0.7471009
6.200500	159.7119	-0.6698176
6.250500	159.7198	-0.5961262
6.300500	159.7274	-0.5204697
6.353832	159.7360	-0.4366522
6.403832	159.7441	-0.3557946
6.455500	159.7516	-0.2731486
6.507168	159.7592	-0.1848159
6.557166	159.7669	-.09838334
6.610500	159.7756	-2.5709E-3
6.660500	159.7826	0.09105268
6.712168	159.7910	0.1877074
6.763834	159.7992	0.2877910
6.813834	159.8069	0.3880550
6.865500	159.8153	0.4915216
6.917168	159.8230	0.6009912
6.967168	159.8311	0.7100170
7.020500	159.8411	0.8252062
7.070500	159.8488	0.9421472
7.122168	159.8567	1.060450
7.173834	159.8669	1.181256
7.223834	159.8749	1.304230
7.275500	159.8836	1.430449
7.327168	159.8933	1.560975
7.377168	159.9021	1.689537
7.430500	159.9116	1.829706
7.480500	159.9207	1.962445
7.532166	159.9314	2.096974
7.583832	159.9404	2.237764
7.633832	159.9500	2.373818
7.685500	159.9602	2.513260
7.737168	159.9696	2.656962
7.787168	159.9782	2.790460
7.840500	159.9888	2.936175
7.890500	159.9977	3.070581
7.942168	160.0088	3.204181
7.993834	160.0166	3.341068
8.043834	160.0254	3.465910
8.095500	160.0341	3.594107
8.147168	160.0426	3.712672
8.197168	160.0506	3.826890
8.250500	160.0582	3.936731
8.300500	160.0654	4.035141
8.352168	160.0720	4.127292
8.403832	160.0771	4.214186
8.453834	160.0845	4.288402
8.505500	160.0895	4.361966
8.557168	160.0944	4.430347
8.607166	160.0998	4.496960
8.660499	160.1052	4.571270
8.710499	160.1102	4.657710
8.762168	160.1168	4.752258
8.813834	160.1240	4.863034
8.863834	160.1318	4.990717
8.917168	160.1417	5.147450
8.967168	160.1506	5.316761
9.017168	160.1636	5.508344
9.070500	160.1781	5.738224
9.120499	160.1931	5.985053
9.172168	160.2104	6.255176
9.223832	160.2295	6.542305
9.273834	160.2484	6.827934
9.327168	160.2682	7.143370
9.377168	160.2871	7.424278
9.427168	160.3045	7.690239
9.480500	160.3218	7.944755
9.530500	160.3367	8.146538
9.582168	160.3486	8.314352
9.633832	160.3575	8.429276
9.683832	160.3626	8.494666
9.737168	160.3652	8.518360
9.787168	160.3644	8.516418
9.837168	160.3617	8.511040
9.890500	160.3550	8.428139
9.940500	160.3488	8.278240
9.992166	160.3408	8.126535
10.04383	160.3318	7.975747
10.09383	160.3231	7.833642
10.14717	160.3133	7.678938
10.19717	160.3036	7.541772
10.24717	160.2950	7.408848
10.30050	160.2869	7.271954
10.35050	160.2788	7.153611
10.40217	160.2709	7.033898
10.45383	160.2648	6.925078
10.50384	160.2569	6.828243
10.55717	160.2516	6.729697
10.60717	160.2457	6.649810
10.65717	160.2413	6.572076
10.71050	160.2346	6.498266
10.76050	160.2305	6.431168
10.81216	160.2265	6.364247
10.86383	160.2228	6.301016
10.91383	160.2187	6.246734
10.96717	160.2149	6.189120
11.01717	160.2113	6.138305
11.06716	160.2088	6.085531
11.12050	160.2039	6.034302
11.17050	160.2016	5.982886
11.22217	160.1984	5.936065
11.27383	160.1952	5.886181
11.32383	160.1928	5.840350
11.37717	160.1894	5.791901
11.42717	160.1870	5.749030
11.47884	160.1840	5.706072
11.53050	160.1823	5.662430
11.58050	160.1801	5.626002
11.63216	160.1769	5.589801
11.68383	160.1738	5.551266
11.73383	160.1718	5.514957
11.78717	160.1708	5.478370
11.83717	160.1684	5.447282
11.88883	160.1654	5.416610
11.94050	160.1639	5.386193
11.99050	160.1613	5.358899
12.04217	160.1599	5.333191
12.09383	160.1572	5.309164
12.14383	160.1560	5.285910
12.19717	160.1546	5.264566
12.24717	160.1523	5.244488
12.29884	160.1516	5.225628
12.35050	160.1499	5.209336
12.40050	160.1492	5.193250
12.45217	160.1464	5.179120
12.50384	160.1455	5.165480
12.55383	160.1436	5.152261
12.60717	160.1426	5.138346
12.65717	160.1415	5.128433
12.70883	160.1404	5.119484
12.76050	160.1388	5.110840
12.81050	160.1390	5.103050
12.86217	160.1384	5.095665
12.91383	160.1372	5.088138
12.96383	160.1372	5.080942
13.01717	160.1368	5.073426
13.06716	160.1369	5.066551
13.11884	160.1364	5.059765
13.17050	160.1371	5.053339
13.22050	160.1364	5.047512
13.27217	160.1382	5.042026
13.32384	160.1376	5.037207
13.37384	160.1381	5.033153
13.42717	160.1398	5.029434
13.47717	160.1409	5.026709
13.52883	160.1414	5.024554
13.58050	160.1425	5.023027
13.63050	160.1427	5.022244
13.68383	160.1437	5.022090
13.73383	160.1454	5.022484
13.78383	160.1472	5.023511
13.83717	160.1468	5.025076
13.88717	160.1473	5.026934
13.93883	160.1483	5.029211
13.99050	160.1499	5.031876
14.04050	160.1497	5.034730
14.09383	160.1512	5.038111
14.14383	160.1522	5.041580
14.19384	160.1516	5.045368
14.24717	160.1520	5.049830
14.29717	160.1526	5.054347
14.34883	160.1528	5.059524
14.40050	160.1538	5.064760
14.45050	160.1540	5.070119
14.50383	160.1538	5.075880
14.55383	160.1546	5.081034
14.60383	160.1538	5.085800
14.65717	160.1522	5.090014
14.70717	160.1510	5.093050
14.75883	160.1499	5.095859
14.81050	160.1477	5.093292
14.86050	160.1450	5.076098
14.91383	160.1416	5.032702
14.96383	160.1380	4.968032
15.01383	160.1343	4.887324
15.06716	160.1282	4.793538
15.11716	160.1234	4.698514
15.16883	160.1166	4.594019
15.22050	160.1112	4.480266
15.27050	160.1025	4.366125
15.32384	160.0950	4.233632
15.37384	160.0874	4.106068
15.42383	160.0782	3.971657
15.47717	160.0680	3.822703
15.52717	160.0595	3.679658
15.57883	160.0499	3.530153
15.63050	160.0388	3.378506
15.68050	160.0296	3.224590
15.73383	160.0197	3.065111
15.78383	160.0096	2.913306
15.83383	159.9982	2.757758
15.88716	159.9884	2.594930
15.93717	159.9781	2.445380
15.98883	159.9677	2.287553
16.04050	159.9581	2.133757
16.09050	159.9486	1.985317
16.14383	159.9384	1.828500
16.19383	159.9294	1.683006
16.24550	159.9199	1.537147
16.29716	159.9109	1.396189
16.34717	159.9017	1.260420
16.39883	159.8926	1.124700
16.45050	159.8846	0.9904179
16.50050	159.8762	0.8669082
16.55383	159.8682	0.7389920
16.60383	159.8599	0.6243110
16.65550	159.8530	0.5077209
16.70716	159.8445	0.3969390
16.75716	159.8381	0.2894924
16.80883	159.8306	0.1870125
16.86050	159.8242	0.08668686
16.91050	159.8188	-5.8959E-3
16.96383	159.8122	-.09940061
17.01383	159.8060	-0.1846018
17.06550	159.8002	-0.2662050
17.11716	159.7950	-0.3490747
17.16716	159.7903	-0.4268434
17.21883	159.7855	-0.4981317
17.27050	159.7810	-0.5711682
17.32050	159.7776	-0.6346629
17.37383	159.7726	-0.6980713
17.42383	159.7689	-0.7558562
17.47550	159.7651	-0.8113900
17.52716	159.7618	-0.8666649
17.57716	159.7574	-0.9155457
17.62883	159.7545	-0.9641540
17.68050	159.7504	-1.008949
17.73050	159.7478	-1.052496
17.78383	159.7446	-1.094518
17.83383	159.7406	-1.132771
17.88550	159.7384	-1.173007
17.93716	159.7364	-1.210474
17.98716	159.7332	-1.243247
18.03883	159.7306	-1.277748
18.09050	159.7287	-1.309058
18.14050	159.7254	-1.338908
18.19383	159.7241	-1.368828
18.24383	159.7228	-1.393708
18.29550	159.7202	-1.417538
18.34716	159.7188	-1.441292
18.39716	159.7171	-1.462151
18.45050	159.7154	-1.483388
18.50050	159.7138	-1.501548
18.55050	159.7117	-1.516706
18.60383	159.7116	-1.535640
18.65383	159.7101	-1.551968
18.70550	159.7090	-1.566277
18.75716	159.7074	-1.580674
18.80716	159.7066	-1.595740
18.86050	159.7052	-1.608616
18.91050	159.7046	-1.623930
18.96050	159.7044	-1.636646
19.01383	159.7033	-1.649445
19.06383	159.7024	-1.660188
19.11550	159.7016	-1.670877
19.16716	159.7011	-1.680696
19.21716	159.7005	-1.689622
19.27050	159.6994	-1.699149
19.32050	159.6984	-1.707876
19.37050	159.6973	-1.716430
19.42383	159.6972	-1.725612
19.47383	159.6956	-1.734062
19.52550	159.6952	-1.742924
19.57716	159.6944	-1.751941
19.62716	159.6933	-1.760745
19.68050	159.6927	-1.770716
19.73050	159.6919	-1.779690
19.78050	159.6907	-1.788838
19.83383	159.6896	-1.798448
19.88383	159.6898	-1.807606
19.93550	159.6889	-1.816875
19.98716	159.6890	-1.826183
20.03717	159.6885	-1.835206
20.09050	159.6872	-1.844858
20.14050	159.6874	-1.853918
20.19050	159.6856	-1.862885
20.24383	159.6862	-1.872394
20.29383	159.6858	-1.881271
20.34550	159.6861	-1.890384
20.39716	159.6856	-1.899349
20.44716	159.6846	-1.907855
20.50050	159.6842	-1.916924
20.55050	159.6839	-1.925374
20.60050	159.6834	-1.933844
20.65383	159.6841	-1.942663
20.70383	159.6825	-1.950792
20.75550	159.6825	-1.959157
20.80716	159.6822	-1.967392
20.85716	159.6814	-1.975262
20.91050	159.6806	-1.983493
20.96050	159.6819	-1.991267
21.01216	159.6811	-1.999078
21.06383	159.6806	-2.006772
21.11383	159.6808	-2.014092
21.16550	159.6805	-2.021575
21.21716	159.6797	-2.028896
21.26716	159.6798	-2.035922
21.32050	159.6798	-2.043273
21.37050	159.6786	-2.049959
21.42216	159.6785	-2.056750
21.47383	159.6777	-2.063418
21.52383	159.6778	-2.069792
21.57550	159.6774	-2.076228
21.62716	159.6778	-2.082526
21.67717	159.6770	-2.088560
21.73050	159.6764	-2.094798
21.78050	159.6764	-2.100509
21.83216	159.6763	-2.106299
21.88383	159.6746	-2.111856
21.93383	159.6748	-2.117154
21.98550	159.6749	-2.122517
22.03717	159.6734	-2.127701
22.08716	159.6732	-2.132598
22.14050	159.6732	-2.137717
22.19050	159.6728	-2.142387
22.24216	159.6721	-2.147103
22.29383	159.6724	-2.151825
22.34383	159.6713	-2.156232
22.39550	159.6719	-2.160769
22.44716	159.6714	-2.165304
22.49716	159.6718	-2.169734
22.55050	159.6721	-2.174400
22.60050	159.6724	-2.178669
22.65216	159.6730	-2.182952
22.70383	159.6733	-2.187156
22.75383	159.6725	-2.191178
22.80550	159.6729	-2.195284
22.85716	159.6724	-2.199236
22.90716	159.6727	-2.202944
22.96050	159.6719	-2.206809
23.01050	159.6724	-2.210388
23.06216	159.6718	-2.213794
23.11383	159.6716	-2.217196
23.16383	159.6713	-2.220380
23.21716	159.6715	-2.223596
23.26716	159.6716	-2.226558
23.31716	159.6710	-2.229424
23.37050	159.6714	-2.232390
23.42050	159.6709	-2.235108
23.47216	159.6701	-2.237818
23.52383	159.6696	-2.240409
23.57383	159.6694	-2.242910
23.62716	159.6698	-2.245552
23.67717	159.6694	-2.248001
23.72716	159.6691	-2.250478
23.78050	159.6687	-2.253135
23.83050	159.6693	-2.255717
23.88216	159.6694	-2.258308
23.93383	159.6698	-2.260944
23.98383	159.6691	-2.263368
24.03717	159.6693	-2.265966
24.08716	159.6703	-2.268225
24.13716	159.6705	-2.270464
24.19050	159.6702	-2.272810
24.24050	159.6705	-2.274882
24.29216	159.6695	-2.276876
24.34383	159.6694	-2.278918
24.39383	159.6691	-2.280802
24.44716	159.6689	-2.282704
24.49716	159.6688	-2.284393
24.54716	159.6685	-2.286056
24.60050	159.6687	-2.287775
24.65050	159.6678	-2.289359
24.70216	159.6676	-2.290877
24.75383	159.6677	-2.292401
24.80383	159.6677	-2.293970
24.85716	159.6677	-2.295582
24.90716	159.6675	-2.297246
24.95717	159.6679	-2.298884
25.01050	159.6670	-2.300564
25.06050	159.6678	-2.302268
25.11216	159.6675	-2.303877
25.16383	159.6681	-2.305489
25.21383	159.6681	-2.307082
25.26716	159.6675	-2.308773
25.31716	159.6677	-2.310364
25.36716	159.6675	-2.311952
25.42050	159.6671	-2.313564
25.47050	159.6680	-2.315040
25.52216	159.6672	-2.316513
25.57383	159.6672	-2.318018
25.62383	159.6675	-2.319375
25.67717	159.6683	-2.320842
25.72717	159.6685	-2.322072
25.77883	159.6676	-2.323322
25.83050	159.6664	-2.324458
25.88050	159.6665	-2.325548
25.93216	159.6663	-2.326652
25.98383	159.6658	-2.327743
26.03383	159.6664	-2.328789
26.08716	159.6660	-2.329863
26.13716	159.6651	-2.330914
26.18883	159.6654	-2.331978
26.24050	159.6656	-2.333066
26.29050	159.6662	-2.334210
26.34216	159.6652	-2.335492
26.39383	159.6655	-2.336824
26.44383	159.6663	-2.338069
26.49716	159.6662	-2.339339
26.54716	159.6653	-2.340401
26.59883	159.6659	-2.341434
26.65050	159.6658	-2.342370
26.70050	159.6651	-2.343180
26.75217	159.6648	-2.344037
26.80383	159.6660	-2.344983
26.85383	159.6648	-2.345949
26.90716	159.6658	-2.347088
26.95716	159.6654	-2.348148
27.00883	159.6659	-2.349267
27.06050	159.6655	-2.350349
27.11050	159.6659	-2.351316
27.16217	159.6662	-2.352300
27.21383	159.6664	-2.353222
27.26383	159.6662	-2.354104
27.31716	159.6661	-2.355020
27.36716	159.6658	-2.355837
27.41883	159.6659	-2.356516
27.47050	159.6660	-2.357195
27.52050	159.6661	-2.357748
27.57217	159.6650	-2.358296
27.62383	159.6648	-2.358858
27.67383	159.6645	-2.359492
27.72717	159.6654	-2.360287
27.77717	159.6655	-2.361006
27.82883	159.6655	-2.361820
27.88050	159.6647	-2.362592
27.93050	159.6652	-2.363444
27.98383	159.6658	-2.364277
28.03383	159.6656	-2.364927
28.08383	159.6659	-2.365578
28.13716	159.6664	-2.366268
28.18717	159.6660	-2.366900
28.23883	159.6659	-2.367606
28.29050	159.6657	-2.368258
28.34050	159.6664	-2.368828
28.39383	159.6658	-2.369453
28.44383	159.6652	-2.370022
28.49383	159.6650	-2.370570
28.54716	159.6656	-2.371067
28.59716	159.6654	-2.371435
28.64883	159.6650	-2.371902
28.70050	159.6652	-2.372305
28.75050	159.6644	-2.372588
28.80383	159.6644	-2.372910
28.85383	159.6636	-2.373180
28.90383	159.6645	-2.373467
28.95716	159.6633	-2.373766
29.00716	159.6641	-2.374168
29.05883	159.6646	-2.374723
29.11050	159.6639	-2.375308
29.16050	159.6651	-2.375978
29.21383	159.6649	-2.376612
29.26383	159.6652	-2.377244
29.31383	159.6650	-2.377897
29.36716	159.6646	-2.378457
29.41716	159.6659	-2.378944
29.46883	159.6647	-2.379324
29.52050	159.6648	-2.379696
29.57050	159.6646	-2.379959
29.62383	159.6649	-2.380281
29.67383	159.6644	-2.380504
29.72383	159.6638	-2.380713
29.77717	159.6636	-2.380991
29.82717	159.6633	-2.381228
29.87883	159.6637	-2.381463
29.93050	159.6629	-2.381722
29.98050	159.6622	-2.381932
30.03383	159.6631	-2.382318
30.08383	159.6624	-2.382678
30.13383	159.6623	-2.383052
30.18717	159.6621	-2.383412
30.23716	159.6624	-2.383792
30.28883	159.6630	-2.384134
30.34050	159.6630	-2.384475
30.39050	159.6629	-2.384812
30.44383	159.6626	-2.385176
30.49383	159.6629	-2.385680
30.54550	159.6634	-2.386095
30.59716	159.6642	-2.386656
30.64716	159.6649	-2.387142
30.69883	159.6634	-2.387695
30.75050	159.6641	-2.388289
30.80050	159.6656	-2.388767
30.85383	159.6643	-2.389150
30.90383	159.6648	-2.389580
30.95550	159.6640	-2.389917
31.00716	159.6646	-2.390356
31.05716	159.6646	-2.390716
31.10883	159.6644	-2.390902
31.16050	159.6642	-2.391094
31.21050	159.6638	-2.391299
31.26383	159.6636	-2.391556
31.31383	159.6640	-2.391836
31.36550	159.6644	-2.392167
31.41716	159.6638	-2.392480
31.46716	159.6640	-2.392801
31.51883	159.6643	-2.393148
31.57050	159.6644	-2.393489
31.62050	159.6641	-2.393854
31.67383	159.6644	-2.394266
31.72383	159.6641	-2.394502
31.77550	159.6644	-2.394777
31.82717	159.6645	-2.395083
31.87717	159.6647	-2.395286
31.92883	159.6639	-2.395398
31.98050	159.6639	-2.395481
32.03050	159.6638	-2.395535
32.08383	159.6631	-2.395620
32.13383	159.6632	-2.395638
32.18550	159.6631	-2.395685
32.23717	159.6632	-2.395740
32.28717	159.6634	-2.395816
32.33883	159.6629	-2.395954
32.39050	159.6634	-2.396246
32.44050	159.6624	-2.396502
32.49383	159.6631	-2.396958
32.54383	159.6639	-2.397355
32.59550	159.6630	-2.397754
32.64717	159.6630	-2.398218
32.69717	159.6639	-2.398618
32.75050	159.6652	-2.398988
32.80050	159.6645	-2.399301
32.85050	159.6641	-2.399594
32.90383	159.6646	-2.399888
32.95383	159.6647	-2.400147
33.00550	159.6644	-2.400392
33.05716	159.6639	-2.400569
33.10716	159.6645	-2.400740
33.16050	159.6650	-2.400854
33.21050	159.6645	-2.400915
33.26050	159.6631	-2.400946
33.31383	159.6635	-2.401012
33.36383	159.6637	-2.401110
33.41550	159.6633	-2.401328
33.46716	159.6631	-2.401494
33.51716	159.6636	-2.401713
33.57050	159.6638	-2.402058
33.62050	159.6634	-2.402360
33.67050	159.6638	-2.402726
33.72383	159.6638	-2.403076
33.77383	159.6648	-2.403373
33.82550	159.6637	-2.403604
33.87717	159.6636	-2.403852
33.92717	159.6636	-2.404041
33.98050	159.6641	-2.404272
34.03050	159.6639	-2.404490
34.08050	159.6642	-2.404642
34.13383	159.6639	-2.404842
34.18384	159.6642	-2.404991
34.23550	159.6636	-2.405176
34.28717	159.6633	-2.405278
34.33716	159.6642	-2.405398
34.39050	159.6634	-2.405468
34.44050	159.6633	-2.405558
34.49050	159.6621	-2.405607
34.54383	159.6620	-2.405638
34.59384	159.6624	-2.405707
34.64550	159.6625	-2.405719
34.69717	159.6621	-2.405766
34.74716	159.6613	-2.405834
34.80050	159.6607	-2.405953
34.85050	159.6615	-2.406086
34.90050	159.6604	-2.406286
34.95383	159.6610	-2.406485
35.00383	159.6611	-2.406658
35.05550	159.6615	-2.406851
35.10716	159.6611	-2.407074
35.15716	159.6610	-2.407306
35.21050	159.6618	-2.407606
35.26050	159.6619	-2.407989
35.31216	159.6630	-2.408509
35.36383	159.6629	-2.409023
35.41383	159.6629	-2.409430
35.46550	159.6630	-2.409920
35.51716	159.6628	-2.410363
35.56716	159.6628	-2.410696
35.62050	159.6639	-2.411014
35.67050	159.6640	-2.411201
35.72217	159.6627	-2.411363
35.77383	159.6635	-2.411562
35.82383	159.6633	-2.411744
35.87550	159.6636	-2.411877
35.92717	159.6641	-2.412105
35.97717	159.6636	-2.412238
36.03050	159.6634	-2.412356
36.08050	159.6631	-2.412472
36.13216	159.6634	-2.412474
36.18384	159.6631	-2.412541
36.23383	159.6627	-2.412498
36.28550	159.6628	-2.412414
36.33716	159.6623	-2.412356
36.38716	159.6620	-2.412328
36.44050	159.6620	-2.412408
36.49050	159.6619	-2.412570
36.54217	159.6624	-2.412816
36.59384	159.6624	-2.413074
36.64383	159.6633	-2.413326
36.69550	159.6629	-2.413593
36.74716	159.6632	-2.413838
36.79716	159.6632	-2.414055
36.85050	159.6631	-2.414236
36.90050	159.6627	-2.414389
36.95216	159.6634	-2.414517
37.00383	159.6631	-2.414671
37.05383	159.6635	-2.414760
37.10550	159.6625	-2.414801
37.15716	159.6628	-2.415022
37.20716	159.6630	-2.415234
37.26050	159.6642	-2.415450
37.31050	159.6629	-2.415524
37.36217	159.6629	-2.415672
37.41383	159.6627	-2.415859
37.46383	159.6628	-2.416014
37.51716	159.6627	-2.416185
37.56716	159.6630	-2.416369
37.61716	159.6631	-2.416454
37.67050	159.6621	-2.416533
37.72050	159.6622	-2.416629
37.77217	159.6620	-2.416644
37.82383	159.6617	-2.416674
37.87383	159.6612	-2.416636
37.92717	159.6610	-2.416648
37.97717	159.6613	-2.416644
38.02716	159.6606	-2.416604
38.08050	159.6608	-2.416623
38.13050	159.6609	-2.416720
38.18216	159.6608	-2.416853
38.23383	159.6617	-2.417110
38.28383	159.6615	-2.417482
38.33716	159.6623	-2.417839
38.38716	159.6627	-2.418293
38.43716	159.6630	-2.418682
38.49050	159.6627	-2.419124
38.54050	159.6639	-2.419478
38.59216	159.6631	-2.419862
38.64383	159.6634	-2.420159
38.69383	159.6631	-2.420342
38.74716	159.6642	-2.420541
38.79716	159.6624	-2.420584
38.84716	159.6631	-2.420606
38.90050	159.6631	-2.420590
38.95050	159.6631	-2.420547
39.00217	159.6623	-2.420432
39.05383	159.6628	-2.420326
39.10383	159.6619	-2.420208
39.15716	159.6629	-2.420155
39.20716	159.6611	-2.420000
39.25716	159.6612	-2.419919
39.31050	159.6618	-2.419900
39.36050	159.6616	-2.419945
39.41217	159.6620	-2.420127
39.46383	159.6625	-2.420302
39.51383	159.6629	-2.420512
39.56716	159.6626	-2.420755
39.61716	159.6627	-2.420908
39.66716	159.6629	-2.421127
39.72050	159.6632	-2.421368
39.77050	159.6624	-2.421540
39.82217	159.6624	-2.421664
39.87383	159.6632	-2.421818
39.92383	159.6637	-2.421963
39.97717	159.6631	-2.421970
40.02716	159.6630	-2.422012
40.07883	159.6636	-2.422053
40.13050	159.6632	-2.422041
40.18050	159.6622	-2.422089
40.23216	159.6628	-2.422158
40.28383	159.6630	-2.422220
40.33383	159.6635	-2.422311
40.38716	159.6629	-2.422338
40.43716	159.6630	-2.422386
40.48883	159.6626	-2.422424
40.54050	159.6619	-2.422430
40.59050	159.6617	-2.422500
40.64216	159.6622	-2.422472
40.69383	159.6616	-2.422397
40.74383	159.6610	-2.422312
40.79716	159.6612	-2.422253
40.84716	159.6612	-2.422223
40.89883	159.6616	-2.422182
40.95050	159.6610	-2.422264
41.00050	159.6616	-2.422446
41.05217	159.6616	-2.422591
41.10383	159.6616	-2.422804
41.15383	159.6620	-2.422977
41.20717	159.6624	-2.423169
41.25717	159.6620	-2.423345
41.30883	159.6621	-2.423472
41.36050	159.6626	-2.423610
41.41050	159.6617	-2.423710
41.46216	159.6621	-2.423706
41.51383	159.6630	-2.423740
41.56383	159.6617	-2.423696
41.61716	159.6616	-2.423758
41.66716	159.6615	-2.423767
41.71884	159.6614	-2.423645
41.77050	159.6620	-2.423590
41.82050	159.6614	-2.423474
41.87216	159.6612	-2.423396
41.92383	159.6620	-2.423516
41.97383	159.6616	-2.423655
42.02716	159.6619	-2.423867
42.07717	159.6620	-2.424094
42.12883	159.6620	-2.424322
42.18050	159.6622	-2.424644
42.23050	159.6625	-2.424869
42.28383	159.6626	-2.425083
42.33383	159.6622	-2.425292
42.38383	159.6622	-2.425446
42.43716	159.6628	-2.425590
42.48717	159.6631	-2.425708
42.53883	159.6624	-2.425743
42.59050	159.6634	-2.425885
42.64050	159.6628	-2.426046
42.69383	159.6622	-2.426088
42.74383	159.6618	-2.426179
42.79383	159.6622	-2.426240
42.84716	159.6628	-2.426314
42.89717	159.6624	-2.426355
42.94883	159.6625	-2.426281
-2.000000	2.000000	0.0000000
43.05050	159.6821	-2.970705
43.10050	159.9099	-6.368922
43.15050	160.3546	-9.736024
43.20383	160.9821	-12.68840
43.25383	161.6808	-14.79742
43.30550	162.4788	-16.42818
43.35717	163.3366	-17.65171
43.40717	164.2040	-18.53557
43.46050	165.1633	-19.24755
43.51050	166.0822	-19.74574
43.56050	167.0186	-20.13908
43.61383	168.0302	-20.46819
43.66383	168.9869	-20.72203
43.71550	169.9825	-20.93787
43.76717	170.9822	-21.13960
43.81717	171.9532	-21.31928
43.87050	172.9928	-21.49276
43.92050	173.9706	-21.63423
43.97050	174.9495	-21.79189
44.02383	175.9965	-21.94330
44.07383	176.9782	-22.08032
44.12550	177.9941	-22.23870
44.17717	179.0107	-22.40839
44.22717	179.9935	-22.57408
44.28050	181.0431	-22.76598
44.33050	182.0271	-22.96758
44.38050	183.0115	-23.17959
44.43383	184.0608	-23.41498
44.48383	185.0451	-23.65748
44.53550	186.0612	-23.92034
44.58716	187.0760	-24.21332
44.63716	188.0566	-24.51912
44.69050	189.1027	-24.88346
44.74050	190.0792	-25.24660
44.79050	191.0556	-25.64928
44.84384	192.0951	-26.13066
44.89383	193.0668	-26.60425
44.94550	194.0717	-27.03815
44.99716	195.0744	-27.56241
45.04716	196.0425	-28.16508
45.10050	197.0692	-28.88893
45.15050	198.0282	-29.64130
45.20050	198.9821	-30.48321
45.25383	199.9939	-31.47982
45.30383	200.9376	-32.57825
45.35550	201.9022	-33.93922
45.40717	202.8546	-35.54007
45.45717	203.7647	-37.25900
45.51050	204.7226	-39.28642
45.56050	205.6125	-41.22369
45.61217	206.5279	-43.21717
45.66383	207.4425	-45.16934
45.71383	208.3286	-47.05266
45.76550	209.2452	-48.97720
45.81717	210.1635	-50.85447
45.86716	211.0555	-52.61300
45.92050	212.0083	-54.49736
45.97050	212.9036	-56.22951
46.02217	213.8335	-57.77474
46.07383	214.7807	-58.58124
46.12383	215.7543	-57.18502
46.17550	216.8993	-51.53467
46.22717	218.2283	-43.19221
46.27716	219.6020	-36.90195
46.33050	221.0110	-33.14438
46.38050	222.2493	-30.77045
46.43217	223.4653	-28.99146
46.48383	224.6315	-27.68919
46.53383	225.7243	-26.77592
46.58550	226.8285	-26.09029
46.63716	227.9123	-25.59965
46.68716	228.9481	-25.26666
46.74050	230.0430	-25.02319
46.79050	231.0620	-24.84936
46.84217	232.1088	-24.74468
46.89383	233.1523	-24.67249
46.94383	234.1584	-24.62895
46.99550	235.1965	-24.61200
47.04716	236.2320	-24.60123
47.09716	237.2337	-24.59870
47.15050	238.3006	-24.59835
47.20050	239.3013	-24.59904
47.25217	240.3338	-24.60344
47.30383	241.3657	-24.61660
47.35383	242.3652	-24.64228
47.40550	243.3970	-24.67034
47.45717	244.4292	-24.70451
47.50717	245.4277	-24.73666
47.56050	246.4922	-24.79682
47.61050	247.4903	-24.82422
47.66217	248.5219	-24.85869
47.71383	249.5544	-24.89622
47.76383	250.5538	-24.93193
47.81717	251.6189	-24.97404
47.86716	252.6175	-25.00686
47.91716	253.6160	-25.03939
47.97050	254.6804	-25.08015
48.02050	255.6773	-25.45656
48.07217	256.6986	-25.57407
48.12383	257.7275	-25.54713
48.17383	258.7262	-25.53547
48.22717	259.7934	-25.53390
48.27716	260.7942	-25.53367
48.32717	261.7910	-25.53521
48.38050	262.8574	-25.54782
48.43050	263.8563	-25.56864
48.48217	264.8874	-25.59711
48.53383	265.9194	-25.63472
48.58383	266.9185	-25.66568
48.63716	267.9827	-25.69360
48.68716	268.9810	-25.72616
48.73717	269.9800	-25.76751
48.79050	271.0446	-25.79612
48.84050	272.0429	-25.82240
48.89217	273.0748	-25.85113
48.94383	274.1064	-25.88020
48.99383	275.1050	-25.89320
49.04550	276.0995	-26.50228
49.09716	276.5911	-24.17262
49.14717	276.6180	-16.91027
49.19883	276.3694	-9.660301
49.25050	275.9215	-3.685790
49.30050	275.3539	0.8023332
49.35383	274.6389	4.420512
49.40383	273.8945	6.956088
49.45550	273.0680	8.922722
49.50717	272.1990	10.38278
49.55717	271.3249	11.44983
49.60883	270.3990	12.26992
49.66050	269.4541	12.89786
49.71050	268.5262	13.35768
49.76383	267.5239	13.74058
49.81383	266.5774	14.01449
49.86550	265.5877	14.24350
49.91716	264.5938	14.41025
49.96717	263.6266	14.55376
50.01883	262.6250	14.66086
50.07050	261.6183	14.75245
50.12050	260.6433	14.82244
50.17383	259.5990	14.88629
50.22383	258.6192	14.93678
50.27550	257.6047	14.98491
50.32717	256.5905	15.02240
50.37717	255.6056	15.06335
50.42883	254.5882	15.09723
50.48050	253.5704	15.13413
50.53050	252.5840	15.16856
50.58383	251.5302	15.20056
50.63383	250.5430	15.22725
50.68550	249.5219	15.25323
50.73717	248.5003	15.28129
50.78717	247.5098	15.30086
50.83883	246.4868	15.31921
50.89050	245.4628	15.33425
50.94050	244.4724	15.34922
50.99383	243.4149	15.36011
51.04383	242.4235	15.36844
51.09550	241.3994	15.37661
51.14717	240.3744	15.38570
51.19717	239.3823	15.39458
51.25050	238.3237	15.40285
51.30050	237.3316	15.41444
51.35050	236.3396	15.42403
51.40383	235.2805	15.43333
51.45383	234.2882	15.44156
51.50550	233.2623	15.45085
51.55717	232.2364	15.45874
51.60717	231.2444	15.46642
51.66050	230.1828	15.47786
51.71050	229.1910	15.48573
51.76050	228.1973	15.49505
51.81383	227.1373	15.50539
51.86383	226.1426	15.51395
51.91550	225.1164	15.52364
51.96717	224.0885	15.53271
52.01716	223.0954	15.54089
52.07050	222.0353	15.54956
52.12050	221.0420	15.55815
52.17050	220.0480	15.56647
52.22383	218.9879	15.57537
52.27383	217.9948	15.58367
52.32550	216.9679	15.59216
52.37717	215.9414	15.60153
52.42717	214.9482	15.61139
52.48050	213.8892	15.62091
52.53050	212.8956	15.63024
52.58050	211.9022	15.63920
52.63383	210.8419	15.64923
52.68383	209.8484	15.65900
52.73550	208.8212	15.66925
52.78716	207.7940	15.67875
52.83716	206.8005	15.68779
52.89050	205.7389	15.69715
52.94050	204.7439	15.70589
52.99050	203.7494	15.71432
53.04382	202.6878	15.72308
53.09384	201.6938	15.73075
53.14550	200.6660	15.73883
53.19717	199.6396	15.74689
53.24717	198.6447	15.75466
53.30050	197.5844	15.76289
53.35050	196.5896	15.77058
53.40050	195.5950	15.77849
53.45383	194.5348	15.78789
53.50383	193.5402	15.79570
53.55550	192.5121	15.80361
53.60717	191.4838	15.81163
53.65717	190.4894	15.81913
53.71050	189.4289	15.82704
53.76050	188.4341	15.83434
53.81216	187.4061	15.84157
53.86382	186.3776	15.84879
53.91382	185.3836	15.85547
53.96550	184.3553	15.86219
54.01716	183.3277	15.86858
54.06716	182.3329	15.87483
54.12050	181.2714	15.88147
54.17050	180.2784	15.88759
54.22217	179.2503	15.89492
54.27383	178.2233	15.90353
54.32383	177.2291	15.91237
54.37550	176.2009	15.92313
54.42717	175.1732	15.93221
54.47717	174.1780	15.94119
54.53050	173.1172	15.95415
54.58050	172.1215	15.97235
54.63217	171.0945	16.02432
54.68383	170.0712	16.19008
54.73383	169.0835	16.45916
54.78550	168.0686	16.83186
54.83716	167.0642	17.41234
54.88716	166.1051	18.28392
54.94050	165.1049	19.66991
54.99050	164.1943	21.46482
55.04217	163.2833	23.84150
55.09384	162.4047	26.65886
55.14384	161.5785	29.63078
55.19550	160.7406	32.66500
55.24717	159.9012	35.36963
55.29717	159.0713	37.45211
55.35050	158.1532	38.94884
55.40050	157.2547	39.63120
55.45216	156.2800	39.63180
55.50383	155.2627	39.20257
55.55383	154.2407	37.94939
55.60550	153.1531	36.53928
55.65717	152.0429	34.96390
55.70717	150.9556	33.36124
55.76050	149.7876	31.67563
55.81050	148.6886	30.01464
55.86217	147.5502	28.34447
55.91382	146.4169	26.88036
55.96382	145.3275	25.59679
56.01716	144.1738	24.36320
56.06716	143.1020	23.34750
56.11716	142.0377	22.45720
56.17050	140.9120	21.63282
56.22050	139.8632	20.98197
56.27217	138.7846	20.24482
56.32383	137.7094	19.69382
56.37383	136.6772	19.24936
56.42717	135.5838	18.87753
56.47717	134.5626	18.58744
56.52717	133.5480	18.35864
56.58050	132.4677	18.15352
56.63050	131.4583	17.99594
56.68217	130.4184	17.85119
56.73383	129.3794	17.74330
56.78383	128.3769	17.63759
56.83716	127.3069	17.55886
56.88716	126.3056	17.46574
56.93716	125.3044	17.40021
56.99050	124.2370	17.32524
57.04050	123.2368	17.25892
57.09217	122.2038	17.20259
57.14384	121.1719	17.14206
57.19384	120.1719	17.09091
57.24717	119.1067	17.03629
57.29717	118.1072	16.99192
57.34716	117.1086	16.95520
57.40050	116.0438	16.91563
57.45050	115.0439	16.82939
57.50217	114.0091	16.68514
57.55383	112.9741	16.60912
57.60383	111.9728	16.55126
57.65717	110.9035	16.39964
57.70717	109.9006	16.32074
57.75717	108.8994	16.24525
57.81050	107.8317	16.17980
57.86050	106.8319	16.11762
57.91216	105.7986	16.05810
57.96382	104.7655	16.00550
58.01382	103.7654	15.95112
58.06716	102.6995	15.89584
58.11716	101.6996	15.84441
58.16716	100.7008	15.79049
58.22050	99.63488	15.73640
58.27050	98.63541	15.68978
58.32217	97.60289	15.65013
58.37383	96.57028	15.59911
58.42383	95.57130	15.55375
58.47717	94.50592	15.50356
58.52717	93.50669	15.45628
58.57883	92.47355	15.40646
58.63050	91.44110	15.35560
58.68050	90.44218	15.31049
58.73217	89.41005	15.25886
58.78383	88.37799	15.21648
58.83383	87.37912	15.17732
58.88716	86.31336	15.12680
58.93716	85.31461	15.08750
58.98882	84.28336	15.04456
59.04050	83.25042	15.00417
59.09050	82.25128	14.95575
59.14216	81.21954	14.90656
59.19384	80.18774	14.86366
59.24382	79.18790	14.82185
59.29717	78.12188	14.77562
59.34716	77.12306	14.73002
59.39883	76.08970	14.68704
59.45050	75.05806	14.63600
59.50050	74.05847	14.60261
59.55217	73.02641	14.55787
59.60383	71.99484	14.51127
59.65383	70.99568	14.46784
59.70717	69.93086	14.41955
59.75717	68.93085	14.37807
59.80883	67.89756	14.33460
59.86050	66.86469	14.27942
59.91050	65.86592	14.23899
59.96216	64.83362	14.19457
60.01382	63.80051	14.14658
60.06382	62.80206	14.09517
60.11716	61.73526	14.04365
60.16716	60.73700	13.99425
60.21884	59.70498	13.94719
60.27050	58.67224	13.90321
60.32050	57.67228	13.85634
60.37217	56.64082	13.81016
60.42383	55.60768	13.76364
60.47382	54.61044	13.71989
60.52717	53.54326	13.67276
60.57717	52.54310	13.62729
60.62883	51.51024	13.58084
60.68050	50.47743	13.52635
60.73050	49.47860	13.48375
60.78383	48.41122	13.43482
60.83383	47.41261	13.38213
60.88383	46.41400	13.34363
60.93716	45.34746	13.29198
60.98717	44.34826	13.25173
61.03882	43.31470	13.20383
61.09050	42.28184	13.15494
61.14050	41.28217	13.11586
61.19384	40.21602	13.05944
61.24382	39.21605	13.00774
61.29382	38.21700	12.94569
61.34716	37.14998	12.89050
61.39717	36.14960	12.85020
61.44883	35.11592	12.77069
61.50050	34.08096	12.69486
61.55050	33.08067	12.63694
61.60383	32.01205	12.56496
61.65383	31.01150	12.49721
61.70383	30.01055	12.43376
61.75717	28.94185	12.36070
61.80717	27.94022	12.28451
61.85883	26.90528	12.21465
61.91050	25.86961	12.14053
61.96050	24.86782	12.10094
62.01050	23.86594	12.10265
62.06050	22.96037	12.51062
62.11217	22.56818	8.115761
62.16382	22.56564	3.169592
62.21382	22.83242	-0.6814202
62.26716	23.32352	-3.642873
62.31716	23.92670	-5.677735
62.36716	24.62590	-7.162290
62.42050	25.45170	-8.334328
62.47050	26.27777	-9.153926
62.52217	27.17069	-9.792637
62.57383	28.09411	-10.29146
62.62383	29.00781	-10.65048
62.67717	29.99945	-10.95954
62.72717	30.94048	-11.18665
62.77883	31.92289	-11.38934
62.83050	32.91170	-11.54938
62.88050	33.87536	-11.68364
62.93217	34.87574	-11.79591
62.98383	35.87930	-11.90003
63.03383	36.85234	-11.99411
63.08716	37.89336	-12.08165
63.13716	38.87178	-12.15995
63.18882	39.88300	-12.23750
63.24050	40.89804	-12.31300
63.29050	41.88045	-12.37366
63.34217	42.89760	-12.44940
63.39384	43.91542	-12.53306
63.44384	44.90198	-12.58416
63.49717	45.95498	-12.64624
63.54717	46.94295	-12.71082
63.59882	47.96437	-12.78902
63.65050	48.98662	-12.84825
63.70050	49.97514	-12.91791
63.75217	50.99744	-12.99874
63.80383	52.02006	-13.06468
63.85383	53.01175	-13.13354
63.90718	54.06865	-13.20713
63.95717	55.06100	-13.26960
64.00884	56.08655	-13.33419
64.06050	57.11124	-13.40662
64.11050	58.10432	-13.47494
64.16217	59.13026	-13.54485
64.21384	60.15666	-13.61350
64.26384	61.14913	-13.68801
64.31717	62.20972	-13.76328
64.36718	63.20293	-13.83493
64.41884	64.22990	-13.89736
64.47050	65.25742	-13.97162
64.52050	66.25012	-14.04538
64.57218	67.27728	-14.12462
64.62383	68.30484	-14.19972
64.67383	69.29824	-14.27814
64.72718	70.35978	-14.35450
64.77717	71.35388	-14.42368
64.82885	72.38286	-14.50380
64.88050	73.40951	-14.58105
64.93050	74.40561	-14.65932
64.98383	75.46632	-14.73639
65.03384	76.46125	-14.81754
65.08384	77.45606	-14.89346
65.13717	78.51788	-14.98359
65.18717	79.51166	-15.06399
65.23882	80.53993	-15.15059
65.29050	81.56796	-15.23530
65.34050	82.56314	-15.31650
65.39384	83.62406	-15.40543
65.44384	84.61870	-15.49173
65.49384	85.61378	-15.57840
65.54718	86.67447	-15.66606
65.59718	87.66901	-15.76009
65.64884	88.69784	-15.85339
65.70050	89.72464	-15.95159
65.75050	90.72094	-16.03554
65.80384	91.78238	-16.12738
65.85384	92.77801	-16.21770
65.90384	93.77247	-16.29923
65.95718	94.83369	-16.40047
66.00718	95.82799	-16.49594
66.05884	96.85626	-16.61041
66.11050	97.88370	-16.68774
66.16050	98.87962	-16.78198
66.21384	99.93988	-16.87818
66.26384	100.9339	-16.97470
66.31384	101.9288	-17.07812
66.36718	102.9900	-17.16804
66.41718	103.9842	-17.27828
66.46884	105.0117	-17.38083
66.52050	106.0392	-17.48358
66.57050	107.0327	-17.58873
66.62384	108.0934	-17.70265
66.67384	109.0877	-17.79799
66.72384	110.0819	-17.90170
66.77718	111.1445	-17.97441
66.82718	112.1403	-18.03012
66.87884	113.1763	-18.08634
66.93050	114.2026	-18.17452
66.98050	115.1987	-18.25381
67.03384	116.2617	-18.32288
67.08384	117.2586	-18.40506
67.13384	118.2546	-18.52056
67.18718	119.3147	-18.60578
67.23718	120.3095	-18.70525
67.28882	121.3378	-18.81960
67.34050	122.3631	-18.93088
67.39050	123.3562	-19.06266
67.44384	124.4160	-19.18416
67.49384	125.4082	-19.29902
67.54550	126.4375	-19.34985
67.59718	127.4702	-19.34028
67.64718	128.4685	-19.35535
67.69884	129.4989	-19.42244
67.75050	130.5286	-19.54185
67.80050	131.5245	-19.64700
67.85384	132.5854	-19.74784
67.90384	133.5794	-19.86795
67.95550	134.6072	-19.95824
68.00718	135.6372	-19.97937
68.05718	136.6346	-20.05218
68.10884	137.6620	-20.14726
68.16050	138.6922	-20.21832
68.21050	139.6887	-20.26689
68.26384	140.7549	-20.27410
68.31384	141.7532	-20.29894
68.36550	142.7854	-20.36620
68.41718	143.8158	-20.43778
68.46718	144.8131	-20.51186
68.51882	145.8423	-20.58695
68.57050	146.8716	-20.69450
68.62050	147.8681	-20.77446
68.67384	148.9297	-20.86846
68.72384	149.9258	-20.95138
68.77550	150.9548	-21.03914
68.82718	151.9824	-21.12870
68.87718	152.9787	-21.22197
68.92884	154.0080	-21.30568
68.98050	155.0358	-21.39190
69.03050	156.0318	-21.50121
69.08384	157.0934	-21.61696
69.13384	158.0870	-21.72670
69.18550	159.1152	-21.83369
69.23718	160.1428	-21.91435
69.28718	161.1388	-22.00385
69.33884	162.1675	-22.06104
69.39050	163.1980	-22.11718
69.44050	164.1960	-22.15493
69.49384	165.2621	-22.19152
69.54384	166.2613	-22.21924
69.59550	167.2930	-22.24979
69.64718	168.3242	-22.28705
69.69718	169.3230	-22.34469
69.75050	170.3857	-22.42981
69.80050	171.3835	-22.52192
69.85050	172.3800	-22.62594
69.90384	173.4429	-22.73010
69.95384	174.4370	-22.84409
70.00550	175.4646	-22.96993
70.05718	176.4915	-23.12315
70.10718	177.4823	-23.27035
70.16050	178.5398	-23.47037
70.21050	179.5310	-23.66346
70.26050	180.5204	-23.87160
70.31384	181.5733	-24.13748
70.36384	182.5604	-24.40277
70.41550	183.5781	-24.71214
70.46718	184.5942	-25.04898
70.51716	185.5750	-25.40332
70.57050	186.6204	-25.82284
70.62050	187.5973	-26.26976
70.67050	188.5720	-26.72954
70.72384	189.6092	-27.29479
70.77384	190.5788	-27.85227
70.82550	191.5779	-28.47889
70.87718	192.5755	-29.12432
70.92718	193.5382	-29.77050
70.98050	194.5649	-30.47661
71.03050	195.5248	-31.17443
71.08050	196.4830	-31.91328
71.13384	197.5035	-32.76128
71.18384	198.4559	-33.63586
71.23550	199.4364	-34.62604
71.28718	200.4111	-35.68898
71.33716	201.3526	-36.77542
71.39050	202.3516	-37.94222
71.44050	203.2880	-39.01412
71.49050	204.2263	-39.97258
71.54384	205.2341	-40.73150
71.59384	206.1948	-40.97026
71.64550	207.2165	-40.60775
71.69718	208.2829	-38.73112
71.74718	209.3741	-35.95197
71.80050	210.5983	-32.32068
71.85050	211.7734	-29.33322
71.90050	212.9349	-27.35640
71.95384	214.1349	-26.02304
72.00384	215.2277	-25.15004
72.05550	216.3309	-24.51080
72.10718	217.4148	-24.03746
72.15718	218.4514	-23.71642
72.21050	219.5450	-23.47078
72.26050	220.5639	-23.32912
72.31216	221.6105	-23.21918
72.36384	222.6536	-23.15078
72.41382	223.6598	-23.11694
72.46550	224.6982	-23.09546
72.51716	225.7345	-23.08486
72.56718	226.7372	-23.08357
72.62050	227.8047	-23.08324
72.67050	228.8048	-23.08419
72.72218	229.8376	-23.09274
72.77384	230.8710	-23.10908
72.82384	231.8702	-23.13683
72.87550	232.9016	-23.17427
72.92718	233.9338	-23.21256
72.97718	234.9316	-23.25199
73.03050	235.9968	-23.29644
73.08050	236.9957	-23.34372
73.13218	238.0265	-23.38276
73.18384	239.0586	-23.42865
73.23384	240.0567	-23.47370
73.28550	241.0885	-23.52662
73.33716	242.1206	-23.57355
73.38718	243.1187	-23.61721
73.44050	244.1854	-23.65226
73.49050	245.1836	-23.68852
73.54218	246.2165	-23.72592
73.59384	247.2482	-23.76187
73.64384	248.2469	-23.79765
73.69550	249.2788	-23.83547
73.74718	250.3096	-23.87324
73.79718	251.3090	-23.92504
73.85050	252.3743	-23.96396
73.90050	253.3725	-24.00847
73.95216	254.4045	-24.04450
74.00384	255.4361	-24.08696
74.05384	256.4347	-24.13674
74.10550	257.4656	-24.17872
74.15718	258.4966	-24.23330
74.20718	259.4956	-24.28188
74.26050	260.5604	-24.33222
74.31050	261.5583	-24.37431
74.36218	262.5897	-24.43566
74.41382	263.6211	-24.47412
74.46384	264.6196	-24.51972
74.51716	265.6836	-24.56740
74.56718	266.6826	-24.61482
74.61718	267.6796	-24.66247
74.67050	268.7446	-24.72217
74.72050	269.7424	-24.76401
74.77218	270.7737	-24.80374
74.82384	271.8052	-24.84802
-2.000000	5.000000	0.0000000