File: 7-C1(1.2mol%)+C20(0.6mol%)(1)/matlab/170-2.txt
CLOSED
Version	1.0
Language	English
Mode	Standard
Run	2
RunSerial	12304
Instrument	DSC Q2000 V24.11 Build 124
Module	DSC Standard Cell RC
Operator
File	\\AE520-1454\Users\dsc\Desktop\Data\29-08-17-3\170-2.001
ProcName
InstSerial	2000-0883
AutoSerial	1293
Sample	170-2
Size	13.0000	mg
PanMass	Not available
PanResist	Automatic Automatic  K/W
PanFactor	Default Default
Method
Comment
Xcomment	Pan: Tzero Aluminum Hermetic
Xcomment	Gas1: Nitrogen 50.0 ml/min
Xcomment	Gas2: Nitrogen 50.0 ml/min
Text
Exotherm	UP
Kcell	1.05230
Cpconst	Standard: 0.938
Calib	-38.6961
TempCal	1	pts	157.46	156.60
TzeroDt	-87.6168 -0.0009 -1.4231
TzeroDtz	-87.6168 0.0057 6.9570
InstCalFile	Tzero: \\Ae520-1454\ta\Data\DSC\Calibration\2017\CALIBRATION\1562_RCS (90)_05_18_2017 10_50_44.TZR
InstCalFile	Baseline: \\Ae520-1454\ta\Data\DSC\Calibration\2017\2017-05-17_Calibration.001
InstCalFile	Sapphire: \\Ae520-1454\ta\Data\DSC\Calibration\2017\2017-05-17_Saphire.001
InstCalDate	Tzero 2017-05-18 Time 10:50:44
TempRange	-87.39 to 398.39 °C at 10.00 °C/min Heat Only
AutoZero	Delta T Offset 0.000 uV
AutoZero	Delta T0 Offset 0.000 uV
MultiptCal	0
MultiPtDesc	0) Not set
AutoCellConst	Calibration Date 2017-05-18 16:59:28
Controls	Gas 1  Event Off  Sampling 0.2
Cell#	RC-01562
CoolingUnit	RCS (90)
SelHeatFlow	Heat Flow T4P (mW)
AutoLidII	Installed
AutoAnalysis	Off
MacroFile
Nsig	3
Sig1	Time (min)
Sig2	Temperature (°C)
Sig3	Heat Flow (mW)
Date	2017-08-31
Time	11:03:48
OrgMethod	1: Equilibrate at 80.00 °C
OrgMethod	2: Isothermal for 3.00 min
OrgMethod	3: Jump to 170.00 °C
OrgMethod	4: Mark end of cycle 1
OrgMethod	5: Isothermal for 40.00 min
OrgMethod	6: Mark end of cycle 2
OrgMethod	7: Ramp 20.00 °C/min to 280.00 °C
OrgMethod	8: Mark end of cycle 3
OrgMethod	9: Ramp 20.00 °C/min to 20.00 °C
OrgMethod	10: Mark end of cycle 4
OrgMethod	11: Ramp 20.00 °C/min to 280.00 °C
OrgMethod	12: Mark end of cycle 5
OrgFile	C:\Users\jarra\Desktop\DSC\7-C1(1.2mol%)+C20(0.6mol%)(1)\170-2.001
StartOfData
4.99994E-4	79.92764	-0.6676142
0.05383332	79.92695	-0.6388004
0.1038333	79.92345	-0.6248241
0.1538333	79.92245	-0.6178933
0.2055000	79.91916	-0.6147260
0.2571667	79.91756	-0.6130816
0.3071666	79.91458	-0.6115152
0.3571666	79.91205	-0.6101925
0.4105000	79.91048	-0.6090346
0.4605000	79.90824	-0.6081810
0.5105000	79.90695	-0.6075935
0.5621668	79.90544	-0.6072352
0.6138334	79.90387	-0.6070132
0.6638332	79.90234	-0.6070600
0.7138332	79.90056	-0.6072506
0.7655000	79.89955	-0.6076841
0.8171668	79.89868	-0.6082378
0.8671666	79.89725	-0.6089535
0.9171668	79.89636	-0.6098362
0.9705000	79.89538	-0.6108457
1.020500	79.89472	-0.6119175
1.070500	79.89355	-0.6130812
1.122166	79.89259	-0.6143455
1.173834	79.89163	-0.6156661
1.223833	79.89093	-0.6169202
1.273834	79.88997	-0.6181716
1.325500	79.88950	-0.6196160
1.377166	79.88876	-0.6209507
1.427167	79.88842	-0.6223412
1.477166	79.88746	-0.6237019
1.530500	79.88645	-0.6252832
1.580500	79.88611	-0.6267384
1.630500	79.88575	-0.6282370
1.682167	79.88412	-0.6297839
1.733833	79.88453	-0.6313832
1.783833	79.88400	-0.6329547
1.833833	79.88303	-0.6344774
1.885500	79.88203	-0.6360210
1.937166	79.88228	-0.6375584
1.987166	79.88160	-0.6390362
2.037166	79.88062	-0.6404768
2.090500	79.87982	-0.6420274
2.140500	79.87942	-0.6434861
2.190500	79.87924	-0.6449130
2.242166	79.87808	-0.6463985
2.293833	79.87806	-0.6479541
2.343834	79.87818	-0.6494556
2.393833	79.87684	-0.6509394
2.447166	79.87610	-0.6524711
2.497166	79.87574	-0.6539232
2.547166	79.87515	-0.6553191
2.598834	79.87493	-0.6567172
2.650500	79.87468	-0.6581257
2.700500	79.87424	-0.6594572
2.750500	79.87225	-0.6607310
2.802166	79.87344	-0.6622250
2.853833	79.87235	-0.6636087
2.903833	79.87280	-0.6649824
2.953833	79.87222	-0.6663532
3.000500	79.87175	-0.6676242
3.053833	80.24759	-7.824889
3.103833	82.16242	-20.81752
3.153833	84.90009	-29.30090
3.205500	88.30769	-36.49803
3.257167	92.12814	-42.01154
3.307167	96.09788	-46.05802
3.357167	100.2523	-49.10902
3.410500	104.8179	-51.50400
3.460500	109.1808	-53.15253
3.510500	113.5895	-54.36928
3.562167	118.1698	-55.34724
3.613834	122.7611	-56.12255
3.663833	127.2091	-56.60826
3.713833	131.6555	-56.92481
3.765500	136.2450	-57.10515
3.817166	140.8232	-57.14348
3.867166	145.2460	-57.06934
3.917167	149.6538	-56.79001
3.970500	154.3211	-56.46379
4.020500	158.2907	-50.55728
4.070500	160.9999	-38.89317
4.122166	162.9648	-29.81265
4.173834	164.3644	-22.22417
4.223834	165.3536	-16.64461
4.273834	166.0944	-12.41182
4.325500	166.6756	-9.216031
4.377167	167.1247	-6.918910
4.427166	167.4703	-5.332222
4.477167	167.7501	-4.201991
4.530500	167.9956	-3.366226
4.580500	168.1883	-2.818113
4.630500	168.3527	-2.438240
4.682167	168.5005	-2.152346
4.733834	168.6291	-1.951309
4.783834	168.7386	-1.805791
4.833834	168.8342	-1.692380
4.885500	168.9241	-1.591696
4.937167	169.0041	-1.505262
4.987167	169.0730	-1.428509
5.037167	169.1352	-1.351492
5.090500	169.1958	-1.268064
5.140500	169.2466	-1.186885
5.190500	169.2938	-1.102354
5.242167	169.3372	-1.010237
5.293832	169.3780	-0.9157939
5.343834	169.4138	-0.8155170
5.393832	169.4471	-0.7109558
5.447168	169.4797	-0.5949482
5.497168	169.5083	-0.4790150
5.547168	169.5359	-0.3614072
5.598832	169.5616	-0.2286045
5.650500	169.5876	-.09145486
5.700500	169.6106	0.04681038
5.750500	169.6319	0.1933866
5.802168	169.6542	0.3509331
5.853832	169.6759	0.5169334
5.903834	169.6947	0.6874692
5.953832	169.7149	0.8582228
6.007168	169.7364	1.052688
6.057168	169.7545	1.240030
6.107168	169.7744	1.434681
6.158832	169.7937	1.643968
6.210500	169.8134	1.853332
6.260500	169.8314	2.066427
6.310500	169.8485	2.284248
6.362168	169.8676	2.506735
6.413832	169.8858	2.732440
6.463834	169.9026	2.951832
6.513834	169.9201	3.161906
6.567168	169.9386	3.384689
6.617166	169.9538	3.589086
6.667168	169.9676	3.777618
6.718832	169.9830	3.961217
6.770500	169.9956	4.126519
6.820500	170.0076	4.266964
6.870500	170.0184	4.387552
6.922168	170.0278	4.491864
6.973834	170.0348	4.572246
7.023834	170.0398	4.622170
7.073834	170.0450	4.654268
7.127168	170.0468	4.669469
7.177168	170.0488	4.672688
7.227168	170.0480	4.672776
7.278832	170.0475	4.668974
7.330500	170.0453	4.647085
7.380500	170.0435	4.597198
7.430500	170.0410	4.528988
7.483832	170.0382	4.453388
7.533832	170.0348	4.387516
7.583832	170.0317	4.330816
7.635500	170.0291	4.280548
7.687168	170.0289	4.238462
7.737168	170.0284	4.213452
7.787168	170.0266	4.199258
7.838834	170.0282	4.195086
7.890500	170.0302	4.193718
7.940500	170.0328	4.195352
7.990500	170.0379	4.215805
8.043834	170.0437	4.292504
8.093832	170.0487	4.397150
8.143832	170.0551	4.511834
8.195500	170.0631	4.634220
8.247168	170.0715	4.764472
8.297168	170.0808	4.890137
8.347168	170.0882	5.018928
8.398834	170.0973	5.144262
8.450500	170.1058	5.266693
8.500500	170.1123	5.374218
8.550500	170.1188	5.466757
8.603832	170.1255	5.554093
8.653832	170.1295	5.616674
8.703834	170.1330	5.661749
8.755500	170.1353	5.692960
8.807168	170.1375	5.707795
8.857166	170.1374	5.712198
8.907166	170.1360	5.713272
8.958832	170.1348	5.712101
9.010499	170.1320	5.698132
9.060500	170.1294	5.657252
9.110500	170.1255	5.585316
9.163834	170.1212	5.494207
9.213834	170.1171	5.408002
9.263832	170.1108	5.317695
9.315500	170.1061	5.221502
9.367166	170.1009	5.124750
9.417168	170.0947	5.028633
9.467168	170.0882	4.932926
9.520500	170.0821	4.827420
9.570500	170.0751	4.732239
9.620499	170.0698	4.632444
9.672168	170.0644	4.529680
9.723832	170.0590	4.429519
9.773834	170.0519	4.331932
9.823834	170.0465	4.234508
9.875500	170.0398	4.136422
9.927168	170.0339	4.039708
9.977168	170.0279	3.951103
10.02717	170.0226	3.859650
10.08050	170.0166	3.767441
10.13050	170.0111	3.687047
10.18050	170.0062	3.606018
10.23217	170.0010	3.530979
10.28383	169.9959	3.455217
10.33383	169.9920	3.384011
10.38383	169.9890	3.322058
10.43550	169.9836	3.259867
10.48717	169.9804	3.202029
10.53717	169.9770	3.151350
10.58717	169.9738	3.103903
10.64050	169.9721	3.057622
10.69050	169.9691	3.020655
10.74050	169.9674	2.985030
10.79217	169.9641	2.955031
10.84383	169.9620	2.926060
10.89383	169.9613	2.902118
10.94383	169.9594	2.881470
10.99550	169.9580	2.862730
11.04717	169.9561	2.847728
11.09717	169.9556	2.833345
11.14717	169.9546	2.822692
11.20050	169.9536	2.812260
11.25050	169.9531	2.804284
11.30050	169.9525	2.798358
11.35217	169.9513	2.792234
11.40383	169.9515	2.786068
11.45384	169.9508	2.779984
11.50384	169.9501	2.773797
11.55717	169.9504	2.766954
11.60717	169.9490	2.760449
11.65717	169.9498	2.753751
11.70883	169.9479	2.746706
11.76050	169.9478	2.739354
11.81050	169.9467	2.731322
11.86050	169.9464	2.720630
11.91217	169.9454	2.705699
11.96383	169.9439	2.683950
12.01383	169.9430	2.655029
12.06383	169.9413	2.614619
12.11716	169.9384	2.566644
12.16717	169.9369	2.511813
12.21717	169.9336	2.450137
12.26883	169.9309	2.377365
12.32050	169.9268	2.307111
12.37050	169.9243	2.232500
12.42050	169.9194	2.159587
12.47217	169.9155	2.077559
12.52383	169.9094	1.989656
12.57383	169.9044	1.899639
12.62383	169.8984	1.805978
12.67717	169.8918	1.699915
12.72717	169.8862	1.598523
12.77717	169.8785	1.488556
12.82883	169.8723	1.371409
12.88050	169.8632	1.256278
12.93050	169.8565	1.135644
12.98050	169.8498	1.013248
13.03217	169.8406	0.8882584
13.08383	169.8322	0.7574864
13.13383	169.8238	0.6314402
13.18383	169.8149	0.5011930
13.23716	169.8060	0.3627550
13.28717	169.7975	0.2310719
13.33717	169.7886	0.09831391
13.38883	169.7801	-.03724309
13.44050	169.7713	-0.1745690
13.49050	169.7631	-0.3025607
13.54050	169.7551	-0.4277934
13.59383	169.7460	-0.5643826
13.64383	169.7386	-0.6810626
13.69384	169.7308	-0.7998144
13.74550	169.7234	-0.9128090
13.79717	169.7164	-1.025301
13.84717	169.7101	-1.128348
13.89717	169.7030	-1.221610
13.94884	169.6972	-1.318881
14.00050	169.6914	-1.408528
14.05050	169.6866	-1.486241
14.10050	169.6811	-1.559584
14.15383	169.6760	-1.633066
14.20383	169.6720	-1.699349
14.25383	169.6674	-1.755331
14.30550	169.6642	-1.810064
14.35716	169.6613	-1.858006
14.40717	169.6589	-1.900340
14.45717	169.6554	-1.936266
14.50883	169.6532	-1.969951
14.56050	169.6513	-1.999288
14.61050	169.6495	-2.025545
14.66050	169.6478	-2.049506
14.71383	169.6465	-2.071522
14.76383	169.6458	-2.091459
14.81383	169.6443	-2.107156
14.86550	169.6435	-2.121383
14.91716	169.6418	-2.133683
14.96716	169.6406	-2.144832
15.01717	169.6402	-2.153339
15.06884	169.6390	-2.161928
15.12050	169.6383	-2.170005
15.17050	169.6368	-2.176610
15.22050	169.6359	-2.183536
15.27383	169.6355	-2.190632
15.32384	169.6336	-2.197451
15.37384	169.6340	-2.204490
15.42550	169.6332	-2.211846
15.47717	169.6328	-2.219320
15.52717	169.6317	-2.226648
15.57717	169.6308	-2.234052
15.63050	169.6300	-2.241914
15.68050	169.6302	-2.249384
15.73050	169.6301	-2.256756
15.78217	169.6299	-2.264475
15.83383	169.6292	-2.272062
15.88383	169.6293	-2.279477
15.93383	169.6290	-2.286861
15.98550	169.6292	-2.294354
16.03717	169.6289	-2.301764
16.08716	169.6284	-2.308813
16.13716	169.6288	-2.315830
16.19050	169.6285	-2.322992
16.24050	169.6284	-2.329596
16.29050	169.6288	-2.336089
16.34216	169.6280	-2.342545
16.39383	169.6277	-2.348875
16.44383	169.6269	-2.354852
16.49383	169.6267	-2.360746
16.54550	169.6260	-2.366582
16.59716	169.6259	-2.372382
16.64716	169.6247	-2.377792
16.69716	169.6252	-2.383092
16.75050	169.6240	-2.388640
16.80050	169.6240	-2.393788
16.85050	169.6239	-2.398775
16.90216	169.6238	-2.403948
16.95383	169.6230	-2.408887
17.00383	169.6236	-2.413640
17.05383	169.6229	-2.418282
17.10550	169.6228	-2.422984
17.15716	169.6232	-2.427544
17.20716	169.6224	-2.431825
17.25716	169.6229	-2.436225
17.31050	169.6233	-2.440705
17.36050	169.6230	-2.444925
17.41050	169.6229	-2.449038
17.46216	169.6236	-2.453275
17.51383	169.6234	-2.457302
17.56383	169.6234	-2.461164
17.61383	169.6228	-2.464873
17.66716	169.6235	-2.468721
17.71716	169.6229	-2.472133
17.76716	169.6228	-2.475544
17.81883	169.6239	-2.478960
17.87050	169.6226	-2.482236
17.92050	169.6233	-2.485315
17.97050	169.6230	-2.488302
18.02216	169.6230	-2.491312
18.07383	169.6227	-2.494274
18.12383	169.6225	-2.497144
18.17383	169.6225	-2.499860
18.22716	169.6220	-2.502611
18.27716	169.6218	-2.505155
18.32716	169.6233	-2.507620
18.37883	169.6220	-2.510055
18.43050	169.6210	-2.512462
18.48050	169.6209	-2.514760
18.53050	169.6219	-2.517144
18.58216	169.6218	-2.519521
18.63383	169.6214	-2.521650
18.68383	169.6219	-2.523786
18.73383	169.6216	-2.525787
18.78717	169.6209	-2.527861
18.83716	169.6210	-2.529780
18.88716	169.6205	-2.531663
18.93883	169.6205	-2.533520
18.99050	169.6205	-2.535358
19.04050	169.6200	-2.537048
19.09050	169.6196	-2.538790
19.14216	169.6204	-2.540486
19.19383	169.6201	-2.542134
19.24383	169.6198	-2.543652
19.29383	169.6196	-2.545182
19.34716	169.6191	-2.546770
19.39716	169.6196	-2.548263
19.44716	169.6197	-2.549723
19.49883	169.6204	-2.551301
19.55050	169.6210	-2.552916
19.60050	169.6206	-2.554468
19.65050	169.6213	-2.555932
19.70383	169.6208	-2.557369
19.75383	169.6201	-2.558762
19.80383	169.6208	-2.560085
19.85550	169.6204	-2.561384
19.90716	169.6206	-2.562731
19.95716	169.6209	-2.563926
20.00716	169.6197	-2.565043
20.05883	169.6199	-2.566170
20.11050	169.6197	-2.567213
20.16050	169.6193	-2.568247
20.21050	169.6201	-2.569284
20.26383	169.6198	-2.570444
20.31383	169.6201	-2.571522
20.36383	169.6210	-2.572660
20.41550	169.6204	-2.573797
20.46716	169.6211	-2.574844
20.51716	169.6202	-2.575754
20.56716	169.6201	-2.576616
20.61883	169.6201	-2.577399
20.67050	169.6194	-2.578158
20.72050	169.6190	-2.578919
20.77050	169.6192	-2.579648
20.82383	169.6194	-2.580532
20.87383	169.6192	-2.581299
20.92383	169.6200	-2.582174
20.97550	169.6201	-2.582974
21.02717	169.6198	-2.583798
21.07716	169.6201	-2.584558
21.12716	169.6195	-2.585308
21.17883	169.6201	-2.586106
21.23050	169.6201	-2.586845
21.28050	169.6201	-2.587530
21.33050	169.6200	-2.588219
21.38383	169.6197	-2.588989
21.43383	169.6199	-2.589613
21.48383	169.6199	-2.590156
21.53550	169.6194	-2.590823
21.58716	169.6186	-2.591386
21.63716	169.6188	-2.591945
21.68716	169.6190	-2.592451
21.74050	169.6181	-2.592993
21.79050	169.6184	-2.593515
21.84050	169.6179	-2.593982
21.89216	169.6177	-2.594551
21.94383	169.6179	-2.595112
21.99383	169.6182	-2.595669
22.04383	169.6179	-2.596142
22.09550	169.6176	-2.596632
22.14716	169.6179	-2.597123
22.19716	169.6172	-2.597647
22.24716	169.6178	-2.598130
22.30050	169.6180	-2.598613
22.35050	169.6177	-2.599076
22.40050	169.6176	-2.599634
22.45216	169.6182	-2.600269
22.50383	169.6184	-2.600915
22.55383	169.6186	-2.601594
22.60383	169.6198	-2.602324
22.65550	169.6197	-2.602977
22.70717	169.6186	-2.603525
22.75716	169.6202	-2.604116
22.80716	169.6198	-2.604590
22.86050	169.6201	-2.605137
22.91050	169.6206	-2.605664
22.96050	169.6201	-2.606064
23.01216	169.6206	-2.606469
23.06383	169.6206	-2.606916
23.11383	169.6202	-2.607220
23.16383	169.6205	-2.607600
23.21550	169.6203	-2.607964
23.26716	169.6204	-2.608336
23.31716	169.6200	-2.608619
23.36716	169.6201	-2.608944
23.42050	169.6202	-2.609278
23.47050	169.6196	-2.609523
23.52050	169.6191	-2.609746
23.57216	169.6192	-2.610020
23.62383	169.6191	-2.610224
23.67383	169.6186	-2.610402
23.72383	169.6184	-2.610624
23.77717	169.6180	-2.610826
23.82716	169.6174	-2.610982
23.87716	169.6175	-2.611242
23.92883	169.6178	-2.611396
23.98050	169.6177	-2.611504
24.03050	169.6177	-2.611690
24.08050	169.6168	-2.611912
24.13216	169.6173	-2.612227
24.18383	169.6178	-2.612474
24.23383	169.6176	-2.612782
24.28383	169.6178	-2.613109
24.33716	169.6182	-2.613525
24.38716	169.6182	-2.613945
24.43716	169.6182	-2.614428
24.48883	169.6194	-2.614918
24.54050	169.6185	-2.615362
24.59050	169.6192	-2.615746
24.64050	169.6195	-2.616128
24.69216	169.6198	-2.616500
24.74383	169.6198	-2.616804
24.79383	169.6199	-2.617102
24.84383	169.6200	-2.617398
24.89716	169.6201	-2.617627
24.94716	169.6197	-2.617806
24.99716	169.6190	-2.617998
25.04883	169.6197	-2.618113
25.10050	169.6189	-2.618193
25.15050	169.6196	-2.618251
25.20050	169.6189	-2.618312
25.25217	169.6187	-2.618444
25.30383	169.6180	-2.618592
25.35383	169.6180	-2.618772
25.40383	169.6190	-2.618945
25.45717	169.6181	-2.619064
25.50716	169.6181	-2.619127
25.55716	169.6187	-2.619198
25.60883	169.6175	-2.619321
25.66050	169.6175	-2.619468
25.71050	169.6187	-2.619722
25.76050	169.6190	-2.619989
25.81383	169.6190	-2.620306
25.86383	169.6193	-2.620608
25.91383	169.6193	-2.620881
25.96550	169.6197	-2.621132
26.01716	169.6200	-2.621328
26.06716	169.6197	-2.621548
26.11716	169.6195	-2.621751
26.16883	169.6199	-2.622006
26.22050	169.6202	-2.622216
26.27050	169.6212	-2.622457
26.32050	169.6198	-2.622474
26.37383	169.6188	-2.622550
26.42383	169.6191	-2.622642
26.47383	169.6180	-2.622748
26.52550	169.6182	-2.622814
26.57717	169.6194	-2.622842
26.62716	169.6180	-2.622774
26.67717	169.6176	-2.622825
26.72883	169.6181	-2.622875
26.78050	169.6176	-2.622958
26.83050	169.6183	-2.623106
26.88050	169.6188	-2.623269
26.93383	169.6194	-2.623538
26.98383	169.6195	-2.623720
27.03383	169.6186	-2.623910
27.08550	169.6191	-2.624125
27.13716	169.6190	-2.624352
27.18717	169.6193	-2.624420
27.23716	169.6188	-2.624460
27.28883	169.6190	-2.624515
27.34050	169.6186	-2.624497
27.39050	169.6185	-2.624546
27.44050	169.6181	-2.624454
27.49383	169.6181	-2.624536
27.54383	169.6186	-2.624633
27.59383	169.6177	-2.624736
27.64550	169.6184	-2.624988
27.69717	169.6188	-2.625298
27.74716	169.6191	-2.625586
27.79716	169.6197	-2.625889
27.85050	169.6184	-2.626167
27.90050	169.6195	-2.626390
27.95050	169.6190	-2.626559
28.00217	169.6189	-2.626690
28.05383	169.6187	-2.626742
28.10383	169.6177	-2.626714
28.15383	169.6186	-2.626716
28.20550	169.6186	-2.626718
28.25716	169.6186	-2.626709
28.30716	169.6178	-2.626707
28.35716	169.6182	-2.626788
28.41050	169.6188	-2.626956
28.46050	169.6181	-2.627165
28.51050	169.6190	-2.627408
28.56217	169.6190	-2.627680
28.61383	169.6196	-2.627878
28.66383	169.6196	-2.628023
28.71383	169.6202	-2.628206
28.76550	169.6197	-2.628384
28.81716	169.6197	-2.628484
28.86716	169.6202	-2.628570
28.91716	169.6192	-2.628592
28.97050	169.6197	-2.628581
29.02050	169.6186	-2.628601
29.07050	169.6198	-2.628590
29.12216	169.6196	-2.628526
29.17383	169.6184	-2.628506
29.22383	169.6185	-2.628486
29.27383	169.6186	-2.628423
29.32550	169.6186	-2.628414
29.37716	169.6185	-2.628401
29.42717	169.6185	-2.628375
29.47717	169.6190	-2.628432
29.53050	169.6195	-2.628595
29.58050	169.6193	-2.628760
29.63050	169.6190	-2.628993
29.68216	169.6198	-2.629241
29.73383	169.6198	-2.629439
29.78383	169.6194	-2.629581
29.83383	169.6197	-2.629736
29.88716	169.6208	-2.629926
29.93717	169.6201	-2.629982
29.98716	169.6201	-2.630081
30.03883	169.6197	-2.630144
30.09050	169.6195	-2.630228
30.14050	169.6196	-2.630252
30.19050	169.6199	-2.630185
30.24216	169.6193	-2.630115
30.29383	169.6195	-2.630040
30.34383	169.6193	-2.630049
30.39383	169.6201	-2.629990
30.44717	169.6194	-2.629950
30.49716	169.6193	-2.629877
30.54716	169.6190	-2.629739
30.59883	169.6191	-2.629704
30.65050	169.6189	-2.629594
30.70050	169.6190	-2.629530
30.75050	169.6190	-2.629544
30.80217	169.6195	-2.629575
30.85383	169.6196	-2.629648
30.90383	169.6195	-2.629704
30.95383	169.6198	-2.629846
31.00716	169.6190	-2.629842
31.05716	169.6203	-2.629977
31.10716	169.6200	-2.630008
31.15883	169.6199	-2.630076
31.21050	169.6191	-2.629944
31.26050	169.6193	-2.629860
31.31050	169.6196	-2.629779
31.36216	169.6189	-2.629602
31.41383	169.6184	-2.629539
31.46383	169.6190	-2.629513
31.51383	169.6186	-2.629499
31.56716	169.6181	-2.629422
31.61716	169.6187	-2.629375
31.66716	169.6178	-2.629367
31.71883	169.6180	-2.629369
31.77050	169.6172	-2.629409
31.82050	169.6182	-2.629570
31.87050	169.6190	-2.629731
31.92383	169.6190	-2.629913
31.97383	169.6201	-2.630090
32.02383	169.6198	-2.630241
32.07550	169.6194	-2.630376
32.12717	169.6200	-2.630514
32.17717	169.6203	-2.630582
32.22717	169.6202	-2.630689
32.27883	169.6203	-2.630760
32.33050	169.6206	-2.630858
32.38050	169.6206	-2.630850
32.43050	169.6202	-2.630825
32.48383	169.6198	-2.630750
32.53383	169.6195	-2.630746
32.58383	169.6200	-2.630657
32.63550	169.6191	-2.630452
32.68716	169.6184	-2.630399
32.73717	169.6186	-2.630338
32.78717	169.6191	-2.630307
32.83883	169.6194	-2.630168
32.89050	169.6192	-2.630176
32.94050	169.6186	-2.630251
32.99050	169.6192	-2.630330
33.04383	169.6192	-2.630432
33.09384	169.6194	-2.630480
33.14383	169.6194	-2.630592
33.19550	169.6196	-2.630654
33.24716	169.6193	-2.630681
33.29716	169.6201	-2.630725
33.34716	169.6200	-2.630699
33.39883	169.6190	-2.630616
33.45050	169.6184	-2.630622
33.50050	169.6182	-2.630564
33.55050	169.6187	-2.630507
33.60383	169.6192	-2.630463
33.65383	169.6184	-2.630366
33.70383	169.6189	-2.630486
33.75550	169.6191	-2.630668
33.80716	169.6198	-2.630882
33.85716	169.6199	-2.631106
33.90716	169.6192	-2.631275
33.96050	169.6196	-2.631520
34.01050	169.6202	-2.631607
34.06050	169.6197	-2.631629
34.11217	169.6197	-2.631677
34.16383	169.6199	-2.631690
34.21383	169.6202	-2.631812
34.26383	169.6206	-2.631843
34.31550	169.6204	-2.631881
34.36716	169.6205	-2.631892
34.41716	169.6192	-2.631844
34.46716	169.6193	-2.631816
34.52050	169.6193	-2.631774
34.57050	169.6199	-2.631742
34.62050	169.6190	-2.631634
34.67216	169.6189	-2.631646
34.72383	169.6192	-2.631558
34.77383	169.6186	-2.631519
34.82383	169.6188	-2.631557
34.87550	169.6188	-2.631574
34.92717	169.6188	-2.631652
34.97717	169.6187	-2.631735
35.02716	169.6190	-2.631759
35.08050	169.6187	-2.631737
35.13050	169.6187	-2.631672
35.18050	169.6187	-2.631654
35.23216	169.6184	-2.631622
35.28383	169.6180	-2.631614
35.33383	169.6189	-2.631628
35.38383	169.6185	-2.631719
35.43550	169.6191	-2.631938
35.48717	169.6197	-2.632046
35.53717	169.6196	-2.632216
35.58716	169.6196	-2.632389
35.64050	169.6198	-2.632508
35.69050	169.6200	-2.632650
35.74050	169.6198	-2.632759
35.79217	169.6199	-2.632950
35.84384	169.6200	-2.633016
35.89383	169.6201	-2.633076
35.94383	169.6210	-2.633102
35.99716	169.6210	-2.633142
36.04716	169.6201	-2.633188
36.09716	169.6199	-2.633194
36.14883	169.6196	-2.633172
36.20050	169.6206	-2.633265
36.25050	169.6199	-2.633344
36.30050	169.6199	-2.633424
36.35217	169.6202	-2.633502
36.40383	169.6198	-2.633475
36.45383	169.6197	-2.633420
36.50383	169.6202	-2.633461
36.55716	169.6191	-2.633362
36.60716	169.6201	-2.633362
36.65716	169.6202	-2.633283
36.70883	169.6194	-2.633230
36.76050	169.6189	-2.633204
36.81050	169.6189	-2.633212
36.86050	169.6198	-2.633358
36.91217	169.6191	-2.633389
36.96383	169.6198	-2.633525
37.01383	169.6193	-2.633558
37.06383	169.6203	-2.633613
37.11716	169.6194	-2.633644
37.16716	169.6185	-2.633588
37.21716	169.6189	-2.633585
37.26883	169.6187	-2.633502
37.32050	169.6185	-2.633420
37.37050	169.6182	-2.633298
37.42050	169.6185	-2.633271
37.47217	169.6184	-2.633154
37.52383	169.6185	-2.633200
37.57383	169.6190	-2.633295
37.62383	169.6194	-2.633404
37.67717	169.6197	-2.633532
37.72717	169.6197	-2.633661
37.77716	169.6195	-2.633802
37.82883	169.6200	-2.633922
37.88050	169.6193	-2.634037
37.93050	169.6205	-2.634154
37.98050	169.6196	-2.634211
38.03383	169.6197	-2.634178
38.08383	169.6197	-2.634135
38.13383	169.6194	-2.634071
38.18550	169.6197	-2.634080
38.23717	169.6196	-2.634078
38.28717	169.6194	-2.634180
38.33716	169.6198	-2.634280
38.38883	169.6200	-2.634363
38.44050	169.6192	-2.634298
38.49050	169.6195	-2.634285
38.54050	169.6203	-2.634308
38.59384	169.6204	-2.634224
38.64383	169.6193	-2.634256
38.69383	169.6194	-2.634265
38.74550	169.6195	-2.634284
38.79716	169.6196	-2.634328
38.84716	169.6203	-2.634379
38.89717	169.6199	-2.634394
38.94883	169.6200	-2.634422
39.00050	169.6201	-2.634500
39.05050	169.6200	-2.634552
39.10050	169.6201	-2.634552
39.15383	169.6204	-2.634596
39.20383	169.6200	-2.634586
39.25383	169.6199	-2.634609
39.30550	169.6199	-2.634647
39.35716	169.6194	-2.634648
39.40716	169.6198	-2.634672
39.45716	169.6198	-2.634641
39.50883	169.6196	-2.634572
39.56050	169.6193	-2.634497
39.61050	169.6190	-2.634341
39.66050	169.6186	-2.634230
39.71383	169.6186	-2.634162
39.76383	169.6180	-2.634096
39.81383	169.6189	-2.634150
39.86550	169.6188	-2.634106
39.91716	169.6184	-2.634140
39.96716	169.6188	-2.634135
40.01716	169.6189	-2.634182
40.07050	169.6184	-2.634248
40.12050	169.6192	-2.634341
40.17050	169.6194	-2.634392
40.22217	169.6186	-2.634365
40.27383	169.6180	-2.634248
40.32383	169.6191	-2.634268
40.37383	169.6188	-2.634174
40.42550	169.6188	-2.634141
40.47717	169.6180	-2.634054
40.52716	169.6187	-2.633998
40.57717	169.6190	-2.633900
40.63050	169.6186	-2.633742
40.68050	169.6186	-2.633732
40.73050	169.6185	-2.633826
40.78216	169.6195	-2.633942
40.83383	169.6189	-2.633984
40.88383	169.6186	-2.634090
40.93384	169.6190	-2.634216
40.98550	169.6196	-2.634462
41.03717	169.6195	-2.634516
41.08716	169.6198	-2.634625
41.13716	169.6193	-2.634604
41.19050	169.6197	-2.634554
41.24050	169.6199	-2.634506
41.29050	169.6196	-2.634556
41.34217	169.6191	-2.634550
41.39383	169.6207	-2.634648
41.44383	169.6198	-2.634627
41.49383	169.6199	-2.634625
41.54550	169.6199	-2.634575
41.59716	169.6198	-2.634499
41.64717	169.6199	-2.634424
41.69717	169.6196	-2.634340
41.75050	169.6198	-2.634219
41.80050	169.6197	-2.634145
41.85050	169.6197	-2.634082
41.90216	169.6196	-2.634012
41.95383	169.6196	-2.633994
42.00383	169.6196	-2.634062
42.05383	169.6190	-2.634135
42.10717	169.6204	-2.634252
42.15717	169.6195	-2.634310
42.20717	169.6196	-2.634451
42.25883	169.6192	-2.634424
42.31050	169.6193	-2.634455
42.36050	169.6190	-2.634463
42.41050	169.6197	-2.634488
42.46216	169.6192	-2.634456
42.51383	169.6196	-2.634453
42.56383	169.6201	-2.634535
42.61383	169.6198	-2.634552
42.66716	169.6198	-2.634705
42.71717	169.6199	-2.634806
42.76717	169.6202	-2.634932
42.81883	169.6199	-2.635054
42.87050	169.6196	-2.635115
42.92050	169.6209	-2.635258
42.97050	169.6203	-2.635301
43.02050	169.6219	-2.635732
43.07217	169.6965	-4.715576
43.12383	170.0491	-8.397722
43.17383	170.5919	-10.82883
43.22383	171.2719	-12.57400
43.27716	172.1002	-13.80201
43.32717	172.9431	-14.57750
43.37717	173.8254	-15.11666
43.42883	174.7676	-15.50100
43.48050	175.7310	-15.77104
43.53050	176.6783	-15.97558
43.58050	177.6321	-16.11234
43.63217	178.6272	-16.25311
43.68383	179.6266	-16.35725
43.73383	180.5969	-16.46633
43.78383	181.5717	-16.56049
43.83716	182.6118	-16.67576
43.88716	183.5905	-16.78844
43.93716	184.5689	-16.91462
43.98883	185.5804	-17.05631
44.04050	186.5934	-17.21109
44.09050	187.5738	-17.37475
44.14050	188.5544	-17.57044
44.19383	189.5999	-17.78911
44.24383	190.5803	-18.00799
44.29383	191.5636	-18.17436
44.34550	192.5768	-18.45059
44.39717	193.5884	-18.77889
44.44717	194.5652	-19.16952
44.49716	195.5384	-19.62976
44.54883	196.5399	-20.21150
44.60050	197.5333	-20.96574
44.65050	198.4879	-21.86748
44.70050	199.4303	-23.00592
44.75383	200.4216	-24.48179
44.80383	201.3379	-26.11837
44.85383	202.2400	-27.96130
44.90550	203.1579	-30.10531
44.95717	204.0634	-32.39286
45.00717	204.9335	-34.59038
45.05717	205.8004	-36.85306
45.10883	206.6901	-39.31306
45.16050	207.5768	-41.74634
45.21050	208.4378	-43.84694
45.26050	209.3166	-45.21641
45.31383	210.3013	-45.22906
45.36383	211.2980	-43.49469
45.41383	212.3895	-39.59143
45.46550	213.6370	-33.55438
45.51717	214.9783	-27.22806
45.56717	216.2727	-23.59559
45.61716	217.4930	-21.69160
45.66883	218.6833	-20.43566
45.72050	219.8220	-19.61678
45.77050	220.8898	-19.08459
45.82050	221.9362	-18.74673
45.87383	223.0362	-18.50280
45.92383	224.0553	-18.36301
45.97383	225.0694	-18.27879
46.02550	226.1098	-18.23464
46.07717	227.1475	-18.22259
46.12717	228.1499	-18.21630
46.17717	229.1496	-18.21652
46.23050	230.2173	-18.21798
46.28050	231.2154	-18.22168
46.33050	232.2133	-18.24108
46.38217	233.2448	-18.27019
46.43383	234.2754	-18.30284
46.48383	235.2740	-18.34693
46.53383	236.2720	-18.37895
46.58550	237.3026	-18.41202
46.63716	238.3345	-18.45006
46.68716	239.3332	-18.47591
46.73717	240.3312	-18.51186
46.79050	241.3953	-18.54645
46.84050	242.3930	-18.58151
46.89050	243.3915	-18.61349
46.94217	244.4234	-18.64657
46.99383	245.4550	-18.67453
47.04383	246.4534	-18.70724
47.09384	247.4515	-18.73190
47.14550	248.4829	-18.75890
47.19717	249.5148	-18.79002
47.24716	250.5128	-18.81804
47.29716	251.5110	-18.84932
47.35050	252.5765	-18.87982
47.40050	253.5742	-18.90422
47.45050	254.5722	-18.93348
47.50217	255.6018	-18.97166
47.55383	256.6328	-19.02408
47.60383	257.6299	-19.06474
47.65383	258.6280	-19.10336
47.70550	259.6581	-19.14498
47.75717	260.6890	-19.18580
47.80717	261.6860	-19.22095
47.85717	262.6836	-19.26855
47.91050	263.7484	-19.29729
47.96050	264.7450	-19.32846
48.01050	265.7423	-19.37091
48.06216	266.7747	-19.40320
48.11383	267.8048	-19.43298
48.16383	268.8012	-19.46896
48.21383	269.7990	-19.51176
48.26717	270.8634	-19.54054
48.31717	271.8614	-19.57199
48.36716	272.8589	-19.60814
48.41883	273.8890	-19.63956
48.47050	274.9203	-19.65360
48.51717	275.8509	-19.74691
48.56717	276.6880	-20.59949
48.62050	276.9524	-14.12163
48.67050	276.8097	-7.566913
48.72050	276.4100	-2.477715
48.77217	275.8167	1.244023
48.82383	275.0996	3.815941
48.87383	274.3237	5.522866
48.92383	273.4927	6.664995
48.97550	272.5942	7.493525
49.02716	271.6680	8.076282
49.07717	270.7526	8.460856
49.12717	269.8218	8.724369
49.18050	268.8184	8.925687
49.23050	267.8682	9.051242
49.28050	266.9124	9.144359
49.33217	265.9197	9.210092
49.38383	264.9212	9.265884
49.43383	263.9522	9.299712
49.48383	262.9804	9.328820
49.53717	261.9414	9.352775
49.58716	260.9648	9.375684
49.63716	259.9861	9.391063
49.68883	258.9736	9.405562
49.74050	257.9596	9.419478
49.79050	256.9775	9.433438
49.84050	255.9938	9.445982
49.89217	254.9761	9.458701
49.94383	253.9584	9.471505
49.99383	252.9722	9.484488
50.04383	251.9846	9.497147
50.09716	250.9300	9.508709
50.14717	249.9429	9.519653
50.19717	248.9540	9.532551
50.24883	247.9339	9.547149
50.30050	246.9122	9.569416
50.35050	245.9223	9.591460
50.40050	244.9327	9.610866
50.45216	243.9094	9.627658
50.50383	242.8860	9.643262
50.55383	241.8944	9.654418
50.60383	240.9031	9.667176
50.65717	239.8454	9.680230
50.70717	238.8539	9.694556
50.75717	237.8614	9.706281
50.80883	236.8369	9.721129
50.86050	235.8114	9.735259
50.91050	234.8184	9.747358
50.96050	233.8258	9.756889
51.01216	232.7985	9.766353
51.06383	231.7730	9.775929
51.11383	230.7792	9.786444
51.16383	229.7866	9.796512
51.21717	228.7263	9.806324
51.26716	227.7337	9.815969
51.31716	226.7405	9.827160
51.36883	225.7146	9.840735
51.42050	224.6896	9.855956
51.47050	223.6950	9.872105
51.52050	222.7026	9.887976
51.57383	221.6424	9.904797
51.62383	220.6486	9.915656
51.67383	219.6550	9.929035
51.72550	218.6280	9.940999
51.77717	217.6006	9.953522
51.82717	216.6074	9.965321
51.87717	215.6131	9.977512
51.92883	214.5862	9.988599
51.98050	213.5584	10.00158
52.03050	212.5647	10.01213
52.08050	211.5702	10.02333
52.13383	210.5108	10.03546
52.18383	209.5156	10.04856
52.23383	208.5212	10.05956
52.28550	207.4934	10.06963
52.33716	206.4649	10.08030
52.38716	205.4711	10.08964
52.43716	204.4758	10.10041
52.48882	203.4476	10.11013
52.54050	202.4203	10.12028
52.59050	201.4270	10.12968
52.64050	200.4330	10.14179
52.69384	199.3730	10.15337
52.74382	198.3792	10.16898
52.79382	197.3857	10.18178
52.84550	196.3574	10.19581
52.89717	195.3296	10.20889
52.94717	194.3361	10.22330
52.99717	193.3421	10.23703
53.04883	192.3144	10.25071
53.10050	191.2870	10.26580
53.15050	190.2929	10.27695
53.20050	189.2991	10.29002
53.25383	188.2388	10.30342
53.30383	187.2434	10.31523
53.35383	186.2501	10.32559
53.40550	185.2215	10.33925
53.45717	184.1934	10.34966
53.50717	183.1992	10.36012
53.55717	182.2055	10.37069
53.61050	181.1445	10.38253
53.66050	180.1510	10.39556
53.71050	179.1558	10.41487
53.76216	178.1293	10.43133
53.81382	177.1014	10.45302
53.86382	176.1074	10.46636
53.91382	175.1125	10.48782
53.96550	174.0841	10.50290
54.01716	173.0551	10.51543
54.06716	172.0616	10.52454
54.11716	171.0657	10.54122
54.17050	170.0048	10.56209
54.22050	169.0116	10.60008
54.27050	168.0186	10.70584
54.32217	166.9940	10.88802
54.37383	165.9736	11.17867
54.42383	164.9951	11.57850
54.47382	164.0264	12.24000
54.52550	163.0427	13.31625
54.57717	162.0858	14.96208
54.62717	161.1919	17.15976
54.67717	160.3336	19.85667
54.73050	159.4468	22.93818
54.78050	158.6264	25.59330
54.83050	157.7941	27.67871
54.88217	156.9006	29.02508
54.93383	155.9631	29.49722
54.98383	155.0059	29.15826
55.03383	154.0024	28.20674
55.08550	152.9228	26.77088
55.13716	151.8157	25.14072
55.18716	150.7272	23.51812
55.23717	149.6323	21.98857
55.29050	148.4662	20.46844
55.34050	147.3796	19.22189
55.39050	146.2999	18.10094
55.44216	145.1933	17.09631
55.49382	144.0957	16.23613
55.54382	143.0421	15.51187
55.59384	141.9989	14.92714
55.64717	140.8911	14.38692
55.69717	139.8622	13.98981
55.74717	138.8380	13.66211
55.79883	137.7810	13.27698
55.85050	136.7283	13.02441
55.90050	135.7148	12.83163
55.95050	134.7044	12.68448
56.00217	133.6643	12.55898
56.05383	132.6262	12.45093
56.10383	131.6223	12.35963
56.15383	130.6192	12.27795
56.20717	129.5500	12.20836
56.25717	128.5490	12.15085
56.30717	127.5492	12.10372
56.35883	126.5163	12.06204
56.41050	125.4838	12.01909
56.46050	124.4834	11.98156
56.51050	123.4845	11.94201
56.56216	122.4531	11.90790
56.61382	121.4221	11.86963
56.66382	120.4231	11.84109
56.71382	119.4243	11.70012
56.76716	118.3518	11.43618
56.81716	117.3478	11.43008
56.86716	116.3624	11.89902
56.91882	115.3266	11.46536
56.97050	114.2905	11.37933
57.02050	113.2895	11.33213
57.07050	112.2890	11.26921
57.12217	111.2561	11.22180
57.17383	110.2223	11.17985
57.22382	109.2244	11.14301
57.27383	108.2240	11.11197
57.32717	107.1578	11.05806
57.37717	106.1603	11.02285
57.42717	105.1619	10.99881
57.47883	104.1314	10.97750
57.53050	103.0988	10.93579
57.58050	102.1012	10.90900
57.63050	101.1038	10.88718
57.68383	100.0384	10.85998
57.73383	99.03922	10.80922
57.78383	98.04054	10.76449
57.83550	97.00932	10.73352
57.88716	95.97609	10.65161
57.93716	94.97486	10.59398
57.98717	93.97626	10.54911
58.03882	92.94328	10.51887
58.09050	91.91119	10.48561
58.14050	90.91138	10.45774
58.19050	89.91218	10.42635
58.24382	88.84610	10.34870
58.29382	87.84801	10.33971
58.34384	86.85016	10.33299
58.39550	85.81909	10.31560
58.44717	84.78780	10.29841
58.49717	83.79011	10.27804
58.54717	82.79119	10.25790
58.59882	81.75855	10.23023
58.65050	80.72696	10.19611
58.70050	79.72720	10.16863
58.75050	78.72845	10.13379
58.80383	77.66293	10.09538
58.85383	76.66376	10.06069
58.90383	75.66249	9.958007
58.95550	74.62939	9.929280
59.00717	73.59701	9.912079
59.05717	72.59974	9.891069
59.10717	71.60107	9.870647
59.15883	70.56968	9.847808
59.21050	69.53826	9.825519
59.26050	68.53985	9.796942
59.31050	67.54019	9.767781
59.36382	66.47578	9.735261
59.41382	65.47801	9.710548
59.46382	64.47873	9.685806
59.51550	63.44758	9.654355
59.56716	62.41528	9.620618
59.61716	61.41701	9.578995
59.66716	60.41865	9.543843
59.72050	59.35222	9.507706
59.77050	58.35249	9.472522
59.82050	57.35328	9.438175
59.87217	56.32089	9.404728
59.92383	55.28842	9.368046
59.97382	54.28899	9.339120
60.02383	53.29126	9.310429
60.07550	52.25900	9.280474
60.12717	51.22774	9.254205
60.17717	50.22964	9.227936
60.22717	49.23165	9.205504
60.28050	48.16607	9.173636
60.33050	47.16744	9.141970
60.38050	46.16930	9.115382
60.43217	45.13742	9.085184
60.48383	44.10546	9.054188
60.53383	43.10656	9.020264
60.58383	42.10684	8.990790
60.63550	41.07363	8.956150
60.68716	40.04150	8.918574
60.73717	39.04078	8.879351
60.78716	38.04200	8.831041
60.84050	36.97466	8.786836
60.89050	35.97434	8.743554
60.94050	34.97454	8.696984
60.99216	33.94142	8.650382
61.04382	32.90881	8.605297
61.09384	31.90761	8.563806
61.14384	30.90607	8.522265
61.19550	29.87293	8.469211
61.24717	28.83976	8.419272
61.29717	27.83820	8.367244
61.34716	26.83684	8.315516
61.40050	25.76981	8.264668
61.45050	24.76833	8.228539
-2.000000	4.000000	0.0000000
61.54883	22.84160	8.641781
61.60050	22.33066	5.652776
61.65050	22.30530	1.361557
61.70050	22.57381	-1.709184
61.75383	23.09576	-3.849468
61.80383	23.73320	-5.173680
61.85383	24.46961	-6.051129
61.90550	25.30295	-6.674056
61.95717	26.18777	-7.102497
62.00717	27.07831	-7.390054
62.05717	27.99162	-7.598124
62.10883	28.95284	-7.750616
62.16050	29.92790	-7.858556
62.21050	30.87930	-7.938134
62.26050	31.83766	-8.006974
62.31382	32.86676	-8.053639
62.36382	33.83476	-8.091920
62.41382	34.80620	-8.117504
62.46550	35.81225	-8.144171
62.51716	36.82025	-8.166838
62.56716	37.79814	-8.190955
62.61716	38.77804	-8.211422
62.66882	39.79136	-8.233536
62.72050	40.80700	-8.255024
62.77050	41.79084	-8.280145
62.82050	42.77522	-8.306514
62.87383	43.82559	-8.336688
62.92383	44.81363	-8.364796
62.97382	45.80075	-8.392672
63.02550	46.82150	-8.427688
63.07717	47.84265	-8.470881
63.12717	48.83180	-8.506031
63.17717	49.82194	-8.542031
63.22883	50.84616	-8.591175
63.28050	51.86956	-8.636124
63.33050	52.86080	-8.679707
63.38050	53.85251	-8.722062
63.43383	54.91196	-8.767819
63.48383	55.90479	-8.810431
63.53383	56.89843	-8.852019
63.58550	57.92546	-8.895535
63.63716	58.95101	-8.948012
63.68716	59.94526	-8.996722
63.73717	60.93790	-9.042382
63.79050	61.99726	-9.108394
63.84050	62.99150	-9.156570
63.89050	63.98630	-9.211738
63.94216	65.01454	-9.255199
63.99382	66.04228	-9.307549
64.04384	67.03876	-9.355482
64.09384	68.03382	-9.412030
64.14550	69.06311	-9.461216
64.19717	70.09236	-9.514822
64.24717	71.08844	-9.564890
64.29718	72.08371	-9.624668
64.35050	73.14590	-9.679978
64.40050	74.14063	-9.736543
64.45050	75.13672	-9.790671
64.50217	76.16616	-9.848982
64.55383	77.19639	-9.908655
64.60383	78.19116	-9.968082
64.65384	79.18702	-10.02128
64.70550	80.21495	-10.08627
64.75718	81.24321	-10.15453
64.80717	82.24035	-10.21753
64.85718	83.23564	-10.27716
64.91050	84.29751	-10.34225
64.96050	85.29424	-10.39982
65.01050	86.28992	-10.45801
65.06216	87.31982	-10.52503
65.11384	88.34754	-10.58834
65.16382	89.34282	-10.65970
65.21384	90.33899	-10.72716
65.26550	91.36728	-10.79249
65.31717	92.39566	-10.86990
65.36718	93.38928	-10.93776
65.41717	94.38491	-11.00670
65.47050	95.44657	-11.07755
65.52050	96.44268	-11.14524
65.57050	97.43814	-11.20638
65.62218	98.46753	-11.27570
65.67384	99.49637	-11.34934
65.72384	100.4935	-11.41549
65.77384	101.4888	-11.48811
65.82718	102.5517	-11.57160
65.87718	103.5476	-11.67228
65.92718	104.5431	-11.73597
65.97884	105.5720	-11.79734
66.03050	106.6021	-11.85683
66.08050	107.5985	-11.91840
66.13050	108.5967	-11.97401
66.18218	109.6258	-12.04052
66.23384	110.6559	-12.10610
66.28384	111.6525	-12.18224
66.33384	112.6488	-12.25344
66.38718	113.7123	-12.33305
66.43718	114.7080	-12.39739
66.48718	115.7039	-12.48039
66.53882	116.7347	-12.54490
66.59050	117.7642	-12.61938
66.64050	118.7599	-12.68901
66.69050	119.7548	-12.76932
66.74218	120.7834	-12.85484
66.79384	121.8135	-12.93666
66.84384	122.8090	-13.02320
66.89384	123.8040	-13.10150
66.94718	124.8661	-13.18908
66.99718	125.8610	-13.27624
67.04718	126.8567	-13.35620
67.09882	127.8851	-13.44441
67.15050	128.9136	-13.53156
67.20050	129.9092	-13.61526
67.25050	130.9054	-13.70435
67.30218	131.9334	-13.79546
67.35384	132.9603	-13.89400
67.40384	133.9537	-14.00082
67.45384	134.9489	-14.10505
67.50718	136.0095	-14.21862
67.55718	137.0028	-14.33566
67.60718	137.9954	-14.44155
67.65884	139.0238	-14.54917
67.71050	140.0511	-14.63948
67.76050	141.0453	-14.74452
67.81050	142.0400	-14.84515
67.86384	143.1010	-14.94987
67.91382	144.0964	-15.06284
67.96384	145.0908	-15.18293
68.01550	146.1185	-15.28162
68.06718	147.1472	-15.33736
68.11718	148.1431	-15.39041
68.16718	149.1384	-15.49172
68.21884	150.1673	-15.57701
68.27050	151.1953	-15.68431
68.32050	152.1896	-15.77018
68.37050	153.1849	-15.86100
68.42384	154.2482	-15.87007
68.47384	155.2467	-15.88596
68.52384	156.2453	-15.91844
68.57550	157.2769	-15.94995
68.62718	158.3096	-15.98238
68.67718	159.3082	-16.01210
68.72718	160.3064	-16.03434
68.77884	161.3392	-16.05820
68.83050	162.3725	-16.07784
68.88050	163.3724	-16.09588
68.93050	164.3728	-16.12091
68.98384	165.4384	-16.15610
69.03384	166.4371	-16.21887
69.08384	167.4347	-16.30349
69.13550	168.4658	-16.37611
69.18718	169.4969	-16.45900
69.23718	170.4937	-16.54380
69.28718	171.4884	-16.64888
69.33884	172.5172	-16.75780
69.39050	173.5455	-16.86374
69.44050	174.5404	-16.97538
69.49050	175.5347	-17.09313
69.54384	176.5949	-17.22915
69.59384	177.5881	-17.37521
69.64384	178.5802	-17.53864
69.69550	179.6042	-17.71741
69.74718	180.6266	-17.92530
69.79718	181.6134	-18.15354
69.84718	182.6014	-18.40171
69.90050	183.6524	-18.69449
69.95050	184.6373	-18.99586
70.00050	185.6207	-19.32408
70.05218	186.6336	-19.69967
70.10384	187.6455	-20.10575
70.15384	188.6229	-20.52059
70.20384	189.5988	-20.96167
70.25550	190.6054	-21.41757
70.30718	191.6102	-21.88875
70.35718	192.5825	-22.36862
70.40718	193.5545	-22.85192
70.46050	194.5892	-23.41930
70.51050	195.5573	-24.01436
70.56050	196.5222	-24.68854
70.61218	197.5146	-25.45527
70.66382	198.5039	-26.26982
70.71384	199.4562	-27.11404
70.76384	200.4087	-27.94970
70.81550	201.3896	-28.78206
70.86718	202.3755	-29.49412
70.91718	203.3368	-29.90084
70.96718	204.3146	-29.84744
71.02050	205.3877	-28.91904
71.07050	206.4406	-26.94291
71.12050	207.5467	-24.06134
71.17218	208.7311	-21.15680
71.22384	209.9099	-19.38072
71.27384	211.0140	-18.49159
71.32384	212.0865	-17.95018
71.37550	213.1680	-17.60431
71.42718	214.2335	-17.37987
71.47718	215.2536	-17.25064
71.52718	216.2660	-17.18523
71.58050	217.3417	-17.13658
71.63050	218.3464	-17.12439
71.68050	219.3497	-17.11922
71.73218	220.3842	-17.11934
71.78384	221.4180	-17.12046
71.83384	222.4188	-17.12260
71.88384	223.4178	-17.12901
71.93718	224.4841	-17.14423
71.98718	225.4835	-17.16020
72.03718	226.4830	-17.18186
72.08884	227.5154	-17.20916
72.14050	228.5472	-17.23456
72.19050	229.5454	-17.27337
72.24050	230.5434	-17.31916
72.29218	231.5741	-17.36653
72.34384	232.6058	-17.42356
72.39384	233.6025	-17.46612
72.44384	234.6004	-17.51351
72.49718	235.6652	-17.55408
72.54718	236.6624	-17.58562
72.59718	237.6618	-17.61996
72.64884	238.6935	-17.65565
72.70050	239.7249	-17.69156
72.75050	240.7228	-17.73033
72.80050	241.7207	-17.78087
72.85218	242.7530	-17.82226
72.90384	243.7836	-17.86156
72.95384	244.7832	-17.89863
73.00384	245.7806	-17.93237
73.05718	246.8459	-17.97222
73.10718	247.8436	-18.01034
73.15718	248.8427	-18.04272
73.20884	249.8742	-18.07639
73.26050	250.9056	-18.11906
73.31050	251.9027	-18.15695
73.36050	252.9008	-18.19968
73.41218	253.9323	-18.24031
73.46384	254.9626	-18.28590
73.51384	255.9601	-18.33257
73.56384	256.9580	-18.37964
73.61718	258.0224	-18.42577
73.66718	259.0203	-18.46966
73.71718	260.0172	-18.51430
73.76882	261.0473	-18.55941
73.82050	262.0768	-18.61340
73.87050	263.0750	-18.66518
73.92050	264.0720	-18.70418
73.97384	265.1366	-18.75646
74.02384	266.1338	-18.79788
74.07384	267.1322	-18.84018
74.12550	268.1632	-18.88095
74.17718	269.1932	-18.93209
74.22718	270.1910	-18.97569
74.27718	271.1887	-19.02144
74.32884	272.2197	-19.06316
-2.000000	5.000000	0.0000000