File: 7-C1(1.2mol%)+C20(0.6mol%)(1)/matlab/170-1.txt
CLOSED
Version	1.0
Language	English
Mode	Standard
Run	35
RunSerial	12303
Instrument	DSC Q2000 V24.11 Build 124
Module	DSC Standard Cell RC
Operator
File	\\AE520-1454\Users\dsc\Desktop\Data\29-08-17-3\170-1.001
ProcName
InstSerial	2000-0883
AutoSerial	1293
Sample	170-1
Size	12.2000	mg
PanMass	Not available
PanResist	Automatic Automatic  K/W
PanFactor	Default Default
Method
Comment
Xcomment	Pan: Tzero Aluminum Hermetic
Xcomment	Gas1: Nitrogen 50.0 ml/min
Xcomment	Gas2: Nitrogen 50.0 ml/min
Text
Exotherm	UP
Kcell	1.05230
Cpconst	Standard: 0.938
Calib	-38.6961
TempCal	1	pts	157.46	156.60
TzeroDt	-87.6168 -0.0009 -1.4231
TzeroDtz	-87.6168 0.0057 6.9570
InstCalFile	Tzero: \\Ae520-1454\ta\Data\DSC\Calibration\2017\CALIBRATION\1562_RCS (90)_05_18_2017 10_50_44.TZR
InstCalFile	Baseline: \\Ae520-1454\ta\Data\DSC\Calibration\2017\2017-05-17_Calibration.001
InstCalFile	Sapphire: \\Ae520-1454\ta\Data\DSC\Calibration\2017\2017-05-17_Saphire.001
InstCalDate	Tzero 2017-05-18 Time 10:50:44
TempRange	-87.39 to 398.39 °C at 10.00 °C/min Heat Only
AutoZero	Delta T Offset 0.000 uV
AutoZero	Delta T0 Offset 0.000 uV
MultiptCal	0
MultiPtDesc	0) Not set
AutoCellConst	Calibration Date 2017-05-18 16:59:28
Controls	Gas 1  Event Off  Sampling 0.2
Cell#	RC-01562
CoolingUnit	RCS (90)
SelHeatFlow	Heat Flow T4P (mW)
AutoLidII	Installed
AutoAnalysis	Off
MacroFile
Nsig	3
Sig1	Time (min)
Sig2	Temperature (°C)
Sig3	Heat Flow (mW)
Date	2017-08-31
Time	09:42:54
OrgMethod	1: Equilibrate at 80.00 °C
OrgMethod	2: Isothermal for 3.00 min
OrgMethod	3: Jump to 170.00 °C
OrgMethod	4: Mark end of cycle 1
OrgMethod	5: Isothermal for 40.00 min
OrgMethod	6: Mark end of cycle 2
OrgMethod	7: Ramp 20.00 °C/min to 280.00 °C
OrgMethod	8: Mark end of cycle 3
OrgMethod	9: Ramp 20.00 °C/min to 20.00 °C
OrgMethod	10: Mark end of cycle 4
OrgMethod	11: Ramp 20.00 °C/min to 280.00 °C
OrgMethod	12: Mark end of cycle 5
OrgFile	C:\Users\jarra\Desktop\DSC\7-C1(1.2mol%)+C20(0.6mol%)(1)\170-1.001
StartOfData
4.99994E-4	79.93524	-0.7266437
0.05383332	79.93540	-0.6781611
0.1038333	79.93439	-0.6505484
0.1538333	79.93220	-0.6349079
0.2055000	79.92962	-0.6256394
0.2571667	79.92720	-0.6213328
0.3071666	79.92455	-0.6195176
0.3571666	79.92238	-0.6175792
0.4105000	79.92053	-0.6157114
0.4605000	79.91819	-0.6140222
0.5105000	79.91690	-0.6125952
0.5621668	79.91489	-0.6113182
0.6138334	79.91230	-0.6101599
0.6638332	79.91118	-0.6093621
0.7138332	79.91043	-0.6086162
0.7655000	79.90754	-0.6080068
0.8171668	79.90656	-0.6076449
0.8671666	79.90563	-0.6074624
0.9171668	79.90486	-0.6074698
0.9705000	79.90280	-0.6075750
1.020500	79.90390	-0.6078313
1.070500	79.90066	-0.6081343
1.122166	79.90076	-0.6085904
1.173834	79.89863	-0.6091028
1.223833	79.89868	-0.6096711
1.273834	79.89716	-0.6102410
1.325500	79.89649	-0.6109880
1.377166	79.89612	-0.6117539
1.427167	79.89580	-0.6126149
1.477166	79.89438	-0.6134478
1.530500	79.89324	-0.6144672
1.580500	79.89388	-0.6155195
1.630500	79.89249	-0.6164570
1.682167	79.89148	-0.6174469
1.733833	79.89049	-0.6185406
1.783833	79.89016	-0.6196079
1.833833	79.88950	-0.6207934
1.885500	79.88938	-0.6220518
1.937166	79.88868	-0.6232812
1.987166	79.88968	-0.6245672
2.037166	79.88769	-0.6256912
2.090500	79.88743	-0.6270112
2.140500	79.88588	-0.6281865
2.190500	79.88542	-0.6293974
2.242166	79.88500	-0.6305874
2.293833	79.88562	-0.6319415
2.343834	79.88439	-0.6331632
2.393833	79.88370	-0.6342962
2.447166	79.88362	-0.6356175
2.497166	79.88353	-0.6368067
2.547166	79.88121	-0.6380082
2.598834	79.88164	-0.6393593
2.650500	79.88062	-0.6405919
2.700500	79.88093	-0.6418300
2.750500	79.88082	-0.6430873
2.802166	79.88016	-0.6443172
2.853833	79.87921	-0.6456080
2.903833	79.87901	-0.6468882
2.953833	79.87878	-0.6481368
3.000500	79.87876	-0.6494072
3.053833	80.29381	-8.255028
3.103833	82.23257	-21.26054
3.153833	84.96781	-30.02984
3.205500	88.36372	-37.54820
3.257167	92.17091	-43.33306
3.307167	96.13447	-47.59516
3.357167	100.3299	-49.72182
3.410500	104.8704	-52.74204
3.460500	109.2073	-54.69468
3.510500	113.5974	-56.13934
3.562167	118.1644	-57.29709
3.613834	122.7472	-58.19074
3.663833	127.1916	-58.72963
3.713833	131.6338	-59.14141
3.765500	136.2186	-59.35934
3.817166	140.7952	-59.37182
3.867166	145.2196	-59.27700
3.917167	149.6271	-58.89688
3.970500	154.2903	-58.52768
4.020500	158.1960	-52.84646
4.070500	160.8517	-41.20145
4.122166	162.8064	-31.86428
4.173834	164.2089	-23.94936
4.223834	165.2089	-18.01296
4.273834	165.9633	-13.47511
4.325500	166.5582	-9.987350
4.377167	167.0209	-7.437671
4.427166	167.3764	-5.655741
4.477167	167.6660	-4.382284
4.530500	167.9217	-3.414962
4.580500	168.1209	-2.776711
4.630500	168.2926	-2.324354
4.682167	168.4453	-1.995736
4.733834	168.5789	-1.756227
4.783834	168.6937	-1.587948
4.833834	168.7940	-1.461870
4.885500	168.8877	-1.352475
4.937167	168.9719	-1.264466
4.987167	169.0430	-1.182658
5.037167	169.1097	-1.110084
5.090500	169.1725	-1.029027
5.140500	169.2263	-0.9538859
5.190500	169.2758	-0.8721579
5.242167	169.3216	-0.7836122
5.293832	169.3648	-0.6955132
5.343834	169.4024	-0.6008738
5.393832	169.4370	-0.5035226
5.447168	169.4707	-0.3943990
5.497168	169.5011	-0.2852851
5.547168	169.5290	-0.1713380
5.598832	169.5556	-.04826504
5.650500	169.5809	0.08172455
5.700500	169.6051	0.2142389
5.750500	169.6275	0.3504912
5.802168	169.6500	0.5015503
5.853832	169.6713	0.6554986
5.903834	169.6918	0.8111332
5.953832	169.7113	0.9828804
6.007168	169.7324	1.164255
6.057168	169.7513	1.341419
6.107168	169.7693	1.530973
6.158832	169.7894	1.725280
6.210500	169.8077	1.931559
6.260500	169.8268	2.135616
6.310500	169.8447	2.343816
6.362168	169.8633	2.566370
6.413832	169.8825	2.789828
6.463834	169.8997	3.014295
6.513834	169.9180	3.235975
6.567168	169.9363	3.474960
6.617166	169.9536	3.690324
6.667168	169.9703	3.910781
6.718832	169.9875	4.126820
6.770500	170.0038	4.336206
6.820500	170.0181	4.529591
6.870500	170.0324	4.709359
6.922168	170.0460	4.883422
6.973834	170.0578	5.036312
7.023834	170.0687	5.168070
7.073834	170.0781	5.281430
7.127168	170.0863	5.383165
7.177168	170.0932	5.460144
7.227168	170.0995	5.517724
7.278832	170.1040	5.561128
7.330500	170.1078	5.590688
7.380500	170.1102	5.606132
7.430500	170.1118	5.613370
7.483832	170.1132	5.615870
7.533832	170.1133	5.617380
7.583832	170.1142	5.618344
7.635500	170.1144	5.618469
7.687168	170.1139	5.617879
7.737168	170.1148	5.616465
7.787168	170.1141	5.614707
7.838834	170.1147	5.612587
7.890500	170.1151	5.610668
7.940500	170.1161	5.609399
7.990500	170.1189	5.609115
8.043834	170.1209	5.613373
8.093832	170.1242	5.632021
8.143832	170.1273	5.674758
8.195500	170.1323	5.744775
8.247168	170.1375	5.831643
8.297168	170.1424	5.922312
8.347168	170.1489	6.009097
8.398834	170.1551	6.102815
8.450500	170.1609	6.193962
8.500500	170.1665	6.279484
8.550500	170.1718	6.355955
8.603832	170.1767	6.431201
8.653832	170.1818	6.489137
8.703834	170.1856	6.536739
8.755500	170.1890	6.571882
8.807168	170.1911	6.593384
8.857166	170.1919	6.603692
8.907166	170.1921	6.607022
8.958832	170.1922	6.608176
9.010499	170.1905	6.607169
9.060500	170.1874	6.595086
9.110500	170.1849	6.554119
9.163834	170.1803	6.482797
9.213834	170.1764	6.395152
9.263832	170.1716	6.301338
9.315500	170.1666	6.206892
9.367166	170.1605	6.110904
9.417168	170.1538	6.014656
9.467168	170.1494	5.911770
9.520500	170.1430	5.808140
9.570500	170.1363	5.711462
9.620499	170.1303	5.613420
9.672168	170.1246	5.518085
9.723832	170.1186	5.419709
9.773834	170.1133	5.333752
9.823834	170.1086	5.249550
9.875500	170.1034	5.167075
9.927168	170.0981	5.090862
9.977168	170.0950	5.021925
10.02717	170.0910	4.962960
10.08050	170.0874	4.905454
10.13050	170.0837	4.859535
10.18050	170.0814	4.818096
10.23217	170.0784	4.778462
10.28383	170.0746	4.743176
10.33383	170.0732	4.709542
10.38383	170.0705	4.678232
10.43550	170.0685	4.644986
10.48717	170.0666	4.610941
10.53717	170.0644	4.576012
10.58717	170.0604	4.537981
10.64050	170.0585	4.488965
10.69050	170.0549	4.440815
10.74050	170.0522	4.386553
10.79217	170.0490	4.323820
10.84383	170.0448	4.255887
10.89383	170.0411	4.182591
10.94383	170.0369	4.107701
10.99550	170.0320	4.020877
11.04717	170.0269	3.929460
11.09717	170.0224	3.839600
11.14717	170.0168	3.749963
11.20050	170.0114	3.652816
11.25050	170.0058	3.560862
11.30050	169.9996	3.470101
11.35217	169.9940	3.377236
11.40383	169.9888	3.285236
11.45384	169.9832	3.202583
11.50384	169.9776	3.119632
11.55717	169.9719	3.037844
11.60717	169.9676	2.967706
11.65717	169.9625	2.900162
11.70883	169.9578	2.835203
11.76050	169.9534	2.776467
11.81050	169.9497	2.723864
11.86050	169.9464	2.676518
11.91217	169.9428	2.631120
11.96383	169.9406	2.589560
12.01383	169.9377	2.555959
12.06383	169.9356	2.523500
12.11716	169.9324	2.488735
12.16717	169.9315	2.456453
12.21717	169.9287	2.424421
12.26883	169.9268	2.390487
12.32050	169.9244	2.352027
12.37050	169.9211	2.312909
12.42050	169.9198	2.269931
12.47217	169.9156	2.220778
12.52383	169.9128	2.166196
12.57383	169.9092	2.108044
12.62383	169.9060	2.046130
12.67717	169.9015	1.972483
12.72717	169.8975	1.902199
12.77717	169.8940	1.825474
12.82883	169.8891	1.748503
12.88050	169.8839	1.666994
12.93050	169.8787	1.582558
12.98050	169.8732	1.489379
13.03217	169.8668	1.393084
13.08383	169.8596	1.288453
13.13383	169.8542	1.182678
13.18383	169.8471	1.075301
13.23716	169.8400	0.9623274
13.28717	169.8337	0.8485831
13.33717	169.8251	0.7345147
13.38883	169.8182	0.6138782
13.44050	169.8112	0.4904166
13.49050	169.8039	0.3658341
13.54050	169.7955	0.2450363
13.59383	169.7872	0.1123621
13.64383	169.7801	-6.5972E-3
13.69384	169.7693	-0.1745632
13.74550	169.7615	-0.2814291
13.79717	169.7541	-0.3975078
13.84717	169.7468	-0.5036828
13.89717	169.7400	-0.6126728
13.94884	169.7330	-0.7209405
14.00050	169.7260	-0.8234722
14.05050	169.7198	-0.9186584
14.10050	169.7140	-1.011594
14.15383	169.7074	-1.104616
14.20383	169.7019	-1.185066
14.25383	169.6974	-1.262717
14.30550	169.6922	-1.338661
14.35716	169.6872	-1.407956
14.40717	169.6832	-1.470195
14.45717	169.6793	-1.527599
14.50883	169.6763	-1.581575
14.56050	169.6714	-1.628330
14.61050	169.6691	-1.673400
14.66050	169.6671	-1.712588
14.71383	169.6651	-1.749072
14.76383	169.6622	-1.781866
14.81383	169.6616	-1.812188
14.86550	169.6598	-1.838152
14.91716	169.6581	-1.860836
14.96716	169.6570	-1.880228
15.01717	169.6556	-1.897510
15.06884	169.6539	-1.911784
15.12050	169.6534	-1.925396
15.17050	169.6514	-1.935610
15.22050	169.6506	-1.945758
15.27383	169.6496	-1.954901
15.32384	169.6480	-1.962051
15.37384	169.6476	-1.969782
15.42550	169.6475	-1.977075
15.47717	169.6455	-1.983926
15.52717	169.6448	-1.990668
15.57717	169.6439	-1.997851
15.63050	169.6433	-2.005424
15.68050	169.6428	-2.012638
15.73050	169.6417	-2.019940
15.78217	169.6411	-2.027532
15.83383	169.6395	-2.035109
15.88383	169.6394	-2.042655
15.93383	169.6398	-2.050020
15.98550	169.6387	-2.057610
16.03717	169.6379	-2.065122
16.08716	169.6384	-2.072453
16.13716	169.6378	-2.079717
16.19050	169.6380	-2.087461
16.24050	169.6377	-2.094642
16.29050	169.6382	-2.101782
16.34216	169.6374	-2.109039
16.39383	169.6378	-2.116201
16.44383	169.6378	-2.122927
16.49383	169.6373	-2.129490
16.54550	169.6371	-2.136126
16.59716	169.6374	-2.142654
16.64716	169.6370	-2.148832
16.69716	169.6360	-2.154880
16.75050	169.6365	-2.161138
16.80050	169.6368	-2.166906
16.85050	169.6358	-2.172484
16.90216	169.6359	-2.178260
16.95383	169.6356	-2.183844
17.00383	169.6356	-2.189121
17.05383	169.6355	-2.194166
17.10550	169.6348	-2.199251
17.15716	169.6343	-2.204287
17.20716	169.6344	-2.209019
17.25716	169.6347	-2.213584
17.31050	169.6336	-2.218321
17.36050	169.6341	-2.222629
17.41050	169.6346	-2.226825
17.46216	169.6329	-2.230975
17.51383	169.6328	-2.235140
17.56383	169.6325	-2.239035
17.61383	169.6319	-2.242832
17.66716	169.6317	-2.246846
17.71716	169.6318	-2.250439
17.76716	169.6316	-2.254006
17.81883	169.6310	-2.257563
17.87050	169.6312	-2.261111
17.92050	169.6310	-2.264470
17.97050	169.6311	-2.267764
18.02216	169.6308	-2.271031
18.07383	169.6314	-2.274303
18.12383	169.6311	-2.277358
18.17383	169.6318	-2.280328
18.22716	169.6296	-2.283366
18.27716	169.6303	-2.286196
18.32716	169.6304	-2.288953
18.37883	169.6309	-2.291787
18.43050	169.6303	-2.294535
18.48050	169.6306	-2.297082
18.53050	169.6306	-2.299556
18.58216	169.6301	-2.302061
18.63383	169.6305	-2.304588
18.68383	169.6310	-2.306953
18.73383	169.6306	-2.309310
18.78717	169.6314	-2.311772
18.83716	169.6302	-2.313945
18.88716	169.6320	-2.316176
18.93883	169.6315	-2.318241
18.99050	169.6318	-2.320213
19.04050	169.6307	-2.322076
19.09050	169.6317	-2.323958
19.14216	169.6312	-2.325822
19.19383	169.6304	-2.327592
19.24383	169.6311	-2.329317
19.29383	169.6312	-2.331036
19.34716	169.6306	-2.332738
19.39716	169.6310	-2.334258
19.44716	169.6306	-2.335781
19.49883	169.6299	-2.337270
19.55050	169.6304	-2.338696
19.60050	169.6300	-2.340066
19.65050	169.6291	-2.341410
19.70383	169.6294	-2.342932
19.75383	169.6300	-2.344299
19.80383	169.6302	-2.345748
19.85550	169.6297	-2.347210
19.90716	169.6296	-2.348660
19.95716	169.6291	-2.350000
20.00716	169.6294	-2.351280
20.05883	169.6294	-2.352493
20.11050	169.6294	-2.353706
20.16050	169.6298	-2.354913
20.21050	169.6295	-2.356053
20.26383	169.6297	-2.357190
20.31383	169.6292	-2.358284
20.36383	169.6297	-2.359384
20.41550	169.6286	-2.360390
20.46716	169.6291	-2.361470
20.51716	169.6298	-2.362569
20.56716	169.6299	-2.363655
20.61883	169.6302	-2.364800
20.67050	169.6300	-2.365904
20.72050	169.6303	-2.366957
20.77050	169.6308	-2.367982
20.82383	169.6309	-2.369030
20.87383	169.6309	-2.369926
20.92383	169.6302	-2.370789
20.97550	169.6313	-2.371635
21.02717	169.6310	-2.372407
21.07716	169.6310	-2.373220
21.12716	169.6312	-2.373989
21.17883	169.6316	-2.374867
21.23050	169.6306	-2.375525
21.28050	169.6304	-2.376068
21.33050	169.6303	-2.376610
21.38383	169.6303	-2.377166
21.43383	169.6308	-2.377690
21.48383	169.6299	-2.378237
21.53550	169.6296	-2.378838
21.58716	169.6306	-2.379466
21.63716	169.6302	-2.380025
21.68716	169.6300	-2.380555
21.74050	169.6300	-2.381136
21.79050	169.6291	-2.381606
21.84050	169.6289	-2.382023
21.89216	169.6285	-2.382398
21.94383	169.6284	-2.382774
21.99383	169.6281	-2.383193
22.04383	169.6279	-2.383617
22.09550	169.6285	-2.384098
22.14716	169.6284	-2.384577
22.19716	169.6285	-2.385121
22.24716	169.6286	-2.385683
22.30050	169.6279	-2.386260
22.35050	169.6280	-2.386762
22.40050	169.6283	-2.387266
22.45216	169.6284	-2.387766
22.50383	169.6279	-2.388236
22.55383	169.6285	-2.388707
22.60383	169.6278	-2.389187
22.65550	169.6287	-2.389678
22.70717	169.6290	-2.390062
22.75716	169.6276	-2.390406
22.80716	169.6284	-2.390785
22.86050	169.6288	-2.391160
22.91050	169.6280	-2.391539
22.96050	169.6284	-2.391973
23.01216	169.6280	-2.392445
23.06383	169.6295	-2.392964
23.11383	169.6290	-2.393319
23.16383	169.6287	-2.393640
23.21550	169.6291	-2.394066
23.26716	169.6289	-2.394414
23.31716	169.6292	-2.394716
23.36716	169.6284	-2.395047
23.42050	169.6288	-2.395341
23.47050	169.6291	-2.395672
23.52050	169.6293	-2.396041
23.57216	169.6292	-2.396382
23.62383	169.6301	-2.396824
23.67383	169.6303	-2.397266
23.72383	169.6296	-2.397646
23.77717	169.6302	-2.398095
23.82716	169.6296	-2.398481
23.87716	169.6309	-2.398852
23.92883	169.6305	-2.399224
23.98050	169.6305	-2.399570
24.03050	169.6298	-2.399842
24.08050	169.6301	-2.400138
24.13216	169.6299	-2.400470
24.18383	169.6302	-2.400761
24.23383	169.6291	-2.400952
24.28383	169.6301	-2.401128
24.33716	169.6291	-2.401285
24.38716	169.6292	-2.401326
24.43716	169.6289	-2.401390
24.48883	169.6281	-2.401441
24.54050	169.6289	-2.401526
24.59050	169.6290	-2.401508
24.64050	169.6282	-2.401628
24.69216	169.6281	-2.401840
24.74383	169.6286	-2.402172
24.79383	169.6293	-2.402490
24.84383	169.6294	-2.402842
24.89716	169.6290	-2.403234
24.94716	169.6284	-2.403613
24.99716	169.6297	-2.403980
25.04883	169.6298	-2.404336
25.10050	169.6294	-2.404598
25.15050	169.6287	-2.404829
25.20050	169.6294	-2.404968
25.25217	169.6290	-2.405130
25.30383	169.6294	-2.405241
25.35383	169.6291	-2.405350
25.40383	169.6287	-2.405405
25.45717	169.6287	-2.405414
25.50716	169.6284	-2.405486
25.55716	169.6284	-2.405550
25.60883	169.6281	-2.405670
25.66050	169.6281	-2.405820
25.71050	169.6278	-2.405879
25.76050	169.6276	-2.406057
25.81383	169.6274	-2.406270
25.86383	169.6269	-2.406477
25.91383	169.6275	-2.406685
25.96550	169.6274	-2.406907
26.01716	169.6273	-2.407168
26.06716	169.6282	-2.407496
26.11716	169.6281	-2.407867
26.16883	169.6291	-2.408257
26.22050	169.6284	-2.408632
26.27050	169.6290	-2.409008
26.32050	169.6291	-2.409280
26.37383	169.6297	-2.409483
26.42383	169.6295	-2.409639
26.47383	169.6294	-2.409846
26.52550	169.6289	-2.410080
26.57717	169.6290	-2.410301
26.62716	169.6306	-2.410551
26.67717	169.6297	-2.410701
26.72883	169.6302	-2.410923
26.78050	169.6297	-2.411118
26.83050	169.6297	-2.411200
26.88050	169.6299	-2.411375
26.93383	169.6294	-2.411466
26.98383	169.6291	-2.411545
27.03383	169.6294	-2.411596
27.08550	169.6287	-2.411596
27.13716	169.6287	-2.411629
27.18717	169.6292	-2.411690
27.23716	169.6287	-2.411634
27.28883	169.6288	-2.411688
27.34050	169.6289	-2.411843
27.39050	169.6293	-2.412048
27.44050	169.6290	-2.412227
27.49383	169.6281	-2.412374
27.54383	169.6294	-2.412621
27.59383	169.6289	-2.412740
27.64550	169.6288	-2.412858
27.69717	169.6282	-2.412839
27.74716	169.6283	-2.412829
27.79716	169.6287	-2.412770
27.85050	169.6278	-2.412756
27.90050	169.6288	-2.412776
27.95050	169.6281	-2.412739
28.00217	169.6284	-2.412737
28.05383	169.6284	-2.412703
28.10383	169.6281	-2.412727
28.15383	169.6289	-2.412832
28.20550	169.6288	-2.412992
28.25716	169.6285	-2.413058
28.30716	169.6293	-2.413168
28.35716	169.6289	-2.413215
28.41050	169.6288	-2.413249
28.46050	169.6294	-2.413304
28.51050	169.6295	-2.413302
28.56217	169.6293	-2.413294
28.61383	169.6294	-2.413278
28.66383	169.6289	-2.413148
28.71383	169.6282	-2.413080
28.76550	169.6289	-2.413030
28.81716	169.6287	-2.413006
28.86716	169.6290	-2.413010
28.91716	169.6281	-2.412918
28.97050	169.6290	-2.412988
29.02050	169.6289	-2.413094
29.07050	169.6291	-2.413204
29.12216	169.6297	-2.413393
29.17383	169.6296	-2.413569
29.22383	169.6298	-2.413629
29.27383	169.6304	-2.413718
29.32550	169.6293	-2.413789
29.37716	169.6295	-2.413857
29.42717	169.6301	-2.413867
29.47717	169.6303	-2.413848
29.53050	169.6303	-2.413928
29.58050	169.6295	-2.413937
29.63050	169.6288	-2.413967
29.68216	169.6296	-2.413938
29.73383	169.6288	-2.413951
29.78383	169.6297	-2.413936
29.83383	169.6292	-2.413845
29.88716	169.6289	-2.413760
29.93717	169.6292	-2.413727
29.98716	169.6284	-2.413702
30.03883	169.6286	-2.413708
30.09050	169.6276	-2.413822
30.14050	169.6291	-2.414033
30.19050	169.6294	-2.414104
30.24216	169.6293	-2.414254
30.29383	169.6288	-2.414354
30.34383	169.6291	-2.414468
30.39383	169.6297	-2.414584
30.44717	169.6288	-2.414556
30.49716	169.6288	-2.414533
30.54716	169.6284	-2.414473
30.59883	169.6281	-2.414535
30.65050	169.6295	-2.414664
30.70050	169.6288	-2.414749
30.75050	169.6294	-2.414889
30.80217	169.6298	-2.415028
30.85383	169.6296	-2.415130
30.90383	169.6289	-2.415251
30.95383	169.6299	-2.415355
31.00716	169.6303	-2.415444
31.05716	169.6291	-2.415472
31.10716	169.6303	-2.415444
31.15883	169.6297	-2.415308
31.21050	169.6294	-2.415196
31.26050	169.6294	-2.415068
31.31050	169.6296	-2.414886
31.36216	169.6288	-2.414766
31.41383	169.6285	-2.414711
31.46383	169.6287	-2.414712
31.51383	169.6276	-2.417438
31.56716	169.6279	-2.418073
31.61716	169.6280	-2.418528
31.66716	169.6284	-2.418780
31.71883	169.6276	-2.418990
31.77050	169.6279	-2.419072
31.82050	169.6278	-2.419144
31.87050	169.6275	-2.419263
31.92383	169.6272	-2.419432
31.97383	169.6275	-2.419533
32.02383	169.6277	-2.419623
32.07550	169.6276	-2.419794
32.12717	169.6275	-2.420092
32.17717	169.6280	-2.420399
32.22717	169.6284	-2.420743
32.27883	169.6283	-2.421162
32.33050	169.6290	-2.421524
32.38050	169.6295	-2.421768
32.43050	169.6295	-2.421995
32.48383	169.6285	-2.422130
32.53383	169.6290	-2.422304
32.58383	169.6285	-2.422332
32.63550	169.6284	-2.422438
32.68716	169.6281	-2.422494
32.73717	169.6274	-2.422544
32.78717	169.6293	-2.422688
32.83883	169.6284	-2.422826
32.89050	169.6291	-2.422960
32.94050	169.6282	-2.423103
32.99050	169.6284	-2.423248
33.04383	169.6280	-2.423302
33.09384	169.6282	-2.423456
33.14383	169.6290	-2.423615
33.19550	169.6289	-2.423719
33.24716	169.6291	-2.423897
33.29716	169.6296	-2.424008
33.34716	169.6294	-2.424146
33.39883	169.6287	-2.424180
33.45050	169.6290	-2.424178
33.50050	169.6287	-2.424180
33.55050	169.6289	-2.424170
33.60383	169.6288	-2.424250
33.65383	169.6294	-2.424291
33.70383	169.6294	-2.424291
33.75550	169.6289	-2.424305
33.80716	169.6284	-2.424312
33.85716	169.6288	-2.424378
33.90716	169.6285	-2.424366
33.96050	169.6285	-2.424463
34.01050	169.6287	-2.424444
34.06050	169.6290	-2.424428
34.11217	169.6287	-2.424425
34.16383	169.6284	-2.424308
34.21383	169.6286	-2.424255
34.26383	169.6273	-2.424160
34.31550	169.6278	-2.424144
34.36716	169.6278	-2.424182
34.41716	169.6280	-2.424238
34.46716	169.6287	-2.424355
34.52050	169.6282	-2.424412
34.57050	169.6288	-2.424545
34.62050	169.6290	-2.424690
34.67216	169.6288	-2.424764
34.72383	169.6285	-2.424800
34.77383	169.6286	-2.424823
34.82383	169.6288	-2.424869
34.87550	169.6291	-2.424980
34.92717	169.6291	-2.425024
34.97717	169.6287	-2.425108
35.02716	169.6286	-2.425278
35.08050	169.6286	-2.425442
35.13050	169.6290	-2.425609
35.18050	169.6297	-2.425719
35.23216	169.6285	-2.425838
35.28383	169.6290	-2.425918
35.33383	169.6285	-2.425926
35.38383	169.6285	-2.426013
35.43550	169.6286	-2.426072
35.48717	169.6292	-2.426276
35.53717	169.6284	-2.426331
35.58716	169.6294	-2.426436
35.64050	169.6287	-2.426477
35.69050	169.6290	-2.426573
35.74050	169.6281	-2.426561
35.79217	169.6288	-2.426524
35.84384	169.6282	-2.426395
35.89383	169.6284	-2.426357
35.94383	169.6284	-2.426280
35.99716	169.6276	-2.426147
36.04716	169.6274	-2.426065
36.09716	169.6279	-2.425962
36.14883	169.6280	-2.425918
36.20050	169.6269	-2.425780
36.25050	169.6272	-2.425701
36.30050	169.6269	-2.425648
36.35217	169.6277	-2.425600
36.40383	169.6266	-2.425523
36.45383	169.6277	-2.425651
36.50383	169.6280	-2.425740
36.55716	169.6284	-2.425846
36.60716	169.6287	-2.425968
36.65716	169.6287	-2.426094
36.70883	169.6282	-2.426222
36.76050	169.6289	-2.426361
36.81050	169.6278	-2.426416
36.86050	169.6287	-2.426506
36.91217	169.6289	-2.426670
36.96383	169.6293	-2.426789
37.01383	169.6280	-2.426766
37.06383	169.6288	-2.426921
37.11716	169.6285	-2.426940
37.16716	169.6297	-2.426942
37.21716	169.6282	-2.426863
37.26883	169.6285	-2.426836
37.32050	169.6288	-2.426695
37.37050	169.6283	-2.426580
37.42050	169.6284	-2.426524
37.47217	169.6278	-2.426424
37.52383	169.6283	-2.426396
37.57383	169.6286	-2.426405
37.62383	169.6280	-2.426404
37.67717	169.6281	-2.426384
37.72717	169.6284	-2.426426
37.77716	169.6280	-2.426479
37.82883	169.6288	-2.426444
37.88050	169.6273	-2.426438
37.93050	169.6286	-2.426375
37.98050	169.6280	-2.426324
38.03383	169.6276	-2.426285
38.08383	169.6272	-2.426135
38.13383	169.6279	-2.425999
38.18550	169.6272	-2.425894
38.23717	169.6281	-2.425859
38.28717	169.6280	-2.425938
38.33716	169.6281	-2.426021
38.38883	169.6280	-2.426168
38.44050	169.6277	-2.426326
38.49050	169.6280	-2.426520
38.54050	169.6285	-2.426675
38.59384	169.6286	-2.426889
38.64383	169.6290	-2.427020
38.69383	169.6283	-2.427116
38.74550	169.6287	-2.427223
38.79716	169.6287	-2.427352
38.84716	169.6287	-2.427390
38.89717	169.6286	-2.427376
38.94883	169.6283	-2.427306
39.00050	169.6284	-2.427307
39.05050	169.6277	-2.427233
39.10050	169.6277	-2.427177
39.15383	169.6281	-2.427133
39.20383	169.6281	-2.427131
39.25383	169.6284	-2.427148
39.30550	169.6278	-2.427278
39.35716	169.6280	-2.427375
39.40716	169.6278	-2.427450
39.45716	169.6285	-2.427480
39.50883	169.6276	-2.427456
39.56050	169.6271	-2.427389
39.61050	169.6275	-2.427360
39.66050	169.6277	-2.427272
39.71383	169.6283	-2.427191
39.76383	169.6281	-2.427108
39.81383	169.6285	-2.427161
39.86550	169.6276	-2.427129
39.91716	169.6280	-2.427180
39.96716	169.6281	-2.427238
40.01716	169.6281	-2.427196
40.07050	169.6278	-2.427198
40.12050	169.6282	-2.427238
40.17050	169.6279	-2.427280
40.22217	169.6285	-2.427292
40.27383	169.6284	-2.427351
40.32383	169.6279	-2.427298
40.37383	169.6283	-2.427314
40.42550	169.6277	-2.427305
40.47717	169.6279	-2.427246
40.52716	169.6279	-2.427169
40.57717	169.6283	-2.427056
40.63050	169.6274	-2.426960
40.68050	169.6283	-2.426872
40.73050	169.6283	-2.426858
40.78216	169.6289	-2.426918
40.83383	169.6288	-2.426965
40.88383	169.6290	-2.427063
40.93384	169.6290	-2.427134
40.98550	169.6291	-2.427143
41.03717	169.6300	-2.427222
41.08716	169.6287	-2.427226
41.13716	169.6302	-2.427216
41.19050	169.6292	-2.427139
41.24050	169.6287	-2.427070
41.29050	169.6294	-2.426949
41.34217	169.6291	-2.426831
41.39383	169.6292	-2.426686
41.44383	169.6280	-2.426424
41.49383	169.6279	-2.426281
41.54550	169.6282	-2.426172
41.59716	169.6285	-2.426120
41.64717	169.6288	-2.426082
41.69717	169.6276	-2.426115
41.75050	169.6292	-2.426226
41.80050	169.6292	-2.426376
41.85050	169.6293	-2.426516
41.90216	169.6289	-2.426582
41.95383	169.6292	-2.426580
42.00383	169.6292	-2.426575
42.05383	169.6294	-2.426642
42.10717	169.6291	-2.426664
42.15717	169.6298	-2.426666
42.20717	169.6286	-2.426622
42.25883	169.6291	-2.426645
42.31050	169.6296	-2.426617
42.36050	169.6291	-2.426650
42.41050	169.6287	-2.426637
42.46216	169.6290	-2.426678
42.51383	169.6287	-2.426646
42.56383	169.6283	-2.426648
42.61383	169.6287	-2.426616
42.66716	169.6297	-2.426507
42.71717	169.6291	-2.426404
42.76717	169.6291	-2.426240
42.81883	169.6282	-2.426080
42.87050	169.6279	-2.425924
42.92050	169.6279	-2.425736
42.97050	169.6280	-2.425657
43.02050	169.6295	-2.426124
43.07217	169.7201	-4.343176
43.12383	170.0971	-7.785809
43.17383	170.6484	-10.22849
43.22383	171.3278	-12.08379
43.27716	172.1486	-13.47029
43.32717	172.9818	-14.37591
43.37717	173.8570	-15.03130
43.42883	174.7925	-15.53101
43.48050	175.7484	-15.88825
43.53050	176.6899	-16.15934
43.58050	177.6397	-16.38301
43.63217	178.6289	-16.58395
43.68383	179.6245	-16.75970
43.73383	180.5925	-16.91657
43.78383	181.5626	-17.08306
43.83716	182.5999	-17.25979
43.88716	183.5748	-17.42978
43.93716	184.5491	-17.61334
43.98883	185.5581	-17.82911
44.04050	186.5667	-18.04319
44.09050	187.5511	-17.97530
44.14050	188.5400	-17.97829
44.19383	189.5930	-18.09546
44.24383	190.5779	-18.28887
44.29383	191.5610	-18.51718
44.34550	192.5752	-18.78099
44.39717	193.5866	-19.09797
44.44717	194.5636	-19.46457
44.49716	195.5380	-19.88413
44.54883	196.5397	-20.45718
44.60050	197.5349	-21.24034
44.65050	198.4899	-22.07203
44.70050	199.4340	-23.21242
44.75383	200.4251	-24.77915
44.80383	201.3310	-26.87176
44.85383	202.2144	-29.09832
44.90550	203.1147	-31.43671
44.95717	204.0082	-33.83828
45.00717	204.8709	-35.99388
45.05717	205.7367	-38.24182
45.10883	206.6228	-40.89880
45.16050	207.4963	-43.73836
45.21050	208.3392	-46.24259
45.26050	209.1957	-48.05284
45.31383	210.1556	-48.44060
45.36383	211.1340	-46.77676
45.41383	212.2215	-42.55104
45.46550	213.4836	-36.10540
45.51717	214.8327	-29.74174
45.56717	216.1496	-25.30894
45.61716	217.4001	-22.92926
45.66883	218.6150	-21.39394
45.72050	219.7725	-20.38434
45.77050	220.8550	-19.72262
45.82050	221.9129	-19.20404
45.87383	223.0207	-18.88910
45.92383	224.0459	-18.68802
45.97383	225.0620	-18.56403
46.02550	226.1076	-18.49905
46.07717	227.1472	-18.45643
46.12717	228.1510	-18.44080
46.17717	229.1538	-18.44216
46.23050	230.2192	-18.44291
46.28050	231.2182	-18.44487
46.33050	232.2162	-18.45172
46.38217	233.2464	-18.55797
46.43383	234.2773	-18.58079
46.48383	235.2760	-18.58922
46.53383	236.2744	-18.60736
46.58550	237.3056	-18.62035
46.63716	238.3381	-18.64093
46.68716	239.3356	-18.66631
46.73717	240.3340	-18.69247
46.79050	241.3988	-18.71675
46.84050	242.3962	-18.74470
46.89050	243.3938	-18.77675
46.94217	244.4247	-18.81667
46.99383	245.4554	-18.84546
47.04383	246.4528	-18.87575
47.09384	247.4510	-18.90060
47.14550	248.4829	-18.93059
47.19717	249.5138	-18.94943
47.24716	250.5137	-18.97445
47.29716	251.5112	-19.00498
47.35050	252.5752	-19.02984
47.40050	253.5739	-19.05043
47.45050	254.5728	-19.08594
47.50217	255.6034	-19.10904
47.55383	256.6342	-19.15181
47.60383	257.6321	-19.18197
47.65383	258.6284	-19.22205
47.70550	259.6589	-19.27014
47.75717	260.6892	-19.30969
47.80717	261.6858	-19.34842
47.85717	262.6845	-19.38642
47.91050	263.7478	-19.42308
47.96050	264.7455	-19.45738
48.01050	265.7426	-19.48342
48.06216	266.7748	-19.51287
48.11383	267.8060	-19.54625
48.16383	268.8020	-19.57158
48.21383	269.8002	-19.60821
48.26717	270.8648	-19.64147
48.31717	271.8622	-19.66310
48.36716	272.8589	-19.70403
48.41883	273.8908	-19.72430
48.47050	274.9220	-19.73520
48.51717	275.8517	-19.85259
48.56717	276.6664	-20.63161
48.62050	276.9010	-14.34898
48.67050	276.7502	-7.804334
48.72050	276.3510	-2.588485
48.77217	275.7654	1.320539
48.82383	275.0562	4.070741
48.87383	274.2900	5.928250
48.92383	273.4680	7.230210
48.97550	272.5776	8.162675
49.02716	271.6578	8.806426
49.07717	270.7462	9.240819
49.12717	269.8201	9.549481
49.18050	268.8188	9.777159
49.23050	267.8715	9.924591
49.28050	266.9170	10.03380
49.33217	265.9264	10.11530
49.38383	264.9281	10.18115
49.43383	263.9604	10.21952
49.48383	262.9884	10.24980
49.53717	261.9499	10.27386
49.58716	260.9736	10.29457
49.63716	259.9951	10.30997
49.68883	258.9828	10.32255
49.74050	257.9688	10.33626
49.79050	256.9863	10.34773
49.84050	256.0020	10.35749
49.89217	254.9847	10.36830
49.94383	253.9668	10.37923
49.99383	252.9792	10.39140
50.04383	251.9921	10.40283
50.09716	250.9399	10.41267
50.14717	249.9518	10.42719
50.19717	248.9636	10.44014
50.24883	247.9425	10.45973
50.30050	246.9211	10.47889
50.35050	245.9304	10.49399
50.40050	244.9406	10.50628
50.45216	243.9166	10.52055
50.50383	242.8930	10.52959
50.55383	241.9012	10.53726
50.60383	240.9100	10.54520
50.65717	239.8533	10.55419
50.70717	238.8614	10.56599
50.75717	237.8690	10.57855
50.80883	236.8443	10.58807
50.86050	235.8188	10.60219
50.91050	234.8262	10.61113
50.96050	233.8330	10.62058
51.01216	232.8066	10.62927
51.06383	231.7815	10.63778
51.11383	230.7887	10.64760
51.16383	229.7956	10.65762
51.21717	228.7366	10.66691
51.26716	227.7441	10.67803
51.31716	226.7515	10.69097
51.36883	225.7249	10.70302
51.42050	224.6993	10.71794
51.47050	223.7056	10.73216
51.52050	222.7124	10.74432
51.57383	221.6523	10.75642
51.62383	220.6586	10.76676
51.67383	219.6648	10.77901
51.72550	218.6366	10.79015
51.77717	217.6092	10.79930
51.82717	216.6158	10.80845
51.87717	215.6216	10.81760
51.92883	214.5947	10.82681
51.98050	213.5675	10.83636
52.03050	212.5745	10.84609
52.08050	211.5795	10.85544
52.13383	210.5193	10.86569
52.18383	209.5254	10.87461
52.23383	208.5312	10.88464
52.28550	207.5039	10.89431
52.33716	206.4770	10.90535
52.38716	205.4828	10.91478
52.43716	204.4881	10.92342
52.48882	203.4605	10.93366
52.54050	202.4326	10.94248
52.59050	201.4391	10.95118
52.64050	200.4455	10.96017
52.69384	199.3853	10.97256
52.74382	198.3911	10.98273
52.79382	197.3970	10.99371
52.84550	196.3692	11.00475
52.89717	195.3419	11.01524
52.94717	194.3456	11.02495
52.99717	193.3513	11.03390
53.04883	192.3238	11.04424
53.10050	191.2970	11.05340
53.15050	190.3022	11.06216
53.20050	189.3082	11.07149
53.25383	188.2475	11.08104
53.30383	187.2537	11.09090
53.35383	186.2594	11.10038
53.40550	185.2311	11.11042
53.45717	184.2038	11.11939
53.50717	183.2095	11.12901
53.55717	182.2140	11.13789
53.61050	181.1525	11.14700
53.66050	180.1585	11.15663
53.71050	179.1637	11.16610
53.76216	178.1369	11.17744
53.81382	177.1085	11.18969
53.86382	176.1152	11.20027
53.91382	175.1203	11.21726
53.96550	174.0930	11.22913
54.01716	173.0652	11.24071
54.06716	172.0712	11.25078
54.11716	171.0756	11.26161
54.17050	170.0147	11.27483
54.22050	169.0216	11.30152
54.27050	168.0278	11.37680
54.32217	167.0023	11.51852
54.37383	165.9797	11.79119
54.42383	164.9965	12.16689
54.47382	164.0267	12.82028
54.52550	163.0431	13.96035
54.57717	162.0900	15.75599
54.62717	161.2066	18.21023
54.67717	160.3651	21.28730
54.73050	159.5031	24.85398
54.78050	158.7098	27.95065
54.83050	157.9044	30.40789
54.88217	157.0354	31.99995
54.93383	156.1147	32.56188
54.98383	155.1658	32.19124
55.03383	154.1606	31.04016
55.08550	153.0730	29.34256
55.13716	151.9501	27.36402
55.18716	150.8419	25.42065
55.23717	149.7285	23.57436
55.29050	148.5453	21.86381
55.34050	147.4440	20.43389
55.39050	146.3532	19.18010
55.44216	145.2361	18.06583
55.49382	144.1302	17.12266
55.54382	143.0720	16.35022
55.59384	142.0224	15.72978
55.64717	140.9121	15.16410
55.69717	139.8791	14.75952
55.74717	138.8547	14.41641
55.79883	137.8013	14.15961
55.85050	136.7535	13.95981
55.90050	135.7433	13.81858
55.95050	134.7361	13.69480
56.00217	133.6980	13.59106
56.05383	132.6483	13.03769
56.10383	131.6339	12.84715
56.15383	130.6220	12.69470
56.20717	129.5477	12.56798
56.25717	128.5425	12.48306
56.30717	127.5398	12.39457
56.35883	126.5039	12.32938
56.41050	125.4692	12.26868
56.46050	124.4697	12.22949
56.51050	123.4703	12.17903
56.56216	122.4360	12.08448
56.61382	121.4020	12.01902
56.66382	120.4022	11.96329
56.71382	119.4013	11.89649
56.76716	118.3341	11.83204
56.81716	117.3333	11.77879
56.86716	116.3341	11.73079
56.91882	115.3009	11.68072
56.97050	114.2670	11.63564
57.02050	113.2677	11.58425
57.07050	112.2681	11.53535
57.12217	111.2346	11.48596
57.17383	110.2019	11.43397
57.22382	109.2032	11.39816
57.27383	108.2037	11.35993
57.32717	107.1369	11.30940
57.37717	106.1366	11.26576
57.42717	105.1384	11.22028
57.47883	104.1051	11.18398
57.53050	103.0741	11.14662
57.58050	102.0748	11.10671
57.63050	101.0745	11.06562
57.68383	100.0094	11.02049
57.73383	99.00946	10.98622
57.78383	98.01020	10.94186
57.83550	96.97711	10.90148
57.88716	95.94569	10.85689
57.93716	94.94696	10.82392
57.98717	93.94812	10.79454
58.03882	92.91666	10.76336
58.09050	91.88332	10.72825
58.14050	90.88598	10.69168
58.19050	89.88634	10.65635
58.24382	88.82281	10.61667
58.29382	87.82414	10.58890
58.34384	86.82504	10.55467
58.39550	85.79361	10.52191
58.44717	84.76218	10.49319
58.49717	83.76321	10.46130
58.54717	82.76446	10.43125
58.59882	81.73270	10.39874
58.65050	80.69978	10.36624
58.70050	79.70157	10.32783
58.75050	78.70176	10.29541
58.80383	77.63512	10.25589
58.85383	76.63660	10.22082
58.90383	75.63862	10.18976
58.95550	74.60704	10.16144
59.00717	73.57636	10.13044
59.05717	72.57720	10.10633
59.10717	71.57859	10.07101
59.15883	70.54595	10.04210
59.21050	69.51374	10.00611
59.26050	68.51378	9.973322
59.31050	67.51609	9.932613
59.36382	66.45030	9.898614
59.41382	65.45169	9.867106
59.46382	64.45337	9.840775
59.51550	63.42105	9.799126
59.56716	62.38814	9.761382
59.61716	61.38861	9.717019
59.66716	60.38810	9.677174
59.72050	59.32318	9.633343
59.77050	58.32362	9.600347
59.82050	57.32570	9.562866
59.87217	56.29368	9.535743
59.92383	55.26195	9.500390
59.97382	54.26260	9.471546
60.02383	53.26366	9.441528
60.07550	52.23190	9.406234
60.12717	51.19963	9.371080
60.17717	50.20191	9.336732
60.22717	49.20299	9.305825
60.28050	48.13629	9.267465
60.33050	47.13803	9.231842
60.38050	46.13914	9.202246
60.43217	45.10620	9.169485
60.48383	44.07511	9.133691
60.53383	43.07500	9.103085
60.58383	42.07726	9.069970
60.63550	41.04460	9.033312
60.68716	40.01190	8.992061
60.73717	39.01164	8.951870
60.78716	38.01246	8.905542
60.84050	36.94529	8.855175
60.89050	35.94580	8.812848
60.94050	34.94476	8.768045
60.99216	33.91169	8.713851
61.04382	32.87766	8.668149
61.09384	31.87570	8.617400
61.14384	30.87490	8.567834
61.19550	29.84177	8.522413
61.24717	28.80852	8.466122
61.29717	27.80723	8.418272
61.34716	26.80530	8.366326
61.40050	25.73702	8.310020
61.45050	24.73651	8.270558
-2.000000	4.000000	0.0000000
61.54883	22.82115	8.513424
61.60050	22.37936	6.065463
61.65050	22.39332	2.360557
61.70050	22.68076	-0.5581222
61.75383	23.20494	-2.782107
61.80383	23.83464	-4.267096
61.85383	24.56176	-5.324500
61.90550	25.38447	-6.113490
61.95717	26.25847	-6.678744
62.00717	27.13885	-7.084305
62.05717	28.04378	-7.379028
62.10883	28.99820	-7.606182
62.16050	29.96888	-7.779234
62.21050	30.91577	-7.899147
62.26050	31.87242	-8.004470
62.31382	32.90006	-8.079544
62.36382	33.86618	-8.139343
62.41382	34.83632	-8.186851
62.46550	35.84219	-8.228126
62.51716	36.84972	-8.266606
62.56716	37.82694	-8.301720
62.61716	38.80580	-8.338628
62.66882	39.81983	-8.372832
62.72050	40.83434	-8.409988
62.77050	41.81759	-8.446691
62.82050	42.80154	-8.471434
62.87383	43.85220	-8.500226
62.92383	44.84026	-8.529003
62.97382	45.82757	-8.563720
63.02550	46.84956	-8.596168
63.07717	47.87228	-8.633602
63.12717	48.86228	-8.669351
63.17717	49.85309	-8.706618
63.22883	50.87678	-8.749868
63.28050	51.90100	-8.790962
63.33050	52.89424	-8.834102
63.38050	53.88709	-8.875194
63.43383	54.94439	-8.916491
63.48383	55.93614	-8.963451
63.53383	56.92955	-9.009499
63.58550	57.95563	-9.059508
63.63716	58.98199	-9.112747
63.68716	59.97631	-9.160340
63.73717	60.96855	-9.203070
63.79050	62.02984	-9.266785
63.84050	63.02379	-9.315866
63.89050	64.01810	-9.363570
63.94216	65.04695	-9.413153
63.99382	66.07551	-9.456894
64.04384	67.07038	-9.507660
64.09384	68.06621	-9.557976
64.14550	69.09532	-9.611890
64.19717	70.12274	-9.664616
64.24717	71.11774	-9.717934
64.29718	72.11182	-9.776474
64.35050	73.17501	-9.839947
64.40050	74.17100	-9.887891
64.45050	75.16688	-9.942809
64.50217	76.19700	-9.997278
64.55383	77.22491	-10.05212
64.60383	78.21978	-10.10659
64.65384	79.21576	-10.16784
64.70550	80.24551	-10.22620
64.75718	81.27468	-10.28706
64.80717	82.27132	-10.34282
64.85718	83.26708	-10.40080
64.91050	84.32946	-10.46486
64.96050	85.32491	-10.52678
65.01050	86.32166	-10.58783
65.06216	87.35005	-10.64985
65.11384	88.37997	-10.71336
65.16382	89.37505	-10.77416
65.21384	90.37168	-10.83799
65.26550	91.40106	-10.90122
65.31717	92.42978	-10.96602
65.36718	93.42538	-11.02451
65.41717	94.42169	-11.09130
65.47050	95.48406	-11.16032
65.52050	96.48101	-11.22332
65.57050	97.47724	-11.27801
65.62218	98.50701	-11.34730
65.67384	99.53606	-11.41079
65.72384	100.5324	-11.46961
65.77384	101.5290	-11.53474
65.82718	102.5917	-11.60246
65.87718	103.5897	-11.66550
65.92718	104.5850	-11.72290
65.97884	105.6156	-11.79796
66.03050	106.6450	-11.86438
66.08050	107.6412	-11.93099
66.13050	108.6380	-11.99470
66.18218	109.6671	-12.06224
66.23384	110.6961	-12.12978
66.28384	111.6919	-12.20168
66.33384	112.6887	-12.27730
66.38718	113.7506	-12.34864
66.43718	114.7457	-12.41530
66.48718	115.7413	-12.49041
66.53882	116.7700	-12.55795
66.59050	117.7990	-12.63878
66.64050	118.7946	-12.70939
66.69050	119.7911	-12.78529
66.74218	120.8195	-12.86061
66.79384	121.8492	-12.94365
66.84384	122.8443	-13.01554
66.89384	123.8400	-13.09844
66.94718	124.9022	-13.17637
66.99718	125.8983	-13.25690
67.04718	126.8949	-13.32469
67.09882	127.9244	-13.40524
67.15050	128.9551	-13.47500
67.20050	129.9506	-13.54513
67.25050	130.9463	-13.63578
67.30218	131.9756	-13.71718
67.35384	133.0037	-13.79873
67.40384	133.9987	-13.88474
67.45384	134.9943	-13.97398
67.50718	136.0563	-14.06550
67.55718	137.0510	-14.15854
67.60718	138.0450	-14.25015
67.65884	139.0732	-14.34607
67.71050	140.1018	-14.43827
67.76050	141.0964	-14.53308
67.81050	142.0918	-14.62364
67.86384	143.1527	-14.72083
67.91382	144.1480	-14.81567
67.96384	145.1434	-14.90219
68.01550	146.1705	-15.00067
68.06718	147.1982	-15.09506
68.11718	148.1929	-15.18255
68.16718	149.1877	-15.26763
68.21884	150.2151	-15.36453
68.27050	151.2432	-15.45511
68.32050	152.2379	-15.53760
68.37050	153.2334	-15.62163
68.42384	154.2952	-15.70211
68.47384	155.2913	-15.78176
68.52384	156.2864	-15.85014
68.57550	157.3153	-15.91199
68.62718	158.3458	-15.96606
68.67718	159.3430	-15.99899
68.72718	160.3409	-16.02742
68.77884	161.3723	-16.05039
68.83050	162.4051	-16.06304
68.88050	163.4037	-16.07478
68.93050	164.4038	-16.09102
68.98384	165.4708	-16.11531
69.03384	166.4687	-16.15389
69.08384	167.4663	-16.24232
69.13550	168.4970	-16.29903
69.18718	169.5276	-16.37465
69.23718	170.5234	-16.46192
69.28718	171.5195	-16.55103
69.33884	172.5478	-16.65411
69.39050	173.5755	-16.75538
69.44050	174.5706	-16.87236
69.49050	175.5647	-16.98235
69.54384	176.6238	-17.11784
69.59384	177.6155	-17.24496
69.64384	178.6082	-17.40692
69.69550	179.6319	-17.63599
69.74718	180.6547	-17.77452
69.79718	181.6448	-17.98256
69.84718	182.6332	-18.20824
69.90050	183.6871	-18.47125
69.95050	184.6720	-18.75915
70.00050	185.6556	-19.08287
70.05218	186.6696	-19.44031
70.10384	187.6818	-19.83928
70.15384	188.6595	-20.25881
70.20384	189.6351	-20.69373
70.25550	190.6427	-21.15562
70.30718	191.6482	-21.62022
70.35718	192.6218	-22.07840
70.40718	193.5928	-22.56811
70.46050	194.6274	-23.13335
70.51050	195.5953	-23.71526
70.56050	196.5596	-24.38244
70.61218	197.5528	-25.13552
70.66382	198.5409	-25.96240
70.71384	199.4938	-26.82626
70.76384	200.4423	-27.70673
70.81550	201.4227	-28.60973
70.86718	202.4040	-29.41802
70.91718	203.3588	-30.03044
70.96718	204.3234	-30.28269
71.02050	205.3768	-30.02028
71.07050	206.4033	-28.37737
71.12050	207.4852	-25.72425
71.17218	208.6589	-22.51685
71.22384	209.8491	-20.14771
71.27384	210.9755	-18.86341
71.32384	212.0677	-18.08964
71.37550	213.1663	-17.55509
71.42718	214.2444	-17.21294
71.47718	215.2735	-17.00020
71.52718	216.2928	-16.84821
71.58050	217.3740	-16.75432
71.63050	218.3814	-16.70620
71.68050	219.3873	-16.67780
71.73218	220.4250	-16.66979
71.78384	221.4610	-16.66728
71.83384	222.4619	-16.66699
71.88384	223.4609	-16.66764
71.93718	224.5264	-16.67092
71.98718	225.5260	-16.67675
72.03718	226.5250	-16.68989
72.08884	227.5572	-16.70652
72.14050	228.5892	-16.72657
72.19050	229.5874	-16.75140
72.24050	230.5857	-16.78984
72.29218	231.6168	-16.82981
72.34384	232.6490	-16.87511
72.39384	233.6451	-16.92026
72.44384	234.6437	-16.96213
72.49718	235.7084	-17.00242
72.54718	236.7066	-17.03522
72.59718	237.7042	-17.06860
72.64884	238.7365	-17.10343
72.70050	239.7680	-17.14060
72.75050	240.7664	-17.17583
72.80050	241.7644	-17.21030
72.85218	242.7960	-17.25623
72.90384	243.8276	-17.29788
72.95384	244.8252	-17.33157
73.00384	245.8231	-17.37711
73.05718	246.8877	-17.41443
73.10718	247.8866	-17.44986
73.15718	248.8835	-17.48440
73.20884	249.9148	-17.52339
73.26050	250.9451	-17.56480
73.31050	251.9434	-17.60440
73.36050	252.9417	-17.64233
73.41218	253.9727	-17.68099
73.46384	255.0035	-17.72480
73.51384	256.0013	-17.76671
73.56384	256.9991	-17.81492
73.61718	258.0635	-17.85700
73.66718	259.0611	-17.90475
73.71718	260.0588	-17.94970
73.76882	261.0892	-17.99542
73.82050	262.1198	-18.04637
73.87050	263.1177	-18.09667
73.92050	264.1169	-18.13658
73.97384	265.1802	-18.18998
74.02384	266.1788	-18.23597
74.07384	267.1765	-18.27820
74.12550	268.2070	-18.32489
74.17718	269.2380	-18.38852
74.22718	270.2346	-18.43383
74.27718	271.2325	-18.47966
74.32884	272.2625	-18.53173
-2.000000	5.000000	0.0000000